{
  "name": "bridge_deadzone_1",
  "refpalette": "c70cities:bridge_deadzone_1_palette",
  "xsize": 16,
  "zsize": 16,
  "slices": [
    [
      "                ",
      "aabaabbabbaaabbb",
      "cdedcdceeecccddc",
      "ceeccdceccdedeec",
      "faafbaabfffbfaaf",
      "HHHHHHHHHgHHHHHH",
      "HHHHHHHgHHgHgggH",
      "HgHggHHHHHHHHHHH",
      "HHggHHgHgHHHggHH",
      "HHHHHHHHHHHgHHHH",
      "HHHHHHgHgHHHHHHH",
      "abafbffbaafbfaba",
      "eeeddcccceedeecc",
      "eeedddcddeedeecc",
      "abbffffaabbabbab",
      "                "
    ],
    [
      "                ",
      " hh hb hhbhhhhbh",
      "                ",
      "                ",
      " ziiizihzjzihizz",
      "zi      ki      ",
      "  z zz          ",
      "       zz  zz   ",
      "          z     ",
      "   k z z z    z ",
      "z  z            ",
      "iiiijiihzhiihzhi",
      "                ",
      "                ",
      " bhhhbhhhbhhhhb ",
      "                "
    ],
    [
      "                ",
      "                ",
      "                ",
      "                ",
      "         j      ",
      "                ",
      "                ",
      "                ",
      "                ",
      "                ",
      "                ",
      "    j           ",
      "                ",
      "                ",
      "                ",
      "                "
    ],
    [
      "                ",
      "                ",
      "                ",
      "                ",
      "         j      ",
      "                ",
      "                ",
      "                ",
      "                ",
      "                ",
      "                ",
      "                ",
      "                ",
      "                ",
      "                ",
      "                "
    ]
  ],
  "meta": [
    {
      "key": "support",
      "char": "v"
    }
  ]
}