{
  "name": "bridge_3",
  "refpalette": "c70cities:bridge_3_palette",
  "xsize": 16,
  "zsize": 16,
  "slices": [
    [
      "                ",
      "aaaaaaaaaaaaaaaa",
      "bbbbbbbbbbbbbbbb",
      "bbbbbbbbbbbbbbbb",
      "cddeddddccddeddd",
      "aaffffffaaffffaa",
      "HHHHHHHHHHHHHHHH",
      "HHHHHHHHHHHHHHHH",
      "HHHHHHHHHHHHHHHH",
      "HHHHHHHHHHHHHHHH",
      "aaffffffffffffaa",
      "dddedddcddddedcc",
      "bbbbbbbbbbbbbbbb",
      "bbbbbbbbbbbbbbbb",
      "aaaaaaaaaaaaaaaa",
      "                "
    ],
    [
      "                ",
      "faggggggggg ggaf",
      "                ",
      "                ",
      "   hi       j   ",
      "kallllllffllllak",
      "                ",
      "                ",
      "                ",
      "                ",
      "kallllllllllllak",
      "   h       mh   ",
      "                ",
      "                ",
      "faggggggggggggaf",
      "                "
    ],
    [
      "                ",
      " n            n ",
      "                ",
      "                ",
      "   h        j   ",
      "                ",
      "                ",
      "                ",
      "                ",
      "                ",
      "                ",
      "   h        h   ",
      "                ",
      "                ",
      " n            n ",
      "                "
    ],
    [
      "                ",
      "                ",
      "                ",
      "                ",
      "   h            ",
      "                ",
      "                ",
      "                ",
      "                ",
      "                ",
      "                ",
      "   h        h   ",
      "                ",
      "                ",
      "                ",
      "                "
    ],
    [
      "                ",
      "                ",
      "                ",
      "                ",
      "                ",
      "                ",
      "                ",
      "                ",
      "                ",
      "                ",
      "                ",
      "   i        i   ",
      "                ",
      "                ",
      "                ",
      "                "
    ]
  ],
  "meta": [
    {
      "key": "support",
      "char": "v"
    }
  ]
}