{
  "name": "bridge_1",
  "refpalette": "c70cities:bridge_1_palette",
  "xsize": 16,
  "zsize": 16,
  "slices": [
    [
      "                ",
      "aaaaaaaaaaaaaaaa",
      "bbbbbbbbbbbbbbbb",
      "bbbbbbbbbbbbbbbb",
      "cccdccccccccdccc",
      "eaeeeeeeeeeeeeae",
      "ffffffffffffffff",
      "ffffffffffffffff",
      "ffffffffffffffff",
      "ffffffffffffffff",
      "eaeeeeeeeeeeeeae",
      "cccdccccccccdccc",
      "bbbbbbbbbbbbbbbb",
      "bbbbbbbbbbbbbbbb",
      "aaaaaaaaaaaaaaaa",
      "                "
    ],
    [
      "                ",
      "gahhhhhhhhhhhhag",
      "                ",
      "                ",
      "  ij        k   ",
      "lammmmmmmmmmmmal",
      "                ",
      "                ",
      "                ",
      "                ",
      "lammmmmmmmmmmmal",
      "   j        j   ",
      "                ",
      "                ",
      "gahhhhhhhhhhhhag",
      "                "
    ],
    [
      "                ",
      " n            n ",
      "                ",
      "                ",
      "   j        k   ",
      "                ",
      "                ",
      "                ",
      "                ",
      "                ",
      "                ",
      "   j        j   ",
      "                ",
      "                ",
      " n            n ",
      "                "
    ],
    [
      "                ",
      "                ",
      "                ",
      "            o   ",
      "   j        k   ",
      "                ",
      "                ",
      "                ",
      "                ",
      "                ",
      "                ",
      "   j        j   ",
      "            p   ",
      "                ",
      "                ",
      "                "
    ],
    [
      "                ",
      "                ",
      "                ",
      "            q   ",
      "   r        r   ",
      "                ",
      "                ",
      "                ",
      "                ",
      "                ",
      "                ",
      "   q        q   ",
      "   r            ",
      "                ",
      "                ",
      "                "
    ]
  ],
  "meta": [
    {
      "key": "support",
      "char": "v"
    }
  ]
}