{
  "name": "bridge_2",
  "refpalette": "c70cities:bridge_2_palette",
  "xsize": 16,
  "zsize": 16,
  "slices": [
    [
      "                ",
      "aaaaaaaaaaaaaaaa",
      "bbbbbbbbbbbbbbbb",
      "bbbbbbbbbbbbbbbb",
      "cccdcceeccccdccc",
      "aaffffffffffffaa",
      "HHHHHHHHHHHHHHHH",
      "HHHHHHHHHHHHHHHH",
      "HHHHHHHHHHHHHHHH",
      "HHHHHHgHHHHHHHHH",
      "aaffffffffffffaa",
      "eccdccccecccdccc",
      "bbbbbbbbbbbbbbbb",
      "bbbbbbbbbbbbbbbb",
      "aaaaaaaaaaaaaaaa",
      "                "
    ],
    [
      "                ",
      "fahhhhhhhhhhhhaf",
      "                ",
      "                ",
      "  ij        k   ",
      "lammmmmmmmmmmmal",
      "                ",
      "                ",
      "                ",
      "                ",
      "lammmmmmmmmmmmal",
      "   j        j   ",
      "                ",
      "                ",
      "fahhhhhhhhhhhhaf",
      "                "
    ],
    [
      "                ",
      " n            n ",
      "                ",
      "                ",
      "   j        k   ",
      "                ",
      "                ",
      "                ",
      "                ",
      "                ",
      "                ",
      "   j        j   ",
      "                ",
      "                ",
      " n            n ",
      "                "
    ],
    [
      "                ",
      "                ",
      "                ",
      "   o            ",
      "   j        k   ",
      "                ",
      "                ",
      "                ",
      "                ",
      "                ",
      "                ",
      "   j        j   ",
      "            o   ",
      "                ",
      "                ",
      "                "
    ],
    [
      "                ",
      "                ",
      "                ",
      "   p        p   ",
      "   q        q   ",
      "                ",
      "                ",
      "                ",
      "                ",
      "                ",
      "                ",
      "   p        p   ",
      "            q   ",
      "                ",
      "                ",
      "                "
    ]
  ],
  "meta": [
    {
      "key": "support",
      "char": "v"
    }
  ]
}