{
  "name": "bridge_1",
  "refpalette": "c70cities:bridge_1_palette",
  "xsize": 16,
  "zsize": 16,
  "slices": [
    [
      "                ",
      "aaaaaaaaaaaaaaaa",
      "bbbbbbbbbbbbbbbb",
      "bbbbbbbbbbbbbbbb",
      "cccdccccccccdccc",
      "aaeeeeeeeeeeeeaa",
      "HHHHHHHHHHHHHHHH",
      "HHHHHHHHHHHHHHHH",
      "HHHHHHHHHHHHHHHH",
      "HHHHHHfHHHHHHHHH",
      "aaeeeeeeeeeeeeaa",
      "cccdccccccccdccc",
      "bbbbbbbbbbbbbbbb",
      "bbbbbbbbbbbbbbbb",
      "aaaaaaaaaaaaaaaa",
      "                "
    ],
    [
      "                ",
      "eaggggggggggggae",
      "                ",
      "                ",
      "  hi        j   ",
      "kallllllllllllak",
      "                ",
      "                ",
      "                ",
      "                ",
      "kallllllllllllak",
      "   i        i   ",
      "                ",
      "                ",
      "eaggggggggggggae",
      "                "
    ],
    [
      "                ",
      " m            m ",
      "                ",
      "                ",
      "   i        j   ",
      "                ",
      "                ",
      "                ",
      "                ",
      "                ",
      "                ",
      "   i        i   ",
      "                ",
      "                ",
      " m            m ",
      "                "
    ],
    [
      "                ",
      "                ",
      "                ",
      "            n   ",
      "   i        j   ",
      "                ",
      "                ",
      "                ",
      "                ",
      "                ",
      "                ",
      "   i        i   ",
      "            o   ",
      "                ",
      "                ",
      "                "
    ],
    [
      "                ",
      "                ",
      "                ",
      "            p   ",
      "   q        q   ",
      "                ",
      "                ",
      "                ",
      "                ",
      "                ",
      "                ",
      "   p        p   ",
      "   q            ",
      "                ",
      "                ",
      "                "
    ]
  ],
  "meta": [
    {
      "key": "support",
      "char": "v"
    }
  ]
}