{
  "name": "building_hotel1_floor3_180",
  "refpalette": "c70cities:building_hotel1_floor3_palette_180",
  "xsize": 16,
  "zsize": 16,
  "slices": [
    [
      "                ",
      " aagggggaaaaaaa ",
      " abbbbbbbbbbbba ",
      " fbbbbcbbbbbbbd ",
      " fbbbbcbbbbbbbd ",
      " fbbbbcccccbbbd ",
      " fbbbbe   cbbbd ",
      " abbbb    cbbbd ",
      " abbbb    cbbbd ",
      " abbbd    cbbbd ",
      " acccccccccbbba ",
      " abbbbbbbbbbbba ",
      " abbbbbbbbbbbba ",
      " abbbbbbbbbbbba ",
      " aaaaaaaaaaaaaa ",
      "                "
    ],
    [
      "                ",
      " aaaaaaaaaaaaaa ",
      " aneeeaC      a ",
      " f BBeaA f y  a ",
      " f    axwfut  a ",
      " f    aaaapaa a ",
      " f    dee a=  a ",
      " an  s    ar  a ",
      " a   s    ar  a ",
      " a        a=  a ",
      " aaqapaaaap   a ",
      " a   o == o   a ",
      " a          nma ",
      " a l  kjji  h a ",
      " aaaaaaaaaaaaaa ",
      "                "
    ],
    [
      "                ",
      " aaaaaaffffffaa ",
      " aI   a       a ",
      " f    a  f    a ",
      " f    aK f    a ",
      " f    aaaapaa a ",
      " f      deaJ  f ",
      " aI      ea   f ",
      " a        a   f ",
      " a        aF  f ",
      " aaEapaaaap   a ",
      " a   o    o   a ",
      " a          D a ",
      " a            a ",
      " aaaaaaaaaaaaaa ",
      "                "
    ],
    [
      "                ",
      " aaaaaaaaaaaaaa ",
      " aI   a       a ",
      " f    a  f    a ",
      " f    aM fL   a ",
      " f    aaaapaaaa ",
      " f        a   a ",
      " aI      daB  a ",
      " a       eaB  a ",
      " a       ea   a ",
      " aaaapaaaap   a ",
      " a   o    o   a ",
      " a            a ",
      " a   L    L   a ",
      " aaaaaaaaaaaaaa ",
      "                "
    ],
    [
      "                ",
      " aaaaaaffaaaaaa ",
      " a    a  f    a ",
      " f    a  f    a ",
      " f    a  fN   a ",
      " f    aaaapaaaa ",
      " f        a   a ",
      " a        a   a ",
      " a        a   a ",
      " a     eeda   a ",
      " aaaapaaaap   a ",
      " a            f ",
      " a            f ",
      " a   N    N   a ",
      " aaaaaaaaaaaaaa ",
      "                "
    ],
    [
      "                ",
      " aaaaaaaaaaaaaa ",
      " aOOOOaOOOOOOOa ",
      " fOOOOaOOOOOOOa ",
      " fOOOOaOOOOOOOa ",
      " fOOOOaaaapaaaa ",
      " fOOOO    aOOOa ",
      " aOOOO    aOOOa ",
      " aOOOO    aOOOa ",
      " aOOOOed  aOOOa ",
      " aaaapaaaapOOOa ",
      " aOOOOOOOOOOOOa ",
      " aOOOOOOOOOOOOa ",
      " aOOOOOOOOOOOOa ",
      " aaaaaaaaaaaaaa ",
      "                "
    ]
  ]
}