{
  "name": "building_hotel1_floor3_90",
  "refpalette": "c70cities:building_hotel1_floor3_palette_90",
  "xsize": 16,
  "zsize": 16,
  "slices": [
    [
      "                ",
      " aaaaaaaaffffaa ",
      " abbbcbbbbbbbba ",
      " abbbcbbbbbbbbg ",
      " abbbcbbbbbbbbg ",
      " abbbcdbbbbbbbg ",
      " abbbc   ecccbg ",
      " abbbc    cbbbg ",
      " abbbc    cbbba ",
      " abbbc    cbbba ",
      " abbbccccccbbba ",
      " abbbbbbbbbbbba ",
      " abbbbbbbbbbbba ",
      " abbbbbbbbbbbba ",
      " aaaaadddddddaa ",
      "                "
    ],
    [
      "                ",
      " aaaaaaaaffffaa ",
      " a   a  n    na ",
      " al  q      Cea ",
      " a   a      Cea ",
      " a  op ss   eea ",
      " ak  a   daaaaa ",
      " aj =a   eaxBDa ",
      " aj =a   eawA a ",
      " ai  a    aff a ",
      " a  opaaaapu  a ",
      " a    =rr=aty a ",
      " ahn      aty a ",
      " a m          a ",
      " aaaaaaaaaaaaaa ",
      "                "
    ],
    [
      "                ",
      " aaaaaaaaffffaa ",
      " a   a  J    Ja ",
      " a   F        a ",
      " a   a        a ",
      " a  op        a ",
      " a   a    aaaaa ",
      " a   a    a   f ",
      " a   a   da   f ",
      " a   a  eeaff f ",
      " a  opaaaap   f ",
      " a    I  Ka   f ",
      " a E      a   f ",
      " a            a ",
      " aaaaaffffaaaaa ",
      "                "
    ],
    [
      "                ",
      " aaaaaaaa fffaa ",
      " a   a  J    Ja ",
      " a   a        a ",
      " a   a        a ",
      " aL op        a ",
      " a   a    aaaaa ",
      " a   a    a   a ",
      " a   a    a   a ",
      " a   aeed aff a ",
      " aL opaaaapL  a ",
      " a     CC a   a ",
      " a        a   a ",
      " a        a   a ",
      " aaaaaaaaaaaaaa ",
      "                "
    ],
    [
      "                ",
      " aaaaaaaaffffaa ",
      " a   a        a ",
      " a   a        a ",
      " a   a        a ",
      " aM  p        a ",
      " a   a    aaaaa ",
      " a   ae   a   f ",
      " a   ae   a   f ",
      " a   ad   afffa ",
      " aM  paaaapM  a ",
      " a        a   a ",
      " a        a   a ",
      " a        a   a ",
      " aaffaaaaaaaaaa ",
      "                "
    ],
    [
      "                ",
      " aaaaaaaaffffaa ",
      " aNNNaNNNNNNNNa ",
      " aNNNaNNNNNNNNa ",
      " aNNNaNNNNNNNNa ",
      " aNNNpNNNNNNNNa ",
      " aNNNae   aaaaa ",
      " aNNNad   aNNNa ",
      " aNNNa    aNNNa ",
      " aNNNa    aNNNa ",
      " aNNNpaaaapNNNa ",
      " aNNNNNNNNaNNNa ",
      " aNNNNNNNNaNNNa ",
      " aNNNNNNNNaNNNa ",
      " aaaaaaaaaaaaaa ",
      "                "
    ]
  ]
}