{
  "name": "building_bunker1_base1_270",
  "refpalette": "c70cities:building_bunker1_base1_palette_270",
  "xsize": 16,
  "zsize": 16,
  "slices": [
    [
      "================",
      "================",
      "================",
      "================",
      "=aa=aa==========",
      "=aa=aa==========",
      "=aa=aa==========",
      "==a=a===========",
      "=aaaaa====aaaa==",
      "=aaaaa====aaaa==",
      "==========aaaa==",
      "==========aaaa==",
      "==========aaaa==",
      "==========aaaa==",
      "================",
      "================"
    ],
    [
      "zzzzzzbbbbbbbbbz",
      "zzzzzzbAs oljcbz",
      "zzzzzzbB     cbz",
      "bbbbbbbbbbb  bbz",
      "bJNbNJbowsb  dbz",
      "bK b Kb  sb  dbz",
      "bT b Lb   b  dbz",
      "bbObObEbxbbmbbbz",
      "bU   nbn tp  ebz",
      "bU    F      fbz",
      "bbRbbbbC     ebz",
      "bV bP     q  gbz",
      "bW bQ   y r  hbz",
      "bXSbIMIDyuqnkibz",
      "bbbbbbbbbbbbbbbz",
      "zzzzzzzzzzzzzzzz"
    ],
    [
      "zzzzzzEEEEEEEEEz",
      "zzzzzzEA@  o 0Ez",
      "zzzzzzE$     1Ez",
      "EEEEEEEEEEE  EEz",
      "E}-E&0E wsE   Ez",
      "E\\ E 1E   E   Ez",
      "ET E LE   E   Ez",
      "EE*E*EEE#EE5EEEz",
      "ET   6E6  7  LEz",
      ";     %      2Ez",
      "EE[EEEE      3Ez",
      "E|]E(         Yz",
      "E`]E)     8   Yz",
      "E: E+ ^   96  Yz",
      "E{{EEEEEEEEE44Zz",
      "zzzzzzzzzzzzzzzz"
    ],
    [
      "zzzzzzEEEEEEEEEz",
      "zzzzzzEA      Ez",
      "zzzzzzE!     'Ez",
      "EEEEEEEEEEE  EEz",
      "Ef E fE w E  ,Ez",
      "E  E <E   E  ,Ez",
      "E >E> E   E  ,Ez",
      "EEEEEEEE{EEEEEEz",
      "E\u00c0   6E6     .Ez",
      "E\u00c0    E      .Ez",
      "EEEEEEE      .Ez",
      "E \u00a5E?        .Ez",
      "E\u00c1\u00a7E\u00a3        .Ez",
      "E\u00c2 E\u00a4//    6 .Ez",
      "EEEEEEEEEEEEEEEz",
      "zzzzzzzzzzzzzzzz"
    ],
    [
      "zzzzzzEEEEEEEEEz",
      "zzzzzzEA\u00c3\u00c3\u00c5\u00c3\u00c3\u00c3Ez",
      "zzzzzzE\u00c3\u00c3\u00c3\u00c5\u00c3\u00c3\u00c3Ez",
      "EEEEEEEEEEE\u00c5\u00c6EEz",
      "E\u00c5\u00c6E\u00c6\u00c5EEwEE\u00c3\u00c3\u00c4Ez",
      "E\u00c3\u00c3E\u00c3\u00c3EEEEE\u00c3\u00c3\u00c4Ez",
      "E\u00c3\u00c3E\u00c3\u00c3EEEEE\u00c3\u00c3\u00c4Ez",
      "EEEEEEEEEEEEEEEz",
      "E\u00c5\u00c3\u00c3\u00c3\u00c3E\u00c3\u00c3\u00c3\u00c3\u00c3\u00c3\u00c5Ez",
      "E\u00c5\u00c3\u00c3\u00c3\u00c3E\u00c3\u00c3\u00c3\u00c3\u00c3\u00c3\u00c5Ez",
      "EEEEEEE\u00c3\u00c3\u00c3\u00c3\u00c3\u00c3\u00c5Ez",
      "E\u00c3\u00c3EEEE\u00c3\u00c3\u00c3\u00c3\u00c3\u00c3\u00c5Ez",
      "E\u00c3\u00c3E\u00c5\u00c5\u00c5\u00c3\u00c3\u00c3\u00c3\u00c3\u00c3\u00c5Ez",
      "E\u00c5\u00c5EEEE\u00c3\u00c3\u00c3\u00c3\u00c3\u00c3\u00c5Ez",
      "EEEEEEEEEEEEEEEz",
      "zzzzzzzzzzzzzzzz"
    ],
    [
      "zzzzzzzzzzzzzzzz",
      "zzzzzzzzzzzzzzzz",
      "zzzzzzzzzzzzzzzz",
      "zzzzzzzzEzzzzzzz",
      "zzzzzzzEwEzzzzzz",
      "zzzzzzzzEzzzzzzz",
      "zzzzzzzzzzzzzzzz",
      "zzzzzzzzzzzzzzzz",
      "zzzzzzzzzzzzzzzz",
      "zzzzzzzzzzzzzzzz",
      "zzzzzzzzzzzzzzzz",
      "zzzzzzzzzzzzzzzz",
      "zzzzzzzzzzzzzzzz",
      "zzzzzzzzzzzzzzzz",
      "zzzzzzzzzzzzzzzz",
      "zzzzzzzzzzzzzzzz"
    ]
  ]
}