{
  "name": "building_office3_floor1_180",
  "refpalette": "c70cities:building_office3_floor1_palette_180",
  "xsize": 16,
  "zsize": 16,
  "slices": [
    [
      "                ",
      " aabaabaabaabaa ",
      " acccccccccccca ",
      " bccccccccccccb ",
      " acc!ccccccccca ",
      " acccccccccccca ",
      " bccccccccccccb ",
      " acccccdvccccca ",
      " acccccdvccccca ",
      " bccccccccccccb ",
      " acccccccccccca ",
      " acccccccccccca ",
      " bccccccccccccb ",
      " acccccccccccca ",
      " aabaabaabaabaa ",
      "                "
    ],
    [
      "                ",
      " eebeebeebeebee ",
      " e            e ",
      " b f  q p   f b ",
      " e  ppppp     e ",
      " e   g g      e ",
      " b           ob ",
      " e     dvn e he ",
      " e     dvm e he ",
      " b           lb ",
      " e    k k     e ",
      " e   ji  ih   e ",
      " b f   g g  f b ",
      " e            e ",
      " eebeebeebeebee ",
      "                "
    ],
    [
      "                ",
      " rrbrrbrrbrrbrr ",
      " r            r ",
      " b f        f b ",
      " r            r ",
      " r            r ",
      " b            b ",
      " r     dvt    r ",
      " r     dvt    r ",
      " b            b ",
      " r            r ",
      " r    ssss    r ",
      " b f        f b ",
      " r            r ",
      " rrbrrbrrbrrbrr ",
      "                "
    ],
    [
      "                ",
      " rrbrrbrrbrrbrr ",
      " r            r ",
      " b f        f b ",
      " r            r ",
      " r            r ",
      " b            b ",
      " r     dvt    r ",
      " r     dvt    r ",
      " b            b ",
      " r            r ",
      " r            r ",
      " b f        f b ",
      " r            r ",
      " rrbrrbrrbrrbrr ",
      "                "
    ],
    [
      "                ",
      " rrbrrbrrbrrbrr ",
      " r            r ",
      " b f        f b ",
      " r            r ",
      " r            r ",
      " b            b ",
      " r     dv     r ",
      " r     dv     r ",
      " b            b ",
      " r            r ",
      " r            r ",
      " b f        f b ",
      " r            r ",
      " rrbrrbrrbrrbrr ",
      "                "
    ],
    [
      "                ",
      " rrbrrbrrbrrbrr ",
      " ruuuuuuuuuuuur ",
      " bufwwwwwwwwfub ",
      " ruwwwwwwwwwwur ",
      " ruwwwwwwwwwwur ",
      " buwwwwwwwwwwub ",
      " ruwwwwdvwwwwur ",
      " ruwwwwdvwwwwur ",
      " buwwwwwwwwwwub ",
      " ruwwwwwwwwwwur ",
      " ruwwwwwwwwwwur ",
      " bufwwwwwwwwfub ",
      " ruuuuuuuuuuuur ",
      " rrbrrbrrbrrbrr ",
      "                "
    ]
  ]
}