{
  "name": "building_office4_ground_90",
  "refpalette": "c70cities:building_office4_ground_palette_90",
  "xsize": 16,
  "zsize": 16,
  "slices": [
    [
      "GGGGGGGGGGGGGGGG",
      "GaaaaaaaaaaaaaaG",
      "GabbbcbbbbcbbbaG",
      "GabbbbbbbbbbbbaG",
      "GabbbbbbbbbbbbaG",
      "GacbbbbbbbbbbcaG",
      "GabbbbbbbbbbbbaG",
      "GabbbbbbbbbbbbaG",
      "GabbbbbbbbbbbbaG",
      "GabbbbbbbbbbbbaG",
      "GacbbbbbbbbbbcaG",
      "GabbbbbbbbbbbbaG",
      "GabbbbbbbbbbbbaG",
      "GabbbcbbbbcbbbaG",
      "GaaaaaaaaaaaaaaG",
      "GGGGGGGGGGGGGGGG"
    ],
    [
      "                ",
      " aaaadaopadaaaa ",
      " aekkc    ckkea ",
      " af          qa ",
      " af          qa ",
      " dc          cd ",
      " ai           a ",
      " ah   m  m   sa ",
      " ag  llllll  ra ",
      " a    j  j    a ",
      " dc          cd ",
      " af          qa ",
      " af          qa ",
      " aejjc nn cjjea ",
      " aaaadaaaadaaaa ",
      "                "
    ],
    [
      "                ",
      " aaaadawxadaaaa ",
      " at  c    c  ta ",
      " a            a ",
      " a            a ",
      " dc          cd ",
      " a            a ",
      " a            a ",
      " a     u  y   a ",
      " a            a ",
      " dc          cd ",
      " a            a ",
      " a            a ",
      " at  c nn c  ta ",
      " aaaadaaaadaaaa ",
      "                "
    ],
    [
      "                ",
      " aaaadaaaadaaaa ",
      " at  c    c  ta ",
      " a            a ",
      " a            a ",
      " dc          cd ",
      " a            a ",
      " a            a ",
      " a            a ",
      " a            a ",
      " dc          cd ",
      " a            a ",
      " a            a ",
      " at  c nn c  ta ",
      " aaaadaaaadaaaa ",
      "                "
    ],
    [
      "                ",
      " aaaadaaaadaaaa ",
      " a   c    c   a ",
      " a            a ",
      " a            a ",
      " dc          cd ",
      " a            a ",
      " a     BB     a ",
      " a     AA     a ",
      " a            a ",
      " dc          cd ",
      " a            a ",
      " a            a ",
      " a   c nn c   a ",
      " aaaadaaaadaaaa ",
      "                "
    ],
    [
      "                ",
      "    adaaaada    ",
      "  CCCcDDDDcCCC  ",
      "  CDDDDDDDDDDC  ",
      " aCDDDDDDDDDDCa ",
      " dcDDDDDDDDDDcd ",
      " aDDDDDDDDDDDDa ",
      " aDDDDDEEDDDDDa ",
      " aDDDDDEEDDDDDa ",
      " aDDDDDDDDDDDDa ",
      " dcDDDDDDDDDDcd ",
      " aCDDDDDDDDDDCa ",
      "  CDDDDDDDDDDC  ",
      "  CCCcDnnDcCCC  ",
      "    adaaaada    ",
      "                "
    ]
  ]
}