{
  "name": "building_hotel2_base1_180",
  "refpalette": "c70cities:building_hotel2_base1_palette_180",
  "xsize": 16,
  "zsize": 16,
  "slices": [
    [
      "vvvvvvvvvvvvvvvv",
      "vaaaaaaaaaaaaaav",
      "va!bbbb!bbbbb!av",
      "vabbbbbbbbbbbbav",
      "vabbbbbbbbbbbbav",
      "vabbbbbbbbbbbbav",
      "vabbbbbbbbbbbbav",
      "vabbbbbbbbbbbbav",
      "vabbbbbbbbbbbbav",
      "vabbbbbbbbbbbbav",
      "vabbbbbbbbbbbbav",
      "vabbbbbbbbbbbbav",
      "vabbbbbbbbbbbbav",
      "vabbbbbbbbbbbbav",
      "vaaaaaaaaaaaaaav",
      "vvvvvvvvvvvvvvvv"
    ],
    [
      "vvvvvvvvvvvvvvvv",
      "vccccccccccccccv",
      "vco  mf       fv",
      "vcl  nfi i i ifv",
      "vcl  mfe  e  efv",
      "vcl  kfg g g gfv",
      "vcf  ff       fv",
      "vcj      i i ifv",
      "vc=hhh    e  efv",
      "vcbbb=   g g gfv",
      "vcbbb=e       fv",
      "vcbbb=      e==v",
      "vcbbb=e      dcv",
      "vcbbb=       dcv",
      "vccccccccccccccv",
      "vvvvvvvvvvvvvvvv"
    ],
    [
      "vvvvvvvvvvvvvvvv",
      "vccccccccccccccv",
      "vc   wf       fv",
      "vc   uf       fv",
      "vc    fj jjj jfv",
      "vc   tf       fv",
      "vcf  ff       fv",
      "vcj           fv",
      "vc=      jjj jfv",
      "vcp  =        fv",
      "vcps =q       fv",
      "vcp  =      r==v",
      "vcp  =q      dcv",
      "vcpoo=       dcv",
      "vccccccccccccccv",
      "vvvvvvvvvvvvvvvv"
    ],
    [
      "vvvvvvvvvvvvvvvv",
      "vccccccccccccccv",
      "vc    f       fv",
      "vcy   f       fv",
      "vcA   f       fv",
      "vcy   f       fv",
      "vcf  ff       fv",
      "vcj           fv",
      "vc=           fv",
      "vcs           fv",
      "vcs           fv",
      "vc          r==v",
      "vcs          dcv",
      "vcs  x       dcv",
      "vccccccccccccccv",
      "vvvvvvvvvvvvvvvv"
    ],
    [
      "vvvvvvvvvvvvvvvv",
      "vccccccccccccccv",
      "vc    f       fv",
      "vc    f       fv",
      "vcA   f       fv",
      "vc    f       fv",
      "vcfffff       fv",
      "vcj           fv",
      "vc=           fv",
      "vcs           fv",
      "vc            fv",
      "vcs          ==v",
      "vcs          dcv",
      "vcs          dcv",
      "vccccccccccccccv",
      "vvvvvvvvvvvvvvvv"
    ],
    [
      "vvvvvvvvvvvvvvvv",
      "vccccccccccccccv",
      "vcBBBBfBBBBBBBBv",
      "vcBBBBfBBBBBBBBv",
      "vcBBBBfBBBBBBBBv",
      "vcBBBBfBBBBBBBBv",
      "vcfffffBBBBBBBBv",
      "vcBBBBBBBBBBBBBv",
      "vc=BBBBBBBBBBBBv",
      "vcDBBBBBBBBBBBBv",
      "vcCBBBBBBBBBBBBv",
      "vcCBBBBBBBBBB==v",
      "vcDBBBBBBBBBBdcv",
      "vcCBBBBBBBBBBdcv",
      "vccccccccccccccv",
      "vvvvvvvvvvvvvvvv"
    ]
  ]
}