{
  "name": "building_hotel1_floor3_270",
  "refpalette": "c70cities:building_hotel1_floor3_palette_270",
  "xsize": 16,
  "zsize": 16,
  "slices": [
    [
      "                ",
      " aadddddddaaaaa ",
      " abbbbbbbbbbbba ",
      " abbbbbbbbbbbba ",
      " abbbbbbbbbbbba ",
      " abbbccccccbbba ",
      " abbbc    cbbba ",
      " abbbc    cbbba ",
      " gbbbc    cbbba ",
      " gbccce   cbbba ",
      " gbbbbbbbdcbbba ",
      " gbbbbbbbbcbbba ",
      " gbbbbbbbbcbbba ",
      " abbbbbbbbcbbba ",
      " aaffffaaaaaaaa ",
      "                "
    ],
    [
      "                ",
      " aaaaaaaaaaaaaa ",
      " a          m a ",
      " a   a      nha ",
      " a yta=rr=    a ",
      " a  upaaaapo  a ",
      " a ffa    a  ia ",
      " a  wae   a= ja ",
      " aCAxae   a= ja ",
      " aaaaad   a  ka ",
      " aee   ss po  a ",
      " aeB      a   a ",
      " aeB      q  la ",
      " an    n  a   a ",
      " aaffffaaaaaaaa ",
      "                "
    ],
    [
      "                ",
      " aaaaaffffaaaaa ",
      " a            a ",
      " f   a      D a ",
      " f   aJ  F    a ",
      " f   paaaapo  a ",
      " f ffaee  a   a ",
      " f   ad   a   a ",
      " f  Ka    a   a ",
      " aaaaa    a   a ",
      " a        po  a ",
      " a        a   a ",
      " a        E   a ",
      " aI    I  a   a ",
      " aaffffaaaaaaaa ",
      "                "
    ],
    [
      "                ",
      " aaaaaaaaaaaaaa ",
      " a   a        a ",
      " a   a        a ",
      " a   a BB     a ",
      " a  Lpaaaapo La ",
      " a ffa deea   a ",
      " a   a    a   a ",
      " a  Ma    a   a ",
      " aaaaa    a   a ",
      " a        po La ",
      " a        a   a ",
      " a        a   a ",
      " aI    I  a   a ",
      " aaffffaaaaaaaa ",
      "                "
    ],
    [
      "                ",
      " aaaaaaaaaaffaa ",
      " a   a        a ",
      " a   a        a ",
      " a   a        a ",
      " a  Npaaaap  Na ",
      " afffa   da   a ",
      " f   a   ea   a ",
      " f   a   ea   a ",
      " aaaaa    a   a ",
      " a        p  Na ",
      " a        a   a ",
      " a        a   a ",
      " a        a   a ",
      " aaffffaaaaaaaa ",
      "                "
    ],
    [
      "                ",
      " aaaaaaaaaaaaaa ",
      " aOOOaOOOOOOOOa ",
      " aOOOaOOOOOOOOa ",
      " aOOOaOOOOOOOOa ",
      " aOOOpaaaapOOOa ",
      " aOOOa    aOOOa ",
      " aOOOa    aOOOa ",
      " aOOOa   daOOOa ",
      " aaaaa   eaOOOa ",
      " aOOOOOOOOpOOOa ",
      " aOOOOOOOOaOOOa ",
      " aOOOOOOOOaOOOa ",
      " aOOOOOOOOaOOOa ",
      " aaffffaaaaaaaa ",
      "                "
    ]
  ]
}