{
  "name": "building_hotel3_floor1_270",
  "refpalette": "c70cities:building_hotel3_floor1_palette_270",
  "xsize": 16,
  "zsize": 16,
  "slices": [
    [
      "                ",
      "  a a a a a a   ",
      "  bbbbbbbbbbbba ",
      " abccccccccccb  ",
      "  bceeeeeeeecba ",
      " abceffffffecb  ",
      "  bceffffffecba ",
      " abceffffffedb  ",
      "  bceffffffedba ",
      " abceffffffecb  ",
      "  bceffffffecba ",
      " abceeeeeeeecb  ",
      "  bccccccccccba ",
      " abbbbbbbbbbbb  ",
      "   a a a a a a  ",
      "                "
    ],
    [
      "                ",
      "  a a a a a a   ",
      "  bbbbbbbbbbbba ",
      " ab          b  ",
      "  b seeeeeee ba ",
      " ab l n jjhe b  ",
      "  b lr    he ba ",
      " ab loo mhhedb  ",
      "  b lpp h iedba ",
      " ab lqq hkhe b  ",
      "  b l      g ba ",
      " ab slllllee b  ",
      "  b          ba ",
      " abbbbbbbbbbbb  ",
      "   a a a a a a  ",
      "                "
    ],
    [
      "                ",
      "  a a a a a a   ",
      "  bbbbbbbbbbbba ",
      " ab          b  ",
      "  b sewwwwee ba ",
      " ab  y    ue b  ",
      "  b  y     e ba ",
      " ab  oo  hhedb  ",
      "  b     h  edba ",
      " ab     hxhe b  ",
      "  b        t ba ",
      " ab s     ee b  ",
      "  b          ba ",
      " abbbbbbbbbbbb  ",
      "   a a a a a a  ",
      "                "
    ],
    [
      "                ",
      "  a a a a a a   ",
      "  bbbbbbbbbbbba ",
      " ab          b  ",
      "  b seeeeeee ba ",
      " ab        e b  ",
      "  b        e ba ",
      " ab  oo  hhedb  ",
      "  b     h  edba ",
      " ab     hhhe b  ",
      "  b        e ba ",
      " ab s     ee b  ",
      "  b          ba ",
      " abbbbbbbbbbbb  ",
      "   a a a a a a  ",
      "                "
    ],
    [
      "                ",
      "  a a a a a a   ",
      "  bbbbbbbbbbbba ",
      " ab          b  ",
      "  b seeeeeee ba ",
      " ab       ye b  ",
      "  b       ye ba ",
      " ab   !  hhedb  ",
      "  b     h  edba ",
      " ab     hhhe b  ",
      "  b        e ba ",
      " ab s     ee b  ",
      "  b          ba ",
      " abbbbbbbbbbbb  ",
      "   a a a a a a  ",
      "                "
    ],
    [
      "                ",
      "  a a a a a a   ",
      "  bbbbbbbbbbbba ",
      " ab          b  ",
      "  b eeeeeeee ba ",
      " ab eAAAAAAe b  ",
      "  b eAAAAAAe ba ",
      " ab eAAAAAAedb  ",
      "  b eAAAAAAedba ",
      " ab eAAAAAAe b  ",
      "  b eAAAAAAe ba ",
      " ab eeeeeeee b  ",
      "  b          ba ",
      " abbbbbbbbbbbb  ",
      "   a a a a a a  ",
      "                "
    ]
  ]
}