{
  "name": "building_residential4_floor1",
  "refpalette": "c70cities:building_residential4_floor1_palette",
  "xsize": 16,
  "zsize": 16,
  "slices": [
    [
      "                ",
      "                ",
      "                ",
      " aaaaaaaaaaaaaa ",
      " bcdeeeeeeeedcb ",
      "  cd      f dc  ",
      "  cd     gh dc  ",
      "   i      j i   ",
      "   i        i   ",
      "  cd   klllldc  ",
      "  cd  m     dc  ",
      " ncd  m     dcn ",
      " oooooooooooooo ",
      "                ",
      "                ",
      "                "
    ],
    [
      "                ",
      "                ",
      "                ",
      "     p    q     ",
      " aaaaressetaaaa ",
      " bcdbbb  bbbdcb ",
      "  cd        dc  ",
      "  ui        iu  ",
      "  ui        iu  ",
      "  cd   llllldc  ",
      " ncd  m   wxdcn ",
      " oooooooooooooo ",
      "                ",
      "                ",
      "                ",
      "                "
    ],
    [
      "                ",
      "                ",
      "                ",
      "      p  q      ",
      "      peeq      ",
      " aaaaaryytaaaaa ",
      " bcdbbbbbbbbdcb ",
      "  cd        dc  ",
      "  cd        dc  ",
      " ncdnnnnnnnndcn ",
      " oooooooooooooo ",
      "                ",
      "                ",
      "                ",
      "                ",
      "                "
    ],
    [
      "                ",
      "                ",
      "                ",
      "       pq       ",
      "       pq       ",
      "       pq       ",
      " aaaaaaABaaaaaa ",
      " bcd        dcb ",
      " ncd        dcn ",
      " oooooooooooooo ",
      "                ",
      "                ",
      "                ",
      "                ",
      "                ",
      "                "
    ],
    [
      "                ",
      "                ",
      "                ",
      "                ",
      "                ",
      "                ",
      "                ",
      " aaaaaaaaaaaaaa ",
      " oooooooooooooo ",
      "                ",
      "                ",
      "                ",
      "                ",
      "                ",
      "                ",
      "                "
    ],
    [
      "                ",
      "                ",
      "                ",
      "                ",
      "                ",
      "                ",
      "                ",
      "        ~       ",
      "       ~~       ",
      "                ",
      "                ",
      "                ",
      "                ",
      "                ",
      "                ",
      "                "
    ]
  ]
}