{
  "name": "building_apartment1_floor1_90",
  "refpalette": "c70cities:building_apartment1_floor1_palette_90",
  "xsize": 16,
  "zsize": 16,
  "slices": [
    [
      "                ",
      " aaaaaaaaa      ",
      " abbbbbbbbdeei  ",
      " abbbbbbbbbbfh  ",
      " abbbbbbbbbb g  ",
      " abbbbbbbbc  d  ",
      " abbbbbbbbbbbba ",
      " abbbbbbbbbbbba ",
      " abbbbbbbbbbbba ",
      " abbbbbbbbbbbba ",
      " abbbbbbbbbbbba ",
      " abbbbbbbbbbbba ",
      " abbbbbbbbbbbba ",
      " abbbbbbbbbbbba ",
      " aaaaaaaaaaaaaa ",
      "                "
    ],
    [
      "                ",
      " ltttttttt      ",
      " ks ACpF pdddd  ",
      " k   BpF L RUd  ",
      " kou  ppIp   W  ",
      " kppx p  p   W  ",
      " k  x p  pppppY ",
      " kr y p  K QT!Y ",
      " kq x y  K    Y ",
      " kpwppp  J PP Y ",
      " k    D       Y ",
      " kou CpEIE    Y ",
      " kou Bpr pN   Y ",
      " kn   pq pMOSVY ",
      " jmmmmmmmmmmmmX ",
      "                "
    ],
    [
      "                ",
      " pZZZppppp      ",
      " p   4p  phWdd  ",
      " p    p  9  Rd  ",
      " pou  pp8p  %d  ",
      " pppx p  p   d  ",
      " p1 x p  pppppp ",
      " p  3 p    ## 7 ",
      " p  x 3       Z ",
      " pp2ppp       Z ",
      " p    6       Z ",
      " p    pE8E    Z ",
      " p    p  p@   Z ",
      " p0   p  p  $^7 ",
      " pZZZp577577775 ",
      "                "
    ],
    [
      "                ",
      " pZZZppZZp      ",
      " p(+[ p  pddd`  ",
      " Z    p  p   |  ",
      " Z    pppp  ]d  ",
      " pppx p  p  Ud  ",
      " p* x p  pppppp ",
      " Z  x p       7 ",
      " Z  x p      \\Z ",
      " pppppp      \\Z ",
      " p    p      }Z ",
      " Z    pEEE   {Z ",
      " Z    p  p   {Z ",
      " p&)- p  p    7 ",
      " pZZZp5ZZ57ZZZ5 ",
      "                "
    ],
    [
      "                ",
      " p777pp77p      ",
      " p    p  p|||d  ",
      " k    p fp   W  ",
      " k    pppp   W  ",
      " pppx p  p :]e  ",
      " p  x p  pppppp ",
      " k  x p       7 ",
      " k  x p       7 ",
      " pppppp       7 ",
      " p    p       7 ",
      " k    pEEE    7 ",
      " k    p  p    7 ",
      " p    p  p    7 ",
      " p777p577577775 ",
      "                "
    ],
    [
      "                ",
      " ppppppppp      ",
      " pddddpddpdddd  ",
      " pddddpddp   d  ",
      " pddddpppp   d  ",
      " pddddpddpUc d  ",
      " p;;ddpddpppppp ",
      " p;;ddpdddddddp ",
      " p;;ddpdddddddp ",
      " ppppppdddddddp ",
      " pddddpdddddddp ",
      " pddddpdddddddp ",
      " pddddp;;dddddp ",
      " pddddp;;dddddp ",
      " pppppppppppppp ",
      "                "
    ]
  ]
}