{
  "name": "building_residential2_ground",
  "refpalette": "c70cities:building_residential2_ground_palette",
  "xsize": 16,
  "zsize": 16,
  "slices": [
    [
      "GGGGGGGGGGGGGGGG",
      "GGGGGGGGGGGGGGGG",
      "GGGGGGGGGGGGGGGG",
      "GGGaaaaaaaaaaGGG",
      "GGGabbbbccccaGGG",
      "GGGabbbbccccaGGG",
      "GGGabbbbccccaGGG",
      "GGGabbbbccccaGGG",
      "GGdeeeeeeeeeedGG",
      "GGdccccccccccdGG",
      "GGdccccccccccdGG",
      "GGdccccccccccdGG",
      "GGdccccccccccdGG",
      "GGddddddddddddGG",
      "GGGGGGGGGGGGGGGG",
      "GGGGGGGGGGGGGGGG"
    ],
    [
      "fgggghgggghggggf",
      "g              g",
      "g iiiiiiiiiiii g",
      "g iaaaaaaaaaai g",
      "g iajklmnopqai g",
      "h ia    n   ai h",
      "g ia    n   ai g",
      "g ia  r n   ai g",
      "g s tt  nuu  s g",
      "g s          s g",
      "f s       wwxs h",
      "  y    A BC  s g",
      "  D    E BCFIs g",
      "f ssssssssssss g",
      "g              g",
      "fgggghgggghggggf"
    ],
    [
      "fgggghgggghggggf",
      "g              g",
      "g              g",
      "g  aaaaaaaaaa  g",
      "g  aJK Ln !Ma  g",
      "h  a    n   a  h",
      "g  a    n   a  g",
      "g  aNNN nuu a  g",
      "g s     n    s g",
      "g O          O g",
      "f s       wwPs h",
      "  Q      RC  S g",
      "  T      RC  S g",
      "f ssOOOsssssss g",
      "g              g",
      "fgggghgggghggggf"
    ],
    [
      "                ",
      "                ",
      "                ",
      "   aaUUaaUUaa   ",
      "   a    n   a   ",
      "   U    n   U   ",
      "   U    nuu U   ",
      "   a    n   a   ",
      "  s     n    s  ",
      "  O          O  ",
      "  s       wwws  ",
      "  O       C  S  ",
      "  O       C  S  ",
      "  ssOOOsssssss  ",
      "                ",
      "                "
    ],
    [
      "                ",
      "                ",
      "  VVVVVVVVVVVV  ",
      "  VaaaaaaaaaaV  ",
      "  Va    n   aV  ",
      "  Va    nuu aV  ",
      "  Va    n   aV  ",
      "  Va    n   aV  ",
      "  s     n    s  ",
      "  VWWWWWWWWWWV  ",
      "  VWWWWWWWWWWV  ",
      "  VWWWWWWWWWWV  ",
      "  VWWWWWWWWWWV  ",
      "  VVVVVVVVVVVV  ",
      "                ",
      "                "
    ],
    [
      "                ",
      "                ",
      "  ssssssssssss  ",
      "  sccccccccccs  ",
      "  sccccccuuccs  ",
      "  scccccc  ccs  ",
      "  scccccc  ccs  ",
      "  scccccc  ccs  ",
      "  seeeeeeeeees  ",
      "  s  uu X Y Zs  ",
      "  s     0 1 2s  ",
      "  s         3s  ",
      "  snn  nn  nns  ",
      "  ssssssssssss  ",
      "                ",
      "                "
    ]
  ]
}