{
  "name": "building_restaurant2_ground_270",
  "refpalette": "c70cities:building_restaurant2_ground_palette_270",
  "xsize": 16,
  "zsize": 16,
  "slices": [
    [
      "GGGGGGaGaGGGGGGG",
      "GGGGGGGaabGGGGGG",
      "GGGGGGGbaGGGGGGG",
      "GGaaaaaaaaaabaGG",
      "GGccccccccccccGG",
      "GacgdeegdeegdcaG",
      "GaceeffeeffeecaG",
      "GacffgdffgdffcaG",
      "GacgdgdgdgdgdcaG",
      "GbcgdeegdeegdcbG",
      "GbceeffeeffeecaG",
      "GccccgdffgdccccG",
      "GccccgdgdgdccccG",
      "GccccaaaaaaccccG",
      "GccccbbaabaccccG",
      "GGGGGGGGGGGGGGGG"
    ],
    [
      "                ",
      "                ",
      "                ",
      "  msqom  msqom  ",
      " hmmmmm  mmmmmh ",
      " imp piIEip pmi ",
      " Qm          mj ",
      " Rm  tttttt  mk ",
      " Rm  JAAAAu  mk ",
      " Rm  Kmmmmw  mk ",
      " Sm  LBBBBx  ml ",
      " iiEi      iiii ",
      " iO iMCCFC r ni ",
      " iP iiiiiiiinni ",
      " iiiiNDDDDyiiii ",
      "                "
    ],
    [
      "                ",
      "                ",
      "                ",
      "  mXXXm  mXXXm  ",
      " TmUUUm  mUUUmT ",
      " im   i63i   mi ",
      "  m          m  ",
      "  U          U  ",
      "  U  11111Z  U  ",
      "  U  800000  U  ",
      "  m   2 42   m  ",
      " ii3i      iiii ",
      " i  i9!75  Y Vi ",
      " i@ iiiiiiii Wi ",
      " iiiiXXXXXXiiii ",
      "                "
    ],
    [
      "                ",
      "                ",
      "                ",
      "  mXXXm&&mXXXm  ",
      " TmUUUm  mUUUmT ",
      " im   iiii   mi ",
      " Xm*        VmX ",
      " Xm(        $mX ",
      " Xm( %%%%%% $mX ",
      " Xm( ^^^^^^ $mX ",
      " Xm)        WmX ",
      " iiii      iiii ",
      " i  i      i #i ",
      " i  iiiiiiii  i ",
      " iUUiXXXXXXiUUi ",
      "                "
    ],
    [
      "                ",
      "                ",
      "  -   -  -   -  ",
      "  m+++m&&m+++m  ",
      "  miiim  miiim  ",
      " imiiiiiiiiiimi ",
      " +m]        [m+ ",
      " +m]        [m+ ",
      " +m]        [m+ ",
      " +m]        [m+ ",
      " +m]        [m+ ",
      " iiii      iiii ",
      " i  i      i  i ",
      " i  iiiiiiii  i ",
      " i++i++++++i++i ",
      "                "
    ],
    [
      "                ",
      " {{{{{{{{{{{{{{ ",
      " {{{{{{{{{{{{{{ ",
      " {{{{{{{{{{{{{{ ",
      " {{{{{{{{{{{{{{ ",
      " im}}}}}}}}}}mi ",
      " imPP|PPPP|PPmi ",
      " imPP|PPPP|PPmi ",
      " imPP|PPPP|PPmi ",
      " imPP|PPPP|PPmi ",
      " imPP|PPPP|PPmi ",
      " i}}}}}}}}}}}}i ",
      " i\\\\i}}}}}}i\\\\i ",
      " i\\\\iiiiiiii\\\\i ",
      " iiii}}}}}}iiii ",
      "                "
    ]
  ]
}