{
  "name": "building_office3_floor1",
  "refpalette": "c70cities:building_office3_floor1_palette",
  "xsize": 16,
  "zsize": 16,
  "slices": [
    [
      "                ",
      " aabaabaabaabaa ",
      " acccccccccccca ",
      " bccccccccccccb ",
      " acccccccccccca ",
      " acccccccccccca ",
      " bccccccccccccb ",
      " acccccvdccccca ",
      " acccccvdccccca ",
      " bccccccccccccb ",
      " acccccccccccca ",
      " accccccccc!cca ",
      " bccccccccccccb ",
      " acccccccccccca ",
      " aabaabaabaabaa ",
      "                "
    ],
    [
      "                ",
      " eebeebeebeebee ",
      " e            e ",
      " b f  g g   f b ",
      " e   hi  ij   e ",
      " e     k k    e ",
      " bl           b ",
      " eh e mvd     e ",
      " eh e nvd     e ",
      " bo           b ",
      " e      g g   e ",
      " e     ppppp  e ",
      " b f   p q  f b ",
      " e            e ",
      " eebeebeebeebee ",
      "                "
    ],
    [
      "                ",
      " rrbrrbrrbrrbrr ",
      " r            r ",
      " b f        f b ",
      " r    ssss    r ",
      " r            r ",
      " b            b ",
      " r    tvd     r ",
      " r    tvd     r ",
      " b            b ",
      " r            r ",
      " r            r ",
      " b f        f b ",
      " r            r ",
      " rrbrrbrrbrrbrr ",
      "                "
    ],
    [
      "                ",
      " rrbrrbrrbrrbrr ",
      " r            r ",
      " b f        f b ",
      " r            r ",
      " r            r ",
      " b            b ",
      " r    tvd     r ",
      " r    tvd     r ",
      " b            b ",
      " r            r ",
      " r            r ",
      " b f        f b ",
      " r            r ",
      " rrbrrbrrbrrbrr ",
      "                "
    ],
    [
      "                ",
      " rrbrrbrrbrrbrr ",
      " r            r ",
      " b f        f b ",
      " r            r ",
      " r            r ",
      " b            b ",
      " r     vd     r ",
      " r     vd     r ",
      " b            b ",
      " r            r ",
      " r            r ",
      " b f        f b ",
      " r            r ",
      " rrbrrbrrbrrbrr ",
      "                "
    ],
    [
      "                ",
      " rrbrrbrrbrrbrr ",
      " ruuuuuuuuuuuur ",
      " bufwwwwwwwwfub ",
      " ruwwwwwwwwwwur ",
      " ruwwwwwwwwwwur ",
      " buwwwwwwwwwwub ",
      " ruwwwwvdwwwwur ",
      " ruwwwwvdwwwwur ",
      " buwwwwwwwwwwub ",
      " ruwwwwwwwwwwur ",
      " ruwwwwwwwwwwur ",
      " bufwwwwwwwwfub ",
      " ruuuuuuuuuuuur ",
      " rrbrrbrrbrrbrr ",
      "                "
    ]
  ]
}