{
  "name": "building_policeoffice1_ground_180",
  "refpalette": "c70cities:building_policeoffice1_ground_palette_180",
  "xsize": 16,
  "zsize": 16,
  "slices": [
    [
      "GGgGGGgGGGGGGGGG",
      "eeeeeeeeeeeeeeeG",
      "eGGgbbbbbbbbbfeG",
      "eGGGbbbbbbbbbfeG",
      "eeeeebbbbbbbbeeG",
      "GGdGabbbbbbbbaGG",
      "GGGGabbbbbbbbaGG",
      "GcccabbbbbbbbaGG",
      "cGccabbbbbbbbaGG",
      "GGGGabbbbbbbbaGG",
      "HHHGabbb!bbbbaGG",
      "HHHGabbbbbbbbaGG",
      "HHHGabbbbbbbbaGG",
      "HHHGabbbbbbbbaGG",
      "HHHGaaaaaaaaaaGG",
      "GGGGGGGGGGGGGGGG"
    ],
    [
      "  e   t         ",
      "ey  eyeeexeeexe ",
      "e  tu wsssa  fe ",
      "e   u  ttsa  fe ",
      "eeree     aqpee ",
      "hhhham       ah ",
      "    a        ah ",
      "    o        ah ",
      "    n        ah ",
      "    a        ah ",
      "    am llll  ah ",
      "    a  k  k  ah ",
      "    a        ah ",
      "    ai jjjj iah ",
      "    aaaaaaaaaah ",
      "                "
    ],
    [
      "                ",
      "ex   yeeexeeexe ",
      "e         a  fe ",
      "e         a  fe ",
      "eeree     aEDee ",
      "    aA       a  ",
      "    a        a  ",
      "    C        a  ",
      "    B        a  ",
      "    a        a  ",
      "    aA       a  ",
      "    u        a  ",
      "    u        a  ",
      "    ai jjjj ia  ",
      "    aauaaaauaa  ",
      "                "
    ],
    [
      "                ",
      "exy exeeexeeexe ",
      "e         a  fe ",
      "e         s  fe ",
      "eeree     aaaee ",
      "    aA       a  ",
      "    a        a  ",
      "    a        a  ",
      "    a        a  ",
      "    a        a  ",
      "    aA       a  ",
      "    a        a  ",
      "    a        a  ",
      "    ai j  j ia  ",
      "    aauaaaauaa  ",
      "                "
    ],
    [
      "                ",
      "exeyexeeexeeexe ",
      "e         a  fe ",
      "e         a  fe ",
      "eeree     aaaee ",
      "    a        a  ",
      "    a        a  ",
      "    a        a  ",
      "    u        a  ",
      "    u        a  ",
      "    u        a  ",
      "    u        a  ",
      "    a        a  ",
      "    a  jjjj  a  ",
      "    aaaaaaaaaa  ",
      "                "
    ],
    [
      "                ",
      "exeeexeeexeeexe ",
      "e   IIIIIIaIIfe ",
      "e   IIIIIIaIIfe ",
      "eereeIIIIIaaaee ",
      "    FIIIIIIIIF  ",
      "    FIIIIIIIIF  ",
      "    FIIIIIIIIF  ",
      "    FIIIIIIIIF  ",
      "    FIIIIIIIIF  ",
      "    FIIIIIIIIF  ",
      "    FIIIIIIIIF  ",
      "    FIIIIIIIIF  ",
      "    FIIIIIIIIF  ",
      "    FFFFFFFFFF  ",
      "                "
    ]
  ]
}