{
  "name": "building_office2_ground_90",
  "refpalette": "c70cities:building_office2_ground_palette_90",
  "xsize": 16,
  "zsize": 16,
  "slices": [
    [
      "GGGGGGGGGGGGGGGG",
      "GaGGGGGGGGGGGGaG",
      "GaGbbbbbbbbbbGaG",
      "GabccccccccccbaG",
      "GaccccccccccccaG",
      "Gaccccccccc!ccaG",
      "GaccccccccccccaG",
      "GaccccccccccccaG",
      "GaccccccccccccaG",
      "GaccccccccccccaG",
      "GaccccccccccccaG",
      "GaccccccccccccaG",
      "GabccccccccccbaG",
      "GaGbbbbbbbbbbGaG",
      "GaGGGGGGGGGGGGaG",
      "GGGGGGGGGGGGGGGG"
    ],
    [
      "                ",
      " a            a ",
      " a ggggklgggg a ",
      " ab          ba ",
      " ad          ra ",
      " af  i     m oa ",
      " ae hij      pa ",
      " af  i       qa ",
      " af  i       qa ",
      " af hij      pa ",
      " ae  i       oa ",
      " ad          na ",
      " ab          ba ",
      " a gggggggggg a ",
      " a            a ",
      "                "
    ],
    [
      "                ",
      " a            a ",
      " a ggggtugggg a ",
      " ab          ba ",
      " as           a ",
      " a            a ",
      " a           wa ",
      " a           qa ",
      " a           qa ",
      " a           wa ",
      " a            a ",
      " as           a ",
      " ab          ba ",
      " a gggggggggg a ",
      " a            a ",
      "                "
    ],
    [
      "                ",
      " a            a ",
      " a gggggggggg a ",
      " ab          ba ",
      " as           a ",
      " a            a ",
      " a            a ",
      " a           qa ",
      " a      x    qa ",
      " a            a ",
      " a            a ",
      " as           a ",
      " ab          ba ",
      " a gggggggggg a ",
      " a            a ",
      "                "
    ],
    [
      "                ",
      " a            a ",
      " a gggggggggg a ",
      " ab          ba ",
      " a            a ",
      " a            a ",
      " a            a ",
      " a     xx    qa ",
      " a     xx    qa ",
      " a            a ",
      " a            a ",
      " a            a ",
      " ab          ba ",
      " a gggggggggg a ",
      " a            a ",
      "                "
    ],
    [
      "                ",
      " a            a ",
      " a gggggggggg a ",
      " ab          ba ",
      " ayyyyyyyyyyyya ",
      " ayyyyyyyyyyyya ",
      " ayyyyyyyyyyyya ",
      " ayyyyyAAyyyyqa ",
      " ayyyyyAAyyyyqa ",
      " ayyyyyyyyyyyya ",
      " ayyyyyyyyyyyya ",
      " ayyyyyyyyyyyya ",
      " ab          ba ",
      " a gggggggggg a ",
      " a            a ",
      "                "
    ]
  ]
}