{
  "name": "building_restaurant1_floor1",
  "refpalette": "c70cities:building_restaurant1_floor1_palette",
  "xsize": 16,
  "zsize": 16,
  "slices": [
    [
      "                ",
      "  aaaaaaa       ",
      "  abb bc        ",
      "  abbdbc        ",
      " ==bb======eeee ",
      " =Gbbbbbbbbbbbe ",
      " =Gbbbbbbbbbbbe ",
      " =Gbbbbbbbbbbbe ",
      " =Gbbbbbbbbbb!= ",
      " ===bbbbbb===== ",
      "  fgggggggggh   ",
      "  fgggggggggh   ",
      "  fgggggggggh   ",
      "  fgggggggggh   ",
      "  ffffffffffff  ",
      "                "
    ],
    [
      "                ",
      "  aaaaaaa       ",
      "  a   ic        ",
      "  a  dic        ",
      " ==jk========== ",
      " =lm  nop qr s= ",
      " =lm      t  u= ",
      " =lm   op q  s= ",
      " =lm  w   qxyx= ",
      " ===     A===== ",
      "  fB   CA BD    ",
      "  fCE    EFD    ",
      "  f        D    ",
      "  fCE I CEID    ",
      "  ffffffffffff  ",
      "   JKLLLLMJJNJ  "
    ],
    [
      "                ",
      "  aaaaaaa       ",
      "  a   ic        ",
      "  e  dic        ",
      " ==OP====cccc== ",
      " =Q       RS  = ",
      " =Q          T= ",
      " =Q    U  A   = ",
      " =Q       AV  = ",
      " ===      ===== ",
      "  fQ      QD    ",
      "  f        D    ",
      "  f        D    ",
      "  f        D    ",
      "  ffWWWWWWffWf  ",
      "                "
    ],
    [
      "                ",
      "  aaaaaaa       ",
      "  a   ic        ",
      "  e  dic        ",
      " ============== ",
      " =            = ",
      " X     Y      = ",
      " X            e ",
      " =            e ",
      " ===      ===== ",
      "  fQ      QD    ",
      "  f        D    ",
      "  f        D    ",
      "  f        D    ",
      "  ff      ff f  ",
      "                "
    ],
    [
      "                ",
      "  aaaaaaa       ",
      "  a   ic        ",
      "  a  dic        ",
      " ============== ",
      " =            = ",
      " =     Z    Z = ",
      " =            = ",
      " =            = ",
      " ============== ",
      "  f        D    ",
      "  f        D    ",
      "  f      Y D    ",
      "  f        D    ",
      "  ff      ff f  ",
      "                "
    ],
    [
      "                ",
      "  aaaaaaa       ",
      "  a   ic        ",
      "  a0 dic        ",
      " ============== ",
      " =111111111111= ",
      " =111111111111= ",
      " =111111111111= ",
      " =111111111111= ",
      " ============== ",
      "  f        D    ",
      "  f        D    ",
      "  f Z    Z D    ",
      "  f        D    ",
      "  ffffffffffff  ",
      "                "
    ]
  ]
}