{
  "name": "building_office5_floor1_90",
  "refpalette": "c70cities:building_office5_floor1_palette_90",
  "xsize": 16,
  "zsize": 16,
  "slices": [
    [
      "                ",
      "                ",
      "     dbdbdbdbd  ",
      "     deeeeeeeb  ",
      "  abadeeeeeeed  ",
      "  bccdeeeeeeeb  ",
      "  accdeee!eeed  ",
      "  bccdfeeeeeeb  ",
      "  accdfeeeeeed  ",
      "  bccdeeeeeeeb  ",
      "  acceeeeeeeed  ",
      "  bcceeeeeeeeb  ",
      "  abadeeeeeeed  ",
      "     dbdbdbdbd  ",
      "                ",
      "                "
    ],
    [
      "                ",
      "                ",
      "     dbdbdbdbd  ",
      "     d       b  ",
      "  abad   n n d  ",
      "  b hdj  mmm b  ",
      "  a hd  kmmm d  ",
      "  b !df    l b  ",
      "  a gdf  n  od  ",
      "  b  di  mmm b  ",
      "  a      mmm d  ",
      "  b        l b  ",
      "  abadg  l   d  ",
      "     dbdbdbdbd  ",
      "                ",
      "                "
    ],
    [
      "                ",
      "                ",
      "     dbdbdbdbd  ",
      "     d       b  ",
      "  abar       d  ",
      "  b qds    t b  ",
      "  a  d       d  ",
      "  b  df      b  ",
      "  a pdf      d  ",
      "  b pd   t   b  ",
      "  a        t d  ",
      "  b          b  ",
      "  abad       d  ",
      "     dbdbdbdbd  ",
      "                ",
      "                "
    ],
    [
      "                ",
      "                ",
      "     dbdbdbdbd  ",
      "     d       b  ",
      "  abau       d  ",
      "  b  d       b  ",
      "  a  d       d  ",
      "  b  df      b  ",
      "  a  df      d  ",
      "  b  d       b  ",
      "  a  u       d  ",
      "  b  u       b  ",
      "  abad       d  ",
      "     dbdbdbdbd  ",
      "                ",
      "                "
    ],
    [
      "                ",
      "                ",
      "     dbdbdbdbd  ",
      "     d       b  ",
      "  abad       d  ",
      "  b  d       b  ",
      "  a  d       d  ",
      "  b  df      b  ",
      "  a  df      d  ",
      "  b  d       b  ",
      "  a  d       d  ",
      "  b  d       b  ",
      "  abad       d  ",
      "     dbdbdbdbd  ",
      "                ",
      "                "
    ],
    [
      "                ",
      "                ",
      "     dbdbdbdbd  ",
      "     dwwwwwwwb  ",
      "  abadwwwwwwwd  ",
      "  b  dwwwwwwwb  ",
      "  a  dwwwwwwwd  ",
      "  b  dfwwwwwwb  ",
      "  a  dfwwwwwwd  ",
      "  b  dwwwwwwwb  ",
      "  a  dwwwwwwwd  ",
      "  b  dwwwwwwwb  ",
      "  abadwwwwwwwd  ",
      "     dbdbdbdbd  ",
      "                ",
      "                "
    ]
  ]
}