{
  "name": "building_hotel1_floor1_90",
  "refpalette": "c70cities:building_hotel1_floor1_palette_90",
  "xsize": 16,
  "zsize": 16,
  "slices": [
    [
      "                ",
      " aaaaaaaaffffaa ",
      " abbbcbbbbbbbba ",
      " abbbcbbbbbbbbg ",
      " abbbcbbbbbbbbg ",
      " abbbcdbbbbbbbg ",
      " abbbc   ebbbbg ",
      " abbbc    bbbbg ",
      " abbbc    bbbba ",
      " abbbc    bbbba ",
      " abbbcbbbbbbbba ",
      " abbbcbbbbbbbba ",
      " abbbcbbbbbbbba ",
      " abbbcbbbbbbbba ",
      " aaaaadddddddaa ",
      "                "
    ],
    [
      "                ",
      " aaaaaaaaffffaa ",
      " ai  p  t    ta ",
      " ai op       ra ",
      " ai          ta ",
      " a   a ss    qa ",
      " a   a   d    a ",
      " a  na   e   ra ",
      " a  ma   e   ta ",
      " a  la       qa ",
      " a  la        a ",
      " a  ka r r   ra ",
      " a  ja  t    ta ",
      " ah ja q q   qa ",
      " aaaaaaaaaaaaaa ",
      "                "
    ],
    [
      "                ",
      " aaaaaaaaffffaa ",
      " a      y    ya ",
      " a            a ",
      " a           xa ",
      " a   a        a ",
      " a   a        a ",
      " a  wa        f ",
      " a   a   d   xf ",
      " a   a  ee    f ",
      " a   a        f ",
      " a  ua        f ",
      " a   a xxx   xf ",
      " a   a        a ",
      " aaaaaffffaaaaa ",
      "                "
    ],
    [
      "                ",
      " aaaaaaaaffffaa ",
      " a      y    ya ",
      " a            a ",
      " a            a ",
      " a   a        a ",
      " a   a        a ",
      " a   a        a ",
      " a   a        a ",
      " a   aeed     a ",
      " a   a        a ",
      " a   a        a ",
      " a   a        a ",
      " a   a        a ",
      " aaaaaaaaaaaaaa ",
      "                "
    ],
    [
      "                ",
      " aaaaaaaaffffaa ",
      " a   a        a ",
      " a   a        a ",
      " a   a        a ",
      " a   a        a ",
      " a   a        a ",
      " a   ae       f ",
      " a   ae       f ",
      " a   ad       a ",
      " a   a        a ",
      " a   a        a ",
      " a   a        a ",
      " a   a        a ",
      " aaffaaaaaaaaaa ",
      "                "
    ],
    [
      "                ",
      " aaaaaaaaffffaa ",
      " aAAAaAAAAAAAAa ",
      " aAAAaAAAAAAAAa ",
      " aAAAaAAAAAAAAa ",
      " aAAAaAAAAAAAAa ",
      " aAAAae   AAAAa ",
      " aAAAad   AAAAa ",
      " aAAAa    AAAAa ",
      " aAAAa    AAAAa ",
      " aAAAaAAAAAAAAa ",
      " aAAAaAAAAAAAAa ",
      " aAAAaAAAAAAAAa ",
      " aAAAaAAAAAAAAa ",
      " aaaaaaaaaaaaaa ",
      "                "
    ]
  ]
}