{
  "name": "building_office1_base2_90",
  "refpalette": "c70cities:building_office1_base2_palette_90",
  "xsize": 16,
  "zsize": 16,
  "slices": [
    [
      "vvvvvvvvvvvvvvvv",
      "vaaaaaaaaaaaaaav",
      "vaaaaaaaaaaaa!av",
      "vaaaaaaaaaaaaaav",
      "vaaaaaaaaaaaaaav",
      "vaaaaaaaaaaaaaav",
      "vaaaaa!aaaaaaaav",
      "vaaaaaaaaaaaaaav",
      "vaaaaaaaaaaaaaav",
      "vaaaaa!aaaaaaaav",
      "vaaaaaaaaaaaaaav",
      "vaaaaaaaaaaaaaav",
      "vaaaaaaaaaaaaaav",
      "vaaaaaaaaaaaaaav",
      "vaaaaaaaaaaaaaav",
      "vvvvvvvvvvvvvvvv"
    ],
    [
      "vvvvvvvvvvvvvvvv",
      "vbbbbbbbbbbbbbbv",
      "vb         ejjbv",
      "vb         f  bv",
      "vb         f  bv",
      "vb     d   f  bv",
      "vb   dd d  e  bv",
      "vb c       h  bv",
      "vb         g  bv",
      "vb   dddd  e  bv",
      "vb    d    f  bv",
      "vb         f  bv",
      "vb         f  bv",
      "vb         eiibv",
      "vbbbbbbbbbbbbbbv",
      "vvvvvvvvvvvvvvvv"
    ],
    [
      "vvvvvvvvvvvvvvvv",
      "vbbbbbbbbbbbbbbv",
      "vb         emnbv",
      "vb         f  bv",
      "vb         f  bv",
      "vb         f  bv",
      "vb         e  bv",
      "vb         l  bv",
      "vb         k  bv",
      "vb         e  bv",
      "vb         f  bv",
      "vb         f  bv",
      "vb         f  bv",
      "vb         eiibv",
      "vbbbbbbbbbbbbbbv",
      "vvvvvvvvvvvvvvvv"
    ],
    [
      "vvvvvvvvvvvvvvvv",
      "vbbbbbbbbbbbbbbv",
      "vb         e obv",
      "vb         f  bv",
      "vb         f  bv",
      "vb         f  bv",
      "vb         e  bv",
      "vb         e  bv",
      "vb         e  bv",
      "vb         e  bv",
      "vb         f  bv",
      "vb         f  bv",
      "vb         f  bv",
      "vb         eiibv",
      "vbbbbbbbbbbbbbbv",
      "vvvvvvvvvvvvvvvv"
    ],
    [
      "vvvvvvvvvvvvvvvv",
      "vbbbbbbbbbbbbbbv",
      "vb         e  bv",
      "vb         f  bv",
      "vb         f  bv",
      "vb         f  bv",
      "vb         f  bv",
      "vb         f  bv",
      "vb         f  bv",
      "vb         f  bv",
      "vb         f  bv",
      "vb         f  bv",
      "vb         f  bv",
      "vb         eiibv",
      "vbbbbbbbbbbbbbbv",
      "vvvvvvvvvvvvvvvv"
    ],
    [
      "vvvvvvvvvvvvvvvv",
      "vbbbbbbbbbbbbbbv",
      "vbpppppppppeppbv",
      "vbppppppppppppbv",
      "vbppppppppppppbv",
      "vbppppppppppppbv",
      "vbppppppppppppbv",
      "vbpqpprppcppppbv",
      "vbpcppcpprppppbv",
      "vbppppppppppppbv",
      "vbppppppppppppbv",
      "vbppppppppppppbv",
      "vbppppppppppppbv",
      "vbpppppppppeiibv",
      "vbbbbbbbbbbbbbbv",
      "vvvvvvvvvvvvvvvv"
    ]
  ]
}