{
  "name": "building_office3_top",
  "refpalette": "c70cities:building_office3_top_palette",
  "xsize": 16,
  "zsize": 16,
  "slices": [
    [
      "                ",
      " aabaabaabaabaa ",
      " acccccccccccca ",
      " bccccccccccccb ",
      " acccccccccccca ",
      " acccccccccccca ",
      " bccccccccccccb ",
      " acccccvdccccca ",
      " acccccvdccccca ",
      " bccccccccccccb ",
      " accc!cccccccca ",
      " acccccccccccca ",
      " bccccccccccccb ",
      " acccccccccccca ",
      " aabaabaabaabaa ",
      "                "
    ],
    [
      "                ",
      " eebeebeebeebee ",
      " effffffffffffe ",
      " bf          fb ",
      " ef gg       fe ",
      " ef gghhhhh  fe ",
      " bf hi    h  fb ",
      " ef hi    hhhfe ",
      " efiii    h  fe ",
      " bfih     h  fb ",
      " efigg   iiiife ",
      " ef ggiiiih  fe ",
      " bf       h  fb ",
      " effffffffffffe ",
      " eebeebeebeebee ",
      "                "
    ],
    [
      "                ",
      " jjjjjjjjjjjjjj ",
      " j            j ",
      " j            j ",
      " j  gg        j ",
      " j  gg        j ",
      " j            j ",
      " j            j ",
      " j            j ",
      " j            j ",
      " j  gg        j ",
      " j  gg        j ",
      " j            j ",
      " j            j ",
      " jjjjjjjjjjjjjj ",
      "                "
    ],
    [
      "                ",
      "                ",
      "                ",
      "                ",
      "                ",
      "     k          ",
      "                ",
      "                ",
      "                ",
      "                ",
      "                ",
      "     k          ",
      "                ",
      "                ",
      "                ",
      "                "
    ],
    [
      "                ",
      "                ",
      "                ",
      "                ",
      "                ",
      "     l          ",
      "                ",
      "                ",
      "                ",
      "                ",
      "                ",
      "     l          ",
      "                ",
      "                ",
      "                ",
      "                "
    ],
    [
      "                ",
      "                ",
      "                ",
      "                ",
      "                ",
      "     m          ",
      "                ",
      "                ",
      "                ",
      "                ",
      "                ",
      "     m          ",
      "                ",
      "                ",
      "                ",
      "                "
    ]
  ]
}