{
  "name": "building_lab1_base1_270",
  "refpalette": "c70cities:building_lab1_base1_palette_270",
  "xsize": 16,
  "zsize": 16,
  "slices": [
    [
      "zzzzzzzzzzzzzzzz",
      "===============z",
      "===============z",
      "===============z",
      "===============z",
      "===============z",
      "==cc!==a====a==z",
      "==ccc==========z",
      "==ccc=====aaa==z",
      "========a==aa==z",
      "============!==z",
      "===============z",
      "===============z",
      "========b======z",
      "===============z",
      "zzzzzzzzzzzzzzzz"
    ],
    [
      "zzzzzzzzzzzzzzzz",
      "zzdddddddzdddzzz",
      "zdWSMJDysd jedzz",
      "zd    E sd  fdzz",
      "zdssNK  tdn  dzz",
      "zzdddddAdddkddzz",
      "zddTOd Bfqo gadz",
      "zdX  L      gadz",
      "zdYUPdF    lgadz",
      "zzddddI u   gadz",
      "zdZQQdI weeegadz",
      "zd  RddCddddddzz",
      "zd0  !f   pmhdzz",
      "zdVV Ee xr hidzz",
      "zdddddddddddddzz",
      "zzzzzzzzzzzzzzzz"
    ],
    [
      "zzzzzzzzzzzzzzzz",
      "z11###1111111zzz",
      "z1*     61 j 1zz",
      "z1(      1   1zz",
      "z1)6     1   1zz",
      "z11$$$18111411zz",
      "z11&&1   52  laz",
      "z-   %       uaz",
      "z-+  1       B1z",
      "z11111@      B1z",
      "z1  Q1U  e   2az",
      "z1   119111111zz",
      "z1   ^     331zz",
      "z16     7  331zz",
      "z1111111111111zz",
      "zzzzzzzzzzzzzzzz"
    ],
    [
      "zzzzzzzzzzzzzzzz",
      "z111111111111zzz",
      "z1|      1 j 1zz",
      "z1`      1   1zz",
      "z1F      1   1zz",
      "z111111}111[11zz",
      "z11\\\\1    2   1z",
      "z1   -        az",
      "z1:  1        1z",
      "z11111        1z",
      "z1   1       21z",
      "z1   11[111111zz",
      "z1         331zz",
      "z1      { ]331zz",
      "z1111111111111zz",
      "zzzzzzzzzzzzzzzz"
    ],
    [
      "zzzzzzzzzzzzzzzz",
      "z111111111111zzz",
      "z1;;;,;;/1 j 1zz",
      "z1;;;.;;/1   1zz",
      "z1;;;,;;/1   1zz",
      "z1111111111111zz",
      "z11//1;;;,;;;;1z",
      "z1;;;1;;;.;;;;1z",
      "z1;;;1;;;,;;;;1z",
      "z11111;;;.;;;;1z",
      "z1;;;1;;;,;;;;1z",
      "z1;;;111111111zz",
      "z1;;;;;,   ''1zz",
      "z1;;;;;,{ ]''1zz",
      "z1111111111111zz",
      "zzzzzzzzzzzzzzzz"
    ],
    [
      "zzzzzzzzzzzzzzzz",
      "zzzzzzzzz1111zzz",
      "zzzzzzzzz11j11zz",
      "zzzzzzzzz11111zz",
      "zzzzzzzzz11111zz",
      "zzzzzzzzz11111zz",
      "zzzzzzzzzzzzzzzz",
      "zzzzzzzzzzzzzzzz",
      "zzzzzzzzzzzzzzzz",
      "zzzzzzzzzzzzzzzz",
      "zzzzzzzzzzzzzzzz",
      "zzzzzzzzzzzzzzzz",
      "zzzzzzzz11111zzz",
      "zzzzzzzzb1111zzz",
      "zzzzzzzzzzzzzzzz",
      "zzzzzzzzzzzzzzzz"
    ]
  ]
}