{
  "name": "building_carservice1_floor2_90",
  "refpalette": "c70cities:building_carservice1_floor2_palette_90",
  "xsize": 16,
  "zsize": 16,
  "slices": [
    [
      "                ",
      "      eeeeee    ",
      " a    acffcdd   ",
      "      dcfffcdd  ",
      "      dcffffcde ",
      "      dcfffffie ",
      " a    acffffffa ",
      "      dcff    e ",
      "      dcff!   e ",
      "    HHdcff    e ",
      " a  bbacffgggga ",
      "    bbccffghhge ",
      "  bbbbccffgggge ",
      "  bbbbccffffffe ",
      " a    aeeeeeeea ",
      "                "
    ],
    [
      "                ",
      "      eeeeee    ",
      " a    aqst rr   ",
      "      ep    rr  ",
      "      eo     re ",
      "      eo     ie ",
      " ajjjkan      a ",
      " j  HHem  y  ye ",
      " j  bbem      e ",
      " j    el  y  ye ",
      " a    a   w  wa ",
      " j        xAAxe ",
      " j        w  we ",
      " j        u   e ",
      " ajjjkaerrrrrea ",
      "                "
    ],
    [
      "                ",
      "      errree    ",
      " a    a    rr   ",
      "      eC    rr  ",
      "      e      re ",
      "    HHe      ie ",
      " aaBbba      Fa ",
      "      e   EEEEe ",
      "      e   EbbEe ",
      "      e   EEEEe ",
      " a    a    DD a ",
      "          D  Ie ",
      "           DD e ",
      "             Fe ",
      " a    aerrrrrea ",
      "                "
    ],
    [
      "                ",
      "      eeeeee    ",
      " a    a    rr   ",
      "  bbbbe     rr  ",
      "  bbbbeLM    re ",
      "  bb  eKM    ie ",
      " abb  a       a ",
      "  HH  e       e ",
      "      e       e ",
      "      e       e ",
      " a    a       a ",
      "      J       e ",
      "      J       e ",
      "      J       e ",
      " a    aerrrrrea ",
      "                "
    ],
    [
      "                ",
      "      eeeeee    ",
      " akjjja    rr   ",
      " j    e     rr  ",
      " j    e      re ",
      " j    e      ie ",
      " a    a       a ",
      " j    e       e ",
      " jbb  e       e ",
      " jHH  e       e ",
      " akjjja       a ",
      "      e       e ",
      "      e       e ",
      "      e       e ",
      " a    aeNNNNNea ",
      "                "
    ],
    [
      "                ",
      "      eeeeee    ",
      " a    a    rr   ",
      "      e  j  rr  ",
      "      e  jj  re ",
      "      e  jjj ie ",
      " a    a  jjjj a ",
      "      e  jjjjje ",
      "      e  jjjjje ",
      "      e  jjjjje ",
      " abbBaa  jjjjja ",
      "  HH  e  jjjjje ",
      "      e  jjjjje ",
      "      e  jjjjje ",
      " a    aeeeeeeea ",
      "                "
    ]
  ]
}