{
  "name": "building_residential4_ground",
  "refpalette": "c70cities:building_residential4_ground_palette",
  "xsize": 16,
  "zsize": 16,
  "slices": [
    [
      "GGGGGGGGGGGGGGGG",
      "GGGGGGGGGGGGGGGG",
      "GGaaaaaaaaaaaaGG",
      "GGabbbbbbcccdGGG",
      "GGabbbbbbcccdGGG",
      "GGabbbbbbcccdGGG",
      "GGabbbbbbcccdGGG",
      "GGabbbbbbcccdGGG",
      "GGabbbbbbcccdGGG",
      "GGabbbbbbcccdGGG",
      "GGabbbbbbcccdGGG",
      "GGabbbbbbcccdGGG",
      "GGabbbbbbcccdGGG",
      "GGaaaaaaaaaaaaGG",
      "GGGGGGGGGGGGGGGG",
      "GGGGGGGGGGGGGGGG"
    ],
    [
      "effffgffffgffffe",
      "f              f",
      "f hhiihiihiihh f",
      "f j   k lm ndo f",
      "f jp qk lm ndo f",
      "f jr qk  s tdo g",
      "e h   u    wdo f",
      "  x   u    ydo f",
      "  A        Bdo f",
      "e h        Cdo f",
      "f j      DDDdo g",
      "f jE     F Ido f",
      "f jJ  K  L  do f",
      "f hhMMhMMhMMhh f",
      "f              f",
      "effffgffffgffffe"
    ],
    [
      "effffgffffgffffe",
      "f              f",
      "f hhNNhNNhNNhh f",
      "f N   O     d  f",
      "f N  PO  Q  d  f",
      "f N  PO    Rd  g",
      "e h   u     d  f",
      "  S   u     T  f",
      "  U         T  f",
      "e h        Vd  f",
      "f N      DDDd  g",
      "f N      W Xd  f",
      "f N YK   L  d  f",
      "f hhNNhNNhZZhh f",
      "f              f",
      "effffgffffgffffe"
    ],
    [
      "                ",
      "                ",
      "  hhhhhhhhhhhh  ",
      "  N   O     d0  ",
      "  N   O     d0  ",
      "  N   O     d0  ",
      "  h   u     d0  ",
      "  N   u     T0  ",
      "  N         T0  ",
      "  h         d0  ",
      "  N      DDDd0  ",
      "  N 1    L  d0  ",
      "  N      L  d0  ",
      "  hhhhhhhhhhhh  ",
      "                ",
      "                "
    ],
    [
      "                ",
      " 22222222222222 ",
      " MhhhhhhhhhhhhM ",
      "  hbbbbbbbbbd3  ",
      "  hbbbbbbbbbd3  ",
      "  hbbbbbbbbbd3  ",
      "  hbbbbbbbbbd3  ",
      "  hbbbbbbbbbd   ",
      "  hbbbbbbbbbd   ",
      "  hbbbbbbbbbd3  ",
      "  hb1  bbbbbd3  ",
      "  hb   bbbbbd3  ",
      "  hb   bbbbbd3  ",
      " ihhhhhhhhhhhhi ",
      " 44444444444444 ",
      "                "
    ],
    [
      "                ",
      "                ",
      " 22222222222222 ",
      " M3dhhhhhhhhd3M ",
      "  3d33333333d3  ",
      "  3d567  88 d3  ",
      "  3d567  889d3  ",
      "  @d#77 $88%d^  ",
      "  &d        d*  ",
      "  3d (()++++d3  ",
      "  3d  -    [d3  ",
      "  3d  -    ]d3  ",
      " i3d  - !{{ d3i ",
      " 44444444444444 ",
      "                ",
      "                "
    ]
  ]
}