{
  "name": "building_hotel1_floor1",
  "refpalette": "c70cities:building_hotel1_floor1_palette",
  "xsize": 16,
  "zsize": 16,
  "slices": [
    [
      "                ",
      " aaaaaaaaaaaaaa ",
      " abbbbbbbbbbbba ",
      " abbbbbbbbbbbba ",
      " abbbbbbbbbbbba ",
      " acccccccccccca ",
      " dbbbb    dbbba ",
      " dbbbb    bbbba ",
      " dbbbb    bbbba ",
      " dbbbb   ebbbbf ",
      " dbbbbbbbbbbbbf ",
      " dbbbbbbbbbbbbf ",
      " dbbbbbbbbbbbbf ",
      " abbbbbbbbbbbba ",
      " aaaaaaagggggaa ",
      "                "
    ],
    [
      "                ",
      " aaaaaaaaaaaaaa ",
      " ah        iiia ",
      " a            a ",
      " ajjkllmn   o a ",
      " aaaaaaaaaa ppa ",
      " a            a ",
      " aq r     s   a ",
      " a t      s  ta ",
      " aq r  eed    f ",
      " a            f ",
      " a            f ",
      " a            f ",
      " aqtr qtr qtrta ",
      " aaaaaaaaaaaaaa ",
      "                "
    ],
    [
      "                ",
      " aaaaaaaaaaaaaa ",
      " a            a ",
      " a            a ",
      " a  u   w     a ",
      " aaaaaaaaaa   a ",
      " f            a ",
      " f x          a ",
      " f x  e      ya ",
      " f x  ed      f ",
      " a            f ",
      " a            f ",
      " a            f ",
      " a x   x   x ya ",
      " aaffffffaaaaaa ",
      "                "
    ],
    [
      "                ",
      " aaaaaaaaaaaaaa ",
      " a            a ",
      " a            a ",
      " a            a ",
      " aaaaaaaaaa   a ",
      " a    e       a ",
      " a    e       a ",
      " a    d      ya ",
      " a            f ",
      " a            f ",
      " a            f ",
      " a            f ",
      " a           ya ",
      " aaaaaaaaaaaaaa ",
      "                "
    ],
    [
      "                ",
      " aaaaaaaaaaaaaa ",
      " a            a ",
      " f            a ",
      " f            a ",
      " aaaaaaaaaaaaaa ",
      " a    dee     a ",
      " a            a ",
      " a            a ",
      " a            f ",
      " a            f ",
      " a            f ",
      " a            f ",
      " a            a ",
      " aaaaaaffaaaaaa ",
      "                "
    ],
    [
      "                ",
      " aaaaaaaaaaaaaa ",
      " aAAAAAAAAAAAAa ",
      " aAAAAAAAAAAAAa ",
      " aAAAAAAAAAAAAa ",
      " aaaaaaaaaaaaaa ",
      " aAAAA  deAAAAa ",
      " aAAAA    AAAAa ",
      " aAAAA    AAAAa ",
      " aAAAA    AAAAf ",
      " aAAAAAAAAAAAAf ",
      " aAAAAAAAAAAAAf ",
      " aAAAAAAAAAAAAf ",
      " aAAAAAAAAAAAAa ",
      " aaaaaaaaaaaaaa ",
      "                "
    ]
  ]
}