{
  "name": "building_office2_floor1_90",
  "refpalette": "c70cities:building_office2_floor1_palette_90",
  "xsize": 16,
  "zsize": 16,
  "slices": [
    [
      "                ",
      " a            a ",
      " a dddddddddd a ",
      " abeeeeeeeeeeba ",
      " acccccccccccca ",
      " acccccccccccca ",
      " acccccccccccca ",
      " acccccccccccfa ",
      " acccccccccccfa ",
      " acccccccccccca ",
      " acccccccccccca ",
      " acccccccccccca ",
      " abeeeeeeeeeeba ",
      " a dddddddddd a ",
      " a            a ",
      "                "
    ],
    [
      "                ",
      " a            a ",
      " a dddddddddd a ",
      " ab          ba ",
      " ag          na ",
      " ah  k k k   na ",
      " ag   l l m  oa ",
      " ag i        fa ",
      " ag i        fa ",
      " ah   l l m  oa ",
      " ag  j j j   na ",
      " ag          na ",
      " ab          ba ",
      " a dddddddddd a ",
      " a            a ",
      "                "
    ],
    [
      "                ",
      " a            a ",
      " a dddddddddd a ",
      " ab          ba ",
      " ap          pa ",
      " a            a ",
      " a   qqqqq   sa ",
      " a   q   q   fa ",
      " a   q   q   fa ",
      " a   qqqqq   sa ",
      " ap           a ",
      " ap          ra ",
      " ab          ba ",
      " a dddddddddd a ",
      " a            a ",
      "                "
    ],
    [
      "                ",
      " a            a ",
      " a dddddddddd a ",
      " ab          ba ",
      " a            a ",
      " a            a ",
      " a            a ",
      " a           fa ",
      " a           fa ",
      " a            a ",
      " a            a ",
      " ap           a ",
      " ab          ba ",
      " a dddddddddd a ",
      " a            a ",
      "                "
    ],
    [
      "                ",
      " a            a ",
      " a dddddddddd a ",
      " ab          ba ",
      " a            a ",
      " a            a ",
      " a            a ",
      " a      !    fa ",
      " a           fa ",
      " a            a ",
      " a            a ",
      " a            a ",
      " ab          ba ",
      " a dddddddddd a ",
      " a            a ",
      "                "
    ],
    [
      "                ",
      " a            a ",
      " a dddddddddd a ",
      " ab          ba ",
      " a ttttttttttta ",
      " a ttttttttttta ",
      " a ttttttttttta ",
      " a ttttuuttttfa ",
      " a ttttuuttttfa ",
      " a ttttttttttta ",
      " a ttttttttttta ",
      " a ttttttttttta ",
      " ab          ba ",
      " a dddddddddd a ",
      " a            a ",
      "                "
    ]
  ]
}