{
  "name": "building_bank1_floor1_270",
  "refpalette": "c70cities:building_bank1_floor1_palette_270",
  "xsize": 16,
  "zsize": 16,
  "slices": [
    [
      "                ",
      "   hbbf  hbbf   ",
      "  deeeedeeeeed  ",
      " jeeee     eeea ",
      " beeeeeeeeeeeeb ",
      " beeeeeeeeeeeeb ",
      " keeeeeeeeeeeec ",
      "  eeeeeeeeeeed  ",
      "  deeeeeeeeeee  ",
      " jeeeeeeeeeeeea ",
      " beeeeeeeeeeeeb ",
      " beeeeeeeeeeeeb ",
      " keeeeeeeeeeeec ",
      "  deeeeedeeeed  ",
      "   ibbg  ibbg   ",
      "                "
    ],
    [
      "                ",
      "  hbbf  hbbf    ",
      "  llllmlllqlmla ",
      "  m       r  lb ",
      " jl   sssss  lb ",
      " bl          lc ",
      " bl xxAx     m  ",
      " klbbbbbbbbpnl  ",
      "  lDDyyyut   la ",
      "  m     wt   lb ",
      " jl  BB      lb ",
      " bl          lc ",
      " bl  CC     om  ",
      " klmlllllmllll  ",
      "    ibbg  ibbg  ",
      "                "
    ],
    [
      "                ",
      " Ebbf  hbbf  hE ",
      " klllmlllqlmllb ",
      "  l      r   lb ",
      "  m   s s s  lc ",
      " jl          m  ",
      " bl   K      l  ",
      " blbbbbbbbbIFla ",
      " klL     t   lb ",
      "  l      J   lb ",
      "  m          lc ",
      " jl          m  ",
      " bl         ol  ",
      " bllmlllllmllla ",
      " Eg  ibbg  ibbE ",
      "                "
    ],
    [
      "                ",
      " Ebf  hbbf  hbE ",
      " bllmlllq mlllb ",
      " kl     r    lc ",
      "  l   s s s  m  ",
      "  m          l  ",
      " jl   K      la ",
      " blbbbbbbbbbblb ",
      " bl      t   lb ",
      " kl      t   lc ",
      "  l          m  ",
      "  m          l  ",
      " jl         ola ",
      " blllmlllllmllb ",
      " Ebg  ibbg  ibE ",
      "                "
    ],
    [
      "                ",
      " Ef  hbbf  hbbE ",
      " blmlllq mllllc ",
      " bl    r     m  ",
      " kl   s s s  l  ",
      "  l          la ",
      "  m          lb ",
      " jlbbbbbbbbbblb ",
      " bl          lc ",
      " bl          m  ",
      " kl          l  ",
      "  l          la ",
      "  m          lb ",
      " jllllmlllllmlb ",
      " Ebbg  ibbg  iE ",
      "                "
    ],
    [
      "                ",
      "    hbbf  hbbf  ",
      " jmlllq mllllm  ",
      " blMMMr    MMl  ",
      " blMMMs s sMMla ",
      " klMMMMMMMMMMlb ",
      "  lMMMMMMMMMMlb ",
      "  mbbbbbbbbbblc ",
      " jlMMMMMMMMMMm  ",
      " blMMNNNNMMMMl  ",
      " blMMN!!NMMMMla ",
      " klMMNNNNMMMMlb ",
      "  lMMMMMMMMMMlb ",
      "  mllllmlllllmc ",
      "  ibbg  ibbg    ",
      "                "
    ]
  ]
}