{
  "name": "building_office3_ground_270",
  "refpalette": "c70cities:building_office3_ground_palette_270",
  "xsize": 16,
  "zsize": 16,
  "slices": [
    [
      "GGGGGGGGGGGGGGGG",
      "GaaaaaaaaaaaaaaG",
      "GabbbbbbbbbbbbaG",
      "Gabbbbbbbbbb!baG",
      "GabbbbbbbbbbbbaG",
      "GabbbbbbbbbbbbaG",
      "GabbbbbbbbbbbbaG",
      "GabbbbbbbbbbbbaG",
      "GabbbbbbbbbbbbaG",
      "GabbbbbbbbbbbbaG",
      "GabbbbbbbbbbbbaG",
      "GabbbbbbbbbbbbaG",
      "GabbbbbbbbbbbbaG",
      "GabbbbbbbbbbbbaG",
      "GaaaaaaaaaaaaaaG",
      "GGGGGGGGGGGGGGGG"
    ],
    [
      "                ",
      " ccdccdccdccdcc ",
      " ceeffgffgffeec ",
      " deh        hed ",
      " cf          fc ",
      " cf          fc ",
      " dg     i    gd ",
      " cf    vv    fc ",
      " cf    jj    fc ",
      " dg          gd ",
      " cf          fc ",
      " cf          fc ",
      " deh        hed ",
      " ceeffg  gffeec ",
      " ccdccdlkdccdcc ",
      "                "
    ],
    [
      "                ",
      " ccdccdccdccdcc ",
      " c    m  m    c ",
      " d h        h d ",
      " c            c ",
      " c            c ",
      " dm          md ",
      " c     vv     c ",
      " c     jj     c ",
      " dm          md ",
      " c            c ",
      " c            c ",
      " d h        h d ",
      " c    m  m    c ",
      " ccdccdondccdcc ",
      "                "
    ],
    [
      "                ",
      " ppdppdppdppdpp ",
      " p            p ",
      " d h        h d ",
      " p            p ",
      " p            p ",
      " d            d ",
      " p     vv     p ",
      " p     jj     p ",
      " d            d ",
      " p            p ",
      " p            p ",
      " d h        h d ",
      " p            p ",
      " ppdppdppdppdpp ",
      "                "
    ],
    [
      "                ",
      " ccdccdccdccdcc ",
      " cqqqqqqqqqqqqc ",
      " dqh        hqd ",
      " cq          qc ",
      " cq          qc ",
      " dq          qd ",
      " cq    vv    qc ",
      " cq    jj    qc ",
      " dq          qd ",
      " cq          qc ",
      " cq          qc ",
      " dqh        hqd ",
      " cqqqqqqqqqqqqc ",
      " ccdccdccdccdcc ",
      "                "
    ],
    [
      "                ",
      " rrrrrrrrrrrrrr ",
      " raaaaaaaaaaaar ",
      " rasddddddddsar ",
      " raddddddddddar ",
      " raddddddddddar ",
      " raddddddddddar ",
      " raddddvvddddar ",
      " raddddjjddddar ",
      " raddddddddddar ",
      " raddddddddddar ",
      " raddddddddddar ",
      " rasddddddddsar ",
      " raaaaaaaaaaaar ",
      " rrrrrrrrrrrrrr ",
      "                "
    ]
  ]
}