{
  "name": "building_apartment1_floor1_90",
  "refpalette": "c70cities:building_apartment1_floor1_palette_90",
  "xsize": 16,
  "zsize": 16,
  "slices": [
    [
      "                ",
      " aaaaaaaaa      ",
      " abbbbbbbbdeei  ",
      " abbbbbbbbbbfh  ",
      " abbbbbbbbbb g  ",
      " abbbbbbbbc  d  ",
      " abbbbbbbbbbbba ",
      " abbbbbbbbbbbba ",
      " abbbbbbbbbbbba ",
      " abbbbbbbbbbbba ",
      " abbbbbbbbbbbba ",
      " abbbbbbbbbbbba ",
      " abbbbbbbbbbbba ",
      " abbbbbbbbbbbba ",
      " aaaaaaaaaaaaaa ",
      "                "
    ],
    [
      "                ",
      " lssssssss      ",
      " kot ApD pdddd  ",
      " kn  ypD J ORd  ",
      " k    ppEp   T  ",
      " kppw p  p   T  ",
      " k  w p  pppppV ",
      " kr x p  I NQ!V ",
      " kq w x  I    V ",
      " kpuppp  F MM V ",
      " k    B       V ",
      " kot ApCEC    V ",
      " kot ypq pK   V ",
      " kn   pr pqLPSV ",
      " jmmmmmmmmmmmmU ",
      "                "
    ],
    [
      "                ",
      " pWWWppppp      ",
      " p    p  phTdd  ",
      " p    p  6  Od  ",
      " p    pp5p  @d  ",
      " pppw p  p   d  ",
      " p  w p  pppppp ",
      " pY 0 p    88 3 ",
      " p  w 0       W ",
      " ppZppp       W ",
      " p    2       W ",
      " p    pC5C    W ",
      " p    p  p7   W ",
      " pX   p4 p  9#3 ",
      " pWWWp133133331 ",
      "                "
    ],
    [
      "                ",
      " pWWWppWWp      ",
      " p%&( p  pddd\\  ",
      " W    p  p   }  ",
      " W    pppp  -d  ",
      " pppw p  p  Rd  ",
      " p  w p  pppppp ",
      " W  w p    ++ 3 ",
      " W  w p      {W ",
      " pppppp  )   {W ",
      " p    p      ]W ",
      " W    pCCC   [W ",
      " W    p  p   [W ",
      " p$^* p  p    3 ",
      " pWWWp1WW13WWW1 ",
      "                "
    ],
    [
      "                ",
      " p333pp33p      ",
      " p    p  p}}}d  ",
      " k    p fp   T  ",
      " k    pppp   T  ",
      " pppw p  p |-e  ",
      " p  w p  pppppp ",
      " k  w p       3 ",
      " k  w p       3 ",
      " pppppp  f    3 ",
      " p    p       3 ",
      " k    pCCC    3 ",
      " k    p  p    3 ",
      " p    p  p    3 ",
      " p333p133133331 ",
      "                "
    ],
    [
      "                ",
      " ppppppppp      ",
      " pddddpddpdddd  ",
      " pddddpddp   d  ",
      " pddddpppp   d  ",
      " pddddpddpRc d  ",
      " p``ddpddpppppp ",
      " p``ddpdddddddp ",
      " p``ddpdddddddp ",
      " ppppppdddddddp ",
      " pddddpdddddddp ",
      " pddddpdddddddp ",
      " pddddp``dddddp ",
      " pddddp``dddddp ",
      " pppppppppppppp ",
      "                "
    ]
  ]
}