{
  "name": "building_residential1_ground",
  "refpalette": "c70cities:building_residential1_ground_palette",
  "xsize": 16,
  "zsize": 16,
  "slices": [
    [
      "GGGGGGGGGGGGGGGG",
      "GGGGGGGGGGGGGGGG",
      "GGaaaaaaaaaaaaGG",
      "GGabbbbbbbbbbaGG",
      "GGabbbbbbbbbbaGG",
      "GGabbbbbbbbbbaGG",
      "GGabbbbbbbbbbaGG",
      "GGabbbbbbbbbbaGG",
      "GGacddddddeecaGG",
      "GGGcddddddeecGGG",
      "GGGcddddddeecGGG",
      "GGGcddddddeecGGG",
      "GGGccccccccccGGG",
      "GGGGGGGGGGGGGGGG",
      "GGGGGGGGGGGGGGGG",
      "GGGGGGGGGGGGGGGG"
    ],
    [
      "fgggghgggghggggf",
      "g              g",
      "f iijjjiijjjii g",
      "  k    ll    j g",
      "  m          j g",
      "f innn op    i f",
      "g jq   rrrrr j g",
      "g js    t    j g",
      "g icuu    wwci g",
      "g xcyyA   B cx g",
      "h xc      C cx h",
      "g xcDEFIJ!CKcx g",
      "g xccccccccccx g",
      "g xxxxxxxxxxxx g",
      "g              g",
      "fgggghgggghggggf"
    ],
    [
      "fgggghgggghggggf",
      "g              g",
      "f iijjjiijjjii g",
      "  L    MM    j g",
      "  N          j g",
      "f innn       i f",
      "g j    rrrrr j g",
      "g j      t   j g",
      "g ic      wwci g",
      "g  c  O   P c  g",
      "h  Q      C R  h",
      "g  cS  TU CVc  g",
      "g  cccQQQQccc  g",
      "g              g",
      "g              g",
      "fgggghgggghggggf"
    ],
    [
      "                ",
      "                ",
      "  iiWWWiiWWWii  ",
      "  X          Y  ",
      "  X          Y  ",
      "  innn       i Z",
      "  X    rrrrr Y  ",
      "  X       t  Y  ",
      "  ic      wwci  ",
      "   c      C c   ",
      "   Q      C R   ",
      "   c      C c   ",
      "   cccccccccc   ",
      "  000000000000  ",
      "                ",
      "                "
    ],
    [
      "                ",
      "                ",
      "  iiiiiiiiiiii  ",
      "  ibbbbbbbbbbi  ",
      "  ibbbbbbbbbbi  ",
      "  ibbbbbbbbbbi  ",
      "  ibbbbbbbbbbi  ",
      "  i        tbi  ",
      "  ic      wwci  ",
      "   c      12c   ",
      "   c      12c   ",
      "  0c00000012c0  ",
      "  333333333333  ",
      "  444444444444  ",
      "                ",
      "                "
    ],
    [
      "                ",
      " 55555555555555 ",
      "  iiiiiiiiiiii  ",
      "  j6777 89   j  ",
      "  jX@#7 $%^  j  ",
      "  jX@#7 &*   j  ",
      "  j 777      j  ",
      "  j((((((((( j  ",
      "  ic      wwci  ",
      "  0c000000C)c0  ",
      "  333333333333  ",
      "  444444444444  ",
      "                ",
      "                ",
      "                ",
      "                "
    ]
  ]
}