{
  "name": "building_restaurant1_top_180",
  "refpalette": "c70cities:building_restaurant1_top_palette_180",
  "xsize": 16,
  "zsize": 16,
  "slices": [
    [
      "                ",
      "  iiiiiiiiiiii  ",
      "  chgggggggggf  ",
      "   hgggggggggf  ",
      "   hgggggggggf  ",
      "   hgggggggggf  ",
      " ============== ",
      " =bbb!bbbbbbbb= ",
      " ebbbbbbbbbbbb= ",
      " ebbbbbbbbbbbb= ",
      " ebbbbbbbbbbbb= ",
      " eeee======bb== ",
      "        cbdbba  ",
      "        cb bba  ",
      "       aaaaaaa  ",
      "                "
    ],
    [
      "                ",
      "                ",
      "  iiiiiiiiiiii  ",
      "  ccAy x  w uf  ",
      "    Ay B  B uf  ",
      "    Ay x  w uf  ",
      " =====      === ",
      " =stsn       m= ",
      " =p  n       m= ",
      " =r  q       m= ",
      " =p on cccc  m= ",
      " ==========lk== ",
      "        cj   a  ",
      "        cj   a  ",
      "       aaaaaaa  ",
      "                "
    ],
    [
      "                ",
      "                ",
      "                ",
      "  iiii      ii  ",
      "  ccA       uf  ",
      "    A      Nuf  ",
      " =====      === ",
      " =           M= ",
      " =L  K        = ",
      " =J           = ",
      " =  I  eeee  F= ",
      " ==cccc====ED== ",
      "        cj   e  ",
      "        cj   a  ",
      "       CCCCCCC  ",
      "                "
    ],
    [
      "                ",
      "                ",
      "                ",
      "                ",
      "  iiii      ii  ",
      "  ccA NNNNNNuf  ",
      " =====      === ",
      " e            = ",
      " e            O ",
      " =        P   O ",
      " =     eeee   = ",
      " ============== ",
      "        cj   e  ",
      "       CCCCCCC  ",
      "                ",
      "                "
    ],
    [
      "                ",
      "                ",
      "                ",
      "                ",
      "                ",
      "  iiiiiiiiiiii  ",
      " ============== ",
      " =            = ",
      " =            = ",
      " = R   R  R   = ",
      " =     QQQQ   = ",
      " ============== ",
      "       CCCCCCC  ",
      "                ",
      "                ",
      "                "
    ],
    [
      "                ",
      "                ",
      "                ",
      "                ",
      "                ",
      "                ",
      " ============== ",
      " ============== ",
      " ============== ",
      " ============== ",
      " ============== ",
      " ============== ",
      "                ",
      "                ",
      "                ",
      "                "
    ]
  ]
}