{
  "name": "building_residential4_ground_90",
  "refpalette": "c70cities:building_residential4_ground_palette_90",
  "xsize": 16,
  "zsize": 16,
  "slices": [
    [
      "GGGGGGGGGGGGGGGG",
      "GGGGGGGGGGGGGGGG",
      "GGaGGGGGGGGGGaGG",
      "GGaddddddddddaGG",
      "GGaccccccccccaGG",
      "GGaccccccccccaGG",
      "GGaccccccccccaGG",
      "GGabbbbbbbbbbaGG",
      "GGabbbbbbbbbbaGG",
      "GGabbbbbbbbbbaGG",
      "GGabbbbbbbbbbaGG",
      "GGabbbbbbbbbbaGG",
      "GGabbbbbbbbbbaGG",
      "GGaaaaaaaaaaaaGG",
      "GGGGGGGGGGGGGGGG",
      "GGGGGGGGGGGGGGGG"
    ],
    [
      "effffgffffgffffe",
      "f              f",
      "f hooooooooooh f",
      "f hddddddddddh f",
      "f inntwyBwCF L f",
      "g i       C  L g",
      "f hmms    CEKh f",
      "f ill        L f",
      "f i          L f",
      "f hkkkuu    Jh f",
      "g i qq       L g",
      "f i          L f",
      "f h pr     DIh f",
      "f hjjjhxAhjjjh f",
      "f              f",
      "efffffe  efffffe"
    ],
    [
      "effffgffffgffffe",
      "f              f",
      "f h          h f",
      "f hddddSSddddh f",
      "f M  Q  UVCX Z f",
      "g M       C  Z g",
      "f h P     CWKh f",
      "f M          M f",
      "f M          M f",
      "f hNNNuu     h f",
      "g M OO      JM g",
      "f M         YM f",
      "f h          h f",
      "f hMMMhRThMMMh f",
      "f              f",
      "efffffe  efffffe"
    ],
    [
      "                ",
      "                ",
      "  h0000000000h  ",
      "  hddddSSddddh  ",
      "  h       C  h  ",
      "  h       C  h  ",
      "  h       CKKh  ",
      "  h          h  ",
      "  h          h  ",
      "  hNNNuu     h  ",
      "  h          h  ",
      "  h        1 h  ",
      "  h          h  ",
      "  hMMMhMMhMMMh  ",
      "                ",
      "                "
    ],
    [
      "                ",
      " 2L          i4 ",
      " 2h3333  3333h4 ",
      " 2hddddddddddh4 ",
      " 2hbbbbbbbbbbh4 ",
      " 2hbbbbbbbbbbh4 ",
      " 2hbbbbbbbbbbh4 ",
      " 2hbbbbbbbbbbh4 ",
      " 2hbbbbbbbbbbh4 ",
      " 2hbbbbbbb   h4 ",
      " 2hbbbbbbb   h4 ",
      " 2hbbbbbbb1  h4 ",
      " 2hbbbbbbbbbbh4 ",
      " 2hhhhhhhhhhhh4 ",
      " 2L          i4 ",
      "                "
    ],
    [
      "                ",
      "  2L        i4  ",
      "  23333^*33334  ",
      "  2dddddddddd4  ",
      "  2h3 9% +[] 4  ",
      "  2h3888 +  {4  ",
      "  2h3888 +  {4  ",
      "  2h3  $ +  !4  ",
      "  2h3    )   4  ",
      "  2h3777 (---4  ",
      "  2h3667 (   4  ",
      "  2h355#     4  ",
      "  2dddddddddd4  ",
      "  23333@&33334  ",
      "  2L        i4  ",
      "                "
    ]
  ]
}