{
  "name": "building_office3_floor3_270",
  "refpalette": "c70cities:building_office3_floor3_palette_270",
  "xsize": 16,
  "zsize": 16,
  "slices": [
    [
      "                ",
      " aabaabaabaabaa ",
      " acccccccccccca ",
      " bccccccccccccb ",
      " acccccccccccca ",
      " accccccccc!cca ",
      " bccccccccccccb ",
      " acccccvvccccca ",
      " acccccddccccca ",
      " bccccccccccccb ",
      " acccccccccccca ",
      " acccccccccccca ",
      " bccccccccccccb ",
      " acccccccccccca ",
      " aabaabaabaabaa ",
      "                "
    ],
    [
      "                ",
      " eebeebeebeebee ",
      " e            e ",
      " b f        f b ",
      " e            e ",
      " e gg      gg e ",
      " b gh      hg b ",
      " e gh  vv  hg e ",
      " e gg  dd  gg e ",
      " b            b ",
      " e            e ",
      " e   kiiiii   e ",
      " b f  j  j  f b ",
      " e            e ",
      " eebeebeebeebee ",
      "                "
    ],
    [
      "                ",
      " llbllbllbllbll ",
      " l            l ",
      " b f        f b ",
      " l            l ",
      " l            l ",
      " b            b ",
      " l     vv     l ",
      " l     dd     l ",
      " b            b ",
      " l            l ",
      " l            l ",
      " b f        f b ",
      " l            l ",
      " llbllbllbllbll ",
      "                "
    ],
    [
      "                ",
      " llbllbllbllbll ",
      " l            l ",
      " b f        f b ",
      " l            l ",
      " l            l ",
      " b            b ",
      " l     vv     l ",
      " l     dd     l ",
      " b            b ",
      " l            l ",
      " l            l ",
      " b f        f b ",
      " l            l ",
      " llbllbllbllbll ",
      "                "
    ],
    [
      "                ",
      " llbllbllbllbll ",
      " l            l ",
      " b f        f b ",
      " l            l ",
      " l            l ",
      " b            b ",
      " l     vv     l ",
      " l     dd     l ",
      " b            b ",
      " l            l ",
      " l            l ",
      " b f        f b ",
      " l            l ",
      " llbllbllbllbll ",
      "                "
    ],
    [
      "                ",
      " llbllbllbllbll ",
      " lmmmmmmmmmmmml ",
      " bmfnnnnnnnnfmb ",
      " lmnnnnnnnnnnml ",
      " lmnnnnnnnnnnml ",
      " bmnnnnnnnnnnmb ",
      " lmnnnnvvnnnnml ",
      " lmnnnnddnnnnml ",
      " bmnnnnnnnnnnmb ",
      " lmnnnnnnnnnnml ",
      " lmnnnnnnnnnnml ",
      " bmfnnnnnnnnfmb ",
      " lmmmmmmmmmmmml ",
      " llbllbllbllbll ",
      "                "
    ]
  ]
}