{
  "name": "building_residential1_ground_180",
  "refpalette": "c70cities:building_residential1_ground_palette_180",
  "xsize": 16,
  "zsize": 16,
  "slices": [
    [
      "GGGGGGGGGGGGGGGG",
      "GGGGGGGGGGGGGGGG",
      "GGGGGGGGGGGGGGGG",
      "GGGccccccccccGGG",
      "GGGceeddddddcGGG",
      "GGGceeddddddcGGG",
      "GGGceeddddddcGGG",
      "GGaceeddddddcaGG",
      "GGabbbbbbbbbbaGG",
      "GGabbbbbbbbbbaGG",
      "GGabbbbbbbbbbaGG",
      "GGabbbbbbbbbbaGG",
      "GGabbbbbbbbbbaGG",
      "GGaaaaaaaaaaaaGG",
      "GGGGGGGGGGGGGGGG",
      "GGGGGGGGGGGGGGGG"
    ],
    [
      "fgggghgggghggggf",
      "g              g",
      "g AAAAAAAAAAAA g",
      "g AccccccccccA g",
      "g AcMF!JLKJIcA g",
      "h Ac F      cA h",
      "g AcED   CBBcA g",
      "g jcyy    xxcj g",
      "g k    w    uk g",
      "g k ttttt   sk g",
      "f jr   qp oooj f",
      "g k          n  ",
      "g k    mm    l  ",
      "g jjkkkjjkkkjj i",
      "g              f",
      "fgggghgggghggggf"
    ],
    [
      "fgggghgggghggggf",
      "g              g",
      "g              g",
      "g  cccUUUUccc  g",
      "g  c F  X  Wc  g",
      "h  V F      U  h",
      "g  c T   S  c  g",
      "g jcyy     Rcj g",
      "g k   w      k g",
      "g k ttttt    k g",
      "f jQ      oooj f",
      "g k          P  ",
      "g k    OO    N  ",
      "g jjkkkjjkkkjj  ",
      "g              f",
      "fgggghgggghggggf"
    ],
    [
      "                ",
      "                ",
      "  222222222222  ",
      "   cccccccccc   ",
      "   c F      c   ",
      "   V F      U   ",
      "   c F      c   ",
      "  jcyy      cj  ",
      "  0  w       Z  ",
      "  0 ttttt    Z  ",
      "1 j       oooj  ",
      "  0          Z  ",
      "  0          Z  ",
      "  jjYYYjjYYYjj  ",
      "                ",
      "                "
    ],
    [
      "                ",
      "                ",
      "  666666666666  ",
      "  555555555555  ",
      "  2c43222222c2  ",
      "   c43      c   ",
      "   c43      c   ",
      "  jcyy      cj  ",
      "  jbw        j  ",
      "  jbbbbbbbbbbj  ",
      "  jbbbbbbbbbbj  ",
      "  jbbbbbbbbbbj  ",
      "  jbbbbbbbbbbj  ",
      "  jjjjjjjjjjjj  ",
      "                ",
      "                "
    ],
    [
      "                ",
      "                ",
      "                ",
      "                ",
      "  666666666666  ",
      "  555555555555  ",
      "  2c[F222222c2  ",
      "  jcyy      cj  ",
      "  k ---------k  ",
      "  k      999 k  ",
      "  k   +) 9^%Zk  ",
      "  k  (*& 9^%Zk  ",
      "  k$  #@ 9998k  ",
      "  jjjjjjjjjjjj  ",
      " 77777777777777 ",
      "                "
    ]
  ]
}