{
  "name": "building_restaurant1_top_90",
  "refpalette": "c70cities:building_restaurant1_top_palette_90",
  "xsize": 16,
  "zsize": 16,
  "slices": [
    [
      "                ",
      "    eeee==      ",
      "    ebbbb=   ci ",
      "    ebbbb=hhhhi ",
      "    ebbbb=ggggi ",
      "    =bbb!=ggggi ",
      "    =bbbb=ggggi ",
      " a  =bbbb=ggggi ",
      " acc=bbbb=ggggi ",
      " abb=bbbb=ggggi ",
      " a d=bbbb=ggggi ",
      " abbbbbbb=ggggi ",
      " abbbbbbb=ggggi ",
      " aaa=bbbb=ffffi ",
      "    ======      ",
      "                "
    ],
    [
      "                ",
      "    ======      ",
      "    =prps=  ci  ",
      "    =   t=  ci  ",
      "    =o  s=AAAi  ",
      "    =nqnn=yyyi  ",
      "    =        i  ",
      " a  =c    xBxi  ",
      " acc=c       i  ",
      " ajj=c       i  ",
      " a  =c    wBwi  ",
      " a  l        i  ",
      " a  k    =uuui  ",
      " aaa=mmmm=fffi  ",
      "    ======      ",
      "                "
    ],
    [
      "                ",
      "    ======      ",
      "    = JL = ci   ",
      "    c    = ci   ",
      "    cI   =AAi   ",
      "    c  K =  i   ",
      "    c           ",
      " C  =e          ",
      " Ccc=e          ",
      " Cjj=e          ",
      " C  =e          ",
      " C  E     N     ",
      " C  D    =uui   ",
      " Cae=F  M=ffi   ",
      "    ======      ",
      "                "
    ],
    [
      "                ",
      "    ===ee=      ",
      "    =    =ci    ",
      "    =    =ci    ",
      "    =    =Ai    ",
      "    =    = i    ",
      "    =     N     ",
      "  C =e    N     ",
      "  Cc=e    N     ",
      "  Cj=e    N     ",
      "  C =eP   N     ",
      "  C =     N     ",
      "  C =    =ui    ",
      "  Ce=    =fi    ",
      "    ==OO==      ",
      "                "
    ],
    [
      "                ",
      "    ======      ",
      "    =    =i     ",
      "    = R  =i     ",
      "    =    =i     ",
      "    =    =i     ",
      "    =    =i     ",
      "   C=QR  =i     ",
      "   C=Q   =i     ",
      "   C=Q   =i     ",
      "   C=QR  =i     ",
      "   C=    =i     ",
      "   C=    =i     ",
      "   C=    =i     ",
      "    ======      ",
      "                "
    ],
    [
      "                ",
      "    ======      ",
      "    ======      ",
      "    ======      ",
      "    ======      ",
      "    ======      ",
      "    ======      ",
      "    ======      ",
      "    ======      ",
      "    ======      ",
      "    ======      ",
      "    ======      ",
      "    ======      ",
      "    ======      ",
      "    ======      ",
      "                "
    ]
  ]
}