{
  "name": "building_office5_floor2",
  "refpalette": "c70cities:building_office5_floor2_palette",
  "xsize": 16,
  "zsize": 16,
  "slices": [
    [
      "                ",
      "                ",
      "   ababababa    ",
      "   bcccccccb    ",
      "   accccccca    ",
      "  ddeedddddddd  ",
      "  beeeeffeeeeb  ",
      "  deeeeeeeeeed  ",
      "  beeeeeeeeeeb  ",
      "  deeeeeeeeeed  ",
      "  beeeeeeeeeeb  ",
      "  deeeeeeeeeed  ",
      "  beeeeeeeeeeb  ",
      "  ddbdbdbdbdbd  ",
      "                ",
      "                "
    ],
    [
      "                ",
      "                ",
      "   ababababa    ",
      "   b       b    ",
      "   a  gghija    ",
      "  dd  dddddddd  ",
      "  bk  kff    b  ",
      "  d          d  ",
      "  b       l  b  ",
      "  dm   l     d  ",
      "  b gg gg gg b  ",
      "  d  n     n d  ",
      "  b      n   b  ",
      "  ddbdbdbdbdbd  ",
      "                ",
      "                "
    ],
    [
      "                ",
      "                ",
      "   ababababa    ",
      "   b       b    ",
      "   a   o   a    ",
      "  dd  ddddd!dd  ",
      "  bk  kff    b  ",
      "  d          d  ",
      "  b          b  ",
      "  d          d  ",
      "  b  p     p b  ",
      "  d          d  ",
      "  b          b  ",
      "  ddbdbdbdbdbd  ",
      "                ",
      "                "
    ],
    [
      "                ",
      "                ",
      "   ababababa    ",
      "   b       b    ",
      "   a   qqqqa    ",
      "  ddrrdddddrdd  ",
      "  b    ff    b  ",
      "  d          d  ",
      "  b          b  ",
      "  d          d  ",
      "  b          b  ",
      "  d          d  ",
      "  b          b  ",
      "  ddbdbdbdbdbd  ",
      "                ",
      "                "
    ],
    [
      "                ",
      "                ",
      "   ababababa    ",
      "   b       b    ",
      "   a       a    ",
      "  dddddddddddd  ",
      "  b    ff    b  ",
      "  d          d  ",
      "  b          b  ",
      "  d          d  ",
      "  b          b  ",
      "  d          d  ",
      "  b          b  ",
      "  ddbdbdbdbdbd  ",
      "                ",
      "                "
    ],
    [
      "                ",
      "                ",
      "   ababababa    ",
      "   b       b    ",
      "   a       a    ",
      "  dddddddddddd  ",
      "  bssssffssssb  ",
      "  dssssssssssd  ",
      "  bssssssssssb  ",
      "  dssssssssssd  ",
      "  bssssssssssb  ",
      "  dssssssssssd  ",
      "  bssssssssssb  ",
      "  ddbdbdbdbdbd  ",
      "                ",
      "                "
    ]
  ]
}