{
  "name": "building_policeoffice1_top_270",
  "refpalette": "c70cities:building_policeoffice1_top_palette_270",
  "xsize": 16,
  "zsize": 16,
  "slices": [
    [
      "                ",
      " cccc           ",
      " geecaaaaaaaaaa ",
      " cbbcbbbbbbbbba ",
      " cbbbbbbbbbbbba ",
      " cbbcbbbbbb!bba ",
      " gbbcbbbbbbbbba ",
      " cbbcbbbbbbbbba ",
      " cbbcbbbbbbbbba ",
      " cbbcbbbbbb!bba ",
      " gbbcbbbbbbbbba ",
      " cbbcaaaaaaaaaa ",
      " c  c           ",
      " c  d           ",
      " g  c           ",
      " cffc           "
    ],
    [
      "                ",
      " cccc           ",
      " g  caaaaaaaaaa ",
      " c  c       i a ",
      " c       hhgg a ",
      " c  c    h ggha ",
      " g  c    h j ha ",
      " c  c    h   ha ",
      " c  chhhhhhggha ",
      " c  c      gg a ",
      " g  ck     j  a ",
      " cllcaaaaaaaaaa ",
      " c  c           ",
      " c  d           ",
      " g  c           ",
      " cccc           "
    ],
    [
      "                ",
      " cccc           ",
      " g  cnnnnnnnnn  ",
      " c  c         m ",
      " c         gg m ",
      " c  c      gg m ",
      " g  c         m ",
      " c  c         m ",
      " c  c      gg m ",
      " c  c      gg m ",
      " g  c         m ",
      " c  cooooooooo  ",
      " c  c           ",
      " c  d           ",
      " g  c           ",
      " cppc           "
    ],
    [
      "                ",
      " cccc           ",
      " g  c           ",
      " c  c           ",
      " c  c      q    ",
      " c  c           ",
      " g  c           ",
      " c  c           ",
      " c  c      q    ",
      " c  c           ",
      " g  c           ",
      " c  c           ",
      " c  c           ",
      " c  d           ",
      " g  c           ",
      " cppc           "
    ],
    [
      "                ",
      " cccc           ",
      " c  c           ",
      " c  c      q    ",
      " c  c      qq   ",
      " c  c           ",
      " c  c           ",
      " c  c           ",
      " c  c      qq   ",
      " c  c      q    ",
      " c  c           ",
      " c  c           ",
      " c  c           ",
      " c  c           ",
      " c  c           ",
      " cccc           "
    ],
    [
      "                ",
      " cccc           ",
      " cccc           ",
      " cccc      r    ",
      " cccc       r   ",
      " cccc           ",
      " cccc           ",
      " cccc           ",
      " cccc       r   ",
      " cccc      r    ",
      " cccc           ",
      " cccc           ",
      " cccc           ",
      " cccc           ",
      " cccc           ",
      " cccc           "
    ]
  ]
}