{
  "name": "building_warehouse2_ground_90",
  "refpalette": "c70cities:building_warehouse2_ground_palette_90",
  "xsize": 16,
  "zsize": 16,
  "slices": [
    [
      "zzzzzzzzzzzzzzzz",
      "zbbbbbbbbbbdbbbz",
      "zbcccccccbdbbbdz",
      "zbcccccccbbbbbdz",
      "zbcccccccbbbbbbz",
      "zbcccccccbbbbbbz",
      "zbcccccccbbbbbbz",
      "zbcccccccbbbbbdz",
      "zbcccccccbbbbbbz",
      "zbcccccccbbbbbbz",
      "zbbbbbbbbbbbbbbz",
      "zbbddbbdbddbbbdz",
      "azaaaaaaaaaaaaaz",
      "zaaaaaaaaaaaaazz",
      "aaazaazzaazaaaaa",
      "zzzaazzzzzazzzza"
    ],
    [
      " e    e e  eu e ",
      "egffgfggff     u",
      " gkmkiijqf  gf  ",
      " fkkkijn grrfg e",
      "egkinii      g e",
      " gjk i p     x e",
      " gil         w  ",
      "eg   o      tf  ",
      " g l     g  sg e",
      "eg     o grrgg  ",
      " fhhhf   g  gf  ",
      "e              u",
      "                ",
      "               e",
      "   e      e     ",
      "     e  e  e e  "
    ],
    [
      "                ",
      " gggggfggf      ",
      " fmkiin qg  fg  ",
      " gkiji   grrgg  ",
      " fj  i       g  ",
      " r   l       B  ",
      " rn          A  ",
      " g          yg  ",
      " f       g   f  ",
      " g       grrff  ",
      " ghhhghhhf  gg  ",
      "                ",
      "                ",
      "                ",
      "                ",
      "                "
    ],
    [
      "                ",
      " fgfggfggg      ",
      " f! i   qg  fg  ",
      " gj  l   frrgg  ",
      " g       C   f  ",
      " g       C   E  ",
      " g       C   E  ",
      " g       C  Dg  ",
      " g       g   f  ",
      " g   j   frrgg  ",
      " fhhhghhhg  gg  ",
      "                ",
      "                ",
      "                ",
      "                ",
      "                "
    ],
    [
      "                ",
      " gggfgggggFFFFF ",
      " fj     qgFFggF ",
      " g       gIIggF ",
      " g      Eg  JgF ",
      " g      Eg   gF ",
      " g      Eg   gF ",
      " f   J  Eg  JgF ",
      " g       f   gF ",
      " gIIIjIIIgIIggF ",
      " ggggggfgfKKggF ",
      "  FFFFFFFFFFFFF ",
      "                ",
      "                ",
      "                ",
      "                "
    ],
    [
      "                ",
      " gggggggfg      ",
      " gLLLLLLqgMMMM  ",
      " gLLLLLLLgMMMM  ",
      " gLLLLLLLgMMMM  ",
      " fLLLLLLLgMMMM  ",
      " gLLLLLLLgMMMM  ",
      " gLLLbLLLgMMMM  ",
      " gLLLLLLLgMMMM  ",
      " gLLLLLLLgMMMM  ",
      " gfgggfggfMMMM  ",
      "                ",
      "                ",
      "                ",
      "                ",
      "                "
    ]
  ]
}