{
  "name": "building_policeoffice1_base1_90",
  "refpalette": "c70cities:building_policeoffice1_base1_palette_90",
  "xsize": 16,
  "zsize": 16,
  "slices": [
    [
      "vvvvvvvvvvvvvvvv",
      "v==============v",
      "v=!==!======cc=v",
      "v===========cc=v",
      "v===========cc=v",
      "v===========cc=v",
      "v===========cc=v",
      "v===========cc=v",
      "v===========cc=v",
      "v===========cc=v",
      "v===========cc=v",
      "v===========cc=v",
      "v===========cc=v",
      "v=!==!=====abb=v",
      "v==============v",
      "vvvvvvvvvvvvvvvv"
    ],
    [
      "vvvvvvvvvvvvvvvv",
      "vaaaaaaaaaaaaaav",
      "vahi hi himi  av",
      "vagi gi gi ii av",
      "va            av",
      "va    l    i  av",
      "vaf ff ff nip av",
      "vaaaaaaaaaao  av",
      "vafjff ff  i  av",
      "va  k  k   i  av",
      "va         i  av",
      "va i  i  i i  av",
      "vaei ei ei i  av",
      "vadi di dimabbav",
      "vaaaaaaaaaaaaaav",
      "vvvvvvvvvvvvvvvv"
    ],
    [
      "vvvvvvvvvvvvvvvv",
      "vaaaaaaaaaaaaaav",
      "va i  i  i i  av",
      "va i  i  i i  av",
      "va            av",
      "va         i  av",
      "va    j    i  av",
      "vaaaaaaaaao   av",
      "va  j      i  av",
      "va         i  av",
      "va         i  av",
      "va i  i  i i  av",
      "va i  i  i i  av",
      "va i  i  i abbav",
      "vaaaaaaaaaaaaaav",
      "vvvvvvvvvvvvvvvv"
    ],
    [
      "vvvvvvvvvvvvvvvv",
      "vaaaaaaaaaaaaaav",
      "va         i  av",
      "va         i  av",
      "va         i  av",
      "va         i  av",
      "va         i  av",
      "vaaaaaaaaaaa  av",
      "va   j     i  av",
      "va         i  av",
      "va         i  av",
      "va         i  av",
      "va         i  av",
      "va    j   jabbav",
      "vaaaaaaaaaaaaaav",
      "vvvvvvvvvvvvvvvv"
    ],
    [
      "vvvvvvvvvvvvvvvv",
      "vaaaaaaaaaaaaaav",
      "va j  j   ja  av",
      "va         aj av",
      "va         a  av",
      "va        ja  av",
      "va j     jja  av",
      "vaaaaaaaaaaa  av",
      "vaj jjj   ja  av",
      "va  j      a  av",
      "va j       a  av",
      "va         a  av",
      "va        ja  av",
      "vajj jj  jjabbav",
      "vaaaaaaaaaaaaaav",
      "vvvvvvvvvvvvvvvv"
    ],
    [
      "vqqqqqqqqqqqqqqv",
      "qaaaaaaaaaaaaaav",
      "qarrrrrrrrrassav",
      "qarrrrrrrrrassav",
      "qarrrrrrrrrassav",
      "qarrrrrrrrrassav",
      "qarrrrrrrrrassav",
      "qaaaaaaaaaaassav",
      "qarrrrrrrrrassav",
      "qarrrrrrrrrassav",
      "qarrrrrrrrrassav",
      "qarrrrrrrrrassav",
      "qarrrrrrrrrassav",
      "qarrrrrrrrrabbav",
      "qaaaaaaaaaaaaaav",
      "vvvvvvvvvvvvvvvv"
    ]
  ]
}