{
  "name": "building_office3_top_270",
  "refpalette": "c70cities:building_office3_top_palette_270",
  "xsize": 16,
  "zsize": 16,
  "slices": [
    [
      "                ",
      " aabaabaabaabaa ",
      " acccccccccccca ",
      " bccccccccccccb ",
      " acccccccccccca ",
      " accc!cccccccca ",
      " bccccccccccccb ",
      " acccccvvccccca ",
      " acccccddccccca ",
      " bccccccccccccb ",
      " acccccccccccca ",
      " acccccccccccca ",
      " bccccccccccccb ",
      " acccccccccccca ",
      " aabaabaabaabaa ",
      "                "
    ],
    [
      "                ",
      " eebeebeebeebee ",
      " effffffffffffe ",
      " bf  iii     fb ",
      " ef gghihhgg fe ",
      " ef gg iiigg fe ",
      " bf i     h  fb ",
      " ef i     h  fe ",
      " ef i     h  fe ",
      " bf ii    h  fb ",
      " efhhihhhhh  fe ",
      " ef  i  h    fe ",
      " bf  i  h    fb ",
      " effffffffffffe ",
      " eebeebeebeebee ",
      "                "
    ],
    [
      "                ",
      " jjjjjjjjjjjjjj ",
      " j            j ",
      " j            j ",
      " j  gg    gg  j ",
      " j  gg    gg  j ",
      " j            j ",
      " j            j ",
      " j            j ",
      " j            j ",
      " j            j ",
      " j            j ",
      " j            j ",
      " j            j ",
      " jjjjjjjjjjjjjj ",
      "                "
    ],
    [
      "                ",
      "                ",
      "                ",
      "                ",
      "                ",
      "    k     k     ",
      "                ",
      "                ",
      "                ",
      "                ",
      "                ",
      "                ",
      "                ",
      "                ",
      "                ",
      "                "
    ],
    [
      "                ",
      "                ",
      "                ",
      "                ",
      "                ",
      "    l     l     ",
      "                ",
      "                ",
      "                ",
      "                ",
      "                ",
      "                ",
      "                ",
      "                ",
      "                ",
      "                "
    ],
    [
      "                ",
      "                ",
      "                ",
      "                ",
      "                ",
      "    m     m     ",
      "                ",
      "                ",
      "                ",
      "                ",
      "                ",
      "                ",
      "                ",
      "                ",
      "                ",
      "                "
    ]
  ]
}