{
  "name": "building_restaurant1_base1_270",
  "refpalette": "c70cities:building_restaurant1_base1_palette_270",
  "xsize": 16,
  "zsize": 16,
  "slices": [
    [
      "vvvvvvvvvvvvvvvv",
      "v==============v",
      "vbbbbbvvvvvvva=v",
      "vbdddcvvvvvvvv=v",
      "vbdddcvvvvvvvv=v",
      "vbdddcvvvvvvvv=v",
      "vbccccvvvvvvvv=v",
      "vbccccvvvvvvvv=v",
      "vbccccvvv!vvvv=v",
      "vbccccvvvvvvvv=v",
      "vbccccvvvvvvvv=v",
      "vb!cccvvvvvvvv=v",
      "vbccccvvvvvvvv=v",
      "vbbbbbvvvvvvvv=v",
      "v==============v",
      "vvvvvvvvvvvvvvvv"
    ],
    [
      "vvvvvvvvvvvvvvvv",
      "v==============v",
      "vbbbbbhk  jjja=v",
      "vbtttdk    jje=v",
      "vbtttd     j  =v",
      "vbtttd        =v",
      "vbdddq  ln    =v",
      "vb      llll  =v",
      "vbu sq llll   =v",
      "vb     llln   =v",
      "vbus s  lo   f=v",
      "vbw sqq      g=v",
      "vbxu q      kh=v",
      "vbbbbbrp   mii=v",
      "v==============v",
      "vvvvvvvvvvvvvvvv"
    ],
    [
      "vvvvvvvvvvvvvvvv",
      "v==============v",
      "vbbbbbg    jja=v",
      "vb   q       e=v",
      "vb   q        =v",
      "vb   q        =v",
      "vb            =v",
      "vb      ll    =v",
      "vb      lll   =v",
      "vb      l     =v",
      "vb            =v",
      "vb   q        =v",
      "vbu  q       g=v",
      "vbbbbbA     yk=v",
      "v==============v",
      "vvvvvvvvvvvvvvvv"
    ],
    [
      "vvvvvvvvvvvvvvvv",
      "v==============v",
      "vbbbbb      ja=v",
      "vbB  q       e=v",
      "vb   q        =v",
      "vb            =v",
      "vb            =v",
      "vb            =v",
      "vb      ln    =v",
      "vb            =v",
      "vb            =v",
      "vb            =v",
      "vb   q        =v",
      "vbbbbb        =v",
      "v==============v",
      "vvvvvvvvvvvvvvvv"
    ],
    [
      "vvvvvvvvvvvvvvvv",
      "v==============v",
      "vbbbbb       a=v",
      "vbC  q       e=v",
      "vb   q        =v",
      "vb   q        =v",
      "vb   q        =v",
      "vb   qq       =v",
      "vb   q        =v",
      "vb            =v",
      "vb   q        =v",
      "vb   q        =v",
      "vb   q        =v",
      "vbbbbb        =v",
      "v==============v",
      "vvvvvvvvvvvvvvvv"
    ],
    [
      "vvvvvvvvvvvvvvvv",
      "v==============v",
      "vbbbbbDDDDDDDa=v",
      "vbEdddDDDDDDDe=v",
      "vbddddDDDDDDDD=v",
      "vbddddDDDDDDDD=v",
      "vbddddDDDDDDDD=v",
      "vbddddDDDDDDDD=v",
      "vbddddDDDDDDDD=v",
      "vbddddDDDDDDDD=v",
      "vbddddDDDDDDDD=v",
      "vbddddDDDDDDDD=v",
      "vbddddDDDDDDDD=v",
      "vbbbbbDDDDDDDD=v",
      "v==============v",
      "vvvvvvvvvvvvvvvv"
    ]
  ]
}