{
  "name": "building_hotel2_floor2",
  "refpalette": "c70cities:building_hotel2_floor2_palette",
  "xsize": 16,
  "zsize": 16,
  "slices": [
    [
      "                ",
      " aaaaaaaaaaaaaa ",
      " abccccccccd    ",
      " abccccccccd    ",
      " a=ccccccccd    ",
      " acccccccccd    ",
      " acccccccccd    ",
      " a!ccccccccd    ",
      " accccc!cccd    ",
      " a!ccccccccd    ",
      " acccccccccd    ",
      " acccccccccd    ",
      " acccccccccd    ",
      " adddddddddd    ",
      " a              ",
      "                "
    ],
    [
      "                ",
      " aaaaaaaaaaaaaa ",
      " ab   e    f    ",
      " ab   a    f    ",
      " a=aagahi jf    ",
      " akla ahi jf    ",
      " amna ao   f    ",
      " ap q ar   f    ",
      " aaaa ap ssf    ",
      " a=tt aaaaaf    ",
      " a     uuw f    ",
      " a     xx  f    ",
      " ayAB      f    ",
      " affffffffff    ",
      " a              ",
      "                "
    ],
    [
      "                ",
      " aaaaaaaaaaaaaa ",
      " ab   C    f    ",
      " ab   a    f    ",
      " a=aaDa    f    ",
      " a  a a    f    ",
      " a  a a    f    ",
      " a  E a    f    ",
      " aaaa a  F f    ",
      " aI   aaaaaf    ",
      " a         f    ",
      " a         f    ",
      " a J       f    ",
      " affffffffff    ",
      " a              ",
      "                "
    ],
    [
      "                ",
      " aaaaaaaaaaaaaa ",
      " ab   a    f    ",
      " ab   a    f    ",
      " a=aaaa    f    ",
      " a  a a    f    ",
      " a  a a    f    ",
      " a  a a    f    ",
      " aaaa a    f    ",
      " aKLL aaaaaf    ",
      " a         f    ",
      " a         f    ",
      " a         f    ",
      " affffffffff    ",
      " a              ",
      "                "
    ],
    [
      "                ",
      " aaaaaaaaaaaaaa ",
      " ab M a    f    ",
      " ab M a    f    ",
      " a=aaaa    f    ",
      " a  a a    f    ",
      " a  a a    f    ",
      " a  a a    f    ",
      " aaaa a    f    ",
      " aN   aaaaaf    ",
      " a         f    ",
      " a         f    ",
      " a         f    ",
      " affffffffff    ",
      " a              ",
      "                "
    ],
    [
      "                ",
      " aaaaaaaaaaaaaa ",
      " abOOOaOOOOJ    ",
      " abOOOaOOOOJ    ",
      " a=aaaaOOOOJ    ",
      " aOOaOaOOOOJ    ",
      " aOOaOaOOOOJ    ",
      " aOOaOaOOOOJ    ",
      " aaaaOaOOOOJ    ",
      " aOOOOaaaaOJ    ",
      " aOOOOOOOOOJ    ",
      " aOOOOOOOOOJ    ",
      " aOOOOOOOOOJ    ",
      " aJJJJJJJJJJ    ",
      " a              ",
      "                "
    ]
  ]
}