{
  "name": "building_residential4_ground",
  "refpalette": "c70cities:building_residential4_ground_palette",
  "xsize": 16,
  "zsize": 16,
  "slices": [
    [
      "GGGGGGGGGGGGGGGG",
      "GGGGGGGGGGGGGGGG",
      "GGaaaaaaaaaaaaGG",
      "GGabbbbbbcccdGGG",
      "GGabbbbbbcccdGGG",
      "GGabbbbbbcccdGGG",
      "GGabbbbbbcccdGGG",
      "GGabbbbbbcccdGGG",
      "GGabbbbbbcccdGGG",
      "GGabbbbbbcccdGGG",
      "GGabbbbbbcccdGGG",
      "GGabbbbbbcccdGGG",
      "GGabbbbbbcccdGGG",
      "GGaaaaaaaaaaaaGG",
      "GGGGGGGGGGGGGGGG",
      "GGGGGGGGGGGGGGGG"
    ],
    [
      "effffgffffgffffe",
      "f              f",
      "f hhiihiihiihh f",
      "f j   k lm ndo f",
      "f jp qk lm ndo f",
      "e jr qk  s tdo g",
      "u h   w    xdo f",
      "  y   w    Ado f",
      "  B        Cdo f",
      "e h        xdo f",
      "f j      DDDdo g",
      "f jE     F Ido f",
      "f jJ  K  LMNdo f",
      "f hhOOhOOhOOhh f",
      "f              f",
      "effffgffffgffffe"
    ],
    [
      "effffgffffgffffe",
      "f              f",
      "f hhPPhPPhPPhh f",
      "f P   Q     d  f",
      "f P  RQ  S  d  f",
      "e P  RQ    Td  g",
      "  h   w     d  f",
      "  U   w     V  f",
      "  W        XV  f",
      "e h        Yd  f",
      "f P      DDDd  g",
      "f P      Z  d  f",
      "f P 0K   L  d  f",
      "f hhPPhPPh11hh f",
      "f              f",
      "effffgffffgffffe"
    ],
    [
      "                ",
      "                ",
      "  hhhhhhhhhhhh  ",
      "  P   Q     d2  ",
      "  P   Q     d2  ",
      "  P   Q     d2  ",
      "  h   w     d2  ",
      "  P   w     V2  ",
      "  P         V2  ",
      "  h         d2  ",
      "  P      DDDd2  ",
      "  P 3    L  d2  ",
      "  P      L  d2  ",
      "  hhhhhhhhhhhh  ",
      "                ",
      "                "
    ],
    [
      "                ",
      " 44444444444444 ",
      " OhhhhhhhhhhhhO ",
      "  hbbbbbbbbbd5  ",
      "  hbbbbbbbbbd5  ",
      "  hbbbbbbbbbd5  ",
      "  hbbbbbbbbbd5  ",
      "  hbbbbbbbbbd   ",
      "  hbbbbbbbbbd   ",
      "  hbbbbbbbbbd5  ",
      "  hb3  bbbbbd5  ",
      "  hb   bbbbbd5  ",
      "  hb   bbbbbd5  ",
      " ihhhhhhhhhhhhi ",
      " 66666666666666 ",
      "                "
    ],
    [
      "                ",
      "                ",
      " 44444444444444 ",
      " O5dhhhhhhhhd5O ",
      "  5d55555555d5  ",
      "  5d789  @@ d5  ",
      "  5d789  @@#d5  ",
      "  $d%99 ^@@&d*  ",
      "  (d        d)  ",
      "  5d ++-[[[[d5  ",
      "  5d  ]    {d5  ",
      "  5d  ]    }d5  ",
      " i5d  ] !\\\\ d5i ",
      " 66666666666666 ",
      "                ",
      "                "
    ]
  ]
}