{
  "name": "building_apartment1_ground_180",
  "refpalette": "c70cities:building_apartment1_ground_palette_180",
  "xsize": 16,
  "zsize": 16,
  "slices": [
    [
      "GGGGGGGGGGGGGGGG",
      "GaaaaaaaaaaaaaaG",
      "GaaaaaaaaaaaaaaG",
      "GaaaaaaaaaaaaaaG",
      "GaaaaaaaaaaaaaaG",
      "GaaaaaaaaaaaaaaG",
      "GaaaaaaaaaaaaaaG",
      "GaaaaaaaaaaaaaaG",
      "GaaaaaaaaaaaaaaG",
      "GaaaaaaaaaaaaaaG",
      "GaaaaaaaaaaaaaaG",
      "GaaaaaaaaaaaaaaG",
      "GaaaaaaaaaaaaaaG",
      "GaaaaaaaaaaaaaaG",
      "GaaaaaaaaaaaaaaG",
      "GGGGGGGGGGGGGGGG"
    ],
    [
      "                ",
      "      bKddddddd ",
      "  CCJJbp      d ",
      "  Cr  b  DI I d ",
      "  CF  E  DDDD d ",
      "  C   B      pd ",
      " bbbbbb      rq ",
      " dpAy        ux ",
      " d       w   ut ",
      " d ss        rq ",
      " dmllk   b   pb ",
      " dmllkbobbn   d ",
      " dmllkb  bg   d ",
      " d jj bihbgfe d ",
      " bbccccccccccbb ",
      "                "
    ],
    [
      "                ",
      "      bKddddddd ",
      "  CCCCbp      d ",
      "  CFS b       d ",
      "  J   R   Q   d ",
      "  P   O      pd ",
      " bbbbbb      rq ",
      " dp           N ",
      " d            M ",
      " d           rq ",
      " d       b   pb ",
      " d    bLbb    d ",
      " d    b  b    d ",
      " d    b  bg   d ",
      " bbbbbbbbbbbbbb ",
      "                "
    ],
    [
      "                ",
      "      bKddddddd ",
      "  YXCCb       d ",
      "  C Wrb       d ",
      "  C   V       d ",
      "  C   V       d ",
      " bbbbbb      rq ",
      " d            U ",
      " d            U ",
      " d           rq ",
      " d       b    b ",
      " d    bTbb    d ",
      " d    b  b    d ",
      " d    b  b    d ",
      " bbddbbddbbddbb ",
      "                "
    ],
    [
      "                ",
      "      bKKKKKKKq ",
      "  CJJ0b       K ",
      "  X  Wb       K ",
      "  X  Zb       K ",
      "  X   b       K ",
      " bbbbbb      rq ",
      " K    b      r  ",
      " K    b      r  ",
      " K    b      rq ",
      " K    b  b    b ",
      " K    bbbb    K ",
      " K    b  b    K ",
      " K    b  b    K ",
      " bbccbbccbbccbb ",
      "                "
    ],
    [
      "                ",
      "      bbbbbbbbb ",
      "  CCCCbCCCCCCCb ",
      "  C   bCCCCCCCb ",
      "  C  4bCCCCCCCb ",
      "  C  rbCCCCCCCb ",
      " bbbbbbCCCCCCCb ",
      " bCCCCbCC3wCCCb ",
      " bCCCCbCC2!CCCb ",
      " bCCCCbCCCCCCCb ",
      " bCCCCbCCbCCCCb ",
      " bCCCCbbbbCCCCb ",
      " bCCCCb11bCCCCb ",
      " bCCCCb11bCCCCb ",
      " bbbbbbbbbbbbbb ",
      "                "
    ]
  ]
}