{
  "name": "building_hotel2_base1_270",
  "refpalette": "c70cities:building_hotel2_base1_palette_270",
  "xsize": 16,
  "zsize": 16,
  "slices": [
    [
      "vvvvvvvvvvvvvvvv",
      "vaaaaaaaaaaaaaav",
      "va!bbbbbbbbbbbav",
      "vabbbbbbbbbbbbav",
      "vabbbbbbbbbbbbav",
      "vabbbbbbbbbbbbav",
      "vabbbbbbbbbbbbav",
      "vabbbbbbbbbbbbav",
      "va!bbbbbbbbbbbav",
      "vabbbbbbbbbbbbav",
      "vabbbbbbbbbbbbav",
      "vabbbbbbbbbbbbav",
      "vabbbbbbbbbbbbav",
      "va!bbbbbbbbbbbav",
      "vaaaaaaaaaaaaaav",
      "vvvvvvvvvvvvvvvv"
    ],
    [
      "vvvvvvvvvvvvvvvv",
      "vcfffffffff=cccv",
      "vc ieg ieg =ddcv",
      "vc         e  cv",
      "vc i g i g    cv",
      "vc  e   e     cv",
      "vc i g i g    cv",
      "vc            cv",
      "vc ieg        cv",
      "vcfffff   e e cv",
      "vcmnmkf h=====cv",
      "vc      hbbbbbcv",
      "vc      hbbbbbcv",
      "vcolllfj=bbbbbcv",
      "vccccccccccccccv",
      "vvvvvvvvvvvvvvvv"
    ],
    [
      "vvvvvvvvvvvvvvvv",
      "vcfffffffff=cccv",
      "vc  j   j  =ddcv",
      "vc         s  cv",
      "vc  j   j     cv",
      "vc  j   j     cv",
      "vc  j   j     cv",
      "vc            cv",
      "vc  j         cv",
      "vcfffff   q q cv",
      "vcxw uf  rrrr=cv",
      "vc           ocv",
      "vc        t  ocv",
      "vc    fj=pppppcv",
      "vccccccccccccccv",
      "vvvvvvvvvvvvvvvv"
    ],
    [
      "vvvvvvvvvvvvvvvv",
      "vcfffffffff=cccv",
      "vc         =ddcv",
      "vc         s  cv",
      "vc            cv",
      "vc            cv",
      "vc            cv",
      "vc            cv",
      "vc            cv",
      "vcfffff       cv",
      "vc    f      ycv",
      "vc            cv",
      "vc            cv",
      "vc ABAfj=tt ttcv",
      "vccccccccccccccv",
      "vvvvvvvvvvvvvvvv"
    ],
    [
      "vvvvvvvvvvvvvvvv",
      "vcfffffffff=cccv",
      "vc         =ddcv",
      "vc            cv",
      "vc            cv",
      "vc            cv",
      "vc            cv",
      "vc            cv",
      "vc            cv",
      "vcfffff       cv",
      "vc    f       cv",
      "vc    f       cv",
      "vc    f       cv",
      "vc  B fj=t tttcv",
      "vccccccccccccccv",
      "vvvvvvvvvvvvvvvv"
    ],
    [
      "vvvvvvvvvvvvvvvv",
      "vcCCCCCCCCC=cccv",
      "vcCCCCCCCCC=ddcv",
      "vcCCCCCCCCCCCCcv",
      "vcCCCCCCCCCCCCcv",
      "vcCCCCCCCCCCCCcv",
      "vcCCCCCCCCCCCCcv",
      "vcCCCCCCCCCCCCcv",
      "vcCCCCCCCCCCCCcv",
      "vcfffffCCCCCCCcv",
      "vcCCCCfCCCCCCCcv",
      "vcCCCCfCCCCCCCcv",
      "vcCCCCfCCCCCCCcv",
      "vcCCCCfC=EDDEDcv",
      "vccccccccccccccv",
      "vvvvvvvvvvvvvvvv"
    ]
  ]
}