{
  "name": "building_office3_floor1_270",
  "refpalette": "c70cities:building_office3_floor1_palette_270",
  "xsize": 16,
  "zsize": 16,
  "slices": [
    [
      "                ",
      " aabaabaabaabaa ",
      " acccccccccccca ",
      " bccccccccccccb ",
      " acccccccccccca ",
      " acccccccccccca ",
      " bccccccccccccb ",
      " acccccvvccccca ",
      " acccccddccccca ",
      " bccccccccccccb ",
      " acccccccccccca ",
      " acc!ccccccccca ",
      " bccccccccccccb ",
      " acccccccccccca ",
      " aabaabaabaabaa ",
      "                "
    ],
    [
      "                ",
      " eebeebeebeebee ",
      " e    ohhl    e ",
      " b f        f b ",
      " e     ee     e ",
      " e         h  e ",
      " b     nm  ig b ",
      " e pp  vv k   e ",
      " e  pg dd   g e ",
      " b kp     ki  b ",
      " e  pg     j  e ",
      " e  p         e ",
      " b f        f b ",
      " e            e ",
      " eebeebeebeebee ",
      "                "
    ],
    [
      "                ",
      " qqbqqbqqbqqbqq ",
      " q            q ",
      " b f        f b ",
      " q            q ",
      " q            q ",
      " b     ss  r  b ",
      " q     vv  r  q ",
      " q     dd  r  q ",
      " b         r  b ",
      " q            q ",
      " q            q ",
      " b f        f b ",
      " q            q ",
      " qqbqqbqqbqqbqq ",
      "                "
    ],
    [
      "                ",
      " qqbqqbqqbqqbqq ",
      " q            q ",
      " b f        f b ",
      " q            q ",
      " q            q ",
      " b     ss     b ",
      " q     vv     q ",
      " q     dd     q ",
      " b            b ",
      " q            q ",
      " q            q ",
      " b f        f b ",
      " q            q ",
      " qqbqqbqqbqqbqq ",
      "                "
    ],
    [
      "                ",
      " qqbqqbqqbqqbqq ",
      " q            q ",
      " b f        f b ",
      " q            q ",
      " q            q ",
      " b            b ",
      " q     vv     q ",
      " q     dd     q ",
      " b            b ",
      " q            q ",
      " q            q ",
      " b f        f b ",
      " q            q ",
      " qqbqqbqqbqqbqq ",
      "                "
    ],
    [
      "                ",
      " qqbqqbqqbqqbqq ",
      " qttttttttttttq ",
      " btfuuuuuuuuftb ",
      " qtuuuuuuuuuutq ",
      " qtuuuuuuuuuutq ",
      " btuuuuuuuuuutb ",
      " qtuuuuvvuuuutq ",
      " qtuuuudduuuutq ",
      " btuuuuuuuuuutb ",
      " qtuuuuuuuuuutq ",
      " qtuuuuuuuuuutq ",
      " btfuuuuuuuuftb ",
      " qttttttttttttq ",
      " qqbqqbqqbqqbqq ",
      "                "
    ]
  ]
}