{
  "name": "building_office1_top",
  "refpalette": "c70cities:building_office1_top_palette",
  "xsize": 16,
  "zsize": 16,
  "slices": [
    [
      "                ",
      "                ",
      "  aaaaaaaaaaaa  ",
      "  abbbbbbbbbba  ",
      "  abbbbbbbbbba  ",
      "  abbbbbbbbbba  ",
      "  abbbbbbbbbba  ",
      "  abbbbbbbbbba  ",
      " ccbbbbbbbbbbcc ",
      "  dbbbbbbbbbbd  ",
      "  dbbbbbbbbbbd  ",
      " efgbbbbbbbbbfe ",
      " ebbbbbbbbbbbbe ",
      " ebbbbbbbbbbbbe ",
      " eeeeeeeeeeeeee ",
      "                "
    ],
    [
      "                ",
      "                ",
      "  hhhhhhhhhhhh  ",
      "  h          h  ",
      "  h ii    ii h  ",
      "  h ij kk ji h  ",
      "  h ij kk ji h  ",
      "  h ii    ii h  ",
      " ccl        lcc ",
      "  d          d  ",
      "  d          d  ",
      " mf          fm ",
      " m            m ",
      " m     nn     m ",
      " mmmmmmmmmmmmmm ",
      "                "
    ],
    [
      "                ",
      "                ",
      "                ",
      "  o          o  ",
      "                ",
      "  o          o  ",
      "                ",
      "  o          o  ",
      " ccp        pcc ",
      "  d          d  ",
      "  d          d  ",
      " mf          fm ",
      " m            m ",
      " m            m ",
      " mmqddddddddqmm ",
      "                "
    ],
    [
      "                ",
      "                ",
      "                ",
      "  o          o  ",
      "                ",
      "  o          o  ",
      "                ",
      "  o          o  ",
      " cc          cc ",
      "  d          d  ",
      "  d          d  ",
      " mf          fm ",
      " m            m ",
      " m            m ",
      " mmqddddddddqmm ",
      "                "
    ],
    [
      "                ",
      "                ",
      "                ",
      "  o          o  ",
      "                ",
      "  o          o  ",
      "                ",
      "  o          o  ",
      " ccffffffffffcc ",
      "  frrrrrrrrrrf  ",
      "  frrrrrrrrrrf  ",
      " mffffffffffffm ",
      " m            m ",
      " m            m ",
      " mmmmmmmmmmmmmm ",
      "                "
    ],
    [
      "                ",
      "                ",
      "  ssssssssssss  ",
      "  seeeeeeeeees  ",
      "  seeeeeeeeees  ",
      "  seeeeeeeeees  ",
      "  seeeeeeeeees  ",
      "  seeeeeeeeees  ",
      " ccsssssssssscc ",
      "                ",
      "                ",
      " mrrrrrrrrrrrrm ",
      " mrrrrrrrrrrrrm ",
      " mrrrrrrrrrrrrm ",
      " mmmmmmmmmmmmmm ",
      "                "
    ]
  ]
}