{
  "name": "building_office1_floor1_180",
  "refpalette": "c70cities:building_office1_floor1_palette_180",
  "xsize": 16,
  "zsize": 16,
  "slices": [
    [
      "                ",
      " eeeeeeeeeeeeee ",
      " ebbbbbbbbbbbbe ",
      " ebbb!bbbbbbbbe ",
      " efbbbbbbbbbgfe ",
      "  dbbbbbbbbbbd  ",
      "  dbbbbbbbbbbd  ",
      " ccbbbbbbbbbbcc ",
      "  abbbbbbbbbba  ",
      "  abbbbbbbbbba  ",
      "  abbbbbbbbbba  ",
      "  abbbbbbbbbba  ",
      "  abbbbbbbbbba  ",
      "  aaaaaaaaaaaa  ",
      "                ",
      "                "
    ],
    [
      "                ",
      " ssssssssssssss ",
      " sC   B fA   us ",
      " sy  xxxfw   us ",
      " sf  i ift  gfs ",
      "  d     r    d  ",
      "  d     fq   d  ",
      " ccfffffffpofcc ",
      "  hn         h  ",
      "  h  m m m   h  ",
      "  h l k  k j h  ",
      "  h   i i i  h  ",
      "  h          h  ",
      "  hhhhhhhhhhhh  ",
      "                ",
      "                "
    ],
    [
      "                ",
      " ssOddddddddOss ",
      " s      f    us ",
      " sN  MLKf    us ",
      " sf     f   gfs ",
      "  d     J    d  ",
      "  d     fq   d  ",
      " ccfffffffIFfcc ",
      "  hE         h  ",
      "  h          h  ",
      "  h  DDDDDD  h  ",
      "  h          h  ",
      "  h          h  ",
      "  hhhhhhhhhhhh  ",
      "                ",
      "                "
    ],
    [
      "                ",
      " ssOddddddddOss ",
      " s      f    us ",
      " s      f    us ",
      " sf     f   gfs ",
      "  d     f    d  ",
      "  d     f    d  ",
      " ccffffffffffcc ",
      "  h          h  ",
      "  h          h  ",
      "  h          h  ",
      "  h          h  ",
      "  h          h  ",
      "  hhhhhhhhhhhh  ",
      "                ",
      "                "
    ],
    [
      "                ",
      " ssssssssssssss ",
      " s      f    Ps ",
      " s      f    Ps ",
      " sf     f   gfs ",
      "  d     f    d  ",
      "  d     f    d  ",
      " ccffffffffffcc ",
      "  h          h  ",
      "  h          h  ",
      "  h          h  ",
      "  h          h  ",
      "  h          h  ",
      "  hhhhhhhhhhhh  ",
      "                ",
      "                "
    ],
    [
      "                ",
      " ssssssssssssss ",
      " sOOOOOOfOOOOOs ",
      " sOOOOOOfOOOOOs ",
      " sf OOOOfOOOgfs ",
      "  d OOOOfOOO d  ",
      "  d OOOOfOOO d  ",
      " ccffffffffffcc ",
      "  hOOOOOOOOOOh  ",
      "  hOOOOOOOOOOh  ",
      "  hOOOOOOOOOOh  ",
      "  hOOOOOOOOOOh  ",
      "  hOOOOOOOOOOh  ",
      "  hhhhhhhhhhhh  ",
      "                ",
      "                "
    ]
  ]
}