{
  "name": "building_office2_floor2_270",
  "refpalette": "c70cities:building_office2_floor2_palette_270",
  "xsize": 16,
  "zsize": 16,
  "slices": [
    [
      "                ",
      " a            a ",
      " a dddddddddd a ",
      " abeeeeeeeeeeba ",
      " accccccccccc!a ",
      " acccccccccccca ",
      " acccccccccccca ",
      " afccccccccccca ",
      " afccccccccccca ",
      " acccccccccccca ",
      " acccccccccccca ",
      " acccccccccccca ",
      " abeeeeeeeeeeba ",
      " a dddddddddd a ",
      " a            a ",
      "                "
    ],
    [
      "                ",
      " a            a ",
      " a dddddddddd a ",
      " ab          ba ",
      " aj  g      g a ",
      " aj  hhh  hhh a ",
      " ak    i  i   a ",
      " af           a ",
      " af           a ",
      " ak    g  g   a ",
      " al  hhh  hhh a ",
      " aj  i      i a ",
      " ab          ba ",
      " a dddddddddd a ",
      " a            a ",
      "                "
    ],
    [
      "                ",
      " a            a ",
      " a dddddddddd a ",
      " ab          ba ",
      " a            a ",
      " a   m m  m m a ",
      " an           a ",
      " af           a ",
      " af           a ",
      " an           a ",
      " a   m m  m m a ",
      " a            a ",
      " ab          ba ",
      " a dddddddddd a ",
      " a            a ",
      "                "
    ],
    [
      "                ",
      " a            a ",
      " a dddddddddd a ",
      " ab          ba ",
      " a            a ",
      " a            a ",
      " a            a ",
      " af           a ",
      " af           a ",
      " a            a ",
      " a            a ",
      " a            a ",
      " ab          ba ",
      " a dddddddddd a ",
      " a            a ",
      "                "
    ],
    [
      "                ",
      " a            a ",
      " a dddddddddd a ",
      " ab          ba ",
      " a            a ",
      " a            a ",
      " a            a ",
      " af           a ",
      " af           a ",
      " a            a ",
      " a            a ",
      " a            a ",
      " ab          ba ",
      " a dddddddddd a ",
      " a            a ",
      "                "
    ],
    [
      "                ",
      " a            a ",
      " a dddddddddd a ",
      " ab          ba ",
      " aooooooooooooa ",
      " aooooooooooooa ",
      " aooooooooooooa ",
      " afoooooooooooa ",
      " afoooooooooooa ",
      " aooooooooooooa ",
      " aooooooooooooa ",
      " aooooooooooooa ",
      " ab          ba ",
      " a dddddddddd a ",
      " a            a ",
      "                "
    ]
  ]
}