{
  "name": "building_restaurant2_ground_180",
  "refpalette": "c70cities:building_restaurant2_ground_palette_180",
  "xsize": 16,
  "zsize": 16,
  "slices": [
    [
      "GGGGGGGGGGGGGGGG",
      "GccccbbaaaaGGGGG",
      "GcccccccccccaGGG",
      "GcccceggfegcaGGG",
      "GcccceddfedcaGGG",
      "GbaggfeggfecaGGG",
      "GbaddfeddfecaGGa",
      "GaagfeggfegcabaG",
      "Gaadfeddfedcaaaa",
      "GbaggfeggfecaGbG",
      "GaaddfeddfecaGGG",
      "GcccceggfegcaGGG",
      "GcccceddfedcbGGG",
      "GcccccccccccaGGG",
      "GccccabaaaaGGGGG",
      "GGGGGGGGGGGGGGGG"
    ],
    [
      "                ",
      " iiiiTSSSRih    ",
      " iQPimmmmmmmm   ",
      " iO E     pms   ",
      " iiii      mq   ",
      " NiM LKJt pmo   ",
      " DiC BmAt imm   ",
      " DiC BmAt I     ",
      " DiF BmAt E     ",
      " DiC BmAt imm   ",
      " yi  xwut pms   ",
      " iiri      mq   ",
      " in i     pmo   ",
      " innimmmmmmmm   ",
      " iiiilkkkjih    ",
      "                "
    ],
    [
      "                ",
      " iiii     iU    ",
      " i  imVVVmmmm   ",
      " i  4      VY   ",
      " iiii      VY   ",
      " Yi@  92   VY   ",
      " Yi! 312  imm   ",
      " Yi8  12  7     ",
      " Yi6 512  4     ",
      " Yi  312  imm   ",
      " Yi   10   VY   ",
      " iiZi      VY   ",
      " i  i      VY   ",
      " iXWimVVVmmmm   ",
      " iiii     iU    ",
      "                "
    ],
    [
      "                ",
      " iiiiYYYYYiU    ",
      " V  immmmmmmm   ",
      " V  i+)))( VY   ",
      " iiii      VY   ",
      " Yi   &^   VY   ",
      " Yi   &^  imm   ",
      " Yi   &^  i *   ",
      " Yi   &^  i *   ",
      " Yi   &^  imm   ",
      " Yi   &^   VY   ",
      " iiii      VY   ",
      " V  iX%%%W VY   ",
      " V$#immmmmmmm   ",
      " iiiiYYYYYiU    ",
      "                "
    ],
    [
      "                ",
      " iiii-----i     ",
      " -  immmmmmmm[  ",
      " -  i}}}}{ii-   ",
      " iiii     ii-   ",
      " -i       ii-   ",
      " -i       imm[  ",
      " -i       i *   ",
      " -i       i *   ",
      " -i       imm[  ",
      " -i       ii-   ",
      " iiii     ii-   ",
      " -  i]]]]]ii-   ",
      " -  immmmmmmm[  ",
      " iiii-----i     ",
      "                "
    ],
    [
      "                ",
      " iiiiiiiiii\\\\\\\\ ",
      " i``|mmmmmm\\\\\\\\ ",
      " i``|:::::|\\\\\\\\ ",
      " iii|:::::|\\\\\\\\ ",
      " |i||;;;;;|\\\\\\\\ ",
      " |i||:::::|\\\\\\\\ ",
      " |i||:::::|\\\\\\\\ ",
      " |i||:::::|\\\\\\\\ ",
      " |i||:::::|\\\\\\\\ ",
      " |i||;;;;;|\\\\\\\\ ",
      " iii|:::::|\\\\\\\\ ",
      " i``|:::::|\\\\\\\\ ",
      " i``|mmmmmm\\\\\\\\ ",
      " iiiiiiiiii\\\\\\\\ ",
      "                "
    ]
  ]
}