{
  "name": "building_office4_floor3_90",
  "refpalette": "c70cities:building_office4_floor3_palette_90",
  "xsize": 16,
  "zsize": 16,
  "slices": [
    [
      "                ",
      "    abaaaaba    ",
      "  cccdeeeedccc  ",
      "  ceeeeeeeeeec  ",
      " aceeeeeeeeeeca ",
      " bdeeeeeeeeeedb ",
      " aeeeeeeeeeeeea ",
      " aeeeeeeeeeeeea ",
      " aeeeeeeeeeeeea ",
      " aeeeeeeeeeeeea ",
      " bdeeeeee!eeedb ",
      " aceeeeeeeeeeca ",
      "  ceeeeeeeeeec  ",
      "  cccdeffedccc  ",
      "    abaaaaba    ",
      "                "
    ],
    [
      "                ",
      "    abaaaaba    ",
      "  gggd    dggg  ",
      "  g          g  ",
      " ag    ll    ga ",
      " bd          db ",
      " ah   jkkm   na ",
      " ah          oa ",
      " ai   j  m   na ",
      " ah    kk    na ",
      " bd   j  m   db ",
      " ag          ga ",
      "  g          g  ",
      "  gggd ff dggg  ",
      "    abaaaaba    ",
      "                "
    ],
    [
      "                ",
      "    abaaaaba    ",
      "  gggd    dggg  ",
      "  g          g  ",
      " ag          ga ",
      " bd    pp    db ",
      " a     pp     a ",
      " a     pp     a ",
      " a     pp     a ",
      " a     pp     a ",
      " bd    pp    db ",
      " ag          ga ",
      "  g          g  ",
      "  gggd ff dggg  ",
      "    abaaaaba    ",
      "                "
    ],
    [
      "                ",
      "    abaaaaba    ",
      "  gggd    dggg  ",
      "  g          g  ",
      " ag          ga ",
      " bd          db ",
      " a            a ",
      " a            a ",
      " a            a ",
      " a            a ",
      " bd          db ",
      " ag          ga ",
      "  g          g  ",
      "  gggd ff dggg  ",
      "    abaaaaba    ",
      "                "
    ],
    [
      "                ",
      "    abaaaaba    ",
      "  gggd    dggg  ",
      "  g          g  ",
      " ag          ga ",
      " bd          db ",
      " a            a ",
      " a            a ",
      " a            a ",
      " a            a ",
      " bd          db ",
      " ag          ga ",
      "  g          g  ",
      "  gggd ff dggg  ",
      "    abaaaaba    ",
      "                "
    ],
    [
      "                ",
      "    abaaaaba    ",
      "  gggdqqqqdggg  ",
      "  gqqqqqqqqqqg  ",
      " agqqqqqqqqqqga ",
      " bdqqqqqqqqqqdb ",
      " aqqqqqqqqqqqqa ",
      " aqqqqqqqqqqqqa ",
      " aqqqqqqqqqqqqa ",
      " aqqqqqqqqqqqqa ",
      " bdqqqqqqqqqqdb ",
      " agqqqqqqqqqqga ",
      "  gqqqqqqqqqqg  ",
      "  gggdqffqdggg  ",
      "    abaaaaba    ",
      "                "
    ]
  ]
}