{
  "name": "building_restaurant1_ground",
  "refpalette": "c70cities:building_restaurant1_ground_palette",
  "xsize": 16,
  "zsize": 16,
  "slices": [
    [
      "GGGGGGGGGGGGGGGG",
      "GGaaaaaaaGGGGGGG",
      "GGabcccaddGddGGd",
      "GGaccccaddddGddG",
      "G==cc==========G",
      "G=ccccccccccc!=G",
      "G=cccccccccccc=G",
      "G=cccccccccccc=G",
      "G=cccccccccccc=G",
      "G==============G",
      "GGefffffffffaeGG",
      "GGefffffffffaeGG",
      "GGefffffffffaeGG",
      "GGefffffffffaeGG",
      "GGeeeeeeeeeeeeGG",
      "GGGGGGGGGGGGGGGG"
    ],
    [
      "                ",
      "  aaaaaaa    g  ",
      "  a        g    ",
      "  a  h       g  ",
      " ==ij========== ",
      " =    k      l= ",
      " =k     k m  n= ",
      " =o  o  o m  p= ",
      " =q  q  qrmstt= ",
      " ===     r===== ",
      "  eu      uwx   ",
      "  eqo   qoywx   ",
      "  e o      wx   ",
      "  eAo    oywx   ",
      "  eeeeeeeeeeee  ",
      "   BCDDDDEBBFB  "
    ],
    [
      "                ",
      "  aaaaaaa       ",
      "  a             ",
      "  I  h          ",
      " ==JK====LLLL== ",
      " =            = ",
      " =        M  N= ",
      " =r       r   = ",
      " =        rOP = ",
      " ===      ===== ",
      "  eQ      Qw    ",
      "  e        w    ",
      "  e r      w    ",
      "  e      R w    ",
      "  eexxxxxxeexe  ",
      "                "
    ],
    [
      "                ",
      "  aaaaaaa       ",
      "  a   SLLL      ",
      "  I  hSLLL      ",
      " ============== ",
      " =            = ",
      " T          U = ",
      " T            I ",
      " =            I ",
      " ===      ===== ",
      "  eQ      Qw    ",
      "  e        w    ",
      "  e        w    ",
      "  e        w    ",
      "  ee      ee e  ",
      "                "
    ],
    [
      "                ",
      "  aaaaaaa       ",
      "  a   SLL       ",
      "  a  hSLL       ",
      " ============== ",
      " =            = ",
      " =V    V    V = ",
      " =            = ",
      " =            = ",
      " ============== ",
      "  e        w    ",
      "  e        w    ",
      "  e U      w    ",
      "  e        w    ",
      "  ee      ee e  ",
      "                "
    ],
    [
      "                ",
      "  aaaaaaa       ",
      "  a   SL        ",
      "  a  hSL        ",
      " ============== ",
      " =WWWWWWWWWWWW= ",
      " =WWWWWWWWWWWW= ",
      " =WWWWWWWWWWWW= ",
      " =WWWWWWWWWWWW= ",
      " ============== ",
      "  e        w    ",
      "  e        w    ",
      "  e V    V w    ",
      "  e        w    ",
      "  eeeeeeeeeeee  ",
      "                "
    ]
  ]
}