{
  "name": "building_bank1_top_180",
  "refpalette": "c70cities:building_bank1_top_palette_180",
  "xsize": 16,
  "zsize": 16,
  "slices": [
    [
      "                ",
      "  abbbc abbbc   ",
      "  deeeedeeeeeda ",
      " ceeeeeeeeeeeeb ",
      " beeeeeeeeeeeeb ",
      " beeeeeeeeeeeeb ",
      " beeeeeeeeee ec ",
      " aeeeeeeeeee d  ",
      "  deeeeeeeee ea ",
      " ceeeeeeeeee eb ",
      " beeeeeeeeee eb ",
      " beeeeeeeeeeeeb ",
      " beeeeeeeeeeeec ",
      " adeeeeedeeeed  ",
      "   cbbba cbbba  ",
      "                "
    ],
    [
      "                ",
      " fbcc abbcc abf ",
      " bgggghggggghgb ",
      " ahxwwwuuwwwugc ",
      "  gttttttttttgc ",
      " cg          g  ",
      " cg ssrq     ha ",
      " bg    n m   gb ",
      " bg  p o     gb ",
      " ah    n m   gc ",
      "  g  lkj     gc ",
      " cg          g  ",
      " cgi         ha ",
      " bghggggghggggb ",
      " fba ccbba ccbf ",
      "                "
    ],
    [
      "                ",
      " fbbbbbbbbbbbbf ",
      " bgggghggggghgb ",
      " bhwwwwwwwwwwgb ",
      " bg          gb ",
      " bg          gb ",
      " bg ss A     hb ",
      " bg          gb ",
      " bg          gb ",
      " bh          gb ",
      " bg    y     gb ",
      " bg          gb ",
      " bg          hb ",
      " bghggggghggggb ",
      " fbbbbbbbbbbbbf ",
      "                "
    ],
    [
      "                ",
      "                ",
      "   gghggggghg   ",
      "  gg        gg  ",
      "  h          g  ",
      "  g          h  ",
      "  g          g  ",
      "  g          g  ",
      "  g          g  ",
      "  g          g  ",
      "  h          g  ",
      "  g          h  ",
      "  gg        gg  ",
      "   ghggggghgg   ",
      "                ",
      "                "
    ],
    [
      "                ",
      "                ",
      "                ",
      "    gggggggg    ",
      "   gggggggggg   ",
      "   ggg    ggg   ",
      "   gg     Bgg   ",
      "   gg      gg   ",
      "   gg      gg   ",
      "   ggB     gg   ",
      "   ggg    ggg   ",
      "   gggggggggg   ",
      "    gggggggg    ",
      "                ",
      "                ",
      "                "
    ],
    [
      "                ",
      "                ",
      "                ",
      "                ",
      "                ",
      "      gggg      ",
      "     gggggg     ",
      "     gggggg     ",
      "     gggggg     ",
      "     gggggg     ",
      "      gggg      ",
      "                ",
      "                ",
      "                ",
      "                ",
      "                "
    ]
  ]
}