{
  "name": "building_residential3_ground_90",
  "refpalette": "c70cities:building_residential3_ground_palette_90",
  "xsize": 16,
  "zsize": 16,
  "slices": [
    [
      "GGGGGGGGGGGGGGGG",
      "GGGGGGGGGGGGGGGG",
      "GGaaaaaaaaaaaaGG",
      "GGabbbbbbbbbbaGG",
      "GGabbbbbbbbbbaGG",
      "GGabbbbbbbbbbaGG",
      "GGabbbbbbbbbbaGG",
      "GGabbbbbbbbbaaGG",
      "GGabbbbbddddcGGG",
      "GGabbbbbddddcGGG",
      "GGabbbbbddddcGGG",
      "GGabbbbbddddcGGG",
      "GGabbbbacccccGGG",
      "GGaaaaaaGGGGGGGG",
      "GGGGGGGGGGGGGGGG",
      "GGGGGGGGGGGGGGGG"
    ],
    [
      "effffgffffeffffe",
      "f              f",
      "f hhhhhhhhhhhh f",
      "f h mo uu yE i f",
      "f h  p       F f",
      "g hkko       F g",
      "f h!      xx i f",
      "f h    tthhhhh f",
      "f h        Dcw f",
      "f hj   s   Ccw f",
      "g h   qr   Bcw g",
      "f h   qr   Acw f",
      "f h    hcccccw f",
      "f hilnih wwwww f",
      "f              f",
      "effe  efffgffffe"
    ],
    [
      "effffgffffeffffe",
      "f              f",
      "f hhIhFhhFFFhh f",
      "f h Ko NO    i f",
      "f I  M       F f",
      "g hkko       F g",
      "f F       QQ i f",
      "f h    tthhhhh f",
      "f hj       Sc  f",
      "f F         P  f",
      "g F         P  g",
      "f F        Rc  f",
      "f h    hcPPcc  f",
      "f hiJLih       f",
      "f              f",
      "effe  efffgffffe"
    ],
    [
      "          U     ",
      "                ",
      "  hhWhWhhWWWhh  ",
      "  h  o       i  ",
      "  T  o       Y  ",
      "  hkko       Y  ",
      "  T          i  ",
      "  hj   tthhhhh  ",
      "  h         cX  ",
      "  T         cX  ",
      "  T         cX  ",
      "  T         cX  ",
      "  h    hcccccX  ",
      "  hiVVihXXXXXX  ",
      "                ",
      "   U            "
    ],
    [
      "                ",
      "                ",
      "  hhhhhhhhhhhh  ",
      "  hbbbbbbbbbbh  ",
      "  hbbbbbbbbbbh  ",
      "  hbbbbbbbbbbh  ",
      "  hjbbbbbbbbbh  ",
      "  h bbbbbbbbhh  ",
      "  h bbbb    2Z  ",
      "  h bbbb    2Z  ",
      "  hbbbbb    2Z  ",
      "  hbbbbb    2Z  ",
      "  hbbbbh00001Z  ",
      "  hhhhhhZZZZZZ  ",
      "                ",
      "                "
    ],
    [
      "                ",
      "                ",
      "  hFFFFhhWWWhh  ",
      "  h    $i7** F  ",
      "  T   8#i^&&^F  ",
      "  T    @i^^^^F  ",
      "  T 5        F  ",
      "  h 5  99999hh  ",
      "  h 5  9%   cZ  ",
      "  T 5  9    cZ  ",
      "  T4  79    cZ  ",
      "  T3  69    cZ  ",
      "  h3  6hcccccZ  ",
      "  hFFFFhZZZZZZ  ",
      "                ",
      "                "
    ]
  ]
}