{
  "name": "building_apartment1_floor2",
  "refpalette": "c70cities:building_apartment1_floor2_palette",
  "xsize": 16,
  "zsize": 16,
  "slices": [
    [
      "                ",
      " aaaaaaaaaaaaaa ",
      " abbbbbbbbbbbba ",
      " abbbbbbbbbbbba ",
      " abbbbbbbbbbbba ",
      " abbbbbbbbbbbba ",
      " abbbbbbbbbbbba ",
      " abbbbbbbbbbbba ",
      " abbbbbbbbbbbba ",
      " abbbbbbbbbbbba ",
      " abbbbbbbbcbbd  ",
      " abbbbbbbb bbe  ",
      " abbbbbbbb  fe  ",
      " abbbbbbbbdghi  ",
      " aaaaaaaaa      ",
      "                "
    ],
    [
      "                ",
      " jkkkkkkkkkkkkl ",
      " mnoopqrs q!not ",
      " m uu w   q  ut ",
      " m    qxyxx   t ",
      " m AB q     ABt ",
      " mqqqCqyqqqqqqt ",
      " msrD      qEEt ",
      " m  F      F  t ",
      " mqqD IJJqqqKqt ",
      " mrL     q   d  ",
      " mM   N Oq  Pd  ",
      " mQ   N Rq  Sd  ",
      " mT      qUUdd  ",
      " VWWWWWWWW      ",
      "                "
    ],
    [
      "                ",
      " qqqqqqqqqqqqqq ",
      " XY   q Z q   X ",
      " X    0   q   X ",
      " X    qx1xx   X ",
      " q    q       q ",
      " 2qqq3q1qqqqqqq ",
      " 45 D      q  q ",
      " 4  6      6  q ",
      " 2qqD   7qqq8qq ",
      " 4       q   h  ",
      " 4      9q   U  ",
      " 4@     9q #Pd  ",
      " 4$      qdddd  ",
      " 24XXXXX4q      ",
      "                "
    ],
    [
      "                ",
      " qqXXqqXXqqXXqq ",
      " X%   q   q  ^X ",
      " X&   q   q  *X ",
      " X(   qxxxx  )X ",
      " q    q       q ",
      " 2qqqqqqqqqqqqq ",
      " X  D      q  X ",
      " X  D      q  X ",
      " 2qqD    qqqqqq ",
      " 4       q   d  ",
      " X      +q   d  ",
      " X      +qS- d  ",
      " X []{}\\ qdd|`  ",
      " 24XXXXX4q      ",
      "                "
    ],
    [
      "                ",
      " qqkkqqkkqqkkqq ",
      " 4    q   q   4 ",
      " 4    q   q   4 ",
      " 4    qxxxx   4 ",
      " q    q       q ",
      " 2qqqqqqqqqqqqq ",
      " 4  D      q  4 ",
      " 4  D      qf 4 ",
      " 2qqD :  qqqqqq ",
      " 4       q   |  ",
      " 4       q;  |  ",
      " 4       q-  |  ",
      " 4       qeUUd  ",
      " 24444444q      ",
      "                "
    ],
    [
      "                ",
      " qqqqqqqqqqqqqq ",
      " qddddq'''ddddq ",
      " qddddq'''ddddq ",
      " qddddqdddddddq ",
      " qddddqdddddddq ",
      " qqqqqqqqqqqqqq ",
      " q''dddddddqddq ",
      " q''dddddddqddq ",
      " qdddddddqqqqqq ",
      " qdddddddqS  d  ",
      " qdddddddqc  d  ",
      " qdddddddq   d  ",
      " qdddddddqdddd  ",
      " qqqqqqqqq      ",
      "                "
    ]
  ]
}