{
  "name": "building_bank1_ground_90",
  "refpalette": "c70cities:building_bank1_ground_palette_90",
  "xsize": 16,
  "zsize": 16,
  "slices": [
    [
      "GGGGGGGGGGGGGGGG",
      "GGaGGaaaaGGaaaGG",
      "GabbbbbbbbbbbbaG",
      "GabbbbbbbbbbbbGG",
      "GabbbbbbbbbbbbGG",
      "GGbbbbbbbbbbbbaG",
      "GGbbbbbbbbbbbbaG",
      "GabbbbbbbbbbbbaG",
      "Gabbbbbbbbb!bbaG",
      "GabbbbbbbbbbbbGG",
      "GabbbbbbbbbbbbGG",
      "GGbbbbbbbbbbbbaG",
      "GGbbbbbbbbbbcbaG",
      "GabbbbbbbbbbbbaG",
      "GGaaaGGaaaaGGaGG",
      "GGGGGGGGGGGGGGGG"
    ],
    [
      "                ",
      " da  aaaa  aaad ",
      " aehfeeeehfeeea ",
      " ag  mnpm    e  ",
      " ae          f  ",
      "  f        uuea ",
      "  e j    s wuea ",
      " ae kl   s wuea ",
      " ae k      uuea ",
      " ae jl       e  ",
      " ae j        f  ",
      "  f       ataea ",
      "  e i  oqoa  ea ",
      " aeeefeeerefeea ",
      " daaa  aaaa  ad ",
      "                "
    ],
    [
      "                ",
      " da  aaaa  aaad ",
      " aexfeeeexfeeea ",
      " ag  m  m    e  ",
      " ae          f  ",
      "  f          ea ",
      "  e          ea ",
      " ae          ea ",
      " ae A        ea ",
      " ae          e  ",
      " ae y        f  ",
      "  f       aBaea ",
      "  e  i    a  ea ",
      " aeeefeeerefeea ",
      " daaa  aaaa  ad ",
      "                "
    ],
    [
      "                ",
      " dD  aaaD  aaad ",
      " aefeeeeefeeeeF ",
      " ae          f  ",
      " ae          e  ",
      "  e          ea ",
      "  f          ea ",
      " Ce          ea ",
      " ae          eF ",
      " ae          f  ",
      " ae          e  ",
      "  e       aaaea ",
      "  f   i   a  ea ",
      " Ceeeefeereefea ",
      " daaa  Eaaa  Ed ",
      "                "
    ],
    [
      "                ",
      " d   aaa   aaad ",
      " aefeeeeefeeee  ",
      " ae          f  ",
      " ae          e  ",
      "  e          ea ",
      "  f          ea ",
      "  e          ea ",
      " ae          e  ",
      " ae          f  ",
      " ae          e  ",
      "  e       aaaea ",
      "  f    i  a  ea ",
      "  eeeefeereefea ",
      " daaa   aaa   d ",
      "                "
    ],
    [
      "                ",
      "    KaaD  KaaD  ",
      " Cfeeeeefeeeef  ",
      " aeJJJJJJJJJJe  ",
      " aeJJJJJJJJJJeO ",
      " IeJJMMMMMMJJea ",
      "  eJJMNNNNMJJea ",
      "  fJJMNNNNMJJeF ",
      " CeJJMMMMMMJJf  ",
      " aeJJJJJJJJJJe  ",
      " aeJJJJJJJJJJeO ",
      " IeJJJJJJJaaaea ",
      "  eJJ   iJaJJea ",
      "  feeeefereeefF ",
      "  EaaL  EaaL    ",
      "                "
    ]
  ]
}