{
  "name": "building_residential1_ground_180",
  "refpalette": "c70cities:building_residential1_ground_palette_180",
  "xsize": 16,
  "zsize": 16,
  "slices": [
    [
      "GGGGGGGGGGGGGGGG",
      "GGGGGGGGGGGGGGGG",
      "GGGGGGGGGGGGGGGG",
      "GGGccccccccccGGG",
      "GGGceeddddddcGGG",
      "GGGceeddddddcGGG",
      "GGGceeddddddcGGG",
      "GGaceeddddddcaGG",
      "GGabbbbbbbbbbaGG",
      "GGabbbbbbbbbbaGG",
      "GGabbbbbbbbbbaGG",
      "GGabbbbbbbbbbaGG",
      "GGabbbbbbbbbbaGG",
      "GGaaaaaaaaaaaaGG",
      "GGGGGGGGGGGGGGGG",
      "GGGGGGGGGGGGGGGG"
    ],
    [
      "fgggghgggghggggf",
      "g              g",
      "g xxxxxxxxxxxx g",
      "g xccccccccccx g",
      "g xcKC!JIFEDcx g",
      "h xc C      cx h",
      "g xc B   Ayycx g",
      "g icww    uuci g",
      "g j    t    sj g",
      "g j rrrrr   qj g",
      "f i    po nnni f",
      "g j          m  ",
      "g j    ll    k  ",
      "g iijjjiijjjii f",
      "g              g",
      "fgggghgggghggggf"
    ],
    [
      "fgggghgggghggggf",
      "g              g",
      "g              g",
      "g  cccRRRRccc  g",
      "g  cWC VU  Tc  g",
      "h  S C      R  h",
      "g  c Q   P  c  g",
      "g icww     Oci g",
      "g j   t      j g",
      "g j rrrrr    j g",
      "f i       nnni f",
      "g j          N  ",
      "g j    MM    L  ",
      "g iijjjiijjjii f",
      "g              g",
      "fgggghgggghggggf"
    ],
    [
      "                ",
      "                ",
      "  111111111111  ",
      "   cccccccccc   ",
      "   c C      c   ",
      "   S C      R   ",
      "   c C      c   ",
      "  icww      ci  ",
      "  Z  t       Y  ",
      "  Z rrrrr    Y  ",
      "0 i       nnni  ",
      "  Z          Y  ",
      "  Z          Y  ",
      "  iiXXXiiXXXii  ",
      "                ",
      "                "
    ],
    [
      "                ",
      "                ",
      "  555555555555  ",
      "  444444444444  ",
      "  1c32111111c1  ",
      "   c32      c   ",
      "   c32      c   ",
      "  icww      ci  ",
      "  ibt        i  ",
      "  ibbbbbbbbbbi  ",
      "  ibbbbbbbbbbi  ",
      "  ibbbbbbbbbbi  ",
      "  ibbbbbbbbbbi  ",
      "  iiiiiiiiiiii  ",
      "                ",
      "                "
    ],
    [
      "                ",
      "                ",
      "                ",
      "                ",
      "  555555555555  ",
      "  444444444444  ",
      "  1c+C111111c1  ",
      "  icww      ci  ",
      "  j )))))))))j  ",
      "  j      888 j  ",
      "  j   (* 8$#Yj  ",
      "  j  &^% 8$#Yj  ",
      "  j   @9 8887j  ",
      "  iiiiiiiiiiii  ",
      " 66666666666666 ",
      "                "
    ]
  ]
}