{
  "name": "building_residential1_ground_90",
  "refpalette": "c70cities:building_residential1_ground_palette_90",
  "xsize": 16,
  "zsize": 16,
  "slices": [
    [
      "GGGGGGGGGGGGGGGG",
      "GGGGGGGGGGGGGGGG",
      "GGaaaaaaaGGGGGGG",
      "GGabbbbbcccccGGG",
      "GGabbbbbeeeecGGG",
      "GGabbbbbeeeecGGG",
      "GGabbbbbddddcGGG",
      "GGabbbbbddddcGGG",
      "GGabbbbbddddcGGG",
      "GGabbbbbddddcGGG",
      "GGabbbbbddddcGGG",
      "GGabbbbbddddcGGG",
      "GGabbbbbcccccGGG",
      "GGaaaaaaaGGGGGGG",
      "GGGGGGGGGGGGGGGG",
      "GGGGGGGGGGGGGGGG"
    ],
    [
      "fggggfgggghggggf",
      "g              g",
      "g ijjijjixxxxx g",
      "g i     cccccx g",
      "g j   r w  Kcx g",
      "h j   r wBCCcx h",
      "g j   r    !cx g",
      "g il prt   Jcx g",
      "g il or    Icx g",
      "g j      A Fcx g",
      "h j  n  uy Ecx h",
      "g j  n  uy Dcx g",
      "g i  nqscccccx g",
      "g ikmijjixxxxx g",
      "g              g",
      "fgf  fgggghggggf"
    ],
    [
      "fggggfgggghggggf",
      "g              g",
      "g ijjijji      g",
      "g i     ccRcc  g",
      "g j   r w  Vc  g",
      "h j   r wPCCc  h",
      "g j   rt    Q  g",
      "g iM  r    UQ  g",
      "g iM  r    TQ  g",
      "g j      O  Q  g",
      "h j  n      c  h",
      "g j  n     Sc  g",
      "g i  n  ccQcc  g",
      "g iLNijji      g",
      "g              g",
      "fgf  fgggghggggf"
    ],
    [
      "     Z          ",
      "                ",
      "  iYYiYYi    0  ",
      "  i     ccRcc0  ",
      "  W   r w   c0  ",
      "  W   rtwCCCc0  ",
      "  W   r     c0  ",
      "  i   r     c0  ",
      "  i   r     c0  ",
      "  W         c0  ",
      "  W  n      c0  ",
      "  W  n      c0  ",
      "  i  n  ccQcc0  ",
      "  iXXiXXi    0  ",
      "                ",
      "                "
    ],
    [
      "                ",
      "                ",
      "  iiiiiii  034  ",
      "  ibbbbbcccc34  ",
      "  ibbbbtw22234  ",
      "  ibbbb w11134  ",
      "  ibbbb    034  ",
      "  ibbbb    034  ",
      "  ibbbb    034  ",
      "  ibbbb    034  ",
      "  ibbbb    034  ",
      "  ibbbb    034  ",
      "  ibbbb cccc34  ",
      "  iiiiiii  034  ",
      "                ",
      "                "
    ],
    [
      "                ",
      " 5              ",
      " 5ijjjjji034    ",
      " 5i     cc34    ",
      " 5i    (w)34    ",
      " 5i ^  (wC34    ",
      " 5i9%* ( 034    ",
      " 5i8$& ( 034    ",
      " 5i    ( 034    ",
      " 5i7777( 034    ",
      " 5i7##7( 034    ",
      " 5i7@@7( 034    ",
      " 5i6XX (cc34    ",
      " 5ijjjjji034    ",
      " 5              ",
      "                "
    ]
  ]
}