{
  "name": "building_gasstation1_ground",
  "refpalette": "c70cities:building_gasstation1_ground_palette",
  "xsize": 16,
  "zsize": 16,
  "slices": [
    [
      "GGGGGGGGGGGGGGGG",
      "aHHHHHHHHHbGGGGG",
      "HHHHHHHHHHbGGGGG",
      "HHHHaHHaaaaaaaGG",
      "HHHHaHHaaaaaaaGG",
      "HHHHaHHaaaaaaaGG",
      "HHHHaHHaaaaaaaGG",
      "HHHHaHHaaaaaaaGG",
      "HHHHaHHaaaaaaaGG",
      "HHHHaHHaaaaaaaGG",
      "HHHHaHHaaaaaaaGG",
      "HHHHaHHaaaaaaaGG",
      "HHHHaHHaaaaaaaGG",
      "HHHHHHHHHHbGGGGG",
      "HHHHHHHHHHbGGGGG",
      "GGGGGGGGGGGGGGGG"
    ],
    [
      "                ",
      "c      d ef     ",
      "       g hf     ",
      "    i  jjjjjjj  ",
      "  klm  jnno!pj  ",
      "       q   rrj  ",
      "  sti  u  oooj  ",
      "  klw  x     j  ",
      "    y  q     j  ",
      "  sti  jA jjBj  ",
      "  klm  C  jD j  ",
      "       CE jFIj  ",
      "  sti  jjjjjjj  ",
      "       d ef     ",
      "       g hf     ",
      "                "
    ],
    [
      "                ",
      "c               ",
      "                ",
      "    i  jjjjjjj  ",
      "    J  j  pKoj  ",
      "       q     j  ",
      "    i  L  oroj  ",
      "       M     j  ",
      "       q     j  ",
      "    i  jN jjOj  ",
      "    J  P  j  j  ",
      "       P  j  j  ",
      "    i  jjjjjjj  ",
      "                ",
      "                ",
      "                "
    ],
    [
      "                ",
      "Q               ",
      "                ",
      "    i  RRRRRRR  ",
      "       RST r U  ",
      "       R     U  ",
      "    i  R     R  ",
      "       R     U  ",
      "       R     U  ",
      "    i  R  jjjR  ",
      "       R  j  U  ",
      "       R  j  U  ",
      "    i  RRRRRRR  ",
      "                ",
      "                ",
      "                "
    ],
    [
      "                ",
      "                ",
      "                ",
      "    jV jjjjjjj  ",
      "       jrWj rj  ",
      "       j  j  j  ",
      "    jV j Xj  j  ",
      "       j  j  j  ",
      "       j  j  j  ",
      "    jX j Vjjjj  ",
      "       j  jYYj  ",
      "       j  jYYj  ",
      "    jV jjjjjjj  ",
      "                ",
      "                ",
      "                "
    ],
    [
      "                ",
      "                ",
      " ZZZZZZZZZZZZZZ ",
      " ZffaaaaaaaaaaZ ",
      " ZffaffaffaffaZ ",
      " ZffaffaffaffaZ ",
      " ZffaffaffaffaZ ",
      " ZffaffaffaffaZ ",
      " ZffaffaffaffaZ ",
      " ZffaffaffaffaZ ",
      " ZffaffaffaffaZ ",
      " ZffaffaffaffaZ ",
      " ZffaaaaaaaaaaZ ",
      " ZZZZZZZZZZZZZZ ",
      "                ",
      "                "
    ]
  ]
}