{
  "name": "building_hotel3_ground_270",
  "refpalette": "c70cities:building_hotel3_ground_palette_270",
  "xsize": 16,
  "zsize": 16,
  "slices": [
    [
      "GGGGGGGGGGGGGGGG",
      "GaaaaaaaaaaaaaaG",
      "GabbbbbbbbbbbbaG",
      "Gabbbbbbbb!bbbaG",
      "GabbcbbbbbbcbbaG",
      "GabbbbbbbbbbbbaG",
      "GabbbbbbbbbbbbaG",
      "GabbbbbbbbdcbbaG",
      "GabbbbbbbbdcbbaG",
      "GabbbbbbbbbbbbaG",
      "GabbbbbbbbbbbbaG",
      "GabbcbbbbbbcbbaG",
      "GabbbbbbbbbbbbaG",
      "GabbbbbbbbbbbbaG",
      "GaaaaaaaaaaaaaaG",
      "GGGGGGGGGGGGGGGG"
    ],
    [
      "                ",
      " aaaaaaaaaaaaaa ",
      " aeeeeeeeeeeeea ",
      " a    hhhh   ea ",
      " ao l hiihccfea ",
      " a           ea ",
      " a nm        ea ",
      " a  m      cgea ",
      " a  m      cgea ",
      " a nm        ea ",
      " a           ea ",
      " ao l     ccfea ",
      " a           ea ",
      " aeee  eeeeeeea ",
      " aaaakjaaaaaaaa ",
      "                "
    ],
    [
      "                ",
      " aaaaaaaaaaap   ",
      " aeeeeeeeeeeeep ",
      " a           e  ",
      " af l     ccfep ",
      " a           e  ",
      " a           ep ",
      " a         cge  ",
      " a  s      cgep ",
      " a           e  ",
      " a           ep ",
      " af l     ccfe  ",
      " a           ep ",
      " aeee  eeeeeee  ",
      " aaaarqaaaaa p  ",
      "                "
    ],
    [
      "                ",
      " aaaaaaaa p p   ",
      " aeeeeeeeeeeeep ",
      " a           e  ",
      " af l     ccfep ",
      " a           e  ",
      " a           ep ",
      " a         cge  ",
      " a         cgep ",
      " a           e  ",
      " a           ep ",
      " af l     ccfe  ",
      " a           ep ",
      " aeeeeeeeeeeee  ",
      " aaaaaaaap p p  ",
      "                "
    ],
    [
      "                ",
      " aaaaap p p p   ",
      " aeeeeeeeeeeeep ",
      " a           e  ",
      " a  l     cc ep ",
      " a         t e  ",
      " a         t ep ",
      " a         cge  ",
      " a         cgep ",
      " a         t e  ",
      " a         t ep ",
      " a  l     cc e  ",
      " a           ep ",
      " aeeeeeeeeeeee  ",
      " aaaaa p p p p  ",
      "                "
    ],
    [
      "                ",
      " aa p p p p p   ",
      " aeeeeeeeeeeeep ",
      " ae          e  ",
      " ae lccccccc ep ",
      " ae cuuuuuuc e  ",
      " ae cuuuuuuc ep ",
      " ae cuuuuuucge  ",
      " ae cuuuuuucgep ",
      " ae cuuuuuuc e  ",
      " ae cuuuuuuc ep ",
      " ae lccccccc e  ",
      " ae          ep ",
      " aeeeeeeeeeeee  ",
      " aap p p p p p  ",
      "                "
    ]
  ]
}