{
  "name": "building_lab1_ground_180",
  "refpalette": "c70cities:building_lab1_ground_palette_180",
  "xsize": 16,
  "zsize": 16,
  "slices": [
    [
      "zzzzzzzzzzzzzzzz",
      "zzzzzzzzzzzzzzzz",
      "zzzzzazzzazzzzzz",
      "zzzzzzazzzzzzzzz",
      "zzzzaazazzzzzzzz",
      "zzzzzzazzzHHHHzz",
      "zzzzzazazzHHHHzz",
      "zzzzazazzzHHHHzz",
      "zzzzazzzzzHHHHzz",
      "zzzazzazzzHHHHzz",
      "zzzzazzazzHHHHbz",
      "zzaazaazzzHHHcbz",
      "zzaaaaaazaHHHHbz",
      "zzzzazazaaHHHHzz",
      "zzzzzzzzzzzzzzzz",
      "zzzzzzzzzzzzzzzz"
    ],
    [
      "e ed           e",
      " gg d      egggd",
      " gh     d   d g ",
      "dghdd     ddd   ",
      "   d  d   f  Bfh",
      "d             bh",
      "d dd  e stts Abh",
      "  y     xw!t rbe",
      "e u     stts rbd",
      "  q      dp  of ",
      "dgd        i nbh",
      "dg      dd  n bh",
      " gh  h      mlb ",
      "dghe hhkjh   ibh",
      " gg     ggf   fe",
      "dd ed d de dd dd"
    ],
    [
      "                ",
      "                ",
      "                ",
      "                ",
      "          f   f ",
      "              bh",
      "        JIFE Mb ",
      "        LF K  b ",
      "        JIFE  b ",
      "          p  Df ",
      "             Cb ",
      "              b ",
      "             ib ",
      "  h           b ",
      "          f   f ",
      "                "
    ],
    [
      "                ",
      "                ",
      "                ",
      "                ",
      "          p   f ",
      "              N ",
      "          OO  N ",
      "        ~LLL  N ",
      "          OO  N ",
      "          p   f ",
      "              N ",
      "              N ",
      "              N ",
      "              N ",
      "          p   f ",
      "                "
    ],
    [
      "                ",
      "                ",
      "                ",
      "                ",
      "          QQPPp ",
      "          QNRR  ",
      "          QNRR  ",
      "        ~ QNRR  ",
      "          QNRR  ",
      "          QQPPp ",
      "          QNRR  ",
      "          QNRR  ",
      "          QNRR  ",
      "          QNRR  ",
      "          QQPPp ",
      "                "
    ],
    [
      "                ",
      "                ",
      "                ",
      "                ",
      "              QQ",
      "              NQ",
      "              NQ",
      "        ~     NQ",
      "              NQ",
      "              QQ",
      "              NQ",
      "              NQ",
      "              NQ",
      "              NQ",
      "              QQ",
      "                "
    ]
  ]
}