{
  "name": "building_hotel3_top",
  "refpalette": "c70cities:building_hotel3_top_palette",
  "xsize": 16,
  "zsize": 16,
  "slices": [
    [
      "                ",
      "  a a a a a a   ",
      "  bbbbbbbbbbbba ",
      " abccccddccccb  ",
      "  bceeeeeeeecba ",
      " abceffffffecb  ",
      "  bceffffffecba ",
      " abceffffffecb  ",
      "  bceffffffecba ",
      " abceffffffecb  ",
      "  bceffffffecba ",
      " abceeeeeeeecb  ",
      "  bccccccccccba ",
      " abbbbbbbbbbbb  ",
      "   a a a a a a  ",
      "                "
    ],
    [
      "                ",
      "  a a a a a a   ",
      "  bbbbbbbbbbbba ",
      " ab          b  ",
      "  b eeeee  e ba ",
      " ab egggh  e b  ",
      "  b egggh  i ba ",
      " ab egggh  i b  ",
      "  b egggh  i ba ",
      " ab ehhhh  i b  ",
      "  b e!     i ba ",
      "    jiiiiiij    ",
      "                ",
      "                ",
      "                ",
      "                "
    ],
    [
      "                ",
      "  a a a a a a   ",
      "  bbbbbbbbbbbba ",
      " ab          b  ",
      "  b eeeee  e ba ",
      " ab e      e b  ",
      "  b k        ba ",
      " ab k        b  ",
      "    k           ",
      "    k           ",
      "    e           ",
      "    j      j    ",
      "                ",
      "                ",
      "                ",
      "                "
    ],
    [
      "                ",
      "  a a a a a a   ",
      "  bbbbbbbbbbbba ",
      " ab          b  ",
      "  b eeeee  e ba ",
      "    e      e    ",
      "    e           ",
      "    e           ",
      "    e           ",
      "    e           ",
      "    e           ",
      "    j      j    ",
      "                ",
      "                ",
      "                ",
      "                "
    ],
    [
      "                ",
      "                ",
      "                ",
      "                ",
      "    eeeeelle    ",
      "    e      e    ",
      "    e           ",
      "    e           ",
      "    e           ",
      "    e           ",
      "    e           ",
      "    j      j    ",
      "                ",
      "                ",
      "                ",
      "                "
    ],
    [
      "                ",
      "                ",
      "                ",
      "                ",
      "    hhhhhhhh    ",
      "    hhhhhhhh    ",
      "    hcccccch    ",
      "    hcccccch    ",
      "    hcccccch    ",
      "    hcccccch    ",
      "    hcccccch    ",
      "    hhhhhhhh    ",
      "                ",
      "                ",
      "                ",
      "                "
    ]
  ]
}