{
  "name": "building_office1_floor1_90",
  "refpalette": "c70cities:building_office1_floor1_palette_90",
  "xsize": 16,
  "zsize": 16,
  "slices": [
    [
      "                ",
      "        c  eeee ",
      "  aaaaaacddfbbe ",
      "  abbbbbbbbbbbe ",
      "  abbbbbbbbbbbe ",
      "  abbbbbbbbb!be ",
      "  abbbbbbbbbbbe ",
      "  abbbbbbbbbbbe ",
      "  abbbbbbbbbbbe ",
      "  abbbbbbbbbbbe ",
      "  abbbbbbbbbbbe ",
      "  abbbbbbbbbbbe ",
      "  abbbbbbbbgbbe ",
      "  aaaaaacddfbbe ",
      "        c  eeee ",
      "                "
    ],
    [
      "                ",
      "        c  ssss ",
      "  hhhhhhcddfyCs ",
      "  h    nf     s ",
      "  h  l  f     s ",
      "  h   m f  ix s ",
      "  h ik  f   xBs ",
      "  h   m f  ix s ",
      "  h i   ffrfffs ",
      "  h  km fq twAs ",
      "  h i   p     s ",
      "  h  j  o     s ",
      "  h     f  g  s ",
      "  hhhhhhcddfuus ",
      "        c  ssss ",
      "                "
    ],
    [
      "                ",
      "        c  ssss ",
      "  hhhhhhcddfN s ",
      "  h    Ef     O ",
      "  h     f     d ",
      "  h  D  f   M d ",
      "  h  D  f   L d ",
      "  h  D  f   K d ",
      "  h  D  ffJfffd ",
      "  h  D  fq    d ",
      "  h  D  I     d ",
      "  h     F     d ",
      "  h     f  g  O ",
      "  hhhhhhcddfuus ",
      "        c  ssss ",
      "                "
    ],
    [
      "                ",
      "        c  ssss ",
      "  hhhhhhcddf  s ",
      "  h     f     O ",
      "  h     f     d ",
      "  h     f     d ",
      "  h     f     d ",
      "  h     f     d ",
      "  h     ffffffd ",
      "  h     f     d ",
      "  h     f     d ",
      "  h     f     d ",
      "  h     f  g  O ",
      "  hhhhhhcddfuus ",
      "        c  ssss ",
      "                "
    ],
    [
      "                ",
      "        c  ssss ",
      "  hhhhhhcddf  s ",
      "  h     f     s ",
      "  h     f     s ",
      "  h     f     s ",
      "  h     f     s ",
      "  h     f     s ",
      "  h     ffffffs ",
      "  h     f     s ",
      "  h     f     s ",
      "  h     f     s ",
      "  h     f  g  s ",
      "  hhhhhhcddfPPs ",
      "        c  ssss ",
      "                "
    ],
    [
      "                ",
      "        c  ssss ",
      "  hhhhhhcddfOOs ",
      "  hOOOOOf   OOs ",
      "  hOOOOOfOOOOOs ",
      "  hOOOOOfOOOOOs ",
      "  hOOOOOfOOOOOs ",
      "  hOOOOOfOOOOOs ",
      "  hOOOOOffffffs ",
      "  hOOOOOfOOOOOs ",
      "  hOOOOOfOOOOOs ",
      "  hOOOOOfOOOOOs ",
      "  hOOOOOf  gOOs ",
      "  hhhhhhcddfOOs ",
      "        c  ssss ",
      "                "
    ]
  ]
}