{
  "name": "building_hotel3_floor2_270",
  "refpalette": "c70cities:building_hotel3_floor2_palette_270",
  "xsize": 16,
  "zsize": 16,
  "slices": [
    [
      "                ",
      "  a a a a a a   ",
      "  bbbbbbbbbbbba ",
      " abccccccccccb  ",
      "  bceeeeeeeecba ",
      " abceffffffecb  ",
      "  bceffffffecba ",
      " abcefff!ffedb  ",
      "  bceffffffedba ",
      " abceffffffecb  ",
      "  bceffffffecba ",
      " abceeeeeeeecb  ",
      "  bccccccccccba ",
      " abbbbbbbbbbbb  ",
      "   a a a a a a  ",
      "                "
    ],
    [
      "                ",
      "  a a a a a a   ",
      "  bbbbbbbbbbbba ",
      " ab          b  ",
      "  b qeeeeeee ba ",
      " ab l n   he b  ",
      "  b lp    he ba ",
      " ab l    iiedb  ",
      "  b l omi jedba ",
      " ab l omikie b  ",
      "  b l      g ba ",
      " ab qlllllee b  ",
      "  b          ba ",
      " abbbbbbbbbbbb  ",
      "   a a a a a a  ",
      "                "
    ],
    [
      "                ",
      "  a a a a a a   ",
      "  bbbbbbbbbbbba ",
      " ab          b  ",
      "  b qessssee ba ",
      " ab  u     e b  ",
      "  b  u     e ba ",
      " ab      iiedb  ",
      "  b     i  edba ",
      " ab     itie b  ",
      "  b        r ba ",
      " ab q     ee b  ",
      "  b          ba ",
      " abbbbbbbbbbbb  ",
      "   a a a a a a  ",
      "                "
    ],
    [
      "                ",
      "  a a a a a a   ",
      "  bbbbbbbbbbbba ",
      " ab          b  ",
      "  b qeeeeeee ba ",
      " ab       ue b  ",
      "  b       ue ba ",
      " ab      iiedb  ",
      "  b     i  edba ",
      " ab     iiie b  ",
      "  b        e ba ",
      " ab q     ee b  ",
      "  b          ba ",
      " abbbbbbbbbbbb  ",
      "   a a a a a a  ",
      "                "
    ],
    [
      "                ",
      "  a a a a a a   ",
      "  bbbbbbbbbbbba ",
      " ab          b  ",
      "  b qeeeeeee ba ",
      " ab     i  e b  ",
      "  b     i  e ba ",
      " ab     iiiedb  ",
      "  b     i  edba ",
      " ab     iiie b  ",
      "  b        e ba ",
      " ab q     ee b  ",
      "  b          ba ",
      " abbbbbbbbbbbb  ",
      "   a a a a a a  ",
      "                "
    ],
    [
      "                ",
      "  a a a a a a   ",
      "  bbbbbbbbbbbba ",
      " ab          b  ",
      "  b eeeeeeee ba ",
      " ab ewwwwwwe b  ",
      "  b ewwwwwwe ba ",
      " ab ewwwwwwedb  ",
      "  b ewwwwwwedba ",
      " ab ewwwwwwe b  ",
      "  b ewwwwwwe ba ",
      " ab eeeeeeee b  ",
      "  b          ba ",
      " abbbbbbbbbbbb  ",
      "   a a a a a a  ",
      "                "
    ]
  ]
}