{
  "name": "building_bunker1_base1_90",
  "refpalette": "c70cities:building_bunker1_base1_palette_90",
  "xsize": 16,
  "zsize": 16,
  "slices": [
    [
      "================",
      "================",
      "==aaaa==========",
      "==aaaa==========",
      "==aaaa==========",
      "==aaaa==========",
      "==aaaa====aaaaa=",
      "==aaaa====aaaaa=",
      "===========a=a==",
      "==========aa=aa=",
      "==========aa=aa=",
      "==========aa=aa=",
      "================",
      "================",
      "================",
      "================"
    ],
    [
      "zzzzzzzzzzzzzzzz",
      "zbbbbbbbbbbbbbbb",
      "zbiknquyDIMIbSXb",
      "zbh  r y   Qb Wb",
      "zbg  q     Pb Vb",
      "zbe     CbbbbRbb",
      "zbf      F    Ub",
      "zbe  pt nbn   Ub",
      "zbbbmbbxbEbObObb",
      "zbd  b   bL b Tb",
      "zbd  bs  bK b Kb",
      "zbd  bswobJNbNJb",
      "zbb  bbbbbbbbbbb",
      "zbc     Bbzzzzzz",
      "zbcjlo sAbzzzzzz",
      "zbbbbbbbbbzzzzzz"
    ],
    [
      "zzzzzzzzzzzzzzzz",
      "zZ44EEEEEEEEE{{E",
      "zY  69   ^ +E :E",
      "zY   8     )E]`E",
      "zY         (E]|E",
      "zE3      EEEE[EE",
      "zE2      %     ;",
      "zEL  7  6E6   TE",
      "zEEE5EE#EEE*E*EE",
      "zE   E   EL E TE",
      "zE   E   E1 E \\E",
      "zE   Esw E0&E-}E",
      "zEE  EEEEEEEEEEE",
      "zE1     $Ezzzzzz",
      "zE0 o  @AEzzzzzz",
      "zEEEEEEEEEzzzzzz"
    ],
    [
      "zzzzzzzzzzzzzzzz",
      "zEEEEEEEEEEEEEEE",
      "zE. 6    //\u00a4E \u00c2E",
      "zE.        \u00a3E\u00a7\u00c1E",
      "zE.        ?E\u00a5 E",
      "zE.      EEEEEEE",
      "zE.      E    \u00c0E",
      "zE.     6E6   \u00c0E",
      "zEEEEEE{EEEEEEEE",
      "zE,  E   E >E> E",
      "zE,  E   E< E  E",
      "zE,  E w Ef E fE",
      "zEE  EEEEEEEEEEE",
      "zE'     !Ezzzzzz",
      "zE      AEzzzzzz",
      "zEEEEEEEEEzzzzzz"
    ],
    [
      "zzzzzzzzzzzzzzzz",
      "zEEEEEEEEEEEEEEE",
      "zE\u00c5\u00c3\u00c3\u00c3\u00c3\u00c3\u00c3EEEE\u00c5\u00c5E",
      "zE\u00c5\u00c3\u00c3\u00c3\u00c3\u00c3\u00c3\u00c5\u00c5\u00c5E\u00c3\u00c3E",
      "zE\u00c5\u00c3\u00c3\u00c3\u00c3\u00c3\u00c3EEEE\u00c3\u00c3E",
      "zE\u00c5\u00c3\u00c3\u00c3\u00c3\u00c3\u00c3EEEEEEE",
      "zE\u00c5\u00c3\u00c3\u00c3\u00c3\u00c3\u00c3E\u00c3\u00c3\u00c3\u00c3\u00c5E",
      "zE\u00c5\u00c3\u00c3\u00c3\u00c3\u00c3\u00c3E\u00c3\u00c3\u00c3\u00c3\u00c5E",
      "zEEEEEEEEEEEEEEE",
      "zE\u00c4\u00c3\u00c3EEEEE\u00c3\u00c3E\u00c3\u00c3E",
      "zE\u00c4\u00c3\u00c3EEEEE\u00c3\u00c3E\u00c3\u00c3E",
      "zE\u00c4\u00c3\u00c3EEwEE\u00c5\u00c6E\u00c6\u00c5E",
      "zEE\u00c6\u00c5EEEEEEEEEEE",
      "zE\u00c3\u00c3\u00c3\u00c5\u00c3\u00c3\u00c3Ezzzzzz",
      "zE\u00c3\u00c3\u00c3\u00c5\u00c3\u00c3AEzzzzzz",
      "zEEEEEEEEEzzzzzz"
    ],
    [
      "zzzzzzzzzzzzzzzz",
      "zzzzzzzzzzzzzzzz",
      "zzzzzzzzzzzzzzzz",
      "zzzzzzzzzzzzzzzz",
      "zzzzzzzzzzzzzzzz",
      "zzzzzzzzzzzzzzzz",
      "zzzzzzzzzzzzzzzz",
      "zzzzzzzzzzzzzzzz",
      "zzzzzzzzzzzzzzzz",
      "zzzzzzzzzzzzzzzz",
      "zzzzzzzEzzzzzzzz",
      "zzzzzzEwEzzzzzzz",
      "zzzzzzzEzzzzzzzz",
      "zzzzzzzzzzzzzzzz",
      "zzzzzzzzzzzzzzzz",
      "zzzzzzzzzzzzzzzz"
    ]
  ]
}