{
  "name": "building_hotel1_floor2_180",
  "refpalette": "c70cities:building_hotel1_floor2_palette_180",
  "xsize": 16,
  "zsize": 16,
  "slices": [
    [
      "                ",
      " aagggggaaaaaaa ",
      " abbbbbbbbbbbba ",
      " fbbbbcbbbbbbbd ",
      " fbbbbcbbbbbbbd ",
      " fbbbbcccccbbbd ",
      " fbbbbe   cbbbd ",
      " abbbb    cbbbd ",
      " abbbb    cbbbd ",
      " abbbd    cbbbd ",
      " acccccccccbbba ",
      " abbbbbbbbbbbba ",
      " abbbbbbbbbbbba ",
      " abbbbbbbbbbbba ",
      " aaaaaaaaaaaaaa ",
      "                "
    ],
    [
      "                ",
      " aaaaaaaaaaaaaa ",
      " aneeeaF      a ",
      " f EEeaDCf BB a ",
      " f    aAyf xx a ",
      " f    aaaasaa a ",
      " f    dee a=  a ",
      " an  w    au  a ",
      " a   w    au  a ",
      " a        a=  a ",
      " aatasaaaasr  a ",
      " a   opqqpo   a ",
      " a          nma ",
      " a l  kjji  h a ",
      " aaaaaaaaaaaaaa ",
      "                "
    ],
    [
      "                ",
      " aaaaaaffffffaa ",
      " aM   a       a ",
      " f    a  f    a ",
      " f    a  f    a ",
      " f    aaaasaa a ",
      " f      deaN  f ",
      " aM      ea   f ",
      " a        a   f ",
      " a        aL  f ",
      " aaKasaaaas   a ",
      " a   o J  o   a ",
      " a          I a ",
      " a            a ",
      " aaaaaaaaaaaaaa ",
      "                "
    ],
    [
      "                ",
      " aaaaaaaaaaaaaa ",
      " aM   a       a ",
      " f    a  f    a ",
      " f    a  fO   a ",
      " f    aaaasaaaa ",
      " f        a   a ",
      " aM      daE  a ",
      " a       eaE  a ",
      " a       ea   a ",
      " aaaasaaaas   a ",
      " a            a ",
      " a            a ",
      " a   O    O   a ",
      " aaaaaaaaaaaaaa ",
      "                "
    ],
    [
      "                ",
      " aaaaaaffaaaaaa ",
      " a    a  f    a ",
      " f    a  f    a ",
      " f    a  fP   a ",
      " f    aaaasaaaa ",
      " f        a   a ",
      " a        a   a ",
      " a        a   a ",
      " a     eeda   a ",
      " aaaasaaaas   a ",
      " a            f ",
      " a            f ",
      " a   P    P   a ",
      " aaaaaaaaaaaaaa ",
      "                "
    ],
    [
      "                ",
      " aaaaaaaaaaaaaa ",
      " aQQQQaQQQQQQQa ",
      " fQQQQaQQQQQQQa ",
      " fQQQQaQQQQQQQa ",
      " fQQQQaaaasQQQa ",
      " fQQQQ    aQQQa ",
      " aQQQQ    aQQQa ",
      " aQQQQ    aQQQa ",
      " aQQQQed  aQQQa ",
      " aaaasaaaasQQQa ",
      " aQQQQQQQQQQQQa ",
      " aQQQQQQQQQQQQa ",
      " aQQQQQQQQQQQQa ",
      " aaaaaaaaaaaaaa ",
      "                "
    ]
  ]
}