{
  "name": "building_carservice1_base1_270",
  "refpalette": "c70cities:building_carservice1_base1_palette_270",
  "xsize": 16,
  "zsize": 16,
  "slices": [
    [
      "vvvvvvvvvvvvvvvv",
      "vaaaaaaaaaaaaaav",
      "va====aaaaaaaaav",
      "va====aaaaaaaaav",
      "vaaaaaaaaaaaaaav",
      "vaaaaaaaaaaaaaav",
      "vaaaaaaaaaaaaaav",
      "vaaaaaaaaaaaaaav",
      "vaaaaaaaaaaaaaav",
      "vaaaaa!aaaaaaaav",
      "vaaaaaaaaaaaaaav",
      "vaaaaaaaaaaaaaav",
      "vaaaaaaaaaaaaaav",
      "vaaaaaaaaaaaaaav",
      "vaaaaaaaaaaaaaav",
      "vvvvvvvvvvvvvvvv"
    ],
    [
      "vvvvvvvvvvvvvvvv",
      "vvvvvvvvvvvvvvvv",
      "vvp   j=====vvvv",
      "vv    j=====vvvv",
      "vbbnnnbbbb==vvvv",
      "vb       bddvvvv",
      "vbq        dvvvv",
      "vbq   k     vvvv",
      "vb    ki bd!vvvv",
      "vuoo  bhhbbbbbbv",
      "vbr     e  e  bv",
      "vbs   lcfccfc bv",
      "vbs   mcccgcc bv",
      "vbt   lcfccfc bv",
      "vbbbbbbbbbbbbbbv",
      "vvvvvvvvvvvvvvvv"
    ],
    [
      "vvvvvvvvvvvvvvvv",
      "vvvvvvvvvvvvvvvv",
      "vvp     j===vvvv",
      "vv      j===vvvv",
      "vbbnnnbbbb==vvvv",
      "vb       b  vvvv",
      "vb          vvvv",
      "vb          vvvv",
      "vb       b dvvvv",
      "vuoo  bhhbbbbbbv",
      "vb            bv",
      "vb     BBAAxw bv",
      "vb     DCA yw bv",
      "vb     BBAAxw bv",
      "vbbbbbbbbbbbbbbv",
      "vvvvvvvvvvvvvvvv"
    ],
    [
      "vvvvvvvvvvvvvvvv",
      "vvvvvvvvvvvvvvvv",
      "vvp       jjvvvv",
      "vvp       jjvvvv",
      "vbbnnnbbbb==vvvv",
      "vb       b  vvvv",
      "vb       b  vvvv",
      "vb       b  vvvv",
      "vb       b  vvvv",
      "vuoo  bhhbbbbbbv",
      "vb            bv",
      "vb       BB   bv",
      "vb       DCD  bv",
      "vb       BB   bv",
      "vbbbbbbbbbbbbbbv",
      "vvvvvvvvvvvvvvvv"
    ],
    [
      "vvvvvvvvvvvvvvvv",
      "vvvvvvvvvvvvvvvv",
      "vvp         vvvv",
      "vvp         vvvv",
      "vbbbbbbbbb  vvvv",
      "vb       bjjvvvv",
      "vb       b==vvvv",
      "vb       b==vvvv",
      "vb       b==vvvv",
      "vbbbbbbbbbbbbbbv",
      "vb            bv",
      "vb            bv",
      "vb            bv",
      "vb            bv",
      "vbbbbbbbbbbbbbbv",
      "vvvvvvvvvvvvvvvv"
    ],
    [
      "vvvvvvvvvvvvvvvv",
      "vvvvvvvvvvvvvvvv",
      "vvIIIIIII   vvvv",
      "vvIIIIIII   vvvv",
      "vbbbbbbbbb  vvvv",
      "vbFFFFFFFb  vvvv",
      "vbFFFFFFFb  vvvv",
      "vbFFFFFFFbjjvvvv",
      "vbFFFFFFFb==vvvv",
      "vbbbbbbbbbbbbbbv",
      "vb FFFFFEFFFFEbv",
      "vbFFFFFFFFFFFFbv",
      "vbFFFFFFFFFFFFbv",
      "vbEFFFFFJFFFF bv",
      "vbbbbbbbbbbbbbbv",
      "vvvvvvvvvvvvvvvv"
    ]
  ]
}