{
  "name": "building_gasstation1_ground_270",
  "refpalette": "c70cities:building_gasstation1_ground_palette_270",
  "xsize": 16,
  "zsize": 16,
  "slices": [
    [
      "GHHHHHHHHHHHHHaG",
      "GHHHHHHHHHHHHHHG",
      "GHHHHHHHHHHHHHHG",
      "GHHHHHHHHHHHHHHG",
      "GHHaaaaaaaaaaHHG",
      "GHHHHHHHHHHHHHHG",
      "GHHHHHHHHHHHHHHG",
      "GHHaaaaaaaaaaHHG",
      "GHHaaaaaaaaaaHHG",
      "GHHaaaaaaaaaaHHG",
      "GbbaaaaaaaaaabbG",
      "GGGaaaaaaaaaaGGG",
      "GGGaaaaaaaaaaGGG",
      "GGGaaaaaaaaaaGGG",
      "GGGGGGGGGGGGGGGG",
      "GGGGGGGGGGGGGGGG"
    ],
    [
      "              c ",
      "                ",
      "   s ks ks k    ",
      "   t lt lt l    ",
      "   i miywi mi   ",
      "                ",
      "                ",
      " gdjCCjqxuqjjgd ",
      "   jE A    nj   ",
      " hej       njhe ",
      " ffjjjj  o ojff ",
      "   jFDj  or!j   ",
      "   jI B  orpj   ",
      "   jjjjjjjjjj   ",
      "                ",
      "                "
    ],
    [
      "              c ",
      "                ",
      "                ",
      "                ",
      "   i Ji  i Ji   ",
      "                ",
      "                ",
      "   jPPjqMLqjj   ",
      "   j  N     j   ",
      "   j        j   ",
      "   jjjj  o pj   ",
      "   j  j  r Kj   ",
      "   j  O  o oj   ",
      "   jjjjjjjjjj   ",
      "                ",
      "                "
    ],
    [
      "              Q ",
      "                ",
      "                ",
      "                ",
      "   i  i  i  i   ",
      "                ",
      "                ",
      "   RRRRRRRRRR   ",
      "   R       SR   ",
      "   R       TR   ",
      "   Rjjj     R   ",
      "   R  j    rR   ",
      "   R  j     R   ",
      "   RUURUURUUR   ",
      "                ",
      "                "
    ],
    [
      "                ",
      "                ",
      "                ",
      "                ",
      "   j  j  j  j   ",
      "   V  X  V  V   ",
      "                ",
      "   jjjjjjjjjj   ",
      "   j       rj   ",
      "   j  V  X Wj   ",
      "   jjjjjjjjjj   ",
      "   jYYj     j   ",
      "   jYYj    rj   ",
      "   jjjjjjjjjj   ",
      "                ",
      "                "
    ],
    [
      "                ",
      "  ZZZZZZZZZZZZ  ",
      "  ZffffffffffZ  ",
      "  ZffffffffffZ  ",
      "  ZaaaaaaaaaaZ  ",
      "  ZaffffffffaZ  ",
      "  ZaffffffffaZ  ",
      "  ZaaaaaaaaaaZ  ",
      "  ZaffffffffaZ  ",
      "  ZaffffffffaZ  ",
      "  ZaaaaaaaaaaZ  ",
      "  ZaffffffffaZ  ",
      "  ZaffffffffaZ  ",
      "  ZaaaaaaaaaaZ  ",
      "  ZZZZZZZZZZZZ  ",
      "                "
    ]
  ]
}