{
  "name": "building_warehouse2_ground",
  "refpalette": "c70cities:building_warehouse2_ground_palette",
  "xsize": 16,
  "zsize": 16,
  "slices": [
    [
      "zazazzzzzzzzzzzz",
      "zaazbbbbbbbbbbbz",
      "zaaabbccccccccbz",
      "azaadbccccccccbz",
      "aaaadbccccccccbz",
      "zaaabbccccccccbz",
      "zzaabbccccccccbz",
      "zzaadbccccccccbz",
      "zaaabbccccccccbz",
      "zaaadbbbbbbbbbbz",
      "azaadbbbbbbbbdbz",
      "zaaabbbbbbbbbbdz",
      "zaaabbbbbbbbbbbz",
      "zaaabbbbbbbbbbbz",
      "zazadbbbdbbbddbz",
      "aazzzzzzzzzzzzzz"
    ],
    [
      "    e e e  e  e ",
      "     fggggggfgge",
      "     h   ijkkkf ",
      " e   h l lkikmf ",
      "     h     nkkg ",
      "e    f  o iiiif ",
      "           ijige",
      "      o   p njg ",
      "e            qfe",
      "     ggg    gff ",
      " e    r     r   ",
      "e     r     r  e",
      "     ggst   fg u",
      "e    fggfwxggf  ",
      "               e",
      "  e u  e  eee u "
    ],
    [
      "                ",
      "     ggfgrrfgfg ",
      "     h   n jkmg ",
      "     h      ikg ",
      "     h      jig ",
      "     g    liiig ",
      "     h       nf ",
      "     h        g ",
      "     h       qg ",
      "     fgg    ggf ",
      "      r     r   ",
      "      r     r   ",
      "     gf y   gf  ",
      "     gffgABggg  ",
      "                ",
      "                "
    ],
    [
      "                ",
      "     fgggggggff ",
      "     h      j!g ",
      "     h        f ",
      "     h       ig ",
      "     gj     l g ",
      "     h        f ",
      "     h        g ",
      "     h       qg ",
      "     gfgCCCCfgg ",
      "      r     r   ",
      "      r     r   ",
      "     gg D   gf  ",
      "     ggfgEEfgg  ",
      "                ",
      "                "
    ],
    [
      "                ",
      "     gggfggggfg ",
      "    FgI      jg ",
      "    FgI       g ",
      "    FgI       f ",
      "    Fgj J     g ",
      "    FgI       g ",
      "    FfI       g ",
      "    FgI EEEE qg ",
      "    Ffgfggggggg ",
      "    FKI     IFF ",
      "    FKI     IFF ",
      "    Fgg J  JggF ",
      "    FgggggggggF ",
      "    FFFFFFFFFFF ",
      "                "
    ],
    [
      "                ",
      "     gggggfgggg ",
      "     fLLLLLLLLg ",
      "     gLLLLLLLLg ",
      "     gLLLLLLLLg ",
      "     gLLbLLLLLg ",
      "     fLLLLLLLLg ",
      "     gLLLLLLLLg ",
      "     gLLLLLLLqf ",
      "     fggggggggg ",
      "     MMMMMMMMM  ",
      "     MMMMMMMMM  ",
      "     MMMMMMMMM  ",
      "     MMMMMMMMM  ",
      "                ",
      "                "
    ]
  ]
}