{
  "name": "building_carfactory1_floor1",
  "refpalette": "c70cities:building_carfactory1_floor1_palette",
  "xsize": 16,
  "zsize": 16,
  "slices": [
    [
      "                ",
      "                ",
      "                ",
      " abbbbbbbbbbbba ",
      " cdddddddddddde ",
      " cdf       f de ",
      " cdgghigghhggde ",
      " cd          de ",
      " cd          de ",
      " cd          de ",
      " cd          de ",
      " cdgghhggjhggde ",
      " cdf         de ",
      " cdddddddddddde ",
      " akllkkkkkkkkka ",
      "                "
    ],
    [
      "                ",
      "                ",
      " mmmmmmmmmmmmmm ",
      " mmmmmmmmmmmmmm ",
      " noppppppppppon ",
      " noqqrrqqrrqqon ",
      "  oqqssqqssqqo  ",
      "  oqq  qq  qqo  ",
      "  o          o  ",
      "  of         o  ",
      "  of         o  ",
      "  o  tt  tt! o  ",
      "  o         fo  ",
      "  oooooooooooo  ",
      " a ll         a ",
      "                "
    ],
    [
      "                ",
      "                ",
      "                ",
      "                ",
      "                ",
      "                ",
      " mm  uu  uu  mm ",
      " mm  uu  uu  mm ",
      " noqqrrqqrrqqon ",
      " noqqrrqqrrqqon ",
      "  oqq  qq  qqo  ",
      "  o  tt  tt  o  ",
      "  o    ff   fo  ",
      "  oooooooooooo  ",
      " a ll         a ",
      "                "
    ],
    [
      "                ",
      "                ",
      "                ",
      "                ",
      "                ",
      "                ",
      "                ",
      "                ",
      "                ",
      "        ~       ",
      " mm  uu  uu  mm ",
      " mmuuuuuuuuuumm ",
      " norrrrrrrrrron ",
      " noppppppppppon ",
      " akllkkkkkkkkka ",
      "                "
    ],
    [
      "                ",
      "                ",
      "                ",
      "                ",
      "                ",
      "                ",
      "                ",
      "                ",
      "                ",
      "        ~       ",
      "                ",
      "                ",
      "   ll           ",
      "   ll           ",
      " mmllmmmmmmmmmm ",
      " mmmmmmmmmmmmmm "
    ],
    [
      "                ",
      "                ",
      "                ",
      "                ",
      "                ",
      "                ",
      "                ",
      "                ",
      "                ",
      "        ~       ",
      "                ",
      "                ",
      "                ",
      "   wx           ",
      "   ly           ",
      "                "
    ]
  ]
}