{
  "name": "building_residential3_ground_180",
  "refpalette": "c70cities:building_residential3_ground_palette_180",
  "xsize": 16,
  "zsize": 16,
  "slices": [
    [
      "GGGGGGGGGGGGGGGG",
      "GGGGGGGGGGGGGGGG",
      "GGaaaaaaGGGGGGGG",
      "GGabbbbacccccGGG",
      "GGabbbbbddddcGGG",
      "GGabbbbbddddcGGG",
      "GGabbbbbddddcGGG",
      "GGabbbbbddddcGGG",
      "GGabbbbbbbbbaaGG",
      "GGabbbbbbbbbbaGG",
      "GGabbbbbbbbbbaGG",
      "GGabbbbbbbbbbaGG",
      "GGabbbbbbbbbbaGG",
      "GGaaaaaaaaaaaaGG",
      "GGGGGGGGGGGGGGGG",
      "GGGGGGGGGGGGGGGG"
    ],
    [
      "effffgffffgffffe",
      "f              f",
      "f hjKKjhAAAAAA f",
      "f h    hcccccA f",
      "f hJ  BhIFEDcA f",
      "e hC  Bh    cA g",
      "f h    h    cA f",
      "f hx   w   yc  f",
      "f hx   w utthh f",
      "f h       ss j e",
      "g hqrq       p  ",
      "f ho l       n  ",
      "f hm l!  k   j i",
      "f hhhhhhhhhhhh e",
      "f              f",
      "effffgffffgffffe"
    ],
    [
      "effffgffffgffffe",
      "f              f",
      "f hjKKjh       f",
      "f h    hcSScc  f",
      "f K   ThV  Uc  f",
      "e K   Th    S  g",
      "f K    h    S  f",
      "f hR   w    c  f",
      "f hQ   w    hh f",
      "f K          j e",
      "g hqPq       O  ",
      "f L  lN      M  ",
      "f h  l  k    j  ",
      "f hhLhKhhKKKhh e",
      "f              f",
      "effffgffffgffffe"
    ],
    [
      "                ",
      "                ",
      "  hj11jh000000  ",
      "  h    hccccc0  ",
      "  Z    h    c0  ",
      "W Z    h    c0  ",
      "  Z    h    c0  ",
      "  h    w    c0  ",
      "  h    w    hh  ",
      "  Z          j  ",
      "  hqqq       Y  ",
      "  Z  l       Y  ",
      "  h  l k     j  ",
      "  hhXhXhhXXXhh W",
      "                ",
      "                "
    ],
    [
      "                ",
      "                ",
      "  hhhhhh222222  ",
      "  hbbbbh555542  ",
      "  hbbbbb    32  ",
      "  hbbbbb    32  ",
      "  hbbbbb    32  ",
      "  hbbbbb    32  ",
      "  hbbbbbbbbbhh  ",
      "  hbbbbbbbbbbh  ",
      "  hbbbbbbbbbbh  ",
      "  hbbbbbbbbbbh  ",
      "  hbbbk   bbbh  ",
      "  hhhhhhhhhhhh  ",
      "                ",
      "                "
    ],
    [
      "                ",
      "                ",
      "  hKKKKh222222  ",
      "  h )) hccccc2  ",
      "  Z-+) %    c2  ",
      "  Z-+) %    c2  ",
      "  Z#)) %    c2  ",
      "  hjjj %(   c2  ",
      "  h*&^ %%%%%hh  ",
      "  K $     #@@K  ",
      "  K          K  ",
      "  K   9999   K  ",
      "  K8      766K  ",
      "  hhXXXhhXXXhh  ",
      "                ",
      "                "
    ]
  ]
}