{
  "name": "building_hotel1_floor1_270",
  "refpalette": "c70cities:building_hotel1_floor1_palette_270",
  "xsize": 16,
  "zsize": 16,
  "slices": [
    [
      "                ",
      " aadddddddaaaaa ",
      " abbbbbbbbcbbba ",
      " abbbbbbbbcbbba ",
      " abbbbbbbbcbbba ",
      " abbbbbbbbcbbba ",
      " abbbb    cbbba ",
      " abbbb    cbbba ",
      " gbbbb    cbbba ",
      " gbbbbe   cbbba ",
      " gbbbbbbbdcbbba ",
      " gbbbbbbbbcbbba ",
      " gbbbbbbbbcbbba ",
      " abbbbbbbbcbbba ",
      " aaffffaaaaaaaa ",
      "                "
    ],
    [
      "                ",
      " aaaaaaaaaaaaaa ",
      " ar   r r aj ha ",
      " au    u  ak  a ",
      " as   s s al  a ",
      " a        am  a ",
      " ar       am  a ",
      " au   e   an  a ",
      " as   e   ao  a ",
      " a    d   ak  a ",
      " ar    tt a   a ",
      " au          ia ",
      " as       qp ia ",
      " au    u  q  ia ",
      " aaffffaaaaaaaa ",
      "                "
    ],
    [
      "                ",
      " aaaaaffffaaaaa ",
      " a        a   a ",
      " fy   yyy a   a ",
      " f        aw  a ",
      " f        a   a ",
      " f    ee  a   a ",
      " fy   d   a   a ",
      " f        ax  a ",
      " a        a   a ",
      " a        a   a ",
      " ay           a ",
      " a            a ",
      " aA    A      a ",
      " aaffffaaaaaaaa ",
      "                "
    ],
    [
      "                ",
      " aaaaaaaaaaaaaa ",
      " a        a   a ",
      " a        a   a ",
      " a        a   a ",
      " a        a   a ",
      " a     deea   a ",
      " a        a   a ",
      " a        a   a ",
      " a        a   a ",
      " a        a   a ",
      " a            a ",
      " a            a ",
      " aA    A      a ",
      " aaffffaaaaaaaa ",
      "                "
    ],
    [
      "                ",
      " aaaaaaaaaaffaa ",
      " a        a   a ",
      " a        a   a ",
      " a        a   a ",
      " a        a   a ",
      " a       da   a ",
      " f       ea   a ",
      " f       ea   a ",
      " a        a   a ",
      " a        a   a ",
      " a        a   a ",
      " a        a   a ",
      " a        a   a ",
      " aaffffaaaaaaaa ",
      "                "
    ],
    [
      "                ",
      " aaaaaaaaaaaaaa ",
      " aBBBBBBBBaBBBa ",
      " aBBBBBBBBaBBBa ",
      " aBBBBBBBBaBBBa ",
      " aBBBBBBBBaBBBa ",
      " aBBBB    aBBBa ",
      " aBBBB    aBBBa ",
      " aBBBB   daBBBa ",
      " aBBBB   eaBBBa ",
      " aBBBBBBBBaBBBa ",
      " aBBBBBBBBaBBBa ",
      " aBBBBBBBBaBBBa ",
      " aBBBBBBBBaBBBa ",
      " aaffffaaaaaaaa ",
      "                "
    ]
  ]
}