{
  "name": "building_office3_ground_180",
  "refpalette": "c70cities:building_office3_ground_palette_180",
  "xsize": 16,
  "zsize": 16,
  "slices": [
    [
      "GGGGGGGGGGGGGGGG",
      "GaaaaaaaaaaaaaaG",
      "GabbbbbbbbbbbbaG",
      "GabbbbbbbbbbbbaG",
      "GabbbbbbbbbbbbaG",
      "GabbbbbbbbbbbbaG",
      "GabbbbbbbbbbbbaG",
      "GabbbbbbbbbbbbaG",
      "GabbbbbbbbbbbbaG",
      "GabbbbbbbbbbbbaG",
      "GabbbbbbbbbbbbaG",
      "GabbbbbbbbbbbbaG",
      "Gabbbbbbbbbb!baG",
      "GabbbbbbbbbbbbaG",
      "GaaaaaaaaaaaaaaG",
      "GGGGGGGGGGGGGGGG"
    ],
    [
      "                ",
      " ccdccdccdccdcc ",
      " ceeeefeefeeeec ",
      " deg        ged ",
      " ce          ec ",
      " ce          ec ",
      " df          fd ",
      " k     iv    ec ",
      " j     ivh   ec ",
      " df          fd ",
      " ce          ec ",
      " ce          ec ",
      " deg        ged ",
      " ceeeefeefeeeec ",
      " ccdccdccdccdcc ",
      "                "
    ],
    [
      "                ",
      " ccdccdccdccdcc ",
      " c    l  l    c ",
      " d g        g d ",
      " c            c ",
      " c            c ",
      " dl          ld ",
      " n     iv     c ",
      " m     iv     c ",
      " dl          ld ",
      " c            c ",
      " c            c ",
      " d g        g d ",
      " c    l  l    c ",
      " ccdccdccdccdcc ",
      "                "
    ],
    [
      "                ",
      " oodoodoodoodoo ",
      " o            o ",
      " d g        g d ",
      " o            o ",
      " o            o ",
      " d            d ",
      " o     iv     o ",
      " o     iv     o ",
      " d            d ",
      " o            o ",
      " o            o ",
      " d g        g d ",
      " o            o ",
      " oodoodoodoodoo ",
      "                "
    ],
    [
      "                ",
      " ccdccdccdccdcc ",
      " cppppppppppppc ",
      " dpg        gpd ",
      " cp          pc ",
      " cp          pc ",
      " dp          pd ",
      " cp    iv    pc ",
      " cp    iv    pc ",
      " dp          pd ",
      " cp          pc ",
      " cp          pc ",
      " dpg        gpd ",
      " cppppppppppppc ",
      " ccdccdccdccdcc ",
      "                "
    ],
    [
      "                ",
      " qqqqqqqqqqqqqq ",
      " qaaaaaaaaaaaaq ",
      " qarddddddddraq ",
      " qaddddddddddaq ",
      " qaddddddddddaq ",
      " qaddddddddddaq ",
      " qaddddivddddaq ",
      " qaddddivddddaq ",
      " qaddddddddddaq ",
      " qaddddddddddaq ",
      " qaddddddddddaq ",
      " qarddddddddraq ",
      " qaaaaaaaaaaaaq ",
      " qqqqqqqqqqqqqq ",
      "                "
    ]
  ]
}