{
  "name": "building_bank1_base1",
  "refpalette": "c70cities:building_bank1_base1_palette",
  "xsize": 16,
  "zsize": 16,
  "slices": [
    [
      "vvvvvvvvvvvvvvvv",
      "vaabbaaaabbaaaav",
      "vab!bbbbbbbbbbav",
      "vabbbbbbbbbbbbbv",
      "vabbbbbbbbbbbbbv",
      "vbbbbbbbbbbbbbav",
      "vbbbbbbbbbbbbbav",
      "vabbbbbbbbbbbbav",
      "vabbbbbbbbbbbbav",
      "vabbbbbbbbbbbbbv",
      "vabbbbbbbbbbbbbv",
      "vbbbbbbbbbbbbbav",
      "vbbbbbbbbbbbbbav",
      "vabbbbbbbbb!bbav",
      "vaaaabbaaaabbaav",
      "vvvvvvvvvvvvvvvv"
    ],
    [
      "vvvvvvvvvvvvvvvv",
      "vaabbaaaabbaaaav",
      "va ccd eecc  fav",
      "vae  e       cbv",
      "va           cbv",
      "vbc          eav",
      "vbc     e    eav",
      "vag    hih   eav",
      "vad    ihi   eav",
      "vag   ehih   cbv",
      "vae          cbv",
      "vbc          dav",
      "vbcj         gav",
      "va   cceeeeccgav",
      "vaaaabbaaaabbaav",
      "vvvvvvvvvvvvvvvv"
    ],
    [
      "vvvvvvvvvvvvvvvv",
      "vaabbaaaabbaaaav",
      "va cc  k cc   av",
      "va           cbv",
      "va           cbv",
      "vbc           av",
      "vbc          lav",
      "vam    nnn   lav",
      "vad    ooo    av",
      "vam    ooo   cbv",
      "va           cbv",
      "vbc          dav",
      "vbcj         lav",
      "va   ccpgp ccgav",
      "vaaaabbaaaabbaav",
      "vvvvvvvvvvvvvvvv"
    ],
    [
      "vvvvvvvvvvvvvvvv",
      "vaabbaaaabbaaaav",
      "va cc    cc   av",
      "va           cbv",
      "va           cbv",
      "vbc           av",
      "vbc           av",
      "va            av",
      "va      o     av",
      "va           cbv",
      "va           cbv",
      "vbc           av",
      "vbcj          av",
      "va   cc    cc av",
      "vaaaabbaaaabbaav",
      "vvvvvvvvvvvvvvvv"
    ],
    [
      "vvvvvvvvvvvvvvvv",
      "vaabbaaaabbaaaav",
      "va cc    cc   av",
      "va           cbv",
      "va           cbv",
      "vbc           av",
      "vbc           av",
      "va            av",
      "va            av",
      "va           cbv",
      "va           cbv",
      "vbc           av",
      "vbcj          av",
      "va   cc    cc av",
      "vaaaabbaaaabbaav",
      "vvvvvvvvvvvvvvvv"
    ],
    [
      "vvvvvvvvvvvvvvvv",
      "vaabbaaaabbaaaav",
      "vafccqqqqccqqrav",
      "vaqqqqqqqqqqqcbv",
      "vaqqqqqqqqqqqcbv",
      "vbcqqqqqqqqqqqav",
      "vbcqqqqqqqqqqqav",
      "vaqqqqqqqqqqqqav",
      "vaqqqqqqqqqqqqav",
      "vaqqqqqqqqqqqcbv",
      "vaqqqqqqqqqqqcbv",
      "vbcqqqqqqqqqqqav",
      "vbcjqqqqqqqqqqav",
      "vasqqccqqqqccfav",
      "vaaaabbaaaabbaav",
      "vvvvvvvvvvvvvvvv"
    ]
  ]
}