{
  "name": "building_hotel2_base1",
  "refpalette": "c70cities:building_hotel2_base1_palette",
  "xsize": 16,
  "zsize": 16,
  "slices": [
    [
      "vvvvvvvvvvvvvvvv",
      "vaaaaaaaaaaaaaav",
      "vabbbbbbbbbbbbav",
      "vabbbbbbbbbbbbav",
      "vabbbbbbbbbbbbav",
      "vabbbbbbbbbbbbav",
      "vabbbbbbbbbbbbav",
      "vabbbbbbbbbbbbav",
      "vabbbbbbbbbbbbav",
      "vabbbbbbbbbbbbav",
      "vabbbbbbbbbbbbav",
      "vabbbbbbbbbbbbav",
      "vabbbbbbbbbbbbav",
      "va!bbbbb!bbbb!av",
      "vaaaaaaaaaaaaaav",
      "vvvvvvvvvvvvvvvv"
    ],
    [
      "vvvvvvvvvvvvvvvv",
      "vccccccccccccccv",
      "vcd       =bbbcv",
      "vcd      e=bbbcv",
      "v==e      =bbbcv",
      "vf       e=bbbcv",
      "vfg g g   =bbbcv",
      "vfe  e    hhh=cv",
      "vfi i i      jcv",
      "vf       ff  fcv",
      "vfg g g gfk  lcv",
      "vfe  e  efm  lcv",
      "vfi i i ifn  lcv",
      "vf       fm  ocv",
      "vccccccccccccccv",
      "vvvvvvvvvvvvvvvv"
    ],
    [
      "vvvvvvvvvvvvvvvv",
      "vccccccccccccccv",
      "vcd       =oopcv",
      "vcd      qr  pcv",
      "v==s      r  pcv",
      "vf       qr tpcv",
      "vf        r  pcv",
      "vfj jjj      =cv",
      "vf           jcv",
      "vf       ff  fcv",
      "vf       fu   cv",
      "vfj jjj jf    cv",
      "vf       fw   cv",
      "vf       fx   cv",
      "vccccccccccccccv",
      "vvvvvvvvvvvvvvvv"
    ],
    [
      "vvvvvvvvvvvvvvvv",
      "vccccccccccccccv",
      "vcd       y  tcv",
      "vcd          tcv",
      "v==s          cv",
      "vf           tcv",
      "vf           tcv",
      "vf           =cv",
      "vf           jcv",
      "vf       ff  fcv",
      "vf       f   Acv",
      "vf       f   Bcv",
      "vf       f   Acv",
      "vf       f    cv",
      "vccccccccccccccv",
      "vvvvvvvvvvvvvvvv"
    ],
    [
      "vvvvvvvvvvvvvvvv",
      "vccccccccccccccv",
      "vcd          tcv",
      "vcd          tcv",
      "v==          tcv",
      "vf            cv",
      "vf           tcv",
      "vf           =cv",
      "vf           jcv",
      "vf       fffffcv",
      "vf       f    cv",
      "vf       f   Bcv",
      "vf       f    cv",
      "vf       f    cv",
      "vccccccccccccccv",
      "vvvvvvvvvvvvvvvv"
    ],
    [
      "vvvvvvvvvvvvvvvv",
      "vccccccccccccccv",
      "vcdCCCCCCCCCCDcv",
      "vcdCCCCCCCCCCEcv",
      "v==CCCCCCCCCCDcv",
      "vCCCCCCCCCCCCDcv",
      "vCCCCCCCCCCCCEcv",
      "vCCCCCCCCCCCC=cv",
      "vCCCCCCCCCCCCCcv",
      "vCCCCCCCCfffffcv",
      "vCCCCCCCCfCCCCcv",
      "vCCCCCCCCfCCCCcv",
      "vCCCCCCCCfCCCCcv",
      "vCCCCCCCCfCCCCcv",
      "vccccccccccccccv",
      "vvvvvvvvvvvvvvvv"
    ]
  ]
}