{
  "name": "building_factory1_ground_180",
  "refpalette": "c70cities:building_factory1_ground_palette_180",
  "xsize": 16,
  "zsize": 16,
  "slices": [
    [
      "zzzzzzzzzzzzzaaa",
      "zzzzzzzzzzzzzzaa",
      "zzbbbbbbbbbbbzaa",
      "zzbbbbbbbbbbbaaa",
      "zzbbbbbbbbbbbaaz",
      "zzbbcbbbbbbbbaaz",
      "zzbbbbbbbbbbbaaa",
      "zzbbcbbbbbbbbaaa",
      "zzbbbbbbbbbbbaza",
      "zzbbbbbbbbbbbaaa",
      "zzbbbbbbbbbbbaaa",
      "zzbbbbbbbbbbbaaz",
      "zzbbbbbbbbbbbaaa",
      "zzbbbbbbbbbbbzaa",
      "zzzzzzzzzzzzzaaa",
      "zzzzzzzzzzzzzzaa"
    ],
    [
      " e  ddNd ddO    ",
      "    Nd ddd dd   ",
      " dhhhhhhhhhhh   ",
      "  hiMMLiKJIih   ",
      " dhxFEDxxxxx    ",
      "d hxCu A B      ",
      "  hxwuA   y     ",
      "  hxwur   t     ",
      "  h sr          ",
      " dh q           ",
      "  hoopo         ",
      "  h   k nnn     ",
      "d himlki!jjih   ",
      "  hhhhhhhhhhh   ",
      " d g     d      ",
      "d d d f e  d    "
    ],
    [
      "                ",
      "                ",
      "  hhhhhhhhhhh   ",
      "  hiMM i W ih   ",
      "  hxV US    Q   ",
      "  hx        Q   ",
      "  hx        Q   ",
      "  hx        Q   ",
      "  h T       Q   ",
      "  h S       Q   ",
      "  hooRo     Q   ",
      "  h   k     Q   ",
      "  hiP ki nnih   ",
      "  hhhhhhhhhhh   ",
      "   g            ",
      "                "
    ],
    [
      "                ",
      "                ",
      "  hhhhhhhhhhh   ",
      "  hiMM i321ih   ",
      "  h  0      Q   ",
      "  hx        Q   ",
      "  hxZ       Q   ",
      "  hxZ       Q   ",
      "  h         Q   ",
      "  h         Q   ",
      "  hoooo     Q   ",
      "  h   k Y   Q   ",
      "  hi  ki   ih   ",
      "  hhhhhhhhhhh   ",
      "   X            ",
      "                "
    ],
    [
      "                ",
      "                ",
      "  hh654h654hh   ",
      "  hi777i777ih   ",
      "  h         h8  ",
      "  h         h8  ",
      "  h         h8  ",
      "  h      ^  h8  ",
      "  h        9h8  ",
      "  h        9h8  ",
      "  hoooo%   9h8  ",
      "  h   k$##@9h8  ",
      "  hi777i777ih   ",
      "  hh654h654hh   ",
      "                ",
      "                "
    ],
    [
      "                ",
      "                ",
      "  &&&&&&&&&&&   ",
      "  h*********h   ",
      "  h+   +   +h   ",
      "  h777777777h   ",
      "  h         h   ",
      "  h  )   )  h   ",
      "  h         h   ",
      "  h         h   ",
      "  h777777777h   ",
      "  h(   (   (h   ",
      "  h*********h   ",
      "  &&&&&&&&&&&   ",
      "                ",
      "                "
    ]
  ]
}