{
  "name": "building_hotel3_floor1",
  "refpalette": "c70cities:building_hotel3_floor1_palette",
  "xsize": 16,
  "zsize": 16,
  "slices": [
    [
      "                ",
      "  a a a a a a   ",
      "  bbbbbbbbbbbba ",
      " abccccddccccb  ",
      "  bceeeeeeeecba ",
      " abceffffffecb  ",
      "  bceffffffecba ",
      " abceffffffecb  ",
      "  bceffffffecba ",
      " abceffffffecb  ",
      "  bceffffffecba ",
      " abceeeeeeeecb  ",
      "  bccccccccccba ",
      " abbbbbbbbbbbb  ",
      "   a a a a a a  ",
      "                "
    ],
    [
      "                ",
      "  a a a a a a   ",
      "  bbbbbbbbbbbba ",
      " ab    dd    b  ",
      "  b eeeeeege ba ",
      " ab ehhhih e b  ",
      "  b ej h k l ba ",
      " ab ej mhh l b  ",
      "  b e      l ba ",
      " ab en opq l b  ",
      "  b e ropq l ba ",
      " ab slllllls b  ",
      "  b          ba ",
      " abbbbbbbbbbbb  ",
      "   a a a a a a  ",
      "                "
    ],
    [
      "                ",
      "  a a a a a a   ",
      "  bbbbbbbbbbbba ",
      " ab    dd    b  ",
      "  b eeeeeete ba ",
      " ab eu h h e b  ",
      "  b w  h x   ba ",
      " ab w   hh   b  ",
      "  b w        ba ",
      " ab w  o     b  ",
      "  b eyyo     ba ",
      " ab s      s b  ",
      "  b          ba ",
      " abbbbbbbbbbbb  ",
      "   a a a a a a  ",
      "                "
    ],
    [
      "                ",
      "  a a a a a a   ",
      "  bbbbbbbbbbbba ",
      " ab    dd    b  ",
      "  b eeeeeeee ba ",
      " ab e  h h e b  ",
      "  b e  h h   ba ",
      " ab e   hh   b  ",
      "  b e        ba ",
      " ab e  o     b  ",
      "  b e  o     ba ",
      " ab s      s b  ",
      "  b          ba ",
      " abbbbbbbbbbbb  ",
      "   a a a a a a  ",
      "                "
    ],
    [
      "                ",
      "  a a a a a a   ",
      "  bbbbbbbbbbbba ",
      " ab    dd    b  ",
      "  b eeeeeeee ba ",
      " ab eyyh h e b  ",
      "  b e  h h   ba ",
      " ab e   hh   b  ",
      "  b e        ba ",
      " ab e  !     b  ",
      "  b e        ba ",
      " ab s      s b  ",
      "  b          ba ",
      " abbbbbbbbbbbb  ",
      "   a a a a a a  ",
      "                "
    ],
    [
      "                ",
      "  a a a a a a   ",
      "  bbbbbbbbbbbba ",
      " ab    dd    b  ",
      "  b eeeeeeee ba ",
      " ab eAAAAAAe b  ",
      "  b eAAAAAAe ba ",
      " ab eAAAAAAe b  ",
      "  b eAAAAAAe ba ",
      " ab eAAAAAAe b  ",
      "  b eAAAAAAe ba ",
      " ab eeeeeeee b  ",
      "  b          ba ",
      " abbbbbbbbbbbb  ",
      "   a a a a a a  ",
      "                "
    ]
  ]
}