{
  "name": "building_restaurant2_ground_90",
  "refpalette": "c70cities:building_restaurant2_ground_palette_90",
  "xsize": 16,
  "zsize": 16,
  "slices": [
    [
      "GGGGGGGGGGGGGGGG",
      "GccccabaabbccccG",
      "GccccaaaaaaccccG",
      "GccccdgdgdgccccG",
      "GccccdgffdgccccG",
      "GaceeffeeffeecbG",
      "GbcdgeedgeedgcbG",
      "GacdgdgdgdgdgcaG",
      "GacffdgffdgffcaG",
      "GaceeffeeffeecaG",
      "GacdgeedgeedgcaG",
      "GGccccccccccccGG",
      "GGabaaaaaaaaaaGG",
      "GGGGGGGabGGGGGGG",
      "GGGGGGbaaGGGGGGG",
      "GGGGGGGaGaGGGGGG"
    ],
    [
      "                ",
      " iiiiyDDDDNiiii ",
      " inniiiiiiii Pi ",
      " in r CFCCMi Oi ",
      " iiii      iEii ",
      " lm  xBBBBL  mS ",
      " km  wmmmmK  mR ",
      " km  uAAAAJ  mR ",
      " km  tttttt  mR ",
      " jm          mQ ",
      " imp piEIip pmi ",
      " hmmmmm  mmmmmh ",
      "  moqsm  moqsm  ",
      "                ",
      "                ",
      "                "
    ],
    [
      "                ",
      " iiiiXXXXXXiiii ",
      " iW iiiiiiii @i ",
      " iV Y  57!9i  i ",
      " iiii      i3ii ",
      "  m   24 2   m  ",
      "  U  000008  U  ",
      "  U  Z11111  U  ",
      "  U          U  ",
      "  m          m  ",
      " im   i36i   mi ",
      " TmUUUm  mUUUmT ",
      "  mXXXm  mXXXm  ",
      "                ",
      "                ",
      "                "
    ],
    [
      "                ",
      " iUUiXXXXXXiUUi ",
      " i  iiiiiiii  i ",
      " i# i      i  i ",
      " iiii      iiii ",
      " XmW        )mX ",
      " Xm$ ^^^^^^ (mX ",
      " Xm$ %%%%%% (mX ",
      " Xm$        (mX ",
      " XmV        *mX ",
      " im   iiii   mi ",
      " TmUUUm  mUUUmT ",
      "  mXXXm&&mXXXm  ",
      "                ",
      "                ",
      "                "
    ],
    [
      "                ",
      " i++i++++++i++i ",
      " i  iiiiiiii  i ",
      " i  i      i  i ",
      " iiii      iiii ",
      " +m[        ]m+ ",
      " +m[        ]m+ ",
      " +m[        ]m+ ",
      " +m[        ]m+ ",
      " +m[        ]m+ ",
      " imiiiiiiiiiimi ",
      "  miiim  miiim  ",
      "  m+++m&&m+++m  ",
      "  -   -  -   -  ",
      "                ",
      "                "
    ],
    [
      "                ",
      " iiii}}}}}}iiii ",
      " i\\\\iiiiiiii\\\\i ",
      " i\\\\i}}}}}}i\\\\i ",
      " i}}}}}}}}}}}}i ",
      " imPP|PPPP|PPmi ",
      " imPP|PPPP|PPmi ",
      " imPP|PPPP|PPmi ",
      " imPP|PPPP|PPmi ",
      " imPP|PPPP|PPmi ",
      " im}}}}}}}}}}mi ",
      " {{{{{{{{{{{{{{ ",
      " {{{{{{{{{{{{{{ ",
      " {{{{{{{{{{{{{{ ",
      " {{{{{{{{{{{{{{ ",
      "                "
    ]
  ]
}