{
  "name": "building_office1_base1",
  "refpalette": "c70cities:building_office1_base1_palette",
  "xsize": 16,
  "zsize": 16,
  "slices": [
    [
      "vvvvvvvvvvvvvvvv",
      "vaaaaaaaaaaaaaav",
      "va!aaaaaaaaaa!av",
      "vaaaaaaaaaaaaaav",
      "vaaaaaaaaaaaaaav",
      "vaaaaaaaaaaaaaav",
      "vaaaaaaaaaaaaaav",
      "vaaaaaaaaaaaaaav",
      "vaaaaaaaaaaaaaav",
      "vaaaaaaaaaaaaaav",
      "vaaaaaaaaaaaaaav",
      "vaaaaaaaaaaaaaav",
      "vabaaaaaaaaaaaav",
      "vabaaaaaaaaaaaav",
      "vaaaaaaaaaaaaaav",
      "vvvvvvvvvvvvvvvv"
    ],
    [
      "vvvvvvvvvvvvvvvv",
      "vccccccccccccccv",
      "vcd   d  d   dcv",
      "vcd   d  d   dcv",
      "vcd   d  d   dcv",
      "vcd   d  d   dcv",
      "vcd          dcv",
      "vcd          dcv",
      "vcd   d  d   dcv",
      "vcd   d  d   dcv",
      "vcd   d  d   dcv",
      "vce          ecv",
      "vcb          fcv",
      "vcb          fcv",
      "vccccccccccccccv",
      "vvvvvvvvvvvvvvvv"
    ],
    [
      "vvvvvvvvvvvvvvvv",
      "vccccccccccccccv",
      "vcd   d  d   dcv",
      "vcd   d  d   dcv",
      "vcd   d  d   dcv",
      "vcd   d  d   dcv",
      "vcd          dcv",
      "vcd          dcv",
      "vcd   d  d   dcv",
      "vcd   d  d   dcv",
      "vcd   d  d   dcv",
      "vce          ecv",
      "vcb           cv",
      "vcb           cv",
      "vccccccccccccccv",
      "vvvvvvvvvvvvvvvv"
    ],
    [
      "vvvvvvvvvvvvvvvv",
      "vccccccccccccccv",
      "vcd          dcv",
      "vcd          dcv",
      "vcd          dcv",
      "vcd          dcv",
      "vcd          dcv",
      "vcd          dcv",
      "vcd          dcv",
      "vcd          dcv",
      "vcd          dcv",
      "vce          ecv",
      "vcb           cv",
      "vcb           cv",
      "vccccccccccccccv",
      "vvvvvvvvvvvvvvvv"
    ],
    [
      "vvvvvvvvvvvvvvvv",
      "vccccccccccccccv",
      "vc            cv",
      "vc            cv",
      "vc            cv",
      "vc            cv",
      "vc            cv",
      "vc            cv",
      "vc            cv",
      "vc            cv",
      "vc            cv",
      "vce          ecv",
      "vcb           cv",
      "vcb           cv",
      "vccccccccccccccv",
      "vvvvvvvvvvvvvvvv"
    ],
    [
      "vvvvvvvvvvvvvvvv",
      "vccccccccccccccv",
      "vcggggggggggggcv",
      "vcggggggggggggcv",
      "vcggggggggggggcv",
      "vcggggggggggggcv",
      "vcggggggggggggcv",
      "vcggggggggggggcv",
      "vcggggggggggggcv",
      "vcggggggggggggcv",
      "vcggggggggggggcv",
      "vceggggggggggecv",
      "vcbgggggggggggcv",
      "vcbgggggggggggcv",
      "vccccccccccccccv",
      "vvvvvvvvvvvvvvvv"
    ]
  ]
}