{
  "name": "building_hotel3_floor3_90",
  "refpalette": "c70cities:building_hotel3_floor3_palette_90",
  "xsize": 16,
  "zsize": 16,
  "slices": [
    [
      "                ",
      "  a a a a a a   ",
      "  bbbbbbbbbbbba ",
      " abccccccccccb  ",
      "  bceeeeeeeecba ",
      " abceffffffecb  ",
      "  bceffffffecba ",
      " abdeffffffecb  ",
      "  bdeffffffecba ",
      " abceffffffecb  ",
      "  bceffffffecba ",
      " abceeeeeeeecb  ",
      "  bccccccccccba ",
      " abbbbbbbbbbbb  ",
      "   a a a a a a  ",
      "                "
    ],
    [
      "                ",
      "  a a a a a a   ",
      "  bbbbbbbbbbbba ",
      " ab          b  ",
      "  b eelllllp ba ",
      " ab h      l b  ",
      "  b e  mno l ba ",
      " abdeikmeeee b  ",
      "  bdeee!no l ba ",
      " ab eijmno l b  ",
      "  b g      l ba ",
      " ab eeeeeeep b  ",
      "  b          ba ",
      " abbbbbbbbbbbb  ",
      "   a a a a a a  ",
      "                "
    ],
    [
      "                ",
      "  a a a a a a   ",
      "  bbbbbbbbbbbba ",
      " ab          b  ",
      "  b ee     p ba ",
      " ab r        b  ",
      "  b e        ba ",
      " abde  teeee b  ",
      "  bdeeee     ba ",
      " ab e        b  ",
      "  b q        ba ",
      " ab eessssep b  ",
      "  b          ba ",
      " abbbbbbbbbbbb  ",
      "   a a a a a a  ",
      "                "
    ],
    [
      "                ",
      "  a a a a a a   ",
      "  bbbbbbbbbbbba ",
      " ab          b  ",
      "  b ee     p ba ",
      " ab e        b  ",
      "  b e        ba ",
      " abde   eeee b  ",
      "  bdeeee     ba ",
      " ab e        b  ",
      "  b e        ba ",
      " ab eeeeeeep b  ",
      "  b          ba ",
      " abbbbbbbbbbbb  ",
      "   a a a a a a  ",
      "                "
    ],
    [
      "                ",
      "  a a a a a a   ",
      "  bbbbbbbbbbbba ",
      " ab          b  ",
      "  b ee     p ba ",
      " ab e        b  ",
      "  b e        ba ",
      " abde   eeee b  ",
      "  bdeeee     ba ",
      " ab e        b  ",
      "  b e        ba ",
      " ab eeeeeeep b  ",
      "  b          ba ",
      " abbbbbbbbbbbb  ",
      "   a a a a a a  ",
      "                "
    ],
    [
      "                ",
      "  a a a a a a   ",
      "  bbbbbbbbbbbba ",
      " ab          b  ",
      "  b eeeeeeee ba ",
      " ab euuuuuue b  ",
      "  b euuuuuue ba ",
      " abdeuuuuuue b  ",
      "  bdeeeeuuue ba ",
      " ab euuuuuue b  ",
      "  b euuuuuue ba ",
      " ab eeeeeeee b  ",
      "  b          ba ",
      " abbbbbbbbbbbb  ",
      "   a a a a a a  ",
      "                "
    ]
  ]
}