{
  "name": "building_office1_base2_270",
  "refpalette": "c70cities:building_office1_base2_palette_270",
  "xsize": 16,
  "zsize": 16,
  "slices": [
    [
      "vvvvvvvvvvvvvvvv",
      "vaaaaaaaaaaaaaav",
      "vaaaaaaaaaaaaaav",
      "vaaaaaaaaaaaaaav",
      "vaaaaaaaaaaaaaav",
      "vaaaaaaaaaaaaaav",
      "vaaaaaaaa!aaaaav",
      "vaaaaaaaaaaaaaav",
      "vaaaaaaaaaaaaaav",
      "vaaaaaaaa!aaaaav",
      "vaaaaaaaaaaaaaav",
      "vaaaaaaaaaaaaaav",
      "vaaaaaaaaaaaaaav",
      "va!aaaaaaaaaaaav",
      "vaaaaaaaaaaaaaav",
      "vvvvvvvvvvvvvvvv"
    ],
    [
      "vvvvvvvvvvvvvvvv",
      "vbbbbbbbbbbbbbbv",
      "vbiie         bv",
      "vb  f         bv",
      "vb  f         bv",
      "vb  f    d    bv",
      "vb  e  dddd   bv",
      "vb  g         bv",
      "vb  h       c bv",
      "vb  e  d dd   bv",
      "vb  f   d     bv",
      "vb  f         bv",
      "vb  f         bv",
      "vbjje         bv",
      "vbbbbbbbbbbbbbbv",
      "vvvvvvvvvvvvvvvv"
    ],
    [
      "vvvvvvvvvvvvvvvv",
      "vbbbbbbbbbbbbbbv",
      "vbiie         bv",
      "vb  f         bv",
      "vb  f         bv",
      "vb  f         bv",
      "vb  e         bv",
      "vb  k         bv",
      "vb  l         bv",
      "vb  e         bv",
      "vb  f         bv",
      "vb  f         bv",
      "vb  f         bv",
      "vbnme         bv",
      "vbbbbbbbbbbbbbbv",
      "vvvvvvvvvvvvvvvv"
    ],
    [
      "vvvvvvvvvvvvvvvv",
      "vbbbbbbbbbbbbbbv",
      "vbiie         bv",
      "vb  f         bv",
      "vb  f         bv",
      "vb  f         bv",
      "vb  e         bv",
      "vb  e         bv",
      "vb  e         bv",
      "vb  e         bv",
      "vb  f         bv",
      "vb  f         bv",
      "vb  f         bv",
      "vbo e         bv",
      "vbbbbbbbbbbbbbbv",
      "vvvvvvvvvvvvvvvv"
    ],
    [
      "vvvvvvvvvvvvvvvv",
      "vbbbbbbbbbbbbbbv",
      "vbiie         bv",
      "vb  f         bv",
      "vb  f         bv",
      "vb  f         bv",
      "vb  f         bv",
      "vb  f         bv",
      "vb  f         bv",
      "vb  f         bv",
      "vb  f         bv",
      "vb  f         bv",
      "vb  f         bv",
      "vb  e         bv",
      "vbbbbbbbbbbbbbbv",
      "vvvvvvvvvvvvvvvv"
    ],
    [
      "vvvvvvvvvvvvvvvv",
      "vbbbbbbbbbbbbbbv",
      "vbiiepppppppppbv",
      "vbppppppppppppbv",
      "vbppppppppppppbv",
      "vbppppppppppppbv",
      "vbppppppppppppbv",
      "vbpppprppcppcpbv",
      "vbppppcpprppqpbv",
      "vbppppppppppppbv",
      "vbppppppppppppbv",
      "vbppppppppppppbv",
      "vbppppppppppppbv",
      "vbppepppppppppbv",
      "vbbbbbbbbbbbbbbv",
      "vvvvvvvvvvvvvvvv"
    ]
  ]
}