{
  "name": "building_factory2_floor1_270",
  "refpalette": "c70cities:building_factory2_floor1_palette_270",
  "xsize": 16,
  "zsize": 16,
  "slices": [
    [
      "                ",
      "                ",
      "                ",
      " acccccccccccca ",
      " jddddddddddddb ",
      " jdf g f fg fdb ",
      " jdf h    h  db ",
      " jd  h    h  db ",
      " jd  g    g  db ",
      " jd  g    g  db ",
      " jd  h    h  db ",
      " jd  h    h  db ",
      " jdf g    g  db ",
      " jddddddddddddb ",
      " aeeeiieeiieeea ",
      "                "
    ],
    [
      "                ",
      "                ",
      " kkkkkkkkkkkkkk ",
      " kkkkkkkkkkkkkk ",
      " lqddddddddddml ",
      " lqnnoonnoonnml ",
      "  mnnp nn pnnm  ",
      "  mnn  nn  nnm  ",
      "  m  p    p  m  ",
      "  m  p    p  m  ",
      "  m          m  ",
      "  mf p    p  m  ",
      "  mff     f fm  ",
      "  mmmmmmmmmmmm  ",
      " a   ii  ii   a ",
      "                "
    ],
    [
      "                ",
      "                ",
      "                ",
      "                ",
      "                ",
      "                ",
      " kk  ss  ss  kk ",
      " kk  ss  ss  kk ",
      " lqnnddnnddnnql ",
      " lqnnddnnddnnql ",
      "  mnnddnnddnnm  ",
      "  m ror  ror m  ",
      "  m ror fror m  ",
      "  mmmmmmmmmmmm  ",
      " a   ii  ii   a ",
      "                "
    ],
    [
      "                ",
      "                ",
      "                ",
      "                ",
      "                ",
      "                ",
      "                ",
      "                ",
      "                ",
      "                ",
      " kk          kk ",
      " kkssiissiisskk ",
      " lqddiiddiiddql ",
      " lqddiiddiiddql ",
      " aeeeiieeiieeea ",
      "                "
    ],
    [
      "                ",
      "                ",
      "                ",
      "                ",
      "                ",
      "                ",
      "                ",
      "                ",
      "                ",
      "                ",
      "                ",
      "       ~        ",
      "     wt  wt     ",
      "     iu  iu     ",
      " kkkkkkkkkkkkkk ",
      " kkkkkkkkkkkkkk "
    ],
    [
      "                ",
      "                ",
      "                ",
      "                ",
      "                ",
      "                ",
      "                ",
      "                ",
      "                ",
      "                ",
      "                ",
      "       ~        ",
      "                ",
      "                ",
      "                ",
      "                "
    ]
  ]
}