{
  "name": "building_restaurant1_base1_90",
  "refpalette": "c70cities:building_restaurant1_base1_palette_90",
  "xsize": 16,
  "zsize": 16,
  "slices": [
    [
      "vvvvvvvvvvvvvvvv",
      "v==============v",
      "v=vvvvvvvvbbbbbv",
      "v=vvvvvvvvccccbv",
      "v=vvvvvvvvccc!bv",
      "v=vvvvvvvvccccbv",
      "v=vvvvvvvvccccbv",
      "v=vvvv!vvvccccbv",
      "v=vvvvvvvvccccbv",
      "v=vvvvvvvvccccbv",
      "v=vvvvvvvvcdddbv",
      "v=vvvvvvvvcdddbv",
      "v=vvvvvvvvcdddbv",
      "v=avvvvvvvbbbbbv",
      "v==============v",
      "vvvvvvvvvvvvvvvv"
    ],
    [
      "vvvvvvvvvvvvvvvv",
      "v==============v",
      "v=iim   prbbbbbv",
      "v=hk      q uxbv",
      "v=g      qqs wbv",
      "v=f   ol  s subv",
      "v=   nlll     bv",
      "v=   llll qs ubv",
      "v=  llll      bv",
      "v=    nl  qdddbv",
      "v=        dtttbv",
      "v=  j     dtttbv",
      "v=ejj    kdtttbv",
      "v=ajjj  khbbbbbv",
      "v==============v",
      "vvvvvvvvvvvvvvvv"
    ],
    [
      "vvvvvvvvvvvvvvvv",
      "v==============v",
      "v=ky     Abbbbbv",
      "v=g       q  ubv",
      "v=        q   bv",
      "v=            bv",
      "v=     l      bv",
      "v=   lll      bv",
      "v=    ll      bv",
      "v=            bv",
      "v=        q   bv",
      "v=        q   bv",
      "v=e       q   bv",
      "v=ajj    gbbbbbv",
      "v==============v",
      "vvvvvvvvvvvvvvvv"
    ],
    [
      "vvvvvvvvvvvvvvvv",
      "v==============v",
      "v=        bbbbbv",
      "v=        q   bv",
      "v=            bv",
      "v=            bv",
      "v=            bv",
      "v=    nl      bv",
      "v=            bv",
      "v=            bv",
      "v=            bv",
      "v=        q   bv",
      "v=e       q  Bbv",
      "v=aj      bbbbbv",
      "v==============v",
      "vvvvvvvvvvvvvvvv"
    ],
    [
      "vvvvvvvvvvvvvvvv",
      "v==============v",
      "v=        bbbbbv",
      "v=        q   bv",
      "v=        q   bv",
      "v=        q   bv",
      "v=            bv",
      "v=        q   bv",
      "v=       qq   bv",
      "v=        q   bv",
      "v=        q   bv",
      "v=        q   bv",
      "v=e       q  Cbv",
      "v=a       bbbbbv",
      "v==============v",
      "vvvvvvvvvvvvvvvv"
    ],
    [
      "vvvvvvvvvvvvvvvv",
      "v==============v",
      "v=DDDDDDDDbbbbbv",
      "v=DDDDDDDDddddbv",
      "v=DDDDDDDDddddbv",
      "v=DDDDDDDDddddbv",
      "v=DDDDDDDDddddbv",
      "v=DDDDDDDDddddbv",
      "v=DDDDDDDDddddbv",
      "v=DDDDDDDDddddbv",
      "v=DDDDDDDDddddbv",
      "v=DDDDDDDDddddbv",
      "v=eDDDDDDDdddEbv",
      "v=aDDDDDDDbbbbbv",
      "v==============v",
      "vvvvvvvvvvvvvvvv"
    ]
  ]
}