{
  "name": "building_office1_ground_270",
  "refpalette": "c70cities:building_office1_ground_palette_270",
  "xsize": 16,
  "zsize": 16,
  "slices": [
    [
      "GGGGGGGGGGGGGGGG",
      "GbbbbbbbbbbbbbbG",
      "GbeeddddccccccbG",
      "GbbbbbbbbbbbbcbG",
      "Gbbbbbbbbbbbbcba",
      "GbbbbbbbbbbbbcbG",
      "GbbbbbbbbbbbbcbG",
      "GbbbbbbbbbbbbcbG",
      "Gbbbbbbbb!bbbcbG",
      "GbbbbbbbbbbbbcbG",
      "GbbbbbbbbbbbbcbG",
      "Gbbbbbbbbbbbbcba",
      "GbbbbbbbbbbbbcbG",
      "GbddddddccccccbG",
      "GbbbbbbbbbbbbbbG",
      "GGGGGGGGGGGGGGGG"
    ],
    [
      "               f",
      " ssss  g  g  g f",
      " sxxdhhdhhhhhh f",
      " s  t       ihgf",
      " s           h f",
      " s  uqn  mk  h f",
      " s       l j hgf",
      " s  ooo  l   h f",
      " s  ooo  l   h f",
      " s       l j hgf",
      " s  wrp  ll  h f",
      " s           h f",
      " s          ihgf",
      " s  dhhdhhhhhh f",
      " sAys  g  g  g f",
      "               f"
    ],
    [
      "                ",
      " ssss  g  g  g  ",
      " s  dhhdhhhhhh  ",
      " I  t       Bhg ",
      " h           h  ",
      " h           h  ",
      " h           hg ",
      " h           h  ",
      " h           h  ",
      " h       C   hg ",
      " h       D   h  ",
      " h           h  ",
      " I          Bhg ",
      " s  dhhdhhhhhh  ",
      " sFEs  g  g  g  ",
      "                "
    ],
    [
      "                ",
      " ssss  g  g  g  ",
      " sKJdhhdhhhhhh  ",
      " I  t       Bhg ",
      " h           h  ",
      " h           h  ",
      " h           hg ",
      " h           h  ",
      " h           h  ",
      " h           hg ",
      " h           h  ",
      " h           h  ",
      " I          Bhg ",
      " s  dhhdhhhhhh  ",
      " ssss  g  g  g  ",
      "                "
    ],
    [
      "                ",
      " ssss  g  g  g  ",
      " sL dhhdhhhhhh  ",
      " s  t        hg ",
      " s           h  ",
      " s           h  ",
      " s           hg ",
      " s           h  ",
      " s           h  ",
      " s           hg ",
      " s           h  ",
      " s           h  ",
      " s           hg ",
      " s  dhhdhhhhhh  ",
      " ssss  g  g  g  ",
      "                "
    ],
    [
      "                ",
      " ssss  MMMMMMMM ",
      " sIIdhhMMMMMMMM ",
      " sIIt  IIIIIIMM ",
      " sIIIIIIIIIIIMM ",
      " sIIIIIIIIIIIMM ",
      " sIIIIIIIIIIIMM ",
      " sIIIIIIIIIIIMM ",
      " sIIIIIIIIIIIMM ",
      " sIIIIIIIIIIIMM ",
      " sIIIIIIIIIIIMM ",
      " sIIIIIIIIIII M ",
      " sII   IIIIIIMM ",
      " sIIdhhMMMMMMMM ",
      " ssss  MMMMMMMM ",
      "                "
    ]
  ]
}