{
  "name": "building_apartment1_floor1_270",
  "refpalette": "c70cities:building_apartment1_floor1_palette_270",
  "xsize": 16,
  "zsize": 16,
  "slices": [
    [
      "                ",
      " aaaaaaaaaaaaaa ",
      " abbbbbbbbbbbba ",
      " abbbbbbbbbbbba ",
      " abbbbbbbbbbbba ",
      " abbbbbbbbbbbba ",
      " abbbbbbbbbbbba ",
      " abbbbbbbbbbbba ",
      " abbbbbbbbbbbba ",
      " abbbbbbbbbbbba ",
      "  d  cbbbbbbbba ",
      "  g bbbbbbbbbba ",
      "  hfbbbbbbbbbba ",
      "  ieedbbbbbbbba ",
      "      aaaaaaaaa ",
      "                "
    ],
    [
      "                ",
      " Zmmmmmmmmmmmmj ",
      " 0XUQOp Fp   nk ",
      " 0   Pp qpC tok ",
      " 0    IKIpD tok ",
      " 0       E    k ",
      " 0 RR L  pppupk ",
      " 0    M  y x qk ",
      " 0!VS M  p y  k ",
      " 0ppppp  p xw k ",
      "  Y   p  p xppk ",
      "  Y   pKpp Atok ",
      "  dWT N JpC   k ",
      "  ddddp JpDB rk ",
      "      ssssssssl ",
      "                "
    ],
    [
      "                ",
      " 8@@@@8@@8p111p ",
      " @(&  p  p   2p ",
      " 1   %p  p    p ",
      " 1    I#Ip    p ",
      " 1       9    p ",
      " 1       ppp4pp ",
      " 1       5 x  p ",
      " @ ^^    p 5  p ",
      " pppppp  p x 3p ",
      "  d   p  p xppp ",
      "  d*  p#pp 6top ",
      "  dT  $  p    p ",
      "  ddYhp  p7   p ",
      "      ppppp111p ",
      "                "
    ],
    [
      "                ",
      " 8111@8118p111p ",
      " @    p  p {[)p ",
      " 1:   p  p    1 ",
      " 1:   IIIp    1 ",
      " 1;      p    p ",
      " 1'   \\  pppppp ",
      " 1'      p x  1 ",
      " @ ||    p x  1 ",
      " pppppp  p x +p ",
      "  dW  p  p xppp ",
      "  d`  pppp    1 ",
      "  ,   p  p    1 ",
      "  .dddp  p }]-p ",
      "      p11pp111p ",
      "                "
    ],
    [
      "                ",
      " 8@@@@8@@8p@@@p ",
      " @    p  p    p ",
      " @    p  p    k ",
      " @    IIIp    k ",
      " @       p    p ",
      " @    /  pppppp ",
      " @       p x  k ",
      " @       p x  k ",
      " pppppp  p x  p ",
      "  e`< p  p xppp ",
      "  Y   pppp    k ",
      "  Y   pf p    k ",
      "  d,,,p  p    p ",
      "      p@@pp@@@p ",
      "                "
    ],
    [
      "                ",
      " pppppppppppppp ",
      " pddddd>>pddddp ",
      " pddddd>>pddddp ",
      " pdddddddpddddp ",
      " pdddddddpddddp ",
      " pdddddddpppppp ",
      " pdddddddpdd>>p ",
      " pdddddddpdd>>p ",
      " ppppppddpdd>>p ",
      "  d cWpddpddddp ",
      "  d   ppppddddp ",
      "  d   pddpddddp ",
      "  ddddpddpddddp ",
      "      ppppppppp ",
      "                "
    ]
  ]
}