{
  "name": "building_residential3_ground_180",
  "refpalette": "c70cities:building_residential3_ground_palette_180",
  "xsize": 16,
  "zsize": 16,
  "slices": [
    [
      "GGGGGGGGGGGGGGGG",
      "GGGGGGGGGGGGGGGG",
      "GGaaaaaaGGGGGGGG",
      "GGabbbbacccccGGG",
      "GGabbbbbddddcGGG",
      "GGabbbbbddddcGGG",
      "GGabbbbbddddcGGG",
      "GGabbbbbddddcGGG",
      "GGabbbbbbbbbaaGG",
      "GGabbbbbbbbbbaGG",
      "GGabbbbbbbbbbaGG",
      "GGabbbbbbbbbbaGG",
      "GGabbbbbbbbbbaGG",
      "GGaaaaaaaaaaaaGG",
      "GGGGGGGGGGGGGGGG",
      "GGGGGGGGGGGGGGGG"
    ],
    [
      "effffgffffgffffe",
      "f              f",
      "f hiJJihyyyyyy f",
      "f h    hcccccy f",
      "f hI  AhFEDCcy f",
      "e hB  Ah    cy g",
      "f h    h    cy f",
      "f hw   u   xc  f",
      "f hw   u tsshh f",
      "f h       rr i e",
      "g hpqp       o  ",
      "f hn k       m  ",
      "f hl k!  j   i e",
      "f hhhhhhhhhhhh f",
      "f              f",
      "effffgffffgffffe"
    ],
    [
      "effffgffffgffffe",
      "f              f",
      "f hiJJih       f",
      "f h    hcRRcc  f",
      "f J   ShU  Tc  f",
      "e J   Sh    R  g",
      "f J    h    R  f",
      "f hQ   u    c  f",
      "f hP   u    hh f",
      "f J          i e",
      "g hpOp       N  ",
      "f K  kM      L  ",
      "f h  k  j    i e",
      "f hhKhJhhJJJhh f",
      "f              f",
      "effffgffffgffffe"
    ],
    [
      "                ",
      "                ",
      "  hi00ihZZZZZZ  ",
      "  h    hcccccZ  ",
      "  Y    h    cZ  ",
      "W Y    h    cZ  ",
      "  Y    h    cZ  ",
      "  h    u    cZ  ",
      "  h    u    hh  ",
      "  Y          i  ",
      "  hppp       X  ",
      "  Y  k       X  ",
      "  h  k j     i W",
      "  hhVhVhhVVVhh  ",
      "                ",
      "                "
    ],
    [
      "                ",
      "                ",
      "  hhhhhh111111  ",
      "  hbbbbh444431  ",
      "  hbbbbb    21  ",
      "  hbbbbb    21  ",
      "  hbbbbb    21  ",
      "  hbbbbb    21  ",
      "  hbbbbbbbbbhh  ",
      "  hbbbbbbbbbbh  ",
      "  hbbbbbbbbbbh  ",
      "  hbbbbbbbbbbh  ",
      "  hbbbj   bbbh  ",
      "  hhhhhhhhhhhh  ",
      "                ",
      "                "
    ],
    [
      "                ",
      "                ",
      "  hJJJJh111111  ",
      "  h (( hccccc1  ",
      "  Y+)( $    c1  ",
      "  Y+)( $    c1  ",
      "  Y@(( $    c1  ",
      "  hiii $*   c1  ",
      "  h&^% $$$$$hh  ",
      "  J #     @99J  ",
      "  J          J  ",
      "  J   8888   J  ",
      "  J7      655J  ",
      "  hhVVVhhVVVhh  ",
      "                ",
      "                "
    ]
  ]
}