{
  "name": "building_residential4_ground_270",
  "refpalette": "c70cities:building_residential4_ground_palette_270",
  "xsize": 16,
  "zsize": 16,
  "slices": [
    [
      "GGGGGGGGGGGGGGGG",
      "GGGGGGGGGGGGGGGG",
      "GGaaaaaaaaaaaaGG",
      "GGabbbbbbbbbbaGG",
      "GGabbbbbbbbbbaGG",
      "GGabbbbbbbbbbaGG",
      "GGabbbbbbbbbbaGG",
      "GGabbbbbbbbbbaGG",
      "GGabbbbbbbbbbaGG",
      "GGaccccccccccaGG",
      "GGaccccccccccaGG",
      "GGaccccccccccaGG",
      "GGaddddddddddaGG",
      "GGaGGGGGGGGGGaGG",
      "GGGGGGGGGGGGGGGG",
      "GGGGGGGGGGGGGGGG"
    ],
    [
      "efffffe  efffffe",
      "f              f",
      "f hjjjhAxhjjjh f",
      "f hID     rp h f",
      "f L          i f",
      "g L       qq i g",
      "f hJ    uukkkh f",
      "f L          i f",
      "f L        lli f",
      "f hKEC    smmh f",
      "g L  C       i g",
      "f L FCwBywtnni f",
      "f hddddddddddh f",
      "f hooooooooooh f",
      "f              f",
      "effffgffffgffffe"
    ],
    [
      "efffffe  efffffe",
      "f              f",
      "f hMMMhTRhMMMh f",
      "f h          h f",
      "f MY         M f",
      "g MJ      OO M g",
      "f h     uuNNNh f",
      "f M          M f",
      "f M          M f",
      "f hKWC     P h f",
      "g Z  C       M g",
      "f Z XCVU  Q  M f",
      "f hddddSSddddh f",
      "f h          h f",
      "f              f",
      "effffgffffgffffe"
    ],
    [
      "                ",
      "                ",
      "  hMMMhMMhMMMh  ",
      "  h          h  ",
      "  h 1        h  ",
      "  h          h  ",
      "  h     uuNNNh  ",
      "  h          h  ",
      "  h          h  ",
      "  hKKC       h  ",
      "  h  C       h  ",
      "  h  C       h  ",
      "  hddddSSddddh  ",
      "  h0000000000h  ",
      "                ",
      "                "
    ],
    [
      "                ",
      " 4i          L2 ",
      " 4hhhhhhhhhhhh2 ",
      " 4hbbbbbbbbbbh2 ",
      " 4h  1bbbbbbbh2 ",
      " 4h   bbbbbbbh2 ",
      " 4h   bbbbbbbh2 ",
      " 4hbbbbbbbbbbh2 ",
      " 4hbbbbbbbbbbh2 ",
      " 4hbbbbbbbbbbh2 ",
      " 4hbbbbbbbbbbh2 ",
      " 4hbbbbbbbbbbh2 ",
      " 4hddddddddddh2 ",
      " 4h3333  3333h2 ",
      " 4i          L2 ",
      "                "
    ],
    [
      "                ",
      "  4i        L2  ",
      "  43333&@33332  ",
      "  4dddddddddd2  ",
      "  4     #553h2  ",
      "  4   ( 7663h2  ",
      "  4---( 7773h2  ",
      "  4   )    3h2  ",
      "  4!  + $  3h2  ",
      "  4{  + 8883h2  ",
      "  4{  + 8883h2  ",
      "  4 ][+ %9 3h2  ",
      "  4dddddddddd2  ",
      "  43333*^33332  ",
      "  4i        L2  ",
      "                "
    ]
  ]
}