{
  "name": "building_office5_ground_270",
  "refpalette": "c70cities:building_office5_ground_palette_270",
  "xsize": 16,
  "zsize": 16,
  "slices": [
    [
      "GGGGGGGGGGGGGGGG",
      "GaaaaaaaaaaaaaaG",
      "GaaaaaaaaaaaaaaG",
      "GaaaaaaaaaaaaaaG",
      "GaaaaaaaaaaaaaaG",
      "GaaaaaaaaaaaaaaG",
      "GaaaaaaaaaaaaaaG",
      "GaaaaaaaaaaGGaaG",
      "GaaaaaaaaaaGGaaG",
      "Gaaaaaaaa!aaaaaG",
      "GaaaaaaaaaaaaaaG",
      "GaaaaaaaaaaaaaaG",
      "GaaaaaaaaaaaaaaG",
      "GaaaaaaaaaaaaaaG",
      "GaaaaaaaaaaaaaaG",
      "GGGGGGGGGGGGGGGG"
    ],
    [
      "                ",
      " bc  cc  cc  cb ",
      " cdeeddeedbeedc ",
      "  ex         e  ",
      "  e      ml fe  ",
      " cd ur   ml gdc ",
      " cdy sq   bhhdc ",
      "  e  s   nckie  ",
      "  e  s   ncije  ",
      " cdy sq   bhhdc ",
      " cd wt   ml gdc ",
      "  e      ml fe  ",
      "  ex         e  ",
      " cdeeddpodbeedc ",
      " bc  cc  cc  cb ",
      "                "
    ],
    [
      "                ",
      " bc  cc  cc  cb ",
      " cdeeddeedbeedc ",
      "  em         e  ",
      "  e          e  ",
      " cd          dc ",
      " cd  D    b  dc ",
      "  e      ncA e  ",
      "  e      nc  e  ",
      " cd  D    b  dc ",
      " cd          dc ",
      "  e          e  ",
      "  em         e  ",
      " cdeeddCBdbeedc ",
      " bc  cc  cc  cb ",
      "                "
    ],
    [
      "                ",
      " bc  cc  cc  cb ",
      " cdeeddeedbeedc ",
      "  em         e  ",
      "  e          e  ",
      " cd          dc ",
      " cd       b  dc ",
      "  e      nc  e  ",
      "  e    E nc  e  ",
      " cd       b  dc ",
      " cd          dc ",
      "  e          e  ",
      "  em         e  ",
      " cdeeddeedbeedc ",
      " bc  cc  cc  cb ",
      "                "
    ],
    [
      "                ",
      " bcFFccFFccFFcb ",
      " cddddddddcdddc ",
      " Fd       c  dF ",
      " Fd       c  dF ",
      " cd       c  dc ",
      " cd       c  dc ",
      " Fd    IEnc  dF ",
      " Fd    EInc  dF ",
      " cd       c  dc ",
      " cd       c  dc ",
      " Fd       c  dF ",
      " Fd       c  dF ",
      " cddddddddcdddc ",
      " bcFFccFFccFFcb ",
      "                "
    ],
    [
      "                ",
      " bccccccccccccb ",
      " cccccccccccccc ",
      " ccJJJJJJJccccc ",
      " ccJJJJJJJccccc ",
      " ccJJJJJJJccccc ",
      " ccJJJK  Kccccc ",
      " ccJJJ LLnccccc ",
      " ccJJJ LLnccccc ",
      " ccJJJK  Kccccc ",
      " ccJJJJJJJccccc ",
      " ccJJJJJJJccccc ",
      " ccJJJJJJJccccc ",
      " cccccccccccccc ",
      " bccccccccccccb ",
      "                "
    ]
  ]
}