{
  "name": "building_restaurant1_ground_90",
  "refpalette": "c70cities:building_restaurant1_ground_palette_90",
  "xsize": 16,
  "zsize": 16,
  "slices": [
    [
      "GGdGGGGGGGGGGGGG",
      "GGGd======GGGGGG",
      "GGGd=!ccc=eeeeeG",
      "GGdG=cccc=aaaaeG",
      "GGdd=cccc=ffffeG",
      "GGGd=cccc=ffffeG",
      "GGdd=cccc=ffffeG",
      "Gadd=cccc=ffffeG",
      "Gaaa=cccc=ffffeG",
      "Gacc=cccc=ffffeG",
      "Gacc=cccc=ffffeG",
      "Gaccccccc=ffffeG",
      "Gabcccccc=ffffeG",
      "Gaaa=cccc=eeeeeG",
      "GGGG======GGGGGG",
      "GGGGGGGGGGGGGGGG"
    ],
    [
      "                ",
      "    ======      ",
      " g g=lnpt=    eB",
      "    =   t=xxxxeF",
      "  g =   s=wwwweB",
      "    = mmm=uy yeB",
      "    =   rr o oeE",
      " a  = koq  q  eD",
      " a  =         eD",
      " a  =k        eD",
      " a h=  oq     eD",
      " a  j      oooeC",
      " a  i    =uq AeB",
      " aaa= koq=eeeee ",
      "    ======      ",
      "                "
    ],
    [
      "                ",
      "    ======      ",
      "    = N  =    e ",
      "    L   P=    x ",
      "    L   O=wwwwe ",
      "    L Mrr=Q   e ",
      "    L        Rx ",
      " a  =         x ",
      " a  =         x ",
      " a  =         x ",
      " a h=         x ",
      " a  K       r x ",
      " a  J    =Q   e ",
      " aaI=  r =eeeee ",
      "    ======      ",
      "                "
    ],
    [
      "                ",
      "    ===II=      ",
      "    =    =    e ",
      "    = U  =      ",
      "    =    =wwwwe ",
      "    =    =Q   e ",
      "  LL=           ",
      " aLL=           ",
      " aLL=           ",
      " aSS=           ",
      " a h=           ",
      " a  =           ",
      " a  =    =Q   e ",
      " aaI=    =eeeee ",
      "    ==TT==      ",
      "                "
    ],
    [
      "                ",
      "    ======      ",
      "    =    =    e ",
      "    = V  =      ",
      "    =    =wwwwe ",
      "    =    =    e ",
      "    =    =      ",
      " aLL=    =      ",
      " aLL= V  =      ",
      " aSS=    =      ",
      " a h=    =      ",
      " a  =    =  U   ",
      " a  =    =    e ",
      " aaa= V  =eeeee ",
      "    ======      ",
      "                "
    ],
    [
      "                ",
      "    ======      ",
      "    =WWWW=    e ",
      "    =WWWW=    e ",
      "    =WWWW=wwwwe ",
      "    =WWWW=    e ",
      "    =WWWW=  V e ",
      " a  =WWWW=    e ",
      " aLL=WWWW=    e ",
      " aSS=WWWW=    e ",
      " a h=WWWW=    e ",
      " a  =WWWW=  V e ",
      " a  =WWWW=    e ",
      " aaa=WWWW=eeeee ",
      "    ======      ",
      "                "
    ]
  ]
}