{
  "name": "building_factory2_ground_90",
  "refpalette": "c70cities:building_factory2_ground_palette_90",
  "xsize": 16,
  "zsize": 16,
  "slices": [
    [
      "zzzzzzzzzzzzzzzz",
      "zzzzzzzzzzzzzzzz",
      "zzzzzzzzHHzzzzzz",
      "zzzHHHHHHHHHHzzz",
      "zzzHHHHHHHHHHzzz",
      "zzzHHHHHHHHHHzzz",
      "zzzHHHHHHHHHHzzz",
      "zzzHHHHHHHHHHzzz",
      "zzzHHHHHHHHHHzzz",
      "zzzHHHHHHHHHHzzz",
      "zzzHHHHHHHHHHzzz",
      "zzzHHHHHHHHHHzzz",
      "zzzzaaaaazzzzzzz",
      "zzzzaaazaazzzzzz",
      "zzzzzazaazazzzzz",
      "zzzzazzzzzzzzzzz"
    ],
    [
      " b dceec eebdcc ",
      " efffeeffeefffeb",
      "bcffffffffffffcb",
      "ccfkkkknkyCEgf d",
      "dcfkknknuxB gfc ",
      "  fkknknki   fcc",
      "b fffmpst  DFfb ",
      " bfj   r     fc ",
      "  fi i      Ffcb",
      "bcfh      Aggfc ",
      "dcfgi   gwgg!fdb",
      "ccfflfoqqqqoffc ",
      " ecb     b ccceb",
      "bcd       bb cb ",
      " b b        db b",
      "                "
    ],
    [
      "     ee  ee     ",
      " efffeeffeefffe ",
      " cffffffMfffff  ",
      "  f KKKnL  OjI  ",
      "  fnKnKn     I  ",
      "  fuKKKnL    Ic ",
      "  f          f  ",
      "  f          fc ",
      "  I          Ic ",
      "  I        N I  ",
      " cI        gNI  ",
      " cffJfoqqqqoff  ",
      " ec         cce ",
      "                ",
      "                ",
      "                "
    ],
    [
      "     ee  ee     ",
      " efffeeffeefffe ",
      "  ffffffPfffff  ",
      "  fjQQQ      I  ",
      "  f QQQO     I  ",
      "  f QQQ      I  ",
      "  f          f  ",
      "  f          f  ",
      "  I          I  ",
      "  I          I  ",
      "  I          I  ",
      " cffPfoqqqqoff  ",
      " e            e ",
      "                ",
      "                ",
      "                "
    ],
    [
      "     SS  SS     ",
      " eSSSTTSSTTSSSe ",
      "  ffffffffffff  ",
      "  fj   V   V R  ",
      "  f          R  ",
      "  f          R  ",
      "  f          f  ",
      "  f          f  ",
      "  R          R  ",
      "  R          R  ",
      "  R          R  ",
      "  ffffooooooff  ",
      " e     UUUU   e ",
      "                ",
      "                ",
      "                "
    ],
    [
      "                ",
      " e   TT  TT   e ",
      "  ffffffffffff  ",
      "  W          W  ",
      "  W          W  ",
      "  W          W  ",
      "  f  Y    Y  f  ",
      "  f  X    Y  f  ",
      "  W          W  ",
      "  W          W  ",
      "  W          W  ",
      "  ffffWWWWWWff  ",
      " e            e ",
      "                ",
      "                ",
      "                "
    ]
  ]
}