{
  "name": "building_office1_base2_270",
  "refpalette": "c70cities:building_office1_base2_palette_270",
  "xsize": 16,
  "zsize": 16,
  "slices": [
    [
      "vvvvvvvvvvvvvvvv",
      "vaaaaaaaaaaaaaav",
      "vaaaaaaaaaaaaaav",
      "vaaaaaaaaaaaaaav",
      "vaaaaaaaaaaaaaav",
      "vaaaaaaaaaaaaaav",
      "vaaaaaaaa!aaaaav",
      "vaaaaaaaaaaaaaav",
      "vaaaaaaaaaaaaaav",
      "vaaaaaaaa!aaaaav",
      "vaaaaaaaaaaaaaav",
      "vaaaaaaaaaaaaaav",
      "vaaaaaaaaaaaaaav",
      "va!aaaaaaaaaaaav",
      "vaaaaaaaaaaaaaav",
      "vvvvvvvvvvvvvvvv"
    ],
    [
      "vvvvvvvvvvvvvvvv",
      "vbbbbbbbbbbbbbbv",
      "vbsso fiifiifcbv",
      "vb  p   n l  dbv",
      "vb  p       d bv",
      "vb  p    m    bv",
      "vb  o  mmmm   bv",
      "vb  q         bv",
      "vb  r       g bv",
      "vb  o  m mm   bv",
      "vb  p   m     bv",
      "vb  p     d   bv",
      "vb  p  j   j  bv",
      "vbttoehkkhkkhebv",
      "vbbbbbbbbbbbbbbv",
      "vvvvvvvvvvvvvvvv"
    ],
    [
      "vvvvvvvvvvvvvvvv",
      "vbbbbbbbbbbbbbbv",
      "vbsso    l d  bv",
      "vb  p         bv",
      "vb  p         bv",
      "vb  p         bv",
      "vb  o         bv",
      "vb  u         bv",
      "vb  w         bv",
      "vb  o         bv",
      "vb  p         bv",
      "vb  p         bv",
      "vb  p         bv",
      "vbyxo n j   j bv",
      "vbbbbbbbbbbbbbbv",
      "vvvvvvvvvvvvvvvv"
    ],
    [
      "vvvvvvvvvvvvvvvv",
      "vbbbbbbbbbbbbbbv",
      "vbsso         bv",
      "vb  p         bv",
      "vb  p         bv",
      "vb  p         bv",
      "vb  o         bv",
      "vb  o         bv",
      "vb  o         bv",
      "vb  o         bv",
      "vb  p         bv",
      "vb  p         bv",
      "vb  p         bv",
      "vbA o         bv",
      "vbbbbbbbbbbbbbbv",
      "vvvvvvvvvvvvvvvv"
    ],
    [
      "vvvvvvvvvvvvvvvv",
      "vbbbbbbbbbbbbbbv",
      "vbssoBCBBCBBCBbv",
      "vb  p         bv",
      "vb  p         bv",
      "vb  p         bv",
      "vb  p         bv",
      "vb  p         bv",
      "vb  p         bv",
      "vb  p         bv",
      "vb  p         bv",
      "vb  p         bv",
      "vb  p         bv",
      "vb  oBCBBCBBCBbv",
      "vbbbbbbbbbbbbbbv",
      "vvvvvvvvvvvvvvvv"
    ],
    [
      "vvvvvvvvvvvvvvvv",
      "vbbbbbbbbbbbbbbv",
      "vbssoDDDDDDDDDbv",
      "vbDDDDDDDDDDDDbv",
      "vbDDDDDDDDDDDDbv",
      "vbDDDDDDDDDDDDbv",
      "vbDDDDDDDDDDDDbv",
      "vbDDDDFDDgDDgDbv",
      "vbDDDDgDDFDDEDbv",
      "vbDDDDDDDDDDDDbv",
      "vbDDDDDDDDDDDDbv",
      "vbDDDDDDDDDDDDbv",
      "vbDDDDDDDDDDDDbv",
      "vbDDoDDDDDDDDDbv",
      "vbbbbbbbbbbbbbbv",
      "vvvvvvvvvvvvvvvv"
    ]
  ]
}