{
  "name": "building_policeoffice1_base2_180",
  "refpalette": "c70cities:building_policeoffice1_base2_palette_180",
  "xsize": 16,
  "zsize": 16,
  "slices": [
    [
      "vvvvvvvvvvvvvvvv",
      "vaaaaaaaaaaaaaav",
      "vabbbbbbbbbbbbav",
      "vabbbbbbbbbbbbav",
      "vabbbbbbbbbbbbav",
      "vabbbbbbbbbbbbav",
      "vabbbbbbbbbbbbav",
      "vabbbbbbbbbbbbav",
      "vabbbbbbbbbbbbav",
      "vabbbbbbbbbbbbav",
      "vabbbbbbbbbbbbav",
      "vabbbbbbbbbbbbav",
      "vabbbbbbbbbbbbav",
      "vabbbbbbbbbbbbav",
      "vabbbbbbbbbbbbav",
      "vvvvvvvvvvvvvvvv"
    ],
    [
      "vvvvvvvvvvvvvvvv",
      "vccccccccccccccv",
      "vcn       q  ocv",
      "vcnp      i  ocv",
      "vcn  mmm  ccclcv",
      "vckkk   kkkkkkcv",
      "vcj       e hhcv",
      "vc        i  hcv",
      "vc        e   cv",
      "vc        e   cv",
      "vc        e   cv",
      "vc  g     e   cv",
      "vcf       e  dcv",
      "vcff      e ddcv",
      "vccccccccccccccv",
      "vvvvvvvvvvvvvvvv"
    ],
    [
      "vvvvvvvvvvvvvvvv",
      "vccccccccccccccv",
      "vc        s  ocv",
      "vc        r  ocv",
      "vc   mmm  ccclcv",
      "vckkk   kkkkkkcv",
      "vc        e  hcv",
      "vc        r   cv",
      "vc        e   cv",
      "vc        e   cv",
      "vc        e   cv",
      "vc        e   cv",
      "vc        e   cv",
      "vcf       e   cv",
      "vccccccccccccccv",
      "vvvvvvvvvvvvvvvv"
    ],
    [
      "vvvvvvvvvvvvvvvv",
      "vccccccccccccccv",
      "vc        c  ocv",
      "vc        c  ocv",
      "vc   mmm  ccclcv",
      "vckkk   kkkkkkcv",
      "vc        e   cv",
      "vc        e   cv",
      "vc        e   cv",
      "vc        e   cv",
      "vc        e   cv",
      "vc        e   cv",
      "vc        e   cv",
      "vc        e   cv",
      "vccccccccccccccv",
      "vvvvvvvvvvvvvvvv"
    ],
    [
      "vvvvvvvvvvvvvvvv",
      "vccccccccccccccv",
      "vc        c  ocv",
      "vc        ct ocv",
      "vc        ccclcv",
      "vckkkkkkkkkkkkcv",
      "vc        e   cv",
      "vc        e   cv",
      "vc        e   cv",
      "vc        e   cv",
      "vc        e   cv",
      "vc        e   cv",
      "vc        e   cv",
      "vc        e   cv",
      "vccccccccccccccv",
      "vvvvvvvvvvvvvvvv"
    ],
    [
      "vvvvvvvvvvvvvvvv",
      "vccccccccccccccv",
      "vcuuuuuuuucuuocv",
      "vcuuuuuuuucuuocv",
      "vcuuuuuuuuccclcv",
      "vckkkkkkkkkkkkcv",
      "vcuuuuuuuuuuuucv",
      "vcuuuuuuuuuuuucv",
      "vcuuuuuuuuuuuucv",
      "vcuuuuuuuuuuuucv",
      "vcuuuuuuuuuuuucv",
      "vcuuuuuuuuuuuucv",
      "vcuuuuuuuuuuuucv",
      "vcuuuuuuuuuuuucv",
      "vccccccccccccccv",
      "vvvvvvvvvvvvvvvv"
    ]
  ]
}