{
  "name": "building_office4_floor3_180",
  "refpalette": "c70cities:building_office4_floor3_palette_180",
  "xsize": 16,
  "zsize": 16,
  "slices": [
    [
      "                ",
      "    abaaaaba    ",
      "  cccdeeeedccc  ",
      "  ceeeeeeeeeec  ",
      " aceeeeeeeeeeca ",
      " bdeeeeeeeeeedb ",
      " aeeeeeeee!eeea ",
      " aeeeeeeeeeeefa ",
      " aeeeeeeeeeeefa ",
      " aeeeeeeeeeeeea ",
      " bdeeeeeeeeeedb ",
      " aceeeeeeeeeeca ",
      "  ceeeeeeeeeec  ",
      "  cccdeeeedccc  ",
      "    abaaaaba    ",
      "                "
    ],
    [
      "                ",
      "    abaaaaba    ",
      "  gggdnonndggg  ",
      "  g          g  ",
      " ag          ga ",
      " bd          db ",
      " a    m m m   a ",
      " a  l k  k   fa ",
      " a  l k  k   fa ",
      " a    j j j   a ",
      " bd          db ",
      " ag          ga ",
      "  g          g  ",
      "  gggdhhihdggg  ",
      "    abaaaaba    ",
      "                "
    ],
    [
      "                ",
      "    abaaaaba    ",
      "  gggd    dggg  ",
      "  g          g  ",
      " ag          ga ",
      " bd          db ",
      " a            a ",
      " a   qqqqqq  fa ",
      " a   qqqqqq  fa ",
      " a            a ",
      " bd          db ",
      " ag          ga ",
      "  g          g  ",
      "  gggdp   dggg  ",
      "    abaaaaba    ",
      "                "
    ],
    [
      "                ",
      "    abaaaaba    ",
      "  gggd    dggg  ",
      "  g          g  ",
      " ag          ga ",
      " bd          db ",
      " a            a ",
      " a           fa ",
      " a           fa ",
      " a            a ",
      " bd          db ",
      " ag          ga ",
      "  g          g  ",
      "  gggd    dggg  ",
      "    abaaaaba    ",
      "                "
    ],
    [
      "                ",
      "    abaaaaba    ",
      "  gggd    dggg  ",
      "  g          g  ",
      " ag          ga ",
      " bd          db ",
      " a            a ",
      " a           fa ",
      " a           fa ",
      " a            a ",
      " bd          db ",
      " ag          ga ",
      "  g          g  ",
      "  gggd    dggg  ",
      "    abaaaaba    ",
      "                "
    ],
    [
      "                ",
      "    abaaaaba    ",
      "  gggdrrrrdggg  ",
      "  grrrrrrrrrrg  ",
      " agrrrrrrrrrrga ",
      " bdrrrrrrrrrrdb ",
      " arrrrrrrrrrrra ",
      " arrrrrrrrrrrfa ",
      " arrrrrrrrrrrfa ",
      " arrrrrrrrrrrra ",
      " bdrrrrrrrrrrdb ",
      " agrrrrrrrrrrga ",
      "  grrrrrrrrrrg  ",
      "  gggdrrrrdggg  ",
      "    abaaaaba    ",
      "                "
    ]
  ]
}