{
  "name": "building_office3_ground",
  "refpalette": "c70cities:building_office3_ground_palette",
  "xsize": 16,
  "zsize": 16,
  "slices": [
    [
      "GGGGGGGGGGGGGGGG",
      "GaaaaaaaaaaaaaaG",
      "GabbbbbbbbbbbbaG",
      "Gab!bbbbbbbbbbaG",
      "GabbbbbbbbbbbbaG",
      "GabbbbbbbbbbbbaG",
      "GabbbbbbbbbbbbaG",
      "GabbbbbbbbbbbbaG",
      "GabbbbbbbbbbbbaG",
      "GabbbbbbbbbbbbaG",
      "GabbbbbbbbbbbbaG",
      "GabbbbbbbbbbbbaG",
      "GabbbbbbbbbbbbaG",
      "GabbbbbbbbbbbbaG",
      "GaaaaaaaaaaaaaaG",
      "GGGGGGGGGGGGGGGG"
    ],
    [
      "                ",
      " ccdccdccdccdcc ",
      " ceeeefeefeeeec ",
      " deg        ged ",
      " ce          ec ",
      " ce          ec ",
      " df          fd ",
      " ce   hvi     j ",
      " ce    vi     k ",
      " df          fd ",
      " ce          ec ",
      " ce          ec ",
      " deg        ged ",
      " ceeeefeefeeeec ",
      " ccdccdccdccdcc ",
      "                "
    ],
    [
      "                ",
      " ccdccdccdccdcc ",
      " c    l  l    c ",
      " d g        g d ",
      " c            c ",
      " c            c ",
      " dl          ld ",
      " c     vi     m ",
      " c     vi     n ",
      " dl          ld ",
      " c            c ",
      " c            c ",
      " d g        g d ",
      " c    l  l    c ",
      " ccdccdccdccdcc ",
      "                "
    ],
    [
      "                ",
      " oodoodoodoodoo ",
      " o            o ",
      " d g        g d ",
      " o            o ",
      " o            o ",
      " d            d ",
      " o     vi     o ",
      " o     vi     o ",
      " d            d ",
      " o            o ",
      " o            o ",
      " d g        g d ",
      " o            o ",
      " oodoodoodoodoo ",
      "                "
    ],
    [
      "                ",
      " ccdccdccdccdcc ",
      " cppppppppppppc ",
      " dpg        gpd ",
      " cp          pc ",
      " cp          pc ",
      " dp          pd ",
      " cp    vi    pc ",
      " cp    vi    pc ",
      " dp          pd ",
      " cp          pc ",
      " cp          pc ",
      " dpg        gpd ",
      " cppppppppppppc ",
      " ccdccdccdccdcc ",
      "                "
    ],
    [
      "                ",
      " qqqqqqqqqqqqqq ",
      " qaaaaaaaaaaaaq ",
      " qarddddddddraq ",
      " qaddddddddddaq ",
      " qaddddddddddaq ",
      " qaddddddddddaq ",
      " qaddddviddddaq ",
      " qaddddviddddaq ",
      " qaddddddddddaq ",
      " qaddddddddddaq ",
      " qaddddddddddaq ",
      " qarddddddddraq ",
      " qaaaaaaaaaaaaq ",
      " qqqqqqqqqqqqqq ",
      "                "
    ]
  ]
}