{
  "name": "building_bank1_top_270",
  "refpalette": "c70cities:building_bank1_top_palette_270",
  "xsize": 16,
  "zsize": 16,
  "slices": [
    [
      "                ",
      "  abbbc abbbc   ",
      "  deeeedeeeeeda ",
      " ceeee     eeeb ",
      " beeeeeeeeeeeeb ",
      " beeeeeeeeeeeeb ",
      " beeeeeeeeeeeec ",
      " aeeeeeeeeeeed  ",
      "  deeeeeeeeeeea ",
      " ceeeeeeeeeeeeb ",
      " beeeeeeeeeeeeb ",
      " beeeeeeeeeeeeb ",
      " beeeeeeeeeeeec ",
      " adeeeeedeeeed  ",
      "   cbbba cbbba  ",
      "                "
    ],
    [
      "                ",
      " fbcc abbcc abf ",
      " bgggghggggghgb ",
      " ahut        gc ",
      "  gwt        gc ",
      " cgwt        g  ",
      " cgwt  m m   ha ",
      " bgut        gb ",
      " bgut qnonj  gb ",
      " ahwt r   k  gc ",
      "  gwt s p l  gc ",
      " cgwt s      g  ",
      " cgxt       iha ",
      " bghggggghggggb ",
      " fba ccbba ccbf ",
      "                "
    ],
    [
      "                ",
      " fbbbbbbbbbbbbf ",
      " bgggghggggghgb ",
      " bhw         gb ",
      " bgw         gb ",
      " bgw         gb ",
      " bgw         hb ",
      " bgw         gb ",
      " bgw  A   y  gb ",
      " bhw         gb ",
      " bgw  s      gb ",
      " bgw  s      gb ",
      " bgw         hb ",
      " bghggggghggggb ",
      " fbbbbbbbbbbbbf ",
      "                "
    ],
    [
      "                ",
      "                ",
      "   gghggggghg   ",
      "  gg        gg  ",
      "  h          g  ",
      "  g          h  ",
      "  g          g  ",
      "  g          g  ",
      "  g          g  ",
      "  g          g  ",
      "  h          g  ",
      "  g          h  ",
      "  gg        gg  ",
      "   ghggggghgg   ",
      "                ",
      "                "
    ],
    [
      "                ",
      "                ",
      "                ",
      "    gggggggg    ",
      "   gggggggggg   ",
      "   gggB   ggg   ",
      "   gg      gg   ",
      "   gg      gg   ",
      "   gg      gg   ",
      "   gg      gg   ",
      "   ggg   Bggg   ",
      "   gggggggggg   ",
      "    gggggggg    ",
      "                ",
      "                ",
      "                "
    ],
    [
      "                ",
      "                ",
      "                ",
      "                ",
      "                ",
      "      gggg      ",
      "     gggggg     ",
      "     gggggg     ",
      "     gggggg     ",
      "     gggggg     ",
      "      gggg      ",
      "                ",
      "                ",
      "                ",
      "                ",
      "                "
    ]
  ]
}