{
  "name": "building_restaurant1_base1",
  "refpalette": "c70cities:building_restaurant1_base1_palette",
  "xsize": 16,
  "zsize": 16,
  "slices": [
    [
      "vvvvvvvvvvvvvvvv",
      "v==============v",
      "v=avvvvvvvvvvv=v",
      "v=vvvvvvvvvvvv=v",
      "v=vvvvvvvvvvvv=v",
      "v=vvvvvvvvvvvv=v",
      "v=vvvvvv!vvvvv=v",
      "v=vvvvvvvvvvvv=v",
      "v=vvvvvvvvvvvv=v",
      "v=vvvvvvvvvvvv=v",
      "v=bccccccccccb=v",
      "v=bdddcccccccb=v",
      "v=bdddcccccccb=v",
      "v=bdddccccc!cb=v",
      "v=bbbbbbbbbbbb=v",
      "vvvvvvvvvvvvvvvv"
    ],
    [
      "vvvvvvvvvvvvvvvv",
      "v==============v",
      "v=ae      fghi=v",
      "v=jj        ki=v",
      "v=jjj  l     m=v",
      "v=j    lln    =v",
      "v=    nlllo   =v",
      "v=    lllll   =v",
      "v=k     ll   p=v",
      "v=hk       q r=v",
      "v=bdddq q sqqb=v",
      "v=btttd s  s b=v",
      "v=btttd   s ub=v",
      "v=btttd u uwxb=v",
      "v=bbbbbbbbbbbb=v",
      "vvvvvvvvvvvvvvvv"
    ],
    [
      "vvvvvvvvvvvvvvvv",
      "v==============v",
      "v=ae        gk=v",
      "v=j          y=v",
      "v=j           =v",
      "v=      l     =v",
      "v=     ll     =v",
      "v=     lll    =v",
      "v=            =v",
      "v=g          A=v",
      "v=bqqq     qqb=v",
      "v=b          b=v",
      "v=b          b=v",
      "v=b         ub=v",
      "v=bbbbbbbbbbbb=v",
      "vvvvvvvvvvvvvvvv"
    ],
    [
      "vvvvvvvvvvvvvvvv",
      "v==============v",
      "v=ae          =v",
      "v=j           =v",
      "v=            =v",
      "v=            =v",
      "v=      n     =v",
      "v=      l     =v",
      "v=            =v",
      "v=            =v",
      "v=bqq       qb=v",
      "v=b          b=v",
      "v=b          b=v",
      "v=bB         b=v",
      "v=bbbbbbbbbbbb=v",
      "vvvvvvvvvvvvvvvv"
    ],
    [
      "vvvvvvvvvvvvvvvv",
      "v==============v",
      "v=ae          =v",
      "v=            =v",
      "v=            =v",
      "v=            =v",
      "v=            =v",
      "v=            =v",
      "v=            =v",
      "v=     q      =v",
      "v=bqqqqqq qqqb=v",
      "v=b          b=v",
      "v=b          b=v",
      "v=bC         b=v",
      "v=bbbbbbbbbbbb=v",
      "vvvvvvvvvvvvvvvv"
    ],
    [
      "vvvvvvvvvvvvvvvv",
      "v==============v",
      "v=aeDDDDDDDDDD=v",
      "v=DDDDDDDDDDDD=v",
      "v=DDDDDDDDDDDD=v",
      "v=DDDDDDDDDDDD=v",
      "v=DDDDDDDDDDDD=v",
      "v=DDDDDDDDDDDD=v",
      "v=DDDDDDDDDDDD=v",
      "v=DDDDDDDDDDDD=v",
      "v=bddddddddddb=v",
      "v=bddddddddddb=v",
      "v=bddddddddddb=v",
      "v=bEdddddddddb=v",
      "v=bbbbbbbbbbbb=v",
      "vvvvvvvvvvvvvvvv"
    ]
  ]
}