{
  "name": "building_policeoffice1_base2_270",
  "refpalette": "c70cities:building_policeoffice1_base2_palette_270",
  "xsize": 16,
  "zsize": 16,
  "slices": [
    [
      "vvvvvvvvvvvvvvvv",
      "vaaaaaaaaaaaaaav",
      "vabbbbbbbbbbbbbv",
      "vabbbbbbbbbbbbbv",
      "vabbbbbbbbbbbbbv",
      "vabbbbbbbbbbbbbv",
      "vabbbbbbbbbbbbbv",
      "vabbbbbbbbbbbbbv",
      "vabbbbbbbbbbbbbv",
      "vabbbbbbbbbbbbbv",
      "vabbbbbbbbbbbbbv",
      "vabbbbbbbbbbbbbv",
      "vabbbbbbbbbbbbbv",
      "vabbbbbbbbbbbbbv",
      "vaaaaaaaaaaaaaav",
      "vvvvvvvvvvvvvvvv"
    ],
    [
      "vvvvvvvvvvvvvvvv",
      "vccccccccccccccv",
      "vcoolkhh    ddcv",
      "vc  ckh      dcv",
      "vc  ck        cv",
      "vcqickeieeeeeecv",
      "vc   k        cv",
      "vc   k        cv",
      "vc  m         cv",
      "vc  m         cv",
      "vc  m         cv",
      "vc   k     g  cv",
      "vc p k       fcv",
      "vcnnnkj     ffcv",
      "vccccccccccccccv",
      "vvvvvvvvvvvvvvvv"
    ],
    [
      "vvvvvvvvvvvvvvvv",
      "vccccccccccccccv",
      "vcoolkh       cv",
      "vc  ck        cv",
      "vc  ck        cv",
      "vcsrckereeeeeecv",
      "vc   k        cv",
      "vc   k        cv",
      "vc  m         cv",
      "vc  m         cv",
      "vc  m         cv",
      "vc   k        cv",
      "vc   k        cv",
      "vc   k       fcv",
      "vccccccccccccccv",
      "vvvvvvvvvvvvvvvv"
    ],
    [
      "vvvvvvvvvvvvvvvv",
      "vccccccccccccccv",
      "vcoolk        cv",
      "vc  ck        cv",
      "vc  ck        cv",
      "vcccckeeeeeeeecv",
      "vc   k        cv",
      "vc   k        cv",
      "vc  m         cv",
      "vc  m         cv",
      "vc  m         cv",
      "vc   k        cv",
      "vc   k        cv",
      "vc   k        cv",
      "vccccccccccccccv",
      "vvvvvvvvvvvvvvvv"
    ],
    [
      "vvvvvvvvvvvvvvvv",
      "vccccccccccccccv",
      "vcoolk        cv",
      "vc  ck        cv",
      "vc tck        cv",
      "vcccckeeeeeeeecv",
      "vc   k        cv",
      "vc   k        cv",
      "vc   k        cv",
      "vc   k        cv",
      "vc   k        cv",
      "vc   k        cv",
      "vc   k        cv",
      "vc   k        cv",
      "vccccccccccccccv",
      "vvvvvvvvvvvvvvvv"
    ],
    [
      "vvvvvvvvvvvvvvvv",
      "vccccccccccccccv",
      "vcoolkuuuuuuuucv",
      "vcuuckuuuuuuuucv",
      "vcuuckuuuuuuuucv",
      "vcccckuuuuuuuucv",
      "vcuuukuuuuuuuucv",
      "vcuuukuuuuuuuucv",
      "vcuuukuuuuuuuucv",
      "vcuuukuuuuuuuucv",
      "vcuuukuuuuuuuucv",
      "vcuuukuuuuuuuucv",
      "vcuuukuuuuuuuucv",
      "vcuuukuuuuuuuucv",
      "vccccccccccccccv",
      "vvvvvvvvvvvvvvvv"
    ]
  ]
}