{
  "name": "building_office1_top_180",
  "refpalette": "c70cities:building_office1_top_palette_180",
  "xsize": 16,
  "zsize": 16,
  "slices": [
    [
      "                ",
      " eeeeeeeeeeeeee ",
      " ebbbbbbbbbbbbe ",
      " ebbbbbbbbbbbbe ",
      " efbbbbbbbbbgfe ",
      "  dbbbbbbbbbbd  ",
      "  dbbbbbbbbbbd  ",
      " ccbbbbbbbbbbcc ",
      "  abbbbbbbbbba  ",
      "  abbbbbbbbbba  ",
      "  abbbbbbbbbba  ",
      "  abbbbbbbbbba  ",
      "  abbbbbbbbbba  ",
      "  aaaaaaaaaaaa  ",
      "                ",
      "                "
    ],
    [
      "                ",
      " mmmmmmmmmmmmmm ",
      " m     nn     m ",
      " m            m ",
      " mf          fm ",
      "  d          d  ",
      "  d          d  ",
      " ccl        lcc ",
      "  h ii    ii h  ",
      "  h ij kk ji h  ",
      "  h ij kk ji h  ",
      "  h ii    ii h  ",
      "  h          h  ",
      "  hhhhhhhhhhhh  ",
      "                ",
      "                "
    ],
    [
      "                ",
      " mmqddddddddqmm ",
      " m            m ",
      " m            m ",
      " mf          fm ",
      "  d          d  ",
      "  d          d  ",
      " ccp        pcc ",
      "  o          o  ",
      "                ",
      "  o          o  ",
      "                ",
      "  o          o  ",
      "                ",
      "                ",
      "                "
    ],
    [
      "                ",
      " mmqddddddddqmm ",
      " m            m ",
      " m            m ",
      " mf          fm ",
      "  d          d  ",
      "  d          d  ",
      " cc          cc ",
      "  o          o  ",
      "                ",
      "  o          o  ",
      "                ",
      "  o          o  ",
      "                ",
      "                ",
      "                "
    ],
    [
      "                ",
      " mmmmmmmmmmmmmm ",
      " m            m ",
      " m            m ",
      " mffffffffffffm ",
      "  frrrrrrrrrrf  ",
      "  frrrrrrrrrrf  ",
      " ccffffffffffcc ",
      "  o          o  ",
      "                ",
      "  o          o  ",
      "                ",
      "  o          o  ",
      "                ",
      "                ",
      "                "
    ],
    [
      "                ",
      " mmmmmmmmmmmmmm ",
      " mrrrrrrrrrrrrm ",
      " mrrrrrrrrrrrrm ",
      " mrrrrrrrrrrrrm ",
      "                ",
      "                ",
      " ccsssssssssscc ",
      "  seeeeeeeeees  ",
      "  seeeeeeeeees  ",
      "  seeeeeeeeees  ",
      "  seeeeeeeeees  ",
      "  seeeeeeeeees  ",
      "  ssssssssssss  ",
      "                ",
      "                "
    ]
  ]
}