{
  "name": "building_hotel1_floor1",
  "refpalette": "c70cities:building_hotel1_floor1_palette",
  "xsize": 16,
  "zsize": 16,
  "slices": [
    [
      "                ",
      " aaaaaaaaaaaaaa ",
      " abbbbbbbbbbbba ",
      " abbbbbbbbbbbba ",
      " abbbbbbbbbbbba ",
      " acccccccccccca ",
      " dbbbb    dbbba ",
      " dbbbb    bbbba ",
      " dbbbb    bbbba ",
      " dbbbb   ebbbbf ",
      " dbbbbbbbbbbbbf ",
      " dbbbbbbbbbbbbf ",
      " dbbbbbbbbbbbbf ",
      " abbbbbbbbbbbba ",
      " aaaaaaagggggaa ",
      "                "
    ],
    [
      "                ",
      " aaaaaaaaaaaaaa ",
      " ah        iiia ",
      " a            a ",
      " ajklmmnok  p a ",
      " aaaaaaaaaa qqa ",
      " a            a ",
      " ar s     t   a ",
      " a u      t  ua ",
      " ar s  eed    f ",
      " a            f ",
      " a            f ",
      " a            f ",
      " arus rus rusua ",
      " aaaaaaaaaaaaaa ",
      "                "
    ],
    [
      "                ",
      " aaaaaaaaaaaaaa ",
      " a            a ",
      " a            a ",
      " a  w   x     a ",
      " aaaaaaaaaa   a ",
      " f            a ",
      " f y          a ",
      " f y  e      Aa ",
      " f y  ed      f ",
      " a            f ",
      " a            f ",
      " a            f ",
      " a y   y   y Aa ",
      " aaffffffaaaaaa ",
      "                "
    ],
    [
      "                ",
      " aaaaaaaaaaaaaa ",
      " a            a ",
      " a            a ",
      " a            a ",
      " aaaaaaaaaa   a ",
      " a    e       a ",
      " a    e       a ",
      " a    d      Aa ",
      " a            f ",
      " a            f ",
      " a            f ",
      " a            f ",
      " a           Aa ",
      " aaaaaaaaaaaaaa ",
      "                "
    ],
    [
      "                ",
      " aaaaaaaaaaaaaa ",
      " a            a ",
      " f            a ",
      " f            a ",
      " aaaaaaaaaaaaaa ",
      " a    dee     a ",
      " a            a ",
      " a            a ",
      " a            f ",
      " a            f ",
      " a            f ",
      " a            f ",
      " a            a ",
      " aaaaaaffaaaaaa ",
      "                "
    ],
    [
      "                ",
      " aaaaaaaaaaaaaa ",
      " aBBBBBBBBBBBBa ",
      " aBBBBBBBBBBBBa ",
      " aBBBBBBBBBBBBa ",
      " aaaaaaaaaaaaaa ",
      " aBBBB  deBBBBa ",
      " aBBBB    BBBBa ",
      " aBBBB    BBBBa ",
      " aBBBB    BBBBf ",
      " aBBBBBBBBBBBBf ",
      " aBBBBBBBBBBBBf ",
      " aBBBBBBBBBBBBf ",
      " aBBBBBBBBBBBBa ",
      " aaaaaaaaaaaaaa ",
      "                "
    ]
  ]
}