{
  "name": "building_bunker1_base1_270",
  "refpalette": "c70cities:building_bunker1_base1_palette_270",
  "xsize": 16,
  "zsize": 16,
  "slices": [
    [
      "================",
      "================",
      "================",
      "================",
      "=aa=aa==========",
      "=aa=aa==========",
      "=aa=aa==========",
      "==a=a===========",
      "=aaaaa====aaaa==",
      "=aaaaa====aaaa==",
      "==========aaaa==",
      "==========aaaa==",
      "==========aaaa==",
      "==========aaaa==",
      "================",
      "================"
    ],
    [
      "zzzzzzbbbbbbbbbz",
      "zzzzzzbAs oljcbz",
      "zzzzzzbB     cbz",
      "bbbbbbbbbbb  bbz",
      "bJNbNJbowsb  dbz",
      "bK b Kb  sb  dbz",
      "bT b Lb   b  dbz",
      "bbObObEbxbbmbbbz",
      "bU   nbn tp  ebz",
      "bU    F      fbz",
      "bbRbbbbC     ebz",
      "bV bP     q  gbz",
      "bW bQ   y r  hbz",
      "bXSbIMIDyuqnkibz",
      "bbbbbbbbbbbbbbbz",
      "zzzzzzzzzzzzzzzz"
    ],
    [
      "zzzzzzEEEEEEEEEz",
      "zzzzzzEA@  o 0Ez",
      "zzzzzzE$     1Ez",
      "EEEEEEEEEEE  EEz",
      "E}-E&0E wsE   Ez",
      "E\\ E 1E   E   Ez",
      "ET E LE   E   Ez",
      "EE*E*EEE#EE5EEEz",
      "ET   6E6  7  LEz",
      ";     %      2Ez",
      "EE[EEEE      3Ez",
      "E|]E(         Yz",
      "E`]E)     8   Yz",
      "E: E+ ^   96  Yz",
      "E{{EEEEEEEEE44Zz",
      "zzzzzzzzzzzzzzzz"
    ],
    [
      "zzzzzzEEEEEEEEEz",
      "zzzzzzEA     0Ez",
      "zzzzzzE!     1Ez",
      "EEEEEEEEEEE  EEz",
      "Ef E fE w E  'Ez",
      "E  E /E   E  'Ez",
      "E <E< E   E  'Ez",
      "EEEEEEEE{EEEEEEz",
      "E\u00a7   6E6     ,Ez",
      "E\u00a7    E      ,Ez",
      "EEEEEEE      ,Ez",
      "E \u00a4E>        ,Ez",
      "E\u00c0\u00a5E?        ,Ez",
      "E\u00c1 E\u00a3..    6 ,Ez",
      "EEEEEEEEEEEEEEEz",
      "zzzzzzzzzzzzzzzz"
    ],
    [
      "zzzzzzEEEEEEEEEz",
      "zzzzzzEA\u00c2\u00c2\u00c4\u00c2\u00c2\u00c2Ez",
      "zzzzzzE\u00c2\u00c2\u00c2\u00c4\u00c2\u00c2\u00c2Ez",
      "EEEEEEEEEEE\u00c4\u00c5EEz",
      "E\u00c4\u00c5E\u00c5\u00c4EEwEE\u00c2\u00c2\u00c3Ez",
      "E\u00c2\u00c2E\u00c2\u00c2EEEEE\u00c2\u00c2\u00c3Ez",
      "E\u00c2\u00c2E\u00c2\u00c2EEEEE\u00c2\u00c2\u00c3Ez",
      "EEEEEEEEEEEEEEEz",
      "E\u00c4\u00c2\u00c2\u00c2\u00c2E\u00c2\u00c2\u00c2\u00c2\u00c2\u00c2\u00c4Ez",
      "E\u00c4\u00c2\u00c2\u00c2\u00c2E\u00c2\u00c2\u00c2\u00c2\u00c2\u00c2\u00c4Ez",
      "EEEEEEE\u00c2\u00c2\u00c2\u00c2\u00c2\u00c2\u00c4Ez",
      "E\u00c2\u00c2EEEE\u00c2\u00c2\u00c2\u00c2\u00c2\u00c2\u00c4Ez",
      "E\u00c2\u00c2E\u00c4\u00c4\u00c4\u00c2\u00c2\u00c2\u00c2\u00c2\u00c2\u00c4Ez",
      "E\u00c4\u00c4EEEE\u00c2\u00c2\u00c2\u00c2\u00c2\u00c2\u00c4Ez",
      "EEEEEEEEEEEEEEEz",
      "zzzzzzzzzzzzzzzz"
    ],
    [
      "zzzzzzzzzzzzzzzz",
      "zzzzzzzzzzzzzzzz",
      "zzzzzzzzzzzzzzzz",
      "zzzzzzzzEzzzzzzz",
      "zzzzzzzEwEzzzzzz",
      "zzzzzzzzEzzzzzzz",
      "zzzzzzzzzzzzzzzz",
      "zzzzzzzzzzzzzzzz",
      "zzzzzzzzzzzzzzzz",
      "zzzzzzzzzzzzzzzz",
      "zzzzzzzzzzzzzzzz",
      "zzzzzzzzzzzzzzzz",
      "zzzzzzzzzzzzzzzz",
      "zzzzzzzzzzzzzzzz",
      "zzzzzzzzzzzzzzzz",
      "zzzzzzzzzzzzzzzz"
    ]
  ]
}