{
  "name": "building_gasstation1_ground_90",
  "refpalette": "c70cities:building_gasstation1_ground_palette_90",
  "xsize": 16,
  "zsize": 16,
  "slices": [
    [
      "GGGGGGGGGGGGGGGG",
      "GGGGGGGGGGGGGGGG",
      "GGGaaaaaaaaaaGGG",
      "GGGaaaaaaaaaaGGG",
      "GGGaaaaaaaaaaGGG",
      "GbbaaaaaaaaaabbG",
      "GHHaaaaaaaaaaHHG",
      "GHHaaaaaaaaaaHHG",
      "GHHaaaaaaaaaaHHG",
      "GHHHHHHHHHHHHHHG",
      "GHHHHHHHHHHHHHHG",
      "GHHaaaaaaaaaaHHG",
      "GHHHHHHHHHHHHHHG",
      "GHHHHHHHHHHHHHHG",
      "GHHHHHHHHHHHHHHG",
      "GaHHHHHHHHHHHHHG"
    ],
    [
      "                ",
      "                ",
      "   jjjjjjjjjj   ",
      "   jpro  B  j   ",
      "   j!ro  jDFj   ",
      " ffjo o  jjjjff ",
      " ehjn       jeh ",
      "   jn    A Ej   ",
      " dgjjquxqjCCjdg ",
      "                ",
      "                ",
      "   im iwyim i   ",
      "    l tl tl t   ",
      "    k sk sk s   ",
      "                ",
      " c              "
    ],
    [
      "                ",
      "                ",
      "   jjjjjjjjjj   ",
      "   jo o  O  j   ",
      "   jK r  j Qj   ",
      "   jp o  jjjj   ",
      "   jJ       j   ",
      "   jJ    N  j   ",
      "   jjqLMqjPPj   ",
      "                ",
      "                ",
      "   iI i  iI i   ",
      "                ",
      "                ",
      "                ",
      " c              "
    ],
    [
      "                ",
      "                ",
      "   SVVSVVSVVS   ",
      "   S     j  S   ",
      "   Sr    j  S   ",
      "   S     jjjS   ",
      "   SU       S   ",
      "   ST       S   ",
      "   SSSSSSSSSS   ",
      "                ",
      "                ",
      "   i  i  i  i   ",
      "                ",
      "                ",
      "                ",
      " R              "
    ],
    [
      "                ",
      "                ",
      "   jjjjjjjjjj   ",
      "   jr    jZZj   ",
      "   j     jZZj   ",
      "   jjjjjjjjjj   ",
      "   jX Y  W  j   ",
      "   jr       j   ",
      "   jjjjjjjjjj   ",
      "                ",
      "   W  W  Y  W   ",
      "   j  j  j  j   ",
      "                ",
      "                ",
      "                ",
      "                "
    ],
    [
      "                ",
      "  000000000000  ",
      "  0aaaaaaaaaa0  ",
      "  0affffffffa0  ",
      "  0affffffffa0  ",
      "  0aaaaaaaaaa0  ",
      "  0affffffffa0  ",
      "  0affffffffa0  ",
      "  0aaaaaaaaaa0  ",
      "  0affffffffa0  ",
      "  0affffffffa0  ",
      "  0aaaaaaaaaa0  ",
      "  0ffffffffff0  ",
      "  0ffffffffff0  ",
      "  000000000000  ",
      "                "
    ]
  ]
}