{
  "name": "building_warehouse2_ground_270",
  "refpalette": "c70cities:building_warehouse2_ground_palette_270",
  "xsize": 16,
  "zsize": 16,
  "slices": [
    [
      "azzzzazzzzzaazzz",
      "aaaaazaazzaazaaa",
      "zzaaaaaaaaaaaaaz",
      "zaaaaaaaaaaaaaza",
      "zdbbbddbdbbddbbz",
      "zbbbbbbbbbbbbbbz",
      "zbbbbbbcccccccbz",
      "zbbbbbbcccccccbz",
      "zdbbbbbcccccccbz",
      "zbbbbbbcccccccbz",
      "zbbbbbbcccccccbz",
      "zbbbbbbcccccccbz",
      "zdbbbbbcccccccbz",
      "zdbbbdbcccccccbz",
      "zbbbdbbbbbbbbbbz",
      "zzzzzzzzzzzzzzzz"
    ],
    [
      "  e e  e  e     ",
      "     e      e   ",
      "e               ",
      "                ",
      "u              e",
      "  fg  g   fhhhf ",
      "  ggrrg o     ge",
      "e gs  g     l g ",
      "  ft      o   ge",
      "  w         lig ",
      "e x     p i kjg ",
      "e g      iinikge",
      "e gfrrg njikkkf ",
      "  fg  fqjiikmkg ",
      "u     ffggfgffge",
      " e ue  e e    e "
    ],
    [
      "                ",
      "                ",
      "                ",
      "                ",
      "                ",
      "  gg  fhhhghhhg ",
      "  ffrrg       g ",
      "  f   g       f ",
      "  gy          g ",
      "  A          nr ",
      "  B       l   r ",
      "  g       i  jf ",
      "  ggrrg   ijikg ",
      "  gf  gq niikmf ",
      "      fggfggggg ",
      "                "
    ],
    [
      "                ",
      "                ",
      "                ",
      "                ",
      "                ",
      "  gg  ghhhghhhf ",
      "  ggrrf   j   g ",
      "  f   g       g ",
      "  gD  C       g ",
      "  E   C       g ",
      "  E   C       g ",
      "  f   C       g ",
      "  ggrrf   l  jg ",
      "  gf  gq   i !f ",
      "      gggfggfgf ",
      "                "
    ],
    [
      "                ",
      "                ",
      "                ",
      "                ",
      " FFFFFFFFFFFFF  ",
      " FggKKfgfgggggg ",
      " FggIIgIIIjIIIg ",
      " Fg   f       g ",
      " FgJ  gE  J   f ",
      " Fg   gE      g ",
      " Fg   gE      g ",
      " FgJ  gE      g ",
      " FggIIg       g ",
      " FggFFgq     jf ",
      " FFFFFgggggfggg ",
      "                "
    ],
    [
      "                ",
      "                ",
      "                ",
      "                ",
      "                ",
      "  MMMMfggfgggfg ",
      "  MMMMgLLLLLLLg ",
      "  MMMMgLLLLLLLg ",
      "  MMMMgLLLbLLLg ",
      "  MMMMgLLLLLLLg ",
      "  MMMMgLLLLLLLf ",
      "  MMMMgLLLLLLLg ",
      "  MMMMgLLLLLLLg ",
      "  MMMMgqLLLLLLg ",
      "      gfggggggg ",
      "                "
    ]
  ]
}