{
  "name": "building_residential1_ground",
  "refpalette": "c70cities:building_residential1_ground_palette",
  "xsize": 16,
  "zsize": 16,
  "slices": [
    [
      "GGGGGGGGGGGGGGGG",
      "GGGGGGGGGGGGGGGG",
      "GGaaaaaaaaaaaaGG",
      "GGabbbbbbbbbbaGG",
      "GGabbbbbbbbbbaGG",
      "GGabbbbbbbbbbaGG",
      "GGabbbbbbbbbbaGG",
      "GGabbbbbbbbbbaGG",
      "GGacddddddeecaGG",
      "GGGcddddddeecGGG",
      "GGGcddddddeecGGG",
      "GGGcddddddeecGGG",
      "GGGccccccccccGGG",
      "GGGGGGGGGGGGGGGG",
      "GGGGGGGGGGGGGGGG",
      "GGGGGGGGGGGGGGGG"
    ],
    [
      "fgggghgggghggggf",
      "f              g",
      "i jjkkkjjkkkjj g",
      "  l    mm    k g",
      "  n          k g",
      "f jooo pq   rj f",
      "g ks   ttttt k g",
      "g ku    w    k g",
      "g jcxx    yycj g",
      "g AcBBC   DEcA g",
      "h Ac      F cA h",
      "g AcIJKLJ!FMcA g",
      "g AccccccccccA g",
      "g AAAAAAAAAAAA g",
      "g              g",
      "fgggghgggghggggf"
    ],
    [
      "fgggghgggghggggf",
      "f              g",
      "  jjkkkjjkkkjj g",
      "  N    OO    k g",
      "  P          k g",
      "f jooo      Qj f",
      "g k    ttttt k g",
      "g k      w   k g",
      "g jcR     yycj g",
      "g  c  S   T c  g",
      "h  U      F V  h",
      "g  cW  X  F c  g",
      "g  cccUUUUccc  g",
      "g              g",
      "g              g",
      "fgggghgggghggggf"
    ],
    [
      "                ",
      "                ",
      "  jjYYYjjYYYjj  ",
      "  Z          0  ",
      "  Z          0  ",
      "  jooo       j 1",
      "  Z    ttttt 0  ",
      "  Z       w  0  ",
      "  jc      yycj  ",
      "   c      F c   ",
      "   U      F V   ",
      "   c      F c   ",
      "   cccccccccc   ",
      "  222222222222  ",
      "                ",
      "                "
    ],
    [
      "                ",
      "                ",
      "  jjjjjjjjjjjj  ",
      "  jbbbbbbbbbbj  ",
      "  jbbbbbbbbbbj  ",
      "  jbbbbbbbbbbj  ",
      "  jbbbbbbbbbbj  ",
      "  j        wbj  ",
      "  jc      yycj  ",
      "   c      34c   ",
      "   c      34c   ",
      "  2c22222234c2  ",
      "  555555555555  ",
      "  666666666666  ",
      "                ",
      "                "
    ],
    [
      "                ",
      " 77777777777777 ",
      "  jjjjjjjjjjjj  ",
      "  k8999 @#  $k  ",
      "  kZ%^9 &*(  k  ",
      "  kZ%^9 )+   k  ",
      "  k 999      k  ",
      "  k--------- k  ",
      "  jc      yycj  ",
      "  2c222222F[c2  ",
      "  555555555555  ",
      "  666666666666  ",
      "                ",
      "                ",
      "                ",
      "                "
    ]
  ]
}