{
  "name": "building_restaurant2_ground_180",
  "refpalette": "c70cities:building_restaurant2_ground_palette_180",
  "xsize": 16,
  "zsize": 16,
  "slices": [
    [
      "GGGGGGGGGGGGGGGG",
      "GccccbbaaaaGGGGG",
      "GcccccccccccaGGG",
      "GcccceggfegcaGGG",
      "GcccceddfedcaGGG",
      "GbaggfeggfecaGGG",
      "GbaddfeddfecaGGa",
      "GaagfeggfegcabaG",
      "Gaadfeddfedcaaaa",
      "GbaggfeggfecaGbG",
      "GaaddfeddfecaGGG",
      "GcccceggfegcaGGG",
      "GcccceddfedcbGGG",
      "GcccccccccccaGGG",
      "GccccabaaaaGGGGG",
      "GGGGGGGGGGGGGGGG"
    ],
    [
      "                ",
      " iiiiSRRRQih    ",
      " iPOimmmmmmmm   ",
      " i  E     pms   ",
      " iiii      mq   ",
      " NiM LKJt pmo   ",
      " DiC BmAt imm   ",
      " DiC BmAt I     ",
      " DiF BmAt E     ",
      " DiC BmAt imm   ",
      " yi  xwut pms   ",
      " iiri      mq   ",
      " in i     pmo   ",
      " innimmmmmmmm   ",
      " iiiilkkkjih    ",
      "                "
    ],
    [
      "                ",
      " iiii     iT    ",
      " i@ imUUUmmmm   ",
      " i  3      UX   ",
      " iiii      UX   ",
      " Xi9  81   UX   ",
      " Xi! 201  imm   ",
      " Xi7  01  6     ",
      " Xi5 401  3     ",
      " Xi  201  imm   ",
      " Xi   0Z   UX   ",
      " iiYi      UX   ",
      " i  i      UX   ",
      " iWVimUUUmmmm   ",
      " iiii     iT    ",
      "                "
    ],
    [
      "                ",
      " iiiiXXXXXiT    ",
      " U  immmmmmmm   ",
      " U  i)(((* UX   ",
      " iiii      UX   ",
      " Xi   ^%   UX   ",
      " Xi   ^%  imm   ",
      " Xi   ^%  i &   ",
      " Xi   ^%  i &   ",
      " Xi   ^%  imm   ",
      " Xi   ^%   UX   ",
      " iiii      UX   ",
      " U  iW$$$V UX   ",
      " U #immmmmmmm   ",
      " iiiiXXXXXiT    ",
      "                "
    ],
    [
      "                ",
      " iiii+++++i     ",
      " +  immmmmmmm-  ",
      " +  i]]]]]ii+   ",
      " iiii     ii+   ",
      " +i       ii+   ",
      " +i       imm-  ",
      " +i       i &   ",
      " +i       i &   ",
      " +i       imm-  ",
      " +i       ii+   ",
      " iiii     ii+   ",
      " +  i[[[[[ii+   ",
      " +  immmmmmmm-  ",
      " iiii+++++i     ",
      "                "
    ],
    [
      "                ",
      " iiiiiiiiii{{{{ ",
      " i\\\\}mmmmmm{{{{ ",
      " i\\\\}PPPPP}{{{{ ",
      " iii}PPPPP}{{{{ ",
      " }i}}|||||}{{{{ ",
      " }i}}PPPPP}{{{{ ",
      " }i}}PPPPP}{{{{ ",
      " }i}}PPPPP}{{{{ ",
      " }i}}PPPPP}{{{{ ",
      " }i}}|||||}{{{{ ",
      " iii}PPPPP}{{{{ ",
      " i\\\\}PPPPP}{{{{ ",
      " i\\\\}mmmmmm{{{{ ",
      " iiiiiiiiii{{{{ ",
      "                "
    ]
  ]
}