{
  "name": "building_hotel1_ground_180",
  "refpalette": "c70cities:building_hotel1_ground_palette_180",
  "xsize": 16,
  "zsize": 16,
  "slices": [
    [
      "GGGGGGGGGGGGGGGG",
      "GbbbbbbbbbbbbbbG",
      "Gbccccccccccc!bG",
      "GdccccccccccccbG",
      "GdccccccccccccbG",
      "GdccccccccccccbG",
      "GdccccddddccccbG",
      "GbccccGGGdccccbG",
      "GbccccGGGdccccbG",
      "GbccccGGG!ccccbG",
      "GbccccccccccccbG",
      "GbccccccccccccbG",
      "GbccccccccccccbG",
      "GbccccccccccccbG",
      "GbbbbbbbbbbbbbbG",
      "GGGGaGGGGGGaGGGG"
    ],
    [
      "                ",
      " bbbbbbbbbbbbbb ",
      " bm  B A   byxb ",
      " po  wuuuu b  b ",
      "  t   s s  brbb ",
      "  q           b ",
      " po   nggl   kb ",
      " bm   e  l   kb ",
      " b    e  l   kb ",
      " b    eeel   kb ",
      " b           jb ",
      " bgg   gg    jb ",
      " bgi h ig    fb ",
      " bgg h gg ffffb ",
      " bbbbbbbbbbbbbb ",
      " eeeeeeeeeeeeee "
    ],
    [
      "                ",
      " bbbbbbppppppbb ",
      " bC        b  b ",
      " po     I  b  b ",
      "  F        bEbb ",
      "  D           b ",
      " po     ng    p ",
      " bC      g    p ",
      " b       l    p ",
      " b       l    p ",
      " b            b ",
      " b            b ",
      " b           fb ",
      " b         fffb ",
      " bbbbbbbbbbbbbb ",
      "                "
    ],
    [
      "                ",
      " bbbbbbbbbbbbbb ",
      " bC        b Jb ",
      " po        b  b ",
      " po        bbbb ",
      " po           b ",
      " po           b ",
      " bC      n    b ",
      " b       g    b ",
      " b       g    b ",
      " b            b ",
      " b            b ",
      " b            b ",
      " b          Jfb ",
      " bbbbbbbbbbbbbb ",
      "                "
    ],
    [
      "                ",
      " bbbbbbppbbbbbb ",
      " b         b Jb ",
      " po        b Jb ",
      " po        bbbb ",
      " po          Jb ",
      " po           b ",
      " b            b ",
      " b            b ",
      " b     ggn    b ",
      " b            b ",
      " b            p ",
      " b            p ",
      " b          JJb ",
      " bbbbbbbbbbbbbb ",
      "                "
    ],
    [
      "                ",
      " bbbbbbbbbbbbbb ",
      " bKKKKKKKKKbKKb ",
      " pKKKKKKKKKbKKb ",
      " pKKKKKKKKKbbbb ",
      " pKKKKKKKKKKKKb ",
      " pKKKK    KKKKb ",
      " bKKKK    KKKKb ",
      " bKKKK    KKKKb ",
      " bKKKKgn  KKKKb ",
      " bKKKKKKKKKKKKb ",
      " bKKKKKKKKKKKKb ",
      " bKKKKKKKKKKKKb ",
      " bKKKKKKKKKKKKb ",
      " bbbbbbbbbbbbbb ",
      "                "
    ]
  ]
}