{
  "name": "building_hotel3_base2_180",
  "refpalette": "c70cities:building_hotel3_base2_palette_180",
  "xsize": 16,
  "zsize": 16,
  "slices": [
    [
      "aaaaaaaaaaaaaaaa",
      "abbcbbbbfbcbbbba",
      "abbbbbbbbbbbbbba",
      "abbbbbbbbbbbbbba",
      "abbbdeeeeeedfbba",
      "abbbeeeeeeeebbca",
      "abbbeeeeeeeebbba",
      "acbbeeeeeeeebbba",
      "abbbeeeeeeeebbba",
      "abbbeeeeeeeebbca",
      "abbbeeeeeeeebbca",
      "abbbdeeeeeedbbba",
      "abbbbbbbbbbbbbba",
      "abbcbbbbbbbbbbba",
      "abbbbbb!bbbbbcba",
      "aaaaaaaaaaaaaaaa"
    ],
    [
      "aaaaaaaaaaaaaaaa",
      "agghggggighiggga",
      "aggijijijiigigfa",
      "agiiijiiiiiiiiga",
      "agjidkkkkkkdiiia",
      "ajiik    kikiiha",
      "agiik r  qikigga",
      "ahjik p  okkiiia",
      "aiiik p  o kijia",
      "agiik n  m kiiha",
      "aijik  ll  kiiha",
      "agjidkkddkkdigga",
      "aggjiiiiiiiiiiia",
      "agghijiiigiiiiia",
      "aggggigijggjihga",
      "aaaaaaaaaaaaaaaa"
    ],
    [
      "aaaaaaaaaaaaaaaa",
      "agghiggiijhiijja",
      "agjijijijiiiiiia",
      "aiiiijiiiiiiiija",
      "aijidkkkkkkdiiia",
      "ajiik     ikiiha",
      "aiiik      kiija",
      "ahjik      kiiia",
      "aiiik      kijia",
      "ajiik      kiiha",
      "aijik  ll  kiiha",
      "agjidkkddkkdiija",
      "agijiiiiiiiiiiia",
      "agghijiiijiiiiia",
      "aggjgiiijgijihia",
      "aaaaaaaaaaaaaaaa"
    ],
    [
      "aaaaaaaaaaaaaaaa",
      "agihigsiishiissa",
      "assisisisiiiiiia",
      "aiiiisiiiiiiiisa",
      "aisidkkkkkkdiiia",
      "asiik     iiiiha",
      "aiiik      kiisa",
      "ahsik      kiiia",
      "aiiik      kisia",
      "asiik      kiiha",
      "aisik  ll  kiiha",
      "assidkkddkkdiisa",
      "agisiiiiiiiiiiia",
      "agshisiiisiiiiia",
      "agtsiiiissisihia",
      "aaaaaaaaaaaaaaaa"
    ],
    [
      "aaaaaaaaaaaaaaaa",
      "a              a",
      "a              a",
      "a              a",
      "a   dkkkkkkd   a",
      "a   k          a",
      "a   k          a",
      "a   k      k   a",
      "a   k      k   a",
      "a   k      k   a",
      "a   k  ll  k   a",
      "a   dkkddkkd   a",
      "a              a",
      "a              a",
      "ag             a",
      "aaaaaaaaaaaaaaaa"
    ],
    [
      "aaaaaaaaaaaaaaaa",
      "auuuuuuuuuuuuuua",
      "auuuuuuuuuuuuuua",
      "auuuuuuuuuuuuuua",
      "auuudwwwwwwduuua",
      "auuuwwwwwwwwuuua",
      "auuuwwwwwwwwuuua",
      "auuuwwwwwwwwuuua",
      "auuuwwwwwwwwuuua",
      "auuuwwwwwwwwuuua",
      "auuuwwwllwwwuuua",
      "auuudwwddwwduuua",
      "auuuuuuuuuuuuuua",
      "auuuuuuuuuuuuuua",
      "auuuuuuuuuuuuuua",
      "aaaaaaaaaaaaaaaa"
    ]
  ]
}