{
  "name": "building_policeoffice1_floor1",
  "refpalette": "c70cities:building_policeoffice1_floor1_palette",
  "xsize": 16,
  "zsize": 16,
  "slices": [
    [
      "                ",
      "  aaaaaaaaaa    ",
      "  abbbbbbbba    ",
      "  abbbbbbbba    ",
      "  abbbbbbbba    ",
      "  abbbbb!bba    ",
      "  abbbbbbbba    ",
      "  abbbbbbbba    ",
      "  abbbbbbbba    ",
      "  abbbbbbbba    ",
      "  abbbbbbbba    ",
      " ccbbbbbbbbccdcc",
      " cebbbbbbbbb   c",
      " cebbbbbbbbb   c",
      " cfcccfcccfcccfc",
      "                "
    ],
    [
      "                ",
      "  aggggggggg    ",
      "  a        g    ",
      "  a  h h   g    ",
      "  a  ijjkl g    ",
      "  a mncco  g    ",
      "  a  nccol g    ",
      "  a mpqqr  g    ",
      "  a   s s  g    ",
      "  a        g    ",
      "  a        a    ",
      " cctuw     ccdcc",
      " ce  w     x   c",
      " ce  wyyyy x   c",
      " cfcccfcccfcccfc",
      "                "
    ],
    [
      "                ",
      "  aggggggggg    ",
      "  a        g    ",
      "  a        g    ",
      "  a    A   g    ",
      "  a  A     g    ",
      "  a     A  g    ",
      "  a   A    g    ",
      "  a        g    ",
      "  a        g    ",
      "  a        a    ",
      " ccBCw     ccdcc",
      " ce  w         c",
      " ce  w D E     c",
      " cfcccfcccfcccfc",
      "                "
    ],
    [
      "                ",
      "  aggggggggg    ",
      "  a        g    ",
      "  a        g    ",
      "  a        g    ",
      "  a   f    g    ",
      "  a    f   g    ",
      "  a        g    ",
      "  a        g    ",
      "  a        g    ",
      "  a        a    ",
      " ccwww     ccdcc",
      " ce  y         c",
      " ce  w   E     c",
      " cfcccfcccfcccfc",
      "                "
    ],
    [
      "                ",
      "  aggggggggg    ",
      "  a        g    ",
      "  a        g    ",
      "  a        g    ",
      "  a   EE   g    ",
      "  a   EE   g    ",
      "  a        g    ",
      "  a        g    ",
      "  a        g    ",
      "  a        a    ",
      " ccwww     ccdcc",
      " ce  w         c",
      " ce  w   E     c",
      " cfcccfcccfcccfc",
      "                "
    ],
    [
      "                ",
      "  aFFFFFFFFF    ",
      "  aIIIIIIIIF    ",
      "  aIIIIIIIIF    ",
      "  aIIIIIIIIF    ",
      "  aIIIIIIIIF    ",
      "  aIIIIIIIIF    ",
      "  aIIIIIIIIF    ",
      "  aIIIIIIIIF    ",
      "  aIIIIIIIIF    ",
      "  aIIIIIIIIa    ",
      " ccwwwIIIIIccdcc",
      " ceIIwIIIIII   c",
      " ceIIwIIIIII   c",
      " cfcccfcccfcccfc",
      "                "
    ]
  ]
}