{
  "name": "building_policeoffice1_base2_90",
  "refpalette": "c70cities:building_policeoffice1_base2_palette_90",
  "xsize": 16,
  "zsize": 16,
  "slices": [
    [
      "vvvvvvvvvvvvvvvv",
      "vaaaaaaaaaaaaaav",
      "vbbbbbbbbbbbbbav",
      "vbbbbbbbbbbbbbav",
      "vbbbbbbbbbbbbbav",
      "vbbbbbbbbbbbbbav",
      "vbbbbbbbbbbbbbav",
      "vbbbbbbbbbbbbbav",
      "vbbbbbbbbbbbbbav",
      "vbbbbbbbbbbbbbav",
      "vbbbbbbbbbbbbbav",
      "vbbbbbbbbbbbbbav",
      "vbbbbbbbbbbbbbav",
      "vbbbbbbbbbbbbbav",
      "vaaaaaaaaaaaaaav",
      "vvvvvvvvvvvvvvvv"
    ],
    [
      "vvvvvvvvvvvvvvvv",
      "vccccccccccccccv",
      "vcff     jknnncv",
      "vcf       k p cv",
      "vc  g     k   cv",
      "vc         m  cv",
      "vc         m  cv",
      "vc         m  cv",
      "vc        k   cv",
      "vc        k   cv",
      "vceeeeeeiekciqcv",
      "vc        kc  cv",
      "vcd      hkc  cv",
      "vcdd    hhkloocv",
      "vccccccccccccccv",
      "vvvvvvvvvvvvvvvv"
    ],
    [
      "vvvvvvvvvvvvvvvv",
      "vccccccccccccccv",
      "vcf       k  tcv",
      "vc        k   cv",
      "vc        k   cv",
      "vc         m  cv",
      "vc         m  cv",
      "vc         m  cv",
      "vc        k   cv",
      "vc        k   cv",
      "vceeeeeerekcrscv",
      "vc        kc  cv",
      "vc        kc  cv",
      "vc       hkloocv",
      "vccccccccccccccv",
      "vvvvvvvvvvvvvvvv"
    ],
    [
      "vvvvvvvvvvvvvvvv",
      "vccccccccccccccv",
      "vc        k   cv",
      "vc        k   cv",
      "vc        k   cv",
      "vc         m  cv",
      "vc         m  cv",
      "vc         m  cv",
      "vc        k   cv",
      "vc        k   cv",
      "vceeeeeeeekccccv",
      "vc        kc  cv",
      "vc        kc  cv",
      "vc        kloocv",
      "vccccccccccccccv",
      "vvvvvvvvvvvvvvvv"
    ],
    [
      "vvvvvvvvvvvvvvvv",
      "vccccccccccccccv",
      "vcuuwuuwuuuuuucv",
      "vc        k   cv",
      "vc        k   cv",
      "vc        k   cv",
      "vc        k   cv",
      "vc        k   cv",
      "vc        k   cv",
      "vc        k   cv",
      "vceeeeeeeekccccv",
      "vc        kcx cv",
      "vc        kc  cv",
      "vc        kloocv",
      "vccccccccccccccv",
      "vvvvvvvvvvvvvvvv"
    ],
    [
      "vvvvvvvvvvvvvvvv",
      "vccccccccccccccv",
      "vcyyyyyyyykyyycv",
      "vcyyyyyyyykyyycv",
      "vcyyyyyyyykyyycv",
      "vcyyyyyyyykyyycv",
      "vcyyyyyyyykyyycv",
      "vcyyyyyyyykyyycv",
      "vcyyyyyyyykyyycv",
      "vcyyyyyyyykyyycv",
      "vcyyyyyyyykccccv",
      "vcyyyyyyyykcyycv",
      "vcyyyyyyyykcyycv",
      "vcyyyyyyyykloocv",
      "vccccccccccccccv",
      "vvvvvvvvvvvvvvvv"
    ]
  ]
}