{
  "name": "building_hotel1_floor2_180",
  "refpalette": "c70cities:building_hotel1_floor2_palette_180",
  "xsize": 16,
  "zsize": 16,
  "slices": [
    [
      "                ",
      " aagggggaaaaaaa ",
      " abbbbbbbbbbbba ",
      " fbbbbcbbbbbbbd ",
      " fbbbbcbbbbbbbd ",
      " fbbbbcccccbbbd ",
      " fbbbbe   cbbbd ",
      " abbbb    cbbbd ",
      " abbbb    cbbbd ",
      " abbbd    cbbbd ",
      " acccccccccbbba ",
      " abbbbbbbbbbbba ",
      " abbbbbbbbbbbba ",
      " abbbbbbbbbbbba ",
      " aaaaaaaaaaaaaa ",
      "                "
    ],
    [
      "                ",
      " aaaaaaaaaaaaaa ",
      " aneeeaE      a ",
      " f DDeaC f BB a ",
      " f    aAyf xx a ",
      " f    aaaasaa a ",
      " f    dee a=  a ",
      " an  w    au  a ",
      " a   w    au  a ",
      " a        a=  a ",
      " aatasaaaasr  a ",
      " a   opqqpo   a ",
      " a          nma ",
      " a l  kjji  h a ",
      " aaaaaaaaaaaaaa ",
      "                "
    ],
    [
      "                ",
      " aaaaaaffffffaa ",
      " aL   a       a ",
      " f    a  f    a ",
      " f    aN f    a ",
      " f    aaaasaa a ",
      " f      deaM  f ",
      " aL      ea   f ",
      " a        a   f ",
      " a        aK  f ",
      " aaJasaaaas   a ",
      " a   o I  o   a ",
      " a          F a ",
      " a            a ",
      " aaaaaaaaaaaaaa ",
      "                "
    ],
    [
      "                ",
      " aaaaaaaaaaaaaa ",
      " aL   a       a ",
      " f    a  f    a ",
      " f    aP fO   a ",
      " f    aaaasaaaa ",
      " f        a   a ",
      " aL      daD  a ",
      " a       eaD  a ",
      " a       ea   a ",
      " aaaasaaaas   a ",
      " a            a ",
      " a            a ",
      " a   O    O   a ",
      " aaaaaaaaaaaaaa ",
      "                "
    ],
    [
      "                ",
      " aaaaaaffaaaaaa ",
      " a    a  f    a ",
      " f    a  f    a ",
      " f    a  fQ   a ",
      " f    aaaasaaaa ",
      " f        a   a ",
      " a        a   a ",
      " a        a   a ",
      " a     eeda   a ",
      " aaaasaaaas   a ",
      " a            f ",
      " a            f ",
      " a   Q    Q   a ",
      " aaaaaaaaaaaaaa ",
      "                "
    ],
    [
      "                ",
      " aaaaaaaaaaaaaa ",
      " aRRRRaRRRRRRRa ",
      " fRRRRaRRRRRRRa ",
      " fRRRRaRRRRRRRa ",
      " fRRRRaaaasRRRa ",
      " fRRRR    aRRRa ",
      " aRRRR    aRRRa ",
      " aRRRR    aRRRa ",
      " aRRRRed  aRRRa ",
      " aaaasaaaasRRRa ",
      " aRRRRRRRRRRRRa ",
      " aRRRRRRRRRRRRa ",
      " aRRRRRRRRRRRRa ",
      " aaaaaaaaaaaaaa ",
      "                "
    ]
  ]
}