{
  "name": "building_hotel2_floor1_180",
  "refpalette": "c70cities:building_hotel2_floor1_palette_180",
  "xsize": 16,
  "zsize": 16,
  "slices": [
    [
      "                ",
      "              a ",
      "    dddddddddda ",
      "    dccccccccca ",
      "    dccccccccca ",
      "    dccccccccca ",
      "    dccccccccca ",
      "    dccccccccca ",
      "    dccccccccca ",
      "    dccccccccca ",
      "    dcccccc!cca ",
      "    dcccccccc=a ",
      "    dccccccccba ",
      "    d!cccccccba ",
      " aaaaaaaaaaaaaa ",
      "                "
    ],
    [
      "                ",
      "              a ",
      "    hhhhhhhhhha ",
      "    h         a ",
      "    hu tsr  ==a ",
      "    hu tsr  q=a ",
      "    h       ==a ",
      "    h         a ",
      "    hj   japaaa ",
      "    h     a  oa ",
      "    hn n  amlka ",
      "    h j   aaa=a ",
      "    hj    i  ba ",
      "    hgff  e  ba ",
      " aaaaaaaaaaaaaa ",
      "                "
    ],
    [
      "                ",
      "              a ",
      "    hhhhhhhhhha ",
      "    h         a ",
      "    h    r    a ",
      "    h    r    a ",
      "    h         a ",
      "    h         a ",
      "    hC   CaBaaa ",
      "    h     a   a ",
      "    h     a  Aa ",
      "    hyyy  aaa=a ",
      "    hy    x  ba ",
      "    h     w  ba ",
      " aaaaaaaaaaaaaa ",
      "                "
    ],
    [
      "                ",
      "              a ",
      "    hhhhhhhhhha ",
      "    h         a ",
      "    h         a ",
      "    h         a ",
      "    h         a ",
      "    h         a ",
      "    hC   Caaaaa ",
      "    h     a   a ",
      "    h     a  Ea ",
      "    h     aaa=a ",
      "    h     a  ba ",
      "    hDDD  a  ba ",
      " aaaaaaaaaaaaaa ",
      "                "
    ],
    [
      "                ",
      "              a ",
      "    hhhhhhhhhha ",
      "    h         a ",
      "    h         a ",
      "    h         a ",
      "    h         a ",
      "    h         a ",
      "    h     aaaaa ",
      "    h     a   a ",
      "    h     a   a ",
      "    h     aaa=a ",
      "    h     a  ba ",
      "    h F   a  ba ",
      " aaaaaaaaaaaaaa ",
      "                "
    ],
    [
      "                ",
      "              a ",
      "    yyyyyyyyyya ",
      "    yIIIIIIIIIa ",
      "    yIIIIIIIIIa ",
      "    yIIIIIIIIIa ",
      "    yIIIIIIIIIa ",
      "    yIIIIIIIIIa ",
      "    yIIIIIaaaaa ",
      "    yIIIIIaIIIa ",
      "    yIIIIIaIIIa ",
      "    yIIIIIaaa=a ",
      "    yIIIIIaIIba ",
      "    yIIIIIaIIba ",
      " aaaaaaaaaaaaaa ",
      "                "
    ]
  ]
}