{
  "name": "building_residential1_ground_270",
  "refpalette": "c70cities:building_residential1_ground_palette_270",
  "xsize": 16,
  "zsize": 16,
  "slices": [
    [
      "GGGGGGGGGGGGGGGG",
      "GGGGGGGGGGGGGGGG",
      "GGGGGGGaaaaaaaGG",
      "GGGcccccbbbbbaGG",
      "GGGcddddbbbbbaGG",
      "GGGcddddbbbbbaGG",
      "GGGcddddbbbbbaGG",
      "GGGcddddbbbbbaGG",
      "GGGcddddbbbbbaGG",
      "GGGcddddbbbbbaGG",
      "GGGceeeebbbbbaGG",
      "GGGceeeebbbbbaGG",
      "GGGcccccbbbbbaGG",
      "GGGGGGGaaaaaaaGG",
      "GGGGGGGGGGGGGGGG",
      "GGGGGGGGGGGGGGGG"
    ],
    [
      "fgggghggggf  fgf",
      "g              g",
      "g xxxxxijjimki g",
      "g xcccccsqn  i g",
      "g xcD yu  n  j g",
      "h xcE yu  n  j h",
      "g xcF A      j g",
      "g xcI    ro li g",
      "g xcJ   trp li g",
      "g xc!    r   j g",
      "h xcCCBw r   j h",
      "g xcK  w r   j g",
      "g xccccc     i g",
      "g xxxxxijjijji g",
      "g              g",
      "fgggghggggfggggf"
    ],
    [
      "fgggghggggf  fgf",
      "g              g",
      "g      ijjiNLi g",
      "g  ccRcc  n  i g",
      "g  cT  O  n  j g",
      "h  c      n  j h",
      "g  R  P      j g",
      "g  RU    r  Mi g",
      "g  RV    r  Mi g",
      "g  R    tr   j g",
      "h  cCCQw r   j h",
      "g  cW  w r   j g",
      "g  ccScc     i g",
      "g      ijjijji g",
      "g              g",
      "fgggghggggfggggf"
    ],
    [
      "                ",
      "                ",
      "  1    iYYiYYi  ",
      "  1ccRcc  n  i  ",
      "  1c      n  X  ",
      "  1c      n  X  ",
      "  1c         X  ",
      "  1c     r   i  ",
      "  1c     r   i  ",
      "  1c     r   X  ",
      "  1cCCCwtr   X  ",
      "  1c   w r   X  ",
      "  1ccScc     i  ",
      "  1    iZZiZZi  ",
      "                ",
      "          0     "
    ],
    [
      "                ",
      "                ",
      "  541  iiiiiii  ",
      "  54cccc bbbbi  ",
      "  541    bbbbi  ",
      "  541    bbbbi  ",
      "  541    bbbbi  ",
      "  541    bbbbi  ",
      "  541    bbbbi  ",
      "  541    bbbbi  ",
      "  54222w bbbbi  ",
      "  54333wtbbbbi  ",
      "  54ccccbbbbbi  ",
      "  541  iiiiiii  ",
      "                ",
      "                "
    ],
    [
      "                ",
      "              6 ",
      "    541ijjjjji6 ",
      "    54cc) YY7i6 ",
      "    541 )8##8i6 ",
      "    541 )8$$8i6 ",
      "    541 )8888i6 ",
      "    541 )    i6 ",
      "    541 ) *%9i6 ",
      "    541 ) (^@i6 ",
      "    54Cw)  & i6 ",
      "    54+w)    i6 ",
      "    54cc     i6 ",
      "    541ijjjjji6 ",
      "              6 ",
      "                "
    ]
  ]
}