{
  "name": "building_hotel1_ground_270",
  "refpalette": "c70cities:building_hotel1_ground_palette_270",
  "xsize": 16,
  "zsize": 16,
  "slices": [
    [
      "GGGGGGGGGGGGGGGG",
      "GbbbbbbbbbbbbbbG",
      "Gb!cccccccccccbG",
      "GbccccccccccccbG",
      "Gbccccccccccccba",
      "GbccccccccccccbG",
      "Gbccccddd!ccccbG",
      "GbccccdGGGccccbG",
      "GbccccdGGGccccbG",
      "GbccccdGGGccccbG",
      "GbccccccccccccbG",
      "Gbccccccccccccba",
      "GbccccccccccccbG",
      "GbccccccccccccbG",
      "GbbddddbbbbbbbbG",
      "GGGGGGGGGGGGGGGG"
    ],
    [
      "                ",
      " bbbbbbbbbbbbbbe",
      " bx b kkkkjjffbe",
      " b  r        fbe",
      " bbbb        fbe",
      " b           fbe",
      " b u  llll    be",
      " b us g  e gggbe",
      " byu  g  e gigbe",
      " b us neee    be",
      " bAw        hhbe",
      " b            be",
      " b         gigbe",
      " bmotqom   gggbe",
      " bbp  pbbbbbbbbe",
      "                "
    ],
    [
      "                ",
      " bbbbbppppbbbbb ",
      " b  b       ffb ",
      " p  D        fb ",
      " pbbb        fb ",
      " p            b ",
      " p    ggll    b ",
      " p F  n       b ",
      " p            b ",
      " b            b ",
      " b            b ",
      " b            b ",
      " b            b ",
      " bBoECoB      b ",
      " bbp  pbbbbbbbb ",
      "                "
    ],
    [
      "                ",
      " bbbbbbbbbbbbbb ",
      " bI b        fb ",
      " b  b        Ib ",
      " bbbb         b ",
      " b            b ",
      " b     ngg    b ",
      " b            b ",
      " b            b ",
      " b            b ",
      " b            b ",
      " b            b ",
      " b            b ",
      " bBooooB      b ",
      " bbppppbbbbbbbb ",
      "                "
    ],
    [
      "      ~         ",
      " bbbbbbbbbbppbb ",
      " bIIbI       Ib ",
      " b  b        Ib ",
      " bbbb         b ",
      " b            b ",
      " b       n    b ",
      " p       g    b ",
      " p       g    b ",
      " b            b ",
      " b            b ",
      " b            b ",
      " b            b ",
      " b oooo       b ",
      " bbppppbbbbbbbb ",
      "                "
    ],
    [
      "                ",
      " bbbbbbbbbbbbbb ",
      " bJJbJJJJJJJJJb ",
      " bJJbJJJJJJJJJb ",
      " bbbbJJJJJJJJJb ",
      " bJJJJJJJJJJJJb ",
      " bJJJJ    JJJJb ",
      " bJJJJ    JJJJb ",
      " bJJJJ   nJJJJb ",
      " bJJJJ   gJJJJb ",
      " bJJJJJJJJJJJJb ",
      " bJJJJJJJJJJJJb ",
      " bJJJJJJJJJJJJb ",
      " bJJJJJJJJJJJJb ",
      " bbppppbbbbbbbb ",
      "                "
    ]
  ]
}