{
  "name": "building_hotel1_floor1_180",
  "refpalette": "c70cities:building_hotel1_floor1_palette_180",
  "xsize": 16,
  "zsize": 16,
  "slices": [
    [
      "                ",
      " aagggggaaaaaaa ",
      " abbbbbbbbbbbba ",
      " fbbbbbbbbbbbbd ",
      " fbbbbbbbbbbbbd ",
      " fbbbbbbbbbbbbd ",
      " fbbbbe   bbbbd ",
      " abbbb    bbbbd ",
      " abbbb    bbbbd ",
      " abbbd    bbbbd ",
      " acccccccccccca ",
      " abbbbbbbbbbbba ",
      " abbbbbbbbbbbba ",
      " abbbbbbbbbbbba ",
      " aaaaaaaaaaaaaa ",
      "                "
    ],
    [
      "                ",
      " aaaaaaaaaaaaaa ",
      " atrtq rtq rtqa ",
      " f            a ",
      " f            a ",
      " f            a ",
      " f    dee  r qa ",
      " at  s      t a ",
      " a   s     r qa ",
      " a            a ",
      " app aaaaaaaaaa ",
      " a o   nmllkjja ",
      " a            a ",
      " aiii        ha ",
      " aaaaaaaaaaaaaa ",
      "                "
    ],
    [
      "                ",
      " aaaaaaffffffaa ",
      " ay x   x   x a ",
      " f            a ",
      " f            a ",
      " f            a ",
      " f      de  x f ",
      " ay      e  x f ",
      " a          x f ",
      " a            f ",
      " a   aaaaaaaaaa ",
      " a     w   u  a ",
      " a            a ",
      " a            a ",
      " aaaaaaaaaaaaaa ",
      "                "
    ],
    [
      "                ",
      " aaaaaaaaaaaaaa ",
      " ay           a ",
      " f            a ",
      " f            a ",
      " f            a ",
      " f            a ",
      " ay      d    a ",
      " a       e    a ",
      " a       e    a ",
      " a   aaaaaaaaaa ",
      " a            a ",
      " a            a ",
      " a            a ",
      " aaaaaaaaaaaaaa ",
      "                "
    ],
    [
      "                ",
      " aaaaaaffaaaaaa ",
      " a            a ",
      " f            a ",
      " f            a ",
      " f            a ",
      " f            a ",
      " a            a ",
      " a            a ",
      " a     eed    a ",
      " aaaaaaaaaaaaaa ",
      " a            f ",
      " a            f ",
      " a            a ",
      " aaaaaaaaaaaaaa ",
      "                "
    ],
    [
      "                ",
      " aaaaaaaaaaaaaa ",
      " aAAAAAAAAAAAAa ",
      " fAAAAAAAAAAAAa ",
      " fAAAAAAAAAAAAa ",
      " fAAAAAAAAAAAAa ",
      " fAAAA    AAAAa ",
      " aAAAA    AAAAa ",
      " aAAAA    AAAAa ",
      " aAAAAed  AAAAa ",
      " aaaaaaaaaaaaaa ",
      " aAAAAAAAAAAAAa ",
      " aAAAAAAAAAAAAa ",
      " aAAAAAAAAAAAAa ",
      " aaaaaaaaaaaaaa ",
      "                "
    ]
  ]
}