{
  "name": "building_hotel3_base2",
  "refpalette": "c70cities:building_hotel3_base2_palette",
  "xsize": 16,
  "zsize": 16,
  "slices": [
    [
      "aaaaaaaaaaaaaaaa",
      "abcbbbbb!bbbbbba",
      "abbbbbbbbbbbcbba",
      "abbbbbbbbbbbbbba",
      "abbbdeeeeeedbbba",
      "acbbeeeeeeeebbba",
      "acbbeeeeeeeebbba",
      "abbbeeeeeeeebbba",
      "abbbeeeeeeeebbca",
      "abbbeeeeeeeebbba",
      "acbbeeeeeeeebbba",
      "abbfdeeeeeedbbba",
      "abbbbbbbbbbbbbba",
      "abbbbbbbbbbbbbba",
      "abbbbcbfbbbbcbba",
      "aaaaaaaaaaaaaaaa"
    ],
    [
      "aaaaaaaaaaaaaaaa",
      "aghijggjigigggga",
      "aiiiiigiiijihgga",
      "aiiiiiiiiiiijgga",
      "aggidkkddkkdijga",
      "ahiik  ll  kijia",
      "ahiik m  n kiiga",
      "aijik o  p kiiia",
      "aiiikko  p kijha",
      "aggikiq  r kiiga",
      "ahiikik    kiija",
      "aiiidkkkkkkdijga",
      "agiiiiiiiijiiiga",
      "afgigiijijijigga",
      "agggihgigggghgga",
      "aaaaaaaaaaaaaaaa"
    ],
    [
      "aaaaaaaaaaaaaaaa",
      "aihijigjiiigjgga",
      "aiiiiijiiijihgga",
      "aiiiiiiiiiiijiga",
      "ajiidkkddkkdijga",
      "ahiik  ll  kijia",
      "ahiik      kiija",
      "aijik      kiiia",
      "aiiik      kijha",
      "ajiik      kiiia",
      "ahiiki     kiija",
      "aiiidkkkkkkdijia",
      "ajiiiiiiiijiiiia",
      "aiiiiiijijijijga",
      "ajjiihjiiggihgga",
      "aaaaaaaaaaaaaaaa"
    ],
    [
      "aaaaaaaaaaaaaaaa",
      "aihisissiiiistga",
      "aiiiiisiiisihsga",
      "aiiiiiiiiiiisiga",
      "asiidkkddkkdissa",
      "ahiik  ll  kisia",
      "ahiik      kiisa",
      "aisik      kiiia",
      "aiiik      kisha",
      "asiik      kiiia",
      "ahiiii     kiisa",
      "aiiidkkkkkkdisia",
      "asiiiiiiiisiiiia",
      "aiiiiiisisisissa",
      "assiihsiisgihiga",
      "aaaaaaaaaaaaaaaa"
    ],
    [
      "aaaaaaaaaaaaaaaa",
      "a             ga",
      "a              a",
      "a              a",
      "a   dkkddkkd   a",
      "a   k  ll  k   a",
      "a   k      k   a",
      "a   k      k   a",
      "a   k      k   a",
      "a          k   a",
      "a          k   a",
      "a   dkkkkkkd   a",
      "a              a",
      "a              a",
      "a              a",
      "aaaaaaaaaaaaaaaa"
    ],
    [
      "aaaaaaaaaaaaaaaa",
      "auuuuuuuuuuuuuua",
      "auuuuuuuuuuuuuua",
      "auuuuuuuuuuuuuua",
      "auuudwwddwwduuua",
      "auuuwwwllwwwuuua",
      "auuuwwwwwwwwuuua",
      "auuuwwwwwwwwuuua",
      "auuuwwwwwwwwuuua",
      "auuuwwwwwwwwuuua",
      "auuuwwwwwwwwuuua",
      "auuudwwwwwwduuua",
      "auuuuuuuuuuuuuua",
      "auuuuuuuuuuuuuua",
      "auuuuuuuuuuuuuua",
      "aaaaaaaaaaaaaaaa"
    ]
  ]
}