{
  "name": "building_hotel2_floor1_90",
  "refpalette": "c70cities:building_hotel2_floor1_palette_90",
  "xsize": 16,
  "zsize": 16,
  "slices": [
    [
      "                ",
      " a              ",
      " a              ",
      " a              ",
      " adddddddddddd  ",
      " a!ccccccccccd  ",
      " acccccccccccd  ",
      " acccccccccccd  ",
      " acccccccccccd  ",
      " acccccccccccd  ",
      " acccccccccccd  ",
      " accc!cccccccd  ",
      " acccccccccccd  ",
      " abb=ccccccccd  ",
      " aaaaaaaaaaaaaa ",
      "                "
    ],
    [
      "                ",
      " a              ",
      " a              ",
      " a              ",
      " ahhhhhhhhhhhh  ",
      " agj m j  uu h  ",
      " af j        h  ",
      " af  m    tt h  ",
      " a        ss h  ",
      " a     j  rr h  ",
      " aeiaaaa     h  ",
      " a  ag p     h  ",
      " a  aloa =q= h  ",
      " abb=kna === h  ",
      " aaaaaaaaaaaaaa ",
      "                "
    ],
    [
      "                ",
      " a              ",
      " a              ",
      " a              ",
      " ahhhhhhhhhhhh  ",
      " a yy  B     h  ",
      " a  y        h  ",
      " a  y        h  ",
      " a           h  ",
      " a     B  rr h  ",
      " awxaaaa     h  ",
      " a  a  A     h  ",
      " a  a  a     h  ",
      " abb=  a     h  ",
      " aaaaaaaaaaaaaa ",
      "                "
    ],
    [
      "                ",
      " a              ",
      " a              ",
      " a              ",
      " ahhhhhhhhhhhh  ",
      " aC    B     h  ",
      " aC          h  ",
      " aC          h  ",
      " a           h  ",
      " a     B     h  ",
      " aaaaaaa     h  ",
      " a  a  a     h  ",
      " a  a  a     h  ",
      " abb=  a     h  ",
      " aaaaaaaaaaaaaa ",
      "                "
    ],
    [
      "                ",
      " a              ",
      " a              ",
      " a              ",
      " ahhhhhhhhhhhh  ",
      " a           h  ",
      " a           h  ",
      " a           h  ",
      " a           h  ",
      " a           h  ",
      " aaaaaaa     h  ",
      " a  a  a     h  ",
      " a  a  a     h  ",
      " abb=  a     h  ",
      " aaaaaaaaaaaaaa ",
      "                "
    ],
    [
      "                ",
      " a              ",
      " a              ",
      " a              ",
      " ayyyyyyyyyyyy  ",
      " aDDDDDDDDDDDy  ",
      " aDDDDDDDDDDDy  ",
      " aDDDDDDDDDDDy  ",
      " aDDDDDDDDDDDy  ",
      " aDDDDDDDDDDDy  ",
      " aaaaaaaDDDDDy  ",
      " aDDaDDaDDDDDy  ",
      " aDDaDDaDDDDDy  ",
      " abb=DDaDDDDDy  ",
      " aaaaaaaaaaaaaa ",
      "                "
    ]
  ]
}