{
  "name": "building_office2_ground",
  "refpalette": "c70cities:building_office2_ground_palette",
  "xsize": 16,
  "zsize": 16,
  "slices": [
    [
      "GGGGGGGGGGGGGGGG",
      "GaaaaaaaaaaaaaaG",
      "GGGbccccccccbGGG",
      "GGbccccccccccbGG",
      "GGbccccccccccbGG",
      "GGbccccccccccbGG",
      "GGbccccccccccbGG",
      "GGbccccccccccbGG",
      "GGbccccccccccbGG",
      "GGbccccccccccbGG",
      "GGbccccccccccbGG",
      "GGbccccccc!ccbGG",
      "GGbccccccccccbGG",
      "GGGbccccccccbGGG",
      "GaaaaaaaaaaaaaaG",
      "GGGGGGGGGGGGGGGG"
    ],
    [
      "                ",
      " aaaaaaaaaaaaaa ",
      "   bdefffefdb   ",
      "  g          g  ",
      "  g   h  h   g  ",
      "  g  iiiiii  g  ",
      "  g   j  j   g  ",
      "  g          k  ",
      "  g          l  ",
      "  g          g  ",
      "  g          g  ",
      "  g       m  g  ",
      "  g          g  ",
      "   bnopqqporb   ",
      " aaaaaaaaaaaaaa ",
      "                "
    ],
    [
      "                ",
      " aaaaaaaaaaaaaa ",
      "   bs      sb   ",
      "  g          g  ",
      "  g          g  ",
      "  g          g  ",
      "  g          g  ",
      "  g          t  ",
      "  g          u  ",
      "  g          g  ",
      "  g          g  ",
      "  g          g  ",
      "  g          g  ",
      "   b  wqqw  b   ",
      " aaaaaaaaaaaaaa ",
      "                "
    ],
    [
      "                ",
      " aaaaaaaaaaaaaa ",
      "   bs      sb   ",
      "  g          g  ",
      "  g          g  ",
      "  g          g  ",
      "  g          g  ",
      "  g          g  ",
      "  g    x     g  ",
      "  g          g  ",
      "  g          g  ",
      "  g          g  ",
      "  g          g  ",
      "   b   qq   b   ",
      " aaaaaaaaaaaaaa ",
      "                "
    ],
    [
      "                ",
      " aaaaaaaaaaaaaa ",
      "   b        b   ",
      "  g          g  ",
      "  g          g  ",
      "  g          g  ",
      "  g          g  ",
      "  g    xx    g  ",
      "  g    xx    g  ",
      "  g          g  ",
      "  g          g  ",
      "  g          g  ",
      "  g          g  ",
      "   b   qq   b   ",
      " aaaaaaaaaaaaaa ",
      "                "
    ],
    [
      "                ",
      " aaaaaaaaaaaaaa ",
      "   byyyyyyyyb   ",
      "  g yyyyyyyy g  ",
      "  g yyyyyyyy g  ",
      "  g yyyyyyyy g  ",
      "  g yyyyyyyy g  ",
      "  g yyyAAyyy g  ",
      "  g yyyAAyyy g  ",
      "  g yyyyyyyy g  ",
      "  g yyyyyyyy g  ",
      "  g yyyyyyyy g  ",
      "  g yyyyyyyy g  ",
      "   byyyqqyyyb   ",
      " aaaaaaaaaaaaaa ",
      "                "
    ]
  ]
}