{
  "name": "building_carservice1_ground_180",
  "refpalette": "c70cities:building_carservice1_ground_palette_180",
  "xsize": 16,
  "zsize": 16,
  "slices": [
    [
      "GGGGGGGGGGGGGGGG",
      "GGGGeeaeeeaeeeaG",
      "GGGffff!fffff!eG",
      "GGffffffffffffeG",
      "Geffffff fml feG",
      "Gefffffff kjifeG",
      "Geffffffff hgfeG",
      "GeffffffffffffeG",
      "GeffffffffffffeG",
      "GeaeeeaeeeaeeeaG",
      "HH=ddcb       vG",
      "HH=ddcb       vG",
      "HHvvvvvvvvvvvvvG",
      "HHvvvvvvvvvvvvvG",
      "GGavvvavvvavvvaG",
      "GGGGGGGGGGGGGGGG"
    ],
    [
      "                ",
      "    eeaeeeaeeea ",
      "   wwDpABBCBBAe ",
      "  ww          w ",
      " ew           w ",
      " eA           w ",
      " ey           w ",
      " ey     x     w ",
      " eu   t   srqpe ",
      " ea   aeeeaeeea ",
      "              o ",
      "              o ",
      "  nHooooooooooo ",
      "  nH            ",
      "  a   a   a   a ",
      "                "
    ],
    [
      "                ",
      "    eeaeeeaeeea ",
      "   wwD A     Ae ",
      "  ww          w ",
      " ew           w ",
      " eA           w ",
      " w            w ",
      " w            w ",
      " w         JI e ",
      " ea   aeeeaeeea ",
      "      F       F ",
      "      F       F ",
      "    nHF       F ",
      "    nHE       E ",
      "  a   a   a   a ",
      "                "
    ],
    [
      "                ",
      "    eeaeeeaeeea ",
      "   wwD        e ",
      "  ww          w ",
      " ew           w ",
      " e            w ",
      " e            w ",
      " e            w ",
      " e            e ",
      " eaKKKaeeeaeeea ",
      "                ",
      "                ",
      "      nH        ",
      "      nH        ",
      "  a   a   a   a ",
      "                "
    ],
    [
      "                ",
      "    eeaeeeaeeea ",
      "   wwD        e ",
      "  ww          L ",
      " ew           L ",
      " e            L ",
      " e            L ",
      " e            L ",
      " e            e ",
      " eaeeeaeeeaeeea ",
      "  F       F     ",
      "  F       F     ",
      "  F     nHF     ",
      "  E     nHE     ",
      "  aFFFaFFFa   a ",
      "                "
    ],
    [
      "                ",
      "    eeaeeeaeeea ",
      "   wwD FFFFFFFe ",
      "  ww  FFFFFFFFe ",
      " ew  FFFFFFFFFe ",
      " e  FFFFFFFFFFe ",
      " e FFFFFFFFFFFe ",
      " e            e ",
      " e            e ",
      " eaeeeaeeeaeeea ",
      "          a     ",
      "          M     ",
      "          nH    ",
      "          nH    ",
      "  a   a   a   a ",
      "                "
    ]
  ]
}