{
  "name": "building_bank1_floor2_90",
  "refpalette": "c70cities:building_bank1_floor2_palette_90",
  "xsize": 16,
  "zsize": 16,
  "slices": [
    [
      "                ",
      "   gbbi  gbbi   ",
      "  deeeedeeeeed  ",
      " ceeeeeeeeeeeel ",
      " beeeeeeeeeeeeb ",
      " beeeeee!eeeeeb ",
      " aeeeeeeeeeeeek ",
      "  eee!eeeeeeed  ",
      "  deeeeeeeeeee  ",
      " ceeeeeeeeeeeel ",
      " beeeeeeeeeeeeb ",
      " beeeeeeeeeeeeb ",
      " aeee    jeeeek ",
      "  deeeeedeeeed  ",
      "   fbbh  fbbh   ",
      "                "
    ],
    [
      "                ",
      "  gbbi  gbbi    ",
      "  mmmmnmmmmmnml ",
      "  n     o    mb ",
      " cm r x o rC mb ",
      " bm quw o B  mk ",
      " bm     o Ax n  ",
      " amoooo y    m  ",
      "  m pp    oooml ",
      "  n          mb ",
      " cm          mb ",
      " bm  ttttt   mk ",
      " bm  j       n  ",
      " amnmsmmmnmmmm  ",
      "    fbbh  fbbh  ",
      "                "
    ],
    [
      "                ",
      " Dbbi  gbbi  gD ",
      " ammmnmmmmmnmmb ",
      "  m     o    mb ",
      "  n     o    mk ",
      " cm     o    n  ",
      " bm     o    m  ",
      " bmoooo E    ml ",
      " am       ooomb ",
      "  m          mb ",
      "  n          mk ",
      " cm  t t t   n  ",
      " bm   j      m  ",
      " bmmnmsmmmnmmml ",
      " Dh  fbbh  fbbD ",
      "                "
    ],
    [
      "                ",
      " Dbi  gbbi  gbD ",
      " bmmnmmmmmnmmmb ",
      " am          mk ",
      "  m          n  ",
      "  n          m  ",
      " cm          ml ",
      " bm     E    mb ",
      " bm          mb ",
      " am          mk ",
      "  m          n  ",
      "  n  t t t   m  ",
      " cm    j     ml ",
      " bmmmnmsmmmnmmb ",
      " Dbh  fbbh  fbD ",
      "                "
    ],
    [
      "                ",
      " Di  gbbi  gbbD ",
      " bmnmmmmmnmmmmk ",
      " bm          n  ",
      " am          m  ",
      "  m          ml ",
      "  n          mb ",
      " cm          mb ",
      " bm          mk ",
      " bm          n  ",
      " am          m  ",
      "  m  t t t   ml ",
      "  n     j    mb ",
      " cmmmmnmsmmmnmb ",
      " Dbbh  fbbh  fD ",
      "                "
    ],
    [
      "                ",
      "    gbbi  gbbi  ",
      " cnmmmmmnmmmmn  ",
      " bmFFFFFFFFFFm  ",
      " bmFFFFFFFFFFml ",
      " amFFFFFFFFFFmb ",
      "  mFFFFFFFFFFmb ",
      "  nFFFFFFFFFFmk ",
      " cmFFFFFFFFFFn  ",
      " bmFFFFFFFFFFm  ",
      " bmFFFFFFFFFFml ",
      " amFFt t tFFFmb ",
      "  mFF    jFFFmb ",
      "  nmmmmnmsmmmnk ",
      "  fbbh  fbbh    ",
      "                "
    ]
  ]
}