{
  "name": "building_residential3_ground_270",
  "refpalette": "c70cities:building_residential3_ground_palette_270",
  "xsize": 16,
  "zsize": 16,
  "slices": [
    [
      "GGGGGGGGGGGGGGGG",
      "GGGGGGGGGGGGGGGG",
      "GGGGGGGGaaaaaaGG",
      "GGGcccccabbbbaGG",
      "GGGcddddbbbbbaGG",
      "GGGcddddbbbbbaGG",
      "GGGcddddbbbbbaGG",
      "GGGcddddbbbbbaGG",
      "GGaabbbbbbbbbaGG",
      "GGabbbbbbbbbbaGG",
      "GGabbbbbbbbbbaGG",
      "GGabbbbbbbbbbaGG",
      "GGabbbbbbbbbbaGG",
      "GGaaaaaaaaaaaaGG",
      "GGGGGGGGGGGGGGGG",
      "GGGGGGGGGGGGGGGG"
    ],
    [
      "effffgfffe  effe",
      "f              f",
      "f wwwww hinlih f",
      "f wccccch    h f",
      "f wcA   rq   h f",
      "g wcB   rq   h g",
      "f wcC   s   jh f",
      "f wcD        h f",
      "f hhhhhtt    h f",
      "f i xx      !h f",
      "g F       okkh g",
      "f F       p  h f",
      "f i Ey uu om h f",
      "f hhhhhhhhhhhh f",
      "f              f",
      "effffeffffgffffe"
    ],
    [
      "effffgfffe  effe",
      "f              f",
      "f       hiLJih f",
      "f  ccPPch    h f",
      "f  cR        F f",
      "g  P         F g",
      "f  P         F f",
      "f  cS       jh f",
      "f hhhhhtt    h f",
      "f i QQ       F f",
      "g F       okkh g",
      "f F       M  I f",
      "f i    ON oK h f",
      "f hhFFFhhFhIhh f",
      "f              f",
      "effffeffffgffffe"
    ],
    [
      "            U   ",
      "                ",
      "  XXXXXXhiVVih  ",
      "  Xccccch    h  ",
      "  Xc         T  ",
      "  Xc         T  ",
      "  Xc         T  ",
      "  Xc         h  ",
      "  hhhhhtt   jh  ",
      "  i          T  ",
      "  Y       okkh  ",
      "  Y       o  T  ",
      "  i       o  h  ",
      "  hhWWWhhWhWhh  ",
      "                ",
      "     U          "
    ],
    [
      "                ",
      "                ",
      "  ZZZZZZhhhhhh  ",
      "  Z10000hbbbbh  ",
      "  Z2    bbbbbh  ",
      "  Z2    bbbbbh  ",
      "  Z2    bbbb h  ",
      "  Z2    bbbb h  ",
      "  hhbbbbbbbb h  ",
      "  hbbbbbbbbbjh  ",
      "  hbbbbbbbbbbh  ",
      "  hbbbbbbbbbbh  ",
      "  hbbbbbbbbbbh  ",
      "  hhhhhhhhhhhh  ",
      "                ",
      "                "
    ],
    [
      "                ",
      "                ",
      "  ZZZZZZhFFFFh  ",
      "  Zccccch6  3h  ",
      "  Zc    96  3T  ",
      "  Zc    97  4T  ",
      "  Zc    9  5 T  ",
      "  Zc   %9  5 h  ",
      "  hh99999  5 h  ",
      "  F        5 T  ",
      "  F^^^^i@    T  ",
      "  F^&&^i#8   T  ",
      "  F **7i$    h  ",
      "  hhWWWhhFFFFh  ",
      "                ",
      "                "
    ]
  ]
}