{
  "name": "building_hotel2_floor1",
  "refpalette": "c70cities:building_hotel2_floor1_palette",
  "xsize": 16,
  "zsize": 16,
  "slices": [
    [
      "                ",
      " aaaaaaaaaaaaaa ",
      " abccccccc!d    ",
      " abccccccccd    ",
      " a=ccccccccd    ",
      " acc!ccccccd    ",
      " acccccccccd    ",
      " acccccccccd    ",
      " acccccccccd    ",
      " acccccccccd    ",
      " acccccccccd    ",
      " acccccccccd    ",
      " acccccccccd    ",
      " adddddddddd    ",
      " a              ",
      "                "
    ],
    [
      "                ",
      " aaaaaaaaaaaaaa ",
      " ab  e  ffgh    ",
      " ab  i    jh    ",
      " a=aaa   j h    ",
      " aklma  n nh    ",
      " ao  a     h    ",
      " aaapaj   jh    ",
      " a         h    ",
      " a==       h    ",
      " a=q  rst uh    ",
      " a==  rst uh    ",
      " a         h    ",
      " ahhhhhhhhhh    ",
      " a              ",
      "                "
    ],
    [
      "                ",
      " aaaaaaaaaaaaaa ",
      " ab  w     h    ",
      " ab  x    yh    ",
      " a=aaa  yyyh    ",
      " aA  a     h    ",
      " a   a     h    ",
      " aaaBaC   Ch    ",
      " a         h    ",
      " a         h    ",
      " a    r    h    ",
      " a    r    h    ",
      " a         h    ",
      " ahhhhhhhhhh    ",
      " a              ",
      "                "
    ],
    [
      "                ",
      " aaaaaaaaaaaaaa ",
      " ab  a  DDDh    ",
      " ab  a     h    ",
      " a=aaa     h    ",
      " aE  a     h    ",
      " a   a     h    ",
      " aaaaaC   Ch    ",
      " a         h    ",
      " a         h    ",
      " a         h    ",
      " a         h    ",
      " a         h    ",
      " ahhhhhhhhhh    ",
      " a              ",
      "                "
    ],
    [
      "                ",
      " aaaaaaaaaaaaaa ",
      " ab  a   F h    ",
      " ab  a     h    ",
      " a=aaa     h    ",
      " a   a     h    ",
      " a   a     h    ",
      " aaaaa     h    ",
      " a         h    ",
      " a         h    ",
      " a         h    ",
      " a         h    ",
      " a         h    ",
      " ahhhhhhhhhh    ",
      " a              ",
      "                "
    ],
    [
      "                ",
      " aaaaaaaaaaaaaa ",
      " abIIaIIIIIy    ",
      " abIIaIIIIIy    ",
      " a=aaaIIIIIy    ",
      " aIIIaIIIIIy    ",
      " aIIIaIIIIIy    ",
      " aaaaaIIIIIy    ",
      " aIIIIIIIIIy    ",
      " aIIIIIIIIIy    ",
      " aIIIIIIIIIy    ",
      " aIIIIIIIIIy    ",
      " aIIIIIIIIIy    ",
      " ayyyyyyyyyy    ",
      " a              ",
      "                "
    ]
  ]
}