{
  "name": "building_hotel1_ground_270",
  "refpalette": "c70cities:building_hotel1_ground_palette_270",
  "xsize": 16,
  "zsize": 16,
  "slices": [
    [
      "GGGGGGGGGGGGGGGG",
      "GbbbbbbbbbbbbbbG",
      "Gb!cccccccccccbG",
      "GbccccccccccccbG",
      "Gbccccccccccccba",
      "GbccccccccccccbG",
      "Gbccccddd!ccccbG",
      "GbccccdGGGccccbG",
      "GbccccdGGGccccbG",
      "GbccccdGGGccccbG",
      "GbccccccccccccbG",
      "Gbccccccccccccba",
      "GbccccccccccccbG",
      "GbccccccccccccbG",
      "GbbddddbbbbbbbbG",
      "GGGGGGGGGGGGGGGG"
    ],
    [
      "                ",
      " bbbbbbbbbbbbbbe",
      " bx b kkkkjjffbe",
      " by r        fbe",
      " bbbb        fbe",
      " b           fbe",
      " b u  llll    be",
      " b us g  e gggbe",
      " bAu  g  e gigbe",
      " b us neee    be",
      " bBw        hhbe",
      " b            be",
      " b         gigbe",
      " bmotqom   gggbe",
      " bbp  pbbbbbbbbe",
      "                "
    ],
    [
      "                ",
      " bbbbbppppbbbbb ",
      " b  b       ffb ",
      " p  E        fb ",
      " pbbb        fb ",
      " p            b ",
      " p    ggll    b ",
      " p I  n       b ",
      " p            b ",
      " b            b ",
      " b            b ",
      " b            b ",
      " b            b ",
      " bCoFDoC      b ",
      " bbp  pbbbbbbbb ",
      "                "
    ],
    [
      "                ",
      " bbbbbbbbbbbbbb ",
      " bJ b        fb ",
      " b  b        Jb ",
      " bbbb         b ",
      " b            b ",
      " b     ngg    b ",
      " b            b ",
      " b            b ",
      " b            b ",
      " b            b ",
      " b            b ",
      " b            b ",
      " bCooooC      b ",
      " bbppppbbbbbbbb ",
      "                "
    ],
    [
      "                ",
      " bbbbbbbbbbppbb ",
      " bJJbJ       Jb ",
      " b  b        Jb ",
      " bbbb         b ",
      " b            b ",
      " b       n    b ",
      " p       g    b ",
      " p       g    b ",
      " b            b ",
      " b            b ",
      " b            b ",
      " b            b ",
      " b oooo       b ",
      " bbppppbbbbbbbb ",
      "                "
    ],
    [
      "                ",
      " bbbbbbbbbbbbbb ",
      " bKKbKKKKKKKKKb ",
      " bKKbKKKKKKKKKb ",
      " bbbbKKKKKKKKKb ",
      " bKKKKKKKKKKKKb ",
      " bKKKK    KKKKb ",
      " bKKKK    KKKKb ",
      " bKKKK   nKKKKb ",
      " bKKKK   gKKKKb ",
      " bKKKKKKKKKKKKb ",
      " bKKKKKKKKKKKKb ",
      " bKKKKKKKKKKKKb ",
      " bKKKKKKKKKKKKb ",
      " bbppppbbbbbbbb ",
      "                "
    ]
  ]
}