{
  "name": "building_hotel1_floor3_270",
  "refpalette": "c70cities:building_hotel1_floor3_palette_270",
  "xsize": 16,
  "zsize": 16,
  "slices": [
    [
      "                ",
      " aadddddddaaaaa ",
      " abbbbbbbbbbbba ",
      " abbbbbbbbbbbba ",
      " abbbbbbbbbbbba ",
      " abbbccccccbbba ",
      " abbbc    cbbba ",
      " abbbc    cbbba ",
      " gbbbc    cbbba ",
      " gbccce   cbbba ",
      " gbbbbbbbdcbbba ",
      " gbbbbbbbbcbbba ",
      " gbbbbbbbbcbbba ",
      " abbbbbbbbcbbba ",
      " aaffffaaaaaaaa ",
      "                "
    ],
    [
      "                ",
      " aaaaaaaaaaaaaa ",
      " a          m a ",
      " a yta      nha ",
      " a yta=rr=    a ",
      " a  upaaaapo  a ",
      " a ffa    a  ia ",
      " a Awae   a= ja ",
      " aDBxae   a= ja ",
      " aaaaad   a  ka ",
      " aee   ss po  a ",
      " aeC      a   a ",
      " aeC      q  la ",
      " an    n  a   a ",
      " aaffffaaaaaaaa ",
      "                "
    ],
    [
      "                ",
      " aaaaaffffaaaaa ",
      " a            a ",
      " f   a      E a ",
      " f   aK  I    a ",
      " f   paaaapo  a ",
      " f ffaee  a   a ",
      " f   ad   a   a ",
      " f   a    a   a ",
      " aaaaa    a   a ",
      " a        po  a ",
      " a        a   a ",
      " a        F   a ",
      " aJ    J  a   a ",
      " aaffffaaaaaaaa ",
      "                "
    ],
    [
      "                ",
      " aaaaaaaaaaaaaa ",
      " a   a        a ",
      " a   a        a ",
      " a   a CC     a ",
      " a  Lpaaaapo La ",
      " a ffa deea   a ",
      " a   a    a   a ",
      " a   a    a   a ",
      " aaaaa    a   a ",
      " a        po La ",
      " a        a   a ",
      " a        a   a ",
      " aJ    J  a   a ",
      " aafff aaaaaaaa ",
      "                "
    ],
    [
      "                ",
      " aaaaaaaaaaffaa ",
      " a   a        a ",
      " a   a        a ",
      " a   a        a ",
      " a  Mpaaaap  Ma ",
      " afffa   da   a ",
      " f   a   ea   a ",
      " f   a   ea   a ",
      " aaaaa    a   a ",
      " a        p  Ma ",
      " a        a   a ",
      " a        a   a ",
      " a        a   a ",
      " aaffffaaaaaaaa ",
      "                "
    ],
    [
      "                ",
      " aaaaaaaaaaaaaa ",
      " aNNNaNNNNNNNNa ",
      " aNNNaNNNNNNNNa ",
      " aNNNaNNNNNNNNa ",
      " aNNNpaaaapNNNa ",
      " aNNNa    aNNNa ",
      " aNNNa    aNNNa ",
      " aNNNa   daNNNa ",
      " aaaaa   eaNNNa ",
      " aNNNNNNNNpNNNa ",
      " aNNNNNNNNaNNNa ",
      " aNNNNNNNNaNNNa ",
      " aNNNNNNNNaNNNa ",
      " aaffffaaaaaaaa ",
      "                "
    ]
  ]
}