{
  "name": "building_gasstation1_ground",
  "refpalette": "c70cities:building_gasstation1_ground_palette",
  "xsize": 16,
  "zsize": 16,
  "slices": [
    [
      "GGGGGGGGGGGGGGGG",
      "aHHHHHHHHHbGGGGG",
      "HHHHHHHHHHbGGGGG",
      "HHHHaHHaaaaaaaGG",
      "HHHHaHHaaaaaaaGG",
      "HHHHaHHaaaaaaaGG",
      "HHHHaHHaaaaaaaGG",
      "HHHHaHHaaaaaaaGG",
      "HHHHaHHaaaaaaaGG",
      "HHHHaHHaaaaaaaGG",
      "HHHHaHHaaaaaaaGG",
      "HHHHaHHaaaaaaaGG",
      "HHHHaHHaaaaaaaGG",
      "HHHHHHHHHHbGGGGG",
      "HHHHHHHHHHbGGGGG",
      "GGGGGGGGGGGGGGGG"
    ],
    [
      "                ",
      "c      d ef     ",
      "       g hf     ",
      "    i  jjjjjjj  ",
      "  klm  jnno!pj  ",
      "       q   rrj  ",
      "  sti  u  oooj  ",
      "  klw  x     j  ",
      "    y  q     j  ",
      "  sti  jA jjBj  ",
      "  klm  C  jD j  ",
      "       CE jF j  ",
      "  sti  jjjjjjj  ",
      "       d ef     ",
      "       g hf     ",
      "                "
    ],
    [
      "                ",
      "c               ",
      "                ",
      "    i  jjjjjjj  ",
      "    I  jJJpooj  ",
      "       q     j  ",
      "    i  K  oroj  ",
      "       L     j  ",
      "       q     j  ",
      "    i  jM jjNj  ",
      "    I  O  j  j  ",
      "       O  jP j  ",
      "    i  jjjjjjj  ",
      "                ",
      "                ",
      "                "
    ],
    [
      "                ",
      "Q               ",
      "                ",
      "    i  RRRRRRR  ",
      "       R   r S  ",
      "       R     S  ",
      "    i  R     R  ",
      "       R     S  ",
      "       R     S  ",
      "    i  R  jjjR  ",
      "       R  j  S  ",
      "       R  j  S  ",
      "    i  RRRRRRR  ",
      "                ",
      "                ",
      "                "
    ],
    [
      "                ",
      "                ",
      "                ",
      "    jT jjjjjjj  ",
      "       jr j rj  ",
      "       j  j  j  ",
      "    jT j Uj  j  ",
      "       j  j  j  ",
      "       j  j  j  ",
      "    jU j Tjjjj  ",
      "       j  jVVj  ",
      "       j  jVVj  ",
      "    jT jjjjjjj  ",
      "                ",
      "                ",
      "                "
    ],
    [
      "                ",
      "                ",
      " WWWWWWWWWWWWWW ",
      " WffaaaaaaaaaaW ",
      " WffaffaffaffaW ",
      " WffaffaffaffaW ",
      " WffaffaffaffaW ",
      " WffaffaffaffaW ",
      " WffaffaffaffaW ",
      " WffaffaffaffaW ",
      " WffaffaffaffaW ",
      " WffaffaffaffaW ",
      " WffaaaaaaaaaaW ",
      " WWWWWWWWWWWWWW ",
      "                ",
      "                "
    ]
  ]
}