{
  "name": "building_residential1_ground",
  "refpalette": "c70cities:building_residential1_ground_palette",
  "xsize": 16,
  "zsize": 16,
  "slices": [
    [
      "GGGGGGGGGGGGGGGG",
      "GGGGGGGGGGGGGGGG",
      "GGaaaaaaaaaaaaGG",
      "GGabbbbbbbbbbaGG",
      "GGabbbbbbbbbbaGG",
      "GGabbbbbbbbbbaGG",
      "GGabbbbbbbbbbaGG",
      "GGabbbbbbbbbbaGG",
      "GGacddddddeecaGG",
      "GGGcddddddeecGGG",
      "GGGcddddddeecGGG",
      "GGGcddddddeecGGG",
      "GGGccccccccccGGG",
      "GGGGGGGGGGGGGGGG",
      "GGGGGGGGGGGGGGGG",
      "GGGGGGGGGGGGGGGG"
    ],
    [
      "fgggghgggghggggf",
      "g              g",
      "f iijjjiijjjii g",
      "  k    ll    j g",
      "  m          j g",
      "f innn op   qi f",
      "g jr   sssss j g",
      "g jt    u    j g",
      "g icww    xxci g",
      "g ycAAB   CDcy g",
      "h yc      E cy h",
      "g ycFIJKI!ELcy g",
      "g yccccccccccy g",
      "g yyyyyyyyyyyy g",
      "g              g",
      "fgggghgggghggggf"
    ],
    [
      "fgggghgggghggggf",
      "g              g",
      "f iijjjiijjjii g",
      "  M    NN    j g",
      "  O          j g",
      "f innn      Pi f",
      "g j    sssss j g",
      "g j      u   j g",
      "g icQ     xxci g",
      "g  c  R   S c  g",
      "h  T      E U  h",
      "g  cV  W  E c  g",
      "g  cccTTTTccc  g",
      "g              g",
      "g              g",
      "fgggghgggghggggf"
    ],
    [
      "                ",
      "                ",
      "  iiXXXiiXXXii  ",
      "  Y          Z  ",
      "  Y          Z  ",
      "  innn       i 0",
      "  Y    sssss Z  ",
      "  Y       u  Z  ",
      "  ic      xxci  ",
      "   c      E c   ",
      "   T      E U   ",
      "   c      E c   ",
      "   cccccccccc   ",
      "  111111111111  ",
      "                ",
      "                "
    ],
    [
      "                ",
      "                ",
      "  iiiiiiiiiiii  ",
      "  ibbbbbbbbbbi  ",
      "  ibbbbbbbbbbi  ",
      "  ibbbbbbbbbbi  ",
      "  ibbbbbbbbbbi  ",
      "  i        ubi  ",
      "  ic      xxci  ",
      "   c      23c   ",
      "   c      23c   ",
      "  1c11111123c1  ",
      "  444444444444  ",
      "  555555555555  ",
      "                ",
      "                "
    ],
    [
      "                ",
      " 66666666666666 ",
      "  iiiiiiiiiiii  ",
      "  j7888 9@  #j  ",
      "  jY$%8 ^&*  j  ",
      "  jY$%8 ()   j  ",
      "  j 888      j  ",
      "  j+++++++++ j  ",
      "  ic      xxci  ",
      "  1c111111E-c1  ",
      "  444444444444  ",
      "  555555555555  ",
      "                ",
      "                ",
      "                ",
      "                "
    ]
  ]
}