{
  "name": "building_bank1_top_180",
  "refpalette": "c70cities:building_bank1_top_palette_180",
  "xsize": 16,
  "zsize": 16,
  "slices": [
    [
      "                ",
      "  abbbc abbbc   ",
      "  deeeedeeeeeda ",
      " ceeeeeeeeeeeeb ",
      " beeeeeeeeeeeeb ",
      " beeeeeeeeeeeeb ",
      " beeeeeeeeee ec ",
      " aeeeeeeeeee d  ",
      "  deeeeeeeee ea ",
      " ceeeeeeeeee eb ",
      " beeeeeeeeee eb ",
      " beeeeeeeeeeeeb ",
      " beeeeeeeeeeeec ",
      " adeeeeedeeeed  ",
      "   cbbba cbbba  ",
      "                "
    ],
    [
      "                ",
      " fbcc abbcc abf ",
      " bgggghggggghgb ",
      " ahwuuuttuuutgc ",
      "  gssssssssssgc ",
      " cg          g  ",
      " cg rrqp     ha ",
      " bg    m l   gb ",
      " bg  o n     gb ",
      " ah    m l   gc ",
      "  g  kji     gc ",
      " cg          g  ",
      " cg          ha ",
      " bghggggghggggb ",
      " fba ccbba ccbf ",
      "                "
    ],
    [
      "                ",
      " fbbbbbbbbbbbbf ",
      " bgggghggggghgb ",
      " bhuuuuuuuuuugb ",
      " bg          gb ",
      " bg          gb ",
      " bg rr y     hb ",
      " bg          gb ",
      " bg          gb ",
      " bh          gb ",
      " bg    x     gb ",
      " bg          gb ",
      " bg          hb ",
      " bghggggghggggb ",
      " fbbbbbbbbbbbbf ",
      "                "
    ],
    [
      "                ",
      "                ",
      "   gghggggghg   ",
      "  gg        gg  ",
      "  h          g  ",
      "  g          h  ",
      "  g          g  ",
      "  g          g  ",
      "  g          g  ",
      "  g          g  ",
      "  h          g  ",
      "  g          h  ",
      "  gg        gg  ",
      "   ghggggghgg   ",
      "                ",
      "                "
    ],
    [
      "                ",
      "                ",
      "                ",
      "    gggggggg    ",
      "   gggggggggg   ",
      "   ggg    ggg   ",
      "   gg     Agg   ",
      "   gg      gg   ",
      "   gg      gg   ",
      "   ggA     gg   ",
      "   ggg    ggg   ",
      "   gggggggggg   ",
      "    gggggggg    ",
      "                ",
      "                ",
      "                "
    ],
    [
      "                ",
      "                ",
      "                ",
      "                ",
      "                ",
      "      gggg      ",
      "     gggggg     ",
      "     gggggg     ",
      "     gggggg     ",
      "     gggggg     ",
      "      gggg      ",
      "                ",
      "                ",
      "                ",
      "                ",
      "                "
    ]
  ]
}