{
  "name": "building_bank1_base1",
  "refpalette": "c70cities:building_bank1_base1_palette",
  "xsize": 16,
  "zsize": 16,
  "slices": [
    [
      "vvvvvvvvvvvvvvvv",
      "vaabbaaaabbaaaav",
      "vab!bbbbbbbbbbav",
      "vabbbbbbbbbbbbbv",
      "vabbbbbbbbbbbbbv",
      "vbbbbbbbbbbbbbav",
      "vbbbbbbbbbbbbbav",
      "vabbbbbbbbbbbbav",
      "vabbbbbbbbbbbbav",
      "vabbbbbbbbbbbbbv",
      "vabbbbbbbbbbbbbv",
      "vbbbbbbbbbbbbbav",
      "vbbbbbbbbbbbbbav",
      "vabbbbbbbbb!bbav",
      "vaaaabbaaaabbaav",
      "vvvvvvvvvvvvvvvv"
    ],
    [
      "vvvvvvvvvvvvvvvv",
      "vaabbaaaabbaaaav",
      "va ccd eecc efav",
      "vae  e       cbv",
      "va           cbv",
      "vbc          eav",
      "vbc     e    eav",
      "vag    hih   eav",
      "vad    ihi   eav",
      "vag   ehih   cbv",
      "vae          cbv",
      "vbc          dav",
      "vbcj         gav",
      "va   cceeeecckav",
      "vaaaabbaaaabbaav",
      "vvvvvvvvvvvvvvvv"
    ],
    [
      "vvvvvvvvvvvvvvvv",
      "vaabbaaaabbaaaav",
      "va cc  l cc  mav",
      "va           cbv",
      "va           cbv",
      "vbc           av",
      "vbc          nav",
      "vao    ppp   nav",
      "vad    qqq    av",
      "va     qqq   cbv",
      "va           cbv",
      "vbc          dav",
      "vbcj          av",
      "va   ccrgr ccgav",
      "vaaaabbaaaabbaav",
      "vvvvvvvvvvvvvvvv"
    ],
    [
      "vvvvvvvvvvvvvvvv",
      "vaabbaaaabbaaaav",
      "va cc    cc   av",
      "va           cbv",
      "va           cbv",
      "vbc           av",
      "vbc           av",
      "va            av",
      "va      q     av",
      "va           cbv",
      "va           cbv",
      "vbc           av",
      "vbcj          av",
      "va   cc    cc av",
      "vaaaabbaaaabbaav",
      "vvvvvvvvvvvvvvvv"
    ],
    [
      "vvvvvvvvvvvvvvvv",
      "vaabbaaaabbaaaav",
      "va cc    cc   av",
      "va           cbv",
      "va           cbv",
      "vbc           av",
      "vbc           av",
      "va            av",
      "va            av",
      "va           cbv",
      "va           cbv",
      "vbc           av",
      "vbcj          av",
      "va   cc    cc av",
      "vaaaabbaaaabbaav",
      "vvvvvvvvvvvvvvvv"
    ],
    [
      "vvvvvvvvvvvvvvvv",
      "vaabbaaaabbaaaav",
      "vamccssssccsstav",
      "vassssssssssscbv",
      "vassssssssssscbv",
      "vbcsssssssssssav",
      "vbcsssssssssssav",
      "vassssssssssssav",
      "vassssssssssssav",
      "vassssssssssscbv",
      "vassssssssssscbv",
      "vbcsssssssssssav",
      "vbcjssssssssssav",
      "vaussccssssccmav",
      "vaaaabbaaaabbaav",
      "vvvvvvvvvvvvvvvv"
    ]
  ]
}