{
  "name": "building_restaurant2_ground",
  "refpalette": "c70cities:building_restaurant2_ground_palette",
  "xsize": 16,
  "zsize": 16,
  "slices": [
    [
      "GGGGGGGGGGGGGGGG",
      "GGGGGaaaabaccccG",
      "GGGacccccccccccG",
      "GGGbcdefddeccccG",
      "GGGacgefggeccccG",
      "GGGacefddefddaaG",
      "GbGacefggefggabG",
      "aaaacdefddefdaaG",
      "GabacgefggefgaaG",
      "aGGacefddefddabG",
      "GGGacefggefggabG",
      "GGGacdefddeccccG",
      "GGGacgefggeccccG",
      "GGGacccccccccccG",
      "GGGGGaaaabbccccG",
      "GGGGGGGGGGGGGGGG"
    ],
    [
      "                ",
      "    hijkkkliiii ",
      "   mmmmmmmminni ",
      "   omp     i ni ",
      "   qm      irii ",
      "   smp tuwx  iy ",
      "   mmi tAmB CiD ",
      "     E tAmB FiD ",
      "     I tAmB CiD ",
      "   mmi tAmB CiD ",
      "   omp tJKL MiN ",
      "   qm      iiii ",
      "   smp     E Oi ",
      "   mmmmmmmmiPQi ",
      "    hiRSSSTiiii ",
      "                "
    ],
    [
      "                ",
      "    Ui     iiii ",
      "   mmmmVVVmiWXi ",
      "   YV      i  i ",
      "   YV      iZii ",
      "   YV   01   iY ",
      "   mmi  213  iY ",
      "     4  215 6iY ",
      "     7  21  8iY ",
      "   mmi  213 !iY ",
      "   YV   29  @iY ",
      "   YV      iiii ",
      "   YV      4  i ",
      "   mmmmVVVmi  i ",
      "    Ui     iiii ",
      "                "
    ],
    [
      "                ",
      "    UiYYYYYiiii ",
      "   mmmmmmmmi#$V ",
      "   YV W%%%Xi  V ",
      "   YV      iiii ",
      "   YV   ^&   iY ",
      "   mmi  ^&   iY ",
      "   * i  ^&   iY ",
      "   * i  ^&   iY ",
      "   mmi  ^&   iY ",
      "   YV   ^&   iY ",
      "   YV      iiii ",
      "   YV ()))+i  V ",
      "   mmmmmmmmi  V ",
      "    UiYYYYYiiii ",
      "                "
    ],
    [
      "                ",
      "     i-----iiii ",
      "  [mmmmmmmmi  - ",
      "   -ii]]]]]i  - ",
      "   -ii     iiii ",
      "   -ii       i- ",
      "  [mmi       i- ",
      "   * i       i- ",
      "   * i       i- ",
      "  [mmi       i- ",
      "   -ii       i- ",
      "   -ii     iiii ",
      "   -ii{}}}}i  - ",
      "  [mmmmmmmmi  - ",
      "     i-----iiii ",
      "                "
    ],
    [
      "                ",
      " \\\\\\\\iiiiiiiiii ",
      " \\\\\\\\mmmmmm|``i ",
      " \\\\\\\\|:::::|``i ",
      " \\\\\\\\|:::::|iii ",
      " \\\\\\\\|;;;;;||i| ",
      " \\\\\\\\|:::::||i| ",
      " \\\\\\\\|:::::||i| ",
      " \\\\\\\\|:::::||i| ",
      " \\\\\\\\|:::::||i| ",
      " \\\\\\\\|;;;;;||i| ",
      " \\\\\\\\|:::::|iii ",
      " \\\\\\\\|:::::|``i ",
      " \\\\\\\\mmmmmm|``i ",
      " \\\\\\\\iiiiiiiiii ",
      "                "
    ]
  ]
}