{
  "name": "building_hotel2_floor3_270",
  "refpalette": "c70cities:building_hotel2_floor3_palette_270",
  "xsize": 16,
  "zsize": 16,
  "slices": [
    [
      "                ",
      " aaaaaaaaaaaaaa ",
      "  dcccccccc=bba ",
      "  dccccccccccca ",
      "  dccccccccccca ",
      "  dccccccccccca ",
      "  dccccccccccca ",
      "  dccccccccccca ",
      "  dccccccccccca ",
      "  dc!ccccc!ccca ",
      "  dccccccccccca ",
      "  dddddddddddda ",
      "              a ",
      "              a ",
      "              a ",
      "                "
    ],
    [
      "                ",
      " aaaaaaaaaaaaaa ",
      "  e hhmlkhh=bba ",
      "  e        f  a ",
      "  e           a ",
      "  e           a ",
      "  e           a ",
      "  e ig ig ig  a ",
      "  e i  i  i   a ",
      "  e j  j  j   a ",
      "  e           a ",
      "  eeeeeeeeeeeea ",
      "              a ",
      "              a ",
      "              a ",
      "                "
    ],
    [
      "                ",
      " aaaaaaaaaaaaaa ",
      "  e hh   hh=bba ",
      "  e        n  a ",
      "  e           a ",
      "  e           a ",
      "  e           a ",
      "  e           a ",
      "  e           a ",
      "  e           a ",
      "  e           a ",
      "  eeeeeeeeeeeea ",
      "              a ",
      "              a ",
      "              a ",
      "                "
    ],
    [
      "                ",
      " aaaaaaaaaaaaaa ",
      "  e hh   hh=bba ",
      "  e        n  a ",
      "  e           a ",
      "  e           a ",
      "  e           a ",
      "  e           a ",
      "  e           a ",
      "  e           a ",
      "  e           a ",
      "  eeeeeeeeeeeea ",
      "              a ",
      "              a ",
      "              a ",
      "                "
    ],
    [
      "                ",
      " aaaaaaaaaaaaaa ",
      "  e        =bba ",
      "  e           a ",
      "  e           a ",
      "  e           a ",
      "  e   o  o  o a ",
      "  e           a ",
      "  e           a ",
      "  e           a ",
      "  e           a ",
      "  eeeeeeeeeeeea ",
      "              a ",
      "              a ",
      "              a ",
      "                "
    ],
    [
      "                ",
      " aaaaaaaaaaaaaa ",
      "  ipppppppp=bba ",
      "  ipppppppppppa ",
      "  ipppppppppppa ",
      "  ipppppppppppa ",
      "  ipppppppppppa ",
      "  ipppppppppppa ",
      "  ipppppppppppa ",
      "  ipppppppppppa ",
      "  ipppppppppppa ",
      "  iiiiiiiiiiiia ",
      "              a ",
      "              a ",
      "              a ",
      "                "
    ]
  ]
}