{
  "name": "building_carservice1_floor1_180",
  "refpalette": "c70cities:building_carservice1_floor1_palette_180",
  "xsize": 16,
  "zsize": 16,
  "slices": [
    [
      "                ",
      "    eeaeeeaeeea ",
      "   ddjfggggggfe ",
      "  ddcffgighbgfe ",
      " edcfffgighbgfe ",
      " ecffffggg!hgfe ",
      " effffffffffffe ",
      " effffffffffffe ",
      " ecccccccccccce ",
      " eadddadddaccca ",
      "         Hbbbb  ",
      "         Hbbbb  ",
      "            bb  ",
      "            bb  ",
      "  a   a   a   a ",
      "                "
    ],
    [
      "                ",
      "    eeaeeeaeeea ",
      "   ssjDpypx   e ",
      "  ss   yCy    s ",
      " es    yCy    s ",
      " eB    Aypx  ws ",
      " eu          ws ",
      " eu   t       s ",
      " errrqponn    e ",
      " eaeeeaeeea  ma ",
      "      lHb     l ",
      "      kHb     k ",
      "      k       k ",
      "      k       k ",
      "  a   akkkakkka ",
      "                "
    ],
    [
      "                ",
      "    eeaeeeaeeea ",
      "   ssjNKMK    e ",
      "  ss   J L    s ",
      " es           s ",
      " e     LKJ    s ",
      " s      I     s ",
      " s            s ",
      " s FF   n     e ",
      " eaeeeaeeea mma ",
      "     Hb         ",
      "     Hb         ",
      "      E         ",
      "      a         ",
      "  a   a   a   a ",
      "                "
    ],
    [
      "                ",
      "    eeaeeeaeeea ",
      "   ssj P P    e ",
      "  ss   O O    s ",
      " es    O O    s ",
      " e     OOO    s ",
      " e            s ",
      " e            s ",
      " e            e ",
      " eaeeeaeeeammma ",
      "   bb           ",
      "   bb           ",
      "   bbbbH        ",
      "   bbbbH        ",
      "  a   a   a   a ",
      "                "
    ],
    [
      "                ",
      "    eeaeeeaeeea ",
      "   ssj        e ",
      "  ss          Q ",
      " es           Q ",
      " e            Q ",
      " e            Q ",
      " e            Q ",
      " e            e ",
      " eaeeeaeeeaeeea ",
      "  k       k     ",
      "  k       k     ",
      "  k     bHk     ",
      "  l     bHl     ",
      "  akkkakkka   a ",
      "                "
    ],
    [
      "                ",
      "    eeaeeeaeeea ",
      "   ssj kkkkkkke ",
      "  ss  kkkkkkkke ",
      " es  kkkkkkkkke ",
      " e  kkkkkkkkkke ",
      " e kkkkkkkkkkke ",
      " e            e ",
      " e            e ",
      " eaeeeaeeeaeeea ",
      "          a     ",
      "          E     ",
      "          bH    ",
      "          bH    ",
      "  a   a   a   a ",
      "                "
    ]
  ]
}