{
  "name": "building_restaurant1_base1",
  "refpalette": "c70cities:building_restaurant1_base1_palette",
  "xsize": 16,
  "zsize": 16,
  "slices": [
    [
      "vvvvvvvvvvvvvvvv",
      "v==============v",
      "v=avvvvvvvvvvv=v",
      "v=vvvvvvvvvvvv=v",
      "v=vvvvvvvvvvvv=v",
      "v=vvvvvvvvvvvv=v",
      "v=vvvvvv!vvvvv=v",
      "v=vvvvvvvvvvvv=v",
      "v=vvvvvvvvvvvv=v",
      "v=vvvvvvvvvvvv=v",
      "v=bccccccccccb=v",
      "v=bdddcccccccb=v",
      "v=bdddcccccccb=v",
      "v=bdddccccc!cb=v",
      "v=bbbbbbbbbbbb=v",
      "vvvvvvvvvvvvvvvv"
    ],
    [
      "vvvvvvvvvvvvvvvv",
      "v==============v",
      "v=ae      fghi=v",
      "v=jj        ki=v",
      "v=jjj  l     m=v",
      "v=j    lln    =v",
      "v=    nlllo   =v",
      "v=    lllll   =v",
      "v=k     ll   f=v",
      "v=hk       p q=v",
      "v=bdddp p rppb=v",
      "v=bsssd r  r b=v",
      "v=bsssd   r tb=v",
      "v=bsssd t tuwb=v",
      "v=bbbbbbbbbbbb=v",
      "vvvvvvvvvvvvvvvv"
    ],
    [
      "vvvvvvvvvvvvvvvv",
      "v==============v",
      "v=ae        gk=v",
      "v=j          x=v",
      "v=j           =v",
      "v=      l     =v",
      "v=     ll     =v",
      "v=     lll    =v",
      "v=           f=v",
      "v=g           =v",
      "v=bppp     ppb=v",
      "v=b          b=v",
      "v=b          b=v",
      "v=b         tb=v",
      "v=bbbbbbbbbbbb=v",
      "vvvvvvvvvvvvvvvv"
    ],
    [
      "vvvvvvvvvvvvvvvv",
      "v==============v",
      "v=ae          =v",
      "v=j           =v",
      "v=            =v",
      "v=            =v",
      "v=      n     =v",
      "v=      l     =v",
      "v=            =v",
      "v=            =v",
      "v=bpp       pb=v",
      "v=b          b=v",
      "v=b          b=v",
      "v=by         b=v",
      "v=bbbbbbbbbbbb=v",
      "vvvvvvvvvvvvvvvv"
    ],
    [
      "vvvvvvvvvvvvvvvv",
      "v==============v",
      "v=ae          =v",
      "v=            =v",
      "v=            =v",
      "v=            =v",
      "v=            =v",
      "v=            =v",
      "v=            =v",
      "v=     p      =v",
      "v=bpppppp pppb=v",
      "v=b          b=v",
      "v=b          b=v",
      "v=bA         b=v",
      "v=bbbbbbbbbbbb=v",
      "vvvvvvvvvvvvvvvv"
    ],
    [
      "vvvvvvvvvvvvvvvv",
      "v==============v",
      "v=aeBBBBBBBBBB=v",
      "v=BBBBBBBBBBBB=v",
      "v=BBBBBBBBBBBB=v",
      "v=BBBBBBBBBBBB=v",
      "v=BBBBBBBBBBBB=v",
      "v=BBBBBBBBBBBB=v",
      "v=BBBBBBBBBBBB=v",
      "v=BBBBBBBBBBBB=v",
      "v=bddddddddddb=v",
      "v=bddddddddddb=v",
      "v=bddddddddddb=v",
      "v=bCdddddddddb=v",
      "v=bbbbbbbbbbbb=v",
      "vvvvvvvvvvvvvvvv"
    ]
  ]
}