{
  "name": "building_factory2_ground_270",
  "refpalette": "c70cities:building_factory2_ground_palette_270",
  "xsize": 16,
  "zsize": 16,
  "slices": [
    [
      "zzzzzzzzzzzazzzz",
      "zzzzzazaazazzzzz",
      "zzzzzzaazaaazzzz",
      "zzzzzzzaaaaazzzz",
      "zzzHHHHHHHHHHzzz",
      "zzzHHHHHHHHHHzzz",
      "zzzHHHHHHHHHHzzz",
      "zzzHHHHHHHHHHzzz",
      "zzzHHHHHHHHHHzzz",
      "zzzHHHHHHHHHHzzz",
      "zzzHHHHHHHHHHzzz",
      "zzzHHHHHHHHHHzzz",
      "zzzHHHHHHHHHHzzz",
      "zzzzzzHHzzzzzzzz",
      "zzzzzzzzzzzzzzzz",
      "zzzzzzzzzzzzzzzz"
    ],
    [
      "                ",
      "b bd        b b ",
      " bc bb       dcb",
      "beccc b     bce ",
      " cffoqqqqoflffcc",
      "bdf!ggwg   igfcd",
      " cfggA      hfcb",
      "bcfF      i if  ",
      " cf     r   jfb ",
      " bfFD  tspmfff b",
      "ccf   iknknkkf  ",
      " cfg Bxunknkkfcd",
      "d fgECyknkkkkfcc",
      "bcffffffffffffcb",
      "befffeeffeefffe ",
      " ccdbee ceecd b "
    ],
    [
      "                ",
      "                ",
      "                ",
      " ecc         ce ",
      "  ffoqqqqofJffc ",
      "  INg        Ic ",
      "  I N        I  ",
      " cI          I  ",
      " cf          f  ",
      "  f          f  ",
      " cI    LnKKKuf  ",
      "  I     nKnKnf  ",
      "  IjO  LnKKK f  ",
      "  fffffMffffffc ",
      " efffeeffeefffe ",
      "     ee  ee     "
    ],
    [
      "                ",
      "                ",
      "                ",
      " e            e ",
      "  ffoqqqqofPffc ",
      "  I          I  ",
      "  I          I  ",
      "  I          I  ",
      "  f          f  ",
      "  f          f  ",
      "  I      QQQ f  ",
      "  I     OQQQ f  ",
      "  I      QQQjf  ",
      "  fffffPffffff  ",
      " efffeeffeefffe ",
      "     ee  ee     "
    ],
    [
      "                ",
      "                ",
      "                ",
      " e   UUUU     e ",
      "  ffooooooffff  ",
      "  R          R  ",
      "  R          R  ",
      "  R          R  ",
      "  f          f  ",
      "  f          f  ",
      "  R          f  ",
      "  R          f  ",
      "  R V   V   jf  ",
      "  ffffffffffff  ",
      " eSSSTTSSTTSSSe ",
      "     SS  SS     "
    ],
    [
      "                ",
      "                ",
      "                ",
      " e            e ",
      "  ffWWWWWWffff  ",
      "  W          W  ",
      "  W          W  ",
      "  W          W  ",
      "  f  Y    X  f  ",
      "  f  Y    Y  f  ",
      "  W          W  ",
      "  W          W  ",
      "  W          W  ",
      "  ffffffffffff  ",
      " e   TT  TT   e ",
      "                "
    ]
  ]
}