{
  "name": "building_residential3_floor1",
  "refpalette": "c70cities:building_residential3_floor1_palette",
  "xsize": 16,
  "zsize": 16,
  "slices": [
    [
      "                ",
      "                ",
      "  aabbbaabbbaa  ",
      "  b          b  ",
      "  b          b  ",
      "  b          b  ",
      "  b          b  ",
      "  aa         a  ",
      "  cd   e  fffa  ",
      "  cg         b  ",
      "  cg         b  ",
      "  cd         b  ",
      "  cddggda    a  ",
      "  ccccccabbbba  ",
      "                ",
      "                "
    ],
    [
      "                ",
      " hhhhhhhhhhhhhh ",
      " haaaaaaaaaaaah ",
      "  a          a  ",
      "  a          a  ",
      "  a          a  ",
      "  a          a  ",
      "  aa        ia  ",
      "  cd   e  fffa  ",
      "  cd         a  ",
      "  cd         a  ",
      "  cd         a  ",
      "  cddddda    a  ",
      " hccccccaaaaaah ",
      " hhhhhhhhhhhhhh ",
      "                "
    ],
    [
      "                ",
      " ~              ",
      " jjjjjjjjjjjjjj ",
      " kkkkkkkkkkkkkk ",
      " llllllllllllll ",
      " hahhhhhhhhhhah ",
      "  a          a  ",
      "  aa        ea  ",
      "  cd   e  lmla  ",
      "  cd         a  ",
      " hcdhhhhhhhhhah ",
      " llllllllllllll ",
      " nnnnnnnnnnnnnn ",
      " jjjjjjjjjjjjjj ",
      "              ~ ",
      "                "
    ],
    [
      "                ",
      "~~              ",
      "                ",
      "                ",
      "                ",
      " jjjjjjjjjjjjjj ",
      " kkkkkkkkkkkkkk ",
      " llllllllllllll ",
      " llllllllllllll ",
      " nnnnnnnnnnnnnn ",
      " jjjjjjjjjjjjjj ",
      "                ",
      "                ",
      "                ",
      "              ~ ",
      "                "
    ],
    [
      "                ",
      " ~~~~~~~~~~~~~~ ",
      " ~~~~~~~~~~~~~~ ",
      " ~~~~~~~~~~~~~~ ",
      " ~~~~~~~~~~~~~~ ",
      " ~~~~~~~~~~~~~~ ",
      " ~~~~~~~~~~~~~~ ",
      " ~~~~~~~~~~~~~~ ",
      " ~~~~~~~~~~~~~~ ",
      " ~~~~~~~~~~~~~~ ",
      " ~~~~~~~~~~~~~~ ",
      " ~~~~~~~~~~~~~~ ",
      " ~~~~~~~~~~~~~~ ",
      " ~~~~~~~~~~~~~~ ",
      " ~~~~~~~~~~~~~~ ",
      "                "
    ],
    [
      "                ",
      " ~~~~~~~~~~~~~~ ",
      " ~~~~~~~~~~~~~~ ",
      " ~~~~~~~~~~~~~~ ",
      " ~~~~~~~~~~~~~~ ",
      " ~~~~~~~~~~~~~~ ",
      " ~~~~~~~~~~~~~~ ",
      " ~~~~~~~~~~~~~~ ",
      " ~~~~~~~~~~~~~~ ",
      " ~~~~~~~~~~~~~~ ",
      " ~~~~~~~~~~~~~~ ",
      " ~~~~~~~~~~~~~~ ",
      " ~~~~~~~~~~~~~~ ",
      " ~~~~~~~~~~~~~~ ",
      " ~~~~~~~~~~~~~~ ",
      "                "
    ]
  ]
}