{
  "name": "building_bunker1_base1",
  "refpalette": "c70cities:building_bunker1_base1_palette",
  "xsize": 16,
  "zsize": 16,
  "slices": [
    [
      "================",
      "================",
      "========aaaaaa==",
      "========aaaaaa==",
      "========aaaaaa==",
      "========aaaaaa==",
      "================",
      "================",
      "================",
      "================",
      "====aaa=aa======",
      "====aaaaaa======",
      "========aa======",
      "====aaaaaa======",
      "====aaa=aa======",
      "================"
    ],
    [
      "zzzzzzzzzzzzzzzz",
      "bbbbbbbbbbbbbbbz",
      "bccbdddbefeghibz",
      "bj     b     kbz",
      "bl     m     nbz",
      "bo bbbbbp  qrqbz",
      "b  bss bt    ubz",
      "bs bw  x    yybz",
      "bABbo  bn C  Dbz",
      "bbbbbbbEbFb  Ibz",
      "zzzbJKLbn b  Mbz",
      "zzzbN  O  bPQIbz",
      "zzzbbbbb  bbbbbz",
      "zzzbN  O  R  Sbz",
      "zzzbJKTbUUbVWXbz",
      "zzzbbbbbbbbbbbbz"
    ],
    [
      "zzzzzzzzzzzzzzzz",
      "EEEEEEEEEEEYYYZz",
      "E01E   EL23   4z",
      "E      E      4z",
      "Eo     5     6Ez",
      "E  EEEEE7   89Ez",
      "E  Es  E      Ez",
      "E@ Ew  #      Ez",
      "EA$E   E6     Ez",
      "EEEEEEEEE%E  ^Ez",
      "zzzE01LE6 E   Ez",
      "zzzE&  *  E()+Ez",
      "zzzEEEEE  EEEEEz",
      "zzzE-  *  []] {z",
      "zzzE}\\TET E|`:{z",
      "zzzEEEEEE;EEEEEz"
    ],
    [
      "zzzzzzzzzzzzzzzz",
      "EEEEEEEEEEEEEEEz",
      "E 'E,,,E......Ez",
      "E      E      Ez",
      "E      E     6Ez",
      "E  EEEEE      Ez",
      "E  E   E      Ez",
      "E  Ew  {      Ez",
      "EA!E   E6     Ez",
      "EEEEEEEEEEE  /Ez",
      "zzzEf< E6 E  /Ez",
      "zzzE  >E  E?\u00a3\u00a4Ez",
      "zzzEEEEE  EEEEEz",
      "zzzE  >E  E\u00a5\u00a7 Ez",
      "zzzEf  E\u00c0\u00c0E \u00c1\u00c2Ez",
      "zzzEEEEEEEEEEEEz"
    ],
    [
      "zzzzzzzzzzzzzzzz",
      "EEEEEEEEEEEEEEEz",
      "E\u00c3\u00c3E\u00c4\u00c4\u00c4E\u00c5\u00c5\u00c5\u00c5\u00c5\u00c5Ez",
      "E\u00c3\u00c3\u00c6\u00c3\u00c3\u00c3E\u00c3\u00c3\u00c3\u00c3\u00c3\u00c3Ez",
      "E\u00c3\u00c3\u00c5\u00c3\u00c3\u00c3E\u00c3\u00c3\u00c3\u00c3\u00c3\u00c3Ez",
      "E\u00c5\u00c5EEEEE\u00c3\u00c3\u00c3\u00c3\u00c3\u00c3Ez",
      "E\u00c3\u00c3EEEEE\u00c3\u00c3\u00c3\u00c3\u00c3\u00c3Ez",
      "E\u00c3\u00c3EwEEE\u00c3\u00c3\u00c3\u00c3\u00c3\u00c3Ez",
      "EA\u00c3EEEEE\u00c3\u00c3\u00c3\u00c3\u00c3\u00c3Ez",
      "EEEEEEEEEEEE\u00c5EEz",
      "zzzE\u00c5\u00c3\u00c3E\u00c3\u00c3EE\u00c5EEz",
      "zzzE\u00c6\u00c3\u00c3E\u00c3\u00c3EE\u00c5EEz",
      "zzzEEEEE\u00c3\u00c3EEEEEz",
      "zzzE\u00c6\u00c3\u00c3E\u00c3\u00c3E\u00c3\u00c3\u00c5Ez",
      "zzzE\u00c5\u00c3\u00c3E\u00c5\u00c5E\u00c3\u00c3\u00c5Ez",
      "zzzEEEEEEEEEEEEz"
    ],
    [
      "zzzzzzzzzzzzzzzz",
      "zzzzzzzzzzzzzzzz",
      "zzzzzzzzzzzzzzzz",
      "zzzzzzzzzzzzzzzz",
      "zzzzzzzzzzzzzzzz",
      "zzzzzzzzzzzzzzzz",
      "zzzzEzzzzzzzzzzz",
      "zzzEwEzzzzzzzzzz",
      "zzzzEzzzzzzzzzzz",
      "zzzzzzzzzzzzzzzz",
      "zzzzzzzzzzzzzzzz",
      "zzzzzzzzzzzzzzzz",
      "zzzzzzzzzzzzzzzz",
      "zzzzzzzzzzzzzzzz",
      "zzzzzzzzzzzzzzzz",
      "zzzzzzzzzzzzzzzz"
    ]
  ]
}