{
  "name": "building_hotel2_floor1_270",
  "refpalette": "c70cities:building_hotel2_floor1_palette_270",
  "xsize": 16,
  "zsize": 16,
  "slices": [
    [
      "                ",
      " aaaaaaaaaaaaaa ",
      "  dcccccccc=bba ",
      "  dccccccccccca ",
      "  dccccccc!ccca ",
      "  dccccccccccca ",
      "  dccccccccccca ",
      "  dccccccccccca ",
      "  dccccccccccca ",
      "  dccccccccccca ",
      "  dcccccccccc!a ",
      "  dddddddddddda ",
      "              a ",
      "              a ",
      "              a ",
      "                "
    ],
    [
      "                ",
      " aaaaaaaaaaaaaa ",
      "  h === aok=bba ",
      "  h =q= a la  a ",
      "  h     p ma  a ",
      "  h     aaaaiea ",
      "  h rr  j     a ",
      "  h ss        a ",
      "  h tt    n  fa ",
      "  h        j fa ",
      "  h uu  j n jga ",
      "  hhhhhhhhhhhha ",
      "              a ",
      "              a ",
      "              a ",
      "                "
    ],
    [
      "                ",
      " aaaaaaaaaaaaaa ",
      "  h     a A=bba ",
      "  h     a  a  a ",
      "  h     B  a  a ",
      "  h     aaaaxwa ",
      "  h rr  C     a ",
      "  h           a ",
      "  h        y  a ",
      "  h        y  a ",
      "  h     C  yy a ",
      "  hhhhhhhhhhhha ",
      "              a ",
      "              a ",
      "              a ",
      "                "
    ],
    [
      "                ",
      " aaaaaaaaaaaaaa ",
      "  h     a E=bba ",
      "  h     a  a  a ",
      "  h     a  a  a ",
      "  h     aaaaaaa ",
      "  h     C     a ",
      "  h           a ",
      "  h          Da ",
      "  h          Da ",
      "  h     C    Da ",
      "  hhhhhhhhhhhha ",
      "              a ",
      "              a ",
      "              a ",
      "                "
    ],
    [
      "                ",
      " aaaaaaaaaaaaaa ",
      "  h     a  =bba ",
      "  h     a  a  a ",
      "  h     a  a  a ",
      "  h     aaaaaaa ",
      "  h           a ",
      "  h           a ",
      "  h           a ",
      "  h          Fa ",
      "  h           a ",
      "  hhhhhhhhhhhha ",
      "              a ",
      "              a ",
      "              a ",
      "                "
    ],
    [
      "                ",
      " aaaaaaaaaaaaaa ",
      "  yIIIIIaII=bba ",
      "  yIIIIIaIIaIIa ",
      "  yIIIIIaIIaIIa ",
      "  yIIIIIaaaaaaa ",
      "  yIIIIIIIIIIIa ",
      "  yIIIIIIIIIIIa ",
      "  yIIIIIIIIIIIa ",
      "  yIIIIIIIIIIIa ",
      "  yIIIIIIIIIIIa ",
      "  yyyyyyyyyyyya ",
      "              a ",
      "              a ",
      "              a ",
      "                "
    ]
  ]
}