{
  "name": "building_residential3_ground_270",
  "refpalette": "c70cities:building_residential3_ground_palette_270",
  "xsize": 16,
  "zsize": 16,
  "slices": [
    [
      "GGGGGGGGGGGGGGGG",
      "GGGGGGGGGGGGGGGG",
      "GGGGGGGGaaaaaaGG",
      "GGGcccccabbbbaGG",
      "GGGcddddbbbbbaGG",
      "GGGcddddbbbbbaGG",
      "GGGcddddbbbbbaGG",
      "GGGcddddbbbbbaGG",
      "GGaabbbbbbbbbaGG",
      "GGabbbbbbbbbbaGG",
      "GGabbbbbbbbbbaGG",
      "GGabbbbbbbbbbaGG",
      "GGabbbbbbbbbbaGG",
      "GGaaaaaaaaaaaaGG",
      "GGGGGGGGGGGGGGGG",
      "GGGGGGGGGGGGGGGG"
    ],
    [
      "effffgfffe  iefe",
      "f              f",
      "f AAAAA hjpnjh f",
      "f Accccch    h f",
      "f AcD  yts   h f",
      "g AcE   ts   h g",
      "f AcF   u   kh f",
      "f AcI        h f",
      "f hhhhhww    h f",
      "f j BB      !h f",
      "g K       qllh g",
      "f K       r  h f",
      "f j JC xx qomh f",
      "f hhhhhhhhhhhh f",
      "f              f",
      "effffeffffgffffe"
    ],
    [
      "effffgfffe   efe",
      "f              f",
      "f       hjOMjh f",
      "f  ccSSch    h f",
      "f  cU        K f",
      "g  S         K g",
      "f  S         K f",
      "f  cV       kh f",
      "f hhhhhww    h f",
      "f j TT     N K f",
      "g K       qllh g",
      "f K       P  L f",
      "f j    RQ q  h f",
      "f hhKKKhhKhLhh f",
      "f              f",
      "effffeffffgffffe"
    ],
    [
      "             W  ",
      "                ",
      "  000000hjYYjh  ",
      "  0ccccch    h  ",
      "  0c         X  ",
      "  0c         X  ",
      "  0c         X  ",
      "  0c         h  ",
      "  hhhhhww   kh  ",
      "  j          X  ",
      "  1       qllh  ",
      "  1       q  X  ",
      "  j       q  h  ",
      "  hhZZZhhZhZhh  ",
      "                ",
      "     W          "
    ],
    [
      "                ",
      "                ",
      "  222222hhhhhh  ",
      "  243333hbbbbh  ",
      "  25    bbbbbh  ",
      "  25    bbbbbh  ",
      "  25    bbbb h  ",
      "  25    bbbb h  ",
      "  hhbbbbbbbb h  ",
      "  hbbbbbbbbbkh  ",
      "  hbbbbbbbbbbh  ",
      "  hbbbbbbbbbbh  ",
      "  hbbbbbbbbbbh  ",
      "  hhhhhhhhhhhh  ",
      "                ",
      "                "
    ],
    [
      "                ",
      "                ",
      "  222222hKKKKh  ",
      "  2ccccch@  6h  ",
      "  2c    %@  6X  ",
      "  2c    %#  7X  ",
      "  2c    %  9 X  ",
      "  2c   (%  9 h  ",
      "  hh%%%%%  9 h  ",
      "  K        9 X  ",
      "  K))))j^    X  ",
      "  K)++)j&$   X  ",
      "  K --#j*   8h  ",
      "  hhZZZhhKKKKh  ",
      "                ",
      "                "
    ]
  ]
}