{
  "name": "building_factory1_ground",
  "refpalette": "c70cities:building_factory1_ground_palette",
  "xsize": 16,
  "zsize": 16,
  "slices": [
    [
      "aazzzzzzzzzzzzzz",
      "aaazzzzzzzzzzzzz",
      "aazbbbbbbbbbbbzz",
      "aaabbbbbbbbbbbzz",
      "zaabbbbbbbbbbbzz",
      "aaabbbbbbbbbbbzz",
      "aaabbbbbbbbbbbzz",
      "azabbbbbbbbbbbzz",
      "aaabbbbbbbbcbbzz",
      "aaabbbbbbbbbbbzz",
      "zaabbbbbbbbcbbzz",
      "zaabbbbbbbbbbbzz",
      "aaabbbbbbbbbbbzz",
      "aazbbbbbbbbbbbzz",
      "aazzzzzzzzzzzzzz",
      "aaazzzzzzzzzzzzz"
    ],
    [
      "    d  e f d d d",
      "      d     g d ",
      "   hhhhhhhhhhh  ",
      "   hijj!iklmih d",
      "     nnn k   h  ",
      "         opooh  ",
      "           q hd ",
      "          rs h  ",
      "     t   ruwxh  ",
      "     y   Auwxh  ",
      "      B A uCxh d",
      "    xxxxxDEFxhd ",
      "   hiIJKiLMMih  ",
      "   hhhhhhhhhhhd ",
      "   dd ddd dN    ",
      "    Odd dNdd  e "
    ],
    [
      "                ",
      "            g   ",
      "   hhhhhhhhhhh  ",
      "   hinn ik Pih  ",
      "   Q     k   h  ",
      "   Q     oRooh  ",
      "   Q       S h  ",
      "   Q       T h  ",
      "   Q        xh  ",
      "   Q        xh  ",
      "   Q        xh  ",
      "   Q    UV Wxh  ",
      "   hi X i MMih  ",
      "   hhhhhhhhhhh  ",
      "                ",
      "                "
    ],
    [
      "                ",
      "            Y   ",
      "   hhhhhhhhhhh  ",
      "   hi   ik  ih  ",
      "   Q   Z k   h  ",
      "   Q     ooooh  ",
      "   Q         h  ",
      "   Q         h  ",
      "   Q       0xh  ",
      "   Q       0xh  ",
      "   Q        xh  ",
      "   Q      1  h  ",
      "   hi234i MMih  ",
      "   hhhhhhhhhhh  ",
      "                ",
      "                "
    ],
    [
      "                ",
      "                ",
      "   hh567h567hh  ",
      "   hi888i888ih  ",
      "  9h@#$$%k   h  ",
      "  9h@   ^ooooh  ",
      "  9h@        h  ",
      "  9h@        h  ",
      "  9h  &      h  ",
      "  9h         h  ",
      "  9h         h  ",
      "  9h         h  ",
      "   hi888i888ih  ",
      "   hh567h567hh  ",
      "                ",
      "                "
    ],
    [
      "                ",
      "                ",
      "   ***********  ",
      "   h(((((((((h  ",
      "   h)   )   )h  ",
      "   h888888888h  ",
      "   h         h  ",
      "   h         h  ",
      "   h  +   +  h  ",
      "   h         h  ",
      "   h888888888h  ",
      "   h-   -   -h  ",
      "   h(((((((((h  ",
      "   ***********  ",
      "                ",
      "                "
    ]
  ]
}