{
  "name": "building_bank1_top_90",
  "refpalette": "c70cities:building_bank1_top_palette_90",
  "xsize": 16,
  "zsize": 16,
  "slices": [
    [
      "                ",
      "  abbbc abbbc   ",
      "  deeeedeeeeeda ",
      " ceeeeeeeeeeeeb ",
      " beeeeeeeeeeeeb ",
      " beeeeeeeeeeeeb ",
      " beeeeeeeeeeeec ",
      " aeeeeeeeeeeed  ",
      "  deeeeeeeeeeea ",
      " ceeeeeeeeeeeeb ",
      " beeeeeeeeeeeeb ",
      " beeeeeeeeeeeeb ",
      " beee     eeeec ",
      " adeeeeedeeeed  ",
      "   cbbba cbbba  ",
      "                "
    ],
    [
      "                ",
      " fbcc abbcc abf ",
      " bgggghggggghgb ",
      " ah        swgc ",
      "  g      r sugc ",
      " cg  k o r sug  ",
      " cg  j   q suha ",
      " bg  imnmp stgb ",
      " bg        stgb ",
      " ah   l l  sugc ",
      "  g        sugc ",
      " cg        sug  ",
      " cg        stha ",
      " bghggggghggggb ",
      " fba ccbba ccbf ",
      "                "
    ],
    [
      "                ",
      " fbbbbbbbbbbbbf ",
      " bgggghggggghgb ",
      " bh         ugb ",
      " bg      r  ugb ",
      " bg      r  ugb ",
      " bg         uhb ",
      " bg  x   y  ugb ",
      " bg         ugb ",
      " bh         ugb ",
      " bg         ugb ",
      " bg         ugb ",
      " bg         uhb ",
      " bghggggghggggb ",
      " fbbbbbbbbbbbbf ",
      "                "
    ],
    [
      "                ",
      "                ",
      "   gghggggghg   ",
      "  gg        gg  ",
      "  h          g  ",
      "  g          h  ",
      "  g          g  ",
      "  g          g  ",
      "  g          g  ",
      "  g          g  ",
      "  h          g  ",
      "  g          h  ",
      "  gg        gg  ",
      "   ghggggghgg   ",
      "                ",
      "                "
    ],
    [
      "                ",
      "                ",
      "                ",
      "    gggggggg    ",
      "   gggggggggg   ",
      "   gggA   ggg   ",
      "   gg      gg   ",
      "   gg      gg   ",
      "   gg      gg   ",
      "   gg      gg   ",
      "   ggg   Aggg   ",
      "   gggggggggg   ",
      "    gggggggg    ",
      "                ",
      "                ",
      "                "
    ],
    [
      "                ",
      "                ",
      "                ",
      "                ",
      "                ",
      "      gggg      ",
      "     gggggg     ",
      "     gggggg     ",
      "     gggggg     ",
      "     gggggg     ",
      "      gggg      ",
      "                ",
      "                ",
      "                ",
      "                ",
      "                "
    ]
  ]
}