{
  "name": "building_residential3_ground",
  "refpalette": "c70cities:building_residential3_ground_palette",
  "xsize": 16,
  "zsize": 16,
  "slices": [
    [
      "GGGGGGGGGGGGGGGG",
      "GGGGGGGGGGGGGGGG",
      "GGaaaaaaaaaaaaGG",
      "GGabbbbbbbbbbaGG",
      "GGabbbbbbbbbbaGG",
      "GGabbbbbbbbbbaGG",
      "GGabbbbbbbbbbaGG",
      "GGaabbbbbbbbbaGG",
      "GGGcddddbbbbbaGG",
      "GGGcddddbbbbbaGG",
      "GGGcddddbbbbbaGG",
      "GGGcddddbbbbbaGG",
      "GGGcccccabbbbaGG",
      "GGGGGGGGaaaaaaGG",
      "GGGGGGGGGGGGGGGG",
      "GGGGGGGGGGGGGGGG"
    ],
    [
      "effffgffffgffffe",
      "f              f",
      "e hhhhhhhhhhhh f",
      "i j   k  !l mh f",
      "  n       l oh f",
      "  p       qrqh g",
      "e j ss       h f",
      "f hhttu w   xh f",
      "f  cy   w   xh f",
      "f Ac    h    h f",
      "g Ac    hB  Ch e",
      "f AcDEFIhB  Jh f",
      "f Accccch    h f",
      "f AAAAAAhjKKjh f",
      "f              f",
      "effffgffffgffffe"
    ],
    [
      "effffgffffgffffe",
      "f              f",
      "e hhKKKhhKhLhh f",
      "  j    k  l  h f",
      "  M      Nl  L f",
      "  O       qPqh g",
      "e j          K f",
      "f hh    w   Qh f",
      "f  c    w   Rh f",
      "f  S    h    K f",
      "g  S    hT   K e",
      "f  cU  VhT   K f",
      "f  ccSSch    h f",
      "f       hjKKjh f",
      "f              f",
      "effffgffffgffffe"
    ],
    [
      "                ",
      "                ",
      "W hhXXXhhXhXhh  ",
      "  j     k l  h  ",
      "  Y       l  Z  ",
      "  Y       qqqh  ",
      "  j          Z  ",
      "  hh    w    h  ",
      "  0c    w    h  ",
      "  0c    h    Z  ",
      "  0c    h    Z W",
      "  0c    h    Z  ",
      "  0ccccch    h  ",
      "  000000hj11jh  ",
      "                ",
      "                "
    ],
    [
      "                ",
      "                ",
      "  hhhhhhhhhhhh  ",
      "  hbbb   kbbbh  ",
      "  hbbbbbbbbbbh  ",
      "  hbbbbbbbbbbh  ",
      "  hbbbbbbbbbbh  ",
      "  hhbbbbbbbbbh  ",
      "  23    bbbbbh  ",
      "  23    bbbbbh  ",
      "  23    bbbbbh  ",
      "  23    bbbbbh  ",
      "  245555hbbbbh  ",
      "  222222hhhhhh  ",
      "                ",
      "                "
    ],
    [
      "                ",
      "                ",
      "  hhXXXhhXXXhh  ",
      "  K667      8K  ",
      "  K   9999   K  ",
      "  K          K  ",
      "  K@@#     $ K  ",
      "  hh%%%%% ^&*h  ",
      "  2c   (% jjjh  ",
      "  2c    % ))#Z  ",
      "  2c    % )+-Z  ",
      "  2c    % )+-Z  ",
      "  2ccccch )) h  ",
      "  222222hKKKKh  ",
      "                ",
      "                "
    ]
  ]
}