{
  "name": "building_office3_floor2_90",
  "refpalette": "c70cities:building_office3_floor2_palette_90",
  "xsize": 16,
  "zsize": 16,
  "slices": [
    [
      "                ",
      " aabaabaabaabaa ",
      " acccccccccccca ",
      " bccccccccccccb ",
      " acccccccccccca ",
      " acccccccccccca ",
      " bccccccccccccb ",
      " acccccddccccca ",
      " acccccvvccccca ",
      " bccccccccccccb ",
      " accc!cccccccca ",
      " acccccccccccca ",
      " bccccccccccccb ",
      " acccccccccccca ",
      " aabaabaabaabaa ",
      "                "
    ],
    [
      "                ",
      " eebeebeebeebee ",
      " ef          fe ",
      " b g ij  hi g b ",
      " e   i    i   e ",
      " e  hi    ij  e ",
      " b            b ",
      " e     dd     e ",
      " e     vv     e ",
      " b     kk     b ",
      " e  hi    ij  e ",
      " e   i    i   e ",
      " b g ij  hi g b ",
      " ef          fe ",
      " eebeebeebeebee ",
      "                "
    ],
    [
      "                ",
      " llbllbllbllbll ",
      " lf          fl ",
      " b g        g b ",
      " l            l ",
      " l            l ",
      " b            b ",
      " l     dd     l ",
      " l     vv     l ",
      " b            b ",
      " l            l ",
      " l            l ",
      " b g        g b ",
      " lf          fl ",
      " llbllbllbllbll ",
      "                "
    ],
    [
      "                ",
      " llbllbllbllbll ",
      " l            l ",
      " b g        g b ",
      " l            l ",
      " l            l ",
      " b            b ",
      " l     dd     l ",
      " l     vv     l ",
      " b            b ",
      " l            l ",
      " l            l ",
      " b g        g b ",
      " l            l ",
      " llbllbllbllbll ",
      "                "
    ],
    [
      "                ",
      " llbllbllbllbll ",
      " l            l ",
      " b g        g b ",
      " l            l ",
      " l            l ",
      " b            b ",
      " l     dd     l ",
      " l     vv     l ",
      " b            b ",
      " l            l ",
      " l            l ",
      " b g        g b ",
      " l            l ",
      " llbllbllbllbll ",
      "                "
    ],
    [
      "                ",
      " llbllbllbllbll ",
      " lmmmmmmmmmmmml ",
      " bmgnnnnnnnngmb ",
      " lmnnnnnnnnnnml ",
      " lmnnnnnnnnnnml ",
      " bmnnnnnnnnnnmb ",
      " lmnnnnddnnnnml ",
      " lmnnnnvvnnnnml ",
      " bmnnnnnnnnnnmb ",
      " lmnnnnnnnnnnml ",
      " lmnnnnnnnnnnml ",
      " bmgnnnnnnnngmb ",
      " lmmmmmmmmmmmml ",
      " llbllbllbllbll ",
      "                "
    ]
  ]
}