{
  "name": "building_bank1_base1_270",
  "refpalette": "c70cities:building_bank1_base1_palette_270",
  "xsize": 16,
  "zsize": 16,
  "slices": [
    [
      "vvvvvvvvvvvvvvvv",
      "vaabbaaaabbaaaav",
      "vabbbbbbbbbbbbav",
      "vabbbbbbbbbbb!bv",
      "vabbbbbbbbbbbbbv",
      "vbbbbbbbbbbbbbav",
      "vbbbbbbbbbbbbbav",
      "vabbbbbbbbbbbbav",
      "vabbbbbbbbbbbbav",
      "vabbbbbbbbbbbbbv",
      "vabbbbbbbbbbbbbv",
      "vb!bbbbbbbbbbbav",
      "vbbbbbbbbbbbbbav",
      "vabbbbbbbbbbbbav",
      "vaaaabbaaaabbaav",
      "vvvvvvvvvvvvvvvv"
    ],
    [
      "vvvvvvvvvvvvvvvv",
      "vaabbaaaabbaaaav",
      "va ccfidhcc f av",
      "va j         cbv",
      "va           cbv",
      "vbc         fdav",
      "vbc   f      eav",
      "vaf          fav",
      "vaf      f   fav",
      "vaf          cbv",
      "vaf          cbv",
      "vbc          eav",
      "vbc           av",
      "vaiidccffffccgav",
      "vaaaabbaaaabbaav",
      "vvvvvvvvvvvvvvvv"
    ],
    [
      "vvvvvvvvvvvvvvvv",
      "vaabbaaaabbaaaav",
      "va cce dmcc   av",
      "va j         cbv",
      "va           cbv",
      "vbc          eav",
      "vbc           av",
      "van          kav",
      "vai           av",
      "van          cbv",
      "va           cbv",
      "vbc           av",
      "vbc           av",
      "vaiedcc hlhcc av",
      "vaaaabbaaaabbaav",
      "vvvvvvvvvvvvvvvv"
    ],
    [
      "vvvvvvvvvvvvvvvv",
      "vaabbaaaabbaaaav",
      "va cc    cc   av",
      "va j         cbv",
      "va           cbv",
      "vbc           av",
      "vbc           av",
      "va            av",
      "va            av",
      "va           cbv",
      "va           cbv",
      "vbc           av",
      "vbc           av",
      "va   cc    cc av",
      "vaaaabbaaaabbaav",
      "vvvvvvvvvvvvvvvv"
    ],
    [
      "vvvvvvvvvvvvvvvv",
      "vaabbaaaabbaaaav",
      "va cc    cc   av",
      "va j         cbv",
      "va           cbv",
      "vbc           av",
      "vbc           av",
      "va            av",
      "va            av",
      "va           cbv",
      "va           cbv",
      "vbc           av",
      "vbc           av",
      "va   cc    cc av",
      "vaaaabbaaaabbaav",
      "vvvvvvvvvvvvvvvv"
    ],
    [
      "vvvvvvvvvvvvvvvv",
      "vaabbaaaabbaaaav",
      "vaqccooooccoogav",
      "vaojooooooooocbv",
      "vaooooooooooocbv",
      "vbcoooooooooooav",
      "vbcoooooooooooav",
      "vaooooooooooooav",
      "vaooooooooooooav",
      "vaooooooooooocbv",
      "vaooooooooooocbv",
      "vbcoooooooooooav",
      "vbcoooooooooooav",
      "vagooccooooccpav",
      "vaaaabbaaaabbaav",
      "vvvvvvvvvvvvvvvv"
    ]
  ]
}