{
  "name": "building_apartment1_top",
  "refpalette": "c70cities:building_apartment1_top_palette",
  "xsize": 16,
  "zsize": 16,
  "slices": [
    [
      "                ",
      " aaaaaaaaaaaaaa ",
      " abbbbbbbbbbbba ",
      " abccccccccccba ",
      " abccccccccccba ",
      " abccccccccccba ",
      " abccccccccccba ",
      " abccccccccccba ",
      " abccccccccccba ",
      " abccccccccccba ",
      " abcccccccd  b  ",
      " abccccccc   e  ",
      " abccccccc   e  ",
      " abbbbbbbbbfgh  ",
      " aaaaaaaaa      ",
      "                "
    ],
    [
      "                ",
      "                ",
      "  iijbbklbiijm  ",
      "  in  on     l  ",
      "  i   o      b  ",
      "  bn  o      b  ",
      "  boooo      i  ",
      "  m !on      i  ",
      "  l  o       p  ",
      "  l  o  nqrqqb  ",
      "  s no ntq   b  ",
      "  boou  tq   b  ",
      "  b no  nq   b  ",
      "  bbbbllwbiibb  ",
      "                ",
      "                "
    ],
    [
      "                ",
      "                ",
      "  bbiiibbbbbbb  ",
      "  b          b  ",
      "  b          b  ",
      "  b          b  ",
      "  b          b  ",
      "  b          b  ",
      "  b          b  ",
      "  b      qxqqb  ",
      "  b     yq   g  ",
      "  l     yq   i  ",
      "  l      q   b  ",
      "  biijbbbbbbbb  ",
      "                ",
      "                "
    ],
    [
      "                ",
      "                ",
      "  bbbbbbkllbbb  ",
      "  b          l  ",
      "  b          l  ",
      "  l          l  ",
      "  l          s  ",
      "  l          b  ",
      "  b          b  ",
      "  b      AAAAb  ",
      "  b      AAAAb  ",
      "  b     nAAAAb  ",
      "  b      AAAAb  ",
      "  bbbbbllbbbbb  ",
      "                ",
      "                "
    ],
    [
      "                ",
      "                ",
      "                ",
      "                ",
      "                ",
      "                ",
      "                ",
      "                ",
      "                ",
      "                ",
      "                ",
      "                ",
      "                ",
      "                ",
      "                ",
      "                "
    ],
    [
      "                ",
      "                ",
      "                ",
      "                ",
      "                ",
      "                ",
      "                ",
      "                ",
      "                ",
      "                ",
      "                ",
      "                ",
      "                ",
      "                ",
      "                ",
      "                "
    ]
  ]
}