{
  "name": "building_residential4_ground_90",
  "refpalette": "c70cities:building_residential4_ground_palette_90",
  "xsize": 16,
  "zsize": 16,
  "slices": [
    [
      "GGGGGGGGGGGGGGGG",
      "GGGGGGGGGGGGGGGG",
      "GGaGGGGGGGGGGaGG",
      "GGaddddddddddaGG",
      "GGaccccccccccaGG",
      "GGaccccccccccaGG",
      "GGaccccccccccaGG",
      "GGabbbbbbbbbbaGG",
      "GGabbbbbbbbbbaGG",
      "GGabbbbbbbbbbaGG",
      "GGabbbbbbbbbbaGG",
      "GGabbbbbbbbbbaGG",
      "GGabbbbbbbbbbaGG",
      "GGaaaaaaaaaaaaGG",
      "GGGGGGGGGGGGGGGG",
      "GGGGGGGGGGGGGGGG"
    ],
    [
      "effffgffffgffffe",
      "f              f",
      "f hooooooooooh f",
      "f hddddddddddh f",
      "f inntwyBwCFMN f",
      "g i       C LN g",
      "f hmms    CEKh f",
      "f ill        N f",
      "f i          N f",
      "f hkkkuu    Jh f",
      "g i qq       N g",
      "f i          N f",
      "f h pr     DIh f",
      "f hjjjhxAhjjjh f",
      "f              f",
      "efffffe  efffffe"
    ],
    [
      "effffgffffgffffe",
      "f              f",
      "f h          h f",
      "f hddddUUddddh f",
      "f O  S  WXC  0 f",
      "g O       C  0 g",
      "f h R     CYKh f",
      "f O          O f",
      "f O          O f",
      "f hPPPuu     h f",
      "g O QQ      JO g",
      "f O         ZO f",
      "f h          h f",
      "f hOOOhTVhOOOh f",
      "f              f",
      "efffffe  efffffe"
    ],
    [
      "                ",
      "                ",
      "  h1111111111h  ",
      "  hddddUUddddh  ",
      "  h       C  h  ",
      "  h       C  h  ",
      "  h       CKKh  ",
      "  h          h  ",
      "  h          h  ",
      "  hPPPuu     h  ",
      "  h          h  ",
      "  h        2 h  ",
      "  h          h  ",
      "  hOOOhOOhOOOh  ",
      "                ",
      "                "
    ],
    [
      "                ",
      " 3N          i5 ",
      " 3h4444  4444h5 ",
      " 3hddddddddddh5 ",
      " 3hbbbbbbbbbbh5 ",
      " 3hbbbbbbbbbbh5 ",
      " 3hbbbbbbbbbbh5 ",
      " 3hbbbbbbbbbbh5 ",
      " 3hbbbbbbbbbbh5 ",
      " 3hbbbbbbb   h5 ",
      " 3hbbbbbbb   h5 ",
      " 3hbbbbbbb2  h5 ",
      " 3hbbbbbbbbbbh5 ",
      " 3hhhhhhhhhhhh5 ",
      " 3N          i5 ",
      "                "
    ],
    [
      "                ",
      "  3N        i5  ",
      "  34444&(44445  ",
      "  3dddddddddd5  ",
      "  3h4 @^ -]{ 5  ",
      "  3h4999 -  }5  ",
      "  3h4999 -  }5  ",
      "  3h4  % -  !5  ",
      "  3h4    +   5  ",
      "  3h4888 )[[[5  ",
      "  3h4778 )   5  ",
      "  3h466$     5  ",
      "  3dddddddddd5  ",
      "  34444#*44445  ",
      "  3N        i5  ",
      "                "
    ]
  ]
}