{
  "name": "building_office2_floor2_180",
  "refpalette": "c70cities:building_office2_floor2_palette_180",
  "xsize": 16,
  "zsize": 16,
  "slices": [
    [
      "                ",
      " aaaaaaaaaaaaaa ",
      "   bcccffcccb   ",
      "  decccccccced  ",
      "  decccccccced  ",
      "  decccccccced  ",
      "  decccccccced  ",
      "  decccccccced  ",
      "  decccccccced  ",
      "  decccccccced  ",
      "  decccccccced  ",
      "  decccccccced  ",
      "  decccccccced  ",
      "   bccccccc!b   ",
      " aaaaaaaaaaaaaa ",
      "                "
    ],
    [
      "                ",
      " aaaaaaaaaaaaaa ",
      "   bjlkffkjjb   ",
      "  d          d  ",
      "  d          d  ",
      "  d ih    hg d  ",
      "  d  h    h  d  ",
      "  d  hg  ih  d  ",
      "  d          d  ",
      "  d          d  ",
      "  d  hg  ih  d  ",
      "  d  h    h  d  ",
      "  d ih    hg d  ",
      "   b        b   ",
      " aaaaaaaaaaaaaa ",
      "                "
    ],
    [
      "                ",
      " aaaaaaaaaaaaaa ",
      "   b  nffn  b   ",
      "  d          d  ",
      "  d          d  ",
      "  d  m    m  d  ",
      "  d          d  ",
      "  d  m    m  d  ",
      "  d          d  ",
      "  d          d  ",
      "  d  m    m  d  ",
      "  d          d  ",
      "  d  m    m  d  ",
      "   b        b   ",
      " aaaaaaaaaaaaaa ",
      "                "
    ],
    [
      "                ",
      " aaaaaaaaaaaaaa ",
      "   b   ff   b   ",
      "  d          d  ",
      "  d          d  ",
      "  d          d  ",
      "  d          d  ",
      "  d          d  ",
      "  d          d  ",
      "  d          d  ",
      "  d          d  ",
      "  d          d  ",
      "  d          d  ",
      "   b        b   ",
      " aaaaaaaaaaaaaa ",
      "                "
    ],
    [
      "                ",
      " aaaaaaaaaaaaaa ",
      "   b   ff   b   ",
      "  d          d  ",
      "  d          d  ",
      "  d          d  ",
      "  d          d  ",
      "  d          d  ",
      "  d          d  ",
      "  d          d  ",
      "  d          d  ",
      "  d          d  ",
      "  d          d  ",
      "   b        b   ",
      " aaaaaaaaaaaaaa ",
      "                "
    ],
    [
      "                ",
      " aaaaaaaaaaaaaa ",
      "   boooffooob   ",
      "  d oooooooo d  ",
      "  d oooooooo d  ",
      "  d oooooooo d  ",
      "  d oooooooo d  ",
      "  d oooooooo d  ",
      "  d oooooooo d  ",
      "  d oooooooo d  ",
      "  d oooooooo d  ",
      "  d oooooooo d  ",
      "  d oooooooo d  ",
      "   boooooooob   ",
      " aaaaaaaaaaaaaa ",
      "                "
    ]
  ]
}