{
  "name": "building_office4_ground_180",
  "refpalette": "c70cities:building_office4_ground_palette_180",
  "xsize": 16,
  "zsize": 16,
  "slices": [
    [
      "GGGGGGGGGGGGGGGG",
      "GaaaaaaaaaaaaaaG",
      "GabbbcbbbbcbbbaG",
      "GabbbbbbbbbbbbaG",
      "GabbbbbbbbbbbbaG",
      "GacbbbbbbbbbbcaG",
      "GabbbbbbbbbbbbaG",
      "GabbbbbbbbbbbbaG",
      "GabbbbbbbbbbbbaG",
      "GabbbbbbbbbbbbaG",
      "GacbbbbbbbbbbcaG",
      "GabbbbbbbbbbbbaG",
      "GabbbbbbbbbbbbaG",
      "GabbbcbbbbcbbbaG",
      "GaaaaaaaaaaaaaaG",
      "GGGGGGGGGGGGGGGG"
    ],
    [
      "                ",
      " aaaadaaaadaaaa ",
      " aeqqc sr cqqea ",
      " ak          ja ",
      " ak          ja ",
      " dc     l    cd ",
      " a     mlj    a ",
      " p      l    na ",
      " o      l    na ",
      " a     mlj    a ",
      " dc     l    cd ",
      " ak          ja ",
      " ak          ja ",
      " aeffcihg cffea ",
      " aaaadaaaadaaaa ",
      "                "
    ],
    [
      "                ",
      " aaaadaaaadaaaa ",
      " at  c    c  ta ",
      " a            a ",
      " a            a ",
      " dc     y    cd ",
      " a            a ",
      " x           na ",
      " w      u    na ",
      " a            a ",
      " dc          cd ",
      " a            a ",
      " a            a ",
      " at  c    c  ta ",
      " aaaadaaaadaaaa ",
      "                "
    ],
    [
      "                ",
      " aaaadaaaadaaaa ",
      " at  c    c  ta ",
      " a            a ",
      " a            a ",
      " dc          cd ",
      " a            a ",
      " a           na ",
      " a           na ",
      " a            a ",
      " dc          cd ",
      " a            a ",
      " a            a ",
      " at  c    c  ta ",
      " aaaadaaaadaaaa ",
      "                "
    ],
    [
      "                ",
      " aaaadaaaadaaaa ",
      " a   c    c   a ",
      " a            a ",
      " a            a ",
      " dc          cd ",
      " a            a ",
      " a     BA    na ",
      " a     BA    na ",
      " a            a ",
      " dc          cd ",
      " a            a ",
      " a            a ",
      " a   c    c   a ",
      " aaaadaaaadaaaa ",
      "                "
    ],
    [
      "                ",
      "    adaaaada    ",
      "  CCCcDDDDcCCC  ",
      "  CDDDDDDDDDDC  ",
      " aCDDDDDDDDDDCa ",
      " dcDDDDDDDDDDcd ",
      " aDDDDDDDDDDDDa ",
      " aDDDDDEEDDDDna ",
      " aDDDDDEEDDDDna ",
      " aDDDDDDDDDDDDa ",
      " dcDDDDDDDDDDcd ",
      " aCDDDDDDDDDDCa ",
      "  CDDDDDDDDDDC  ",
      "  CCCcDDDDcCCC  ",
      "    adaaaada    ",
      "                "
    ]
  ]
}