{
  "name": "building_residential3_ground",
  "refpalette": "c70cities:building_residential3_ground_palette",
  "xsize": 16,
  "zsize": 16,
  "slices": [
    [
      "GGGGGGGGGGGGGGGG",
      "GGGGGGGGGGGGGGGG",
      "GGaaaaaaaaaaaaGG",
      "GGabbbbbbbbbbaGG",
      "GGabbbbbbbbbbaGG",
      "GGabbbbbbbbbbaGG",
      "GGabbbbbbbbbbaGG",
      "GGaabbbbbbbbbaGG",
      "GGGcddddbbbbbaGG",
      "GGGcddddbbbbbaGG",
      "GGGcddddbbbbbaGG",
      "GGGcddddbbbbbaGG",
      "GGGcccccabbbbaGG",
      "GGGGGGGGaaaaaaGG",
      "GGGGGGGGGGGGGGGG",
      "GGGGGGGGGGGGGGGG"
    ],
    [
      "effffgffffgffffe",
      "f              f",
      "f hhhhhhhhhhhh f",
      "e i   j  !k  h f",
      "  l       k mh f",
      "  n       opoh g",
      "e i qq       h f",
      "f hhrrs t   uh f",
      "f  cw   t   uh f",
      "f xc    h    h f",
      "g xc    hy  Ah e",
      "f xcBCDEhy  Fh f",
      "f xccccch    h f",
      "f xxxxxxhiIIih f",
      "f              f",
      "effffgffffgffffe"
    ],
    [
      "effffgffffgffffe",
      "f              f",
      "f hhIIIhhIhJhh f",
      "e i    j  k  h f",
      "  K      Lk MJ f",
      "  N       oOoh g",
      "e i          I f",
      "f hh    t   Ph f",
      "f  c    t   Qh f",
      "f  R    h    I f",
      "g  R    hS   I e",
      "f  cT  UhS   I f",
      "f  ccRRch    h f",
      "f       hiIIih f",
      "f              f",
      "effffgffffgffffe"
    ],
    [
      "                ",
      "                ",
      "  hhVVVhhVhVhh  ",
      "W i     j k  h  ",
      "  X       k  Y  ",
      "  X       oooh  ",
      "  i          Y  ",
      "  hh    t    h  ",
      "  Zc    t    h  ",
      "  Zc    h    Y  ",
      "  Zc    h    Y W",
      "  Zc    h    Y  ",
      "  Zccccch    h  ",
      "  ZZZZZZhi00ih  ",
      "                ",
      "                "
    ],
    [
      "                ",
      "                ",
      "  hhhhhhhhhhhh  ",
      "  hbbb   jbbbh  ",
      "  hbbbbbbbbbbh  ",
      "  hbbbbbbbbbbh  ",
      "  hbbbbbbbbbbh  ",
      "  hhbbbbbbbbbh  ",
      "  12    bbbbbh  ",
      "  12    bbbbbh  ",
      "  12    bbbbbh  ",
      "  12    bbbbbh  ",
      "  134444hbbbbh  ",
      "  111111hhhhhh  ",
      "                ",
      "                "
    ],
    [
      "                ",
      "                ",
      "  hhVVVhhVVVhh  ",
      "  I556       I  ",
      "  I   7777   I  ",
      "  I          I  ",
      "  I889     @ I  ",
      "  hh##### $%^h  ",
      "  1c   &# iiih  ",
      "  1c    # **9Y  ",
      "  1c    # *()Y  ",
      "  1c    # *()Y  ",
      "  1ccccch ** h  ",
      "  111111hIIIIh  ",
      "                ",
      "                "
    ]
  ]
}