{
  "name": "building_hotel3_ground",
  "refpalette": "c70cities:building_hotel3_ground_palette",
  "xsize": 16,
  "zsize": 16,
  "slices": [
    [
      "GGGGGGGGGGGGGGGG",
      "GaaaaaaaaaaaaaaG",
      "GabbbbbbbbbbbbaG",
      "GabbbbbbbbbbbbaG",
      "GabbcbbccbbcbbaG",
      "Gab!bbbddbbbbbaG",
      "GabbbbbbbbbbbbaG",
      "GabbbbbbbbbbbbaG",
      "GabbbbbbbbbbbbaG",
      "GabbbbbbbbbbbbaG",
      "GabbbbbbbbbbbbaG",
      "GabbcbbbbbbcbbaG",
      "GabbbbbbbbbbbbaG",
      "GabbbbbbbbbbbbaG",
      "GaaaaaaaaaaaaaaG",
      "GGGGGGGGGGGGGGGG"
    ],
    [
      "                ",
      " aaaaaaaaaaaaaa ",
      " aeeeeeeeeeeeea ",
      " ae f  gg  f ea ",
      " ae c  cc  c ea ",
      " ae c      c ea ",
      " aehh        ea ",
      " aehi        ea ",
      " aehi        ea ",
      " aehh         j ",
      " ae           k ",
      " ae l mmmm l ea ",
      " ae   n  n   ea ",
      " ae o      o ea ",
      " aaaaaaaaaaaaaa ",
      "                "
    ],
    [
      "                ",
      "  p p p p p p   ",
      "  eeeeeeeeeeeep ",
      " pe f  gg  f e  ",
      " ae c  cc  c ea ",
      " ae c      c ea ",
      " ae          ea ",
      " ae          ea ",
      " ae          ea ",
      " ae           q ",
      " ae           r ",
      " ae l   s  l ea ",
      " ae          ea ",
      " ae f      f ea ",
      " aaaaaaaaaaaaaa ",
      "                "
    ],
    [
      "                ",
      "  p p p p p p   ",
      "  eeeeeeeeeeeep ",
      " pe f  gg  f e  ",
      "  e c  cc  c ep ",
      " pe c      c e  ",
      "  e          ep ",
      " ae          ea ",
      " ae          ea ",
      " ae          ea ",
      " ae          ea ",
      " ae l      l ea ",
      " ae          ea ",
      " ae f      f ea ",
      " aaaaaaaaaaaaaa ",
      "                "
    ],
    [
      "                ",
      "  p p p p p p   ",
      "  eeeeeeeeeeeep ",
      " pe    gg    e  ",
      "  e cttccttc ep ",
      " pe c      c e  ",
      "  e          ep ",
      " pe          e  ",
      "  e          ep ",
      " pe          e  ",
      " ae          ea ",
      " ae l      l ea ",
      " ae          ea ",
      " ae          ea ",
      " aaaaaaaaaaaaaa ",
      "                "
    ],
    [
      "                ",
      "  p p p p p p   ",
      "  eeeeeeeeeeeep ",
      " pe    gg    e  ",
      "  e cccccccc ep ",
      " pe cuuuuuuc e  ",
      "  e cuuuuuuc ep ",
      " pe cuuuuuuc e  ",
      "  e cuuuuuuc ep ",
      " pe cuuuuuuc e  ",
      "  e cuuuuuuc ep ",
      " pe lccccccl e  ",
      "  e          ep ",
      " aeeeeeeeeeeeea ",
      " aaaaaaaaaaaaaa ",
      "                "
    ]
  ]
}