{
  "name": "building_office1_top_90",
  "refpalette": "c70cities:building_office1_top_palette_90",
  "xsize": 16,
  "zsize": 16,
  "slices": [
    [
      "                ",
      "        c  eeee ",
      "  aaaaaacddfbbe ",
      "  abbbbbbbbbbbe ",
      "  abbbbbbbbbbbe ",
      "  abbbbbbbbbbbe ",
      "  abbbbbbbbbbbe ",
      "  abbbbbbbbbbbe ",
      "  abbbbbbbbbbbe ",
      "  abbbbbbbbbbbe ",
      "  abbbbbbbbbbbe ",
      "  abbbbbbbbbbbe ",
      "  abbbbbbbbgbbe ",
      "  aaaaaacddfbbe ",
      "        c  eeee ",
      "                "
    ],
    [
      "                ",
      "        c  mmmm ",
      "  hhhhhhcddfppm ",
      "  h     l  n  m ",
      "  h iiii      m ",
      "  h ijji   k qm ",
      "  h        k qm ",
      "  h  kk       m ",
      "  h  kk       m ",
      "  h        k qm ",
      "  h ijji   k qm ",
      "  h iiii      m ",
      "  h     l     m ",
      "  hhhhhhcddfoom ",
      "        c  mmmm ",
      "                "
    ],
    [
      "                ",
      "        c  mmmm ",
      "   r r rcddfppm ",
      "        s     t ",
      "              d ",
      "              d ",
      "              d ",
      "              d ",
      "              d ",
      "              d ",
      "              d ",
      "              d ",
      "        s     t ",
      "   r r rcddfoom ",
      "        c  mmmm ",
      "                "
    ],
    [
      "                ",
      "        c  mmmm ",
      "   r r rcddf  m ",
      "              t ",
      "              d ",
      "              d ",
      "              d ",
      "              d ",
      "              d ",
      "              d ",
      "              d ",
      "              d ",
      "              t ",
      "   r r rcddfoom ",
      "        c  mmmm ",
      "                "
    ],
    [
      "                ",
      "        c  mmmm ",
      "   r r rcfff  m ",
      "        fuuf  m ",
      "        fuuf  m ",
      "        fuuf  m ",
      "        fuuf  m ",
      "        fuuf  m ",
      "        fuuf  m ",
      "        fuuf  m ",
      "        fuuf  m ",
      "        fuuf  m ",
      "        fuuf  m ",
      "   r r rcfff  m ",
      "        c  mmmm ",
      "                "
    ],
    [
      "                ",
      "        c  mmmm ",
      "  wwwwwwc  uuum ",
      "  weeeeew  uuum ",
      "  weeeeew  uuum ",
      "  weeeeew  uuum ",
      "  weeeeew  uuum ",
      "  weeeeew  uuum ",
      "  weeeeew  uuum ",
      "  weeeeew  uuum ",
      "  weeeeew  uuum ",
      "  weeeeew  uuum ",
      "  weeeeew  uuum ",
      "  wwwwwwc  uuum ",
      "        c  mmmm ",
      "                "
    ]
  ]
}