{
  "name": "building_hotel2_floor2",
  "refpalette": "c70cities:building_hotel2_floor2_palette",
  "xsize": 16,
  "zsize": 16,
  "slices": [
    [
      "                ",
      " aaaaaaaaaaaaaa ",
      " abccccccccd    ",
      " abccccccccd    ",
      " a=ccccccccd    ",
      " acccccccccd    ",
      " acccccccccd    ",
      " a!ccccccccd    ",
      " accccc!cccd    ",
      " a!ccccccccd    ",
      " acccccccccd    ",
      " acccccccccd    ",
      " acccccccccd    ",
      " adddddddddd    ",
      " a              ",
      "                "
    ],
    [
      "                ",
      " aaaaaaaaaaaaaa ",
      " ab   e    f    ",
      " ab   a    f    ",
      " a=aagahi jf    ",
      " akla ahi jf    ",
      " am a an   f    ",
      " ao p aq   f    ",
      " aaaa ar ssf    ",
      " a=tt aaaaaf    ",
      " a     uuw f    ",
      " a     xx  f    ",
      " ayAB      f    ",
      " affffffffff    ",
      " a              ",
      "                "
    ],
    [
      "                ",
      " aaaaaaaaaaaaaa ",
      " ab   C    f    ",
      " ab   a    f    ",
      " a=aaDa    f    ",
      " aE a a    f    ",
      " a  a a    f    ",
      " a  F a    f    ",
      " aaaa a  I f    ",
      " aJ   aaaaaf    ",
      " a         f    ",
      " a         f    ",
      " a K       f    ",
      " affffffffff    ",
      " a              ",
      "                "
    ],
    [
      "                ",
      " aaaaaaaaaaaaaa ",
      " ab   a    f    ",
      " ab   a    f    ",
      " a=aaaa    f    ",
      " aL a a    f    ",
      " a  a a    f    ",
      " a  a a    f    ",
      " aaaa a    f    ",
      " aMNN aaaaaf    ",
      " a         f    ",
      " a         f    ",
      " a         f    ",
      " affffffffff    ",
      " a              ",
      "                "
    ],
    [
      "                ",
      " aaaaaaaaaaaaaa ",
      " ab O a    f    ",
      " ab O a    f    ",
      " a=aaaa    f    ",
      " a  a a    f    ",
      " a  a a    f    ",
      " a  a a    f    ",
      " aaaa a    f    ",
      " aP   aaaaaf    ",
      " a         f    ",
      " a         f    ",
      " a         f    ",
      " affffffffff    ",
      " a              ",
      "                "
    ],
    [
      "                ",
      " aaaaaaaaaaaaaa ",
      " abQQQaQQQQK    ",
      " abQQQaQQQQK    ",
      " a=aaaaQQQQK    ",
      " aQQaQaQQQQK    ",
      " aQQaQaQQQQK    ",
      " aQQaQaQQQQK    ",
      " aaaaQaQQQQK    ",
      " aQQQQaaaaQK    ",
      " aQQQQQQQQQK    ",
      " aQQQQQQQQQK    ",
      " aQQQQQQQQQK    ",
      " aKKKKKKKKKK    ",
      " a              ",
      "                "
    ]
  ]
}