{
  "name": "building_hotel1_ground_180",
  "refpalette": "c70cities:building_hotel1_ground_palette_180",
  "xsize": 16,
  "zsize": 16,
  "slices": [
    [
      "GGGGGGGGGGGGGGGG",
      "GbbbbbbbbbbbbbbG",
      "Gbccccccccccc!bG",
      "GdccccccccccccbG",
      "GdccccccccccccbG",
      "GdccccccccccccbG",
      "GdccccddddccccbG",
      "GbccccGGGdccccbG",
      "GbccccGGGdccccbG",
      "GbccccGGG!ccccbG",
      "GbccccccccccccbG",
      "GbccccccccccccbG",
      "GbccccccccccccbG",
      "GbccccccccccccbG",
      "GbbbbbbbbbbbbbbG",
      "GGGGaGGGGGGaGGGG"
    ],
    [
      "                ",
      " bbbbbbbbbbbbbb ",
      " bm  A y   b xb ",
      " po  wuuuu b  b ",
      "  t   s s  brbb ",
      "  q           b ",
      " po   nggl   kb ",
      " bm   e  l   kb ",
      " b    e  l   kb ",
      " b    eeel   kb ",
      " b           jb ",
      " bgg   gg    jb ",
      " bgi h ig    fb ",
      " bgg h gg ffffb ",
      " bbbbbbbbbbbbbb ",
      " eeeeeeeeeeeeee "
    ],
    [
      "                ",
      " bbbbbbppppppbb ",
      " bB        b  b ",
      " po     F  b  b ",
      "  E        bDbb ",
      "  C           b ",
      " po     ng    p ",
      " bB      g    p ",
      " b       l    p ",
      " b       l    p ",
      " b            b ",
      " b            b ",
      " b           fb ",
      " b         fffb ",
      " bbbbbbbbbbbbbb ",
      "                "
    ],
    [
      "                ",
      " bbbbbbbbbbbbbb ",
      " bB        b Ib ",
      " po        b  b ",
      " po        bbbb ",
      " po           b ",
      " po           b ",
      " bB      n    b ",
      " b       g    b ",
      " b       g    b ",
      " b            b ",
      " b            b ",
      " b            b ",
      " b          Ifb ",
      " bbbbbbbbbbbbbb ",
      "                "
    ],
    [
      "                ",
      " bbbbbbppbbbbbb ",
      " b         b Ib ",
      " po        b Ib ",
      " po        bbbb ",
      " po          Ib ",
      " po           b~",
      " b            b ",
      " b            b ",
      " b     ggn    b ",
      " b            b ",
      " b            p ",
      " b            p ",
      " b          IIb ",
      " bbbbbbbbbbbbbb ",
      "                "
    ],
    [
      "                ",
      " bbbbbbbbbbbbbb ",
      " bJJJJJJJJJbJJb ",
      " pJJJJJJJJJbJJb ",
      " pJJJJJJJJJbbbb ",
      " pJJJJJJJJJJJJb ",
      " pJJJJ    JJJJb ",
      " bJJJJ    JJJJb ",
      " bJJJJ    JJJJb ",
      " bJJJJgn  JJJJb ",
      " bJJJJJJJJJJJJb ",
      " bJJJJJJJJJJJJb ",
      " bJJJJJJJJJJJJb ",
      " bJJJJJJJJJJJJb ",
      " bbbbbbbbbbbbbb ",
      "                "
    ]
  ]
}