{
  "name": "building_residential4_ground",
  "refpalette": "c70cities:building_residential4_ground_palette",
  "xsize": 16,
  "zsize": 16,
  "slices": [
    [
      "GGGGGGGGGGGGGGGG",
      "GGGGGGGGGGGGGGGG",
      "GGaaaaaaaaaaaaGG",
      "GGabbbbbbcccdGGG",
      "GGabbbbbbcccdGGG",
      "GGabbbbbbcccdGGG",
      "GGabbbbbbcccdGGG",
      "GGabbbbbbcccdGGG",
      "GGabbbbbbcccdGGG",
      "GGabbbbbbcccdGGG",
      "GGabbbbbbcccdGGG",
      "GGabbbbbbcccdGGG",
      "GGabbbbbbcccdGGG",
      "GGaaaaaaaaaaaaGG",
      "GGGGGGGGGGGGGGGG",
      "GGGGGGGGGGGGGGGG"
    ],
    [
      "effffgffffgffffe",
      "f              f",
      "f hhiihiihiihh f",
      "f j   k lm ndo f",
      "f jp qk lm ndo f",
      "f jr qk  s tdo g",
      "e h   u    wdo f",
      "  x   u    ydo f",
      "  A        Bdo f",
      "e h        wdo f",
      "f j      CCCdo g",
      "f jD     E Fdo f",
      "f jI  J  KLMdo f",
      "f hhNNhNNhNNhh f",
      "f              f",
      "effffgffffgffffe"
    ],
    [
      "effffgffffgffffe",
      "f              f",
      "f hhOOhOOhOOhh f",
      "f O   P     d  f",
      "f O  QP  R  d  f",
      "f O  QP    Sd  g",
      "e h   u     d  f",
      "  T   u     U  f",
      "  V        WU  f",
      "e h        Xd  f",
      "f O      CCCd  g",
      "f O      Y  d  f",
      "f O ZJ   K  d  f",
      "f hhOOhOOh00hh f",
      "f              f",
      "effffgffffgffffe"
    ],
    [
      "                ",
      "                ",
      "  hhhhhhhhhhhh  ",
      "  O   P     d1  ",
      "  O   P     d1  ",
      "  O   P     d1  ",
      "  h   u     d1  ",
      "  O   u     U1  ",
      "  O         U1  ",
      "  h         d1  ",
      "  O      CCCd1  ",
      "  O 2    K  d1  ",
      "  O      K  d1  ",
      "  hhhhhhhhhhhh  ",
      "                ",
      "                "
    ],
    [
      "                ",
      " 33333333333333 ",
      " NhhhhhhhhhhhhN ",
      "  hbbbbbbbbbd4  ",
      "  hbbbbbbbbbd4  ",
      "  hbbbbbbbbbd4  ",
      "  hbbbbbbbbbd4  ",
      "  hbbbbbbbbbd   ",
      "  hbbbbbbbbbd   ",
      "  hbbbbbbbbbd4  ",
      "  hb2  bbbbbd4  ",
      "  hb   bbbbbd4  ",
      "  hb   bbbbbd4  ",
      " ihhhhhhhhhhhhi ",
      " 55555555555555 ",
      "                "
    ],
    [
      "                ",
      "                ",
      " 33333333333333 ",
      " N4dhhhhhhhhd4N ",
      "  4d44444444d4  ",
      "  4d678  99 d4  ",
      "  4d678  99@d4  ",
      "  #d$88 %99^d&  ",
      "  *d        d(  ",
      "  4d ))+----d4  ",
      "  4d  [    ]d4  ",
      "  4d  [    {d4  ",
      " i4d  [ !}} d4i ",
      " 55555555555555 ",
      "                ",
      "                "
    ]
  ]
}