{
  "name": "building_carservice1_top_270",
  "refpalette": "c70cities:building_carservice1_top_palette_270",
  "xsize": 16,
  "zsize": 16,
  "slices": [
    [
      "                ",
      " aeeeeeeea    a ",
      " effffffccbbbb  ",
      " effffffccbbbb  ",
      " effffffccbb    ",
      " affffffca    a ",
      " effffffcd      ",
      " effffffcd      ",
      " effffffcd      ",
      " affffffca    a ",
      " egfffffcd      ",
      " edcffffcd      ",
      "  ddcfffcd      ",
      "   ddcffca    a ",
      "    eeeeee      ",
      "                "
    ],
    [
      "                ",
      " aeoooooeaihhha ",
      " e sss   j    h ",
      " e sss   j    h ",
      " eytutr  j    h ",
      " a uxu   a    a ",
      " e usu  ke    h ",
      " eytstr ke    h ",
      " e wsw  ke    h ",
      " a      laihhha ",
      " e      me      ",
      " eo   pp!e      ",
      "  oo   qme      ",
      "   oo   na    a ",
      "    eeeeee      ",
      "                "
    ],
    [
      "                ",
      " aeoooooea    a ",
      " e BsB   j      ",
      " e  u    j      ",
      " e  B    j      ",
      " a  C    a    a ",
      " e  B    e      ",
      " e       e      ",
      " e      Ae      ",
      " a      la    a ",
      " e      me      ",
      " eo     me      ",
      "  oo    me      ",
      "   oo    a    a ",
      "    eeoooe      ",
      "                "
    ],
    [
      "                ",
      " aaaaaaaaaDDDDa ",
      " e       j      ",
      " e       j      ",
      " e       j      ",
      " aDDDDDDDaDDDDa ",
      " e       e      ",
      " e       e      ",
      " e       e      ",
      " aDDDDDDDaDDDDa ",
      " e      Ee      ",
      " eo     Ee      ",
      "  oo    Ee      ",
      "   oo    aDDDDa ",
      "    eeeeee      ",
      "                "
    ],
    [
      "                ",
      " eeeeeeeee      ",
      " eFFFFFFFe      ",
      " eFFFFFFFe      ",
      " eFFFFFFFe      ",
      " eFFFFFFFe      ",
      " eFFFFFFFe      ",
      " eFFFFFFFe      ",
      " eFFFFFFFe      ",
      " eFFFFFFFe      ",
      " eFFFFFFFe      ",
      " eFFFFFFFe      ",
      "  FFFFFFFe      ",
      "   FFFFFFe      ",
      "    eeeeee      ",
      "                "
    ],
    [
      "                ",
      " eeeeeeeee      ",
      " e       e      ",
      " e       e      ",
      " e       e      ",
      " e       e      ",
      " e       e      ",
      " e       e      ",
      " e       e      ",
      " e       e      ",
      " e       e      ",
      " e       e      ",
      "         e      ",
      "         e      ",
      "    eeeeee      ",
      "                "
    ]
  ]
}