{
  "name": "building_hotel1_floor1_90",
  "refpalette": "c70cities:building_hotel1_floor1_palette_90",
  "xsize": 16,
  "zsize": 16,
  "slices": [
    [
      "                ",
      " aaaaaaaaffffaa ",
      " abbbcbbbbbbbba ",
      " abbbcbbbbbbbbg ",
      " abbbcbbbbbbbbg ",
      " abbbcdbbbbbbbg ",
      " abbbc   ebbbbg ",
      " abbbc    bbbbg ",
      " abbbc    bbbba ",
      " abbbc    bbbba ",
      " abbbcbbbbbbbba ",
      " abbbcbbbbbbbba ",
      " abbbcbbbbbbbba ",
      " abbbcbbbbbbbba ",
      " aaaaadddddddaa ",
      "                "
    ],
    [
      "                ",
      " aaaaaaaaffffaa ",
      " ai  q  u    ua ",
      " ai pq       sa ",
      " ai          ua ",
      " a   a tt    ra ",
      " a  ka   d    a ",
      " a  oa   e   sa ",
      " a  na   e   ua ",
      " a  ma       ra ",
      " a  ma        a ",
      " a  la s s   sa ",
      " a  ka  u    ua ",
      " ah ja r r   ra ",
      " aaaaaaaaaaaaaa ",
      "                "
    ],
    [
      "                ",
      " aaaaaaaaffffaa ",
      " a      A    Aa ",
      " a            a ",
      " a           ya ",
      " a   a        a ",
      " a   a        a ",
      " a  xa        f ",
      " a   a   d   yf ",
      " a   a  ee    f ",
      " a   a        f ",
      " a  wa        f ",
      " a   a yyy   yf ",
      " a   a        a ",
      " aaaaaffffaaaaa ",
      "                "
    ],
    [
      "                ",
      " aaaaaaaaffffaa ",
      " a      A    Aa ",
      " a            a ",
      " a            a ",
      " a   a        a ",
      " a   a        a ",
      " a   a        a ",
      " a   a        a ",
      " a   aeed     a ",
      " a   a        a ",
      " a   a        a ",
      " a   a        a ",
      " a   a        a ",
      " aaaaaaaaaaaaaa ",
      "                "
    ],
    [
      "                ",
      " aaaaaaaaffffaa ",
      " a   a        a ",
      " a   a        a ",
      " a   a        a ",
      " a   a        a ",
      " a   a        a ",
      " a   ae       f ",
      " a   ae       f ",
      " a   ad       a ",
      " a   a        a ",
      " a   a        a ",
      " a   a        a ",
      " a   a        a ",
      " aaffaaaaaaaaaa ",
      "                "
    ],
    [
      "                ",
      " aaaaaaaaffffaa ",
      " aBBBaBBBBBBBBa ",
      " aBBBaBBBBBBBBa ",
      " aBBBaBBBBBBBBa ",
      " aBBBaBBBBBBBBa ",
      " aBBBae   BBBBa ",
      " aBBBad   BBBBa ",
      " aBBBa    BBBBa ",
      " aBBBa    BBBBa ",
      " aBBBaBBBBBBBBa ",
      " aBBBaBBBBBBBBa ",
      " aBBBaBBBBBBBBa ",
      " aBBBaBBBBBBBBa ",
      " aaaaaaaaaaaaaa ",
      "                "
    ]
  ]
}