{
  "name": "building_office1_base2_180",
  "refpalette": "c70cities:building_office1_base2_palette_180",
  "xsize": 16,
  "zsize": 16,
  "slices": [
    [
      "vvvvvvvvvvvvvvvv",
      "vaaaaaaaaaaaaaav",
      "va!aaaaaaaaaaaav",
      "vaaaaaaaaaaaaaav",
      "vaaaaaaaaaaaaaav",
      "vaaaaaaaaaaaaaav",
      "vaaaaaaaaaaaaaav",
      "vaaaaaaaaaaaaaav",
      "vaaaaaaaaaaaaaav",
      "vaaaaa!aa!aaaaav",
      "vaaaaaaaaaaaaaav",
      "vaaaaaaaaaaaaaav",
      "vaaaaaaaaaaaaaav",
      "vaaaaaaaaaaaaaav",
      "vaaaaaaaaaaaaaav",
      "vvvvvvvvvvvvvvvv"
    ],
    [
      "vvvvvvvvvvvvvvvv",
      "vbbbbbbbbbbbbbbv",
      "vbj          ibv",
      "vbj          ibv",
      "vbefffehgefffebv",
      "vb            bv",
      "vb            bv",
      "vb    d  d    bv",
      "vb   d   d    bv",
      "vb    d  dd   bv",
      "vb    d  d    bv",
      "vb            bv",
      "vb     c      bv",
      "vb            bv",
      "vbbbbbbbbbbbbbbv",
      "vvvvvvvvvvvvvvvv"
    ],
    [
      "vvvvvvvvvvvvvvvv",
      "vbbbbbbbbbbbbbbv",
      "vbn          ibv",
      "vbm          ibv",
      "vbefffelkefffebv",
      "vb            bv",
      "vb            bv",
      "vb            bv",
      "vb            bv",
      "vb            bv",
      "vb            bv",
      "vb            bv",
      "vb            bv",
      "vb            bv",
      "vbbbbbbbbbbbbbbv",
      "vvvvvvvvvvvvvvvv"
    ],
    [
      "vvvvvvvvvvvvvvvv",
      "vbbbbbbbbbbbbbbv",
      "vbo          ibv",
      "vb           ibv",
      "vbefffeeeefffebv",
      "vb            bv",
      "vb            bv",
      "vb            bv",
      "vb            bv",
      "vb            bv",
      "vb            bv",
      "vb            bv",
      "vb            bv",
      "vb            bv",
      "vbbbbbbbbbbbbbbv",
      "vvvvvvvvvvvvvvvv"
    ],
    [
      "vvvvvvvvvvvvvvvv",
      "vbbbbbbbbbbbbbbv",
      "vb           ibv",
      "vb           ibv",
      "vbeffffffffffebv",
      "vb            bv",
      "vb            bv",
      "vb            bv",
      "vb            bv",
      "vb            bv",
      "vb            bv",
      "vb            bv",
      "vb            bv",
      "vb            bv",
      "vbbbbbbbbbbbbbbv",
      "vvvvvvvvvvvvvvvv"
    ],
    [
      "vvvvvvvvvvvvvvvv",
      "vbbbbbbbbbbbbbbv",
      "vbpppppppppppibv",
      "vbpppppppppppibv",
      "vbeppppppppppebv",
      "vbppppppppppppbv",
      "vbpppppcrpppppbv",
      "vbppppppppppppbv",
      "vbppppppppppppbv",
      "vbppppprcpppppbv",
      "vbppppppppppppbv",
      "vbppppppppppppbv",
      "vbpppppqcpppppbv",
      "vbppppppppppppbv",
      "vbbbbbbbbbbbbbbv",
      "vvvvvvvvvvvvvvvv"
    ]
  ]
}