{
  "name": "building_hotel2_floor1_270",
  "refpalette": "c70cities:building_hotel2_floor1_palette_270",
  "xsize": 16,
  "zsize": 16,
  "slices": [
    [
      "                ",
      " aaaaaaaaaaaaaa ",
      "  dcccccccc=bba ",
      "  dccccccccccca ",
      "  dccccccc!ccca ",
      "  dccccccccccca ",
      "  dccccccccccca ",
      "  dccccccccccca ",
      "  dccccccccccca ",
      "  dccccccccccca ",
      "  dcccccccccc!a ",
      "  dddddddddddda ",
      "              a ",
      "              a ",
      "              a ",
      "                "
    ],
    [
      "                ",
      " aaaaaaaaaaaaaa ",
      "  h === ank=bba ",
      "  h =q= aola  a ",
      "  h     p ga  a ",
      "  h     aaaaiea ",
      "  h rr  j     a ",
      "  h ss        a ",
      "  h tt    m  fa ",
      "  h        j fa ",
      "  h uu  j m jga ",
      "  hhhhhhhhhhhha ",
      "              a ",
      "              a ",
      "              a ",
      "                "
    ],
    [
      "                ",
      " aaaaaaaaaaaaaa ",
      "  h     a  =bba ",
      "  h     a  a  a ",
      "  h     A  a  a ",
      "  h     aaaaxwa ",
      "  h rr  B     a ",
      "  h           a ",
      "  h        y  a ",
      "  h        y  a ",
      "  h     B  yy a ",
      "  hhhhhhhhhhhha ",
      "              a ",
      "              a ",
      "              a ",
      "                "
    ],
    [
      "                ",
      " aaaaaaaaaaaaaa ",
      "  h     a  =bba ",
      "  h     a  a  a ",
      "  h     a  a  a ",
      "  h     aaaaaaa ",
      "  h     B     a ",
      "  h           a ",
      "  h          Ca ",
      "  h          Ca ",
      "  h     B    Ca ",
      "  hhhhhhhhhhhha ",
      "              a ",
      "              a ",
      "              a ",
      "                "
    ],
    [
      "                ",
      " aaaaaaaaaaaaaa ",
      "  h     a  =bba ",
      "  h     a  a  a ",
      "  h     a  a  a ",
      "  h     aaaaaaa ",
      "  h           a ",
      "  h           a ",
      "  h           a ",
      "  h           a ",
      "  h           a ",
      "  hhhhhhhhhhhha ",
      "              a ",
      "              a ",
      "              a ",
      "                "
    ],
    [
      "                ",
      " aaaaaaaaaaaaaa ",
      "  yDDDDDaDD=bba ",
      "  yDDDDDaDDaDDa ",
      "  yDDDDDaDDaDDa ",
      "  yDDDDDaaaaaaa ",
      "  yDDDDDDDDDDDa ",
      "  yDDDDDDDDDDDa ",
      "  yDDDDDDDDDDDa ",
      "  yDDDDDDDDDDDa ",
      "  yDDDDDDDDDDDa ",
      "  yyyyyyyyyyyya ",
      "              a ",
      "              a ",
      "              a ",
      "                "
    ]
  ]
}