{
  "name": "building_office4_ground",
  "refpalette": "c70cities:building_office4_ground_palette",
  "xsize": 16,
  "zsize": 16,
  "slices": [
    [
      "GGGGGGGGGGGGGGGG",
      "GaaaaaaaaaaaaaaG",
      "GabbbcbbbbcbbbaG",
      "GabbbbbbbbbbbbaG",
      "GabbbbbbbbbbbbaG",
      "GacbbbbbbbbbbcaG",
      "GabbbbbbbbbbbbaG",
      "GabbbbbbbbbbbbaG",
      "GabbbbbbbbbbbbaG",
      "GabbbbbbbbbbbbaG",
      "GacbbbbbbbbbbcaG",
      "GabbbbbbbbbbbbaG",
      "GabbbbbbbbbbbbaG",
      "GabbbcbbbbcbbbaG",
      "GaaaaaaaaaaaaaaG",
      "GGGGGGGGGGGGGGGG"
    ],
    [
      "                ",
      " aaaadaaaadaaaa ",
      " aeffc ghicffea ",
      " aj          ka ",
      " aj          ka ",
      " dc    l     cd ",
      " a    jlm     a ",
      " an    l      o ",
      " an    l      p ",
      " a    jlm     a ",
      " dc    l     cd ",
      " aj          ka ",
      " aj          ka ",
      " aeqqc rs cqqea ",
      " aaaadaaaadaaaa ",
      "                "
    ],
    [
      "                ",
      " aaaadaaaadaaaa ",
      " at  c    c  ta ",
      " a            a ",
      " a            a ",
      " dc          cd ",
      " a            a ",
      " an    u      w ",
      " an           x ",
      " a            a ",
      " dc    y     cd ",
      " a            a ",
      " a            a ",
      " at  c    c  ta ",
      " aaaadaaaadaaaa ",
      "                "
    ],
    [
      "                ",
      " aaaadaaaadaaaa ",
      " at  c    c  ta ",
      " a            a ",
      " a            a ",
      " dc          cd ",
      " a            a ",
      " an           a ",
      " an           a ",
      " a            a ",
      " dc          cd ",
      " a            a ",
      " a            a ",
      " at  c    c  ta ",
      " aaaadaaaadaaaa ",
      "                "
    ],
    [
      "                ",
      " aaaadaaaadaaaa ",
      " a   c    c   a ",
      " a            a ",
      " a            a ",
      " dc          cd ",
      " a            a ",
      " an    AB     a ",
      " an    AB     a ",
      " a            a ",
      " dc          cd ",
      " a            a ",
      " a            a ",
      " a   c    c   a ",
      " aaaadaaaadaaaa ",
      "                "
    ],
    [
      "                ",
      "    adaaaada    ",
      "  CCCcDDDDcCCC  ",
      "  CDDDDDDDDDDC  ",
      " aCDDDDDDDDDDCa ",
      " dcDDDDDDDDDDcd ",
      " aDDDDDDDDDDDDa ",
      " anDDDDEEDDDDDa ",
      " anDDDDEEDDDDDa ",
      " aDDDDDDDDDDDDa ",
      " dcDDDDDDDDDDcd ",
      " aCDDDDDDDDDDCa ",
      "  CDDDDDDDDDDC  ",
      "  CCCcDDDDcCCC  ",
      "    adaaaada    ",
      "                "
    ]
  ]
}