{
  "name": "building_office1_floor1_270",
  "refpalette": "c70cities:building_office1_floor1_palette_270",
  "xsize": 16,
  "zsize": 16,
  "slices": [
    [
      "                ",
      " eeee  c        ",
      " ebbfddcaaaaaa  ",
      " ebbgbbbbbbbba  ",
      " ebbbbbbbbbbba  ",
      " ebbbbbbbbbbba  ",
      " ebbbbbbbbbbba  ",
      " ebbbbbbbbbbba  ",
      " ebbbbbbbbbbba  ",
      " ebbbbbbbbbbba  ",
      " eb!bbbbbbbbba  ",
      " ebbbbbbbbbbba  ",
      " ebbbbbbbbbbba  ",
      " ebbfddcaaaaaa  ",
      " eeee  c        ",
      "                "
    ],
    [
      "                ",
      " ssss  c        ",
      " suufddchhhhhh  ",
      " s  g  f     h  ",
      " s     o  j  h  ",
      " s     p   i h  ",
      " sAwt qf mk  h  ",
      " sfffrff   i h  ",
      " s xi  f m   h  ",
      " sBx   f  ki h  ",
      " s xi  f m   h  ",
      " s     f  l  h  ",
      " s     fn    h  ",
      " sCyfddchhhhhh  ",
      " ssss  c        ",
      "                "
    ],
    [
      "                ",
      " ssss  c        ",
      " suufddchhhhhh  ",
      " N  g  f     h  ",
      " d     E     h  ",
      " d     F  D  h  ",
      " d    qf  D  h  ",
      " dfffIff  D  h  ",
      " d J   f  D  h  ",
      " d K   f  D  h  ",
      " d L   f  D  h  ",
      " d     f     h  ",
      " N     f     h  ",
      " s Mfddchhhhhh  ",
      " ssss  c        ",
      "                "
    ],
    [
      "                ",
      " ssss  c        ",
      " suufddchhhhhh  ",
      " N  g  f     h  ",
      " d     f     h  ",
      " d     f     h  ",
      " d     f     h  ",
      " dffffff     h  ",
      " d     f     h  ",
      " d     f     h  ",
      " d     f     h  ",
      " d     f     h  ",
      " N     f     h  ",
      " s  fddchhhhhh  ",
      " ssss  c        ",
      "                "
    ],
    [
      "                ",
      " ssss  c        ",
      " sOOfddchhhhhh  ",
      " s  g  f     h  ",
      " s     f     h  ",
      " s     f     h  ",
      " s     f     h  ",
      " sffffff     h  ",
      " s     f     h  ",
      " s     f     h  ",
      " s     f     h  ",
      " s     f     h  ",
      " s     f     h  ",
      " s  fddchhhhhh  ",
      " ssss  c        ",
      "                "
    ],
    [
      "                ",
      " ssss  c        ",
      " sNNfddchhhhhh  ",
      " sNNg  fNNNNNh  ",
      " sNNNNNfNNNNNh  ",
      " sNNNNNfNNNNNh  ",
      " sNNNNNfNNNNNh  ",
      " sffffffNNNNNh  ",
      " sNNNNNfNNNNNh  ",
      " sNNNNNfNNNNNh  ",
      " sNNNNNfNNNNNh  ",
      " sNNNNNfNNNNNh  ",
      " sNN   fNNNNNh  ",
      " sNNfddchhhhhh  ",
      " ssss  c        ",
      "                "
    ]
  ]
}