{
  "name": "building_hotel3_top_180",
  "refpalette": "c70cities:building_hotel3_top_palette_180",
  "xsize": 16,
  "zsize": 16,
  "slices": [
    [
      "                ",
      "  a a a a a a   ",
      "  bbbbbbbbbbbba ",
      " abccccccccccb  ",
      "  bceeeeeeeecba ",
      " abceffffffecb  ",
      "  bceffffffecba ",
      " abceffffffecb  ",
      "  bceffffffecba ",
      " abceffffffecb  ",
      "  bceffffffecba ",
      " abceeeeeeeecb  ",
      "  bccccddccccba ",
      " abbbbbbbbbbbb  ",
      "   a a a a a a  ",
      "                "
    ],
    [
      "                ",
      "                ",
      "                ",
      "                ",
      "    jiiiiiij    ",
      " ab i     !e b  ",
      "  b i  hhhhe ba ",
      " ab i  hggge b  ",
      "  b i  hggge ba ",
      " ab i  hggge b  ",
      "  b e  hggge ba ",
      " ab e  eeeee b  ",
      "  b          ba ",
      " abbbbbbbbbbbb  ",
      "   a a a a a a  ",
      "                "
    ],
    [
      "                ",
      "                ",
      "                ",
      "                ",
      "    j      j    ",
      "           e    ",
      "           k    ",
      "           k    ",
      "  b        k ba ",
      " ab        k b  ",
      "  b e      e ba ",
      " ab e  eeeee b  ",
      "  b          ba ",
      " abbbbbbbbbbbb  ",
      "   a a a a a a  ",
      "                "
    ],
    [
      "                ",
      "                ",
      "                ",
      "                ",
      "    j      j    ",
      "           e    ",
      "           e    ",
      "           e    ",
      "           e    ",
      "           e    ",
      "    e      e    ",
      " ab e  eeeee b  ",
      "  b          ba ",
      " abbbbbbbbbbbb  ",
      "   a a a a a a  ",
      "                "
    ],
    [
      "                ",
      "                ",
      "                ",
      "                ",
      "    j      j    ",
      "           e    ",
      "           e    ",
      "           e    ",
      "           e    ",
      "           e    ",
      "    e      e    ",
      "    elleeeee    ",
      "                ",
      "                ",
      "                ",
      "                "
    ],
    [
      "                ",
      "                ",
      "                ",
      "                ",
      "    hhhhhhhh    ",
      "    hcccccch    ",
      "    hcccccch    ",
      "    hcccccch    ",
      "    hcccccch    ",
      "    hcccccch    ",
      "    hhhhhhhh    ",
      "    hhhhhhhh    ",
      "                ",
      "                ",
      "                ",
      "                "
    ]
  ]
}