{
  "name": "building_office2_top",
  "refpalette": "c70cities:building_office2_top_palette",
  "xsize": 16,
  "zsize": 16,
  "slices": [
    [
      "                ",
      " aaaaaaaaaaaaaa ",
      "   bccccccc!b   ",
      "  decccccccced  ",
      "  decccccccced  ",
      "  decccccccced  ",
      "  decccccccced  ",
      "  decccccccced  ",
      "  decccccccced  ",
      "  decccccccced  ",
      "  decccccccced  ",
      "  decccccccced  ",
      "  decccccccced  ",
      "   bcccffcccb   ",
      " aaaaaaaaaaaaaa ",
      "                "
    ],
    [
      "                ",
      " aaaaaaaaaaaaaa ",
      "   bg      gb   ",
      "  d    h     d  ",
      "  d   iiii   d  ",
      "  d          d  ",
      "  d          d  ",
      "  d          d  ",
      "  d j        d  ",
      "  d k l      d  ",
      "  d m     n  d  ",
      "  d          d  ",
      "  d          d  ",
      "   boop  poob   ",
      " aaaaaaaaaaaaaa ",
      "                "
    ],
    [
      "                ",
      " aaaaaaaaaaaaaa ",
      "   bg      gb   ",
      "  d          d  ",
      "  d    q     d  ",
      "  d          d  ",
      "  d          d  ",
      "  d          d  ",
      "  d          d  ",
      "  d          d  ",
      "  d       r  d  ",
      "  d          d  ",
      "  d          d  ",
      "   boog  goob   ",
      " aaaaaaaaaaaaaa ",
      "                "
    ],
    [
      "                ",
      " aaaaaaaaaaaaaa ",
      "   b        b   ",
      "  d          d  ",
      "  d          d  ",
      "  d          d  ",
      "  d          d  ",
      "  d          d  ",
      "  d          d  ",
      "  d          d  ",
      "  d       r  d  ",
      "  d          d  ",
      "  d          d  ",
      "   b        b   ",
      " aaaaaaaaaaaaaa ",
      "                "
    ],
    [
      "                ",
      " aaaaaaaaaaaaaa ",
      "  ssssddddssss  ",
      "  ssssddddssss  ",
      "  ssssddddssss  ",
      "  ssssddddssss  ",
      "  ssssddddssss  ",
      "  ssssddddssss  ",
      "  ssssddddssss  ",
      "  ssssddddssss  ",
      "  ssssddddssss  ",
      "  ssssddddssss  ",
      "  ssssddddssss  ",
      "  ssssddddssss  ",
      " aaaaaaaaaaaaaa ",
      "                "
    ],
    [
      "                ",
      " aaaaaaaaaaaaaa ",
      "                ",
      "                ",
      "                ",
      "                ",
      "                ",
      "                ",
      "                ",
      "                ",
      "                ",
      "                ",
      "                ",
      "                ",
      " aaaaaaaaaaaaaa ",
      "                "
    ]
  ]
}