{
  "name": "building_office3_floor1_180",
  "refpalette": "c70cities:building_office3_floor1_palette_180",
  "xsize": 16,
  "zsize": 16,
  "slices": [
    [
      "                ",
      " aabaabaabaabaa ",
      " acccccccccccca ",
      " bccccccccccccb ",
      " acc!ccccccccca ",
      " acccccccccccca ",
      " bccccccccccccb ",
      " acccccdvccccca ",
      " acccccdvccccca ",
      " bccccccccccccb ",
      " acccccccccccca ",
      " acccccccccccca ",
      " bccccccccccccb ",
      " acccccccccccca ",
      " aabaabaabaabaa ",
      "                "
    ],
    [
      "                ",
      " eebeebeebeebee ",
      " e            e ",
      " b f  k p   f b ",
      " e  ppppp     e ",
      " e   g g      e ",
      " b           ob ",
      " e     dvn e he ",
      " e     dvm e he ",
      " b           lb ",
      " e    k k     e ",
      " e   ji  ih   e ",
      " b f   g g  f b ",
      " e            e ",
      " eebeebeebeebee ",
      "                "
    ],
    [
      "                ",
      " qqbqqbqqbqqbqq ",
      " q            q ",
      " b f        f b ",
      " q            q ",
      " q            q ",
      " b            b ",
      " q     dvs    q ",
      " q     dvs    q ",
      " b            b ",
      " q            q ",
      " q    rrrr    q ",
      " b f        f b ",
      " q            q ",
      " qqbqqbqqbqqbqq ",
      "                "
    ],
    [
      "                ",
      " qqbqqbqqbqqbqq ",
      " q            q ",
      " b f        f b ",
      " q            q ",
      " q            q ",
      " b            b ",
      " q     dvs    q ",
      " q     dvs    q ",
      " b            b ",
      " q            q ",
      " q            q ",
      " b f        f b ",
      " q            q ",
      " qqbqqbqqbqqbqq ",
      "                "
    ],
    [
      "                ",
      " qqbqqbqqbqqbqq ",
      " q            q ",
      " b f        f b ",
      " q            q ",
      " q            q ",
      " b            b ",
      " q     dv     q ",
      " q     dv     q ",
      " b            b ",
      " q            q ",
      " q            q ",
      " b f        f b ",
      " q            q ",
      " qqbqqbqqbqqbqq ",
      "                "
    ],
    [
      "                ",
      " qqbqqbqqbqqbqq ",
      " qttttttttttttq ",
      " btfuuuuuuuuftb ",
      " qtuuuuuuuuuutq ",
      " qtuuuuuuuuuutq ",
      " btuuuuuuuuuutb ",
      " qtuuuudvuuuutq ",
      " qtuuuudvuuuutq ",
      " btuuuuuuuuuutb ",
      " qtuuuuuuuuuutq ",
      " qtuuuuuuuuuutq ",
      " btfuuuuuuuuftb ",
      " qttttttttttttq ",
      " qqbqqbqqbqqbqq ",
      "                "
    ]
  ]
}