{
  "name": "building_residential2_floor1",
  "refpalette": "c70cities:building_residential2_floor1_palette",
  "xsize": 16,
  "zsize": 16,
  "slices": [
    [
      "                ",
      "    abc  abc    ",
      "  dddddddddddd  ",
      "  defff      d  ",
      " gdhiff  jk ldm ",
      " ndhiff  jkopdq ",
      " rdsfff  jk tdu ",
      "  d      jk  d  ",
      "  dwwxywwwwwwd  ",
      "                ",
      "                ",
      "            A   ",
      "   BB  BB  BB   ",
      "                ",
      "                ",
      "                "
    ],
    [
      "                ",
      "                ",
      "  dCDDDDDDDDCd  ",
      "  CE         C  ",
      "  D          D  ",
      "  D         FD  ",
      "  D          D  ",
      "  C          C  ",
      "  dwwIJwwwwwwd  ",
      "                ",
      "                ",
      "                ",
      "   BB  BB  BB   ",
      "                ",
      "                ",
      "                "
    ],
    [
      "                ",
      "                ",
      "  dCDDDDDDDDCd  ",
      "  C          C  ",
      "  D          D  ",
      "  D          D  ",
      "  D          D  ",
      "  C          C  ",
      "  dwwwwwwwwwwd  ",
      "                ",
      "                ",
      " KKKKKKKKKKKKKK ",
      " CCCCCCCCCCCCCC ",
      " LLLLLLLLLLLLLL ",
      " MMMMMMMMMMMMMM ",
      "                "
    ],
    [
      "                ",
      "                ",
      "  dddddddddddd  ",
      "  d          d  ",
      "  d          d  ",
      "  d          d  ",
      "  d          d  ",
      "  d          d  ",
      " KdCCCCCCCCCCdK ",
      " CCCCCCCCCCCCCC ",
      " LLLLLLLLLLLLLL ",
      " MMMMMMMMMMMMMM ",
      "                ",
      "                ",
      "              ~ ",
      "                "
    ],
    [
      "                ",
      "                ",
      "  B  BB  BB  B  ",
      "  B          B  ",
      "                ",
      " KKKKKKKKKKKKKK ",
      " CCCCCCCCCCCCCC ",
      " LLLLLLLLLLLLLL ",
      " MMMMMMMMMMMMMM ",
      "                ",
      "                ",
      "                ",
      "                ",
      "                ",
      "              ~ ",
      "                "
    ],
    [
      "                ",
      "                ",
      " KCKKCCKKCCKKCK ",
      " CCCCCCCCCCCCCC ",
      " LLLLLLLLLLLLLL ",
      " MMMMMMMMMMMMMM ",
      "                ",
      "                ",
      "                ",
      "                ",
      "                ",
      "                ",
      "                ",
      "                ",
      "              ~ ",
      "                "
    ]
  ]
}