{
  "name": "building_office2_floor1_180",
  "refpalette": "c70cities:building_office2_floor1_palette_180",
  "xsize": 16,
  "zsize": 16,
  "slices": [
    [
      "                ",
      " aaaaaaaaaaaaaa ",
      "   bcccffcccb   ",
      "  decccccccced  ",
      "  decccccccced  ",
      "  decccccccced  ",
      "  decccccccced  ",
      "  decccccccced  ",
      "  decccccccced  ",
      "  decccccccced  ",
      "  decccccccced  ",
      "  decccccccced  ",
      "  decccccccced  ",
      "   bccccccccb   ",
      " aaaaaaaaaaaaaa ",
      "                "
    ],
    [
      "                ",
      " aaaaaaaaaaaaaa ",
      "   bnnoffonnb   ",
      "  d          d  ",
      "  d          d  ",
      "  d   m  m   d  ",
      "  d  k    j  d  ",
      "  d   l  l   d  ",
      "  d  k    j  d  ",
      "  d   l  l   d  ",
      "  d  k    j  d  ",
      "  d    ii    d  ",
      "  d          d  ",
      "   bghggghggb   ",
      " aaaaaaaaaaaaaa ",
      "                "
    ],
    [
      "                ",
      " aaaaaaaaaaaaaa ",
      "   bp sffs rb   ",
      "  d          d  ",
      "  d          d  ",
      "  d          d  ",
      "  d   qqqq   d  ",
      "  d   q  q   d  ",
      "  d   q  q   d  ",
      "  d   q  q   d  ",
      "  d   qqqq   d  ",
      "  d          d  ",
      "  d          d  ",
      "   bp     ppb   ",
      " aaaaaaaaaaaaaa ",
      "                "
    ],
    [
      "                ",
      " aaaaaaaaaaaaaa ",
      "   b   ff   b   ",
      "  d          d  ",
      "  d          d  ",
      "  d          d  ",
      "  d          d  ",
      "  d          d  ",
      "  d          d  ",
      "  d          d  ",
      "  d          d  ",
      "  d          d  ",
      "  d          d  ",
      "   b       pb   ",
      " aaaaaaaaaaaaaa ",
      "                "
    ],
    [
      "                ",
      " aaaaaaaaaaaaaa ",
      "   b   ff   b   ",
      "  d          d  ",
      "  d          d  ",
      "  d          d  ",
      "  d          d  ",
      "  d    !     d  ",
      "  d          d  ",
      "  d          d  ",
      "  d          d  ",
      "  d          d  ",
      "  d          d  ",
      "   b        b   ",
      " aaaaaaaaaaaaaa ",
      "                "
    ],
    [
      "                ",
      " aaaaaaaaaaaaaa ",
      "   btttfftttb   ",
      "  d tttttttt d  ",
      "  d tttttttt d  ",
      "  d tttttttt d  ",
      "  d tttttttt d  ",
      "  d tttuuttt d  ",
      "  d tttuuttt d  ",
      "  d tttttttt d  ",
      "  d tttttttt d  ",
      "  d tttttttt d  ",
      "  d tttttttt d  ",
      "   b        b   ",
      " aaaaaaaaaaaaaa ",
      "                "
    ]
  ]
}