{
  "name": "building_bunker1_base1",
  "refpalette": "c70cities:building_bunker1_base1_palette",
  "xsize": 16,
  "zsize": 16,
  "slices": [
    [
      "vvvvvvvvvvvvvvvv",
      "v==============v",
      "v=======aaaaaa=v",
      "v=======aaaaaa=v",
      "v=======aaaaaa=v",
      "v=======aaaaaa=v",
      "v==============v",
      "v==============v",
      "v==============v",
      "v==============v",
      "v===aaa=aa=====v",
      "v===aaaaaa=====v",
      "v=======aa=====v",
      "v===aaaaaa=====v",
      "v===aaa=aa=====v",
      "vvvvvvvvvvvvvvvv"
    ],
    [
      "vvvvvvvvvvvvvvvv",
      "vbbbbbbbbbbbbbbv",
      "vccbdddbefeghibv",
      "vj     b     kbv",
      "vl     m     nbv",
      "vo bbbbbp  qrqbv",
      "v  bss bt    ubv",
      "vs bw  x    yybv",
      "vABbo  bn C  Dbv",
      "vbbbbbbEbFb  Ibv",
      "vzzbJKLbn b  Mbv",
      "vzzbN  O  bPQIbv",
      "vzzbbbbb  bbbbbv",
      "vzzbN  O  R  Sbv",
      "vzzbJKTbUUbVWXbv",
      "vvvvvvvvvvvvvvvv"
    ],
    [
      "vvvvvvvvvvvvvvvv",
      "vEEEEEEEEEEYYYZv",
      "v01E   EL23   4v",
      "v      E      4v",
      "vo     5     6Ev",
      "v  EEEEE7   89Ev",
      "v  Es  E      Ev",
      "v@ Ew  #      Ev",
      "vA$E   E6     Ev",
      "vEEEEEEEE%E  ^Ev",
      "vzzE01LE6 E   Ev",
      "vzzE&  *  E()+Ev",
      "vzzEEEEE  EEEEEv",
      "vzzE-  *  []] {v",
      "vzzE}\\TET E|`:{v",
      "vvvvvvvvvvvvvvvv"
    ],
    [
      "vvvvvvvvvvvvvvvv",
      "vEEEEEEEEEEEEEEv",
      "v ;E'''E,,,,,,Ev",
      "v      E      Ev",
      "v      E     6Ev",
      "v  EEEEE      Ev",
      "v  E   E      Ev",
      "v  Ew  {      Ev",
      "vA!E   E6     Ev",
      "vEEEEEEEEEE  .Ev",
      "vzzEf/ E6 E  .Ev",
      "vzzE  <E  E>?\u00a3Ev",
      "vzzEEEEE  EEEEEv",
      "vzzE  <E  E\u00a4\u00a5 Ev",
      "vzzEf  E\u00a7\u00a7E \u00c0\u00c1Ev",
      "vvvvvvvvvvvvvvvv"
    ],
    [
      "vvvvvvvvvvvvvvvv",
      "vEEEEEEEEEEEEEEv",
      "v\u00c2\u00c2E\u00c3\u00c3\u00c3E\u00c4\u00c4\u00c4\u00c4\u00c4\u00c4Ev",
      "v\u00c2\u00c2\u00c5\u00c2\u00c2\u00c2E\u00c2\u00c2\u00c2\u00c2\u00c2\u00c2Ev",
      "v\u00c2\u00c2\u00c4\u00c2\u00c2\u00c2E\u00c2\u00c2\u00c2\u00c2\u00c2\u00c2Ev",
      "v\u00c4\u00c4EEEEE\u00c2\u00c2\u00c2\u00c2\u00c2\u00c2Ev",
      "v\u00c2\u00c2EEEEE\u00c2\u00c2\u00c2\u00c2\u00c2\u00c2Ev",
      "v\u00c2\u00c2EwEEE\u00c2\u00c2\u00c2\u00c2\u00c2\u00c2Ev",
      "vA\u00c2EEEEE\u00c2\u00c2\u00c2\u00c2\u00c2\u00c2Ev",
      "vEEEEEEEEEEE\u00c4EEv",
      "vzzE\u00c4\u00c2\u00c2E\u00c2\u00c2EE\u00c4EEv",
      "vzzE\u00c5\u00c2\u00c2E\u00c2\u00c2EE\u00c4EEv",
      "vzzEEEEE\u00c2\u00c2EEEEEv",
      "vzzE\u00c5\u00c2\u00c2E\u00c2\u00c2E\u00c2\u00c2\u00c4Ev",
      "vzzE\u00c4\u00c2\u00c2E\u00c4\u00c4E\u00c2\u00c2\u00c4Ev",
      "vvvvvvvvvvvvvvvv"
    ],
    [
      "vvvvvvvvvvvvvvvv",
      "vzzzzzzzzzzzzzzv",
      "vzzzzzzzzzzzzzzv",
      "vzzzzzzzzzzzzzzv",
      "vzzzzzzzzzzzzzzv",
      "vzzzzzzzzzzzzzzv",
      "vzzzEzzzzzzzzzzv",
      "vzzEwEzzzzzzzzzv",
      "vzzzEzzzzzzzzzzv",
      "vzzzzzzzzzzzzzzv",
      "vzzzzzzzzzzzzzzv",
      "vzzzzzzzzzzzzzzv",
      "vzzzzzzzzzzzzzzv",
      "vzzzzzzzzzzzzzzv",
      "vzzzzzzzzzzzzzzv",
      "vvvvvvvvvvvvvvvv"
    ]
  ]
}