{
  "name": "building_office4_floor1_90",
  "refpalette": "c70cities:building_office4_floor1_palette_90",
  "xsize": 16,
  "zsize": 16,
  "slices": [
    [
      "                ",
      "    abaaaaba    ",
      "  cccdeeeedccc  ",
      "  ceeeeeeeeeec  ",
      " aceeeeeeeeeeca ",
      " bdeeeeeeeeeedb ",
      " aeeeeeeeeeeeea ",
      " aeeeeeee!eeeea ",
      " aeeeeeeeeeeeea ",
      " aeeeeeeeeeeeea ",
      " bdeeeeeeeeeedb ",
      " aceeeeeeeeeeca ",
      "  ceeeeeeeeeec  ",
      "  cccdeffedccc  ",
      "    abaaaaba    ",
      "                "
    ],
    [
      "                ",
      "    abaaaaba    ",
      "  gggdoooodggg  ",
      "  g   n  n   g  ",
      " ag          ga ",
      " bd          db ",
      " ahj  mqqt  uwa ",
      " ah   l      wa ",
      " ai      s   wa ",
      " ahj  kppr  uwa ",
      " bd          db ",
      " ag          ga ",
      "  g          g  ",
      "  gggd ff dggg  ",
      "    abaaaaba    ",
      "                "
    ],
    [
      "                ",
      "    abaaaaba    ",
      "  gggd    dggg  ",
      "  g          g  ",
      " ag          ga ",
      " bd          db ",
      " a            a ",
      " a            a ",
      " a            a ",
      " a            a ",
      " bd          db ",
      " ag          ga ",
      "  g          g  ",
      "  gggd ff dggg  ",
      "    abaaaaba    ",
      "                "
    ],
    [
      "                ",
      "    abaaaaba    ",
      "  gggd    dggg  ",
      "  g          g  ",
      " ag          ga ",
      " bd          db ",
      " a            a ",
      " a            a ",
      " a            a ",
      " a            a ",
      " bd          db ",
      " ag          ga ",
      "  g          g  ",
      "  gggd ff dggg  ",
      "    abaaaaba    ",
      "                "
    ],
    [
      "                ",
      "    abaaaaba    ",
      "  gggd    dggg  ",
      "  g          g  ",
      " ag          ga ",
      " bd          db ",
      " a            a ",
      " a            a ",
      " a            a ",
      " a            a ",
      " bd          db ",
      " ag          ga ",
      "  g          g  ",
      "  gggd ff dggg  ",
      "    abaaaaba    ",
      "                "
    ],
    [
      "                ",
      "    abaaaaba    ",
      "  gggdxxxxdggg  ",
      "  gxxxxxxxxxxg  ",
      " agxxxxxxxxxxga ",
      " bdxxxxxxxxxxdb ",
      " axxxxxxxxxxxxa ",
      " axxxxxxxxxxxxa ",
      " axxxxxxxxxxxxa ",
      " axxxxxxxxxxxxa ",
      " bdxxxxxxxxxxdb ",
      " agxxxxxxxxxxga ",
      "  gxxxxxxxxxxg  ",
      "  gggdxffxdggg  ",
      "    abaaaaba    ",
      "                "
    ]
  ]
}