{
  "name": "building_carfactory1_floor1_180",
  "refpalette": "c70cities:building_carfactory1_floor1_palette_180",
  "xsize": 16,
  "zsize": 16,
  "slices": [
    [
      "                ",
      " akkkkkkkkkllka ",
      " eddddddddddddc ",
      " ed         fdc ",
      " edgghjgghhggdc ",
      " ed          dc ",
      " ed          dc ",
      " ed          dc ",
      " ed          dc ",
      " edgghhggihggdc ",
      " ed f       fdc ",
      " eddddddddddddc ",
      " abbbbbbbbbbbba ",
      "                ",
      "                ",
      "                "
    ],
    [
      "                ",
      " a         ll a ",
      "  oooooooooooo  ",
      "  of         o  ",
      "  o !tt  tt  o  ",
      "  o         fo  ",
      "  o         fo  ",
      "  o          o  ",
      "  oqq  qq  qqo  ",
      "  oqqssqqssqqo  ",
      " noqqrrqqrrqqon ",
      " noppppppppppon ",
      " mmmmmmmmmmmmmm ",
      " mmmmmmmmmmmmmm ",
      "                ",
      "                "
    ],
    [
      "                ",
      " a         ll a ",
      "  oooooooooooo  ",
      "  of   ff    o  ",
      "  o  tt  tt  o  ",
      "  oqq  qq  qqo  ",
      " noqqrrqqrrqqon ",
      " noqqrrqqrrqqon ",
      " mm  uu  uu  mm ",
      " mm  uu  uu  mm ",
      "                ",
      "                ",
      "                ",
      "                ",
      "                ",
      "                "
    ],
    [
      "                ",
      " akkkkkkkkkllka ",
      " noppppppppppon ",
      " norrrrrrrrrron ",
      " mmuuuuuuuuuumm ",
      " mm  uu  uu  mm ",
      "       ~        ",
      "                ",
      "                ",
      "                ",
      "                ",
      "                ",
      "                ",
      "                ",
      "                ",
      "                "
    ],
    [
      " mmmmmmmmmmmmmm ",
      " mmmmmmmmmmllmm ",
      "           ll   ",
      "           ll   ",
      "                ",
      "                ",
      "       ~        ",
      "                ",
      "                ",
      "                ",
      "                ",
      "                ",
      "                ",
      "                ",
      "                ",
      "                "
    ],
    [
      "                ",
      "           yl   ",
      "           xw   ",
      "                ",
      "                ",
      "                ",
      "       ~        ",
      "                ",
      "                ",
      "                ",
      "                ",
      "                ",
      "                ",
      "                ",
      "                ",
      "                "
    ]
  ]
}