{
  "name": "building_hotel2_base1",
  "refpalette": "c70cities:building_hotel2_base1_palette",
  "xsize": 16,
  "zsize": 16,
  "slices": [
    [
      "vvvvvvvvvvvvvvvv",
      "vaaaaaaaaaaaaaav",
      "vabbbbbbbbbbbbav",
      "vabbbbbbbbbbbbav",
      "vabbbbbbbbbbbbav",
      "vabbbbbbbbbbbbav",
      "vabbbbbbbbbbbbav",
      "vabbbbbbbbbbbbav",
      "vabbbbbbbbbbbbav",
      "vabbbbbbbbbbbbav",
      "vabbbbbbbbbbbbav",
      "vabbbbbbbbbbbbav",
      "vabbbbbbbbbbbbav",
      "va!bbbbb!bbbb!av",
      "vaaaaaaaaaaaaaav",
      "vvvvvvvvvvvvvvvv"
    ],
    [
      "vvvvvvvvvvvvvvvv",
      "vccccccccccccccv",
      "vcd       =bbbcv",
      "vcd      e=bbbcv",
      "v==e      =bbbcv",
      "vf       e=bbbcv",
      "vfg g g   =bbbcv",
      "vfe  e    hhh=cv",
      "vfi i i      jcv",
      "vf       ff  fcv",
      "vfg g g gfk  lcv",
      "vfe  e  efm  lcv",
      "vfi i i ifn  lcv",
      "vf       fm  ocv",
      "vccccccccccccccv",
      "vvvvvvvvvvvvvvvv"
    ],
    [
      "vvvvvvvvvvvvvvvv",
      "vccccccccccccccv",
      "vcd       =oopcv",
      "vcd      q=  pcv",
      "v==r      =  pcv",
      "vf       q= spcv",
      "vf        =  pcv",
      "vfj jjj      =cv",
      "vf           jcv",
      "vf       ff  fcv",
      "vf       ft   cv",
      "vfj jjj jf    cv",
      "vf       fu   cv",
      "vf       fw   cv",
      "vccccccccccccccv",
      "vvvvvvvvvvvvvvvv"
    ],
    [
      "vvvvvvvvvvvvvvvv",
      "vccccccccccccccv",
      "vcd       x  scv",
      "vcd          scv",
      "v==r          cv",
      "vf           scv",
      "vf           scv",
      "vf           =cv",
      "vf           jcv",
      "vf       ff  fcv",
      "vf       f   ycv",
      "vf       f   Acv",
      "vf       f   ycv",
      "vf       f    cv",
      "vccccccccccccccv",
      "vvvvvvvvvvvvvvvv"
    ],
    [
      "vvvvvvvvvvvvvvvv",
      "vccccccccccccccv",
      "vcd          scv",
      "vcd          scv",
      "v==          scv",
      "vf            cv",
      "vf           scv",
      "vf           =cv",
      "vf           jcv",
      "vf       fffffcv",
      "vf       f    cv",
      "vf       f   Acv",
      "vf       f    cv",
      "vf       f    cv",
      "vccccccccccccccv",
      "vvvvvvvvvvvvvvvv"
    ],
    [
      "vvvvvvvvvvvvvvvv",
      "vccccccccccccccv",
      "vcdBBBBBBBBBBCcv",
      "vcdBBBBBBBBBBDcv",
      "v==BBBBBBBBBBCcv",
      "vBBBBBBBBBBBBCcv",
      "vBBBBBBBBBBBBDcv",
      "vBBBBBBBBBBBB=cv",
      "vBBBBBBBBBBBBBcv",
      "vBBBBBBBBfffffcv",
      "vBBBBBBBBfBBBBcv",
      "vBBBBBBBBfBBBBcv",
      "vBBBBBBBBfBBBBcv",
      "vBBBBBBBBfBBBBcv",
      "vccccccccccccccv",
      "vvvvvvvvvvvvvvvv"
    ]
  ]
}