{
  "name": "building_office5_floor2_90",
  "refpalette": "c70cities:building_office5_floor2_palette_90",
  "xsize": 16,
  "zsize": 16,
  "slices": [
    [
      "                ",
      "                ",
      "     dbdbdbdbd  ",
      "     deeeeeeeb  ",
      "  abadeeeeeeed  ",
      "  bccdeeeeeeeb  ",
      "  accdeeeeeeed  ",
      "  bccdfeeeeeeb  ",
      "  accdfeeeeeed  ",
      "  bccdeeeeeeeb  ",
      "  acceeeeeeeed  ",
      "  bcceeeeeeeeb  ",
      "  abadeeeeeeed  ",
      "     dbdbdbdbd  ",
      "                ",
      "                "
    ],
    [
      "                ",
      "                ",
      "     dbdbdbdbd  ",
      "     d       b  ",
      "  abad    gm d  ",
      "  b id  k g  b  ",
      "  a id      md  ",
      "  b hdf   g  b  ",
      "  a gdf  kg  d  ",
      "  b gdj      b  ",
      "  a       gm d  ",
      "  b       g  b  ",
      "  abadj  l   d  ",
      "     dbdbdbdbd  ",
      "                ",
      "                "
    ],
    [
      "                ",
      "                ",
      "     dbdbdbdbd  ",
      "     d       b  ",
      "  aba!    o  d  ",
      "  b  d       b  ",
      "  a  d       d  ",
      "  b  df      b  ",
      "  a ndf      d  ",
      "  b  dj      b  ",
      "  a       o  d  ",
      "  b          b  ",
      "  abadj      d  ",
      "     dbdbdbdbd  ",
      "                ",
      "                "
    ],
    [
      "                ",
      "                ",
      "     dbdbdbdbd  ",
      "     d       b  ",
      "  abaq       d  ",
      "  b pd       b  ",
      "  a pd       d  ",
      "  b pdf      b  ",
      "  a pdf      d  ",
      "  b  d       b  ",
      "  a  q       d  ",
      "  b  q       b  ",
      "  abad       d  ",
      "     dbdbdbdbd  ",
      "                ",
      "                "
    ],
    [
      "                ",
      "                ",
      "     dbdbdbdbd  ",
      "     d       b  ",
      "  abad       d  ",
      "  b  d       b  ",
      "  a  d       d  ",
      "  b  df      b  ",
      "  a  df      d  ",
      "  b  d       b  ",
      "  a  d       d  ",
      "  b  d       b  ",
      "  abad       d  ",
      "     dbdbdbdbd  ",
      "                ",
      "                "
    ],
    [
      "                ",
      "                ",
      "     dbdbdbdbd  ",
      "     drrrrrrrb  ",
      "  abadrrrrrrrd  ",
      "  b  drrrrrrrb  ",
      "  a  drrrrrrrd  ",
      "  b  dfrrrrrrb  ",
      "  a  dfrrrrrrd  ",
      "  b  drrrrrrrb  ",
      "  a  drrrrrrrd  ",
      "  b  drrrrrrrb  ",
      "  abadrrrrrrrd  ",
      "     dbdbdbdbd  ",
      "                ",
      "                "
    ]
  ]
}