{
  "name": "building_bunker1_base1",
  "refpalette": "c70cities:building_bunker1_base1_palette",
  "xsize": 16,
  "zsize": 16,
  "slices": [
    [
      "================",
      "================",
      "========aaaaaa==",
      "========aaaaaa==",
      "========aaaaaa==",
      "========aaaaaa==",
      "================",
      "================",
      "================",
      "================",
      "====aaa=aa======",
      "====aaaaaa======",
      "========aa======",
      "====aaaaaa======",
      "====aaa=aa======",
      "================"
    ],
    [
      "zzzzzzzzzzzzzzzz",
      "bbbbbbbbbbbbbbbz",
      "bccbdddbefeghibz",
      "bj     b     kbz",
      "bl     m     nbz",
      "bo bbbbbp  qrqbz",
      "b  bss bt    ubz",
      "bs bw  x    yybz",
      "bABbo  bn C  Dbz",
      "bbbbbbbEbFb  Ibz",
      "zzzbJKLbn b  Mbz",
      "zzzbN  O  bPQIbz",
      "zzzbbbbb  bbbbbz",
      "zzzbN  O  R  Sbz",
      "zzzbJKTbUUbVWXbz",
      "zzzbbbbbbbbbbbbz"
    ],
    [
      "zzzzzzzzzzzzzzzz",
      "EEEEEEEEEEEYYYZz",
      "E01E   EL23   4z",
      "E      E      4z",
      "Eo     5     6Ez",
      "E  EEEEE7   89Ez",
      "E  Es  E      Ez",
      "E@ Ew  #      Ez",
      "EA$E   E6     Ez",
      "EEEEEEEEE%E  ^Ez",
      "zzzE01LE6 E   Ez",
      "zzzE&  *  E()+Ez",
      "zzzEEEEE  EEEEEz",
      "zzzE-  *  []] {z",
      "zzzE}\\TET E|`:{z",
      "zzzEEEEEE;EEEEEz"
    ],
    [
      "zzzzzzzzzzzzzzzz",
      "EEEEEEEEEEEEEEEz",
      "E01E'''E,,,,,,Ez",
      "E      E      Ez",
      "E      E     6Ez",
      "E  EEEEE      Ez",
      "E  E   E      Ez",
      "E  Ew  {      Ez",
      "EA!E   E6     Ez",
      "EEEEEEEEEEE  .Ez",
      "zzzEf/ E6 E  .Ez",
      "zzzE  <E  E>?\u00a3Ez",
      "zzzEEEEE  EEEEEz",
      "zzzE  <E  E\u00a4\u00a5 Ez",
      "zzzEf  E\u00a7\u00a7E \u00c0\u00c1Ez",
      "zzzEEEEEEEEEEEEz"
    ],
    [
      "zzzzzzzzzzzzzzzz",
      "EEEEEEEEEEEEEEEz",
      "E\u00c2\u00c2E\u00c3\u00c3\u00c3E\u00c4\u00c4\u00c4\u00c4\u00c4\u00c4Ez",
      "E\u00c2\u00c2\u00c5\u00c2\u00c2\u00c2E\u00c2\u00c2\u00c2\u00c2\u00c2\u00c2Ez",
      "E\u00c2\u00c2\u00c4\u00c2\u00c2\u00c2E\u00c2\u00c2\u00c2\u00c2\u00c2\u00c2Ez",
      "E\u00c4\u00c4EEEEE\u00c2\u00c2\u00c2\u00c2\u00c2\u00c2Ez",
      "E\u00c2\u00c2EEEEE\u00c2\u00c2\u00c2\u00c2\u00c2\u00c2Ez",
      "E\u00c2\u00c2EwEEE\u00c2\u00c2\u00c2\u00c2\u00c2\u00c2Ez",
      "EA\u00c2EEEEE\u00c2\u00c2\u00c2\u00c2\u00c2\u00c2Ez",
      "EEEEEEEEEEEE\u00c4EEz",
      "zzzE\u00c4\u00c2\u00c2E\u00c2\u00c2EE\u00c4EEz",
      "zzzE\u00c5\u00c2\u00c2E\u00c2\u00c2EE\u00c4EEz",
      "zzzEEEEE\u00c2\u00c2EEEEEz",
      "zzzE\u00c5\u00c2\u00c2E\u00c2\u00c2E\u00c2\u00c2\u00c4Ez",
      "zzzE\u00c4\u00c2\u00c2E\u00c4\u00c4E\u00c2\u00c2\u00c4Ez",
      "zzzEEEEEEEEEEEEz"
    ],
    [
      "zzzzzzzzzzzzzzzz",
      "zzzzzzzzzzzzzzzz",
      "zzzzzzzzzzzzzzzz",
      "zzzzzzzzzzzzzzzz",
      "zzzzzzzzzzzzzzzz",
      "zzzzzzzzzzzzzzzz",
      "zzzzEzzzzzzzzzzz",
      "zzzEwEzzzzzzzzzz",
      "zzzzEzzzzzzzzzzz",
      "zzzzzzzzzzzzzzzz",
      "zzzzzzzzzzzzzzzz",
      "zzzzzzzzzzzzzzzz",
      "zzzzzzzzzzzzzzzz",
      "zzzzzzzzzzzzzzzz",
      "zzzzzzzzzzzzzzzz",
      "zzzzzzzzzzzzzzzz"
    ]
  ]
}