{
  "name": "building_residential3_ground_180",
  "refpalette": "c70cities:building_residential3_ground_palette_180",
  "xsize": 16,
  "zsize": 16,
  "slices": [
    [
      "GGGGGGGGGGGGGGGG",
      "GGGGGGGGGGGGGGGG",
      "GGaaaaaaGGGGGGGG",
      "GGabbbbacccccGGG",
      "GGabbbbbddddcGGG",
      "GGabbbbbddddcGGG",
      "GGabbbbbddddcGGG",
      "GGabbbbbddddcGGG",
      "GGabbbbbbbbbaaGG",
      "GGabbbbbbbbbbaGG",
      "GGabbbbbbbbbbaGG",
      "GGabbbbbbbbbbaGG",
      "GGabbbbbbbbbbaGG",
      "GGaaaaaaaaaaaaGG",
      "GGGGGGGGGGGGGGGG",
      "GGGGGGGGGGGGGGGG"
    ],
    [
      "effffgffffgffffe",
      "f              f",
      "f hiFFihwwwwww f",
      "f h    hcccccw f",
      "f hE  xhDCBAcw f",
      "e hy  xh    cw g",
      "f h    h    cw f",
      "f hu   t    c  f",
      "f hu   t srrhh f",
      "f h       qq i e",
      "g hopo       n  ",
      "f hm k       l  ",
      "f h  k!  j   i e",
      "f hhhhhhhhhhhh f",
      "f              f",
      "effffgffffgffffe"
    ],
    [
      "effffgffffgffffe",
      "f              f",
      "f hiFFih       f",
      "f h    hcQQcc  f",
      "f F   RhT  Sc  f",
      "e F   Rh    Q  g",
      "f F    h    Q  f",
      "f hP   t    c  f",
      "f hO   t    hh f",
      "f F          i e",
      "g hoNo       M  ",
      "f IL kK      J  ",
      "f h  k  j    i e",
      "f hhIhFhhFFFhh f",
      "f              f",
      "effffgffffgffffe"
    ],
    [
      "                ",
      "                ",
      "  hiZZihYYYYYY  ",
      "  h    hcccccY  ",
      "  X    h    cY  ",
      "V X    h    cY  ",
      "  X    h    cY  ",
      "  h    t    cY  ",
      "  h    t    hh  ",
      "  X          i  ",
      "  hooo       W  ",
      "  X  k       W  ",
      "  h  k j     i V",
      "  hhUhUhhUUUhh  ",
      "                ",
      "                "
    ],
    [
      "                ",
      "                ",
      "  hhhhhh000000  ",
      "  hbbbbh333320  ",
      "  hbbbbb    10  ",
      "  hbbbbb    10  ",
      "  hbbbbb    10  ",
      "  hbbbbb    10  ",
      "  hbbbbbbbbbhh  ",
      "  hbbbbbbbbbbh  ",
      "  hbbbbbbbbbbh  ",
      "  hbbbbbbbbbbh  ",
      "  hbbbj   bbbh  ",
      "  hhhhhhhhhhhh  ",
      "                ",
      "                "
    ],
    [
      "                ",
      "                ",
      "  hFFFFh000000  ",
      "  h && hccccc0  ",
      "  X(*& @    c0  ",
      "  X(*& @    c0  ",
      "  X8&& @    c0  ",
      "  hiii @^   c0  ",
      "  h%$# @@@@@hh  ",
      "  F 9     877F  ",
      "  F          F  ",
      "  F   6666   F  ",
      "  F       544F  ",
      "  hhUUUhhUUUhh  ",
      "                ",
      "                "
    ]
  ]
}