{
  "name": "building_hotel1_floor3_90",
  "refpalette": "c70cities:building_hotel1_floor3_palette_90",
  "xsize": 16,
  "zsize": 16,
  "slices": [
    [
      "                ",
      " aaaaaaaaffffaa ",
      " abbbcbbbbbbbba ",
      " abbbcbbbbbbbbg ",
      " abbbcbbbbbbbbg ",
      " abbbcdbbbbbbbg ",
      " abbbc   ecccbg ",
      " abbbc    cbbbg ",
      " abbbc    cbbba ",
      " abbbc    cbbba ",
      " abbbccccccbbba ",
      " abbbbbbbbbbbba ",
      " abbbbbbbbbbbba ",
      " abbbbbbbbbbbba ",
      " aaaaadddddddaa ",
      "                "
    ],
    [
      "                ",
      " aaaaaaaaffffaa ",
      " a   a  n    na ",
      " al  q      Bea ",
      " a   a      Bea ",
      " a  op ss   eea ",
      " ak  a   daaaaa ",
      " aj =a   eaxACa ",
      " aj =a   eaw  a ",
      " ai  a    aff a ",
      " a  opaaaapu  a ",
      " a    =rr=aty a ",
      " ahn      a   a ",
      " a m          a ",
      " aaaaaaaaaaaaaa ",
      "                "
    ],
    [
      "                ",
      " aaaaaaaaffffaa ",
      " a   a  I    Ia ",
      " a   E        a ",
      " a   a        a ",
      " a  op        a ",
      " a   a    aaaaa ",
      " a   a    aK  f ",
      " a   a   da   f ",
      " a   a  eeaff f ",
      " a  opaaaap   f ",
      " a    F  Ja   f ",
      " a D      a   f ",
      " a            a ",
      " aaaaaffffaaaaa ",
      "                "
    ],
    [
      "                ",
      " aaaaaaaaffffaa ",
      " a   a  I    Ia ",
      " a   a        a ",
      " a   a        a ",
      " aL op        a ",
      " a   a    aaaaa ",
      " a   a    aM  a ",
      " a   a    a   a ",
      " a   aeed aff a ",
      " aL opaaaapL  a ",
      " a     BB a   a ",
      " a        a   a ",
      " a        a   a ",
      " aaaaaaaaaaaaaa ",
      "                "
    ],
    [
      "                ",
      " aaaaaaaaffffaa ",
      " a   a        a ",
      " a   a        a ",
      " a   a        a ",
      " aN  p        a ",
      " a   a    aaaaa ",
      " a   ae   a   f ",
      " a   ae   a   f ",
      " a   ad   afffa ",
      " aN  paaaapN  a ",
      " a        a   a ",
      " a        a   a ",
      " a        a   a ",
      " aaffaaaaaaaaaa ",
      "                "
    ],
    [
      "                ",
      " aaaaaaaaffffaa ",
      " aOOOaOOOOOOOOa ",
      " aOOOaOOOOOOOOa ",
      " aOOOaOOOOOOOOa ",
      " aOOOpOOOOOOOOa ",
      " aOOOae   aaaaa ",
      " aOOOad   aOOOa ",
      " aOOOa    aOOOa ",
      " aOOOa    aOOOa ",
      " aOOOpaaaapOOOa ",
      " aOOOOOOOOaOOOa ",
      " aOOOOOOOOaOOOa ",
      " aOOOOOOOOaOOOa ",
      " aaaaaaaaaaaaaa ",
      "                "
    ]
  ]
}