{
  "name": "building_factory2_floor1_90",
  "refpalette": "c70cities:building_factory2_floor1_palette_90",
  "xsize": 16,
  "zsize": 16,
  "slices": [
    [
      "                ",
      " aeeeiieeiieeea ",
      " bddddddddddddj ",
      " bd  g    g fdj ",
      " bd  h    h  dj ",
      " bd  h    h  dj ",
      " bd  g    g  dj ",
      " bd  g    g  dj ",
      " bd  h    h  dj ",
      " bd  h    h fdj ",
      " bdf gf f g fdj ",
      " bddddddddddddj ",
      " acccccccccccca ",
      "                ",
      "                ",
      "                "
    ],
    [
      "                ",
      " a   ii  ii   a ",
      "  mmmmmmmmmmmm  ",
      "  mf f     ffm  ",
      "  m  p    p fm  ",
      "  m          m  ",
      "  m  p    p  m  ",
      "  m  p    p  m  ",
      "  mnn  nn  nnm  ",
      "  mnnp nn pnnm  ",
      " lmnnoonnoonnql ",
      " lmddddddddddql ",
      " kkkkkkkkkkkkkk ",
      " kkkkkkkkkkkkkk ",
      "                ",
      "                "
    ],
    [
      "                ",
      " a   ii  ii   a ",
      "  mmmmmmmmmmmm  ",
      "  m rorf ror m  ",
      "  m ror  ror m  ",
      "  mnnddnnddnnm  ",
      " lqnnddnnddnnql ",
      " lqnnddnnddnnql ",
      " kk  ss  ss  kk ",
      " kk  ss  ss  kk ",
      "                ",
      "                ",
      "                ",
      "                ",
      "                ",
      "                "
    ],
    [
      "                ",
      " aeeeiieeiieeea ",
      " lqddiiddiiddql ",
      " lqddiiddiiddql ",
      " kkssiissiisskk ",
      " kk          kk ",
      "                ",
      "                ",
      "                ",
      "                ",
      "                ",
      "                ",
      "                ",
      "                ",
      "                ",
      "                "
    ],
    [
      " kkkkkkkkkkkkkk ",
      " kkkkkkkkkkkkkk ",
      "     ui  ui     ",
      "     tw  tw     ",
      "        ~       ",
      "                ",
      "                ",
      "                ",
      "                ",
      "                ",
      "                ",
      "                ",
      "                ",
      "                ",
      "                ",
      "                "
    ],
    [
      "                ",
      "                ",
      "                ",
      "                ",
      "        ~       ",
      "                ",
      "                ",
      "                ",
      "                ",
      "                ",
      "                ",
      "                ",
      "                ",
      "                ",
      "                ",
      "                "
    ]
  ]
}