{
  "name": "building_office1_ground_180",
  "refpalette": "c70cities:building_office1_ground_palette_180",
  "xsize": 16,
  "zsize": 16,
  "slices": [
    [
      "GGGGGGGGGGGGGGGG",
      "GbbbbbbbbbbbbbbG",
      "GbdbbbbbbbbbbebG",
      "GbdbbbbbbbbbbebG",
      "GbdbbbbbbbbbbdbG",
      "GbdbbbbbbbbbbdbG",
      "GbdbbbbbbbbbbdbG",
      "GbdbbbbbbbbbbdbG",
      "GbcbbbbbbbbbbcbG",
      "Gbcbbbb!bbbbbcbG",
      "GbcbbbbbbbbbbcbG",
      "GbcbbbbbbbbbbcbG",
      "GbcbbbbbbbbbbcbG",
      "GbccccccccccccbG",
      "GbbbbbbbbbbbbbbG",
      "GGGGaGGGGGGaGGGG"
    ],
    [
      "                ",
      " ssssssssssssss ",
      " A           xs ",
      " y           xs ",
      " sd  w oo u tds ",
      "  h  r oo q  h  ",
      "  h  p oo n  h  ",
      " gd          dg ",
      "  h          h  ",
      "  h  lllllm  h  ",
      " gh  l    k  hg ",
      "  h   j  j   h  ",
      "  hi        ih  ",
      " ghhhhhhhhhhhhg ",
      "   g  g  g  g   ",
      "ffffffffffffffff"
    ],
    [
      "                ",
      " ssIhhhhhhhhIss ",
      " F            s ",
      " E            s ",
      " sd         tds ",
      "  h          h  ",
      "  h          h  ",
      " gd          dg ",
      "  h          h  ",
      "  h  DC      h  ",
      " gh          hg ",
      "  h          h  ",
      "  hB        Bh  ",
      " ghhhhhhhhhhhhg ",
      "   g  g  g  g   ",
      "                "
    ],
    [
      "                ",
      " ssIhhhhhhhhIss ",
      " s           Ks ",
      " s           Js ",
      " sd         tds ",
      "  h          h  ",
      "  h          h  ",
      " gd          dg ",
      "  h          h  ",
      "  h          h  ",
      " gh          hg ",
      "  h          h  ",
      "  hB        Bh  ",
      " ghhhhhhhhhhhhg ",
      "   g  g  g  g   ",
      "                "
    ],
    [
      "                ",
      " ssssssssssssss ",
      " s           Ls ",
      " s            s ",
      " sd         tds ",
      "  h          h  ",
      "  h          h  ",
      " gd          dg ",
      "  h          h  ",
      "  h          h  ",
      " gh          hg ",
      "  h          h  ",
      "  h          h  ",
      " ghhhhhhhhhhhhg ",
      "   g  g  g  g   ",
      "                "
    ],
    [
      "                ",
      " ssssssssssssss ",
      " sIIIIIIIIIIIIs ",
      " sIIIIIIIIIIIIs ",
      " sd IIIIIIIItds ",
      "  h IIIIIIII h  ",
      "  h IIIIIIII h  ",
      " MMIIIIIIIIIIMM ",
      " MMIIIIIIIIIIMM ",
      " MMIIIIIIIIIIMM ",
      " MMIIIIIIIIIIMM ",
      " MMIIIIIIIIIIMM ",
      " MMIIIIIIIIIIMM ",
      " MMM MMMMMMMMMM ",
      " MMMMMMMMMMMMMM ",
      "                "
    ]
  ]
}