{
  "name": "building_carservice1_floor1_90",
  "refpalette": "c70cities:building_carservice1_floor1_palette_90",
  "xsize": 16,
  "zsize": 16,
  "slices": [
    [
      "                ",
      "      eeeeee    ",
      " a    acffcdd   ",
      "      dcfffcdd  ",
      "      dcffffcde ",
      "      dcfffffje ",
      " a    acffffffa ",
      "      dcffgggge ",
      "      dcffgiige ",
      "    HHdcffgggge ",
      " a  bbacff!hhga ",
      "    bbccffhbbge ",
      "  bbbbccffgggge ",
      "  bbbbccffffffe ",
      " a    aeeeeeeea ",
      "                "
    ],
    [
      "                ",
      "      eeeeee    ",
      " a    aruuBss   ",
      "      er    ss  ",
      "      er     se ",
      "      eq     je ",
      " akkklapt    Da ",
      " k  HHeo  Ayype ",
      " k  bben  yCCye ",
      " k    en  pyype ",
      " a    a   x  xa ",
      " k            e ",
      " k            e ",
      " k    m  ww   e ",
      " akkklaesssssea ",
      "                "
    ],
    [
      "                ",
      "      esssee    ",
      " a    a    ss   ",
      "      eF    ss  ",
      "      eF     se ",
      "    HHe      je ",
      " aaEbba      Na ",
      "      e   L JKe ",
      "      en IK  Me ",
      "      e   J LKe ",
      " a    a       a ",
      "              e ",
      "      m       e ",
      "      m       e ",
      " a    aesssssea ",
      "                "
    ],
    [
      "                ",
      "      eeeeee    ",
      " a    a    ss   ",
      "  bbbbe     ss  ",
      "  bbbbe      se ",
      "  bb  e      je ",
      " abb  a       a ",
      "  HH  e   OOOPe ",
      "      e   O   e ",
      "      e   OOOPe ",
      " a    a       a ",
      "      m       e ",
      "      m       e ",
      "      m       e ",
      " a    aesssssea ",
      "                "
    ],
    [
      "                ",
      "      eeeeee    ",
      " alkkka    ss   ",
      " k    e     ss  ",
      " k    e      se ",
      " k    e      je ",
      " a    a       a ",
      " k    e       e ",
      " kbb  e       e ",
      " kHH  e       e ",
      " alkkka       a ",
      "      e       e ",
      "      e       e ",
      "      e       e ",
      " a    aeQQQQQea ",
      "                "
    ],
    [
      "                ",
      "      eeeeee    ",
      " a    a    ss   ",
      "      e  k  ss  ",
      "      e  kk  se ",
      "      e  kkk je ",
      " a    a  kkkk a ",
      "      e  kkkkke ",
      "      e  kkkkke ",
      "      e  kkkkke ",
      " abbEaa  kkkkka ",
      "  HH  e  kkkkke ",
      "      e  kkkkke ",
      "      e  kkkkke ",
      " a    aeeeeeeea ",
      "                "
    ]
  ]
}