{
  "name": "building_policeoffice1_floor2_90",
  "refpalette": "c70cities:building_policeoffice1_floor2_palette_90",
  "xsize": 16,
  "zsize": 16,
  "slices": [
    [
      "           cccc ",
      "           c  f ",
      "           d  c ",
      "           c  c ",
      " aaaaaaaaaacbbc ",
      " abbbbbbbbbbbbf ",
      " abbbbbbbbbbbbc ",
      " abbbb!bbbbbbbc ",
      " abbbbbbbbbbbbc ",
      " abbbbbbbbbbbbf ",
      " abbbbbbbbbbbbc ",
      " abbbb!bbbbbbbc ",
      " abbbbbbbbbbbbc ",
      " aaaaaaaaaaceef ",
      "           cccc ",
      "                "
    ],
    [
      "           cccc ",
      "           c  f ",
      "           d  c ",
      "           c  c ",
      " gggggggggacllc ",
      " g            f ",
      " g ch ch ch  mc ",
      " g c  c  c   mc ",
      " g ch ch ch  mc ",
      " g           mf ",
      " g ch ch   kkkc ",
      " g c  c    j  c ",
      " g ch ch   i  c ",
      " aaaaaaaaaaceef ",
      "           cccc ",
      "                "
    ],
    [
      "           cccc ",
      "           c  f ",
      "           d  c ",
      "           c  c ",
      " gggggggggac  c ",
      " g            f ",
      " g n  n  n   sc ",
      " g            c ",
      " g n  n  n   rc ",
      " g           qf ",
      " g n  n    kkkc ",
      " g         p  c ",
      " g n  n    o  c ",
      " aaaaaaaaaaceef ",
      "           cccc ",
      "                "
    ],
    [
      "           cccc ",
      "           c  f ",
      "           d  c ",
      "           c  c ",
      " gggggggggac  c ",
      " g            f ",
      " g           sc ",
      " g            c ",
      " g            c ",
      " g            f ",
      " g         kmkc ",
      " g         k  c ",
      " g         k  c ",
      " aaaaaaaaaaceef ",
      "           cccc ",
      "                "
    ],
    [
      "           cccc ",
      "           c  f ",
      "           d  c ",
      "           c  c ",
      " gggggggggac  c ",
      " g            f ",
      " g           sc ",
      " g            c ",
      " g            c ",
      " g            f ",
      " g         kkkc ",
      " g         k  c ",
      " g         k  c ",
      " aaaaaaaaaaceef ",
      "           cccc ",
      "                "
    ],
    [
      "           cccc ",
      "           c  f ",
      "           d  c ",
      "           c  c ",
      " tttttttttacuuc ",
      " tuuuuuuuuuuuuf ",
      " tuuuuuuuuuuuuc ",
      " tuuuuuuuuuuuuc ",
      " tuuuuuuuuuuuuc ",
      " tuuuuuuuuuuuuf ",
      " tuuuuuuuuukkkc ",
      " tuuuuuuuuukuuc ",
      " tuuuuuuuuukuuc ",
      " aaaaaaaaaaceef ",
      "           cccc ",
      "                "
    ]
  ]
}