{
  "name": "building_hotel3_floor1_180",
  "refpalette": "c70cities:building_hotel3_floor1_palette_180",
  "xsize": 16,
  "zsize": 16,
  "slices": [
    [
      "                ",
      "  a a a a a a   ",
      "  bbbbbbbbbbbba ",
      " abccccccccccb  ",
      "  bceeeeeeeecba ",
      " abceffffffecb  ",
      "  bceffffffecba ",
      " abceffffffecb  ",
      "  bceffffffecba ",
      " abceffffffecb  ",
      "  bceffffffecba ",
      " abceeeeeeeecb  ",
      "  bccccddccccba ",
      " abbbbbbbbbbbb  ",
      "   a a a a a a  ",
      "                "
    ],
    [
      "                ",
      "  a a a a a a   ",
      "  bbbbbbbbbbbba ",
      " ab          b  ",
      "  b tmmmmmmt ba ",
      " ab m rqps e b  ",
      "  b m rqp oe ba ",
      " ab m      e b  ",
      "  b m hhn je ba ",
      " ab m lkh je b  ",
      "  b e hihhhe ba ",
      " ab egeeeeee b  ",
      "  b    dd    ba ",
      " abbbbbbbbbbbb  ",
      "   a a a a a a  ",
      "                "
    ],
    [
      "                ",
      "  a a a a a a   ",
      "  bbbbbbbbbbbba ",
      " ab          b  ",
      "  b t      t ba ",
      " ab     pAAe b  ",
      "  b     p  x ba ",
      " ab        x b  ",
      "  b   hh   x ba ",
      " ab   y h  x b  ",
      "  b e h h we ba ",
      " ab eueeeeee b  ",
      "  b    dd    ba ",
      " abbbbbbbbbbbb  ",
      "   a a a a a a  ",
      "                "
    ],
    [
      "                ",
      "  a a a a a a   ",
      "  bbbbbbbbbbbba ",
      " ab          b  ",
      "  b t      t ba ",
      " ab     p  e b  ",
      "  b     p  e ba ",
      " ab        e b  ",
      "  b   hh   e ba ",
      " ab   h h  e b  ",
      "  b e h h  e ba ",
      " ab eeeeeeee b  ",
      "  b    dd    ba ",
      " abbbbbbbbbbbb  ",
      "   a a a a a a  ",
      "                "
    ],
    [
      "                ",
      "  a a a a a a   ",
      "  bbbbbbbbbbbba ",
      " ab          b  ",
      "  b t      t ba ",
      " ab        e b  ",
      "  b     !  e ba ",
      " ab        e b  ",
      "  b   hh   e ba ",
      " ab   h h  e b  ",
      "  b e h hAAe ba ",
      " ab eeeeeeee b  ",
      "  b    dd    ba ",
      " abbbbbbbbbbbb  ",
      "   a a a a a a  ",
      "                "
    ],
    [
      "                ",
      "  a a a a a a   ",
      "  bbbbbbbbbbbba ",
      " ab          b  ",
      "  b eeeeeeee ba ",
      " ab eBBBBBBe b  ",
      "  b eBBBBBBe ba ",
      " ab eBBBBBBe b  ",
      "  b eBBBBBBe ba ",
      " ab eBBBBBBe b  ",
      "  b eBBBBBBe ba ",
      " ab eeeeeeee b  ",
      "  b    dd    ba ",
      " abbbbbbbbbbbb  ",
      "   a a a a a a  ",
      "                "
    ]
  ]
}