{
  "name": "building_factory2_ground_90",
  "refpalette": "c70cities:building_factory2_ground_palette_90",
  "xsize": 16,
  "zsize": 16,
  "slices": [
    [
      "zzzzzzzzzzzzzzzz",
      "zzzzzzzzzzzzzzzz",
      "zzzzzzzzHHzzzzzz",
      "zzzHHHHHHHHHHzzz",
      "zzzHHHHHHHHHHzzz",
      "zzzHHHHHHHHHHzzz",
      "zzzHHHHHHHHHHzzz",
      "zzzHHHHHHHHHHzzz",
      "zzzHHHHHHHHHHzzz",
      "zzzHHHHHHHHHHzzz",
      "zzzHHHHHHHHHHzzz",
      "zzzHHHHHHHHHHzzz",
      "zzzzaaaaazzzzzzz",
      "zzzzaaazaazzzzzz",
      "zzzzzazaazazzzzz",
      "zzzzazzzzzzzzzzz"
    ],
    [
      " b dceec eebdcc ",
      " efffeeffeefffeb",
      "bcffffffffffffcb",
      "ccfkkkknkyCEgf d",
      "dcfkknknuxB gfc ",
      "  fkknknki   fcc",
      "b fffmpst  DFfb ",
      " bfj   r     fc ",
      "  fi i      Ffcb",
      "bcfh      Aggfc ",
      "dcfgi   gwgg!fdb",
      "ccfflfoqqqqoffc ",
      " ecb     b ccceb",
      "bcd       bb cb ",
      " b b        db b",
      "                "
    ],
    [
      "     ee  ee     ",
      " efffeeffeefffe ",
      " cffffffNfffff  ",
      "  f  KKnM  PjI  ",
      "  fnKnKn     I  ",
      "  fuKKKnM    Ic ",
      "  f  L       f  ",
      "  f          fc ",
      "  I          Ic ",
      "  I        O I  ",
      " cI        gOI  ",
      " cffJfoqqqqoff  ",
      " ec         cce ",
      "                ",
      "                ",
      "                "
    ],
    [
      "     ee  ee     ",
      " efffeeffeefffe ",
      "  ffffffQfffff  ",
      "  fjRRR      I  ",
      "  f RRRP     I  ",
      "  f RRR      I  ",
      "  f  S       f  ",
      "  f          f  ",
      "  I          I  ",
      "  I          I  ",
      "  I          I  ",
      " cffQfoqqqqoff  ",
      " e            e ",
      "                ",
      "                ",
      "                "
    ],
    [
      "     UU  UU     ",
      " eUUUVVUUVVUUUe ",
      "  ffffffffffff  ",
      "  fj   X   X T  ",
      "  f          T  ",
      "  f          T  ",
      "  f          f  ",
      "  f          f  ",
      "  T          T  ",
      "  T          T  ",
      "  T          T  ",
      "  ffffooooooff  ",
      " e     WWWW   e ",
      "                ",
      "                ",
      "                "
    ],
    [
      "                ",
      " e   VV  VV   e ",
      "  ffffffffffff  ",
      "  Y          Y  ",
      "  Y          Y  ",
      "  Y          Y  ",
      "  f  0    0  f  ",
      "  f  Z    0  f  ",
      "  Y          Y  ",
      "  Y          Y  ",
      "  Y          Y  ",
      "  ffffYYYYYYff  ",
      " e            e ",
      "                ",
      "                ",
      "                "
    ]
  ]
}