{
  "name": "building_apartment1_top",
  "refpalette": "c70cities:building_apartment1_top_palette",
  "xsize": 16,
  "zsize": 16,
  "slices": [
    [
      "                ",
      " aaaaaaaaaaaaaa ",
      " abbbbbbbbbbbba ",
      " abccccccccccba ",
      " abccccccccccba ",
      " abccccccccccba ",
      " abccccccccccba ",
      " abccccccccccba ",
      " abccccccccccba ",
      " abccccccccccba ",
      " abcccccccd  b  ",
      " abccccccc   e  ",
      " abccccccc   e  ",
      " abbbbbbbbbfgh  ",
      " aaaaaaaaa      ",
      "                "
    ],
    [
      "                ",
      "                ",
      "  iijbbklbiijm  ",
      "  in   n     l  ",
      "  i  ooppopp b  ",
      "  bn o pp pp b  ",
      "  booo       i  ",
      "  m !on      i  ",
      "  l  o       q  ",
      "  l  o  nrsrrb  ",
      "  t no nur   b  ",
      "  boow  ur   b  ",
      "  b no  nr   b  ",
      "  bbbbllxbiibb  ",
      "                ",
      "                "
    ],
    [
      "                ",
      "                ",
      "  bbiiibbbbbbb  ",
      "  b          b  ",
      "  b    yy yA b  ",
      "  b    By yA b  ",
      "  b          b  ",
      "  b          b  ",
      "  b          b  ",
      "  b      rCrrb  ",
      "  b     Dr   g  ",
      "  l     Dr   i  ",
      "  l      r   b  ",
      "  biijbbbbbbbb  ",
      "                ",
      "                "
    ],
    [
      "                ",
      "                ",
      "  bbbbbbkllbbb  ",
      "  b          l  ",
      "  b          l  ",
      "  l          l  ",
      "  l          t  ",
      "  l          b  ",
      "  b          b  ",
      "  b      EEEEb  ",
      "  b      EEEEb  ",
      "  b     nEEEEb  ",
      "  b      EEEEb  ",
      "  bbbbbllbbbbb  ",
      "                ",
      "                "
    ],
    [
      "                ",
      "                ",
      "                ",
      "                ",
      "                ",
      "                ",
      "                ",
      "                ",
      "                ",
      "                ",
      "                ",
      "                ",
      "                ",
      "                ",
      "                ",
      "                "
    ],
    [
      "                ",
      "                ",
      "                ",
      "                ",
      "                ",
      "                ",
      "                ",
      "                ",
      "                ",
      "                ",
      "                ",
      "                ",
      "                ",
      "                ",
      "                ",
      "                "
    ]
  ]
}