{
  "name": "building_office1_floor1_90",
  "refpalette": "c70cities:building_office1_floor1_palette_90",
  "xsize": 16,
  "zsize": 16,
  "slices": [
    [
      "                ",
      "        c  eeee ",
      "  aaaaaacddfbbe ",
      "  abbbbbbbbbbbe ",
      "  abbbbbbbbbbbe ",
      "  abbbbbbbbb!be ",
      "  abbbbbbbbbbbe ",
      "  abbbbbbbbbbbe ",
      "  abbbbbbbbbbbe ",
      "  abbbbbbbbbbbe ",
      "  abbbbbbbbbbbe ",
      "  abbbbbbbbbbbe ",
      "  abbbbbbbbgbbe ",
      "  aaaaaacddfbbe ",
      "        c  eeee ",
      "                "
    ],
    [
      "                ",
      "        c  ssss ",
      "  hhhhhhcddfADs ",
      "  h    nf     s ",
      "  h  l  f     s ",
      "  h   m f  uy s ",
      "  h ik  f   yCs ",
      "  h   m f  uy s ",
      "  h i   ffrfffs ",
      "  h  km fq txBs ",
      "  h i   p     s ",
      "  h  j  o     s ",
      "  h     f  g  s ",
      "  hhhhhhcddfwws ",
      "        c  ssss ",
      "                "
    ],
    [
      "                ",
      "        c  ssss ",
      "  hhhhhhcddfO s ",
      "  h    Ff     P ",
      "  h     f     d ",
      "  h  E  f   N d ",
      "  h  E  f   M d ",
      "  h  E  f   L d ",
      "  h  E  ffKfffd ",
      "  h  E  fq    d ",
      "  h  E  J     d ",
      "  h     I     d ",
      "  h     f  g  P ",
      "  hhhhhhcddfwws ",
      "        c  ssss ",
      "                "
    ],
    [
      "                ",
      "        c  ssss ",
      "  hhhhhhcddf  s ",
      "  h     f     P ",
      "  h     f     d ",
      "  h     f     d ",
      "  h     f     d ",
      "  h     f     d ",
      "  h     ffffffd ",
      "  h     f     d ",
      "  h     f     d ",
      "  h     f     d ",
      "  h     f  g  P ",
      "  hhhhhhcddfwws ",
      "        c  ssss ",
      "                "
    ],
    [
      "                ",
      "        c  ssss ",
      "  hhhhhhcddf  s ",
      "  h     f     s ",
      "  h     f     s ",
      "  h     f     s ",
      "  h     f     s ",
      "  h     f     s ",
      "  h     ffffffs ",
      "  h     f     s ",
      "  h     f     s ",
      "  h     f     s ",
      "  h     f  g  s ",
      "  hhhhhhcddfQQs ",
      "        c  ssss ",
      "                "
    ],
    [
      "                ",
      "        c  ssss ",
      "  hhhhhhcddfPPs ",
      "  hPPPPPf   PPs ",
      "  hPPPPPfPPPPPs ",
      "  hPPPPPfPPPPPs ",
      "  hPPPPPfPPPPPs ",
      "  hPPPPPfPPPPPs ",
      "  hPPPPPffffffs ",
      "  hPPPPPfPPPPPs ",
      "  hPPPPPfPPPPPs ",
      "  hPPPPPfPPPPPs ",
      "  hPPPPPf  gPPs ",
      "  hhhhhhcddfPPs ",
      "        c  ssss ",
      "                "
    ]
  ]
}