{
  "name": "building_carfactory1_ground_90",
  "refpalette": "c70cities:building_carfactory1_ground_palette_90",
  "xsize": 16,
  "zsize": 16,
  "slices": [
    [
      "zzzzzzzzzzzzzzzz",
      "zzzzzzzzzzzzzzzz",
      "zzzzzzzzzzzzzzzz",
      "zzzzzHHHHHHHHzza",
      "zzazHHcdcdcdHHaz",
      "azaaHHdgdcgdHHza",
      "zazaHHcdddccHHaa",
      "azaaHHbebhihHHaa",
      "zzaaHHbfbfffHHaz",
      "zazazHbfbfffHzzz",
      "zzzzzHbebhihHzzz",
      "zzzzzHHHHHHHHHzz",
      "zzzzzHHHH!HHHHzz",
      "zzzzzzzzzzzzzzzz",
      "zzzzzzzzzzzzzzzz",
      "zzzzzzzzzzzzzzzz"
    ],
    [
      " jj   j j j knj ",
      " jnqnnk nn nnnqk",
      "  ptuuuuuuuuuunn",
      "jkoturpDFlKMlun ",
      "   swmA     lw  ",
      "             P  ",
      "             P  ",
      "         I I P  ",
      " j n         P j",
      "  knwr      Cwnj",
      "j jmuty  I I uun",
      "  nru  C     OQq",
      "  mruxmBEEJL NQq",
      "  lluuuuuuuuuuun",
      "   qnnn nnnknnqj",
      "jjj nnjk j jjnj "
    ],
    [
      "                ",
      "   q    n   nnq ",
      "   tuSSSuuSSSun ",
      "    uU  W   lun ",
      "    w        w  ",
      "    R        P  ",
      "    R        P  ",
      "    R   VX XYP  ",
      "    R    b b P  ",
      "   nwT   b b w  ",
      "    u   VX XYuun",
      "    u        ZQq",
      "   ru        NQq",
      "   luSSSuuSSSuun",
      "   qnn   n   nq ",
      "                "
    ],
    [
      "                ",
      "   q          q ",
      "   0uSSSuuSSSun ",
      "    u        u  ",
      "    w        w  ",
      "    R        P  ",
      "    R        P  ",
      "    R   ot2tyP  ",
      "    R    242 P  ",
      "    w    232 w  ",
      "    u    12tyuu ",
      "    u        5Qq",
      "    u        5Qq",
      "    uSSSuuSSSuu ",
      "   qn         q ",
      "                "
    ],
    [
      "                ",
      "   q          q ",
      "    u777uu777u  ",
      "    u        u  ",
      "    w        w  ",
      "   6w        w6 ",
      "   6w        w6 ",
      "   6w    #^# w6 ",
      "   6w    @ @ w6 ",
      "    w    9%9 w  ",
      "    u    8$8 u& ",
      "    u        uQ&",
      "    u        uQ&",
      "    u777uu777u& ",
      "   q          q ",
      "                "
    ],
    [
      "                ",
      "   q          q ",
      "    u***uu***u  ",
      "    u        u  ",
      "    *        *  ",
      "    * (    ( *  ",
      "    * )      *  ",
      "    *        *  ",
      "    *        *  ",
      "    *    + + *  ",
      "    u (    ( u  ",
      "    u        uQ ",
      "    u        uQ ",
      "    u***uu***u  ",
      "   q          q ",
      "                "
    ]
  ]
}