{
  "name": "building_bank1_base1_90",
  "refpalette": "c70cities:building_bank1_base1_palette_90",
  "xsize": 16,
  "zsize": 16,
  "slices": [
    [
      "vvvvvvvvvvvvvvvv",
      "vaabbaaaabbaaaav",
      "vabbbbbbbbbbbbav",
      "vabbbbbbbbbbbbbv",
      "vabbbbbbbbbbb!bv",
      "vbbbbbbbbbbbbbav",
      "vbbbbbbbbbbbbbav",
      "vabbbbbbbbbbbbav",
      "vabbbbbbbbbbbbav",
      "vabbbbbbbbbbbbbv",
      "vabbbbbbbbbbbbbv",
      "vbbbbbbbbbbbbbav",
      "vb!bbbbbbbbbbbav",
      "vabbbbbbbbbbbbav",
      "vaaaabbaaaabbaav",
      "vvvvvvvvvvvvvvvv"
    ],
    [
      "vvvvvvvvvvvvvvvv",
      "vaabbaaaabbaaaav",
      "vagccffffccdiiav",
      "va           cbv",
      "vae          cbv",
      "vbc          fav",
      "vbc          fav",
      "vaf   f      fav",
      "vaf          fav",
      "vae      f   cbv",
      "vadf         cbv",
      "vbc           av",
      "vbc         j av",
      "va f cchdifcc av",
      "vaaaabbaaaabbaav",
      "vvvvvvvvvvvvvvvv"
    ],
    [
      "vvvvvvvvvvvvvvvv",
      "vaabbaaaabbaaaav",
      "va cchlh ccdeiav",
      "va           cbv",
      "va           cbv",
      "vbc           av",
      "vbc          nav",
      "va           iav",
      "vak          nav",
      "va           cbv",
      "vae          cbv",
      "vbc           av",
      "vbc         j av",
      "va   ccmd ecc av",
      "vaaaabbaaaabbaav",
      "vvvvvvvvvvvvvvvv"
    ],
    [
      "vvvvvvvvvvvvvvvv",
      "vaabbaaaabbaaaav",
      "va cc    cc   av",
      "va           cbv",
      "va           cbv",
      "vbc           av",
      "vbc           av",
      "va            av",
      "va            av",
      "va           cbv",
      "va           cbv",
      "vbc           av",
      "vbc         j av",
      "va   cc    cc av",
      "vaaaabbaaaabbaav",
      "vvvvvvvvvvvvvvvv"
    ],
    [
      "vvvvvvvvvvvvvvvv",
      "vaabbaaaabbaaaav",
      "va cc    cc   av",
      "va           cbv",
      "va           cbv",
      "vbc           av",
      "vbc           av",
      "va            av",
      "va            av",
      "va           cbv",
      "va           cbv",
      "vbc           av",
      "vbc         j av",
      "va   cc    cc av",
      "vaaaabbaaaabbaav",
      "vvvvvvvvvvvvvvvv"
    ],
    [
      "vvvvvvvvvvvvvvvv",
      "vaabbaaaabbaaaav",
      "vapccooooccoogav",
      "vaooooooooooocbv",
      "vaooooooooooocbv",
      "vbcoooooooooooav",
      "vbcoooooooooooav",
      "vaooooooooooooav",
      "vaooooooooooooav",
      "vaooooooooooocbv",
      "vaooooooooooocbv",
      "vbcoooooooooooav",
      "vbcooooooooojoav",
      "vagooccooooccqav",
      "vaaaabbaaaabbaav",
      "vvvvvvvvvvvvvvvv"
    ]
  ]
}