{
  "name": "building_office1_floor2_270",
  "refpalette": "c70cities:building_office1_floor2_palette_270",
  "xsize": 16,
  "zsize": 16,
  "slices": [
    [
      "                ",
      " eeee  c        ",
      " ebbfddcaaaaaa  ",
      " ebbgbbbbbbbba  ",
      " ebbbbbbbbbbba  ",
      " ebbbbbbbbbbba  ",
      " ebbbbbbbbbbba  ",
      " ebbbbbbbbbbba  ",
      " ebbbbbbbbbbba  ",
      " ebbbbbbbbbbba  ",
      " ebbbb!bbbbbba  ",
      " ebbbbbbbbbbba  ",
      " ebbbbbbbbbbba  ",
      " ebbfddcaaaaaa  ",
      " eeee  c        ",
      "                "
    ],
    [
      "                ",
      " llll  c        ",
      " lmmfddchhhhhh  ",
      " l  g        h  ",
      " l    ji  ji h  ",
      " l    j   j  h  ",
      " l   kj  kj  h  ",
      " l           h  ",
      " l           h  ",
      " l    ji  ji h  ",
      " l    j   j  h  ",
      " l   kj  kj  h  ",
      " l           h  ",
      " lnnfddchhhhhh  ",
      " llll  c        ",
      "                "
    ],
    [
      "                ",
      " llll  c        ",
      " l  fddchhhhhh  ",
      " r  g        h  ",
      " d    o   o  h  ",
      " d    p   p  h  ",
      " d    o   o  h  ",
      " d           h  ",
      " d           h  ",
      " d    o   o  h  ",
      " d    p   p  h  ",
      " d    o   o  h  ",
      " r           h  ",
      " lq fddchhhhhh  ",
      " llll  c        ",
      "                "
    ],
    [
      "                ",
      " llll  c        ",
      " lssfddchhhhhh  ",
      " r  g        h  ",
      " d           h  ",
      " d           h  ",
      " d           h  ",
      " d           h  ",
      " d           h  ",
      " d           h  ",
      " d           h  ",
      " d           h  ",
      " r           h  ",
      " l  fddchhhhhh  ",
      " llll  c        ",
      "                "
    ],
    [
      "                ",
      " llll  c        ",
      " l  fddchhhhhh  ",
      " l  g        h  ",
      " l           h  ",
      " l           h  ",
      " l           h  ",
      " l           h  ",
      " l           h  ",
      " l           h  ",
      " l           h  ",
      " l           h  ",
      " l           h  ",
      " l  fddchhhhhh  ",
      " llll  c        ",
      "                "
    ],
    [
      "                ",
      " llll  c        ",
      " lrrfddchhhhhh  ",
      " lrrg  rrrrrrh  ",
      " lrrrrrrrrrrrh  ",
      " lrrrrrrrrrrrh  ",
      " lrrrrrrrrrrrh  ",
      " lrrrrrrrrrrrh  ",
      " lrrrrrrrrrrrh  ",
      " lrrrrrrrrrrrh  ",
      " lrrrrrrrrrrrh  ",
      " lrrrrrrrrrrrh  ",
      " lrr   rrrrrrh  ",
      " lrrfddchhhhhh  ",
      " llll  c        ",
      "                "
    ]
  ]
}