{
  "name": "building_office5_floor2_270",
  "refpalette": "c70cities:building_office5_floor2_palette_270",
  "xsize": 16,
  "zsize": 16,
  "slices": [
    [
      "                ",
      "                ",
      "  dbdbdbdbd     ",
      "  deeeeeeedaba  ",
      "  beeeeeeeeccb  ",
      "  deeeeeeeecca  ",
      "  beeeeeeedccb  ",
      "  deeeeeefdcca  ",
      "  beeeeeefdccb  ",
      "  deeeeeeedcca  ",
      "  beeeeeeedccb  ",
      "  deeeeeeedaba  ",
      "  beeeeeeed     ",
      "  dbdbdbdbd     ",
      "                ",
      "                "
    ],
    [
      "                ",
      "                ",
      "  dbdbdbdbd     ",
      "  d   l  jdaba  ",
      "  b  g       b  ",
      "  d mg       a  ",
      "  b      jdg b  ",
      "  d  gk  fdg a  ",
      "  b  g   fdh b  ",
      "  dm      di a  ",
      "  b  g k  di b  ",
      "  d mg    daba  ",
      "  b       d     ",
      "  dbdbdbdbd     ",
      "                ",
      "                "
    ],
    [
      "                ",
      "                ",
      "  dbdbdbdbd     ",
      "  d      jdaba  ",
      "  b          b  ",
      "  d  o       a  ",
      "  b      jd  b  ",
      "  d      fdn a  ",
      "  b      fd  b  ",
      "  d       d  a  ",
      "  b       d  b  ",
      "  d  o    !aba  ",
      "  b       d     ",
      "  dbdbdbdbd     ",
      "                ",
      "                "
    ],
    [
      "                ",
      "                ",
      "  dbdbdbdbd     ",
      "  d       daba  ",
      "  b       q  b  ",
      "  d       q  a  ",
      "  b       d  b  ",
      "  d      fdp a  ",
      "  b      fdp b  ",
      "  d       dp a  ",
      "  b       dp b  ",
      "  d       qaba  ",
      "  b       d     ",
      "  dbdbdbdbd     ",
      "                ",
      "                "
    ],
    [
      "                ",
      "                ",
      "  dbdbdbdbd     ",
      "  d       daba  ",
      "  b       d  b  ",
      "  d       d  a  ",
      "  b       d  b  ",
      "  d      fd  a  ",
      "  b      fd  b  ",
      "  d       d  a  ",
      "  b       d  b  ",
      "  d       daba  ",
      "  b       d     ",
      "  dbdbdbdbd     ",
      "                ",
      "                "
    ],
    [
      "                ",
      "                ",
      "  dbdbdbdbd     ",
      "  drrrrrrrdaba  ",
      "  brrrrrrrd  b  ",
      "  drrrrrrrd  a  ",
      "  brrrrrrrd  b  ",
      "  drrrrrrfd  a  ",
      "  brrrrrrfd  b  ",
      "  drrrrrrrd  a  ",
      "  brrrrrrrd  b  ",
      "  drrrrrrrdaba  ",
      "  brrrrrrrd     ",
      "  dbdbdbdbd     ",
      "                ",
      "                "
    ]
  ]
}