{
  "name": "building_hotel3_base1_90",
  "refpalette": "c70cities:building_hotel3_base1_palette_90",
  "xsize": 16,
  "zsize": 16,
  "slices": [
    [
      "vvvvvvvvvvvvvvvv",
      "vaaaaaaaaaaaaaav",
      "vabbbbbbbbbbbbav",
      "vabbbbbbbbbbbbav",
      "vabbcbbbbbbcbbav",
      "vabbbbbbbbbbbbav",
      "vabbbbbbbbbbbbav",
      "vabbcdbbbbbbbbav",
      "vabbcdbbbbbbbbav",
      "vabbbbbbbbbbbbav",
      "vabbbbbbbbbbbbav",
      "vabbbbbbbbbcbbav",
      "vabbbbbbbbbbbbav",
      "vabbbbbbbbbbbbav",
      "vaaaaaaaaaaaaaav",
      "vvvvvvvvvvvvvvvv"
    ],
    [
      "vvvvvvvvvvvvvvvv",
      "vaaaaaaaaaaaaaav",
      "va     ms w  wav",
      "va njr ms u  uav",
      "va mcq ms tc tav",
      "va lop ms     av",
      "va      s w  wav",
      "vajjcd    u  uav",
      "vaiicd    u  uav",
      "vahki     t  tav",
      "vag  i       !av",
      "vaf    i  wc wav",
      "vaf    i  u  uav",
      "vae    i  t  tav",
      "vaaaaaaaaaaaaaav",
      "vvvvvvvvvvvvvvvv"
    ],
    [
      "vvvvvvvvvvvvvvvv",
      "vaaaaaaaaaaaaaav",
      "va      s     av",
      "va EIA Ls M  Mav",
      "va DcK Ls  c  av",
      "va  FJ Ls     av",
      "va      s     av",
      "va!Ccd    M  Mav",
      "vaiicd    M  Mav",
      "va  i         av",
      "vaB  i        av",
      "vaA        c  av",
      "vay       M  Mav",
      "vax           av",
      "vaaaaaaaaaaaaaav",
      "vvvvvvvvvvvvvvvv"
    ],
    [
      "vvvvvvvvvvvvvvvv",
      "vaaaaaaaaaaaaaav",
      "va      s     av",
      "va      s     av",
      "va  c   s  c  av",
      "va      s     av",
      "va      s     av",
      "va  cd        av",
      "vaiicd        av",
      "vaNOi         av",
      "va   i        av",
      "va         c  av",
      "va            av",
      "va            av",
      "vaaaaaaaaaaaaaav",
      "vvvvvvvvvvvvvvvv"
    ],
    [
      "vvvvvvvvvvvvvvvv",
      "vaaaaaaaaaaaaaav",
      "va      s     av",
      "va      s     av",
      "va  c   s  c  av",
      "va      s     av",
      "va      s     av",
      "va  cd        av",
      "vaiicd        av",
      "vaPQi         av",
      "va   i        av",
      "va         c  av",
      "va            av",
      "va            av",
      "vaaaaaaaaaaaaaav",
      "vvvvvvvvvvvvvvvv"
    ],
    [
      "vvvvvvvvvvvvvvvv",
      "vaaaaaaaaaaaaaav",
      "vaRRRRRRRRRRRRav",
      "vaRRRRRRRRRRRRav",
      "vaRRcRRRRRRcRRav",
      "vaRRRRRRRRRRRRav",
      "vaRRRRRRRRRRRRav",
      "vaRRcdRRRRRRRRav",
      "vaRRcdRRRRRRRRav",
      "vaRRRRRRRRRRRRav",
      "vaRRRRRRRRRRRRav",
      "vaRRcRRRRRRcRRav",
      "vaRRRRRRRRRRRRav",
      "vaRRRRRRRRRRRRav",
      "vaaaaaaaaaaaaaav",
      "vvvvvvvvvvvvvvvv"
    ]
  ]
}