{
  "name": "building_hotel1_floor1",
  "refpalette": "c70cities:building_hotel1_floor1_palette",
  "xsize": 16,
  "zsize": 16,
  "slices": [
    [
      "                ",
      " aaaaaaaaaaaaaa ",
      " abbbbbbbbbbbba ",
      " abbbbbbbbbbbba ",
      " abbbbbbbbbbbba ",
      " acccccccccccca ",
      " dbbbb    dbbba ",
      " dbbbb    bbbba ",
      " dbbbb    bbbba ",
      " dbbbb   ebbbbf ",
      " dbbbbbbbbbbbbf ",
      " dbbbbbbbbbbbbf ",
      " dbbbbbbbbbbbbf ",
      " abbbbbbbbbbbba ",
      " aaaaaaagggggaa ",
      "                "
    ],
    [
      "                ",
      " aaaaaaaaaaaaaa ",
      " ah        iiia ",
      " a            a ",
      " ajklmnopk  q a ",
      " aaaaaaaaaa rra ",
      " a            a ",
      " as t     u   a ",
      " a w      u  wa ",
      " as t  eed    f ",
      " a            f ",
      " a            f ",
      " a            f ",
      " aswt swt swtwa ",
      " aaaaaaaaaaaaaa ",
      "                "
    ],
    [
      "                ",
      " aaaaaaaaaaaaaa ",
      " a            a ",
      " a            a ",
      " a  x y A     a ",
      " aaaaaaaaaa   a ",
      " f            a ",
      " f B          a ",
      " f B  e      Ca ",
      " f B  ed      f ",
      " a            f ",
      " a            f ",
      " a            f ",
      " a B   B   B Ca ",
      " aaffffffaaaaaa ",
      "                "
    ],
    [
      "                ",
      " aaaaaaaaaaaaaa ",
      " a            a ",
      " a            a ",
      " a            a ",
      " aaaaaaaaaa   a ",
      " a    e       a ",
      " a    e       a ",
      " a    d      Ca ",
      " a            f ",
      " a            f ",
      " a            f ",
      " a            f ",
      " a           Ca ",
      " aaaaaaaaaaaaaa ",
      "                "
    ],
    [
      "                ",
      " aaaaaaaaaaaaaa ",
      " a            a ",
      " f            a ",
      " f            a ",
      " aaaaaaaaaaaaaa ",
      " a    dee     a ",
      " a            a ",
      " a            a ",
      " a            f ",
      " a            f ",
      " a            f ",
      " a            f ",
      " a            a ",
      " aaaaaaffaaaaaa ",
      "                "
    ],
    [
      "                ",
      " aaaaaaaaaaaaaa ",
      " aDDDDDDDDDDDDa ",
      " aDDDDDDDDDDDDa ",
      " aDDDDDDDDDDDDa ",
      " aaaaaaaaaaaaaa ",
      " aDDDD  deDDDDa ",
      " aDDDD    DDDDa ",
      " aDDDD    DDDDa ",
      " aDDDD    DDDDf ",
      " aDDDDDDDDDDDDf ",
      " aDDDDDDDDDDDDf ",
      " aDDDDDDDDDDDDf ",
      " aDDDDDDDDDDDDa ",
      " aaaaaaaaaaaaaa ",
      "                "
    ]
  ]
}