{
  "name": "building_hotel1_floor3_180",
  "refpalette": "c70cities:building_hotel1_floor3_palette_180",
  "xsize": 16,
  "zsize": 16,
  "slices": [
    [
      "                ",
      " aagggggaaaaaaa ",
      " abbbbbbbbbbbba ",
      " fbbbbcbbbbbbbd ",
      " fbbbbcbbbbbbbd ",
      " fbbbbcccccbbbd ",
      " fbbbbe   cbbbd ",
      " abbbb    cbbbd ",
      " abbbb    cbbbd ",
      " abbbd    cbbbd ",
      " acccccccccbbba ",
      " abbbbbbbbbbbba ",
      " abbbbbbbbbbbba ",
      " abbbbbbbbbbbba ",
      " aaaaaaaaaaaaaa ",
      "                "
    ],
    [
      "                ",
      " aaaaaaaaaaaaaa ",
      " aneeeaD      a ",
      " f CCeaBAf yy a ",
      " f    axwfutt a ",
      " f    aaaapaa a ",
      " f    dee a=  a ",
      " an  s    ar  a ",
      " a   s    ar  a ",
      " a        a=  a ",
      " aaqapaaaap   a ",
      " a   o == o   a ",
      " a          nma ",
      " a l  kjji  h a ",
      " aaaaaaaaaaaaaa ",
      "                "
    ],
    [
      "                ",
      " aaaaaaffffffaa ",
      " aJ   a       a ",
      " f    a  f    a ",
      " f    a  f    a ",
      " f    aaaapaa a ",
      " f      deaK  f ",
      " aJ      ea   f ",
      " a        a   f ",
      " a        aI  f ",
      " aaFapaaaap   a ",
      " a   o    o   a ",
      " a          E a ",
      " a            a ",
      " aaaaaaaaaaaaaa ",
      "                "
    ],
    [
      "                ",
      " aaaaaaaaaaaaaa ",
      " aJ   a       a ",
      " f    a  f    a ",
      " f    a  fL   a ",
      " f    aaaapaaaa ",
      "          a   a ",
      " aJ      daC  a ",
      " a       eaC  a ",
      " a       ea   a ",
      " aaaapaaaap   a ",
      " a   o    o   a ",
      " a            a ",
      " a   L    L   a ",
      " aaaaaaaaaaaaaa ",
      "                "
    ],
    [
      "                ",
      " aaaaaaffaaaaaa ",
      " a    a  f    a ",
      " f    a  f    a ",
      " f    a  fM   a ",
      " f    aaaapaaaa ",
      " f        a   a ",
      " a        a   a ",
      " a        a   a ",
      " a     eeda   a ",
      " aaaapaaaap   a ",
      " a            f ",
      " a            f ",
      " a   M    M   a ",
      " aaaaaaaaaaaaaa ",
      "                "
    ],
    [
      "                ",
      " aaaaaaaaaaaaaa ",
      " aNNNNaNNNNNNNa ",
      " fNNNNaNNNNNNNa ",
      " fNNNNaNNNNNNNa ",
      " fNNNNaaaapaaaa ",
      " fNNNN    aNNNa ",
      " aNNNN    aNNNa ",
      " aNNNN    aNNNa ",
      " aNNNNed  aNNNa ",
      " aaaapaaaapNNNa ",
      " aNNNNNNNNNNNNa ",
      " aNNNNNNNNNNNNa ",
      " aNNNNNNNNNNNNa ",
      " aaaaaaaaaaaaaa ",
      "                "
    ]
  ]
}