{
  "name": "building_bunker1_ground_90",
  "refpalette": "c70cities:building_bunker1_ground_palette_90",
  "xsize": 16,
  "zsize": 16,
  "slices": [
    [
      "zzzzzzzzzzzzzzzz",
      "zzzzaazaazzzzzzz",
      "zaaaazazzzzzzzzz",
      "zzazazzzzzzzzzzz",
      "zazazzzzzzzzzzzz",
      "zazzazzzzzzzzzzz",
      "zzazaazzzzzzzzzz",
      "zazazzzzzzzzzzzz",
      "zzazzzzzzzzzzzzz",
      "zzzzzzzzzzzzzzzz",
      "zzzzzzvvvzzzzzzz",
      "zzzzzzvcvzzzzzzz",
      "zzzzzzbvbzzzzzzz",
      "zzzzzzzzzzzzzzzz",
      "zzzzzzzzzzzzzzzz",
      "zzzzzzzzzzzzzzzz"
    ],
    [
      "          d d  d",
      "      d  deeeee ",
      "         g fffed",
      " d      d ddf e ",
      "             g d",
      "  d         d e ",
      "             fe ",
      "        ~   dff ",
      "           i fd ",
      " dd  hhhhh    d ",
      "  g   hhhhh   d ",
      " e     ff   g   ",
      "def f ff     ff ",
      " eff  g   d ffe ",
      " eeee d d  eeee ",
      "   dd           "
    ],
    [
      "                ",
      "                ",
      "             f  ",
      "                ",
      "                ",
      "                ",
      "                ",
      "        ~       ",
      "                ",
      "                ",
      "       hh       ",
      "       f        ",
      "                ",
      "   f         f  ",
      "                ",
      "                "
    ],
    [
      "                ",
      "                ",
      "                ",
      "                ",
      "                ",
      "                ",
      "                ",
      "        ~       ",
      "                ",
      "                ",
      "                ",
      "                ",
      "                ",
      "                ",
      "                ",
      "                "
    ],
    [
      "                ",
      "                ",
      "                ",
      "                ",
      "                ",
      "                ",
      "                ",
      "        ~       ",
      "                ",
      "                ",
      "                ",
      "                ",
      "                ",
      "                ",
      "                ",
      "                "
    ],
    [
      "                ",
      "                ",
      "                ",
      "                ",
      "                ",
      "                ",
      "                ",
      "        ~       ",
      "                ",
      "                ",
      "                ",
      "                ",
      "                ",
      "                ",
      "                ",
      "                "
    ]
  ]
}