{
  "name": "building_hotel2_ground_90",
  "refpalette": "c70cities:building_hotel2_ground_palette_90",
  "xsize": 16,
  "zsize": 16,
  "slices": [
    [
      "GGGGGfGfGGGGGGGG",
      "GaeGfffGGGGGGGGG",
      "GaeGGfGGGGGGGGGG",
      "GaeGffGGGGGGGGGG",
      "GaddddddddddddGG",
      "GacccccccccccdGG",
      "GacccccccccccdGG",
      "GaccccchjhjccdGG",
      "GaccccchgijccdGG",
      "GacccccgigiccdGG",
      "GacccccccccccdGG",
      "Gacccccc!ccccdGG",
      "GacccccccccccdGG",
      "Gabb=ccccccccdGG",
      "GaaaaaaaaaaaaaaG",
      "GGGGGGGGGGGGGGGG"
    ],
    [
      "                ",
      " am             ",
      " am             ",
      " am             ",
      " alopqolllllll  ",
      " ak          l  ",
      " a           l  ",
      " a==         l  ",
      " a=n         l  ",
      " a=n         l  ",
      " a==         l  ",
      " a     suuu  l  ",
      " a     rt t  l  ",
      " abb=k      kl  ",
      " aaaaaaaaaaaaaa ",
      "                "
    ],
    [
      "                ",
      " a              ",
      " a              ",
      " a              ",
      " aloxyolllllll  ",
      " aw          l  ",
      " a           l  ",
      " a           l  ",
      " a           l  ",
      " a           l  ",
      " a           l  ",
      " a      A    l  ",
      " a           l  ",
      " abb=w      wl  ",
      " aaaaaaaaaaaaaa ",
      "                "
    ],
    [
      "                ",
      " a              ",
      " a              ",
      " a              ",
      " aloooolllllll  ",
      " aw          l  ",
      " a           l  ",
      " a           l  ",
      " a           l  ",
      " a           l  ",
      " a           l  ",
      " a           l  ",
      " a           l  ",
      " abb=w      wl  ",
      " aaaaaaaaaaaaaa ",
      "                "
    ],
    [
      "                ",
      " a              ",
      " a              ",
      " a              ",
      " allllllllllll  ",
      " a           l  ",
      " a           l  ",
      " a           l  ",
      " a           l  ",
      " a           l  ",
      " a           l  ",
      " a           l  ",
      " a           l  ",
      " abb=        l  ",
      " aaaaaaaaaaaaaa ",
      "                "
    ],
    [
      "                ",
      " a              ",
      " a              ",
      " a              ",
      " aCCCCCCCCCCCC  ",
      " aBBBBBBBBBBBC  ",
      " aBBBBBBBBBBBC  ",
      " aBBBBBBBBBBBC  ",
      " aBBBBBBBBBBBC  ",
      " aBBBBBBBBBBBC  ",
      " aBBBBBBBBBBBC  ",
      " aBBBBBBBBBBBC  ",
      " aBBBBBBBBBBBC  ",
      " abb=BBBBBBBBC  ",
      " aaaaaaaaaaaaaa ",
      "                "
    ]
  ]
}