{
  "name": "building_office2_floor2",
  "refpalette": "c70cities:building_office2_floor2_palette",
  "xsize": 16,
  "zsize": 16,
  "slices": [
    [
      "                ",
      " aaaaaaaaaaaaaa ",
      "   b!cccccccb   ",
      "  decccccccced  ",
      "  decccccccced  ",
      "  decccccccced  ",
      "  decccccccced  ",
      "  decccccccced  ",
      "  decccccccced  ",
      "  decccccccced  ",
      "  decccccccced  ",
      "  decccccccced  ",
      "  decccccccced  ",
      "   bcccffcccb   ",
      " aaaaaaaaaaaaaa ",
      "                "
    ],
    [
      "                ",
      " aaaaaaaaaaaaaa ",
      "   b        b   ",
      "  d gh    hi d  ",
      "  d  h    h  d  ",
      "  d  hi  gh  d  ",
      "  d          d  ",
      "  d          d  ",
      "  d  hi  gh  d  ",
      "  d  h    h  d  ",
      "  d gh    hi d  ",
      "  d          d  ",
      "  d          d  ",
      "   bjjkffkljb   ",
      " aaaaaaaaaaaaaa ",
      "                "
    ],
    [
      "                ",
      " aaaaaaaaaaaaaa ",
      "   b        b   ",
      "  d  m    m  d  ",
      "  d          d  ",
      "  d  m    m  d  ",
      "  d          d  ",
      "  d          d  ",
      "  d  m    m  d  ",
      "  d          d  ",
      "  d  m    m  d  ",
      "  d          d  ",
      "  d          d  ",
      "   b  nffn  b   ",
      " aaaaaaaaaaaaaa ",
      "                "
    ],
    [
      "                ",
      " aaaaaaaaaaaaaa ",
      "   b        b   ",
      "  d          d  ",
      "  d          d  ",
      "  d          d  ",
      "  d          d  ",
      "  d          d  ",
      "  d          d  ",
      "  d          d  ",
      "  d          d  ",
      "  d          d  ",
      "  d          d  ",
      "   b   ff   b   ",
      " aaaaaaaaaaaaaa ",
      "                "
    ],
    [
      "                ",
      " aaaaaaaaaaaaaa ",
      "   b        b   ",
      "  d          d  ",
      "  d          d  ",
      "  d          d  ",
      "  d          d  ",
      "  d          d  ",
      "  d          d  ",
      "  d          d  ",
      "  d          d  ",
      "  d          d  ",
      "  d          d  ",
      "   b   ff   b   ",
      " aaaaaaaaaaaaaa ",
      "                "
    ],
    [
      "                ",
      " aaaaaaaaaaaaaa ",
      "   boooooooob   ",
      "  d oooooooo d  ",
      "  d oooooooo d  ",
      "  d oooooooo d  ",
      "  d oooooooo d  ",
      "  d oooooooo d  ",
      "  d oooooooo d  ",
      "  d oooooooo d  ",
      "  d oooooooo d  ",
      "  d oooooooo d  ",
      "  d oooooooo d  ",
      "   boooffooob   ",
      " aaaaaaaaaaaaaa ",
      "                "
    ]
  ]
}