{
  "name": "building_apartment1_floor2_180",
  "refpalette": "c70cities:building_apartment1_floor2_palette_180",
  "xsize": 16,
  "zsize": 16,
  "slices": [
    [
      "                ",
      "      aaaaaaaaa ",
      "  ihgdbbbbbbbba ",
      "  ef  bbbbbbbba ",
      "  ebb bbbbbbbba ",
      "  dbbcbbbbbbbba ",
      " abbbbbbbbbbbba ",
      " abbbbbbbbbbbba ",
      " abbbbbbbbbbbba ",
      " abbbbbbbbbbbba ",
      " abbbbbbbbbbbba ",
      " abbbbbbbbbbbba ",
      " abbbbbbbbbbbba ",
      " abbbbbbbbbbbba ",
      " aaaaaaaaaaaaaa ",
      "                "
    ],
    [
      "                ",
      "      ZZZZZZZZY ",
      "  ddXXq      Wm ",
      "  dV  qU Q   Tm ",
      "  dS  qR Q   Pm ",
      "  d   q     ONm ",
      " uqMqqqLLK Fqqm ",
      " u  J      J  m ",
      " uIIq      Fsrm ",
      " uqqqqqqAqEqqqm ",
      " uDC     q DC m ",
      " uB  yyAyq    m ",
      " uw  q   x ww m ",
      " uot!q srqpoonm ",
      " lkkkkkkkkkkkkj ",
      "                "
    ],
    [
      "                ",
      "      q80000086 ",
      "  ddddq      *8 ",
      "  dS& q%     ^8 ",
      "  X   q%      8 ",
      "  h   q       8 ",
      " qq$qqq# @ Fqq6 ",
      " q  9      9  8 ",
      " q  q      F  8 ",
      " qqqqqqq5q7qqq6 ",
      " q       q    q ",
      " 0   yy5yq    0 ",
      " 0   q4  3    0 ",
      " 0   q2  q   10 ",
      " qqqqqqqqqqqqqq ",
      "                "
    ],
    [
      "                ",
      "      q80000086 ",
      "  ,'ddq ;:`|\\ 0 ",
      "  d }Vq       0 ",
      "  d   q       0 ",
      "  d   q       8 ",
      " qqqqqq    Fqq6 ",
      " 0  q      F  0 ",
      " 0  q      F  0 ",
      " qqqqqqqqqqqqq6 ",
      " q       q    q ",
      " 0{  yyyyq   ]0 ",
      " 0[  q   q   -0 ",
      " 0+  q)  q   (0 ",
      " qq00qq00qq00qq ",
      "                "
    ],
    [
      "                ",
      "      q88888886 ",
      "  dXXeq       8 ",
      "  '  }q       8 ",
      "  '  .q       8 ",
      "  '   q       8 ",
      " qqqqqq    Fqq6 ",
      " 8 fq      F  8 ",
      " 8  q      F  8 ",
      " qqqqqqqqqqqqq6 ",
      " q       q    q ",
      " 8   yyyyq    8 ",
      " 8   q   q    8 ",
      " 8   q   q    8 ",
      " qqkkqqkkqqkkqq ",
      "                "
    ],
    [
      "                ",
      "      qqqqqqqqq ",
      "  ddddqdddddddq ",
      "  d   qdddddddq ",
      "  d  cqdddddddq ",
      "  d  Vqdddddddq ",
      " qqqqqqdddddddq ",
      " qddqddddddd//q ",
      " qddqddddddd//q ",
      " qqqqqqqqqqqqqq ",
      " qdddddddqddddq ",
      " qdddddddqddddq ",
      " qdddd///qddddq ",
      " qdddd///qddddq ",
      " qqqqqqqqqqqqqq ",
      "                "
    ]
  ]
}