{
  "name": "building_restaurant1_floor1_90",
  "refpalette": "c70cities:building_restaurant1_floor1_palette_90",
  "xsize": 16,
  "zsize": 16,
  "slices": [
    [
      "                ",
      "    eeee==      ",
      "    ebbb!=    f ",
      "    ebbbb=hhhhf ",
      "    ebbbb=ggggf ",
      "    =bbbb=ggggf ",
      "    =bbbbbggggf ",
      " a  =bbbbbggggf ",
      " acc=bbbbbggggf ",
      " abb=bbbbbggggf ",
      " a d=bbbbbggggf ",
      " abbbbbbbbggggf ",
      " abbbbbbb=ggggf ",
      " aaa=GGGG=fffff ",
      "    ======      ",
      "                "
    ],
    [
      "                ",
      "    ======      ",
      "    =susx=    fJ",
      "    =   y=    fN",
      "    =r  x=DDDDfJ",
      "    =qtqq=BF IfJ",
      "    =    A E EfM",
      " a  =p p  A  CfL",
      " acc=o o  C   fL",
      " aii=n  w    IfL",
      " a d=         fL",
      " a  k      E EfK",
      " a  jmmmm=BC CfJ",
      " aaa=llll=fffff ",
      "    ======      ",
      "                "
    ],
    [
      "                ",
      "    ======      ",
      "    = T  =    f ",
      "    c    =    W ",
      "    cS  V=DDDDf ",
      "    cR AA=Q   f ",
      "    c         W ",
      " a  =         W ",
      " acc=  U      W ",
      " aii=         W ",
      " a d=         W ",
      " a  P         W ",
      " a  O    =Q   f ",
      " aae=QQQQ=fffff ",
      "    ======      ",
      "                "
    ],
    [
      "                ",
      "    ===ee=      ",
      "    =    =    f ",
      "    =    =      ",
      "    =    =DDDDf ",
      "    =    =Q   f ",
      "    =           ",
      " a  =           ",
      " acc= Y         ",
      " aii=           ",
      " a d=           ",
      " a  =           ",
      " a  =    =Q   f ",
      " aae=    =fffff ",
      "    ==XX==      ",
      "                "
    ],
    [
      "                ",
      "    ======      ",
      "    =    =    f ",
      "    = Z  =      ",
      "    =    =DDDDf ",
      "    =    =    f ",
      "    =    =  Y   ",
      " a  =    =      ",
      " acc= Z  =      ",
      " aii=    =      ",
      " a d=    =      ",
      " a  =    =      ",
      " a  =    =    f ",
      " aaa=    =fffff ",
      "    ======      ",
      "                "
    ],
    [
      "                ",
      "    ======      ",
      "    =1111=    f ",
      "    =1111=    f ",
      "    =1111=DDDDf ",
      "    =1111=    f ",
      "    =1111=  Z f ",
      " a  =1111=    f ",
      " acc=1111=    f ",
      " aii=1111=    f ",
      " a d=1111=    f ",
      " a  =1111=  Z f ",
      " a 0=1111=    f ",
      " aaa=1111=fffff ",
      "    ======      ",
      "                "
    ]
  ]
}