{
  "name": "building_hotel3_ground_90",
  "refpalette": "c70cities:building_hotel3_ground_palette_90",
  "xsize": 16,
  "zsize": 16,
  "slices": [
    [
      "GGGGGGGGGGGGGGGG",
      "GaaaaaaaaaaaaaaG",
      "GabbbbbbbbbbbbaG",
      "GabbbbbbbbbbbbaG",
      "GabbcbbbbbbcbbaG",
      "GabbbbbbbbbbbbaG",
      "GabbbbbbbbbbbbaG",
      "GabbcdbbbbbbbbaG",
      "GabbcdbbbbbbbbaG",
      "GabbbbbbbbbbbbaG",
      "GabbbbbbbbbbbbaG",
      "GabbcbbbbbbcbbaG",
      "Gabbb!bbbbbbbbaG",
      "GabbbbbbbbbbbbaG",
      "GaaaaaaaaaaaaaaG",
      "GGGGGGGGGGGGGGGG"
    ],
    [
      "                ",
      " aaaaaaaajkaaaa ",
      " aeeeeeee  eeea ",
      " ae           a ",
      " aefcc     l oa ",
      " ae           a ",
      " ae        mn a ",
      " aegc      m  a ",
      " aegc      m  a ",
      " ae        mn a ",
      " ae           a ",
      " aefcchiih l oa ",
      " ae   hhhh    a ",
      " aeeeeeeeeeeeea ",
      " aaaaaaaaaaaaaa ",
      "                "
    ],
    [
      "                ",
      "  p aaaaaqraaaa ",
      "  eeeeeee  eeea ",
      " pe           a ",
      "  efcc     l fa ",
      " pe           a ",
      "  e           a ",
      " pegc      s  a ",
      "  egc         a ",
      " pe           a ",
      "  e           a ",
      " pefcc     l fa ",
      "  e           a ",
      " peeeeeeeeeeeea ",
      "   paaaaaaaaaaa ",
      "                "
    ],
    [
      "                ",
      "  p p paaaaaaaa ",
      "  eeeeeeeeeeeea ",
      " pe           a ",
      "  efcc     l fa ",
      " pe           a ",
      "  e           a ",
      " pegc         a ",
      "  egc         a ",
      " pe           a ",
      "  e           a ",
      " pefcc     l fa ",
      "  e           a ",
      " peeeeeeeeeeeea ",
      "   p p aaaaaaaa ",
      "                "
    ],
    [
      "                ",
      "  p p p p aaaaa ",
      "  eeeeeeeeeeeea ",
      " pe           a ",
      "  e cc     l  a ",
      " pe t         a ",
      "  e t         a ",
      " pegc         a ",
      "  egc         a ",
      " pe t         a ",
      "  e t         a ",
      " pe cc     l  a ",
      "  e           a ",
      " peeeeeeeeeeeea ",
      "   p p p paaaaa ",
      "                "
    ],
    [
      "                ",
      "  p p p p p paa ",
      "  eeeeeeeeeeeea ",
      " pe          ea ",
      "  e cccccccl ea ",
      " pe cuuuuuuc ea ",
      "  e cuuuuuuc ea ",
      " pegcuuuuuuc ea ",
      "  egcuuuuuuc ea ",
      " pe cuuuuuuc ea ",
      "  e cuuuuuuc ea ",
      " pe cccccccl ea ",
      "  e          ea ",
      " peeeeeeeeeeeea ",
      "   p p p p p aa ",
      "                "
    ]
  ]
}