{
  "name": "building_gasstation1_ground_90",
  "refpalette": "c70cities:building_gasstation1_ground_palette_90",
  "xsize": 16,
  "zsize": 16,
  "slices": [
    [
      "GGGGGGGGGGGGGGGG",
      "GGGGGGGGGGGGGGGG",
      "GGGaaaaaaaaaaGGG",
      "GGGaaaaaaaaaaGGG",
      "GGGaaaaaaaaaaGGG",
      "GbbaaaaaaaaaabbG",
      "GHHaaaaaaaaaaHHG",
      "GHHaaaaaaaaaaHHG",
      "GHHaaaaaaaaaaHHG",
      "GHHHHHHHHHHHHHHG",
      "GHHHHHHHHHHHHHHG",
      "GHHaaaaaaaaaaHHG",
      "GHHHHHHHHHHHHHHG",
      "GHHHHHHHHHHHHHHG",
      "GHHHHHHHHHHHHHHG",
      "GaHHHHHHHHHHHHHG"
    ],
    [
      "                ",
      "                ",
      "   jjjjjjjjjj   ",
      "   jpro  B Ij   ",
      "   j!ro  jDFj   ",
      " ffjo o  jjjjff ",
      " ehjn       jeh ",
      "   jn    A Ej   ",
      " dgjjquxqjCCjdg ",
      "                ",
      "                ",
      "   im iwyim i   ",
      "    l tl tl t   ",
      "    k sk sk s   ",
      "                ",
      " c              "
    ],
    [
      "                ",
      "                ",
      "   jjjjjjjjjj   ",
      "   jo o  O  j   ",
      "   jK r  j  j   ",
      "   jp o  jjjj   ",
      "   j        j   ",
      "   j     N  j   ",
      "   jjqLMqjPPj   ",
      "                ",
      "                ",
      "   iJ i  iJ i   ",
      "                ",
      "                ",
      "                ",
      " c              "
    ],
    [
      "                ",
      "                ",
      "   RUURUURUUR   ",
      "   R     j  R   ",
      "   Rr    j  R   ",
      "   R     jjjR   ",
      "   RT       R   ",
      "   RS       R   ",
      "   RRRRRRRRRR   ",
      "                ",
      "                ",
      "   i  i  i  i   ",
      "                ",
      "                ",
      "                ",
      " Q              "
    ],
    [
      "                ",
      "                ",
      "   jjjjjjjjjj   ",
      "   jr    jYYj   ",
      "   j     jYYj   ",
      "   jjjjjjjjjj   ",
      "   jW X  V  j   ",
      "   jr       j   ",
      "   jjjjjjjjjj   ",
      "                ",
      "   V  V  X  V   ",
      "   j  j  j  j   ",
      "                ",
      "                ",
      "                ",
      "                "
    ],
    [
      "                ",
      "  ZZZZZZZZZZZZ  ",
      "  ZaaaaaaaaaaZ  ",
      "  ZaffffffffaZ  ",
      "  ZaffffffffaZ  ",
      "  ZaaaaaaaaaaZ  ",
      "  ZaffffffffaZ  ",
      "  ZaffffffffaZ  ",
      "  ZaaaaaaaaaaZ  ",
      "  ZaffffffffaZ  ",
      "  ZaffffffffaZ  ",
      "  ZaaaaaaaaaaZ  ",
      "  ZffffffffffZ  ",
      "  ZffffffffffZ  ",
      "  ZZZZZZZZZZZZ  ",
      "                "
    ]
  ]
}