{
  "name": "building_office3_floor3",
  "refpalette": "c70cities:building_office3_floor3_palette",
  "xsize": 16,
  "zsize": 16,
  "slices": [
    [
      "                ",
      " aabaabaabaabaa ",
      " acccccccccccca ",
      " bccccccccccccb ",
      " accc!cccccccca ",
      " acccccccccccca ",
      " bccccccccccccb ",
      " acccccvdccccca ",
      " acccccvdccccca ",
      " bccccccccccccb ",
      " acccccccccccca ",
      " acccccccccccca ",
      " bccccccccccccb ",
      " acccccccccccca ",
      " aabaabaabaabaa ",
      "                "
    ],
    [
      "                ",
      " eebeebeebeebee ",
      " e            e ",
      " b f gggg   f b ",
      " e   ghhg     e ",
      " e         i  e ",
      " b         ij b ",
      " e     vd  i  e ",
      " e     vd  i  e ",
      " b         ij b ",
      " e         k  e ",
      " e   ghhg     e ",
      " b f gggg   f b ",
      " e            e ",
      " eebeebeebeebee ",
      "                "
    ],
    [
      "                ",
      " llbllbllbllbll ",
      " l            l ",
      " b f        f b ",
      " l            l ",
      " l            l ",
      " b            b ",
      " l     vd     l ",
      " l     vd     l ",
      " b            b ",
      " l            l ",
      " l            l ",
      " b f        f b ",
      " l            l ",
      " llbllbllbllbll ",
      "                "
    ],
    [
      "                ",
      " llbllbllbllbll ",
      " l            l ",
      " b f        f b ",
      " l            l ",
      " l            l ",
      " b            b ",
      " l     vd     l ",
      " l     vd     l ",
      " b            b ",
      " l            l ",
      " l            l ",
      " b f        f b ",
      " l            l ",
      " llbllbllbllbll ",
      "                "
    ],
    [
      "                ",
      " llbllbllbllbll ",
      " l            l ",
      " b f        f b ",
      " l            l ",
      " l            l ",
      " b            b ",
      " l     vd     l ",
      " l     vd     l ",
      " b            b ",
      " l            l ",
      " l            l ",
      " b f        f b ",
      " l            l ",
      " llbllbllbllbll ",
      "                "
    ],
    [
      "                ",
      " llbllbllbllbll ",
      " lmmmmmmmmmmmml ",
      " bmfnnnnnnnnfmb ",
      " lmnnnnnnnnnnml ",
      " lmnnnnnnnnnnml ",
      " bmnnnnnnnnnnmb ",
      " lmnnnnvdnnnnml ",
      " lmnnnnvdnnnnml ",
      " bmnnnnnnnnnnmb ",
      " lmnnnnnnnnnnml ",
      " lmnnnnnnnnnnml ",
      " bmfnnnnnnnnfmb ",
      " lmmmmmmmmmmmml ",
      " llbllbllbllbll ",
      "                "
    ]
  ]
}