{
  "name": "building_factory1_ground_90",
  "refpalette": "c70cities:building_factory1_ground_palette_90",
  "xsize": 16,
  "zsize": 16,
  "slices": [
    [
      "zzzzzzzzzzzzzzzz",
      "zzzzzzzzzzzzzzzz",
      "zzbbbbbbbbbbbbzz",
      "zzbbbbbbbbbbbbzz",
      "zzbbbbbbcbcbbbzz",
      "zzbbbbbbbbbbbbzz",
      "zzbbbbbbbbbbbbzz",
      "zzbbbbbbbbbbbbzz",
      "zzbbbbbbbbbbbbzz",
      "zzbbbbbbbbbbbbzz",
      "zzbbbbbbbbbbbbzz",
      "zzbbbbbbbbbbbbzz",
      "zzbbbbbbbbbbbbzz",
      "zazaaaaaaaaaazza",
      "aaaaaaazaaaaaaaa",
      "aaaazaaaaazzaaaa"
    ],
    [
      "d  d      d     ",
      " d    d    d d e",
      "d hhhhhhhhhhhh  ",
      " ghi o  xxxxih  ",
      "d hm oqswwCFMhNd",
      "  hl p ruuuEMhdd",
      "f hkko  rA DLh N",
      "  hi      Axihdd",
      "e h!n      xKhd ",
      " dhjn     BxJhdd",
      "  hjn   ty xIh d",
      "d hi       xihdO",
      "  hh        hhd ",
      "                ",
      "                ",
      "                "
    ],
    [
      "                ",
      "                ",
      "  hhhhhhhhhhhh  ",
      " ghi o  xxxxih  ",
      "  hP oST   WMh  ",
      "  h  R      Mh  ",
      "  hkko     V h  ",
      "  hi       Uih  ",
      "  h          h  ",
      "  hn        Xh  ",
      "  hn         h  ",
      "  hi        ih  ",
      "  hhQQQQQQQQhh  ",
      "                ",
      "                ",
      "                "
    ],
    [
      "                ",
      "                ",
      "  hhhhhhhhhhhh  ",
      " Yhi o  xxx ih  ",
      "  h  o  00  Mh  ",
      "  h  o     1Mh  ",
      "  hkko       h  ",
      "  hi        ih  ",
      "  h Z       4h  ",
      "  h         3h  ",
      "  h         2h  ",
      "  hi        ih  ",
      "  hhQQQQQQQQhh  ",
      "                ",
      "                ",
      "                "
    ],
    [
      "                ",
      "                ",
      "  hhhhhhhhhhhh  ",
      "  hi o      ih  ",
      "  78 o      87  ",
      "  68 o      86  ",
      "  58ko      85  ",
      "  hi%^      ih  ",
      "  78$       87  ",
      "  68$   &   86  ",
      "  58#       85  ",
      "  hi@@@@    ih  ",
      "  hhhhhhhhhhhh  ",
      "    99999999    ",
      "                ",
      "                "
    ],
    [
      "                ",
      "                ",
      "  *hhhhhhhhhh*  ",
      "  *()8    8-(*  ",
      "  *( 8    8 (*  ",
      "  *( 8  + 8 (*  ",
      "  *( 8    8 (*  ",
      "  *()8    8-(*  ",
      "  *( 8    8 (*  ",
      "  *( 8  + 8 (*  ",
      "  *( 8    8 (*  ",
      "  *()8    8-(*  ",
      "  *hhhhhhhhhh*  ",
      "                ",
      "                ",
      "                "
    ]
  ]
}