{
  "name": "building_bank1_base1_180",
  "refpalette": "c70cities:building_bank1_base1_palette_180",
  "xsize": 16,
  "zsize": 16,
  "slices": [
    [
      "vvvvvvvvvvvvvvvv",
      "vaabbaaaabbaaaav",
      "vabb!bbbbbbbbbav",
      "vabbbbbbbbbbbbbv",
      "vabbbbbbbbbbbbbv",
      "vbbbbbbbbbbbbbav",
      "vbbbbbbbbbbbbbav",
      "vabbbbbbbbbbbbav",
      "vabbbbbbbbbbbbav",
      "vabbbbbbbbbbbbbv",
      "vabbbbbbbbbbbbbv",
      "vbbbbbbbbbbbbbav",
      "vbbbbbbbbbbbbbav",
      "vabbbbbbbbbb!bav",
      "vaaaabbaaaabbaav",
      "vvvvvvvvvvvvvvvv"
    ],
    [
      "vvvvvvvvvvvvvvvv",
      "vaabbaaaabbaaaav",
      "vaiccffffcc   av",
      "vai         jcbv",
      "vad          cbv",
      "vbc          fav",
      "vbc      f   iav",
      "vaf          dav",
      "vaf          hav",
      "vaf    f     cbv",
      "vaf          cbv",
      "vbc           av",
      "vbc       f  fav",
      "vag eccffedcc av",
      "vaaaabbaaaabbaav",
      "vvvvvvvvvvvvvvvv"
    ],
    [
      "vvvvvvvvvvvvvvvv",
      "vaabbaaaabbaaaav",
      "vaicc nincc   av",
      "vae         jcbv",
      "vad          cbv",
      "vbc          eav",
      "vbc           av",
      "va           dav",
      "vah          mav",
      "val          cbv",
      "vah          cbv",
      "vbc           av",
      "vbc           av",
      "va   cc k ecc av",
      "vaaaabbaaaabbaav",
      "vvvvvvvvvvvvvvvv"
    ],
    [
      "vvvvvvvvvvvvvvvv",
      "vaabbaaaabbaaaav",
      "va cc    cc   av",
      "va          jcbv",
      "va           cbv",
      "vbc           av",
      "vbc           av",
      "va            av",
      "va            av",
      "va           cbv",
      "va           cbv",
      "vbc           av",
      "vbc           av",
      "va   cc    cc av",
      "vaaaabbaaaabbaav",
      "vvvvvvvvvvvvvvvv"
    ],
    [
      "vvvvvvvvvvvvvvvv",
      "vaabbaaaabbaaaav",
      "va cc    cc   av",
      "va          jcbv",
      "va           cbv",
      "vbc           av",
      "vbc           av",
      "va            av",
      "va            av",
      "va           cbv",
      "va           cbv",
      "vbc           av",
      "vbc           av",
      "va   cc    cc av",
      "vaaaabbaaaabbaav",
      "vvvvvvvvvvvvvvvv"
    ],
    [
      "vvvvvvvvvvvvvvvv",
      "vaabbaaaabbaaaav",
      "vagccooooccooqav",
      "vaoooooooooojcbv",
      "vaooooooooooocbv",
      "vbcoooooooooooav",
      "vbcoooooooooooav",
      "vaooooooooooooav",
      "vaooooooooooooav",
      "vaooooooooooocbv",
      "vaooooooooooocbv",
      "vbcoooooooooooav",
      "vbcoooooooooooav",
      "vapooccooooccgav",
      "vaaaabbaaaabbaav",
      "vvvvvvvvvvvvvvvv"
    ]
  ]
}