{
  "name": "building_apartment1_floor1",
  "refpalette": "c70cities:building_apartment1_floor1_palette",
  "xsize": 16,
  "zsize": 16,
  "slices": [
    [
      "                ",
      " aaaaaaaaaaaaaa ",
      " abbbbbbbbbbbba ",
      " abbbbbbbbbbbba ",
      " abbbbbbbbbbbba ",
      " abbbbbbbbbbbba ",
      " abbbbbbbbbbbba ",
      " abbbbbbbbbbbba ",
      " abbbbbbbbbbbba ",
      " abbbbbbbbbbbba ",
      " abbbbbbbbcbbd  ",
      " abbbbbbbb bbe  ",
      " abbbbbbbb  fe  ",
      " abbbbbbbbdghi  ",
      " aaaaaaaaa      ",
      "                "
    ],
    [
      "                ",
      " jkkkkkkkkkkkkl ",
      " mnoo pq  po rs ",
      " m tt u  wpt  s ",
      " m    pxyxxA Bs ",
      " m CD p     CDs ",
      " mpppEpypppppps ",
      " mFqI      pJJs ",
      " m  K      K  s ",
      " mppI LMMpppNps ",
      " mOP     p   d  ",
      " mQ   R Sp  Td  ",
      " mU   R Vp  Wd  ",
      " mX     !pYYdd  ",
      " Z00000000      ",
      "                "
    ],
    [
      "                ",
      " pppppppppppppp ",
      " 12   p  3po  1 ",
      " 1    4   pt  1 ",
      " 1    px5xx6  1 ",
      " p    p      7p ",
      " 8ppp9p5ppppppp ",
      " @  I      p  p ",
      " @  #      #  p ",
      " 8ppI    ppp$pp ",
      " @ %     p   h  ",
      " @      ^p   Y  ",
      " @&     ^p *Td  ",
      " @(      pdddd  ",
      " 8@11111@p      ",
      "                "
    ],
    [
      "                ",
      " pp11pp11pp11pp ",
      " 1)   p  +p  -1 ",
      " 1[   p   p  ]1 ",
      " 1{   pxxxx  }1 ",
      " p    p       p ",
      " 8ppppppppppppp ",
      " 1  I      p  1 ",
      " 1  I      p  1 ",
      " 8ppI    pppppp ",
      " @       p   d  ",
      " 1      \\p   d  ",
      " 1      \\pW| d  ",
      " 1 ``:;; pdd',  ",
      " 8@11111@p      ",
      "                "
    ],
    [
      "                ",
      " ppkkppkkppkkpp ",
      " @    p   p   @ ",
      " @    p   p   @ ",
      " @    pxxxx   @ ",
      " p    p       p ",
      " 8ppppppppppppp ",
      " @  I      p  @ ",
      " @  I      pf @ ",
      " 8ppI    pppppp ",
      " @       p   '  ",
      " @       p.  '  ",
      " @       p|  '  ",
      " @       peYYd  ",
      " 8@@@@@@@p      ",
      "                "
    ],
    [
      "                ",
      " pppppppppppppp ",
      " pddddp///ddddp ",
      " pddddp///ddddp ",
      " pddddpdddddddp ",
      " pddddpdddddddp ",
      " pppppppppppppp ",
      " p//dddddddpddp ",
      " p//dddddddpddp ",
      " pdddddddpppppp ",
      " pdddddddpW  d  ",
      " pdddddddpc  d  ",
      " pdddddddp   d  ",
      " pdddddddpdddd  ",
      " ppppppppp      ",
      "                "
    ]
  ]
}