{
  "name": "building_bank1_top",
  "refpalette": "c70cities:building_bank1_top_palette",
  "xsize": 16,
  "zsize": 16,
  "slices": [
    [
      "                ",
      "  abbbc abbbc   ",
      "  deeeedeeeeeda ",
      " ceeeeeeeeeeeeb ",
      " beeeeeeeeeeeeb ",
      " be eeeeeeeeeeb ",
      " be eeeeeeeeeec ",
      " ae eeeeeeeeed  ",
      "  d eeeeeeeeeea ",
      " ce eeeeeeeeeeb ",
      " beeeeeeeeeeeeb ",
      " beeeeeeeeeeeeb ",
      " beeeeeeeeeeeec ",
      " adeeeeedeeeed  ",
      "   cbbba cbbba  ",
      "                "
    ],
    [
      "                ",
      " fbcc abbcc abf ",
      " bgggghggggghgb ",
      " ah         igc ",
      "  g          gc ",
      " cg     jkl  g  ",
      " cg   m n    ha ",
      " bg     o p  gb ",
      " bg   m n    gb ",
      " ah     qrss gc ",
      "  g          gc ",
      " cgttttttttttg  ",
      " cguwwwuuwwwxha ",
      " bghggggghggggb ",
      " fba ccbba ccbf ",
      "                "
    ],
    [
      "                ",
      " fbbbbbbbbbbbbf ",
      " bgggghggggghgb ",
      " bh          gb ",
      " bg          gb ",
      " bg     y    gb ",
      " bg          hb ",
      " bg          gb ",
      " bg          gb ",
      " bh     A ss gb ",
      " bg          gb ",
      " bg          gb ",
      " bgwwwwwwwwwwhb ",
      " bghggggghggggb ",
      " fbbbbbbbbbbbbf ",
      "                "
    ],
    [
      "                ",
      "                ",
      "   gghggggghg   ",
      "  gg        gg  ",
      "  h          g  ",
      "  g          h  ",
      "  g          g  ",
      "  g          g  ",
      "  g          g  ",
      "  g          g  ",
      "  h          g  ",
      "  g          h  ",
      "  gg        gg  ",
      "   ghggggghgg   ",
      "                ",
      "                "
    ],
    [
      "                ",
      "                ",
      "                ",
      "    gggggggg    ",
      "   gggggggggg   ",
      "   ggg    ggg   ",
      "   gg     Bgg   ",
      "   gg      gg   ",
      "   gg      gg   ",
      "   ggB     gg   ",
      "   ggg    ggg   ",
      "   gggggggggg   ",
      "    gggggggg    ",
      "                ",
      "                ",
      "                "
    ],
    [
      "                ",
      "                ",
      "                ",
      "                ",
      "                ",
      "      gggg      ",
      "     gggggg     ",
      "     gggggg     ",
      "     gggggg     ",
      "     gggggg     ",
      "      gggg      ",
      "                ",
      "                ",
      "                ",
      "                ",
      "                "
    ]
  ]
}