{
  "name": "building_hotel2_floor2_270",
  "refpalette": "c70cities:building_hotel2_floor2_palette_270",
  "xsize": 16,
  "zsize": 16,
  "slices": [
    [
      "                ",
      " aaaaaaaaaaaaaa ",
      "  dccc!c!cc=bba ",
      "  dccccccccccca ",
      "  dccccccccccca ",
      "  dccccccccccca ",
      "  dccccccccccca ",
      "  dcccc!cccccca ",
      "  dccccccccccca ",
      "  dccccccccccca ",
      "  dccccccccccca ",
      "  dddddddddddda ",
      "              a ",
      "              a ",
      "              a ",
      "                "
    ],
    [
      "                ",
      " aaaaaaaaaaaaaa ",
      "  fx  =apmk=bba ",
      "  fy  sa nla  a ",
      "  fA  saqaaa  a ",
      "  f        g  a ",
      "  f   aaaaaaaea ",
      "  f wtap ohh  a ",
      "  f wta   ii  a ",
      "  f  uar      a ",
      "  f   ar  jj  a ",
      "  ffffffffffffa ",
      "              a ",
      "              a ",
      "              a ",
      "                "
    ],
    [
      "                ",
      " aaaaaaaaaaaaaa ",
      "  f   Fa   =bba ",
      "  fI   a   a  a ",
      "  f    aDaaa  a ",
      "  f        C  a ",
      "  f   aaaaaaaBa ",
      "  f   a       a ",
      "  f   a       a ",
      "  f   aE      a ",
      "  f   a       a ",
      "  ffffffffffffa ",
      "              a ",
      "              a ",
      "              a ",
      "                "
    ],
    [
      "                ",
      " aaaaaaaaaaaaaa ",
      "  f   Ja   =bba ",
      "  f   Ka   a  a ",
      "  f   Kaaaaa  a ",
      "  f        a  a ",
      "  f   aaaaaaaaa ",
      "  f   a       a ",
      "  f   a       a ",
      "  f   a       a ",
      "  f   a       a ",
      "  ffffffffffffa ",
      "              a ",
      "              a ",
      "              a ",
      "                "
    ],
    [
      "                ",
      " aaaaaaaaaaaaaa ",
      "  f    a   =bba ",
      "  f    a   a  a ",
      "  f    aaaaaLLa ",
      "  f        a  a ",
      "  f   aaaaaaaaa ",
      "  f   a       a ",
      "  f   a       a ",
      "  f   a       a ",
      "  f   a       a ",
      "  ffffffffffffa ",
      "              a ",
      "              a ",
      "              a ",
      "                "
    ],
    [
      "                ",
      " aaaaaaaaaaaaaa ",
      "  IMMMMaMMM=bba ",
      "  IMMMMaMMMaMMa ",
      "  IMMMMaaaaaMMa ",
      "  IMMMMMMMMaMMa ",
      "  IMMMaaaaaaaaa ",
      "  IMMMaMMMMMMMa ",
      "  IMMMaMMMMMMMa ",
      "  IMMMaMMMMMMMa ",
      "  IMMMMMMMMMMMa ",
      "  IIIIIIIIIIIIa ",
      "              a ",
      "              a ",
      "              a ",
      "                "
    ]
  ]
}