{
  "name": "building_residential3_ground_270",
  "refpalette": "c70cities:building_residential3_ground_palette_270",
  "xsize": 16,
  "zsize": 16,
  "slices": [
    [
      "GGGGGGGGGGGGGGGG",
      "GGGGGGGGGGGGGGGG",
      "GGGGGGGGaaaaaaGG",
      "GGGcccccabbbbaGG",
      "GGGcddddbbbbbaGG",
      "GGGcddddbbbbbaGG",
      "GGGcddddbbbbbaGG",
      "GGGcddddbbbbbaGG",
      "GGaabbbbbbbbbaGG",
      "GGabbbbbbbbbbaGG",
      "GGabbbbbbbbbbaGG",
      "GGabbbbbbbbbbaGG",
      "GGabbbbbbbbbbaGG",
      "GGaaaaaaaaaaaaGG",
      "GGGGGGGGGGGGGGGG",
      "GGGGGGGGGGGGGGGG"
    ],
    [
      "effffgfffe  effe",
      "f              f",
      "f yyyyy hiomih f",
      "f yccccch    h f",
      "f ycC  xsr   h f",
      "g ycD   sr   h g",
      "f ycE   t   jh f",
      "f ycF        h f",
      "f hhhhhuu    h f",
      "f i AA      !h f",
      "g J       pkkh g",
      "f J       q  h f",
      "f i IB ww pnlh f",
      "f hhhhhhhhhhhh f",
      "f              f",
      "effffeffffgffffe"
    ],
    [
      "effffgfffe  effe",
      "f              f",
      "f       hiNLih f",
      "f  ccRRch    h f",
      "f  cT        J f",
      "g  R         J g",
      "f  R         J f",
      "f  cU       jh f",
      "f hhhhhuu    h f",
      "f i SS     M J f",
      "g J       pkkh g",
      "f J       O  K f",
      "f i    QP p  h f",
      "f hhJJJhhJhKhh f",
      "f              f",
      "effffeffffgffffe"
    ],
    [
      "            W   ",
      "                ",
      "  ZZZZZZhiXXih  ",
      "  Zccccch    h  ",
      "  Zc         V  ",
      "  Zc         V  ",
      "  Zc         V  ",
      "  Zc         h  ",
      "  hhhhhuu   jh  ",
      "  i          V  ",
      "  0       pkkh  ",
      "  0       p  V  ",
      "  i       p  h  ",
      "  hhYYYhhYhYhh  ",
      "                ",
      "     W          "
    ],
    [
      "                ",
      "                ",
      "  111111hhhhhh  ",
      "  132222hbbbbh  ",
      "  14    bbbbbh  ",
      "  14    bbbbbh  ",
      "  14    bbbb h  ",
      "  14    bbbb h  ",
      "  hhbbbbbbbb h  ",
      "  hbbbbbbbbbjh  ",
      "  hbbbbbbbbbbh  ",
      "  hbbbbbbbbbbh  ",
      "  hbbbbbbbbbbh  ",
      "  hhhhhhhhhhhh  ",
      "                ",
      "                "
    ],
    [
      "                ",
      "                ",
      "  111111hJJJJh  ",
      "  1ccccch9  5h  ",
      "  1c    $9  5V  ",
      "  1c    $@  6V  ",
      "  1c    $  8 V  ",
      "  1c   *$  8 h  ",
      "  hh$$$$$  8 h  ",
      "  J        8 V  ",
      "  J((((i%    V  ",
      "  J())(i^#   V  ",
      "  J ++@i&   7h  ",
      "  hhYYYhhJJJJh  ",
      "                ",
      "                "
    ]
  ]
}