{
  "name": "building_office5_ground_180",
  "refpalette": "c70cities:building_office5_ground_palette_180",
  "xsize": 16,
  "zsize": 16,
  "slices": [
    [
      "GGGGGGGGGGGGGGGG",
      "GaaaaaaaaaaaaaaG",
      "GaaaaaaaaaaaaaaG",
      "GaaaaaaaaaaaaaaG",
      "GaaaaaaaaaaaaaaG",
      "GaaaaaaaaaaaaaaG",
      "GaaaaaaaaaaaaaaG",
      "GaaaaaaaaaaaaaaG",
      "GaaaaaaaaaaaaaaG",
      "Gaaaaa!aaaaaaaaG",
      "GaaaaaaaaaaaaaaG",
      "GaaaaaaGGaaaaaaG",
      "GaaaaaaGGaaaaaaG",
      "GaaaaaaaaaaaaaaG",
      "GaaaaaaaaaaaaaaG",
      "GGGGGGGGGGGGGGGG"
    ],
    [
      "                ",
      " bc  cc  cc  cb ",
      " cdeeddeeddeedc ",
      "  ex  y  y  xe  ",
      "  e  w    u  e  ",
      " cd  tssssr  dc ",
      " cd   q  q   dc ",
      "  p          e  ",
      "  o          e  ",
      " cd mm nn mm dc ",
      " cb llbccbll bc ",
      "  e   hikh   e  ",
      "  e fghjihgf e  ",
      " cdeeddeeddeedc ",
      " bc  cc  cc  cb ",
      "                "
    ],
    [
      "                ",
      " bc  cc  cc  cb ",
      " cdeeddeeddeedc ",
      "  em        me  ",
      "  e          e  ",
      " cd   D  D   dc ",
      " cd          dc ",
      "  C          e  ",
      "  B          e  ",
      " cd    nn    dc ",
      " cb   bccb   bc ",
      "  e     A    e  ",
      "  e          e  ",
      " cdeeddeeddeedc ",
      " bc  cc  cc  cb ",
      "                "
    ],
    [
      "                ",
      " bc  cc  cc  cb ",
      " cdeeddeeddeedc ",
      "  em        me  ",
      "  e          e  ",
      " cd          dc ",
      " cd          dc ",
      "  e    E     e  ",
      "  e          e  ",
      " cd    nn    dc ",
      " cb   bccb   bc ",
      "  e          e  ",
      "  e          e  ",
      " cdeeddeeddeedc ",
      " bc  cc  cc  cb ",
      "                "
    ],
    [
      "                ",
      " bcFFccFFccFFcb ",
      " cddddddddddddc ",
      " Fd          dF ",
      " Fd          dF ",
      " cd          dc ",
      " cd          dc ",
      " Fd    EI    dF ",
      " Fd    IE    dF ",
      " cd    nn    dc ",
      " cccccccccccccc ",
      " Fd          dF ",
      " Fd          dF ",
      " cddddddddddddc ",
      " bcFFccFFccFFcb ",
      "                "
    ],
    [
      "                ",
      " bccccccccccccb ",
      " cccccccccccccc ",
      " ccJJJJJJJJJJcc ",
      " ccJJJJJJJJJJcc ",
      " ccJJJJJJJJJJcc ",
      " ccJJJK  KJJJcc ",
      " ccJJJ LL JJJcc ",
      " ccJJJ LL JJJcc ",
      " ccJJJKnnKJJJcc ",
      " cccccccccccccc ",
      " cccccccccccccc ",
      " cccccccccccccc ",
      " cccccccccccccc ",
      " bccccccccccccb ",
      "                "
    ]
  ]
}