{
  "name": "building_hotel1_floor3",
  "refpalette": "c70cities:building_hotel1_floor3_palette",
  "xsize": 16,
  "zsize": 16,
  "slices": [
    [
      "                ",
      " aaaaaaaaaaaaaa ",
      " abbbbbbbbbbbba ",
      " abbbbbbbbbbbba ",
      " abbbbbbbbbbbba ",
      " abbbccccccccca ",
      " dbbbc    dbbba ",
      " dbbbc    bbbba ",
      " dbbbc    bbbba ",
      " dbbbc   ebbbbf ",
      " dbbbcccccbbbbf ",
      " dbbbbbbbcbbbbf ",
      " dbbbbbbbcbbbbf ",
      " abbbbbbbbbbbba ",
      " aaaaaaagggggaa ",
      "                "
    ],
    [
      "                ",
      " aaaaaaaaaaaaaa ",
      " a h  ijjk  l a ",
      " amn          a ",
      " a   o == o   a ",
      " a   paaaapaqaa ",
      " a  =a        a ",
      " a  ra    s   a ",
      " a  ra    s  na ",
      " a  =a eed    f ",
      " a aapaaaa    f ",
      " a ttufwxa    f ",
      " a yy fABaeCC f ",
      " a      Daeeena ",
      " aaaaaaaaaaaaaa ",
      "                "
    ],
    [
      "                ",
      " aaaaaaaaaaaaaa ",
      " a            a ",
      " a E          a ",
      " a   o    o   a ",
      " a   paaaapaFaa ",
      " f  Ia        a ",
      " f   a        a ",
      " f   ae      Ja ",
      " f  Kaed      f ",
      " a aapaaaa    f ",
      " a    f  a    f ",
      " a    f  a    f ",
      " a       a   Ja ",
      " aaffffffaaaaaa ",
      "                "
    ],
    [
      "                ",
      " aaaaaaaaaaaaaa ",
      " a   L    L   a ",
      " a            a ",
      " a   o    o   a ",
      " a   paaaapaaaa ",
      " a   ae       a ",
      " a  Cae       a ",
      " a  Cad      Ja ",
      " a   a          ",
      " aaaapaaaa    f ",
      " a   Lf  a    f ",
      " a    f  a    f ",
      " a       a   Ja ",
      " aaaaaaaaaaaaaa ",
      "                "
    ],
    [
      "                ",
      " aaaaaaaaaaaaaa ",
      " a   M    M   a ",
      " f            a ",
      " f            a ",
      " a   paaaapaaaa ",
      " a   adee     a ",
      " a   a        a ",
      " a   a        a ",
      " a   a        f ",
      " aaaapaaaa    f ",
      " a   Mf  a    f ",
      " a    f  a    f ",
      " a    f  a    a ",
      " aaaaaaffaaaaaa ",
      "                "
    ],
    [
      "                ",
      " aaaaaaaaaaaaaa ",
      " aNNNNNNNNNNNNa ",
      " aNNNNNNNNNNNNa ",
      " aNNNNNNNNNNNNa ",
      " aNNNpaaaapaaaa ",
      " aNNNa  deNNNNa ",
      " aNNNa    NNNNa ",
      " aNNNa    NNNNa ",
      " aNNNa    NNNNf ",
      " aaaapaaaaNNNNf ",
      " aNNNNNNNaNNNNf ",
      " aNNNNNNNaNNNNf ",
      " aNNNNNNNaNNNNa ",
      " aaaaaaaaaaaaaa ",
      "                "
    ]
  ]
}