{
  "name": "building_residential2_floor1",
  "refpalette": "c70cities:building_residential2_floor1_palette",
  "xsize": 16,
  "zsize": 16,
  "slices": [
    [
      "                ",
      "    abc  abc    ",
      "  dddddddddddd  ",
      "  defff      d  ",
      " gdhiff  jk ldm ",
      " ndhiff  jkopdq ",
      " rdsfff  jk tdu ",
      "  d      jk wd  ",
      "  dxxyAxxxxxxd  ",
      "                ",
      "                ",
      "            B   ",
      "   CC  CC  CC   ",
      "                ",
      "                ",
      "                "
    ],
    [
      "                ",
      "                ",
      "  dDEEEEEEEEDd  ",
      "  DF         D  ",
      "  E          E  ",
      "  E         IE  ",
      "  E          E  ",
      "  D          D  ",
      "  dxxJKxxxxxxd  ",
      "                ",
      "                ",
      "                ",
      "   CC  CC  CC   ",
      "                ",
      "                ",
      "                "
    ],
    [
      "                ",
      "                ",
      "  dDEEEEEEEEDd  ",
      "  D          D  ",
      "  E          E  ",
      "  E          E  ",
      "  E          E  ",
      "  D          D  ",
      "  dxxxxxxxxxxd  ",
      "                ",
      "                ",
      " LLLLLLLLLLLLLL ",
      " DDDDDDDDDDDDDD ",
      " MMMMMMMMMMMMMM ",
      " NNNNNNNNNNNNNN ",
      "                "
    ],
    [
      "                ",
      "                ",
      "  dddddddddddd  ",
      "  d          d  ",
      "  d          d  ",
      "  d          d  ",
      "  d          d  ",
      "  d          d  ",
      " LdDDDDDDDDDDdL ",
      " DDDDDDDDDDDDDD ",
      " MMMMMMMMMMMMMM ",
      " NNNNNNNNNNNNNN ",
      "                ",
      "                ",
      "                ",
      "                "
    ],
    [
      "                ",
      "                ",
      "  C  CC  CC  C  ",
      "  C          C  ",
      "                ",
      " LLLLLLLLLLLLLL ",
      " DDDDDDDDDDDDDD ",
      " MMMMMMMMMMMMMM ",
      " NNNNNNNNNNNNNN ",
      "                ",
      "                ",
      "                ",
      "                ",
      "                ",
      "                ",
      "                "
    ],
    [
      "                ",
      "                ",
      " LDLLDDLLDDLLDL ",
      " DDDDDDDDDDDDDD ",
      " MMMMMMMMMMMMMM ",
      " NNNNNNNNNNNNNN ",
      "                ",
      "       ~        ",
      "                ",
      "                ",
      "                ",
      "                ",
      "                ",
      "                ",
      "                ",
      "                "
    ]
  ]
}