{
  "name": "building_bank1_base1_90",
  "refpalette": "c70cities:building_bank1_base1_palette_90",
  "xsize": 16,
  "zsize": 16,
  "slices": [
    [
      "vvvvvvvvvvvvvvvv",
      "vaabbaaaabbaaaav",
      "vabbbbbbbbbbbbav",
      "vabbbbbbbbbbbbbv",
      "vabbbbbbbbbbb!bv",
      "vbbbbbbbbbbbbbav",
      "vbbbbbbbbbbbbbav",
      "vabbbbbbbbbbbbav",
      "vabbbbbbbbbbbbav",
      "vabbbbbbbbbbbbbv",
      "vabbbbbbbbbbbbbv",
      "vbbbbbbbbbbbbbav",
      "vb!bbbbbbbbbbbav",
      "vabbbbbbbbbbbbav",
      "vaaaabbaaaabbaav",
      "vvvvvvvvvvvvvvvv"
    ],
    [
      "vvvvvvvvvvvvvvvv",
      "vaabbaaaabbaaaav",
      "vafcceeeeccdgkav",
      "vae          cbv",
      "va           cbv",
      "vbc          eav",
      "vbc    hih   eav",
      "vae   eihi   eav",
      "vae    hih   eav",
      "va       e   cbv",
      "vade         cbv",
      "vbc           av",
      "vbc         j av",
      "va e ccgdgecc av",
      "vaaaabbaaaabbaav",
      "vvvvvvvvvvvvvvvv"
    ],
    [
      "vvvvvvvvvvvvvvvv",
      "vaabbaaaabbaaaav",
      "vamcc nn ccd gav",
      "va           cbv",
      "va           cbv",
      "vbc           av",
      "vbc    pqq   rav",
      "va     pqq   gav",
      "val    pqq   rav",
      "va           cbv",
      "va           cbv",
      "vbc           av",
      "vbc         j av",
      "va   ccod  cc av",
      "vaaaabbaaaabbaav",
      "vvvvvvvvvvvvvvvv"
    ],
    [
      "vvvvvvvvvvvvvvvv",
      "vaabbaaaabbaaaav",
      "va cc    cc   av",
      "va           cbv",
      "va           cbv",
      "vbc           av",
      "vbc           av",
      "va      q     av",
      "va            av",
      "va           cbv",
      "va           cbv",
      "vbc           av",
      "vbc         j av",
      "va   cc    cc av",
      "vaaaabbaaaabbaav",
      "vvvvvvvvvvvvvvvv"
    ],
    [
      "vvvvvvvvvvvvvvvv",
      "vaabbaaaabbaaaav",
      "va cc    cc   av",
      "va           cbv",
      "va           cbv",
      "vbc           av",
      "vbc           av",
      "va            av",
      "va            av",
      "va           cbv",
      "va           cbv",
      "vbc           av",
      "vbc         j av",
      "va   cc    cc av",
      "vaaaabbaaaabbaav",
      "vvvvvvvvvvvvvvvv"
    ],
    [
      "vvvvvvvvvvvvvvvv",
      "vaabbaaaabbaaaav",
      "vatccssssccssmav",
      "vassssssssssscbv",
      "vassssssssssscbv",
      "vbcsssssssssssav",
      "vbcsssssssssssav",
      "vassssssssssssav",
      "vassssssssssssav",
      "vassssssssssscbv",
      "vassssssssssscbv",
      "vbcsssssssssssav",
      "vbcsssssssssjsav",
      "vamssccssssccuav",
      "vaaaabbaaaabbaav",
      "vvvvvvvvvvvvvvvv"
    ]
  ]
}