{
  "name": "building_hotel1_top_270",
  "refpalette": "c70cities:building_hotel1_top_palette_270",
  "xsize": 16,
  "zsize": 16,
  "slices": [
    [
      "                ",
      " aaeeeeeeeaaaaa ",
      " abccccccccccba ",
      " acddddccddddca ",
      " acddddccddddca ",
      " acddccccccddca ",
      " acddc    cddca ",
      " acccc    cccca ",
      " gcccc    cccca ",
      " gcddc    cddca ",
      " gcddccccecddca ",
      " gcddddccccddca ",
      " gcddddccccddca ",
      " abccccccccccba ",
      " aafffffaaaaaaa ",
      "                "
    ],
    [
      "                ",
      " aaaaaaaaaaaaaa ",
      " a            a ",
      " a kkkk  hhhh a ",
      " a kkkk  hhhh a ",
      " a kkjjjjjjhh a ",
      " a kkj    jhh a ",
      " a   j    j   a ",
      " a   j    j   a ",
      " a llj    jii a ",
      " a lljjjj jii a ",
      " a llll    ii a ",
      " a llll    ii a ",
      " a            a ",
      " aaffffffaaaaaa ",
      "                "
    ],
    [
      "                ",
      " aaaaaffffaaaaa ",
      " a            a ",
      " f            a ",
      " f            a ",
      " f            a ",
      " f            a ",
      " f            a ",
      " f            a ",
      " a            a ",
      " a            a ",
      " a            a ",
      " a            a ",
      " a            a ",
      " aafffffffaaaaa ",
      "                "
    ],
    [
      "                ",
      " aaaaaaaaaaaaaa ",
      " a            a ",
      " a            a ",
      " a            a ",
      " a            a ",
      " a            a ",
      " a            a ",
      " a            a ",
      " a            a ",
      " a            a ",
      " a            a ",
      " a            a ",
      " a            a ",
      " aaffffffffaaaa ",
      "                "
    ],
    [
      "                ",
      " aaaaaaaaaaaaaa ",
      " ammmmmmmmmmmma ",
      " amnnnnnnnnnnma ",
      " amnnnnnnnnnnma ",
      " amnnnnnnnnnnma ",
      " amnnnnnnnnnnma ",
      " amnnnnnnnnnnma ",
      " amnnnnnnnnnnma ",
      " amnnnnnnnnnnma ",
      " amnnnnnnnnnnma ",
      " amnnnnnnnnnnma ",
      " amnnnnnnnnnnma ",
      " ammmmmmmmmmmma ",
      " aammmmmmmmmaaa ",
      "                "
    ],
    [
      "                ",
      " aaaaaaaaaaaaaa ",
      " a            a ",
      " a            a ",
      " a            a ",
      " a            a ",
      " a            a ",
      " a            a ",
      " a            a ",
      " a            a ",
      " a            a ",
      " a            a ",
      " a            a ",
      " a            a ",
      " aa          aa ",
      "                "
    ]
  ]
}