{
  "name": "building_office5_top_270",
  "refpalette": "c70cities:building_office5_top_palette_270",
  "xsize": 16,
  "zsize": 16,
  "slices": [
    [
      "                ",
      "                ",
      "  cdcdcdcdc     ",
      "  ceeeeeeecbba  ",
      "  deeeeeeec  a  ",
      "  ceeeeeeec  a  ",
      "  deeeeeeec  a  ",
      "  ceGGGeefc  a  ",
      "  deGGGeefc  a  ",
      "  ceeeeeeec  a  ",
      "  deee!eeec  a  ",
      "  ceeeeeeecbba  ",
      "  deeeeeeec     ",
      "  cdcdcdcdc     ",
      "                ",
      "                "
    ],
    [
      "                ",
      "                ",
      "  cdcdcdcdc     ",
      "  cgs l jgcba   ",
      "  d   l  hc a   ",
      "  c   l khc a   ",
      "  d       c a   ",
      "  c tpm   c a   ",
      "  d uqn   c a   ",
      "  c       c a   ",
      "  d ooo  ic a   ",
      "  c  r   icba   ",
      "  dg     gc     ",
      "  cdcdcdcdc     ",
      "                ",
      "                "
    ],
    [
      "                ",
      "                ",
      "  cdcdcdcdc     ",
      "  c   l   ca    ",
      "  d   l   wa    ",
      "  c       xa    ",
      "  d       ya    ",
      "  c       ca    ",
      "  d       ca    ",
      "  c       Aa    ",
      "  d DCB    a    ",
      "  c       ma    ",
      "  d       c     ",
      "  cdcdcdcdc     ",
      "                ",
      "                "
    ],
    [
      "                ",
      "                ",
      "  ccccccccc     ",
      "  c       c     ",
      "  c       c     ",
      "  c       c     ",
      "  c       c     ",
      "  c       c     ",
      "  c       c     ",
      "  c       c     ",
      "  c       c     ",
      "  c       c     ",
      "  c       c     ",
      "  ccccccccc     ",
      "                ",
      "                "
    ],
    [
      "                ",
      "                ",
      "  ccccccccc     ",
      "  cEEEEEEEc     ",
      "  cEEEEEEEc     ",
      "  cEEEEEEEc     ",
      "  cEFFFEEEc     ",
      "  cEFFFEEEc     ",
      "  cEFFFEEEc     ",
      "  cEFFFEEEc     ",
      "  cEEEEEEEc     ",
      "  cEEEEEEEc     ",
      "  cEEEEEEEc     ",
      "  ccccccccc     ",
      "                ",
      "                "
    ],
    [
      "                ",
      "                ",
      "  ccccccccc     ",
      "  c   I I c     ",
      "  cIIII I c     ",
      "  c     IIc     ",
      "  c       c     ",
      "  c       c     ",
      "  c       c     ",
      "  c       c     ",
      "  c       c     ",
      "  c IIII  c     ",
      "  c I     c     ",
      "  ccccccccc     ",
      "                ",
      "                "
    ]
  ]
}