{
  "name": "building_apartment1_ground_90",
  "refpalette": "c70cities:building_apartment1_ground_palette_90",
  "xsize": 16,
  "zsize": 16,
  "slices": [
    [
      "GGGGGGGGGGGGGGGG",
      "GaaaaaaaaaaaaaaG",
      "GaaaaaaaaaaaaaaG",
      "GaaaaaaaaaaaaaaG",
      "GaaaaaaaaaaaaaaG",
      "GaaaaaaaaaaaaaaG",
      "GaaaaaaaaaaaaaaG",
      "GaaaaaaaaaaaaaaG",
      "GaaaaaaaaaaaaaaG",
      "GaaaaaaaaaaaaaaG",
      "GaaaaaaaaaaaaaaG",
      "GaaaaaaaaaaaaaaG",
      "GaaaaaaaaaaaaaaG",
      "GaaaaaaaaaaaaaaG",
      "GaaaaaaaaaaaaaaG",
      "GGGGGGGGGGGGGGGG"
    ],
    [
      "                ",
      " bdddddddb      ",
      " b mmm  pbCCCC  ",
      " cjllls Ab FrC  ",
      " cjllls yb   J  ",
      " c kkk   b   J  ",
      " cbbb    bBEbbb ",
      " ci o        pK ",
      " ch b         d ",
      " cbbbb w   DD d ",
      " cggn      DI d ",
      " cf        D  d ",
      " ce        DI d ",
      " b   pruurp   d ",
      " bdddbqtxqddddd ",
      "                "
    ],
    [
      "                ",
      " bdddddddb      ",
      " b      pbQJCC  ",
      " b       b  FC  ",
      " b       b  TC  ",
      " b       b   C  ",
      " bbbb    bPSbbb ",
      " bL M        pK ",
      " b  b         d ",
      " bbbbb        d ",
      " bg        R  d ",
      " b            d ",
      " b            d ",
      " b   pr  rp   d ",
      " bdddbqNOqddddd ",
      "                "
    ],
    [
      "                ",
      " bdddddddb      ",
      " b       bCCCZ  ",
      " d       b   Y  ",
      " d       b  XC  ",
      " b       b  rC  ",
      " bbbb    bWWbbb ",
      " d  U         K ",
      " d  b         d ",
      " bbbbb        d ",
      " b            d ",
      " d            d ",
      " d            d ",
      " b    r  r    d ",
      " bdddbqVVqddddd ",
      "                "
    ],
    [
      "                ",
      " bKKKKKKKb      ",
      " b       bYYYC  ",
      " c       b   J  ",
      " c       b   J  ",
      " b       b 0X1  ",
      " bbbbbbbbbbbbbb ",
      " c  b         K ",
      " c  b         K ",
      " bbbbb        K ",
      " b            K ",
      " c            K ",
      " c            K ",
      " b    rrrr    K ",
      " bKKKbq  qKKKKq ",
      "                "
    ],
    [
      "                ",
      " bbbbbbbbb      ",
      " bCCCCCCCbCCCC  ",
      " bCCCCCCCb   C  ",
      " bCCCCCCCb   C  ",
      " bCCCCCCCbr5 C  ",
      " bbbbbbbbbbbbbb ",
      " b22bCCCCCCCCCb ",
      " b22bCCCCCCCCCb ",
      " bbbbbC34CCCCCb ",
      " bCCCCC!wCCCCCb ",
      " bCCCCCCCCCCCCb ",
      " bCCCCCCCCCCCCb ",
      " bCCCCCCCCCCCCb ",
      " bbbbbbbbbbbbbb ",
      "                "
    ]
  ]
}