{
  "name": "building_hotel2_floor2_90",
  "refpalette": "c70cities:building_hotel2_floor2_palette_90",
  "xsize": 16,
  "zsize": 16,
  "slices": [
    [
      "                ",
      " a              ",
      " a              ",
      " a              ",
      " adddddddddddd  ",
      " acccccccccccd  ",
      " acccccccccccd  ",
      " acccccccccccd  ",
      " acccccc!ccccd  ",
      " acccccccccccd  ",
      " acccccccccccd  ",
      " acccccccccccd  ",
      " acccccccccccd  ",
      " abb=cc!c!cccd  ",
      " aaaaaaaaaaaaaa ",
      "                "
    ],
    [
      "                ",
      " a              ",
      " a              ",
      " a              ",
      " affffffffffff  ",
      " a  jj  ra   f  ",
      " a      rau  f  ",
      " a  ii   atw f  ",
      " a  hho patw f  ",
      " aeaaaaaaa   f  ",
      " a  g        f  ",
      " a  aaaqas  Af  ",
      " a  aln as  yf  ",
      " abb=kmpa=  xf  ",
      " aaaaaaaaaaaaaa ",
      "                "
    ],
    [
      "                ",
      " a              ",
      " a              ",
      " a              ",
      " affffffffffff  ",
      " a       a   f  ",
      " a      Ea   f  ",
      " a       a   f  ",
      " a       a   f  ",
      " aBaaaaaaa   f  ",
      " a  C        f  ",
      " a  aaaDa    f  ",
      " a  a   a   If  ",
      " abb=   aF   f  ",
      " aaaaaaaaaaaaaa ",
      "                "
    ],
    [
      "                ",
      " a              ",
      " a              ",
      " a              ",
      " affffffffffff  ",
      " a       a   f  ",
      " a       a   f  ",
      " a       a   f  ",
      " a       a   f  ",
      " aaaaaaaaa   f  ",
      " a  a        f  ",
      " a  aaaaaK   f  ",
      " a  a   aK   f  ",
      " abb=   aJ   f  ",
      " aaaaaaaaaaaaaa ",
      "                "
    ],
    [
      "                ",
      " a              ",
      " a              ",
      " a              ",
      " affffffffffff  ",
      " a       a   f  ",
      " a       a   f  ",
      " a       a   f  ",
      " a       a   f  ",
      " aaaaaaaaa   f  ",
      " a  a        f  ",
      " aLLaaaaa    f  ",
      " a  a   a    f  ",
      " abb=   a    f  ",
      " aaaaaaaaaaaaaa ",
      "                "
    ],
    [
      "                ",
      " a              ",
      " a              ",
      " a              ",
      " aIIIIIIIIIIII  ",
      " aMMMMMMMMMMMI  ",
      " aMMMMMMMaMMMI  ",
      " aMMMMMMMaMMMI  ",
      " aMMMMMMMaMMMI  ",
      " aaaaaaaaaMMMI  ",
      " aMMaMMMMMMMMI  ",
      " aMMaaaaaMMMMI  ",
      " aMMaMMMaMMMMI  ",
      " abb=MMMaMMMMI  ",
      " aaaaaaaaaaaaaa ",
      "                "
    ]
  ]
}