{
  "name": "building_hotel3_floor3_180",
  "refpalette": "c70cities:building_hotel3_floor3_palette_180",
  "xsize": 16,
  "zsize": 16,
  "slices": [
    [
      "                ",
      "  a a a a a a   ",
      "  bbbbbbbbbbbba ",
      " abccccccccccb  ",
      "  bceeeeeeeecba ",
      " abceffffffecb  ",
      "  bceffffffecba ",
      " abceffffffecb  ",
      "  bceffffffecba ",
      " abceffffffecb  ",
      "  bceffffffecba ",
      " abceeeeeeeecb  ",
      "  bccccddccccba ",
      " abbbbbbbbbbbb  ",
      "   a a a a a a  ",
      "                "
    ],
    [
      "                ",
      "  a a a a a a   ",
      "  bbbbbbbbbbbba ",
      " ab          b  ",
      "  b pllelllp ba ",
      " ab l  e   e b  ",
      "  b l oeoo e ba ",
      " ab l nenn e b  ",
      "  b l mm!m e ba ",
      " ab l  kej e b  ",
      "  b e  iei e ba ",
      " ab eheeeege b  ",
      "  b    dd    ba ",
      " abbbbbbbbbbbb  ",
      "   a a a a a a  ",
      "                "
    ],
    [
      "                ",
      "  a a a a a a   ",
      "  bbbbbbbbbbbba ",
      " ab          b  ",
      "  b p  e   p ba ",
      " ab    e   e b  ",
      "  b    e   s ba ",
      " ab    e   s b  ",
      "  b    te  s ba ",
      " ab     e  s b  ",
      "  b e   e  e ba ",
      " ab ereeeeqe b  ",
      "  b    dd    ba ",
      " abbbbbbbbbbbb  ",
      "   a a a a a a  ",
      "                "
    ],
    [
      "                ",
      "  a a a a a a   ",
      "  bbbbbbbbbbbba ",
      " ab          b  ",
      "  b p  e   p ba ",
      " ab    e   e b  ",
      "  b    e   e ba ",
      " ab    e   e b  ",
      "  b     e  e ba ",
      " ab     e  e b  ",
      "  b e   e  e ba ",
      " ab eeeeeeee b  ",
      "  b    dd    ba ",
      " abbbbbbbbbbbb  ",
      "   a a a a a a  ",
      "                "
    ],
    [
      "                ",
      "  a a a a a a   ",
      "  bbbbbbbbbbbba ",
      " ab          b  ",
      "  b p  e   p ba ",
      " ab    e   e b  ",
      "  b    e   e ba ",
      " ab    e   e b  ",
      "  b     e  e ba ",
      " ab     e  e b  ",
      "  b e   e  e ba ",
      " ab eeeeeeee b  ",
      "  b    dd    ba ",
      " abbbbbbbbbbbb  ",
      "   a a a a a a  ",
      "                "
    ],
    [
      "                ",
      "  a a a a a a   ",
      "  bbbbbbbbbbbba ",
      " ab          b  ",
      "  b eeeeeeee ba ",
      " ab euuuuuue b  ",
      "  b euuuuuue ba ",
      " ab euuuuuue b  ",
      "  b euuueuue ba ",
      " ab euuueuue b  ",
      "  b euuueuue ba ",
      " ab eeeeeeee b  ",
      "  b    dd    ba ",
      " abbbbbbbbbbbb  ",
      "   a a a a a a  ",
      "                "
    ]
  ]
}