{
  "name": "building_office2_ground_270",
  "refpalette": "c70cities:building_office2_ground_palette_270",
  "xsize": 16,
  "zsize": 16,
  "slices": [
    [
      "GGGGGGGGGGGGGGGG",
      "GaGGGGGGGGGGGGaG",
      "GaGbbbbbbbbbbGaG",
      "GabccccccccccbaG",
      "GaccccccccccccaG",
      "GaccccccccccccaG",
      "GaccccccccccccaG",
      "GaccccccccccccaG",
      "GaccccccccccccaG",
      "GaccccccccccccaG",
      "Gacc!cccccccccaG",
      "GaccccccccccccaG",
      "GabccccccccccbaG",
      "GaGbbbbbbbbbbGaG",
      "GaGGGGGGGGGGGGaG",
      "GGGGGGGGGGGGGGGG"
    ],
    [
      "                ",
      " a            a ",
      " a gggggggggg a ",
      " ab          ba ",
      " an          da ",
      " ao       i  ea ",
      " ap      jih fa ",
      " aq       i  fa ",
      " aq       i  fa ",
      " ap      jih ea ",
      " ao m     i  fa ",
      " ar          da ",
      " ab          ba ",
      " a gggglkgggg a ",
      " a            a ",
      "                "
    ],
    [
      "                ",
      " a            a ",
      " a gggggggggg a ",
      " ab          ba ",
      " a           sa ",
      " a            a ",
      " aw           a ",
      " aq           a ",
      " aq           a ",
      " aw           a ",
      " a            a ",
      " a           sa ",
      " ab          ba ",
      " a ggggutgggg a ",
      " a            a ",
      "                "
    ],
    [
      "                ",
      " a            a ",
      " a gggggggggg a ",
      " ab          ba ",
      " a           sa ",
      " a            a ",
      " a            a ",
      " aq    x      a ",
      " aq           a ",
      " a            a ",
      " a            a ",
      " a           sa ",
      " ab          ba ",
      " a gggggggggg a ",
      " a            a ",
      "                "
    ],
    [
      "                ",
      " a            a ",
      " a gggggggggg a ",
      " ab          ba ",
      " a            a ",
      " a            a ",
      " a            a ",
      " aq    xx     a ",
      " aq    xx     a ",
      " a            a ",
      " a            a ",
      " a            a ",
      " ab          ba ",
      " a gggggggggg a ",
      " a            a ",
      "                "
    ],
    [
      "                ",
      " a            a ",
      " a gggggggggg a ",
      " ab          ba ",
      " ayyyyyyyyyyyya ",
      " ayyyyyyyyyyyya ",
      " ayyyyyyyyyyyya ",
      " aqyyyyAAyyyyya ",
      " aqyyyyAAyyyyya ",
      " ayyyyyyyyyyyya ",
      " ayyyyyyyyyyyya ",
      " ayyyyyyyyyyyya ",
      " ab          ba ",
      " a gggggggggg a ",
      " a            a ",
      "                "
    ]
  ]
}