{
  "name": "building_policeoffice1_base1_180",
  "refpalette": "c70cities:building_policeoffice1_base1_palette_180",
  "xsize": 16,
  "zsize": 16,
  "slices": [
    [
      "vvvvvvvvvvvvvvvv",
      "v==============v",
      "v=cccccccccccb=v",
      "v=cccccccccccb=v",
      "v============a=v",
      "v==============v",
      "v==============v",
      "v==============v",
      "v==============v",
      "v==============v",
      "v=!==========!=v",
      "v==============v",
      "v==============v",
      "v=!==========!=v",
      "v==============v",
      "vvvvvvvvvvvvvvvv"
    ],
    [
      "vvvvvvvvvvvvvvvv",
      "vaaaaaaaaaaaaaav",
      "va           bav",
      "va i  p      bav",
      "vaii iioiiiiiaav",
      "vam   na     mav",
      "vaii   a   iiiav",
      "vahg  faf   edav",
      "va    fafk    av",
      "vaii l a   iiiav",
      "vahg  faf   edav",
      "va    fafk    av",
      "vaii   aj  iiiav",
      "vahg  faf   edav",
      "vaaaaaaaaaaaaaav",
      "vvvvvvvvvvvvvvvv"
    ],
    [
      "vvvvvvvvvvvvvvvv",
      "vaaaaaaaaaaaaaav",
      "va           bav",
      "va           bav",
      "vaii ii iiiiiaav",
      "va     o      av",
      "vaii   a   iiiav",
      "va     a      av",
      "va     a      av",
      "vaii  ja   iiiav",
      "va     a      av",
      "va     aj     av",
      "vaii   a   iiiav",
      "va     a      av",
      "vaaaaaaaaaaaaaav",
      "vvvvvvvvvvvvvvvv"
    ],
    [
      "vvvvvvvvvvvvvvvv",
      "vaaaaaaaaaaaaaav",
      "va           bav",
      "va           bav",
      "vaiiiiiaiiiiiaav",
      "va     a     jav",
      "va     a      av",
      "va     a      av",
      "va     a      av",
      "va     a     jav",
      "va     aj     av",
      "va     a      av",
      "va     a      av",
      "va     a      av",
      "vaaaaaaaaaaaaaav",
      "vvvvvvvvvvvvvvvv"
    ],
    [
      "vvvvvvvvvvvvvvvv",
      "vaaaaaaaaaaaaaav",
      "va           bav",
      "va j         bav",
      "vaaaaaaaaaaaaaav",
      "vaj  jjaj   jjav",
      "va    ja     jav",
      "va     a      av",
      "va     a      av",
      "vaj    aj    jav",
      "va     aj    jav",
      "va     ajj    av",
      "vaj   ja  j  jav",
      "va     aj    jav",
      "vaaaaaaaaaaaaaav",
      "vvvvvvvvvvvvvvvv"
    ],
    [
      "vvvvvvvvvvvvvvvv",
      "qaaaaaaaaaaaaaav",
      "qasssssssssssbav",
      "qasssssssssssbav",
      "qaaaaaaaaaaaaaav",
      "qarrrrrarrrrrrav",
      "qarrrrrarrrrrrav",
      "qarrrrrarrrrrrav",
      "qarrrrrarrrrrrav",
      "qarrrrrarrrrrrav",
      "qarrrrrarrrrrrav",
      "qarrrrrarrrrrrav",
      "qarrrrrarrrrrrav",
      "qarrrrrarrrrrrav",
      "qaaaaaaaaaaaaaav",
      "vqqqqqqqqqqqqqqv"
    ]
  ]
}