{
  "name": "building_bank1_base1_270",
  "refpalette": "c70cities:building_bank1_base1_palette_270",
  "xsize": 16,
  "zsize": 16,
  "slices": [
    [
      "vvvvvvvvvvvvvvvv",
      "vaabbaaaabbaaaav",
      "vabbbbbbbbbbbbav",
      "vabbbbbbbbbbb!bv",
      "vabbbbbbbbbbbbbv",
      "vbbbbbbbbbbbbbav",
      "vbbbbbbbbbbbbbav",
      "vabbbbbbbbbbbbav",
      "vabbbbbbbbbbbbav",
      "vabbbbbbbbbbbbbv",
      "vabbbbbbbbbbbbbv",
      "vb!bbbbbbbbbbbav",
      "vbbbbbbbbbbbbbav",
      "vabbbbbbbbbbbbav",
      "vaaaabbaaaabbaav",
      "vvvvvvvvvvvvvvvv"
    ],
    [
      "vvvvvvvvvvvvvvvv",
      "vaabbaaaabbaaaav",
      "va ccegdgcc e av",
      "va j         cbv",
      "va           cbv",
      "vbc         edav",
      "vbc   e       av",
      "vae   hih    eav",
      "vae   ihie   eav",
      "vae   hih    cbv",
      "vae          cbv",
      "vbc           av",
      "vbc           av",
      "vaggdcceeeeccfav",
      "vaaaabbaaaabbaav",
      "vvvvvvvvvvvvvvvv"
    ],
    [
      "vvvvvvvvvvvvvvvv",
      "vaabbaaaabbaaaav",
      "va cc mdmcc   av",
      "va j         cbv",
      "va           cbv",
      "vbc           av",
      "vbc           av",
      "vap   oon    kav",
      "vag   oon     av",
      "vap   oon    cbv",
      "va           cbv",
      "vbc           av",
      "vbc           av",
      "vagldcc ll cc av",
      "vaaaabbaaaabbaav",
      "vvvvvvvvvvvvvvvv"
    ],
    [
      "vvvvvvvvvvvvvvvv",
      "vaabbaaaabbaaaav",
      "va cc    cc   av",
      "va j         cbv",
      "va           cbv",
      "vbc           av",
      "vbc           av",
      "va            av",
      "va     o      av",
      "va           cbv",
      "va           cbv",
      "vbc           av",
      "vbc           av",
      "va   cc    cc av",
      "vaaaabbaaaabbaav",
      "vvvvvvvvvvvvvvvv"
    ],
    [
      "vvvvvvvvvvvvvvvv",
      "vaabbaaaabbaaaav",
      "va cc    cc   av",
      "va j         cbv",
      "va           cbv",
      "vbc           av",
      "vbc           av",
      "va            av",
      "va            av",
      "va           cbv",
      "va           cbv",
      "vbc           av",
      "vbc           av",
      "va   cc    cc av",
      "vaaaabbaaaabbaav",
      "vvvvvvvvvvvvvvvv"
    ],
    [
      "vvvvvvvvvvvvvvvv",
      "vaabbaaaabbaaaav",
      "vasccqqqqccqqfav",
      "vaqjqqqqqqqqqcbv",
      "vaqqqqqqqqqqqcbv",
      "vbcqqqqqqqqqqqav",
      "vbcqqqqqqqqqqqav",
      "vaqqqqqqqqqqqqav",
      "vaqqqqqqqqqqqqav",
      "vaqqqqqqqqqqqcbv",
      "vaqqqqqqqqqqqcbv",
      "vbcqqqqqqqqqqqav",
      "vbcqqqqqqqqqqqav",
      "vafqqccqqqqccrav",
      "vaaaabbaaaabbaav",
      "vvvvvvvvvvvvvvvv"
    ]
  ]
}