{
  "name": "building_hotel1_floor1_180",
  "refpalette": "c70cities:building_hotel1_floor1_palette_180",
  "xsize": 16,
  "zsize": 16,
  "slices": [
    [
      "                ",
      " aagggggaaaaaaa ",
      " abbbbbbbbbbbba ",
      " fbbbbbbbbbbbbd ",
      " fbbbbbbbbbbbbd ",
      " fbbbbbbbbbbbbd ",
      " fbbbbe   bbbbd ",
      " abbbb    bbbbd ",
      " abbbb    bbbbd ",
      " abbbd    bbbbd ",
      " acccccccccccca ",
      " abbbbbbbbbbbba ",
      " abbbbbbbbbbbba ",
      " abbbbbbbbbbbba ",
      " aaaaaaaaaaaaaa ",
      "                "
    ],
    [
      "                ",
      " aaaaaaaaaaaaaa ",
      " awtws tws twsa ",
      " f            a ",
      " f            a ",
      " f            a ",
      " f    dee  t sa ",
      " aw  u      w a ",
      " a   u     t sa ",
      " a            a ",
      " arr aaaaaaaaaa ",
      " a q  kponmlkja ",
      " a            a ",
      " aiii        ha ",
      " aaaaaaaaaaaaaa ",
      "                "
    ],
    [
      "                ",
      " aaaaaaffffffaa ",
      " aC B   B   B a ",
      " f            a ",
      " f            a ",
      " f            a ",
      " f      de  B f ",
      " aC      e  B f ",
      " a          B f ",
      " a            f ",
      " a   aaaaaaaaaa ",
      " a     A y x  a ",
      " a            a ",
      " a            a ",
      " aaaaaaaaaaaaaa ",
      "                "
    ],
    [
      "                ",
      " aaaaaaaaaaaaaa ",
      " aC           a ",
      " f            a ",
      " f            a ",
      " f            a ",
      " f            a ",
      " aC      d    a ",
      " a       e    a ",
      " a       e    a ",
      " a   aaaaaaaaaa ",
      " a            a ",
      " a            a ",
      " a            a ",
      " aaaaaaaaaaaaaa ",
      "                "
    ],
    [
      "                ",
      " aaaaaaffaaaaaa ",
      " a            a ",
      " f            a ",
      " f            a ",
      " f            a ",
      " f            a ",
      " a            a ",
      " a            a ",
      " a     eed    a ",
      " aaaaaaaaaaaaaa ",
      " a            f ",
      " a            f ",
      " a            a ",
      " aaaaaaaaaaaaaa ",
      "                "
    ],
    [
      "                ",
      " aaaaaaaaaaaaaa ",
      " aDDDDDDDDDDDDa ",
      " fDDDDDDDDDDDDa ",
      " fDDDDDDDDDDDDa ",
      " fDDDDDDDDDDDDa ",
      " fDDDD    DDDDa ",
      " aDDDD    DDDDa ",
      " aDDDD    DDDDa ",
      " aDDDDed  DDDDa ",
      " aaaaaaaaaaaaaa ",
      " aDDDDDDDDDDDDa ",
      " aDDDDDDDDDDDDa ",
      " aDDDDDDDDDDDDa ",
      " aaaaaaaaaaaaaa ",
      "                "
    ]
  ]
}