{
  "name": "building_office3_ground_180",
  "refpalette": "c70cities:building_office3_ground_palette_180",
  "xsize": 16,
  "zsize": 16,
  "slices": [
    [
      "GGGGGGGGGGGGGGGG",
      "GaaaaaaaaaaaaaaG",
      "GabbbbbbbbbbbbaG",
      "GabbbbbbbbbbbbaG",
      "GabbbbbbbbbbbbaG",
      "GabbbbbbbbbbbbaG",
      "GabbbbbbbbbbbbaG",
      "GabbbbbbbbbbbbaG",
      "GabbbbbbbbbbbbaG",
      "GabbbbbbbbbbbbaG",
      "GabbbbbbbbbbbbaG",
      "GabbbbbbbbbbbbaG",
      "Gabbbbbbbbbb!baG",
      "GabbbbbbbbbbbbaG",
      "GaaaaaaaaaaaaaaG",
      "GGGGGGGGGGGGGGGG"
    ],
    [
      "                ",
      " ccdccdccdccdcc ",
      " ceeffgffgffeec ",
      " deh        hed ",
      " cf          fc ",
      " cf          fc ",
      " dg          gd ",
      " l     jv    fc ",
      " k     jvi   fc ",
      " dg          gd ",
      " cf          fc ",
      " cf          fc ",
      " deh        hed ",
      " ceeffgffgffeec ",
      " ccdccdccdccdcc ",
      "                "
    ],
    [
      "                ",
      " ccdccdccdccdcc ",
      " c    m  m    c ",
      " d h        h d ",
      " c            c ",
      " c            c ",
      " dm          md ",
      " o     jv     c ",
      " n     jv     c ",
      " dm          md ",
      " c            c ",
      " c            c ",
      " d h        h d ",
      " c    m  m    c ",
      " ccdccdccdccdcc ",
      "                "
    ],
    [
      "                ",
      " ppdppdppdppdpp ",
      " p            p ",
      " d h        h d ",
      " p            p ",
      " p            p ",
      " d            d ",
      " p     jv     p ",
      " p     jv     p ",
      " d            d ",
      " p            p ",
      " p            p ",
      " d h        h d ",
      " p            p ",
      " ppdppdppdppdpp ",
      "                "
    ],
    [
      "                ",
      " ccdccdccdccdcc ",
      " cqqqqqqqqqqqqc ",
      " dqh        hqd ",
      " cq          qc ",
      " cq          qc ",
      " dq          qd ",
      " cq    jv    qc ",
      " cq    jv    qc ",
      " dq          qd ",
      " cq          qc ",
      " cq          qc ",
      " dqh        hqd ",
      " cqqqqqqqqqqqqc ",
      " ccdccdccdccdcc ",
      "                "
    ],
    [
      "                ",
      " rrrrrrrrrrrrrr ",
      " raaaaaaaaaaaar ",
      " rasddddddddsar ",
      " raddddddddddar ",
      " raddddddddddar ",
      " raddddddddddar ",
      " raddddjvddddar ",
      " raddddjvddddar ",
      " raddddddddddar ",
      " raddddddddddar ",
      " raddddddddddar ",
      " rasddddddddsar ",
      " raaaaaaaaaaaar ",
      " rrrrrrrrrrrrrr ",
      "                "
    ]
  ]
}