{
  "name": "building_office1_base2_90",
  "refpalette": "c70cities:building_office1_base2_palette_90",
  "xsize": 16,
  "zsize": 16,
  "slices": [
    [
      "vvvvvvvvvvvvvvvv",
      "vaaaaaaaaaaaaaav",
      "vaaaaaaaaaaaa!av",
      "vaaaaaaaaaaaaaav",
      "vaaaaaaaaaaaaaav",
      "vaaaaaaaaaaaaaav",
      "vaaaaa!aaaaaaaav",
      "vaaaaaaaaaaaaaav",
      "vaaaaaaaaaaaaaav",
      "vaaaaa!aaaaaaaav",
      "vaaaaaaaaaaaaaav",
      "vaaaaaaaaaaaaaav",
      "vaaaaaaaaaaaaaav",
      "vaaaaaaaaaaaaaav",
      "vaaaaaaaaaaaaaav",
      "vvvvvvvvvvvvvvvv"
    ],
    [
      "vvvvvvvvvvvvvvvv",
      "vbbbbbbbbbbbbbbv",
      "vbehkkhkkheottbv",
      "vb  j   j  p  bv",
      "vb   d     p  bv",
      "vb     m   p  bv",
      "vb   mm m  o  bv",
      "vb g       r  bv",
      "vb         q  bv",
      "vb   mmmm  o  bv",
      "vb    m    p  bv",
      "vb d       p  bv",
      "vbd  l n   p  bv",
      "vbcfiifiif ossbv",
      "vbbbbbbbbbbbbbbv",
      "vvvvvvvvvvvvvvvv"
    ],
    [
      "vvvvvvvvvvvvvvvv",
      "vbbbbbbbbbbbbbbv",
      "vb j   j n oxybv",
      "vb         p  bv",
      "vb         p  bv",
      "vb         p  bv",
      "vb         o  bv",
      "vb         w  bv",
      "vb         u  bv",
      "vb         o  bv",
      "vb         p  bv",
      "vb         p  bv",
      "vb         p  bv",
      "vb  d l    ossbv",
      "vbbbbbbbbbbbbbbv",
      "vvvvvvvvvvvvvvvv"
    ],
    [
      "vvvvvvvvvvvvvvvv",
      "vbbbbbbbbbbbbbbv",
      "vb         o Abv",
      "vb         p  bv",
      "vb         p  bv",
      "vb         p  bv",
      "vb         o  bv",
      "vb         o  bv",
      "vb         o  bv",
      "vb         o  bv",
      "vb         p  bv",
      "vb         p  bv",
      "vb         p  bv",
      "vb         ossbv",
      "vbbbbbbbbbbbbbbv",
      "vvvvvvvvvvvvvvvv"
    ],
    [
      "vvvvvvvvvvvvvvvv",
      "vbbbbbbbbbbbbbbv",
      "vbBCBBCBBCBo  bv",
      "vb         p  bv",
      "vb         p  bv",
      "vb         p  bv",
      "vb         p  bv",
      "vb         p  bv",
      "vb         p  bv",
      "vb         p  bv",
      "vb         p  bv",
      "vb         p  bv",
      "vb         p  bv",
      "vbBCBBCBBCBossbv",
      "vbbbbbbbbbbbbbbv",
      "vvvvvvvvvvvvvvvv"
    ],
    [
      "vvvvvvvvvvvvvvvv",
      "vbbbbbbbbbbbbbbv",
      "vbDDDDDDDDDoDDbv",
      "vbDDDDDDDDDDDDbv",
      "vbDDDDDDDDDDDDbv",
      "vbDDDDDDDDDDDDbv",
      "vbDDDDDDDDDDDDbv",
      "vbDEDDFDDgDDDDbv",
      "vbDgDDgDDFDDDDbv",
      "vbDDDDDDDDDDDDbv",
      "vbDDDDDDDDDDDDbv",
      "vbDDDDDDDDDDDDbv",
      "vbDDDDDDDDDDDDbv",
      "vbDDDDDDDDDossbv",
      "vbbbbbbbbbbbbbbv",
      "vvvvvvvvvvvvvvvv"
    ]
  ]
}