{
  "name": "building_residential3_floor1_180",
  "refpalette": "c70cities:building_residential3_floor1_palette_180",
  "xsize": 16,
  "zsize": 16,
  "slices": [
    [
      "                ",
      "                ",
      "  abbbbacccccc  ",
      "  a    adggddc  ",
      "  b         dc  ",
      "  b         gc  ",
      "  b         gc  ",
      "  afff  e   dc  ",
      "  a         aa  ",
      "  b          b  ",
      "  b          b  ",
      "  b          b  ",
      "  b          b  ",
      "  aabbbaabbbaa  ",
      "                ",
      "                "
    ],
    [
      "                ",
      " hhhhhhhhhhhhhh ",
      " haaaaaacccccch ",
      "  a    adddddc  ",
      "  a         dc  ",
      "  a         dc  ",
      "  a         dc  ",
      "  afff  e   dc  ",
      "  a         aa  ",
      "  a          a  ",
      "  a          a  ",
      "  a          a  ",
      "  a          a  ",
      " haaaaaaaaaaaah ",
      " hhhhhhhhhhhhhh ",
      "                "
    ],
    [
      "                ",
      "                ",
      " iiiiiiiiiiiiii ",
      " mmmmmmmmmmmmmm ",
      " kkkkkkkkkkkkkk ",
      " hahhhhhhhhhdch ",
      "  a         dc  ",
      "  aklk  e   dc  ",
      "  ae        aa  ",
      "  a          a  ",
      " hahhhhhhhhhhah ",
      " kkkkkkkkkkkkkk ",
      " jjjjjjjjjjjjjj ",
      " iiiiiiiiiiiiii ",
      "                ",
      "                "
    ],
    [
      "                ",
      "                ",
      "                ",
      "                ",
      "                ",
      " iiiiiiiiiiiiii ",
      " mmmmmmmmmmmmmm ",
      " kkkkkkkkkkkkkk ",
      " kkkkkkkkkkkkkk ",
      " jjjjjjjjjjjjjj ",
      " iiiiiiiiiiiiii ",
      "                ",
      "                ",
      "                ",
      "                ",
      "                "
    ],
    [
      "                ",
      "                ",
      "                ",
      "                ",
      "                ",
      "                ",
      "                ",
      "                ",
      "        ~       ",
      "        ~       ",
      "                ",
      "                ",
      "                ",
      "                ",
      "                ",
      "                "
    ],
    [
      "                ",
      "                ",
      "                ",
      "                ",
      "                ",
      "                ",
      "                ",
      "                ",
      "        ~       ",
      "                ",
      "                ",
      "                ",
      "                ",
      "                ",
      "                ",
      "                "
    ]
  ]
}