{
  "name": "building_hotel2_floor3_90",
  "refpalette": "c70cities:building_hotel2_floor3_palette_90",
  "xsize": 16,
  "zsize": 16,
  "slices": [
    [
      "                ",
      " a              ",
      " a              ",
      " a              ",
      " adddddddddddd  ",
      " acccccccccccd  ",
      " accc!ccccc!cd  ",
      " acccccccccccd  ",
      " acccccccccccd  ",
      " acccccccccccd  ",
      " acccccccccccd  ",
      " acccccccccccd  ",
      " acccccccccccd  ",
      " abb=ccccccccd  ",
      " aaaaaaaaaaaaaa ",
      "                "
    ],
    [
      "                ",
      " a              ",
      " a              ",
      " a              ",
      " aeeeeeeeeeeee  ",
      " a           e  ",
      " a   j  j  j e  ",
      " a   i  i  i e  ",
      " a  gi gi gi e  ",
      " a           e  ",
      " a           e  ",
      " a           e  ",
      " a  f        e  ",
      " abb=hhklmhh e  ",
      " aaaaaaaaaaaaaa ",
      "                "
    ],
    [
      "                ",
      " a              ",
      " a              ",
      " a              ",
      " aeeeeeeeeeeee  ",
      " a           e  ",
      " a           e  ",
      " a           e  ",
      " a           e  ",
      " a           e  ",
      " a           e  ",
      " a           e  ",
      " a  n        e  ",
      " abb=hh   hh e  ",
      " aaaaaaaaaaaaaa ",
      "                "
    ],
    [
      "                ",
      " a              ",
      " a              ",
      " a              ",
      " aeeeeeeeeeeee  ",
      " a           e  ",
      " a           e  ",
      " a           e  ",
      " a           e  ",
      " a           e  ",
      " a           e  ",
      " a           e  ",
      " a  n        e  ",
      " abb=hh   hh e  ",
      " aaaaaaaaaaaaaa ",
      "                "
    ],
    [
      "                ",
      " a              ",
      " a              ",
      " a              ",
      " aeeeeeeeeeeee  ",
      " a           e  ",
      " a           e  ",
      " a           e  ",
      " a           e  ",
      " a o  o  o   e  ",
      " a           e  ",
      " a           e  ",
      " a           e  ",
      " abb=        e  ",
      " aaaaaaaaaaaaaa ",
      "                "
    ],
    [
      "                ",
      " a              ",
      " a              ",
      " a              ",
      " aiiiiiiiiiiii  ",
      " apppppppppppi  ",
      " apppppppppppi  ",
      " apppppppppppi  ",
      " apppppppppppi  ",
      " apppppppppppi  ",
      " apppppppppppi  ",
      " apppppppppppi  ",
      " apppppppppppi  ",
      " abb=ppppppppi  ",
      " aaaaaaaaaaaaaa ",
      "                "
    ]
  ]
}