{
  "name": "building_office1_ground_90",
  "refpalette": "c70cities:building_office1_ground_palette_90",
  "xsize": 16,
  "zsize": 16,
  "slices": [
    [
      "GGGGGGGGGGGGGGGG",
      "GbbbbbbbbbbbbbbG",
      "GbccccccddddddbG",
      "GbcbbbbbbbbbbbbG",
      "abcbbbbbbbbbbbbG",
      "GbcbbbbbbbbbbbbG",
      "GbcbbbbbbbbbbbbG",
      "Gbcbbb!bbbbbbbbG",
      "GbcbbbbbbbbbbbbG",
      "GbcbbbbbbbbbbbbG",
      "GbcbbbbbbbbbbbbG",
      "abcbbbbbbbbbbbbG",
      "GbcbbbbbbbbbbbbG",
      "GbccccccddddeebG",
      "GbbbbbbbbbbbbbbG",
      "GGGGGGGGGGGGGGGG"
    ],
    [
      "f               ",
      "f g  g  g  prsp ",
      "f hhhhhhdhhd  p ",
      "fghi          p ",
      "f h           p ",
      "f h  ll  nnn  p ",
      "fgh j l  non  p ",
      "f h   l       p ",
      "f h   l       p ",
      "fgh j l  non  p ",
      "f h  km  nnn  p ",
      "f h           p ",
      "fghi       q  p ",
      "f hhhhhhdhhd  p ",
      "f g  g  g  pppp ",
      "f               "
    ],
    [
      "                ",
      "  g  g  g  pwxp ",
      "  hhhhhhdhhd  p ",
      " ght          y ",
      "  h           h ",
      "  h           h ",
      " gh   u       h ",
      "  h           h ",
      "  h           h ",
      " gh           h ",
      "  h           h ",
      "  h           h ",
      " ght       q  y ",
      "  hhhhhhdhhd  p ",
      "  g  g  g  pppp ",
      "                "
    ],
    [
      "                ",
      "  g  g  g  pppp ",
      "  hhhhhhdhhd  p ",
      " ght          y ",
      "  h           h ",
      "  h           h ",
      " gh           h ",
      "  h           h ",
      "  h           h ",
      " gh           h ",
      "  h           h ",
      "  h           h ",
      " ght       q  y ",
      "  hhhhhhdhhd  p ",
      "  g  g  g  pppp ",
      "                "
    ],
    [
      "                ",
      "  g  g  g  pppp ",
      "  hhhhhhdhhd  p ",
      " gh           p ",
      "  h           p ",
      "  h           p ",
      " gh           p ",
      "  h           p ",
      "  h           p ",
      " gh           p ",
      "  h           p ",
      "  h           p ",
      " gh        q  p ",
      "  hhhhhhdhhd  p ",
      "  g  g  g  pppp ",
      "                "
    ],
    [
      "                ",
      " AAAAAAAA  pppp ",
      " AAAAAAAAhhdyyp ",
      " AAyyyyyy   yyp ",
      " A yyyyyyyyyyyp ",
      " AAyyyyyyyyyyyp ",
      " AAyyyyyyyyyyyp ",
      " AAyyyyyyyyyyyp ",
      " AAyyyyyyyyyyyp ",
      " AAyyyyyyyyyyyp ",
      " AAyyyyyyyyyyyp ",
      " AAyyyyyyyyyyyp ",
      " AAyyyyyy  qyyp ",
      " AAAAAAAAhhdyyp ",
      " AAAAAAAA  pppp ",
      "                "
    ]
  ]
}