{
  "name": "building_apartment1_floor1_180",
  "refpalette": "c70cities:building_apartment1_floor1_palette_180",
  "xsize": 16,
  "zsize": 16,
  "slices": [
    [
      "                ",
      "      aaaaaaaaa ",
      "  ihgdbbbbbbbba ",
      "  ef  bbbbbbbba ",
      "  ebb bbbbbbbba ",
      "  dbbcbbbbbbbba ",
      " abbbbbbbbbbbba ",
      " abbbbbbbbbbbba ",
      " abbbbbbbbbbbba ",
      " abbbbbbbbbbbba ",
      " abbbbbbbbbbbba ",
      " abbbbbbbbbbbba ",
      " abbbbbbbbbbbba ",
      " abbbbbbbbbbbba ",
      " aaaaaaaaaaaaaa ",
      "                "
    ],
    [
      "                ",
      "      VVVVVVVVU ",
      "  ddTTp!     Sm ",
      "  dR  pQ M   Pm ",
      "  dO  pN M   Lm ",
      "  d   p     Kqm ",
      " spJpppIIF Cppm ",
      " s  E      E  m ",
      " sDDp      Cqrm ",
      " sppppppxpBpppm ",
      " sAy     p Ay m ",
      " s   wwxwp    m ",
      " st  p   u tt m ",
      " son p rqp oonm ",
      " lkkkkkkkkkkkkj ",
      "                "
    ],
    [
      "                ",
      "      p3WWWWW31 ",
      "  ddddp      #3 ",
      "  dO@ p8     93 ",
      "  T   p8      3 ",
      "  h   p     7 3 ",
      " pp6ppp    Cpp1 ",
      " p  5      5  3 ",
      " p  p      C 43 ",
      " ppppppp0p2ppp1 ",
      " p       p    p ",
      " W   ww0wp    W ",
      " W   p   Z    W ",
      " W   p Y p   XW ",
      " pppppppppppppp ",
      "                "
    ],
    [
      "                ",
      "      p3WWWWW31 ",
      "  \\}ddp {{][[ W ",
      "  d -Rp+      W ",
      "  d   p+      W ",
      "  d   p       3 ",
      " pppppp  ) Cpp1 ",
      " W  p      C  W ",
      " W  p      C  W ",
      " ppppppppppppp1 ",
      " p       p    p ",
      " W(  wwwwp   *W ",
      " W&  p   p   ^W ",
      " W%  p   p   $W ",
      " ppWWppWWppWWpp ",
      "                "
    ],
    [
      "                ",
      "      p33333331 ",
      "  dTTep       3 ",
      "  }  -p       3 ",
      "  }  |p       3 ",
      "  }   p       3 ",
      " pppppp  f Cpp1 ",
      " 3 fp      C  3 ",
      " 3  p      C  3 ",
      " ppppppppppppp1 ",
      " p       p    p ",
      " 3   wwwwp    3 ",
      " 3   p   p    3 ",
      " 3   p   p    3 ",
      " ppkkppkkppkkpp ",
      "                "
    ],
    [
      "                ",
      "      ppppppppp ",
      "  ddddpdddddddp ",
      "  d   pdddddddp ",
      "  d  cpdddddddp ",
      "  d  Rpdddddddp ",
      " ppppppdddddddp ",
      " pddpddddddd``p ",
      " pddpddddddd``p ",
      " pppppppppppppp ",
      " pdddddddpddddp ",
      " pdddddddpddddp ",
      " pdddd```pddddp ",
      " pdddd```pddddp ",
      " pppppppppppppp ",
      "                "
    ]
  ]
}