{
  "name": "building_hotel1_floor2_90",
  "refpalette": "c70cities:building_hotel1_floor2_palette_90",
  "xsize": 16,
  "zsize": 16,
  "slices": [
    [
      "                ",
      " aaaaaaaaffffaa ",
      " abbbcbbbbbbbba ",
      " abbbcbbbbbbbbg ",
      " abbbcbbbbbbbbg ",
      " abbbcdbbbbbbbg ",
      " abbbc   ecccbg ",
      " abbbc    cbbbg ",
      " abbbc    cbbba ",
      " abbbc    cbbba ",
      " abbbccccccbbba ",
      " abbbbbbbbbbbba ",
      " abbbbbbbbbbbba ",
      " abbbbbbbbbbbba ",
      " aaaaadddddddaa ",
      "                "
    ],
    [
      "                ",
      " aaaaaaaaffffaa ",
      " a   a  n    na ",
      " al  t      Dea ",
      " a   a      Dea ",
      " a  os ww   eea ",
      " ak pa   daaaaa ",
      " aj qa   eaACEa ",
      " aj qa   eay  a ",
      " ai pa    aff a ",
      " a  osaaaas   a ",
      " a   r=uu=axB a ",
      " ahn      axB a ",
      " a m          a ",
      " aaaaaaaaaaaaaa ",
      "                "
    ],
    [
      "                ",
      " aaaaaaaaffffaa ",
      " a   a  L    La ",
      " a   J        a ",
      " a   a        a ",
      " a  os        a ",
      " a   a    aaaaa ",
      " a  Ia    aN  f ",
      " a   a   da   f ",
      " a   a  eeaff f ",
      " a  osaaaas   f ",
      " a    K  Ma   f ",
      " a F      a   f ",
      " a            a ",
      " aaaaaffffaaaaa ",
      "                "
    ],
    [
      "                ",
      " aaaaaaaaffffaa ",
      " a   a  L    La ",
      " a   a        a ",
      " a   a        a ",
      " aO  s        a ",
      " a   a    aaaaa ",
      " a   a    aP  a ",
      " a   a    a   a ",
      " a   aeed aff a ",
      " aO  saaaasO  a ",
      " a     DD a   a ",
      " a        a   a ",
      " a        a   a ",
      " aaaaaaaaaaaaaa ",
      "                "
    ],
    [
      "                ",
      " aaaaaaaaffffaa ",
      " a   a        a ",
      " a   a        a ",
      " a   a        a ",
      " aQ  s        a ",
      " a   a    aaaaa ",
      " a   ae   a   f ",
      " a   ae   a   f ",
      " a   ad   afffa ",
      " aQ  saaaasQ  a ",
      " a        a   a ",
      " a        a   a ",
      " a        a   a ",
      " aaffaaaaaaaaaa ",
      "                "
    ],
    [
      "                ",
      " aaaaaaaaffffaa ",
      " aRRRaRRRRRRRRa ",
      " aRRRaRRRRRRRRa ",
      " aRRRaRRRRRRRRa ",
      " aRRRsRRRRRRRRa ",
      " aRRRae   aaaaa ",
      " aRRRad   aRRRa ",
      " aRRRa    aRRRa ",
      " aRRRa    aRRRa ",
      " aRRRsaaaasRRRa ",
      " aRRRRRRRRRRRRa ",
      " aRRRRRRRRRRRRa ",
      " aRRRRRRRRRRRRa ",
      " aaaaaaaaaaaaaa ",
      "                "
    ]
  ]
}