{
  "name": "building_bank1_floor2_180",
  "refpalette": "c70cities:building_bank1_floor2_palette_180",
  "xsize": 16,
  "zsize": 16,
  "slices": [
    [
      "                ",
      "   lbbk  lbbk   ",
      "  deeeedeeeeed  ",
      " ieeeeeeeeeeeeh ",
      " beeeeeeeeeeeeb ",
      " beeeeeeeeeeeeb ",
      " geeeeeeeeeejef ",
      "  eee!eeeeee d  ",
      "  deeeeeeeee e  ",
      " ieeeeeeeeee eh ",
      " beeeee!eeee eb ",
      " beeeeeeeeeeeeb ",
      " geeeeeeeeeeeef ",
      "  deeeeedeeeed  ",
      "   cbba  cbba   ",
      "                "
    ],
    [
      "                ",
      "  lbbk  lbbk    ",
      "  mmmmnmmmmmnmh ",
      "  n     o    mb ",
      " im C x o    mb ",
      " bm rBA o    mf ",
      " bm        t n  ",
      " gmooooy   t m  ",
      "  m        t mh ",
      "  n xw o   t mb ",
      " im  u op  tjsb ",
      " bm rq op    mf ",
      " bm    o     n  ",
      " gmnmmmmmnmmmm  ",
      "    cbba  cbba  ",
      "                "
    ],
    [
      "                ",
      " Dbbk  lbbk  lD ",
      " gmmmnmmmmmnmmb ",
      "  m     o    mb ",
      "  n     o    mf ",
      " im     o    n  ",
      " bm        t m  ",
      " bmooooE     mh ",
      " gm        t mb ",
      "  m    o    jsb ",
      "  n    o   t mf ",
      " im    o     n  ",
      " bm    o     m  ",
      " bmmnmmmmmnmmmh ",
      " Da  cbba  cbbD ",
      "                "
    ],
    [
      "                ",
      " Dbk  lbbk  lbD ",
      " bmmnmmmmmnmmmb ",
      " gm          mf ",
      "  m          n  ",
      "  n          m  ",
      " im        t mh ",
      " bm    E     mb ",
      " bm        tjsb ",
      " gm          mf ",
      "  m        t n  ",
      "  n          m  ",
      " im          mh ",
      " bmmmnmmmmmnmmb ",
      " Dba  cbba  cbD ",
      "                "
    ],
    [
      "                ",
      " Dk  lbbk  lbbD ",
      " bmnmmmmmnmmmmf ",
      " bm          n  ",
      " gm          m  ",
      "  m          mh ",
      "  n        t mb ",
      " im         jsb ",
      " bm        t mf ",
      " bm          n  ",
      " gm        t m  ",
      "  m          mh ",
      "  n          mb ",
      " immmmnmmmmmnmb ",
      " Dbba  cbba  cD ",
      "                "
    ],
    [
      "                ",
      "    lbbk  lbbk  ",
      " inmmmmmnmmmmn  ",
      " bmFFFFFFFFFFm  ",
      " bmFFFFFFFFFFmh ",
      " gmFFFFFFFFFFmb ",
      "  mFFFFFFFFtjsb ",
      "  nFFFFFFFF  mf ",
      " imFFFFFFFFt n  ",
      " bmFFFFFFFF  m  ",
      " bmFFFFFFFFt mh ",
      " gmFFFFFFFFFFmb ",
      "  mFFFFFFFFFFmb ",
      "  nmmmmnmmmmmnf ",
      "  cbba  cbba    ",
      "                "
    ]
  ]
}