{
  "name": "building_office1_ground_90",
  "refpalette": "c70cities:building_office1_ground_palette_90",
  "xsize": 16,
  "zsize": 16,
  "slices": [
    [
      "GGGGGGGGGGGGGGGG",
      "GbbbbbbbbbbbbbbG",
      "GbccccccddddddbG",
      "GbcbbbbbbbbbbbbG",
      "abcbbbbbbbbbbbbG",
      "GbcbbbbbbbbbbbbG",
      "GbcbbbbbbbbbbbbG",
      "Gbcbbb!bbbbbbbbG",
      "GbcbbbbbbbbbbbbG",
      "GbcbbbbbbbbbbbbG",
      "GbcbbbbbbbbbbbbG",
      "abcbbbbbbbbbbbbG",
      "GbcbbbbbbbbbbbbG",
      "GbccccccddddeebG",
      "GbbbbbbbbbbbbbbG",
      "GGGGGGGGGGGGGGGG"
    ],
    [
      "f               ",
      "f g  g  g  syAs ",
      "f hhhhhhdhhd  s ",
      "fghi          s ",
      "f h           s ",
      "f h  ll  prw  s ",
      "fgh j l       s ",
      "f h   l  ooo  s ",
      "f h   l  ooo  s ",
      "fgh j l       s ",
      "f h  km  nqu  s ",
      "f h           s ",
      "fghi       t  s ",
      "f hhhhhhdhhdxxs ",
      "f g  g  g  ssss ",
      "f               "
    ],
    [
      "                ",
      "  g  g  g  sEFs ",
      "  hhhhhhdhhd  s ",
      " ghB          I ",
      "  h           h ",
      "  h   D       h ",
      " gh   C       h ",
      "  h           h ",
      "  h           h ",
      " gh           h ",
      "  h           h ",
      "  h           h ",
      " ghB       t  I ",
      "  hhhhhhdhhd  s ",
      "  g  g  g  ssss ",
      "                "
    ],
    [
      "                ",
      "  g  g  g  ssss ",
      "  hhhhhhdhhd  s ",
      " ghB          I ",
      "  h           h ",
      "  h           h ",
      " gh           h ",
      "  h           h ",
      "  h           h ",
      " gh           h ",
      "  h           h ",
      "  h           h ",
      " ghB       t  I ",
      "  hhhhhhdhhdJKs ",
      "  g  g  g  ssss ",
      "                "
    ],
    [
      "                ",
      "  g  g  g  ssss ",
      "  hhhhhhdhhd  s ",
      " gh           s ",
      "  h           s ",
      "  h           s ",
      " gh           s ",
      "  h           s ",
      "  h           s ",
      " gh           s ",
      "  h           s ",
      "  h           s ",
      " gh        t  s ",
      "  hhhhhhdhhd Ls ",
      "  g  g  g  ssss ",
      "                "
    ],
    [
      "                ",
      " MMMMMMMM  ssss ",
      " MMMMMMMMhhdIIs ",
      " MMIIIIII   IIs ",
      " M IIIIIIIIIIIs ",
      " MMIIIIIIIIIIIs ",
      " MMIIIIIIIIIIIs ",
      " MMIIIIIIIIIIIs ",
      " MMIIIIIIIIIIIs ",
      " MMIIIIIIIIIIIs ",
      " MMIIIIIIIIIIIs ",
      " MMIIIIIIIIIIIs ",
      " MMIIIIII  tIIs ",
      " MMMMMMMMhhdIIs ",
      " MMMMMMMM  ssss ",
      "                "
    ]
  ]
}