{
  "name": "building_lab1_base1",
  "refpalette": "c70cities:building_lab1_base1_palette",
  "xsize": 16,
  "zsize": 16,
  "slices": [
    [
      "zzzzzzzzzzzzzzzz",
      "z==============z",
      "z==============z",
      "z=====a=aa!====z",
      "z=======aa=====z",
      "z=======a======z",
      "z==============z",
      "z========a===b=z",
      "z=====a========z",
      "z==============z",
      "z==============z",
      "z=====!cc======z",
      "z=====ccc======z",
      "z=====ccc======z",
      "z==============z",
      "z==============z"
    ],
    [
      "zzzzzzzzzzzzzzzz",
      "zzzzzzdddddzzzzz",
      "zzddddaaaaaddddz",
      "zdef dgggggdhidz",
      "zdj  k  l edmhdz",
      "zd  ndo   edp dz",
      "zzddddq   ed rdz",
      "zdsstdf  uwd xdz",
      "zdy  AB    C  dz",
      "zdDE d  FIIdfedz",
      "zdJ KddLdddd!Edz",
      "zdM NdO PdQR  dz",
      "zdS sdT UdQ  Vdz",
      "zdW sddXYdZ 0Vdz",
      "zzdddzdddzdddddz",
      "zzzzzzzzzzzzzzzz"
    ],
    [
      "zzzzzzzzzzzzzzzz",
      "zzzzzzaa11azzzzz",
      "zz1111luBB21111z",
      "z1   1     1331z",
      "z1j  4     1331z",
      "z1   12    1  1z",
      "z111115   e1  1z",
      "z16  1     1 71z",
      "z1   8     9  1z",
      "z1   1   @U1  1z",
      "z#   $1%1111^ 1z",
      "z#   $&  1Q   1z",
      "z#  6$&  1    1z",
      "z1*()11 +1   61z",
      "z111111--111111z",
      "zzzzzzzzzzzzzzzz"
    ],
    [
      "zzzzzzzzzzzzzzzz",
      "zzzzzz1a111zzzzz",
      "zz1111    21111z",
      "z1   1     1331z",
      "z1j  [     1331z",
      "z1   12    1 ]1z",
      "z11111     1  1z",
      "z1   1     1 {1z",
      "z1   }     [  1z",
      "z1   1     1  1z",
      "z1   11-1111  1z",
      "z1   1\\  1    1z",
      "z1   1\\  1    1z",
      "z1|`F11 :1    1z",
      "z11111111111111z",
      "zzzzzzzzzzzzzzzz"
    ],
    [
      "zzzzzzzzzzzzzzzz",
      "zzzzzz11111zzzzz",
      "zz1111;;;;;1111z",
      "z1   1;;;;;1''1z",
      "z1j  1;;;;;1''1z",
      "z1   1;;;;;1 ]1z",
      "z11111,.,.,1  1z",
      "z1///1;;;;;1 {1z",
      "z1;;;1;;;;;1,,1z",
      "z1;;;1;;;;;1;;1z",
      "z1,.,1111111;;1z",
      "z1;;;1/;;1;;;;1z",
      "z1;;;1/;;1;;;;1z",
      "z1;;;11;;1;;;;1z",
      "z11111111111111z",
      "zzzzzzzzzzzzzzzz"
    ],
    [
      "zzzzzzzzzzzzzzzz",
      "zzzzzzzzzzzzzzzz",
      "zz1111zzzzzzzzzz",
      "z11111zzzzzz11zz",
      "z1j111zzzzzz11zz",
      "z11111zzzzzz11zz",
      "z11111zzzzzz11zz",
      "zzzzzzzzzzzz1bzz",
      "zzzzzzzzzzzzzzzz",
      "zzzzzzzzzzzzzzzz",
      "zzzzzzzzzzzzzzzz",
      "zzzzzzzzzzzzzzzz",
      "zzzzzzzzzzzzzzzz",
      "zzzzzzzzzzzzzzzz",
      "zzzzzzzzzzzzzzzz",
      "zzzzzzzzzzzzzzzz"
    ]
  ]
}