{
  "name": "building_apartment1_floor1",
  "refpalette": "c70cities:building_apartment1_floor1_palette",
  "xsize": 16,
  "zsize": 16,
  "slices": [
    [
      "                ",
      " aaaaaaaaaaaaaa ",
      " abbbbbbbbbbbba ",
      " abbbbbbbbbbbba ",
      " abbbbbbbbbbbba ",
      " abbbbbbbbbbbba ",
      " abbbbbbbbbbbba ",
      " abbbbbbbbbbbba ",
      " abbbbbbbbbbbba ",
      " abbbbbbbbbbbba ",
      " abbbbbbbbcbbd  ",
      " abbbbbbbb bbe  ",
      " abbbbbbbb  fe  ",
      " abbbbbbbbdghi  ",
      " aaaaaaaaa      ",
      "                "
    ],
    [
      "                ",
      " jkkkkkkkkkkkkl ",
      " mnoo pqr po st ",
      " m uu w   pu  t ",
      " m    pxyxx  At ",
      " m BC p     BCt ",
      " mpppDpyppppppt ",
      " mqrE      pFFt ",
      " m  I      I  t ",
      " mppE JKKpppLpt ",
      " mMN     p   d  ",
      " mO   P Qp  Rd  ",
      " mS   P Tp  Ud  ",
      " mV     !pWWdd  ",
      " XYYYYYYYY      ",
      "                "
    ],
    [
      "                ",
      " pppppppppppppp ",
      " Z0   p  1po  Z ",
      " Z    2   pu  Z ",
      " Z    px3xx   Z ",
      " p    p      4p ",
      " 5ppp6p3ppppppp ",
      " 7  E      p  p ",
      " 7  8      8  p ",
      " 5ppE    ppp9pp ",
      " 7 @     p   h  ",
      " 7      #p   W  ",
      " 7$     #p %Rd  ",
      " 7^      pdddd  ",
      " 57ZZZZZ7p      ",
      "                "
    ],
    [
      "                ",
      " ppZZppZZppZZpp ",
      " Z&   p  *p  (Z ",
      " Z)   p   p  +Z ",
      " Z-   pxxxx  [Z ",
      " p    p       p ",
      " 5ppppppppppppp ",
      " Z  E      p  Z ",
      " Z  E      p  Z ",
      " 5ppE    pppppp ",
      " 7       p   d  ",
      " Z       p   d  ",
      " Z       pU] d  ",
      " Z {{}\\\\ pdd|`  ",
      " 57ZZZZZ7p      ",
      "                "
    ],
    [
      "                ",
      " ppkkppkkppkkpp ",
      " 7    p   p   7 ",
      " 7    p   p   7 ",
      " 7    pxxxx   7 ",
      " p    p       p ",
      " 5ppppppppppppp ",
      " 7  E      p  7 ",
      " 7  E      pf 7 ",
      " 5ppE    pppppp ",
      " 7       p   |  ",
      " 7       p:  |  ",
      " 7       p]  |  ",
      " 7       peWWd  ",
      " 57777777p      ",
      "                "
    ],
    [
      "                ",
      " pppppppppppppp ",
      " pddddp;;;ddddp ",
      " pddddp;;;ddddp ",
      " pddddpdddddddp ",
      " pddddpdddddddp ",
      " pppppppppppppp ",
      " p;;dddddddpddp ",
      " p;;dddddddpddp ",
      " pdddddddpppppp ",
      " pdddddddpU  d  ",
      " pdddddddpc  d  ",
      " pdddddddp   d  ",
      " pdddddddpdddd  ",
      " ppppppppp      ",
      "                "
    ]
  ]
}