{
  "name": "building_warehouse1_ground_270",
  "refpalette": "c70cities:building_warehouse1_ground_palette_270",
  "xsize": 16,
  "zsize": 16,
  "slices": [
    [
      "zazazzzzzzzzaaaz",
      "zaaaazaazzaazaaz",
      "zzaaaaaaaaaaaaaz",
      "zaaaaaaaaaaaaazz",
      "zdbbbddbdbbddbbz",
      "zbbbbbbbbbbbbbbz",
      "zbbbbbbcccccccbz",
      "zbbbbbbcccccccbz",
      "zdbbbbbcccccccbz",
      "zbbbbbbcccccccbz",
      "zbbbbbbcccccccbz",
      "zbbbbbbcccccccbz",
      "zdbbbbbcccccccbz",
      "zdbbbdbcccccccbz",
      "zbbbdbbbbbbbbbbz",
      "zzzzzzzzzzzzzzzz"
    ],
    [
      "e   e  e  e     ",
      "               e",
      "                ",
      "                ",
      "e              e",
      "  gg  fhhhghhhf ",
      "  ggppgi      g ",
      "u fq  g      ife",
      "  gr         jg ",
      "e s       m jjge",
      "  t         jjf ",
      "e g      nnjjjge",
      "  fgppgi nnjjkg ",
      "u gf  fonnnjklf ",
      "      gfgggggfge",
      " e  e e  e  e e "
    ],
    [
      "                ",
      "                ",
      "                ",
      "                ",
      "                ",
      "  fg  ghhhghhhf ",
      "  gfppg       g ",
      "  g   g       g ",
      "  gw          f ",
      "  x           p ",
      "  y          jp ",
      "  g          jg ",
      "  ggppg  n i jf ",
      "  fg  fo nn!jjf ",
      "      fggggfggg ",
      "                "
    ],
    [
      "                ",
      "                ",
      "                ",
      "                ",
      "                ",
      "  gg  ghhhfhhhg ",
      "  fgppg       g ",
      "  f   g       g ",
      "  gB  A       g ",
      "  C   A       g ",
      "  C   A       g ",
      "  g   A      ig ",
      "  gfppf      jf ",
      "  gg  goin  jjg ",
      "      ggfgggfgg ",
      "                "
    ],
    [
      "                ",
      "                ",
      "                ",
      "                ",
      " DDDDDDDDDDDDD  ",
      " DggDDfgfgggggg ",
      " DggEEgEEEiEEEf ",
      " Dg   fi     ig ",
      " DgF  gC  F  ig ",
      " Dg   gC      g ",
      " Dg   gC      g ",
      " DgB  gC      g ",
      " DggEEg       g ",
      " DggDDgo     ig ",
      " DDDDDfgggggggf ",
      "                "
    ],
    [
      "                ",
      "                ",
      "                ",
      "                ",
      "                ",
      "  JJJJggggfgfgg ",
      "  JJJJgIIIIIIIg ",
      "  JJJJgIIIIIIIg ",
      "  JJJJgIIIbIIIg ",
      "  JJJJgIIIIIIIg ",
      "  JJJJgIIIIIIIf ",
      "  JJJJgIIIIIIIg ",
      "  JJJJgIIIIIIIg ",
      "  JJJJgoIIIIIIg ",
      "      ggggggggg ",
      "                "
    ]
  ]
}