{
  "name": "building_policeoffice1_top",
  "refpalette": "c70cities:building_policeoffice1_top_palette",
  "xsize": 16,
  "zsize": 16,
  "slices": [
    [
      "                ",
      "  aaaaaaaaaa    ",
      "  abbbbbbbba    ",
      "  abbbbbbbba    ",
      "  abb!bbb!ba    ",
      "  abbbbbbbba    ",
      "  abbbbbbbba    ",
      "  abbbbbbbba    ",
      "  abbbbbbbba    ",
      "  abbbbbbbba    ",
      "  abbbbbbbba    ",
      " cccbccccccccdcc",
      " cebbbbbbbbb   f",
      " cebbbbbbbbb   f",
      " cgcccgcccgcccgc",
      "                "
    ],
    [
      "                ",
      "  aaaaaaaaaa    ",
      "  a  hhhh  a    ",
      "  aigg  gg a    ",
      "  a ggj ggja    ",
      "  a h   h  a    ",
      "  a hhhhh  a    ",
      "  a     h  a    ",
      "  a     h  a    ",
      "  a     h  a    ",
      "  a     h ka    ",
      " ccc ccccccccdcc",
      " c         l   c",
      " c         l   c",
      " cgcccgcccgcccgc",
      "                "
    ],
    [
      "                ",
      "   mmmmmmmm     ",
      "  n        o    ",
      "  n gg  gg o    ",
      "  n gg  gg o    ",
      "  n        o    ",
      "  n        o    ",
      "  n        o    ",
      "  n        o    ",
      "  n        o    ",
      "  n        o    ",
      " ccc ccccccccdcc",
      " c             p",
      " c             p",
      " cgcccgcccgcccgc",
      "                "
    ],
    [
      "                ",
      "                ",
      "                ",
      "                ",
      "    q   q       ",
      "                ",
      "                ",
      "                ",
      "                ",
      "                ",
      "                ",
      " ccccccccccccdcc",
      " c             p",
      " c             p",
      " cgcccgcccgcccgc",
      "                "
    ],
    [
      "                ",
      "                ",
      "                ",
      "    q   q       ",
      "   qq   qq      ",
      "                ",
      "                ",
      "                ",
      "                ",
      "                ",
      "                ",
      " ccccccccccccccc",
      " c             c",
      " c             c",
      " ccccccccccccccc",
      "                "
    ],
    [
      "                ",
      "                ",
      "                ",
      "    r   r       ",
      "   r     r      ",
      "                ",
      "                ",
      "                ",
      "                ",
      "                ",
      "                ",
      " ccccccccccccccc",
      " ccccccccccccccc",
      " ccccccccccccccc",
      " ccccccccccccccc",
      "                "
    ]
  ]
}