{
  "name": "building_bunker1_ground_180",
  "refpalette": "c70cities:building_bunker1_ground_palette_180",
  "xsize": 16,
  "zsize": 16,
  "slices": [
    [
      "zzzzzzzzzzzzzzzz",
      "zzzzzzzzzzzzzzzz",
      "zzzzzzzzzzzzzzzz",
      "zzzzzzzzzzzzzzzz",
      "zzzzzzzzzzzzzzzz",
      "zzzzzzzzzzzzzzzz",
      "zzzzzzzzzzzzzzzz",
      "zazzzzzzzzvvbzzz",
      "zazzzzzzzzvcvzzz",
      "zzazzzzzzzvvbzzz",
      "zazzzzazzzzzzzzz",
      "zaaazaazzzzzzzzz",
      "zzazazzazzzzzzzz",
      "zzaazzazazzzzzzz",
      "zzazaazazzzzzzzz",
      "zzzzzzzzzzzzzzzz"
    ],
    [
      "d d d           ",
      " eee eefddd fee ",
      " ef g fff   ffe ",
      "deff d d   g fe ",
      " efd    i     e ",
      "de d      h  d  ",
      " dg      hh     ",
      "   d   ~ hhf  d ",
      "         hhff   ",
      " d       hh fgd ",
      "         h      ",
      "            f ed",
      "             fed",
      "     d   dg ffe ",
      "   d     d eeee ",
      "            d   "
    ],
    [
      "                ",
      "                ",
      "  f          f  ",
      "                ",
      "                ",
      "                ",
      "                ",
      "       ~  h     ",
      "          hf    ",
      "                ",
      "                ",
      "                ",
      "             f  ",
      "                ",
      "                ",
      "                "
    ],
    [
      "                ",
      "                ",
      "                ",
      "                ",
      "                ",
      "                ",
      "                ",
      "       ~        ",
      "                ",
      "                ",
      "                ",
      "                ",
      "                ",
      "                ",
      "                ",
      "                "
    ],
    [
      "                ",
      "                ",
      "                ",
      "                ",
      "                ",
      "                ",
      "                ",
      "       ~        ",
      "                ",
      "                ",
      "                ",
      "                ",
      "                ",
      "                ",
      "                ",
      "                "
    ],
    [
      "                ",
      "                ",
      "                ",
      "                ",
      "                ",
      "                ",
      "                ",
      "       ~        ",
      "                ",
      "                ",
      "                ",
      "                ",
      "                ",
      "                ",
      "                ",
      "                "
    ]
  ]
}