{
  "name": "building_apartment1_floor2",
  "refpalette": "c70cities:building_apartment1_floor2_palette",
  "xsize": 16,
  "zsize": 16,
  "slices": [
    [
      "                ",
      " aaaaaaaaaaaaaa ",
      " abbbbbbbbbbbba ",
      " abbbbbbbbbbbba ",
      " abbbbbbbbbbbba ",
      " abbbbbbbbbbbba ",
      " abbbbbbbbbbbba ",
      " abbbbbbbbbbbba ",
      " abbbbbbbbbbbba ",
      " abbbbbbbbbbbba ",
      " abbbbbbbbcbbd  ",
      " abbbbbbbb bbe  ",
      " abbbbbbbb  fe  ",
      " abbbbbbbbdghi  ",
      " aaaaaaaaa      ",
      "                "
    ],
    [
      "                ",
      " jkkkkkkkkkkkkl ",
      " mnoopqr  q!sot ",
      " m uu w  xq  ut ",
      " m    qyAyy  Bt ",
      " m CD q     CDt ",
      " mqqqEqAqqqqqqt ",
      " mFrI      qJJt ",
      " m  K      K  t ",
      " mqqI LMMqqqNqt ",
      " mOP     q   d  ",
      " mQ   R Sq  Td  ",
      " mU   R Vq  Wd  ",
      " mX      qYYdd  ",
      " Z00000000      ",
      "                "
    ],
    [
      "                ",
      " qqqqqqqqqqqqqq ",
      " 12   q  3q   1 ",
      " 1    45  q   1 ",
      " 1    qy6yy   1 ",
      " q    q       q ",
      " 7qqq8q6qqqqqqq ",
      " 9  I      q  q ",
      " 9  @      @  q ",
      " 7qqI   #qqq$qq ",
      " 9       q   h  ",
      " 9      %q   Y  ",
      " 9^     %q &Td  ",
      " 9*      qdddd  ",
      " 79111119q      ",
      "                "
    ],
    [
      "                ",
      " qq11qq11qq11qq ",
      " 1(   q  )q  +1 ",
      " 1-   q   q  [1 ",
      " 1]   qyyyy  {1 ",
      " q    q       q ",
      " 7qqqqqqqqqqqqq ",
      " 1  I      q  1 ",
      " 1  I      q  1 ",
      " 7qqI }  qqqqqq ",
      " 9       q   d  ",
      " 1      \\q   d  ",
      " 1      \\qW| d  ",
      " 1 `:;', qdd./  ",
      " 79111119q      ",
      "                "
    ],
    [
      "                ",
      " qqkkqqkkqqkkqq ",
      " 9    q   q   9 ",
      " 9    q   q   9 ",
      " 9    qyyyy   9 ",
      " q    q       q ",
      " 7qqqqqqqqqqqqq ",
      " 9  I      q  9 ",
      " 9  I      qf 9 ",
      " 7qqI <  qqqqqq ",
      " 9       q   .  ",
      " 9       q>  .  ",
      " 9       q|  .  ",
      " 9       qeYYd  ",
      " 79999999q      ",
      "                "
    ],
    [
      "                ",
      " qqqqqqqqqqqqqq ",
      " qddddq???ddddq ",
      " qddddq???ddddq ",
      " qddddqdddddddq ",
      " qddddqdddddddq ",
      " qqqqqqqqqqqqqq ",
      " q??dddddddqddq ",
      " q??dddddddqddq ",
      " qdddddddqqqqqq ",
      " qdddddddqW  d  ",
      " qdddddddqc  d  ",
      " qdddddddq   d  ",
      " qdddddddqdddd  ",
      " qqqqqqqqq      ",
      "                "
    ]
  ]
}