{
  "name": "building_office5_floor2_180",
  "refpalette": "c70cities:building_office5_floor2_palette_180",
  "xsize": 16,
  "zsize": 16,
  "slices": [
    [
      "                ",
      "                ",
      "  dbdbdbdbdbdd  ",
      "  beeeeeeeeeeb  ",
      "  deeeeeeeeeed  ",
      "  beeeeeeeeeeb  ",
      "  deeeeeeeeeed  ",
      "  beeeeeeeeeeb  ",
      "  deeeeeeeeeed  ",
      "  beeeeffeeeeb  ",
      "  ddddddddeedd  ",
      "    accccccca   ",
      "    bcccccccb   ",
      "    ababababa   ",
      "                ",
      "                "
    ],
    [
      "                ",
      "                ",
      "  dbdbdbdbdbdd  ",
      "  b   n      b  ",
      "  d n     n  d  ",
      "  b gg gg gg b  ",
      "  d     l   md  ",
      "  b  l       b  ",
      "  d          d  ",
      "  b    ffk  kb  ",
      "  dddddddd  dd  ",
      "    ajihgg  a   ",
      "    b       b   ",
      "    ababababa   ",
      "                ",
      "                "
    ],
    [
      "                ",
      "                ",
      "  dbdbdbdbdbdd  ",
      "  b          b  ",
      "  d          d  ",
      "  b p     p  b  ",
      "  d          d  ",
      "  b          b  ",
      "  d          d  ",
      "  b    ffk  kb  ",
      "  dd!ddddd  dd  ",
      "    a   o   a   ",
      "    b       b   ",
      "    ababababa   ",
      "                ",
      "                "
    ],
    [
      "                ",
      "                ",
      "  dbdbdbdbdbdd  ",
      "  b          b  ",
      "  d          d  ",
      "  b          b  ",
      "  d          d  ",
      "  b          b  ",
      "  d          d  ",
      "  b    ff    b  ",
      "  ddrdddddrrdd  ",
      "    aqqqq   a   ",
      "    b       b   ",
      "    ababababa   ",
      "                ",
      "                "
    ],
    [
      "                ",
      "                ",
      "  dbdbdbdbdbdd  ",
      "  b          b  ",
      "  d          d  ",
      "  b          b  ",
      "  d          d  ",
      "  b          b  ",
      "  d          d  ",
      "  b    ff    b  ",
      "  dddddddddddd  ",
      "    a       a   ",
      "    b       b   ",
      "    ababababa   ",
      "                ",
      "                "
    ],
    [
      "                ",
      "                ",
      "  dbdbdbdbdbdd  ",
      "  bssssssssssb  ",
      "  dssssssssssd  ",
      "  bssssssssssb  ",
      "  dssssssssssd  ",
      "  bssssssssssb  ",
      "  dssssssssssd  ",
      "  bssssffssssb  ",
      "  dddddddddddd  ",
      "    a       a   ",
      "    b       b   ",
      "    ababababa   ",
      "                ",
      "                "
    ]
  ]
}