{
  "name": "building_residential1_ground_180",
  "refpalette": "c70cities:building_residential1_ground_palette_180",
  "xsize": 16,
  "zsize": 16,
  "slices": [
    [
      "GGGGGGGGGGGGGGGG",
      "GGGGGGGGGGGGGGGG",
      "GGGGGGGGGGGGGGGG",
      "GGGccccccccccGGG",
      "GGGceeddddddcGGG",
      "GGGceeddddddcGGG",
      "GGGceeddddddcGGG",
      "GGaceeddddddcaGG",
      "GGabbbbbbbbbbaGG",
      "GGabbbbbbbbbbaGG",
      "GGabbbbbbbbbbaGG",
      "GGabbbbbbbbbbaGG",
      "GGabbbbbbbbbbaGG",
      "GGaaaaaaaaaaaaGG",
      "GGGGGGGGGGGGGGGG",
      "GGGGGGGGGGGGGGGG"
    ],
    [
      "fgggghgggghggggf",
      "g              g",
      "g yyyyyyyyyyyy g",
      "g yccccccccccy g",
      "g ycLE!IKJIFcy g",
      "h yc E      cy h",
      "g ycDC   BAAcy g",
      "g icxx    wwci g",
      "g j    u    tj g",
      "g j sssss   rj g",
      "f iq   po nnni f",
      "g j          m  ",
      "g j    ll    k  ",
      "g iijjjiijjjii f",
      "g              g",
      "fgggghgggghggggf"
    ],
    [
      "fgggghgggghggggf",
      "g              g",
      "g              g",
      "g  cccTTTTccc  g",
      "g  c E  W  Vc  g",
      "h  U E      T  h",
      "g  c S   R  c  g",
      "g icxx     Qci g",
      "g j   u      j g",
      "g j sssss    j g",
      "f iP      nnni f",
      "g j          O  ",
      "g j    NN    M  ",
      "g iijjjiijjjii f",
      "g              g",
      "fgggghgggghggggf"
    ],
    [
      "                ",
      "                ",
      "  111111111111  ",
      "   cccccccccc   ",
      "   c E      c   ",
      "   U E      T   ",
      "   c E      c   ",
      "  icxx      ci  ",
      "  Z  u       Y  ",
      "  Z sssss    Y  ",
      "0 i       nnni  ",
      "  Z          Y  ",
      "  Z          Y  ",
      "  iiXXXiiXXXii  ",
      "                ",
      "                "
    ],
    [
      "                ",
      "                ",
      "  555555555555  ",
      "  444444444444  ",
      "  1c32111111c1  ",
      "   c32      c   ",
      "   c32      c   ",
      "  icxx      ci  ",
      "  ibu        i  ",
      "  ibbbbbbbbbbi  ",
      "  ibbbbbbbbbbi  ",
      "  ibbbbbbbbbbi  ",
      "  ibbbbbbbbbbi  ",
      "  iiiiiiiiiiii  ",
      "                ",
      "                "
    ],
    [
      "                ",
      "                ",
      "                ",
      "                ",
      "  555555555555  ",
      "  444444444444  ",
      "  1c-E111111c1  ",
      "  icxx      ci  ",
      "  j +++++++++j  ",
      "  j      888 j  ",
      "  j   )( 8%$Yj  ",
      "  j  *&^ 8%$Yj  ",
      "  j#  @9 8887j  ",
      "  iiiiiiiiiiii  ",
      " 66666666666666 ",
      "                "
    ]
  ]
}