{
  "name": "building_bunker1_base1_180",
  "refpalette": "c70cities:building_bunker1_base1_palette_180",
  "xsize": 16,
  "zsize": 16,
  "slices": [
    [
      "================",
      "======aa=aaa====",
      "======aaaaaa====",
      "======aa========",
      "======aaaaaa====",
      "======aa=aaa====",
      "================",
      "================",
      "================",
      "================",
      "==aaaaaa========",
      "==aaaaaa========",
      "==aaaaaa========",
      "==aaaaaa========",
      "================",
      "================"
    ],
    [
      "zbbbbbbbbbbbbzzz",
      "zbXWVbUUbTKJbzzz",
      "zbS  R  O  Nbzzz",
      "zbbbbb  bbbbbzzz",
      "zbIQPb  O  Nbzzz",
      "zbM  b nbLKJbzzz",
      "zbI  bFbEbbbbbbb",
      "zbD  C nb  obBAb",
      "zbyy    x  wb sb",
      "zbu    tb ssb  b",
      "zbqrq  pbbbbb ob",
      "zbn     m     lb",
      "zbk     b     jb",
      "zbihgefebdddbccb",
      "zbbbbbbbbbbbbbbb",
      "zzzzzzzzzzzzzzzz"
    ],
    [
      "zEEEEE;EEEEEEzzz",
      "z{:`|E TET\\}Ezzz",
      "z{ ]][  *  -Ezzz",
      "zEEEEE  EEEEEzzz",
      "zE+)(E  *  &Ezzz",
      "zE   E 6EL10Ezzz",
      "zE^  E%EEEEEEEEE",
      "zE     6E   E$AE",
      "zE      #  wE @E",
      "zE      E  sE  E",
      "zE98   7EEEEE  E",
      "zE6     5     oE",
      "z4      E      E",
      "z4   32LE   E10E",
      "zZYYYEEEEEEEEEEE",
      "zzzzzzzzzzzzzzzz"
    ],
    [
      "zEEEEEEEEEEEEzzz",
      "zE\u00c2\u00c1 E\u00c0\u00c0E  fEzzz",
      "zE \u00a7\u00a5E  E>  Ezzz",
      "zEEEEE  EEEEEzzz",
      "zE\u00a4\u00a3?E  E>  Ezzz",
      "zE/  E 6E <fEzzz",
      "zE/  EEEEEEEEEEE",
      "zE     6E   E!AE",
      "zE      {  wE  E",
      "zE      E   E  E",
      "zE      EEEEE  E",
      "zE6     E      E",
      "zE      E      E",
      "zE......E,,,E' E",
      "zEEEEEEEEEEEEEEE",
      "zzzzzzzzzzzzzzzz"
    ],
    [
      "zEEEEEEEEEEEEzzz",
      "zE\u00c5\u00c3\u00c3E\u00c5\u00c5E\u00c3\u00c3\u00c5Ezzz",
      "zE\u00c5\u00c3\u00c3E\u00c3\u00c3E\u00c3\u00c3\u00c6Ezzz",
      "zEEEEE\u00c3\u00c3EEEEEzzz",
      "zEE\u00c5EE\u00c3\u00c3E\u00c3\u00c3\u00c6Ezzz",
      "zEE\u00c5EE\u00c3\u00c3E\u00c3\u00c3\u00c5Ezzz",
      "zEE\u00c5EEEEEEEEEEEE",
      "zE\u00c3\u00c3\u00c3\u00c3\u00c3\u00c3EEEEE\u00c3AE",
      "zE\u00c3\u00c3\u00c3\u00c3\u00c3\u00c3EEEwE\u00c3\u00c3E",
      "zE\u00c3\u00c3\u00c3\u00c3\u00c3\u00c3EEEEE\u00c3\u00c3E",
      "zE\u00c3\u00c3\u00c3\u00c3\u00c3\u00c3EEEEE\u00c5\u00c5E",
      "zE\u00c3\u00c3\u00c3\u00c3\u00c3\u00c3E\u00c3\u00c3\u00c3\u00c5\u00c3\u00c3E",
      "zE\u00c3\u00c3\u00c3\u00c3\u00c3\u00c3E\u00c3\u00c3\u00c3\u00c6\u00c3\u00c3E",
      "zE\u00c5\u00c5\u00c5\u00c5\u00c5\u00c5E\u00c4\u00c4\u00c4E\u00c3\u00c3E",
      "zEEEEEEEEEEEEEEE",
      "zzzzzzzzzzzzzzzz"
    ],
    [
      "zzzzzzzzzzzzzzzz",
      "zzzzzzzzzzzzzzzz",
      "zzzzzzzzzzzzzzzz",
      "zzzzzzzzzzzzzzzz",
      "zzzzzzzzzzzzzzzz",
      "zzzzzzzzzzzzzzzz",
      "zzzzzzzzzzzzzzzz",
      "zzzzzzzzzzzEzzzz",
      "zzzzzzzzzzEwEzzz",
      "zzzzzzzzzzzEzzzz",
      "zzzzzzzzzzzzzzzz",
      "zzzzzzzzzzzzzzzz",
      "zzzzzzzzzzzzzzzz",
      "zzzzzzzzzzzzzzzz",
      "zzzzzzzzzzzzzzzz",
      "zzzzzzzzzzzzzzzz"
    ]
  ]
}