{
  "name": "building_hotel1_floor1_270",
  "refpalette": "c70cities:building_hotel1_floor1_palette_270",
  "xsize": 16,
  "zsize": 16,
  "slices": [
    [
      "                ",
      " aadddddddaaaaa ",
      " abbbbbbbbcbbba ",
      " abbbbbbbbcbbba ",
      " abbbbbbbbcbbba ",
      " abbbbbbbbcbbba ",
      " abbbb    cbbba ",
      " abbbb    cbbba ",
      " gbbbb    cbbba ",
      " gbbbbe   cbbba ",
      " gbbbbbbbdcbbba ",
      " gbbbbbbbbcbbba ",
      " gbbbbbbbbcbbba ",
      " abbbbbbbbcbbba ",
      " aaffffaaaaaaaa ",
      "                "
    ],
    [
      "                ",
      " aaaaaaaaaaaaaa ",
      " aq   q q aj ha ",
      " at    t  aj  a ",
      " ar   r r ak  a ",
      " a        al  a ",
      " aq       al  a ",
      " at   e   am  a ",
      " ar   e   an  a ",
      " a    d   a   a ",
      " aq    ss a   a ",
      " at          ia ",
      " ar       po ia ",
      " at    t  p  ia ",
      " aaffffaaaaaaaa ",
      "                "
    ],
    [
      "                ",
      " aaaaaffffaaaaa ",
      " a        a   a ",
      " fx   xxx a   a ",
      " f        au  a ",
      " f        a   a ",
      " f    ee  a   a ",
      " fx   d   a   a ",
      " f        aw  a ",
      " a        a   a ",
      " a        a   a ",
      " ax           a ",
      " a            a ",
      " ay    y      a ",
      " aaffffaaaaaaaa ",
      "                "
    ],
    [
      "                ",
      " aaaaaaaaaaaaaa ",
      " a        a   a ",
      " a        a   a ",
      " a        a   a ",
      " a        a   a ",
      " a     deea   a ",
      " a        a   a ",
      " a        a   a ",
      " a        a   a ",
      " a        a   a ",
      " a            a ",
      " a            a ",
      " ay    y      a ",
      " aaffffaaaaaaaa ",
      "                "
    ],
    [
      "                ",
      " aaaaaaaaaaffaa ",
      " a        a   a ",
      " a        a   a ",
      " a        a   a ",
      " a        a   a ",
      " a       da   a ",
      " f       ea   a ",
      " f       ea   a ",
      " a        a   a ",
      " a        a   a ",
      " a        a   a ",
      " a        a   a ",
      " a        a   a ",
      " aaffffaaaaaaaa ",
      "                "
    ],
    [
      "                ",
      " aaaaaaaaaaaaaa ",
      " aAAAAAAAAaAAAa ",
      " aAAAAAAAAaAAAa ",
      " aAAAAAAAAaAAAa ",
      " aAAAAAAAAaAAAa ",
      " aAAAA    aAAAa ",
      " aAAAA    aAAAa ",
      " aAAAA   daAAAa ",
      " aAAAA   eaAAAa ",
      " aAAAAAAAAaAAAa ",
      " aAAAAAAAAaAAAa ",
      " aAAAAAAAAaAAAa ",
      " aAAAAAAAAaAAAa ",
      " aaffffaaaaaaaa ",
      "                "
    ]
  ]
}