{
  "name": "building_apartment1_floor2_90",
  "refpalette": "c70cities:building_apartment1_floor2_palette_90",
  "xsize": 16,
  "zsize": 16,
  "slices": [
    [
      "                ",
      " aaaaaaaaa      ",
      " abbbbbbbbdeei  ",
      " abbbbbbbbbbfh  ",
      " abbbbbbbbbb g  ",
      " abbbbbbbbc  d  ",
      " abbbbbbbbbbbba ",
      " abbbbbbbbbbbba ",
      " abbbbbbbbbbbba ",
      " abbbbbbbbbbbba ",
      " abbbbbbbbbbbba ",
      " abbbbbbbbbbbba ",
      " abbbbbbbbbbbba ",
      " abbbbbbbbbbbba ",
      " aaaaaaaaaaaaaa ",
      "                "
    ],
    [
      "                ",
      " ltttttttt      ",
      " kouBDqJ qdddd  ",
      " ks  CqJ N TWd  ",
      " k!   qqKq   Y  ",
      " kqqy q  q   Y  ",
      " k xy q  qqqqq0 ",
      " k  A q  M SV 0 ",
      " kr y A  M    0 ",
      " kqwqqq  L RR 0 ",
      " kp   E       0 ",
      " kou DqIKI    0 ",
      " kou Cqr qP   0 ",
      " kn   qF qOQUX0 ",
      " jmmmmmmmmmmmmZ ",
      "                "
    ],
    [
      "                ",
      " q111qqqqq      ",
      " q    q  qhYdd  ",
      " q    q  $  Td  ",
      " q    qq@q  &d  ",
      " qqqy q  q   d  ",
      " q3 y q  qqqqqq ",
      " q  6 q  # %% 9 ",
      " q 5y 6       1 ",
      " qq4qqq       1 ",
      " q    8       1 ",
      " q    qI@I    1 ",
      " q    q  q    1 ",
      " q2   q  q  ^*9 ",
      " q111q799799997 ",
      "                "
    ],
    [
      "                ",
      " q111qq11q      ",
      " q+[{ q  qddd.  ",
      " 1    q  q   ,  ",
      " 1    qqqq  \\d  ",
      " qqqy q  q  Wd  ",
      " q) y q  qqqqqq ",
      " 1  y q    }} 9 ",
      " 1  y q      '1 ",
      " qqqqqq      ;1 ",
      " q    q      :1 ",
      " 1    qIII   `1 ",
      " 1    q  q   |1 ",
      " q(-] q  q    9 ",
      " q111q711791117 ",
      "                "
    ],
    [
      "                ",
      " q999qq99q      ",
      " q    q  q,,,d  ",
      " k    q fq   Y  ",
      " k    qqqq   Y  ",
      " qqqy q  q /\\e  ",
      " q  y q  qqqqqq ",
      " k  y q       9 ",
      " k  y q       9 ",
      " qqqqqq       9 ",
      " q    q       9 ",
      " k    qIII    9 ",
      " k    q  q    9 ",
      " q    q  q    9 ",
      " q999q799799997 ",
      "                "
    ],
    [
      "                ",
      " qqqqqqqqq      ",
      " qddddqddqdddd  ",
      " qddddqddq   d  ",
      " qddddqqqq   d  ",
      " qddddqddqWc d  ",
      " q<<ddqddqqqqqq ",
      " q<<ddqdddddddq ",
      " q<<ddqdddddddq ",
      " qqqqqqdddddddq ",
      " qddddqdddddddq ",
      " qddddqdddddddq ",
      " qddddq<<dddddq ",
      " qddddq<<dddddq ",
      " qqqqqqqqqqqqqq ",
      "                "
    ]
  ]
}