{
  "name": "building_office5_top",
  "refpalette": "c70cities:building_office5_top_palette",
  "xsize": 16,
  "zsize": 16,
  "slices": [
    [
      "                ",
      "                ",
      "   aaaaaaaaa    ",
      "   b       b    ",
      "   b       b    ",
      "  cccccccccccc  ",
      "  deeeeffeeeed  ",
      "  ceeeeeeeeeec  ",
      "  deeeeeeeeeed  ",
      "  ceeeeGGe!eec  ",
      "  deeeeGGeeeed  ",
      "  ceeeeGGeeeec  ",
      "  deeeeeeeeeed  ",
      "  ccdcdcdcdcdc  ",
      "                ",
      "                "
    ],
    [
      "                ",
      "                ",
      "                ",
      "   aaaaaaaaa    ",
      "   b       b    ",
      "  cccccccccccc  ",
      "  dghh    iigd  ",
      "  cj k       c  ",
      "  d          d  ",
      "  clll mn o  c  ",
      "  d    pq or d  ",
      "  cs   tu o  c  ",
      "  dg        gd  ",
      "  ccdcdcdcdcdc  ",
      "                ",
      "                "
    ],
    [
      "                ",
      "                ",
      "                ",
      "                ",
      "   aaaaaaaaa    ",
      "  ccwxyccA mcc  ",
      "  d          d  ",
      "  c          c  ",
      "  d          d  ",
      "  cll     B  c  ",
      "  d       C  d  ",
      "  c       D  c  ",
      "  d          d  ",
      "  ccdcdcdcdcdc  ",
      "                ",
      "                "
    ],
    [
      "                ",
      "                ",
      "                ",
      "                ",
      "                ",
      "  cccccccccccc  ",
      "  c          c  ",
      "  c          c  ",
      "  c          c  ",
      "  c          c  ",
      "  c          c  ",
      "  c          c  ",
      "  c          c  ",
      "  cccccccccccc  ",
      "                ",
      "                "
    ],
    [
      "                ",
      "                ",
      "                ",
      "                ",
      "                ",
      "  cccccccccccc  ",
      "  cEEEEEEEEEEc  ",
      "  cEEEEEEEEEEc  ",
      "  cEEEEEEEEEEc  ",
      "  cEEEFFFFEEEc  ",
      "  cEEEFFFFEEEc  ",
      "  cEEEFFFFEEEc  ",
      "  cEEEEEEEEEEc  ",
      "  cccccccccccc  ",
      "                ",
      "                "
    ],
    [
      "                ",
      "                ",
      "                ",
      "                ",
      "                ",
      "  cccccccccccc  ",
      "  c  I       c  ",
      "  cIII       c  ",
      "  c        I c  ",
      "  cII      I c  ",
      "  c I      I c  ",
      "  c I      IIc  ",
      "  c I        c  ",
      "  cccccccccccc  ",
      "                ",
      "                "
    ]
  ]
}