{
  "name": "building_residential1_ground_270",
  "refpalette": "c70cities:building_residential1_ground_palette_270",
  "xsize": 16,
  "zsize": 16,
  "slices": [
    [
      "GGGGGGGGGGGGGGGG",
      "GGGGGGGGGGGGGGGG",
      "GGGGGGGaaaaaaaGG",
      "GGGcccccbbbbbaGG",
      "GGGcddddbbbbbaGG",
      "GGGcddddbbbbbaGG",
      "GGGcddddbbbbbaGG",
      "GGGcddddbbbbbaGG",
      "GGGcddddbbbbbaGG",
      "GGGcddddbbbbbaGG",
      "GGGceeeebbbbbaGG",
      "GGGceeeebbbbbaGG",
      "GGGcccccbbbbbaGG",
      "GGGGGGGaaaaaaaGG",
      "GGGGGGGGGGGGGGGG",
      "GGGGGGGGGGGGGGGG"
    ],
    [
      "fgggghggggf  fgf",
      "g              g",
      "g xxxxxijjimki g",
      "g xcccccsqn  i g",
      "g xcD yu  n  j g",
      "h xcE yu  n  j h",
      "g xcF A      j g",
      "g xcI    ro li g",
      "g xcJ   trp li g",
      "g xc!    r   j g",
      "h xcCCBw r   j h",
      "g xcK  w r   j g",
      "g xccccc     i g",
      "g xxxxxijjijji g",
      "g              g",
      "fgggghggggfggggf"
    ],
    [
      "fgggghggggf  fgf",
      "g              g",
      "g      ijjiNLi g",
      "g  ccQcc  n  i g",
      "g  cS     n  j g",
      "h  c      n  j h",
      "g  Q  O      j g",
      "g  QT    r  Mi g",
      "g  QU    r  Mi g",
      "g  Q    tr   j g",
      "h  cCCPw r   j h",
      "g  cV  w r   j g",
      "g  ccRcc     i g",
      "g      ijjijji g",
      "g              g",
      "fgggghggggfggggf"
    ],
    [
      "                ",
      "                ",
      "  0    iXXiXXi  ",
      "  0ccQcc  n  i  ",
      "  0c      n  W  ",
      "  0c      n  W  ",
      "  0c         W  ",
      "  0c     r   i  ",
      "  0c     r   i  ",
      "  0c     r   W  ",
      "  0cCCCwtr   W  ",
      "  0c   w r   W  ",
      "  0ccRcc     i  ",
      "  0    iYYiYYi  ",
      "                ",
      "          Z     "
    ],
    [
      "                ",
      "                ",
      "  430  iiiiiii  ",
      "  43cccc bbbbi  ",
      "  430    bbbbi  ",
      "  430    bbbbi  ",
      "  430    bbbbi  ",
      "  430    bbbbi  ",
      "  430    bbbbi  ",
      "  430    bbbbi  ",
      "  43111w bbbbi  ",
      "  43222wtbbbbi  ",
      "  43ccccbbbbbi  ",
      "  430  iiiiiii  ",
      "                ",
      "                "
    ],
    [
      "                ",
      "              5 ",
      "    430ijjjjji5 ",
      "    43cc( XX6i5 ",
      "    430 (7@@7i5 ",
      "    430 (7##7i5 ",
      "    430 (7777i5 ",
      "    430 (    i5 ",
      "    430 ( &$8i5 ",
      "    430 ( *%9i5 ",
      "    43Cw(  ^ i5 ",
      "    43)w(    i5 ",
      "    43cc     i5 ",
      "    430ijjjjji5 ",
      "              5 ",
      "                "
    ]
  ]
}