{
  "name": "building_hotel1_floor3",
  "refpalette": "c70cities:building_hotel1_floor3_palette",
  "xsize": 16,
  "zsize": 16,
  "slices": [
    [
      "                ",
      " aaaaaaaaaaaaaa ",
      " abbbbbbbbbbbba ",
      " abbbbbbbbbbbba ",
      " abbbbbbbbbbbba ",
      " abbbccccccccca ",
      " dbbbc    dbbba ",
      " dbbbc    bbbba ",
      " dbbbc    bbbba ",
      " dbbbc   ebbbbf ",
      " dbbbcccccbbbbf ",
      " dbbbbbbbcbbbbf ",
      " dbbbbbbbcbbbbf ",
      " abbbbbbbbbbbba ",
      " aaaaaaagggggaa ",
      "                "
    ],
    [
      "                ",
      " aaaaaaaaaaaaaa ",
      " a h  ijjk  l a ",
      " amn          a ",
      " a   o == o   a ",
      " a   paaaapaqaa ",
      " a  =a        a ",
      " a  ra    s   a ",
      " a  ra    s  na ",
      " a  =a eed    f ",
      " a aapaaaa    f ",
      " a  tufwxa    f ",
      " a  y f AaeBB f ",
      " a      Caeeena ",
      " aaaaaaaaaaaaaa ",
      "                "
    ],
    [
      "                ",
      " aaaaaaaaaaaaaa ",
      " a            a ",
      " a D          a ",
      " a   o    o   a ",
      " a   paaaapaEaa ",
      " f  Fa        a ",
      " f   a        a ",
      " f   ae      Ia ",
      " f  Jaed      f ",
      " a aapaaaa    f ",
      " a    f Ka    f ",
      " a    f  a    f ",
      " a       a   Ia ",
      " aaffffffaaaaaa ",
      "                "
    ],
    [
      "                ",
      " aaaaaaaaaaaaaa ",
      " a   L    L   a ",
      " a            a ",
      " a   o    o   a ",
      " a   paaaapaaaa ",
      " a   ae       a ",
      " a  Bae       a ",
      " a  Bad      Ia ",
      " a   a        f ",
      " aaaapaaaa    f ",
      " a   Lf Ma    f ",
      " a    f  a    f ",
      " a       a   Ia ",
      " aaaaaaaaaaaaaa ",
      "                "
    ],
    [
      "                ",
      " aaaaaaaaaaaaaa ",
      " a   N    N   a ",
      " f            a ",
      " f            a ",
      " a   paaaapaaaa ",
      " a   adee     a ",
      " a   a        a ",
      " a   a        a ",
      " a   a        f ",
      " aaaapaaaa    f ",
      " a   Nf  a    f ",
      " a    f  a    f ",
      " a    f  a    a ",
      " aaaaaaffaaaaaa ",
      "                "
    ],
    [
      "                ",
      " aaaaaaaaaaaaaa ",
      " aOOOOOOOOOOOOa ",
      " aOOOOOOOOOOOOa ",
      " aOOOOOOOOOOOOa ",
      " aOOOpaaaapaaaa ",
      " aOOOa  deOOOOa ",
      " aOOOa    OOOOa ",
      " aOOOa    OOOOa ",
      " aOOOa    OOOOf ",
      " aaaapaaaaOOOOf ",
      " aOOOOOOOaOOOOf ",
      " aOOOOOOOaOOOOf ",
      " aOOOOOOOaOOOOa ",
      " aaaaaaaaaaaaaa ",
      "                "
    ]
  ]
}