{
  "name": "building_carservice1_floor2_90",
  "refpalette": "c70cities:building_carservice1_floor2_palette_90",
  "xsize": 16,
  "zsize": 16,
  "slices": [
    [
      "                ",
      "      eeeeee    ",
      " a    acffcdd   ",
      "      dcfffcdd  ",
      "      dcffffcde ",
      "      dcfffffie ",
      " a    acffffffa ",
      "      dcff    e ",
      "      dcff!   e ",
      "    HHdcff    e ",
      " a  bbacffgggga ",
      "    bbccffghhge ",
      "  bbbbccffgggge ",
      "  bbbbccffffffe ",
      " a    aeeeeeeea ",
      "                "
    ],
    [
      "                ",
      "      eeeeee    ",
      " a    aqst rr   ",
      "      ep    rr  ",
      "      eo     re ",
      "      eo     ie ",
      " ajjjkan      a ",
      " j  HHem  y  ye ",
      " j  bbem      e ",
      " j    el  y  ye ",
      " a    a   w  wa ",
      " j        xAAxe ",
      " j        w  we ",
      " j        u   e ",
      " ajjjkaerrrrrea ",
      "                "
    ],
    [
      "                ",
      "      errree    ",
      " a    a    rr   ",
      "      eD    rr  ",
      "      e      re ",
      "    HHe      ie ",
      " aaBbbaC     Ia ",
      "      e   FFFFe ",
      "      e   FbbFe ",
      "      e   FFFFe ",
      " a    a    EE a ",
      "          E  Je ",
      "           EE e ",
      "             Ie ",
      " a    aerrrrrea ",
      "                "
    ],
    [
      "                ",
      "      eeeeee    ",
      " a    a    rr   ",
      "  bbbbe     rr  ",
      "  bbbbeMN    re ",
      "  bb  eLN    ie ",
      " abb  a       a ",
      "  HH  e       e ",
      "      e       e ",
      "      e       e ",
      " a    a       a ",
      "      K       e ",
      "      K       e ",
      "      K       e ",
      " a    aerrrrrea ",
      "                "
    ],
    [
      "                ",
      "      eeeeee    ",
      " akjjja    rr   ",
      " j    e     rr  ",
      " j    e      re ",
      " j    e      ie ",
      " a    a       a ",
      " j    e       e ",
      " jbb  e       e ",
      " jHH  e       e ",
      " akjjja       a ",
      "      e       e ",
      "      e       e ",
      "      e       e ",
      " a    aeOOOOOea ",
      "                "
    ],
    [
      "                ",
      "      eeeeee    ",
      " a    a    rr   ",
      "      e  j  rr  ",
      "      e  jj  re ",
      "      e  jjj ie ",
      " a    a  jjjj a ",
      "      e  jjjjje ",
      "      e  jjjjje ",
      "      e  jjjjje ",
      " abbBaa  jjjjja ",
      "  HH  e  jjjjje ",
      "      e  jjjjje ",
      "      e  jjjjje ",
      " a    aeeeeeeea ",
      "                "
    ]
  ]
}