{
  "name": "building_office2_ground_180",
  "refpalette": "c70cities:building_office2_ground_palette_180",
  "xsize": 16,
  "zsize": 16,
  "slices": [
    [
      "GGGGGGGGGGGGGGGG",
      "GaaaaaaaaaaaaaaG",
      "GGGbccccccccbGGG",
      "GGbccccccccccbGG",
      "GGbcc!cccccccbGG",
      "GGbccccccccccbGG",
      "GGbccccccccccbGG",
      "GGbccccccccccbGG",
      "GGbccccccccccbGG",
      "GGbccccccccccbGG",
      "GGbccccccccccbGG",
      "GGbccccccccccbGG",
      "GGbccccccccccbGG",
      "GGGbccccccccbGGG",
      "GaaaaaaaaaaaaaaG",
      "GGGGGGGGGGGGGGGG"
    ],
    [
      "                ",
      " aaaaaaaaaaaaaa ",
      "   bropqqponb   ",
      "  g          g  ",
      "  g  m       g  ",
      "  g          g  ",
      "  g          g  ",
      "  l          g  ",
      "  k          g  ",
      "  g   j  j   g  ",
      "  g  iiiiii  g  ",
      "  g   h  h   g  ",
      "  g          g  ",
      "   bdfefffedb   ",
      " aaaaaaaaaaaaaa ",
      "                "
    ],
    [
      "                ",
      " aaaaaaaaaaaaaa ",
      "   b  wqqw  b   ",
      "  g          g  ",
      "  g          g  ",
      "  g          g  ",
      "  g          g  ",
      "  u          g  ",
      "  t          g  ",
      "  g          g  ",
      "  g          g  ",
      "  g          g  ",
      "  g          g  ",
      "   bs      sb   ",
      " aaaaaaaaaaaaaa ",
      "                "
    ],
    [
      "                ",
      " aaaaaaaaaaaaaa ",
      "   b   qq   b   ",
      "  g          g  ",
      "  g          g  ",
      "  g          g  ",
      "  g          g  ",
      "  g     x    g  ",
      "  g          g  ",
      "  g          g  ",
      "  g          g  ",
      "  g          g  ",
      "  g          g  ",
      "   bs      sb   ",
      " aaaaaaaaaaaaaa ",
      "                "
    ],
    [
      "                ",
      " aaaaaaaaaaaaaa ",
      "   b   qq   b   ",
      "  g          g  ",
      "  g          g  ",
      "  g          g  ",
      "  g          g  ",
      "  g    xx    g  ",
      "  g    xx    g  ",
      "  g          g  ",
      "  g          g  ",
      "  g          g  ",
      "  g          g  ",
      "   b        b   ",
      " aaaaaaaaaaaaaa ",
      "                "
    ],
    [
      "                ",
      " aaaaaaaaaaaaaa ",
      "   byyyqqyyyb   ",
      "  g yyyyyyyy g  ",
      "  g yyyyyyyy g  ",
      "  g yyyyyyyy g  ",
      "  g yyyyyyyy g  ",
      "  g yyyAAyyy g  ",
      "  g yyyAAyyy g  ",
      "  g yyyyyyyy g  ",
      "  g yyyyyyyy g  ",
      "  g yyyyyyyy g  ",
      "  g yyyyyyyy g  ",
      "   byyyyyyyyb   ",
      " aaaaaaaaaaaaaa ",
      "                "
    ]
  ]
}