{
  "name": "building_hotel1_ground",
  "refpalette": "c70cities:building_hotel1_ground_palette",
  "xsize": 16,
  "zsize": 16,
  "slices": [
    [
      "GGGGaGGGGGGaGGGG",
      "GbbbbbbbbbbbbbbG",
      "GbccccccccccccbG",
      "GbccccccccccccbG",
      "GbccccccccccccbG",
      "GbccccccccccccbG",
      "Gbcccc!GGGccccbG",
      "GbccccdGGGccccbG",
      "GbccccdGGGccccbG",
      "GbccccddddccccdG",
      "GbccccccccccccdG",
      "GbccccccccccccdG",
      "GbccccccccccccdG",
      "Gb!cccccccccccbG",
      "GbbbbbbbbbbbbbbG",
      "GGGGGGGGGGGGGGGG"
    ],
    [
      " eeeeeeeeeeeeee ",
      " bbbbbbbbbbbbbb ",
      " bffff gg h ggb ",
      " bf    gi h igb ",
      " bj    gg   ggb ",
      " bj           b ",
      " bk   leee    b ",
      " bk   l  e    b ",
      " bk   l  e   mb ",
      " bk   lggn   op ",
      " b           q  ",
      " bbrb  s s   t  ",
      " b  b uuuuw  op ",
      " bx b   y A  mb ",
      " bbbbbbbbbbbbbb ",
      "                "
    ],
    [
      "                ",
      " bbbbbbbbbbbbbb ",
      " bfff         b ",
      " bf           b ",
      " b            b ",
      " b            b ",
      " p    l       b ",
      " p    l       b ",
      " p    g      Bb ",
      " p    gn     op ",
      " b           C  ",
      " bbDb        E  ",
      " b  b  F     op ",
      " b  b        Bb ",
      " bbppppppbbbbbb ",
      "                "
    ],
    [
      "                ",
      " bbbbbbbbbbbbbb ",
      " bfI          b ",
      " b            b ",
      " b            b ",
      " b            b ",
      " b    g       b ",
      " b    g       b ",
      " b    n      Bb ",
      " b           op ",
      " b           op ",
      " bbbb        op ",
      " b  b        op ",
      " bI b        Bb ",
      " bbbbbbbbbbbbbb ",
      "                "
    ],
    [
      "                ",
      " bbbbbbbbbbbbbb ",
      " bII          b ",
      " p            b ",
      " p            b ",
      " b            b ",
      " b    ngg     b ",
      " b            b ",
      " b            b ",
      "~b           op ",
      " bI          op ",
      " bbbb        op ",
      " bI b        op ",
      " bI b         b ",
      " bbbbbbppbbbbbb ",
      "                "
    ],
    [
      "                ",
      " bbbbbbbbbbbbbb ",
      " bJJJJJJJJJJJJb ",
      " bJJJJJJJJJJJJb ",
      " bJJJJJJJJJJJJb ",
      " bJJJJJJJJJJJJb ",
      " bJJJJ  ngJJJJb ",
      " bJJJJ    JJJJb ",
      " bJJJJ    JJJJb ",
      " bJJJJ    JJJJp ",
      " bJJJJJJJJJJJJp ",
      " bbbbJJJJJJJJJp ",
      " bJJbJJJJJJJJJp ",
      " bJJbJJJJJJJJJb ",
      " bbbbbbbbbbbbbb ",
      "                "
    ]
  ]
}