{
  "name": "building_office5_floor1_270",
  "refpalette": "c70cities:building_office5_floor1_palette_270",
  "xsize": 16,
  "zsize": 16,
  "slices": [
    [
      "                ",
      "                ",
      "  dbdbdbdbd     ",
      "  deeeeeeedaba  ",
      "  beeeeeeeeccb  ",
      "  deeeeeeeecca  ",
      "  beeeeeeedccb  ",
      "  deeeeeefdcca  ",
      "  beeeeeefdccb  ",
      "  deee!eeedcca  ",
      "  beeeeeeedccb  ",
      "  deeeeeeedaba  ",
      "  beeeeeeed     ",
      "  dbdbdbdbd     ",
      "                ",
      "                "
    ],
    [
      "                ",
      "                ",
      "  dbdbdbdbd     ",
      "  d   l  gdaba  ",
      "  b l        b  ",
      "  d mmm      a  ",
      "  b mmm  id  b  ",
      "  do  n  fdg a  ",
      "  b l    fd! b  ",
      "  d mmmk  dh a  ",
      "  b mmm  jdh b  ",
      "  d n n   daba  ",
      "  b       d     ",
      "  dbdbdbdbd     ",
      "                ",
      "                "
    ],
    [
      "                ",
      "                ",
      "  dbdbdbdbd     ",
      "  d       daba  ",
      "  b          b  ",
      "  d t        a  ",
      "  b   t   dp b  ",
      "  d      fdp a  ",
      "  b      fd  b  ",
      "  d       d  a  ",
      "  b t    sdq b  ",
      "  d       raba  ",
      "  b       d     ",
      "  dbdbdbdbd     ",
      "                ",
      "                "
    ],
    [
      "                ",
      "                ",
      "  dbdbdbdbd     ",
      "  d       daba  ",
      "  b       u  b  ",
      "  d       u  a  ",
      "  b       d  b  ",
      "  d      fd  a  ",
      "  b      fd  b  ",
      "  d       d  a  ",
      "  b       d  b  ",
      "  d       uaba  ",
      "  b       d     ",
      "  dbdbdbdbd     ",
      "                ",
      "                "
    ],
    [
      "                ",
      "                ",
      "  dbdbdbdbd     ",
      "  d       daba  ",
      "  b       d  b  ",
      "  d       d  a  ",
      "  b       d  b  ",
      "  d      fd  a  ",
      "  b      fd  b  ",
      "  d       d  a  ",
      "  b       d  b  ",
      "  d       daba  ",
      "  b       d     ",
      "  dbdbdbdbd     ",
      "                ",
      "                "
    ],
    [
      "                ",
      "                ",
      "  dbdbdbdbd     ",
      "  dwwwwwwwdaba  ",
      "  bwwwwwwwd  b  ",
      "  dwwwwwwwd  a  ",
      "  bwwwwwwwd  b  ",
      "  dwwwwwwfd  a  ",
      "  bwwwwwwfd  b  ",
      "  dwwwwwwwd  a  ",
      "  bwwwwwwwd  b  ",
      "  dwwwwwwwdaba  ",
      "  bwwwwwwwd     ",
      "  dbdbdbdbd     ",
      "                ",
      "                "
    ]
  ]
}