{
  "name": "building_office4_floor2_180",
  "refpalette": "c70cities:building_office4_floor2_palette_180",
  "xsize": 16,
  "zsize": 16,
  "slices": [
    [
      "                ",
      "    abaaaaba    ",
      "  cccdeeeedccc  ",
      "  ceeeeeeeeeec  ",
      " aceeeeeeeeeeca ",
      " bdeeeeeeeeeedb ",
      " aeeeeeeeeeeeea ",
      " aeeeeeeeeeeefa ",
      " aeeeeeeeeeeefa ",
      " aeeeeeeeeeeeea ",
      " bdeeeeeeeeeedb ",
      " aceeeeeeeeeeca ",
      "  ceeeeeeeeeec  ",
      "  cccdeeeedccc  ",
      "    abaaaaba    ",
      "                "
    ],
    [
      "                ",
      "    abaaaaba    ",
      "  gggd    dggg  ",
      "  g          g  ",
      " ag  ih ih   ga ",
      " bd  i  i    db ",
      " a  ki ki  j  a ",
      " a        dl fa ",
      " a        dl fa ",
      " a  ki ki  j  a ",
      " bd  i  i    db ",
      " ag  ih ih   ga ",
      "  g          g  ",
      "  gggd    dggg  ",
      "    abaaaaba    ",
      "                "
    ],
    [
      "                ",
      "    abaaaaba    ",
      "  gggdmmmmdggg  ",
      "  g          g  ",
      " ag          ga ",
      " bd          db ",
      " a         j  a ",
      " a        d  fa ",
      " a        d  fa ",
      " a         j  a ",
      " bd          db ",
      " ag          ga ",
      "  g          g  ",
      "  gggdmmmmdggg  ",
      "    abaaaaba    ",
      "                "
    ],
    [
      "                ",
      "    abaaaaba    ",
      "  gggd    dggg  ",
      "  g          g  ",
      " ag          ga ",
      " bd          db ",
      " a         j  a ",
      " a        d  fa ",
      " a        d  fa ",
      " a         j  a ",
      " bd          db ",
      " ag          ga ",
      "  g          g  ",
      "  gggd    dggg  ",
      "    abaaaaba    ",
      "                "
    ],
    [
      "                ",
      "    abaaaaba    ",
      "  gggd    dggg  ",
      "  g          g  ",
      " ag          ga ",
      " bd          db ",
      " a         j  a ",
      " a        d  fa ",
      " a        d  fa ",
      " a         j  a ",
      " bd          db ",
      " ag          ga ",
      "  g          g  ",
      "  gggd    dggg  ",
      "    abaaaaba    ",
      "                "
    ],
    [
      "                ",
      "    abaaaaba    ",
      "  gggdnnnndggg  ",
      "  gnnnnnnnnnng  ",
      " agnnnnnnnnnnga ",
      " bdnnnnnnnnnndb ",
      " annnnnnnn!nnna ",
      " annnnnnnndnnfa ",
      " annnnnnnndnnfa ",
      " annnnnnnnnnnna ",
      " bdnnnnnnnnnndb ",
      " agnnnnnnnnnnga ",
      "  gnnnnnnnnnng  ",
      "  gggdnnnndggg  ",
      "    abaaaaba    ",
      "                "
    ]
  ]
}