{
  "name": "building_gasstation1_ground_180",
  "refpalette": "c70cities:building_gasstation1_ground_palette_180",
  "xsize": 16,
  "zsize": 16,
  "slices": [
    [
      "GGGGGGGGGGGGGGGG",
      "GGGGGbHHHHHHHHHH",
      "GGGGGbHHHHHHHHHH",
      "GGaaaaaaaHHaHHHH",
      "GGaaaaaaaHHaHHHH",
      "GGaaaaaaaHHaHHHH",
      "GGaaaaaaaHHaHHHH",
      "GGaaaaaaaHHaHHHH",
      "GGaaaaaaaHHaHHHH",
      "GGaaaaaaaHHaHHHH",
      "GGaaaaaaaHHaHHHH",
      "GGaaaaaaaHHaHHHH",
      "GGaaaaaaaHHaHHHH",
      "GGGGGbHHHHHHHHHH",
      "GGGGGbHHHHHHHHHa",
      "GGGGGGGGGGGGGGGG"
    ],
    [
      "                ",
      "     fh g       ",
      "     fe d       ",
      "  jjjjjjj  its  ",
      "  jIFj EC       ",
      "  j Dj  C  mlk  ",
      "  jBjj Aj  its  ",
      "  j     q  y    ",
      "  j     x  wlk  ",
      "  jooo  u  its  ",
      "  jrr   q       ",
      "  jp!onnj  mlk  ",
      "  jjjjjjj  i    ",
      "     fh g       ",
      "     fe d      c",
      "                "
    ],
    [
      "                ",
      "                ",
      "                ",
      "  jjjjjjj  i    ",
      "  j  j  P       ",
      "  j  j  P  J    ",
      "  jOjj Nj  i    ",
      "  j     q       ",
      "  j     M       ",
      "  joro  L  i    ",
      "  j     q       ",
      "  joKp  j  J    ",
      "  jjjjjjj  i    ",
      "                ",
      "               c",
      "                "
    ],
    [
      "                ",
      "                ",
      "                ",
      "  RRRRRRR  i    ",
      "  U  j  R       ",
      "  U  j  R       ",
      "  Rjjj  R  i    ",
      "  U     R       ",
      "  U     R       ",
      "  R     R  i    ",
      "  U     R       ",
      "  U r TSR       ",
      "  RRRRRRR  i    ",
      "                ",
      "               Q",
      "                "
    ],
    [
      "                ",
      "                ",
      "                ",
      "  jjjjjjj Vj    ",
      "  jYYj  j       ",
      "  jYYj  j       ",
      "  jjjjV j Xj    ",
      "  j  j  j       ",
      "  j  j  j       ",
      "  j  jX j Vj    ",
      "  j  j  j       ",
      "  jr jWrj       ",
      "  jjjjjjj Vj    ",
      "                ",
      "                ",
      "                "
    ],
    [
      "                ",
      "                ",
      " ZZZZZZZZZZZZZZ ",
      " ZaaaaaaaaaaffZ ",
      " ZaffaffaffaffZ ",
      " ZaffaffaffaffZ ",
      " ZaffaffaffaffZ ",
      " ZaffaffaffaffZ ",
      " ZaffaffaffaffZ ",
      " ZaffaffaffaffZ ",
      " ZaffaffaffaffZ ",
      " ZaffaffaffaffZ ",
      " ZaaaaaaaaaaffZ ",
      " ZZZZZZZZZZZZZZ ",
      "                ",
      "                "
    ]
  ]
}