{
  "name": "building_restaurant1_floor1_180",
  "refpalette": "c70cities:building_restaurant1_floor1_palette_180",
  "xsize": 16,
  "zsize": 16,
  "slices": [
    [
      "                ",
      "  ffffffffffff  ",
      "   hgggggggggf  ",
      "   hgggggggggf  ",
      "   hgggggggggf  ",
      "   hgggggggggf  ",
      " =====bbbbbb=== ",
      " =!bbbbbbbbbbG= ",
      " ebbbbbbbbbbbG= ",
      " ebbbbbbbbbbbG= ",
      " ebbbbbbbbbbbG= ",
      " eeee======bb== ",
      "        cbdbba  ",
      "        cb bba  ",
      "       aaaaaaa  ",
      "                "
    ],
    [
      "  JNJJMLLLLKJ   ",
      "  ffffffffffff  ",
      "    DIEC I ECf  ",
      "    D        f  ",
      "    DFE    ECf  ",
      "    DB AC   Bf  ",
      " =====A     === ",
      " =xyxq   w  ml= ",
      " =s  q po   ml= ",
      " =u  t      ml= ",
      " =s rq pon  ml= ",
      " ==========kj== ",
      "        cid  a  ",
      "        ci   a  ",
      "       aaaaaaa  ",
      "                "
    ],
    [
      "                ",
      "  fWffWWWWWWff  ",
      "    D        f  ",
      "    D        f  ",
      "    D        f  ",
      "    DQ      Qf  ",
      " =====      === ",
      " =  VA       Q= ",
      " =   A  U    Q= ",
      " =T          Q= ",
      " =  SR       Q= ",
      " ==cccc====PO== ",
      "        cid  e  ",
      "        ci   a  ",
      "       aaaaaaa  ",
      "                "
    ],
    [
      "                ",
      "  f ff      ff  ",
      "    D        f  ",
      "    D        f  ",
      "    D        f  ",
      "    DQ      Qf  ",
      " =====      === ",
      " e            = ",
      " e            X ",
      " =      Y     X ",
      " =            = ",
      " ============== ",
      "        cid  e  ",
      "        ci   a  ",
      "       aaaaaaa  ",
      "                "
    ],
    [
      "                ",
      "  f ff      ff  ",
      "    D        f  ",
      "    D Y      f  ",
      "    D        f  ",
      "    D        f  ",
      " ============== ",
      " =            = ",
      " =            = ",
      " = Z    Z     = ",
      " =            = ",
      " ============== ",
      "        cid  a  ",
      "        ci   a  ",
      "       aaaaaaa  ",
      "                "
    ],
    [
      "                ",
      "  ffffffffffff  ",
      "    D        f  ",
      "    D Z    Z f  ",
      "    D        f  ",
      "    D        f  ",
      " ============== ",
      " =111111111111= ",
      " =111111111111= ",
      " =111111111111= ",
      " =111111111111= ",
      " ============== ",
      "        cid 0a  ",
      "        ci   a  ",
      "       aaaaaaa  ",
      "                "
    ]
  ]
}