{
  "name": "building_office4_floor3_270",
  "refpalette": "c70cities:building_office4_floor3_palette_270",
  "xsize": 16,
  "zsize": 16,
  "slices": [
    [
      "                ",
      "    abaaaaba    ",
      "  cccdeffedccc  ",
      "  ceeeeeeeeeec  ",
      " aceeeeeeeeeeca ",
      " bdeee!eeeeeedb ",
      " aeeeeeeeeeeeea ",
      " aeeeeeeeeeeeea ",
      " aeeeeeeeeeeeea ",
      " aeeeeeeeeeeeea ",
      " bdeeeeeeeeeedb ",
      " aceeeeeeeeeeca ",
      "  ceeeeeeeeeec  ",
      "  cccdeeeedccc  ",
      "    abaaaaba    ",
      "                "
    ],
    [
      "                ",
      "    abaaaaba    ",
      "  gggd ff dggg  ",
      "  g          g  ",
      " ag          ga ",
      " bd   m  j   db ",
      " an    kk    ha ",
      " an   m  j   ia ",
      " ao          ha ",
      " an   mkkj   ha ",
      " bd          db ",
      " ag    ll    ga ",
      "  g          g  ",
      "  gggd    dggg  ",
      "    abaaaaba    ",
      "                "
    ],
    [
      "                ",
      "    abaaaaba    ",
      "  gggd ff dggg  ",
      "  g          g  ",
      " ag          ga ",
      " bd    qq    db ",
      " a     qq     a ",
      " a     qq     a ",
      " a     qq     a ",
      " a     qq    pa ",
      " bd    qq    db ",
      " ag          ga ",
      "  g          g  ",
      "  gggd    dggg  ",
      "    abaaaaba    ",
      "                "
    ],
    [
      "                ",
      "    abaaaaba    ",
      "  gggd ff dggg  ",
      "  g          g  ",
      " ag          ga ",
      " bd          db ",
      " a            a ",
      " a            a ",
      " a            a ",
      " a            a ",
      " bd          db ",
      " ag          ga ",
      "  g          g  ",
      "  gggd    dggg  ",
      "    abaaaaba    ",
      "                "
    ],
    [
      "                ",
      "    abaaaaba    ",
      "  gggd ff dggg  ",
      "  g          g  ",
      " ag          ga ",
      " bd          db ",
      " a            a ",
      " a            a ",
      " a            a ",
      " a            a ",
      " bd          db ",
      " ag          ga ",
      "  g          g  ",
      "  gggd    dggg  ",
      "    abaaaaba    ",
      "                "
    ],
    [
      "                ",
      "    abaaaaba    ",
      "  gggdrffrdggg  ",
      "  grrrrrrrrrrg  ",
      " agrrrrrrrrrrga ",
      " bdrrrrrrrrrrdb ",
      " arrrrrrrrrrrra ",
      " arrrrrrrrrrrra ",
      " arrrrrrrrrrrra ",
      " arrrrrrrrrrrra ",
      " bdrrrrrrrrrrdb ",
      " agrrrrrrrrrrga ",
      "  grrrrrrrrrrg  ",
      "  gggdrrrrdggg  ",
      "    abaaaaba    ",
      "                "
    ]
  ]
}