{
  "name": "building_hotel3_floor2_270",
  "refpalette": "c70cities:building_hotel3_floor2_palette_270",
  "xsize": 16,
  "zsize": 16,
  "slices": [
    [
      "                ",
      "  a a a a a a   ",
      "  bbbbbbbbbbbba ",
      " abccccccccccb  ",
      "  bceeeeeeeecba ",
      " abceffffffecb  ",
      "  bceffffffecba ",
      " abcefff!ffedb  ",
      "  bceffffffedba ",
      " abceffffffecb  ",
      "  bceffffffecba ",
      " abceeeeeeeecb  ",
      "  bccccccccccba ",
      " abbbbbbbbbbbb  ",
      "   a a a a a a  ",
      "                "
    ],
    [
      "                ",
      "  a a a a a a   ",
      "  bbbbbbbbbbbba ",
      " ab          b  ",
      "  b reeeeeee ba ",
      " ab m o   he b  ",
      "  b mq    he ba ",
      " ab m    iiedb  ",
      "  b m pnikjedba ",
      " ab m pnilie b  ",
      "  b m      g ba ",
      " ab rmmmmmee b  ",
      "  b          ba ",
      " abbbbbbbbbbbb  ",
      "   a a a a a a  ",
      "                "
    ],
    [
      "                ",
      "  a a a a a a   ",
      "  bbbbbbbbbbbba ",
      " ab          b  ",
      "  b rettttee ba ",
      " ab  w     e b  ",
      "  b  w     e ba ",
      " ab      iiedb  ",
      "  b     i  edba ",
      " ab     iuie b  ",
      "  b        s ba ",
      " ab r     ee b  ",
      "  b          ba ",
      " abbbbbbbbbbbb  ",
      "   a a a a a a  ",
      "                "
    ],
    [
      "                ",
      "  a a a a a a   ",
      "  bbbbbbbbbbbba ",
      " ab          b  ",
      "  b reeeeeee ba ",
      " ab       we b  ",
      "  b       we ba ",
      " ab      iiedb  ",
      "  b     i  edba ",
      " ab     iiie b  ",
      "  b        e ba ",
      " ab r     ee b  ",
      "  b          ba ",
      " abbbbbbbbbbbb  ",
      "   a a a a a a  ",
      "                "
    ],
    [
      "                ",
      "  a a a a a a   ",
      "  bbbbbbbbbbbba ",
      " ab          b  ",
      "  b reeeeeee ba ",
      " ab     i  e b  ",
      "  b     i  e ba ",
      " ab     iiiedb  ",
      "  b     i  edba ",
      " ab     iiie b  ",
      "  b        e ba ",
      " ab r     ee b  ",
      "  b          ba ",
      " abbbbbbbbbbbb  ",
      "   a a a a a a  ",
      "                "
    ],
    [
      "                ",
      "  a a a a a a   ",
      "  bbbbbbbbbbbba ",
      " ab          b  ",
      "  b eeeeeeee ba ",
      " ab exxxxxxe b  ",
      "  b exxxxxxe ba ",
      " ab exxxxxxedb  ",
      "  b exxxxxxedba ",
      " ab exxxxxxe b  ",
      "  b exxxxxxe ba ",
      " ab eeeeeeee b  ",
      "  b          ba ",
      " abbbbbbbbbbbb  ",
      "   a a a a a a  ",
      "                "
    ]
  ]
}