{
  "name": "building_hotel3_base2_180",
  "refpalette": "c70cities:building_hotel3_base2_palette_180",
  "xsize": 16,
  "zsize": 16,
  "slices": [
    [
      "aaaaaaaaaaaaaaaa",
      "abbcbbbbfbcbbbba",
      "abbbbbbbbbbbbbba",
      "abbbbbbbbbbbbbba",
      "abbbdeeeeeedfbba",
      "abbbeeeeeeeebbca",
      "abbbeeeeeeeebbba",
      "acbbeeeeeeeebbba",
      "abbbeeeeeeeebbba",
      "abbbeeeeeeeebbca",
      "abbbeeeeeeeebbca",
      "abbbdeeeeeedbbba",
      "abbbbbbbbbbbbbba",
      "abbcbbbbbbbbbbba",
      "abbbbbb!bbbbbcba",
      "aaaaaaaaaaaaaaaa"
    ],
    [
      "aaaaaaaaaaaaaaaa",
      "agghggggighiggga",
      "aggijijijiigigfa",
      "agiiijiiiiiiiiga",
      "agjidkkkkkkdiiia",
      "ajiik    ktkiiha",
      "agiik s  rqkigga",
      "ahjik p  okkiiia",
      "aiiik p  o kijia",
      "agiik n  m kiiha",
      "aijik  ll  kiiha",
      "agjidkkddkkdigga",
      "aggjiiiiiiiiiiia",
      "agghijiiigiiiiia",
      "aggggigijggjihga",
      "aaaaaaaaaaaaaaaa"
    ],
    [
      "aaaaaaaaaaaaaaaa",
      "agghiggiijhiijja",
      "agjijijijiiiiiia",
      "aiiiijiiiiiiiija",
      "aijidkkkkkkdiiia",
      "ajiik     tkiiha",
      "aiiik      kiija",
      "ahjik      kiiia",
      "aiiik      kijia",
      "ajiik      kiiha",
      "aijik  ll  kiiha",
      "agjidkkddkkdiija",
      "agijiiiiiiiiiiia",
      "agghijiiijiiiiia",
      "aggjgiiijgijihia",
      "aaaaaaaaaaaaaaaa"
    ],
    [
      "aaaaaaaaaaaaaaaa",
      "agihiguiiuhiiuua",
      "auuiuiuiuiiiiiia",
      "aiiiiuiiiiiiiiua",
      "aiuidkkkkkkdiiia",
      "auiik     xqiiha",
      "aiiik      kiiua",
      "ahuik      kiiia",
      "aiiik      kiuia",
      "auiik      kiiha",
      "aiuik  ll  kiiha",
      "auuidkkddkkdiiua",
      "agiuiiiiiiiiiiia",
      "aguhiuiiiuiiiiia",
      "agwuiiiiuuiuihia",
      "aaaaaaaaaaaaaaaa"
    ],
    [
      "aaaaaaaaaaaaaaaa",
      "a              a",
      "a              a",
      "a              a",
      "a   dkkkkkkd   a",
      "a   k          a",
      "a   k          a",
      "a   k      k   a",
      "a   k      k   a",
      "a   k      k   a",
      "a   k  ll  k   a",
      "a   dkkddkkd   a",
      "a              a",
      "a              a",
      "ag             a",
      "aaaaaaaaaaaaaaaa"
    ],
    [
      "aaaaaaaaaaaaaaaa",
      "ayyyyyyyyyyyyyya",
      "ayyyyyyyyyyyyyya",
      "ayyyyyyyyyyyyyya",
      "ayyydAAAAAAdyyya",
      "ayyyAAAAAAAAyyya",
      "ayyyAAAAAAAAyyya",
      "ayyyAAAAAAAAyyya",
      "ayyyAAAAAAAAyyya",
      "ayyyAAAAAAAAyyya",
      "ayyyAAAllAAAyyya",
      "ayyydAAddAAdyyya",
      "ayyyyyyyyyyyyyya",
      "ayyyyyyyyyyyyyya",
      "ayyyyyyyyyyyyyya",
      "aaaaaaaaaaaaaaaa"
    ]
  ]
}