{
  "name": "building_office1_top_180",
  "refpalette": "c70cities:building_office1_top_palette_180",
  "xsize": 16,
  "zsize": 16,
  "slices": [
    [
      "                ",
      " eeeeeeeeeeeeee ",
      " ebbbbbbbbbbbbe ",
      " ebbbbbbbbbbbbe ",
      " efbbbbbbbbbgfe ",
      "  dbbbbbbbbbbd  ",
      "  dbbbbbbbbbbd  ",
      " ccbbbbbbbbbbcc ",
      "  abbbbbbbbbba  ",
      "  abbbbbbbbbba  ",
      "  abbbbbbbbbba  ",
      "  abbbbbbbbbba  ",
      "  abbbbbbbbbba  ",
      "  aaaaaaaaaaaa  ",
      "                ",
      "                "
    ],
    [
      "                ",
      " mmmmmmmmmmmmmm ",
      " mp  qq  qq  om ",
      " mp          om ",
      " mfn kk  kk  fm ",
      "  d          d  ",
      "  d          d  ",
      " ccl        lcc ",
      "  h ii    ii h  ",
      "  h ij kk ji h  ",
      "  h ij kk ji h  ",
      "  h ii    ii h  ",
      "  h          h  ",
      "  hhhhhhhhhhhh  ",
      "                ",
      "                "
    ],
    [
      "                ",
      " mmtddddddddtmm ",
      " mp          om ",
      " mp          om ",
      " mf          fm ",
      "  d          d  ",
      "  d          d  ",
      " ccs        scc ",
      "  r          r  ",
      "                ",
      "  r          r  ",
      "                ",
      "  r          r  ",
      "                ",
      "                ",
      "                "
    ],
    [
      "                ",
      " mmtddddddddtmm ",
      " m           om ",
      " m           om ",
      " mf          fm ",
      "  d          d  ",
      "  d          d  ",
      " cc          cc ",
      "  r          r  ",
      "                ",
      "  r          r  ",
      "                ",
      "  r          r  ",
      "                ",
      "                ",
      "                "
    ],
    [
      "                ",
      " mmmmmmmmmmmmmm ",
      " m            m ",
      " m            m ",
      " mffffffffffffm ",
      "  fuuuuuuuuuuf  ",
      "  fuuuuuuuuuuf  ",
      " ccffffffffffcc ",
      "  r          r  ",
      "                ",
      "  r          r  ",
      "                ",
      "  r          r  ",
      "                ",
      "                ",
      "                "
    ],
    [
      "                ",
      " mmmmmmmmmmmmmm ",
      " muuuuuuuuuuuum ",
      " muuuuuuuuuuuum ",
      " muuuuuuuuuuuum ",
      "                ",
      "                ",
      " ccwwwwwwwwwwcc ",
      "  weeeeeeeeeew  ",
      "  weeeeeeeeeew  ",
      "  weeeeeeeeeew  ",
      "  weeeeeeeeeew  ",
      "  weeeeeeeeeew  ",
      "  wwwwwwwwwwww  ",
      "                ",
      "                "
    ]
  ]
}