{
  "name": "building_hotel3_ground_180",
  "refpalette": "c70cities:building_hotel3_ground_palette_180",
  "xsize": 16,
  "zsize": 16,
  "slices": [
    [
      "GGGGGGGGGGGGGGGG",
      "GaaaaaaaaaaaaaaG",
      "GabbbbbbbbbbbbaG",
      "GabbbbbbbbbbbbaG",
      "GabbcbbbbbbcbbaG",
      "GabbbbbbbbbbbbaG",
      "GabbbbbbbbbbbbaG",
      "GabbbbbbbbbbbbaG",
      "GabbbbbbbbbbbbaG",
      "GabbbbbbbbbbbbaG",
      "Gabbbbbddbbb!baG",
      "GabbcbbccbbcbbaG",
      "GabbbbbbbbbbbbaG",
      "GabbbbbbbbbbbbaG",
      "GaaaaaaaaaaaaaaG",
      "GGGGGGGGGGGGGGGG"
    ],
    [
      "                ",
      " aaaaaaaaaaaaaa ",
      " ae o      o ea ",
      " ae   n  n   ea ",
      " ae l mmmm l ea ",
      " k           ea ",
      " j         hhea ",
      " ae        ihea ",
      " ae        ihea ",
      " ae        hhea ",
      " ae c      c ea ",
      " ae c  cc  c ea ",
      " ae f  gg  f ea ",
      " aeeeeeeeeeeeea ",
      " aaaaaaaaaaaaaa ",
      "                "
    ],
    [
      "                ",
      " aaaaaaaaaaaaaa ",
      " ae f      f ea ",
      " ae          ea ",
      " ae l  s   l ea ",
      " r           ea ",
      " q           ea ",
      " ae          ea ",
      " ae          ea ",
      " ae          ea ",
      " ae c      c ea ",
      " ae c  cc  c ea ",
      "  e f  gg  f ep ",
      " peeeeeeeeeeee  ",
      "   p p p p p p  ",
      "                "
    ],
    [
      "                ",
      " aaaaaaaaaaaaaa ",
      " ae f      f ea ",
      " ae          ea ",
      " ae l      l ea ",
      " ae          ea ",
      " ae          ea ",
      " ae          ea ",
      " ae          ea ",
      " pe          e  ",
      "  e c      c ep ",
      " pe c  cc  c e  ",
      "  e f  gg  f ep ",
      " peeeeeeeeeeee  ",
      "   p p p p p p  ",
      "                "
    ],
    [
      "                ",
      " aaaaaaaaaaaaaa ",
      " ae          ea ",
      " ae          ea ",
      " ae l      l ea ",
      " ae          ea ",
      "  e          ep ",
      " pe          e  ",
      "  e          ep ",
      " pe          e  ",
      "  e c      c ep ",
      " pe cttccttc e  ",
      "  e    gg    ep ",
      " peeeeeeeeeeee  ",
      "   p p p p p p  ",
      "                "
    ],
    [
      "                ",
      " aaaaaaaaaaaaaa ",
      " aeeeeeeeeeeeea ",
      " pe          e  ",
      "  e lccccccl ep ",
      " pe cuuuuuuc e  ",
      "  e cuuuuuuc ep ",
      " pe cuuuuuuc e  ",
      "  e cuuuuuuc ep ",
      " pe cuuuuuuc e  ",
      "  e cuuuuuuc ep ",
      " pe cccccccc e  ",
      "  e    gg    ep ",
      " peeeeeeeeeeee  ",
      "   p p p p p p  ",
      "                "
    ]
  ]
}