{
  "name": "building_bank1_top_90",
  "refpalette": "c70cities:building_bank1_top_palette_90",
  "xsize": 16,
  "zsize": 16,
  "slices": [
    [
      "                ",
      "  abbbc abbbc   ",
      "  deeeedeeeeeda ",
      " ceeeeeeeeeeeeb ",
      " beeeeeeeeeeeeb ",
      " beeeeeeeeeeeeb ",
      " beeeeeeeeeeeec ",
      " aeeeeeeeeeeed  ",
      "  deeeeeeeeeeea ",
      " ceeeeeeeeeeeeb ",
      " beeeeeeeeeeeeb ",
      " beeeeeeeeeeeeb ",
      " beee     eeeec ",
      " adeeeeedeeeed  ",
      "   cbbba cbbba  ",
      "                "
    ],
    [
      "                ",
      " fbcc abbcc abf ",
      " bgggghggggghgb ",
      " ahi       txgc ",
      "  g      s twgc ",
      " cg  l p s twg  ",
      " cg  k   r twha ",
      " bg  jnonq tugb ",
      " bg        tugb ",
      " ah   m m  twgc ",
      "  g        twgc ",
      " cg        twg  ",
      " cg        tuha ",
      " bghggggghggggb ",
      " fba ccbba ccbf ",
      "                "
    ],
    [
      "                ",
      " fbbbbbbbbbbbbf ",
      " bgggghggggghgb ",
      " bh         wgb ",
      " bg      s  wgb ",
      " bg      s  wgb ",
      " bg         whb ",
      " bg  y   A  wgb ",
      " bg         wgb ",
      " bh         wgb ",
      " bg         wgb ",
      " bg         wgb ",
      " bg         whb ",
      " bghggggghggggb ",
      " fbbbbbbbbbbbbf ",
      "                "
    ],
    [
      "                ",
      "                ",
      "   gghggggghg   ",
      "  gg        gg  ",
      "  h          g  ",
      "  g          h  ",
      "  g          g  ",
      "  g          g  ",
      "  g          g  ",
      "  g          g  ",
      "  h          g  ",
      "  g          h  ",
      "  gg        gg  ",
      "   ghggggghgg   ",
      "                ",
      "                "
    ],
    [
      "                ",
      "                ",
      "                ",
      "    gggggggg    ",
      "   gggggggggg   ",
      "   gggB   ggg   ",
      "   gg      gg   ",
      "   gg      gg   ",
      "   gg      gg   ",
      "   gg      gg   ",
      "   ggg   Bggg   ",
      "   gggggggggg   ",
      "    gggggggg    ",
      "                ",
      "                ",
      "                "
    ],
    [
      "                ",
      "                ",
      "                ",
      "                ",
      "                ",
      "      gggg      ",
      "     gggggg     ",
      "     gggggg     ",
      "     gggggg     ",
      "     gggggg     ",
      "      gggg      ",
      "                ",
      "                ",
      "                ",
      "                ",
      "                "
    ]
  ]
}