{
  "name": "building_restaurant1_base1_270",
  "refpalette": "c70cities:building_restaurant1_base1_palette_270",
  "xsize": 16,
  "zsize": 16,
  "slices": [
    [
      "vvvvvvvvvvvvvvvv",
      "v==============v",
      "vbbbbbvvvvvvva=v",
      "vbdddcvvvvvvvv=v",
      "vbdddcvvvvvvvv=v",
      "vbdddcvvvvvvvv=v",
      "vbccccvvvvvvvv=v",
      "vbccccvvvvvvvv=v",
      "vbccccvvv!vvvv=v",
      "vbccccvvvvvvvv=v",
      "vbccccvvvvvvvv=v",
      "vb!cccvvvvvvvv=v",
      "vbccccvvvvvvvv=v",
      "vbbbbbvvvvvvvv=v",
      "v==============v",
      "vvvvvvvvvvvvvvvv"
    ],
    [
      "vvvvvvvvvvvvvvvv",
      "v==============v",
      "vbbbbbhk  jjja=v",
      "vbsssdk    jje=v",
      "vbsssd     j  =v",
      "vbsssd        =v",
      "vbdddp  ln    =v",
      "vb      llll  =v",
      "vbt rp llll   =v",
      "vb     llln   =v",
      "vbtr r  lo   f=v",
      "vbu rpp      g=v",
      "vbwt p      kh=v",
      "vbbbbbqf   mii=v",
      "v==============v",
      "vvvvvvvvvvvvvvvv"
    ],
    [
      "vvvvvvvvvvvvvvvv",
      "v==============v",
      "vbbbbbg    jja=v",
      "vb   p       e=v",
      "vb   p        =v",
      "vb   p        =v",
      "vb            =v",
      "vb      ll    =v",
      "vb      lll   =v",
      "vb      l     =v",
      "vb            =v",
      "vb   p        =v",
      "vbt  p       g=v",
      "vbbbbb f    xk=v",
      "v==============v",
      "vvvvvvvvvvvvvvvv"
    ],
    [
      "vvvvvvvvvvvvvvvv",
      "v==============v",
      "vbbbbb      ja=v",
      "vby  p       e=v",
      "vb   p        =v",
      "vb            =v",
      "vb            =v",
      "vb            =v",
      "vb      ln    =v",
      "vb            =v",
      "vb            =v",
      "vb            =v",
      "vb   p        =v",
      "vbbbbb        =v",
      "v==============v",
      "vvvvvvvvvvvvvvvv"
    ],
    [
      "vvvvvvvvvvvvvvvv",
      "v==============v",
      "vbbbbb       a=v",
      "vbA  p       e=v",
      "vb   p        =v",
      "vb   p        =v",
      "vb   p        =v",
      "vb   pp       =v",
      "vb   p        =v",
      "vb            =v",
      "vb   p        =v",
      "vb   p        =v",
      "vb   p        =v",
      "vbbbbb        =v",
      "v==============v",
      "vvvvvvvvvvvvvvvv"
    ],
    [
      "vvvvvvvvvvvvvvvv",
      "v==============v",
      "vbbbbbBBBBBBBa=v",
      "vbCdddBBBBBBBe=v",
      "vbddddBBBBBBBB=v",
      "vbddddBBBBBBBB=v",
      "vbddddBBBBBBBB=v",
      "vbddddBBBBBBBB=v",
      "vbddddBBBBBBBB=v",
      "vbddddBBBBBBBB=v",
      "vbddddBBBBBBBB=v",
      "vbddddBBBBBBBB=v",
      "vbddddBBBBBBBB=v",
      "vbbbbbBBBBBBBB=v",
      "v==============v",
      "vvvvvvvvvvvvvvvv"
    ]
  ]
}