{
  "name": "building_office2_top_270",
  "refpalette": "c70cities:building_office2_top_palette_270",
  "xsize": 16,
  "zsize": 16,
  "slices": [
    [
      "                ",
      " a            a ",
      " a dddddddddd a ",
      " abeeeeeeeeeeba ",
      " acccccccccccca ",
      " acccccccccccca ",
      " acccccccccccca ",
      " afccccccccccca ",
      " afccccccccccca ",
      " acccccccccccca ",
      " acccccccccccca ",
      " accccccccccc!a ",
      " abeeeeeeeeeeba ",
      " a dddddddddd a ",
      " a            a ",
      "                "
    ],
    [
      "                ",
      " a            a ",
      " a dddddddddd a ",
      " ab          ba ",
      " ao  mkj     ga ",
      " ao           a ",
      " ap   l    i  a ",
      " a         ih a ",
      " a         i  a ",
      " ap        i  a ",
      " ao  n        a ",
      " ao          ga ",
      " ab          ba ",
      " a dddddddddd a ",
      " a            a ",
      "                "
    ],
    [
      "                ",
      " a            a ",
      " a dddddddddd a ",
      " ab          ba ",
      " ao          ga ",
      " ao           a ",
      " ag           a ",
      " a         q  a ",
      " a            a ",
      " ag           a ",
      " ao  r        a ",
      " ao          ga ",
      " ab          ba ",
      " a dddddddddd a ",
      " a            a ",
      "                "
    ],
    [
      "                ",
      " a            a ",
      " a dddddddddd a ",
      " ab          ba ",
      " a            a ",
      " a            a ",
      " a            a ",
      " a            a ",
      " a            a ",
      " a            a ",
      " a   r        a ",
      " a            a ",
      " ab          ba ",
      " a dddddddddd a ",
      " a            a ",
      "                "
    ],
    [
      "                ",
      " a            a ",
      " assssssssssssa ",
      " assssssssssssa ",
      " assssssssssssa ",
      " assssssssssssa ",
      " adddddddddddda ",
      " adddddddddddda ",
      " adddddddddddda ",
      " adddddddddddda ",
      " assssssssssssa ",
      " assssssssssssa ",
      " assssssssssssa ",
      " assssssssssssa ",
      " a            a ",
      "                "
    ],
    [
      "                ",
      " a            a ",
      " a            a ",
      " a            a ",
      " a            a ",
      " a            a ",
      " a            a ",
      " a            a ",
      " a            a ",
      " a            a ",
      " a            a ",
      " a            a ",
      " a            a ",
      " a            a ",
      " a            a ",
      "                "
    ]
  ]
}