{
  "name": "building_hotel2_floor3_180",
  "refpalette": "c70cities:building_hotel2_floor3_palette_180",
  "xsize": 16,
  "zsize": 16,
  "slices": [
    [
      "                ",
      "              a ",
      "    dddddddddda ",
      "    dccccccccca ",
      "    dc!ccccccca ",
      "    dccccccccca ",
      "    dccccccccca ",
      "    dccccccccca ",
      "    dccccccccca ",
      "    dccccccccca ",
      "    dc!ccccccca ",
      "    dcccccccc=a ",
      "    dccccccccba ",
      "    dccccccccba ",
      " aaaaaaaaaaaaaa ",
      "                "
    ],
    [
      "                ",
      "              a ",
      "    eeeeeeeeeea ",
      "    e         a ",
      "    e jii    ha ",
      "    e   g    ha ",
      "    e        ma ",
      "    e jii    la ",
      "    e   g    ka ",
      "    e        ha ",
      "    e jii    ha ",
      "    e   g   f=a ",
      "    e        ba ",
      "    e        ba ",
      " aaaaaaaaaaaaaa ",
      "                "
    ],
    [
      "                ",
      "              a ",
      "    eeeeeeeeeea ",
      "    e         a ",
      "    e        ha ",
      "    e        ha ",
      "    e         a ",
      "    e         a ",
      "    e         a ",
      "    e        ha ",
      "    e        ha ",
      "    e       n=a ",
      "    e        ba ",
      "    e        ba ",
      " aaaaaaaaaaaaaa ",
      "                "
    ],
    [
      "                ",
      "              a ",
      "    eeeeeeeeeea ",
      "    e         a ",
      "    e        ha ",
      "    e        ha ",
      "    e         a ",
      "    e         a ",
      "    e         a ",
      "    e        ha ",
      "    e        ha ",
      "    e       n=a ",
      "    e        ba ",
      "    e        ba ",
      " aaaaaaaaaaaaaa ",
      "                "
    ],
    [
      "                ",
      "              a ",
      "    eeeeeeeeeea ",
      "    e         a ",
      "    e         a ",
      "    e         a ",
      "    e    o    a ",
      "    e         a ",
      "    e         a ",
      "    e    o    a ",
      "    e         a ",
      "    e        =a ",
      "    e    o   ba ",
      "    e        ba ",
      " aaaaaaaaaaaaaa ",
      "                "
    ],
    [
      "                ",
      "              a ",
      "    iiiiiiiiiia ",
      "    ipppppppppa ",
      "    ipppppppppa ",
      "    ipppppppppa ",
      "    ipppppppppa ",
      "    ipppppppppa ",
      "    ipppppppppa ",
      "    ipppppppppa ",
      "    ipppppppppa ",
      "    ipppppppp=a ",
      "    ippppppppba ",
      "    ippppppppba ",
      " aaaaaaaaaaaaaa ",
      "                "
    ]
  ]
}