{
  "name": "building_hotel1_floor1_180",
  "refpalette": "c70cities:building_hotel1_floor1_palette_180",
  "xsize": 16,
  "zsize": 16,
  "slices": [
    [
      "                ",
      " aagggggaaaaaaa ",
      " abbbbbbbbbbbba ",
      " fbbbbbbbbbbbbd ",
      " fbbbbbbbbbbbbd ",
      " fbbbbbbbbbbbbd ",
      " fbbbbe   bbbbd ",
      " abbbb    bbbbd ",
      " abbbb    bbbbd ",
      " abbbd    bbbbd ",
      " acccccccccccca ",
      " abbbbbbbbbbbba ",
      " abbbbbbbbbbbba ",
      " abbbbbbbbbbbba ",
      " aaaaaaaaaaaaaa ",
      "                "
    ],
    [
      "                ",
      " aaaaaaaaaaaaaa ",
      " ausur sur sura ",
      " f            a ",
      " f            a ",
      " f            a ",
      " f    dee  s ra ",
      " au  t      u a ",
      " a   t     s ra ",
      " a            a ",
      " aqq aaaaaaaaaa ",
      " a p  konmmlkja ",
      " a            a ",
      " aiii        ha ",
      " aaaaaaaaaaaaaa ",
      "                "
    ],
    [
      "                ",
      " aaaaaaffffffaa ",
      " aA y   y   y a ",
      " f            a ",
      " f            a ",
      " f            a ",
      " f      de  y f ",
      " aA      e  y f ",
      " a          y f ",
      " a            f ",
      " a   aaaaaaaaaa ",
      " a     x   w  a ",
      " a            a ",
      " a            a ",
      " aaaaaaaaaaaaaa ",
      "                "
    ],
    [
      "                ",
      " aaaaaaaaaaaaaa ",
      " aA           a ",
      " f            a ",
      " f            a ",
      " f            a ",
      " f            a ",
      " aA      d    a ",
      " a       e    a ",
      " a       e    a ",
      " a   aaaaaaaaaa ",
      " a            a ",
      " a            a ",
      " a            a ",
      " aaaaaaaaaaaaaa ",
      "                "
    ],
    [
      "                ",
      " aaaaaaffaaaaaa ",
      " a            a ",
      " f            a ",
      " f            a ",
      " f            a ",
      " f            a ",
      " a            a ",
      " a            a ",
      " a     eed    a ",
      " aaaaaaaaaaaaaa ",
      " a            f ",
      " a            f ",
      " a            a ",
      " aaaaaaaaaaaaaa ",
      "                "
    ],
    [
      "                ",
      " aaaaaaaaaaaaaa ",
      " aBBBBBBBBBBBBa ",
      " fBBBBBBBBBBBBa ",
      " fBBBBBBBBBBBBa ",
      " fBBBBBBBBBBBBa ",
      " fBBBB    BBBBa ",
      " aBBBB    BBBBa ",
      " aBBBB    BBBBa ",
      " aBBBBed  BBBBa ",
      " aaaaaaaaaaaaaa ",
      " aBBBBBBBBBBBBa ",
      " aBBBBBBBBBBBBa ",
      " aBBBBBBBBBBBBa ",
      " aaaaaaaaaaaaaa ",
      "                "
    ]
  ]
}