{
  "name": "building_office1_ground",
  "refpalette": "c70cities:building_office1_ground_palette",
  "xsize": 16,
  "zsize": 16,
  "slices": [
    [
      "GGGGaGGGGGGaGGGG",
      "GbbbbbbbbbbbbbbG",
      "GbccccccccccccbG",
      "GbcbbbbbbbbbbcbG",
      "GbcbbbbbbbbbbcbG",
      "GbcbbbbbbbbbbcbG",
      "Gbcbbbbb!bbbbcbG",
      "GbcbbbbbbbbbbcbG",
      "GbdbbbbbbbbbbdbG",
      "GbdbbbbbbbbbbdbG",
      "GbdbbbbbbbbbbdbG",
      "GbdbbbbbbbbbbdbG",
      "GbebbbbbbbbbbdbG",
      "GbebbbbbbbbbbdbG",
      "GbbbbbbbbbbbbbbG",
      "GGGGGGGGGGGGGGGG"
    ],
    [
      "ffffffffffffffff",
      "   g  g  g  g   ",
      " ghhhhhhhhhhhhg ",
      "  hi        ih  ",
      "  h   j  j   h  ",
      " gh  k    l  hg ",
      "  h  mlllll  h  ",
      "  h          h  ",
      " gd          dg ",
      "  h  nn  nn  h  ",
      "  h  no  on  h  ",
      " pdq nn  nn  dp ",
      " p            r ",
      " p            s ",
      " pppppppppppppp ",
      "                "
    ],
    [
      "                ",
      "   g  g  g  g   ",
      " ghhhhhhhhhhhhg ",
      "  ht        th  ",
      "  h          h  ",
      " gh          hg ",
      "  h      u   h  ",
      "  h          h  ",
      " gd          dg ",
      "  h          h  ",
      "  h          h  ",
      " pdq         dp ",
      " p            w ",
      " p            x ",
      " ppyhhhhhhhhypp ",
      "                "
    ],
    [
      "                ",
      "   g  g  g  g   ",
      " ghhhhhhhhhhhhg ",
      "  ht        th  ",
      "  h          h  ",
      " gh          hg ",
      "  h          h  ",
      "  h          h  ",
      " gd          dg ",
      "  h          h  ",
      "  h          h  ",
      " pdq         dp ",
      " p            p ",
      " p            p ",
      " ppyhhhhhhhhypp ",
      "                "
    ],
    [
      "                ",
      "   g  g  g  g   ",
      " ghhhhhhhhhhhhg ",
      "  h          h  ",
      "  h          h  ",
      " gh          hg ",
      "  h          h  ",
      "  h          h  ",
      " gd          dg ",
      "  h          h  ",
      "  h          h  ",
      " pdq         dp ",
      " p            p ",
      " p            p ",
      " pppppppppppppp ",
      "                "
    ],
    [
      "                ",
      " AAAAAAAAAAAAAA ",
      " AAAAAAAAAA AAA ",
      " AAyyyyyyyyyyAA ",
      " AAyyyyyyyyyyAA ",
      " AAyyyyyyyyyyAA ",
      " AAyyyyyyyyyyAA ",
      " AAyyyyyyyyyyAA ",
      " AAyyyyyyyyyyAA ",
      "  h yyyyyyyy h  ",
      "  h yyyyyyyy h  ",
      " pdqyyyyyyyy dp ",
      " pyyyyyyyyyyyyp ",
      " pyyyyyyyyyyyyp ",
      " pppppppppppppp ",
      "                "
    ]
  ]
}