{
  "name": "building_restaurant1_ground_270",
  "refpalette": "c70cities:building_restaurant1_ground_palette_270",
  "xsize": 16,
  "zsize": 16,
  "slices": [
    [
      "GGGGGGGGGGGGGGGG",
      "GGGGGG======GGGG",
      "Geeeee=cccc=aaaG",
      "Geffff=ccccccbaG",
      "Geffff=cccccccaG",
      "Geffff=cccc=ccaG",
      "Geffff=cccc=ccaG",
      "Geffff=cccc=aaaG",
      "Geffff=cccc=ddaG",
      "Geffff=cccc=ddGG",
      "Geffff=cccc=dGGG",
      "Geffff=cccc=ddGG",
      "Geaaaa=cccc=GdGG",
      "Geeeee=ccc!=dGGG",
      "GGGGGG======dGGG",
      "GGGGGGGGGGGGGdGG"
    ],
    [
      "                ",
      "      ======    ",
      " eeeee=qok =aaa ",
      "BeA qu=    i  a ",
      "Ceooo      j  a ",
      "De     qo  =h a ",
      "De        k=  a ",
      "De         =  a ",
      "De  q  qok =  a ",
      "Eeo o rr   =    ",
      "Bey yu=mmm =    ",
      "Bewwww=s   = g  ",
      "Fexxxx=t   =    ",
      "Be    =tpnl=g g ",
      "      ======    ",
      "                "
    ],
    [
      "                ",
      "      ======    ",
      " eeeee= r  =Iaa ",
      " e   Q=    J  a ",
      " x r       K  a ",
      " x         =h a ",
      " x         =  a ",
      " x         =  a ",
      " x         =  a ",
      " xR        L    ",
      " e   Q=rrM L    ",
      " ewwww=O   L    ",
      " x    =P   L    ",
      " e    =  N =    ",
      "      ======    ",
      "                "
    ],
    [
      "                ",
      "      ==TT==    ",
      " eeeee=    =Iaa ",
      " e   Q=    =  a ",
      "           =  a ",
      "           =h a ",
      "           =SSa ",
      "           =LLa ",
      "           =LLa ",
      "           =LL  ",
      " e   Q=    =    ",
      " ewwww=    =    ",
      "      =  U =    ",
      " e    =    =    ",
      "      =II===    ",
      "                "
    ],
    [
      "                ",
      "      ======    ",
      " eeeee=  V =aaa ",
      " e    =    =  a ",
      "   U  =    =  a ",
      "      =    =h a ",
      "      =    =SSa ",
      "      =  V =LLa ",
      "      =    =LLa ",
      "      =    =    ",
      " e    =    =    ",
      " ewwww=    =    ",
      "      =  V =    ",
      " e    =    =    ",
      "      ======    ",
      "                "
    ],
    [
      "                ",
      "      ======    ",
      " eeeee=WWWW=aaa ",
      " e    =WWWW=  a ",
      " e V  =WWWW=  a ",
      " e    =WWWW=h a ",
      " e    =WWWW=SSa ",
      " e    =WWWW=LLa ",
      " e    =WWWW=  a ",
      " e V  =WWWW=    ",
      " e    =WWWW=    ",
      " ewwww=WWWW=    ",
      " e    =WWWW=    ",
      " e    =WWWW=    ",
      "      ======    ",
      "                "
    ]
  ]
}