{
  "name": "building_hotel3_base1_90",
  "refpalette": "c70cities:building_hotel3_base1_palette_90",
  "xsize": 16,
  "zsize": 16,
  "slices": [
    [
      "vvvvvvvvvvvvvvvv",
      "vaaaaaaaaaaaaaav",
      "vabbbbbbbbbbbbav",
      "vabbbbbbbbbbbbav",
      "vabbcbbbbbbcbbav",
      "vabbbbbbbbbbbbav",
      "vabbbbbbbbbbbbav",
      "vabbcdbbbbbbbbav",
      "vabbcdbbbbbbbbav",
      "vabbbbbbbbbbbbav",
      "vabbbbbbbbbbbbav",
      "vabbbbbbbbbcbbav",
      "vabbbbbbbbbbbbav",
      "vabbbbbbbbbbbbav",
      "vaaaaaaaaaaaaaav",
      "vvvvvvvvvvvvvvvv"
    ],
    [
      "vvvvvvvvvvvvvvvv",
      "vaaaaaaaaaaaaaav",
      "va     ms w  wav",
      "va njr ms u  uav",
      "va mcq ms tc tav",
      "va lop ms    !av",
      "va      s w  wav",
      "vajjcd    u  uav",
      "vaiicd    u  uav",
      "vahki     t  tav",
      "vag  i       !av",
      "vaf    i  wc wav",
      "vaf    i  u  uav",
      "vae    i  t  tav",
      "vaaaaaaaaaaaaaav",
      "vvvvvvvvvvvvvvvv"
    ],
    [
      "vvvvvvvvvvvvvvvv",
      "vaaaaaaaaaaaaaav",
      "va      s     av",
      "va      s C  Cav",
      "va  c   s  c  av",
      "va      s     av",
      "va      s     av",
      "va  cd    C  Cav",
      "vaiicd    C  Cav",
      "va  i         av",
      "vaB  i        av",
      "vaA        c  av",
      "vay       C  Cav",
      "vax           av",
      "vaaaaaaaaaaaaaav",
      "vvvvvvvvvvvvvvvv"
    ],
    [
      "vvvvvvvvvvvvvvvv",
      "vaaaaaaaaaaaaaav",
      "va      s     av",
      "va      s     av",
      "va  c   s  c  av",
      "va      s     av",
      "va      s     av",
      "va  cd        av",
      "vaiicd        av",
      "vaDEi         av",
      "va   i        av",
      "va         c  av",
      "va            av",
      "va            av",
      "vaaaaaaaaaaaaaav",
      "vvvvvvvvvvvvvvvv"
    ],
    [
      "vvvvvvvvvvvvvvvv",
      "vaaaaaaaaaaaaaav",
      "va      s     av",
      "va      s     av",
      "va  c   s  c  av",
      "va      s     av",
      "va      s     av",
      "va  cd        av",
      "vaiicd        av",
      "vaFIi         av",
      "va   i        av",
      "va         c  av",
      "va            av",
      "va            av",
      "vaaaaaaaaaaaaaav",
      "vvvvvvvvvvvvvvvv"
    ],
    [
      "vvvvvvvvvvvvvvvv",
      "vaaaaaaaaaaaaaav",
      "vaJJJJJJJJJJJJav",
      "vaJJJJJJJJJJJJav",
      "vaJJcJJJJJJcJJav",
      "vaJJJJJJJJJJJJav",
      "vaJJJJJJJJJJJJav",
      "vaJJcdJJJJJJJJav",
      "vaJJcdJJJJJJJJav",
      "vaJJJJJJJJJJJJav",
      "vaJJJJJJJJJJJJav",
      "vaJJcJJJJJJcJJav",
      "vaJJJJJJJJJJJJav",
      "vaJJJJJJJJJJJJav",
      "vaaaaaaaaaaaaaav",
      "vvvvvvvvvvvvvvvv"
    ]
  ]
}