{
  "name": "building_residential1_floor1_270",
  "refpalette": "c70cities:building_residential1_floor1_palette_270",
  "xsize": 16,
  "zsize": 16,
  "slices": [
    [
      "                ",
      "            cba ",
      "      jdffffdba ",
      "      jd  hgeba ",
      "      ji    eba ",
      "      ji    eba ",
      "      ji    eba ",
      "      ji    eba ",
      "      ji    eba ",
      "      ji    eba ",
      "      ji    eba ",
      "      ji    eba ",
      "      jd    eba ",
      "      jdffffdba ",
      "            cba ",
      "                "
    ],
    [
      "                ",
      "          cba   ",
      "       dffdba   ",
      "       d  eba   ",
      "       k  eba   ",
      "       k  eba   ",
      "       k  eba   ",
      "       k  eba   ",
      "       k  eba   ",
      "       k  eba   ",
      "       k  eba   ",
      "       k  eba   ",
      "       d  eba   ",
      "       dffdba   ",
      "          cba   ",
      "                "
    ],
    [
      "                ",
      "        cba     ",
      "       ddba     ",
      "       deba     ",
      "       deba     ",
      "       deba     ",
      "       deba     ",
      "       deba     ",
      "       deba     ",
      "       deba     ",
      "       deba     ",
      "       deba     ",
      "       deba     ",
      "       ddba     ",
      "        cba     ",
      "                "
    ],
    [
      "                ",
      "      cba       ",
      "      cba       ",
      "      cba       ",
      "      cba       ",
      "      cba       ",
      "      cba       ",
      "      cba       ",
      "      cba       ",
      "      cba       ",
      "      cba       ",
      "      cba       ",
      "      cba       ",
      "      cba       ",
      "      cba       ",
      "                "
    ],
    [
      "                ",
      "      a         ",
      "      a         ",
      "      a         ",
      "      a         ",
      "      a         ",
      "      a         ",
      "      a         ",
      "      a         ",
      "      a         ",
      "      a         ",
      "      a         ",
      "      a         ",
      "      a         ",
      "      a         ",
      "                "
    ],
    [
      "                ",
      "                ",
      "                ",
      "                ",
      "                ",
      "                ",
      "                ",
      "                ",
      "      ~         ",
      "                ",
      "                ",
      "                ",
      "                ",
      "                ",
      "                ",
      "                "
    ]
  ]
}