{
  "name": "building_bank1_floor2",
  "refpalette": "c70cities:building_bank1_floor2_palette",
  "xsize": 16,
  "zsize": 16,
  "slices": [
    [
      "                ",
      "   abbc  abbc   ",
      "  deeeedeeeeed  ",
      " feeeeeeeeeeeeg ",
      " beeeeeeeeeeeeb ",
      " be eeee!eeeeeb ",
      " he eeeeeeeeeei ",
      "  e eeeeeeeeed  ",
      "  d eeeeee!eee  ",
      " fejeeeeeeeeeeg ",
      " beeeeeeeeeeeeb ",
      " beeeeeeeeeeeeb ",
      " heeeeeeeeeeeei ",
      "  deeeeedeeeed  ",
      "   kbbl  kbbl   ",
      "                "
    ],
    [
      "                ",
      "  abbc  abbc    ",
      "  mmmmnmmmmmnmg ",
      "  n     o    mb ",
      " fm    po qr mb ",
      " bsjt  po u  mi ",
      " bm t   o wx n  ",
      " hm t        m  ",
      "  m t   yoooomg ",
      "  n t        mb ",
      " fm    o ABr mb ",
      " bm    o x C mi ",
      " bm    o     n  ",
      " hmnmmmmmnmmmm  ",
      "    kbbl  kbbl  ",
      "                "
    ],
    [
      "                ",
      " Dbbc  abbc  aD ",
      " hmmmnmmmmmnmmb ",
      "  m     o    mb ",
      "  n     o    mi ",
      " fm t   o    n  ",
      " bsj    o    m  ",
      " bm t        mg ",
      " hm     Eoooomb ",
      "  m t        mb ",
      "  n    o     mi ",
      " fm    o     n  ",
      " bm    o     m  ",
      " bmmnmmmmmnmmmg ",
      " Dl  kbbl  kbbD ",
      "                "
    ],
    [
      "                ",
      " Dbc  abbc  abD ",
      " bmmnmmmmmnmmmb ",
      " hm          mi ",
      "  m          n  ",
      "  n t        m  ",
      " fm          mg ",
      " bsjt        mb ",
      " bm     E    mb ",
      " hm t        mi ",
      "  m          n  ",
      "  n          m  ",
      " fm          mg ",
      " bmmmnmmmmmnmmb ",
      " Dbl  kbbl  kbD ",
      "                "
    ],
    [
      "                ",
      " Dc  abbc  abbD ",
      " bmnmmmmmnmmmmi ",
      " bm          n  ",
      " hm          m  ",
      "  m t        mg ",
      "  n          mb ",
      " fm t        mb ",
      " bsj         mi ",
      " bm t        n  ",
      " hm          m  ",
      "  m          mg ",
      "  n          mb ",
      " fmmmmnmmmmmnmb ",
      " Dbbl  kbbl  kD ",
      "                "
    ],
    [
      "                ",
      "    abbc  abbc  ",
      " fnmmmmmnmmmmn  ",
      " bmFFFFFFFFFFm  ",
      " bmFFFFFFFFFFmg ",
      " hm tFFFFFFFFmb ",
      "  m  FFFFFFFFmb ",
      "  n tFFFFFFFFmi ",
      " fm  FFFFFFFFn  ",
      " bsjtFFFFFFFFm  ",
      " bmFFFFFFFFFFmg ",
      " hmFFFFFFFFFFmb ",
      "  mFFFFFFFFFFmb ",
      "  nmmmmnmmmmmni ",
      "  kbbl  kbbl    ",
      "                "
    ]
  ]
}