{
  "name": "building_warehouse2_ground_180",
  "refpalette": "c70cities:building_warehouse2_ground_palette_180",
  "xsize": 16,
  "zsize": 16,
  "slices": [
    [
      "zzzzzzzzzzzzzzaa",
      "zbddbbbdbbbdazaz",
      "zbbbbbbbbbbbaaaz",
      "zbbbbbbbbbbbaaaz",
      "zdbbbbbbbbbbaaaz",
      "zbdbbbbbbbbdaaza",
      "zbbbbbbbbbbdaaaz",
      "zbccccccccbbaaaz",
      "zbccccccccbdaazz",
      "zbccccccccbbaazz",
      "zbccccccccbbaaaz",
      "zbccccccccbdaaaa",
      "zbccccccccbdaaza",
      "zbccccccccbbaaaz",
      "zbbbbbbbbbbbzaaz",
      "zzzzzzzzzzzzazaz"
    ],
    [
      " u eee  e  u e  ",
      "e               ",
      "  fggxwfggf    e",
      "u gf   tsgg     ",
      "e  r     r     e",
      "   r     r    e ",
      " ffg    ggg     ",
      "efq            e",
      " gjn p   o      ",
      "egiji           ",
      " fiiii o  f    e",
      " gkkn     h     ",
      " fmkikl l h   e ",
      " fkkkji   h     ",
      "eggfggggggf     ",
      " e  e  e e e    "
    ],
    [
      "                ",
      "                ",
      "  gggBAgffg     ",
      "  fg   y fg     ",
      "   r     r      ",
      "   r     r      ",
      " fgg    ggf     ",
      " gq       h     ",
      " g        h     ",
      " fn       h     ",
      " giiil    g     ",
      " gij      h     ",
      " gki      h     ",
      " gmkj n   h     ",
      " gfgfrrgfgg     ",
      "                "
    ],
    [
      "                ",
      "                ",
      "  ggfEEgfgg     ",
      "  fg   D gg     ",
      "   r     r      ",
      "   r     r      ",
      " ggfCCCCgfg     ",
      " gq       h     ",
      " g        h     ",
      " f        h     ",
      " g l     jg     ",
      " gi       h     ",
      " f        h     ",
      " g!j      h     ",
      " ffgggggggf     ",
      "                "
    ],
    [
      "                ",
      " FFFFFFFFFFF    ",
      " FgggggggggF    ",
      " FggJ  J ggF    ",
      " FFI     IKF    ",
      " FFI     IKF    ",
      " gggggggfgfF    ",
      " gq EEEE IgF    ",
      " g       IfF    ",
      " g       IgF    ",
      " g     J jgF    ",
      " f       IgF    ",
      " g       IgF    ",
      " gj      IgF    ",
      " gfggggfggg     ",
      "                "
    ],
    [
      "                ",
      "                ",
      "  MMMMMMMMM     ",
      "  MMMMMMMMM     ",
      "  MMMMMMMMM     ",
      "  MMMMMMMMM     ",
      " gggggggggf     ",
      " fqLLLLLLLg     ",
      " gLLLLLLLLg     ",
      " gLLLLLLLLf     ",
      " gLLLLLbLLg     ",
      " gLLLLLLLLg     ",
      " gLLLLLLLLg     ",
      " gLLLLLLLLf     ",
      " ggggfggggg     ",
      "                "
    ]
  ]
}