{
  "name": "building_hotel2_base1_90",
  "refpalette": "c70cities:building_hotel2_base1_palette_90",
  "xsize": 16,
  "zsize": 16,
  "slices": [
    [
      "vvvvvvvvvvvvvvvv",
      "vaaaaaaaaaaaaaav",
      "vabbbbbbbbbbb!av",
      "vabbbbbbbbbbbbav",
      "vabbbbbbbbbbbbav",
      "vabbbbbbbbbbbbav",
      "vabbbbbbbbbbbbav",
      "vabbbbbbbbbbb!av",
      "vabbbbbbbbbbbbav",
      "vabbbbbbbbbbbbav",
      "vabbbbbbbbbbbbav",
      "vabbbbbbbbbbbbav",
      "vabbbbbbbbbbbbav",
      "vabbbbbbbbbbb!av",
      "vaaaaaaaaaaaaaav",
      "vvvvvvvvvvvvvvvv"
    ],
    [
      "vvvvvvvvvvvvvvvv",
      "vccccccccccccccv",
      "vcbbbbb=jflllocv",
      "vcbbbbbh      cv",
      "vcbbbbbh      cv",
      "vc=====h fkmnmcv",
      "vc e e   fffffcv",
      "vc        gei cv",
      "vc            cv",
      "vc    g i g i cv",
      "vc     e   e  cv",
      "vc    g i g i cv",
      "vc  e         cv",
      "vcdd= gei gei cv",
      "vccc=fffffffffcv",
      "vvvvvvvvvvvvvvvv"
    ],
    [
      "vvvvvvvvvvvvvvvv",
      "vccccccccccccccv",
      "vcppppp=jf    cv",
      "vco  t        cv",
      "vco           cv",
      "vc=rrrr  fu wxcv",
      "vc q q   fffffcv",
      "vc         j  cv",
      "vc            cv",
      "vc     j   j  cv",
      "vc     j   j  cv",
      "vc     j   j  cv",
      "vc  s         cv",
      "vcdd=  j   j  cv",
      "vccc=fffffffffcv",
      "vvvvvvvvvvvvvvvv"
    ],
    [
      "vvvvvvvvvvvvvvvv",
      "vccccccccccccccv",
      "vctt tt=jfABA cv",
      "vc            cv",
      "vc            cv",
      "vcy      f    cv",
      "vc       fffffcv",
      "vc            cv",
      "vc            cv",
      "vc            cv",
      "vc            cv",
      "vc            cv",
      "vc  s         cv",
      "vcdd=         cv",
      "vccc=fffffffffcv",
      "vvvvvvvvvvvvvvvv"
    ],
    [
      "vvvvvvvvvvvvvvvv",
      "vccccccccccccccv",
      "vcttt t=jf B  cv",
      "vc       f    cv",
      "vc       f    cv",
      "vc       f    cv",
      "vc       fffffcv",
      "vc            cv",
      "vc            cv",
      "vc            cv",
      "vc            cv",
      "vc            cv",
      "vc            cv",
      "vcdd=         cv",
      "vccc=fffffffffcv",
      "vvvvvvvvvvvvvvvv"
    ],
    [
      "vvvvvvvvvvvvvvvv",
      "vccccccccccccccv",
      "vcDEDDE=CfCCCCcv",
      "vcCCCCCCCfCCCCcv",
      "vcCCCCCCCfCCCCcv",
      "vcCCCCCCCfCCCCcv",
      "vcCCCCCCCfffffcv",
      "vcCCCCCCCCCCCCcv",
      "vcCCCCCCCCCCCCcv",
      "vcCCCCCCCCCCCCcv",
      "vcCCCCCCCCCCCCcv",
      "vcCCCCCCCCCCCCcv",
      "vcCCCCCCCCCCCCcv",
      "vcdd=CCCCCCCCCcv",
      "vccc=CCCCCCCCCcv",
      "vvvvvvvvvvvvvvvv"
    ]
  ]
}