{
  "name": "building_restaurant1_floor1_270",
  "refpalette": "c70cities:building_restaurant1_floor1_palette_270",
  "xsize": 16,
  "zsize": 16,
  "slices": [
    [
      "                ",
      "      ======    ",
      " fffff=GGGG=aaa ",
      " fgggg=bbbbbbba ",
      " fggggbbbbbbbba ",
      " fggggbbbbb=d a ",
      " fggggbbbbb=bba ",
      " fggggbbbbb=cca ",
      " fggggbbbbb=  a ",
      " fggggbbbbb=    ",
      " fgggg=bbbb=    ",
      " fgggg=bbbbe    ",
      " fhhhh=bbbbe    ",
      " f    =!bbbe    ",
      "      ==eeee    ",
      "                "
    ],
    [
      "                ",
      "      ======    ",
      " fffff=llll=aaa ",
      "JfC CB=mmmmj  a ",
      "KfE E      k  a ",
      "Lf         =d a ",
      "LfI    w  n=iia ",
      "Lf   C  o o=cca ",
      "LfC  A  p p=  a ",
      "MfE E A    =    ",
      "JfI FB=qqtq=    ",
      "JfDDDD=x  r=    ",
      "Nf    =y   =    ",
      "Jf    =xsus=    ",
      "      ======    ",
      "                "
    ],
    [
      "                ",
      "      ======    ",
      " fffff=QQQQ=eaa ",
      " f   Q=    O  a ",
      " W         P  a ",
      " W         =d a ",
      " W         =iia ",
      " W      U  =cca ",
      " W         =  a ",
      " W         c    ",
      " f   Q=AA Rc    ",
      " fDDDD=V  Sc    ",
      " W    =    c    ",
      " f    =  T =    ",
      "      ======    ",
      "                "
    ],
    [
      "                ",
      "      ==XX==    ",
      " fffff=    =eaa ",
      " f   Q=    =  a ",
      "           =  a ",
      "           =d a ",
      "           =iia ",
      "         Y =cca ",
      "           =  a ",
      "           =    ",
      " f   Q=    =    ",
      " fDDDD=    =    ",
      "      =    =    ",
      " f    =    =    ",
      "      =ee===    ",
      "                "
    ],
    [
      "                ",
      "      ======    ",
      " fffff=    =aaa ",
      " f    =    =  a ",
      "      =    =  a ",
      "      =    =d a ",
      "      =    =iia ",
      "      =  Z =cca ",
      "      =    =  a ",
      "   Y  =    =    ",
      " f    =    =    ",
      " fDDDD=    =    ",
      "      =  Z =    ",
      " f    =    =    ",
      "      ======    ",
      "                "
    ],
    [
      "                ",
      "      ======    ",
      " fffff=1111=aaa ",
      " f    =1111=0 a ",
      " f Z  =1111=  a ",
      " f    =1111=d a ",
      " f    =1111=iia ",
      " f    =1111=cca ",
      " f    =1111=  a ",
      " f Z  =1111=    ",
      " f    =1111=    ",
      " fDDDD=1111=    ",
      " f    =1111=    ",
      " f    =1111=    ",
      "      ======    ",
      "                "
    ]
  ]
}