{
  "name": "building_hotel1_floor2",
  "refpalette": "c70cities:building_hotel1_floor2_palette",
  "xsize": 16,
  "zsize": 16,
  "slices": [
    [
      "                ",
      " aaaaaaaaaaaaaa ",
      " abbbbbbbbbbbba ",
      " abbbbbbbbbbbba ",
      " abbbbbbbbbbbba ",
      " abbbccccccccca ",
      " dbbbc    dbbba ",
      " dbbbc    bbbba ",
      " dbbbc    bbbba ",
      " dbbbc   ebbbbf ",
      " dbbbcccccbbbbf ",
      " dbbbbbbbcbbbbf ",
      " dbbbbbbbcbbbbf ",
      " abbbbbbbbbbbba ",
      " aaaaaaagggggaa ",
      "                "
    ],
    [
      "                ",
      " aaaaaaaaaaaaaa ",
      " a h  ijjk  l a ",
      " amn          a ",
      " a   opqqpo   a ",
      " a  rsaaaasataa ",
      " a  =a        a ",
      " a  ua    w   a ",
      " a  ua    w  na ",
      " a  =a eed    f ",
      " a aasaaaa    f ",
      " a xx fyAa    f ",
      " a BB f CaeDD f ",
      " a      Eaeeena ",
      " aaaaaaaaaaaaaa ",
      "                "
    ],
    [
      "                ",
      " aaaaaaaaaaaaaa ",
      " a            a ",
      " a F          a ",
      " a   o  I o   a ",
      " a   saaaasaJaa ",
      " f  Ka        a ",
      " f   a        a ",
      " f   ae      La ",
      " f  Maed      f ",
      " a aasaaaa    f ",
      " a    f Na    f ",
      " a    f  a    f ",
      " a       a   La ",
      " aaffffffaaaaaa ",
      "                "
    ],
    [
      "                ",
      " aaaaaaaaaaaaaa ",
      " a   O    O   a ",
      " a            a ",
      " a            a ",
      " a   saaaasaaaa ",
      " a   ae       a ",
      " a  Dae       a ",
      " a  Dad      La ",
      " a   a        f ",
      " aaaasaaaa    f ",
      " a   Of Pa    f ",
      " a    f  a    f ",
      " a       a   La ",
      " aaaaaaaaaaaaaa ",
      "                "
    ],
    [
      "                ",
      " aaaaaaaaaaaaaa ",
      " a   Q    Q   a ",
      " f            a ",
      " f            a ",
      " a   saaaasaaaa ",
      " a   adee     a ",
      " a   a        a ",
      " a   a        a ",
      " a   a        f ",
      " aaaasaaaa    f ",
      " a   Qf  a    f ",
      " a    f  a    f ",
      " a    f  a    a ",
      " aaaaaaffaaaaaa ",
      "                "
    ],
    [
      "                ",
      " aaaaaaaaaaaaaa ",
      " aRRRRRRRRRRRRa ",
      " aRRRRRRRRRRRRa ",
      " aRRRRRRRRRRRRa ",
      " aRRRsaaaasaaaa ",
      " aRRRa  deRRRRa ",
      " aRRRa    RRRRa ",
      " aRRRa    RRRRa ",
      " aRRRa    RRRRf ",
      " aRRRsaaaaRRRRf ",
      " aRRRRRRRaRRRRf ",
      " aRRRRRRRaRRRRf ",
      " aRRRRRRRaRRRRa ",
      " aaaaaaaaaaaaaa ",
      "                "
    ]
  ]
}