{
  "name": "building_warehouse1_ground_180",
  "refpalette": "c70cities:building_warehouse1_ground_palette_180",
  "xsize": 16,
  "zsize": 16,
  "slices": [
    [
      "zzzzzzzzzzzzzzzz",
      "zbddbbbdbbbdazaa",
      "zbbbbbbbbbbbaaaz",
      "zbbbbbbbbbbbaaaa",
      "zdbbbbbbbbbbaaaz",
      "zbdbbbbbbbbdaazz",
      "zbbbbbbbbbbdaaaz",
      "zbccccccccbbaaaz",
      "zbccccccccbdaazz",
      "zbccccccccbbaazz",
      "zbccccccccbbaaaz",
      "zbccccccccbdaaaz",
      "zbccccccccbdaaza",
      "zbccccccccbbaaaa",
      "zbbbbbbbbbbbzaaa",
      "zzzzzzzzzzzzzzzz"
    ],
    [
      "  u e e u  e   e",
      "e               ",
      "  gfgtsgfgg     ",
      "  fg   rqgg     ",
      "e  p     p     e",
      "   p     p      ",
      "egfg    ggf     ",
      " foi     ih    e",
      " gn       h     ",
      "egnnn     h     ",
      " gnnn m   g    e",
      " gjjj     h     ",
      "egkjjjj   h     ",
      " flkjjjji h     ",
      "egfggfggfgf     ",
      " e  e e e  e  e "
    ],
    [
      "                ",
      "                ",
      "  fggyxgggf     ",
      "  gg   w fg     ",
      "   p     p      ",
      "   p     p      ",
      " ffg    ggg     ",
      " go       h     ",
      " g        h     ",
      " gnn      h     ",
      " gn       g     ",
      " f!i      h     ",
      " gj       h     ",
      " gjjjj    h     ",
      " gffgppfggf     ",
      "                "
    ],
    [
      "                ",
      "                ",
      "  gggCCgffg     ",
      "  gf   B gg     ",
      "   p     p      ",
      "   p     p      ",
      " ggfAAAAggg     ",
      " go       h     ",
      " fi       h     ",
      " gn       h     ",
      " g        f     ",
      " g        h     ",
      " fj       h     ",
      " gjji     h     ",
      " ggfggggggg     ",
      "                "
    ],
    [
      "                ",
      " DDDDDDDDDDD    ",
      " DgggggggggD    ",
      " DggB  F ggD    ",
      " DDE     EDD    ",
      " DDE     EDD    ",
      " fggggggfgfD    ",
      " go CCCCiEgD    ",
      " g       EfD    ",
      " g       EgD    ",
      " g     F igD    ",
      " g       EgD    ",
      " g       EgD    ",
      " gi    iiEgD    ",
      " fgggggggfg     ",
      "                "
    ],
    [
      "                ",
      "                ",
      "  JJJJJJJJJ     ",
      "  JJJJJJJJJ     ",
      "  JJJJJJJJJ     ",
      "  JJJJJJJJJ     ",
      " gggggggggg     ",
      " goIIIIIIIg     ",
      " gIIIIIIIIg     ",
      " gIIIIIIIIg     ",
      " gIIIIIbIIf     ",
      " gIIIIIIIIg     ",
      " gIIIIIIIIf     ",
      " gIIIIIIIIg     ",
      " ggggfggggg     ",
      "                "
    ]
  ]
}