{
  "name": "building_factory1_ground_270",
  "refpalette": "c70cities:building_factory1_ground_palette_270",
  "xsize": 16,
  "zsize": 16,
  "slices": [
    [
      "aaaazzaaaaazaaaa",
      "aaaaaaaazaaaaaaa",
      "azzaaaaaaaaaazaz",
      "zzbbbbbbbbbbbbzz",
      "zzbbbbbbbbbbbbzz",
      "zzbbbbbbbbbbbbzz",
      "zzbbbbbbbbbbbbzz",
      "zzbbbbbbbbbbbbzz",
      "zzbbbbbbbbbbbbzz",
      "zzbbbbbbbbbbbbzz",
      "zzbbbbbbbbbbbbzz",
      "zzbbbcbcbbbbbbzz",
      "zzbbbbbbbbbbbbzz",
      "zzbbbbbbbbbbbbzz",
      "zzzzzzzzzzzzzzzz",
      "zzzzzzzzzzzzzzzz"
    ],
    [
      "                ",
      "                ",
      "                ",
      " dhh        hh  ",
      "Odhix       ih d",
      "d hIx yt   njh  ",
      "ddhJxB     njhd ",
      " dhKx      n!h e",
      "ddhixA      ih  ",
      "N hLD Ar  okkh f",
      "ddhMEuuur p lh  ",
      "dNhMFCwwsqo mh d",
      "  hixxxx  o ihg ",
      "  hhhhhhhhhhhh d",
      "e d d    d    d ",
      "     d      d  d"
    ],
    [
      "                ",
      "                ",
      "                ",
      "  hhQQQQQQQQhh  ",
      "  hi        ih  ",
      "  h         nh  ",
      "  hX        nh  ",
      "  h          h  ",
      "  hiU       ih  ",
      "  h V     okkh  ",
      "  hM      R  h  ",
      "  hMW   TSo Ph  ",
      "  hixxxx  o ihg ",
      "  hhhhhhhhhhhh  ",
      "                ",
      "                "
    ],
    [
      "                ",
      "                ",
      "                ",
      "  hhQQQQQQQQhh  ",
      "  hi        ih  ",
      "  h2         h  ",
      "  h3         h  ",
      "  h4       Z h  ",
      "  hi        ih  ",
      "  h       okkh  ",
      "  hM1     o  h  ",
      "  hM  00  o  h  ",
      "  hi xxx  o ihY ",
      "  hhhhhhhhhhhh  ",
      "                ",
      "                "
    ],
    [
      "                ",
      "                ",
      "    99999999    ",
      "  hhhhhhhhhhhh  ",
      "  hi    @@@@ih  ",
      "  58       #85  ",
      "  68   &   $86  ",
      "  78       $87  ",
      "  hi      ^%ih  ",
      "  58      ok85  ",
      "  68      o 86  ",
      "  78      o 87  ",
      "  hi      o ih  ",
      "  hhhhhhhhhhhh  ",
      "                ",
      "                "
    ],
    [
      "                ",
      "                ",
      "                ",
      "  *hhhhhhhhhh*  ",
      "  *(-8    8)(*  ",
      "  *( 8    8 (*  ",
      "  *( 8 +  8 (*  ",
      "  *( 8    8 (*  ",
      "  *(-8    8)(*  ",
      "  *( 8    8 (*  ",
      "  *( 8 +  8 (*  ",
      "  *( 8    8 (*  ",
      "  *(-8    8)(*  ",
      "  *hhhhhhhhhh*  ",
      "                ",
      "                "
    ]
  ]
}