{
  "name": "building_warehouse1_ground",
  "refpalette": "c70cities:building_warehouse1_ground_palette",
  "xsize": 16,
  "zsize": 16,
  "slices": [
    [
      "zzzzzzzzzzzzzzzz",
      "aaazbbbbbbbbbbbz",
      "aaaabbccccccccbz",
      "azaadbccccccccbz",
      "zaaadbccccccccbz",
      "zaaabbccccccccbz",
      "zzaabbccccccccbz",
      "zzaadbccccccccbz",
      "zaaabbccccccccbz",
      "zaaadbbbbbbbbbbz",
      "zzaadbbbbbbbbdbz",
      "zaaabbbbbbbbbbdz",
      "aaaabbbbbbbbbbbz",
      "zaaabbbbbbbbbbbz",
      "aazadbbbdbbbddbz",
      "zzzzzzzzzzzzzzzz"
    ],
    [
      " e  e  e e e  e ",
      "     fgfggfggfge",
      "     h ijjjjklf ",
      "     h   jjjjkge",
      "     h     jjjg ",
      "e    g   m nnng ",
      "     h     nnnge",
      "     h       ng ",
      "e    hi     iof ",
      "     fgg    gfge",
      "      p     p   ",
      "e     p     p  e",
      "     ggqr   gf  ",
      "     ggfgstgfg  ",
      "               e",
      "e   e  u e e u  "
    ],
    [
      "                ",
      "     fggfppgffg ",
      "     h    jjjjg ",
      "     h       jg ",
      "     h      i!f ",
      "     g       ng ",
      "     h      nng ",
      "     h        g ",
      "     h       og ",
      "     ggg    gff ",
      "      p     p   ",
      "      p     p   ",
      "     gf w   gg  ",
      "     fgggxyggf  ",
      "                ",
      "                "
    ],
    [
      "                ",
      "     gggggggfgg ",
      "     h     ijjg ",
      "     h       jf ",
      "     h        g ",
      "     f        g ",
      "     h       ng ",
      "     h       if ",
      "     h       og ",
      "     gggAAAAfgg ",
      "      p     p   ",
      "      p     p   ",
      "     gg B   fg  ",
      "     gffgCCggg  ",
      "                ",
      "                "
    ],
    [
      "                ",
      "     gfgggggggf ",
      "    DgEii    ig ",
      "    DgE       g ",
      "    DgE       g ",
      "    Dgi F     g ",
      "    DgE       g ",
      "    DfE       g ",
      "    DgEiCCCC og ",
      "    Dfgfggggggf ",
      "    DDE     EDD ",
      "    DDE     EDD ",
      "    Dgg F  BggD ",
      "    DgggggggggD ",
      "    DDDDDDDDDDD ",
      "                "
    ],
    [
      "                ",
      "     gggggfgggg ",
      "     gIIIIIIIIg ",
      "     fIIIIIIIIg ",
      "     gIIIIIIIIg ",
      "     fIIbIIIIIg ",
      "     gIIIIIIIIg ",
      "     gIIIIIIIIg ",
      "     gIIIIIIIog ",
      "     gggggggggg ",
      "     JJJJJJJJJ  ",
      "     JJJJJJJJJ  ",
      "     JJJJJJJJJ  ",
      "     JJJJJJJJJ  ",
      "                ",
      "                "
    ]
  ]
}