{
  "name": "building_bank1_top",
  "refpalette": "c70cities:building_bank1_top_palette",
  "xsize": 16,
  "zsize": 16,
  "slices": [
    [
      "                ",
      "  abbbc abbbc   ",
      "  deeeedeeeeeda ",
      " ceeeeeeeeeeeeb ",
      " beeeeeeeeeeeeb ",
      " be eeeeeeeeeeb ",
      " be eeeeeeeeeec ",
      " ae eeeeeeeeed  ",
      "  d eeeeeeeeeea ",
      " ce eeeeeeeeeeb ",
      " beeeeeeeeeeeeb ",
      " beeeeeeeeeeeeb ",
      " beeeeeeeeeeeec ",
      " adeeeeedeeeed  ",
      "   cbbba cbbba  ",
      "                "
    ],
    [
      "                ",
      " fbcc abbcc abf ",
      " bgggghggggghgb ",
      " ah          gc ",
      "  g          gc ",
      " cg     ijk  g  ",
      " cg   l m    ha ",
      " bg     n o  gb ",
      " bg   l m    gb ",
      " ah     pqrr gc ",
      "  g          gc ",
      " cgssssssssssg  ",
      " cgtuuuttuuuwha ",
      " bghggggghggggb ",
      " fba ccbba ccbf ",
      "                "
    ],
    [
      "                ",
      " fbbbbbbbbbbbbf ",
      " bgggghggggghgb ",
      " bh          gb ",
      " bg          gb ",
      " bg     x    gb ",
      " bg          hb ",
      " bg          gb ",
      " bg          gb ",
      " bh     y rr gb ",
      " bg          gb ",
      " bg          gb ",
      " bguuuuuuuuuuhb ",
      " bghggggghggggb ",
      " fbbbbbbbbbbbbf ",
      "                "
    ],
    [
      "                ",
      "                ",
      "   gghggggghg   ",
      "  gg        gg  ",
      "  h          g  ",
      "  g          h  ",
      "  g          g  ",
      "  g          g  ",
      "  g          g  ",
      "  g          g  ",
      "  h          g  ",
      "  g          h  ",
      "  gg        gg  ",
      "   ghggggghgg   ",
      "                ",
      "                "
    ],
    [
      "                ",
      "                ",
      "                ",
      "    gggggggg    ",
      "   gggggggggg   ",
      "   ggg    ggg   ",
      "   gg     Agg   ",
      "   gg      gg   ",
      "   gg      gg   ",
      "   ggA     gg   ",
      "   ggg    ggg   ",
      "   gggggggggg   ",
      "    gggggggg    ",
      "                ",
      "                ",
      "                "
    ],
    [
      "                ",
      "                ",
      "                ",
      "                ",
      "                ",
      "      gggg      ",
      "     gggggg     ",
      "     gggggg     ",
      "     gggggg     ",
      "     gggggg     ",
      "      gggg      ",
      "                ",
      "                ",
      "                ",
      "                ",
      "                "
    ]
  ]
}