{
  "name": "building_restaurant1_ground_180",
  "refpalette": "c70cities:building_restaurant1_ground_palette_180",
  "xsize": 16,
  "zsize": 16,
  "slices": [
    [
      "GGGGGGGGGGGGGGGG",
      "GGeeeeeeeeeeeeGG",
      "GGeafffffffffeGG",
      "GGeafffffffffeGG",
      "GGeafffffffffeGG",
      "GGeafffffffffeGG",
      "G==============G",
      "G=cccccccccccc=G",
      "G=cccccccccccc=G",
      "G=cccccccccccc=G",
      "G=!ccccccccccc=G",
      "G==========cc==G",
      "GddGddddaccccaGG",
      "dGGddGddacccbaGG",
      "GGGGGGGaaaaaaaGG",
      "GGGGGGGGGGGGGGGG"
    ],
    [
      "  BFBBEDDDDCB   ",
      "  eeeeeeeeeeee  ",
      "   xwyo    oAe  ",
      "   xw      o e  ",
      "   xwyoq   oqe  ",
      "   xwu      ue  ",
      " =====r     === ",
      " =ttsmrq  q  q= ",
      " =p  m o  o  o= ",
      " =n  m k     k= ",
      " =l      k    = ",
      " ==========ji== ",
      "  g       h  a  ",
      "    g        a  ",
      "  g    aaaaaaa  ",
      "                "
    ],
    [
      "                ",
      "  exeexxxxxxee  ",
      "    w R      e  ",
      "    w      r e  ",
      "    w        e  ",
      "    wQ      Qe  ",
      " =====      === ",
      " = POr        = ",
      " =   r       r= ",
      " =N  M        = ",
      " =            = ",
      " ==LLLL====KJ== ",
      "          h  I  ",
      "             a  ",
      "       aaaaaaa  ",
      "                "
    ],
    [
      "                ",
      "  e ee      ee  ",
      "    w        e  ",
      "    w        e  ",
      "    w        e  ",
      "    wQ      Qe  ",
      " =====      === ",
      " I            = ",
      " I            T ",
      " = U          T ",
      " =            = ",
      " ============== ",
      "      LLLSh  I  ",
      "      LLLS   a  ",
      "       aaaaaaa  ",
      "                "
    ],
    [
      "                ",
      "  e ee      ee  ",
      "    w        e  ",
      "    w      U e  ",
      "    w        e  ",
      "    w        e  ",
      " ============== ",
      " =            = ",
      " =            = ",
      " = V    V    V= ",
      " =            = ",
      " ============== ",
      "       LLSh  a  ",
      "       LLS   a  ",
      "       aaaaaaa  ",
      "                "
    ],
    [
      "                ",
      "  eeeeeeeeeeee  ",
      "    w        e  ",
      "    w V    V e  ",
      "    w        e  ",
      "    w        e  ",
      " ============== ",
      " =WWWWWWWWWWWW= ",
      " =WWWWWWWWWWWW= ",
      " =WWWWWWWWWWWW= ",
      " =WWWWWWWWWWWW= ",
      " ============== ",
      "        LSh  a  ",
      "        LS   a  ",
      "       aaaaaaa  ",
      "                "
    ]
  ]
}