{
  "name": "building_residential3_ground_90",
  "refpalette": "c70cities:building_residential3_ground_palette_90",
  "xsize": 16,
  "zsize": 16,
  "slices": [
    [
      "GGGGGGGGGGGGGGGG",
      "GGGGGGGGGGGGGGGG",
      "GGaaaaaaaaaaaaGG",
      "GGabbbbbbbbbbaGG",
      "GGabbbbbbbbbbaGG",
      "GGabbbbbbbbbbaGG",
      "GGabbbbbbbbbbaGG",
      "GGabbbbbbbbbaaGG",
      "GGabbbbbddddcGGG",
      "GGabbbbbddddcGGG",
      "GGabbbbbddddcGGG",
      "GGabbbbbddddcGGG",
      "GGabbbbacccccGGG",
      "GGaaaaaaGGGGGGGG",
      "GGGGGGGGGGGGGGGG",
      "GGGGGGGGGGGGGGGG"
    ],
    [
      "effffgffffeffffe",
      "f              f",
      "f hhhhhhhhhhhh f",
      "f h mo uu yE i f",
      "f h  p       F f",
      "g hkko       F g",
      "f h!      xx i f",
      "f h    tthhhhh f",
      "f h        Dcw f",
      "f hj   s   Ccw f",
      "g h   qr   Bcw g",
      "f h   qr   Acw f",
      "f h    hcccccw f",
      "f hilnih wwwww f",
      "f              f",
      "effe  efffgffffe"
    ],
    [
      "effffgffffeffffe",
      "f              f",
      "f hhIhFhhFFFhh f",
      "f h Lo OP    i f",
      "f I  N       F f",
      "g hkko       F g",
      "f F K     RR i f",
      "f h    tthhhhh f",
      "f hj       Tc  f",
      "f F         Q  f",
      "g F         Q  g",
      "f F        Sc  f",
      "f h    hcQQcc  f",
      "f hiJMih       f",
      "f              f",
      "effe  efffgffffe"
    ],
    [
      "          V     ",
      "                ",
      "  hhXhXhhXXXhh  ",
      "  h  o       i  ",
      "  U  o       Z  ",
      "  hkko       Z  ",
      "  U          i  ",
      "  hj   tthhhhh  ",
      "  h         cY  ",
      "  U         cY  ",
      "  U         cY  ",
      "  U         cY  ",
      "  h    hcccccY  ",
      "  hiWWihYYYYYY  ",
      "                ",
      "   V            "
    ],
    [
      "                ",
      "                ",
      "  hhhhhhhhhhhh  ",
      "  hbbbbbbbbbbh  ",
      "  hbbbbbbbbbbh  ",
      "  hbbbbbbbbbbh  ",
      "  hjbbbbbbbbbh  ",
      "  h bbbbbbbbhh  ",
      "  h bbbb    30  ",
      "  h bbbb    30  ",
      "  hbbbbb    30  ",
      "  hbbbbb    30  ",
      "  hbbbbh111120  ",
      "  hhhhhh000000  ",
      "                ",
      "                "
    ],
    [
      "                ",
      "                ",
      "  hFFFFhhXXXhh  ",
      "  h    %i8(( F  ",
      "  U   9$i&**&F  ",
      "  U    #i&&&&F  ",
      "  U 6        F  ",
      "  h 6  @@@@@hh  ",
      "  h 6  @^   c0  ",
      "  U 6  @    c0  ",
      "  U5  8@    c0  ",
      "  U4  7@    c0  ",
      "  h4  7hccccc0  ",
      "  hFFFFh000000  ",
      "                ",
      "                "
    ]
  ]
}