{
  "name": "building_office1_top_270",
  "refpalette": "c70cities:building_office1_top_palette_270",
  "xsize": 16,
  "zsize": 16,
  "slices": [
    [
      "                ",
      " eeee  c        ",
      " ebbfddcaaaaaa  ",
      " ebbgbbbbbbbba  ",
      " ebbbbbbbbbbba  ",
      " ebbbbbbbbbbba  ",
      " ebbbbbbbbbbba  ",
      " ebbbbbbbbbbba  ",
      " ebbbbbbbbbbba  ",
      " ebbbbbbbbbbba  ",
      " ebbbbbbbbbbba  ",
      " ebbbbbbbbbbba  ",
      " ebbbbbbbbbbba  ",
      " ebbfddcaaaaaa  ",
      " eeee  c        ",
      "                "
    ],
    [
      "                ",
      " mmmm  c        ",
      " m  fddchhhhhh  ",
      " m     l     h  ",
      " m      iiii h  ",
      " m      ijji h  ",
      " m           h  ",
      " mn      kk  h  ",
      " mn      kk  h  ",
      " m           h  ",
      " m      ijji h  ",
      " m      iiii h  ",
      " m     l     h  ",
      " m  fddchhhhhh  ",
      " mmmm  c        ",
      "                "
    ],
    [
      "                ",
      " mmmm  c        ",
      " m  fddco o o   ",
      " q     p        ",
      " d              ",
      " d              ",
      " d              ",
      " d              ",
      " d              ",
      " d              ",
      " d              ",
      " d              ",
      " q     p        ",
      " m  fddco o o   ",
      " mmmm  c        ",
      "                "
    ],
    [
      "                ",
      " mmmm  c        ",
      " m  fddco o o   ",
      " q              ",
      " d              ",
      " d              ",
      " d              ",
      " d              ",
      " d              ",
      " d              ",
      " d              ",
      " d              ",
      " q              ",
      " m  fddco o o   ",
      " mmmm  c        ",
      "                "
    ],
    [
      "                ",
      " mmmm  c        ",
      " m  fffco o o   ",
      " m  frrf        ",
      " m  frrf        ",
      " m  frrf        ",
      " m  frrf        ",
      " m  frrf        ",
      " m  frrf        ",
      " m  frrf        ",
      " m  frrf        ",
      " m  frrf        ",
      " m  frrf        ",
      " m  fffco o o   ",
      " mmmm  c        ",
      "                "
    ],
    [
      "                ",
      " mmmm  c        ",
      " mrrr  cssssss  ",
      " mrrr  seeeees  ",
      " mrrr  seeeees  ",
      " mrrr  seeeees  ",
      " mrrr  seeeees  ",
      " mrrr  seeeees  ",
      " mrrr  seeeees  ",
      " mrrr  seeeees  ",
      " mrrr  seeeees  ",
      " mrrr  seeeees  ",
      " mrrr  seeeees  ",
      " mrrr  cssssss  ",
      " mmmm  c        ",
      "                "
    ]
  ]
}