{
  "name": "building_office1_base1_270",
  "refpalette": "c70cities:building_office1_base1_palette_270",
  "xsize": 16,
  "zsize": 16,
  "slices": [
    [
      "vvvvvvvvvvvvvvvv",
      "vaaaaaaaaaaaaaav",
      "vabbaaaaaaaaa!av",
      "vaaaaaaaaaaaaaav",
      "vaaaaaaaaaaaaaav",
      "vaaaaaaaaaaaaaav",
      "vaaaaaaaaaaaaaav",
      "vaaaaaaaaaaaaaav",
      "vaaaaaaaaaaaaaav",
      "vaaaaaaaaaaaaaav",
      "vaaaaaaaaaaaaaav",
      "vaaaaaaaaaaaaaav",
      "vaaaaaaaaaaaaaav",
      "vaaaaaaaaaaaa!av",
      "vaaaaaaaaaaaaaav",
      "vvvvvvvvvvvvvvvv"
    ],
    [
      "vvvvvvvvvvvvvvvv",
      "vccccccccccccccv",
      "vcbbmdkdddkdddcv",
      "vc   g e  g e cv",
      "vc    h    h  cv",
      "vc       e    cv",
      "vc   dkd  ddddcv",
      "vc   e      f cv",
      "vc         e  cv",
      "vc   dkd  diddcv",
      "vc   f        cv",
      "vc       f  g cv",
      "vc    j    je cv",
      "vcnnmdddliddddcv",
      "vccccccccccccccv",
      "vvvvvvvvvvvvvvvv"
    ],
    [
      "vvvvvvvvvvvvvvvv",
      "vccccccccccccccv",
      "vcbbmoddooddodcv",
      "vc            cv",
      "vc            cv",
      "vc            cv",
      "vc   ddd  doddcv",
      "vc            cv",
      "vc            cv",
      "vc   ddd  ddodcv",
      "vc            cv",
      "vc            cv",
      "vc            cv",
      "vc  mdlddddlldcv",
      "vccccccccccccccv",
      "vvvvvvvvvvvvvvvv"
    ],
    [
      "vvvvvvvvvvvvvvvv",
      "vccccccccccccccv",
      "vcbbm trrrrrp cv",
      "vc            cv",
      "vc            cv",
      "vc            cv",
      "vc            cv",
      "vc            cv",
      "vc            cv",
      "vc            cv",
      "vc            cv",
      "vc            cv",
      "vc            cv",
      "vc  m usssssq cv",
      "vccccccccccccccv",
      "vvvvvvvvvvvvvvvv"
    ],
    [
      "vvvvvvvvvvvvvvvv",
      "vccccccccccccccv",
      "vcbbm         cv",
      "vc            cv",
      "vc            cv",
      "vc            cv",
      "vc            cv",
      "vc            cv",
      "vc            cv",
      "vc            cv",
      "vc            cv",
      "vc            cv",
      "vc            cv",
      "vc  m         cv",
      "vccccccccccccccv",
      "vvvvvvvvvvvvvvvv"
    ],
    [
      "vvvvvvvvvvvvvvvv",
      "vccccccccccccccv",
      "vcbbmwwwwwwwwwcv",
      "vcwwwwwwwwwwwwcv",
      "vcwwwwwwwwwwwwcv",
      "vcwwwwwwwwwwwwcv",
      "vcwwwwwwwwwwwwcv",
      "vcwwwwwwwwwwwwcv",
      "vcwwwwwwwwwwwwcv",
      "vcwwwwwwwwwwwwcv",
      "vcwwwwwwwwwwwwcv",
      "vcwwwwwwwwwwwwcv",
      "vcwwwwwwwwwwwwcv",
      "vcwwmwwwwwwwwwcv",
      "vccccccccccccccv",
      "vvvvvvvvvvvvvvvv"
    ]
  ]
}