{
  "name": "building_apartment1_floor2_90",
  "refpalette": "c70cities:building_apartment1_floor2_palette_90",
  "xsize": 16,
  "zsize": 16,
  "slices": [
    [
      "                ",
      " aaaaaaaaa      ",
      " abbbbbbbbdeei  ",
      " abbbbbbbbbbfh  ",
      " abbbbbbbbbb g  ",
      " abbbbbbbbc  d  ",
      " abbbbbbbbbbbba ",
      " abbbbbbbbbbbba ",
      " abbbbbbbbbbbba ",
      " abbbbbbbbbbbba ",
      " abbbbbbbbbbbba ",
      " abbbbbbbbbbbba ",
      " abbbbbbbbbbbba ",
      " abbbbbbbbbbbba ",
      " aaaaaaaaaaaaaa ",
      "                "
    ],
    [
      "                ",
      " luuuuuuuu      ",
      " kowBDqI qdddd  ",
      " kt  CqI M SVd  ",
      " k!   qqJq   X  ",
      " kqqy q  q   X  ",
      " k  y q  qqqqqZ ",
      " ks A q  L RU Z ",
      " kr y A  L    Z ",
      " kqxqqq  K QQ Z ",
      " kp   E       Z ",
      " kow DqFJF    Z ",
      " kow Cqs qO   Z ",
      " kn   qr qNPTWZ ",
      " jmmmmmmmmmmmmY ",
      "                "
    ],
    [
      "                ",
      " q000qqqqq      ",
      " q    q  qhXdd  ",
      " q    q  $  Sd  ",
      " q    qq9q  &d  ",
      " qqqy q  q   d  ",
      " q24y q  qqqqqq ",
      " q  5 q  # %% 8 ",
      " q  y 5       0 ",
      " qq3qqq  @    0 ",
      " q    7       0 ",
      " q    qF9F    0 ",
      " q    q  q    0 ",
      " q1   q  q  ^*8 ",
      " q000q688688886 ",
      "                "
    ],
    [
      "                ",
      " q000qq00q      ",
      " q+[{ q  qddd,  ",
      " 0    q  q   '  ",
      " 0    qqqq  }d  ",
      " qqqy q  q  Vd  ",
      " q) y q  qqqqqq ",
      " 0  y q       8 ",
      " 0  y q      ;0 ",
      " qqqqqq      :0 ",
      " q    q      `0 ",
      " 0    qFFF   |0 ",
      " 0    q  q   \\0 ",
      " q(-] q  q    8 ",
      " q000q600680006 ",
      "                "
    ],
    [
      "                ",
      " q888qq88q      ",
      " q    q  q'''d  ",
      " k    q fq   X  ",
      " k    qqqq   X  ",
      " qqqy q  q .}e  ",
      " q  y q  qqqqqq ",
      " k  y q       8 ",
      " k  y q       8 ",
      " qqqqqq       8 ",
      " q    q       8 ",
      " k    qFFF    8 ",
      " k    q  q    8 ",
      " q    q  q    8 ",
      " q888q688688886 ",
      "                "
    ],
    [
      "                ",
      " qqqqqqqqq      ",
      " qddddqddqdddd  ",
      " qddddqddq   d  ",
      " qddddqqqq   d  ",
      " qddddqddqVc d  ",
      " q//ddqddqqqqqq ",
      " q//ddqdddddddq ",
      " q//ddqdddddddq ",
      " qqqqqqdddddddq ",
      " qddddqdddddddq ",
      " qddddqdddddddq ",
      " qddddq//dddddq ",
      " qddddq//dddddq ",
      " qqqqqqqqqqqqqq ",
      "                "
    ]
  ]
}