{
  "name": "building_bank1_floor1",
  "refpalette": "c70cities:building_bank1_floor1_palette",
  "xsize": 16,
  "zsize": 16,
  "slices": [
    [
      "                ",
      "   abbc  abbc   ",
      "  deeeedeeeeed  ",
      " feeeeeeeeeeeeg ",
      " beeeeeeeeeeeeb ",
      " be eeeeeeeeeeb ",
      " he eeeeeeeeeei ",
      "  e eeeeeeeeed  ",
      "  d eeeeeeeeee  ",
      " fe eeeeeeeeeeg ",
      " beeeeeeeeeeeeb ",
      " beeeeeeeeeeeeb ",
      " heeeeeeeeeeeei ",
      "  deeeeedeeeed  ",
      "   jbbk  jbbk   ",
      "                "
    ],
    [
      "                ",
      "  abbc  abbc    ",
      "  llllmlllllmlg ",
      "  m    n    olb ",
      " fl    p     lb ",
      " bqrs  b     li ",
      " bl s  btt   m  ",
      " hl s  buw   l  ",
      "  l s xby    lg ",
      "  m s Aby B Clb ",
      " fl   xby B Clb ",
      " bl   xbD    li ",
      " bl    bD    m  ",
      " hlmlllllmllll  ",
      "    jbbk  jbbk  ",
      "                "
    ],
    [
      "                ",
      " Ebbc  abbc  aE ",
      " hlllmlllllmllb ",
      "  l    F    olb ",
      "  m    I     li ",
      " fl s  b     m  ",
      " bqr   btJ   l  ",
      " bl s  b     lg ",
      " hl    b     lb ",
      "  l s Kb     lb ",
      "  m    b     li ",
      " fl    b     m  ",
      " bl    bL    l  ",
      " bllmlllllmlllg ",
      " Ek  jbbk  jbbE ",
      "                "
    ],
    [
      "                ",
      " Ebc  abbc  abE ",
      " bllmlllllmlllb ",
      " hl    b    oli ",
      "  l    b     m  ",
      "  m s  b     l  ",
      " f     btt   lg ",
      " bqrs  b     lb ",
      " bl    b     lb ",
      " hl s Kb     li ",
      "  l    b     m  ",
      "  m    b     l  ",
      " fl    b     lg ",
      " blllmlllllmllb ",
      " Ebk  jbbk  jbE ",
      "                "
    ],
    [
      "                ",
      " Ec  abbc  abbE ",
      " blmlllllmlllli ",
      " bl    b     m  ",
      " hl    b     l  ",
      "  l s  b     lg ",
      "  m    b     lb ",
      " f  s  b     lb ",
      " bqr   b     li ",
      " bl s  b     m  ",
      " hl    b     l  ",
      "  l    b     lg ",
      "  m    b     lb ",
      " fllllmlllllmlb ",
      " Ebbk  jbbk  jE ",
      "                "
    ],
    [
      "                ",
      "    abbc  abbc  ",
      " fmlllllmllllm  ",
      " blMMMMbMMMMMl  ",
      " blMMMMbMMMMMlg ",
      " hl sMMbMMMMMlb ",
      "  l  MMbMMMMMlb ",
      "  m sMMbMNNNMli ",
      " f   MMbMN!NMm  ",
      " bqrsMMbMN!NMl  ",
      " blMMMMbMNNNMlg ",
      " hlMMMMbMMMMMlb ",
      "  lMMMMbMMMMMlb ",
      "  mllllmlllllmi ",
      "  jbbk  jbbk    ",
      "                "
    ]
  ]
}