{
  "name": "building_carfactory1_ground_270",
  "refpalette": "c70cities:building_carfactory1_ground_palette_270",
  "xsize": 16,
  "zsize": 16,
  "slices": [
    [
      "zzzzzzzzzzzzzzzz",
      "zzzzzzzzzzzzzzzz",
      "zzzzzzzzzzzzzzzz",
      "zzHHHH!HHHHzzzzz",
      "zzHHHHHHHHHzzzzz",
      "zzzHhihbebHzzzzz",
      "zzzHfffbfbHzazaz",
      "zaHHfffbfbHHaazz",
      "aaHHhihbebHHaaza",
      "aaHHccdddcHHazaz",
      "azHHdgcdgdHHaaza",
      "zaHHdcdcdcHHzazz",
      "azzHHHHHHHHzzzzz",
      "zzzzzzzzzzzzzzzz",
      "zzzzzzzzzzzzzzzz",
      "zzzzzzzzzzzzzzzz"
    ],
    [
      " jnjj j kjnn jjj",
      "jqnnknnn nnnq   ",
      "nuuuuuuuuuuull  ",
      "qQN LJEEBmxurm  ",
      "qQO     C  urn  ",
      "nuu I I  ytumj j",
      "jnwC      rwnk  ",
      "j P         n j ",
      "  P I I         ",
      "  P             ",
      "  P             ",
      "  wl     Amws   ",
      " nulMKlFDprutokj",
      "nnuuuuuuuuuutp  ",
      "kqnnn nn knnqnj ",
      " jnk j j j   jj "
    ],
    [
      "                ",
      " qn   n   nnq   ",
      "nuuSSSuuSSSul   ",
      "qQN        ur   ",
      "qQZ        u    ",
      "nuuYX XV   u    ",
      "  w b b   Twn   ",
      "  P b b    R    ",
      "  PYX XV   R    ",
      "  P        R    ",
      "  P        R    ",
      "  w        w    ",
      " nul   W  Uu    ",
      " nuSSSuuSSSut   ",
      " qnn   n    q   ",
      "                "
    ],
    [
      "                ",
      " q         nq   ",
      " uuSSSuuSSSu    ",
      "qQ5        u    ",
      "qQ5        u    ",
      " uuyt21    u    ",
      "  w 232    w    ",
      "  P 242    R    ",
      "  Pyt2to   R    ",
      "  P        R    ",
      "  P        R    ",
      "  w        w    ",
      "  u        u    ",
      " nuSSSuuSSSu0   ",
      " q          q   ",
      "                "
    ],
    [
      "                ",
      " q          q   ",
      " &u777uu777u    ",
      "&Qu        u    ",
      "&Qu        u    ",
      " &u 8$8    u    ",
      "  w 9%9    w    ",
      " 6w @ @    w6   ",
      " 6w #^#    w6   ",
      " 6w        w6   ",
      " 6w        w6   ",
      "  w        w    ",
      "  u        u    ",
      "  u777uu777u    ",
      " q          q   ",
      "                "
    ],
    [
      "                ",
      " q          q   ",
      "  u***uu***u    ",
      " Qu        u    ",
      " Qu        u    ",
      "  u (    ( u    ",
      "  * + +    *    ",
      "  *        *    ",
      "  *        *    ",
      "  *      ) *    ",
      "  * (    ( *    ",
      "  *        *    ",
      "  u        u    ",
      "  u***uu***u    ",
      " q          q   ",
      "                "
    ]
  ]
}