{
  "name": "building_policeoffice1_base2",
  "refpalette": "c70cities:building_policeoffice1_base2_palette",
  "xsize": 16,
  "zsize": 16,
  "slices": [
    [
      "vvvvvvvvvvvvvvvv",
      "vabbbbbbbbbbbbav",
      "vabbbbbbbbbbbbav",
      "vabbbbbbbbbbbbav",
      "vabbbbbbbbbbbbav",
      "vabbbbbbbbbbbbav",
      "vabbbbbbbbbbbbav",
      "vabbbbbbbbbbbbav",
      "vabbbbbbbbbbbbav",
      "vabbbbbbbbbbbbav",
      "vabbbbbbbbbbbbav",
      "vabbbbbbbbbbbbav",
      "vabbbbbbbbbbbbav",
      "vabbbbbbbbbbbbav",
      "vaaaaaaaaaaaaaav",
      "vvvvvvvvvvvvvvvv"
    ],
    [
      "vvvvvvvvvvvvvvvv",
      "vccccccccccccccv",
      "vcdd e      ffcv",
      "vcd  e       fcv",
      "vc   e     g  cv",
      "vc   e        cv",
      "vc   e        cv",
      "vc   e        cv",
      "vch  i        cv",
      "vchh e       jcv",
      "vckkkkkk   kkkcv",
      "vclccc  mmm  ncv",
      "vco  i      pncv",
      "vco  q       ncv",
      "vccccccccccccccv",
      "vvvvvvvvvvvvvvvv"
    ],
    [
      "vvvvvvvvvvvvvvvv",
      "vccccccccccccccv",
      "vc   e       fcv",
      "vc   e        cv",
      "vc   e        cv",
      "vc   e        cv",
      "vc   e        cv",
      "vc   e        cv",
      "vc   r        cv",
      "vch  e        cv",
      "vckkkkkk   kkkcv",
      "vclccc  mmm   cv",
      "vco  r        cv",
      "vco  s       tcv",
      "vccccccccccccccv",
      "vvvvvvvvvvvvvvvv"
    ],
    [
      "vvvvvvvvvvvvvvvv",
      "vccccccccccccccv",
      "vc   e        cv",
      "vc   e        cv",
      "vc   e        cv",
      "vc   e        cv",
      "vc   e        cv",
      "vc   e        cv",
      "vc   e        cv",
      "vc   e        cv",
      "vckkkkkk   kkkcv",
      "vclccc  mmm   cv",
      "vco  c        cv",
      "vco  c        cv",
      "vccccccccccccccv",
      "vvvvvvvvvvvvvvvv"
    ],
    [
      "vvvvvvvvvvvvvvvv",
      "vccccccccccccccv",
      "vc   e       ucv",
      "vc   e       ucv",
      "vc   e       wcv",
      "vc   e       ucv",
      "vc   e       ucv",
      "vc   e       wcv",
      "vc   e       ucv",
      "vc   e       ucv",
      "vckkkkkkkkkkkucv",
      "vclccc       ucv",
      "vco xc       ucv",
      "vco  c       ucv",
      "vccccccccccccccv",
      "vvvvvvvvvvvvvvvv"
    ],
    [
      "vvvvvvvvvvvvvvvv",
      "vccccccccccccccv",
      "vcyyyyyyyyyyyycv",
      "vcyyyyyyyyyyyycv",
      "vcyyyyyyyyyyyycv",
      "vcyyyyyyyyyyyycv",
      "vcyyyyyyyyyyyycv",
      "vcyyyyyyyyyyyycv",
      "vcyyyyyyyyyyyycv",
      "vcyyyyyyyyyyyycv",
      "vckkkkkkkkkkkkcv",
      "vclcccyyyyyyyycv",
      "vcoyycyyyyyyyycv",
      "vcoyycyyyyyyyycv",
      "vccccccccccccccv",
      "vvvvvvvvvvvvvvvv"
    ]
  ]
}