{
  "name": "building_factory2_ground",
  "refpalette": "c70cities:building_factory2_ground_palette",
  "xsize": 16,
  "zsize": 16,
  "slices": [
    [
      "zzzzzzzzzzzzzzzz",
      "zzzzzzzzzzzzzzzz",
      "zzzzzzzzzzzzzzzz",
      "zzzzHHHHHHHHHzzz",
      "azaaHHHHHHHHHzzz",
      "zaaaHHHHHHHHHzzz",
      "zzaaHHHHHHHHHzzz",
      "zazaHHHHHHHHHzzz",
      "zaaaHHHHHHHHHHzz",
      "zzazHHHHHHHHHHzz",
      "zazzHHHHHHHHHzzz",
      "zzzzHHHHHHHHHzzz",
      "zzzzHHHHHHHHHzzz",
      "zzzzzzzzzzzzzzzz",
      "zzzzzzzzzzzzzzzz",
      "zzzzzzzzzzzzzzzz"
    ],
    [
      "  b cdb  b dcb  ",
      " bceccc b  ccceb",
      "  dcfffffffffff ",
      " b bfghijfkkkffd",
      "    li   fkkkffc",
      "    f  i mnnkfee",
      "    o    pkkkfee",
      "    q   rsnnnffc",
      "    qg   tkukff ",
      "   bqw    ixyfee",
      "  b qgA    BCfee",
      "  bcogg  D  Effb",
      " d cf!gF F ggffd",
      " bccfffffffffffc",
      "  becdcccbcc cec",
      " b b b b  c dbb "
    ],
    [
      "                ",
      "   ecc       ce ",
      "   cfIIIfffffff ",
      "    f     un ff ",
      "    J     KKKff ",
      "    f     KnKfee",
      "    o     KKKfee",
      "    q     nnnff ",
      "    q     L LMf ",
      "    q        fee",
      "    q        fee",
      "    ogN     Off ",
      "   cfN      jff ",
      "   cfIIIffIIIff ",
      "   e   cc c   e ",
      "                "
    ],
    [
      "                ",
      "   ec         e ",
      "    fIIIfffffff ",
      "    f       jff ",
      "    P     QQQff ",
      "    f     QQQfee",
      "    o     QQQfee",
      "    q      O ff ",
      "    q        Pf ",
      "    q        fee",
      "    q        fee",
      "    o        ff ",
      "    f        ff ",
      "    fIIIffIIIff ",
      "   e          e ",
      "                "
    ],
    [
      "                ",
      "   e          e ",
      "    fRRRffffffS ",
      "    f       jfS ",
      "    f        fS ",
      "    f        fTS",
      "    o        fTS",
      "   Uo       VfS ",
      "   Uo        fS ",
      "   Uo        fTS",
      "   Uo        fTS",
      "    o       VfS ",
      "    f        fS ",
      "    fRRRffRRRfS ",
      "   e          e ",
      "                "
    ],
    [
      "                ",
      "   e          e ",
      "    fWWWffWWWf  ",
      "    f        f  ",
      "    f        f  ",
      "    f   XY   fT ",
      "    W        fT ",
      "    W        f  ",
      "    W        f  ",
      "    W        fT ",
      "    W   YY   fT ",
      "    W        f  ",
      "    f        f  ",
      "    fWWWffWWWf  ",
      "   e          e ",
      "                "
    ]
  ]
}