{
  "name": "building_hotel1_floor1_90",
  "refpalette": "c70cities:building_hotel1_floor1_palette_90",
  "xsize": 16,
  "zsize": 16,
  "slices": [
    [
      "                ",
      " aaaaaaaaffffaa ",
      " abbbcbbbbbbbba ",
      " abbbcbbbbbbbbg ",
      " abbbcbbbbbbbbg ",
      " abbbcdbbbbbbbg ",
      " abbbc   ebbbbg ",
      " abbbc    bbbbg ",
      " abbbc    bbbba ",
      " abbbc    bbbba ",
      " abbbcbbbbbbbba ",
      " abbbcbbbbbbbba ",
      " abbbcbbbbbbbba ",
      " abbbcbbbbbbbba ",
      " aaaaadddddddaa ",
      "                "
    ],
    [
      "                ",
      " aaaaaaaaffffaa ",
      " ai  r  w    wa ",
      " ai qr       ta ",
      " ai          wa ",
      " a   a uu    sa ",
      " a  ka   d    a ",
      " a  pa   e   ta ",
      " a  oa   e   wa ",
      " a  na       sa ",
      " a  ma        a ",
      " a  la t t   ta ",
      " a  ka  w    wa ",
      " ah ja s s   sa ",
      " aaaaaaaaaaaaaa ",
      "                "
    ],
    [
      "                ",
      " aaaaaaaaffffaa ",
      " a      C    Ca ",
      " a            a ",
      " a           Ba ",
      " a   a        a ",
      " a   a        a ",
      " a  Aa        f ",
      " a   a   d   Bf ",
      " a  ya  ee    f ",
      " a   a        f ",
      " a  xa        f ",
      " a   a BBB   Bf ",
      " a   a        a ",
      " aaaaaffffaaaaa ",
      "                "
    ],
    [
      "                ",
      " aaaaaaaaffffaa ",
      " a      C    Ca ",
      " a            a ",
      " a            a ",
      " a   a        a ",
      " a   a        a ",
      " a   a        a ",
      " a   a        a ",
      " a   aeed     a ",
      " a   a        a ",
      " a   a        a ",
      " a   a        a ",
      " a   a        a ",
      " aaaaaaaaaaaaaa ",
      "                "
    ],
    [
      "                ",
      " aaaaaaaaffffaa ",
      " a   a        a ",
      " a   a        a ",
      " a   a        a ",
      " a   a        a ",
      " a   a        a ",
      " a   ae       f ",
      " a   ae       f ",
      " a   ad       a ",
      " a   a        a ",
      " a   a        a ",
      " a   a        a ",
      " a   a        a ",
      " aaffaaaaaaaaaa ",
      "                "
    ],
    [
      "                ",
      " aaaaaaaaffffaa ",
      " aDDDaDDDDDDDDa ",
      " aDDDaDDDDDDDDa ",
      " aDDDaDDDDDDDDa ",
      " aDDDaDDDDDDDDa ",
      " aDDDae   DDDDa ",
      " aDDDad   DDDDa ",
      " aDDDa    DDDDa ",
      " aDDDa    DDDDa ",
      " aDDDaDDDDDDDDa ",
      " aDDDaDDDDDDDDa ",
      " aDDDaDDDDDDDDa ",
      " aDDDaDDDDDDDDa ",
      " aaaaaaaaaaaaaa ",
      "                "
    ]
  ]
}