{
  "name": "building_office5_floor2",
  "refpalette": "c70cities:building_office5_floor2_palette",
  "xsize": 16,
  "zsize": 16,
  "slices": [
    [
      "                ",
      "                ",
      "   ababababa    ",
      "   bcccccccb    ",
      "   accccccca    ",
      "  ddeedddddddd  ",
      "  beeeeffeeeeb  ",
      "  deeeeeeeeeed  ",
      "  beeeeeeeeeeb  ",
      "  deeeeeeeeeed  ",
      "  beeeeeeeeeeb  ",
      "  deeeeeeeeeed  ",
      "  beeeeeeeeeeb  ",
      "  ddbdbdbdbdbd  ",
      "                ",
      "                "
    ],
    [
      "                ",
      "                ",
      "   ababababa    ",
      "   b       b    ",
      "   a  gghiia    ",
      "  dd  dddddddd  ",
      "  bj  jff    b  ",
      "  d          d  ",
      "  b       k  b  ",
      "  dl   k     d  ",
      "  b gg gg gg b  ",
      "  d  m     m d  ",
      "  b      m   b  ",
      "  ddbdbdbdbdbd  ",
      "                ",
      "                "
    ],
    [
      "                ",
      "                ",
      "   ababababa    ",
      "   b       b    ",
      "   a   n   a    ",
      "  dd  ddddd!dd  ",
      "  bj  jff    b  ",
      "  d          d  ",
      "  b          b  ",
      "  d          d  ",
      "  b  o     o b  ",
      "  d          d  ",
      "  b          b  ",
      "  ddbdbdbdbdbd  ",
      "                ",
      "                "
    ],
    [
      "                ",
      "                ",
      "   ababababa    ",
      "   b       b    ",
      "   a   ppppa    ",
      "  ddqqdddddqdd  ",
      "  b    ff    b  ",
      "  d          d  ",
      "  b          b  ",
      "  d          d  ",
      "  b          b  ",
      "  d          d  ",
      "  b          b  ",
      "  ddbdbdbdbdbd  ",
      "                ",
      "                "
    ],
    [
      "                ",
      "                ",
      "   ababababa    ",
      "   b       b    ",
      "   a       a    ",
      "  dddddddddddd  ",
      "  b    ff    b  ",
      "  d          d  ",
      "  b          b  ",
      "  d          d  ",
      "  b          b  ",
      "  d          d  ",
      "  b          b  ",
      "  ddbdbdbdbdbd  ",
      "                ",
      "                "
    ],
    [
      "                ",
      "                ",
      "   ababababa    ",
      "   b       b    ",
      "   a       a    ",
      "  dddddddddddd  ",
      "  brrrrffrrrrb  ",
      "  drrrrrrrrrrd  ",
      "  brrrrrrrrrrb  ",
      "  drrrrrrrrrrd  ",
      "  brrrrrrrrrrb  ",
      "  drrrrrrrrrrd  ",
      "  brrrrrrrrrrb  ",
      "  ddbdbdbdbdbd  ",
      "                ",
      "                "
    ]
  ]
}