{
  "name": "building_office3_ground_270",
  "refpalette": "c70cities:building_office3_ground_palette_270",
  "xsize": 16,
  "zsize": 16,
  "slices": [
    [
      "GGGGGGGGGGGGGGGG",
      "GaaaaaaaaaaaaaaG",
      "GabbbbbbbbbbbbaG",
      "Gabbbbbbbbbb!baG",
      "GabbbbbbbbbbbbaG",
      "GabbbbbbbbbbbbaG",
      "GabbbbbbbbbbbbaG",
      "GabbbbbbbbbbbbaG",
      "GabbbbbbbbbbbbaG",
      "GabbbbbbbbbbbbaG",
      "GabbbbbbbbbbbbaG",
      "GabbbbbbbbbbbbaG",
      "GabbbbbbbbbbbbaG",
      "GabbbbbbbbbbbbaG",
      "GaaaaaaaaaaaaaaG",
      "GGGGGGGGGGGGGGGG"
    ],
    [
      "                ",
      " ccdccdccdccdcc ",
      " ceeeefeefeeeec ",
      " deg        ged ",
      " ce          ec ",
      " ce          ec ",
      " df     h    fd ",
      " ce    vv    ec ",
      " ce    ii    ec ",
      " df          fd ",
      " ce          ec ",
      " ce          ec ",
      " deg        ged ",
      " ceeeef  feeeec ",
      " ccdccdkjdccdcc ",
      "                "
    ],
    [
      "                ",
      " ccdccdccdccdcc ",
      " c    l  l    c ",
      " d g        g d ",
      " c            c ",
      " c            c ",
      " dl          ld ",
      " c     vv     c ",
      " c     ii     c ",
      " dl          ld ",
      " c            c ",
      " c            c ",
      " d g        g d ",
      " c    l  l    c ",
      " ccdccdnmdccdcc ",
      "                "
    ],
    [
      "                ",
      " oodoodoodoodoo ",
      " o            o ",
      " d g        g d ",
      " o            o ",
      " o            o ",
      " d            d ",
      " o     vv     o ",
      " o     ii     o ",
      " d            d ",
      " o            o ",
      " o            o ",
      " d g        g d ",
      " o            o ",
      " oodoodoodoodoo ",
      "                "
    ],
    [
      "                ",
      " ccdccdccdccdcc ",
      " cppppppppppppc ",
      " dpg        gpd ",
      " cp          pc ",
      " cp          pc ",
      " dp          pd ",
      " cp    vv    pc ",
      " cp    ii    pc ",
      " dp          pd ",
      " cp          pc ",
      " cp          pc ",
      " dpg        gpd ",
      " cppppppppppppc ",
      " ccdccdccdccdcc ",
      "                "
    ],
    [
      "                ",
      " qqqqqqqqqqqqqq ",
      " qaaaaaaaaaaaaq ",
      " qarddddddddraq ",
      " qaddddddddddaq ",
      " qaddddddddddaq ",
      " qaddddddddddaq ",
      " qaddddvvddddaq ",
      " qaddddiiddddaq ",
      " qaddddddddddaq ",
      " qaddddddddddaq ",
      " qaddddddddddaq ",
      " qarddddddddraq ",
      " qaaaaaaaaaaaaq ",
      " qqqqqqqqqqqqqq ",
      "                "
    ]
  ]
}