{
  "name": "building_apartment1_top_270",
  "refpalette": "c70cities:building_apartment1_top_palette_270",
  "xsize": 16,
  "zsize": 16,
  "slices": [
    [
      "                ",
      " aaaaaaaaaaaaaa ",
      " abbbbbbbbbbbba ",
      " abccccccccccba ",
      " abccccccccccba ",
      " abccccccccccba ",
      " abccccccccccba ",
      " abccccccccccba ",
      " abccccccccccba ",
      " abccccccccccba ",
      "  b  dcccccccba ",
      "  f   cccccccba ",
      "  g   cccccccba ",
      "  heebbbbbbbbba ",
      "      aaaaaaaaa ",
      "                "
    ],
    [
      "                ",
      "                ",
      "  bbbtllmbbiii  ",
      "  b o    on ni  ",
      "  bnon  !o   j  ",
      "  bowooooooo b  ",
      "  l     n  o b  ",
      "  l  n    ppnk  ",
      "  xnuun   pp l  ",
      "  brrrr    o b  ",
      "  i   s   pp i  ",
      "  i   r   pp i  ",
      "  b   r      j  ",
      "  bbbbbqiibblm  ",
      "                ",
      "                "
    ],
    [
      "                ",
      "                ",
      "  bllbbbbbbbbb  ",
      "  i          b  ",
      "  i          i  ",
      "  j          i  ",
      "  b          i  ",
      "  b       By b  ",
      "  b DD    yy b  ",
      "  brrrr      b  ",
      "  b   C   yy b  ",
      "  b   r   AA b  ",
      "  b   r      b  ",
      "  bbigbbbbbbbb  ",
      "                ",
      "                "
    ],
    [
      "                ",
      "                ",
      "  bbbbbblllbbb  ",
      "  b          b  ",
      "  b          b  ",
      "  b          b  ",
      "  b          b  ",
      "  l          b  ",
      "  l n        k  ",
      "  bEEEE      l  ",
      "  bEEEE      l  ",
      "  bEEEE      b  ",
      "  bEEEE      b  ",
      "  bbbbbbbtlllb  ",
      "                ",
      "                "
    ],
    [
      "                ",
      "                ",
      "                ",
      "                ",
      "                ",
      "                ",
      "                ",
      "                ",
      "                ",
      "                ",
      "                ",
      "                ",
      "                ",
      "                ",
      "                ",
      "                "
    ],
    [
      "                ",
      "                ",
      "                ",
      "                ",
      "                ",
      "                ",
      "                ",
      "                ",
      "                ",
      "                ",
      "                ",
      "                ",
      "                ",
      "                ",
      "                ",
      "                "
    ]
  ]
}