{
  "name": "building_office4_ground_270",
  "refpalette": "c70cities:building_office4_ground_palette_270",
  "xsize": 16,
  "zsize": 16,
  "slices": [
    [
      "GGGGGGGGGGGGGGGG",
      "GaaaaaaaaaaaaaaG",
      "GabbbcbbbbcbbbaG",
      "GabbbbbbbbbbbbaG",
      "GabbbbbbbbbbbbaG",
      "GacbbbbbbbbbbcaG",
      "GabbbbbbbbbbbbaG",
      "GabbbbbbbbbbbbaG",
      "GabbbbbbbbbbbbaG",
      "GabbbbbbbbbbbbaG",
      "GacbbbbbbbbbbcaG",
      "GabbbbbbbbbbbbaG",
      "GabbbbbbbbbbbbaG",
      "GabbbcbbbbcbbbaG",
      "GaaaaaaaaaaaaaaG",
      "GGGGGGGGGGGGGGGG"
    ],
    [
      "                ",
      " aaaadaaaadaaaa ",
      " aejjc nn cjjea ",
      " aq          fa ",
      " aq          fa ",
      " dc          cd ",
      " a    j  j    a ",
      " ar  llllll  ga ",
      " as   m  m   ha ",
      " a           ia ",
      " dc          cd ",
      " aq          fa ",
      " aq          fa ",
      " aekkc    ckkea ",
      " aaaadapoadaaaa ",
      "                "
    ],
    [
      "                ",
      " aaaadaaaadaaaa ",
      " at  c nn c  ta ",
      " a            a ",
      " a            a ",
      " dc          cd ",
      " a            a ",
      " a   y  u     a ",
      " a            a ",
      " a            a ",
      " dc          cd ",
      " a            a ",
      " a            a ",
      " at  c    c  ta ",
      " aaaadaxwadaaaa ",
      "                "
    ],
    [
      "                ",
      " aaaadaaaadaaaa ",
      " at  c nn c  ta ",
      " a            a ",
      " a            a ",
      " dc          cd ",
      " a            a ",
      " a            a ",
      " a            a ",
      " a            a ",
      " dc          cd ",
      " a            a ",
      " a            a ",
      " at  c    c  ta ",
      " aaaadaaaadaaaa ",
      "                "
    ],
    [
      "                ",
      " aaaadaaaadaaaa ",
      " a   c nn c   a ",
      " a            a ",
      " a            a ",
      " dc          cd ",
      " a            a ",
      " a     AA     a ",
      " a     BB     a ",
      " a            a ",
      " dc          cd ",
      " a            a ",
      " a            a ",
      " a   c    c   a ",
      " aaaadaaaadaaaa ",
      "                "
    ],
    [
      "                ",
      "    adaaaada    ",
      "  CCCcDnnDcCCC  ",
      "  CDDDDDDDDDDC  ",
      " aCDDDDDDDDDDCa ",
      " dcDDDDDDDDDDcd ",
      " aDDDDDDDDDDDDa ",
      " aDDDDDEEDDDDDa ",
      " aDDDDDEEDDDDDa ",
      " aDDDDDDDDDDDDa ",
      " dcDDDDDDDDDDcd ",
      " aCDDDDDDDDDDCa ",
      "  CDDDDDDDDDDC  ",
      "  CCCcDDDDcCCC  ",
      "    adaaaada    ",
      "                "
    ]
  ]
}