{
  "name": "building_hotel1_floor2",
  "refpalette": "c70cities:building_hotel1_floor2_palette",
  "xsize": 16,
  "zsize": 16,
  "slices": [
    [
      "                ",
      " aaaaaaaaaaaaaa ",
      " abbbbbbbbbbbba ",
      " abbbbbbbbbbbba ",
      " abbbbbbbbbbbba ",
      " abbbccccccccca ",
      " dbbbc    dbbba ",
      " dbbbc    bbbba ",
      " dbbbc    bbbba ",
      " dbbbc   ebbbbf ",
      " dbbbcccccbbbbf ",
      " dbbbbbbbcbbbbf ",
      " dbbbbbbbcbbbbf ",
      " abbbbbbbbbbbba ",
      " aaaaaaagggggaa ",
      "                "
    ],
    [
      "                ",
      " aaaaaaaaaaaaaa ",
      " a h  ijjk  l a ",
      " amn          a ",
      " a   opqqpo   a ",
      " a  rsaaaasataa ",
      " a  =a        a ",
      " a  ua    w   a ",
      " a  ua    w  na ",
      " a  =a eed    f ",
      " a aasaaaa    f ",
      " a xx fyAa    f ",
      " a BB fCDaeEE f ",
      " a      Faeeena ",
      " aaaaaaaaaaaaaa ",
      "                "
    ],
    [
      "                ",
      " aaaaaaaaaaaaaa ",
      " a            a ",
      " a I          a ",
      " a   o  J o   a ",
      " a   saaaasaKaa ",
      " f  La        a ",
      " f   a        a ",
      " f   ae      Ma ",
      " f  Naed      f ",
      " a aasaaaa    f ",
      " a    f  a    f ",
      " a    f  a    f ",
      " a       a   Ma ",
      " aaffffffaaaaaa ",
      "                "
    ],
    [
      "                ",
      " aaaaaaaaaaaaaa ",
      " a   O    O   a ",
      " a            a ",
      " a            a ",
      " a   saaaasaaaa ",
      " a   ae       a ",
      " a  Eae       a ",
      " a  Ead      Ma ",
      " a   a        f ",
      " aaaasaaaa    f ",
      " a   Of  a    f ",
      " a    f  a    f ",
      " a       a   Ma ",
      " aaaaaaaaaaaaaa ",
      "                "
    ],
    [
      "                ",
      " aaaaaaaaaaaaaa ",
      " a   P    P   a ",
      " f            a ",
      " f            a ",
      " a   saaaasaaaa ",
      " a   adee     a ",
      " a   a        a ",
      " a   a        a ",
      " a   a        f ",
      " aaaasaaaa    f ",
      " a   Pf  a    f ",
      " a    f  a    f ",
      " a    f  a    a ",
      " aaaaaaffaaaaaa ",
      "                "
    ],
    [
      "                ",
      " aaaaaaaaaaaaaa ",
      " aQQQQQQQQQQQQa ",
      " aQQQQQQQQQQQQa ",
      " aQQQQQQQQQQQQa ",
      " aQQQsaaaasaaaa ",
      " aQQQa  deQQQQa ",
      " aQQQa    QQQQa ",
      " aQQQa    QQQQa ",
      " aQQQa    QQQQf ",
      " aQQQsaaaaQQQQf ",
      " aQQQQQQQaQQQQf ",
      " aQQQQQQQaQQQQf ",
      " aQQQQQQQaQQQQa ",
      " aaaaaaaaaaaaaa ",
      "                "
    ]
  ]
}