{
  "name": "building_hotel2_floor2_90",
  "refpalette": "c70cities:building_hotel2_floor2_palette_90",
  "xsize": 16,
  "zsize": 16,
  "slices": [
    [
      "                ",
      " a              ",
      " a              ",
      " a              ",
      " adddddddddddd  ",
      " acccccccccccd  ",
      " acccccccccccd  ",
      " acccccccccccd  ",
      " acccccc!ccccd  ",
      " acccccccccccd  ",
      " acccccccccccd  ",
      " acccccccccccd  ",
      " acccccccccccd  ",
      " abb=cc!c!cccd  ",
      " aaaaaaaaaaaaaa ",
      "                "
    ],
    [
      "                ",
      " a              ",
      " a              ",
      " a              ",
      " affffffffffff  ",
      " a  jj  sa   f  ",
      " a      saw  f  ",
      " a  ii   aux f  ",
      " a  hhorpaux f  ",
      " aeaaaaaaa   f  ",
      " a  g        f  ",
      " a  aaaqat  Bf  ",
      " a  aln at  Af  ",
      " abb=kmpa=  yf  ",
      " aaaaaaaaaaaaaa ",
      "                "
    ],
    [
      "                ",
      " a              ",
      " a              ",
      " a              ",
      " affffffffffff  ",
      " a       a   f  ",
      " a      Fa   f  ",
      " a       a   f  ",
      " a       a   f  ",
      " aCaaaaaaa   f  ",
      " a  D        f  ",
      " a  aaaEa    f  ",
      " a  a   a   Jf  ",
      " abb=   aI   f  ",
      " aaaaaaaaaaaaaa ",
      "                "
    ],
    [
      "                ",
      " a              ",
      " a              ",
      " a              ",
      " affffffffffff  ",
      " a       a   f  ",
      " a       a   f  ",
      " a       a   f  ",
      " a       a   f  ",
      " aaaaaaaaa   f  ",
      " a  a        f  ",
      " a  aaaaaL   f  ",
      " a  a   aL   f  ",
      " abb=   aK   f  ",
      " aaaaaaaaaaaaaa ",
      "                "
    ],
    [
      "                ",
      " a              ",
      " a              ",
      " a              ",
      " affffffffffff  ",
      " a       a   f  ",
      " a       a   f  ",
      " a       a   f  ",
      " a       a   f  ",
      " aaaaaaaaa   f  ",
      " a  a        f  ",
      " aMMaaaaa    f  ",
      " a  a   a    f  ",
      " abb=   aN   f  ",
      " aaaaaaaaaaaaaa ",
      "                "
    ],
    [
      "                ",
      " a              ",
      " a              ",
      " a              ",
      " aJJJJJJJJJJJJ  ",
      " aOOOOOOOOOOOJ  ",
      " aOOOOOOOaOOOJ  ",
      " aOOOOOOOaOOOJ  ",
      " aOOOOOOOaOOOJ  ",
      " aaaaaaaaaOOOJ  ",
      " aOOaOOOOOOOOJ  ",
      " aOOaaaaaOOOOJ  ",
      " aOOaOOOaOOOOJ  ",
      " abb=OOOaOOOOJ  ",
      " aaaaaaaaaaaaaa ",
      "                "
    ]
  ]
}