{
  "name": "building_office5_floor2_180",
  "refpalette": "c70cities:building_office5_floor2_palette_180",
  "xsize": 16,
  "zsize": 16,
  "slices": [
    [
      "                ",
      "                ",
      "  dbdbdbdbdbdd  ",
      "  beeeeeeeeeeb  ",
      "  deeeeeeeeeed  ",
      "  beeeeeeeeeeb  ",
      "  deeeeeeeeeed  ",
      "  beeeeeeeeeeb  ",
      "  deeeeeeeeeed  ",
      "  beeeeffeeeeb  ",
      "  ddddddddeedd  ",
      "    accccccca   ",
      "    bcccccccb   ",
      "    ababababa   ",
      "                ",
      "                "
    ],
    [
      "                ",
      "                ",
      "  dbdbdbdbdbdd  ",
      "  b   m      b  ",
      "  d m     m  d  ",
      "  b gg gg gg b  ",
      "  d     k   ld  ",
      "  b  k       b  ",
      "  d          d  ",
      "  b    ffj  jb  ",
      "  dddddddd  dd  ",
      "    aiihgg  a   ",
      "    b       b   ",
      "    ababababa   ",
      "                ",
      "                "
    ],
    [
      "                ",
      "                ",
      "  dbdbdbdbdbdd  ",
      "  b          b  ",
      "  d          d  ",
      "  b o     o  b  ",
      "  d          d  ",
      "  b          b  ",
      "  d          d  ",
      "  b    ffj  jb  ",
      "  dd!ddddd  dd  ",
      "    a   n   a   ",
      "    b       b   ",
      "    ababababa   ",
      "                ",
      "                "
    ],
    [
      "                ",
      "                ",
      "  dbdbdbdbdbdd  ",
      "  b          b  ",
      "  d          d  ",
      "  b          b  ",
      "  d          d  ",
      "  b          b  ",
      "  d          d  ",
      "  b    ff    b  ",
      "  ddqdddddqqdd  ",
      "    apppp   a   ",
      "    b       b   ",
      "    ababababa   ",
      "                ",
      "                "
    ],
    [
      "                ",
      "                ",
      "  dbdbdbdbdbdd  ",
      "  b          b  ",
      "  d          d  ",
      "  b          b  ",
      "  d          d  ",
      "  b          b  ",
      "  d          d  ",
      "  b    ff    b  ",
      "  dddddddddddd  ",
      "    a       a   ",
      "    b       b   ",
      "    ababababa   ",
      "                ",
      "                "
    ],
    [
      "                ",
      "                ",
      "  dbdbdbdbdbdd  ",
      "  brrrrrrrrrrb  ",
      "  drrrrrrrrrrd  ",
      "  brrrrrrrrrrb  ",
      "  drrrrrrrrrrd  ",
      "  brrrrrrrrrrb  ",
      "  drrrrrrrrrrd  ",
      "  brrrrffrrrrb  ",
      "  dddddddddddd  ",
      "    a       a   ",
      "    b       b   ",
      "    ababababa   ",
      "                ",
      "                "
    ]
  ]
}