{
  "name": "building_office4_top_90",
  "refpalette": "c70cities:building_office4_top_palette_90",
  "xsize": 16,
  "zsize": 16,
  "slices": [
    [
      "                ",
      "    abaaaaba    ",
      "  cccdeeeedccc  ",
      "  cfeeeeeeeehc  ",
      " aceeeeeeeeeeca ",
      " bdeeGGeeGGeedb ",
      " aeeeGGeeGGeeea ",
      " aeeeeeGGeeeeea ",
      " aeeeeGGGGeeeea ",
      " aeeeeGGGGeeeea ",
      " bdeeeGeeGeeedb ",
      " aceeeeeeeeeeca ",
      "  cfeeeeeeeefc  ",
      "  cccdeggedccc  ",
      "    abaaaaba    ",
      "                "
    ],
    [
      "                ",
      "    abaaaaba    ",
      "  iiijiiiijiii  ",
      "  ikkk no kkki  ",
      " aik        kia ",
      " bjk        kjb ",
      " ai          ia ",
      " aim        qia ",
      " ail        pia ",
      " ai          ia ",
      " bjk        kjb ",
      " aik        kia ",
      "  ikkk    kkki  ",
      "  iiiji  ijiii  ",
      "    abaaaaba    ",
      "                "
    ],
    [
      "                ",
      "    ab    ba    ",
      "  iiijiiiijiii  ",
      "  i          i  ",
      " ai          ia ",
      " bj          jb ",
      "  i          i  ",
      "  i          i  ",
      "  i          i  ",
      "  i          i  ",
      " bj          jb ",
      " ai          ia ",
      "  i          i  ",
      "  iiiji  ijiii  ",
      "    ab    ba    ",
      "                "
    ],
    [
      "                ",
      "    a      a    ",
      "   iijiiiijii   ",
      "  i          i  ",
      " ai          ia ",
      "  j          j  ",
      "  i          i  ",
      "  i          i  ",
      "  i          i  ",
      "  i          i  ",
      "  j          j  ",
      " ai          ia ",
      "  i          i  ",
      "   iijiiiijii   ",
      "    a      a    ",
      "                "
    ],
    [
      "                ",
      "                ",
      "   iijiiiijii   ",
      "  i          i  ",
      "  i          i  ",
      "  j          j  ",
      "  i          i  ",
      "  i          i  ",
      "  i          i  ",
      "  i          i  ",
      "  j          j  ",
      "  i          i  ",
      "  i          i  ",
      "   iijiiiijii   ",
      "                ",
      "                "
    ],
    [
      "                ",
      "                ",
      "                ",
      "   iijiiiijii   ",
      "   iijiiiijii   ",
      "   jjrjjjjsjj   ",
      "   iijjjjjjii   ",
      "   iijjjjjjii   ",
      "   iijjjjjjii   ",
      "   iijjjjjjii   ",
      "   jjrjjjjrjj   ",
      "   iijiiiijii   ",
      "   iijiiiijii   ",
      "                ",
      "                ",
      "                "
    ]
  ]
}