{
  "name": "building_office1_floor1_90",
  "refpalette": "c70cities:building_office1_floor1_palette_90",
  "xsize": 16,
  "zsize": 16,
  "slices": [
    [
      "                ",
      "        c  eeee ",
      "  aaaaaacddfbbe ",
      "  abbbbbbbbbbbe ",
      "  abbbbbbbbbbbe ",
      "  abbbbbbbbb!be ",
      "  abbbbbbbbbbbe ",
      "  abbbbbbbbbbbe ",
      "  abbbbbbbbbbbe ",
      "  abbbbbbbbbbbe ",
      "  abbbbbbbbbbbe ",
      "  abbbbbbbbbbbe ",
      "  abbbbbbbbgbbe ",
      "  aaaaaacddfbbe ",
      "        c  eeee ",
      "                "
    ],
    [
      "                ",
      "        c  rrrr ",
      "  hhhhhhcddfxxr ",
      "  h    nf     r ",
      "  h  l  f     r ",
      "  h   m f  iw r ",
      "  h ik  f   wAr ",
      "  h   m f  iw r ",
      "  h i   ffqfffr ",
      "  h  km f  suyr ",
      "  h i   p     r ",
      "  h  j  o     r ",
      "  h     f  g  r ",
      "  hhhhhhcddfttr ",
      "        c  rrrr ",
      "                "
    ],
    [
      "                ",
      "        c  rrrr ",
      "  hhhhhhcddfK r ",
      "  h     f     L ",
      "  h     f     d ",
      "  h  B  f   J d ",
      "  h  B  f   I d ",
      "  h  B  f   F d ",
      "  h  B  ffEfffd ",
      "  h  B  f     d ",
      "  h  B  D     d ",
      "  h     C     d ",
      "  h     f  g  L ",
      "  hhhhhhcddfttr ",
      "        c  rrrr ",
      "                "
    ],
    [
      "                ",
      "        c  rrrr ",
      "  hhhhhhcddf  r ",
      "  h     f     L ",
      "  h     f     d ",
      "  h     f     d ",
      "  h     f     d ",
      "  h     f     d ",
      "  h     ffffffd ",
      "  h     f     d ",
      "  h     f     d ",
      "  h     f     d ",
      "  h     f  g  L ",
      "  hhhhhhcddfttr ",
      "        c  rrrr ",
      "                "
    ],
    [
      "                ",
      "        c  rrrr ",
      "  hhhhhhcddf  r ",
      "  h     f     r ",
      "  h     f     r ",
      "  h     f     r ",
      "  h     f     r ",
      "  h     f     r ",
      "  h     ffffffr ",
      "  h     f     r ",
      "  h     f     r ",
      "  h     f     r ",
      "  h     f  g  r ",
      "  hhhhhhcddfMMr ",
      "        c  rrrr ",
      "                "
    ],
    [
      "                ",
      "        c  rrrr ",
      "  hhhhhhcddfLLr ",
      "  hLLLLLf   LLr ",
      "  hLLLLLfLLLLLr ",
      "  hLLLLLfLLLLLr ",
      "  hLLLLLfLLLLLr ",
      "  hLLLLLfLLLLLr ",
      "  hLLLLLffffffr ",
      "  hLLLLLfLLLLLr ",
      "  hLLLLLfLLLLLr ",
      "  hLLLLLfLLLLLr ",
      "  hLLLLLf  gLLr ",
      "  hhhhhhcddfLLr ",
      "        c  rrrr ",
      "                "
    ]
  ]
}