{
  "name": "building_office1_top_90",
  "refpalette": "c70cities:building_office1_top_palette_90",
  "xsize": 16,
  "zsize": 16,
  "slices": [
    [
      "                ",
      "        c  eeee ",
      "  aaaaaacddfbbe ",
      "  abbbbbbbbbbbe ",
      "  abbbbbbbbbbbe ",
      "  abbbbbbbbbbbe ",
      "  abbbbbbbbbbbe ",
      "  abbbbbbbbbbbe ",
      "  abbbbbbbbbbbe ",
      "  abbbbbbbbbbbe ",
      "  abbbbbbbbbbbe ",
      "  abbbbbbbbbbbe ",
      "  abbbbbbbbgbbe ",
      "  aaaaaacddfbbe ",
      "        c  eeee ",
      "                "
    ],
    [
      "                ",
      "        c  mmmm ",
      "  hhhhhhcddf  m ",
      "  h     l     m ",
      "  h iiii      m ",
      "  h ijji      m ",
      "  h           m ",
      "  h  kk      nm ",
      "  h  kk      nm ",
      "  h           m ",
      "  h ijji      m ",
      "  h iiii      m ",
      "  h     l     m ",
      "  hhhhhhcddf  m ",
      "        c  mmmm ",
      "                "
    ],
    [
      "                ",
      "        c  mmmm ",
      "   o o ocddf  m ",
      "        p     q ",
      "              d ",
      "              d ",
      "              d ",
      "              d ",
      "              d ",
      "              d ",
      "              d ",
      "              d ",
      "        p     q ",
      "   o o ocddf  m ",
      "        c  mmmm ",
      "                "
    ],
    [
      "                ",
      "        c  mmmm ",
      "   o o ocddf  m ",
      "              q ",
      "              d ",
      "              d ",
      "              d ",
      "              d ",
      "              d ",
      "              d ",
      "              d ",
      "              d ",
      "              q ",
      "   o o ocddf  m ",
      "        c  mmmm ",
      "                "
    ],
    [
      "                ",
      "        c  mmmm ",
      "   o o ocfff  m ",
      "        frrf  m ",
      "        frrf  m ",
      "        frrf  m ",
      "        frrf  m ",
      "        frrf  m ",
      "        frrf  m ",
      "        frrf  m ",
      "        frrf  m ",
      "        frrf  m ",
      "        frrf  m ",
      "   o o ocfff  m ",
      "        c  mmmm ",
      "                "
    ],
    [
      "                ",
      "        c  mmmm ",
      "  ssssssc  rrrm ",
      "  seeeees  rrrm ",
      "  seeeees  rrrm ",
      "  seeeees  rrrm ",
      "  seeeees  rrrm ",
      "  seeeees  rrrm ",
      "  seeeees  rrrm ",
      "  seeeees  rrrm ",
      "  seeeees  rrrm ",
      "  seeeees  rrrm ",
      "  seeeees  rrrm ",
      "  ssssssc  rrrm ",
      "        c  mmmm ",
      "                "
    ]
  ]
}