{
  "name": "building_bank1_floor2_270",
  "refpalette": "c70cities:building_bank1_floor2_palette_270",
  "xsize": 16,
  "zsize": 16,
  "slices": [
    [
      "                ",
      "   hbbf  hbbf   ",
      "  deeeedeeeeed  ",
      " keeeej    eeea ",
      " beeeeeeeeeeeeb ",
      " beeeeeeeeeeeeb ",
      " leeeeeeeeeeeec ",
      "  eeeeeeeeeeed  ",
      "  deeeeeee!eee  ",
      " keeeeeeeeeeeea ",
      " beeeee!eeeeeeb ",
      " beeeeeeeeeeeeb ",
      " leeeeeeeeeeeec ",
      "  deeeeedeeeed  ",
      "   ibbg  ibbg   ",
      "                "
    ],
    [
      "                ",
      "  hbbf  hbbf    ",
      "  mmmmnmmmsmnma ",
      "  n       j  mb ",
      " km   ttttt  mb ",
      " bm          mc ",
      " bm          n  ",
      " lmooo    pp m  ",
      "  m    y ooooma ",
      "  n xA o     mb ",
      " km  B o wuq mb ",
      " bm Cr o x r mc ",
      " bm    o     n  ",
      " lmnmmmmmnmmmm  ",
      "    ibbg  ibbg  ",
      "                "
    ],
    [
      "                ",
      " Dbbf  hbbf  hD ",
      " lmmmnmmmsmnmmb ",
      "  m      j   mb ",
      "  n   t t t  mc ",
      " km          n  ",
      " bm          m  ",
      " bmooo       ma ",
      " lm    E oooomb ",
      "  m    o     mb ",
      "  n    o     mc ",
      " km    o     n  ",
      " bm    o     m  ",
      " bmmnmmmmmnmmma ",
      " Dg  ibbg  ibbD ",
      "                "
    ],
    [
      "                ",
      " Dbf  hbbf  hbD ",
      " bmmnmmmsmnmmmb ",
      " lm     j    mc ",
      "  m   t t t  n  ",
      "  n          m  ",
      " km          ma ",
      " bm          mb ",
      " bm    E     mb ",
      " lm          mc ",
      "  m          n  ",
      "  n          m  ",
      " km          ma ",
      " bmmmnmmmmmnmmb ",
      " Dbg  ibbg  ibD ",
      "                "
    ],
    [
      "                ",
      " Df  hbbf  hbbD ",
      " bmnmmmsmnmmmmc ",
      " bm    j     n  ",
      " lm   t t t  m  ",
      "  m          ma ",
      "  n          mb ",
      " km          mb ",
      " bm          mc ",
      " bm          n  ",
      " lm          m  ",
      "  m          ma ",
      "  n          mb ",
      " kmmmmnmmmmmnmb ",
      " Dbbg  ibbg  iD ",
      "                "
    ],
    [
      "                ",
      "    hbbf  hbbf  ",
      " knmmmsmnmmmmn  ",
      " bmFFFj    FFm  ",
      " bmFFFt t tFFma ",
      " lmFFFFFFFFFFmb ",
      "  mFFFFFFFFFFmb ",
      "  nFFFFFFFFFFmc ",
      " kmFFFFFFFFFFn  ",
      " bmFFFFFFFFFFm  ",
      " bmFFFFFFFFFFma ",
      " lmFFFFFFFFFFmb ",
      "  mFFFFFFFFFFmb ",
      "  nmmmmnmmmmmnc ",
      "  ibbg  ibbg    ",
      "                "
    ]
  ]
}