{
  "name": "building_factory2_ground",
  "refpalette": "c70cities:building_factory2_ground_palette",
  "xsize": 16,
  "zsize": 16,
  "slices": [
    [
      "zzzzzzzzzzzzzzzz",
      "zzzzzzzzzzzzzzzz",
      "zzzzzzzzzzzzzzzz",
      "zzzzHHHHHHHHHzzz",
      "azaaHHHHHHHHHzzz",
      "zaaaHHHHHHHHHzzz",
      "zzaaHHHHHHHHHzzz",
      "zazaHHHHHHHHHzzz",
      "zaaaHHHHHHHHHHzz",
      "zzazHHHHHHHHHHzz",
      "zazzHHHHHHHHHzzz",
      "zzzzHHHHHHHHHzzz",
      "zzzzHHHHHHHHHzzz",
      "zzzzzzzzzzzzzzzz",
      "zzzzzzzzzzzzzzzz",
      "zzzzzzzzzzzzzzzz"
    ],
    [
      "  b cdb  b dcb  ",
      " bceccc b  ccceb",
      "  dcfffffffffff ",
      " b bfghijfkkkffd",
      "    li   fkkkffc",
      "    f  i mnnkfee",
      "    o    pkkkfee",
      "    q   rsnnnffc",
      "    qg   tkukff ",
      "   bqw    ixyfee",
      "  b qgA    BCfee",
      "  bcogg  D  Effb",
      " d cf!gF F ggffd",
      " bccfffffffffffc",
      "  becdcccbcc cec",
      " b b b b  c dbb "
    ],
    [
      "                ",
      "   ecc       ce ",
      "   cfIIIfffffff ",
      "    f     un ff ",
      "    J     KK ff ",
      "    f    LKnKfee",
      "    o     KKKfee",
      "    q     nnnff ",
      "    q     M MNf ",
      "    q        fee",
      "    q        fee",
      "    ogO     Pff ",
      "   cfO      jff ",
      "   cfIIIffIIIff ",
      "   e   cc c   e ",
      "                "
    ],
    [
      "                ",
      "   ec         e ",
      "    fIIIfffffff ",
      "    f       jff ",
      "    Q     RRRff ",
      "    f    SRRRfee",
      "    o     RRRfee",
      "    q      P ff ",
      "    q        Qf ",
      "    q        fee",
      "    q        fee",
      "    o        ff ",
      "    f        ff ",
      "    fIIIffIIIff ",
      "   e          e ",
      "                "
    ],
    [
      "                ",
      "   e          e ",
      "    fTTTffffffU ",
      "    f       jfU ",
      "    f        fU ",
      "    f        fVU",
      "    o        fVU",
      "   Wo       XfU ",
      "   Wo        fU ",
      "   Wo        fVU",
      "   Wo        fVU",
      "    o       XfU ",
      "    f        fU ",
      "    fTTTffTTTfU ",
      "   e          e ",
      "                "
    ],
    [
      "                ",
      "   e          e ",
      "    fYYYffYYYf  ",
      "    f        f  ",
      "    f        f  ",
      "    f   Z0   fV ",
      "    Y        fV ",
      "    Y        f  ",
      "    Y        f  ",
      "    Y        fV ",
      "    Y   00   fV ",
      "    Y        f  ",
      "    f        f  ",
      "    fYYYffYYYf  ",
      "   e          e ",
      "                "
    ]
  ]
}