{
  "name": "building_factory1_ground_180",
  "refpalette": "c70cities:building_factory1_ground_palette_180",
  "xsize": 16,
  "zsize": 16,
  "slices": [
    [
      "zzzzzzzzzzzzzaaa",
      "zzzzzzzzzzzzzzaa",
      "zzbbbbbbbbbbbzaa",
      "zzbbbbbbbbbbbaaa",
      "zzbbbbbbbbbbbaaz",
      "zzbbcbbbbbbbbaaz",
      "zzbbbbbbbbbbbaaa",
      "zzbbcbbbbbbbbaaa",
      "zzbbbbbbbbbbbaza",
      "zzbbbbbbbbbbbaaa",
      "zzbbbbbbbbbbbaaa",
      "zzbbbbbbbbbbbaaz",
      "zzbbbbbbbbbbbaaa",
      "zzbbbbbbbbbbbzaa",
      "zzzzzzzzzzzzzaaa",
      "zzzzzzzzzzzzzzaa"
    ],
    [
      " e  ddNd ddO    ",
      "    Nd ddd dd   ",
      " dhhhhhhhhhhh   ",
      "  hiMMLiKJIih   ",
      " dhxFEDxxxxx    ",
      "d hxCu A B      ",
      "  hxwuA   y     ",
      "  hxwur   t     ",
      "  h sr          ",
      " dh q           ",
      "  hoopo         ",
      "  h   k nnn     ",
      "d himlki!jjih   ",
      "  hhhhhhhhhhh   ",
      " d g     d      ",
      "d d d f e  d    "
    ],
    [
      "                ",
      "                ",
      "  hhhhhhhhhhh   ",
      "  hiMM i X ih   ",
      "  hxW VU    Q   ",
      "  hx        Q   ",
      "  hx        Q   ",
      "  hx        Q   ",
      "  h T       Q   ",
      "  h S       Q   ",
      "  hooRo     Q   ",
      "  h   k     Q   ",
      "  hiP ki nnih   ",
      "  hhhhhhhhhhh   ",
      "   g            ",
      "                "
    ],
    [
      "                ",
      "                ",
      "  hhhhhhhhhhh   ",
      "  hiMM i432ih   ",
      "  h  1      Q   ",
      "  hx        Q   ",
      "  hx0       Q   ",
      "  hx0       Q   ",
      "  h         Q   ",
      "  h         Q   ",
      "  hoooo     Q   ",
      "  h   k Z   Q   ",
      "  hi  ki   ih   ",
      "  hhhhhhhhhhh   ",
      "   Y            ",
      "                "
    ],
    [
      "                ",
      "                ",
      "  hh765h765hh   ",
      "  hi888i888ih   ",
      "  h         h9  ",
      "  h         h9  ",
      "  h         h9  ",
      "  h      &  h9  ",
      "  h        @h9  ",
      "  h        @h9  ",
      "  hoooo^   @h9  ",
      "  h   k%$$#@h9  ",
      "  hi888i888ih   ",
      "  hh765h765hh   ",
      "                ",
      "                "
    ],
    [
      "                ",
      "                ",
      "  ***********   ",
      "  h(((((((((h   ",
      "  h-   -   -h   ",
      "  h888888888h   ",
      "  h         h   ",
      "  h  +   +  h   ",
      "  h         h   ",
      "  h         h   ",
      "  h888888888h   ",
      "  h)   )   )h   ",
      "  h(((((((((h   ",
      "  ***********   ",
      "                ",
      "                "
    ]
  ]
}