{
  "name": "building_bunker1_base1_180",
  "refpalette": "c70cities:building_bunker1_base1_palette_180",
  "xsize": 16,
  "zsize": 16,
  "slices": [
    [
      "vvvvvvvvvvvvvvvv",
      "v=====aa=aaa===v",
      "v=====aaaaaa===v",
      "v=====aa=======v",
      "v=====aaaaaa===v",
      "v=====aa=aaa===v",
      "v==============v",
      "v==============v",
      "v==============v",
      "v==============v",
      "v=aaaaaa=======v",
      "v=aaaaaa=======v",
      "v=aaaaaa=======v",
      "v=aaaaaa=======v",
      "v==============v",
      "vvvvvvvvvvvvvvvv"
    ],
    [
      "vvvvvvvvvvvvvvvv",
      "vbXWVbUUbTKJbzzv",
      "vbS  R  O  Nbzzv",
      "vbbbbb  bbbbbzzv",
      "vbIQPb  O  Nbzzv",
      "vbM  b nbLKJbzzv",
      "vbI  bFbEbbbbbbv",
      "vbD  C nb  obBAv",
      "vbyy    x  wb sv",
      "vbu    tb ssb  v",
      "vbqrq  pbbbbb ov",
      "vbn     m     lv",
      "vbk     b     jv",
      "vbihgefebdddbccv",
      "vbbbbbbbbbbbbbbv",
      "vvvvvvvvvvvvvvvv"
    ],
    [
      "vvvvvvvvvvvvvvvv",
      "v{:`|E TET\\}Ezzv",
      "v{ ]][  *  -Ezzv",
      "vEEEEE  EEEEEzzv",
      "vE+)(E  *  &Ezzv",
      "vE   E 6EL10Ezzv",
      "vE^  E%EEEEEEEEv",
      "vE     6E   E$Av",
      "vE      #  wE @v",
      "vE      E  sE  v",
      "vE98   7EEEEE  v",
      "vE6     5     ov",
      "v4      E      v",
      "v4   32LE   E10v",
      "vZYYYEEEEEEEEEEv",
      "vvvvvvvvvvvvvvvv"
    ],
    [
      "vvvvvvvvvvvvvvvv",
      "vE\u00c1\u00c0 E\u00a7\u00a7E  fEzzv",
      "vE \u00a5\u00a4E  E<  Ezzv",
      "vEEEEE  EEEEEzzv",
      "vE\u00a3?>E  E<  Ezzv",
      "vE.  E 6E /fEzzv",
      "vE.  EEEEEEEEEEv",
      "vE     6E   E!Av",
      "vE      {  wE  v",
      "vE      E   E  v",
      "vE      EEEEE  v",
      "vE6     E      v",
      "vE      E      v",
      "vE,,,,,,E'''E; v",
      "vEEEEEEEEEEEEEEv",
      "vvvvvvvvvvvvvvvv"
    ],
    [
      "vvvvvvvvvvvvvvvv",
      "vE\u00c4\u00c2\u00c2E\u00c4\u00c4E\u00c2\u00c2\u00c4Ezzv",
      "vE\u00c4\u00c2\u00c2E\u00c2\u00c2E\u00c2\u00c2\u00c5Ezzv",
      "vEEEEE\u00c2\u00c2EEEEEzzv",
      "vEE\u00c4EE\u00c2\u00c2E\u00c2\u00c2\u00c5Ezzv",
      "vEE\u00c4EE\u00c2\u00c2E\u00c2\u00c2\u00c4Ezzv",
      "vEE\u00c4EEEEEEEEEEEv",
      "vE\u00c2\u00c2\u00c2\u00c2\u00c2\u00c2EEEEE\u00c2Av",
      "vE\u00c2\u00c2\u00c2\u00c2\u00c2\u00c2EEEwE\u00c2\u00c2v",
      "vE\u00c2\u00c2\u00c2\u00c2\u00c2\u00c2EEEEE\u00c2\u00c2v",
      "vE\u00c2\u00c2\u00c2\u00c2\u00c2\u00c2EEEEE\u00c4\u00c4v",
      "vE\u00c2\u00c2\u00c2\u00c2\u00c2\u00c2E\u00c2\u00c2\u00c2\u00c4\u00c2\u00c2v",
      "vE\u00c2\u00c2\u00c2\u00c2\u00c2\u00c2E\u00c2\u00c2\u00c2\u00c5\u00c2\u00c2v",
      "vE\u00c4\u00c4\u00c4\u00c4\u00c4\u00c4E\u00c3\u00c3\u00c3E\u00c2\u00c2v",
      "vEEEEEEEEEEEEEEv",
      "vvvvvvvvvvvvvvvv"
    ],
    [
      "vvvvvvvvvvvvvvvv",
      "vzzzzzzzzzzzzzzv",
      "vzzzzzzzzzzzzzzv",
      "vzzzzzzzzzzzzzzv",
      "vzzzzzzzzzzzzzzv",
      "vzzzzzzzzzzzzzzv",
      "vzzzzzzzzzzzzzzv",
      "vzzzzzzzzzzEzzzv",
      "vzzzzzzzzzEwEzzv",
      "vzzzzzzzzzzEzzzv",
      "vzzzzzzzzzzzzzzv",
      "vzzzzzzzzzzzzzzv",
      "vzzzzzzzzzzzzzzv",
      "vzzzzzzzzzzzzzzv",
      "vzzzzzzzzzzzzzzv",
      "vvvvvvvvvvvvvvvv"
    ]
  ]
}