{
  "name": "building_carservice1_base1_180",
  "refpalette": "c70cities:building_carservice1_base1_palette_180",
  "xsize": 16,
  "zsize": 16,
  "slices": [
    [
      "vvvvvvvvvvvvvvvv",
      "vaaaaaaaaaaaaaav",
      "vaaaaaaaaaaa==av",
      "vaaaaaaaaaaa==av",
      "vaaaaaaaaaaa==av",
      "vaaaaaaaaaaa==av",
      "vaaaaa!aaaaaaaav",
      "vaaaaaaaaaaaaaav",
      "vaaaaaaaaaaaaaav",
      "vaaaaaaaaaaaaaav",
      "vaaaaaaaaaaaaaav",
      "vaaaaaaaaaaaaaav",
      "vaaaaaaaaaaaaaav",
      "vaaaaaaaaaaaaaav",
      "vaaaaaaaaaaaaaav",
      "vvvvvvvvvvvvvvvv"
    ],
    [
      "vvvvvvvvvvvvvvvv",
      "vbbbbbubbbbbvvvv",
      "vbtssro qq b pvv",
      "vb    o    n  vv",
      "vb         n  vv",
      "vb         n  vv",
      "vblml bkk  bjjvv",
      "vbccc hi   b==vv",
      "vbfcfeh    b==vv",
      "vbccc bb  bb==vv",
      "vbcgc bd  d===vv",
      "vbfcfeb! dd===vv",
      "vbccc bvvvvvvvvv",
      "vb    bvvvvvvvvv",
      "vbbbbbbvvvvvvvvv",
      "vvvvvvvvvvvvvvvv"
    ],
    [
      "vvvvvvvvvvvvvvvv",
      "vbbbbbubbbbbvvvv",
      "vb    o    b pvv",
      "vb    o    n  vv",
      "vb         n  vv",
      "vb         n  vv",
      "vb    b    b  vv",
      "vbBDB h    b  vv",
      "vbBCB h    bjjvv",
      "vbAAA bb  bb==vv",
      "vbA A b    ===vv",
      "vbxyx bd   ===vv",
      "vbwww bvvvvvvvvv",
      "vb    bvvvvvvvvv",
      "vbbbbbbvvvvvvvvv",
      "vvvvvvvvvvvvvvvv"
    ],
    [
      "vvvvvvvvvvvvvvvv",
      "vbbbbbubbbbbvvvv",
      "vb    o    bppvv",
      "vb    o    n  vv",
      "vb         n  vv",
      "vb         n  vv",
      "vb    b    b  vv",
      "vb    h    b  vv",
      "vb    h    b  vv",
      "vbBDB bbbbbb  vv",
      "vbBCB b    =jjvv",
      "vb D  b    =jjvv",
      "vb    bvvvvvvvvv",
      "vb    bvvvvvvvvv",
      "vbbbbbbvvvvvvvvv",
      "vvvvvvvvvvvvvvvv"
    ],
    [
      "vvvvvvvvvvvvvvvv",
      "vbbbbbbbbbbbvvvv",
      "vb    b    bppvv",
      "vb    b    b  vv",
      "vb    b    b  vv",
      "vb    b    b  vv",
      "vb    b    b  vv",
      "vb    b    b  vv",
      "vb    b    b  vv",
      "vb    bbbbbb  vv",
      "vb    b===j   vv",
      "vb    b===j   vv",
      "vb    bvvvvvvvvv",
      "vb    bvvvvvvvvv",
      "vbbbbbbvvvvvvvvv",
      "vvvvvvvvvvvvvvvv"
    ],
    [
      "vvvvvvvvvvvvvvvv",
      "vbbbbbbbbbbbvvvv",
      "vbEFF bFFFFbIIvv",
      "vbFFFFbFFFFbIIvv",
      "vbFFFFbFFFFbIIvv",
      "vbFFFFbFFFFbIIvv",
      "vbFFFFbFFFFbIIvv",
      "vbFFFFbFFFFbIIvv",
      "vbJFFEbFFFFbIIvv",
      "vbFFFFbbbbbb  vv",
      "vbFFFFb=j     vv",
      "vbFFFFb=j     vv",
      "vbFFFFbvvvvvvvvv",
      "vb FFEbvvvvvvvvv",
      "vbbbbbbvvvvvvvvv",
      "vvvvvvvvvvvvvvvv"
    ]
  ]
}