{
  "name": "building_apartment1_ground",
  "refpalette": "c70cities:building_apartment1_ground_palette",
  "xsize": 16,
  "zsize": 16,
  "slices": [
    [
      "GGGGGGGGGGGGGGGG",
      "GaaaaaaaaaaaaaaG",
      "GaaaaaaaaaaaaaaG",
      "GaaaaaaaaaaaaaaG",
      "GaaaaaaaaaaaaaaG",
      "GaaaaaaaaaaaaaaG",
      "GaaaaaaaaaaaaaaG",
      "GaaaaaaaaaaaaaaG",
      "GaaaaaaaaaaaaaaG",
      "GaaaaaaaaaaaaaaG",
      "GaaaaaaaaaaaaaaG",
      "GaaaaaaaaaaaaaaG",
      "GaaaaaaaaaaaaaaG",
      "GaaaaaaaaaaaaaaG",
      "GaaaaaaaaaaaaaaG",
      "GGGGGGGGGGGGGGGG"
    ],
    [
      "                ",
      " bbccccccccccbb ",
      " d efgbhib jj d ",
      " d   gb  bkllmd ",
      " d   nbbobkllmd ",
      " bp   b   kllmd ",
      " qr        ss d ",
      " tu   w       d ",
      " xu        yApd ",
      " qr      bbbbbb ",
      " dp      B   C  ",
      " d DDDD  E  FC  ",
      " d I ID  b  rC  ",
      " d      pbJJCC  ",
      " dddddddKb      ",
      "                "
    ],
    [
      "                ",
      " bbbbbbbbbbbbbb ",
      " d   gb  b    d ",
      " d    b  b    d ",
      " d    bbLb    d ",
      " bp   b       d ",
      " qr           d ",
      " M            d ",
      " N           pd ",
      " qr      bbbbbb ",
      " dp      O   P  ",
      " d   Q   R   J  ",
      " d       b SFC  ",
      " d      pbCCCC  ",
      " dddddddKb      ",
      "                "
    ],
    [
      "                ",
      " bbddbbddbbddbb ",
      " d    b  b    d ",
      " d    b  b    d ",
      " d    bbTb    d ",
      " b    b       d ",
      " qr           d ",
      " U            d ",
      " U            d ",
      " qr      bbbbbb ",
      " d       V   C  ",
      " d       V   C  ",
      " d       brW C  ",
      " d       bCCXY  ",
      " dddddddKb      ",
      "                "
    ],
    [
      "                ",
      " bbccbbccbbccbb ",
      " K    b  b    K ",
      " K    b  b    K ",
      " K    bbbb    K ",
      " b    b  b    K ",
      " qr      b    K ",
      "  r      b    K ",
      "  r      b    K ",
      " qr      bbbbbb ",
      " K       b   X  ",
      " K       bZ  X  ",
      " K       bW  X  ",
      " K       b0JJC  ",
      " qKKKKKKKb      ",
      "                "
    ],
    [
      "                ",
      " bbbbbbbbbbbbbb ",
      " bCCCCb11bCCCCb ",
      " bCCCCb11bCCCCb ",
      " bCCCCbbbbCCCCb ",
      " bCCCCbCCbCCCCb ",
      " bCCCCCCCbCCCCb ",
      " bCCC!2CCbCCCCb ",
      " bCCCw3CCbCCCCb ",
      " bCCCCCCCbbbbbb ",
      " bCCCCCCCbr  C  ",
      " bCCCCCCCb4  C  ",
      " bCCCCCCCb   C  ",
      " bCCCCCCCbCCCC  ",
      " bbbbbbbbb      ",
      "                "
    ]
  ]
}