{
  "name": "building_apartment1_top_90",
  "refpalette": "c70cities:building_apartment1_top_palette_90",
  "xsize": 16,
  "zsize": 16,
  "slices": [
    [
      "                ",
      " aaaaaaaaa      ",
      " abbbbbbbbbeeh  ",
      " abccccccc   g  ",
      " abccccccc   f  ",
      " abcccccccd  b  ",
      " abccccccccccba ",
      " abccccccccccba ",
      " abccccccccccba ",
      " abccccccccccba ",
      " abccccccccccba ",
      " abccccccccccba ",
      " abccccccccccba ",
      " abbbbbbbbbbbba ",
      " aaaaaaaaaaaaaa ",
      "                "
    ],
    [
      "                ",
      "                ",
      "  mlbbiipbbbbb  ",
      "  j      q   b  ",
      "  i      q   i  ",
      "  i      r   i  ",
      "  b      qqqqb  ",
      "  l      nttnw  ",
      "  kn      n  l  ",
      "  boooon     l  ",
      "  b   ooooouob  ",
      "  j   o!  nonb  ",
      "  in no    o b  ",
      "  iiibbmllsbbb  ",
      "                ",
      "                "
    ],
    [
      "                ",
      "                ",
      "  bbbbbbbbgibb  ",
      "  b      q   b  ",
      "  b      q   b  ",
      "  b      x   b  ",
      "  b      qqqqb  ",
      "  b       yy b  ",
      "  b          b  ",
      "  i          b  ",
      "  i          j  ",
      "  i          i  ",
      "  b          i  ",
      "  bbbbbbbbbllb  ",
      "                ",
      "                "
    ],
    [
      "                ",
      "                ",
      "  blllsbbbbbbb  ",
      "  b      AAAAb  ",
      "  b      AAAAb  ",
      "  l      AAAAb  ",
      "  l      AAAAb  ",
      "  k        n l  ",
      "  b          l  ",
      "  b          b  ",
      "  b          b  ",
      "  b          b  ",
      "  b          b  ",
      "  bbblllbbbbbb  ",
      "                ",
      "                "
    ],
    [
      "                ",
      "                ",
      "                ",
      "                ",
      "                ",
      "                ",
      "                ",
      "                ",
      "                ",
      "                ",
      "                ",
      "                ",
      "                ",
      "                ",
      "                ",
      "                "
    ],
    [
      "                ",
      "                ",
      "                ",
      "                ",
      "                ",
      "                ",
      "                ",
      "                ",
      "                ",
      "                ",
      "                ",
      "                ",
      "                ",
      "                ",
      "                ",
      "                "
    ]
  ]
}