{
  "name": "building_carservice1_ground_90",
  "refpalette": "c70cities:building_carservice1_ground_palette_90",
  "xsize": 16,
  "zsize": 16,
  "slices": [
    [
      "GGHHHHGGGGGGGGGG",
      "GGHHHHeeeeeeGGGG",
      "Gavv==affffffGGG",
      "GvvvddefffffffGG",
      "GvvvddefffffffeG",
      "GvvvccefffffffeG",
      "GavvbbafffffffaG",
      "Gvvv  effffff!eG",
      "Gvvv  effff ffeG",
      "Gvvv  efff fffeG",
      "Gavv  aff kmffaG",
      "Gvvv  effhjlffeG",
      "Gvvv  effgi ffeG",
      "Gvvv  effffff!eG",
      "GavvvvaeeeeeeeaG",
      "GGGGGGGGGGGGGGGG"
    ],
    [
      "                ",
      "      eeeeee    ",
      " ann  auyyAww   ",
      "  HH        ww  ",
      "   o         we ",
      "   o         De ",
      " a o  at     pa ",
      "   o  e      Ae ",
      "   o  e x    Be ",
      "   o  e      Be ",
      " a o  as     Ca ",
      "   o  er     Be ",
      "   o  eq     Be ",
      "   o  ep     Ae ",
      " a oooaewwwwwea ",
      "                "
    ],
    [
      "                ",
      "      ewwwee    ",
      " a    a   Aww   ",
      "            ww  ",
      "  nn         we ",
      "  HH         De ",
      " aEFFFa       a ",
      "      e      Ae ",
      "      e       e ",
      "      e       e ",
      " a    a       a ",
      "      eJ      e ",
      "      eI      e ",
      "      e      Ae ",
      " aEFFFaewwwwwea ",
      "                "
    ],
    [
      "                ",
      "      eeeeee    ",
      " a    a    ww   ",
      "      K     ww  ",
      "      K      we ",
      "      K      De ",
      " ann  a       a ",
      "  HH  e       e ",
      "      e       e ",
      "      e       e ",
      " a    a       a ",
      "      e       e ",
      "      e       e ",
      "      e       e ",
      " a    aewwwwwea ",
      "                "
    ],
    [
      "                ",
      "      eeeeee    ",
      " aEFFFa    ww   ",
      " F    e     ww  ",
      " F    e      we ",
      " F    e      De ",
      " a    a       a ",
      " F    e       e ",
      " Fnn  e       e ",
      " FHH  e       e ",
      " aEFFFa       a ",
      "      e       e ",
      "      e       e ",
      "      e       e ",
      " a    aeLLLLLea ",
      "                "
    ],
    [
      "                ",
      "      eeeeee    ",
      " a    a    ww   ",
      "      e  F  ww  ",
      "      e  FF  we ",
      "      e  FFF De ",
      " a    a  FFFF a ",
      "      e  FFFFFe ",
      "      e  FFFFFe ",
      "      e  FFFFFe ",
      " annMaa  FFFFFa ",
      "  HH  e  FFFFFe ",
      "      e  FFFFFe ",
      "      e  FFFFFe ",
      " a    aeeeeeeea ",
      "                "
    ]
  ]
}