{
  "name": "building_apartment1_floor1_180",
  "refpalette": "c70cities:building_apartment1_floor1_palette_180",
  "xsize": 16,
  "zsize": 16,
  "slices": [
    [
      "                ",
      "      aaaaaaaaa ",
      "  ihgdbbbbbbbba ",
      "  ef  bbbbbbbba ",
      "  ebb bbbbbbbba ",
      "  dbbcbbbbbbbba ",
      " abbbbbbbbbbbba ",
      " abbbbbbbbbbbba ",
      " abbbbbbbbbbbba ",
      " abbbbbbbbbbbba ",
      " abbbbbbbbbbbba ",
      " abbbbbbbbbbbba ",
      " abbbbbbbbbbbba ",
      " abbbbbbbbbbbba ",
      " aaaaaaaaaaaaaa ",
      "                "
    ],
    [
      "                ",
      "      00000000Z ",
      "  ddYYp!     Xm ",
      "  dW  pV R   Um ",
      "  dT  pS R   Qm ",
      "  d   p     POm ",
      " spNpppMML Ippm ",
      " s  K      K  m ",
      " sJJp      IqFm ",
      " sppppppypEpppm ",
      " sDC     p DC m ",
      " sB Axxyxp    m ",
      " s  tpw  u tt m ",
      " sr op  qp oonm ",
      " lkkkkkkkkkkkkj ",
      "                "
    ],
    [
      "                ",
      "      p@11111@8 ",
      "  ddddp      (@ ",
      "  dT* p^     &@ ",
      "  Y   p^      @ ",
      "  h   p     % @ ",
      " pp$ppp    Ipp8 ",
      " p  #      #  @ ",
      " p  p      I  @ ",
      " ppppppp5p9ppp8 ",
      " p7      p    p ",
      " 1  6xx5xp    1 ",
      " 1  tp   4    1 ",
      " 1  op3  p   21 ",
      " pppppppppppppp ",
      "                "
    ],
    [
      "                ",
      "      p@11111@8 ",
      "  ,'ddp ;;:`` 1 ",
      "  d |Wp\\      1 ",
      "  d   p\\      1 ",
      "  d   p       @ ",
      " pppppp    Ipp8 ",
      " 1  p      I  1 ",
      " 1  p      I  1 ",
      " ppppppppppppp8 ",
      " p       p    p ",
      " 1}  xxxxp   {1 ",
      " 1]  p   p   [1 ",
      " 1-  p+  p   )1 ",
      " pp11pp11pp11pp ",
      "                "
    ],
    [
      "                ",
      "      p@@@@@@@8 ",
      "  dYYep       @ ",
      "  '  |p       @ ",
      "  '  .p       @ ",
      "  '   p       @ ",
      " pppppp    Ipp8 ",
      " @ fp      I  @ ",
      " @  p      I  @ ",
      " ppppppppppppp8 ",
      " p       p    p ",
      " @   xxxxp    @ ",
      " @   p   p    @ ",
      " @   p   p    @ ",
      " ppkkppkkppkkpp ",
      "                "
    ],
    [
      "                ",
      "      ppppppppp ",
      "  ddddpdddddddp ",
      "  d   pdddddddp ",
      "  d  cpdddddddp ",
      "  d  Wpdddddddp ",
      " ppppppdddddddp ",
      " pddpddddddd//p ",
      " pddpddddddd//p ",
      " pppppppppppppp ",
      " pdddddddpddddp ",
      " pdddddddpddddp ",
      " pdddd///pddddp ",
      " pdddd///pddddp ",
      " pppppppppppppp ",
      "                "
    ]
  ]
}