{
  "name": "building_carservice1_floor2_180",
  "refpalette": "c70cities:building_carservice1_floor2_palette_180",
  "xsize": 16,
  "zsize": 16,
  "slices": [
    [
      "                ",
      "    eeaeeeaeeea ",
      "   ddif   gggfe ",
      "  ddcff   ghgfe ",
      " edcfff   ghgfe ",
      " ecffff ! gggfe ",
      " effffffffffffe ",
      " effffffffffffe ",
      " ecccccccccccce ",
      " eadddadddaccca ",
      "         Hbbbb  ",
      "         Hbbbb  ",
      "            bb  ",
      "            bb  ",
      "  a   a   a   a ",
      "                "
    ],
    [
      "                ",
      "    eeaeeeaeeea ",
      "   rri y ywxw e ",
      "  rr       A  r ",
      " er        A  r ",
      " e     y ywxwur ",
      " et           r ",
      " es           r ",
      " eqpoonmml    e ",
      " eaeeeaeeea   a ",
      "      kHb     k ",
      "      jHb     j ",
      "      j       j ",
      "      j       j ",
      "  a   ajjjajjja ",
      "                "
    ],
    [
      "                ",
      "    eeaeeeaeeea ",
      "   rriFEEE I Fe ",
      "  rr   EbED D r ",
      " er    EbED D r ",
      " e     EEE D  r ",
      " r            r ",
      " r            r ",
      " r C          e ",
      " eaeeeaeeea   a ",
      "     Hb         ",
      "     Hb         ",
      "      B         ",
      "      a         ",
      "  a   a   a   a ",
      "                "
    ],
    [
      "                ",
      "    eeaeeeaeeea ",
      "   rri        e ",
      "  rr          r ",
      " er           r ",
      " e            r ",
      " e            r ",
      " e  MM        r ",
      " e  LK        e ",
      " eaeeeaeeeaJJJa ",
      "   bb           ",
      "   bb           ",
      "   bbbbH        ",
      "   bbbbH        ",
      "  a   a   a   a ",
      "                "
    ],
    [
      "                ",
      "    eeaeeeaeeea ",
      "   rri        e ",
      "  rr          N ",
      " er           N ",
      " e            N ",
      " e            N ",
      " e            N ",
      " e            e ",
      " eaeeeaeeeaeeea ",
      "  j       j     ",
      "  j       j     ",
      "  j     bHj     ",
      "  k     bHk     ",
      "  ajjjajjja   a ",
      "                "
    ],
    [
      "                ",
      "    eeaeeeaeeea ",
      "   rri jjjjjjje ",
      "  rr  jjjjjjjje ",
      " er  jjjjjjjjje ",
      " e  jjjjjjjjjje ",
      " e jjjjjjjjjjje ",
      " e            e ",
      " e            e ",
      " eaeeeaeeeaeeea ",
      "          a     ",
      "          B     ",
      "          bH    ",
      "          bH    ",
      "  a   a   a   a ",
      "                "
    ]
  ]
}