{
  "name": "building_office3_floor3_180",
  "refpalette": "c70cities:building_office3_floor3_palette_180",
  "xsize": 16,
  "zsize": 16,
  "slices": [
    [
      "                ",
      " aabaabaabaabaa ",
      " acccccccccccca ",
      " bccccccccccccb ",
      " acccccccccccca ",
      " acccccccccccca ",
      " bccccccccccccb ",
      " acccccdvccccca ",
      " acccccdvccccca ",
      " bccccccccccccb ",
      " acccccccccccca ",
      " acccccccc!ccca ",
      " bccccccccccccb ",
      " acccccccccccca ",
      " aabaabaabaabaa ",
      "                "
    ],
    [
      "                ",
      " eebeebeebeebee ",
      " e            e ",
      " b f   gggg f b ",
      " e     ghhg   e ",
      " e  k         e ",
      " b ji         b ",
      " e  i  dv     e ",
      " e  i  dv     e ",
      " b ji         b ",
      " e  i         e ",
      " e     ghhg   e ",
      " b f   gggg f b ",
      " e            e ",
      " eebeebeebeebee ",
      "                "
    ],
    [
      "                ",
      " llbllbllbllbll ",
      " l            l ",
      " b f        f b ",
      " l            l ",
      " l            l ",
      " b            b ",
      " l     dv     l ",
      " l     dv     l ",
      " b            b ",
      " l            l ",
      " l            l ",
      " b f        f b ",
      " l            l ",
      " llbllbllbllbll ",
      "                "
    ],
    [
      "                ",
      " llbllbllbllbll ",
      " l            l ",
      " b f        f b ",
      " l            l ",
      " l            l ",
      " b            b ",
      " l     dv     l ",
      " l     dv     l ",
      " b            b ",
      " l            l ",
      " l            l ",
      " b f        f b ",
      " l            l ",
      " llbllbllbllbll ",
      "                "
    ],
    [
      "                ",
      " llbllbllbllbll ",
      " l            l ",
      " b f        f b ",
      " l            l ",
      " l            l ",
      " b            b ",
      " l     dv     l ",
      " l     dv     l ",
      " b            b ",
      " l            l ",
      " l            l ",
      " b f        f b ",
      " l            l ",
      " llbllbllbllbll ",
      "                "
    ],
    [
      "                ",
      " llbllbllbllbll ",
      " lmmmmmmmmmmmml ",
      " bmfnnnnnnnnfmb ",
      " lmnnnnnnnnnnml ",
      " lmnnnnnnnnnnml ",
      " bmnnnnnnnnnnmb ",
      " lmnnnndvnnnnml ",
      " lmnnnndvnnnnml ",
      " bmnnnnnnnnnnmb ",
      " lmnnnnnnnnnnml ",
      " lmnnnnnnnnnnml ",
      " bmfnnnnnnnnfmb ",
      " lmmmmmmmmmmmml ",
      " llbllbllbllbll ",
      "                "
    ]
  ]
}