{
  "name": "building_office1_floor1_270",
  "refpalette": "c70cities:building_office1_floor1_palette_270",
  "xsize": 16,
  "zsize": 16,
  "slices": [
    [
      "                ",
      " eeee  c        ",
      " ebbfddcaaaaaa  ",
      " ebbgbbbbbbbba  ",
      " ebbbbbbbbbbba  ",
      " ebbbbbbbbbbba  ",
      " ebbbbbbbbbbba  ",
      " ebbbbbbbbbbba  ",
      " ebbbbbbbbbbba  ",
      " ebbbbbbbbbbba  ",
      " eb!bbbbbbbbba  ",
      " ebbbbbbbbbbba  ",
      " ebbbbbbbbbbba  ",
      " ebbfddcaaaaaa  ",
      " eeee  c        ",
      "                "
    ],
    [
      "                ",
      " ssss  c        ",
      " swwfddchhhhhh  ",
      " s  g  f     h  ",
      " s     o  j  h  ",
      " s     p   i h  ",
      " sBxt qf mk  h  ",
      " sfffrff   i h  ",
      " s yu  f m   h  ",
      " sCy   f  ki h  ",
      " s yu  f m   h  ",
      " s     f  l  h  ",
      " s     fn    h  ",
      " sDAfddchhhhhh  ",
      " ssss  c        ",
      "                "
    ],
    [
      "                ",
      " ssss  c        ",
      " swwfddchhhhhh  ",
      " P  g  f     h  ",
      " d     I     h  ",
      " d     J  E  h  ",
      " d    qf  E  h  ",
      " dfffKff  E  h  ",
      " d L   f  E  h  ",
      " d M   f  E  h  ",
      " d N   f  E  h  ",
      " d     f     h  ",
      " P     fF    h  ",
      " s Ofddchhhhhh  ",
      " ssss  c        ",
      "                "
    ],
    [
      "                ",
      " ssss  c        ",
      " swwfddchhhhhh  ",
      " P  g  f     h  ",
      " d     f     h  ",
      " d     f     h  ",
      " d     f     h  ",
      " dffffff     h  ",
      " d     f     h  ",
      " d     f     h  ",
      " d     f     h  ",
      " d     f     h  ",
      " P     f     h  ",
      " s  fddchhhhhh  ",
      " ssss  c        ",
      "                "
    ],
    [
      "                ",
      " ssss  c        ",
      " sQQfddchhhhhh  ",
      " s  g  f     h  ",
      " s     f     h  ",
      " s     f     h  ",
      " s     f     h  ",
      " sffffff     h  ",
      " s     f     h  ",
      " s     f     h  ",
      " s     f     h  ",
      " s     f     h  ",
      " s     f     h  ",
      " s  fddchhhhhh  ",
      " ssss  c        ",
      "                "
    ],
    [
      "                ",
      " ssss  c        ",
      " sPPfddchhhhhh  ",
      " sPPg  fPPPPPh  ",
      " sPPPPPfPPPPPh  ",
      " sPPPPPfPPPPPh  ",
      " sPPPPPfPPPPPh  ",
      " sffffffPPPPPh  ",
      " sPPPPPfPPPPPh  ",
      " sPPPPPfPPPPPh  ",
      " sPPPPPfPPPPPh  ",
      " sPPPPPfPPPPPh  ",
      " sPP   fPPPPPh  ",
      " sPPfddchhhhhh  ",
      " ssss  c        ",
      "                "
    ]
  ]
}