{
  "name": "building_office3_floor3_270",
  "refpalette": "c70cities:building_office3_floor3_palette_270",
  "xsize": 16,
  "zsize": 16,
  "slices": [
    [
      "                ",
      " aabaabaabaabaa ",
      " acccccccccccca ",
      " bccccccccccccb ",
      " acccccccccccca ",
      " accccccccc!cca ",
      " bccccccccccccb ",
      " acccccvvccccca ",
      " acccccddccccca ",
      " bccccccccccccb ",
      " acccccccccccca ",
      " acccccccccccca ",
      " bccccccccccccb ",
      " acccccccccccca ",
      " aabaabaabaabaa ",
      "                "
    ],
    [
      "                ",
      " eebeebeebeebee ",
      " e            e ",
      " b f        f b ",
      " e            e ",
      " e gg      gg e ",
      " b gh   k  hg b ",
      " e gh  vv  hg e ",
      " e gg  dd  gg e ",
      " b            b ",
      " e            e ",
      " e   liiiii   e ",
      " b f  j  j  f b ",
      " e            e ",
      " eebeebeebeebee ",
      "                "
    ],
    [
      "                ",
      " mmbmmbmmbmmbmm ",
      " m            m ",
      " b f        f b ",
      " m            m ",
      " m            m ",
      " b            b ",
      " m     vv     m ",
      " m     dd     m ",
      " b            b ",
      " m            m ",
      " m            m ",
      " b f        f b ",
      " m            m ",
      " mmbmmbmmbmmbmm ",
      "                "
    ],
    [
      "                ",
      " mmbmmbmmbmmbmm ",
      " m            m ",
      " b f        f b ",
      " m            m ",
      " m            m ",
      " b            b ",
      " m     vv     m ",
      " m     dd     m ",
      " b            b ",
      " m            m ",
      " m            m ",
      " b f        f b ",
      " m            m ",
      " mmbmmbmmbmmbmm ",
      "                "
    ],
    [
      "                ",
      " mmbmmbmmbmmbmm ",
      " m            m ",
      " b f        f b ",
      " m            m ",
      " m            m ",
      " b            b ",
      " m     vv     m ",
      " m     dd     m ",
      " b            b ",
      " m            m ",
      " m            m ",
      " b f        f b ",
      " m            m ",
      " mmbmmbmmbmmbmm ",
      "                "
    ],
    [
      "                ",
      " mmbmmbmmbmmbmm ",
      " mnnnnnnnnnnnnm ",
      " bnfoooooooofnb ",
      " mnoooooooooonm ",
      " mnoooooooooonm ",
      " bnoooooooooonb ",
      " mnoooovvoooonm ",
      " mnooooddoooonm ",
      " bnoooooooooonb ",
      " mnoooooooooonm ",
      " mnoooooooooonm ",
      " bnfoooooooofnb ",
      " mnnnnnnnnnnnnm ",
      " mmbmmbmmbmmbmm ",
      "                "
    ]
  ]
}