{
  "name": "building_office1_floor2",
  "refpalette": "c70cities:building_office1_floor2_palette",
  "xsize": 16,
  "zsize": 16,
  "slices": [
    [
      "                ",
      "                ",
      "  aaaaaaaaaaaa  ",
      "  abbbbbbbbbba  ",
      "  abbbbbbbbbba  ",
      "  abbbbbbbbbba  ",
      "  abbbbbbbbbba  ",
      "  abbbbbbbbbba  ",
      " ccbbbbbbbbbbcc ",
      "  dbbbbbbb!bbd  ",
      "  dbbbbbbbbbbd  ",
      " efgbbbbbbbbbfe ",
      " ebbbbbbbbbbbbe ",
      " ebbbbbbbbbbbbe ",
      " eeeeeeeeeeeeee ",
      "                "
    ],
    [
      "                ",
      "                ",
      "  hhhhhhhhhhhh  ",
      "  h          h  ",
      "  h i    i   h  ",
      "  h jjj  jjj h  ",
      "  h   k    k h  ",
      "  h          h  ",
      " cc i    i   cc ",
      "  d jjj  jjj d  ",
      "  d   k    k d  ",
      " lfg         fl ",
      " lm          nl ",
      " lm          nl ",
      " llllllllllllll ",
      "                "
    ],
    [
      "                ",
      "                ",
      "  hhhhhhhhhhhh  ",
      "  h          h  ",
      "  h          h  ",
      "  h opo  opo h  ",
      "  h          h  ",
      "  h          h  ",
      " cc          cc ",
      "  d opo  opo d  ",
      "  d          d  ",
      " lfg         fl ",
      " l            l ",
      " l           ql ",
      " llrddddddddrll ",
      "                "
    ],
    [
      "                ",
      "                ",
      "  hhhhhhhhhhhh  ",
      "  h          h  ",
      "  h          h  ",
      "  h          h  ",
      "  h          h  ",
      "  h          h  ",
      " cc          cc ",
      "  d          d  ",
      "  d          d  ",
      " lfg         fl ",
      " ls           l ",
      " ls           l ",
      " llrddddddddrll ",
      "                "
    ],
    [
      "                ",
      "                ",
      "  hhhhhhhhhhhh  ",
      "  h          h  ",
      "  h          h  ",
      "  h          h  ",
      "  h          h  ",
      "  h          h  ",
      " cc          cc ",
      "  d          d  ",
      "  d          d  ",
      " lfg         fl ",
      " l            l ",
      " l            l ",
      " llllllllllllll ",
      "                "
    ],
    [
      "                ",
      "                ",
      "  hhhhhhhhhhhh  ",
      "  hrrrrrrrrrrh  ",
      "  hrrrrrrrrrrh  ",
      "  hrrrrrrrrrrh  ",
      "  hrrrrrrrrrrh  ",
      "  hrrrrrrrrrrh  ",
      " ccrrrrrrrrrrcc ",
      "  d rrrrrrrr d  ",
      "  d rrrrrrrr d  ",
      " lfgrrrrrrrr fl ",
      " lrrrrrrrrrrrrl ",
      " lrrrrrrrrrrrrl ",
      " llllllllllllll ",
      "                "
    ]
  ]
}