{
  "name": "building_hotel2_base1_180",
  "refpalette": "c70cities:building_hotel2_base1_palette_180",
  "xsize": 16,
  "zsize": 16,
  "slices": [
    [
      "vvvvvvvvvvvvvvvv",
      "vaaaaaaaaaaaaaav",
      "va!bbbb!bbbbb!av",
      "vabbbbbbbbbbbbav",
      "vabbbbbbbbbbbbav",
      "vabbbbbbbbbbbbav",
      "vabbbbbbbbbbbbav",
      "vabbbbbbbbbbbbav",
      "vabbbbbbbbbbbbav",
      "vabbbbbbbbbbbbav",
      "vabbbbbbbbbbbbav",
      "vabbbbbbbbbbbbav",
      "vabbbbbbbbbbbbav",
      "vabbbbbbbbbbbbav",
      "vaaaaaaaaaaaaaav",
      "vvvvvvvvvvvvvvvv"
    ],
    [
      "vvvvvvvvvvvvvvvv",
      "vccccccccccccccv",
      "vco  mf       fv",
      "vcl  nfi i i ifv",
      "vcl  mfe  e  efv",
      "vcl  kfg g g gfv",
      "vcf  ff       fv",
      "vcj      i i ifv",
      "vc=hhh    e  efv",
      "vcbbb=   g g gfv",
      "vcbbb=e       fv",
      "vcbbb=      e==v",
      "vcbbb=e      dcv",
      "vcbbb=       dcv",
      "vccccccccccccccv",
      "vvvvvvvvvvvvvvvv"
    ],
    [
      "vvvvvvvvvvvvvvvv",
      "vccccccccccccccv",
      "vc   xf       fv",
      "vc   wf       fv",
      "vc    fj jjj jfv",
      "vc   uf       fv",
      "vcf  ff       fv",
      "vcj           fv",
      "vc=      jjj jfv",
      "vcp  r        fv",
      "vcpt rq       fv",
      "vcp  r      s==v",
      "vcp  rq      dcv",
      "vcpoo=       dcv",
      "vccccccccccccccv",
      "vvvvvvvvvvvvvvvv"
    ],
    [
      "vvvvvvvvvvvvvvvv",
      "vccccccccccccccv",
      "vc    f       fv",
      "vcA   f       fv",
      "vcB   f       fv",
      "vcA   f       fv",
      "vcf  ff       fv",
      "vcj           fv",
      "vc=           fv",
      "vct           fv",
      "vct           fv",
      "vc          s==v",
      "vct          dcv",
      "vct  y       dcv",
      "vccccccccccccccv",
      "vvvvvvvvvvvvvvvv"
    ],
    [
      "vvvvvvvvvvvvvvvv",
      "vccccccccccccccv",
      "vc    f       fv",
      "vc    f       fv",
      "vcB   f       fv",
      "vc    f       fv",
      "vcfffff       fv",
      "vcj           fv",
      "vc=           fv",
      "vct           fv",
      "vc            fv",
      "vct          ==v",
      "vct          dcv",
      "vct          dcv",
      "vccccccccccccccv",
      "vvvvvvvvvvvvvvvv"
    ],
    [
      "vvvvvvvvvvvvvvvv",
      "vccccccccccccccv",
      "vcCCCCfCCCCCCCCv",
      "vcCCCCfCCCCCCCCv",
      "vcCCCCfCCCCCCCCv",
      "vcCCCCfCCCCCCCCv",
      "vcfffffCCCCCCCCv",
      "vcCCCCCCCCCCCCCv",
      "vc=CCCCCCCCCCCCv",
      "vcECCCCCCCCCCCCv",
      "vcDCCCCCCCCCCCCv",
      "vcDCCCCCCCCCC==v",
      "vcECCCCCCCCCCdcv",
      "vcDCCCCCCCCCCdcv",
      "vccccccccccccccv",
      "vvvvvvvvvvvvvvvv"
    ]
  ]
}