{
  "name": "building_residential4_ground_270",
  "refpalette": "c70cities:building_residential4_ground_palette_270",
  "xsize": 16,
  "zsize": 16,
  "slices": [
    [
      "GGGGGGGGGGGGGGGG",
      "GGGGGGGGGGGGGGGG",
      "GGaaaaaaaaaaaaGG",
      "GGabbbbbbbbbbaGG",
      "GGabbbbbbbbbbaGG",
      "GGabbbbbbbbbbaGG",
      "GGabbbbbbbbbbaGG",
      "GGabbbbbbbbbbaGG",
      "GGabbbbbbbbbbaGG",
      "GGaccccccccccaGG",
      "GGaccccccccccaGG",
      "GGaccccccccccaGG",
      "GGaddddddddddaGG",
      "GGaGGGGGGGGGGaGG",
      "GGGGGGGGGGGGGGGG",
      "GGGGGGGGGGGGGGGG"
    ],
    [
      "efffffe  ueffffe",
      "f              f",
      "f hjjjhByhjjjh f",
      "f hJE     rp h f",
      "f O          i f",
      "g O       qq i g",
      "f hK    wwkkkh f",
      "f O          i f",
      "f O        lli f",
      "f hLFD    smmh f",
      "g OM D       i g",
      "f ONIDxCAxtnni f",
      "f hddddddddddh f",
      "f hooooooooooh f",
      "f              f",
      "effffgffffgffffe"
    ],
    [
      "efffffe   effffe",
      "f              f",
      "f hPPPhWUhPPPh f",
      "f h          h f",
      "f P0         P f",
      "g PK      RR P g",
      "f h     wwQQQh f",
      "f P          P f",
      "f P          P f",
      "f hLZD     S h f",
      "g 1  D       P g",
      "f 1  DYX  T  P f",
      "f hddddVVddddh f",
      "f h          h f",
      "f              f",
      "effffgffffgffffe"
    ],
    [
      "                ",
      "                ",
      "  hPPPhPPhPPPh  ",
      "  h          h  ",
      "  h 3        h  ",
      "  h          h  ",
      "  h     wwQQQh  ",
      "  h          h  ",
      "  h          h  ",
      "  hLLD       h  ",
      "  h  D       h  ",
      "  h  D       h  ",
      "  hddddVVddddh  ",
      "  h2222222222h  ",
      "                ",
      "                "
    ],
    [
      "                ",
      " 6i          O4 ",
      " 6hhhhhhhhhhhh4 ",
      " 6hbbbbbbbbbbh4 ",
      " 6h  3bbbbbbbh4 ",
      " 6h   bbbbbbbh4 ",
      " 6h   bbbbbbbh4 ",
      " 6hbbbbbbbbbbh4 ",
      " 6hbbbbbbbbbbh4 ",
      " 6hbbbbbbbbbbh4 ",
      " 6hbbbbbbbbbbh4 ",
      " 6hbbbbbbbbbbh4 ",
      " 6hddddddddddh4 ",
      " 6h5555  5555h4 ",
      " 6i          O4 ",
      "                "
    ],
    [
      "                ",
      "  6i        O4  ",
      "  65555($55554  ",
      "  6dddddddddd4  ",
      "  6     %775h4  ",
      "  6   + 9885h4  ",
      "  6]]]+ 9995h4  ",
      "  6   -    5h4  ",
      "  6!  [ ^  5h4  ",
      "  6\\  [ @@@5h4  ",
      "  6\\  [ @@@5h4  ",
      "  6 }{[ &# 5h4  ",
      "  6dddddddddd4  ",
      "  65555)*55554  ",
      "  6i        O4  ",
      "                "
    ]
  ]
}