{
  "name": "building_bunker1_base1_90",
  "refpalette": "c70cities:building_bunker1_base1_palette_90",
  "xsize": 16,
  "zsize": 16,
  "slices": [
    [
      "================",
      "================",
      "==aaaa==========",
      "==aaaa==========",
      "==aaaa==========",
      "==aaaa==========",
      "==aaaa====aaaaa=",
      "==aaaa====aaaaa=",
      "===========a=a==",
      "==========aa=aa=",
      "==========aa=aa=",
      "==========aa=aa=",
      "================",
      "================",
      "================",
      "================"
    ],
    [
      "zzzzzzzzzzzzzzzz",
      "zbbbbbbbbbbbbbbb",
      "zbiknquyDIMIbSXb",
      "zbh  r y   Qb Wb",
      "zbg  q     Pb Vb",
      "zbe     CbbbbRbb",
      "zbf      F    Ub",
      "zbe  pt nbn   Ub",
      "zbbbmbbxbEbObObb",
      "zbd  b   bL b Tb",
      "zbd  bs  bK b Kb",
      "zbd  bswobJNbNJb",
      "zbb  bbbbbbbbbbb",
      "zbc     Bbzzzzzz",
      "zbcjlo sAbzzzzzz",
      "zbbbbbbbbbzzzzzz"
    ],
    [
      "zzzzzzzzzzzzzzzz",
      "zZ44EEEEEEEEE{{E",
      "zY  69   ^ +E :E",
      "zY   8     )E]`E",
      "zY         (E]|E",
      "zE3      EEEE[EE",
      "zE2      %     ;",
      "zEL  7  6E6   TE",
      "zEEE5EE#EEE*E*EE",
      "zE   E   EL E TE",
      "zE   E   E1 E \\E",
      "zE   Esw E0&E-}E",
      "zEE  EEEEEEEEEEE",
      "zE1     $Ezzzzzz",
      "zE0 o  @AEzzzzzz",
      "zEEEEEEEEEzzzzzz"
    ],
    [
      "zzzzzzzzzzzzzzzz",
      "zEEEEEEEEEEEEEEE",
      "zE, 6    ..\u00a3E \u00c1E",
      "zE,        ?E\u00a5\u00c0E",
      "zE,        >E\u00a4 E",
      "zE,      EEEEEEE",
      "zE,      E    \u00a7E",
      "zE,     6E6   \u00a7E",
      "zEEEEEE{EEEEEEEE",
      "zE'  E   E <E< E",
      "zE'  E   E/ E  E",
      "zE'  E w Ef E fE",
      "zEE  EEEEEEEEEEE",
      "zE1     !Ezzzzzz",
      "zE0     AEzzzzzz",
      "zEEEEEEEEEzzzzzz"
    ],
    [
      "zzzzzzzzzzzzzzzz",
      "zEEEEEEEEEEEEEEE",
      "zE\u00c4\u00c2\u00c2\u00c2\u00c2\u00c2\u00c2EEEE\u00c4\u00c4E",
      "zE\u00c4\u00c2\u00c2\u00c2\u00c2\u00c2\u00c2\u00c4\u00c4\u00c4E\u00c2\u00c2E",
      "zE\u00c4\u00c2\u00c2\u00c2\u00c2\u00c2\u00c2EEEE\u00c2\u00c2E",
      "zE\u00c4\u00c2\u00c2\u00c2\u00c2\u00c2\u00c2EEEEEEE",
      "zE\u00c4\u00c2\u00c2\u00c2\u00c2\u00c2\u00c2E\u00c2\u00c2\u00c2\u00c2\u00c4E",
      "zE\u00c4\u00c2\u00c2\u00c2\u00c2\u00c2\u00c2E\u00c2\u00c2\u00c2\u00c2\u00c4E",
      "zEEEEEEEEEEEEEEE",
      "zE\u00c3\u00c2\u00c2EEEEE\u00c2\u00c2E\u00c2\u00c2E",
      "zE\u00c3\u00c2\u00c2EEEEE\u00c2\u00c2E\u00c2\u00c2E",
      "zE\u00c3\u00c2\u00c2EEwEE\u00c4\u00c5E\u00c5\u00c4E",
      "zEE\u00c5\u00c4EEEEEEEEEEE",
      "zE\u00c2\u00c2\u00c2\u00c4\u00c2\u00c2\u00c2Ezzzzzz",
      "zE\u00c2\u00c2\u00c2\u00c4\u00c2\u00c2AEzzzzzz",
      "zEEEEEEEEEzzzzzz"
    ],
    [
      "zzzzzzzzzzzzzzzz",
      "zzzzzzzzzzzzzzzz",
      "zzzzzzzzzzzzzzzz",
      "zzzzzzzzzzzzzzzz",
      "zzzzzzzzzzzzzzzz",
      "zzzzzzzzzzzzzzzz",
      "zzzzzzzzzzzzzzzz",
      "zzzzzzzzzzzzzzzz",
      "zzzzzzzzzzzzzzzz",
      "zzzzzzzzzzzzzzzz",
      "zzzzzzzEzzzzzzzz",
      "zzzzzzEwEzzzzzzz",
      "zzzzzzzEzzzzzzzz",
      "zzzzzzzzzzzzzzzz",
      "zzzzzzzzzzzzzzzz",
      "zzzzzzzzzzzzzzzz"
    ]
  ]
}