{
  "name": "building_bank1_base1",
  "refpalette": "c70cities:building_bank1_base1_palette",
  "xsize": 16,
  "zsize": 16,
  "slices": [
    [
      "vvvvvvvvvvvvvvvv",
      "vaabbaaaabbaaaav",
      "vab!bbbbbbbbbbav",
      "vabbbbbbbbbbbbbv",
      "vabbbbbbbbbbbbbv",
      "vbbbbbbbbbbbbbav",
      "vbbbbbbbbbbbbbav",
      "vabbbbbbbbbbbbav",
      "vabbbbbbbbbbbbav",
      "vabbbbbbbbbbbbbv",
      "vabbbbbbbbbbbbbv",
      "vbbbbbbbbbbbbbav",
      "vbbbbbbbbbbbbbav",
      "vabbbbbbbbb!bbav",
      "vaaaabbaaaabbaav",
      "vvvvvvvvvvvvvvvv"
    ],
    [
      "vvvvvvvvvvvvvvvv",
      "vaabbaaaabbaaaav",
      "va ccdeffcce gav",
      "vaf  f       cbv",
      "va           cbv",
      "vbc          fav",
      "vbc     f    fav",
      "vah          fav",
      "vad          fav",
      "vai   f      cbv",
      "vaf          cbv",
      "vbc          dav",
      "vbcj         iav",
      "va   ccffffcciav",
      "vaaaabbaaaabbaav",
      "vvvvvvvvvvvvvvvv"
    ],
    [
      "vvvvvvvvvvvvvvvv",
      "vaabbaaaabbaaaav",
      "va cce k cc   av",
      "va           cbv",
      "va           cbv",
      "vbc          hav",
      "vbc          lav",
      "vam          hav",
      "vad           av",
      "va           cbv",
      "vae          cbv",
      "vbc          dav",
      "vbcj         eav",
      "va   ccnin cciav",
      "vaaaabbaaaabbaav",
      "vvvvvvvvvvvvvvvv"
    ],
    [
      "vvvvvvvvvvvvvvvv",
      "vaabbaaaabbaaaav",
      "va cc    cc   av",
      "va           cbv",
      "va           cbv",
      "vbc           av",
      "vbc           av",
      "va            av",
      "va            av",
      "va           cbv",
      "va           cbv",
      "vbc           av",
      "vbcj          av",
      "va   cc    cc av",
      "vaaaabbaaaabbaav",
      "vvvvvvvvvvvvvvvv"
    ],
    [
      "vvvvvvvvvvvvvvvv",
      "vaabbaaaabbaaaav",
      "va cc    cc   av",
      "va           cbv",
      "va           cbv",
      "vbc           av",
      "vbc           av",
      "va            av",
      "va            av",
      "va           cbv",
      "va           cbv",
      "vbc           av",
      "vbcj          av",
      "va   cc    cc av",
      "vaaaabbaaaabbaav",
      "vvvvvvvvvvvvvvvv"
    ],
    [
      "vvvvvvvvvvvvvvvv",
      "vaabbaaaabbaaaav",
      "vagccooooccoopav",
      "vaooooooooooocbv",
      "vaooooooooooocbv",
      "vbcoooooooooooav",
      "vbcoooooooooooav",
      "vaooooooooooooav",
      "vaooooooooooooav",
      "vaooooooooooocbv",
      "vaooooooooooocbv",
      "vbcoooooooooooav",
      "vbcjooooooooooav",
      "vaqooccooooccgav",
      "vaaaabbaaaabbaav",
      "vvvvvvvvvvvvvvvv"
    ]
  ]
}