{
  "name": "building_residential2_ground_270",
  "refpalette": "c70cities:building_residential2_ground_palette_270",
  "xsize": 16,
  "zsize": 16,
  "slices": [
    [
      "GGGGGGGGGGGGGGGG",
      "GGGGGGGGGGGGGGGG",
      "GGddddddGGGGGGGG",
      "GGdcccceaaaaaGGG",
      "GGdccccebbbbaGGG",
      "GGdccccebbbbaGGG",
      "GGdccccebbbbaGGG",
      "GGdccccebbbbaGGG",
      "GGdcccceccccaGGG",
      "GGdcccceccccaGGG",
      "GGdcccceccccaGGG",
      "GGdcccceccccaGGG",
      "GGdcccceaaaaaGGG",
      "GGddddddGGGGGGGG",
      "GGGGGGGGGGGGGGGG",
      "GGGGGGGGGGGGGGGG"
    ],
    [
      "fgf  fgggghggggf",
      "g              g",
      "g sDysssiiiiii g",
      "g s     aaaaai g",
      "g s    t   jai g",
      "h s    t   kai h",
      "g s     r  lai g",
      "g sEA      mai g",
      "g s    nnnnnai g",
      "g sBB  u   oai g",
      "h sCCw u   pai h",
      "g sF w     qai g",
      "g sI x  aaaaai g",
      "g ssssssiiiiii g",
      "g              g",
      "fgggghgggghggggf"
    ],
    [
      "fgf  fgggghggggf",
      "g              g",
      "g sTQsOs       g",
      "g s     aaaaa  g",
      "g O     N  Ja  g",
      "h O     N  Ka  h",
      "g O     N   a  g",
      "g s        La  g",
      "g s    nnnnna  g",
      "g sRR   u   a  g",
      "h sCCw  u  !a  h",
      "g s  w     Ma  g",
      "g s  P  aaaaa  g",
      "g sSSsOs       g",
      "g              g",
      "fgggghgggghggggf"
    ],
    [
      "                ",
      "                ",
      "  sOOsOs        ",
      "  s     aUUaa   ",
      "  O         a   ",
      "  O         U   ",
      "  O         U   ",
      "  s         a   ",
      "  s    nnnnna   ",
      "  s      u  U   ",
      "  sCCw   u  U   ",
      "  s  w      a   ",
      "  s  w  aUUaa   ",
      "  sSSsOs        ",
      "                ",
      "                "
    ],
    [
      "                ",
      "                ",
      "  VVVVVsVVVVVV  ",
      "  VWWWW aaaaaV  ",
      "  VWWWW     aV  ",
      "  VWWWW     aV  ",
      "  VWWWW     aV  ",
      "  VWWWW     aV  ",
      "  VWWWWnnnnnaV  ",
      "  VWWWW   u aV  ",
      "  VWWWW   u aV  ",
      "  VWWWW     aV  ",
      "  VWWWW aaaaaV  ",
      "  VVVVVsVVVVVV  ",
      "                ",
      "                "
    ],
    [
      "                ",
      "                ",
      "  ssssssssssss  ",
      "  sn   ecccccs  ",
      "  sn   ecccccs  ",
      "  s   uecccccs  ",
      "  s   uecccccs  ",
      "  sn   ecccccs  ",
      "  sn 0Xecccccs  ",
      "  s    e   ucs  ",
      "  s  1Ye   ucs  ",
      "  sn   ecccccs  ",
      "  sn32Zecccccs  ",
      "  ssssssssssss  ",
      "                ",
      "                "
    ]
  ]
}