{
  "name": "building_residential3_ground_180",
  "refpalette": "c70cities:building_residential3_ground_palette_180",
  "xsize": 16,
  "zsize": 16,
  "slices": [
    [
      "GGGGGGGGGGGGGGGG",
      "GGGGGGGGGGGGGGGG",
      "GGaaaaaaGGGGGGGG",
      "GGabbbbacccccGGG",
      "GGabbbbbddddcGGG",
      "GGabbbbbddddcGGG",
      "GGabbbbbddddcGGG",
      "GGabbbbbddddcGGG",
      "GGabbbbbbbbbaaGG",
      "GGabbbbbbbbbbaGG",
      "GGabbbbbbbbbbaGG",
      "GGabbbbbbbbbbaGG",
      "GGabbbbbbbbbbaGG",
      "GGaaaaaaaaaaaaGG",
      "GGGGGGGGGGGGGGGG",
      "GGGGGGGGGGGGGGGG"
    ],
    [
      "effffgffffgffffe",
      "f              f",
      "f hiIIihxxxxxx f",
      "f h    hcccccx f",
      "f hF  yhEDCBcx f",
      "e hA  yh    cx g",
      "f h    h    cx f",
      "f hu   t   wc  f",
      "f hu   t srrhh f",
      "f h       qq i e",
      "g hopo       n  ",
      "f hm k       l  ",
      "f h  k!  j   i e",
      "f hhhhhhhhhhhh f",
      "f              f",
      "effffgffffgffffe"
    ],
    [
      "effffgffffgffffe",
      "f              f",
      "f hiIIih       f",
      "f h    hcRRcc  f",
      "f I   ShU  Tc  f",
      "e I   Sh    R  g",
      "f I    h    R  f",
      "f hQ   t    c  f",
      "f hP   t    hh f",
      "f I          i e",
      "g hoOo       N  ",
      "f JM kL      K  ",
      "f h  k  j    i e",
      "f hhJhIhhIIIhh f",
      "f              f",
      "effffgffffgffffe"
    ],
    [
      "                ",
      "                ",
      "  hi00ihZZZZZZ  ",
      "  h    hcccccZ  ",
      "  Y    h    cZ  ",
      "W Y    h    cZ  ",
      "  Y    h    cZ  ",
      "  h    t    cZ  ",
      "  h    t    hh  ",
      "  Y          i  ",
      "  hooo       X  ",
      "  Y  k       X  ",
      "  h  k j     i W",
      "  hhVhVhhVVVhh  ",
      "                ",
      "                "
    ],
    [
      "                ",
      "                ",
      "  hhhhhh111111  ",
      "  hbbbbh444431  ",
      "  hbbbbb    21  ",
      "  hbbbbb    21  ",
      "  hbbbbb    21  ",
      "  hbbbbb    21  ",
      "  hbbbbbbbbbhh  ",
      "  hbbbbbbbbbbh  ",
      "  hbbbbbbbbbbh  ",
      "  hbbbbbbbbbbh  ",
      "  hbbbj   bbbh  ",
      "  hhhhhhhhhhhh  ",
      "                ",
      "                "
    ],
    [
      "                ",
      "                ",
      "  hIIIIh111111  ",
      "  h ** hccccc1  ",
      "  Y)(* #    c1  ",
      "  Y)(* #    c1  ",
      "  Y9** #    c1  ",
      "  hiii #&   c1  ",
      "  h^%$ #####hh  ",
      "  I @     988I  ",
      "  I          I  ",
      "  I   7777   I  ",
      "  I       655I  ",
      "  hhVVVhhVVVhh  ",
      "                ",
      "                "
    ]
  ]
}