{
  "name": "building_carfactory1_floor1_270",
  "refpalette": "c70cities:building_carfactory1_floor1_palette_270",
  "xsize": 16,
  "zsize": 16,
  "slices": [
    [
      "                ",
      " acccccccccca   ",
      " kddddddddddb   ",
      " ldfg    gfdb   ",
      " ld g    g db   ",
      " kd h    h db   ",
      " kd h    i db   ",
      " kd g    g db   ",
      " kd g    g db   ",
      " kd j    h db   ",
      " kd h    h db   ",
      " kd g    gfdb   ",
      " kd g    g db   ",
      " kddddddddddb   ",
      " aeeeeeeeeeea   ",
      "                "
    ],
    [
      "                ",
      " a        nnmm  ",
      "  oooooooooomm  ",
      " lo  ff qqqpmm  ",
      " lo     qqqpmm  ",
      "  o t    srpmm  ",
      "  o t    srpmm  ",
      "  o     qqqpmm  ",
      "  o     qqqpmm  ",
      "  o t    srpmm  ",
      "  o t    srpmm  ",
      "  o !   qqqpmm  ",
      "  of    qqqpmm  ",
      "  oooooooooomm  ",
      " a        nnmm  ",
      "                "
    ],
    [
      "                ",
      " a    nnmm      ",
      "  oooooomm      ",
      " lo  qqq        ",
      " lo  qqq        ",
      "  o t rruu      ",
      "  o t rruu      ",
      "  of qqq        ",
      "  of qqq        ",
      "  o t rruu      ",
      "  o t rruu      ",
      "  o  qqq        ",
      "  of qqq        ",
      "  oooooomm      ",
      " a    nnmm      ",
      "                "
    ],
    [
      "                ",
      " annmm          ",
      " koomm          ",
      " lpru           ",
      " lpru           ",
      " kpruu          ",
      " kpruu          ",
      " kpru           ",
      " kpru ~         ",
      " kpruu          ",
      " kpruu          ",
      " kpru           ",
      " kpru           ",
      " koomm          ",
      " annmm          ",
      "                "
    ],
    [
      "                ",
      "mm              ",
      "mm              ",
      "mlll            ",
      "mlll            ",
      "mm              ",
      "mm              ",
      "mm              ",
      "mm    ~         ",
      "mm              ",
      "mm              ",
      "mm              ",
      "mm              ",
      "mm              ",
      "mm              ",
      "                "
    ],
    [
      "                ",
      "                ",
      "                ",
      " lw             ",
      " yx             ",
      "                ",
      "                ",
      "                ",
      "      ~         ",
      "                ",
      "                ",
      "                ",
      "                ",
      "                ",
      "                ",
      "                "
    ]
  ]
}