{
  "name": "building_restaurant2_ground_90",
  "refpalette": "c70cities:building_restaurant2_ground_palette_90",
  "xsize": 16,
  "zsize": 16,
  "slices": [
    [
      "GGGGGGGGGGGGGGGG",
      "GccccabaabbccccG",
      "GccccaaaaaaccccG",
      "GccccdgdgdgccccG",
      "GccccdgffdgccccG",
      "GaceeffeeffeecbG",
      "GbcdgeedgeedgcbG",
      "GacdgdgdgdgdgcaG",
      "GacffdgffdgffcaG",
      "GaceeffeeffeecaG",
      "GacdgeedgeedgcaG",
      "GGccccccccccccGG",
      "GGabaaaaaaaaaaGG",
      "GGGGGGGabGGGGGGG",
      "GGGGGGbaaGGGGGGG",
      "GGGGGGGaGaGGGGGG"
    ],
    [
      "                ",
      " iiiiyDDDDNiiii ",
      " inniiiiiiiiOQi ",
      " in r CFCCMi Pi ",
      " iiii      iEii ",
      " lm  xBBBBL  mT ",
      " km  wmmmmK  mS ",
      " km  uAAAAJ  mS ",
      " km  tttttt  mS ",
      " jm          mR ",
      " imp piEIip pmi ",
      " hmmmmm  mmmmmh ",
      "  moqsm  moqsm  ",
      "                ",
      "                ",
      "                "
    ],
    [
      "                ",
      " iiiiYYYYYYiiii ",
      " iX iiiiiiii  i ",
      " iW Z  68!@i  i ",
      " iiii      i4ii ",
      "  m   35 3   m  ",
      "  V  111119  V  ",
      "  V  022222  V  ",
      "  V          V  ",
      "  m          m  ",
      " im   i47i   mi ",
      " UmVVVm  mVVVmU ",
      "  mYYYm  mYYYm  ",
      "                ",
      "                ",
      "                "
    ],
    [
      "                ",
      " iVViYYYYYYiVVi ",
      " i$ iiiiiiii  i ",
      " i# i      i  i ",
      " iiii      iiii ",
      " YmX        +mY ",
      " Ym% &&&&&& )mY ",
      " Ym% ^^^^^^ )mY ",
      " Ym%        )mY ",
      " YmW        (mY ",
      " im   iiii   mi ",
      " UmVVVm  mVVVmU ",
      "  mYYYm**mYYYm  ",
      "                ",
      "                ",
      "                "
    ],
    [
      "                ",
      " i--i------i--i ",
      " i  iiiiiiii  i ",
      " i  i      i  i ",
      " iiii      iiii ",
      " -m]        }m- ",
      " -m]        }m- ",
      " -m]        }m- ",
      " -m]        }m- ",
      " -m]        {m- ",
      " imiiiiiiiiiimi ",
      "  miiim  miiim  ",
      "  m---m**m---m  ",
      "  [   [  [   [  ",
      "                ",
      "                "
    ],
    [
      "                ",
      " iiii||||||iiii ",
      " i``iiiiiiii``i ",
      " i``i||||||i``i ",
      " i||||||||||||i ",
      " im::;::::;::mi ",
      " im::;::::;::mi ",
      " im::;::::;::mi ",
      " im::;::::;::mi ",
      " im::;::::;::mi ",
      " im||||||||||mi ",
      " \\\\\\\\\\\\\\\\\\\\\\\\\\\\ ",
      " \\\\\\\\\\\\\\\\\\\\\\\\\\\\ ",
      " \\\\\\\\\\\\\\\\\\\\\\\\\\\\ ",
      " \\\\\\\\\\\\\\\\\\\\\\\\\\\\ ",
      "                "
    ]
  ]
}