{
  "name": "building_policeoffice1_floor1_90",
  "refpalette": "c70cities:building_policeoffice1_floor1_palette_90",
  "xsize": 16,
  "zsize": 16,
  "slices": [
    [
      "           cccc ",
      "           c  f ",
      "           d  c ",
      "           c  c ",
      " aaaaaaaaaacbbc ",
      " abbbbbbbbbbbbf ",
      " abbbbbbbbbbbbc ",
      " abbb!bbbbbbbbc ",
      " abbbbbbbbbbbbc ",
      " abbbbbbbbbbbbf ",
      " abbbbbbbbbbbbc ",
      " abbbbbbbbbbbbc ",
      " abbbbbbbbbbbbc ",
      " aaaaaaaaaaceef ",
      "           cccc ",
      "                "
    ],
    [
      "           cccc ",
      "           c  f ",
      "           d  c ",
      "           c  c ",
      " gggggggggacxxc ",
      " g            f ",
      " g  l l      yc ",
      " g  koors    yc ",
      " g hjccq     yc ",
      " g  jccqs    yf ",
      " g hinnp   wwwc ",
      " g   m m   u  c ",
      " g         t  c ",
      " aaaaaaaaaaceef ",
      "           cccc ",
      "                "
    ],
    [
      "           cccc ",
      "           c  f ",
      "           d  c ",
      "           c  c ",
      " gggggggggac  c ",
      " g            f ",
      " g           Ec ",
      " g    A       c ",
      " g  A        Dc ",
      " g     A      f ",
      " g   A     wwwc ",
      " g         C  c ",
      " g         B  c ",
      " aaaaaaaaaaceef ",
      "           cccc ",
      "                "
    ],
    [
      "           cccc ",
      "           c  f ",
      "           d  c ",
      "           c  c ",
      " gggggggggac  c ",
      " g            f ",
      " g           Ec ",
      " g            c ",
      " g    f       c ",
      " g   f        f ",
      " g         wywc ",
      " g         w  c ",
      " g         w  c ",
      " aaaaaaaaaaceef ",
      "           cccc ",
      "                "
    ],
    [
      "           cccc ",
      "           c  f ",
      "           d  c ",
      "           c  c ",
      " gggggggggac  c ",
      " g            f ",
      " g           Ec ",
      " g            c ",
      " g   EE       c ",
      " g   EE       f ",
      " g         wwwc ",
      " g         w  c ",
      " g         w  c ",
      " aaaaaaaaaaceef ",
      "           cccc ",
      "                "
    ],
    [
      "           cccc ",
      "           c  f ",
      "           d  c ",
      "           c  c ",
      " FFFFFFFFFacIIc ",
      " FIIIIIIIIIIIIf ",
      " FIIIIIIIIIIIIc ",
      " FIIIIIIIIIIIIc ",
      " FIIIIIIIIIIIIc ",
      " FIIIIIIIIIIIIf ",
      " FIIIIIIIIIwwwc ",
      " FIIIIIIIIIwIIc ",
      " FIIIIIIIIIwIIc ",
      " aaaaaaaaaaceef ",
      "           cccc ",
      "                "
    ]
  ]
}