{
  "name": "building_office5_top_90",
  "refpalette": "c70cities:building_office5_top_palette_90",
  "xsize": 16,
  "zsize": 16,
  "slices": [
    [
      "                ",
      "                ",
      "     cdcdcdcdc  ",
      "     ceeeeeeed  ",
      "  abbceeeeeeec  ",
      "  a  ceee!eeed  ",
      "  a  ceeeeeeec  ",
      "  a  cfeeGGGed  ",
      "  a  cfeeGGGec  ",
      "  a  ceeeeeeed  ",
      "  a  ceeeeeeec  ",
      "  a  ceeeeeeed  ",
      "  abbceeeeeeec  ",
      "     cdcdcdcdc  ",
      "                ",
      "                "
    ],
    [
      "                ",
      "                ",
      "     cdcdcdcdc  ",
      "     cg     gd  ",
      "   abci   r  c  ",
      "   a ci  ooo d  ",
      "   a c       c  ",
      "   a c   nqu d  ",
      "   a c   mpt c  ",
      "   a c       d  ",
      "   a chk l   c  ",
      "   a ch  l   d  ",
      "   abcgj l sgc  ",
      "     cdcdcdcdc  ",
      "                ",
      "                "
    ],
    [
      "                ",
      "                ",
      "     cdcdcdcdc  ",
      "     c       d  ",
      "    am       c  ",
      "    a    BCD d  ",
      "    aA       c  ",
      "    ac       d  ",
      "    ac       c  ",
      "    ay       d  ",
      "    ax       c  ",
      "    aw   l   d  ",
      "    ac   l   c  ",
      "     cdcdcdcdc  ",
      "                ",
      "                "
    ],
    [
      "                ",
      "                ",
      "     ccccccccc  ",
      "     c       c  ",
      "     c       c  ",
      "     c       c  ",
      "     c       c  ",
      "     c       c  ",
      "     c       c  ",
      "     c       c  ",
      "     c       c  ",
      "     c       c  ",
      "     c       c  ",
      "     ccccccccc  ",
      "                ",
      "                "
    ],
    [
      "                ",
      "                ",
      "     ccccccccc  ",
      "     cEEEEEEEc  ",
      "     cEEEEEEEc  ",
      "     cEEEEEEEc  ",
      "     cEEEFFFEc  ",
      "     cEEEFFFEc  ",
      "     cEEEFFFEc  ",
      "     cEEEFFFEc  ",
      "     cEEEEEEEc  ",
      "     cEEEEEEEc  ",
      "     cEEEEEEEc  ",
      "     ccccccccc  ",
      "                ",
      "                "
    ],
    [
      "                ",
      "                ",
      "     ccccccccc  ",
      "     c     I c  ",
      "     c  IIII c  ",
      "     c       c  ",
      "     c       c  ",
      "     c       c  ",
      "     c       c  ",
      "     c       c  ",
      "     cII     c  ",
      "     c I IIIIc  ",
      "     c I I   c  ",
      "     ccccccccc  ",
      "                ",
      "                "
    ]
  ]
}