{
  "name": "building_carservice1_top",
  "refpalette": "c70cities:building_carservice1_top_palette",
  "xsize": 16,
  "zsize": 16,
  "slices": [
    [
      "                ",
      " a   a   a   a  ",
      "  bb            ",
      "  bb            ",
      "  bbb           ",
      "  bbb           ",
      " acccadddadddae ",
      " ecccccccccccce ",
      " effffffffffffe ",
      " effffffffffffe ",
      " efffffffffffce ",
      " effffffffffcde ",
      " efffffffffcdd  ",
      " effffffffgdd   ",
      " aeeeaeeeaee    ",
      "                "
    ],
    [
      "                ",
      " ahhhahhha   a  ",
      " h       h      ",
      " h       h      ",
      " h       h      ",
      " i       i      ",
      " ajjjaeeeaeeeae ",
      " e    kkklm!mne ",
      " o         pq e ",
      " o  r  r   p  e ",
      " osstuutw     e ",
      " ossuxsss    oe ",
      " osstuutw   oo  ",
      " e  y  y   oo   ",
      " aeeeaeeeaee    ",
      "                "
    ],
    [
      "                ",
      " a   a   a   a  ",
      "                ",
      "                ",
      "                ",
      "                ",
      " ajjjaeeeaeeeae ",
      " e      Almmm o ",
      " o            o ",
      " o            o ",
      " oB           e ",
      " osuBCB      oe ",
      " oB         oo  ",
      " e         oo   ",
      " aeeeaeeeaee    ",
      "                "
    ],
    [
      "                ",
      " a   a   a   a  ",
      " D   D   D   D  ",
      " D   D   D   D  ",
      " D   D   D   D  ",
      " D   D   D   D  ",
      " ajjjaeeeaeeeae ",
      " a   D   DEEE e ",
      " a   D   D    e ",
      " a   D   D    e ",
      " a   D   D    e ",
      " a   D   D   oe ",
      " a   D   D  oo  ",
      " a   D   D oo   ",
      " aeeeaeeeaee    ",
      "                "
    ],
    [
      "                ",
      "                ",
      "                ",
      "                ",
      "                ",
      "                ",
      " eeeeeeeeeeeeee ",
      " eFFFFFFFFFFFFe ",
      " eFFFFFFFFFFFFe ",
      " eFFFFFFFFFFFFe ",
      " eFFFFFFFFFFFFe ",
      " eFFFFFFFFFFFFe ",
      " eFFFFFFFFFFFF  ",
      " eFFFFFFFFFFF   ",
      " eeeeeeeeeee    ",
      "                "
    ],
    [
      "                ",
      "                ",
      "                ",
      "                ",
      "                ",
      "                ",
      " eeeeeeeeeeeeee ",
      " e            e ",
      " e            e ",
      " e            e ",
      " e            e ",
      " e            e ",
      " e              ",
      " e              ",
      " eeeeeeeeeee    ",
      "                "
    ]
  ]
}