{
  "name": "building_apartment1_top_90",
  "refpalette": "c70cities:building_apartment1_top_palette_90",
  "xsize": 16,
  "zsize": 16,
  "slices": [
    [
      "                ",
      " aaaaaaaaa      ",
      " abbbbbbbbbeeh  ",
      " abccccccc   g  ",
      " abccccccc   f  ",
      " abcccccccd  b  ",
      " abccccccccccba ",
      " abccccccccccba ",
      " abccccccccccba ",
      " abccccccccccba ",
      " abccccccccccba ",
      " abccccccccccba ",
      " abccccccccccba ",
      " abbbbbbbbbbbba ",
      " aaaaaaaaaaaaaa ",
      "                "
    ],
    [
      "                ",
      "                ",
      "  mlbbiiqbbbbb  ",
      "  j      r   b  ",
      "  i pp   r   i  ",
      "  i pp   s   i  ",
      "  b o    rrrrb  ",
      "  l pp   nuunx  ",
      "  knpp    n  l  ",
      "  b o  n     l  ",
      "  b ooooooowob  ",
      "  j   o!  nonb  ",
      "  in no    o b  ",
      "  iiibbmlltbbb  ",
      "                ",
      "                "
    ],
    [
      "                ",
      "                ",
      "  bbbbbbbbgibb  ",
      "  b      r   b  ",
      "  b AA   r   b  ",
      "  b yy   C   b  ",
      "  b      rrrrb  ",
      "  b yy    DD b  ",
      "  b yB       b  ",
      "  i          b  ",
      "  i          j  ",
      "  i          i  ",
      "  b          i  ",
      "  bbbbbbbbbllb  ",
      "                ",
      "                "
    ],
    [
      "                ",
      "                ",
      "  bllltbbbbbbb  ",
      "  b      EEEEb  ",
      "  b      EEEEb  ",
      "  l      EEEEb  ",
      "  l      EEEEb  ",
      "  k        n l  ",
      "  b          l  ",
      "  b          b  ",
      "  b          b  ",
      "  b          b  ",
      "  b          b  ",
      "  bbblllbbbbbb  ",
      "                ",
      "                "
    ],
    [
      "                ",
      "                ",
      "                ",
      "                ",
      "                ",
      "                ",
      "                ",
      "                ",
      "                ",
      "                ",
      "                ",
      "                ",
      "                ",
      "                ",
      "                ",
      "                "
    ],
    [
      "                ",
      "                ",
      "                ",
      "                ",
      "                ",
      "                ",
      "                ",
      "                ",
      "                ",
      "                ",
      "                ",
      "                ",
      "                ",
      "                ",
      "                ",
      "                "
    ]
  ]
}