{
  "name": "building_factory2_ground_270",
  "refpalette": "c70cities:building_factory2_ground_palette_270",
  "xsize": 16,
  "zsize": 16,
  "slices": [
    [
      "zzzzzzzzzzzazzzz",
      "zzzzzazaazazzzzz",
      "zzzzzzaazaaazzzz",
      "zzzzzzzaaaaazzzz",
      "zzzHHHHHHHHHHzzz",
      "zzzHHHHHHHHHHzzz",
      "zzzHHHHHHHHHHzzz",
      "zzzHHHHHHHHHHzzz",
      "zzzHHHHHHHHHHzzz",
      "zzzHHHHHHHHHHzzz",
      "zzzHHHHHHHHHHzzz",
      "zzzHHHHHHHHHHzzz",
      "zzzHHHHHHHHHHzzz",
      "zzzzzzHHzzzzzzzz",
      "zzzzzzzzzzzzzzzz",
      "zzzzzzzzzzzzzzzz"
    ],
    [
      "                ",
      "b bd        b b ",
      " bc bb       dcb",
      "beccc b     bce ",
      " cffoqqqqoflffcc",
      "bdf!ggwg   igfcd",
      " cfggA      hfcb",
      "bcfF      i if  ",
      " cf     r   jfb ",
      " bfFD  tspmfff b",
      "ccf   iknknkkf  ",
      " cfg Bxunknkkfcd",
      "d fgECyknkkkkfcc",
      "bcffffffffffffcb",
      "befffeeffeefffe ",
      " ccdbee ceecd b "
    ],
    [
      "                ",
      "                ",
      "                ",
      " ecc         ce ",
      "  ffoqqqqofJffc ",
      "  IOg        Ic ",
      "  I O        I  ",
      " cI          I  ",
      " cf          f  ",
      "  f       L  f  ",
      " cI    MnKKKuf  ",
      "  I     nKnKnf  ",
      "  IjP  MnKK  f  ",
      "  fffffNffffffc ",
      " efffeeffeefffe ",
      "     ee  ee     "
    ],
    [
      "                ",
      "                ",
      "                ",
      " e            e ",
      "  ffoqqqqofQffc ",
      "  I          I  ",
      "  I          I  ",
      "  I          I  ",
      "  f          f  ",
      "  f       S  f  ",
      "  I      RRR f  ",
      "  I     PRRR f  ",
      "  I      RRRjf  ",
      "  fffffQffffff  ",
      " efffeeffeefffe ",
      "     ee  ee     "
    ],
    [
      "                ",
      "                ",
      "                ",
      " e   WWWW     e ",
      "  ffooooooffff  ",
      "  T          T  ",
      "  T          T  ",
      "  T          T  ",
      "  f          f  ",
      "  f          f  ",
      "  T          f  ",
      "  T          f  ",
      "  T X   X   jf  ",
      "  ffffffffffff  ",
      " eUUUVVUUVVUUUe ",
      "     UU  UU     "
    ],
    [
      "                ",
      "                ",
      "                ",
      " e            e ",
      "  ffYYYYYYffff  ",
      "  Y          Y  ",
      "  Y          Y  ",
      "  Y          Y  ",
      "  f  0    Z  f  ",
      "  f  0    0  f  ",
      "  Y          Y  ",
      "  Y          Y  ",
      "  Y          Y  ",
      "  ffffffffffff  ",
      " e   VV  VV   e ",
      "                "
    ]
  ]
}