{
  "name": "building_policeoffice1_ground_90",
  "refpalette": "c70cities:building_policeoffice1_ground_palette_90",
  "xsize": 16,
  "zsize": 16,
  "slices": [
    [
      "GHHHHHGcGGGeeeeG",
      "GHHHHHGGcGGeGGeG",
      "GHHHHHGccGdeGGeg",
      "GGGGGGGccGGeGgeG",
      "GaaaaaaaaaaebbeG",
      "GabbbbbbbbbbbbeG",
      "Gabbbbbbbbbbbbeg",
      "GabbbbbbbbbbbbeG",
      "Gabbb!bbbbbbbbeG",
      "GabbbbbbbbbbbbeG",
      "GabbbbbbbbbbbbeG",
      "GabbbbbbbbbbbbeG",
      "GabbbbbbbbbbbbeG",
      "GaaaaaaaaaaeffeG",
      "GGGGGGGGGGGeeeeG",
      "GGGGGGGGGGGGGGGG"
    ],
    [
      "          heeee ",
      "          he  y ",
      "          hr   e",
      "          he t  ",
      " aaaaaanoaaeuue ",
      " ai  m    m   y ",
      " a           wet",
      " aj kl      tse ",
      " aj  l      tse ",
      " aj  l      ssx ",
      " aj kl     aaae ",
      " a         q  e ",
      " ai        p  e ",
      " aaaaaaaaaaeffx ",
      " hhhhhhhhhheeee ",
      "                "
    ],
    [
      "           eeee ",
      "           e  x ",
      "           r    ",
      "           e    ",
      " aauuaaBCaae    ",
      " ai  A    A   y ",
      " u            e ",
      " aj           e ",
      " aj           e ",
      " aj           x ",
      " aj        aaae ",
      " u         E  e ",
      " ai        D  e ",
      " aaaaaaaaaaeffx ",
      "           eeee ",
      "                "
    ],
    [
      "           eeee ",
      "           e  x ",
      "           r  y ",
      "           e    ",
      " aaaaaaaaaae  e ",
      " ai  A    A   x ",
      " u            e ",
      " aj           e ",
      " a            e ",
      " a            x ",
      " aj        asae ",
      " u         a  e ",
      " ai        a  e ",
      " aaaaaaaaaaeffx ",
      "           eeee ",
      "                "
    ],
    [
      "           eeee ",
      "           e  x ",
      "           r  e ",
      "           e  y ",
      " aaauuuuaaae  e ",
      " a            x ",
      " a            e ",
      " aj           e ",
      " aj           e ",
      " aj           x ",
      " aj        aaae ",
      " a         a  e ",
      " a         a  e ",
      " aaaaaaaaaaeffx ",
      "           eeee ",
      "                "
    ],
    [
      "           eeee ",
      "           e  x ",
      "           r  e ",
      "           e  e ",
      " FFFFFFFFFFeIIe ",
      " FIIIIIIIIIIIIx ",
      " FIIIIIIIIIIIIe ",
      " FIIIIIIIIIIIIe ",
      " FIIIIIIIIIIIIe ",
      " FIIIIIIIIIIIIx ",
      " FIIIIIIIIIaaae ",
      " FIIIIIIIIIaIIe ",
      " FIIIIIIIIIaIIe ",
      " FFFFFFFFFFeffx ",
      "           eeee ",
      "                "
    ]
  ]
}