{
  "name": "building_hotel3_base2_90",
  "refpalette": "c70cities:building_hotel3_base2_palette_90",
  "xsize": 16,
  "zsize": 16,
  "slices": [
    [
      "aaaaaaaaaaaaaaaa",
      "abbbbbbbcbbbbbba",
      "abbbbbbbbbbbbbba",
      "abcbbbbbbbbbbbca",
      "abbbdeeeeeedbbba",
      "abbbeeeeeeeebbba",
      "abbbeeeeeeeebbba",
      "a!bbeeeeeeeebbba",
      "abbbeeeeeeeebbfa",
      "abbbeeeeeeeebbba",
      "abbbeeeeeeeebbca",
      "abbbdeeeeeedbbba",
      "abbbbbbbbbbfbbba",
      "acbbbbbbbbbbbbba",
      "abbbbccbbbcbbbba",
      "aaaaaaaaaaaaaaaa"
    ],
    [
      "aaaaaaaaaaaaaaaa",
      "aggggigihgjgggga",
      "agggjjiijiijigga",
      "aghjiiiiiiiiiiha",
      "agiidkkkkkkdijga",
      "aijik      kjiga",
      "agiik npps kijga",
      "aiiidl     kiiga",
      "ajiidl     kijia",
      "aggik moorkkiiga",
      "agiik   kqtkiiha",
      "ajiidkkkkkkdigia",
      "aiiiiiiiiiiiiiga",
      "ahiigiijigiiigga",
      "agiighhiighigfga",
      "aaaaaaaaaaaaaaaa"
    ],
    [
      "aaaaaaaaaaaaaaaa",
      "aggggijihijiigga",
      "aggijjiijiijijga",
      "ajhjiiiiiiiiiiha",
      "agiidkkkkkkdijia",
      "aijik      kjiga",
      "aiiik      kijga",
      "aiiidl     kiiia",
      "ajiidl     kijia",
      "agjik      kiija",
      "aiiik     tkiiha",
      "ajiidkkkkkkdiiia",
      "aiiiiiiiiiiiiiia",
      "ahiiiiijiiiiiija",
      "aiiijhhiijhijija",
      "aaaaaaaaaaaaaaaa"
    ],
    [
      "aaaaaaaaaaaaaaaa",
      "aggguiuihiuiiuga",
      "awuiuuiiuiiuiuia",
      "auhuiiiiiiiiiiha",
      "aiiidkkkkkkdiuia",
      "aiuik      kuiga",
      "aiiik      kiuua",
      "aiiidl     kiiia",
      "auiidl     kiuia",
      "auuik      kiiua",
      "aiiik     xkiiha",
      "auiidkkkkkqdiiia",
      "aiiiiiiiiiiiiiia",
      "ahiiiiiuiiiiiiua",
      "aiiiuhhiiuhiuiua",
      "aaaaaaaaaaaaaaaa"
    ],
    [
      "aaaaaaaaaaaaaaaa",
      "ag             a",
      "a              a",
      "a              a",
      "a   dkkkkkkd   a",
      "a   k      k   a",
      "a   k      k   a",
      "a   dl     k   a",
      "a   dl     k   a",
      "a   k      k   a",
      "a   k      k   a",
      "a   dkkkk  d   a",
      "a              a",
      "a              a",
      "a              a",
      "aaaaaaaaaaaaaaaa"
    ],
    [
      "aaaaaaaaaaaaaaaa",
      "ayyyyyyyyyyyyyya",
      "ayyyyyyyyyyyyyya",
      "ayyyyyyyyyyyyyya",
      "ayyydAAAAAAdyyya",
      "ayyyAAAAAAAAyyya",
      "ayyyAAAAAAAAyyya",
      "ayyydlAAAAAAyyya",
      "ayyydlAAAAAAyyya",
      "ayyyAAAAAAAAyyya",
      "ayyyAAAAAAAAyyya",
      "ayyydAAAAAAdyyya",
      "ayyyyyyyyyyyyyya",
      "ayyyyyyyyyyyyyya",
      "ayyyyyyyyyyyyyya",
      "aaaaaaaaaaaaaaaa"
    ]
  ]
}