{
  "name": "building_hotel1_floor2_270",
  "refpalette": "c70cities:building_hotel1_floor2_palette_270",
  "xsize": 16,
  "zsize": 16,
  "slices": [
    [
      "                ",
      " aadddddddaaaaa ",
      " abbbbbbbbbbbba ",
      " abbbbbbbbbbbba ",
      " abbbbbbbbbbbba ",
      " abbbccccccbbba ",
      " abbbc    cbbba ",
      " abbbc    cbbba ",
      " gbbbc    cbbba ",
      " gbccce   cbbba ",
      " gbbbbbbbdcbbba ",
      " gbbbbbbbbcbbba ",
      " gbbbbbbbbcbbba ",
      " abbbbbbbbcbbba ",
      " aaffffaaaaaaaa ",
      "                "
    ],
    [
      "                ",
      " aaaaaaaaaaaaaa ",
      " a          m a ",
      " a Bxa      nha ",
      " a Bxa=uu=r   a ",
      " a   saaaaso  a ",
      " a ffa    ap ia ",
      " a Cyae   aq ja ",
      " aFDAae   aq ja ",
      " aaaaad   ap ka ",
      " aee   ww so  a ",
      " aeE      a   a ",
      " aeE      t  la ",
      " an    n  a   a ",
      " aaffffaaaaaaaa ",
      "                "
    ],
    [
      "                ",
      " aaaaaffffaaaaa ",
      " a            a ",
      " f   a      I a ",
      " f   aN  L    a ",
      " f   saaaaso  a ",
      " f ffaee  a   a ",
      " f   ad   a   a ",
      " f   a    aJ  a ",
      " aaaaa    a   a ",
      " a        so  a ",
      " a        a   a ",
      " a        K   a ",
      " aM    M  a   a ",
      " aaffffaaaaaaaa ",
      "                "
    ],
    [
      "                ",
      " aaaaaaaaaaaaaa ",
      " a   a        a ",
      " a   a        a ",
      " a   a EE     a ",
      " a  Osaaaas  Oa ",
      " a ffa deea   a ",
      " a   a    a   a ",
      " a   a    a   a ",
      " aaaaa    a   a ",
      " a        s  Oa ",
      " a        a   a ",
      " a        a   a ",
      " aM    M  a   a ",
      " aaffffaaaaaaaa ",
      "                "
    ],
    [
      "                ",
      " aaaaaaaaaaffaa ",
      " a   a        a ",
      " a   a        a ",
      " a   a        a ",
      " a  Psaaaas  Pa ",
      " afffa   da   a ",
      " f   a   ea   a ",
      " f   a   ea   a ",
      " aaaaa    a   a ",
      " a        s  Pa ",
      " a        a   a ",
      " a        a   a ",
      " a        a   a ",
      " aaffffaaaaaaaa ",
      "                "
    ],
    [
      "                ",
      " aaaaaaaaaaaaaa ",
      " aQQQQQQQQQQQQa ",
      " aQQQQQQQQQQQQa ",
      " aQQQQQQQQQQQQa ",
      " aQQQsaaaasQQQa ",
      " aQQQa    aQQQa ",
      " aQQQa    aQQQa ",
      " aQQQa   daQQQa ",
      " aaaaa   eaQQQa ",
      " aQQQQQQQQsQQQa ",
      " aQQQQQQQQaQQQa ",
      " aQQQQQQQQaQQQa ",
      " aQQQQQQQQaQQQa ",
      " aaffffaaaaaaaa ",
      "                "
    ]
  ]
}