{
  "name": "building_office1_ground_180",
  "refpalette": "c70cities:building_office1_ground_palette_180",
  "xsize": 16,
  "zsize": 16,
  "slices": [
    [
      "GGGGGGGGGGGGGGGG",
      "GbbbbbbbbbbbbbbG",
      "GbdbbbbbbbbbbebG",
      "GbdbbbbbbbbbbebG",
      "GbdbbbbbbbbbbdbG",
      "GbdbbbbbbbbbbdbG",
      "GbdbbbbbbbbbbdbG",
      "GbdbbbbbbbbbbdbG",
      "GbcbbbbbbbbbbcbG",
      "Gbcbbbb!bbbbbcbG",
      "GbcbbbbbbbbbbcbG",
      "GbcbbbbbbbbbbcbG",
      "GbcbbbbbbbbbbcbG",
      "GbccccccccccccbG",
      "GbbbbbbbbbbbbbbG",
      "GGGGaGGGGGGaGGGG"
    ],
    [
      "                ",
      " pppppppppppppp ",
      " s            p ",
      " r            p ",
      " pd  nn  nn qdp ",
      "  h  no  on  h  ",
      "  h  nn  nn  h  ",
      " gd          dg ",
      "  h          h  ",
      "  h  lllllm  h  ",
      " gh  l    k  hg ",
      "  h   j  j   h  ",
      "  hi        ih  ",
      " ghhhhhhhhhhhhg ",
      "   g  g  g  g   ",
      "ffffffffffffffff"
    ],
    [
      "                ",
      " ppyhhhhhhhhypp ",
      " x            p ",
      " w            p ",
      " pd         qdp ",
      "  h          h  ",
      "  h          h  ",
      " gd          dg ",
      "  h          h  ",
      "  h   u      h  ",
      " gh          hg ",
      "  h          h  ",
      "  ht        th  ",
      " ghhhhhhhhhhhhg ",
      "   g  g  g  g   ",
      "                "
    ],
    [
      "                ",
      " ppyhhhhhhhhypp ",
      " p            p ",
      " p            p ",
      " pd         qdp ",
      "  h          h  ",
      "  h          h  ",
      " gd          dg ",
      "  h          h  ",
      "  h          h  ",
      " gh          hg ",
      "  h          h  ",
      "  ht        th  ",
      " ghhhhhhhhhhhhg ",
      "   g  g  g  g   ",
      "                "
    ],
    [
      "                ",
      " pppppppppppppp ",
      " p            p ",
      " p            p ",
      " pd         qdp ",
      "  h          h  ",
      "  h          h  ",
      " gd          dg ",
      "  h          h  ",
      "  h          h  ",
      " gh          hg ",
      "  h          h  ",
      "  h          h  ",
      " ghhhhhhhhhhhhg ",
      "   g  g  g  g   ",
      "                "
    ],
    [
      "                ",
      " pppppppppppppp ",
      " pyyyyyyyyyyyyp ",
      " pyyyyyyyyyyyyp ",
      " pd yyyyyyyyqdp ",
      "  h yyyyyyyy h  ",
      "  h yyyyyyyy h  ",
      " AAyyyyyyyyyyAA ",
      " AAyyyyyyyyyyAA ",
      " AAyyyyyyyyyyAA ",
      " AAyyyyyyyyyyAA ",
      " AAyyyyyyyyyyAA ",
      " AAyyyyyyyyyyAA ",
      " AAA AAAAAAAAAA ",
      " AAAAAAAAAAAAAA ",
      "                "
    ]
  ]
}