{
  "name": "building_residential1_ground_90",
  "refpalette": "c70cities:building_residential1_ground_palette_90",
  "xsize": 16,
  "zsize": 16,
  "slices": [
    [
      "GGGGGGGGGGGGGGGG",
      "GGGGGGGGGGGGGGGG",
      "GGaaaaaaaGGGGGGG",
      "GGabbbbbcccccGGG",
      "GGabbbbbeeeecGGG",
      "GGabbbbbeeeecGGG",
      "GGabbbbbddddcGGG",
      "GGabbbbbddddcGGG",
      "GGabbbbbddddcGGG",
      "GGabbbbbddddcGGG",
      "GGabbbbbddddcGGG",
      "GGabbbbbddddcGGG",
      "GGabbbbbcccccGGG",
      "GGaaaaaaaGGGGGGG",
      "GGGGGGGGGGGGGGGG",
      "GGGGGGGGGGGGGGGG"
    ],
    [
      "fggggfgggghggggf",
      "g              g",
      "g ijjijjiyyyyy g",
      "g i  q  cccccy g",
      "g j   s xD Lcy g",
      "h j   s xCEEcy h",
      "g j   s    !cy g",
      "g il psu   Icy g",
      "g il os    Kcy g",
      "g j      B Jcy g",
      "h j  n  wA Icy h",
      "g j  n  wA Fcy g",
      "g i  nrtcccccy g",
      "g ikmijjiyyyyy g",
      "g              g",
      "fgf  fgggghggggf"
    ],
    [
      "fggggfgggghggggf",
      "g              g",
      "g ijjijji      g",
      "g i  P  ccUcc  g",
      "g j   s x   c  g",
      "h j   s xSEEc  h",
      "g j   su    T  g",
      "g iN  s     T  g",
      "g iN  s    WT  g",
      "g j      R  T  g",
      "h j  n      c  h",
      "g j  n  Q  Vc  g",
      "g i  n  ccTcc  g",
      "g iMOijji      g",
      "g              g",
      "fgf  fgggghggggf"
    ],
    [
      "     0          ",
      "                ",
      "  iZZiZZi    1  ",
      "  i     ccUcc1  ",
      "  X   s x   c1  ",
      "  X   suxEEEc1  ",
      "  X   s     c1  ",
      "  i   s     c1  ",
      "  i   s     c1  ",
      "  X         c1  ",
      "  X  n      c1  ",
      "  X  n      c1  ",
      "  i  n  ccTcc1  ",
      "  iYYiYYi    1  ",
      "                ",
      "                "
    ],
    [
      "                ",
      "                ",
      "  iiiiiii  145  ",
      "  ibbbbbcccc45  ",
      "  ibbbbux33345  ",
      "  ibbbb x22245  ",
      "  ibbbb    145  ",
      "  ibbbb    145  ",
      "  ibbbb    145  ",
      "  ibbbb    145  ",
      "  ibbbb    145  ",
      "  ibbbb    145  ",
      "  ibbbb cccc45  ",
      "  iiiiiii  145  ",
      "                ",
      "                "
    ],
    [
      "                ",
      " 6              ",
      " 6ijjjjji145    ",
      " 6i#    cc45    ",
      " 6i    +x-45    ",
      " 6i *  +xE45    ",
      " 6i@&) + 145    ",
      " 6i9^( + 145    ",
      " 6i    + 145    ",
      " 6i8888+ 145    ",
      " 6i8%%8+ 145    ",
      " 6i8$$8+ 145    ",
      " 6i7YY +cc45    ",
      " 6ijjjjji145    ",
      " 6              ",
      "                "
    ]
  ]
}