{
  "name": "building_office5_floor1",
  "refpalette": "c70cities:building_office5_floor1_palette",
  "xsize": 16,
  "zsize": 16,
  "slices": [
    [
      "                ",
      "                ",
      "   ababababa    ",
      "   bcccccccb    ",
      "   accccccca    ",
      "  ddeedddddddd  ",
      "  beeeeffeeeeb  ",
      "  deeeeeeeeeed  ",
      "  beeeeeeeeeeb  ",
      "  deeeeee!eeed  ",
      "  beeeeeeeeeeb  ",
      "  deeeeeeeeeed  ",
      "  beeeeeeeeeeb  ",
      "  ddbdbdbdbdbd  ",
      "                ",
      "                "
    ],
    [
      "                ",
      "                ",
      "   ababababa    ",
      "   b       b    ",
      "   a   g!hha    ",
      "  dd  dddddddd  ",
      "  bg  iff j  b  ",
      "  d          d  ",
      "  b      k   b  ",
      "  dl mmn mmn d  ",
      "  b  mm  mm  b  ",
      "  d lmm lmmn d  ",
      "  b    o     b  ",
      "  ddbdbdbdbdbd  ",
      "                ",
      "                "
    ],
    [
      "                ",
      "                ",
      "   ababababa    ",
      "   b       b    ",
      "   a  pp  qa    ",
      "  dd  dddddrdd  ",
      "  b    ff s  b  ",
      "  d          d  ",
      "  b          b  ",
      "  d   t      d  ",
      "  b          b  ",
      "  d  t    t  d  ",
      "  b          b  ",
      "  ddbdbdbdbdbd  ",
      "                ",
      "                "
    ],
    [
      "                ",
      "                ",
      "   ababababa    ",
      "   b       b    ",
      "   a       a    ",
      "  dduudddddudd  ",
      "  b    ff    b  ",
      "  d          d  ",
      "  b          b  ",
      "  d          d  ",
      "  b          b  ",
      "  d          d  ",
      "  b          b  ",
      "  ddbdbdbdbdbd  ",
      "                ",
      "                "
    ],
    [
      "                ",
      "                ",
      "   ababababa    ",
      "   b       b    ",
      "   a       a    ",
      "  dddddddddddd  ",
      "  b    ff    b  ",
      "  d          d  ",
      "  b          b  ",
      "  d          d  ",
      "  b          b  ",
      "  d          d  ",
      "  b          b  ",
      "  ddbdbdbdbdbd  ",
      "                ",
      "                "
    ],
    [
      "                ",
      "                ",
      "   ababababa    ",
      "   b       b    ",
      "   a       a    ",
      "  dddddddddddd  ",
      "  bwwwwffwwwwb  ",
      "  dwwwwwwwwwwd  ",
      "  bwwwwwwwwwwb  ",
      "  dwwwwwwwwwwd  ",
      "  bwwwwwwwwwwb  ",
      "  dwwwwwwwwwwd  ",
      "  bwwwwwwwwwwb  ",
      "  ddbdbdbdbdbd  ",
      "                ",
      "                "
    ]
  ]
}