{
  "name": "building_residential2_floor1_180",
  "refpalette": "c70cities:building_residential2_floor1_palette_180",
  "xsize": 16,
  "zsize": 16,
  "slices": [
    [
      "                ",
      "                ",
      "                ",
      "   CC  CC  CC   ",
      "   B            ",
      "                ",
      "                ",
      "  dxxxxxxAyxxd  ",
      "  dw kj      d  ",
      " udt kj  fffsdr ",
      " qdpokj  ffihdn ",
      " mdl kj  ffihdg ",
      "  d      fffed  ",
      "  dddddddddddd  ",
      "    cba  cba    ",
      "                "
    ],
    [
      "                ",
      "                ",
      "                ",
      "   CC  CC  CC   ",
      "                ",
      "                ",
      "                ",
      "  dxxxxxxKJxxd  ",
      "  D          D  ",
      "  E          E  ",
      "  EI         E  ",
      "  E          E  ",
      "  D         FD  ",
      "  dDEEEEEEEEDd  ",
      "                ",
      "                "
    ],
    [
      "                ",
      " NNNNNNNNNNNNNN ",
      " MMMMMMMMMMMMMM ",
      " DDDDDDDDDDDDDD ",
      " LLLLLLLLLLLLLL ",
      "                ",
      "                ",
      "  dxxxxxxxxxxd  ",
      "  D          D  ",
      "  E          E  ",
      "  E          E  ",
      "  E          E  ",
      "  D          D  ",
      "  dDEEEEEEEEDd  ",
      "                ",
      "                "
    ],
    [
      "                ",
      "                ",
      "                ",
      "                ",
      " NNNNNNNNNNNNNN ",
      " MMMMMMMMMMMMMM ",
      " DDDDDDDDDDDDDD ",
      " LdDDDDDDDDDDdL ",
      "  d          d  ",
      "  d          d  ",
      "  d          d  ",
      "  d          d  ",
      "  d          d  ",
      "  dddddddddddd  ",
      "                ",
      "                "
    ],
    [
      "                ",
      "                ",
      "                ",
      "                ",
      "                ",
      "                ",
      "                ",
      " NNNNNNNNNNNNNN ",
      " MMMMMMMMMMMMMM ",
      " DDDDDDDDDDDDDD ",
      " LLLLLLLLLLLLLL ",
      "                ",
      "  C          C  ",
      "  C  CC  CC  C  ",
      "                ",
      "                "
    ],
    [
      "                ",
      "                ",
      "                ",
      "                ",
      "                ",
      "                ",
      "                ",
      "                ",
      "        ~       ",
      "                ",
      " NNNNNNNNNNNNNN ",
      " MMMMMMMMMMMMMM ",
      " DDDDDDDDDDDDDD ",
      " LDLLDDLLDDLLDL ",
      "                ",
      "                "
    ]
  ]
}