{
  "name": "building_office3_floor1_90",
  "refpalette": "c70cities:building_office3_floor1_palette_90",
  "xsize": 16,
  "zsize": 16,
  "slices": [
    [
      "                ",
      " aabaabaabaabaa ",
      " acccccccccccca ",
      " bccccccccccccb ",
      " accccccccc!cca ",
      " acccccccccccca ",
      " bccccccccccccb ",
      " acccccddccccca ",
      " acccccvvccccca ",
      " bccccccccccccb ",
      " acccccccccccca ",
      " acccccccccccca ",
      " bccccccccccccb ",
      " acccccccccccca ",
      " aabaabaabaabaa ",
      "                "
    ],
    [
      "                ",
      " eebeebeebeebee ",
      " e            e ",
      " b f        f b ",
      " e         p  e ",
      " e  j     gp  e ",
      " b  ik     pq b ",
      " e g   dd gp  e ",
      " e   k vv  pp e ",
      " b gi  mn     b ",
      " e  h         e ",
      " e     ee     e ",
      " b f        f b ",
      " e    lhho    e ",
      " eebeebeebeebee ",
      "                "
    ],
    [
      "                ",
      " rrbrrbrrbrrbrr ",
      " r            r ",
      " b f        f b ",
      " r            r ",
      " r            r ",
      " b  s         b ",
      " r  s  dd     r ",
      " r  s  vv     r ",
      " b  s  tt     b ",
      " r            r ",
      " r            r ",
      " b f        f b ",
      " r            r ",
      " rrbrrbrrbrrbrr ",
      "                "
    ],
    [
      "                ",
      " rrbrrbrrbrrbrr ",
      " r            r ",
      " b f        f b ",
      " r            r ",
      " r            r ",
      " b            b ",
      " r     dd     r ",
      " r     vv     r ",
      " b     tt     b ",
      " r            r ",
      " r            r ",
      " b f        f b ",
      " r            r ",
      " rrbrrbrrbrrbrr ",
      "                "
    ],
    [
      "                ",
      " rrbrrbrrbrrbrr ",
      " r            r ",
      " b f        f b ",
      " r            r ",
      " r            r ",
      " b            b ",
      " r     dd     r ",
      " r     vv     r ",
      " b            b ",
      " r            r ",
      " r            r ",
      " b f        f b ",
      " r            r ",
      " rrbrrbrrbrrbrr ",
      "                "
    ],
    [
      "                ",
      " rrbrrbrrbrrbrr ",
      " ruuuuuuuuuuuur ",
      " bufwwwwwwwwfub ",
      " ruwwwwwwwwwwur ",
      " ruwwwwwwwwwwur ",
      " buwwwwwwwwwwub ",
      " ruwwwwddwwwwur ",
      " ruwwwwvvwwwwur ",
      " buwwwwwwwwwwub ",
      " ruwwwwwwwwwwur ",
      " ruwwwwwwwwwwur ",
      " bufwwwwwwwwfub ",
      " ruuuuuuuuuuuur ",
      " rrbrrbrrbrrbrr ",
      "                "
    ]
  ]
}