{
  "name": "building_carservice1_floor1_270",
  "refpalette": "c70cities:building_carservice1_floor1_palette_270",
  "xsize": 16,
  "zsize": 16,
  "slices": [
    [
      "                ",
      " aeeeeeeea    a ",
      " effffffccbbbb  ",
      " eggggffccbbbb  ",
      " egbbhffccbb    ",
      " aghh!ffcabb  a ",
      " eggggffcdHH    ",
      " egiigffcd      ",
      " eggggffcd      ",
      " affffffca    a ",
      " ejfffffcd      ",
      " edcffffcd      ",
      "  ddcfffcd      ",
      "   ddcffca    a ",
      "    eeeeee      ",
      "                "
    ],
    [
      "                ",
      " aesssssealkkka ",
      " e   ww  m    k ",
      " e            k ",
      " e            k ",
      " ax  x   a    a ",
      " epyyp  ne    k ",
      " eyCCy  nebb  k ",
      " epyyA  oeHH  k ",
      " aD    tpalkkka ",
      " ej     qe      ",
      " es     re      ",
      "  ss    re      ",
      "   ssBuura    a ",
      "    eeeeee      ",
      "                "
    ],
    [
      "                ",
      " aesssssea    a ",
      " e       m      ",
      " e       m      ",
      " e              ",
      " a       a    a ",
      " eKL J   e      ",
      " eM  KI ne      ",
      " eKJ L   e      ",
      " aN      abbEaa ",
      " ej      eHH    ",
      " es     Fe      ",
      "  ss    Fe      ",
      "   ss    a    a ",
      "    eessse      ",
      "                "
    ],
    [
      "                ",
      " aesssssea    a ",
      " e       m      ",
      " e       m      ",
      " e       m      ",
      " a       a    a ",
      " ePOOO   e      ",
      " e   O   e      ",
      " ePOOO   e  HH  ",
      " a       a  bba ",
      " ej      e  bb  ",
      " es      ebbbb  ",
      "  ss     ebbbb  ",
      "   ss    a    a ",
      "    eeeeee      ",
      "                "
    ],
    [
      "                ",
      " aeQQQQQea    a ",
      " e       e      ",
      " e       e      ",
      " e       e      ",
      " a       akkkla ",
      " e       e  HHk ",
      " e       e  bbk ",
      " e       e    k ",
      " a       a    a ",
      " ej      e    k ",
      " es      e    k ",
      "  ss     e    k ",
      "   ss    akkkla ",
      "    eeeeee      ",
      "                "
    ],
    [
      "                ",
      " aeeeeeeea    a ",
      " ekkkkk  e      ",
      " ekkkkk  e      ",
      " ekkkkk  e  HH  ",
      " akkkkk  aaEbba ",
      " ekkkkk  e      ",
      " ekkkkk  e      ",
      " ekkkkk  e      ",
      " a kkkk  a    a ",
      " ej kkk  e      ",
      " es  kk  e      ",
      "  ss  k  e      ",
      "   ss    a    a ",
      "    eeeeee      ",
      "                "
    ]
  ]
}