{
  "name": "building_hotel2_floor2_180",
  "refpalette": "c70cities:building_hotel2_floor2_palette_180",
  "xsize": 16,
  "zsize": 16,
  "slices": [
    [
      "                ",
      "              a ",
      "    dddddddddda ",
      "    dccccccccca ",
      "    dccccccccca ",
      "    dccccccccca ",
      "    dcccccccc!a ",
      "    dccc!ccccca ",
      "    dcccccccc!a ",
      "    dccccccccca ",
      "    dccccccccca ",
      "    dcccccccc=a ",
      "    dccccccccba ",
      "    dccccccccba ",
      " aaaaaaaaaaaaaa ",
      "                "
    ],
    [
      "                ",
      "              a ",
      "    ffffffffffa ",
      "    f      BAya ",
      "    f  xx     a ",
      "    f wuu     a ",
      "    faaaaa tt=a ",
      "    fss pa aaaa ",
      "    f   ra q pa ",
      "    f   oa anma ",
      "    fj iha alka ",
      "    fj ihagaa=a ",
      "    f    a   ba ",
      "    f    e   ba ",
      " aaaaaaaaaaaaaa ",
      "                "
    ],
    [
      "                ",
      "              a ",
      "    ffffffffffa ",
      "    f       J a ",
      "    f         a ",
      "    f         a ",
      "    faaaaa   Ia ",
      "    f F  a aaaa ",
      "    f    a E  a ",
      "    f    a a  a ",
      "    f    a a  a ",
      "    f    aDaa=a ",
      "    f    a   ba ",
      "    f    C   ba ",
      " aaaaaaaaaaaaaa ",
      "                "
    ],
    [
      "                ",
      "              a ",
      "    ffffffffffa ",
      "    f         a ",
      "    f         a ",
      "    f         a ",
      "    faaaaa LLKa ",
      "    f    a aaaa ",
      "    f    a a  a ",
      "    f    a a  a ",
      "    f    a a  a ",
      "    f    aaaa=a ",
      "    f    a   ba ",
      "    f    a   ba ",
      " aaaaaaaaaaaaaa ",
      "                "
    ],
    [
      "                ",
      "              a ",
      "    ffffffffffa ",
      "    f         a ",
      "    f         a ",
      "    f         a ",
      "    faaaaa   Na ",
      "    f    a aaaa ",
      "    f    a a  a ",
      "    f    a a  a ",
      "    f    a a  a ",
      "    f    aaaa=a ",
      "    f    a M ba ",
      "    f    a M ba ",
      " aaaaaaaaaaaaaa ",
      "                "
    ],
    [
      "                ",
      "              a ",
      "    JJJJJJJJJJa ",
      "    JOOOOOOOOOa ",
      "    JOOOOOOOOOa ",
      "    JOOOOOOOOOa ",
      "    JOaaaaOOOOa ",
      "    JOOOOaOaaaa ",
      "    JOOOOaOaOOa ",
      "    JOOOOaOaOOa ",
      "    JOOOOaOaOOa ",
      "    JOOOOaaaa=a ",
      "    JOOOOaOOOba ",
      "    JOOOOaOOOba ",
      " aaaaaaaaaaaaaa ",
      "                "
    ]
  ]
}