{
  "name": "building_hotel3_floor2_180",
  "refpalette": "c70cities:building_hotel3_floor2_palette_180",
  "xsize": 16,
  "zsize": 16,
  "slices": [
    [
      "                ",
      "  a a a a a a   ",
      "  bbbbbbbbbbbba ",
      " abccccccccccb  ",
      "  bceeeeeeeecba ",
      " abceffffffecb  ",
      "  bceffffffecba ",
      " abceffffffecb  ",
      "  bcefff!ffecba ",
      " abceffffffecb  ",
      "  bceffffffecba ",
      " abceeeeeeeecb  ",
      "  bccccddccccba ",
      " abbbbbbbbbbbb  ",
      "   a a a a a a  ",
      "                "
    ],
    [
      "                ",
      "  a a a a a a   ",
      "  bbbbbbbbbbbba ",
      " ab          b  ",
      "  b rmmmmmmr ba ",
      " ab m    q e b  ",
      "  b m pp  oe ba ",
      " ab m nn   e b  ",
      "  b m ii   e ba ",
      " ab m lki  e b  ",
      "  b e ijihhe ba ",
      " ab egeeeeee b  ",
      "  b    dd    ba ",
      " abbbbbbbbbbbb  ",
      "   a a a a a a  ",
      "                "
    ],
    [
      "                ",
      "  a a a a a a   ",
      "  bbbbbbbbbbbba ",
      " ab          b  ",
      "  b r      r ba ",
      " ab      wwe b  ",
      "  b        t ba ",
      " ab        t b  ",
      "  b   ii   t ba ",
      " ab   u i  t b  ",
      "  b e i i  e ba ",
      " ab eseeeeee b  ",
      "  b    dd    ba ",
      " abbbbbbbbbbbb  ",
      "   a a a a a a  ",
      "                "
    ],
    [
      "                ",
      "  a a a a a a   ",
      "  bbbbbbbbbbbba ",
      " ab          b  ",
      "  b r      r ba ",
      " ab        e b  ",
      "  b        e ba ",
      " ab        e b  ",
      "  b   ii   e ba ",
      " ab   i i  e b  ",
      "  b e i iwwe ba ",
      " ab eeeeeeee b  ",
      "  b    dd    ba ",
      " abbbbbbbbbbbb  ",
      "   a a a a a a  ",
      "                "
    ],
    [
      "                ",
      "  a a a a a a   ",
      "  bbbbbbbbbbbba ",
      " ab          b  ",
      "  b r      r ba ",
      " ab        e b  ",
      "  b        e ba ",
      " ab        e b  ",
      "  b   iiiiie ba ",
      " ab   i i  e b  ",
      "  b e i i  e ba ",
      " ab eeeeeeee b  ",
      "  b    dd    ba ",
      " abbbbbbbbbbbb  ",
      "   a a a a a a  ",
      "                "
    ],
    [
      "                ",
      "  a a a a a a   ",
      "  bbbbbbbbbbbba ",
      " ab          b  ",
      "  b eeeeeeee ba ",
      " ab exxxxxxe b  ",
      "  b exxxxxxe ba ",
      " ab exxxxxxe b  ",
      "  b exxxxxxe ba ",
      " ab exxxxxxe b  ",
      "  b exxxxxxe ba ",
      " ab eeeeeeee b  ",
      "  b    dd    ba ",
      " abbbbbbbbbbbb  ",
      "   a a a a a a  ",
      "                "
    ]
  ]
}