{
  "name": "building_policeoffice1_ground_270",
  "refpalette": "c70cities:building_policeoffice1_ground_palette_270",
  "xsize": 16,
  "zsize": 16,
  "slices": [
    [
      "GGGGGGGGGGGGGGGG",
      "GeeeeGGGGGGGGGGG",
      "GeffeaaaaaaaaaaG",
      "GebbbbbbbbbbbbaG",
      "GebbbbbbbbbbbbaG",
      "GebbbbbbbbbbbbaG",
      "GebbbbbbbbbbbbaG",
      "Gebbbbbbbb!bbbaG",
      "GebbbbbbbbbbbbaG",
      "gebbbbbbbbbbbbaG",
      "GebbbbbbbbbbbbaG",
      "GebbeaaaaaaaaaaG",
      "GegGeGGccGGGGGGG",
      "geGGedGccGHHHHHG",
      "GeGGeGGcGGHHHHHG",
      "GeeeeGGGcGHHHHHG"
    ],
    [
      "                ",
      " eeeehhhhhhhhhh ",
      " xffeaaaaaaaaaa ",
      " e  p        ia ",
      " e  q         a ",
      " eaaa     lk ja ",
      " xss      l  ja ",
      " est      l  ja ",
      " est      lk ja ",
      "tew           a ",
      " y   m    m  ia ",
      " euueaaonaaaaaa ",
      "  t eh          ",
      "e   rh          ",
      " y  eh          ",
      " eeeeh          "
    ],
    [
      "                ",
      " eeee           ",
      " xffeaaaaaaaaaa ",
      " e  D        ia ",
      " e  E         u ",
      " eaaa        ja ",
      " x           ja ",
      " e           ja ",
      " e           ja ",
      " e            u ",
      " y   A    A  ia ",
      "    eaaCBaauuaa ",
      "    e           ",
      "    r           ",
      " x  e           ",
      " eeee           "
    ],
    [
      "                ",
      " eeee           ",
      " xffeaaaaaaaaaa ",
      " e  a        ia ",
      " e  a         u ",
      " easa        ja ",
      " x            a ",
      " e            a ",
      " e           ja ",
      " e            u ",
      " x   A    A  ia ",
      " e  eaaaaaaaaaa ",
      "    e           ",
      " y  r           ",
      " x  e           ",
      " eeee           "
    ],
    [
      "                ",
      " eeee           ",
      " xffeaaaaaaaaaa ",
      " e  a         a ",
      " e  a         a ",
      " eaaa        ja ",
      " x           ja ",
      " e           ja ",
      " e           ja ",
      " e            a ",
      " x            a ",
      " e  eaaauuuuaaa ",
      " y  e           ",
      " e  r           ",
      " x  e           ",
      " eeee           "
    ],
    [
      "                ",
      " eeee           ",
      " xffeFFFFFFFFFF ",
      " eIIaIIIIIIIIIF ",
      " eIIaIIIIIIIIIF ",
      " eaaaIIIIIIIIIF ",
      " xIIIIIIIIIIIIF ",
      " eIIIIIIIIIIIIF ",
      " eIIIIIIIIIIIIF ",
      " eIIIIIIIIIIIIF ",
      " xIIIIIIIIIIIIF ",
      " eIIeFFFFFFFFFF ",
      " e  e           ",
      " e  r           ",
      " x  e           ",
      " eeee           "
    ]
  ]
}