{
  "name": "building_office5_floor1_180",
  "refpalette": "c70cities:building_office5_floor1_palette_180",
  "xsize": 16,
  "zsize": 16,
  "slices": [
    [
      "                ",
      "                ",
      "  dbdbdbdbdbdd  ",
      "  beeeeeeeeeeb  ",
      "  deeeeeeeeeed  ",
      "  beeeeeeeeeeb  ",
      "  deee!eeeeeed  ",
      "  beeeeeeeeeeb  ",
      "  deeeeeeeeeed  ",
      "  beeeeffeeeeb  ",
      "  ddddddddeedd  ",
      "    accccccca   ",
      "    bcccccccb   ",
      "    ababababa   ",
      "                ",
      "                "
    ],
    [
      "                ",
      "                ",
      "  dbdbdbdbdbdd  ",
      "  b     o    b  ",
      "  d nmml mml d  ",
      "  b  mm  mm  b  ",
      "  d nmm nmm ld  ",
      "  b   k      b  ",
      "  d          d  ",
      "  b  j ffi  gb  ",
      "  dddddddd  dd  ",
      "    ahh!g   a   ",
      "    b       b   ",
      "    ababababa   ",
      "                ",
      "                "
    ],
    [
      "                ",
      "                ",
      "  dbdbdbdbdbdd  ",
      "  b          b  ",
      "  d  t    t  d  ",
      "  b          b  ",
      "  d      t   d  ",
      "  b          b  ",
      "  d          d  ",
      "  b  s ff    b  ",
      "  ddrddddd  dd  ",
      "    aq  pp  a   ",
      "    b       b   ",
      "    ababababa   ",
      "                ",
      "                "
    ],
    [
      "                ",
      "                ",
      "  dbdbdbdbdbdd  ",
      "  b          b  ",
      "  d          d  ",
      "  b          b  ",
      "  d          d  ",
      "  b          b  ",
      "  d          d  ",
      "  b    ff    b  ",
      "  dduddddduudd  ",
      "    a       a   ",
      "    b       b   ",
      "    ababababa   ",
      "                ",
      "                "
    ],
    [
      "                ",
      "                ",
      "  dbdbdbdbdbdd  ",
      "  b          b  ",
      "  d          d  ",
      "  b          b  ",
      "  d          d  ",
      "  b          b  ",
      "  d          d  ",
      "  b    ff    b  ",
      "  dddddddddddd  ",
      "    a       a   ",
      "    b       b   ",
      "    ababababa   ",
      "                ",
      "                "
    ],
    [
      "                ",
      "                ",
      "  dbdbdbdbdbdd  ",
      "  bwwwwwwwwwwb  ",
      "  dwwwwwwwwwwd  ",
      "  bwwwwwwwwwwb  ",
      "  dwwwwwwwwwwd  ",
      "  bwwwwwwwwwwb  ",
      "  dwwwwwwwwwwd  ",
      "  bwwwwffwwwwb  ",
      "  dddddddddddd  ",
      "    a       a   ",
      "    b       b   ",
      "    ababababa   ",
      "                ",
      "                "
    ]
  ]
}