{
  "name": "building_office5_ground",
  "refpalette": "c70cities:building_office5_ground_palette",
  "xsize": 16,
  "zsize": 16,
  "slices": [
    [
      "GGGGGGGGGGGGGGGG",
      "GaaaaaaaaaaaaaaG",
      "GaaaaaaaaaaaaaaG",
      "GaaaaaaGGaaaaaaG",
      "GaaaaaaGGaaaaaaG",
      "GaaaaaaaaaaaaaaG",
      "Gaaaaaaaa!aaaaaG",
      "GaaaaaaaaaaaaaaG",
      "GaaaaaaaaaaaaaaG",
      "GaaaaaaaaaaaaaaG",
      "GaaaaaaaaaaaaaaG",
      "GaaaaaaaaaaaaaaG",
      "GaaaaaaaaaaaaaaG",
      "GaaaaaaaaaaaaaaG",
      "GaaaaaaaaaaaaaaG",
      "GGGGGGGGGGGGGGGG"
    ],
    [
      "                ",
      " bc  cc  cc  cb ",
      " cdeeddeeddeedc ",
      "  e fghijhgf e  ",
      "  e   hkih   e  ",
      " cb llbccbll bc ",
      " cd mm nn mm dc ",
      "  e          o  ",
      "  e          p  ",
      " cd   q  q   dc ",
      " cd  rsssst  dc ",
      "  e  u    w  e  ",
      "  ex  y  y  xe  ",
      " cdeeddeeddeedc ",
      " bc  cc  cc  cb ",
      "                "
    ],
    [
      "                ",
      " bc  cc  cc  cb ",
      " cdeeddeeddeedc ",
      "  e          e  ",
      "  e    A     e  ",
      " cb   bccb   bc ",
      " cd    nn    dc ",
      "  e          B  ",
      "  e          C  ",
      " cd          dc ",
      " cd   D  D   dc ",
      "  e          e  ",
      "  em        me  ",
      " cdeeddeeddeedc ",
      " bc  cc  cc  cb ",
      "                "
    ],
    [
      "                ",
      " bc  cc  cc  cb ",
      " cdeeddeeddeedc ",
      "  e          e  ",
      "  e          e  ",
      " cb   bccb   bc ",
      " cd    nn    dc ",
      "  e          e  ",
      "  e     E    e  ",
      " cd          dc ",
      " cd          dc ",
      "  e          e  ",
      "  em        me  ",
      " cdeeddeeddeedc ",
      " bc  cc  cc  cb ",
      "                "
    ],
    [
      "                ",
      " bcFFccFFccFFcb ",
      " cddddddddddddc ",
      " Fd          dF ",
      " Fd          dF ",
      " cccccccccccccc ",
      " cd    nn    dc ",
      " Fd    EI    dF ",
      " Fd    IE    dF ",
      " cd          dc ",
      " cd          dc ",
      " Fd          dF ",
      " Fd          dF ",
      " cddddddddddddc ",
      " bcFFccFFccFFcb ",
      "                "
    ],
    [
      "                ",
      " bccccccccccccb ",
      " cccccccccccccc ",
      " cccccccccccccc ",
      " cccccccccccccc ",
      " cccccccccccccc ",
      " ccJJJKnnKJJJcc ",
      " ccJJJ LL JJJcc ",
      " ccJJJ LL JJJcc ",
      " ccJJJK  KJJJcc ",
      " ccJJJJJJJJJJcc ",
      " ccJJJJJJJJJJcc ",
      " ccJJJJJJJJJJcc ",
      " cccccccccccccc ",
      " bccccccccccccb ",
      "                "
    ]
  ]
}