{
  "name": "building_hotel2_floor1_90",
  "refpalette": "c70cities:building_hotel2_floor1_palette_90",
  "xsize": 16,
  "zsize": 16,
  "slices": [
    [
      "                ",
      " a              ",
      " a              ",
      " a              ",
      " adddddddddddd  ",
      " a!ccccccccccd  ",
      " acccccccccccd  ",
      " acccccccccccd  ",
      " acccccccccccd  ",
      " acccccccccccd  ",
      " acccccccccccd  ",
      " accc!cccccccd  ",
      " acccccccccccd  ",
      " abb=ccccccccd  ",
      " aaaaaaaaaaaaaa ",
      "                "
    ],
    [
      "                ",
      " a              ",
      " a              ",
      " a              ",
      " ahhhhhhhhhhhh  ",
      " agj n j  uu h  ",
      " af j        h  ",
      " af  n    tt h  ",
      " a        ss h  ",
      " a     j  rr h  ",
      " aeiaaaa     h  ",
      " a  am p     h  ",
      " a  al a =q= h  ",
      " abb=koa === h  ",
      " aaaaaaaaaaaaaa ",
      "                "
    ],
    [
      "                ",
      " a              ",
      " a              ",
      " a              ",
      " ahhhhhhhhhhhh  ",
      " a yy  C     h  ",
      " a  y        h  ",
      " a  y        h  ",
      " a           h  ",
      " a     C  rr h  ",
      " awxaaaa     h  ",
      " a  a  B     h  ",
      " a  a  a     h  ",
      " abb=A a     h  ",
      " aaaaaaaaaaaaaa ",
      "                "
    ],
    [
      "                ",
      " a              ",
      " a              ",
      " a              ",
      " ahhhhhhhhhhhh  ",
      " aD    C     h  ",
      " aD          h  ",
      " aD          h  ",
      " a           h  ",
      " a     C     h  ",
      " aaaaaaa     h  ",
      " a  a  a     h  ",
      " a  a  a     h  ",
      " abb=E a     h  ",
      " aaaaaaaaaaaaaa ",
      "                "
    ],
    [
      "                ",
      " a              ",
      " a              ",
      " a              ",
      " ahhhhhhhhhhhh  ",
      " a           h  ",
      " aF          h  ",
      " a           h  ",
      " a           h  ",
      " a           h  ",
      " aaaaaaa     h  ",
      " a  a  a     h  ",
      " a  a  a     h  ",
      " abb=  a     h  ",
      " aaaaaaaaaaaaaa ",
      "                "
    ],
    [
      "                ",
      " a              ",
      " a              ",
      " a              ",
      " ayyyyyyyyyyyy  ",
      " aIIIIIIIIIIIy  ",
      " aIIIIIIIIIIIy  ",
      " aIIIIIIIIIIIy  ",
      " aIIIIIIIIIIIy  ",
      " aIIIIIIIIIIIy  ",
      " aaaaaaaIIIIIy  ",
      " aIIaIIaIIIIIy  ",
      " aIIaIIaIIIIIy  ",
      " abb=IIaIIIIIy  ",
      " aaaaaaaaaaaaaa ",
      "                "
    ]
  ]
}