{
  "name": "building_restaurant1_floor1",
  "refpalette": "c70cities:building_restaurant1_floor1_palette",
  "xsize": 16,
  "zsize": 16,
  "slices": [
    [
      "                ",
      "  aaaaaaa       ",
      "  abb bc        ",
      "  abbdbc        ",
      " ==bb======eeee ",
      " =Gbbbbbbbbbbbe ",
      " =Gbbbbbbbbbbbe ",
      " =Gbbbbbbbbbbbe ",
      " =Gbbbbbbbbbb!= ",
      " ===bbbbbb===== ",
      "  fgggggggggh   ",
      "  fgggggggggh   ",
      "  fgggggggggh   ",
      "  fgggggggggh   ",
      "  ffffffffffff  ",
      "                "
    ],
    [
      "                ",
      "  aaaaaaa       ",
      "  a   ic        ",
      "  a  dic        ",
      " ==jk========== ",
      " =lm  nop qr s= ",
      " =lm      t  u= ",
      " =lm   op q  s= ",
      " =lm  w   qxyx= ",
      " ===     A===== ",
      "  fB   CA BD    ",
      "  fCE    EFD    ",
      "  f        D    ",
      "  fCE I CEID    ",
      "  ffffffffffff  ",
      "   JKLLLLMJJNJ  "
    ],
    [
      "                ",
      "  aaaaaaa       ",
      "  a   ic        ",
      "  e  dic        ",
      " ==OP====cccc== ",
      " =Q       RS  = ",
      " =Q          T= ",
      " =Q    U  A   = ",
      " =Q       AV  = ",
      " ===      ===== ",
      "  fQ      QD    ",
      "  f        D    ",
      "  f        D    ",
      "  f        D    ",
      "  ffWWWWWWffWf  ",
      "                "
    ],
    [
      "                ",
      "  aaaaaaa       ",
      "  a   ic        ",
      "  e  dic        ",
      " ============== ",
      " =           X= ",
      " Y     Z      = ",
      " Y            e ",
      " =            e ",
      " ===      ===== ",
      "  fQ      QD    ",
      "  f        D    ",
      "  f        D    ",
      "  f        D    ",
      "  ff      ff f  ",
      "                "
    ],
    [
      "                ",
      "  aaaaaaa       ",
      "  a   ic        ",
      "  a  dic        ",
      " ============== ",
      " =           0= ",
      " =     1    1 = ",
      " =            = ",
      " =            = ",
      " ============== ",
      "  f        D    ",
      "  f        D    ",
      "  f      Z D    ",
      "  f        D    ",
      "  ff      ff f  ",
      "                "
    ],
    [
      "                ",
      "  aaaaaaa       ",
      "  a   ic        ",
      "  a2 dic        ",
      " ============== ",
      " =333333333333= ",
      " =333333333333= ",
      " =333333333333= ",
      " =333333333333= ",
      " ============== ",
      "  f        D    ",
      "  f        D    ",
      "  f 1    1 D    ",
      "  f        D    ",
      "  ffffffffffff  ",
      "                "
    ]
  ]
}