{
  "name": "building_office3_floor2",
  "refpalette": "c70cities:building_office3_floor2_palette",
  "xsize": 16,
  "zsize": 16,
  "slices": [
    [
      "                ",
      " aabaabaabaabaa ",
      " acccccccccccca ",
      " bccccccccccccb ",
      " acccccccccccca ",
      " accc!cccccccca ",
      " bccccccccccccb ",
      " acccccvdccccca ",
      " acccccvdccccca ",
      " bccccccccccccb ",
      " acccccccccccca ",
      " acccccccccccca ",
      " bccccccccccccb ",
      " acccccccccccca ",
      " aabaabaabaabaa ",
      "                "
    ],
    [
      "                ",
      " eebeebeebeebee ",
      " ef          fe ",
      " b g        g b ",
      " e   h    h   e ",
      " e iii    iii e ",
      " b j        j b ",
      " e    kvd     e ",
      " e    kvd     e ",
      " b h        h b ",
      " e iii    iii e ",
      " e   j    j   e ",
      " b g        g b ",
      " ef          fe ",
      " eebeebeebeebee ",
      "                "
    ],
    [
      "                ",
      " llbllbllbllbll ",
      " lf          fl ",
      " b g        g b ",
      " l            l ",
      " l            l ",
      " b            b ",
      " l     vd     l ",
      " l     vd     l ",
      " b            b ",
      " l            l ",
      " l            l ",
      " b g        g b ",
      " lf          fl ",
      " llbllbllbllbll ",
      "                "
    ],
    [
      "                ",
      " llbllbllbllbll ",
      " l            l ",
      " b g        g b ",
      " l            l ",
      " l            l ",
      " b            b ",
      " l     vd     l ",
      " l     vd     l ",
      " b            b ",
      " l            l ",
      " l            l ",
      " b g        g b ",
      " l            l ",
      " llbllbllbllbll ",
      "                "
    ],
    [
      "                ",
      " llbllbllbllbll ",
      " l            l ",
      " b g        g b ",
      " l            l ",
      " l            l ",
      " b            b ",
      " l     vd     l ",
      " l     vd     l ",
      " b            b ",
      " l            l ",
      " l            l ",
      " b g        g b ",
      " l            l ",
      " llbllbllbllbll ",
      "                "
    ],
    [
      "                ",
      " llbllbllbllbll ",
      " lmmmmmmmmmmmml ",
      " bmgnnnnnnnngmb ",
      " lmnnnnnnnnnnml ",
      " lmnnnnnnnnnnml ",
      " bmnnnnnnnnnnmb ",
      " lmnnnnvdnnnnml ",
      " lmnnnnvdnnnnml ",
      " bmnnnnnnnnnnmb ",
      " lmnnnnnnnnnnml ",
      " lmnnnnnnnnnnml ",
      " bmgnnnnnnnngmb ",
      " lmmmmmmmmmmmml ",
      " llbllbllbllbll ",
      "                "
    ]
  ]
}