{
  "name": "building_restaurant2_ground_270",
  "refpalette": "c70cities:building_restaurant2_ground_palette_270",
  "xsize": 16,
  "zsize": 16,
  "slices": [
    [
      "GGGGGGaGaGGGGGGG",
      "GGGGGGGaabGGGGGG",
      "GGGGGGGbaGGGGGGG",
      "GGaaaaaaaaaabaGG",
      "GGccccccccccccGG",
      "GacgdeegdeegdcaG",
      "GaceeffeeffeecaG",
      "GacffgdffgdffcaG",
      "GacgdgdgdgdgdcaG",
      "GbcgdeegdeegdcbG",
      "GbceeffeeffeecaG",
      "GccccgdffgdccccG",
      "GccccgdgdgdccccG",
      "GccccaaaaaaccccG",
      "GccccbbaabaccccG",
      "GGGGGGGGGGGGGGGG"
    ],
    [
      "                ",
      "                ",
      "                ",
      "  msqom  msqom  ",
      " hmmmmm  mmmmmh ",
      " imp piIEip pmi ",
      " Rm          mj ",
      " Sm  tttttt  mk ",
      " Sm  JAAAAu  mk ",
      " Sm  Kmmmmw  mk ",
      " Tm  LBBBBx  ml ",
      " iiEi      iiii ",
      " iP iMCCFC r ni ",
      " iQOiiiiiiiinni ",
      " iiiiNDDDDyiiii ",
      "                "
    ],
    [
      "                ",
      "                ",
      "                ",
      "  mYYYm  mYYYm  ",
      " UmVVVm  mVVVmU ",
      " im   i74i   mi ",
      "  m          m  ",
      "  V          V  ",
      "  V  222220  V  ",
      "  V  911111  V  ",
      "  m   3 53   m  ",
      " ii4i      iiii ",
      " i  i@!86  Z Wi ",
      " i  iiiiiiii Xi ",
      " iiiiYYYYYYiiii ",
      "                "
    ],
    [
      "                ",
      "                ",
      "                ",
      "  mYYYm**mYYYm  ",
      " UmVVVm  mVVVmU ",
      " im   iiii   mi ",
      " Ym(        WmY ",
      " Ym)        %mY ",
      " Ym) ^^^^^^ %mY ",
      " Ym) &&&&&& %mY ",
      " Ym+        XmY ",
      " iiii      iiii ",
      " i  i      i #i ",
      " i  iiiiiiii $i ",
      " iVViYYYYYYiVVi ",
      "                "
    ],
    [
      "                ",
      "                ",
      "  [   [  [   [  ",
      "  m---m**m---m  ",
      "  miiim  miiim  ",
      " imiiiiiiiiiimi ",
      " -m{        ]m- ",
      " -m}        ]m- ",
      " -m}        ]m- ",
      " -m}        ]m- ",
      " -m}        ]m- ",
      " iiii      iiii ",
      " i  i      i  i ",
      " i  iiiiiiii  i ",
      " i--i------i--i ",
      "                "
    ],
    [
      "                ",
      " \\\\\\\\\\\\\\\\\\\\\\\\\\\\ ",
      " \\\\\\\\\\\\\\\\\\\\\\\\\\\\ ",
      " \\\\\\\\\\\\\\\\\\\\\\\\\\\\ ",
      " \\\\\\\\\\\\\\\\\\\\\\\\\\\\ ",
      " im||||||||||mi ",
      " im::;::::;::mi ",
      " im::;::::;::mi ",
      " im::;::::;::mi ",
      " im::;::::;::mi ",
      " im::;::::;::mi ",
      " i||||||||||||i ",
      " i``i||||||i``i ",
      " i``iiiiiiii``i ",
      " iiii||||||iiii ",
      "                "
    ]
  ]
}