{
  "name": "building_apartment1_floor2_180",
  "refpalette": "c70cities:building_apartment1_floor2_palette_180",
  "xsize": 16,
  "zsize": 16,
  "slices": [
    [
      "                ",
      "      aaaaaaaaa ",
      "  ihgdbbbbbbbba ",
      "  ef  bbbbbbbba ",
      "  ebb bbbbbbbba ",
      "  dbbcbbbbbbbba ",
      " abbbbbbbbbbbba ",
      " abbbbbbbbbbbba ",
      " abbbbbbbbbbbba ",
      " abbbbbbbbbbbba ",
      " abbbbbbbbbbbba ",
      " abbbbbbbbbbbba ",
      " abbbbbbbbbbbba ",
      " abbbbbbbbbbbba ",
      " aaaaaaaaaaaaaa ",
      "                "
    ],
    [
      "                ",
      "      WWWWWWWWV ",
      "  ddUUq      Tm ",
      "  dS  qR N   Qm ",
      "  dP  qO N   Mm ",
      "  d   q     Lrm ",
      " tqKqqqJJI Dqqm ",
      " t  F      F  m ",
      " tEEq      Drsm ",
      " tqqqqqqyqCqqqm ",
      " tBA     q BA m ",
      " t   xxyxq    m ",
      " tu  q   w uu m ",
      " ton!q srqpoonm ",
      " lkkkkkkkkkkkkj ",
      "                "
    ],
    [
      "                ",
      "      q4XXXXX42 ",
      "  ddddq      $4 ",
      "  dP# q9     @4 ",
      "  U   q9      4 ",
      "  h   q       4 ",
      " qq8qqq7   Dqq2 ",
      " q  6      6  4 ",
      " q  q      D 54 ",
      " qqqqqqq1q3qqq2 ",
      " q       q    q ",
      " X   xx1xq    X ",
      " X   q   0    X ",
      " X   q Z q   YX ",
      " qqqqqqqqqqqqqq ",
      "                "
    ],
    [
      "                ",
      "      q4XXXXX42 ",
      "  `|ddq \\}{][ X ",
      "  d -Sq+      X ",
      "  d   q+      X ",
      "  d   q       4 ",
      " qqqqqq    Dqq2 ",
      " X  q      D  X ",
      " X  q      D  X ",
      " qqqqqqqqqqqqq2 ",
      " q       q    q ",
      " X)  xxxxq   (X ",
      " X*  q   q   &X ",
      " X^  q   q   %X ",
      " qqXXqqXXqqXXqq ",
      "                "
    ],
    [
      "                ",
      "      q44444442 ",
      "  dUUeq       4 ",
      "  |  -q       4 ",
      "  |  ;q       4 ",
      "  |   q       4 ",
      " qqqqqq  : Dqq2 ",
      " 4 fq      D  4 ",
      " 4  q      D  4 ",
      " qqqqqqqqqqqqq2 ",
      " q       q    q ",
      " 4   xxxxq    4 ",
      " 4   q   q    4 ",
      " 4   q   q    4 ",
      " qqkkqqkkqqkkqq ",
      "                "
    ],
    [
      "                ",
      "      qqqqqqqqq ",
      "  ddddqdddddddq ",
      "  d   qdddddddq ",
      "  d  cqdddddddq ",
      "  d  Sqdddddddq ",
      " qqqqqqdddddddq ",
      " qddqddddddd''q ",
      " qddqddddddd''q ",
      " qqqqqqqqqqqqqq ",
      " qdddddddqddddq ",
      " qdddddddqddddq ",
      " qdddd'''qddddq ",
      " qdddd'''qddddq ",
      " qqqqqqqqqqqqqq ",
      "                "
    ]
  ]
}