{
  "name": "building_factory2_floor1_180",
  "refpalette": "c70cities:building_factory2_floor1_palette_180",
  "xsize": 16,
  "zsize": 16,
  "slices": [
    [
      "                ",
      " ajjjjjjjjjja   ",
      " eddddddddddc   ",
      " edf     ffdc   ",
      " ed        dc   ",
      " idghhgghhgdc   ",
      " id        dc   ",
      " ed       fdc   ",
      " ed        dc   ",
      " id       fdc   ",
      " idghhgghhgdc   ",
      " ed        dc   ",
      " ed       fdc   ",
      " eddddddddddc   ",
      " abbbbbbbbbba   ",
      "                "
    ],
    [
      "                ",
      " a        llkk  ",
      "  mmmmmmmmqqkk  ",
      "  mff   nnndkk  ",
      "  mf    nnndkk  ",
      " im p pp podkk  ",
      " im       odkk  ",
      "  m     nnndkk  ",
      "  m     nnndkk  ",
      " im       odkk  ",
      " imfp pp podkk  ",
      "  m     nnndkk  ",
      "  mf    nnndkk  ",
      "  mmmmmmmmmmkk  ",
      " a        llkk  ",
      "                "
    ],
    [
      "                ",
      " a    llkk      ",
      "  mmmmqqkk      ",
      "  m  nnn        ",
      "  mrrnnn        ",
      " imoodddss      ",
      " imrrdddss      ",
      "  m  nnn        ",
      "  mf nnn        ",
      " imrrdddss      ",
      " imoodddss      ",
      "  mrrnnn        ",
      "  m  nnn        ",
      "  mmmmqqkk      ",
      " a    llkk      ",
      "                "
    ],
    [
      "                ",
      " allkk          ",
      " eqqkk          ",
      " edds           ",
      " edds           ",
      " iiii           ",
      " iiii           ",
      " edds           ",
      " edds           ",
      " iiii           ",
      " iiii           ",
      " edds           ",
      " edds           ",
      " eqqkk          ",
      " allkk          ",
      "                "
    ],
    [
      "                ",
      "kk              ",
      "kk              ",
      "kk              ",
      "kk              ",
      "kkiw            ",
      "kkut            ",
      "kk  ~           ",
      "kk              ",
      "kkiw            ",
      "kkut            ",
      "kk              ",
      "kk              ",
      "kk              ",
      "kk              ",
      "                "
    ],
    [
      "                ",
      "                ",
      "                ",
      "                ",
      "                ",
      "                ",
      "                ",
      "    ~           ",
      "                ",
      "                ",
      "                ",
      "                ",
      "                ",
      "                ",
      "                ",
      "                "
    ]
  ]
}