{
  "name": "building_residential3_ground",
  "refpalette": "c70cities:building_residential3_ground_palette",
  "xsize": 16,
  "zsize": 16,
  "slices": [
    [
      "GGGGGGGGGGGGGGGG",
      "GGGGGGGGGGGGGGGG",
      "GGaaaaaaaaaaaaGG",
      "GGabbbbbbbbbbaGG",
      "GGabbbbbbbbbbaGG",
      "GGabbbbbbbbbbaGG",
      "GGabbbbbbbbbbaGG",
      "GGaabbbbbbbbbaGG",
      "GGGcddddbbbbbaGG",
      "GGGcddddbbbbbaGG",
      "GGGcddddbbbbbaGG",
      "GGGcddddbbbbbaGG",
      "GGGcccccabbbbaGG",
      "GGGGGGGGaaaaaaGG",
      "GGGGGGGGGGGGGGGG",
      "GGGGGGGGGGGGGGGG"
    ],
    [
      "effffgffffgffffe",
      "f              f",
      "f hhhhhhhhhhhh f",
      "e i   j  !k  h f",
      "  l       k mh f",
      "  n       opoh g",
      "e i qq       h f",
      "f hhrrs t   uh f",
      "f  c    t   uh f",
      "f wc    h    h f",
      "g wc    hx  yh e",
      "f wcABCDhx  Eh f",
      "f wccccch    h f",
      "f wwwwwwhiFFih f",
      "f              f",
      "effffgffffgffffe"
    ],
    [
      "effffgffffgffffe",
      "f              f",
      "f hhFFFhhFhIhh f",
      "e i    j  k  h f",
      "  J       k KI f",
      "  L       oMoh g",
      "e i          F f",
      "f hh    t   Nh f",
      "f  c    t   Oh f",
      "f  P    h    F f",
      "g  P    hQ   F e",
      "f  cR  ShQ   F f",
      "f  ccPPch    h f",
      "f       hiFFih f",
      "f              f",
      "effffgffffgffffe"
    ],
    [
      "                ",
      "                ",
      "  hhTTThhThThh  ",
      "U i     j k  h  ",
      "  V       k  W  ",
      "  V       oooh  ",
      "  i          W  ",
      "  hh    t    h  ",
      "  Xc    t    h  ",
      "  Xc    h    W  ",
      "  Xc    h    W U",
      "  Xc    h    W  ",
      "  Xccccch    h  ",
      "  XXXXXXhiYYih  ",
      "                ",
      "                "
    ],
    [
      "                ",
      "                ",
      "  hhhhhhhhhhhh  ",
      "  hbbb   jbbbh  ",
      "  hbbbbbbbbbbh  ",
      "  hbbbbbbbbbbh  ",
      "  hbbbbbbbbbbh  ",
      "  hhbbbbbbbbbh  ",
      "  Z0    bbbbbh  ",
      "  Z0    bbbbbh  ",
      "  Z0    bbbbbh  ",
      "  Z0    bbbbbh  ",
      "  Z12222hbbbbh  ",
      "  ZZZZZZhhhhhh  ",
      "                ",
      "                "
    ],
    [
      "                ",
      "                ",
      "  hhTTThhTTThh  ",
      "  F334       F  ",
      "  F   5555   F  ",
      "  F          F  ",
      "  F667     8 F  ",
      "  hh99999 @#$h  ",
      "  Zc   %9 iiih  ",
      "  Zc    9 ^^7W  ",
      "  Zc    9 ^&*W  ",
      "  Zc    9 ^&*W  ",
      "  Zccccch ^^ h  ",
      "  ZZZZZZhFFFFh  ",
      "                ",
      "                "
    ]
  ]
}