{
  "name": "building_restaurant1_base1_180",
  "refpalette": "c70cities:building_restaurant1_base1_palette_180",
  "xsize": 16,
  "zsize": 16,
  "slices": [
    [
      "vvvvvvvvvvvvvvvv",
      "v=bbbbbbbbbbbb=v",
      "v=bc!cccccdddb=v",
      "v=bcccccccdddb=v",
      "v=bcccccccdddb=v",
      "v=bccccccccccb=v",
      "v=vvvvvvvvvvvv=v",
      "v=vvvvvvvvvvvv=v",
      "v=vvvvvvvvvvvv=v",
      "v=vvvvv!vvvvvv=v",
      "v=vvvvvvvvvvvv=v",
      "v=vvvvvvvvvvvv=v",
      "v=vvvvvvvvvvvv=v",
      "v=vvvvvvvvvvva=v",
      "v==============v",
      "vvvvvvvvvvvvvvvv"
    ],
    [
      "vvvvvvvvvvvvvvvv",
      "v=bbbbbbbbbbbb=v",
      "v=bwut t dsssb=v",
      "v=bt r   dsssb=v",
      "v=b r  r dsssb=v",
      "v=bppr p pdddb=v",
      "v=q p       kh=v",
      "v=f   ll     k=v",
      "v=   lllll    =v",
      "v=   ollln    =v",
      "v=    nll    j=v",
      "v=m     l  jjj=v",
      "v=ik        jj=v",
      "v=ihgf      ea=v",
      "v==============v",
      "vvvvvvvvvvvvvvvv"
    ],
    [
      "vvvvvvvvvvvvvvvv",
      "v=bbbbbbbbbbbb=v",
      "v=bt         b=v",
      "v=b          b=v",
      "v=b          b=v",
      "v=bpp     pppb=v",
      "v=           g=v",
      "v=f           =v",
      "v=    lll     =v",
      "v=     ll     =v",
      "v=     l      =v",
      "v=           j=v",
      "v=x          j=v",
      "v=kg        ea=v",
      "v==============v",
      "vvvvvvvvvvvvvvvv"
    ],
    [
      "vvvvvvvvvvvvvvvv",
      "v=bbbbbbbbbbbb=v",
      "v=b         yb=v",
      "v=b          b=v",
      "v=b          b=v",
      "v=bp       ppb=v",
      "v=            =v",
      "v=            =v",
      "v=     l      =v",
      "v=     n      =v",
      "v=            =v",
      "v=            =v",
      "v=           j=v",
      "v=          ea=v",
      "v==============v",
      "vvvvvvvvvvvvvvvv"
    ],
    [
      "vvvvvvvvvvvvvvvv",
      "v=bbbbbbbbbbbb=v",
      "v=b         Ab=v",
      "v=b          b=v",
      "v=b          b=v",
      "v=bppp ppppppb=v",
      "v=      p     =v",
      "v=            =v",
      "v=            =v",
      "v=            =v",
      "v=            =v",
      "v=            =v",
      "v=            =v",
      "v=          ea=v",
      "v==============v",
      "vvvvvvvvvvvvvvvv"
    ],
    [
      "vvvvvvvvvvvvvvvv",
      "v=bbbbbbbbbbbb=v",
      "v=bdddddddddCb=v",
      "v=bddddddddddb=v",
      "v=bddddddddddb=v",
      "v=bddddddddddb=v",
      "v=BBBBBBBBBBBB=v",
      "v=BBBBBBBBBBBB=v",
      "v=BBBBBBBBBBBB=v",
      "v=BBBBBBBBBBBB=v",
      "v=BBBBBBBBBBBB=v",
      "v=BBBBBBBBBBBB=v",
      "v=BBBBBBBBBBBB=v",
      "v=BBBBBBBBBBea=v",
      "v==============v",
      "vvvvvvvvvvvvvvvv"
    ]
  ]
}