{
  "name": "building_office3_floor1_90",
  "refpalette": "c70cities:building_office3_floor1_palette_90",
  "xsize": 16,
  "zsize": 16,
  "slices": [
    [
      "                ",
      " aabaabaabaabaa ",
      " acccccccccccca ",
      " bccccccccccccb ",
      " accccccccc!cca ",
      " acccccccccccca ",
      " bccccccccccccb ",
      " acccccddccccca ",
      " acccccvvccccca ",
      " bccccccccccccb ",
      " acccccccccccca ",
      " acccccccccccca ",
      " bccccccccccccb ",
      " acccccccccccca ",
      " aabaabaabaabaa ",
      "                "
    ],
    [
      "                ",
      " eebeebeebeebee ",
      " e            e ",
      " b f        f b ",
      " e         p  e ",
      " e  j     gp  e ",
      " b  ik     pk b ",
      " e g   dd gp  e ",
      " e   k vv  pp e ",
      " b gi  mn     b ",
      " e  h         e ",
      " e     ee     e ",
      " b f        f b ",
      " e    lhho    e ",
      " eebeebeebeebee ",
      "                "
    ],
    [
      "                ",
      " qqbqqbqqbqqbqq ",
      " q            q ",
      " b f        f b ",
      " q            q ",
      " q            q ",
      " b  r         b ",
      " q  r  dd     q ",
      " q  r  vv     q ",
      " b  r  ss     b ",
      " q            q ",
      " q            q ",
      " b f        f b ",
      " q            q ",
      " qqbqqbqqbqqbqq ",
      "                "
    ],
    [
      "                ",
      " qqbqqbqqbqqbqq ",
      " q            q ",
      " b f        f b ",
      " q            q ",
      " q            q ",
      " b            b ",
      " q     dd     q ",
      " q     vv     q ",
      " b     ss     b ",
      " q            q ",
      " q            q ",
      " b f        f b ",
      " q            q ",
      " qqbqqbqqbqqbqq ",
      "                "
    ],
    [
      "                ",
      " qqbqqbqqbqqbqq ",
      " q            q ",
      " b f        f b ",
      " q            q ",
      " q            q ",
      " b            b ",
      " q     dd     q ",
      " q     vv     q ",
      " b            b ",
      " q            q ",
      " q            q ",
      " b f        f b ",
      " q            q ",
      " qqbqqbqqbqqbqq ",
      "                "
    ],
    [
      "                ",
      " qqbqqbqqbqqbqq ",
      " qttttttttttttq ",
      " btfuuuuuuuuftb ",
      " qtuuuuuuuuuutq ",
      " qtuuuuuuuuuutq ",
      " btuuuuuuuuuutb ",
      " qtuuuudduuuutq ",
      " qtuuuuvvuuuutq ",
      " btuuuuuuuuuutb ",
      " qtuuuuuuuuuutq ",
      " qtuuuuuuuuuutq ",
      " btfuuuuuuuuftb ",
      " qttttttttttttq ",
      " qqbqqbqqbqqbqq ",
      "                "
    ]
  ]
}