{
  "name": "building_hotel1_ground_90",
  "refpalette": "c70cities:building_hotel1_ground_palette_90",
  "xsize": 16,
  "zsize": 16,
  "slices": [
    [
      "GGGGGGGGGGGGGGGG",
      "GbbbbbbbbddddbbG",
      "GbccccccccccccbG",
      "GbccccccccccccbG",
      "abccccccccccccbG",
      "GbccccccccccccbG",
      "GbccccGGGdccccbG",
      "GbccccGGGdccccbG",
      "GbccccGGGdccccbG",
      "Gbcccc!dddccccbG",
      "GbccccccccccccbG",
      "abccccccccccccbG",
      "GbccccccccccccbG",
      "Gbccccccccccc!bG",
      "GbbbbbbbbbbbbbbG",
      "GGGGGGGGGGGGGGGG"
    ],
    [
      "                ",
      "ebbbbbbbbp  pbb ",
      "ebggg   moqtomb ",
      "ebgig         b ",
      "eb            b ",
      "ebhh        wBb ",
      "eb    eeen su b ",
      "ebgig e  g  uAb ",
      "ebggg e  g su b ",
      "eb    llll  u b ",
      "ebf           b ",
      "ebf        bbbb ",
      "ebf        r yb ",
      "ebffjjkkkk b xb ",
      "ebbbbbbbbbbbbbb ",
      "                "
    ],
    [
      "                ",
      " bbbbbbbbp  pbb ",
      " b      CoDFoCb ",
      " b            b ",
      " b            b ",
      " b            b ",
      " b            b ",
      " b            p ",
      " b       n  I p ",
      " b    llgg    p ",
      " b            p ",
      " bf        bbbp ",
      " bf        E  p ",
      " bff       b  b ",
      " bbbbbppppbbbbb ",
      "                "
    ],
    [
      "                ",
      " bbbbbbbbppppbb ",
      " b      CooooCb ",
      " b            b ",
      " b            b ",
      " b            b ",
      " b            b ",
      " b            b ",
      " b            b ",
      " b    ggn     b ",
      " b            b ",
      " b         bbbb ",
      " bJ        b  b ",
      " bf        b Jb ",
      " bbbbbbbbbbbbbb ",
      "                "
    ],
    [
      "                ",
      " bbbbbbbbppppbb ",
      " b       oooo b ",
      " b            b ",
      " b            b ",
      " b            b ",
      " b            b ",
      " b    g       p ",
      " b    g       p ",
      " b    n       b ",
      " b            b ",
      " b         bbbb ",
      " bJ        b  b ",
      " bJ       JbJJb ",
      " bbppbbbbbbbbbb ",
      "                "
    ],
    [
      "                ",
      " bbbbbbbbppppbb ",
      " bKKKKKKKKKKKKb ",
      " bKKKKKKKKKKKKb ",
      " bKKKKKKKKKKKKb ",
      " bKKKKKKKKKKKKb ",
      " bKKKKg   KKKKb ",
      " bKKKKn   KKKKb ",
      " bKKKK    KKKKb ",
      " bKKKK    KKKKb ",
      " bKKKKKKKKKKKKb ",
      " bKKKKKKKKKbbbb ",
      " bKKKKKKKKKbKKb ",
      " bKKKKKKKKKbKKb ",
      " bbbbbbbbbbbbbb ",
      "                "
    ]
  ]
}