{
  "name": "building_office5_floor2_270",
  "refpalette": "c70cities:building_office5_floor2_palette_270",
  "xsize": 16,
  "zsize": 16,
  "slices": [
    [
      "                ",
      "                ",
      "  dbdbdbdbd     ",
      "  deeeeeeedaba  ",
      "  beeeeeeeeccb  ",
      "  deeeeeeeecca  ",
      "  beeeeeeedccb  ",
      "  deeeeeefdcca  ",
      "  beeeeeefdccb  ",
      "  deeeeeeedcca  ",
      "  beeeeeeedccb  ",
      "  deeeeeeedaba  ",
      "  beeeeeeed     ",
      "  dbdbdbdbd     ",
      "                ",
      "                "
    ],
    [
      "                ",
      "                ",
      "  dbdbdbdbd     ",
      "  d   m  kdaba  ",
      "  b  g       b  ",
      "  d ng       a  ",
      "  b      kdg b  ",
      "  d  gl  fdg a  ",
      "  b  g   fdh b  ",
      "  dn      di a  ",
      "  b  g l  dj b  ",
      "  d ng    daba  ",
      "  b       d     ",
      "  dbdbdbdbd     ",
      "                ",
      "                "
    ],
    [
      "                ",
      "                ",
      "  dbdbdbdbd     ",
      "  d      kdaba  ",
      "  b          b  ",
      "  d  p       a  ",
      "  b      kd  b  ",
      "  d      fdo a  ",
      "  b      fd  b  ",
      "  d       d  a  ",
      "  b       d  b  ",
      "  d  p    !aba  ",
      "  b       d     ",
      "  dbdbdbdbd     ",
      "                ",
      "                "
    ],
    [
      "                ",
      "                ",
      "  dbdbdbdbd     ",
      "  d       daba  ",
      "  b       r  b  ",
      "  d       r  a  ",
      "  b       d  b  ",
      "  d      fdq a  ",
      "  b      fdq b  ",
      "  d       dq a  ",
      "  b       dq b  ",
      "  d       raba  ",
      "  b       d     ",
      "  dbdbdbdbd     ",
      "                ",
      "                "
    ],
    [
      "                ",
      "                ",
      "  dbdbdbdbd     ",
      "  d       daba  ",
      "  b       d  b  ",
      "  d       d  a  ",
      "  b       d  b  ",
      "  d      fd  a  ",
      "  b      fd  b  ",
      "  d       d  a  ",
      "  b       d  b  ",
      "  d       daba  ",
      "  b       d     ",
      "  dbdbdbdbd     ",
      "                ",
      "                "
    ],
    [
      "                ",
      "                ",
      "  dbdbdbdbd     ",
      "  dsssssssdaba  ",
      "  bsssssssd  b  ",
      "  dsssssssd  a  ",
      "  bsssssssd  b  ",
      "  dssssssfd  a  ",
      "  bssssssfd  b  ",
      "  dsssssssd  a  ",
      "  bsssssssd  b  ",
      "  dsssssssdaba  ",
      "  bsssssssd     ",
      "  dbdbdbdbd     ",
      "                ",
      "                "
    ]
  ]
}