{
  "name": "building_hotel2_floor1_180",
  "refpalette": "c70cities:building_hotel2_floor1_palette_180",
  "xsize": 16,
  "zsize": 16,
  "slices": [
    [
      "                ",
      "              a ",
      "    dddddddddda ",
      "    dccccccccca ",
      "    dccccccccca ",
      "    dccccccccca ",
      "    dccccccccca ",
      "    dccccccccca ",
      "    dccccccccca ",
      "    dccccccccca ",
      "    dcccccc!cca ",
      "    dcccccccc=a ",
      "    dccccccccba ",
      "    d!cccccccba ",
      " aaaaaaaaaaaaaa ",
      "                "
    ],
    [
      "                ",
      "              a ",
      "    hhhhhhhhhha ",
      "    h         a ",
      "    hu tsr  ==a ",
      "    hu tsr  q=a ",
      "    h       ==a ",
      "    h         a ",
      "    hj   japaaa ",
      "    h     a ona ",
      "    hm m  aglka ",
      "    h j   aaa=a ",
      "    hj    i  ba ",
      "    hgff  e  ba ",
      " aaaaaaaaaaaaaa ",
      "                "
    ],
    [
      "                ",
      "              a ",
      "    hhhhhhhhhha ",
      "    h         a ",
      "    h    r    a ",
      "    h    r    a ",
      "    h         a ",
      "    h         a ",
      "    hB   BaAaaa ",
      "    h     a   a ",
      "    h     a   a ",
      "    hyyy  aaa=a ",
      "    hy    x  ba ",
      "    h     w  ba ",
      " aaaaaaaaaaaaaa ",
      "                "
    ],
    [
      "                ",
      "              a ",
      "    hhhhhhhhhha ",
      "    h         a ",
      "    h         a ",
      "    h         a ",
      "    h         a ",
      "    h         a ",
      "    hB   Baaaaa ",
      "    h     a   a ",
      "    h     a   a ",
      "    h     aaa=a ",
      "    h     a  ba ",
      "    hCCC  a  ba ",
      " aaaaaaaaaaaaaa ",
      "                "
    ],
    [
      "                ",
      "              a ",
      "    hhhhhhhhhha ",
      "    h         a ",
      "    h         a ",
      "    h         a ",
      "    h         a ",
      "    h         a ",
      "    h     aaaaa ",
      "    h     a   a ",
      "    h     a   a ",
      "    h     aaa=a ",
      "    h     a  ba ",
      "    h D   a  ba ",
      " aaaaaaaaaaaaaa ",
      "                "
    ],
    [
      "                ",
      "              a ",
      "    yyyyyyyyyya ",
      "    yEEEEEEEEEa ",
      "    yEEEEEEEEEa ",
      "    yEEEEEEEEEa ",
      "    yEEEEEEEEEa ",
      "    yEEEEEEEEEa ",
      "    yEEEEEaaaaa ",
      "    yEEEEEaEEEa ",
      "    yEEEEEaEEEa ",
      "    yEEEEEaaa=a ",
      "    yEEEEEaEEba ",
      "    yEEEEEaEEba ",
      " aaaaaaaaaaaaaa ",
      "                "
    ]
  ]
}