{
  "name": "building_apartment1_floor2_270",
  "refpalette": "c70cities:building_apartment1_floor2_palette_270",
  "xsize": 16,
  "zsize": 16,
  "slices": [
    [
      "                ",
      " aaaaaaaaaaaaaa ",
      " abbbbbbbbbbbba ",
      " abbbbbbbbbbbba ",
      " abbbbbbbbbbbba ",
      " abbbbbbbbbbbba ",
      " abbbbbbbbbbbba ",
      " abbbbbbbbbbbba ",
      " abbbbbbbbbbbba ",
      " abbbbbbbbbbbba ",
      "  d  cbbbbbbbba ",
      "  g bbbbbbbbbba ",
      "  hfbbbbbbbbbba ",
      "  ieedbbbbbbbba ",
      "      aaaaaaaaa ",
      "                "
    ],
    [
      "                ",
      " Zmmmmmmmmmmmmj ",
      " 0XUQOq Fq   nk ",
      " 0   Pq rqC uok ",
      " 0    IKIqD uok ",
      " 0       E   pk ",
      " 0 RR L  qqqwqk ",
      " 0    M  A y rk ",
      " 0 VS M  q A  k ",
      " 0qqqqq  q yx k ",
      "  Y   q  q yqqk ",
      "  Y   qKqq   !k ",
      "  dWT N JqC  sk ",
      "  ddddq JqDBuok ",
      "      ttttttttl ",
      "                "
    ],
    [
      "                ",
      " 799997997q111q ",
      " 9*^  q  q   2q ",
      " 1    q  q    q ",
      " 1    I@Iq    q ",
      " 1       8    q ",
      " 1       qqq4qq ",
      " 1       6 y5 q ",
      " 9 %% #  q 6  q ",
      " qqqqqq  q y 3q ",
      "  d   q  q yqqq ",
      "  d&  q@qq    q ",
      "  dT  $  q    q ",
      "  ddYhq  q    q ",
      "      qqqqq111q ",
      "                "
    ],
    [
      "                ",
      " 711197117q111q ",
      " 9    q  q ]-(q ",
      " 1`   q  q    1 ",
      " 1:   IIIq    1 ",
      " 1;      q    q ",
      " 1'   }  qqqqqq ",
      " 1,      q y  1 ",
      " 9 \\\\    q y  1 ",
      " qqqqqq  q y )q ",
      "  dW  q  q yqqq ",
      "  d|  qqqq    1 ",
      "  .   q  q    1 ",
      "  /dddq  q {[+q ",
      "      q11qq111q ",
      "                "
    ],
    [
      "                ",
      " 799997997q999q ",
      " 9    q  q    q ",
      " 9    q  q    k ",
      " 9    IIIq    k ",
      " 9       q    q ",
      " 9    <  qqqqqq ",
      " 9       q y  k ",
      " 9       q y  k ",
      " qqqqqq  q y  q ",
      "  e|> q  q yqqq ",
      "  Y   qqqq    k ",
      "  Y   qf q    k ",
      "  d...q  q    q ",
      "      q99qq999q ",
      "                "
    ],
    [
      "                ",
      " qqqqqqqqqqqqqq ",
      " qddddd??qddddq ",
      " qddddd??qddddq ",
      " qdddddddqddddq ",
      " qdddddddqddddq ",
      " qdddddddqqqqqq ",
      " qdddddddqdd??q ",
      " qdddddddqdd??q ",
      " qqqqqqddqdd??q ",
      "  d cWqddqddddq ",
      "  d   qqqqddddq ",
      "  d   qddqddddq ",
      "  ddddqddqddddq ",
      "      qqqqqqqqq ",
      "                "
    ]
  ]
}