{
  "name": "building_residential4_ground",
  "refpalette": "c70cities:building_residential4_ground_palette",
  "xsize": 16,
  "zsize": 16,
  "slices": [
    [
      "GGGGGGGGGGGGGGGG",
      "GGGGGGGGGGGGGGGG",
      "GGaaaaaaaaaaaaGG",
      "GGabbbbbbcccdGGG",
      "GGabbbbbbcccdGGG",
      "GGabbbbbbcccdGGG",
      "GGabbbbbbcccdGGG",
      "GGabbbbbbcccdGGG",
      "GGabbbbbbcccdGGG",
      "GGabbbbbbcccdGGG",
      "GGabbbbbbcccdGGG",
      "GGabbbbbbcccdGGG",
      "GGabbbbbbcccdGGG",
      "GGaaaaaaaaaaaaGG",
      "GGGGGGGGGGGGGGGG",
      "GGGGGGGGGGGGGGGG"
    ],
    [
      "effffgffffgffffe",
      "f              f",
      "f hhiihiihiihh f",
      "f j   k lm ndo f",
      "f jp qk lm ndo f",
      "f jr qk  s tdo g",
      "e h   u    wdo f",
      "  x   u    ydo f",
      "  A        Bdo f",
      "e h        wdo f",
      "f j      CCCdo g",
      "f jD     E Fdo f",
      "f jI  J  K  do f",
      "f hhLLhLLhLLhh f",
      "f              f",
      "effffgffffgffffe"
    ],
    [
      "effffgffffgffffe",
      "f              f",
      "f hhMMhMMhMMhh f",
      "f M   N     d  f",
      "f M  ON  P  d  f",
      "f M  ON    Qd  g",
      "e h   u     d  f",
      "  R   u     S  f",
      "  T        US  f",
      "e h        Vd  f",
      "f M      CCCd  g",
      "f M      W Xd  f",
      "f M YJ   K  d  f",
      "f hhMMhMMhZZhh f",
      "f              f",
      "effffgffffgffffe"
    ],
    [
      "                ",
      "                ",
      "  hhhhhhhhhhhh  ",
      "  M   N     d0  ",
      "  M   N     d0  ",
      "  M   N     d0  ",
      "  h   u     d0  ",
      "  M   u     S0  ",
      "  M         S0  ",
      "  h         d0  ",
      "  M      CCCd0  ",
      "  M 1    K  d0  ",
      "  M      K  d0  ",
      "  hhhhhhhhhhhh  ",
      "                ",
      "                "
    ],
    [
      "                ",
      " 22222222222222 ",
      " LhhhhhhhhhhhhL ",
      "  hbbbbbbbbbd3  ",
      "  hbbbbbbbbbd3  ",
      "  hbbbbbbbbbd3  ",
      "  hbbbbbbbbbd3  ",
      "  hbbbbbbbbbd   ",
      "  hbbbbbbbbbd   ",
      "  hbbbbbbbbbd3  ",
      "  hb1  bbbbbd3  ",
      "  hb   bbbbbd3  ",
      "  hb   bbbbbd3  ",
      " ihhhhhhhhhhhhi ",
      " 44444444444444 ",
      "                "
    ],
    [
      "                ",
      "                ",
      " 22222222222222 ",
      " L3dhhhhhhhhd3L ",
      "  3d33333333d3  ",
      "  3d567  88 d3  ",
      "  3d567  889d3  ",
      "  @d#77 $88%d^  ",
      "  &d        d*  ",
      "  3d (()++++d3  ",
      "  3d  -    [d3  ",
      "  3d  -    ]d3  ",
      " i3d  - !{{ d3i ",
      " 44444444444444 ",
      "                ",
      "                "
    ]
  ]
}