{
  "name": "building_policeoffice1_floor2_180",
  "refpalette": "c70cities:building_policeoffice1_floor2_palette_180",
  "xsize": 16,
  "zsize": 16,
  "slices": [
    [
      "                ",
      "cfcccfcccfcccfc ",
      "c   bbbbbbbbbec ",
      "c   bbbbbbbbbec ",
      "ccdccbbbbbbbbcc ",
      "    abbbbbbbba  ",
      "    abbbbbbbba  ",
      "    abbbbbbbba  ",
      "    abbbbbbbba  ",
      "    abb!bbb!ba  ",
      "    abbbbbbbba  ",
      "    abbbbbbbba  ",
      "    abbbbbbbba  ",
      "    abbbbbbbba  ",
      "    aaaaaaaaaa  ",
      "                "
    ],
    [
      "                ",
      "cfcccfcccfcccfc ",
      "c   l mmmmk  ec ",
      "c   l     k  ec ",
      "ccdcc     kjicc ",
      "    a h h    a  ",
      "    g ccc    a  ",
      "    g        a  ",
      "    g h h h ha  ",
      "    g ccc ccca  ",
      "    g        a  ",
      "    g h h h ha  ",
      "    g ccc ccca  ",
      "    g        a  ",
      "    ggggggggga  ",
      "                "
    ],
    [
      "                ",
      "cfcccfcccfcccfc ",
      "c     s rqk  ec ",
      "c         k  ec ",
      "ccdcc     kpocc ",
      "    a        a  ",
      "    g n n    a  ",
      "    g        a  ",
      "    g        a  ",
      "    g n n n na  ",
      "    g        a  ",
      "    g        a  ",
      "    g n n n na  ",
      "    g        a  ",
      "    ggggggggga  ",
      "                "
    ],
    [
      "                ",
      "cfcccfcccfcccfc ",
      "c     s   k  ec ",
      "c         m  ec ",
      "ccdcc     kkkcc ",
      "    a        a  ",
      "    g        a  ",
      "    g        a  ",
      "    g        a  ",
      "    g        a  ",
      "    g        a  ",
      "    g        a  ",
      "    g        a  ",
      "    g        a  ",
      "    ggggggggga  ",
      "                "
    ],
    [
      "                ",
      "cfcccfcccfcccfc ",
      "c     s   k  ec ",
      "c         k  ec ",
      "ccdcc     kkkcc ",
      "    a        a  ",
      "    g        a  ",
      "    g        a  ",
      "    g        a  ",
      "    g        a  ",
      "    g        a  ",
      "    g        a  ",
      "    g        a  ",
      "    g        a  ",
      "    ggggggggga  ",
      "                "
    ],
    [
      "                ",
      "cfcccfcccfcccfc ",
      "c   uuuuuukuuec ",
      "c   uuuuuukuuec ",
      "ccdccuuuuukkkcc ",
      "    auuuuuuuua  ",
      "    tuuuuuuuua  ",
      "    tuuuuuuuua  ",
      "    tuuuuuuuua  ",
      "    tuuuuuuuua  ",
      "    tuuuuuuuua  ",
      "    tuuuuuuuua  ",
      "    tuuuuuuuua  ",
      "    tuuuuuuuua  ",
      "    ttttttttta  ",
      "                "
    ]
  ]
}