{
  "name": "building_residential1_floor1_180",
  "refpalette": "c70cities:building_residential1_floor1_palette_180",
  "xsize": 16,
  "zsize": 16,
  "slices": [
    [
      "                ",
      "                ",
      "                ",
      "                ",
      "                ",
      "                ",
      "  jjjjjjjjjjjj  ",
      "  ddiiiiiiiidd  ",
      "  f          f  ",
      "  f          f  ",
      "  f         hf  ",
      "  f         gf  ",
      " cdeeeeeeeeeedc ",
      " bbbbbbbbbbbbbb ",
      " aaaaaaaaaaaaaa ",
      "                "
    ],
    [
      "                ",
      "                ",
      "                ",
      "                ",
      "                ",
      "                ",
      "                ",
      "  ddkkkkkkkkdd  ",
      "  f          f  ",
      "  f          f  ",
      " cdeeeeeeeeeedc ",
      " bbbbbbbbbbbbbb ",
      " aaaaaaaaaaaaaa ",
      "                ",
      "                ",
      "                "
    ],
    [
      "                ",
      "                ",
      "                ",
      "                ",
      "                ",
      "                ",
      "                ",
      "  dddddddddddd  ",
      " cdeeeeeeeeeedc ",
      " bbbbbbbbbbbbbb ",
      " aaaaaaaaaaaaaa ",
      "                ",
      "                ",
      "                ",
      "                ",
      "                "
    ],
    [
      "                ",
      "                ",
      "                ",
      "                ",
      "                ",
      "                ",
      " cccccccccccccc ",
      " bbbbbbbbbbbbbb ",
      " aaaaaaaaaaaaaa ",
      "                ",
      "                ",
      "                ",
      "                ",
      "                ",
      "                ",
      "                "
    ],
    [
      "                ",
      "                ",
      "                ",
      "                ",
      "                ",
      "                ",
      " aaaaaaaaaaaaaa ",
      "                ",
      "                ",
      "                ",
      "                ",
      "                ",
      "                ",
      "                ",
      "                ",
      "                "
    ],
    [
      "                ",
      "                ",
      "                ",
      "                ",
      "                ",
      "                ",
      "       ~        ",
      "                ",
      "                ",
      "                ",
      "                ",
      "                ",
      "                ",
      "                ",
      "                ",
      "                "
    ]
  ]
}