{
  "name": "building_office5_top_180",
  "refpalette": "c70cities:building_office5_top_palette_180",
  "xsize": 16,
  "zsize": 16,
  "slices": [
    [
      "                ",
      "                ",
      "  cdcdcdcdcdcc  ",
      "  deeeeeeeeeed  ",
      "  ceeeeGGeeeec  ",
      "  deeeeGGeeeed  ",
      "  cee!eGGeeeec  ",
      "  deeeeeeeeeed  ",
      "  ceeeeeeeeeec  ",
      "  deeeeffeeeed  ",
      "  cccccccccccc  ",
      "    b       b   ",
      "    b       b   ",
      "    aaaaaaaaa   ",
      "                ",
      "                "
    ],
    [
      "                ",
      "                ",
      "  cdcdcdcdcdcc  ",
      "  dg        gd  ",
      "  c  o ut   sc  ",
      "  d ro qp    d  ",
      "  c  o nm lllc  ",
      "  d          d  ",
      "  c       k jc  ",
      "  dgii    hhgd  ",
      "  cccccccccccc  ",
      "    b       b   ",
      "    aaaaaaaaa   ",
      "                ",
      "                ",
      "                "
    ],
    [
      "                ",
      "                ",
      "  cdcdcdcdcdcc  ",
      "  d          d  ",
      "  c  D       c  ",
      "  d  C       d  ",
      "  c  B     llc  ",
      "  d          d  ",
      "  c          c  ",
      "  d          d  ",
      "  ccm Accyxwcc  ",
      "    aaaaaaaaa   ",
      "                ",
      "                ",
      "                ",
      "                "
    ],
    [
      "                ",
      "                ",
      "  cccccccccccc  ",
      "  c          c  ",
      "  c          c  ",
      "  c          c  ",
      "  c          c  ",
      "  c          c  ",
      "  c          c  ",
      "  c          c  ",
      "  cccccccccccc  ",
      "                ",
      "                ",
      "                ",
      "                ",
      "                "
    ],
    [
      "                ",
      "                ",
      "  cccccccccccc  ",
      "  cEEEEEEEEEEc  ",
      "  cEEEFFFFEEEc  ",
      "  cEEEFFFFEEEc  ",
      "  cEEEFFFFEEEc  ",
      "  cEEEEEEEEEEc  ",
      "  cEEEEEEEEEEc  ",
      "  cEEEEEEEEEEc  ",
      "  cccccccccccc  ",
      "                ",
      "                ",
      "                ",
      "                ",
      "                "
    ],
    [
      "                ",
      "                ",
      "  cccccccccccc  ",
      "  c        I c  ",
      "  cII      I c  ",
      "  c I      I c  ",
      "  c I      IIc  ",
      "  c I        c  ",
      "  c       IIIc  ",
      "  c       I  c  ",
      "  cccccccccccc  ",
      "                ",
      "                ",
      "                ",
      "                ",
      "                "
    ]
  ]
}