{
  "name": "building_residential3_floor1_180",
  "refpalette": "c70cities:building_residential3_floor1_palette_180",
  "xsize": 16,
  "zsize": 16,
  "slices": [
    [
      "                ",
      "                ",
      "  abbbbacccccc  ",
      "  a    adggddc  ",
      "  b         dc  ",
      "  b         gc  ",
      "  b         gc  ",
      "  afff  e   dc  ",
      "  a         aa  ",
      "  b          b  ",
      "  b          b  ",
      "  b          b  ",
      "  b          b  ",
      "  aabbbaabbbaa  ",
      "                ",
      "                "
    ],
    [
      "                ",
      " hhhhhhhhhhhhhh ",
      " haaaaaacccccch ",
      "  a    adddddc  ",
      "  a         dc  ",
      "  a         dc  ",
      "  a         dc  ",
      "  afff  e   dc  ",
      "  ai        aa  ",
      "  a          a  ",
      "  a          a  ",
      "  a          a  ",
      "  a          a  ",
      " haaaaaaaaaaaah ",
      " hhhhhhhhhhhhhh ",
      "                "
    ],
    [
      "                ",
      " ~              ",
      " jjjjjjjjjjjjjj ",
      " nnnnnnnnnnnnnn ",
      " llllllllllllll ",
      " hahhhhhhhhhdch ",
      "  a         dc  ",
      "  alml  e   dc  ",
      "  ae        aa  ",
      "  a          a  ",
      " hahhhhhhhhhhah ",
      " llllllllllllll ",
      " kkkkkkkkkkkkkk ",
      " jjjjjjjjjjjjjj ",
      "              ~ ",
      "                "
    ],
    [
      "                ",
      " ~              ",
      "                ",
      "                ",
      "                ",
      " jjjjjjjjjjjjjj ",
      " nnnnnnnnnnnnnn ",
      " llllllllllllll ",
      " llllllllllllll ",
      " kkkkkkkkkkkkkk ",
      " jjjjjjjjjjjjjj ",
      "                ",
      "                ",
      "                ",
      "              ~~",
      "                "
    ],
    [
      "                ",
      " ~~~~~~~~~~~~~~ ",
      " ~~~~~~~~~~~~~~ ",
      " ~~~~~~~~~~~~~~ ",
      " ~~~~~~~~~~~~~~ ",
      " ~~~~~~~~~~~~~~ ",
      " ~~~~~~~~~~~~~~ ",
      " ~~~~~~~~~~~~~~ ",
      " ~~~~~~~~~~~~~~ ",
      " ~~~~~~~~~~~~~~ ",
      " ~~~~~~~~~~~~~~ ",
      " ~~~~~~~~~~~~~~ ",
      " ~~~~~~~~~~~~~~ ",
      " ~~~~~~~~~~~~~~ ",
      " ~~~~~~~~~~~~~~ ",
      "                "
    ],
    [
      "                ",
      " ~~~~~~~~~~~~~~ ",
      " ~~~~~~~~~~~~~~ ",
      " ~~~~~~~~~~~~~~ ",
      " ~~~~~~~~~~~~~~ ",
      " ~~~~~~~~~~~~~~ ",
      " ~~~~~~~~~~~~~~ ",
      " ~~~~~~~~~~~~~~ ",
      " ~~~~~~~~~~~~~~ ",
      " ~~~~~~~~~~~~~~ ",
      " ~~~~~~~~~~~~~~ ",
      " ~~~~~~~~~~~~~~ ",
      " ~~~~~~~~~~~~~~ ",
      " ~~~~~~~~~~~~~~ ",
      " ~~~~~~~~~~~~~~ ",
      "                "
    ]
  ]
}