{
  "name": "building_office2_floor1_270",
  "refpalette": "c70cities:building_office2_floor1_palette_270",
  "xsize": 16,
  "zsize": 16,
  "slices": [
    [
      "                ",
      " a            a ",
      " a dddddddddd a ",
      " abeeeeeeeeeeba ",
      " acccccccccccca ",
      " acccccccccccca ",
      " acccccccccccca ",
      " afccccccccccca ",
      " afccccccccccca ",
      " acccccccccccca ",
      " acccccccccccca ",
      " acccccccccccca ",
      " abeeeeeeeeeeba ",
      " a dddddddddd a ",
      " a            a ",
      "                "
    ],
    [
      "                ",
      " a            a ",
      " a dddddddddd a ",
      " ab          ba ",
      " an          ga ",
      " an   j j j  ga ",
      " ao  m l l   ha ",
      " af        i ga ",
      " af        i ga ",
      " ao  m l l   ga ",
      " an   k k k  ha ",
      " an          ga ",
      " ab          ba ",
      " a dddddddddd a ",
      " a            a ",
      "                "
    ],
    [
      "                ",
      " a            a ",
      " a dddddddddd a ",
      " ab          ba ",
      " ar          pa ",
      " a           pa ",
      " as   qqqqq   a ",
      " af   q   q   a ",
      " af   q   q   a ",
      " as   qqqqq   a ",
      " a            a ",
      " ap          pa ",
      " ab          ba ",
      " a dddddddddd a ",
      " a            a ",
      "                "
    ],
    [
      "                ",
      " a            a ",
      " a dddddddddd a ",
      " ab          ba ",
      " a           pa ",
      " a            a ",
      " a            a ",
      " af           a ",
      " af           a ",
      " a            a ",
      " a            a ",
      " a            a ",
      " ab          ba ",
      " a dddddddddd a ",
      " a            a ",
      "                "
    ],
    [
      "                ",
      " a            a ",
      " a dddddddddd a ",
      " ab          ba ",
      " a            a ",
      " a            a ",
      " a            a ",
      " af           a ",
      " af    !      a ",
      " a            a ",
      " a            a ",
      " a            a ",
      " ab          ba ",
      " a dddddddddd a ",
      " a            a ",
      "                "
    ],
    [
      "                ",
      " a            a ",
      " a dddddddddd a ",
      " ab          ba ",
      " attttttttttt a ",
      " attttttttttt a ",
      " attttttttttt a ",
      " afttttuutttt a ",
      " afttttuutttt a ",
      " attttttttttt a ",
      " attttttttttt a ",
      " attttttttttt a ",
      " ab          ba ",
      " a dddddddddd a ",
      " a            a ",
      "                "
    ]
  ]
}