{
  "name": "building_bank1_ground_180",
  "refpalette": "c70cities:building_bank1_ground_palette_180",
  "xsize": 16,
  "zsize": 16,
  "slices": [
    [
      "GGGGGGGGGGGGGGGG",
      "GGaGGaaaaGGaaaGG",
      "GabbbbbbbbbbbbaG",
      "GabbbbbbbbbbcbGG",
      "Gabbbbbb!bbbbbGG",
      "GGbbbbbbbbbbbbaG",
      "GGbbbbbbbbbbbbaG",
      "GabbbbbbbbbbbbaG",
      "GabbbbbbbbbbbbaG",
      "GabbbbbbbbbbbbGG",
      "GabbbbbbbbbbbbGG",
      "GGbbbbbbbbbbbbaG",
      "GGbbbbbbbbbbbbaG",
      "GabbbbbbbbbbbbaG",
      "GGaaaGGaaaaGGaGG",
      "GGGGGGGGGGGGGGGG"
    ],
    [
      "                ",
      " da  aaaa  aaad ",
      " aeefeeeeefeeea ",
      " ae  uuuu  a e  ",
      " ae  uwwu  t f  ",
      "  f        aaea ",
      "  h   ss    ora ",
      " aem        qea ",
      " aep        oea ",
      " aen         e  ",
      " aem   l l   f  ",
      "  f   jkkjj iea ",
      "  h          ea ",
      " aegefeeeeefeea ",
      " daaa  aaaa  ad ",
      "                "
    ],
    [
      "                ",
      " da  aaaa  aaad ",
      " aeefeeeeefeeea ",
      " ae        a e  ",
      " ae        B f  ",
      "  f        aaea ",
      "  x          ra ",
      " aem         ea ",
      " ae          ea ",
      " ae          e  ",
      " aem        if  ",
      "  f     A y  ea ",
      "  x          ea ",
      " aegefeeeeefeea ",
      " daaa  aaaa  ad ",
      "                "
    ],
    [
      "                ",
      " dF  aaaF  aaad ",
      " aefeeeeefeeeeE ",
      " ae        a f  ",
      " ae        a e  ",
      "  e        aaea ",
      "  f          ra ",
      " De          ea ",
      " ae          eE ",
      " ae         if  ",
      " ae          e  ",
      "  e          ea ",
      "  f          ea ",
      " Deeeefeeeeefea ",
      " daaa  Caaa  Cd ",
      "                "
    ],
    [
      "                ",
      " d   aaa   aaad ",
      " aefeeeeefeeee  ",
      " ae        a f  ",
      " ae        a e  ",
      "  e        aaea ",
      "  f          ra ",
      "  e          ea ",
      " ae         ie  ",
      " ae          f  ",
      " ae          e  ",
      "  e          ea ",
      "  f          ea ",
      "  eeeefeeeeefea ",
      " daaa   aaa   d ",
      "                "
    ],
    [
      "                ",
      "    OaaF  OaaF  ",
      " Dfeeeeefeeeef  ",
      " aeJJJJJJJJaJe  ",
      " aeJJJJJJJJaJeL ",
      " KeJJMMMMJJaaea ",
      "  eJJMNNMJJJJra ",
      "  fJJMNNMJJJieE ",
      " DeJJMNNMJJJ f  ",
      " aeJJMNNMJJJ e  ",
      " aeJJMMMMJJJ eL ",
      " KeJJJJJJJJJJea ",
      "  eJJJJJJJJJJea ",
      "  feeeefeeeeefE ",
      "  CaaI  CaaI    ",
      "                "
    ]
  ]
}