{
  "name": "building_residential2_floor1_270",
  "refpalette": "c70cities:building_residential2_floor1_palette_270",
  "xsize": 16,
  "zsize": 16,
  "slices": [
    [
      "                ",
      "         rng    ",
      "       ddddddd  ",
      "   B   w shhed  ",
      "   B   w fiifda ",
      "       x ffffdb ",
      "       y ffffdc ",
      "   B   w     d  ",
      "   B   w     d  ",
      "       wjjjj da ",
      "       wkkkk db ",
      "   B   w  o  dc ",
      "   BA  w tpl d  ",
      "       ddddddd  ",
      "         uqm    ",
      "                "
    ],
    [
      "                ",
      "                ",
      "       dCDDDCd  ",
      "   B   w    EC  ",
      "   B   w     D  ",
      "       I     D  ",
      "       J     D  ",
      "   B   w     D  ",
      "   B   w     D  ",
      "       w     D  ",
      "       w     D  ",
      "   B   w     D  ",
      "   B   w  F  C  ",
      "       dCDDDCd  ",
      "                ",
      "                "
    ],
    [
      "                ",
      " MLCK           ",
      " MLCK  dCDDDCd  ",
      " MLCK  w     C  ",
      " MLCK  w     D  ",
      " MLCK  w     D  ",
      " MLCK  w     D  ",
      " MLCK  w     D  ",
      " MLCK  w     D  ",
      " MLCK  w     D  ",
      " MLCK  w     D  ",
      " MLCK  w     D  ",
      " MLCK  w     C  ",
      " MLCK  dCDDDCd  ",
      " MLCK           ",
      "                "
    ],
    [
      "                ",
      "    MLCK        ",
      "    MLCddddddd  ",
      "    MLCC     d  ",
      "    MLCC     d  ",
      "    MLCC     d  ",
      "    MLCC     d  ",
      "    MLCC     d  ",
      "    MLCC     d  ",
      "    MLCC     d  ",
      "    MLCC     d  ",
      "    MLCC     d  ",
      "    MLCC     d  ",
      "    MLCddddddd  ",
      " ~  MLCK        ",
      "                "
    ],
    [
      "                ",
      "       MLCK     ",
      "       MLCK BB  ",
      "       MLCK     ",
      "       MLCK     ",
      "       MLCK  B  ",
      "       MLCK  B  ",
      "       MLCK     ",
      "       MLCK     ",
      "       MLCK  B  ",
      "       MLCK  B  ",
      "       MLCK     ",
      "       MLCK     ",
      "       MLCK BB  ",
      " ~     MLCK     ",
      "                "
    ],
    [
      "                ",
      "          MLCK  ",
      "          MLCC  ",
      "          MLCK  ",
      "          MLCK  ",
      "          MLCC  ",
      "          MLCC  ",
      "          MLCK  ",
      "          MLCK  ",
      "          MLCC  ",
      "          MLCC  ",
      "          MLCK  ",
      "          MLCK  ",
      "          MLCC  ",
      " ~        MLCK  ",
      "                "
    ]
  ]
}