{
  "name": "building_residential1_ground_90",
  "refpalette": "c70cities:building_residential1_ground_palette_90",
  "xsize": 16,
  "zsize": 16,
  "slices": [
    [
      "GGGGGGGGGGGGGGGG",
      "GGGGGGGGGGGGGGGG",
      "GGaaaaaaaGGGGGGG",
      "GGabbbbbcccccGGG",
      "GGabbbbbeeeecGGG",
      "GGabbbbbeeeecGGG",
      "GGabbbbbddddcGGG",
      "GGabbbbbddddcGGG",
      "GGabbbbbddddcGGG",
      "GGabbbbbddddcGGG",
      "GGabbbbbddddcGGG",
      "GGabbbbbddddcGGG",
      "GGabbbbbcccccGGG",
      "GGaaaaaaaGGGGGGG",
      "GGGGGGGGGGGGGGGG",
      "GGGGGGGGGGGGGGGG"
    ],
    [
      "fggggfgggghggggf",
      "g              g",
      "g ijjijjixxxxx g",
      "g i     cccccx g",
      "g j   r w  Kcx g",
      "h j   r wBCCcx h",
      "g j   r    !cx g",
      "g il prt   Jcx g",
      "g il or    Icx g",
      "g j      A Fcx g",
      "h j  n  uy Ecx h",
      "g j  n  uy Dcx g",
      "g i  nqscccccx g",
      "g ikmijjixxxxx g",
      "g              g",
      "fgf  fgggghggggf"
    ],
    [
      "fggggfgggghggggf",
      "g              g",
      "g ijjijji      g",
      "g i     ccScc  g",
      "g j   r w  Wc  g",
      "h j   r wQCCc  h",
      "g j   rt    R  g",
      "g iM  r    VR  g",
      "g iM  r    UR  g",
      "g j      P  R  g",
      "h j  n      c  h",
      "g j  n  O  Tc  g",
      "g i  n  ccRcc  g",
      "g iLNijji      g",
      "g              g",
      "fgf  fgggghggggf"
    ],
    [
      "     0          ",
      "                ",
      "  iZZiZZi    1  ",
      "  i     ccScc1  ",
      "  X   r w   c1  ",
      "  X   rtwCCCc1  ",
      "  X   r     c1  ",
      "  i   r     c1  ",
      "  i   r     c1  ",
      "  X         c1  ",
      "  X  n      c1  ",
      "  X  n      c1  ",
      "  i  n  ccRcc1  ",
      "  iYYiYYi    1  ",
      "                ",
      "                "
    ],
    [
      "                ",
      "                ",
      "  iiiiiii  145  ",
      "  ibbbbbcccc45  ",
      "  ibbbbtw33345  ",
      "  ibbbb w22245  ",
      "  ibbbb    145  ",
      "  ibbbb    145  ",
      "  ibbbb    145  ",
      "  ibbbb    145  ",
      "  ibbbb    145  ",
      "  ibbbb    145  ",
      "  ibbbb cccc45  ",
      "  iiiiiii  145  ",
      "                ",
      "                "
    ],
    [
      "                ",
      " 6              ",
      " 6ijjjjji145    ",
      " 6i     cc45    ",
      " 6i    )w+45    ",
      " 6i &  )wC45    ",
      " 6i@^( ) 145    ",
      " 6i9%* ) 145    ",
      " 6i    ) 145    ",
      " 6i8888) 145    ",
      " 6i8$$8) 145    ",
      " 6i8##8) 145    ",
      " 6i7YY )cc45    ",
      " 6ijjjjji145    ",
      " 6              ",
      "                "
    ]
  ]
}