{
  "name": "building_residential1_ground",
  "refpalette": "c70cities:building_residential1_ground_palette",
  "xsize": 16,
  "zsize": 16,
  "slices": [
    [
      "GGGGGGGGGGGGGGGG",
      "GGGGGGGGGGGGGGGG",
      "GGaaaaaaaaaaaaGG",
      "GGabbbbbbbbbbaGG",
      "GGabbbbbbbbbbaGG",
      "GGabbbbbbbbbbaGG",
      "GGabbbbbbbbbbaGG",
      "GGabbbbbbbbbbaGG",
      "GGacddddddeecaGG",
      "GGGcddddddeecGGG",
      "GGGcddddddeecGGG",
      "GGGcddddddeecGGG",
      "GGGccccccccccGGG",
      "GGGGGGGGGGGGGGGG",
      "GGGGGGGGGGGGGGGG",
      "GGGGGGGGGGGGGGGG"
    ],
    [
      "fgggghgggghggggf",
      "g              g",
      "f iijjjiijjjii g",
      "  k    ll    j g",
      "  m          j g",
      "f innn op    i f",
      "g jq   rrrrr j g",
      "g js    t    j g",
      "g icuu    wwci g",
      "g xcyyA   B cx g",
      "h xc      C cx h",
      "g xcDEFIJ!CKcx g",
      "g xccccccccccx g",
      "g xxxxxxxxxxxx g",
      "g              g",
      "fgggghgggghggggf"
    ],
    [
      "fgggghgggghggggf",
      "g              g",
      "f iijjjiijjjii g",
      "  L    MM    j g",
      "  N          j g",
      "f innn       i f",
      "g j    rrrrr j g",
      "g j      t   j g",
      "g icO     wwci g",
      "g  c  P   Q c  g",
      "h  R      C S  h",
      "g  cT  UV CWc  g",
      "g  cccRRRRccc  g",
      "g              g",
      "g              g",
      "fgggghgggghggggf"
    ],
    [
      "                ",
      "                ",
      "  iiXXXiiXXXii  ",
      "  Y          Z  ",
      "  Y          Z  ",
      "  innn       i 0",
      "  Y    rrrrr Z  ",
      "  Y       t  Z  ",
      "  ic      wwci  ",
      "   c      C c   ",
      "   R      C S   ",
      "   c      C c   ",
      "   cccccccccc   ",
      "  111111111111  ",
      "                ",
      "                "
    ],
    [
      "                ",
      "                ",
      "  iiiiiiiiiiii  ",
      "  ibbbbbbbbbbi  ",
      "  ibbbbbbbbbbi  ",
      "  ibbbbbbbbbbi  ",
      "  ibbbbbbbbbbi  ",
      "  i        tbi  ",
      "  ic      wwci  ",
      "   c      23c   ",
      "   c      23c   ",
      "  1c11111123c1  ",
      "  444444444444  ",
      "  555555555555  ",
      "                ",
      "                "
    ],
    [
      "                ",
      " 66666666666666 ",
      "  iiiiiiiiiiii  ",
      "  j7888 9@   j  ",
      "  jY#$8 %^&  j  ",
      "  jY#$8 *(   j  ",
      "  j 888      j  ",
      "  j))))))))) j  ",
      "  ic      wwci  ",
      "  1c111111C+c1  ",
      "  444444444444  ",
      "  555555555555  ",
      "                ",
      "                ",
      "                ",
      "                "
    ]
  ]
}