{
  "name": "building_hotel2_floor2_180",
  "refpalette": "c70cities:building_hotel2_floor2_palette_180",
  "xsize": 16,
  "zsize": 16,
  "slices": [
    [
      "                ",
      "              a ",
      "    dddddddddda ",
      "    dccccccccca ",
      "    dccccccccca ",
      "    dccccccccca ",
      "    dcccccccc!a ",
      "    dccc!ccccca ",
      "    dcccccccc!a ",
      "    dccccccccca ",
      "    dccccccccca ",
      "    dcccccccc=a ",
      "    dccccccccba ",
      "    dccccccccba ",
      " aaaaaaaaaaaaaa ",
      "                "
    ],
    [
      "                ",
      "              a ",
      "    ffffffffffa ",
      "    f      BAya ",
      "    f  xx     a ",
      "    f wuu     a ",
      "    faaaaa tt=a ",
      "    fss ra aaaa ",
      "    f   qa p oa ",
      "    f   na a ma ",
      "    fj iha alka ",
      "    fj ihagaa=a ",
      "    f    a   ba ",
      "    f    e   ba ",
      " aaaaaaaaaaaaaa ",
      "                "
    ],
    [
      "                ",
      "              a ",
      "    ffffffffffa ",
      "    f       K a ",
      "    f         a ",
      "    f         a ",
      "    faaaaa   Ja ",
      "    f I  a aaaa ",
      "    f    a F  a ",
      "    f    a a  a ",
      "    f    a a Ea ",
      "    f    aDaa=a ",
      "    f    a   ba ",
      "    f    C   ba ",
      " aaaaaaaaaaaaaa ",
      "                "
    ],
    [
      "                ",
      "              a ",
      "    ffffffffffa ",
      "    f         a ",
      "    f         a ",
      "    f         a ",
      "    faaaaa NNMa ",
      "    f    a aaaa ",
      "    f    a a  a ",
      "    f    a a  a ",
      "    f    a a La ",
      "    f    aaaa=a ",
      "    f    a   ba ",
      "    f    a   ba ",
      " aaaaaaaaaaaaaa ",
      "                "
    ],
    [
      "                ",
      "              a ",
      "    ffffffffffa ",
      "    f         a ",
      "    f         a ",
      "    f         a ",
      "    faaaaa   Oa ",
      "    f    a aaaa ",
      "    f    a a  a ",
      "    f    a a  a ",
      "    f    a a  a ",
      "    f    aaaa=a ",
      "    f    a   ba ",
      "    f    a   ba ",
      " aaaaaaaaaaaaaa ",
      "                "
    ],
    [
      "                ",
      "              a ",
      "    KKKKKKKKKKa ",
      "    KPPPPPPPPPa ",
      "    KPPPPPPPPPa ",
      "    KPPPPPPPPPa ",
      "    KPaaaaPPPPa ",
      "    KPPPPaPaaaa ",
      "    KPPPPaPaPPa ",
      "    KPPPPaPaPPa ",
      "    KPPPPaPaPPa ",
      "    KPPPPaaaa=a ",
      "    KPPPPaPPPba ",
      "    KPPPPaPPPba ",
      " aaaaaaaaaaaaaa ",
      "                "
    ]
  ]
}