{
  "name": "building_factory1_ground_90",
  "refpalette": "c70cities:building_factory1_ground_palette_90",
  "xsize": 16,
  "zsize": 16,
  "slices": [
    [
      "zzzzzzzzzzzzzzzz",
      "zzzzzzzzzzzzzzzz",
      "zzbbbbbbbbbbbbzz",
      "zzbbbbbbbbbbbbzz",
      "zzbbbbbbcbcbbbzz",
      "zzbbbbbbbbbbbbzz",
      "zzbbbbbbbbbbbbzz",
      "zzbbbbbbbbbbbbzz",
      "zzbbbbbbbbbbbbzz",
      "zzbbbbbbbbbbbbzz",
      "zzbbbbbbbbbbbbzz",
      "zzbbbbbbbbbbbbzz",
      "zzbbbbbbbbbbbbzz",
      "zazaaaaaaaaaazza",
      "aaaaaaazaaaaaaaa",
      "aaaazaaaaazzaaaa"
    ],
    [
      "d  d      d     ",
      " d    d    d d e",
      "d hhhhhhhhhhhh  ",
      " ghi o  xxxxih  ",
      "d hm oqswwCFMhNd",
      "  hl p ruuuEMhdd",
      "f hkko  rA DLh N",
      "  hi      Axihdd",
      "e h!n      xKhd ",
      " dhjn     BxJhdd",
      "  hjn   ty xIh d",
      "d hi       xihdO",
      "  hh        hhd ",
      "                ",
      "                ",
      "                "
    ],
    [
      "                ",
      "                ",
      "  hhhhhhhhhhhh  ",
      " ghi o  xxxxih  ",
      "  hP oST   VMh  ",
      "  h  R      Mh  ",
      "  hkko     U h  ",
      "  hi       Sih  ",
      "  h          h  ",
      "  hn        Wh  ",
      "  hn         h  ",
      "  hi        ih  ",
      "  hhQQQQQQQQhh  ",
      "                ",
      "                ",
      "                "
    ],
    [
      "                ",
      "                ",
      "  hhhhhhhhhhhh  ",
      " Xhi o  xxx ih  ",
      "  h  o  ZZ  Mh  ",
      "  h  o     0Mh  ",
      "  hkko       h  ",
      "  hi        ih  ",
      "  h Y       3h  ",
      "  h         2h  ",
      "  h         1h  ",
      "  hi        ih  ",
      "  hhQQQQQQQQhh  ",
      "                ",
      "                ",
      "                "
    ],
    [
      "                ",
      "                ",
      "  hhhhhhhhhhhh  ",
      "  hi o      ih  ",
      "  67 o      76  ",
      "  57 o      75  ",
      "  47ko      74  ",
      "  hi$%      ih  ",
      "  67#       76  ",
      "  57#   ^   75  ",
      "  47@       74  ",
      "  hi9999    ih  ",
      "  hhhhhhhhhhhh  ",
      "    88888888    ",
      "                ",
      "                "
    ],
    [
      "                ",
      "                ",
      "  &hhhhhhhhhh&  ",
      "  &*(7    7+*&  ",
      "  &* 7    7 *&  ",
      "  &* 7  ) 7 *&  ",
      "  &* 7    7 *&  ",
      "  &*(7    7+*&  ",
      "  &* 7    7 *&  ",
      "  &* 7  ) 7 *&  ",
      "  &* 7    7 *&  ",
      "  &*(7    7+*&  ",
      "  &hhhhhhhhhh&  ",
      "                ",
      "                ",
      "                "
    ]
  ]
}