{
  "name": "building_bank1_ground_270",
  "refpalette": "c70cities:building_bank1_ground_palette_270",
  "xsize": 16,
  "zsize": 16,
  "slices": [
    [
      "GGGGGGGGGGGGGGGG",
      "GGaGGaaaaGGaaaGG",
      "GabbbbbbbbbbbbaG",
      "GabcbbbbbbbbbbGG",
      "GabbbbbbbbbbbbGG",
      "GGbbbbbbbbbbbbaG",
      "GGbbbbbbbbbbbbaG",
      "Gabb!bbbbbbbbbaG",
      "GabbbbbbbbbbbbaG",
      "GabbbbbbbbbbbbGG",
      "GabbbbbbbbbbbbGG",
      "GGbbbbbbbbbbbbaG",
      "GGbbbbbbbbbbbbaG",
      "GabbbbbbbbbbbbaG",
      "GGaaaGGaaaaGGaGG",
      "GGGGGGGGGGGGGGGG"
    ],
    [
      "                ",
      " da  aaaa  aaad ",
      " aeefereeefeeea ",
      " ae  aoqo  i e  ",
      " aeata       f  ",
      "  f        j ea ",
      "  e       lj ea ",
      " aeuu      k ea ",
      " aeuw s   lk ea ",
      " aeuw s    j e  ",
      " aeuu        f  ",
      "  f          ea ",
      "  e    mpnm  ga ",
      " aeeefheeeefhea ",
      " daaa  aaaa  ad ",
      "                "
    ],
    [
      "                ",
      " da  aaaa  aaad ",
      " aeefereeefeeea ",
      " ae  a    i  e  ",
      " aeaBa       f  ",
      "  f        y ea ",
      "  e          ea ",
      " ae        A ea ",
      " ae          ea ",
      " ae          e  ",
      " ae          f  ",
      "  f          ea ",
      "  e    m  m  ga ",
      " aeeefxeeeefxea ",
      " daaa  aaaa  ad ",
      "                "
    ],
    [
      "                ",
      " dE  aaaE  aaad ",
      " aefeereefeeeeC ",
      " ae  a   i   f  ",
      " aeaaa       e  ",
      "  e          ea ",
      "  f          ea ",
      " Fe          ea ",
      " ae          eC ",
      " ae          f  ",
      " ae          e  ",
      "  e          ea ",
      "  f          ea ",
      " Feeeefeeeeefea ",
      " daaa  Daaa  Dd ",
      "                "
    ],
    [
      "                ",
      " d   aaa   aaad ",
      " aefeereefeeee  ",
      " ae  a  i    f  ",
      " aeaaa       e  ",
      "  e          ea ",
      "  f          ea ",
      "  e          ea ",
      " ae          e  ",
      " ae          f  ",
      " ae          e  ",
      "  e          ea ",
      "  f          ea ",
      "  eeeefeeeeefea ",
      " daaa   aaa   d ",
      "                "
    ],
    [
      "                ",
      "    LaaE  LaaE  ",
      " Ffeeerefeeeef  ",
      " aeJJaJi   JJe  ",
      " aeaaaJJJJJJJeI ",
      " OeJJJJJJJJJJea ",
      "  eJJJJJJJJJJea ",
      "  fJJMMMMMMJJeC ",
      " FeJJMNNNNMJJf  ",
      " aeJJMNNNNMJJe  ",
      " aeJJMMMMMMJJeI ",
      " OeJJJJJJJJJJea ",
      "  eJJJJJJJJJJea ",
      "  feeeefeeeeefC ",
      "  DaaK  DaaK    ",
      "                "
    ]
  ]
}