{
  "name": "building_apartment1_ground",
  "refpalette": "c70cities:building_apartment1_ground_palette",
  "xsize": 16,
  "zsize": 16,
  "slices": [
    [
      "GGGGGGGGGGGGGGGG",
      "GaaaaaaaaaaaaaaG",
      "GaaaaaaaaaaaaaaG",
      "GaaaaaaaaaaaaaaG",
      "GaaaaaaaaaaaaaaG",
      "GaaaaaaaaaaaaaaG",
      "GaaaaaaaaaaaaaaG",
      "GaaaaaaaaaaaaaaG",
      "GaaaaaaaaaaaaaaG",
      "GaaaaaaaaaaaaaaG",
      "GaaaaaaaaaaaaaaG",
      "GaaaaaaaaaaaaaaG",
      "GaaaaaaaaaaaaaaG",
      "GaaaaaaaaaaaaaaG",
      "GaaaaaaaaaaaaaaG",
      "GGGGGGGGGGGGGGGG"
    ],
    [
      "                ",
      " bbccccccccccbb ",
      " d efgbhib jj d ",
      " d   gb  bkllmd ",
      " d   nbbobkllmd ",
      " bp   b   kllmd ",
      " qr        ss d ",
      " tu   w       d ",
      " xu        yApd ",
      " qr      bbbbbb ",
      " dp      B   C  ",
      " d DDDD  E  FC  ",
      " d I ID  b  rC  ",
      " d      pbJJCC  ",
      " dddddddKb      ",
      "                "
    ],
    [
      "                ",
      " bbbbbbbbbbbbbb ",
      " d   gb Lb    d ",
      " d    b  b    d ",
      " d    bbMb    d ",
      " bp   b       d ",
      " qr           d ",
      " N            d ",
      " O           pd ",
      " qr      bbbbbb ",
      " dp      P   Q  ",
      " d   R   S   J  ",
      " d       b TFC  ",
      " d      pbCCCC  ",
      " dddddddKb      ",
      "                "
    ],
    [
      "                ",
      " bbddbbddbbddbb ",
      " d    b  b    d ",
      " d    b  b    d ",
      " d    bbUb    d ",
      " b    b       d ",
      " qr           d ",
      " V            d ",
      " V            d ",
      " qr      bbbbbb ",
      " d       W   C  ",
      " d       W   C  ",
      " d       brX C  ",
      " d       bCCYZ  ",
      " dddddddKb      ",
      "                "
    ],
    [
      "                ",
      " bbccbbccbbccbb ",
      " K    b  b    K ",
      " K    b  b    K ",
      " K    bbbb    K ",
      " b    b  b    K ",
      " qr      b    K ",
      "  r      b    K ",
      "  r      b    K ",
      " qr      bbbbbb ",
      " K       b   Y  ",
      " K       b0  Y  ",
      " K       bX  Y  ",
      " K       b1JJC  ",
      " qKKKKKKKb      ",
      "                "
    ],
    [
      "                ",
      " bbbbbbbbbbbbbb ",
      " bCCCCb22bCCCCb ",
      " bCCCCb22bCCCCb ",
      " bCCCCbbbbCCCCb ",
      " bCCCCbCCbCCCCb ",
      " bCCCCCCCbCCCCb ",
      " bCCC!3CCbCCCCb ",
      " bCCCw4CCbCCCCb ",
      " bCCCCCCCbbbbbb ",
      " bCCCCCCCbr  C  ",
      " bCCCCCCCb5  C  ",
      " bCCCCCCCb   C  ",
      " bCCCCCCCbCCCC  ",
      " bbbbbbbbb      ",
      "                "
    ]
  ]
}