{
  "name": "building_residential2_floor1_90",
  "refpalette": "c70cities:building_residential2_floor1_palette_90",
  "xsize": 16,
  "zsize": 16,
  "slices": [
    [
      "                ",
      "    mqu         ",
      "  ddddddd       ",
      "  d lpt w  AB   ",
      " cd  o  w   B   ",
      " bd kkkkw       ",
      " ad jjjjw       ",
      "  d     w   B   ",
      "  d     w   B   ",
      " cdffff y       ",
      " bdffff x       ",
      " adfiif w   B   ",
      "  dehhs w   B   ",
      "  ddddddd       ",
      "    gnr         ",
      "                "
    ],
    [
      "                ",
      "                ",
      "  dCDDDCd       ",
      "  C  F  w   B   ",
      "  D     w   B   ",
      "  D     w       ",
      "  D     w       ",
      "  D     w   B   ",
      "  D     w   B   ",
      "  D     J       ",
      "  D     I       ",
      "  D     w   B   ",
      "  CE    w   B   ",
      "  dCDDDCd       ",
      "                ",
      "                "
    ],
    [
      "                ",
      "           KCLM ",
      "  dCDDDCd  KCLM ",
      "  C     w  KCLM ",
      "  D     w  KCLM ",
      "  D     w  KCLM ",
      "  D     w  KCLM ",
      "  D     w  KCLM ",
      "  D     w  KCLM ",
      "  D     w  KCLM ",
      "  D     w  KCLM ",
      "  D     w  KCLM ",
      "  C     w  KCLM ",
      "  dCDDDCd  KCLM ",
      "           KCLM ",
      "                "
    ],
    [
      "                ",
      "        KCLM  ~ ",
      "  dddddddCLM    ",
      "  d     CCLM    ",
      "  d     CCLM    ",
      "  d     CCLM    ",
      "  d     CCLM    ",
      "  d     CCLM    ",
      "  d     CCLM    ",
      "  d     CCLM    ",
      "  d     CCLM    ",
      "  d     CCLM    ",
      "  d     CCLM    ",
      "  dddddddCLM    ",
      "        KCLM    ",
      "                "
    ],
    [
      "                ",
      "     KCLM     ~ ",
      "  BB KCLM       ",
      "     KCLM       ",
      "     KCLM       ",
      "  B  KCLM       ",
      "  B  KCLM       ",
      "     KCLM       ",
      "     KCLM       ",
      "  B  KCLM       ",
      "  B  KCLM       ",
      "     KCLM       ",
      "     KCLM       ",
      "  BB KCLM       ",
      "     KCLM       ",
      "                "
    ],
    [
      "                ",
      "  KCLM        ~ ",
      "  CCLM          ",
      "  KCLM          ",
      "  KCLM          ",
      "  CCLM          ",
      "  CCLM          ",
      "  KCLM          ",
      "  KCLM          ",
      "  CCLM          ",
      "  CCLM          ",
      "  KCLM          ",
      "  KCLM          ",
      "  CCLM          ",
      "  KCLM          ",
      "                "
    ]
  ]
}