{
  "name": "building_residential2_floor1_270",
  "refpalette": "c70cities:building_residential2_floor1_palette_270",
  "xsize": 16,
  "zsize": 16,
  "slices": [
    [
      "                ",
      "         rng    ",
      "       ddddddd  ",
      "   C   x shhed  ",
      "   C   x fiifda ",
      "       y ffffdb ",
      "       A ffffdc ",
      "   C   x     d  ",
      "   C   x     d  ",
      "       xjjjj da ",
      "       xkkkk db ",
      "   C   x  o  dc ",
      "   CB  xwtpl d  ",
      "       ddddddd  ",
      "         uqm    ",
      "                "
    ],
    [
      "                ",
      "                ",
      "       dDEEEDd  ",
      "   C   x    FD  ",
      "   C   x     E  ",
      "       J     E  ",
      "       K     E  ",
      "   C   x     E  ",
      "   C   x     E  ",
      "       x     E  ",
      "       x     E  ",
      "   C   x     E  ",
      "   C   x  I  D  ",
      "       dDEEEDd  ",
      "                ",
      "                "
    ],
    [
      "                ",
      " NMDL           ",
      " NMDL  dDEEEDd  ",
      " NMDL  x     D  ",
      " NMDL  x     E  ",
      " NMDL  x     E  ",
      " NMDL  x     E  ",
      " NMDL  x     E  ",
      " NMDL  x     E  ",
      " NMDL  x     E  ",
      " NMDL  x     E  ",
      " NMDL  x     E  ",
      " NMDL  x     D  ",
      " NMDL  dDEEEDd  ",
      " NMDL           ",
      "                "
    ],
    [
      "                ",
      "    NMDL        ",
      "    NMDddddddd  ",
      "    NMDD     d  ",
      "    NMDD     d  ",
      "    NMDD     d  ",
      "    NMDD     d  ",
      "    NMDD     d  ",
      "    NMDD     d  ",
      "    NMDD     d  ",
      "    NMDD     d  ",
      "    NMDD     d  ",
      "    NMDD     d  ",
      "    NMDddddddd  ",
      "    NMDL        ",
      "                "
    ],
    [
      "                ",
      "       NMDL     ",
      "       NMDL CC  ",
      "       NMDL     ",
      "       NMDL     ",
      "       NMDL  C  ",
      "       NMDL  C  ",
      "       NMDL     ",
      "       NMDL     ",
      "       NMDL  C  ",
      "       NMDL  C  ",
      "       NMDL     ",
      "       NMDL     ",
      "       NMDL CC  ",
      "       NMDL     ",
      "                "
    ],
    [
      "                ",
      "          NMDL  ",
      "          NMDD  ",
      "          NMDL  ",
      "          NMDL  ",
      "          NMDD  ",
      "          NMDD  ",
      "        ~ NMDL  ",
      "          NMDL  ",
      "          NMDD  ",
      "          NMDD  ",
      "          NMDL  ",
      "          NMDL  ",
      "          NMDD  ",
      "          NMDL  ",
      "                "
    ]
  ]
}