{
  "name": "building_hotel2_floor2_180",
  "refpalette": "c70cities:building_hotel2_floor2_palette_180",
  "xsize": 16,
  "zsize": 16,
  "slices": [
    [
      "                ",
      "              a ",
      "    dddddddddda ",
      "    dccccccccca ",
      "    dccccccccca ",
      "    dccccccccca ",
      "    dcccccccc!a ",
      "    dccc!ccccca ",
      "    dcccccccc!a ",
      "    dccccccccca ",
      "    dccccccccca ",
      "    dcccccccc=a ",
      "    dccccccccba ",
      "    dccccccccba ",
      " aaaaaaaaaaaaaa ",
      "                "
    ],
    [
      "                ",
      "              a ",
      "    ffffffffffa ",
      "    f      Ayxa ",
      "    f  ww     a ",
      "    f utt     a ",
      "    faaaaa ss=a ",
      "    frr pa aaaa ",
      "    f    a q pa ",
      "    f   oa anma ",
      "    fj iha alka ",
      "    fj ihagaa=a ",
      "    f    a   ba ",
      "    f    e   ba ",
      " aaaaaaaaaaaaaa ",
      "                "
    ],
    [
      "                ",
      "              a ",
      "    ffffffffffa ",
      "    f       I a ",
      "    f         a ",
      "    f         a ",
      "    faaaaa   Fa ",
      "    f E  a aaaa ",
      "    f    a D  a ",
      "    f    a a  a ",
      "    f    a a  a ",
      "    f    aCaa=a ",
      "    f    a   ba ",
      "    f    B   ba ",
      " aaaaaaaaaaaaaa ",
      "                "
    ],
    [
      "                ",
      "              a ",
      "    ffffffffffa ",
      "    f         a ",
      "    f         a ",
      "    f         a ",
      "    faaaaa KKJa ",
      "    f    a aaaa ",
      "    f    a a  a ",
      "    f    a a  a ",
      "    f    a a  a ",
      "    f    aaaa=a ",
      "    f    a   ba ",
      "    f    a   ba ",
      " aaaaaaaaaaaaaa ",
      "                "
    ],
    [
      "                ",
      "              a ",
      "    ffffffffffa ",
      "    f         a ",
      "    f         a ",
      "    f         a ",
      "    faaaaa    a ",
      "    f    a aaaa ",
      "    f    a a  a ",
      "    f    a a  a ",
      "    f    a a  a ",
      "    f    aaaa=a ",
      "    f    a L ba ",
      "    f    a L ba ",
      " aaaaaaaaaaaaaa ",
      "                "
    ],
    [
      "                ",
      "              a ",
      "    IIIIIIIIIIa ",
      "    IMMMMMMMMMa ",
      "    IMMMMMMMMMa ",
      "    IMMMMMMMMMa ",
      "    IMaaaaMMMMa ",
      "    IMMMMaMaaaa ",
      "    IMMMMaMaMMa ",
      "    IMMMMaMaMMa ",
      "    IMMMMaMaMMa ",
      "    IMMMMaaaa=a ",
      "    IMMMMaMMMba ",
      "    IMMMMaMMMba ",
      " aaaaaaaaaaaaaa ",
      "                "
    ]
  ]
}