{
  "name": "building_hotel2_floor2_90",
  "refpalette": "c70cities:building_hotel2_floor2_palette_90",
  "xsize": 16,
  "zsize": 16,
  "slices": [
    [
      "                ",
      " a              ",
      " a              ",
      " a              ",
      " adddddddddddd  ",
      " acccccccccccd  ",
      " acccccccccccd  ",
      " acccccccccccd  ",
      " acccccc!ccccd  ",
      " acccccccccccd  ",
      " acccccccccccd  ",
      " acccccccccccd  ",
      " acccccccccccd  ",
      " abb=cc!c!cccd  ",
      " aaaaaaaaaaaaaa ",
      "                "
    ],
    [
      "                ",
      " a              ",
      " a              ",
      " a              ",
      " affffffffffff  ",
      " a  jj  sa   f  ",
      " a      saw  f  ",
      " a  ii   aux f  ",
      " a  hhnqraux f  ",
      " aeaaaaaaa   f  ",
      " a  g        f  ",
      " a  aaapat  Bf  ",
      " a  al  at  Af  ",
      " abb=kmoa=  yf  ",
      " aaaaaaaaaaaaaa ",
      "                "
    ],
    [
      "                ",
      " a              ",
      " a              ",
      " a              ",
      " affffffffffff  ",
      " a       a   f  ",
      " a      Ia   f  ",
      " a       a   f  ",
      " a       a   f  ",
      " aCaaaaaaa   f  ",
      " a  D        f  ",
      " a  aaaFa    f  ",
      " a  a   a   Kf  ",
      " abb=E  aJ   f  ",
      " aaaaaaaaaaaaaa ",
      "                "
    ],
    [
      "                ",
      " a              ",
      " a              ",
      " a              ",
      " affffffffffff  ",
      " a       a   f  ",
      " a       a   f  ",
      " a       a   f  ",
      " a       a   f  ",
      " aaaaaaaaa   f  ",
      " a  a        f  ",
      " a  aaaaaN   f  ",
      " a  a   aN   f  ",
      " abb=L  aM   f  ",
      " aaaaaaaaaaaaaa ",
      "                "
    ],
    [
      "                ",
      " a              ",
      " a              ",
      " a              ",
      " affffffffffff  ",
      " a       a   f  ",
      " a       a   f  ",
      " a       a   f  ",
      " a       a   f  ",
      " aaaaaaaaa   f  ",
      " a  a        f  ",
      " aOOaaaaa    f  ",
      " a  a   a    f  ",
      " abb=   aP   f  ",
      " aaaaaaaaaaaaaa ",
      "                "
    ],
    [
      "                ",
      " a              ",
      " a              ",
      " a              ",
      " aKKKKKKKKKKKK  ",
      " aQQQQQQQQQQQK  ",
      " aQQQQQQQaQQQK  ",
      " aQQQQQQQaQQQK  ",
      " aQQQQQQQaQQQK  ",
      " aaaaaaaaaQQQK  ",
      " aQQaQQQQQQQQK  ",
      " aQQaaaaaQQQQK  ",
      " aQQaQQQaQQQQK  ",
      " abb=QQQaQQQQK  ",
      " aaaaaaaaaaaaaa ",
      "                "
    ]
  ]
}