{
  "name": "building_office1_base1_270",
  "refpalette": "c70cities:building_office1_base1_palette_270",
  "xsize": 16,
  "zsize": 16,
  "slices": [
    [
      "vvvvvvvvvvvvvvvv",
      "vaaaaaaaaaaaaaav",
      "vabbaaaaaaaaa!av",
      "vaaaaaaaaaaaaaav",
      "vaaaaaaaaaaaaaav",
      "vaaaaaaaaaaaaaav",
      "vaaaaaaaaaaaaaav",
      "vaaaaaaaaaaaaaav",
      "vaaaaaaaaaaaaaav",
      "vaaaaaaaaaaaaaav",
      "vaaaaaaaaaaaaaav",
      "vaaaaaaaaaaaaaav",
      "vaaaaaaaaaaaaaav",
      "vaaaaaaaaaaaa!av",
      "vaaaaaaaaaaaaaav",
      "vvvvvvvvvvvvvvvv"
    ],
    [
      "vvvvvvvvvvvvvvvv",
      "vccccccccccccccv",
      "vcbbedddddddddcv",
      "vc            cv",
      "vc            cv",
      "vc            cv",
      "vc   ddd  ddddcv",
      "vc            cv",
      "vc            cv",
      "vc   ddd  ddddcv",
      "vc            cv",
      "vc            cv",
      "vc            cv",
      "vcffedddddddddcv",
      "vccccccccccccccv",
      "vvvvvvvvvvvvvvvv"
    ],
    [
      "vvvvvvvvvvvvvvvv",
      "vccccccccccccccv",
      "vcbbedddddddddcv",
      "vc            cv",
      "vc            cv",
      "vc            cv",
      "vc   ddd  ddddcv",
      "vc            cv",
      "vc            cv",
      "vc   ddd  ddddcv",
      "vc            cv",
      "vc            cv",
      "vc            cv",
      "vc  edddddddddcv",
      "vccccccccccccccv",
      "vvvvvvvvvvvvvvvv"
    ],
    [
      "vvvvvvvvvvvvvvvv",
      "vccccccccccccccv",
      "vcbbedddddddddcv",
      "vc            cv",
      "vc            cv",
      "vc            cv",
      "vc            cv",
      "vc            cv",
      "vc            cv",
      "vc            cv",
      "vc            cv",
      "vc            cv",
      "vc            cv",
      "vc  edddddddddcv",
      "vccccccccccccccv",
      "vvvvvvvvvvvvvvvv"
    ],
    [
      "vvvvvvvvvvvvvvvv",
      "vccccccccccccccv",
      "vcbbe         cv",
      "vc            cv",
      "vc            cv",
      "vc            cv",
      "vc            cv",
      "vc            cv",
      "vc            cv",
      "vc            cv",
      "vc            cv",
      "vc            cv",
      "vc            cv",
      "vc  e         cv",
      "vccccccccccccccv",
      "vvvvvvvvvvvvvvvv"
    ],
    [
      "vvvvvvvvvvvvvvvv",
      "vccccccccccccccv",
      "vcbbegggggggggcv",
      "vcggggggggggggcv",
      "vcggggggggggggcv",
      "vcggggggggggggcv",
      "vcggggggggggggcv",
      "vcggggggggggggcv",
      "vcggggggggggggcv",
      "vcggggggggggggcv",
      "vcggggggggggggcv",
      "vcggggggggggggcv",
      "vcggggggggggggcv",
      "vcggegggggggggcv",
      "vccccccccccccccv",
      "vvvvvvvvvvvvvvvv"
    ]
  ]
}