{
  "name": "building_residential3_ground_90",
  "refpalette": "c70cities:building_residential3_ground_palette_90",
  "xsize": 16,
  "zsize": 16,
  "slices": [
    [
      "GGGGGGGGGGGGGGGG",
      "GGGGGGGGGGGGGGGG",
      "GGaaaaaaaaaaaaGG",
      "GGabbbbbbbbbbaGG",
      "GGabbbbbbbbbbaGG",
      "GGabbbbbbbbbbaGG",
      "GGabbbbbbbbbbaGG",
      "GGabbbbbbbbbaaGG",
      "GGabbbbbddddcGGG",
      "GGabbbbbddddcGGG",
      "GGabbbbbddddcGGG",
      "GGabbbbbddddcGGG",
      "GGabbbbacccccGGG",
      "GGaaaaaaGGGGGGGG",
      "GGGGGGGGGGGGGGGG",
      "GGGGGGGGGGGGGGGG"
    ],
    [
      "effffgffffeffffe",
      "f              f",
      "f hhhhhhhhhhhh f",
      "f h mo uu AF i f",
      "f h  p       I f",
      "g hkko       I g",
      "f h!      yy i f",
      "f h    tthhhhh f",
      "f h        Ecx f",
      "f hj   s   Dcx f",
      "g h   qr   Ccx g",
      "f h   qrw  Bcx f",
      "f h    hcccccx f",
      "f hilnih xxxxx f",
      "f              f",
      "effe  efffgffffe"
    ],
    [
      "effffgffffeffffe",
      "f              f",
      "f hhJhIhhIIIhh f",
      "f h Mo PQ    i f",
      "f J  O       I f",
      "g hkko       I g",
      "f I L     SS i f",
      "f h    tthhhhh f",
      "f hj       Uc  f",
      "f I         R  f",
      "g I         R  g",
      "f I        Tc  f",
      "f h    hcRRcc  f",
      "f hiKNih       f",
      "f              f",
      "effe  efffgffffe"
    ],
    [
      "          W     ",
      "                ",
      "  hhYhYhhYYYhh  ",
      "  h  o       i  ",
      "  V  o       0  ",
      "  hkko       0  ",
      "  V          i  ",
      "  hj   tthhhhh  ",
      "  h         cZ  ",
      "  V         cZ  ",
      "  V         cZ  ",
      "  V         cZ  ",
      "  h    hcccccZ  ",
      "  hiXXihZZZZZZ  ",
      "                ",
      "   W            "
    ],
    [
      "                ",
      "                ",
      "  hhhhhhhhhhhh  ",
      "  hbbbbbbbbbbh  ",
      "  hbbbbbbbbbbh  ",
      "  hbbbbbbbbbbh  ",
      "  hjbbbbbbbbbh  ",
      "  h bbbbbbbbhh  ",
      "  h bbbb    41  ",
      "  h bbbb    41  ",
      "  hbbbbb    41  ",
      "  hbbbbb    41  ",
      "  hbbbbh222231  ",
      "  hhhhhh111111  ",
      "                ",
      "                "
    ],
    [
      "                ",
      "                ",
      "  hIIIIhhYYYhh  ",
      "  h    ^i9)) I  ",
      "  V   @%i*((*I  ",
      "  V    $i****I  ",
      "  V 7        I  ",
      "  h 7  #####hh  ",
      "  h 7  #&   c1  ",
      "  V 7  #    c1  ",
      "  V6  9#    c1  ",
      "  V5  8#    c1  ",
      "  h5  8hccccc1  ",
      "  hIIIIh111111  ",
      "                ",
      "                "
    ]
  ]
}