{
  "name": "building_office4_top_180",
  "refpalette": "c70cities:building_office4_top_palette_180",
  "xsize": 16,
  "zsize": 16,
  "slices": [
    [
      "                ",
      "    abaaaaba    ",
      "  cccdeeeedccc  ",
      "  cheeeeeeeefc  ",
      " aceeeeeeeeeeca ",
      " bdeeGGeeeeeedb ",
      " aeeeGGeGGGeeea ",
      " aeeeeeGGGeeega ",
      " aeeeeeGGGeeega ",
      " aeeeGGeGGGeeea ",
      " bdeeGGeeeeeedb ",
      " aceeeeeeeeeeca ",
      "  cfeeeeeeeefc  ",
      "  cccdeeeedccc  ",
      "    abaaaaba    ",
      "                "
    ],
    [
      "                ",
      "    abaaaaba    ",
      "  iiijiiiijiii  ",
      "  ikkk qp kkki  ",
      " aik        kia ",
      " bjk        kjb ",
      " ai          ia ",
      " aio          a ",
      " ain          a ",
      " ai          ia ",
      " bjk        kjb ",
      " aik        kia ",
      "  ikkk ml kkki  ",
      "  iiijiiiijiii  ",
      "    abaaaaba    ",
      "                "
    ],
    [
      "                ",
      "    ab    ba    ",
      "  iiijiiiijiii  ",
      "  i          i  ",
      " ai          ia ",
      " bj          jb ",
      "  i          i  ",
      "  i             ",
      "  i             ",
      "  i          i  ",
      " bj          jb ",
      " ai          ia ",
      "  i          i  ",
      "  iiijiiiijiii  ",
      "    ab    ba    ",
      "                "
    ],
    [
      "                ",
      "    a      a    ",
      "   iijiiiijii   ",
      "  i          i  ",
      " ai          ia ",
      "  j          j  ",
      "  i          i  ",
      "  i          i  ",
      "  i          i  ",
      "  i          i  ",
      "  j          j  ",
      " ai          ia ",
      "  i          i  ",
      "   iijiiiijii   ",
      "    a      a    ",
      "                "
    ],
    [
      "                ",
      "                ",
      "   iijiiiijii   ",
      "  i          i  ",
      "  i          i  ",
      "  j          j  ",
      "  i          i  ",
      "  i          i  ",
      "  i          i  ",
      "  i          i  ",
      "  j          j  ",
      "  i          i  ",
      "  i          i  ",
      "   iijiiiijii   ",
      "                ",
      "                "
    ],
    [
      "                ",
      "                ",
      "                ",
      "   iijiiiijii   ",
      "   iijiiiijii   ",
      "   jjsjjjjrjj   ",
      "   iijjjjjjii   ",
      "   iijjjjjjii   ",
      "   iijjjjjjii   ",
      "   iijjjjjjii   ",
      "   jjrjjjjrjj   ",
      "   iijiiiijii   ",
      "   iijiiiijii   ",
      "                ",
      "                ",
      "                "
    ]
  ]
}