{
  "name": "building_hotel3_floor1_270",
  "refpalette": "c70cities:building_hotel3_floor1_palette_270",
  "xsize": 16,
  "zsize": 16,
  "slices": [
    [
      "                ",
      "  a a a a a a   ",
      "  bbbbbbbbbbbba ",
      " abccccccccccb  ",
      "  bceeeeeeeecba ",
      " abceffffffecb  ",
      "  bceffffffecba ",
      " abceffffffedb  ",
      "  bceffffffedba ",
      " abceffffffecb  ",
      "  bceffffffecba ",
      " abceeeeeeeecb  ",
      "  bccccccccccba ",
      " abbbbbbbbbbbb  ",
      "   a a a a a a  ",
      "                "
    ],
    [
      "                ",
      "  a a a a a a   ",
      "  bbbbbbbbbbbba ",
      " ab          b  ",
      "  b teeeeeee ba ",
      " ab m o jjhe b  ",
      "  b ms    he ba ",
      " ab mpp nhhedb  ",
      "  b mqq hkiedba ",
      " ab mrr hlhe b  ",
      "  b m      g ba ",
      " ab tmmmmmee b  ",
      "  b          ba ",
      " abbbbbbbbbbbb  ",
      "   a a a a a a  ",
      "                "
    ],
    [
      "                ",
      "  a a a a a a   ",
      "  bbbbbbbbbbbba ",
      " ab          b  ",
      "  b texxxxee ba ",
      " ab  A    we b  ",
      "  b  A     e ba ",
      " ab  pp  hhedb  ",
      "  b     h  edba ",
      " ab     hyhe b  ",
      "  b        u ba ",
      " ab t     ee b  ",
      "  b          ba ",
      " abbbbbbbbbbbb  ",
      "   a a a a a a  ",
      "                "
    ],
    [
      "                ",
      "  a a a a a a   ",
      "  bbbbbbbbbbbba ",
      " ab          b  ",
      "  b teeeeeee ba ",
      " ab        e b  ",
      "  b        e ba ",
      " ab  pp  hhedb  ",
      "  b     h  edba ",
      " ab     hhhe b  ",
      "  b        e ba ",
      " ab t     ee b  ",
      "  b          ba ",
      " abbbbbbbbbbbb  ",
      "   a a a a a a  ",
      "                "
    ],
    [
      "                ",
      "  a a a a a a   ",
      "  bbbbbbbbbbbba ",
      " ab          b  ",
      "  b teeeeeee ba ",
      " ab       Ae b  ",
      "  b       Ae ba ",
      " ab   !  hhedb  ",
      "  b     h  edba ",
      " ab     hhhe b  ",
      "  b        e ba ",
      " ab t     ee b  ",
      "  b          ba ",
      " abbbbbbbbbbbb  ",
      "   a a a a a a  ",
      "                "
    ],
    [
      "                ",
      "  a a a a a a   ",
      "  bbbbbbbbbbbba ",
      " ab          b  ",
      "  b eeeeeeee ba ",
      " ab eBBBBBBe b  ",
      "  b eBBBBBBe ba ",
      " ab eBBBBBBedb  ",
      "  b eBBBBBBedba ",
      " ab eBBBBBBe b  ",
      "  b eBBBBBBe ba ",
      " ab eeeeeeee b  ",
      "  b          ba ",
      " abbbbbbbbbbbb  ",
      "   a a a a a a  ",
      "                "
    ]
  ]
}