{
  "name": "building_hotel3_floor3_270",
  "refpalette": "c70cities:building_hotel3_floor3_palette_270",
  "xsize": 16,
  "zsize": 16,
  "slices": [
    [
      "                ",
      "  a a a a a a   ",
      "  bbbbbbbbbbbba ",
      " abccccccccccb  ",
      "  bceeeeeeeecba ",
      " abceffffffecb  ",
      "  bceffffffecba ",
      " abceffffffedb  ",
      "  bceffffffedba ",
      " abceffffffecb  ",
      "  bceffffffecba ",
      " abceeeeeeeecb  ",
      "  bccccccccccba ",
      " abbbbbbbbbbbb  ",
      "   a a a a a a  ",
      "                "
    ],
    [
      "                ",
      "  a a a a a a   ",
      "  bbbbbbbbbbbba ",
      " ab          b  ",
      "  b peeeeeee ba ",
      " ab l      g b  ",
      "  b l onmjie ba ",
      " ab l on!eeedb  ",
      "  b eeeemkiedba ",
      " ab l onm  e b  ",
      "  b l      h ba ",
      " ab plllllee b  ",
      "  b          ba ",
      " abbbbbbbbbbbb  ",
      "   a a a a a a  ",
      "                "
    ],
    [
      "                ",
      "  a a a a a a   ",
      "  bbbbbbbbbbbba ",
      " ab          b  ",
      "  b pessssee ba ",
      " ab        q b  ",
      "  b        e ba ",
      " ab     eeeedb  ",
      "  b eeeet  edba ",
      " ab        e b  ",
      "  b        r ba ",
      " ab p     ee b  ",
      "  b          ba ",
      " abbbbbbbbbbbb  ",
      "   a a a a a a  ",
      "                "
    ],
    [
      "                ",
      "  a a a a a a   ",
      "  bbbbbbbbbbbba ",
      " ab          b  ",
      "  b peeeeeee ba ",
      " ab        e b  ",
      "  b        e ba ",
      " ab     eeeedb  ",
      "  b eeee   edba ",
      " ab        e b  ",
      "  b        e ba ",
      " ab p     ee b  ",
      "  b          ba ",
      " abbbbbbbbbbbb  ",
      "   a a a a a a  ",
      "                "
    ],
    [
      "                ",
      "  a a a a a a   ",
      "  bbbbbbbbbbbba ",
      " ab          b  ",
      "  b peeeeeee ba ",
      " ab        e b  ",
      "  b        e ba ",
      " ab     eeeedb  ",
      "  b eeee   edba ",
      " ab        e b  ",
      "  b        e ba ",
      " ab p     ee b  ",
      "  b          ba ",
      " abbbbbbbbbbbb  ",
      "   a a a a a a  ",
      "                "
    ],
    [
      "                ",
      "  a a a a a a   ",
      "  bbbbbbbbbbbba ",
      " ab          b  ",
      "  b eeeeeeee ba ",
      " ab euuuuuue b  ",
      "  b euuuuuue ba ",
      " ab euuueeeedb  ",
      "  b euuuuuuedba ",
      " ab euuuuuue b  ",
      "  b euuuuuue ba ",
      " ab eeeeeeee b  ",
      "  b          ba ",
      " abbbbbbbbbbbb  ",
      "   a a a a a a  ",
      "                "
    ]
  ]
}