{
  "name": "building_bunker1_ground_270",
  "refpalette": "c70cities:building_bunker1_ground_palette_270",
  "xsize": 16,
  "zsize": 16,
  "slices": [
    [
      "zzzzzzzzzzzzzzzz",
      "zzzzzzzzzzzzzzzz",
      "zzzzzzzzzzzzzzzz",
      "zzzzzzzbvbzzzzzz",
      "zzzzzzzvcvzzzzzz",
      "zzzzzzzvvvzzzzzz",
      "zzzzzzzzzzzzzzzz",
      "zzzzzzzzzzzzzazz",
      "zzzzzzzzzzzzazaz",
      "zzzzzzzzzzaazazz",
      "zzzzzzzzzzzazzaz",
      "zzzzzzzzzzzzazaz",
      "zzzzzzzzzzzazazz",
      "zzzzzzzzzazaaaaz",
      "zzzzzzzaazaazzzz",
      "zzzzzzzzzzzzzzzz"
    ],
    [
      "           dd   ",
      " eeee  d d eeee ",
      " eff d   g  ffe ",
      " ff     ff f fed",
      "   g   ff     e ",
      " d   hhhhh   g  ",
      " d    hhhhh  dd ",
      " df i           ",
      " ffd   ~        ",
      " ef             ",
      " e d         d  ",
      "d g             ",
      " e fdd d      d ",
      "defff g         ",
      " eeeeed  d      ",
      "d  d d          "
    ],
    [
      "                ",
      "                ",
      "  f         f   ",
      "                ",
      "        f       ",
      "       hh       ",
      "                ",
      "                ",
      "       ~        ",
      "                ",
      "                ",
      "                ",
      "                ",
      "  f             ",
      "                ",
      "                "
    ],
    [
      "                ",
      "                ",
      "                ",
      "                ",
      "                ",
      "                ",
      "                ",
      "                ",
      "       ~        ",
      "                ",
      "                ",
      "                ",
      "                ",
      "                ",
      "                ",
      "                "
    ],
    [
      "                ",
      "                ",
      "                ",
      "                ",
      "                ",
      "                ",
      "                ",
      "                ",
      "       ~        ",
      "                ",
      "                ",
      "                ",
      "                ",
      "                ",
      "                ",
      "                "
    ],
    [
      "                ",
      "                ",
      "                ",
      "                ",
      "                ",
      "                ",
      "                ",
      "                ",
      "       ~        ",
      "                ",
      "                ",
      "                ",
      "                ",
      "                ",
      "                ",
      "                "
    ]
  ]
}