{
  "name": "building_policeoffice1_base1",
  "refpalette": "c70cities:building_policeoffice1_base1_palette",
  "xsize": 16,
  "zsize": 16,
  "slices": [
    [
      "vvvvvvvvvvvvvvvv",
      "v==============v",
      "v=!==========!=v",
      "v==============v",
      "v==============v",
      "v=!==========!=v",
      "v==============v",
      "v==============v",
      "v==============v",
      "v==============v",
      "v==============v",
      "v=a============v",
      "v=bccccccccccc=v",
      "v=bccccccccccc=v",
      "v==============v",
      "vvvvvvvvvvvvvvvv"
    ],
    [
      "vvvvvvvvvvvvvvvv",
      "vaaaaaaaaaaaaaav",
      "vade   faf  ghav",
      "vaiii  ja   iiav",
      "va    kfaf    av",
      "vade   faf  ghav",
      "vaiii   a l iiav",
      "va    kfaf    av",
      "vade   faf  ghav",
      "vaiii   a   iiav",
      "vam     an   mav",
      "vaaiiiiioii iiav",
      "vab      p  i av",
      "vab           av",
      "vaaaaaaaaaaaaaav",
      "vvvvvvvvvvvvvvvv"
    ],
    [
      "vvvvvvvvvvvvvvvv",
      "vaaaaaaaaaaaaaav",
      "va      a     av",
      "vaiii   a   iiav",
      "va     ja     av",
      "va      a     av",
      "vaiii   aj  iiav",
      "va      a     av",
      "va      a     av",
      "vaiii   a   iiav",
      "va      o     av",
      "vaaiiiii ii iiav",
      "vab           av",
      "vab           av",
      "vaaaaaaaaaaaaaav",
      "vvvvvvvvvvvvvvvv"
    ],
    [
      "vvvvvvvvvvvvvvvv",
      "vaaaaaaaaaaaaaav",
      "va      a     av",
      "va      a     av",
      "va      a     av",
      "va     ja     av",
      "vaj     a     av",
      "va      a     av",
      "va      a     av",
      "va      a     av",
      "vaj     a     av",
      "vaaiiiiiaiiiiiav",
      "vab           av",
      "vab           av",
      "vaaaaaaaaaaaaaav",
      "vvvvvvvvvvvvvvvv"
    ],
    [
      "vvvvvvvvvvvvvvvv",
      "vaaaaaaaaaaaaaav",
      "vaj    ja     av",
      "vaj  j  aj   jav",
      "va    jja     av",
      "vaj    ja     av",
      "vaj    ja    jav",
      "va      a     av",
      "va      a     av",
      "vaj     aj    av",
      "vajj   jajj  jav",
      "vaaaaaaaaaaaaaav",
      "vab         j av",
      "vab           av",
      "vaaaaaaaaaaaaaav",
      "vvvvvvvvvvvvvvvv"
    ],
    [
      "vqqqqqqqqqqqqqqv",
      "vaaaaaaaaaaaaaaq",
      "varrrrrrarrrrraq",
      "varrrrrrarrrrraq",
      "varrrrrrarrrrraq",
      "varrrrrrarrrrraq",
      "varrrrrrarrrrraq",
      "varrrrrrarrrrraq",
      "varrrrrrarrrrraq",
      "varrrrrrarrrrraq",
      "varrrrrrarrrrraq",
      "vaaaaaaaaaaaaaaq",
      "vabsssssssssssaq",
      "vabsssssssssssaq",
      "vaaaaaaaaaaaaaaq",
      "vvvvvvvvvvvvvvvv"
    ]
  ]
}