{
  "name": "building_warehouse1_ground_90",
  "refpalette": "c70cities:building_warehouse1_ground_palette_90",
  "xsize": 16,
  "zsize": 16,
  "slices": [
    [
      "zzzzzzzzzzzzzzzz",
      "zbbbbbbbbbbdbbbz",
      "zbcccccccbdbbbdz",
      "zbcccccccbbbbbdz",
      "zbcccccccbbbbbbz",
      "zbcccccccbbbbbbz",
      "zbcccccccbbbbbbz",
      "zbcccccccbbbbbdz",
      "zbcccccccbbbbbbz",
      "zbcccccccbbbbbbz",
      "zbbbbbbbbbbbbbbz",
      "zbbddbbdbddbbbdz",
      "zzaaaaaaaaaaaaaz",
      "zaaaaaaaaaaaaazz",
      "zaazaazzaazaaaaz",
      "zaaazzzzzzzzazaz"
    ],
    [
      " e e  e  e e  e ",
      "egfgggggfg      ",
      " flkjnnnof  fg u",
      " gkjjnn igppgf  ",
      "egjjjnn      g e",
      " fjj         t  ",
      "egjj m       s e",
      " gj         rg  ",
      "efi      g  qf u",
      " g      igppgg  ",
      " fhhhghhhf  gg  ",
      "e              e",
      "                ",
      "                ",
      "e               ",
      "     e  e  e   e"
    ],
    [
      "                ",
      " gggfggggf      ",
      " fjj!nn of  gf  ",
      " fj i n  gppgg  ",
      " gj          g  ",
      " pj          y  ",
      " p           x  ",
      " f          wg  ",
      " g       g   g  ",
      " g       gppfg  ",
      " fhhhghhhg  gf  ",
      "                ",
      "                ",
      "                ",
      "                ",
      "                "
    ],
    [
      "                ",
      " ggfgggfgg      ",
      " gjj  niog  gg  ",
      " fj      fppfg  ",
      " gi      A   g  ",
      " g       A   C  ",
      " g       A   C  ",
      " g       A  Bg  ",
      " g       g   f  ",
      " g       gppgf  ",
      " ghhhfhhhg  gg  ",
      "                ",
      "                ",
      "                ",
      "                ",
      "                "
    ],
    [
      "                ",
      " fgggggggfDDDDD ",
      " gi     ogDDggD ",
      " g       gEEggD ",
      " g      Cg  BgD ",
      " g      Cg   gD ",
      " g      Cg   gD ",
      " gi  F  Cg  FgD ",
      " gi     if   gD ",
      " fEEEiEEEgEEggD ",
      " ggggggfgfDDggD ",
      "  DDDDDDDDDDDDD ",
      "                ",
      "                ",
      "                ",
      "                "
    ],
    [
      "                ",
      " ggggggggg      ",
      " gIIIIIIogJJJJ  ",
      " gIIIIIIIgJJJJ  ",
      " gIIIIIIIgJJJJ  ",
      " fIIIIIIIgJJJJ  ",
      " gIIIIIIIgJJJJ  ",
      " gIIIbIIIgJJJJ  ",
      " gIIIIIIIgJJJJ  ",
      " gIIIIIIIgJJJJ  ",
      " ggfgfggggJJJJ  ",
      "                ",
      "                ",
      "                ",
      "                ",
      "                "
    ]
  ]
}