{
  "name": "building_hotel1_ground_90",
  "refpalette": "c70cities:building_hotel1_ground_palette_90",
  "xsize": 16,
  "zsize": 16,
  "slices": [
    [
      "GGGGGGGGGGGGGGGG",
      "GbbbbbbbbddddbbG",
      "GbccccccccccccbG",
      "GbccccccccccccbG",
      "abccccccccccccbG",
      "GbccccccccccccbG",
      "GbccccGGGdccccbG",
      "GbccccGGGdccccbG",
      "GbccccGGGdccccbG",
      "Gbcccc!dddccccbG",
      "GbccccccccccccbG",
      "abccccccccccccbG",
      "GbccccccccccccbG",
      "Gbccccccccccc!bG",
      "GbbbbbbbbbbbbbbG",
      "GGGGGGGGGGGGGGGG"
    ],
    [
      "                ",
      "ebbbbbbbbp  pbb ",
      "ebggg   moqtomb ",
      "ebgig         b ",
      "eb            b ",
      "ebhh        wAb ",
      "eb    eeen su b ",
      "ebgig e  g  uyb ",
      "ebggg e  g su b ",
      "eb    llll  u b ",
      "ebf           b ",
      "ebf        bbbb ",
      "ebf        r  b ",
      "ebffjjkkkk b xb ",
      "ebbbbbbbbbbbbbb ",
      "                "
    ],
    [
      "                ",
      " bbbbbbbbp  pbb ",
      " b      BoCEoBb ",
      " b            b ",
      " b            b ",
      " b            b ",
      " b            b ",
      " b            p ",
      " b       n  F p ",
      " b    llgg    p ",
      " b            p ",
      " bf        bbbp ",
      " bf        D  p ",
      " bff       b  b ",
      " bbbbbppppbbbbb ",
      "                "
    ],
    [
      "                ",
      " bbbbbbbbppppbb ",
      " b      BooooBb ",
      " b            b ",
      " b            b ",
      " b            b ",
      " b            b ",
      " b            b ",
      " b            b ",
      " b    ggn     b ",
      " b            b ",
      " b         bbbb ",
      " bI        b  b ",
      " bf        b Ib ",
      " bbbbbbbbbbbbbb ",
      "                "
    ],
    [
      "                ",
      " bbbbbbbbppppbb ",
      " b       oooo b ",
      " b            b ",
      " b            b ",
      " b            b ",
      " b            b ",
      " b    g       p ",
      " b    g       p ",
      " b    n       b ",
      " b            b ",
      " b         bbbb ",
      " bI        b  b ",
      " bI       IbIIb ",
      " bbppbbbbbbbbbb ",
      "         ~      "
    ],
    [
      "                ",
      " bbbbbbbbppppbb ",
      " bJJJJJJJJJJJJb ",
      " bJJJJJJJJJJJJb ",
      " bJJJJJJJJJJJJb ",
      " bJJJJJJJJJJJJb ",
      " bJJJJg   JJJJb ",
      " bJJJJn   JJJJb ",
      " bJJJJ    JJJJb ",
      " bJJJJ    JJJJb ",
      " bJJJJJJJJJJJJb ",
      " bJJJJJJJJJbbbb ",
      " bJJJJJJJJJbJJb ",
      " bJJJJJJJJJbJJb ",
      " bbbbbbbbbbbbbb ",
      "                "
    ]
  ]
}