{
  "name": "building_factory2_ground_180",
  "refpalette": "c70cities:building_factory2_ground_palette_180",
  "xsize": 16,
  "zsize": 16,
  "slices": [
    [
      "zzzzzzzzzzzzzzzz",
      "zzzzzzzzzzzzzzzz",
      "zzzzzzzzzzzzzzzz",
      "zzzHHHHHHHHHzzzz",
      "zzzHHHHHHHHHzzzz",
      "zzzHHHHHHHHHzzaz",
      "zzHHHHHHHHHHzazz",
      "zzHHHHHHHHHHaaaz",
      "zzzHHHHHHHHHazaz",
      "zzzHHHHHHHHHaazz",
      "zzzHHHHHHHHHaaaz",
      "zzzHHHHHHHHHaaza",
      "zzzHHHHHHHHHzzzz",
      "zzzzzzzzzzzzzzzz",
      "zzzzzzzzzzzzzzzz",
      "zzzzzzzzzzzzzzzz"
    ],
    [
      " bbd c  b b b b ",
      "cec ccbcccdceb  ",
      "cfffffffffffccb ",
      "dffgg F Fg!fc d ",
      "bffE  D  ggocb  ",
      "eefCB    Agq b  ",
      "eefyxi    wqb   ",
      " ffkukt   gq    ",
      "cffnnnsr   q    ",
      "eefkkkp    o    ",
      "eefknnm i  f    ",
      "cffkkkf   il    ",
      "dffkkkfjihgfb b ",
      " fffffffffffcd  ",
      "beccc  b cccecb ",
      "  bcd b  bdc b  "
    ],
    [
      "                ",
      " e   c cc   e   ",
      " ffIIIffIIIfc   ",
      " ffj      Ofc   ",
      " ffP     Ogo    ",
      "eef        q    ",
      "eef        q    ",
      " fNM M     q    ",
      " ffnnn     q    ",
      "eefKKK     o    ",
      "eefKnKL    f    ",
      " ff KK     J    ",
      " ff nu     f    ",
      " fffffffIIIfc   ",
      " ec       cce   ",
      "                "
    ],
    [
      "                ",
      " e          e   ",
      " ffIIIffIIIf    ",
      " ff        f    ",
      " ff        o    ",
      "eef        q    ",
      "eef        q    ",
      " fQ        q    ",
      " ff P      q    ",
      "eefRRR     o    ",
      "eefRRRS    f    ",
      " ffRRR     Q    ",
      " ffj       f    ",
      " fffffffIIIf    ",
      " e         ce   ",
      "                "
    ],
    [
      "                ",
      " e          e   ",
      " UfTTTffTTTf    ",
      " Uf        f    ",
      " UfX       o    ",
      "UVf        oW   ",
      "UVf        oW   ",
      " Uf        oW   ",
      " UfX       oW   ",
      "UVf        o    ",
      "UVf        f    ",
      " Uf        f    ",
      " Ufj       f    ",
      " UffffffTTTf    ",
      " e          e   ",
      "                "
    ],
    [
      "                ",
      " e          e   ",
      "  fYYYffYYYf    ",
      "  f        f    ",
      "  f        Y    ",
      " Vf   00   Y    ",
      " Vf        Y    ",
      "  f        Y    ",
      "  f        Y    ",
      " Vf        Y    ",
      " Vf   0Z   f    ",
      "  f        f    ",
      "  f        f    ",
      "  fYYYffYYYf    ",
      " e          e   ",
      "                "
    ]
  ]
}