{
  "name": "building_apartment1_floor2_270",
  "refpalette": "c70cities:building_apartment1_floor2_palette_270",
  "xsize": 16,
  "zsize": 16,
  "slices": [
    [
      "                ",
      " aaaaaaaaaaaaaa ",
      " abbbbbbbbbbbba ",
      " abbbbbbbbbbbba ",
      " abbbbbbbbbbbba ",
      " abbbbbbbbbbbba ",
      " abbbbbbbbbbbba ",
      " abbbbbbbbbbbba ",
      " abbbbbbbbbbbba ",
      " abbbbbbbbbbbba ",
      "  d  cbbbbbbbba ",
      "  g bbbbbbbbbba ",
      "  hfbbbbbbbbbba ",
      "  ieedbbbbbbbba ",
      "      aaaaaaaaa ",
      "                "
    ],
    [
      "                ",
      " Vmmmmmmmmmmmmj ",
      " WTQMrq sq   nk ",
      " W   Lq rqA uok ",
      " W    DFDqB uok ",
      " W       C   pk ",
      " W NN I  qqqwqk ",
      " W    J  y x rk ",
      " W RO J  q y sk ",
      " Wqqqqq  q x  k ",
      "  U   q  q xqqk ",
      "  U   qFqq   !k ",
      "  dSP K EqA  nk ",
      "  ddddq EqB uok ",
      "      ttttttttl ",
      "                "
    ],
    [
      "                ",
      " 244442442qXXXq ",
      " 4#9  q 5q   Yq ",
      " X    q  q    q ",
      " X    D6Dq    q ",
      " X       3    q ",
      " X       qqq0qq ",
      " X       1 x  q ",
      " 4 88    q 1 Zq ",
      " qqqqqq  q x  q ",
      "  d   q  q xqqq ",
      "  d@  q6qq    q ",
      "  dP  7  q    q ",
      "  ddUhq  q    q ",
      "      qqqqqXXXq ",
      "                "
    ],
    [
      "                ",
      " 2XXX42XX2qXXXq ",
      " 4    q  q *^$q ",
      " X-   q  q    X ",
      " X[   DDDq    X ",
      " X]      q    q ",
      " X{      qqqqqq ",
      " X}      q x  X ",
      " 4 ))    q x  X ",
      " qqqqqq  q x  q ",
      "  dS  q  q xqqq ",
      "  d+  qqqq    X ",
      "  \\   q  q    X ",
      "  |dddq  q (&%q ",
      "      qXXqqXXXq ",
      "                "
    ],
    [
      "                ",
      " 244442442q444q ",
      " 4    q  q    q ",
      " 4    q  q    k ",
      " 4    DDDq    k ",
      " 4       q    q ",
      " 4    `  qqqqqq ",
      " 4       q x  k ",
      " 4       q x  k ",
      " qqqqqq  q x  q ",
      "  e+: q  q xqqq ",
      "  U   qqqq    k ",
      "  U   qf q    k ",
      "  d\\\\\\q  q    q ",
      "      q44qq444q ",
      "                "
    ],
    [
      "                ",
      " qqqqqqqqqqqqqq ",
      " qddddd;;qddddq ",
      " qddddd;;qddddq ",
      " qdddddddqddddq ",
      " qdddddddqddddq ",
      " qdddddddqqqqqq ",
      " qdddddddqdd;;q ",
      " qdddddddqdd;;q ",
      " qqqqqqddqdd;;q ",
      "  d cSqddqddddq ",
      "  d   qqqqddddq ",
      "  d   qddqddddq ",
      "  ddddqddqddddq ",
      "      qqqqqqqqq ",
      "                "
    ]
  ]
}