{
  "name": "building_apartment1_floor1_270",
  "refpalette": "c70cities:building_apartment1_floor1_palette_270",
  "xsize": 16,
  "zsize": 16,
  "slices": [
    [
      "                ",
      " aaaaaaaaaaaaaa ",
      " abbbbbbbbbbbba ",
      " abbbbbbbbbbbba ",
      " abbbbbbbbbbbba ",
      " abbbbbbbbbbbba ",
      " abbbbbbbbbbbba ",
      " abbbbbbbbbbbba ",
      " abbbbbbbbbbbba ",
      " abbbbbbbbbbbba ",
      "  d  cbbbbbbbba ",
      "  g bbbbbbbbbba ",
      "  hfbbbbbbbbbba ",
      "  ieedbbbbbbbba ",
      "      aaaaaaaaa ",
      "                "
    ],
    [
      "                ",
      " Xmmmmmmmmmmmmj ",
      " YVSOMp qp   nk ",
      " Y   Np rpB uok ",
      " Y    EIEpC uok ",
      " Y       D    k ",
      " Y PP J  pppwpk ",
      " Y    K  y x qk ",
      " Y!TQ K  p y rk ",
      " Yppppp  p x  k ",
      "  W   p  p xppk ",
      "  W   pIpp  uok ",
      "  dUR L FpB   k ",
      "  ddddp FpCA sk ",
      "      ttttttttl ",
      "                "
    ],
    [
      "                ",
      " 577775775pZZZp ",
      " 7^$  p  p   0p ",
      " Z   @p  p    p ",
      " Z    E8Ep    p ",
      " Z       6    p ",
      " Z       ppp2pp ",
      " Z       3 x  p ",
      " 7 ##    p 3  p ",
      " pppppp  p x 1p ",
      "  d   p  p xppp ",
      "  d%  p8pp  uop ",
      "  dR  9  p    p ",
      "  ddWhp  p4   p ",
      "      pppppZZZp ",
      "                "
    ],
    [
      "                ",
      " 5ZZZ75ZZ5pZZZp ",
      " 7    p  p -)&p ",
      " Z{   p  p    Z ",
      " Z{   EEEp    Z ",
      " Z}      p    p ",
      " Z\\      pppppp ",
      " Z\\      p x  Z ",
      " 7       p x  Z ",
      " pppppp  p x *p ",
      "  dU  p  p xppp ",
      "  d]  pppp    Z ",
      "  |   p  p    Z ",
      "  `dddp  p [+(p ",
      "      pZZppZZZp ",
      "                "
    ],
    [
      "                ",
      " 577775775p777p ",
      " 7    p  p    p ",
      " 7    p  p    k ",
      " 7    EEEp    k ",
      " 7       p    p ",
      " 7       pppppp ",
      " 7       p x  k ",
      " 7       p x  k ",
      " pppppp  p x  p ",
      "  e]: p  p xppp ",
      "  W   pppp    k ",
      "  W   pf p    k ",
      "  d|||p  p    p ",
      "      p77pp777p ",
      "                "
    ],
    [
      "                ",
      " pppppppppppppp ",
      " pddddd;;pddddp ",
      " pddddd;;pddddp ",
      " pdddddddpddddp ",
      " pdddddddpddddp ",
      " pdddddddpppppp ",
      " pdddddddpdd;;p ",
      " pdddddddpdd;;p ",
      " ppppppddpdd;;p ",
      "  d cUpddpddddp ",
      "  d   ppppddddp ",
      "  d   pddpddddp ",
      "  ddddpddpddddp ",
      "      ppppppppp ",
      "                "
    ]
  ]
}