{
  "name": "building_residential3_ground_180",
  "refpalette": "c70cities:building_residential3_ground_palette_180",
  "xsize": 16,
  "zsize": 16,
  "slices": [
    [
      "GGGGGGGGGGGGGGGG",
      "GGGGGGGGGGGGGGGG",
      "GGaaaaaaGGGGGGGG",
      "GGabbbbacccccGGG",
      "GGabbbbbddddcGGG",
      "GGabbbbbddddcGGG",
      "GGabbbbbddddcGGG",
      "GGabbbbbddddcGGG",
      "GGabbbbbbbbbaaGG",
      "GGabbbbbbbbbbaGG",
      "GGabbbbbbbbbbaGG",
      "GGabbbbbbbbbbaGG",
      "GGabbbbbbbbbbaGG",
      "GGaaaaaaaaaaaaGG",
      "GGGGGGGGGGGGGGGG",
      "GGGGGGGGGGGGGGGG"
    ],
    [
      "effffgffffgffffe",
      "f              f",
      "f hiFFihwwwwww f",
      "f h    hcccccw f",
      "f hE  xhDCBAcw f",
      "e hy  xh    cw g",
      "f h    h    cw f",
      "f hu   t    c  f",
      "f hu   t srrhh f",
      "f h       qq i e",
      "g hopo       n  ",
      "f hm k       l  ",
      "f h  k!  j   i e",
      "f hhhhhhhhhhhh f",
      "f              f",
      "effffgffffgffffe"
    ],
    [
      "effffgffffgffffe",
      "f              f",
      "f hiFFih       f",
      "f h    hcPPcc  f",
      "f F   QhS  Rc  f",
      "e F   Qh    P  g",
      "f F    h    P  f",
      "f hO   t    c  f",
      "f hN   t    hh f",
      "f F          i e",
      "g hoMo       L  ",
      "f IK k       J  ",
      "f h  k  j    i e",
      "f hhIhFhhFFFhh f",
      "f              f",
      "effffgffffgffffe"
    ],
    [
      "                ",
      "                ",
      "  hiYYihXXXXXX  ",
      "  h    hcccccX  ",
      "  W    h    cX  ",
      "U W    h    cX  ",
      "  W    h    cX  ",
      "  h    t    cX  ",
      "  h    t    hh  ",
      "  W          i  ",
      "  hooo       V  ",
      "  W  k       V  ",
      "  h  k j     i U",
      "  hhThThhTTThh  ",
      "                ",
      "                "
    ],
    [
      "                ",
      "                ",
      "  hhhhhhZZZZZZ  ",
      "  hbbbbh22221Z  ",
      "  hbbbbb    0Z  ",
      "  hbbbbb    0Z  ",
      "  hbbbbb    0Z  ",
      "  hbbbbb    0Z  ",
      "  hbbbbbbbbbhh  ",
      "  hbbbbbbbbbbh  ",
      "  hbbbbbbbbbbh  ",
      "  hbbbbbbbbbbh  ",
      "  hbbbj   bbbh  ",
      "  hhhhhhhhhhhh  ",
      "                ",
      "                "
    ],
    [
      "                ",
      "                ",
      "  hFFFFhZZZZZZ  ",
      "  h ^^ hcccccZ  ",
      "  W*&^ 9    cZ  ",
      "  W*&^ 9    cZ  ",
      "  W7^^ 9    cZ  ",
      "  hiii 9%   cZ  ",
      "  h$#@ 99999hh  ",
      "  F 8     766F  ",
      "  F          F  ",
      "  F   5555   F  ",
      "  F       433F  ",
      "  hhTTThhTTThh  ",
      "                ",
      "                "
    ]
  ]
}