{
  "name": "building_hotel3_floor1_180",
  "refpalette": "c70cities:building_hotel3_floor1_palette_180",
  "xsize": 16,
  "zsize": 16,
  "slices": [
    [
      "                ",
      "  a a a a a a   ",
      "  bbbbbbbbbbbba ",
      " abccccccccccb  ",
      "  bceeeeeeeecba ",
      " abceffffffecb  ",
      "  bceffffffecba ",
      " abceffffffecb  ",
      "  bceffffffecba ",
      " abceffffffecb  ",
      "  bceffffffecba ",
      " abceeeeeeeecb  ",
      "  bccccddccccba ",
      " abbbbbbbbbbbb  ",
      "   a a a a a a  ",
      "                "
    ],
    [
      "                ",
      "  a a a a a a   ",
      "  bbbbbbbbbbbba ",
      " ab          b  ",
      "  b slllllls ba ",
      " ab l qpor e b  ",
      "  b l qpo ne ba ",
      " ab l      e b  ",
      "  b l hhm je ba ",
      " ab l k h je b  ",
      "  b e hihhhe ba ",
      " ab egeeeeee b  ",
      "  b    dd    ba ",
      " abbbbbbbbbbbb  ",
      "   a a a a a a  ",
      "                "
    ],
    [
      "                ",
      "  a a a a a a   ",
      "  bbbbbbbbbbbba ",
      " ab          b  ",
      "  b s      s ba ",
      " ab     oyye b  ",
      "  b     o  w ba ",
      " ab        w b  ",
      "  b   hh   w ba ",
      " ab   x h  w b  ",
      "  b e h h ue ba ",
      " ab eteeeeee b  ",
      "  b    dd    ba ",
      " abbbbbbbbbbbb  ",
      "   a a a a a a  ",
      "                "
    ],
    [
      "                ",
      "  a a a a a a   ",
      "  bbbbbbbbbbbba ",
      " ab          b  ",
      "  b s      s ba ",
      " ab     o  e b  ",
      "  b     o  e ba ",
      " ab        e b  ",
      "  b   hh   e ba ",
      " ab   h h  e b  ",
      "  b e h h  e ba ",
      " ab eeeeeeee b  ",
      "  b    dd    ba ",
      " abbbbbbbbbbbb  ",
      "   a a a a a a  ",
      "                "
    ],
    [
      "                ",
      "  a a a a a a   ",
      "  bbbbbbbbbbbba ",
      " ab          b  ",
      "  b s      s ba ",
      " ab        e b  ",
      "  b     !  e ba ",
      " ab        e b  ",
      "  b   hh   e ba ",
      " ab   h h  e b  ",
      "  b e h hyye ba ",
      " ab eeeeeeee b  ",
      "  b    dd    ba ",
      " abbbbbbbbbbbb  ",
      "   a a a a a a  ",
      "                "
    ],
    [
      "                ",
      "  a a a a a a   ",
      "  bbbbbbbbbbbba ",
      " ab          b  ",
      "  b eeeeeeee ba ",
      " ab eAAAAAAe b  ",
      "  b eAAAAAAe ba ",
      " ab eAAAAAAe b  ",
      "  b eAAAAAAe ba ",
      " ab eAAAAAAe b  ",
      "  b eAAAAAAe ba ",
      " ab eeeeeeee b  ",
      "  b    dd    ba ",
      " abbbbbbbbbbbb  ",
      "   a a a a a a  ",
      "                "
    ]
  ]
}