{
  "name": "building_office3_floor1_270",
  "refpalette": "c70cities:building_office3_floor1_palette_270",
  "xsize": 16,
  "zsize": 16,
  "slices": [
    [
      "                ",
      " aabaabaabaabaa ",
      " acccccccccccca ",
      " bccccccccccccb ",
      " acccccccccccca ",
      " acccccccccccca ",
      " bccccccccccccb ",
      " acccccvvccccca ",
      " acccccddccccca ",
      " bccccccccccccb ",
      " acccccccccccca ",
      " acc!ccccccccca ",
      " bccccccccccccb ",
      " acccccccccccca ",
      " aabaabaabaabaa ",
      "                "
    ],
    [
      "                ",
      " eebeebeebeebee ",
      " e    ohhl    e ",
      " b f        f b ",
      " e     ee     e ",
      " e         h  e ",
      " b     nm  ig b ",
      " e pp  vv k   e ",
      " e  pg dd   g e ",
      " b qp     ki  b ",
      " e  pg     j  e ",
      " e  p         e ",
      " b f        f b ",
      " e            e ",
      " eebeebeebeebee ",
      "                "
    ],
    [
      "                ",
      " rrbrrbrrbrrbrr ",
      " r            r ",
      " b f        f b ",
      " r            r ",
      " r            r ",
      " b     tt  s  b ",
      " r     vv  s  r ",
      " r     dd  s  r ",
      " b         s  b ",
      " r            r ",
      " r            r ",
      " b f        f b ",
      " r            r ",
      " rrbrrbrrbrrbrr ",
      "                "
    ],
    [
      "                ",
      " rrbrrbrrbrrbrr ",
      " r            r ",
      " b f        f b ",
      " r            r ",
      " r            r ",
      " b     tt     b ",
      " r     vv     r ",
      " r     dd     r ",
      " b            b ",
      " r            r ",
      " r            r ",
      " b f        f b ",
      " r            r ",
      " rrbrrbrrbrrbrr ",
      "                "
    ],
    [
      "                ",
      " rrbrrbrrbrrbrr ",
      " r            r ",
      " b f        f b ",
      " r            r ",
      " r            r ",
      " b            b ",
      " r     vv     r ",
      " r     dd     r ",
      " b            b ",
      " r            r ",
      " r            r ",
      " b f        f b ",
      " r            r ",
      " rrbrrbrrbrrbrr ",
      "                "
    ],
    [
      "                ",
      " rrbrrbrrbrrbrr ",
      " ruuuuuuuuuuuur ",
      " bufwwwwwwwwfub ",
      " ruwwwwwwwwwwur ",
      " ruwwwwwwwwwwur ",
      " buwwwwwwwwwwub ",
      " ruwwwwvvwwwwur ",
      " ruwwwwddwwwwur ",
      " buwwwwwwwwwwub ",
      " ruwwwwwwwwwwur ",
      " ruwwwwwwwwwwur ",
      " bufwwwwwwwwfub ",
      " ruuuuuuuuuuuur ",
      " rrbrrbrrbrrbrr ",
      "                "
    ]
  ]
}