{
  "name": "building_office3_floor3",
  "refpalette": "c70cities:building_office3_floor3_palette",
  "xsize": 16,
  "zsize": 16,
  "slices": [
    [
      "                ",
      " aabaabaabaabaa ",
      " acccccccccccca ",
      " bccccccccccccb ",
      " accc!cccccccca ",
      " acccccccccccca ",
      " bccccccccccccb ",
      " acccccvdccccca ",
      " acccccvdccccca ",
      " bccccccccccccb ",
      " acccccccccccca ",
      " acccccccccccca ",
      " bccccccccccccb ",
      " acccccccccccca ",
      " aabaabaabaabaa ",
      "                "
    ],
    [
      "                ",
      " eebeebeebeebee ",
      " e            e ",
      " b f gggg   f b ",
      " e   ghhg     e ",
      " e         i  e ",
      " b         ij b ",
      " e    kvd  i  e ",
      " e     vd  i  e ",
      " b         ij b ",
      " e         l  e ",
      " e   ghhg     e ",
      " b f gggg   f b ",
      " e            e ",
      " eebeebeebeebee ",
      "                "
    ],
    [
      "                ",
      " mmbmmbmmbmmbmm ",
      " m            m ",
      " b f        f b ",
      " m            m ",
      " m            m ",
      " b            b ",
      " m     vd     m ",
      " m     vd     m ",
      " b            b ",
      " m            m ",
      " m            m ",
      " b f        f b ",
      " m            m ",
      " mmbmmbmmbmmbmm ",
      "                "
    ],
    [
      "                ",
      " mmbmmbmmbmmbmm ",
      " m            m ",
      " b f        f b ",
      " m            m ",
      " m            m ",
      " b            b ",
      " m     vd     m ",
      " m     vd     m ",
      " b            b ",
      " m            m ",
      " m            m ",
      " b f        f b ",
      " m            m ",
      " mmbmmbmmbmmbmm ",
      "                "
    ],
    [
      "                ",
      " mmbmmbmmbmmbmm ",
      " m            m ",
      " b f        f b ",
      " m            m ",
      " m            m ",
      " b            b ",
      " m     vd     m ",
      " m     vd     m ",
      " b            b ",
      " m            m ",
      " m            m ",
      " b f        f b ",
      " m            m ",
      " mmbmmbmmbmmbmm ",
      "                "
    ],
    [
      "                ",
      " mmbmmbmmbmmbmm ",
      " mnnnnnnnnnnnnm ",
      " bnfoooooooofnb ",
      " mnoooooooooonm ",
      " mnoooooooooonm ",
      " bnoooooooooonb ",
      " mnoooovdoooonm ",
      " mnoooovdoooonm ",
      " bnoooooooooonb ",
      " mnoooooooooonm ",
      " mnoooooooooonm ",
      " bnfoooooooofnb ",
      " mnnnnnnnnnnnnm ",
      " mmbmmbmmbmmbmm ",
      "                "
    ]
  ]
}