{
  "name": "building_residential4_ground_180",
  "refpalette": "c70cities:building_residential4_ground_palette_180",
  "xsize": 16,
  "zsize": 16,
  "slices": [
    [
      "GGGGGGGGGGGGGGGG",
      "GGGGGGGGGGGGGGGG",
      "GGaaaaaaaaaaaaGG",
      "GGGdcccbbbbbbaGG",
      "GGGdcccbbbbbbaGG",
      "GGGdcccbbbbbbaGG",
      "GGGdcccbbbbbbaGG",
      "GGGdcccbbbbbbaGG",
      "GGGdcccbbbbbbaGG",
      "GGGdcccbbbbbbaGG",
      "GGGdcccbbbbbbaGG",
      "GGGdcccbbbbbbaGG",
      "GGGdcccbbbbbbaGG",
      "GGaaaaaaaaaaaaGG",
      "GGGGGGGGGGGGGGGG",
      "GGGGGGGGGGGGGGGG"
    ],
    [
      "effffgffffgffffe",
      "f              f",
      "f hhNNhNNhNNhh f",
      "f odMLK  J  Ij f",
      "f odF E     Dj f",
      "g odCCC      j f",
      "f odw        h e",
      "f odB        A  ",
      "f ody    u   x  ",
      "f odw    u   h e",
      "g odt s  kq rj f",
      "f odn ml kq pj f",
      "f odn ml k   j f",
      "f hhiihiihiihh f",
      "f              f",
      "effffgffffgffffe"
    ],
    [
      "effffgffffgffffe",
      "f              f",
      "f hh00hOOhOOhh f",
      "f  d  K   JZ O f",
      "f  d  Y      O f",
      "g  dCCC      O f",
      "f  dX        h e",
      "f  UW        V  ",
      "f  U     u   T  ",
      "f  d     u   h e",
      "g  dS    PQ  O f",
      "f  d  R  PQ  O f",
      "f  d     P   O f",
      "f hhOOhOOhOOhh f",
      "f              f",
      "effffgffffgffffe"
    ],
    [
      "                ",
      "                ",
      "  hhhhhhhhhhhh  ",
      "  1d  K      O  ",
      "  1d  K    2 O  ",
      "  1dCCC      O  ",
      "  1d         h  ",
      "  1U         O  ",
      "  1U     u   O  ",
      "  1d     u   h  ",
      "  1d     P   O  ",
      "  1d     P   O  ",
      "  1d     P   O  ",
      "  hhhhhhhhhhhh  ",
      "                ",
      "                "
    ],
    [
      "                ",
      " 55555555555555 ",
      " ihhhhhhhhhhhhi ",
      "  4dbbbbb   bh  ",
      "  4dbbbbb   bh  ",
      "  4dbbbbb  2bh  ",
      "  4dbbbbbbbbbh  ",
      "   dbbbbbbbbbh  ",
      "   dbbbbbbbbbh  ",
      "  4dbbbbbbbbbh  ",
      "  4dbbbbbbbbbh  ",
      "  4dbbbbbbbbbh  ",
      "  4dbbbbbbbbbh  ",
      " NhhhhhhhhhhhhN ",
      " 33333333333333 ",
      "                "
    ],
    [
      "                ",
      "                ",
      " 55555555555555 ",
      " i4d }}! [  d4i ",
      "  4d{    [  d4  ",
      "  4d]    [  d4  ",
      "  4d----+)) d4  ",
      "  (d        d*  ",
      "  &d^99% 88$d#  ",
      "  4d@99  876d4  ",
      "  4d 99  876d4  ",
      "  4d44444444d4  ",
      " N4dhhhhhhhhd4N ",
      " 33333333333333 ",
      "                ",
      "                "
    ]
  ]
}