{
  "name": "building_bunker1_base1_90",
  "refpalette": "c70cities:building_bunker1_base1_palette_90",
  "xsize": 16,
  "zsize": 16,
  "slices": [
    [
      "vvvvvvvvvvvvvvvv",
      "v==============v",
      "v=aaaa=========v",
      "v=aaaa=========v",
      "v=aaaa=========v",
      "v=aaaa=========v",
      "v=aaaa====aaaaav",
      "v=aaaa====aaaaav",
      "v==========a=a=v",
      "v=========aa=aav",
      "v=========aa=aav",
      "v=========aa=aav",
      "v==============v",
      "v==============v",
      "v==============v",
      "vvvvvvvvvvvvvvvv"
    ],
    [
      "vvvvvvvvvvvvvvvv",
      "vbbbbbbbbbbbbbbv",
      "vbiknquyDIMIbSXv",
      "vbh  r y   Qb Wv",
      "vbg  q     Pb Vv",
      "vbe     CbbbbRbv",
      "vbf      F    Uv",
      "vbe  pt nbn   Uv",
      "vbbbmbbxbEbObObv",
      "vbd  b   bL b Tv",
      "vbd  bs  bK b Kv",
      "vbd  bswobJNbNJv",
      "vbb  bbbbbbbbbbv",
      "vbc     Bbzzzzzv",
      "vbcjlo sAbzzzzzv",
      "vvvvvvvvvvvvvvvv"
    ],
    [
      "vvvvvvvvvvvvvvvv",
      "vZ44EEEEEEEEE{{v",
      "vY  69   ^ +E :v",
      "vY   8     )E]`v",
      "vY         (E]|v",
      "vE3      EEEE[Ev",
      "vE2      %     v",
      "vEL  7  6E6   Tv",
      "vEEE5EE#EEE*E*Ev",
      "vE   E   EL E Tv",
      "vE   E   E1 E \\v",
      "vE   Esw E0&E-}v",
      "vEE  EEEEEEEEEEv",
      "vE1     $Ezzzzzv",
      "vE0 o  @AEzzzzzv",
      "vvvvvvvvvvvvvvvv"
    ],
    [
      "vvvvvvvvvvvvvvvv",
      "vEEEEEEEEEEEEEEv",
      "vE, 6    ..\u00a3E \u00c1v",
      "vE,        ?E\u00a5\u00c0v",
      "vE,        >E\u00a4 v",
      "vE,      EEEEEEv",
      "vE,      E    \u00a7v",
      "vE,     6E6   \u00a7v",
      "vEEEEEE{EEEEEEEv",
      "vE'  E   E <E< v",
      "vE'  E   E/ E  v",
      "vE'  E w Ef E fv",
      "vEE  EEEEEEEEEEv",
      "vE;     !Ezzzzzv",
      "vE      AEzzzzzv",
      "vvvvvvvvvvvvvvvv"
    ],
    [
      "vvvvvvvvvvvvvvvv",
      "vEEEEEEEEEEEEEEv",
      "vE\u00c4\u00c2\u00c2\u00c2\u00c2\u00c2\u00c2EEEE\u00c4\u00c4v",
      "vE\u00c4\u00c2\u00c2\u00c2\u00c2\u00c2\u00c2\u00c4\u00c4\u00c4E\u00c2\u00c2v",
      "vE\u00c4\u00c2\u00c2\u00c2\u00c2\u00c2\u00c2EEEE\u00c2\u00c2v",
      "vE\u00c4\u00c2\u00c2\u00c2\u00c2\u00c2\u00c2EEEEEEv",
      "vE\u00c4\u00c2\u00c2\u00c2\u00c2\u00c2\u00c2E\u00c2\u00c2\u00c2\u00c2\u00c4v",
      "vE\u00c4\u00c2\u00c2\u00c2\u00c2\u00c2\u00c2E\u00c2\u00c2\u00c2\u00c2\u00c4v",
      "vEEEEEEEEEEEEEEv",
      "vE\u00c3\u00c2\u00c2EEEEE\u00c2\u00c2E\u00c2\u00c2v",
      "vE\u00c3\u00c2\u00c2EEEEE\u00c2\u00c2E\u00c2\u00c2v",
      "vE\u00c3\u00c2\u00c2EEwEE\u00c4\u00c5E\u00c5\u00c4v",
      "vEE\u00c5\u00c4EEEEEEEEEEv",
      "vE\u00c2\u00c2\u00c2\u00c4\u00c2\u00c2\u00c2Ezzzzzv",
      "vE\u00c2\u00c2\u00c2\u00c4\u00c2\u00c2AEzzzzzv",
      "vvvvvvvvvvvvvvvv"
    ],
    [
      "vvvvvvvvvvvvvvvv",
      "vzzzzzzzzzzzzzzv",
      "vzzzzzzzzzzzzzzv",
      "vzzzzzzzzzzzzzzv",
      "vzzzzzzzzzzzzzzv",
      "vzzzzzzzzzzzzzzv",
      "vzzzzzzzzzzzzzzv",
      "vzzzzzzzzzzzzzzv",
      "vzzzzzzzzzzzzzzv",
      "vzzzzzzzzzzzzzzv",
      "vzzzzzzEzzzzzzzv",
      "vzzzzzEwEzzzzzzv",
      "vzzzzzzEzzzzzzzv",
      "vzzzzzzzzzzzzzzv",
      "vzzzzzzzzzzzzzzv",
      "vvvvvvvvvvvvvvvv"
    ]
  ]
}