{
  "name": "building_hotel2_floor2_270",
  "refpalette": "c70cities:building_hotel2_floor2_palette_270",
  "xsize": 16,
  "zsize": 16,
  "slices": [
    [
      "                ",
      " aaaaaaaaaaaaaa ",
      "  dccc!c!cc=bba ",
      "  dccccccccccca ",
      "  dccccccccccca ",
      "  dccccccccccca ",
      "  dccccccccccca ",
      "  dcccc!cccccca ",
      "  dccccccccccca ",
      "  dccccccccccca ",
      "  dccccccccccca ",
      "  dddddddddddda ",
      "              a ",
      "              a ",
      "              a ",
      "                "
    ],
    [
      "                ",
      " aaaaaaaaaaaaaa ",
      "  fy  =aomk=bba ",
      "  fA  ta  la  a ",
      "  fB  tapaaa  a ",
      "  f        g  a ",
      "  f   aaaaaaaea ",
      "  f xuarqnhh  a ",
      "  f xua   ii  a ",
      "  f  was      a ",
      "  f   as  jj  a ",
      "  ffffffffffffa ",
      "              a ",
      "              a ",
      "              a ",
      "                "
    ],
    [
      "                ",
      " aaaaaaaaaaaaaa ",
      "  f   Ja  E=bba ",
      "  fK   a   a  a ",
      "  f    aFaaa  a ",
      "  f        D  a ",
      "  f   aaaaaaaCa ",
      "  f   a       a ",
      "  f   a       a ",
      "  f   aI      a ",
      "  f   a       a ",
      "  ffffffffffffa ",
      "              a ",
      "              a ",
      "              a ",
      "                "
    ],
    [
      "                ",
      " aaaaaaaaaaaaaa ",
      "  f   Ma  L=bba ",
      "  f   Na   a  a ",
      "  f   Naaaaa  a ",
      "  f        a  a ",
      "  f   aaaaaaaaa ",
      "  f   a       a ",
      "  f   a       a ",
      "  f   a       a ",
      "  f   a       a ",
      "  ffffffffffffa ",
      "              a ",
      "              a ",
      "              a ",
      "                "
    ],
    [
      "                ",
      " aaaaaaaaaaaaaa ",
      "  f   Oa   =bba ",
      "  f    a   a  a ",
      "  f    aaaaa  a ",
      "  f        a  a ",
      "  f   aaaaaaaaa ",
      "  f   a       a ",
      "  f   a       a ",
      "  f   a       a ",
      "  f   a       a ",
      "  ffffffffffffa ",
      "              a ",
      "              a ",
      "              a ",
      "                "
    ],
    [
      "                ",
      " aaaaaaaaaaaaaa ",
      "  KPPPPaPPP=bba ",
      "  KPPPPaPPPaPPa ",
      "  KPPPPaaaaaPPa ",
      "  KPPPPPPPPaPPa ",
      "  KPPPaaaaaaaaa ",
      "  KPPPaPPPPPPPa ",
      "  KPPPaPPPPPPPa ",
      "  KPPPaPPPPPPPa ",
      "  KPPPPPPPPPPPa ",
      "  KKKKKKKKKKKKa ",
      "              a ",
      "              a ",
      "              a ",
      "                "
    ]
  ]
}