{
  "name": "building_policeoffice1_floor2_270",
  "refpalette": "c70cities:building_policeoffice1_floor2_palette_270",
  "xsize": 16,
  "zsize": 16,
  "slices": [
    [
      "                ",
      " cccc           ",
      " feecaaaaaaaaaa ",
      " cbbbbbbbbbbbba ",
      " cbbbbbbb!bbbba ",
      " cbbbbbbbbbbbba ",
      " fbbbbbbbbbbbba ",
      " cbbbbbbbbbbbba ",
      " cbbbbbbb!bbbba ",
      " cbbbbbbbbbbbba ",
      " fbbbbbbbbbbbba ",
      " cbbcaaaaaaaaaa ",
      " c  c           ",
      " c  d           ",
      " f  c           ",
      " cccc           "
    ],
    [
      "                ",
      " cccc           ",
      " feecaaaaaaaaaa ",
      " c  i   hc hc g ",
      " c  j    c  c g ",
      " ckkk   hc hc g ",
      " fm           g ",
      " cm  hc hc hc g ",
      " cm   c  c  c g ",
      " cm  hc hc hc g ",
      " f            g ",
      " cllcaggggggggg ",
      " c  c           ",
      " c  d           ",
      " f  c           ",
      " cccc           "
    ],
    [
      "                ",
      " cccc           ",
      " feecaaaaaaaaaa ",
      " c  o    n  n g ",
      " c  p         g ",
      " ckkk    n  n g ",
      " fq           g ",
      " cr   n  n  n g ",
      " c            g ",
      " cs   n  n  n g ",
      " f            g ",
      " c  caggggggggg ",
      " c  c           ",
      " c  d           ",
      " f  c           ",
      " cccc           "
    ],
    [
      "                ",
      " cccc           ",
      " feecaaaaaaaaaa ",
      " c  k         g ",
      " c  k         g ",
      " ckmk         g ",
      " f            g ",
      " c            g ",
      " c            g ",
      " cs           g ",
      " f            g ",
      " c  caggggggggg ",
      " c  c           ",
      " c  d           ",
      " f  c           ",
      " cccc           "
    ],
    [
      "                ",
      " cccc           ",
      " feecaaaaaaaaaa ",
      " c  k         g ",
      " c  k         g ",
      " ckkk         g ",
      " f            g ",
      " c            g ",
      " c            g ",
      " cs           g ",
      " f            g ",
      " c  caggggggggg ",
      " c  c           ",
      " c  d           ",
      " f  c           ",
      " cccc           "
    ],
    [
      "                ",
      " cccc           ",
      " feecaaaaaaaaaa ",
      " cuukuuuuuuuuut ",
      " cuukuuuuuuuuut ",
      " ckkkuuuuuuuuut ",
      " fuuuuuuuuuuuut ",
      " cuuuuuuuuuuuut ",
      " cuuuuuuuuuuuut ",
      " cuuuuuuuuuuuut ",
      " fuuuuuuuuuuuut ",
      " cuucattttttttt ",
      " c  c           ",
      " c  d           ",
      " f  c           ",
      " cccc           "
    ]
  ]
}