{
  "name": "building_office1_base1_90",
  "refpalette": "c70cities:building_office1_base1_palette_90",
  "xsize": 16,
  "zsize": 16,
  "slices": [
    [
      "vvvvvvvvvvvvvvvv",
      "vaaaaaaaaaaaaaav",
      "va!aaaaaaaaaaaav",
      "vaaaaaaaaaaaaaav",
      "vaaaaaaaaaaaaaav",
      "vaaaaaaaaaaaaaav",
      "vaaaaaaaaaaaaaav",
      "vaaaaaaaaaaaaaav",
      "vaaaaaaaaaaaaaav",
      "vaaaaaaaaaaaaaav",
      "vaaaaaaaaaaaaaav",
      "vaaaaaaaaaaaaaav",
      "vaaaaaaaaaaaaaav",
      "va!aaaaaaaaabbav",
      "vaaaaaaaaaaaaaav",
      "vvvvvvvvvvvvvvvv"
    ],
    [
      "vvvvvvvvvvvvvvvv",
      "vccccccccccccccv",
      "vcddddildddmnncv",
      "vc ej    j    cv",
      "vc g  f       cv",
      "vc        f   cv",
      "vcddid  dkd   cv",
      "vc  e         cv",
      "vc f      e   cv",
      "vcdddd  dkd   cv",
      "vc    e       cv",
      "vc  h    h    cv",
      "vc e g  e g   cv",
      "vcdddkdddkdmbbcv",
      "vccccccccccccccv",
      "vvvvvvvvvvvvvvvv"
    ],
    [
      "vvvvvvvvvvvvvvvv",
      "vccccccccccccccv",
      "vcdllddddldm  cv",
      "vc            cv",
      "vc            cv",
      "vc            cv",
      "vcdodd  ddd   cv",
      "vc            cv",
      "vc            cv",
      "vcddod  ddd   cv",
      "vc            cv",
      "vc            cv",
      "vc            cv",
      "vcdoddooddombbcv",
      "vccccccccccccccv",
      "vvvvvvvvvvvvvvvv"
    ],
    [
      "vvvvvvvvvvvvvvvv",
      "vccccccccccccccv",
      "vc qsssssu m  cv",
      "vc            cv",
      "vc            cv",
      "vc            cv",
      "vc            cv",
      "vc            cv",
      "vc            cv",
      "vc            cv",
      "vc            cv",
      "vc            cv",
      "vc            cv",
      "vc prrrrrt mbbcv",
      "vccccccccccccccv",
      "vvvvvvvvvvvvvvvv"
    ],
    [
      "vvvvvvvvvvvvvvvv",
      "vccccccccccccccv",
      "vc         m  cv",
      "vc            cv",
      "vc            cv",
      "vc            cv",
      "vc            cv",
      "vc            cv",
      "vc            cv",
      "vc            cv",
      "vc            cv",
      "vc            cv",
      "vc            cv",
      "vc         mbbcv",
      "vccccccccccccccv",
      "vvvvvvvvvvvvvvvv"
    ],
    [
      "vvvvvvvvvvvvvvvv",
      "vccccccccccccccv",
      "vcwwwwwwwwwmwwcv",
      "vcwwwwwwwwwwwwcv",
      "vcwwwwwwwwwwwwcv",
      "vcwwwwwwwwwwwwcv",
      "vcwwwwwwwwwwwwcv",
      "vcwwwwwwwwwwwwcv",
      "vcwwwwwwwwwwwwcv",
      "vcwwwwwwwwwwwwcv",
      "vcwwwwwwwwwwwwcv",
      "vcwwwwwwwwwwwwcv",
      "vcwwwwwwwwwwwwcv",
      "vcwwwwwwwwwmbbcv",
      "vccccccccccccccv",
      "vvvvvvvvvvvvvvvv"
    ]
  ]
}