{
  "name": "building_bank1_base1_180",
  "refpalette": "c70cities:building_bank1_base1_palette_180",
  "xsize": 16,
  "zsize": 16,
  "slices": [
    [
      "vvvvvvvvvvvvvvvv",
      "vaabbaaaabbaaaav",
      "vabb!bbbbbbbbbav",
      "vabbbbbbbbbbbbbv",
      "vabbbbbbbbbbbbbv",
      "vbbbbbbbbbbbbbav",
      "vbbbbbbbbbbbbbav",
      "vabbbbbbbbbbbbav",
      "vabbbbbbbbbbbbav",
      "vabbbbbbbbbbbbbv",
      "vabbbbbbbbbbbbbv",
      "vbbbbbbbbbbbbbav",
      "vbbbbbbbbbbbbbav",
      "vabbbbbbbbbb!bav",
      "vaaaabbaaaabbaav",
      "vvvvvvvvvvvvvvvv"
    ],
    [
      "vvvvvvvvvvvvvvvv",
      "vaabbaaaabbaaaav",
      "vagcceeeecc   av",
      "vag         jcbv",
      "vad          cbv",
      "vbc          eav",
      "vbc   hihe   gav",
      "vae   ihi    dav",
      "vae   hih    gav",
      "vae    e     cbv",
      "vae          cbv",
      "vbc           av",
      "vbc       e  eav",
      "vaf  ccee dcc av",
      "vaaaabbaaaabbaav",
      "vvvvvvvvvvvvvvvv"
    ],
    [
      "vvvvvvvvvvvvvvvv",
      "vaabbaaaabbaaaav",
      "vagcc pgpcc   av",
      "val         jcbv",
      "vad          cbv",
      "vbc           av",
      "vbc   ooo    mav",
      "va    ooo    dav",
      "val   nnn    mav",
      "val          cbv",
      "va           cbv",
      "vbc           av",
      "vbc           av",
      "va   cc k  cc av",
      "vaaaabbaaaabbaav",
      "vvvvvvvvvvvvvvvv"
    ],
    [
      "vvvvvvvvvvvvvvvv",
      "vaabbaaaabbaaaav",
      "va cc    cc   av",
      "va          jcbv",
      "va           cbv",
      "vbc           av",
      "vbc           av",
      "va     o      av",
      "va            av",
      "va           cbv",
      "va           cbv",
      "vbc           av",
      "vbc           av",
      "va   cc    cc av",
      "vaaaabbaaaabbaav",
      "vvvvvvvvvvvvvvvv"
    ],
    [
      "vvvvvvvvvvvvvvvv",
      "vaabbaaaabbaaaav",
      "va cc    cc   av",
      "va          jcbv",
      "va           cbv",
      "vbc           av",
      "vbc           av",
      "va            av",
      "va            av",
      "va           cbv",
      "va           cbv",
      "vbc           av",
      "vbc           av",
      "va   cc    cc av",
      "vaaaabbaaaabbaav",
      "vvvvvvvvvvvvvvvv"
    ],
    [
      "vvvvvvvvvvvvvvvv",
      "vaabbaaaabbaaaav",
      "vafccqqqqccqqsav",
      "vaqqqqqqqqqqjcbv",
      "vaqqqqqqqqqqqcbv",
      "vbcqqqqqqqqqqqav",
      "vbcqqqqqqqqqqqav",
      "vaqqqqqqqqqqqqav",
      "vaqqqqqqqqqqqqav",
      "vaqqqqqqqqqqqcbv",
      "vaqqqqqqqqqqqcbv",
      "vbcqqqqqqqqqqqav",
      "vbcqqqqqqqqqqqav",
      "varqqccqqqqccfav",
      "vaaaabbaaaabbaav",
      "vvvvvvvvvvvvvvvv"
    ]
  ]
}