{
  "name": "building_office4_floor2_90",
  "refpalette": "c70cities:building_office4_floor2_palette_90",
  "xsize": 16,
  "zsize": 16,
  "slices": [
    [
      "                ",
      "    abaaaaba    ",
      "  cccdeeeedccc  ",
      "  ceeeeeeeeeec  ",
      " aceeeeeeeeeeca ",
      " bdeeeeeeeeeedb ",
      " aeeeeeeeeeeeea ",
      " aeeeeeeeeeeeea ",
      " aeeeeeeeeeeeea ",
      " aeeeeeeeeeeeea ",
      " bdeeeeeeeeeedb ",
      " aceeeeeeeeeeca ",
      "  ceeeeeeeeeec  ",
      "  cccdeffedccc  ",
      "    abaaaaba    ",
      "                "
    ],
    [
      "                ",
      "    abaaaaba    ",
      "  gggd    dggg  ",
      "  g          g  ",
      " ag   k  k   ga ",
      " bd iii  iii db ",
      " a  h      h  a ",
      " a    k  k    a ",
      " a  iii  iii  a ",
      " a  h      h  a ",
      " bd    dd    db ",
      " ag   jllj   ga ",
      "  g          g  ",
      "  gggd ff dggg  ",
      "    abaaaaba    ",
      "                "
    ],
    [
      "                ",
      "    abaaaaba    ",
      "  gggd    dggg  ",
      "  g          g  ",
      " ag          ga ",
      " bd          db ",
      " am          ma ",
      " am          ma ",
      " am          ma ",
      " am          ma ",
      " bd    dd    db ",
      " ag   j  j   ga ",
      "  g          g  ",
      "  gggd ff dggg  ",
      "    abaaaaba    ",
      "                "
    ],
    [
      "                ",
      "    abaaaaba    ",
      "  gggd    dggg  ",
      "  g          g  ",
      " ag          ga ",
      " bd          db ",
      " a            a ",
      " a            a ",
      " a            a ",
      " a            a ",
      " bd    dd    db ",
      " ag   j  j   ga ",
      "  g          g  ",
      "  gggd ff dggg  ",
      "    abaaaaba    ",
      "                "
    ],
    [
      "                ",
      "    abaaaaba    ",
      "  gggd    dggg  ",
      "  g          g  ",
      " ag          ga ",
      " bd          db ",
      " a            a ",
      " a            a ",
      " a            a ",
      " a            a ",
      " bd    dd    db ",
      " ag   j  j   ga ",
      "  g          g  ",
      "  gggd ff dggg  ",
      "    abaaaaba    ",
      "                "
    ],
    [
      "                ",
      "    abaaaaba    ",
      "  gggdnnnndggg  ",
      "  gnnnnnnnnnng  ",
      " agnnnnnnnnnnga ",
      " bdnnnnnnnnnndb ",
      " annnnnnnnnnnna ",
      " annnnnnnnnnnna ",
      " annnnnnnnnnnna ",
      " annnnnnnnnnnna ",
      " bdnnnndd!nnndb ",
      " agnnnnnnnnnnga ",
      "  gnnnnnnnnnng  ",
      "  gggdnffndggg  ",
      "    abaaaaba    ",
      "                "
    ]
  ]
}