{
  "name": "building_apartment1_top_270",
  "refpalette": "c70cities:building_apartment1_top_palette_270",
  "xsize": 16,
  "zsize": 16,
  "slices": [
    [
      "                ",
      " aaaaaaaaaaaaaa ",
      " abbbbbbbbbbbba ",
      " abccccccccccba ",
      " abccccccccccba ",
      " abccccccccccba ",
      " abccccccccccba ",
      " abccccccccccba ",
      " abccccccccccba ",
      " abccccccccccba ",
      "  b  dcccccccba ",
      "  f   cccccccba ",
      "  g   cccccccba ",
      "  heebbbbbbbbba ",
      "      aaaaaaaaa ",
      "                "
    ],
    [
      "                ",
      "                ",
      "  bbbsllmbbiii  ",
      "  b o    on ni  ",
      "  bnon  !o   j  ",
      "  bouooooo   b  ",
      "  l     noooob  ",
      "  l  n      nk  ",
      "  wnttn      l  ",
      "  bqqqq      b  ",
      "  i   r      i  ",
      "  i   q      i  ",
      "  b   q      j  ",
      "  bbbbbpiibblm  ",
      "                ",
      "                "
    ],
    [
      "                ",
      "                ",
      "  bllbbbbbbbbb  ",
      "  i          b  ",
      "  i          i  ",
      "  j          i  ",
      "  b          i  ",
      "  b          b  ",
      "  b yy       b  ",
      "  bqqqq      b  ",
      "  b   x      b  ",
      "  b   q      b  ",
      "  b   q      b  ",
      "  bbigbbbbbbbb  ",
      "                ",
      "                "
    ],
    [
      "                ",
      "                ",
      "  bbbbbblllbbb  ",
      "  b          b  ",
      "  b          b  ",
      "  b          b  ",
      "  b          b  ",
      "  l          b  ",
      "  l n        k  ",
      "  bAAAA      l  ",
      "  bAAAA      l  ",
      "  bAAAA      b  ",
      "  bAAAA      b  ",
      "  bbbbbbbslllb  ",
      "                ",
      "                "
    ],
    [
      "                ",
      "                ",
      "                ",
      "                ",
      "                ",
      "                ",
      "                ",
      "                ",
      "                ",
      "                ",
      "                ",
      "                ",
      "                ",
      "                ",
      "                ",
      "                "
    ],
    [
      "                ",
      "                ",
      "                ",
      "                ",
      "                ",
      "                ",
      "                ",
      "                ",
      "                ",
      "                ",
      "                ",
      "                ",
      "                ",
      "                ",
      "                ",
      "                "
    ]
  ]
}