{
  "name": "building_office1_base1_180",
  "refpalette": "c70cities:building_office1_base1_palette_180",
  "xsize": 16,
  "zsize": 16,
  "slices": [
    [
      "vvvvvvvvvvvvvvvv",
      "vaaaaaaaaaaaaaav",
      "vaaaaaaaaaaaabav",
      "vaaaaaaaaaaaabav",
      "vaaaaaaaaaaaaaav",
      "vaaaaaaaaaaaaaav",
      "vaaaaaaaaaaaaaav",
      "vaaaaaaaaaaaaaav",
      "vaaaaaaaaaaaaaav",
      "vaaaaaaaaaaaaaav",
      "vaaaaaaaaaaaaaav",
      "vaaaaaaaaaaaaaav",
      "vaaaaaaaaaaaaaav",
      "va!aaaaaaaaaa!av",
      "vaaaaaaaaaaaaaav",
      "vvvvvvvvvvvvvvvv"
    ],
    [
      "vvvvvvvvvvvvvvvv",
      "vccccccccccccccv",
      "vcn          bcv",
      "vcn          bcv",
      "vcm          mcv",
      "vcd  fd ed  gdcv",
      "vcdj  k  k h kcv",
      "vcd   d  d  edcv",
      "vcl          dcv",
      "vci f     e  dcv",
      "vcd   d  d  gkcv",
      "vcdj  ie d h dcv",
      "vcdeg d fd  edcv",
      "vcd   d  d   dcv",
      "vccccccccccccccv",
      "vvvvvvvvvvvvvvvv"
    ],
    [
      "vvvvvvvvvvvvvvvv",
      "vccccccccccccccv",
      "vc           bcv",
      "vc           bcv",
      "vcm          mcv",
      "vcd   d  d   ocv",
      "vcl   d  d   dcv",
      "vcd   d  d   dcv",
      "vcd          ocv",
      "vcd          ocv",
      "vcd   d  d   dcv",
      "vcl   d  o   dcv",
      "vcl   o  d   ocv",
      "vcd   d  d   dcv",
      "vccccccccccccccv",
      "vvvvvvvvvvvvvvvv"
    ],
    [
      "vvvvvvvvvvvvvvvv",
      "vccccccccccccccv",
      "vc           bcv",
      "vc           bcv",
      "vcm          mcv",
      "vc            cv",
      "vcu          tcv",
      "vcs          rcv",
      "vcs          rcv",
      "vcs          rcv",
      "vcs          rcv",
      "vcs          rcv",
      "vcq          pcv",
      "vc            cv",
      "vccccccccccccccv",
      "vvvvvvvvvvvvvvvv"
    ],
    [
      "vvvvvvvvvvvvvvvv",
      "vccccccccccccccv",
      "vc           bcv",
      "vc           bcv",
      "vcm          mcv",
      "vc            cv",
      "vc            cv",
      "vc            cv",
      "vc            cv",
      "vc            cv",
      "vc            cv",
      "vc            cv",
      "vc            cv",
      "vc            cv",
      "vccccccccccccccv",
      "vvvvvvvvvvvvvvvv"
    ],
    [
      "vvvvvvvvvvvvvvvv",
      "vccccccccccccccv",
      "vcwwwwwwwwwwwbcv",
      "vcwwwwwwwwwwwbcv",
      "vcmwwwwwwwwwwmcv",
      "vcwwwwwwwwwwwwcv",
      "vcwwwwwwwwwwwwcv",
      "vcwwwwwwwwwwwwcv",
      "vcwwwwwwwwwwwwcv",
      "vcwwwwwwwwwwwwcv",
      "vcwwwwwwwwwwwwcv",
      "vcwwwwwwwwwwwwcv",
      "vcwwwwwwwwwwwwcv",
      "vcwwwwwwwwwwwwcv",
      "vccccccccccccccv",
      "vvvvvvvvvvvvvvvv"
    ]
  ]
}