{
  "name": "building_carfactory1_ground_180",
  "refpalette": "c70cities:building_carfactory1_ground_palette_180",
  "xsize": 16,
  "zsize": 16,
  "slices": [
    [
      "zzzazaaazzzzzzzz",
      "zzzzazaaazzzzzzz",
      "zzzzHHHHHzzHHzzz",
      "zzzHHHHHHHHHHzzz",
      "zzzHddchffhHHzzz",
      "zzzHcgciffiHHzzz",
      "zzzHdcdhffhH!zzz",
      "zzzHcddbbbbHHzzz",
      "zzzHdgdeffeHHzzz",
      "zzzHcdcbbbbHHzzz",
      "zzzHHHHHHHHHHzzz",
      "zzzzHHHHHzzzzzzz",
      "zzzzzaaaaazzzzzz",
      "zzzzaazaazzzzzzz",
      "zzzzzzazzazzzzzz",
      "zzzzzazazzzzzzzz"
    ],
    [
      " kn     jjnqqnj ",
      "jqnn     nuQQuqj",
      "nnuuwPPPPwuONunn",
      "knull    C   unj",
      " nuM   I  I Lukj",
      "j uK        Jun ",
      " nul   I  I Eunj",
      "jnuF        Eun ",
      "  uD       CBu k",
      "jkupA     y munj",
      " nurm    rt xunn",
      " nuuw    wuuuunn",
      " qtts   nnmrrlq ",
      "jnpo     kjnml j",
      "jj k    j      j",
      "   j      j    j"
    ],
    [
      "          nqqn  ",
      " qnn      uQQuq ",
      " nuuwPPPPwuZNun ",
      " nSl   Y  Y  S  ",
      "  S    XbbX  S  ",
      "  S          S  ",
      "  u    XbbX  un ",
      " nuW   V  V  u  ",
      "  S          S  ",
      "  S          S  ",
      "  SU     T   Sn ",
      "  uuwRRRRwuuuun ",
      " qt      n  rlq ",
      "                ",
      "                ",
      "                "
    ],
    [
      "           qq   ",
      " qn       uQQuq ",
      "  uuwPPPPwu55u  ",
      "  S    y  y  S  ",
      "  S    t22t  S  ",
      "  S    2432  S  ",
      "  u    t221  u  ",
      "  u    o     u  ",
      "  S          S  ",
      "  S          S  ",
      "  S          S  ",
      "  uuwRRRRwuuuun ",
      " q0           q ",
      "                ",
      "                ",
      "                "
    ],
    [
      "           &&   ",
      " q   6666 &QQ&q ",
      "  uuwwwwwwuuuu  ",
      "  7          7  ",
      "  7    #@98  7  ",
      "  7    ^ %$  7  ",
      "  u    #@98  u  ",
      "  u          u  ",
      "  7          7  ",
      "  7          7  ",
      "  7          7  ",
      "  uuwwwwwwuuuu  ",
      " q   6666     q ",
      "                ",
      "                ",
      "                "
    ],
    [
      "                ",
      " q         QQ q ",
      "  uu******uuuu  ",
      "  *          *  ",
      "  *  (   +(  *  ",
      "  *          *  ",
      "  u      +   u  ",
      "  u          u  ",
      "  *          *  ",
      "  *  ()   (  *  ",
      "  *          *  ",
      "  uu******uuuu  ",
      " q            q ",
      "                ",
      "                ",
      "                "
    ]
  ]
}