{
  "name": "building_restaurant1_top_270",
  "refpalette": "c70cities:building_restaurant1_top_palette_270",
  "xsize": 16,
  "zsize": 16,
  "slices": [
    [
      "                ",
      "      ======    ",
      " iffff=bbbb=aaa ",
      " igggg=bbbbbbba ",
      " igggg=bbbbbbba ",
      " igggg=bbbb=d a ",
      " igggg=bbbb=bba ",
      " igggg=bbbb=cca ",
      " igggg=bbbb=  a ",
      " igggg=bbbb=    ",
      " igggg=!bbb=    ",
      " igggg=bbbbe    ",
      " ihhhh=bbbbe    ",
      " ic   =bbbbe    ",
      "      ==eeee    ",
      "                "
    ],
    [
      "                ",
      "      ======    ",
      "  ifff=mmmm=aaa ",
      "  iuuu=    k  a ",
      "  i        l  a ",
      "  iwBw    c=  a ",
      "  i       c=jja ",
      "  i       c=cca ",
      "  ixBx    c=  a ",
      "  i        =    ",
      "  iyyy=nnqn=    ",
      "  iAAA=s  o=    ",
      "  ic  =t   =    ",
      "  ic  =sprp=    ",
      "      ======    ",
      "                "
    ],
    [
      "                ",
      "      ======    ",
      "   iff=M  F=eaC ",
      "   iuu=    D  C ",
      "     N     E  C ",
      "          e=  C ",
      "          e=jjC ",
      "          e=ccC ",
      "          e=  C ",
      "           c    ",
      "   i  = K  c    ",
      "   iAA=   Ic    ",
      "   ic =    c    ",
      "   ic = LJ =    ",
      "      ======    ",
      "                "
    ],
    [
      "                ",
      "      ==OO==    ",
      "    if=    =eC  ",
      "    iu=    = C  ",
      "     N     = C  ",
      "     N   Pe= C  ",
      "     N    e=jC  ",
      "     N    e=cC  ",
      "     N    e= C  ",
      "     N     =    ",
      "    i =    =    ",
      "    iA=    =    ",
      "    ic=    =    ",
      "    ic=    =    ",
      "      =ee===    ",
      "                "
    ],
    [
      "                ",
      "      ======    ",
      "     i=    =C   ",
      "     i=    =C   ",
      "     i=    =C   ",
      "     i=  RQ=C   ",
      "     i=   Q=C   ",
      "     i=   Q=C   ",
      "     i=  RQ=C   ",
      "     i=    =    ",
      "     i=    =    ",
      "     i=    =    ",
      "     i=  R =    ",
      "     i=    =    ",
      "      ======    ",
      "                "
    ],
    [
      "                ",
      "      ======    ",
      "      ======    ",
      "      ======    ",
      "      ======    ",
      "      ======    ",
      "      ======    ",
      "      ======    ",
      "      ======    ",
      "      ======    ",
      "      ======    ",
      "      ======    ",
      "      ======    ",
      "      ======    ",
      "      ======    ",
      "                "
    ]
  ]
}