{
  "name": "building_carfactory1_ground",
  "refpalette": "c70cities:building_carfactory1_ground_palette",
  "xsize": 16,
  "zsize": 16,
  "slices": [
    [
      "zzzzzzzzazazzzzz",
      "zzzzzzazzazzzzzz",
      "zzzzzzzaazaazzzz",
      "zzzzzzaaaaazzzzz",
      "zzzzzzzHHHHHzzzz",
      "zzzHHHHHHHHHHzzz",
      "zzzHHbbbbcdcHzzz",
      "zzzHHeffedgdHzzz",
      "zzzHHbbbbddcHzzz",
      "zzz!HhffhdcdHzzz",
      "zzzHHifficgcHzzz",
      "zzzHHhffhcddHzzz",
      "zzzHHHHHHHHHHzzz",
      "zzzHHzzHHHHHzzzz",
      "zzzzzzzaaazazzzz",
      "zzzzzzzzaaazazzz"
    ],
    [
      "j    j      j   ",
      "j      j    k jj",
      "j lmnjk     opnj",
      " qlrrmnn   sttq ",
      "nnuuuuw    wuun ",
      "nnux tr    mrun ",
      "jnum y     Apukj",
      "k uBC       Du  ",
      " nuE        Funj",
      "jnuE I  I   lun ",
      " nuJ        Ku j",
      "jkuL I  I   Mun ",
      "jnu   C    llunk",
      "nnuNOuwPPPPwuunn",
      "jquQQun     nnqj",
      " jnqqnjj     nk "
    ],
    [
      "                ",
      "                ",
      "                ",
      " qlr  n      tq ",
      " nuuuuwRRRRwuu  ",
      " nS   T     US  ",
      "  S          S  ",
      "  S          S  ",
      "  u  V  V   Wun ",
      " nu  XbbX    u  ",
      "  S          S  ",
      "  S  XbbX    S  ",
      "  S  Y  Y   lSn ",
      " nuNZuwPPPPwuun ",
      " quQQu      nnq ",
      "  nqqn          "
    ],
    [
      "                ",
      "                ",
      "                ",
      " q           0q ",
      " nuuuuwRRRRwuu  ",
      "  S          S  ",
      "  S          S  ",
      "  S          S  ",
      "  u     o    u  ",
      "  u  122t    u  ",
      "  S  2342    S  ",
      "  S  t22t    S  ",
      "  S  y  y    S  ",
      "  u55uwPPPPwuu  ",
      " quQQu       nq ",
      "   qq           "
    ],
    [
      "                ",
      "                ",
      "                ",
      " q     6666   q ",
      "  uuuuwwwwwwuu  ",
      "  7          7  ",
      "  7          7  ",
      "  7          7  ",
      "  u          u  ",
      "  u  89@#    u  ",
      "  7  $% ^    7  ",
      "  7  89@#    7  ",
      "  7          7  ",
      "  uuuuwwwwwwuu  ",
      " q&QQ& 6666   q ",
      "   &&           "
    ],
    [
      "                ",
      "                ",
      "                ",
      " q            q ",
      "  uuuu******uu  ",
      "  *          *  ",
      "  *  (   )(  *  ",
      "  *          *  ",
      "  u          u  ",
      "  u   +      u  ",
      "  *          *  ",
      "  *  (+   (  *  ",
      "  *          *  ",
      "  uuuu******uu  ",
      " q QQ         q ",
      "                "
    ]
  ]
}