{
  "name": "building_office1_top_270",
  "refpalette": "c70cities:building_office1_top_palette_270",
  "xsize": 16,
  "zsize": 16,
  "slices": [
    [
      "                ",
      " eeee  c        ",
      " ebbfddcaaaaaa  ",
      " ebbgbbbbbbbba  ",
      " ebbbbbbbbbbba  ",
      " ebbbbbbbbbbba  ",
      " ebbbbbbbbbbba  ",
      " ebbbbbbbbbbba  ",
      " ebbbbbbbbbbba  ",
      " ebbbbbbbbbbba  ",
      " ebbbbbbbbbbba  ",
      " ebbbbbbbbbbba  ",
      " ebbbbbbbbbbba  ",
      " ebbfddcaaaaaa  ",
      " eeee  c        ",
      "                "
    ],
    [
      "                ",
      " mmmm  c        ",
      " moofddchhhhhh  ",
      " m     l     h  ",
      " m      iiii h  ",
      " mq k   ijji h  ",
      " mq k        h  ",
      " m       kk  h  ",
      " m       kk  h  ",
      " mq k        h  ",
      " mq k   ijji h  ",
      " m      iiii h  ",
      " m  n  l     h  ",
      " mppfddchhhhhh  ",
      " mmmm  c        ",
      "                "
    ],
    [
      "                ",
      " mmmm  c        ",
      " moofddcr r r   ",
      " t     s        ",
      " d              ",
      " d              ",
      " d              ",
      " d              ",
      " d              ",
      " d              ",
      " d              ",
      " d              ",
      " t     s        ",
      " mppfddcr r r   ",
      " mmmm  c        ",
      "                "
    ],
    [
      "                ",
      " mmmm  c        ",
      " moofddcr r r   ",
      " t              ",
      " d              ",
      " d              ",
      " d              ",
      " d              ",
      " d              ",
      " d              ",
      " d              ",
      " d              ",
      " t              ",
      " m  fddcr r r   ",
      " mmmm  c        ",
      "                "
    ],
    [
      "                ",
      " mmmm  c        ",
      " m  fffcr r r   ",
      " m  fuuf        ",
      " m  fuuf        ",
      " m  fuuf        ",
      " m  fuuf        ",
      " m  fuuf        ",
      " m  fuuf        ",
      " m  fuuf        ",
      " m  fuuf        ",
      " m  fuuf        ",
      " m  fuuf        ",
      " m  fffcr r r   ",
      " mmmm  c        ",
      "                "
    ],
    [
      "                ",
      " mmmm  c        ",
      " muuu  cwwwwww  ",
      " muuu  weeeeew  ",
      " muuu  weeeeew  ",
      " muuu  weeeeew  ",
      " muuu  weeeeew  ",
      " muuu  weeeeew  ",
      " muuu  weeeeew  ",
      " muuu  weeeeew  ",
      " muuu  weeeeew  ",
      " muuu  weeeeew  ",
      " muuu  weeeeew  ",
      " muuu  cwwwwww  ",
      " mmmm  c        ",
      "                "
    ]
  ]
}