{
  "name": "building_residential1_ground_180",
  "refpalette": "c70cities:building_residential1_ground_palette_180",
  "xsize": 16,
  "zsize": 16,
  "slices": [
    [
      "GGGGGGGGGGGGGGGG",
      "GGGGGGGGGGGGGGGG",
      "GGGGGGGGGGGGGGGG",
      "GGGccccccccccGGG",
      "GGGceeddddddcGGG",
      "GGGceeddddddcGGG",
      "GGGceeddddddcGGG",
      "GGaceeddddddcaGG",
      "GGabbbbbbbbbbaGG",
      "GGabbbbbbbbbbaGG",
      "GGabbbbbbbbbbaGG",
      "GGabbbbbbbbbbaGG",
      "GGabbbbbbbbbbaGG",
      "GGaaaaaaaaaaaaGG",
      "GGGGGGGGGGGGGGGG",
      "GGGGGGGGGGGGGGGG"
    ],
    [
      "fgggghgggghggggf",
      "g              g",
      "g yyyyyyyyyyyy g",
      "g yccccccccccy g",
      "g ycKD!FJIFEcy g",
      "h yc D      cy h",
      "g yc C   BAAcy g",
      "g icxx    wwci g",
      "g j    u    tj g",
      "g j sssss   rj g",
      "f iq   po nnni f",
      "g j          m  ",
      "g j    ll    k  ",
      "g iijjjiijjjii f",
      "g              g",
      "fgggghgggghggggf"
    ],
    [
      "fgggghgggghggggf",
      "g              g",
      "g              g",
      "g  cccSSSSccc  g",
      "g  cWD  V  Uc  g",
      "h  T D      S  h",
      "g  c R   Q  c  g",
      "g icxx     Pci g",
      "g j   u      j g",
      "g j sssss    j g",
      "f iO      nnni f",
      "g j          N  ",
      "g j    MM    L  ",
      "g iijjjiijjjii f",
      "g              g",
      "fgggghgggghggggf"
    ],
    [
      "                ",
      "                ",
      "  111111111111  ",
      "   cccccccccc   ",
      "   c D      c   ",
      "   T D      S   ",
      "   c D      c   ",
      "  icxx      ci  ",
      "  Z  u       Y  ",
      "  Z sssss    Y  ",
      "0 i       nnni  ",
      "  Z          Y  ",
      "  Z          Y  ",
      "  iiXXXiiXXXii  ",
      "                ",
      "                "
    ],
    [
      "                ",
      "                ",
      "  555555555555  ",
      "  444444444444  ",
      "  1c32111111c1  ",
      "   c32      c   ",
      "   c32      c   ",
      "  icxx      ci  ",
      "  ibu        i  ",
      "  ibbbbbbbbbbi  ",
      "  ibbbbbbbbbbi  ",
      "  ibbbbbbbbbbi  ",
      "  ibbbbbbbbbbi  ",
      "  iiiiiiiiiiii  ",
      "                ",
      "                "
    ],
    [
      "                ",
      "                ",
      "                ",
      "                ",
      "  555555555555  ",
      "  444444444444  ",
      "  1c-D111111c1  ",
      "  icxx      ci  ",
      "  j +++++++++j  ",
      "  j      888 j  ",
      "  j   )( 8%$Yj  ",
      "  j  *&^ 8%$Yj  ",
      "  j#  @9 8887j  ",
      "  iiiiiiiiiiii  ",
      " 66666666666666 ",
      "                "
    ]
  ]
}