{
  "name": "building_office1_floor1_180",
  "refpalette": "c70cities:building_office1_floor1_palette_180",
  "xsize": 16,
  "zsize": 16,
  "slices": [
    [
      "                ",
      " eeeeeeeeeeeeee ",
      " ebbbbbbbbbbbbe ",
      " ebbb!bbbbbbbbe ",
      " efbbbbbbbbbgfe ",
      "  dbbbbbbbbbbd  ",
      "  dbbbbbbbbbbd  ",
      " ccbbbbbbbbbbcc ",
      "  abbbbbbbbbba  ",
      "  abbbbbbbbbba  ",
      "  abbbbbbbbbba  ",
      "  abbbbbbbbbba  ",
      "  abbbbbbbbbba  ",
      "  aaaaaaaaaaaa  ",
      "                ",
      "                "
    ],
    [
      "                ",
      " ssssssssssssss ",
      " sD   C fB   ws ",
      " sA  yyyfx   ws ",
      " sf  u uft  gfs ",
      "  d     r    d  ",
      "  d     fq   d  ",
      " ccfffffffpofcc ",
      "  hn         h  ",
      "  h  m m m   h  ",
      "  h l k  k j h  ",
      "  h   i i i  h  ",
      "  h          h  ",
      "  hhhhhhhhhhhh  ",
      "                ",
      "                "
    ],
    [
      "                ",
      " ssPddddddddPss ",
      " s      f    ws ",
      " sO  NMLf    ws ",
      " sf     f   gfs ",
      "  d     K    d  ",
      "  d     fq   d  ",
      " ccfffffffJIfcc ",
      "  hF         h  ",
      "  h          h  ",
      "  h  EEEEEE  h  ",
      "  h          h  ",
      "  h          h  ",
      "  hhhhhhhhhhhh  ",
      "                ",
      "                "
    ],
    [
      "                ",
      " ssPddddddddPss ",
      " s      f    ws ",
      " s      f    ws ",
      " sf     f   gfs ",
      "  d     f    d  ",
      "  d     f    d  ",
      " ccffffffffffcc ",
      "  h          h  ",
      "  h          h  ",
      "  h          h  ",
      "  h          h  ",
      "  h          h  ",
      "  hhhhhhhhhhhh  ",
      "                ",
      "                "
    ],
    [
      "                ",
      " ssssssssssssss ",
      " s      f    Qs ",
      " s      f    Qs ",
      " sf     f   gfs ",
      "  d     f    d  ",
      "  d     f    d  ",
      " ccffffffffffcc ",
      "  h          h  ",
      "  h          h  ",
      "  h          h  ",
      "  h          h  ",
      "  h          h  ",
      "  hhhhhhhhhhhh  ",
      "                ",
      "                "
    ],
    [
      "                ",
      " ssssssssssssss ",
      " sPPPPPPfPPPPPs ",
      " sPPPPPPfPPPPPs ",
      " sf PPPPfPPPgfs ",
      "  d PPPPfPPP d  ",
      "  d PPPPfPPP d  ",
      " ccffffffffffcc ",
      "  hPPPPPPPPPPh  ",
      "  hPPPPPPPPPPh  ",
      "  hPPPPPPPPPPh  ",
      "  hPPPPPPPPPPh  ",
      "  hPPPPPPPPPPh  ",
      "  hhhhhhhhhhhh  ",
      "                ",
      "                "
    ]
  ]
}