{
  "name": "building_gasstation1_ground_270",
  "refpalette": "c70cities:building_gasstation1_ground_palette_270",
  "xsize": 16,
  "zsize": 16,
  "slices": [
    [
      "GHHHHHHHHHHHHHaG",
      "GHHHHHHHHHHHHHHG",
      "GHHHHHHHHHHHHHHG",
      "GHHHHHHHHHHHHHHG",
      "GHHaaaaaaaaaaHHG",
      "GHHHHHHHHHHHHHHG",
      "GHHHHHHHHHHHHHHG",
      "GHHaaaaaaaaaaHHG",
      "GHHaaaaaaaaaaHHG",
      "GHHaaaaaaaaaaHHG",
      "GbbaaaaaaaaaabbG",
      "GGGaaaaaaaaaaGGG",
      "GGGaaaaaaaaaaGGG",
      "GGGaaaaaaaaaaGGG",
      "GGGGGGGGGGGGGGGG",
      "GGGGGGGGGGGGGGGG"
    ],
    [
      "              c ",
      "                ",
      "   s ks ks k    ",
      "   t lt lt l    ",
      "   i miywi mi   ",
      "                ",
      "                ",
      " gdjCCjqxuqjjgd ",
      "   jE A    nj   ",
      " hej       njhe ",
      " ffjjjj  o ojff ",
      "   jFDj  or!j   ",
      "   j  B  orpj   ",
      "   jjjjjjjjjj   ",
      "                ",
      "                "
    ],
    [
      "              c ",
      "                ",
      "                ",
      "                ",
      "   i Ii  i Ii   ",
      "                ",
      "                ",
      "   jOOjqLKqjj   ",
      "   j  M    Jj   ",
      "   j       Jj   ",
      "   jjjj  o pj   ",
      "   jP j  r oj   ",
      "   j  N  o oj   ",
      "   jjjjjjjjjj   ",
      "                ",
      "                "
    ],
    [
      "              Q ",
      "                ",
      "                ",
      "                ",
      "   i  i  i  i   ",
      "                ",
      "                ",
      "   RRRRRRRRRR   ",
      "   R        R   ",
      "   R        R   ",
      "   Rjjj     R   ",
      "   R  j    rR   ",
      "   R  j     R   ",
      "   RSSRSSRSSR   ",
      "                ",
      "                "
    ],
    [
      "                ",
      "                ",
      "                ",
      "                ",
      "   j  j  j  j   ",
      "   T  U  T  T   ",
      "                ",
      "   jjjjjjjjjj   ",
      "   j       rj   ",
      "   j  T  U  j   ",
      "   jjjjjjjjjj   ",
      "   jVVj     j   ",
      "   jVVj    rj   ",
      "   jjjjjjjjjj   ",
      "                ",
      "                "
    ],
    [
      "                ",
      "  WWWWWWWWWWWW  ",
      "  WffffffffffW  ",
      "  WffffffffffW  ",
      "  WaaaaaaaaaaW  ",
      "  WaffffffffaW  ",
      "  WaffffffffaW  ",
      "  WaaaaaaaaaaW  ",
      "  WaffffffffaW  ",
      "  WaffffffffaW  ",
      "  WaaaaaaaaaaW  ",
      "  WaffffffffaW  ",
      "  WaffffffffaW  ",
      "  WaaaaaaaaaaW  ",
      "  WWWWWWWWWWWW  ",
      "                "
    ]
  ]
}