{
  "name": "building_residential1_ground_180",
  "refpalette": "c70cities:building_residential1_ground_palette_180",
  "xsize": 16,
  "zsize": 16,
  "slices": [
    [
      "GGGGGGGGGGGGGGGG",
      "GGGGGGGGGGGGGGGG",
      "GGGGGGGGGGGGGGGG",
      "GGGccccccccccGGG",
      "GGGceeddddddcGGG",
      "GGGceeddddddcGGG",
      "GGGceeddddddcGGG",
      "GGaceeddddddcaGG",
      "GGabbbbbbbbbbaGG",
      "GGabbbbbbbbbbaGG",
      "GGabbbbbbbbbbaGG",
      "GGabbbbbbbbbbaGG",
      "GGabbbbbbbbbbaGG",
      "GGaaaaaaaaaaaaGG",
      "GGGGGGGGGGGGGGGG",
      "GGGGGGGGGGGGGGGG"
    ],
    [
      "fgggghgggghggggf",
      "g              g",
      "g xxxxxxxxxxxx g",
      "g xccccccccccx g",
      "g xcKC!JIFEDcx g",
      "h xc C      cx h",
      "g xc B   Ayycx g",
      "g icww    uuci g",
      "g j    t    sj g",
      "g j rrrrr   qj g",
      "f i    po nnni f",
      "g j          m  ",
      "g j    ll    k  ",
      "g iijjjiijjjii f",
      "g              g",
      "fgggghgggghggggf"
    ],
    [
      "fgggghgggghggggf",
      "g              g",
      "g              g",
      "g  cccQQQQccc  g",
      "g  cVC UT  Sc  g",
      "h  R C      Q  h",
      "g  c P   O  c  g",
      "g icww      ci g",
      "g j   t      j g",
      "g j rrrrr    j g",
      "f i       nnni f",
      "g j          N  ",
      "g j    MM    L  ",
      "g iijjjiijjjii f",
      "g              g",
      "fgggghgggghggggf"
    ],
    [
      "                ",
      "                ",
      "  000000000000  ",
      "   cccccccccc   ",
      "   c C      c   ",
      "   R C      Q   ",
      "   c C      c   ",
      "  icww      ci  ",
      "  Y  t       X  ",
      "  Y rrrrr    X  ",
      "Z i       nnni  ",
      "  Y          X  ",
      "  Y          X  ",
      "  iiWWWiiWWWii  ",
      "                ",
      "                "
    ],
    [
      "                ",
      "                ",
      "  444444444444  ",
      "  333333333333  ",
      "  0c21000000c0  ",
      "   c21      c   ",
      "   c21      c   ",
      "  icww      ci  ",
      "  ibt        i  ",
      "  ibbbbbbbbbbi  ",
      "  ibbbbbbbbbbi  ",
      "  ibbbbbbbbbbi  ",
      "  ibbbbbbbbbbi  ",
      "  iiiiiiiiiiii  ",
      "                ",
      "                "
    ],
    [
      "                ",
      "                ",
      "                ",
      "                ",
      "  444444444444  ",
      "  333333333333  ",
      "  0c)C000000c0  ",
      "  icww      ci  ",
      "  j (((((((((j  ",
      "  j      777 j  ",
      "  j   *& 7#@Xj  ",
      "  j  ^%$ 7#@Xj  ",
      "  j   98 7776j  ",
      "  iiiiiiiiiiii  ",
      " 55555555555555 ",
      "                "
    ]
  ]
}