{
  "name": "building_gasstation1_ground_90",
  "refpalette": "c70cities:building_gasstation1_ground_palette_90",
  "xsize": 16,
  "zsize": 16,
  "slices": [
    [
      "GGGGGGGGGGGGGGGG",
      "GGGGGGGGGGGGGGGG",
      "GGGaaaaaaaaaaGGG",
      "GGGaaaaaaaaaaGGG",
      "GGGaaaaaaaaaaGGG",
      "GbbaaaaaaaaaabbG",
      "GHHaaaaaaaaaaHHG",
      "GHHaaaaaaaaaaHHG",
      "GHHaaaaaaaaaaHHG",
      "GHHHHHHHHHHHHHHG",
      "GHHHHHHHHHHHHHHG",
      "GHHaaaaaaaaaaHHG",
      "GHHHHHHHHHHHHHHG",
      "GHHHHHHHHHHHHHHG",
      "GHHHHHHHHHHHHHHG",
      "GaHHHHHHHHHHHHHG"
    ],
    [
      "                ",
      "                ",
      "   jjjjjjjjjj   ",
      "   jpro  B  j   ",
      "   j!ro  jDFj   ",
      " ffjo o  jjjjff ",
      " ehjn       jeh ",
      "   jn    A Ej   ",
      " dgjjquxqjCCjdg ",
      "                ",
      "                ",
      "   im iwyim i   ",
      "    l tl tl t   ",
      "    k sk sk s   ",
      "                ",
      " c              "
    ],
    [
      "                ",
      "                ",
      "   jjjjjjjjjj   ",
      "   jo o  N  j   ",
      "   jo r  j Pj   ",
      "   jp o  jjjj   ",
      "   jJ       j   ",
      "   jJ    M  j   ",
      "   jjqKLqjOOj   ",
      "                ",
      "                ",
      "   iI i  iI i   ",
      "                ",
      "                ",
      "                ",
      " c              "
    ],
    [
      "                ",
      "                ",
      "   RSSRSSRSSR   ",
      "   R     j  R   ",
      "   Rr    j  R   ",
      "   R     jjjR   ",
      "   R        R   ",
      "   R        R   ",
      "   RRRRRRRRRR   ",
      "                ",
      "                ",
      "   i  i  i  i   ",
      "                ",
      "                ",
      "                ",
      " Q              "
    ],
    [
      "                ",
      "                ",
      "   jjjjjjjjjj   ",
      "   jr    jVVj   ",
      "   j     jVVj   ",
      "   jjjjjjjjjj   ",
      "   j  U  T  j   ",
      "   jr       j   ",
      "   jjjjjjjjjj   ",
      "                ",
      "   T  T  U  T   ",
      "   j  j  j  j   ",
      "                ",
      "                ",
      "                ",
      "                "
    ],
    [
      "                ",
      "  WWWWWWWWWWWW  ",
      "  WaaaaaaaaaaW  ",
      "  WaffffffffaW  ",
      "  WaffffffffaW  ",
      "  WaaaaaaaaaaW  ",
      "  WaffffffffaW  ",
      "  WaffffffffaW  ",
      "  WaaaaaaaaaaW  ",
      "  WaffffffffaW  ",
      "  WaffffffffaW  ",
      "  WaaaaaaaaaaW  ",
      "  WffffffffffW  ",
      "  WffffffffffW  ",
      "  WWWWWWWWWWWW  ",
      "                "
    ]
  ]
}