{
  "name": "building_carservice1_floor2_270",
  "refpalette": "c70cities:building_carservice1_floor2_palette_270",
  "xsize": 16,
  "zsize": 16,
  "slices": [
    [
      "                ",
      " aeeeeeeea    a ",
      " effffffccbbbb  ",
      " eggggffccbbbb  ",
      " eghhgffccbb    ",
      " aggggffcabb  a ",
      " e    ffcdHH    ",
      " e   !ffcd      ",
      " e    ffcd      ",
      " affffffca    a ",
      " eifffffcd      ",
      " edcffffcd      ",
      "  ddcfffcd      ",
      "   ddcffca    a ",
      "    eeeeee      ",
      "                "
    ],
    [
      "                ",
      " aerrrrreakjjja ",
      " e   u        j ",
      " ew  w        j ",
      " exAAx        j ",
      " aw  w   a    a ",
      " ey  y  le    j ",
      " e      mebb  j ",
      " ey  y  meHH  j ",
      " a      nakjjja ",
      " ei     oe      ",
      " er     oe      ",
      "  rr    pe      ",
      "   rr tsqa    a ",
      "    eeeeee      ",
      "                "
    ],
    [
      "                ",
      " aerrrrrea    a ",
      " eI             ",
      " e EE           ",
      " eJ  E          ",
      " a EE    a    a ",
      " eFFFF   e      ",
      " eFbbF   e      ",
      " eFFFF   e      ",
      " aI     CabbBaa ",
      " ei      eHH    ",
      " er      e      ",
      "  rr    De      ",
      "   rr    a    a ",
      "    eerrre      ",
      "                "
    ],
    [
      "                ",
      " aerrrrrea    a ",
      " e       K      ",
      " e       K      ",
      " e       K      ",
      " a       a    a ",
      " e       e      ",
      " e       e      ",
      " e       e  HH  ",
      " a       a  bba ",
      " ei    NLe  bb  ",
      " er    NMebbbb  ",
      "  rr     ebbbb  ",
      "   rr    a    a ",
      "    eeeeee      ",
      "                "
    ],
    [
      "                ",
      " aeOOOOOea    a ",
      " e       e      ",
      " e       e      ",
      " e       e      ",
      " a       ajjjka ",
      " e       e  HHj ",
      " e       e  bbj ",
      " e       e    j ",
      " a       a    a ",
      " ei      e    j ",
      " er      e    j ",
      "  rr     e    j ",
      "   rr    ajjjka ",
      "    eeeeee      ",
      "                "
    ],
    [
      "                ",
      " aeeeeeeea    a ",
      " ejjjjj  e      ",
      " ejjjjj  e      ",
      " ejjjjj  e  HH  ",
      " ajjjjj  aaBbba ",
      " ejjjjj  e      ",
      " ejjjjj  e      ",
      " ejjjjj  e      ",
      " a jjjj  a    a ",
      " ei jjj  e      ",
      " er  jj  e      ",
      "  rr  j  e      ",
      "   rr    a    a ",
      "    eeeeee      ",
      "                "
    ]
  ]
}