{
  "name": "building_residential4_ground_270",
  "refpalette": "c70cities:building_residential4_ground_palette_270",
  "xsize": 16,
  "zsize": 16,
  "slices": [
    [
      "GGGGGGGGGGGGGGGG",
      "GGGGGGGGGGGGGGGG",
      "GGaaaaaaaaaaaaGG",
      "GGabbbbbbbbbbaGG",
      "GGabbbbbbbbbbaGG",
      "GGabbbbbbbbbbaGG",
      "GGabbbbbbbbbbaGG",
      "GGabbbbbbbbbbaGG",
      "GGabbbbbbbbbbaGG",
      "GGaccccccccccaGG",
      "GGaccccccccccaGG",
      "GGaccccccccccaGG",
      "GGaddddddddddaGG",
      "GGaGGGGGGGGGGaGG",
      "GGGGGGGGGGGGGGGG",
      "GGGGGGGGGGGGGGGG"
    ],
    [
      "efffffe  efffffe",
      "f              f",
      "f hjjjhAxhjjjh f",
      "f hID     rp h f",
      "f N          i f",
      "g N       qq i g",
      "f hJ    uukkkh f",
      "f N          i f",
      "f N        lli f",
      "f hKEC    smmh f",
      "g NL C       i g",
      "f NMFCwBywtnni f",
      "f hddddddddddh f",
      "f hooooooooooh f",
      "f              f",
      "effffgffffgffffe"
    ],
    [
      "efffffe  efffffe",
      "f              f",
      "f hOOOhVThOOOh f",
      "f h          h f",
      "f OZ         O f",
      "g OJ      QQ O g",
      "f h     uuPPPh f",
      "f O          O f",
      "f O          O f",
      "f hKYC     R h f",
      "g 0  C       O g",
      "f 0  CXW  S  O f",
      "f hddddUUddddh f",
      "f h          h f",
      "f              f",
      "effffgffffgffffe"
    ],
    [
      "                ",
      "                ",
      "  hOOOhOOhOOOh  ",
      "  h          h  ",
      "  h 2        h  ",
      "  h          h  ",
      "  h     uuPPPh  ",
      "  h          h  ",
      "  h          h  ",
      "  hKKC       h  ",
      "  h  C       h  ",
      "  h  C       h  ",
      "  hddddUUddddh  ",
      "  h1111111111h  ",
      "                ",
      "                "
    ],
    [
      "                ",
      " 5i          N3 ",
      " 5hhhhhhhhhhhh3 ",
      " 5hbbbbbbbbbbh3 ",
      " 5h  2bbbbbbbh3 ",
      " 5h   bbbbbbbh3 ",
      " 5h   bbbbbbbh3 ",
      " 5hbbbbbbbbbbh3 ",
      " 5hbbbbbbbbbbh3 ",
      " 5hbbbbbbbbbbh3 ",
      " 5hbbbbbbbbbbh3 ",
      " 5hbbbbbbbbbbh3 ",
      " 5hddddddddddh3 ",
      " 5h4444  4444h3 ",
      " 5i          N3 ",
      "                "
    ],
    [
      "                ",
      "  5i        N3  ",
      "  54444*#44443  ",
      "  5dddddddddd3  ",
      "  5     $664h3  ",
      "  5   ) 8774h3  ",
      "  5[[[) 8884h3  ",
      "  5   +    4h3  ",
      "  5!  - %  4h3  ",
      "  5}  - 9994h3  ",
      "  5}  - 9994h3  ",
      "  5 {]- ^@ 4h3  ",
      "  5dddddddddd3  ",
      "  54444(&44443  ",
      "  5i        N3  ",
      "                "
    ]
  ]
}