{
  "name": "building_office4_floor2",
  "refpalette": "c70cities:building_office4_floor2_palette",
  "xsize": 16,
  "zsize": 16,
  "slices": [
    [
      "                ",
      "    abaaaaba    ",
      "  cccdeeeedccc  ",
      "  ceeeeeeeeeec  ",
      " aceeeeeeeeeeca ",
      " bdeeeeeeeeeedb ",
      " aeeeeeeeeeeeea ",
      " afeeeeeeeeeeea ",
      " afeeeeeeeeeeea ",
      " aeeeeeeeeeeeea ",
      " bdeeeeeeeeeedb ",
      " aceeeeeeeeeeca ",
      "  ceeeeeeeeeec  ",
      "  cccdeeeedccc  ",
      "    abaaaaba    ",
      "                "
    ],
    [
      "                ",
      "    abaaaaba    ",
      "  gggd    dggg  ",
      "  g          g  ",
      " ag   hi hi  ga ",
      " bd    i  i  db ",
      " a  j  ik ik  a ",
      " af ld        a ",
      " af ld        a ",
      " a  j  ik ik  a ",
      " bd    i  i  db ",
      " ag   hi hi  ga ",
      "  g          g  ",
      "  gggd    dggg  ",
      "    abaaaaba    ",
      "                "
    ],
    [
      "                ",
      "    abaaaaba    ",
      "  gggdmmmmdggg  ",
      "  g          g  ",
      " ag          ga ",
      " bd          db ",
      " a  j         a ",
      " af  d        a ",
      " af  d        a ",
      " a  j         a ",
      " bd          db ",
      " ag          ga ",
      "  g          g  ",
      "  gggdmmmmdggg  ",
      "    abaaaaba    ",
      "                "
    ],
    [
      "                ",
      "    abaaaaba    ",
      "  gggd    dggg  ",
      "  g          g  ",
      " ag          ga ",
      " bd          db ",
      " a  j         a ",
      " af  d        a ",
      " af  d        a ",
      " a  j         a ",
      " bd          db ",
      " ag          ga ",
      "  g          g  ",
      "  gggd    dggg  ",
      "    abaaaaba    ",
      "                "
    ],
    [
      "                ",
      "    abaaaaba    ",
      "  gggd    dggg  ",
      "  g          g  ",
      " ag          ga ",
      " bd          db ",
      " a  j         a ",
      " af  d        a ",
      " af  d        a ",
      " a  j         a ",
      " bd          db ",
      " ag          ga ",
      "  g          g  ",
      "  gggd    dggg  ",
      "    abaaaaba    ",
      "                "
    ],
    [
      "                ",
      "    abaaaaba    ",
      "  gggdnnnndggg  ",
      "  gnnnnnnnnnng  ",
      " agnnnnnnnnnnga ",
      " bdnnnnnnnnnndb ",
      " annnnnnnnnnnna ",
      " afnndnnnnnnnna ",
      " afnndnnnnnnnna ",
      " annn!nnnnnnnna ",
      " bdnnnnnnnnnndb ",
      " agnnnnnnnnnnga ",
      "  gnnnnnnnnnng  ",
      "  gggdnnnndggg  ",
      "    abaaaaba    ",
      "                "
    ]
  ]
}