{
  "name": "building_residential3_ground",
  "refpalette": "c70cities:building_residential3_ground_palette",
  "xsize": 16,
  "zsize": 16,
  "slices": [
    [
      "GGGGGGGGGGGGGGGG",
      "GGGGGGGGGGGGGGGG",
      "GGaaaaaaaaaaaaGG",
      "GGabbbbbbbbbbaGG",
      "GGabbbbbbbbbbaGG",
      "GGabbbbbbbbbbaGG",
      "GGabbbbbbbbbbaGG",
      "GGaabbbbbbbbbaGG",
      "GGGcddddbbbbbaGG",
      "GGGcddddbbbbbaGG",
      "GGGcddddbbbbbaGG",
      "GGGcddddbbbbbaGG",
      "GGGcccccabbbbaGG",
      "GGGGGGGGaaaaaaGG",
      "GGGGGGGGGGGGGGGG",
      "GGGGGGGGGGGGGGGG"
    ],
    [
      "effffgffffgffffe",
      "f              f",
      "f hhhhhhhhhhhh f",
      "e i   j  !k lh f",
      "  m       k nh f",
      "  o       pqph g",
      "e i rr       h f",
      "f hhsst u   wh f",
      "f  cx   u   wh f",
      "f yc    h    h f",
      "g yc    hA  Bh e",
      "f ycCDEFhA  Ih f",
      "f yccccch    h f",
      "f yyyyyyhiJJih f",
      "f              f",
      "effffgffffgffffe"
    ],
    [
      "effffgffffgffffe",
      "f              f",
      "f hhJJJhhJhKhh f",
      "e i    j  k  h f",
      "  L      Mk  K f",
      "  N       pOph g",
      "e i          J f",
      "f hh    u   Ph f",
      "f  c    u   Qh f",
      "f  R    h    J f",
      "g  R    hS   J e",
      "f  cT  UhS   J f",
      "f  ccRRch    h f",
      "f       hiJJih f",
      "f              f",
      "effffgffffgffffe"
    ],
    [
      "                ",
      "                ",
      "  hhVVVhhVhVhh  ",
      "W i     j k  h  ",
      "  X       k  Y  ",
      "  X       ppph  ",
      "  i          Y  ",
      "  hh    u    h  ",
      "  Zc    u    h  ",
      "  Zc    h    Y  ",
      "  Zc    h    Y W",
      "  Zc    h    Y  ",
      "  Zccccch    h  ",
      "  ZZZZZZhi00ih  ",
      "                ",
      "                "
    ],
    [
      "                ",
      "                ",
      "  hhhhhhhhhhhh  ",
      "  hbbb   jbbbh  ",
      "  hbbbbbbbbbbh  ",
      "  hbbbbbbbbbbh  ",
      "  hbbbbbbbbbbh  ",
      "  hhbbbbbbbbbh  ",
      "  12    bbbbbh  ",
      "  12    bbbbbh  ",
      "  12    bbbbbh  ",
      "  12    bbbbbh  ",
      "  134444hbbbbh  ",
      "  111111hhhhhh  ",
      "                ",
      "                "
    ],
    [
      "                ",
      "                ",
      "  hhVVVhhVVVhh  ",
      "  J556      7J  ",
      "  J   8888   J  ",
      "  J          J  ",
      "  J99@     # J  ",
      "  hh$$$$$ %^&h  ",
      "  1c   *$ iiih  ",
      "  1c    $ ((@Y  ",
      "  1c    $ ()+Y  ",
      "  1c    $ ()+Y  ",
      "  1ccccch (( h  ",
      "  111111hJJJJh  ",
      "                ",
      "                "
    ]
  ]
}