{
  "name": "building_lab1_base1_90",
  "refpalette": "c70cities:building_lab1_base1_palette_90",
  "xsize": 16,
  "zsize": 16,
  "slices": [
    [
      "zzzzzzzzzzzzzzzz",
      "z===============",
      "z======b========",
      "z===============",
      "z===============",
      "z==!============",
      "z==aa==a========",
      "z==aaa=====ccc==",
      "z==========ccc==",
      "z==a====a==!cc==",
      "z===============",
      "z===============",
      "z===============",
      "z===============",
      "z===============",
      "zzzzzzzzzzzzzzzz"
    ],
    [
      "zzzzzzzzzzzzzzzz",
      "zzdddddddddddddz",
      "zzdih rx eE VVdz",
      "zzdhmp   f!  0dz",
      "zzddddddCddR  dz",
      "zdageeew IdQQZdz",
      "zdag   u Iddddzz",
      "zdagl    FdPUYdz",
      "zdag      L  Xdz",
      "zdag oqfB dOTddz",
      "zzddkdddAdddddzz",
      "zzd  ndt  KNssdz",
      "zzdf  ds E    dz",
      "zzdej dsyDJMSWdz",
      "zzzdddzdddddddzz",
      "zzzzzzzzzzzzzzzz"
    ],
    [
      "zzzzzzzzzzzzzzzz",
      "zz1111111111111z",
      "zz133  7     61z",
      "zz133     ^   1z",
      "zz111111911   1z",
      "za2   e  U1Q  1z",
      "z1B      @11111z",
      "z1B       1  +-z",
      "zau       %   -z",
      "zal  25   1&&11z",
      "zz11411181$$$11z",
      "zz1   1     6)1z",
      "zz1   1      (1z",
      "zz1 j 16     *1z",
      "zzz1111111###11z",
      "zzzzzzzzzzzzzzzz"
    ],
    [
      "zzzzzzzzzzzzzzzz",
      "zz1111111111111z",
      "zz133] {      1z",
      "zz133         1z",
      "zz111111[11   1z",
      "z12       1   1z",
      "z1        11111z",
      "z1        1  :1z",
      "za        -   1z",
      "z1   2    1\\\\11z",
      "zz11[111}111111z",
      "zz1   1      F1z",
      "zz1   1      `1z",
      "zz1 j 1      |1z",
      "zzz111111111111z",
      "zzzzzzzzzzzzzzzz"
    ],
    [
      "zzzzzzzzzzzzzzzz",
      "zz1111111111111z",
      "zz1''] {,;;;;;1z",
      "zz1''   ,;;;;;1z",
      "zz111111111;;;1z",
      "z1;;;;,;;;1;;;1z",
      "z1;;;;.;;;11111z",
      "z1;;;;,;;;1;;;1z",
      "z1;;;;.;;;1;;;1z",
      "z1;;;;,;;;1//11z",
      "zz1111111111111z",
      "zz1   1/;;,;;;1z",
      "zz1   1/;;.;;;1z",
      "zz1 j 1/;;,;;;1z",
      "zzz111111111111z",
      "zzzzzzzzzzzzzzzz"
    ],
    [
      "zzzzzzzzzzzzzzzz",
      "zzzzzzzzzzzzzzzz",
      "zzz1111bzzzzzzzz",
      "zzz11111zzzzzzzz",
      "zzzzzzzzzzzzzzzz",
      "zzzzzzzzzzzzzzzz",
      "zzzzzzzzzzzzzzzz",
      "zzzzzzzzzzzzzzzz",
      "zzzzzzzzzzzzzzzz",
      "zzzzzzzzzzzzzzzz",
      "zz11111zzzzzzzzz",
      "zz11111zzzzzzzzz",
      "zz11111zzzzzzzzz",
      "zz11j11zzzzzzzzz",
      "zzz1111zzzzzzzzz",
      "zzzzzzzzzzzzzzzz"
    ]
  ]
}