{
  "name": "building_residential1_ground_90",
  "refpalette": "c70cities:building_residential1_ground_palette_90",
  "xsize": 16,
  "zsize": 16,
  "slices": [
    [
      "GGGGGGGGGGGGGGGG",
      "GGGGGGGGGGGGGGGG",
      "GGaaaaaaaGGGGGGG",
      "GGabbbbbcccccGGG",
      "GGabbbbbeeeecGGG",
      "GGabbbbbeeeecGGG",
      "GGabbbbbddddcGGG",
      "GGabbbbbddddcGGG",
      "GGabbbbbddddcGGG",
      "GGabbbbbddddcGGG",
      "GGabbbbbddddcGGG",
      "GGabbbbbddddcGGG",
      "GGabbbbbcccccGGG",
      "GGaaaaaaaGGGGGGG",
      "GGGGGGGGGGGGGGGG",
      "GGGGGGGGGGGGGGGG"
    ],
    [
      "fggggfgggghggggf",
      "g              g",
      "g ijjijjiyyyyy g",
      "g i  q  cccccy g",
      "g j   s x  Kcy g",
      "h j   s xCDDcy h",
      "g j   s    !cy g",
      "g il psu   Fcy g",
      "g il os    Jcy g",
      "g j      B Icy g",
      "h j  n  wA Fcy h",
      "g j  n  wA Ecy g",
      "g i  nrtcccccy g",
      "g ikmijjiyyyyy g",
      "g              g",
      "fgf  fgggghggggf"
    ],
    [
      "fggggfgggghggggf",
      "g              g",
      "g ijjijji      g",
      "g i  O  ccTcc  g",
      "g j   s x  Wc  g",
      "h j   s xRDDc  h",
      "g j   su    S  g",
      "g iM  s     S  g",
      "g iM  s    VS  g",
      "g j      Q  S  g",
      "h j  n      c  h",
      "g j  n  P  Uc  g",
      "g i  n  ccScc  g",
      "g iLNijji      g",
      "g              g",
      "fgf  fgggghggggf"
    ],
    [
      "     0          ",
      "                ",
      "  iZZiZZi    1  ",
      "  i     ccTcc1  ",
      "  X   s x   c1  ",
      "  X   suxDDDc1  ",
      "  X   s     c1  ",
      "  i   s     c1  ",
      "  i   s     c1  ",
      "  X         c1  ",
      "  X  n      c1  ",
      "  X  n      c1  ",
      "  i  n  ccScc1  ",
      "  iYYiYYi    1  ",
      "                ",
      "                "
    ],
    [
      "                ",
      "                ",
      "  iiiiiii  145  ",
      "  ibbbbbcccc45  ",
      "  ibbbbux33345  ",
      "  ibbbb x22245  ",
      "  ibbbb    145  ",
      "  ibbbb    145  ",
      "  ibbbb    145  ",
      "  ibbbb    145  ",
      "  ibbbb    145  ",
      "  ibbbb    145  ",
      "  ibbbb cccc45  ",
      "  iiiiiii  145  ",
      "                ",
      "                "
    ],
    [
      "                ",
      " 6              ",
      " 6ijjjjji145    ",
      " 6i#    cc45    ",
      " 6i    +x-45    ",
      " 6i *  +xD45    ",
      " 6i@&) + 145    ",
      " 6i9^( + 145    ",
      " 6i    + 145    ",
      " 6i8888+ 145    ",
      " 6i8%%8+ 145    ",
      " 6i8$$8+ 145    ",
      " 6i7YY +cc45    ",
      " 6ijjjjji145    ",
      " 6              ",
      "                "
    ]
  ]
}