{
  "name": "building_restaurant1_floor1_270",
  "refpalette": "c70cities:building_restaurant1_floor1_palette_270",
  "xsize": 16,
  "zsize": 16,
  "slices": [
    [
      "                ",
      "      ======    ",
      " fffff=GGGG=aaa ",
      " fgggg=bbbbbbba ",
      " fggggbbbbbbbba ",
      " fggggbbbbb=d a ",
      " fggggbbbbb=bba ",
      " fggggbbbbb=cca ",
      " fggggbbbbb=  a ",
      " fggggbbbbb=    ",
      " fgggg=bbbb=    ",
      " fgggg=bbbbe    ",
      " fhhhh=bbbbe    ",
      " f    =!bbbe    ",
      "      ==eeee    ",
      "                "
    ],
    [
      "                ",
      "      ======    ",
      " fffff=llll=aaa ",
      "JfC CB=mmmmj  a ",
      "KfE E      k  a ",
      "Lf         =d a ",
      "LfI    w  n=iia ",
      "Lf   C  o o=cca ",
      "LfC  A  p p=  a ",
      "MfE E A    =    ",
      "JfI FB=qqtq=    ",
      "JfDDDD=x  r=    ",
      "Nf    =y   =    ",
      "Jf    =xsus=    ",
      "      ======    ",
      "                "
    ],
    [
      "                ",
      "      ======    ",
      " fffff=QQQQ=eaa ",
      " f   Q=    O  a ",
      " W         P  a ",
      " W         =d a ",
      " W         =iia ",
      " W      U  =cca ",
      " W         =  a ",
      " W         c    ",
      " f   Q=AA Rc    ",
      " fDDDD=V  Sc    ",
      " W    =    c    ",
      " f    =  T =    ",
      "      ======    ",
      "                "
    ],
    [
      "                ",
      "      ==YY==    ",
      " fffff=    =eaa ",
      " f   Q=    =  a ",
      "           =  a ",
      "           =d a ",
      "           =iia ",
      "         Z =cca ",
      "           =  a ",
      "           =    ",
      " f   Q=    =    ",
      " fDDDD=    =    ",
      "      =    =    ",
      " f    =   X=    ",
      "      =ee===    ",
      "                "
    ],
    [
      "                ",
      "      ======    ",
      " fffff=    =aaa ",
      " f    =    =  a ",
      "      =    =  a ",
      "      =    =d a ",
      "      =    =iia ",
      "      =  1 =cca ",
      "      =    =  a ",
      "   Z  =    =    ",
      " f    =    =    ",
      " fDDDD=    =    ",
      "      =  1 =    ",
      " f    =   0=    ",
      "      ======    ",
      "                "
    ],
    [
      "                ",
      "      ======    ",
      " fffff=3333=aaa ",
      " f    =3333=2 a ",
      " f 1  =3333=  a ",
      " f    =3333=d a ",
      " f    =3333=iia ",
      " f    =3333=cca ",
      " f    =3333=  a ",
      " f 1  =3333=    ",
      " f    =3333=    ",
      " fDDDD=3333=    ",
      " f    =3333=    ",
      " f    =3333=    ",
      "      ======    ",
      "                "
    ]
  ]
}