{
  "name": "building_office3_floor3_180",
  "refpalette": "c70cities:building_office3_floor3_palette_180",
  "xsize": 16,
  "zsize": 16,
  "slices": [
    [
      "                ",
      " aabaabaabaabaa ",
      " acccccccccccca ",
      " bccccccccccccb ",
      " acccccccccccca ",
      " acccccccccccca ",
      " bccccccccccccb ",
      " acccccdvccccca ",
      " acccccdvccccca ",
      " bccccccccccccb ",
      " acccccccccccca ",
      " acccccccc!ccca ",
      " bccccccccccccb ",
      " acccccccccccca ",
      " aabaabaabaabaa ",
      "                "
    ],
    [
      "                ",
      " eebeebeebeebee ",
      " e            e ",
      " b f   gggg f b ",
      " e     ghhg   e ",
      " e  l         e ",
      " b ji         b ",
      " e  i  dv     e ",
      " e  i  dvk    e ",
      " b ji         b ",
      " e  i         e ",
      " e     ghhg   e ",
      " b f   gggg f b ",
      " e            e ",
      " eebeebeebeebee ",
      "                "
    ],
    [
      "                ",
      " mmbmmbmmbmmbmm ",
      " m            m ",
      " b f        f b ",
      " m            m ",
      " m            m ",
      " b            b ",
      " m     dv     m ",
      " m     dv     m ",
      " b            b ",
      " m            m ",
      " m            m ",
      " b f        f b ",
      " m            m ",
      " mmbmmbmmbmmbmm ",
      "                "
    ],
    [
      "                ",
      " mmbmmbmmbmmbmm ",
      " m            m ",
      " b f        f b ",
      " m            m ",
      " m            m ",
      " b            b ",
      " m     dv     m ",
      " m     dv     m ",
      " b            b ",
      " m            m ",
      " m            m ",
      " b f        f b ",
      " m            m ",
      " mmbmmbmmbmmbmm ",
      "                "
    ],
    [
      "                ",
      " mmbmmbmmbmmbmm ",
      " m            m ",
      " b f        f b ",
      " m            m ",
      " m            m ",
      " b            b ",
      " m     dv     m ",
      " m     dv     m ",
      " b            b ",
      " m            m ",
      " m            m ",
      " b f        f b ",
      " m            m ",
      " mmbmmbmmbmmbmm ",
      "                "
    ],
    [
      "                ",
      " mmbmmbmmbmmbmm ",
      " mnnnnnnnnnnnnm ",
      " bnfoooooooofnb ",
      " mnoooooooooonm ",
      " mnoooooooooonm ",
      " bnoooooooooonb ",
      " mnoooodvoooonm ",
      " mnoooodvoooonm ",
      " bnoooooooooonb ",
      " mnoooooooooonm ",
      " mnoooooooooonm ",
      " bnfoooooooofnb ",
      " mnnnnnnnnnnnnm ",
      " mmbmmbmmbmmbmm ",
      "                "
    ]
  ]
}