{
  "name": "building_carservice1_ground",
  "refpalette": "c70cities:building_carservice1_ground_palette",
  "xsize": 16,
  "zsize": 16,
  "slices": [
    [
      "GGGGGGGGGGGGGGGG",
      "GavvvavvvavvvaGG",
      "GvvvvvvvvvvvvvHH",
      "GvvvvvvvvvvvvvHH",
      "Gv       bcdd=HH",
      "Gv       bcdd=HH",
      "GaeeeaeeeaeeeaeG",
      "GeffffffffffffeG",
      "GeffffffffffffeG",
      "Gefgh ffffffffeG",
      "Gefijk fffffffeG",
      "Gef lmf ffffffeG",
      "GeffffffffffffGG",
      "Ge!fffff!ffffGGG",
      "GaeeeaeeeaeeGGGG",
      "GGGGGGGGGGGGGGGG"
    ],
    [
      "                ",
      " a   a   a   a  ",
      "            Hn  ",
      " oooooooooooHn  ",
      " o              ",
      " o              ",
      " aeeeaeeea   ae ",
      " epqrs   t   ue ",
      " w     x     ye ",
      " w           ye ",
      " w           Ae ",
      " w           we ",
      " w          ww  ",
      " eABBCBBApDww   ",
      " aeeeaeeeaee    ",
      "                "
    ],
    [
      "                ",
      " a   a   a   a  ",
      " E       EHn    ",
      " F       FHn    ",
      " F       F      ",
      " F       F      ",
      " aeeeaeeea   ae ",
      " e IJ         w ",
      " w            w ",
      " w            w ",
      " w           Ae ",
      " w           we ",
      " w          ww  ",
      " eA     A Dww   ",
      " aeeeaeeeaee    ",
      "                "
    ],
    [
      "                ",
      " a   a   a   a  ",
      "        Hn      ",
      "        Hn      ",
      "                ",
      "                ",
      " aeeeaeeeaKKKae ",
      " e            e ",
      " w            e ",
      " w            e ",
      " w            e ",
      " w           we ",
      " w          ww  ",
      " e        Dww   ",
      " aeeeaeeeaee    ",
      "                "
    ],
    [
      "                ",
      " a   aFFFaFFFa  ",
      "     EHn     E  ",
      "     FHn     F  ",
      "     F       F  ",
      "     F       F  ",
      " aeeeaeeeaeeeae ",
      " e            e ",
      " L            e ",
      " L            e ",
      " L            e ",
      " L           we ",
      " L          ww  ",
      " e        Dww   ",
      " aeeeaeeeaee    ",
      "                "
    ],
    [
      "                ",
      " a   a   a   a  ",
      "    Hn          ",
      "    Hn          ",
      "     M          ",
      "     a          ",
      " aeeeaeeeaeeeae ",
      " e            e ",
      " e            e ",
      " eFFFFFFFFFFF e ",
      " eFFFFFFFFFF  e ",
      " eFFFFFFFFF  we ",
      " eFFFFFFFF  ww  ",
      " eFFFFFFF Dww   ",
      " aeeeaeeeaee    ",
      "                "
    ]
  ]
}