{
  "name": "building_office1_ground_270",
  "refpalette": "c70cities:building_office1_ground_palette_270",
  "xsize": 16,
  "zsize": 16,
  "slices": [
    [
      "GGGGGGGGGGGGGGGG",
      "GbbbbbbbbbbbbbbG",
      "GbeeddddccccccbG",
      "GbbbbbbbbbbbbcbG",
      "Gbbbbbbbbbbbbcba",
      "GbbbbbbbbbbbbcbG",
      "GbbbbbbbbbbbbcbG",
      "GbbbbbbbbbbbbcbG",
      "Gbbbbbbbb!bbbcbG",
      "GbbbbbbbbbbbbcbG",
      "GbbbbbbbbbbbbcbG",
      "Gbbbbbbbbbbbbcba",
      "GbbbbbbbbbbbbcbG",
      "GbddddddccccccbG",
      "GbbbbbbbbbbbbbbG",
      "GGGGGGGGGGGGGGGG"
    ],
    [
      "               f",
      " pppp  g  g  g f",
      " p  dhhdhhhhhh f",
      " p  q       ihgf",
      " p           h f",
      " p  nnn  mk  h f",
      " p  non  l j hgf",
      " p       l   h f",
      " p       l   h f",
      " p  non  l j hgf",
      " p  nnn  ll  h f",
      " p           h f",
      " p          ihgf",
      " p  dhhdhhhhhh f",
      " psrp  g  g  g f",
      "               f"
    ],
    [
      "                ",
      " pppp  g  g  g  ",
      " p  dhhdhhhhhh  ",
      " y  q       thg ",
      " h           h  ",
      " h           h  ",
      " h           hg ",
      " h           h  ",
      " h           h  ",
      " h       u   hg ",
      " h           h  ",
      " h           h  ",
      " y          thg ",
      " p  dhhdhhhhhh  ",
      " pxwp  g  g  g  ",
      "                "
    ],
    [
      "                ",
      " pppp  g  g  g  ",
      " p  dhhdhhhhhh  ",
      " y  q       thg ",
      " h           h  ",
      " h           h  ",
      " h           hg ",
      " h           h  ",
      " h           h  ",
      " h           hg ",
      " h           h  ",
      " h           h  ",
      " y          thg ",
      " p  dhhdhhhhhh  ",
      " pppp  g  g  g  ",
      "                "
    ],
    [
      "                ",
      " pppp  g  g  g  ",
      " p  dhhdhhhhhh  ",
      " p  q        hg ",
      " p           h  ",
      " p           h  ",
      " p           hg ",
      " p           h  ",
      " p           h  ",
      " p           hg ",
      " p           h  ",
      " p           h  ",
      " p           hg ",
      " p  dhhdhhhhhh  ",
      " pppp  g  g  g  ",
      "                "
    ],
    [
      "                ",
      " pppp  AAAAAAAA ",
      " pyydhhAAAAAAAA ",
      " pyyq  yyyyyyAA ",
      " pyyyyyyyyyyyAA ",
      " pyyyyyyyyyyyAA ",
      " pyyyyyyyyyyyAA ",
      " pyyyyyyyyyyyAA ",
      " pyyyyyyyyyyyAA ",
      " pyyyyyyyyyyyAA ",
      " pyyyyyyyyyyyAA ",
      " pyyyyyyyyyyy A ",
      " pyy   yyyyyyAA ",
      " pyydhhAAAAAAAA ",
      " pppp  AAAAAAAA ",
      "                "
    ]
  ]
}