{
  "name": "building_hotel2_ground_270",
  "refpalette": "c70cities:building_hotel2_ground_palette_270",
  "xsize": 16,
  "zsize": 16,
  "slices": [
    [
      "GGGGGGGGGGGGGGGG",
      "GaaaaaaaaaaaaaaG",
      "GGdcccccccc=bbaG",
      "GGdcccccccccccaG",
      "GGdcccc!ccccccaG",
      "GGdcccccccccccaG",
      "GGdccigigcccccaG",
      "GGdccjighcccccaG",
      "GGdccjhjhcccccaG",
      "GGdcccccccccccaG",
      "GGdcccccccccccaG",
      "GGddddddddddddaG",
      "GGGGGGGGGGffGeaG",
      "GGGGGGGGGGfGGeaG",
      "GGGGGGGGGfffGeaG",
      "GGGGGGGGfGfGGGGG"
    ],
    [
      "                ",
      " aaaaaaaaaaaaaa ",
      "  lk      k=bba ",
      "  l  t tr     a ",
      "  l  uuus     a ",
      "  l         ==a ",
      "  l         n=a ",
      "  l         n=a ",
      "  l         ==a ",
      "  l           a ",
      "  l          ka ",
      "  llllllloqpola ",
      "             ma ",
      "             ma ",
      "             ma ",
      "                "
    ],
    [
      "                ",
      " aaaaaaaaaaaaaa ",
      "  lw      w=bba ",
      "  l           a ",
      "  l    A      a ",
      "  l           a ",
      "  l           a ",
      "  l           a ",
      "  l           a ",
      "  l           a ",
      "  l          wa ",
      "  llllllloyxola ",
      "              a ",
      "              a ",
      "              a ",
      "                "
    ],
    [
      "                ",
      " aaaaaaaaaaaaaa ",
      "  lw      w=bba ",
      "  l           a ",
      "  l           a ",
      "  l           a ",
      "  l           a ",
      "  l           a ",
      "  l           a ",
      "  l           a ",
      "  l          wa ",
      "  llllllloooola ",
      "              a ",
      "              a ",
      "              a ",
      "                "
    ],
    [
      "                ",
      " aaaaaaaaaaaaaa ",
      "  l        =bba ",
      "  l           a ",
      "  l           a ",
      "  l           a ",
      "  l           a ",
      "  l           a ",
      "  l           a ",
      "  l           a ",
      "  l           a ",
      "  lllllllllllla ",
      "              a ",
      "              a ",
      "              a ",
      "                "
    ],
    [
      "                ",
      " aaaaaaaaaaaaaa ",
      "  CBBBBBBBB=bba ",
      "  CBBBBBBBBBBBa ",
      "  CBBBBBBBBBBBa ",
      "  CBBBBBBBBBBBa ",
      "  CBBBBBBBBBBBa ",
      "  CBBBBBBBBBBBa ",
      "  CBBBBBBBBBBBa ",
      "  CBBBBBBBBBBBa ",
      "  CBBBBBBBBBBBa ",
      "  CCCCCCCCCCCCa ",
      "              a ",
      "              a ",
      "              a ",
      "                "
    ]
  ]
}