{
  "name": "building_office2_ground_270",
  "refpalette": "c70cities:building_office2_ground_palette_270",
  "xsize": 16,
  "zsize": 16,
  "slices": [
    [
      "GGGGGGGGGGGGGGGG",
      "GaGGGGGGGGGGGGaG",
      "GaGbbbbbbbbbbGaG",
      "GabccccccccccbaG",
      "GaccccccccccccaG",
      "GaccccccccccccaG",
      "GaccccccccccccaG",
      "GaccccccccccccaG",
      "GaccccccccccccaG",
      "GaccccccccccccaG",
      "Gacc!cccccccccaG",
      "GaccccccccccccaG",
      "GabccccccccccbaG",
      "GaGbbbbbbbbbbGaG",
      "GaGGGGGGGGGGGGaG",
      "GGGGGGGGGGGGGGGG"
    ],
    [
      "                ",
      " a            a ",
      " a gggggggggg a ",
      " ab          ba ",
      " an          da ",
      " ao       i  ea ",
      " ap      jih fa ",
      " aq       i  fa ",
      " aq       i  fa ",
      " ap      jih ea ",
      " ao m     i  fa ",
      " ar          da ",
      " ab          ba ",
      " a gggglkgggg a ",
      " a            a ",
      "                "
    ],
    [
      "                ",
      " a            a ",
      " a gggggggggg a ",
      " ab          ba ",
      " a           sa ",
      " a            a ",
      " ax           a ",
      " aq           a ",
      " aq           a ",
      " ax           a ",
      " a           ta ",
      " a           sa ",
      " ab          ba ",
      " a ggggwugggg a ",
      " a            a ",
      "                "
    ],
    [
      "                ",
      " a            a ",
      " a gggggggggg a ",
      " ab          ba ",
      " a           sa ",
      " a            a ",
      " a            a ",
      " aq    y      a ",
      " aq           a ",
      " a            a ",
      " a            a ",
      " a           sa ",
      " ab          ba ",
      " a gggggggggg a ",
      " a            a ",
      "                "
    ],
    [
      "                ",
      " a            a ",
      " a gggggggggg a ",
      " ab          ba ",
      " a            a ",
      " a            a ",
      " a            a ",
      " aq    yy     a ",
      " aq    yy     a ",
      " a            a ",
      " a            a ",
      " a            a ",
      " ab          ba ",
      " a gggggggggg a ",
      " a            a ",
      "                "
    ],
    [
      "                ",
      " a            a ",
      " a gggggggggg a ",
      " ab          ba ",
      " aAAAAAAAAAAAAa ",
      " aAAAAAAAAAAAAa ",
      " aAAAAAAAAAAAAa ",
      " aqAAAABBAAAAAa ",
      " aqAAAABBAAAAAa ",
      " aAAAAAAAAAAAAa ",
      " aAAAAAAAAAAAAa ",
      " aAAAAAAAAAAAAa ",
      " ab          ba ",
      " a gggggggggg a ",
      " a            a ",
      "                "
    ]
  ]
}