{
  "name": "building_residential3_floor1_90",
  "refpalette": "c70cities:building_residential3_floor1_palette_90",
  "xsize": 16,
  "zsize": 16,
  "slices": [
    [
      "                ",
      "                ",
      "  abbbbaabbbaa  ",
      "  a     f    b  ",
      "  b     f    b  ",
      "  b     f    b  ",
      "  b          b  ",
      "  a         aa  ",
      "  a     e   dc  ",
      "  b         gc  ",
      "  b         gc  ",
      "  b         dc  ",
      "  a    adggddc  ",
      "  abbbbacccccc  ",
      "                ",
      "                "
    ],
    [
      "                ",
      " hh          hh ",
      " haaaaaaaaaaaah ",
      " ha     f    ah ",
      " ha     f    ah ",
      " ha     f    ah ",
      " ha          ah ",
      " ha         aah ",
      " ha     e   dch ",
      " ha         dch ",
      " ha         dch ",
      " ha         dch ",
      " ha    adddddch ",
      " haaaaaacccccch ",
      " hh          hh ",
      "                "
    ],
    [
      "                ",
      "  ijkh    hkmi  ",
      "  ijkaaaaaakmi  ",
      "  ijkh ek hkmi  ",
      "  ijkh  l hkmi  ",
      "  ijkh  k hkmi  ",
      "  ijkh    hkmi  ",
      "  ijkh    hkmi  ",
      "  ijkh  e hkmi  ",
      "  ijkh    hkmi  ",
      "  ijkh    hkmi  ",
      "  ijkh    hkmi  ",
      "  ijkh adddkmi  ",
      "  ijkaaaccckmi  ",
      "  ijkh    hkmi  ",
      "                "
    ],
    [
      "                ",
      "     ijkkmi     ",
      "     ijkkmi     ",
      "     ijkkmi     ",
      "     ijkkmi     ",
      "     ijkkmi     ",
      "     ijkkmi     ",
      "     ijkkmi     ",
      "     ijkkmi     ",
      "     ijkkmi     ",
      "     ijkkmi     ",
      "     ijkkmi     ",
      "     ijkkmi     ",
      "     ijkkmi     ",
      "     ijkkmi     ",
      "                "
    ],
    [
      "                ",
      "                ",
      "                ",
      "                ",
      "                ",
      "                ",
      "                ",
      "                ",
      "      ~~        ",
      "                ",
      "                ",
      "                ",
      "                ",
      "                ",
      "                ",
      "                "
    ],
    [
      "                ",
      "                ",
      "                ",
      "                ",
      "                ",
      "                ",
      "                ",
      "                ",
      "       ~        ",
      "                ",
      "                ",
      "                ",
      "                ",
      "                ",
      "                ",
      "                "
    ]
  ]
}