{
  "name": "building_residential3_floor1_270",
  "refpalette": "c70cities:building_residential3_floor1_palette_270",
  "xsize": 16,
  "zsize": 16,
  "slices": [
    [
      "                ",
      "                ",
      "  ccccccabbbba  ",
      "  cddggda    a  ",
      "  cd         b  ",
      "  cg         b  ",
      "  cg         b  ",
      "  cd   e     a  ",
      "  aa         a  ",
      "  b          b  ",
      "  b    f     b  ",
      "  b    f     b  ",
      "  b    f     a  ",
      "  aabbbaabbbba  ",
      "                ",
      "                "
    ],
    [
      "                ",
      " hh          hh ",
      " hccccccaaaaaah ",
      " hcddddda    ah ",
      " hcd         ah ",
      " hcd         ah ",
      " hcd         ah ",
      " hcd   e     ah ",
      " haa         ah ",
      " ha          ah ",
      " ha    f     ah ",
      " ha    f     ah ",
      " ha    fi    ah ",
      " haaaaaaaaaaaah ",
      " hh          hh ",
      "                "
    ],
    [
      "                ",
      "  jnlh    hlkj~ ",
      "  jnlcccaaalkj  ",
      "  jnlddda hlkj  ",
      "  jnlh    hlkj  ",
      "  jnlh    hlkj  ",
      "  jnlh    hlkj  ",
      "  jnlh e  hlkj  ",
      "  jnlh    hlkj  ",
      "  jnlh    hlkj  ",
      "  jnlh l  hlkj  ",
      "  jnlh m  hlkj  ",
      "  jnlh le hlkj  ",
      "  jnlaaaaaalkj  ",
      " ~jnlh    hlkj  ",
      "                "
    ],
    [
      "              ~ ",
      "     jnllkj   ~ ",
      "     jnllkj     ",
      "     jnllkj     ",
      "     jnllkj     ",
      "     jnllkj     ",
      "     jnllkj     ",
      "     jnllkj     ",
      "     jnllkj     ",
      "     jnllkj     ",
      "     jnllkj     ",
      "     jnllkj     ",
      "     jnllkj     ",
      "     jnllkj     ",
      " ~   jnllkj     ",
      "                "
    ],
    [
      "                ",
      " ~~~~~~~~~~~~~~ ",
      " ~~~~~~~~~~~~~~ ",
      " ~~~~~~~~~~~~~~ ",
      " ~~~~~~~~~~~~~~ ",
      " ~~~~~~~~~~~~~~ ",
      " ~~~~~~~~~~~~~~ ",
      " ~~~~~~~~~~~~~~ ",
      " ~~~~~~~~~~~~~~ ",
      " ~~~~~~~~~~~~~~ ",
      " ~~~~~~~~~~~~~~ ",
      " ~~~~~~~~~~~~~~ ",
      " ~~~~~~~~~~~~~~ ",
      " ~~~~~~~~~~~~~~ ",
      " ~~~~~~~~~~~~~~ ",
      "                "
    ],
    [
      "                ",
      " ~~~~~~~~~~~~~~ ",
      " ~~~~~~~~~~~~~~ ",
      " ~~~~~~~~~~~~~~ ",
      " ~~~~~~~~~~~~~~ ",
      " ~~~~~~~~~~~~~~ ",
      " ~~~~~~~~~~~~~~ ",
      " ~~~~~~~~~~~~~~ ",
      " ~~~~~~~~~~~~~~ ",
      " ~~~~~~~~~~~~~~ ",
      " ~~~~~~~~~~~~~~ ",
      " ~~~~~~~~~~~~~~ ",
      " ~~~~~~~~~~~~~~ ",
      " ~~~~~~~~~~~~~~ ",
      " ~~~~~~~~~~~~~~ ",
      "                "
    ]
  ]
}