{
  "name": "building_office1_base2_180",
  "refpalette": "c70cities:building_office1_base2_palette_180",
  "xsize": 16,
  "zsize": 16,
  "slices": [
    [
      "vvvvvvvvvvvvvvvv",
      "vaaaaaaaaaaaaaav",
      "va!aaaaaaaaaaaav",
      "vaaaaaaaaaaaaaav",
      "vaaaaaaaaaaaaaav",
      "vaaaaaaaaaaaaaav",
      "vaaaaaaaaaaaaaav",
      "vaaaaaaaaaaaaaav",
      "vaaaaaaaaaaaaaav",
      "vaaaaa!aa!aaaaav",
      "vaaaaaaaaaaaaaav",
      "vaaaaaaaaaaaaaav",
      "vaaaaaaaaaaaaaav",
      "vaaaaaaaaaaaaaav",
      "vaaaaaaaaaaaaaav",
      "vvvvvvvvvvvvvvvv"
    ],
    [
      "vvvvvvvvvvvvvvvv",
      "vbbbbbbbbbbbbbbv",
      "vbt          sbv",
      "vbt          sbv",
      "vboppporqopppobv",
      "vbe           bv",
      "vbh          fbv",
      "vbkj  m  m   ibv",
      "vbk  m   m  nibv",
      "vbh   m  mm  fbv",
      "vbk d m  m  libv",
      "vbkj         ibv",
      "vbh    g   d fbv",
      "vbe         dcbv",
      "vbbbbbbbbbbbbbbv",
      "vvvvvvvvvvvvvvvv"
    ],
    [
      "vvvvvvvvvvvvvvvv",
      "vbbbbbbbbbbbbbbv",
      "vby          sbv",
      "vbx          sbv",
      "vbopppowuopppobv",
      "vb            bv",
      "vbn           bv",
      "vb            bv",
      "vbj           bv",
      "vb           lbv",
      "vb            bv",
      "vb           dbv",
      "vbj           bv",
      "vb            bv",
      "vbbbbbbbbbbbbbbv",
      "vvvvvvvvvvvvvvvv"
    ],
    [
      "vvvvvvvvvvvvvvvv",
      "vbbbbbbbbbbbbbbv",
      "vbA          sbv",
      "vb           sbv",
      "vbopppoooopppobv",
      "vb            bv",
      "vb            bv",
      "vb            bv",
      "vb            bv",
      "vb            bv",
      "vb            bv",
      "vb            bv",
      "vb            bv",
      "vb            bv",
      "vbbbbbbbbbbbbbbv",
      "vvvvvvvvvvvvvvvv"
    ],
    [
      "vvvvvvvvvvvvvvvv",
      "vbbbbbbbbbbbbbbv",
      "vb           sbv",
      "vb           sbv",
      "vboppppppppppobv",
      "vbB          Bbv",
      "vbC          Cbv",
      "vbB          Bbv",
      "vbB          Bbv",
      "vbC          Cbv",
      "vbB          Bbv",
      "vbB          Bbv",
      "vbC          Cbv",
      "vbB          Bbv",
      "vbbbbbbbbbbbbbbv",
      "vvvvvvvvvvvvvvvv"
    ],
    [
      "vvvvvvvvvvvvvvvv",
      "vbbbbbbbbbbbbbbv",
      "vbDDDDDDDDDDDsbv",
      "vbDDDDDDDDDDDsbv",
      "vboDDDDDDDDDDobv",
      "vbDDDDDDDDDDDDbv",
      "vbDDDDDgFDDDDDbv",
      "vbDDDDDDDDDDDDbv",
      "vbDDDDDDDDDDDDbv",
      "vbDDDDDFgDDDDDbv",
      "vbDDDDDDDDDDDDbv",
      "vbDDDDDDDDDDDDbv",
      "vbDDDDDEgDDDDDbv",
      "vbDDDDDDDDDDDDbv",
      "vbbbbbbbbbbbbbbv",
      "vvvvvvvvvvvvvvvv"
    ]
  ]
}