{
  "name": "building_hotel1_top",
  "refpalette": "c70cities:building_hotel1_top_palette",
  "xsize": 16,
  "zsize": 16,
  "slices": [
    [
      "                ",
      " aaaaaaaaaaaaaa ",
      " abccccccccccba ",
      " acddddccddddca ",
      " acddddccddddca ",
      " acddccccccccca ",
      " ecddc    eccca ",
      " ecccc    cccca ",
      " ecccc    ccccf ",
      " ecddc    cddcf ",
      " ecddccccccddcf ",
      " ecddddccddddcf ",
      " ecddddccddddcf ",
      " abccccccccccba ",
      " aaaaaaagggggaa ",
      "                "
    ],
    [
      "                ",
      " aaaaaaaaaaaaaa ",
      " a            a ",
      " a hhhh  iiii a ",
      " a hhhh  iiii a ",
      " a hhjjjjjj   a ",
      " a hhj        a ",
      " a   j    j   f ",
      " a   j    j   f ",
      " a kkj    jll f ",
      " a kkjjjjjjll f ",
      " a kkkk  llll f ",
      " a kkkk  llll f ",
      " a            a ",
      " aaaaaaaaaaaaaa ",
      "                "
    ],
    [
      "                ",
      " aaaaaaaaaaaaaa ",
      " a            a ",
      " a            a ",
      " a            a ",
      " a            a ",
      " f            f ",
      " f            f ",
      " f            f ",
      " f            f ",
      " a            f ",
      " a            f ",
      " a            f ",
      " a            a ",
      " aaffffffaaaaaa ",
      "                "
    ],
    [
      "                ",
      " aaaaaaaaaaaaaa ",
      " a            a ",
      " a            a ",
      " a            a ",
      " a            f ",
      " a            f ",
      " a            f ",
      " a            f ",
      " a            f ",
      " a            f ",
      " a            f ",
      " a            f ",
      " a            a ",
      " aaaaaaaaaaaaaa ",
      "                "
    ],
    [
      "                ",
      " aaaaaaaaaaaaaa ",
      " ammmmmmmmmmmma ",
      " amnnnnnnnnnnma ",
      " amnnnnnnnnnnmm ",
      " amnnnnnnnnnnmm ",
      " amnnnnnnnnnnmm ",
      " amnnnnnnnnnnmm ",
      " amnnnnnnnnnnmm ",
      " amnnnnnnnnnnmm ",
      " amnnnnnnnnnnmm ",
      " amnnnnnnnnnnmm ",
      " amnnnnnnnnnnmm ",
      " ammmmmmmmmmmma ",
      " aaaaaaaaaaaaaa ",
      "                "
    ],
    [
      "                ",
      " aaaaaaaaaaaaaa ",
      " a            a ",
      " a              ",
      " a              ",
      " a              ",
      " a              ",
      " a              ",
      " a              ",
      " a              ",
      " a              ",
      " a              ",
      " a              ",
      " a            a ",
      " aaaaaaaaaaaaaa ",
      "                "
    ]
  ]
}