{
  "name": "building_hotel2_floor2",
  "refpalette": "c70cities:building_hotel2_floor2_palette",
  "xsize": 16,
  "zsize": 16,
  "slices": [
    [
      "                ",
      " aaaaaaaaaaaaaa ",
      " abccccccccd    ",
      " abccccccccd    ",
      " a=ccccccccd    ",
      " acccccccccd    ",
      " acccccccccd    ",
      " a!ccccccccd    ",
      " accccc!cccd    ",
      " a!ccccccccd    ",
      " acccccccccd    ",
      " acccccccccd    ",
      " acccccccccd    ",
      " adddddddddd    ",
      " a              ",
      "                "
    ],
    [
      "                ",
      " aaaaaaaaaaaaaa ",
      " ab   e    f    ",
      " ab   a    f    ",
      " a=aagahi jf    ",
      " akla ahi jf    ",
      " amna ao   f    ",
      " ap q a    f    ",
      " aaaa ap rrf    ",
      " a=ss aaaaaf    ",
      " a     ttu f    ",
      " a     ww  f    ",
      " axyA      f    ",
      " affffffffff    ",
      " a              ",
      "                "
    ],
    [
      "                ",
      " aaaaaaaaaaaaaa ",
      " ab   B    f    ",
      " ab   a    f    ",
      " a=aaCa    f    ",
      " a  a a    f    ",
      " a  a a    f    ",
      " a  D a    f    ",
      " aaaa a  E f    ",
      " aF   aaaaaf    ",
      " a         f    ",
      " a         f    ",
      " a I       f    ",
      " affffffffff    ",
      " a              ",
      "                "
    ],
    [
      "                ",
      " aaaaaaaaaaaaaa ",
      " ab   a    f    ",
      " ab   a    f    ",
      " a=aaaa    f    ",
      " a  a a    f    ",
      " a  a a    f    ",
      " a  a a    f    ",
      " aaaa a    f    ",
      " aJKK aaaaaf    ",
      " a         f    ",
      " a         f    ",
      " a         f    ",
      " affffffffff    ",
      " a              ",
      "                "
    ],
    [
      "                ",
      " aaaaaaaaaaaaaa ",
      " ab L a    f    ",
      " ab L a    f    ",
      " a=aaaa    f    ",
      " a  a a    f    ",
      " a  a a    f    ",
      " a  a a    f    ",
      " aaaa a    f    ",
      " a    aaaaaf    ",
      " a         f    ",
      " a         f    ",
      " a         f    ",
      " affffffffff    ",
      " a              ",
      "                "
    ],
    [
      "                ",
      " aaaaaaaaaaaaaa ",
      " abMMMaMMMMI    ",
      " abMMMaMMMMI    ",
      " a=aaaaMMMMI    ",
      " aMMaMaMMMMI    ",
      " aMMaMaMMMMI    ",
      " aMMaMaMMMMI    ",
      " aaaaMaMMMMI    ",
      " aMMMMaaaaMI    ",
      " aMMMMMMMMMI    ",
      " aMMMMMMMMMI    ",
      " aMMMMMMMMMI    ",
      " aIIIIIIIIII    ",
      " a              ",
      "                "
    ]
  ]
}