{
  "name": "building_bank1_ground",
  "refpalette": "c70cities:building_bank1_ground_palette",
  "xsize": 16,
  "zsize": 16,
  "slices": [
    [
      "GGGGGGGGGGGGGGGG",
      "GGaGGaaaaGGaaaGG",
      "GabbbbbbbbbbbbaG",
      "GabbbbbbbbbbbbGG",
      "GabbbbbbbbbbbbGG",
      "GGbbbbbbbbbbbbaG",
      "GGbbbbbbbbbbbbaG",
      "GabbbbbbbbbbbbaG",
      "GabbbbbbbbbbbbaG",
      "GabbbbbbbbbbbbGG",
      "GabbbbbbbbbbbbGG",
      "GGbbbbb!bbbbbbaG",
      "GGbcbbbbbbbbbbaG",
      "GabbbbbbbbbbbbaG",
      "GGaaaGGaaaaGGaGG",
      "GGGGGGGGGGGGGGGG"
    ],
    [
      "                ",
      " da  aaaa  aaad ",
      " aeefeeeeefegea ",
      " ae          h  ",
      " aei jjkkj   f  ",
      "  f   l l   mea ",
      "  e         nea ",
      " aeo        pea ",
      " aeq        mea ",
      " aro    ss   h  ",
      " aeaa        f  ",
      "  f t  uwwu  ea ",
      "  e a  uuuu  ea ",
      " aeeefeeeeefeea ",
      " daaa  aaaa  ad ",
      "                "
    ],
    [
      "                ",
      " da  aaaa  aaad ",
      " aeefeeeeefegea ",
      " ae          x  ",
      " ae  y A     f  ",
      "  fi        mea ",
      "  e          ea ",
      " ae          ea ",
      " ae         mea ",
      " ar          x  ",
      " aeaa        f  ",
      "  f B        ea ",
      "  e a        ea ",
      " aeeefeeeeefeea ",
      " daaa  aaaa  ad ",
      "                "
    ],
    [
      "                ",
      " dC  aaaC  aaad ",
      " aefeeeeefeeeeD ",
      " ae          f  ",
      " ae          e  ",
      "  e          ea ",
      "  fi         ea ",
      " Ee          ea ",
      " ae          eD ",
      " ar          f  ",
      " aeaa        e  ",
      "  e a        ea ",
      "  f a        ea ",
      " Eeeeefeeeeefea ",
      " daaa  Faaa  Fd ",
      "                "
    ],
    [
      "                ",
      " d   aaa   aaad ",
      " aefeeeeefeeee  ",
      " ae          f  ",
      " ae          e  ",
      "  e          ea ",
      "  f          ea ",
      "  ei         ea ",
      " ae          e  ",
      " ar          f  ",
      " aeaa        e  ",
      "  e a        ea ",
      "  f a        ea ",
      "  eeeefeeeeefea ",
      " daaa   aaa   d ",
      "                "
    ],
    [
      "                ",
      "    IaaC  IaaC  ",
      " Efeeeeefeeeef  ",
      " aeJJJJJJJJJJe  ",
      " aeJJJJJJJJJJeK ",
      " Le JJJMMMMJJea ",
      "  e JJJMNNMJJea ",
      "  f JJJMNNMJJeD ",
      " EeiJJJMNNMJJf  ",
      " arJJJJMNNMJJe  ",
      " aeaaJJMMMMJJeK ",
      " LeJaJJJJJJJJea ",
      "  eJaJJJJJJJJea ",
      "  feeeefeeeeefD ",
      "  FaaO  FaaO    ",
      "                "
    ]
  ]
}