{
  "name": "building_residential4_ground_180",
  "refpalette": "c70cities:building_residential4_ground_palette_180",
  "xsize": 16,
  "zsize": 16,
  "slices": [
    [
      "GGGGGGGGGGGGGGGG",
      "GGGGGGGGGGGGGGGG",
      "GGaaaaaaaaaaaaGG",
      "GGGdcccbbbbbbaGG",
      "GGGdcccbbbbbbaGG",
      "GGGdcccbbbbbbaGG",
      "GGGdcccbbbbbbaGG",
      "GGGdcccbbbbbbaGG",
      "GGGdcccbbbbbbaGG",
      "GGGdcccbbbbbbaGG",
      "GGGdcccbbbbbbaGG",
      "GGGdcccbbbbbbaGG",
      "GGGdcccbbbbbbaGG",
      "GGaaaaaaaaaaaaGG",
      "GGGGGGGGGGGGGGGG",
      "GGGGGGGGGGGGGGGG"
    ],
    [
      "effffgffffgffffe",
      "f              f",
      "f hhOOhOOhOOhh f",
      "f odNML  K  Jj f",
      "f odI F     Ej f",
      "g odDDD      j f",
      "f odx        h e",
      "f odC        B  ",
      "f odA    w   y  ",
      "f odx    w   h u",
      "g odt s  kq rj e",
      "f odn ml kq pj f",
      "f odn ml k   j f",
      "f hhiihiihiihh f",
      "f              f",
      "effffgffffgffffe"
    ],
    [
      "effffgffffgffffe",
      "f              f",
      "f hh11hPPhPPhh f",
      "f  d  L   K0 P f",
      "f  d  Z      P f",
      "g  dDDD      P f",
      "f  dY        h e",
      "f  VX        W  ",
      "f  V     w   U  ",
      "f  d     w   h  ",
      "g  dT    QR  P e",
      "f  d  S  QR  P f",
      "f  d     Q   P f",
      "f hhPPhPPhPPhh f",
      "f              f",
      "effffgffffgffffe"
    ],
    [
      "                ",
      "                ",
      "  hhhhhhhhhhhh  ",
      "  2d  L      P  ",
      "  2d  L    3 P  ",
      "  2dDDD      P  ",
      "  2d         h  ",
      "  2V         P  ",
      "  2V     w   P  ",
      "  2d     w   h  ",
      "  2d     Q   P  ",
      "  2d     Q   P  ",
      "  2d     Q   P  ",
      "  hhhhhhhhhhhh  ",
      "                ",
      "                "
    ],
    [
      "                ",
      " 66666666666666 ",
      " ihhhhhhhhhhhhi ",
      "  5dbbbbb   bh  ",
      "  5dbbbbb   bh  ",
      "  5dbbbbb  3bh  ",
      "  5dbbbbbbbbbh  ",
      "   dbbbbbbbbbh  ",
      "   dbbbbbbbbbh  ",
      "  5dbbbbbbbbbh  ",
      "  5dbbbbbbbbbh  ",
      "  5dbbbbbbbbbh  ",
      "  5dbbbbbbbbbh  ",
      " OhhhhhhhhhhhhO ",
      " 44444444444444 ",
      "                "
    ],
    [
      "                ",
      "                ",
      " 66666666666666 ",
      " i5d \\\\! ]  d5i ",
      "  5d}    ]  d5  ",
      "  5d{    ]  d5  ",
      "  5d[[[[-++ d5  ",
      "  )d        d(  ",
      "  *d&@@^ 99%d$  ",
      "  5d#@@  987d5  ",
      "  5d @@  987d5  ",
      "  5d55555555d5  ",
      " O5dhhhhhhhhd5O ",
      " 44444444444444 ",
      "                ",
      "                "
    ]
  ]
}