{
  "name": "building_bunker1_base1_180",
  "refpalette": "c70cities:building_bunker1_base1_palette_180",
  "xsize": 16,
  "zsize": 16,
  "slices": [
    [
      "================",
      "======aa=aaa====",
      "======aaaaaa====",
      "======aa========",
      "======aaaaaa====",
      "======aa=aaa====",
      "================",
      "================",
      "================",
      "================",
      "==aaaaaa========",
      "==aaaaaa========",
      "==aaaaaa========",
      "==aaaaaa========",
      "================",
      "================"
    ],
    [
      "zbbbbbbbbbbbbzzz",
      "zbXWVbUUbTKJbzzz",
      "zbS  R  O  Nbzzz",
      "zbbbbb  bbbbbzzz",
      "zbIQPb  O  Nbzzz",
      "zbM  b nbLKJbzzz",
      "zbI  bFbEbbbbbbb",
      "zbD  C nb  obBAb",
      "zbyy    x  wb sb",
      "zbu    tb ssb  b",
      "zbqrq  pbbbbb ob",
      "zbn     m     lb",
      "zbk     b     jb",
      "zbihgefebdddbccb",
      "zbbbbbbbbbbbbbbb",
      "zzzzzzzzzzzzzzzz"
    ],
    [
      "zEEEEE;EEEEEEzzz",
      "z{:`|E TET\\}Ezzz",
      "z{ ]][  *  -Ezzz",
      "zEEEEE  EEEEEzzz",
      "zE+)(E  *  &Ezzz",
      "zE   E 6EL10Ezzz",
      "zE^  E%EEEEEEEEE",
      "zE     6E   E$AE",
      "zE      #  wE @E",
      "zE      E  sE  E",
      "zE98   7EEEEE  E",
      "zE6     5     oE",
      "z4      E      E",
      "z4   32LE   E10E",
      "zZYYYEEEEEEEEEEE",
      "zzzzzzzzzzzzzzzz"
    ],
    [
      "zEEEEEEEEEEEEzzz",
      "zE\u00c1\u00c0 E\u00a7\u00a7E  fEzzz",
      "zE \u00a5\u00a4E  E<  Ezzz",
      "zEEEEE  EEEEEzzz",
      "zE\u00a3?>E  E<  Ezzz",
      "zE.  E 6E /fEzzz",
      "zE.  EEEEEEEEEEE",
      "zE     6E   E!AE",
      "zE      {  wE  E",
      "zE      E   E  E",
      "zE      EEEEE  E",
      "zE6     E      E",
      "zE      E      E",
      "zE,,,,,,E'''E10E",
      "zEEEEEEEEEEEEEEE",
      "zzzzzzzzzzzzzzzz"
    ],
    [
      "zEEEEEEEEEEEEzzz",
      "zE\u00c4\u00c2\u00c2E\u00c4\u00c4E\u00c2\u00c2\u00c4Ezzz",
      "zE\u00c4\u00c2\u00c2E\u00c2\u00c2E\u00c2\u00c2\u00c5Ezzz",
      "zEEEEE\u00c2\u00c2EEEEEzzz",
      "zEE\u00c4EE\u00c2\u00c2E\u00c2\u00c2\u00c5Ezzz",
      "zEE\u00c4EE\u00c2\u00c2E\u00c2\u00c2\u00c4Ezzz",
      "zEE\u00c4EEEEEEEEEEEE",
      "zE\u00c2\u00c2\u00c2\u00c2\u00c2\u00c2EEEEE\u00c2AE",
      "zE\u00c2\u00c2\u00c2\u00c2\u00c2\u00c2EEEwE\u00c2\u00c2E",
      "zE\u00c2\u00c2\u00c2\u00c2\u00c2\u00c2EEEEE\u00c2\u00c2E",
      "zE\u00c2\u00c2\u00c2\u00c2\u00c2\u00c2EEEEE\u00c4\u00c4E",
      "zE\u00c2\u00c2\u00c2\u00c2\u00c2\u00c2E\u00c2\u00c2\u00c2\u00c4\u00c2\u00c2E",
      "zE\u00c2\u00c2\u00c2\u00c2\u00c2\u00c2E\u00c2\u00c2\u00c2\u00c5\u00c2\u00c2E",
      "zE\u00c4\u00c4\u00c4\u00c4\u00c4\u00c4E\u00c3\u00c3\u00c3E\u00c2\u00c2E",
      "zEEEEEEEEEEEEEEE",
      "zzzzzzzzzzzzzzzz"
    ],
    [
      "zzzzzzzzzzzzzzzz",
      "zzzzzzzzzzzzzzzz",
      "zzzzzzzzzzzzzzzz",
      "zzzzzzzzzzzzzzzz",
      "zzzzzzzzzzzzzzzz",
      "zzzzzzzzzzzzzzzz",
      "zzzzzzzzzzzzzzzz",
      "zzzzzzzzzzzEzzzz",
      "zzzzzzzzzzEwEzzz",
      "zzzzzzzzzzzEzzzz",
      "zzzzzzzzzzzzzzzz",
      "zzzzzzzzzzzzzzzz",
      "zzzzzzzzzzzzzzzz",
      "zzzzzzzzzzzzzzzz",
      "zzzzzzzzzzzzzzzz",
      "zzzzzzzzzzzzzzzz"
    ]
  ]
}