{
  "name": "building_lab1_base1_180",
  "refpalette": "c70cities:building_lab1_base1_palette_180",
  "xsize": 16,
  "zsize": 16,
  "slices": [
    [
      "z==============z",
      "z==============z",
      "z======ccc=====z",
      "z======ccc=====z",
      "z======cc!=====z",
      "z==============z",
      "z==============z",
      "z========a=====z",
      "z=b===a========z",
      "z==============z",
      "z======a=======z",
      "z=====aa=======z",
      "z====!aa=a=====z",
      "z==============z",
      "z==============z",
      "zzzzzzzzzzzzzzzz"
    ],
    [
      "zzzzzzzzzzzzzzzz",
      "zdddddzdddzdddzz",
      "zdV0 ZdYXdds Wdz",
      "zdV  QdU Tds Sdz",
      "zd  RQdP OdN Mdz",
      "zdE!ddddLddK Jdz",
      "zdefdIIF  d EDdz",
      "zd  C    BA  ydz",
      "zdx dwu  fdtssdz",
      "zdr de   qddddzz",
      "zd pde   odn  dz",
      "zdhmde l  k  jdz",
      "zdihdgggggd fedz",
      "zddddaaaaaddddzz",
      "zzzzzdddddzzzzzz",
      "zzzzzzzzzzzzzzzz"
    ],
    [
      "zzzzzzzzzzzzzzzz",
      "z111111--111111z",
      "z16   1+ 11)(*1z",
      "z1    1  &$6  #z",
      "z1   Q1  &$   #z",
      "z1 ^1111%1$   #z",
      "z1  1U@   1   1z",
      "z1  9     8   1z",
      "z17 1     1  61z",
      "z1  1e   511111z",
      "z1  1    21   1z",
      "z1331     4  j1z",
      "z1331     1   1z",
      "z11112BBul1111zz",
      "zzzzza11aazzzzzz",
      "zzzzzzzzzzzzzzzz"
    ],
    [
      "zzzzzzzzzzzzzzzz",
      "z11111111111111z",
      "z1    1: 11F`|1z",
      "z1    1  \\1   1z",
      "z1    1  \\1   1z",
      "z1  1111-11   1z",
      "z1  1     1   1z",
      "z1  [     }   1z",
      "z1{ 1     1   1z",
      "z1  1     11111z",
      "z1] 1    21   1z",
      "z1331     [  j1z",
      "z1331     1   1z",
      "z11112    1111zz",
      "zzzzz111a1zzzzzz",
      "zzzzzzzzzzzzzzzz"
    ],
    [
      "zzzzzzzzzzzzzzzz",
      "z11111111111111z",
      "z1;;;;1;;11;;;1z",
      "z1;;;;1;;/1;;;1z",
      "z1;;;;1;;/1;;;1z",
      "z1;;1111111,.,1z",
      "z1;;1;;;;;1;;;1z",
      "z1,,1;;;;;1;;;1z",
      "z1{ 1;;;;;1///1z",
      "z1  1,.,.,11111z",
      "z1] 1;;;;;1   1z",
      "z1''1;;;;;1  j1z",
      "z1''1;;;;;1   1z",
      "z1111;;;;;1111zz",
      "zzzzz11111zzzzzz",
      "zzzzzzzzzzzzzzzz"
    ],
    [
      "zzzzzzzzzzzzzzzz",
      "zzzzzzzzzzzzzzzz",
      "zzzzzzzzzzzzzzzz",
      "zzzzzzzzzzzzzzzz",
      "zzzzzzzzzzzzzzzz",
      "zzzzzzzzzzzzzzzz",
      "zzzzzzzzzzzzzzzz",
      "zzzzzzzzzzzzzzzz",
      "zzb1zzzzzzzzzzzz",
      "zz11zzzzzz11111z",
      "zz11zzzzzz11111z",
      "zz11zzzzzz111j1z",
      "zz11zzzzzz11111z",
      "zzzzzzzzzz1111zz",
      "zzzzzzzzzzzzzzzz",
      "zzzzzzzzzzzzzzzz"
    ]
  ]
}