{
  "name": "building_carservice1_floor1",
  "refpalette": "c70cities:building_carservice1_floor1_palette",
  "xsize": 16,
  "zsize": 16,
  "slices": [
    [
      "                ",
      " a   a   a   a  ",
      "  bb            ",
      "  bb            ",
      "  bbbbH         ",
      "  bbbbH         ",
      " acccadddadddae ",
      " ecccccccccccce ",
      " effffffffffffe ",
      " effffffffffffe ",
      " efgh!gggffffce ",
      " efgbhgigfffcde ",
      " efgbhgigffcdd  ",
      " efggggggfjdd   ",
      " aeeeaeeeaee    ",
      "                "
    ],
    [
      "                ",
      " akkkakkka   a  ",
      " k       k      ",
      " k       k      ",
      " k     bHk      ",
      " l     bHl      ",
      " am  aeeeaeeeae ",
      " e    nnopqrrre ",
      " s       t   ue ",
      " sw          ue ",
      " sw  xpyA    Be ",
      " s    yCy    se ",
      " s    yCy   ss  ",
      " e   xpypDjss   ",
      " aeeeaeeeaee    ",
      "                "
    ],
    [
      "                ",
      " a   a   a   a  ",
      "         a      ",
      "         E      ",
      "         bH     ",
      "         bH     ",
      " amm aeeeaeeeae ",
      " e     n   FF s ",
      " s            s ",
      " s     I      s ",
      " s    JKL     e ",
      " s           se ",
      " s    L J   ss  ",
      " e    KMKNjss   ",
      " aeeeaeeeaee    ",
      "                "
    ],
    [
      "                ",
      " a   a   a   a  ",
      "        Hbbbb   ",
      "        Hbbbb   ",
      "           bb   ",
      "           bb   ",
      " ammmaeeeaeeeae ",
      " e            e ",
      " s            e ",
      " s            e ",
      " s    OOO     e ",
      " s    O O    se ",
      " s    O O   ss  ",
      " e    P P jss   ",
      " aeeeaeeeaee    ",
      "                "
    ],
    [
      "                ",
      " a   akkkakkka  ",
      "     lHb     l  ",
      "     kHb     k  ",
      "     k       k  ",
      "     k       k  ",
      " aeeeaeeeaeeeae ",
      " e            e ",
      " Q            e ",
      " Q            e ",
      " Q            e ",
      " Q           se ",
      " Q          ss  ",
      " e        jss   ",
      " aeeeaeeeaee    ",
      "                "
    ],
    [
      "                ",
      " a   a   a   a  ",
      "    Hb          ",
      "    Hb          ",
      "     E          ",
      "     a          ",
      " aeeeaeeeaeeeae ",
      " e            e ",
      " e            e ",
      " ekkkkkkkkkkk e ",
      " ekkkkkkkkkk  e ",
      " ekkkkkkkkk  se ",
      " ekkkkkkkk  ss  ",
      " ekkkkkkk jss   ",
      " aeeeaeeeaee    ",
      "                "
    ]
  ]
}