{
  "name": "building_bank1_top_270",
  "refpalette": "c70cities:building_bank1_top_palette_270",
  "xsize": 16,
  "zsize": 16,
  "slices": [
    [
      "                ",
      "  abbbc abbbc   ",
      "  deeeedeeeeeda ",
      " ceeee     eeeb ",
      " beeeeeeeeeeeeb ",
      " beeeeeeeeeeeeb ",
      " beeeeeeeeeeeec ",
      " aeeeeeeeeeeed  ",
      "  deeeeeeeeeeea ",
      " ceeeeeeeeeeeeb ",
      " beeeeeeeeeeeeb ",
      " beeeeeeeeeeeeb ",
      " beeeeeeeeeeeec ",
      " adeeeeedeeeed  ",
      "   cbbba cbbba  ",
      "                "
    ],
    [
      "                ",
      " fbcc abbcc abf ",
      " bgggghggggghgb ",
      " ahts        gc ",
      "  gus        gc ",
      " cgus        g  ",
      " cgus  l l   ha ",
      " bgts        gb ",
      " bgts pmnmi  gb ",
      " ahus q   j  gc ",
      "  gus r o k  gc ",
      " cgus r      g  ",
      " cgws        ha ",
      " bghggggghggggb ",
      " fba ccbba ccbf ",
      "                "
    ],
    [
      "                ",
      " fbbbbbbbbbbbbf ",
      " bgggghggggghgb ",
      " bhu         gb ",
      " bgu         gb ",
      " bgu         gb ",
      " bgu         hb ",
      " bgu         gb ",
      " bgu  y   x  gb ",
      " bhu         gb ",
      " bgu  r      gb ",
      " bgu  r      gb ",
      " bgu         hb ",
      " bghggggghggggb ",
      " fbbbbbbbbbbbbf ",
      "                "
    ],
    [
      "                ",
      "                ",
      "   gghggggghg   ",
      "  gg        gg  ",
      "  h          g  ",
      "  g          h  ",
      "  g          g  ",
      "  g          g  ",
      "  g          g  ",
      "  g          g  ",
      "  h          g  ",
      "  g          h  ",
      "  gg        gg  ",
      "   ghggggghgg   ",
      "                ",
      "                "
    ],
    [
      "                ",
      "                ",
      "                ",
      "    gggggggg    ",
      "   gggggggggg   ",
      "   gggA   ggg   ",
      "   gg      gg   ",
      "   gg      gg   ",
      "   gg      gg   ",
      "   gg      gg   ",
      "   ggg   Aggg   ",
      "   gggggggggg   ",
      "    gggggggg    ",
      "                ",
      "                ",
      "                "
    ],
    [
      "                ",
      "                ",
      "                ",
      "                ",
      "                ",
      "      gggg      ",
      "     gggggg     ",
      "     gggggg     ",
      "     gggggg     ",
      "     gggggg     ",
      "      gggg      ",
      "                ",
      "                ",
      "                ",
      "                ",
      "                "
    ]
  ]
}