{
  "name": "building_hotel3_base2_90",
  "refpalette": "c70cities:building_hotel3_base2_palette_90",
  "xsize": 16,
  "zsize": 16,
  "slices": [
    [
      "aaaaaaaaaaaaaaaa",
      "abbbbbbbcbbbbbba",
      "abbbbbbbbbbbbbba",
      "abcbbbbbbbbbbbca",
      "abbbdeeeeeedbbba",
      "abbbeeeeeeeebbba",
      "abbbeeeeeeeebbba",
      "a!bbeeeeeeeebbba",
      "abbbeeeeeeeebbfa",
      "abbbeeeeeeeebbba",
      "abbbeeeeeeeebbca",
      "abbbdeeeeeedbbba",
      "abbbbbbbbbbfbbba",
      "acbbbbbbbbbbbbba",
      "abbbbccbbbcbbbba",
      "aaaaaaaaaaaaaaaa"
    ],
    [
      "aaaaaaaaaaaaaaaa",
      "aggggigihgjgggga",
      "agggjjiijiijigga",
      "aghjiiiiiiiiiiha",
      "agiidkkkkkkdijga",
      "aijik      kjiga",
      "agiik nppr kijga",
      "aiiidl     kiiga",
      "ajiidl     kijia",
      "aggik mooqkkiiga",
      "agiik   kiikiiha",
      "ajiidkkkkkkdigia",
      "aiiiiiiiiiiiiiga",
      "ahiigiijigiiigga",
      "agiighhiighigfga",
      "aaaaaaaaaaaaaaaa"
    ],
    [
      "aaaaaaaaaaaaaaaa",
      "aggggijihijiigga",
      "aggijjiijiijijga",
      "ajhjiiiiiiiiiiha",
      "agiidkkkkkkdijia",
      "aijik      kjiga",
      "aiiik      kijga",
      "aiiidl     kiiia",
      "ajiidl     kijia",
      "agjik      kiija",
      "aiiik     ikiiha",
      "ajiidkkkkkkdiiia",
      "aiiiiiiiiiiiiiia",
      "ahiiiiijiiiiiija",
      "aiiijhhiijhijija",
      "aaaaaaaaaaaaaaaa"
    ],
    [
      "aaaaaaaaaaaaaaaa",
      "agggsisihisiisga",
      "atsissiisiisisia",
      "ashsiiiiiiiiiiha",
      "aiiidkkkkkkdisia",
      "aisik      ksiga",
      "aiiik      kissa",
      "aiiidl     kiiia",
      "asiidl     kisia",
      "assik      kiisa",
      "aiiik     ikiiha",
      "asiidkkkkkidiiia",
      "aiiiiiiiiiiiiiia",
      "ahiiiiisiiiiiisa",
      "aiiishhiishisisa",
      "aaaaaaaaaaaaaaaa"
    ],
    [
      "aaaaaaaaaaaaaaaa",
      "ag             a",
      "a              a",
      "a              a",
      "a   dkkkkkkd   a",
      "a   k      k   a",
      "a   k      k   a",
      "a   dl     k   a",
      "a   dl     k   a",
      "a   k      k   a",
      "a   k      k   a",
      "a   dkkkk  d   a",
      "a              a",
      "a              a",
      "a              a",
      "aaaaaaaaaaaaaaaa"
    ],
    [
      "aaaaaaaaaaaaaaaa",
      "auuuuuuuuuuuuuua",
      "auuuuuuuuuuuuuua",
      "auuuuuuuuuuuuuua",
      "auuudwwwwwwduuua",
      "auuuwwwwwwwwuuua",
      "auuuwwwwwwwwuuua",
      "auuudlwwwwwwuuua",
      "auuudlwwwwwwuuua",
      "auuuwwwwwwwwuuua",
      "auuuwwwwwwwwuuua",
      "auuudwwwwwwduuua",
      "auuuuuuuuuuuuuua",
      "auuuuuuuuuuuuuua",
      "auuuuuuuuuuuuuua",
      "aaaaaaaaaaaaaaaa"
    ]
  ]
}