{
  "name": "building_residential4_floor1_270",
  "refpalette": "c70cities:building_residential4_floor1_palette_270",
  "xsize": 16,
  "zsize": 16,
  "slices": [
    [
      "                ",
      "   on      ba   ",
      "   occc  ccca   ",
      "   odddiiddda   ",
      "   o       ea   ",
      "   o       ea   ",
      "   omm     ea   ",
      "   o  k    ea   ",
      "   o  l    ea   ",
      "   o  l  g ea   ",
      "   o  l jhfea   ",
      "   o  l    ea   ",
      "   odddiiddda   ",
      "   occc  ccca   ",
      "   on      ba   ",
      "                "
    ],
    [
      "                ",
      "    on    ba    ",
      "    occuucca    ",
      "    oddiidda    ",
      "    o     ba    ",
      "    o     brp   ",
      "    om    be    ",
      "    owl    s    ",
      "    o l    s    ",
      "    o l   be    ",
      "    oxl   btq   ",
      "    oyl   ba    ",
      "    oddiidda    ",
      "    occuucca    ",
      "    on    ba    ",
      "                "
    ],
    [
      "                ",
      "     on  ba     ",
      "     occcca     ",
      "     odddda     ",
      "     on  ba     ",
      "     on  ba     ",
      "     on  brpp   ",
      "     on  bAe    ",
      "     on  bAe    ",
      "     on  btqq   ",
      "     on  ba     ",
      "     on  ba     ",
      "     odddda     ",
      "     occcca     ",
      "     on  ba     ",
      "                "
    ],
    [
      "                ",
      "      onba      ",
      "      occa      ",
      "      odda      ",
      "      o  a      ",
      "      o  a      ",
      "      o  a      ",
      "      o  Bppp   ",
      "      o  Cqqq   ",
      "      o  a      ",
      "      o  a      ",
      "      o  a      ",
      "      odda      ",
      "      occa      ",
      "      onba      ",
      "                "
    ],
    [
      "                ",
      "       oa       ",
      "       oa       ",
      "       oa       ",
      "       oa       ",
      "       oa       ",
      "       oa       ",
      "       oa       ",
      "       oa       ",
      "       oa       ",
      "       oa       ",
      "       oa       ",
      "       oa       ",
      "       oa       ",
      "       oa       ",
      "                "
    ],
    [
      "                ",
      "       ~~       ",
      "       ~~       ",
      "       ~~       ",
      "       ~~       ",
      "       ~~       ",
      "       ~~       ",
      "       ~~       ",
      "       ~~       ",
      "       ~~       ",
      "       ~~       ",
      "       ~~       ",
      "       ~~       ",
      "       ~~       ",
      "       ~~       ",
      "                "
    ]
  ]
}