{
  "name": "building_office4_floor1",
  "refpalette": "c70cities:building_office4_floor1_palette",
  "xsize": 16,
  "zsize": 16,
  "slices": [
    [
      "                ",
      "    abaaaaba    ",
      "  cccdeeeedccc  ",
      "  ceeeeeeeeeec  ",
      " aceeeeeeeeeeca ",
      " bdeeeeeeeeeedb ",
      " aeeeeeeeeeeeea ",
      " afeeeeeeeeeeea ",
      " afeeeeeeeeeeea ",
      " aeeeeee!eeeeea ",
      " bdeeeeeeeeeedb ",
      " aceeeeeeeeeeca ",
      "  ceeeeeeeeeec  ",
      "  cccdeeeedccc  ",
      "    abaaaaba    ",
      "                "
    ],
    [
      "                ",
      "    abaaaaba    ",
      "  gggdhihhdggg  ",
      "  g   j  j   g  ",
      " ag          ga ",
      " bd          db ",
      " a    k lm  noa ",
      " af   p  q   oa ",
      " af   p  q   oa ",
      " a    rs t  noa ",
      " bd          db ",
      " ag          ga ",
      "  g   u  u   g  ",
      "  gggdwwwwdggg  ",
      "    abaaaaba    ",
      "                "
    ],
    [
      "                ",
      "    abaaaaba    ",
      "  gggd    dggg  ",
      "  g          g  ",
      " ag          ga ",
      " bd          db ",
      " a            a ",
      " af           a ",
      " af           a ",
      " a            a ",
      " bd          db ",
      " ag          ga ",
      "  g          g  ",
      "  gggd  x dggg  ",
      "    abaaaaba    ",
      "                "
    ],
    [
      "                ",
      "    abaaaaba    ",
      "  gggd    dggg  ",
      "  g          g  ",
      " ag          ga ",
      " bd          db ",
      " a            a ",
      " af           a ",
      " af           a ",
      " a            a ",
      " bd          db ",
      " ag          ga ",
      "  g          g  ",
      "  gggd    dggg  ",
      "    abaaaaba    ",
      "                "
    ],
    [
      "                ",
      "    abaaaaba    ",
      "  gggd    dggg  ",
      "  g          g  ",
      " ag          ga ",
      " bd          db ",
      " a            a ",
      " af           a ",
      " af           a ",
      " a            a ",
      " bd          db ",
      " ag          ga ",
      "  g          g  ",
      "  gggd    dggg  ",
      "    abaaaaba    ",
      "                "
    ],
    [
      "                ",
      "    abaaaaba    ",
      "  gggdyyyydggg  ",
      "  gyyyyyyyyyyg  ",
      " agyyyyyyyyyyga ",
      " bdyyyyyyyyyydb ",
      " ayyyyyyyyyyyya ",
      " afyyyyyyyyyyya ",
      " afyyyyyyyyyyya ",
      " ayyyyyyyyyyyya ",
      " bdyyyyyyyyyydb ",
      " agyyyyyyyyyyga ",
      "  gyyyyyyyyyyg  ",
      "  gggdyyyydggg  ",
      "    abaaaaba    ",
      "                "
    ]
  ]
}