{
  "name": "building_gasstation1_ground",
  "refpalette": "c70cities:building_gasstation1_ground_palette",
  "xsize": 16,
  "zsize": 16,
  "slices": [
    [
      "GGGGGGGGGGGGGGGG",
      "aHHHHHHHHHbGGGGG",
      "HHHHHHHHHHbGGGGG",
      "HHHHaHHaaaaaaaGG",
      "HHHHaHHaaaaaaaGG",
      "HHHHaHHaaaaaaaGG",
      "HHHHaHHaaaaaaaGG",
      "HHHHaHHaaaaaaaGG",
      "HHHHaHHaaaaaaaGG",
      "HHHHaHHaaaaaaaGG",
      "HHHHaHHaaaaaaaGG",
      "HHHHaHHaaaaaaaGG",
      "HHHHaHHaaaaaaaGG",
      "HHHHHHHHHHbGGGGG",
      "HHHHHHHHHHbGGGGG",
      "GGGGGGGGGGGGGGGG"
    ],
    [
      "                ",
      "c      d ef     ",
      "       g hf     ",
      "    i  jjjjjjj  ",
      "  klm  jnno!pj  ",
      "       q   rrj  ",
      "  sti  u  oooj  ",
      "  klw  x     j  ",
      "    y  q     j  ",
      "  sti  jA jjBj  ",
      "  klm  C  jD j  ",
      "       CE jF j  ",
      "  sti  jjjjjjj  ",
      "       d ef     ",
      "       g hf     ",
      "                "
    ],
    [
      "                ",
      "c               ",
      "                ",
      "    i  jjjjjjj  ",
      "    I  jJJpKoj  ",
      "       q     j  ",
      "    i  L  oroj  ",
      "       M     j  ",
      "       q     j  ",
      "    i  jN jjOj  ",
      "    I  P  j  j  ",
      "       P  jQ j  ",
      "    i  jjjjjjj  ",
      "                ",
      "                ",
      "                "
    ],
    [
      "                ",
      "R               ",
      "                ",
      "    i  SSSSSSS  ",
      "       STU r V  ",
      "       S     V  ",
      "    i  S     S  ",
      "       S     V  ",
      "       S     V  ",
      "    i  S  jjjS  ",
      "       S  j  V  ",
      "       S  j  V  ",
      "    i  SSSSSSS  ",
      "                ",
      "                ",
      "                "
    ],
    [
      "                ",
      "                ",
      "                ",
      "    jW jjjjjjj  ",
      "       jrXj rj  ",
      "       j  j  j  ",
      "    jW j Yj  j  ",
      "       j  j  j  ",
      "       j  j  j  ",
      "    jY j Wjjjj  ",
      "       j  jZZj  ",
      "       j  jZZj  ",
      "    jW jjjjjjj  ",
      "                ",
      "                ",
      "                "
    ],
    [
      "                ",
      "                ",
      " 00000000000000 ",
      " 0ffaaaaaaaaaa0 ",
      " 0ffaffaffaffa0 ",
      " 0ffaffaffaffa0 ",
      " 0ffaffaffaffa0 ",
      " 0ffaffaffaffa0 ",
      " 0ffaffaffaffa0 ",
      " 0ffaffaffaffa0 ",
      " 0ffaffaffaffa0 ",
      " 0ffaffaffaffa0 ",
      " 0ffaaaaaaaaaa0 ",
      " 00000000000000 ",
      "                ",
      "                "
    ]
  ]
}