{
  "name": "building_residential3_floor1",
  "refpalette": "c70cities:building_residential3_floor1_palette",
  "xsize": 16,
  "zsize": 16,
  "slices": [
    [
      "                ",
      "                ",
      "  aabbbaabbbaa  ",
      "  b          b  ",
      "  b          b  ",
      "  b          b  ",
      "  b          b  ",
      "  aa         a  ",
      "  cd   e  fffa  ",
      "  cg         b  ",
      "  cg         b  ",
      "  cd         b  ",
      "  cddggda    a  ",
      "  ccccccabbbba  ",
      "                ",
      "                "
    ],
    [
      "                ",
      " hhhhhhhhhhhhhh ",
      " haaaaaaaaaaaah ",
      "  a          a  ",
      "  a          a  ",
      "  a          a  ",
      "  a          a  ",
      "  aa         a  ",
      "  cd   e  fffa  ",
      "  cd         a  ",
      "  cd         a  ",
      "  cd         a  ",
      "  cddddda    a  ",
      " hccccccaaaaaah ",
      " hhhhhhhhhhhhhh ",
      "                "
    ],
    [
      "                ",
      "                ",
      " iiiiiiiiiiiiii ",
      " jjjjjjjjjjjjjj ",
      " kkkkkkkkkkkkkk ",
      " hahhhhhhhhhhah ",
      "  a          a  ",
      "  aa        ea  ",
      "  cd   e  klka  ",
      "  cd         a  ",
      " hcdhhhhhhhhhah ",
      " kkkkkkkkkkkkkk ",
      " mmmmmmmmmmmmmm ",
      " iiiiiiiiiiiiii ",
      "                ",
      "                "
    ],
    [
      "                ",
      "                ",
      "                ",
      "                ",
      "                ",
      " iiiiiiiiiiiiii ",
      " jjjjjjjjjjjjjj ",
      " kkkkkkkkkkkkkk ",
      " kkkkkkkkkkkkkk ",
      " mmmmmmmmmmmmmm ",
      " iiiiiiiiiiiiii ",
      "                ",
      "                ",
      "                ",
      "                ",
      "                "
    ],
    [
      "                ",
      "                ",
      "                ",
      "                ",
      "                ",
      "                ",
      "       ~        ",
      "       ~        ",
      "                ",
      "                ",
      "                ",
      "                ",
      "                ",
      "                ",
      "                ",
      "                "
    ],
    [
      "                ",
      "                ",
      "                ",
      "                ",
      "                ",
      "                ",
      "                ",
      "       ~        ",
      "                ",
      "                ",
      "                ",
      "                ",
      "                ",
      "                ",
      "                ",
      "                "
    ]
  ]
}