{
  "name": "building_hotel3_base2_270",
  "refpalette": "c70cities:building_hotel3_base2_palette_270",
  "xsize": 16,
  "zsize": 16,
  "slices": [
    [
      "aaaaaaaaaaaaaaaa",
      "abbbbcbbbccbbbba",
      "abbbbbbbbbbbbbca",
      "abbbfbbbbbbbbbba",
      "abbbdeeeeeedbbba",
      "acbbeeeeeeeebbba",
      "abbbeeeeeeeebbba",
      "afbbeeeeeeeebbba",
      "abbbeeeeeeeebb!a",
      "abbbeeeeeeeebbba",
      "abbbeeeeeeeebbba",
      "abbbdeeeeeedbbba",
      "acbbbbbbbbbbbcba",
      "abbbbbbbbbbbbbba",
      "abbbbbbcbbbbbbba",
      "aaaaaaaaaaaaaaaa"
    ],
    [
      "aaaaaaaaaaaaaaaa",
      "agfgihgiihhgiiga",
      "aggiiigijiigiiha",
      "agiiiiiiiiiiiiia",
      "aigidkkkkkkdiija",
      "ahiikiik   kiiga",
      "agiikkqoom kigga",
      "aijik     ldiija",
      "agiik     ldiiia",
      "agjik rppn kiiga",
      "agijk      kijia",
      "agjidkkkkkkdiiga",
      "ahiiiiiiiiiijhga",
      "aggijiijiijjggga",
      "aggggjghigigggga",
      "aaaaaaaaaaaaaaaa"
    ],
    [
      "aaaaaaaaaaaaaaaa",
      "ajijihjiihhjiiia",
      "ajiiiiiijiiiiiha",
      "aiiiiiiiiiiiiiia",
      "aiiidkkkkkkdiija",
      "ahiiki     kiiia",
      "ajiik      kijga",
      "aijik     ldiija",
      "aiiik     ldiiia",
      "agjik      kiiia",
      "agijk      kijia",
      "aijidkkkkkkdiiga",
      "ahiiiiiiiiiijhja",
      "agjijiijiijjigga",
      "aggiijihijigggga",
      "aaaaaaaaaaaaaaaa"
    ],
    [
      "aaaaaaaaaaaaaaaa",
      "asisihsiihhsiiia",
      "asiiiiiisiiiiiha",
      "aiiiiiiiiiiiiiia",
      "aiiidikkkkkdiisa",
      "ahiiki     kiiia",
      "asiik      kissa",
      "aisik     ldiisa",
      "aiiik     ldiiia",
      "assik      kiiia",
      "agisk      kisia",
      "aisidkkkkkkdiiia",
      "ahiiiiiiiiiishsa",
      "aisisiisiissista",
      "agsiisihisisggga",
      "aaaaaaaaaaaaaaaa"
    ],
    [
      "aaaaaaaaaaaaaaaa",
      "a              a",
      "a              a",
      "a              a",
      "a   d  kkkkd   a",
      "a   k      k   a",
      "a   k      k   a",
      "a   k     ld   a",
      "a   k     ld   a",
      "a   k      k   a",
      "a   k      k   a",
      "a   dkkkkkkd   a",
      "a              a",
      "a              a",
      "a             ga",
      "aaaaaaaaaaaaaaaa"
    ],
    [
      "aaaaaaaaaaaaaaaa",
      "auuuuuuuuuuuuuua",
      "auuuuuuuuuuuuuua",
      "auuuuuuuuuuuuuua",
      "auuudwwwwwwduuua",
      "auuuwwwwwwwwuuua",
      "auuuwwwwwwwwuuua",
      "auuuwwwwwwlduuua",
      "auuuwwwwwwlduuua",
      "auuuwwwwwwwwuuua",
      "auuuwwwwwwwwuuua",
      "auuudwwwwwwduuua",
      "auuuuuuuuuuuuuua",
      "auuuuuuuuuuuuuua",
      "auuuuuuuuuuuuuua",
      "aaaaaaaaaaaaaaaa"
    ]
  ]
}