{
  "name": "building_office1_floor1_270",
  "refpalette": "c70cities:building_office1_floor1_palette_270",
  "xsize": 16,
  "zsize": 16,
  "slices": [
    [
      "                ",
      " eeee  c        ",
      " ebbfddcaaaaaa  ",
      " ebbgbbbbbbbba  ",
      " ebbbbbbbbbbba  ",
      " ebbbbbbbbbbba  ",
      " ebbbbbbbbbbba  ",
      " ebbbbbbbbbbba  ",
      " ebbbbbbbbbbba  ",
      " ebbbbbbbbbbba  ",
      " eb!bbbbbbbbba  ",
      " ebbbbbbbbbbba  ",
      " ebbbbbbbbbbba  ",
      " ebbfddcaaaaaa  ",
      " eeee  c        ",
      "                "
    ],
    [
      "                ",
      " rrrr  c        ",
      " rttfddchhhhhh  ",
      " r  g  f     h  ",
      " r     o  j  h  ",
      " r     p   i h  ",
      " ryus  f mk  h  ",
      " rfffqff   i h  ",
      " r wi  f m   h  ",
      " rAw   f  ki h  ",
      " r wi  f m   h  ",
      " r     f  l  h  ",
      " r     fn    h  ",
      " rxxfddchhhhhh  ",
      " rrrr  c        ",
      "                "
    ],
    [
      "                ",
      " rrrr  c        ",
      " rttfddchhhhhh  ",
      " L  g  f     h  ",
      " d     C     h  ",
      " d     D  B  h  ",
      " d     f  B  h  ",
      " dfffEff  B  h  ",
      " d F   f  B  h  ",
      " d I   f  B  h  ",
      " d J   f  B  h  ",
      " d     f     h  ",
      " L     f     h  ",
      " r Kfddchhhhhh  ",
      " rrrr  c        ",
      "                "
    ],
    [
      "                ",
      " rrrr  c        ",
      " rttfddchhhhhh  ",
      " L  g  f     h  ",
      " d     f     h  ",
      " d     f     h  ",
      " d     f     h  ",
      " dffffff     h  ",
      " d     f     h  ",
      " d     f     h  ",
      " d     f     h  ",
      " d     f     h  ",
      " L     f     h  ",
      " r  fddchhhhhh  ",
      " rrrr  c        ",
      "                "
    ],
    [
      "                ",
      " rrrr  c        ",
      " rMMfddchhhhhh  ",
      " r  g  f     h  ",
      " r     f     h  ",
      " r     f     h  ",
      " r     f     h  ",
      " rffffff     h  ",
      " r     f     h  ",
      " r     f     h  ",
      " r     f     h  ",
      " r     f     h  ",
      " r     f     h  ",
      " r  fddchhhhhh  ",
      " rrrr  c        ",
      "                "
    ],
    [
      "                ",
      " rrrr  c        ",
      " rLLfddchhhhhh  ",
      " rLLg  fLLLLLh  ",
      " rLLLLLfLLLLLh  ",
      " rLLLLLfLLLLLh  ",
      " rLLLLLfLLLLLh  ",
      " rffffffLLLLLh  ",
      " rLLLLLfLLLLLh  ",
      " rLLLLLfLLLLLh  ",
      " rLLLLLfLLLLLh  ",
      " rLLLLLfLLLLLh  ",
      " rLL   fLLLLLh  ",
      " rLLfddchhhhhh  ",
      " rrrr  c        ",
      "                "
    ]
  ]
}