{
  "name": "building_hotel2_floor1",
  "refpalette": "c70cities:building_hotel2_floor1_palette",
  "xsize": 16,
  "zsize": 16,
  "slices": [
    [
      "                ",
      " aaaaaaaaaaaaaa ",
      " abccccccc!d    ",
      " abccccccccd    ",
      " a=ccccccccd    ",
      " acc!ccccccd    ",
      " acccccccccd    ",
      " acccccccccd    ",
      " acccccccccd    ",
      " acccccccccd    ",
      " acccccccccd    ",
      " acccccccccd    ",
      " acccccccccd    ",
      " adddddddddd    ",
      " a              ",
      "                "
    ],
    [
      "                ",
      " aaaaaaaaaaaaaa ",
      " ab  e  ffgh    ",
      " ab  i    jh    ",
      " a=aaa   j h    ",
      " aklga  m mh    ",
      " ano a     h    ",
      " aaapaj   jh    ",
      " a         h    ",
      " a==       h    ",
      " a=q  rst uh    ",
      " a==  rst uh    ",
      " a         h    ",
      " ahhhhhhhhhh    ",
      " a              ",
      "                "
    ],
    [
      "                ",
      " aaaaaaaaaaaaaa ",
      " ab  w     h    ",
      " ab  x    yh    ",
      " a=aaa  yyyh    ",
      " a   a     h    ",
      " a   a     h    ",
      " aaaAaB   Bh    ",
      " a         h    ",
      " a         h    ",
      " a    r    h    ",
      " a    r    h    ",
      " a         h    ",
      " ahhhhhhhhhh    ",
      " a              ",
      "                "
    ],
    [
      "                ",
      " aaaaaaaaaaaaaa ",
      " ab  a  CCCh    ",
      " ab  a     h    ",
      " a=aaa     h    ",
      " a   a     h    ",
      " a   a     h    ",
      " aaaaaB   Bh    ",
      " a         h    ",
      " a         h    ",
      " a         h    ",
      " a         h    ",
      " a         h    ",
      " ahhhhhhhhhh    ",
      " a              ",
      "                "
    ],
    [
      "                ",
      " aaaaaaaaaaaaaa ",
      " ab  a   D h    ",
      " ab  a     h    ",
      " a=aaa     h    ",
      " a   a     h    ",
      " a   a     h    ",
      " aaaaa     h    ",
      " a         h    ",
      " a         h    ",
      " a         h    ",
      " a         h    ",
      " a         h    ",
      " ahhhhhhhhhh    ",
      " a              ",
      "                "
    ],
    [
      "                ",
      " aaaaaaaaaaaaaa ",
      " abEEaEEEEEy    ",
      " abEEaEEEEEy    ",
      " a=aaaEEEEEy    ",
      " aEEEaEEEEEy    ",
      " aEEEaEEEEEy    ",
      " aaaaaEEEEEy    ",
      " aEEEEEEEEEy    ",
      " aEEEEEEEEEy    ",
      " aEEEEEEEEEy    ",
      " aEEEEEEEEEy    ",
      " aEEEEEEEEEy    ",
      " ayyyyyyyyyy    ",
      " a              ",
      "                "
    ]
  ]
}