{
  "name": "building_office1_floor2_180",
  "refpalette": "c70cities:building_office1_floor2_palette_180",
  "xsize": 16,
  "zsize": 16,
  "slices": [
    [
      "                ",
      " eeeeeeeeeeeeee ",
      " ebbbbbbbbbbbbe ",
      " ebbbbbbbbbbbbe ",
      " efbbbbbbbbbgfe ",
      "  dbbbbbbbbbbd  ",
      "  dbb!bbbbbbbd  ",
      " ccbbbbbbbbbbcc ",
      "  abbbbbbbbbba  ",
      "  abbbbbbbbbba  ",
      "  abbbbbbbbbba  ",
      "  abbbbbbbbbba  ",
      "  abbbbbbbbbba  ",
      "  aaaaaaaaaaaa  ",
      "                ",
      "                "
    ],
    [
      "                ",
      " llllllllllllll ",
      " ln          ml ",
      " ln          ml ",
      " lf         gfl ",
      "  d k    k   d  ",
      "  d jjj  jjj d  ",
      " cc   i    i cc ",
      "  h          h  ",
      "  h k    k   h  ",
      "  h jjj  jjj h  ",
      "  h   i    i h  ",
      "  h          h  ",
      "  hhhhhhhhhhhh  ",
      "                ",
      "                "
    ],
    [
      "                ",
      " llrddddddddrll ",
      " lq           l ",
      " l            l ",
      " lf         gfl ",
      "  d          d  ",
      "  d opo  opo d  ",
      " cc          cc ",
      "  h          h  ",
      "  h          h  ",
      "  h opo  opo h  ",
      "  h          h  ",
      "  h          h  ",
      "  hhhhhhhhhhhh  ",
      "                ",
      "                "
    ],
    [
      "                ",
      " llrddddddddrll ",
      " l           sl ",
      " l           sl ",
      " lf         gfl ",
      "  d          d  ",
      "  d          d  ",
      " cc          cc ",
      "  h          h  ",
      "  h          h  ",
      "  h          h  ",
      "  h          h  ",
      "  h          h  ",
      "  hhhhhhhhhhhh  ",
      "                ",
      "                "
    ],
    [
      "                ",
      " llllllllllllll ",
      " l            l ",
      " l            l ",
      " lf         gfl ",
      "  d          d  ",
      "  d          d  ",
      " cc          cc ",
      "  h          h  ",
      "  h          h  ",
      "  h          h  ",
      "  h          h  ",
      "  h          h  ",
      "  hhhhhhhhhhhh  ",
      "                ",
      "                "
    ],
    [
      "                ",
      " llllllllllllll ",
      " lrrrrrrrrrrrrl ",
      " lrrrrrrrrrrrrl ",
      " lf rrrrrrrrgfl ",
      "  d rrrrrrrr d  ",
      "  d rrrrrrrr d  ",
      " ccrrrrrrrrrrcc ",
      "  hrrrrrrrrrrh  ",
      "  hrrrrrrrrrrh  ",
      "  hrrrrrrrrrrh  ",
      "  hrrrrrrrrrrh  ",
      "  hrrrrrrrrrrh  ",
      "  hhhhhhhhhhhh  ",
      "                ",
      "                "
    ]
  ]
}