{
  "name": "building_hotel3_floor2_90",
  "refpalette": "c70cities:building_hotel3_floor2_palette_90",
  "xsize": 16,
  "zsize": 16,
  "slices": [
    [
      "                ",
      "  a a a a a a   ",
      "  bbbbbbbbbbbba ",
      " abccccccccccb  ",
      "  bceeeeeeeecba ",
      " abceffffffecb  ",
      "  bceffffffecba ",
      " abdeffffffecb  ",
      "  bdeff!fffecba ",
      " abceffffffecb  ",
      "  bceffffffecba ",
      " abceeeeeeeecb  ",
      "  bccccccccccba ",
      " abbbbbbbbbbbb  ",
      "   a a a a a a  ",
      "                "
    ],
    [
      "                ",
      "  a a a a a a   ",
      "  bbbbbbbbbbbba ",
      " ab          b  ",
      "  b eelllllq ba ",
      " ab g      l b  ",
      "  b eikimo l ba ",
      " abdej imo l b  ",
      "  bdeii    l ba ",
      " ab eh    pl b  ",
      "  b eh   n l ba ",
      " ab eeeeeeeq b  ",
      "  b          ba ",
      " abbbbbbbbbbbb  ",
      "   a a a a a a  ",
      "                "
    ],
    [
      "                ",
      "  a a a a a a   ",
      "  bbbbbbbbbbbba ",
      " ab          b  ",
      "  b ee     q ba ",
      " ab r        b  ",
      "  b eiti     ba ",
      " abde  i     b  ",
      "  bdeii      ba ",
      " ab e     u  b  ",
      "  b e     u  ba ",
      " ab eesssseq b  ",
      "  b          ba ",
      " abbbbbbbbbbbb  ",
      "   a a a a a a  ",
      "                "
    ],
    [
      "                ",
      "  a a a a a a   ",
      "  bbbbbbbbbbbba ",
      " ab          b  ",
      "  b ee     q ba ",
      " ab e        b  ",
      "  b eiii     ba ",
      " abde  i     b  ",
      "  bdeii      ba ",
      " ab eu       b  ",
      "  b eu       ba ",
      " ab eeeeeeeq b  ",
      "  b          ba ",
      " abbbbbbbbbbbb  ",
      "   a a a a a a  ",
      "                "
    ],
    [
      "                ",
      "  a a a a a a   ",
      "  bbbbbbbbbbbba ",
      " ab          b  ",
      "  b ee     q ba ",
      " ab e        b  ",
      "  b eiii     ba ",
      " abde  i     b  ",
      "  bdeiii     ba ",
      " ab e  i     b  ",
      "  b e  i     ba ",
      " ab eeeeeeeq b  ",
      "  b          ba ",
      " abbbbbbbbbbbb  ",
      "   a a a a a a  ",
      "                "
    ],
    [
      "                ",
      "  a a a a a a   ",
      "  bbbbbbbbbbbba ",
      " ab          b  ",
      "  b eeeeeeee ba ",
      " ab ewwwwwwe b  ",
      "  b ewwwwwwe ba ",
      " abdewwwwwwe b  ",
      "  bdewwwwwwe ba ",
      " ab ewwwwwwe b  ",
      "  b ewwwwwwe ba ",
      " ab eeeeeeee b  ",
      "  b          ba ",
      " abbbbbbbbbbbb  ",
      "   a a a a a a  ",
      "                "
    ]
  ]
}