{
  "name": "building_apartment1_floor2",
  "refpalette": "c70cities:building_apartment1_floor2_palette",
  "xsize": 16,
  "zsize": 16,
  "slices": [
    [
      "                ",
      " aaaaaaaaaaaaaa ",
      " abbbbbbbbbbbba ",
      " abbbbbbbbbbbba ",
      " abbbbbbbbbbbba ",
      " abbbbbbbbbbbba ",
      " abbbbbbbbbbbba ",
      " abbbbbbbbbbbba ",
      " abbbbbbbbbbbba ",
      " abbbbbbbbbbbba ",
      " abbbbbbbbcbbd  ",
      " abbbbbbbb bbe  ",
      " abbbbbbbb  fe  ",
      " abbbbbbbbdghi  ",
      " aaaaaaaaa      ",
      "                "
    ],
    [
      "                ",
      " jkkkkkkkkkkkkl ",
      " mnoopqrs q!tou ",
      " m ww x   q  wu ",
      " m    qyAyy  Bu ",
      " m CD q     CDu ",
      " mqqqEqAqqqqqqu ",
      " mrsF      qIIu ",
      " m  J      J  u ",
      " mqqF KLLqqqMqu ",
      " mNO     q   d  ",
      " mP   Q Rq  Sd  ",
      " mT   Q Uq  Vd  ",
      " mW      qXXdd  ",
      " YZZZZZZZZ      ",
      "                "
    ],
    [
      "                ",
      " qqqqqqqqqqqqqq ",
      " 01   q  2q   0 ",
      " 0    3  4q   0 ",
      " 0    qy5yy   0 ",
      " q    q       q ",
      " 6qqq7q5qqqqqqq ",
      " 8  F      q  q ",
      " 8  9      9  q ",
      " 6qqF @ #qqq$qq ",
      " 8       q   h  ",
      " 8      %q   X  ",
      " 8^     %q &Sd  ",
      " 8*      qdddd  ",
      " 68000008q      ",
      "                "
    ],
    [
      "                ",
      " qq00qq00qq00qq ",
      " 0(   q  )q  +0 ",
      " 0-   q   q  [0 ",
      " 0]   qyyyy  {0 ",
      " q    q       q ",
      " 6qqqqqqqqqqqqq ",
      " 0  F      q  0 ",
      " 0  F      q  0 ",
      " 6qqF    qqqqqq ",
      " 8       q   d  ",
      " 0       q   d  ",
      " 0       qV} d  ",
      " 0 \\|`:; qdd',  ",
      " 68000008q      ",
      "                "
    ],
    [
      "                ",
      " qqkkqqkkqqkkqq ",
      " 8    q   q   8 ",
      " 8    q   q   8 ",
      " 8    qyyyy   8 ",
      " q    q       q ",
      " 6qqqqqqqqqqqqq ",
      " 8  F      q  8 ",
      " 8  F      qf 8 ",
      " 6qqF    qqqqqq ",
      " 8       q   '  ",
      " 8       q.  '  ",
      " 8       q}  '  ",
      " 8       qeXXd  ",
      " 68888888q      ",
      "                "
    ],
    [
      "                ",
      " qqqqqqqqqqqqqq ",
      " qddddq///ddddq ",
      " qddddq///ddddq ",
      " qddddqdddddddq ",
      " qddddqdddddddq ",
      " qqqqqqqqqqqqqq ",
      " q//dddddddqddq ",
      " q//dddddddqddq ",
      " qdddddddqqqqqq ",
      " qdddddddqV  d  ",
      " qdddddddqc  d  ",
      " qdddddddq   d  ",
      " qdddddddqdddd  ",
      " qqqqqqqqq      ",
      "                "
    ]
  ]
}