{
  "name": "building_policeoffice1_base1_270",
  "refpalette": "c70cities:building_policeoffice1_base1_palette_270",
  "xsize": 16,
  "zsize": 16,
  "slices": [
    [
      "vvvvvvvvvvvvvvvv",
      "v==============v",
      "v=bba=====!==!=v",
      "v=cc===========v",
      "v=cc===========v",
      "v=cc===========v",
      "v=cc===========v",
      "v=cc===========v",
      "v=cc===========v",
      "v=cc===========v",
      "v=cc===========v",
      "v=cc===========v",
      "v=cc===========v",
      "v=cc======!==!=v",
      "v==============v",
      "vvvvvvvvvvvvvvvv"
    ],
    [
      "vvvvvvvvvvvvvvvv",
      "vaaaaaaaaaaaaaav",
      "vabbamid id idav",
      "va  i ie ie ieav",
      "va  i i  i  i av",
      "va  i         av",
      "va  i   k  k  av",
      "va  i  ff ffjfav",
      "va  oaaaaaaaaaav",
      "va pin ff ff fav",
      "va  i    l    av",
      "va            av",
      "va ii ig ig igav",
      "va  imih ih ihav",
      "vaaaaaaaaaaaaaav",
      "vvvvvvvvvvvvvvvv"
    ],
    [
      "vvvvvvvvvvvvvvvv",
      "vaaaaaaaaaaaaaav",
      "vabba i  i  i av",
      "va  i i  i  i av",
      "va  i i  i  i av",
      "va  i         av",
      "va  i         av",
      "va  i      j  av",
      "va   oaaaaaaaaav",
      "va  i    j    av",
      "va  i         av",
      "va            av",
      "va  i i  i  i av",
      "va  i i  i  i av",
      "vaaaaaaaaaaaaaav",
      "vvvvvvvvvvvvvvvv"
    ],
    [
      "vvvvvvvvvvvvvvvv",
      "vaaaaaaaaaaaaaav",
      "vabbaj   j    av",
      "va  i         av",
      "va  i         av",
      "va  i         av",
      "va  i         av",
      "va  i     j   av",
      "va  aaaaaaaaaaav",
      "va  i         av",
      "va  i         av",
      "va  i         av",
      "va  i         av",
      "va  i         av",
      "vaaaaaaaaaaaaaav",
      "vvvvvvvvvvvvvvvv"
    ],
    [
      "vvvvvvvvvvvvvvvv",
      "vaaaaaaaaaaaaaav",
      "vabbajj  jj jjav",
      "va  aj        av",
      "va  a         av",
      "va  a       j av",
      "va  a      j  av",
      "va  aj   jjj jav",
      "va  aaaaaaaaaaav",
      "va  ajj     j av",
      "va  aj        av",
      "va  a         av",
      "va ja         av",
      "va  aj   j  j av",
      "vaaaaaaaaaaaaaav",
      "vvvvvvvvvvvvvvvv"
    ],
    [
      "vvvvvvvvvvvvvvvv",
      "vaaaaaaaaaaaaaaq",
      "vabbarrrrrrrrraq",
      "vassarrrrrrrrraq",
      "vassarrrrrrrrraq",
      "vassarrrrrrrrraq",
      "vassarrrrrrrrraq",
      "vassarrrrrrrrraq",
      "vassaaaaaaaaaaaq",
      "vassarrrrrrrrraq",
      "vassarrrrrrrrraq",
      "vassarrrrrrrrraq",
      "vassarrrrrrrrraq",
      "vassarrrrrrrrraq",
      "vaaaaaaaaaaaaaaq",
      "vqqqqqqqqqqqqqqv"
    ]
  ]
}