{
  "name": "building_residential3_floor1_270",
  "refpalette": "c70cities:building_residential3_floor1_palette_270",
  "xsize": 16,
  "zsize": 16,
  "slices": [
    [
      "                ",
      "                ",
      "  ccccccabbbba  ",
      "  cddggda    a  ",
      "  cd         b  ",
      "  cg         b  ",
      "  cg         b  ",
      "  cd   e     a  ",
      "  aa         a  ",
      "  b          b  ",
      "  b    f     b  ",
      "  b    f     b  ",
      "  b    f     a  ",
      "  aabbbaabbbba  ",
      "                ",
      "                "
    ],
    [
      "                ",
      " hh          hh ",
      " hccccccaaaaaah ",
      " hcddddda    ah ",
      " hcd         ah ",
      " hcd         ah ",
      " hcd         ah ",
      " hcd   e     ah ",
      " haa         ah ",
      " ha          ah ",
      " ha    f     ah ",
      " ha    f     ah ",
      " ha    f     ah ",
      " haaaaaaaaaaaah ",
      " hh          hh ",
      "                "
    ],
    [
      "                ",
      "  imkh    hkji  ",
      "  imkcccaaakji  ",
      "  imkddda hkji  ",
      "  imkh    hkji  ",
      "  imkh    hkji  ",
      "  imkh    hkji  ",
      "  imkh e  hkji  ",
      "  imkh    hkji  ",
      "  imkh    hkji  ",
      "  imkh k  hkji  ",
      "  imkh l  hkji  ",
      "  imkh ke hkji  ",
      "  imkaaaaaakji  ",
      "  imkh    hkji  ",
      "                "
    ],
    [
      "                ",
      "     imkkji     ",
      "     imkkji     ",
      "     imkkji     ",
      "     imkkji     ",
      "     imkkji     ",
      "     imkkji     ",
      "     imkkji     ",
      "     imkkji     ",
      "     imkkji     ",
      "     imkkji     ",
      "     imkkji     ",
      "     imkkji     ",
      "     imkkji     ",
      "     imkkji     ",
      "                "
    ],
    [
      "                ",
      "                ",
      "                ",
      "                ",
      "                ",
      "                ",
      "                ",
      "        ~~      ",
      "                ",
      "                ",
      "                ",
      "                ",
      "                ",
      "                ",
      "                ",
      "                "
    ],
    [
      "                ",
      "                ",
      "                ",
      "                ",
      "                ",
      "                ",
      "                ",
      "        ~       ",
      "                ",
      "                ",
      "                ",
      "                ",
      "                ",
      "                ",
      "                ",
      "                "
    ]
  ]
}