{
  "name": "building_bank1_floor1_180",
  "refpalette": "c70cities:building_bank1_floor1_palette_180",
  "xsize": 16,
  "zsize": 16,
  "slices": [
    [
      "                ",
      "   kbbj  kbbj   ",
      "  deeeedeeeeed  ",
      " ieeeeeeeeeeeeh ",
      " beeeeeeeeeeeeb ",
      " beeeeeeeeeeeeb ",
      " geeeeeeeeee ef ",
      "  eeeeeeeeee d  ",
      "  deeeeeeeee e  ",
      " ieeeeeeeeee eh ",
      " beeeeeeeeee eb ",
      " beeeeeeeeeeeeb ",
      " geeeeeeeeeeeef ",
      "  deeeeedeeeed  ",
      "   cbba  cbba   ",
      "                "
    ],
    [
      "                ",
      "  kbbj  kbbj    ",
      "  llllmlllllmlh ",
      "  m    Db    lb ",
      " il    Dbx   lb ",
      " blC B ybx   lf ",
      " blC B ybA s m  ",
      " gl    ybx s l  ",
      "  l   wub  s lh ",
      "  m   ttb  s lb ",
      " il     b  srqb ",
      " bl     p    lf ",
      " blo    n    m  ",
      " glmlllllmllll  ",
      "    cbba  cbba  ",
      "                "
    ],
    [
      "                ",
      " Ebbj  kbbj  kE ",
      " glllmlllllmllb ",
      "  l    Lb    lb ",
      "  m     b    lf ",
      " il     b    m  ",
      " bl     bK s l  ",
      " bl     b    lh ",
      " gl     b  s lb ",
      "  l   Jtb   rqb ",
      "  m     b  s lf ",
      " il     I    m  ",
      " blo    F    l  ",
      " bllmlllllmlllh ",
      " Ea  cbba  cbbE ",
      "                "
    ],
    [
      "                ",
      " Ebj  kbbj  kbE ",
      " bllmlllllmlllb ",
      " gl     b    lf ",
      "  l     b    m  ",
      "  m     b    l  ",
      " il     bK s lh ",
      " bl     b    lb ",
      " bl     b  srqb ",
      " gl   ttb     f ",
      "  l     b  s m  ",
      "  m     b    l  ",
      " ilo    b    lh ",
      " blllmlllllmllb ",
      " Eba  cbba  cbE ",
      "                "
    ],
    [
      "                ",
      " Ej  kbbj  kbbE ",
      " blmlllllmllllf ",
      " bl     b    m  ",
      " gl     b    l  ",
      "  l     b    lh ",
      "  m     b  s lb ",
      " il     b   rqb ",
      " bl     b  s  f ",
      " bl     b    m  ",
      " gl     b  s l  ",
      "  l     b    lh ",
      "  m     b    lb ",
      " illllmlllllmlb ",
      " Ebba  cbba  cE ",
      "                "
    ],
    [
      "                ",
      "    kbbj  kbbj  ",
      " imlllllmllllm  ",
      " blMMMMMbMMMMl  ",
      " blMMMMMbMMMMlh ",
      " glMNNNMbMMMMlb ",
      "  lMN!NMbMMsrqb ",
      "  mMN!NMbMM   f ",
      " ilMNNNMbMMs m  ",
      " blMMMMMbMM  l  ",
      " blMMMMMbMMs lh ",
      " glMMMMMbMMMMlb ",
      "  lMMMMMbMMMMlb ",
      "  mllllmlllllmf ",
      "  cbba  cbba    ",
      "                "
    ]
  ]
}