{
  "name": "building_office5_floor2_90",
  "refpalette": "c70cities:building_office5_floor2_palette_90",
  "xsize": 16,
  "zsize": 16,
  "slices": [
    [
      "                ",
      "                ",
      "     dbdbdbdbd  ",
      "     deeeeeeeb  ",
      "  abadeeeeeeed  ",
      "  bccdeeeeeeeb  ",
      "  accdeeeeeeed  ",
      "  bccdfeeeeeeb  ",
      "  accdfeeeeeed  ",
      "  bccdeeeeeeeb  ",
      "  acceeeeeeeed  ",
      "  bcceeeeeeeeb  ",
      "  abadeeeeeeed  ",
      "     dbdbdbdbd  ",
      "                ",
      "                "
    ],
    [
      "                ",
      "                ",
      "     dbdbdbdbd  ",
      "     d       b  ",
      "  abad    gn d  ",
      "  b jd  l g  b  ",
      "  a id      nd  ",
      "  b hdf   g  b  ",
      "  a gdf  lg  d  ",
      "  b gdk      b  ",
      "  a       gn d  ",
      "  b       g  b  ",
      "  abadk  m   d  ",
      "     dbdbdbdbd  ",
      "                ",
      "                "
    ],
    [
      "                ",
      "                ",
      "     dbdbdbdbd  ",
      "     d       b  ",
      "  aba!    p  d  ",
      "  b  d       b  ",
      "  a  d       d  ",
      "  b  df      b  ",
      "  a odf      d  ",
      "  b  dk      b  ",
      "  a       p  d  ",
      "  b          b  ",
      "  abadk      d  ",
      "     dbdbdbdbd  ",
      "                ",
      "                "
    ],
    [
      "                ",
      "                ",
      "     dbdbdbdbd  ",
      "     d       b  ",
      "  abar       d  ",
      "  b qd       b  ",
      "  a qd       d  ",
      "  b qdf      b  ",
      "  a qdf      d  ",
      "  b  d       b  ",
      "  a  r       d  ",
      "  b  r       b  ",
      "  abad       d  ",
      "     dbdbdbdbd  ",
      "                ",
      "                "
    ],
    [
      "                ",
      "                ",
      "     dbdbdbdbd  ",
      "     d       b  ",
      "  abad       d  ",
      "  b  d       b  ",
      "  a  d       d  ",
      "  b  df      b  ",
      "  a  df      d  ",
      "  b  d       b  ",
      "  a  d       d  ",
      "  b  d       b  ",
      "  abad       d  ",
      "     dbdbdbdbd  ",
      "                ",
      "                "
    ],
    [
      "                ",
      "                ",
      "     dbdbdbdbd  ",
      "     dsssssssb  ",
      "  abadsssssssd  ",
      "  b  dsssssssb  ",
      "  a  dsssssssd  ",
      "  b  dfssssssb  ",
      "  a  dfssssssd  ",
      "  b  dsssssssb  ",
      "  a  dsssssssd  ",
      "  b  dsssssssb  ",
      "  abadsssssssd  ",
      "     dbdbdbdbd  ",
      "                ",
      "                "
    ]
  ]
}