{
  "name": "building_hotel3_floor2",
  "refpalette": "c70cities:building_hotel3_floor2_palette",
  "xsize": 16,
  "zsize": 16,
  "slices": [
    [
      "                ",
      "  a a a a a a   ",
      "  bbbbbbbbbbbba ",
      " abccccddccccb  ",
      "  bceeeeeeeecba ",
      " abceffffffecb  ",
      "  bceffffffecba ",
      " abceff!fffecb  ",
      "  bceffffffecba ",
      " abceffffffecb  ",
      "  bceffffffecba ",
      " abceeeeeeeecb  ",
      "  bccccccccccba ",
      " abbbbbbbbbbbb  ",
      "   a a a a a a  ",
      "                "
    ],
    [
      "                ",
      "  a a a a a a   ",
      "  bbbbbbbbbbbba ",
      " ab    dd    b  ",
      "  b eeeeeege ba ",
      " ab ehhiji e b  ",
      "  b e  ikl m ba ",
      " ab e   ii m b  ",
      "  b e   nn m ba ",
      " ab eo  pp m b  ",
      "  b e q    m ba ",
      " ab rmmmmmmr b  ",
      "  b          ba ",
      " abbbbbbbbbbbb  ",
      "   a a a a a a  ",
      "                "
    ],
    [
      "                ",
      "  a a a a a a   ",
      "  bbbbbbbbbbbba ",
      " ab    dd    b  ",
      "  b eeeeeese ba ",
      " ab e  i i e b  ",
      "  b t  i u   ba ",
      " ab t   ii   b  ",
      "  b t        ba ",
      " ab t        b  ",
      "  b eww      ba ",
      " ab r      r b  ",
      "  b          ba ",
      " abbbbbbbbbbbb  ",
      "   a a a a a a  ",
      "                "
    ],
    [
      "                ",
      "  a a a a a a   ",
      "  bbbbbbbbbbbba ",
      " ab    dd    b  ",
      "  b eeeeeeee ba ",
      " ab ewwi i e b  ",
      "  b e  i i   ba ",
      " ab e   ii   b  ",
      "  b e        ba ",
      " ab e        b  ",
      "  b e        ba ",
      " ab r      r b  ",
      "  b          ba ",
      " abbbbbbbbbbbb  ",
      "   a a a a a a  ",
      "                "
    ],
    [
      "                ",
      "  a a a a a a   ",
      "  bbbbbbbbbbbba ",
      " ab    dd    b  ",
      "  b eeeeeeee ba ",
      " ab e  i i e b  ",
      "  b e  i i   ba ",
      " ab eiiiii   b  ",
      "  b e        ba ",
      " ab e        b  ",
      "  b e        ba ",
      " ab r      r b  ",
      "  b          ba ",
      " abbbbbbbbbbbb  ",
      "   a a a a a a  ",
      "                "
    ],
    [
      "                ",
      "  a a a a a a   ",
      "  bbbbbbbbbbbba ",
      " ab    dd    b  ",
      "  b eeeeeeee ba ",
      " ab exxxxxxe b  ",
      "  b exxxxxxe ba ",
      " ab exxxxxxe b  ",
      "  b exxxxxxe ba ",
      " ab exxxxxxe b  ",
      "  b exxxxxxe ba ",
      " ab eeeeeeee b  ",
      "  b          ba ",
      " abbbbbbbbbbbb  ",
      "   a a a a a a  ",
      "                "
    ]
  ]
}