{
  "name": "building_hotel3_floor2",
  "refpalette": "c70cities:building_hotel3_floor2_palette",
  "xsize": 16,
  "zsize": 16,
  "slices": [
    [
      "                ",
      "  a a a a a a   ",
      "  bbbbbbbbbbbba ",
      " abccccddccccb  ",
      "  bceeeeeeeecba ",
      " abceffffffecb  ",
      "  bceffffffecba ",
      " abceff!fffecb  ",
      "  bceffffffecba ",
      " abceffffffecb  ",
      "  bceffffffecba ",
      " abceeeeeeeecb  ",
      "  bccccccccccba ",
      " abbbbbbbbbbbb  ",
      "   a a a a a a  ",
      "                "
    ],
    [
      "                ",
      "  a a a a a a   ",
      "  bbbbbbbbbbbba ",
      " ab    dd    b  ",
      "  b eeeeeege ba ",
      " ab ehhiji e b  ",
      "  b e  i k l ba ",
      " ab e   ii l b  ",
      "  b e   mm l ba ",
      " ab en  oo l b  ",
      "  b e p    l ba ",
      " ab qllllllq b  ",
      "  b          ba ",
      " abbbbbbbbbbbb  ",
      "   a a a a a a  ",
      "                "
    ],
    [
      "                ",
      "  a a a a a a   ",
      "  bbbbbbbbbbbba ",
      " ab    dd    b  ",
      "  b eeeeeere ba ",
      " ab e  i i e b  ",
      "  b s  i t   ba ",
      " ab s   ii   b  ",
      "  b s        ba ",
      " ab s        b  ",
      "  b euu      ba ",
      " ab q      q b  ",
      "  b          ba ",
      " abbbbbbbbbbbb  ",
      "   a a a a a a  ",
      "                "
    ],
    [
      "                ",
      "  a a a a a a   ",
      "  bbbbbbbbbbbba ",
      " ab    dd    b  ",
      "  b eeeeeeee ba ",
      " ab euui i e b  ",
      "  b e  i i   ba ",
      " ab e   ii   b  ",
      "  b e        ba ",
      " ab e        b  ",
      "  b e        ba ",
      " ab q      q b  ",
      "  b          ba ",
      " abbbbbbbbbbbb  ",
      "   a a a a a a  ",
      "                "
    ],
    [
      "                ",
      "  a a a a a a   ",
      "  bbbbbbbbbbbba ",
      " ab    dd    b  ",
      "  b eeeeeeee ba ",
      " ab e  i i e b  ",
      "  b e  i i   ba ",
      " ab eiiiii   b  ",
      "  b e        ba ",
      " ab e        b  ",
      "  b e        ba ",
      " ab q      q b  ",
      "  b          ba ",
      " abbbbbbbbbbbb  ",
      "   a a a a a a  ",
      "                "
    ],
    [
      "                ",
      "  a a a a a a   ",
      "  bbbbbbbbbbbba ",
      " ab    dd    b  ",
      "  b eeeeeeee ba ",
      " ab ewwwwwwe b  ",
      "  b ewwwwwwe ba ",
      " ab ewwwwwwe b  ",
      "  b ewwwwwwe ba ",
      " ab ewwwwwwe b  ",
      "  b ewwwwwwe ba ",
      " ab eeeeeeee b  ",
      "  b          ba ",
      " abbbbbbbbbbbb  ",
      "   a a a a a a  ",
      "                "
    ]
  ]
}