{
  "name": "building_gasstation1_ground_180",
  "refpalette": "c70cities:building_gasstation1_ground_palette_180",
  "xsize": 16,
  "zsize": 16,
  "slices": [
    [
      "GGGGGGGGGGGGGGGG",
      "GGGGGbHHHHHHHHHH",
      "GGGGGbHHHHHHHHHH",
      "GGaaaaaaaHHaHHHH",
      "GGaaaaaaaHHaHHHH",
      "GGaaaaaaaHHaHHHH",
      "GGaaaaaaaHHaHHHH",
      "GGaaaaaaaHHaHHHH",
      "GGaaaaaaaHHaHHHH",
      "GGaaaaaaaHHaHHHH",
      "GGaaaaaaaHHaHHHH",
      "GGaaaaaaaHHaHHHH",
      "GGaaaaaaaHHaHHHH",
      "GGGGGbHHHHHHHHHH",
      "GGGGGbHHHHHHHHHa",
      "GGGGGGGGGGGGGGGG"
    ],
    [
      "                ",
      "     fh g       ",
      "     fe d       ",
      "  jjjjjjj  its  ",
      "  j Fj EC       ",
      "  j Dj  C  mlk  ",
      "  jBjj Aj  its  ",
      "  j     q  y    ",
      "  j     x  wlk  ",
      "  jooo  u  its  ",
      "  jrr   q       ",
      "  jp!onnj  mlk  ",
      "  jjjjjjj  i    ",
      "     fh g       ",
      "     fe d      c",
      "                "
    ],
    [
      "                ",
      "                ",
      "                ",
      "  jjjjjjj  i    ",
      "  j Pj  O       ",
      "  j  j  O  I    ",
      "  jNjj Mj  i    ",
      "  j     q       ",
      "  j     L       ",
      "  joro  K  i    ",
      "  j     q       ",
      "  joopJJj  I    ",
      "  jjjjjjj  i    ",
      "                ",
      "               c",
      "                "
    ],
    [
      "                ",
      "                ",
      "                ",
      "  RRRRRRR  i    ",
      "  S  j  R       ",
      "  S  j  R       ",
      "  Rjjj  R  i    ",
      "  S     R       ",
      "  S     R       ",
      "  R     R  i    ",
      "  S     R       ",
      "  S r   R       ",
      "  RRRRRRR  i    ",
      "                ",
      "               Q",
      "                "
    ],
    [
      "                ",
      "                ",
      "                ",
      "  jjjjjjj Tj    ",
      "  jVVj  j       ",
      "  jVVj  j       ",
      "  jjjjT j Uj    ",
      "  j  j  j       ",
      "  j  j  j       ",
      "  j  jU j Tj    ",
      "  j  j  j       ",
      "  jr j rj       ",
      "  jjjjjjj Tj    ",
      "                ",
      "                ",
      "                "
    ],
    [
      "                ",
      "                ",
      " WWWWWWWWWWWWWW ",
      " WaaaaaaaaaaffW ",
      " WaffaffaffaffW ",
      " WaffaffaffaffW ",
      " WaffaffaffaffW ",
      " WaffaffaffaffW ",
      " WaffaffaffaffW ",
      " WaffaffaffaffW ",
      " WaffaffaffaffW ",
      " WaffaffaffaffW ",
      " WaaaaaaaaaaffW ",
      " WWWWWWWWWWWWWW ",
      "                ",
      "                "
    ]
  ]
}