{
  "name": "building_residential3_ground",
  "refpalette": "c70cities:building_residential3_ground_palette",
  "xsize": 16,
  "zsize": 16,
  "slices": [
    [
      "GGGGGGGGGGGGGGGG",
      "GGGGGGGGGGGGGGGG",
      "GGaaaaaaaaaaaaGG",
      "GGabbbbbbbbbbaGG",
      "GGabbbbbbbbbbaGG",
      "GGabbbbbbbbbbaGG",
      "GGabbbbbbbbbbaGG",
      "GGaabbbbbbbbbaGG",
      "GGGcddddbbbbbaGG",
      "GGGcddddbbbbbaGG",
      "GGGcddddbbbbbaGG",
      "GGGcddddbbbbbaGG",
      "GGGcccccabbbbaGG",
      "GGGGGGGGaaaaaaGG",
      "GGGGGGGGGGGGGGGG",
      "GGGGGGGGGGGGGGGG"
    ],
    [
      "effffgffffgffffe",
      "f              f",
      "f hhhhhhhhhhhh f",
      "e i   j  !k  h f",
      "  l       k mh f",
      "  n       opoh g",
      "e i qq       h f",
      "f hhrrs t   uh f",
      "f  c    t   uh f",
      "f wc    h    h f",
      "g wc    hx  yh e",
      "f wcABCDhx  Eh f",
      "f wccccch    h f",
      "f wwwwwwhiFFih f",
      "f              f",
      "effffgffffgffffe"
    ],
    [
      "effffgffffgffffe",
      "f              f",
      "f hhFFFhhFhIhh f",
      "e i    j  k  h f",
      "  J      Kk LI f",
      "  M       oNoh g",
      "e i          F f",
      "f hh    t   Oh f",
      "f  c    t   Ph f",
      "f  Q    h    F f",
      "g  Q    hR   F e",
      "f  cS  ThR   F f",
      "f  ccQQch    h f",
      "f       hiFFih f",
      "f              f",
      "effffgffffgffffe"
    ],
    [
      "                ",
      "                ",
      "  hhUUUhhUhUhh  ",
      "V i     j k  h  ",
      "  W       k  X  ",
      "  W       oooh  ",
      "  i          X  ",
      "  hh    t    h  ",
      "  Yc    t    h  ",
      "  Yc    h    X  ",
      "  Yc    h    X V",
      "  Yc    h    X  ",
      "  Yccccch    h  ",
      "  YYYYYYhiZZih  ",
      "                ",
      "                "
    ],
    [
      "                ",
      "                ",
      "  hhhhhhhhhhhh  ",
      "  hbbb   jbbbh  ",
      "  hbbbbbbbbbbh  ",
      "  hbbbbbbbbbbh  ",
      "  hbbbbbbbbbbh  ",
      "  hhbbbbbbbbbh  ",
      "  01    bbbbbh  ",
      "  01    bbbbbh  ",
      "  01    bbbbbh  ",
      "  01    bbbbbh  ",
      "  023333hbbbbh  ",
      "  000000hhhhhh  ",
      "                ",
      "                "
    ],
    [
      "                ",
      "                ",
      "  hhUUUhhUUUhh  ",
      "  F445       F  ",
      "  F   6666   F  ",
      "  F          F  ",
      "  F778     9 F  ",
      "  hh@@@@@ #$%h  ",
      "  0c   ^@ iiih  ",
      "  0c    @ &&8X  ",
      "  0c    @ &*(X  ",
      "  0c    @ &*(X  ",
      "  0ccccch && h  ",
      "  000000hFFFFh  ",
      "                ",
      "                "
    ]
  ]
}