{
  "name": "building_restaurant1_base1_180",
  "refpalette": "c70cities:building_restaurant1_base1_palette_180",
  "xsize": 16,
  "zsize": 16,
  "slices": [
    [
      "vvvvvvvvvvvvvvvv",
      "v=bbbbbbbbbbbb=v",
      "v=bc!cccccdddb=v",
      "v=bcccccccdddb=v",
      "v=bcccccccdddb=v",
      "v=bccccccccccb=v",
      "v=vvvvvvvvvvvv=v",
      "v=vvvvvvvvvvvv=v",
      "v=vvvvvvvvvvvv=v",
      "v=vvvvv!vvvvvv=v",
      "v=vvvvvvvvvvvv=v",
      "v=vvvvvvvvvvvv=v",
      "v=vvvvvvvvvvvv=v",
      "v=vvvvvvvvvvva=v",
      "v==============v",
      "vvvvvvvvvvvvvvvv"
    ],
    [
      "vvvvvvvvvvvvvvvv",
      "v=bbbbbbbbbbbb=v",
      "v=bxwu u dtttb=v",
      "v=bu s   dtttb=v",
      "v=b s  s dtttb=v",
      "v=bqqs q qdddb=v",
      "v=r q       kh=v",
      "v=p   ll     k=v",
      "v=   lllll    =v",
      "v=   ollln    =v",
      "v=    nll    j=v",
      "v=m     l  jjj=v",
      "v=ik        jj=v",
      "v=ihgf      ea=v",
      "v==============v",
      "vvvvvvvvvvvvvvvv"
    ],
    [
      "vvvvvvvvvvvvvvvv",
      "v=bbbbbbbbbbbb=v",
      "v=bu         b=v",
      "v=b          b=v",
      "v=b          b=v",
      "v=bqq     qqqb=v",
      "v=A          g=v",
      "v=            =v",
      "v=    lll     =v",
      "v=     ll     =v",
      "v=     l      =v",
      "v=           j=v",
      "v=y          j=v",
      "v=kg        ea=v",
      "v==============v",
      "vvvvvvvvvvvvvvvv"
    ],
    [
      "vvvvvvvvvvvvvvvv",
      "v=bbbbbbbbbbbb=v",
      "v=b         Bb=v",
      "v=b          b=v",
      "v=b          b=v",
      "v=bq       qqb=v",
      "v=            =v",
      "v=            =v",
      "v=     l      =v",
      "v=     n      =v",
      "v=            =v",
      "v=            =v",
      "v=           j=v",
      "v=          ea=v",
      "v==============v",
      "vvvvvvvvvvvvvvvv"
    ],
    [
      "vvvvvvvvvvvvvvvv",
      "v=bbbbbbbbbbbb=v",
      "v=b         Cb=v",
      "v=b          b=v",
      "v=b          b=v",
      "v=bqqq qqqqqqb=v",
      "v=      q     =v",
      "v=            =v",
      "v=            =v",
      "v=            =v",
      "v=            =v",
      "v=            =v",
      "v=            =v",
      "v=          ea=v",
      "v==============v",
      "vvvvvvvvvvvvvvvv"
    ],
    [
      "vvvvvvvvvvvvvvvv",
      "v=bbbbbbbbbbbb=v",
      "v=bdddddddddEb=v",
      "v=bddddddddddb=v",
      "v=bddddddddddb=v",
      "v=bddddddddddb=v",
      "v=DDDDDDDDDDDD=v",
      "v=DDDDDDDDDDDD=v",
      "v=DDDDDDDDDDDD=v",
      "v=DDDDDDDDDDDD=v",
      "v=DDDDDDDDDDDD=v",
      "v=DDDDDDDDDDDD=v",
      "v=DDDDDDDDDDDD=v",
      "v=DDDDDDDDDDea=v",
      "v==============v",
      "vvvvvvvvvvvvvvvv"
    ]
  ]
}