{
  "name": "building_residential1_ground_270",
  "refpalette": "c70cities:building_residential1_ground_palette_270",
  "xsize": 16,
  "zsize": 16,
  "slices": [
    [
      "GGGGGGGGGGGGGGGG",
      "GGGGGGGGGGGGGGGG",
      "GGGGGGGaaaaaaaGG",
      "GGGcccccbbbbbaGG",
      "GGGcddddbbbbbaGG",
      "GGGcddddbbbbbaGG",
      "GGGcddddbbbbbaGG",
      "GGGcddddbbbbbaGG",
      "GGGcddddbbbbbaGG",
      "GGGcddddbbbbbaGG",
      "GGGceeeebbbbbaGG",
      "GGGceeeebbbbbaGG",
      "GGGcccccbbbbbaGG",
      "GGGGGGGaaaaaaaGG",
      "GGGGGGGGGGGGGGGG",
      "GGGGGGGGGGGGGGGG"
    ],
    [
      "fgggghggggf  iff",
      "g              g",
      "g AAAAAjkkjnlj g",
      "g Acccccuso  j g",
      "g AcI Bx  o  k g",
      "h AcJ Bx  o  k h",
      "g AcK C      k g",
      "g AcL    tp mj g",
      "g AcJ   wtq mj g",
      "g Ac!    t   k g",
      "h AcFFDy t   k h",
      "g AcM Ey t   k g",
      "g Accccc  r  j g",
      "g AAAAAjkkjkkj g",
      "g              g",
      "fgggghggggfggggf"
    ],
    [
      "fgggghggggf   ff",
      "g              g",
      "g      jkkjPNj g",
      "g  ccUcc  o  j g",
      "g  cW  R  o  k g",
      "h  c      o  k h",
      "g  U  S      k g",
      "g  UX    t  Oj g",
      "g  U     t  Oj g",
      "g  U    wt   k g",
      "h  cFFTy t   k h",
      "g  c   y t   k g",
      "g  ccVcc  Q  j g",
      "g      jkkjkkj g",
      "g              g",
      "fgggghggggfggggf"
    ],
    [
      "                ",
      "                ",
      "  2    jZZjZZj  ",
      "  2ccUcc  o  j  ",
      "  2c      o  Y  ",
      "  2c      o  Y  ",
      "  2c         Y  ",
      "  2c     t   j  ",
      "  2c     t   j  ",
      "  2c     t   Y  ",
      "  2cFFFywt   Y  ",
      "  2c   y t   Y  ",
      "  2ccVcc     j  ",
      "  2    j00j00j  ",
      "                ",
      "          1     "
    ],
    [
      "                ",
      "                ",
      "  652  jjjjjjj  ",
      "  65cccc bbbbj  ",
      "  652    bbbbj  ",
      "  652    bbbbj  ",
      "  652    bbbbj  ",
      "  652    bbbbj  ",
      "  652    bbbbj  ",
      "  652    bbbbj  ",
      "  65333y bbbbj  ",
      "  65444ywbbbbj  ",
      "  65ccccbbbbbj  ",
      "  652  jjjjjjj  ",
      "                ",
      "                "
    ],
    [
      "                ",
      "              7 ",
      "    652jkkkkkj7 ",
      "    65cc- ZZ8j7 ",
      "    652 -9%%9j7 ",
      "    652 -9^^9j7 ",
      "    652 -9999j7 ",
      "    652 -    j7 ",
      "    652 - )&@j7 ",
      "    652 - +*#j7 ",
      "    65Fy-  ( j7 ",
      "    65[y-    j7 ",
      "    65cc    $j7 ",
      "    652jkkkkkj7 ",
      "              7 ",
      "                "
    ]
  ]
}