{
  "name": "building_apartment1_floor1_90",
  "refpalette": "c70cities:building_apartment1_floor1_palette_90",
  "xsize": 16,
  "zsize": 16,
  "slices": [
    [
      "                ",
      " aaaaaaaaa      ",
      " abbbbbbbbdeei  ",
      " abbbbbbbbbbfh  ",
      " abbbbbbbbbb g  ",
      " abbbbbbbbc  d  ",
      " abbbbbbbbbbbba ",
      " abbbbbbbbbbbba ",
      " abbbbbbbbbbbba ",
      " abbbbbbbbbbbba ",
      " abbbbbbbbbbbba ",
      " abbbbbbbbbbbba ",
      " abbbbbbbbbbbba ",
      " abbbbbbbbbbbba ",
      " aaaaaaaaaaaaaa ",
      "                "
    ],
    [
      "                ",
      " lssssssss      ",
      " kr BDpJ pdddd  ",
      " k   CpJ N TWd  ",
      " kotA ppKp   Y  ",
      " kppx p  p   Y  ",
      " k wx p  ppppp0 ",
      " k  y p  M SV!0 ",
      " kq x y  M    0 ",
      " kpuppp  L RR 0 ",
      " k    E       0 ",
      " kot DpIKI    0 ",
      " kot Cpq pP   0 ",
      " kn   pF pOQUX0 ",
      " jmmmmmmmmmmmmZ ",
      "                "
    ],
    [
      "                ",
      " p111ppppp      ",
      " p   7p  phYdd  ",
      " p    p  $  Td  ",
      " pot6 pp#p  *d  ",
      " pppx p  p   d  ",
      " p3 x p  pppppp ",
      " p  5 p    ^^ @ ",
      " p  x 5       1 ",
      " pp4ppp       1 ",
      " p    9       1 ",
      " p    pI#I    1 ",
      " p    p  p%   1 ",
      " p2   p  p  &(@ ",
      " p111p8@@8@@@@8 ",
      "                "
    ],
    [
      "                ",
      " p111pp11p      ",
      " p-]} p  pddd,  ",
      " 1    p  p   '  ",
      " 1    pppp  |d  ",
      " pppx p  p  Wd  ",
      " p+ x p  pppppp ",
      " 1  x p    \\\\ @ ",
      " 1  x p      ;1 ",
      " pppppp      ;1 ",
      " p    p      :1 ",
      " 1    pIII   `1 ",
      " 1    p  p   `1 ",
      " p)[{ p  p    @ ",
      " p111p8118@1118 ",
      "                "
    ],
    [
      "                ",
      " p@@@pp@@p      ",
      " p    p  p'''d  ",
      " k    p fp   Y  ",
      " k    pppp   Y  ",
      " pppx p  p .|e  ",
      " p  x p  pppppp ",
      " k  x p       @ ",
      " k  x p       @ ",
      " pppppp       @ ",
      " p    p       @ ",
      " k    pIII    @ ",
      " k    p  p    @ ",
      " p    p  p    @ ",
      " p@@@p8@@8@@@@8 ",
      "                "
    ],
    [
      "                ",
      " ppppppppp      ",
      " pddddpddpdddd  ",
      " pddddpddp   d  ",
      " pddddpppp   d  ",
      " pddddpddpWc d  ",
      " p//ddpddpppppp ",
      " p//ddpdddddddp ",
      " p//ddpdddddddp ",
      " ppppppdddddddp ",
      " pddddpdddddddp ",
      " pddddpdddddddp ",
      " pddddp//dddddp ",
      " pddddp//dddddp ",
      " pppppppppppppp ",
      "                "
    ]
  ]
}