{
  "name": "building_residential1_ground_270",
  "refpalette": "c70cities:building_residential1_ground_palette_270",
  "xsize": 16,
  "zsize": 16,
  "slices": [
    [
      "GGGGGGGGGGGGGGGG",
      "GGGGGGGGGGGGGGGG",
      "GGGGGGGaaaaaaaGG",
      "GGGcccccbbbbbaGG",
      "GGGcddddbbbbbaGG",
      "GGGcddddbbbbbaGG",
      "GGGcddddbbbbbaGG",
      "GGGcddddbbbbbaGG",
      "GGGcddddbbbbbaGG",
      "GGGcddddbbbbbaGG",
      "GGGceeeebbbbbaGG",
      "GGGceeeebbbbbaGG",
      "GGGcccccbbbbbaGG",
      "GGGGGGGaaaaaaaGG",
      "GGGGGGGGGGGGGGGG",
      "GGGGGGGGGGGGGGGG"
    ],
    [
      "fgggghggggf  fgf",
      "g              g",
      "g yyyyyijjimki g",
      "g yccccctrn  i g",
      "g ycE Aw  n  j g",
      "h ycF Aw  n  j h",
      "g ycI B      j g",
      "g ycJ    so li g",
      "g ycF   usp li g",
      "g yc!    s   j g",
      "h ycDDCx s   j h",
      "g ycK  x s   j g",
      "g yccccc  q  i g",
      "g yyyyyijjijji g",
      "g              g",
      "fgggghggggfggggf"
    ],
    [
      "fgggghggggf  fgf",
      "g              g",
      "g      ijjiNLi g",
      "g  ccScc  n  i g",
      "g  cU  P  n  j g",
      "h  c      n  j h",
      "g  S  Q      j g",
      "g  SV    s  Mi g",
      "g  S     s  Mi g",
      "g  S    us   j g",
      "h  cDDRx s   j h",
      "g  cW  x s   j g",
      "g  ccTcc  O  i g",
      "g      ijjijji g",
      "g              g",
      "fgggghggggfggggf"
    ],
    [
      "                ",
      "                ",
      "  1    iYYiYYi  ",
      "  1ccScc  n  i  ",
      "  1c      n  X  ",
      "  1c      n  X  ",
      "  1c         X  ",
      "  1c     s   i  ",
      "  1c     s   i  ",
      "  1c     s   X  ",
      "  1cDDDxus   X  ",
      "  1c   x s   X  ",
      "  1ccTcc     i  ",
      "  1    iZZiZZi  ",
      "                ",
      "          0     "
    ],
    [
      "                ",
      "                ",
      "  541  iiiiiii  ",
      "  54cccc bbbbi  ",
      "  541    bbbbi  ",
      "  541    bbbbi  ",
      "  541    bbbbi  ",
      "  541    bbbbi  ",
      "  541    bbbbi  ",
      "  541    bbbbi  ",
      "  54222x bbbbi  ",
      "  54333xubbbbi  ",
      "  54ccccbbbbbi  ",
      "  541  iiiiiii  ",
      "                ",
      "                "
    ],
    [
      "                ",
      "              6 ",
      "    541ijjjjji6 ",
      "    54cc+ YY7i6 ",
      "    541 +8$$8i6 ",
      "    541 +8%%8i6 ",
      "    541 +8888i6 ",
      "    541 +    i6 ",
      "    541 + (^9i6 ",
      "    541 + )&@i6 ",
      "    54Dx+  * i6 ",
      "    54-x+    i6 ",
      "    54cc    #i6 ",
      "    541ijjjjji6 ",
      "              6 ",
      "                "
    ]
  ]
}