{
  "name": "building_office4_top",
  "refpalette": "c70cities:building_office4_top_palette",
  "xsize": 16,
  "zsize": 16,
  "slices": [
    [
      "                ",
      "    abaaaaba    ",
      "  cccdeeeedccc  ",
      "  cfeeeeeeeefc  ",
      " aceeeeeeeeeeca ",
      " bdeeeeeeGGeedb ",
      " aeeeGGGeGGeeea ",
      " ageeeGGGeeeeea ",
      " ageeeGGGeeeeea ",
      " aeeeGGGeGGeeea ",
      " bdeeeeeeGGeedb ",
      " aceeeeeeeeeeca ",
      "  cfeeeeeeeehc  ",
      "  cccdeeeedccc  ",
      "    abaaaaba    ",
      "                "
    ],
    [
      "                ",
      "    abaaaaba    ",
      "  iiijiiiijiii  ",
      "  ikkk lm kkki  ",
      " aik        kia ",
      " bjk        kjb ",
      " ai          ia ",
      " a          nia ",
      " a          oia ",
      " ai          ia ",
      " bjk        kjb ",
      " aik        kia ",
      "  ikkk pq kkki  ",
      "  iiijiiiijiii  ",
      "    abaaaaba    ",
      "                "
    ],
    [
      "                ",
      "    ab    ba    ",
      "  iiijiiiijiii  ",
      "  i          i  ",
      " ai          ia ",
      " bj          jb ",
      "  i          i  ",
      "             i  ",
      "             i  ",
      "  i          i  ",
      " bj          jb ",
      " ai          ia ",
      "  i          i  ",
      "  iiijiiiijiii  ",
      "    ab    ba    ",
      "                "
    ],
    [
      "                ",
      "    a      a    ",
      "   iijiiiijii   ",
      "  i          i  ",
      " ai          ia ",
      "  j          j  ",
      "  i          i  ",
      "  i          i  ",
      "  i          i  ",
      "  i          i  ",
      "  j          j  ",
      " ai          ia ",
      "  i          i  ",
      "   iijiiiijii   ",
      "    a      a    ",
      "                "
    ],
    [
      "                ",
      "                ",
      "   iijiiiijii   ",
      "  i          i  ",
      "  i          i  ",
      "  j          j  ",
      "  i          i  ",
      "  i          i  ",
      "  i          i  ",
      "  i          i  ",
      "  j          j  ",
      "  i          i  ",
      "  i          i  ",
      "   iijiiiijii   ",
      "                ",
      "                "
    ],
    [
      "                ",
      "                ",
      "                ",
      "   iijiiiijii   ",
      "   iijiiiijii   ",
      "   jjrjjjjrjj   ",
      "   iijjjjjjii   ",
      "   iijjjjjjii   ",
      "   iijjjjjjii   ",
      "   iijjjjjjii   ",
      "   jjrjjjjsjj   ",
      "   iijiiiijii   ",
      "   iijiiiijii   ",
      "                ",
      "                ",
      "                "
    ]
  ]
}