{
  "name": "building_office3_floor1",
  "refpalette": "c70cities:building_office3_floor1_palette",
  "xsize": 16,
  "zsize": 16,
  "slices": [
    [
      "                ",
      " aabaabaabaabaa ",
      " acccccccccccca ",
      " bccccccccccccb ",
      " acccccccccccca ",
      " acccccccccccca ",
      " bccccccccccccb ",
      " acccccvdccccca ",
      " acccccvdccccca ",
      " bccccccccccccb ",
      " acccccccccccca ",
      " accccccccc!cca ",
      " bccccccccccccb ",
      " acccccccccccca ",
      " aabaabaabaabaa ",
      "                "
    ],
    [
      "                ",
      " eebeebeebeebee ",
      " e            e ",
      " b f  g g   f b ",
      " e   hi  ij   e ",
      " e     k k    e ",
      " bl           b ",
      " eh e mvd     e ",
      " eh e nvd     e ",
      " bo           b ",
      " e      g g   e ",
      " e     ppppp  e ",
      " b f   p k  f b ",
      " e            e ",
      " eebeebeebeebee ",
      "                "
    ],
    [
      "                ",
      " qqbqqbqqbqqbqq ",
      " q            q ",
      " b f        f b ",
      " q    rrrr    q ",
      " q            q ",
      " b            b ",
      " q    svd     q ",
      " q    svd     q ",
      " b            b ",
      " q            q ",
      " q            q ",
      " b f        f b ",
      " q            q ",
      " qqbqqbqqbqqbqq ",
      "                "
    ],
    [
      "                ",
      " qqbqqbqqbqqbqq ",
      " q            q ",
      " b f        f b ",
      " q            q ",
      " q            q ",
      " b            b ",
      " q    svd     q ",
      " q    svd     q ",
      " b            b ",
      " q            q ",
      " q            q ",
      " b f        f b ",
      " q            q ",
      " qqbqqbqqbqqbqq ",
      "                "
    ],
    [
      "                ",
      " qqbqqbqqbqqbqq ",
      " q            q ",
      " b f        f b ",
      " q            q ",
      " q            q ",
      " b            b ",
      " q     vd     q ",
      " q     vd     q ",
      " b            b ",
      " q            q ",
      " q            q ",
      " b f        f b ",
      " q            q ",
      " qqbqqbqqbqqbqq ",
      "                "
    ],
    [
      "                ",
      " qqbqqbqqbqqbqq ",
      " qttttttttttttq ",
      " btfuuuuuuuuftb ",
      " qtuuuuuuuuuutq ",
      " qtuuuuuuuuuutq ",
      " btuuuuuuuuuutb ",
      " qtuuuuvduuuutq ",
      " qtuuuuvduuuutq ",
      " btuuuuuuuuuutb ",
      " qtuuuuuuuuuutq ",
      " qtuuuuuuuuuutq ",
      " btfuuuuuuuuftb ",
      " qttttttttttttq ",
      " qqbqqbqqbqqbqq ",
      "                "
    ]
  ]
}