{
  "name": "building_bank1_floor1_90",
  "refpalette": "c70cities:building_bank1_floor1_palette_90",
  "xsize": 16,
  "zsize": 16,
  "slices": [
    [
      "                ",
      "   gbbi  gbbi   ",
      "  deeeedeeeeed  ",
      " ceeeeeeeeeeeek ",
      " beeeeeeeeeeeeb ",
      " beeeeeeeeeeeeb ",
      " aeeeeeeeeeeeej ",
      "  eeeeeeeeeeed  ",
      "  deeeeeeeeeee  ",
      " ceeeeeeeeeeeek ",
      " beeeeeeeeeeeeb ",
      " beeeeeeeeeeeeb ",
      " aeee     eeeej ",
      "  deeeeedeeeed  ",
      "   fbbh  fbbh   ",
      "                "
    ],
    [
      "                ",
      "  gbbi  gbbi    ",
      "  llllmlllllmlk ",
      "  mo     CC  lb ",
      " cl          lb ",
      " bl      BB  lj ",
      " bl   tw     m  ",
      " al   tuyyyDDl  ",
      "  lnpbbbbbbbblk ",
      "  m     xAxx lb ",
      " cl          lb ",
      " bl  sssss   lj ",
      " bl  r       m  ",
      " almlqlllmllll  ",
      "    fbbh  fbbh  ",
      "                "
    ],
    [
      "                ",
      " Ebbi  gbbi  gE ",
      " alllmlllllmllb ",
      "  lo         lb ",
      "  m          lj ",
      " cl          m  ",
      " bl   J      l  ",
      " bl   t     Llk ",
      " alFIbbbbbbbblb ",
      "  l      K   lb ",
      "  m          lj ",
      " cl  s s s   m  ",
      " bl   r      l  ",
      " bllmlqlllmlllk ",
      " Eh  fbbh  fbbE ",
      "                "
    ],
    [
      "                ",
      " Ebi  gbbi  gbE ",
      " bllmlllllmlllb ",
      " alo         lj ",
      "  l          m  ",
      "  m          l  ",
      " cl   t      lk ",
      " bl   t      lb ",
      " blbbbbbbbbbblb ",
      " al      K   lj ",
      "  l          m  ",
      "  m  s s s   l  ",
      " cl    r     lk ",
      " blllm qlllmllb ",
      " Ebh  fbbh  fbE ",
      "                "
    ],
    [
      "                ",
      " Ei  gbbi  gbbE ",
      " blmlllllmllllj ",
      " bl          m  ",
      " al          l  ",
      "  l          lk ",
      "  m          lb ",
      " cl          lb ",
      " blbbbbbbbbbblj ",
      " bl          m  ",
      " al          l  ",
      "  l  s s s   lk ",
      "  m     r    lb ",
      " cllllm qlllmlb ",
      " Ebbh  fbbh  fE ",
      "                "
    ],
    [
      "                ",
      "    gbbi  gbbi  ",
      " cmlllllmllllm  ",
      " blMMMMMMMMMMl  ",
      " blMMMMNNNNMMlk ",
      " alMMMMN!!NMMlb ",
      "  lMMMMNNNNMMlb ",
      "  mMMMMMMMMMMlj ",
      " clbbbbbbbbbbm  ",
      " blMMMMMMMMMMl  ",
      " blMMMMMMMMMMlk ",
      " alMMs s sMMMlb ",
      "  lMM    rMMMlb ",
      "  mllllm qlllmj ",
      "  fbbh  fbbh    ",
      "                "
    ]
  ]
}