{
  "name": "building_office4_floor1_270",
  "refpalette": "c70cities:building_office4_floor1_palette_270",
  "xsize": 16,
  "zsize": 16,
  "slices": [
    [
      "                ",
      "    abaaaaba    ",
      "  cccdeffedccc  ",
      "  ceeeeeeeeeec  ",
      " aceeeeeeeeeeca ",
      " bdeeeeeeeeeedb ",
      " aeeeeeeeeeeeea ",
      " aeeeeeeeeeeeea ",
      " aeeee!eeeeeeea ",
      " aeeeeeeeeeeeea ",
      " bdeeeeeeeeeedb ",
      " aceeeeeeeeeeca ",
      "  ceeeeeeeeeec  ",
      "  cccdeeeedccc  ",
      "    abaaaaba    ",
      "                "
    ],
    [
      "                ",
      "    abaaaaba    ",
      "  gggd ff dggg  ",
      "  g          g  ",
      " ag          ga ",
      " bd          db ",
      " awu  rppk  jha ",
      " aw   s      ia ",
      " aw      l   ha ",
      " awu  tqqm  jha ",
      " bd          db ",
      " ag          ga ",
      "  g   n  n   g  ",
      "  gggdoooodggg  ",
      "    abaaaaba    ",
      "                "
    ],
    [
      "                ",
      "    abaaaaba    ",
      "  gggd ff dggg  ",
      "  g          g  ",
      " ag          ga ",
      " bd          db ",
      " a            a ",
      " a            a ",
      " ax           a ",
      " a            a ",
      " bd          db ",
      " ag          ga ",
      "  g          g  ",
      "  gggd    dggg  ",
      "    abaaaaba    ",
      "                "
    ],
    [
      "                ",
      "    abaaaaba    ",
      "  gggd ff dggg  ",
      "  g          g  ",
      " ag          ga ",
      " bd          db ",
      " a            a ",
      " a            a ",
      " a            a ",
      " a            a ",
      " bd          db ",
      " ag          ga ",
      "  g          g  ",
      "  gggd    dggg  ",
      "    abaaaaba    ",
      "                "
    ],
    [
      "                ",
      "    abaaaaba    ",
      "  gggd ff dggg  ",
      "  g          g  ",
      " ag          ga ",
      " bd          db ",
      " a            a ",
      " a            a ",
      " a            a ",
      " a            a ",
      " bd          db ",
      " ag          ga ",
      "  g          g  ",
      "  gggd    dggg  ",
      "    abaaaaba    ",
      "                "
    ],
    [
      "                ",
      "    abaaaaba    ",
      "  gggdyffydggg  ",
      "  gyyyyyyyyyyg  ",
      " agyyyyyyyyyyga ",
      " bdyyyyyyyyyydb ",
      " ayyyyyyyyyyyya ",
      " ayyyyyyyyyyyya ",
      " ayyyyyyyyyyyya ",
      " ayyyyyyyyyyyya ",
      " bdyyyyyyyyyydb ",
      " agyyyyyyyyyyga ",
      "  gyyyyyyyyyyg  ",
      "  gggdyyyydggg  ",
      "    abaaaaba    ",
      "                "
    ]
  ]
}