{
  "name": "building_restaurant1_base1_90",
  "refpalette": "c70cities:building_restaurant1_base1_palette_90",
  "xsize": 16,
  "zsize": 16,
  "slices": [
    [
      "vvvvvvvvvvvvvvvv",
      "v==============v",
      "v=vvvvvvvvbbbbbv",
      "v=vvvvvvvvccccbv",
      "v=vvvvvvvvccc!bv",
      "v=vvvvvvvvccccbv",
      "v=vvvvvvvvccccbv",
      "v=vvvv!vvvccccbv",
      "v=vvvvvvvvccccbv",
      "v=vvvvvvvvccccbv",
      "v=vvvvvvvvcdddbv",
      "v=vvvvvvvvcdddbv",
      "v=vvvvvvvvcdddbv",
      "v=avvvvvvvbbbbbv",
      "v==============v",
      "vvvvvvvvvvvvvvvv"
    ],
    [
      "vvvvvvvvvvvvvvvv",
      "v==============v",
      "v=iim   fqbbbbbv",
      "v=hk      p twbv",
      "v=g      ppr ubv",
      "v=f   ol  r rtbv",
      "v=   nlll     bv",
      "v=   llll pr tbv",
      "v=  llll      bv",
      "v=    nl  pdddbv",
      "v=        dsssbv",
      "v=  j     dsssbv",
      "v=ejj    kdsssbv",
      "v=ajjj  khbbbbbv",
      "v==============v",
      "vvvvvvvvvvvvvvvv"
    ],
    [
      "vvvvvvvvvvvvvvvv",
      "v==============v",
      "v=kx    f bbbbbv",
      "v=g       p  tbv",
      "v=        p   bv",
      "v=            bv",
      "v=     l      bv",
      "v=   lll      bv",
      "v=    ll      bv",
      "v=            bv",
      "v=        p   bv",
      "v=        p   bv",
      "v=e       p   bv",
      "v=ajj    gbbbbbv",
      "v==============v",
      "vvvvvvvvvvvvvvvv"
    ],
    [
      "vvvvvvvvvvvvvvvv",
      "v==============v",
      "v=        bbbbbv",
      "v=        p   bv",
      "v=            bv",
      "v=            bv",
      "v=            bv",
      "v=    nl      bv",
      "v=            bv",
      "v=            bv",
      "v=            bv",
      "v=        p   bv",
      "v=e       p  ybv",
      "v=aj      bbbbbv",
      "v==============v",
      "vvvvvvvvvvvvvvvv"
    ],
    [
      "vvvvvvvvvvvvvvvv",
      "v==============v",
      "v=        bbbbbv",
      "v=        p   bv",
      "v=        p   bv",
      "v=        p   bv",
      "v=            bv",
      "v=        p   bv",
      "v=       pp   bv",
      "v=        p   bv",
      "v=        p   bv",
      "v=        p   bv",
      "v=e       p  Abv",
      "v=a       bbbbbv",
      "v==============v",
      "vvvvvvvvvvvvvvvv"
    ],
    [
      "vvvvvvvvvvvvvvvv",
      "v==============v",
      "v=BBBBBBBBbbbbbv",
      "v=BBBBBBBBddddbv",
      "v=BBBBBBBBddddbv",
      "v=BBBBBBBBddddbv",
      "v=BBBBBBBBddddbv",
      "v=BBBBBBBBddddbv",
      "v=BBBBBBBBddddbv",
      "v=BBBBBBBBddddbv",
      "v=BBBBBBBBddddbv",
      "v=BBBBBBBBddddbv",
      "v=eBBBBBBBdddCbv",
      "v=aBBBBBBBbbbbbv",
      "v==============v",
      "vvvvvvvvvvvvvvvv"
    ]
  ]
}