{
  "name": "building_factory2_floor1",
  "refpalette": "c70cities:building_factory2_floor1_palette",
  "xsize": 16,
  "zsize": 16,
  "slices": [
    [
      "                ",
      "   abbbbbbbbbba ",
      "   cdddddddddde ",
      "   cdf       de ",
      "   cd        de ",
      "   cdghhgghhgdi ",
      "   cdf       di ",
      "   cd        de ",
      "   cdf       de ",
      "   cd        di ",
      "   cdghhgghhgdi ",
      "   cd        de ",
      "   cdff     fde ",
      "   cdddddddddde ",
      "   ajjjjjjjjjja ",
      "                "
    ],
    [
      "                ",
      "  kkll        a ",
      "  kkmmmmmmmmmm  ",
      "  kkdnnn    fm  ",
      "  kkdnnn     m  ",
      "  kkdop pp pfmi ",
      "  kkdo       mi ",
      "  kkdnnn     m  ",
      "  kkdnnn     m  ",
      "  kkdo       mi ",
      "  kkdop pp p mi ",
      "  kkdnnn    fm  ",
      "  kkdnnn   ffm  ",
      "  kkqqmmmmmmmm  ",
      "  kkll        a ",
      "                "
    ],
    [
      "                ",
      "      kkll    a ",
      "      kkqqmmmm  ",
      "        nnn  m  ",
      "        nnnrrm  ",
      "      ssdddoomi ",
      "      ssdddrrmi ",
      "        nnn fm  ",
      "        nnn  m  ",
      "      ssdddrrmi ",
      "      ssdddoomi ",
      "        nnnrrm  ",
      "        nnn  m  ",
      "      kkqqmmmm  ",
      "      kkll    a ",
      "                "
    ],
    [
      "                ",
      "          kklla ",
      "          kkqqe ",
      "           sdde ",
      "           sdde ",
      "           iiii ",
      "           iiii ",
      "           sdde ",
      "           sdde ",
      "           iiii ",
      "           iiii ",
      "           sdde ",
      "           sdde ",
      "          kkqqe ",
      "          kklla ",
      "                "
    ],
    [
      "                ",
      "              kk",
      "              kk",
      "              kk",
      "              kk",
      "            tukk",
      "            wikk",
      "              kk",
      "           ~  kk",
      "            tukk",
      "            wikk",
      "              kk",
      "              kk",
      "              kk",
      "              kk",
      "                "
    ],
    [
      "                ",
      "                ",
      "                ",
      "                ",
      "                ",
      "                ",
      "                ",
      "                ",
      "           ~    ",
      "                ",
      "                ",
      "                ",
      "                ",
      "                ",
      "                ",
      "                "
    ]
  ]
}