{
  "name": "building_carservice1_floor2",
  "refpalette": "c70cities:building_carservice1_floor2_palette",
  "xsize": 16,
  "zsize": 16,
  "slices": [
    [
      "                ",
      " a   a   a   a  ",
      "  bb            ",
      "  bb            ",
      "  bbbbH         ",
      "  bbbbH         ",
      " acccadddadddae ",
      " ecccccccccccce ",
      " effffffffffffe ",
      " effffffffffffe ",
      " efggg ! ffffce ",
      " efghg   fffcde ",
      " efghg   ffcdd  ",
      " efggg   fidd   ",
      " aeeeaeeeaee    ",
      "                "
    ],
    [
      "                ",
      " ajjjajjja   a  ",
      " j       j      ",
      " j       j      ",
      " j     bHj      ",
      " k     bHk      ",
      " a   aeeeaeeeae ",
      " e    lmmnoopqe ",
      " r           se ",
      " r           te ",
      " ruwxwy y     e ",
      " r  A        re ",
      " r  A       rr  ",
      " e wxwy y irr   ",
      " aeeeaeeeaee    ",
      "                "
    ],
    [
      "                ",
      " a   a   a   a  ",
      "         a      ",
      "         B      ",
      "         bH     ",
      "         bH     ",
      " a   aeeeaeeeae ",
      " e          C r ",
      " r            r ",
      " r            r ",
      " r  D EEE     e ",
      " r D DEbE    re ",
      " r D DEbE   rr  ",
      " eF I EEEFirr   ",
      " aeeeaeeeaee    ",
      "                "
    ],
    [
      "                ",
      " a   a   a   a  ",
      "        Hbbbb   ",
      "        Hbbbb   ",
      "           bb   ",
      "           bb   ",
      " aJJJaeeeaeeeae ",
      " e        KL  e ",
      " r        MM  e ",
      " r            e ",
      " r            e ",
      " r           re ",
      " r          rr  ",
      " e        irr   ",
      " aeeeaeeeaee    ",
      "                "
    ],
    [
      "                ",
      " a   ajjjajjja  ",
      "     kHb     k  ",
      "     jHb     j  ",
      "     j       j  ",
      "     j       j  ",
      " aeeeaeeeaeeeae ",
      " e            e ",
      " N            e ",
      " N            e ",
      " N            e ",
      " N           re ",
      " N          rr  ",
      " e        irr   ",
      " aeeeaeeeaee    ",
      "                "
    ],
    [
      "                ",
      " a   a   a   a  ",
      "    Hb          ",
      "    Hb          ",
      "     B          ",
      "     a          ",
      " aeeeaeeeaeeeae ",
      " e            e ",
      " e            e ",
      " ejjjjjjjjjjj e ",
      " ejjjjjjjjjj  e ",
      " ejjjjjjjjj  re ",
      " ejjjjjjjj  rr  ",
      " ejjjjjjj irr   ",
      " aeeeaeeeaee    ",
      "                "
    ]
  ]
}