{
  "name": "building_hotel1_ground",
  "refpalette": "c70cities:building_hotel1_ground_palette",
  "xsize": 16,
  "zsize": 16,
  "slices": [
    [
      "GGGGaGGGGGGaGGGG",
      "GbbbbbbbbbbbbbbG",
      "GbccccccccccccbG",
      "GbccccccccccccbG",
      "GbccccccccccccbG",
      "GbccccccccccccbG",
      "Gbcccc!GGGccccbG",
      "GbccccdGGGccccbG",
      "GbccccdGGGccccbG",
      "GbccccddddccccdG",
      "GbccccccccccccdG",
      "GbccccccccccccdG",
      "GbccccccccccccdG",
      "Gb!cccccccccccbG",
      "GbbbbbbbbbbbbbbG",
      "GGGGGGGGGGGGGGGG"
    ],
    [
      " eeeeeeeeeeeeee ",
      " bbbbbbbbbbbbbb ",
      " bffff gg h ggb ",
      " bf    gi h igb ",
      " bj    gg   ggb ",
      " bj           b ",
      " bk   leee    b ",
      " bk   l  e    b ",
      " bk   l  e   mb ",
      " bk   lggn   op ",
      " b           q  ",
      " bbrb  s s   t  ",
      " b  b uuuuw  op ",
      " bxyb   A B  mb ",
      " bbbbbbbbbbbbbb ",
      "                "
    ],
    [
      "                ",
      " bbbbbbbbbbbbbb ",
      " bfff         b ",
      " bf           b ",
      " b            b ",
      " b            b ",
      " p    l       b ",
      " p    l       b ",
      " p    g      Cb ",
      " p    gn     op ",
      " b           D  ",
      " bbEb        F  ",
      " b  b  I     op ",
      " b  b        Cb ",
      " bbppppppbbbbbb ",
      "                "
    ],
    [
      "                ",
      " bbbbbbbbbbbbbb ",
      " bfJ          b ",
      " b            b ",
      " b            b ",
      " b            b ",
      " b    g       b ",
      " b    g       b ",
      " b    n      Cb ",
      " b           op ",
      " b           op ",
      " bbbb        op ",
      " b  b        op ",
      " bJ b        Cb ",
      " bbbbbbbbbbbbbb ",
      "                "
    ],
    [
      "                ",
      " bbbbbbbbbbbbbb ",
      " bJJ          b ",
      " p            b ",
      " p            b ",
      " b            b ",
      " b    ngg     b ",
      " b            b ",
      " b            b ",
      " b           op ",
      " bJ          op ",
      " bbbb        op ",
      " bJ b        op ",
      " bJ b         b ",
      " bbbbbbppbbbbbb ",
      "                "
    ],
    [
      "                ",
      " bbbbbbbbbbbbbb ",
      " bKKKKKKKKKKKKb ",
      " bKKKKKKKKKKKKb ",
      " bKKKKKKKKKKKKb ",
      " bKKKKKKKKKKKKb ",
      " bKKKK  ngKKKKb ",
      " bKKKK    KKKKb ",
      " bKKKK    KKKKb ",
      " bKKKK    KKKKp ",
      " bKKKKKKKKKKKKp ",
      " bbbbKKKKKKKKKp ",
      " bKKbKKKKKKKKKp ",
      " bKKbKKKKKKKKKb ",
      " bbbbbbbbbbbbbb ",
      "                "
    ]
  ]
}