{
  "name": "building_office3_floor2_180",
  "refpalette": "c70cities:building_office3_floor2_palette_180",
  "xsize": 16,
  "zsize": 16,
  "slices": [
    [
      "                ",
      " aabaabaabaabaa ",
      " acccccccccccca ",
      " bccccccccccccb ",
      " acccccccccccca ",
      " acccccccccccca ",
      " bccccccccccccb ",
      " acccccdvccccca ",
      " acccccdvccccca ",
      " bccccccccccccb ",
      " acccccccc!ccca ",
      " acccccccccccca ",
      " bccccccccccccb ",
      " acccccccccccca ",
      " aabaabaabaabaa ",
      "                "
    ],
    [
      "                ",
      " eebeebeebeebee ",
      " ef          fe ",
      " b g        g b ",
      " e   j    j   e ",
      " e iii    iii e ",
      " b h        h b ",
      " e     dvk    e ",
      " e     dvk    e ",
      " b j        j b ",
      " e iii    iii e ",
      " e   h    h   e ",
      " b g        g b ",
      " ef          fe ",
      " eebeebeebeebee ",
      "                "
    ],
    [
      "                ",
      " llbllbllbllbll ",
      " lf          fl ",
      " b g        g b ",
      " l            l ",
      " l            l ",
      " b            b ",
      " l     dv     l ",
      " l     dv     l ",
      " b            b ",
      " l            l ",
      " l            l ",
      " b g        g b ",
      " lf          fl ",
      " llbllbllbllbll ",
      "                "
    ],
    [
      "                ",
      " llbllbllbllbll ",
      " l            l ",
      " b g        g b ",
      " l            l ",
      " l            l ",
      " b            b ",
      " l     dv     l ",
      " l     dv     l ",
      " b            b ",
      " l            l ",
      " l            l ",
      " b g        g b ",
      " l            l ",
      " llbllbllbllbll ",
      "                "
    ],
    [
      "                ",
      " llbllbllbllbll ",
      " l            l ",
      " b g        g b ",
      " l            l ",
      " l            l ",
      " b            b ",
      " l     dv     l ",
      " l     dv     l ",
      " b            b ",
      " l            l ",
      " l            l ",
      " b g        g b ",
      " l            l ",
      " llbllbllbllbll ",
      "                "
    ],
    [
      "                ",
      " llbllbllbllbll ",
      " lmmmmmmmmmmmml ",
      " bmgnnnnnnnngmb ",
      " lmnnnnnnnnnnml ",
      " lmnnnnnnnnnnml ",
      " bmnnnnnnnnnnmb ",
      " lmnnnndvnnnnml ",
      " lmnnnndvnnnnml ",
      " bmnnnnnnnnnnmb ",
      " lmnnnnnnnnnnml ",
      " lmnnnnnnnnnnml ",
      " bmgnnnnnnnngmb ",
      " lmmmmmmmmmmmml ",
      " llbllbllbllbll ",
      "                "
    ]
  ]
}