{
  "name": "building_apartment1_ground_270",
  "refpalette": "c70cities:building_apartment1_ground_palette_270",
  "xsize": 16,
  "zsize": 16,
  "slices": [
    [
      "GGGGGGGGGGGGGGGG",
      "GaaaaaaaaaaaaaaG",
      "GaaaaaaaaaaaaaaG",
      "GaaaaaaaaaaaaaaG",
      "GaaaaaaaaaaaaaaG",
      "GaaaaaaaaaaaaaaG",
      "GaaaaaaaaaaaaaaG",
      "GaaaaaaaaaaaaaaG",
      "GaaaaaaaaaaaaaaG",
      "GaaaaaaaaaaaaaaG",
      "GaaaaaaaaaaaaaaG",
      "GaaaaaaaaaaaaaaG",
      "GaaaaaaaaaaaaaaG",
      "GaaaaaaaaaaaaaaG",
      "GaaaaaaaaaaaaaaG",
      "GGGGGGGGGGGGGGGG"
    ],
    [
      "                ",
      " dddddqxtqbdddb ",
      " d   pruurp   b ",
      " d ID        ec ",
      " d  D        fc ",
      " d ID      nggc ",
      " d DD   w bbbbc ",
      " d         b hc ",
      " Kp        o ic ",
      " bbbEBb    bbbc ",
      "  J   b   kkk c ",
      "  J   by sllljc ",
      "  CrF bA sllljc ",
      "  CCCCbp  mmm b ",
      "      bdddddddb ",
      "                "
    ],
    [
      "                ",
      " dddddqNMqbdddb ",
      " d   pr  rp   b ",
      " d            b ",
      " d            b ",
      " d  Q        gb ",
      " d        bbbbb ",
      " d         b  b ",
      " Kp        L  b ",
      " bbbROb    bbbb ",
      "  C   b       b ",
      "  CS  b       b ",
      "  CF  b       b ",
      "  CCJPbp      b ",
      "      bdddddddb ",
      "                "
    ],
    [
      "                ",
      " dddddqUUqbdddb ",
      " d    r  r    b ",
      " d            d ",
      " d            d ",
      " d            b ",
      " d        bbbbb ",
      " d         b  d ",
      " K         T  d ",
      " bbbVVb    bbbb ",
      "  Cr  b       b ",
      "  CW  b       d ",
      "  X   b       d ",
      "  YCCCb       b ",
      "      bdddddddb ",
      "                "
    ],
    [
      "                ",
      " qKKKKq  qbKKKb ",
      " K    rrrr    b ",
      " K            c ",
      " K            c ",
      " K            b ",
      " K        bbbbb ",
      " K         b  c ",
      " K         b  c ",
      " bbbbbbbbbbbbbb ",
      "  0WZ b       b ",
      "  J   b       c ",
      "  J   b       c ",
      "  CXXXb       b ",
      "      bKKKKKKKb ",
      "                "
    ],
    [
      "                ",
      " bbbbbbbbbbbbbb ",
      " bCCCCCCCCCCCCb ",
      " bCCCCCCCCCCCCb ",
      " bCCCCCCCCCCCCb ",
      " bCCCCCw!CCCCCb ",
      " bCCCCC32Cbbbbb ",
      " bCCCCCCCCCb11b ",
      " bCCCCCCCCCb11b ",
      " bbbbbbbbbbbbbb ",
      "  C 4rbCCCCCCCb ",
      "  C   bCCCCCCCb ",
      "  C   bCCCCCCCb ",
      "  CCCCbCCCCCCCb ",
      "      bbbbbbbbb ",
      "                "
    ]
  ]
}