{
  "name": "building_apartment1_ground_180",
  "refpalette": "c70cities:building_apartment1_ground_palette_180",
  "xsize": 16,
  "zsize": 16,
  "slices": [
    [
      "GGGGGGGGGGGGGGGG",
      "GaaaaaaaaaaaaaaG",
      "GaaaaaaaaaaaaaaG",
      "GaaaaaaaaaaaaaaG",
      "GaaaaaaaaaaaaaaG",
      "GaaaaaaaaaaaaaaG",
      "GaaaaaaaaaaaaaaG",
      "GaaaaaaaaaaaaaaG",
      "GaaaaaaaaaaaaaaG",
      "GaaaaaaaaaaaaaaG",
      "GaaaaaaaaaaaaaaG",
      "GaaaaaaaaaaaaaaG",
      "GaaaaaaaaaaaaaaG",
      "GaaaaaaaaaaaaaaG",
      "GaaaaaaaaaaaaaaG",
      "GGGGGGGGGGGGGGGG"
    ],
    [
      "                ",
      "      bKddddddd ",
      "  CCJJbp      d ",
      "  Cr  b  DI I d ",
      "  CF  E  DDDD d ",
      "  C   B      pd ",
      " bbbbbb      rq ",
      " dpAy        ux ",
      " d       w   ut ",
      " d ss        rq ",
      " dmllk   b   pb ",
      " dmllkbobbn   d ",
      " dmllkb  bg   d ",
      " d jj bihbgfe d ",
      " bbccccccccccbb ",
      "                "
    ],
    [
      "                ",
      "      bKddddddd ",
      "  CCCCbp      d ",
      "  CFT b       d ",
      "  J   S   R   d ",
      "  Q   P      pd ",
      " bbbbbb      rq ",
      " dp           O ",
      " d            N ",
      " d           rq ",
      " d       b   pb ",
      " d    bMbb    d ",
      " d    b  b    d ",
      " d    bL bg   d ",
      " bbbbbbbbbbbbbb ",
      "                "
    ],
    [
      "                ",
      "      bKddddddd ",
      "  ZYCCb       d ",
      "  C Xrb       d ",
      "  C   W       d ",
      "  C   W       d ",
      " bbbbbb      rq ",
      " d            V ",
      " d            V ",
      " d           rq ",
      " d       b    b ",
      " d    bUbb    d ",
      " d    b  b    d ",
      " d    b  b    d ",
      " bbddbbddbbddbb ",
      "                "
    ],
    [
      "                ",
      "      bKKKKKKKq ",
      "  CJJ1b       K ",
      "  Y  Xb       K ",
      "  Y  0b       K ",
      "  Y   b       K ",
      " bbbbbb      rq ",
      " K    b      r  ",
      " K    b      r  ",
      " K    b      rq ",
      " K    b  b    b ",
      " K    bbbb    K ",
      " K    b  b    K ",
      " K    b  b    K ",
      " bbccbbccbbccbb ",
      "                "
    ],
    [
      "                ",
      "      bbbbbbbbb ",
      "  CCCCbCCCCCCCb ",
      "  C   bCCCCCCCb ",
      "  C  5bCCCCCCCb ",
      "  C  rbCCCCCCCb ",
      " bbbbbbCCCCCCCb ",
      " bCCCCbCC4wCCCb ",
      " bCCCCbCC3!CCCb ",
      " bCCCCbCCCCCCCb ",
      " bCCCCbCCbCCCCb ",
      " bCCCCbbbbCCCCb ",
      " bCCCCb22bCCCCb ",
      " bCCCCb22bCCCCb ",
      " bbbbbbbbbbbbbb ",
      "                "
    ]
  ]
}