{
  "name": "building_office3_ground",
  "refpalette": "c70cities:building_office3_ground_palette",
  "xsize": 16,
  "zsize": 16,
  "slices": [
    [
      "GGGGGGGGGGGGGGGG",
      "GaaaaaaaaaaaaaaG",
      "GabbbbbbbbbbbbaG",
      "Gab!bbbbbbbbbbaG",
      "GabbbbbbbbbbbbaG",
      "GabbbbbbbbbbbbaG",
      "GabbbbbbbbbbbbaG",
      "GabbbbbbbbbbbbaG",
      "GabbbbbbbbbbbbaG",
      "GabbbbbbbbbbbbaG",
      "GabbbbbbbbbbbbaG",
      "GabbbbbbbbbbbbaG",
      "GabbbbbbbbbbbbaG",
      "GabbbbbbbbbbbbaG",
      "GaaaaaaaaaaaaaaG",
      "GGGGGGGGGGGGGGGG"
    ],
    [
      "                ",
      " ccdccdccdccdcc ",
      " ceeffgffgffeec ",
      " deh        hed ",
      " cf          fc ",
      " cf          fc ",
      " dg          gd ",
      " cf   ivj     k ",
      " cf    vj     l ",
      " dg          gd ",
      " cf          fc ",
      " cf          fc ",
      " deh        hed ",
      " ceeffgffgffeec ",
      " ccdccdccdccdcc ",
      "                "
    ],
    [
      "                ",
      " ccdccdccdccdcc ",
      " c    m  m    c ",
      " d h        h d ",
      " c            c ",
      " c            c ",
      " dm          md ",
      " c     vj     n ",
      " c     vj     o ",
      " dm          md ",
      " c            c ",
      " c            c ",
      " d h        h d ",
      " c    m  m    c ",
      " ccdccdccdccdcc ",
      "                "
    ],
    [
      "                ",
      " ppdppdppdppdpp ",
      " p            p ",
      " d h        h d ",
      " p            p ",
      " p            p ",
      " d            d ",
      " p     vj     p ",
      " p     vj     p ",
      " d            d ",
      " p            p ",
      " p            p ",
      " d h        h d ",
      " p            p ",
      " ppdppdppdppdpp ",
      "                "
    ],
    [
      "                ",
      " ccdccdccdccdcc ",
      " cqqqqqqqqqqqqc ",
      " dqh        hqd ",
      " cq          qc ",
      " cq          qc ",
      " dq          qd ",
      " cq    vj    qc ",
      " cq    vj    qc ",
      " dq          qd ",
      " cq          qc ",
      " cq          qc ",
      " dqh        hqd ",
      " cqqqqqqqqqqqqc ",
      " ccdccdccdccdcc ",
      "                "
    ],
    [
      "                ",
      " rrrrrrrrrrrrrr ",
      " raaaaaaaaaaaar ",
      " rasddddddddsar ",
      " raddddddddddar ",
      " raddddddddddar ",
      " raddddddddddar ",
      " raddddvjddddar ",
      " raddddvjddddar ",
      " raddddddddddar ",
      " raddddddddddar ",
      " raddddddddddar ",
      " rasddddddddsar ",
      " raaaaaaaaaaaar ",
      " rrrrrrrrrrrrrr ",
      "                "
    ]
  ]
}