{
  "name": "building_restaurant2_ground",
  "refpalette": "c70cities:building_restaurant2_ground_palette",
  "xsize": 16,
  "zsize": 16,
  "slices": [
    [
      "GGGGGGGGGGGGGGGG",
      "GGGGGaaaabaccccG",
      "GGGacccccccccccG",
      "GGGbcdefddeccccG",
      "GGGacgefggeccccG",
      "GGGacefddefddaaG",
      "GbGacefggefggabG",
      "aaaacdefddefdaaG",
      "GabacgefggefgaaG",
      "aGGacefddefddabG",
      "GGGacefggefggabG",
      "GGGacdefddeccccG",
      "GGGacgefggeccccG",
      "GGGacccccccccccG",
      "GGGGGaaaabbccccG",
      "GGGGGGGGGGGGGGGG"
    ],
    [
      "                ",
      "    hijkkkliiii ",
      "   mmmmmmmminni ",
      "   omp     i ni ",
      "   qm      irii ",
      "   smp tuwx  iy ",
      "   mmi tAmB CiD ",
      "     E tAmB FiD ",
      "     I tAmB CiD ",
      "   mmi tAmB CiD ",
      "   omp tJKL MiN ",
      "   qm      iiii ",
      "   smp     E  i ",
      "   mmmmmmmmiOPi ",
      "    hiQRRRSiiii ",
      "                "
    ],
    [
      "                ",
      "    Ti     iiii ",
      "   mmmmUUUmiVWi ",
      "   XU      i  i ",
      "   XU      iYii ",
      "   XU   Z0   iX ",
      "   mmi  102  iX ",
      "     3  104 5iX ",
      "     6  10  7iX ",
      "   mmi  102 !iX ",
      "   XU   18  9iX ",
      "   XU      iiii ",
      "   XU      3  i ",
      "   mmmmUUUmi @i ",
      "    Ti     iiii ",
      "                "
    ],
    [
      "                ",
      "    TiXXXXXiiii ",
      "   mmmmmmmmi# U ",
      "   XU V$$$Wi  U ",
      "   XU      iiii ",
      "   XU   %^   iX ",
      "   mmi  %^   iX ",
      "   & i  %^   iX ",
      "   & i  %^   iX ",
      "   mmi  %^   iX ",
      "   XU   %^   iX ",
      "   XU      iiii ",
      "   XU *((()i  U ",
      "   mmmmmmmmi  U ",
      "    TiXXXXXiiii ",
      "                "
    ],
    [
      "                ",
      "     i+++++iiii ",
      "  -mmmmmmmmi  + ",
      "   +ii[[[[[i  + ",
      "   +ii     iiii ",
      "   +ii       i+ ",
      "  -mmi       i+ ",
      "   & i       i+ ",
      "   & i       i+ ",
      "  -mmi       i+ ",
      "   +ii       i+ ",
      "   +ii     iiii ",
      "   +ii]]]]]i  + ",
      "  -mmmmmmmmi  + ",
      "     i+++++iiii ",
      "                "
    ],
    [
      "                ",
      " {{{{iiiiiiiiii ",
      " {{{{mmmmmm}\\\\i ",
      " {{{{}PPPPP}\\\\i ",
      " {{{{}PPPPP}iii ",
      " {{{{}|||||}}i} ",
      " {{{{}PPPPP}}i} ",
      " {{{{}PPPPP}}i} ",
      " {{{{}PPPPP}}i} ",
      " {{{{}PPPPP}}i} ",
      " {{{{}|||||}}i} ",
      " {{{{}PPPPP}iii ",
      " {{{{}PPPPP}\\\\i ",
      " {{{{mmmmmm}\\\\i ",
      " {{{{iiiiiiiiii ",
      "                "
    ]
  ]
}