{
  "name": "building_gasstation1_ground_180",
  "refpalette": "c70cities:building_gasstation1_ground_palette_180",
  "xsize": 16,
  "zsize": 16,
  "slices": [
    [
      "GGGGGGGGGGGGGGGG",
      "GGGGGbHHHHHHHHHH",
      "GGGGGbHHHHHHHHHH",
      "GGaaaaaaaHHaHHHH",
      "GGaaaaaaaHHaHHHH",
      "GGaaaaaaaHHaHHHH",
      "GGaaaaaaaHHaHHHH",
      "GGaaaaaaaHHaHHHH",
      "GGaaaaaaaHHaHHHH",
      "GGaaaaaaaHHaHHHH",
      "GGaaaaaaaHHaHHHH",
      "GGaaaaaaaHHaHHHH",
      "GGaaaaaaaHHaHHHH",
      "GGGGGbHHHHHHHHHH",
      "GGGGGbHHHHHHHHHa",
      "GGGGGGGGGGGGGGGG"
    ],
    [
      "                ",
      "     fh g       ",
      "     fe d       ",
      "  jjjjjjj  its  ",
      "  j Fj EC       ",
      "  j Dj  C  mlk  ",
      "  jBjj Aj  its  ",
      "  j     q  y    ",
      "  j     x  wlk  ",
      "  jooo  u  its  ",
      "  jrr   q       ",
      "  jp!onnj  mlk  ",
      "  jjjjjjj  i    ",
      "     fh g       ",
      "     fe d      c",
      "                "
    ],
    [
      "                ",
      "                ",
      "                ",
      "  jjjjjjj  i    ",
      "  j Qj  P       ",
      "  j  j  P  I    ",
      "  jOjj Nj  i    ",
      "  j     q       ",
      "  j     M       ",
      "  joro  L  i    ",
      "  j     q       ",
      "  joKpJJj  I    ",
      "  jjjjjjj  i    ",
      "                ",
      "               c",
      "                "
    ],
    [
      "                ",
      "                ",
      "                ",
      "  SSSSSSS  i    ",
      "  V  j  S       ",
      "  V  j  S       ",
      "  Sjjj  S  i    ",
      "  V     S       ",
      "  V     S       ",
      "  S     S  i    ",
      "  V     S       ",
      "  V r UTS       ",
      "  SSSSSSS  i    ",
      "                ",
      "               R",
      "                "
    ],
    [
      "                ",
      "                ",
      "                ",
      "  jjjjjjj Wj    ",
      "  jZZj  j       ",
      "  jZZj  j       ",
      "  jjjjW j Yj    ",
      "  j  j  j       ",
      "  j  j  j       ",
      "  j  jY j Wj    ",
      "  j  j  j       ",
      "  jr jXrj       ",
      "  jjjjjjj Wj    ",
      "                ",
      "                ",
      "                "
    ],
    [
      "                ",
      "                ",
      " 00000000000000 ",
      " 0aaaaaaaaaaff0 ",
      " 0affaffaffaff0 ",
      " 0affaffaffaff0 ",
      " 0affaffaffaff0 ",
      " 0affaffaffaff0 ",
      " 0affaffaffaff0 ",
      " 0affaffaffaff0 ",
      " 0affaffaffaff0 ",
      " 0affaffaffaff0 ",
      " 0aaaaaaaaaaff0 ",
      " 00000000000000 ",
      "                ",
      "                "
    ]
  ]
}