{
  "name": "building_lab1_ground",
  "refpalette": "c70cities:building_lab1_ground_palette",
  "xsize": 16,
  "zsize": 16,
  "slices": [
    [
      "zzzzzzzzzzzzzzzz",
      "zzzzzzzzzzzzzzzz",
      "zzHHHHaazazazzzz",
      "zbHHHHazaaaaaazz",
      "zbcHHHzzzaazaazz",
      "zbHHHHzzazzazzzz",
      "zzHHHHzzzazzazzz",
      "zzHHHHzzzzzazzzz",
      "zzHHHHzzzazazzzz",
      "zzHHHHzzazazzzzz",
      "zzHHHHzzzazzzzzz",
      "zzzzzzzzazaazzzz",
      "zzzzzzzzzazzzzzz",
      "zzzzzzazzzazzzzz",
      "zzzzzzzzzzzzzzzz",
      "zzzzzzzzzzzzzzzz"
    ],
    [
      "dd dd ed d de dd",
      "ef   fgg     gg ",
      "hbi   hjkhh ehgd",
      " blm      h  hg ",
      "hb n  dd      gd",
      "hbn i        dgd",
      " fo  pd      q  ",
      "dbr stts     u e",
      "ebr t!wx     y  ",
      "hbA stts e  dd d",
      "hb             d",
      "hfB  f   d  d   ",
      "   ddd     ddhgd",
      " g d   d     hg ",
      "dggge      d gg ",
      "e           de e"
    ],
    [
      "                ",
      " f   f          ",
      " b           h  ",
      " bi             ",
      " b              ",
      " bC             ",
      " fD  p          ",
      " b  EFIJ        ",
      " b  K FL        ",
      " bM EFIJ        ",
      "hb              ",
      " f   f          ",
      "                ",
      "                ",
      "                ",
      "                "
    ],
    [
      "                ",
      " f   p          ",
      " N              ",
      " N              ",
      " N              ",
      " N              ",
      " f   p          ",
      " N  OO          ",
      " N  LLL~        ",
      " N  OO          ",
      " N              ",
      " f   p          ",
      "                ",
      "                ",
      "                ",
      "                "
    ],
    [
      "                ",
      " pPPQQ          ",
      "  RRNQ          ",
      "  RRNQ          ",
      "  RRNQ          ",
      "  RRNQ          ",
      " pPPQQ          ",
      "  RRNQ          ",
      "  RRNQ ~        ",
      "  RRNQ          ",
      "  RRNQ          ",
      " pPPQQ          ",
      "                ",
      "                ",
      "                ",
      "                "
    ],
    [
      "                ",
      "QQ              ",
      "QN              ",
      "QN              ",
      "QN              ",
      "QN              ",
      "QQ              ",
      "QN              ",
      "QN     ~        ",
      "QN              ",
      "QN              ",
      "QQ              ",
      "                ",
      "                ",
      "                ",
      "                "
    ]
  ]
}