{
  "name": "building_apartment1_top_180",
  "refpalette": "c70cities:building_apartment1_top_palette_180",
  "xsize": 16,
  "zsize": 16,
  "slices": [
    [
      "                ",
      "      aaaaaaaaa ",
      "  hgfbbbbbbbbba ",
      "  e   cccccccba ",
      "  e   cccccccba ",
      "  b  dcccccccba ",
      " abccccccccccba ",
      " abccccccccccba ",
      " abccccccccccba ",
      " abccccccccccba ",
      " abccccccccccba ",
      " abccccccccccba ",
      " abccccccccccba ",
      " abbbbbbbbbbbba ",
      " aaaaaaaaaaaaaa ",
      "                "
    ],
    [
      "                ",
      "                ",
      "  bbiibxllbbbb  ",
      "  b   rn  on b  ",
      "  b   ru  woob  ",
      "  b   run on t  ",
      "  brrsrn  o  l  ",
      "  q       o  l  ",
      "  i      no! m  ",
      "  i       ooob  ",
      "  b pp pp o nb  ",
      "  b ppoppoo  i  ",
      "  l     n   ni  ",
      "  mjiiblkbbjii  ",
      "                ",
      "                "
    ],
    [
      "                ",
      "                ",
      "  bbbbbbbbjiib  ",
      "  b   r      l  ",
      "  i   rD     l  ",
      "  g   rD     b  ",
      "  brrCr      b  ",
      "  b          b  ",
      "  b          b  ",
      "  b          b  ",
      "  b Ay yB    b  ",
      "  b Ay yy    b  ",
      "  b          b  ",
      "  bbbbbbbiiibb  ",
      "                ",
      "                "
    ],
    [
      "                ",
      "                ",
      "  bbbbbllbbbbb  ",
      "  bEEEE      b  ",
      "  bEEEEn     b  ",
      "  bEEEE      b  ",
      "  bEEEE      b  ",
      "  b          b  ",
      "  b          l  ",
      "  t          l  ",
      "  l          l  ",
      "  l          b  ",
      "  l          b  ",
      "  bbbllkbbbbbb  ",
      "                ",
      "                "
    ],
    [
      "                ",
      "                ",
      "                ",
      "                ",
      "                ",
      "                ",
      "                ",
      "                ",
      "                ",
      "                ",
      "                ",
      "                ",
      "                ",
      "                ",
      "                ",
      "                "
    ],
    [
      "                ",
      "                ",
      "                ",
      "                ",
      "                ",
      "                ",
      "                ",
      "                ",
      "                ",
      "                ",
      "                ",
      "                ",
      "                ",
      "                ",
      "                ",
      "                "
    ]
  ]
}