{
  "name": "building_hotel2_floor2_270",
  "refpalette": "c70cities:building_hotel2_floor2_palette_270",
  "xsize": 16,
  "zsize": 16,
  "slices": [
    [
      "                ",
      " aaaaaaaaaaaaaa ",
      "  dccc!c!cc=bba ",
      "  dccccccccccca ",
      "  dccccccccccca ",
      "  dccccccccccca ",
      "  dccccccccccca ",
      "  dcccc!cccccca ",
      "  dccccccccccca ",
      "  dccccccccccca ",
      "  dccccccccccca ",
      "  dddddddddddda ",
      "              a ",
      "              a ",
      "              a ",
      "                "
    ],
    [
      "                ",
      " aaaaaaaaaaaaaa ",
      "  fy  =apmk=bba ",
      "  fA  ta nla  a ",
      "  fB  taqaaa  a ",
      "  f        g  a ",
      "  f   aaaaaaaea ",
      "  f xuaprohh  a ",
      "  f xua   ii  a ",
      "  f  was      a ",
      "  f   as  jj  a ",
      "  ffffffffffffa ",
      "              a ",
      "              a ",
      "              a ",
      "                "
    ],
    [
      "                ",
      " aaaaaaaaaaaaaa ",
      "  f   Ia   =bba ",
      "  fJ   a   a  a ",
      "  f    aEaaa  a ",
      "  f        D  a ",
      "  f   aaaaaaaCa ",
      "  f   a       a ",
      "  f   a       a ",
      "  f   aF      a ",
      "  f   a       a ",
      "  ffffffffffffa ",
      "              a ",
      "              a ",
      "              a ",
      "                "
    ],
    [
      "                ",
      " aaaaaaaaaaaaaa ",
      "  f   Ka   =bba ",
      "  f   La   a  a ",
      "  f   Laaaaa  a ",
      "  f        a  a ",
      "  f   aaaaaaaaa ",
      "  f   a       a ",
      "  f   a       a ",
      "  f   a       a ",
      "  f   a       a ",
      "  ffffffffffffa ",
      "              a ",
      "              a ",
      "              a ",
      "                "
    ],
    [
      "                ",
      " aaaaaaaaaaaaaa ",
      "  f    a   =bba ",
      "  f    a   a  a ",
      "  f    aaaaaMMa ",
      "  f        a  a ",
      "  f   aaaaaaaaa ",
      "  f   a       a ",
      "  f   a       a ",
      "  f   a       a ",
      "  f   a       a ",
      "  ffffffffffffa ",
      "              a ",
      "              a ",
      "              a ",
      "                "
    ],
    [
      "                ",
      " aaaaaaaaaaaaaa ",
      "  JNNNNaNNN=bba ",
      "  JNNNNaNNNaNNa ",
      "  JNNNNaaaaaNNa ",
      "  JNNNNNNNNaNNa ",
      "  JNNNaaaaaaaaa ",
      "  JNNNaNNNNNNNa ",
      "  JNNNaNNNNNNNa ",
      "  JNNNaNNNNNNNa ",
      "  JNNNNNNNNNNNa ",
      "  JJJJJJJJJJJJa ",
      "              a ",
      "              a ",
      "              a ",
      "                "
    ]
  ]
}