{
  "name": "building_office2_floor2_90",
  "refpalette": "c70cities:building_office2_floor2_palette_90",
  "xsize": 16,
  "zsize": 16,
  "slices": [
    [
      "                ",
      " a            a ",
      " a dddddddddd a ",
      " abeeeeeeeeeeba ",
      " acccccccccccca ",
      " acccccccccccca ",
      " acccccccccccca ",
      " acccccccccccfa ",
      " acccccccccccfa ",
      " acccccccccccca ",
      " acccccccccccca ",
      " a!ccccccccccca ",
      " abeeeeeeeeeeba ",
      " a dddddddddd a ",
      " a            a ",
      "                "
    ],
    [
      "                ",
      " a            a ",
      " a dddddddddd a ",
      " ab          ba ",
      " a i      i  ja ",
      " a hhh  hhh  la ",
      " a   g  g    ka ",
      " a           fa ",
      " a           fa ",
      " a   i  i    ka ",
      " a hhh  hhh  ja ",
      " a g      g  ja ",
      " ab          ba ",
      " a dddddddddd a ",
      " a            a ",
      "                "
    ],
    [
      "                ",
      " a            a ",
      " a dddddddddd a ",
      " ab          ba ",
      " a            a ",
      " a m m  m m   a ",
      " a           na ",
      " a           fa ",
      " a           fa ",
      " a           na ",
      " a m m  m m   a ",
      " a            a ",
      " ab          ba ",
      " a dddddddddd a ",
      " a            a ",
      "                "
    ],
    [
      "                ",
      " a            a ",
      " a dddddddddd a ",
      " ab          ba ",
      " a            a ",
      " a            a ",
      " a            a ",
      " a           fa ",
      " a           fa ",
      " a            a ",
      " a            a ",
      " a            a ",
      " ab          ba ",
      " a dddddddddd a ",
      " a            a ",
      "                "
    ],
    [
      "                ",
      " a            a ",
      " a dddddddddd a ",
      " ab          ba ",
      " a            a ",
      " a            a ",
      " a            a ",
      " a           fa ",
      " a           fa ",
      " a            a ",
      " a            a ",
      " a            a ",
      " ab          ba ",
      " a dddddddddd a ",
      " a            a ",
      "                "
    ],
    [
      "                ",
      " a            a ",
      " a dddddddddd a ",
      " ab          ba ",
      " aooooooooooooa ",
      " aooooooooooooa ",
      " aooooooooooooa ",
      " aooooooooooofa ",
      " aooooooooooofa ",
      " aooooooooooooa ",
      " aooooooooooooa ",
      " aooooooooooooa ",
      " ab          ba ",
      " a dddddddddd a ",
      " a            a ",
      "                "
    ]
  ]
}