{
  "name": "building_office2_ground",
  "refpalette": "c70cities:building_office2_ground_palette",
  "xsize": 16,
  "zsize": 16,
  "slices": [
    [
      "GGGGGGGGGGGGGGGG",
      "GaaaaaaaaaaaaaaG",
      "GGGbccccccccbGGG",
      "GGbccccccccccbGG",
      "GGbccccccccccbGG",
      "GGbccccccccccbGG",
      "GGbccccccccccbGG",
      "GGbccccccccccbGG",
      "GGbccccccccccbGG",
      "GGbccccccccccbGG",
      "GGbccccccccccbGG",
      "GGbccccccc!ccbGG",
      "GGbccccccccccbGG",
      "GGGbccccccccbGGG",
      "GaaaaaaaaaaaaaaG",
      "GGGGGGGGGGGGGGGG"
    ],
    [
      "                ",
      " aaaaaaaaaaaaaa ",
      "   bdefffefdb   ",
      "  g          g  ",
      "  g   h  h   g  ",
      "  g  iiiiii  g  ",
      "  g   j  j   g  ",
      "  g          k  ",
      "  g          l  ",
      "  g          g  ",
      "  g          g  ",
      "  g       m  g  ",
      "  g          g  ",
      "   bnopqqporb   ",
      " aaaaaaaaaaaaaa ",
      "                "
    ],
    [
      "                ",
      " aaaaaaaaaaaaaa ",
      "   bs     tsb   ",
      "  g          g  ",
      "  g          g  ",
      "  g          g  ",
      "  g          g  ",
      "  g          u  ",
      "  g          w  ",
      "  g          g  ",
      "  g          g  ",
      "  g          g  ",
      "  g          g  ",
      "   b  xqqx  b   ",
      " aaaaaaaaaaaaaa ",
      "                "
    ],
    [
      "                ",
      " aaaaaaaaaaaaaa ",
      "   bs      sb   ",
      "  g          g  ",
      "  g          g  ",
      "  g          g  ",
      "  g          g  ",
      "  g          g  ",
      "  g    y     g  ",
      "  g          g  ",
      "  g          g  ",
      "  g          g  ",
      "  g          g  ",
      "   b   qq   b   ",
      " aaaaaaaaaaaaaa ",
      "                "
    ],
    [
      "                ",
      " aaaaaaaaaaaaaa ",
      "   b        b   ",
      "  g          g  ",
      "  g          g  ",
      "  g          g  ",
      "  g          g  ",
      "  g    yy    g  ",
      "  g    yy    g  ",
      "  g          g  ",
      "  g          g  ",
      "  g          g  ",
      "  g          g  ",
      "   b   qq   b   ",
      " aaaaaaaaaaaaaa ",
      "                "
    ],
    [
      "                ",
      " aaaaaaaaaaaaaa ",
      "   bAAAAAAAAb   ",
      "  g AAAAAAAA g  ",
      "  g AAAAAAAA g  ",
      "  g AAAAAAAA g  ",
      "  g AAAAAAAA g  ",
      "  g AAABBAAA g  ",
      "  g AAABBAAA g  ",
      "  g AAAAAAAA g  ",
      "  g AAAAAAAA g  ",
      "  g AAAAAAAA g  ",
      "  g AAAAAAAA g  ",
      "   bAAAqqAAAb   ",
      " aaaaaaaaaaaaaa ",
      "                "
    ]
  ]
}