{
  "name": "building_hotel1_top_90",
  "refpalette": "c70cities:building_hotel1_top_palette_90",
  "xsize": 16,
  "zsize": 16,
  "slices": [
    [
      "                ",
      " aaaaaaafffffaa ",
      " abccccccccccba ",
      " acddccccddddcg ",
      " acddccccddddcg ",
      " acddceccccddcg ",
      " acddc    cddcg ",
      " acccc    ccccg ",
      " acccc    cccca ",
      " acddc    cddca ",
      " acddccccccddca ",
      " acddddccddddca ",
      " acddddccddddca ",
      " abccccccccccba ",
      " aaaaaeeeeeeeaa ",
      "                "
    ],
    [
      "                ",
      " aaaaaaffffffaa ",
      " a            a ",
      " a ii    llll a ",
      " a ii    llll a ",
      " a iij jjjjll a ",
      " a iij    jll a ",
      " a   j    j   a ",
      " a   j    j   a ",
      " a hhj    jkk a ",
      " a hhjjjjjjkk a ",
      " a hhhh  kkkk a ",
      " a hhhh  kkkk a ",
      " a            a ",
      " aaaaaaaaaaaaaa ",
      "                "
    ],
    [
      "                ",
      " aaaaafffffffaa ",
      " a            a ",
      " a            a ",
      " a            a ",
      " a            a ",
      " a            a ",
      " a            f ",
      " a            f ",
      " a            f ",
      " a            f ",
      " a            f ",
      " a            f ",
      " a            a ",
      " aaaaaffffaaaaa ",
      "                "
    ],
    [
      "                ",
      " aaaaffffffffaa ",
      " a            a ",
      " a            a ",
      " a            a ",
      " a            a ",
      " a            a ",
      " a            a ",
      " a            a ",
      " a            a ",
      " a            a ",
      " a            a ",
      " a            a ",
      " a            a ",
      " aaaaaaaaaaaaaa ",
      "                "
    ],
    [
      "                ",
      " aaammmmmmmmmaa ",
      " ammmmmmmmmmmma ",
      " amnnnnnnnnnnma ",
      " amnnnnnnnnnnma ",
      " amnnnnnnnnnnma ",
      " amnnnnnnnnnnma ",
      " amnnnnnnnnnnma ",
      " amnnnnnnnnnnma ",
      " amnnnnnnnnnnma ",
      " amnnnnnnnnnnma ",
      " amnnnnnnnnnnma ",
      " amnnnnnnnnnnma ",
      " ammmmmmmmmmmma ",
      " aaaaaaaaaaaaaa ",
      "                "
    ],
    [
      "                ",
      " aa          aa ",
      " a            a ",
      " a            a ",
      " a            a ",
      " a            a ",
      " a            a ",
      " a            a ",
      " a            a ",
      " a            a ",
      " a            a ",
      " a            a ",
      " a            a ",
      " a            a ",
      " aaaaaaaaaaaaaa ",
      "                "
    ]
  ]
}