{
  "name": "building_hotel3_floor3",
  "refpalette": "c70cities:building_hotel3_floor3_palette",
  "xsize": 16,
  "zsize": 16,
  "slices": [
    [
      "                ",
      "  a a a a a a   ",
      "  bbbbbbbbbbbba ",
      " abccccddccccb  ",
      "  bceeeeeeeecba ",
      " abceffffffecb  ",
      "  bceffffffecba ",
      " abceffffffecb  ",
      "  bceffffffecba ",
      " abceffffffecb  ",
      "  bceffffffecba ",
      " abceeeeeeeecb  ",
      "  bccccccccccba ",
      " abbbbbbbbbbbb  ",
      "   a a a a a a  ",
      "                "
    ],
    [
      "                ",
      "  a a a a a a   ",
      "  bbbbbbbbbbbba ",
      " ab    dd    b  ",
      "  b egeeeehe ba ",
      " ab e iei  e b  ",
      "  b e jek  l ba ",
      " ab e m!mm l b  ",
      "  b e nnen l ba ",
      " ab e ooeo l b  ",
      "  b e   e  l ba ",
      " ab plllellp b  ",
      "  b          ba ",
      " abbbbbbbbbbbb  ",
      "   a a a a a a  ",
      "                "
    ],
    [
      "                ",
      "  a a a a a a   ",
      "  bbbbbbbbbbbba ",
      " ab    dd    b  ",
      "  b eqeeeere ba ",
      " ab e  e   e b  ",
      "  b s  e     ba ",
      " ab s  et    b  ",
      "  b s   e    ba ",
      " ab s   e    b  ",
      "  b e   e    ba ",
      " ab p   e  p b  ",
      "  b          ba ",
      " abbbbbbbbbbbb  ",
      "   a a a a a a  ",
      "                "
    ],
    [
      "                ",
      "  a a a a a a   ",
      "  bbbbbbbbbbbba ",
      " ab    dd    b  ",
      "  b eeeeeeee ba ",
      " ab e  e   e b  ",
      "  b e  e     ba ",
      " ab e  e     b  ",
      "  b e   e    ba ",
      " ab e   e    b  ",
      "  b e   e    ba ",
      " ab p   e  p b  ",
      "  b          ba ",
      " abbbbbbbbbbbb  ",
      "   a a a a a a  ",
      "                "
    ],
    [
      "                ",
      "  a a a a a a   ",
      "  bbbbbbbbbbbba ",
      " ab    dd    b  ",
      "  b eeeeeeee ba ",
      " ab e  e   e b  ",
      "  b e  e     ba ",
      " ab e  e     b  ",
      "  b e   e    ba ",
      " ab e   e    b  ",
      "  b e   e    ba ",
      " ab p   e  p b  ",
      "  b          ba ",
      " abbbbbbbbbbbb  ",
      "   a a a a a a  ",
      "                "
    ],
    [
      "                ",
      "  a a a a a a   ",
      "  bbbbbbbbbbbba ",
      " ab    dd    b  ",
      "  b eeeeeeee ba ",
      " ab euueuuue b  ",
      "  b euueuuue ba ",
      " ab euueuuue b  ",
      "  b euuuuuue ba ",
      " ab euuuuuue b  ",
      "  b euuuuuue ba ",
      " ab eeeeeeee b  ",
      "  b          ba ",
      " abbbbbbbbbbbb  ",
      "   a a a a a a  ",
      "                "
    ]
  ]
}