{
  "name": "building_residential4_ground_90",
  "refpalette": "c70cities:building_residential4_ground_palette_90",
  "xsize": 16,
  "zsize": 16,
  "slices": [
    [
      "GGGGGGGGGGGGGGGG",
      "GGGGGGGGGGGGGGGG",
      "GGaGGGGGGGGGGaGG",
      "GGaddddddddddaGG",
      "GGaccccccccccaGG",
      "GGaccccccccccaGG",
      "GGaccccccccccaGG",
      "GGabbbbbbbbbbaGG",
      "GGabbbbbbbbbbaGG",
      "GGabbbbbbbbbbaGG",
      "GGabbbbbbbbbbaGG",
      "GGabbbbbbbbbbaGG",
      "GGabbbbbbbbbbaGG",
      "GGaaaaaaaaaaaaGG",
      "GGGGGGGGGGGGGGGG",
      "GGGGGGGGGGGGGGGG"
    ],
    [
      "effffgffffgffffe",
      "f              f",
      "f hooooooooooh f",
      "f hddddddddddh f",
      "f inntxACxDINO f",
      "g i       D MO g",
      "f hmms    DFLh f",
      "f ill        O f",
      "f i          O f",
      "f hkkkww    Kh f",
      "g i qq       O g",
      "f i          O f",
      "f h pr     EJh f",
      "f hjjjhyBhjjjh f",
      "f              f",
      "effffeu  efffffe"
    ],
    [
      "effffgffffgffffe",
      "f              f",
      "f h          h f",
      "f hddddVVddddh f",
      "f P  T  XYD  1 f",
      "g P       D  1 g",
      "f h S     DZLh f",
      "f P          P f",
      "f P          P f",
      "f hQQQww     h f",
      "g P RR      KP g",
      "f P         0P f",
      "f h          h f",
      "f hPPPhUWhPPPh f",
      "f              f",
      "effffe   efffffe"
    ],
    [
      "                ",
      "                ",
      "  h2222222222h  ",
      "  hddddVVddddh  ",
      "  h       D  h  ",
      "  h       D  h  ",
      "  h       DLLh  ",
      "  h          h  ",
      "  h          h  ",
      "  hQQQww     h  ",
      "  h          h  ",
      "  h        3 h  ",
      "  h          h  ",
      "  hPPPhPPhPPPh  ",
      "                ",
      "                "
    ],
    [
      "                ",
      " 4O          i6 ",
      " 4h5555  5555h6 ",
      " 4hddddddddddh6 ",
      " 4hbbbbbbbbbbh6 ",
      " 4hbbbbbbbbbbh6 ",
      " 4hbbbbbbbbbbh6 ",
      " 4hbbbbbbbbbbh6 ",
      " 4hbbbbbbbbbbh6 ",
      " 4hbbbbbbb   h6 ",
      " 4hbbbbbbb   h6 ",
      " 4hbbbbbbb3  h6 ",
      " 4hbbbbbbbbbbh6 ",
      " 4hhhhhhhhhhhh6 ",
      " 4O          i6 ",
      "                "
    ],
    [
      "                ",
      "  4O        i6  ",
      "  45555*)55556  ",
      "  4dddddddddd6  ",
      "  4h5 #& [{} 6  ",
      "  4h5@@@ [  \\6  ",
      "  4h5@@@ [  \\6  ",
      "  4h5  ^ [  !6  ",
      "  4h5    -   6  ",
      "  4h5999 +]]]6  ",
      "  4h5889 +   6  ",
      "  4h577%     6  ",
      "  4dddddddddd6  ",
      "  45555$(55556  ",
      "  4O        i6  ",
      "                "
    ]
  ]
}