{
  "name": "building_hotel3_top_90",
  "refpalette": "c70cities:building_hotel3_top_palette_90",
  "xsize": 16,
  "zsize": 16,
  "slices": [
    [
      "                ",
      "  a a a a a a   ",
      "  bbbbbbbbbbbba ",
      " abccccccccccb  ",
      "  bceeeeeeeecba ",
      " abceffffffecb  ",
      "  bceffffffecba ",
      " abdeffffffecb  ",
      "  bdeffffffecba ",
      " abceffffffecb  ",
      "  bceffffffecba ",
      " abceeeeeeeecb  ",
      "  bccccccccccba ",
      " abbbbbbbbbbbb  ",
      "   a a a a a a  ",
      "                "
    ],
    [
      "                ",
      "  a a a a a     ",
      "  bbbbbbbbb     ",
      " ab             ",
      "  b eeiiiiij    ",
      " ab        i    ",
      "  b        i    ",
      " ab ehhhhh i    ",
      "  b eggggh i    ",
      " ab eggggh i    ",
      "  b eggggh!i    ",
      " ab eeeeeeej    ",
      "  b             ",
      " abbbbbbbbb     ",
      "   a a a a      ",
      "                "
    ],
    [
      "                ",
      "  a a a         ",
      "  bbbbbb        ",
      " ab             ",
      "  b ee     j    ",
      " ab             ",
      "  b             ",
      " ab e           ",
      "  b e           ",
      " ab e           ",
      "  b e           ",
      " ab eekkkkej    ",
      "  b             ",
      " abbbbbb        ",
      "   a a a        ",
      "                "
    ],
    [
      "                ",
      "  a a           ",
      "  bbb           ",
      " ab             ",
      "  b ee     j    ",
      " ab             ",
      "  b             ",
      " ab e           ",
      "  b e           ",
      " ab e           ",
      "  b e           ",
      " ab eeeeeeej    ",
      "  b             ",
      " abbb           ",
      "   a            ",
      "                "
    ],
    [
      "                ",
      "                ",
      "                ",
      "                ",
      "    ee     j    ",
      "    l           ",
      "    l           ",
      "    e           ",
      "    e           ",
      "    e           ",
      "    e           ",
      "    eeeeeeej    ",
      "                ",
      "                ",
      "                ",
      "                "
    ],
    [
      "                ",
      "                ",
      "                ",
      "                ",
      "    hhhhhhhh    ",
      "    hhccccch    ",
      "    hhccccch    ",
      "    hhccccch    ",
      "    hhccccch    ",
      "    hhccccch    ",
      "    hhccccch    ",
      "    hhhhhhhh    ",
      "                ",
      "                ",
      "                ",
      "                "
    ]
  ]
}