{
  "name": "building_residential3_ground_90",
  "refpalette": "c70cities:building_residential3_ground_palette_90",
  "xsize": 16,
  "zsize": 16,
  "slices": [
    [
      "GGGGGGGGGGGGGGGG",
      "GGGGGGGGGGGGGGGG",
      "GGaaaaaaaaaaaaGG",
      "GGabbbbbbbbbbaGG",
      "GGabbbbbbbbbbaGG",
      "GGabbbbbbbbbbaGG",
      "GGabbbbbbbbbbaGG",
      "GGabbbbbbbbbaaGG",
      "GGabbbbbddddcGGG",
      "GGabbbbbddddcGGG",
      "GGabbbbbddddcGGG",
      "GGabbbbbddddcGGG",
      "GGabbbbacccccGGG",
      "GGaaaaaaGGGGGGGG",
      "GGGGGGGGGGGGGGGG",
      "GGGGGGGGGGGGGGGG"
    ],
    [
      "effffgffffeffffe",
      "f              f",
      "f hhhhhhhhhhhh f",
      "f hmoq xx CJ j f",
      "f h  r       K f",
      "g hllq       K g",
      "f h!      BB j f",
      "f h    wwhhhhh f",
      "f h        IcA f",
      "f hk   u   FcA f",
      "g h   st   EcA g",
      "f h   sty  DcA f",
      "f h    hcccccA f",
      "f hjnpjh AAAAA f",
      "f              f",
      "efei  efffgffffe"
    ],
    [
      "effffgffffeffffe",
      "f              f",
      "f hhLhKhhKKKhh f",
      "f h  q QR    j f",
      "f L  P       K f",
      "g hllq       K g",
      "f K N     TT j f",
      "f h    wwhhhhh f",
      "f hk       Vc  f",
      "f K         S  f",
      "g K         S  g",
      "f K        Uc  f",
      "f h    hcSScc  f",
      "f hjMOjh       f",
      "f              f",
      "efe   efffgffffe"
    ],
    [
      "          W     ",
      "                ",
      "  hhZhZhhZZZhh  ",
      "  h  q       j  ",
      "  X  q       1  ",
      "  hllq       1  ",
      "  X          j  ",
      "  hk   wwhhhhh  ",
      "  h         c0  ",
      "  X         c0  ",
      "  X         c0  ",
      "  X         c0  ",
      "  h    hccccc0  ",
      "  hjYYjh000000  ",
      "                ",
      "  W             "
    ],
    [
      "                ",
      "                ",
      "  hhhhhhhhhhhh  ",
      "  hbbbbbbbbbbh  ",
      "  hbbbbbbbbbbh  ",
      "  hbbbbbbbbbbh  ",
      "  hkbbbbbbbbbh  ",
      "  h bbbbbbbbhh  ",
      "  h bbbb    52  ",
      "  h bbbb    52  ",
      "  hbbbbb    52  ",
      "  hbbbbb    52  ",
      "  hbbbbh333342  ",
      "  hhhhhh222222  ",
      "                ",
      "                "
    ],
    [
      "                ",
      "                ",
      "  hKKKKhhZZZhh  ",
      "  h8   *j#-- K  ",
      "  X   $&j)++)K  ",
      "  X    ^j))))K  ",
      "  X 9        K  ",
      "  h 9  %%%%%hh  ",
      "  h 9  %(   c2  ",
      "  X 9  %    c2  ",
      "  X7  #%    c2  ",
      "  X6  @%    c2  ",
      "  h6  @hccccc2  ",
      "  hKKKKh222222  ",
      "                ",
      "                "
    ]
  ]
}