{
  "name": "building_hotel3_base1",
  "refpalette": "c70cities:building_hotel3_base1_palette",
  "xsize": 16,
  "zsize": 16,
  "slices": [
    [
      "vvvvvvvvvvvvvvvv",
      "vaaaaaaaaaaaaaav",
      "vabbbbbbbbbbbbav",
      "vabbbbbbbbbbbbav",
      "vabbbbbccbbcbbav",
      "vabbbbbddbbbbbav",
      "vabbbbbbbbbbbbav",
      "vabbbbbbbbbbbbav",
      "vabbbbbbbbbbbbav",
      "vabbbbbbbbbbbbav",
      "vabbbbbbbbbbbbav",
      "vabbcbbbbbbcbbav",
      "vabbbbbbbbbbbbav",
      "vabbbbbbbbbbbbav",
      "vaaaaaaaaaaaaaav",
      "vvvvvvvvvvvvvvvv"
    ],
    [
      "vvvvvvvvvvvvvvvv",
      "vaaaaaaaaaaaaaav",
      "vaeffghij     av",
      "va    kij lmn av",
      "va    icc ocj av",
      "va   i dd pqr av",
      "va            av",
      "vaiii     mmmmav",
      "va       sssssav",
      "va            av",
      "vatuw tuuw tuwav",
      "va  c      c  av",
      "va            av",
      "vatuw!tuuw tuwav",
      "vaaaaaaaaaaaaaav",
      "vvvvvvvvvvvvvvvv"
    ],
    [
      "vvvvvvvvvvvvvvvv",
      "vaaaaaaaaaaaaaav",
      "vaxyAB i!     av",
      "va     iC  DE av",
      "va    icc FcI av",
      "va   i dd JKA av",
      "va            av",
      "va        LLL av",
      "va       sssssav",
      "va            av",
      "va M   MM   M av",
      "va  c      c  av",
      "va            av",
      "va M   MM   M av",
      "vaaaaaaaaaaaaaav",
      "vvvvvvvvvvvvvvvv"
    ],
    [
      "vvvvvvvvvvvvvvvv",
      "vaaaaaaaaaaaaaav",
      "va    Ni      av",
      "va    Oi      av",
      "va    icc  c  av",
      "va   i dd     av",
      "va            av",
      "va            av",
      "va       sssssav",
      "va            av",
      "va            av",
      "va  c      c  av",
      "va            av",
      "va            av",
      "vaaaaaaaaaaaaaav",
      "vvvvvvvvvvvvvvvv"
    ],
    [
      "vvvvvvvvvvvvvvvv",
      "vaaaaaaaaaaaaaav",
      "va    Pi      av",
      "va    Qi      av",
      "va    icc  c  av",
      "va   i dd     av",
      "va            av",
      "va            av",
      "va       sssssav",
      "va            av",
      "va            av",
      "va  c      c  av",
      "va            av",
      "va            av",
      "vaaaaaaaaaaaaaav",
      "vvvvvvvvvvvvvvvv"
    ],
    [
      "vvvvvvvvvvvvvvvv",
      "vaaaaaaaaaaaaaav",
      "vaRRRRRRRRRRRRav",
      "vaRRRRRRRRRRRRav",
      "vaRRcRRccRRcRRav",
      "vaRRRRRddRRRRRav",
      "vaRRRRRRRRRRRRav",
      "vaRRRRRRRRRRRRav",
      "vaRRRRRRRRRRRRav",
      "vaRRRRRRRRRRRRav",
      "vaRRRRRRRRRRRRav",
      "vaRRcRRRRRRcRRav",
      "vaRRRRRRRRRRRRav",
      "vaRRRRRRRRRRRRav",
      "vaaaaaaaaaaaaaav",
      "vvvvvvvvvvvvvvvv"
    ]
  ]
}