{
  "name": "building_hotel1_top_180",
  "refpalette": "c70cities:building_hotel1_top_palette_180",
  "xsize": 16,
  "zsize": 16,
  "slices": [
    [
      "                ",
      " aagggggaaaaaaa ",
      " abccccccccccba ",
      " fcddddccddddce ",
      " fcddddccddddce ",
      " fcddccccccddce ",
      " fcddc    cddce ",
      " fcccc    cccce ",
      " acccc    cccce ",
      " accce    cddce ",
      " acccccccccddca ",
      " acddddccddddca ",
      " acddddccddddca ",
      " abccccccccccba ",
      " aaaaaaaaaaaaaa ",
      "                "
    ],
    [
      "                ",
      " aaaaaaaaaaaaaa ",
      " a            a ",
      " f llll  kkkk a ",
      " f llll  kkkk a ",
      " f lljjjjjjkk a ",
      " f llj    jkk a ",
      " f   j    j   a ",
      " f   j    j   a ",
      " a        jhh a ",
      " a   jjjjjjhh a ",
      " a iiii  hhhh a ",
      " a iiii  hhhh a ",
      " a            a ",
      " aaaaaaaaaaaaaa ",
      "                "
    ],
    [
      "                ",
      " aaaaaaffffffaa ",
      " a            a ",
      " f            a ",
      " f            a ",
      " f            a ",
      " f            f ",
      " f            f ",
      " f            f ",
      " f            f ",
      " a            a ",
      " a            a ",
      " a            a ",
      " a            a ",
      " aaaaaaaaaaaaaa ",
      "                "
    ],
    [
      "                ",
      " aaaaaaaaaaaaaa ",
      " a            a ",
      " f            a ",
      " f            a ",
      " f            a ",
      " f            a ",
      " f            a ",
      " f            a ",
      " f            a ",
      " f            a ",
      " a            a ",
      " a            a ",
      " a            a ",
      " aaaaaaaaaaaaaa ",
      "                "
    ],
    [
      "                ",
      " aaaaaaaaaaaaaa ",
      " ammmmmmmmmmmma ",
      " mmnnnnnnnnnnma ",
      " mmnnnnnnnnnnma ",
      " mmnnnnnnnnnnma ",
      " mmnnnnnnnnnnma ",
      " mmnnnnnnnnnnma ",
      " mmnnnnnnnnnnma ",
      " mmnnnnnnnnnnma ",
      " mmnnnnnnnnnnma ",
      " mmnnnnnnnnnnma ",
      " amnnnnnnnnnnma ",
      " ammmmmmmmmmmma ",
      " aaaaaaaaaaaaaa ",
      "                "
    ],
    [
      "                ",
      " aaaaaaaaaaaaaa ",
      " a            a ",
      "              a ",
      "              a ",
      "              a ",
      "              a ",
      "              a ",
      "              a ",
      "              a ",
      "              a ",
      "              a ",
      "              a ",
      " a            a ",
      " aaaaaaaaaaaaaa ",
      "                "
    ]
  ]
}