{
  "name": "building_office3_floor3_90",
  "refpalette": "c70cities:building_office3_floor3_palette_90",
  "xsize": 16,
  "zsize": 16,
  "slices": [
    [
      "                ",
      " aabaabaabaabaa ",
      " acccccccccccca ",
      " bccccccccccccb ",
      " acccccccccccca ",
      " acccccccccccca ",
      " bccccccccccccb ",
      " acccccddccccca ",
      " acccccvvccccca ",
      " bccccccccccccb ",
      " acc!ccccccccca ",
      " acccccccccccca ",
      " bccccccccccccb ",
      " acccccccccccca ",
      " aabaabaabaabaa ",
      "                "
    ],
    [
      "                ",
      " eebeebeebeebee ",
      " e            e ",
      " b f  j  j  f b ",
      " e   iiiiil   e ",
      " e            e ",
      " b            b ",
      " e gg  dd  gg e ",
      " e gh  vv  hg e ",
      " b gh  k   hg b ",
      " e gg      gg e ",
      " e            e ",
      " b f        f b ",
      " e            e ",
      " eebeebeebeebee ",
      "                "
    ],
    [
      "                ",
      " mmbmmbmmbmmbmm ",
      " m            m ",
      " b f        f b ",
      " m            m ",
      " m            m ",
      " b            b ",
      " m     dd     m ",
      " m     vv     m ",
      " b            b ",
      " m            m ",
      " m            m ",
      " b f        f b ",
      " m            m ",
      " mmbmmbmmbmmbmm ",
      "                "
    ],
    [
      "                ",
      " mmbmmbmmbmmbmm ",
      " m            m ",
      " b f        f b ",
      " m            m ",
      " m            m ",
      " b            b ",
      " m     dd     m ",
      " m     vv     m ",
      " b            b ",
      " m            m ",
      " m            m ",
      " b f        f b ",
      " m            m ",
      " mmbmmbmmbmmbmm ",
      "                "
    ],
    [
      "                ",
      " mmbmmbmmbmmbmm ",
      " m            m ",
      " b f        f b ",
      " m            m ",
      " m            m ",
      " b            b ",
      " m     dd     m ",
      " m     vv     m ",
      " b            b ",
      " m            m ",
      " m            m ",
      " b f        f b ",
      " m            m ",
      " mmbmmbmmbmmbmm ",
      "                "
    ],
    [
      "                ",
      " mmbmmbmmbmmbmm ",
      " mnnnnnnnnnnnnm ",
      " bnfoooooooofnb ",
      " mnoooooooooonm ",
      " mnoooooooooonm ",
      " bnoooooooooonb ",
      " mnooooddoooonm ",
      " mnoooovvoooonm ",
      " bnoooooooooonb ",
      " mnoooooooooonm ",
      " mnoooooooooonm ",
      " bnfoooooooofnb ",
      " mnnnnnnnnnnnnm ",
      " mmbmmbmmbmmbmm ",
      "                "
    ]
  ]
}