{
  "name": "building_hotel2_floor3",
  "refpalette": "c70cities:building_hotel2_floor3_palette",
  "xsize": 16,
  "zsize": 16,
  "slices": [
    [
      "                ",
      " aaaaaaaaaaaaaa ",
      " abccccccccd    ",
      " abccccccccd    ",
      " a=ccccccccd    ",
      " accccccc!cd    ",
      " acccccccccd    ",
      " acccccccccd    ",
      " acccccccccd    ",
      " acccccccccd    ",
      " acccccccccd    ",
      " accccccc!cd    ",
      " acccccccccd    ",
      " adddddddddd    ",
      " a              ",
      "                "
    ],
    [
      "                ",
      " aaaaaaaaaaaaaa ",
      " ab        e    ",
      " ab        e    ",
      " a=f   g   e    ",
      " ah    iij e    ",
      " ah        e    ",
      " ak    g   e    ",
      " al    iij e    ",
      " am        e    ",
      " ah    g   e    ",
      " ah    iij e    ",
      " a         e    ",
      " aeeeeeeeeee    ",
      " a              ",
      "                "
    ],
    [
      "                ",
      " aaaaaaaaaaaaaa ",
      " ab        e    ",
      " ab        e    ",
      " a=n       e    ",
      " ah        e    ",
      " ah        e    ",
      " a         e    ",
      " a         e    ",
      " a         e    ",
      " ah        e    ",
      " ah        e    ",
      " a         e    ",
      " aeeeeeeeeee    ",
      " a              ",
      "                "
    ],
    [
      "                ",
      " aaaaaaaaaaaaaa ",
      " ab        e    ",
      " ab        e    ",
      " a=n       e    ",
      " ah        e    ",
      " ah        e    ",
      " a         e    ",
      " a         e    ",
      " a         e    ",
      " ah        e    ",
      " ah        e    ",
      " a         e    ",
      " aeeeeeeeeee    ",
      " a              ",
      "                "
    ],
    [
      "                ",
      " aaaaaaaaaaaaaa ",
      " ab        e    ",
      " ab   o    e    ",
      " a=        e    ",
      " a         e    ",
      " a    o    e    ",
      " a         e    ",
      " a         e    ",
      " a    o    e    ",
      " a         e    ",
      " a         e    ",
      " a         e    ",
      " aeeeeeeeeee    ",
      " a              ",
      "                "
    ],
    [
      "                ",
      " aaaaaaaaaaaaaa ",
      " abppppppppi    ",
      " abppppppppi    ",
      " a=ppppppppi    ",
      " apppppppppi    ",
      " apppppppppi    ",
      " apppppppppi    ",
      " apppppppppi    ",
      " apppppppppi    ",
      " apppppppppi    ",
      " apppppppppi    ",
      " apppppppppi    ",
      " aiiiiiiiiii    ",
      " a              ",
      "                "
    ]
  ]
}