{
  "name": "building_hotel2_ground_180",
  "refpalette": "c70cities:building_hotel2_ground_palette_180",
  "xsize": 16,
  "zsize": 16,
  "slices": [
    [
      "GGGGGGGGGGGGGGGG",
      "GGGGGGGGGGGGGGaG",
      "GGGGddddddddddaG",
      "GGGGdcccccccccaG",
      "GGGGdcccccccccaG",
      "GGGGdccjjiccccaG",
      "GGGGdcchigccccaG",
      "GGGGdccjgic!ccaG",
      "fGGGdcchhgccccaG",
      "GfGGdcccccccccaG",
      "ffffdcccccccccaG",
      "GfGfdcccccccc=aG",
      "GGGGdccccccccbaG",
      "GeeedccccccccbaG",
      "GaaaaaaaaaaaaaaG",
      "GGGGGGGGGGGGGGGG"
    ],
    [
      "                ",
      "              a ",
      "    lllllllllla ",
      "    l        ka ",
      "    l         a ",
      "    l      ut a ",
      "    l      u  a ",
      "    l      ut a ",
      "    l      sr a ",
      "    o         a ",
      "    q        ka ",
      "    p        =a ",
      "    o  =nn=  ba ",
      " mmmlk ====  ba ",
      " aaaaaaaaaaaaaa ",
      "                "
    ],
    [
      "                ",
      "              a ",
      "    lllllllllla ",
      "    l        wa ",
      "    l         a ",
      "    l         a ",
      "    l         a ",
      "    l      A  a ",
      "    l         a ",
      "    o         a ",
      "    y        wa ",
      "    x        =a ",
      "    o        ba ",
      "    lw       ba ",
      " aaaaaaaaaaaaaa ",
      "                "
    ],
    [
      "                ",
      "              a ",
      "    lllllllllla ",
      "    l        wa ",
      "    l         a ",
      "    l         a ",
      "    l         a ",
      "    l         a ",
      "    l         a ",
      "    o         a ",
      "    o        wa ",
      "    o        =a ",
      "    o        ba ",
      "    lw       ba ",
      " aaaaaaaaaaaaaa ",
      "                "
    ],
    [
      "                ",
      "              a ",
      "    lllllllllla ",
      "    l         a ",
      "    l         a ",
      "    l         a ",
      "    l         a ",
      "    l         a ",
      "    l         a ",
      "    l         a ",
      "    l         a ",
      "    l        =a ",
      "    l        ba ",
      "    l        ba ",
      " aaaaaaaaaaaaaa ",
      "                "
    ],
    [
      "                ",
      "              a ",
      "    CCCCCCCCCCa ",
      "    CBBBBBBBBBa ",
      "    CBBBBBBBBBa ",
      "    CBBBBBBBBBa ",
      "    CBBBBBBBBBa ",
      "    CBBBBBBBBBa ",
      "    CBBBBBBBBBa ",
      "    CBBBBBBBBBa ",
      "    CBBBBBBBBBa ",
      "    CBBBBBBBB=a ",
      "    CBBBBBBBBba ",
      "    CBBBBBBBBba ",
      " aaaaaaaaaaaaaa ",
      "                "
    ]
  ]
}