{
  "name": "building_carservice1_ground_270",
  "refpalette": "c70cities:building_carservice1_ground_palette_270",
  "xsize": 16,
  "zsize": 16,
  "slices": [
    [
      "GGGGGGGGGGGGGGGG",
      "GaeeeeeeeavvvvaG",
      "Ge!ffffffe  vvvG",
      "Geff igffe  vvvG",
      "Geffljhffe  vvvG",
      "Gaffmk ffa  vvaG",
      "Gefff fffe  vvvG",
      "Geff ffffe  vvvG",
      "Ge!ffffffe  vvvG",
      "GafffffffabbvvaG",
      "GefffffffeccvvvG",
      "GefffffffeddvvvG",
      "GGfffffffeddvvvG",
      "GGGffffffa==vvaG",
      "GGGGeeeeeeHHHHGG",
      "GGGGGGGGGGHHHHGG"
    ],
    [
      "                ",
      " aewwwwweaooo a ",
      " eA     pe  o   ",
      " eB     qe  o   ",
      " eB     re  o   ",
      " aC     sa  o a ",
      " eB      e  o   ",
      " eB    x e  o   ",
      " eA      e  o   ",
      " ap     ta  o a ",
      " eD         o   ",
      " ew         o   ",
      "  ww        HH  ",
      "   wwAyyua  nna ",
      "    eeeeee      ",
      "                "
    ],
    [
      "                ",
      " aewwwwweaFFFEa ",
      " eA      e      ",
      " e      Ie      ",
      " e      Je      ",
      " a       a    a ",
      " e       e      ",
      " e       e      ",
      " eA      e      ",
      " a       aFFFEa ",
      " eD         HH  ",
      " ew         nn  ",
      "  ww            ",
      "   wwA   a    a ",
      "    eewwwe      ",
      "                "
    ],
    [
      "                ",
      " aewwwwwea    a ",
      " e       e      ",
      " e       e      ",
      " e       e      ",
      " a       a    a ",
      " e       e      ",
      " e       e      ",
      " e       e  HH  ",
      " a       a  nna ",
      " eD      K      ",
      " ew      K      ",
      "  ww     K      ",
      "   ww    a    a ",
      "    eeeeee      ",
      "                "
    ],
    [
      "                ",
      " aeLLLLLea    a ",
      " e       e      ",
      " e       e      ",
      " e       e      ",
      " a       aFFFEa ",
      " e       e  HHF ",
      " e       e  nnF ",
      " e       e    F ",
      " a       a    a ",
      " eD      e    F ",
      " ew      e    F ",
      "  ww     e    F ",
      "   ww    aFFFEa ",
      "    eeeeee      ",
      "                "
    ],
    [
      "                ",
      " aeeeeeeea    a ",
      " eFFFFF  e      ",
      " eFFFFF  e      ",
      " eFFFFF  e  HH  ",
      " aFFFFF  aaMnna ",
      " eFFFFF  e      ",
      " eFFFFF  e      ",
      " eFFFFF  e      ",
      " a FFFF  a    a ",
      " eD FFF  e      ",
      " ew  FF  e      ",
      "  ww  F  e      ",
      "   ww    a    a ",
      "    eeeeee      ",
      "                "
    ]
  ]
}