{
  "name": "building_office1_base1_180",
  "refpalette": "c70cities:building_office1_base1_palette_180",
  "xsize": 16,
  "zsize": 16,
  "slices": [
    [
      "vvvvvvvvvvvvvvvv",
      "vaaaaaaaaaaaaaav",
      "vaaaaaaaaaaaabav",
      "vaaaaaaaaaaaabav",
      "vaaaaaaaaaaaaaav",
      "vaaaaaaaaaaaaaav",
      "vaaaaaaaaaaaaaav",
      "vaaaaaaaaaaaaaav",
      "vaaaaaaaaaaaaaav",
      "vaaaaaaaaaaaaaav",
      "vaaaaaaaaaaaaaav",
      "vaaaaaaaaaaaaaav",
      "vaaaaaaaaaaaaaav",
      "va!aaaaaaaaaa!av",
      "vaaaaaaaaaaaaaav",
      "vvvvvvvvvvvvvvvv"
    ],
    [
      "vvvvvvvvvvvvvvvv",
      "vccccccccccccccv",
      "vcf          bcv",
      "vcf          bcv",
      "vce          ecv",
      "vcd   d  d   dcv",
      "vcd   d  d   dcv",
      "vcd   d  d   dcv",
      "vcd          dcv",
      "vcd          dcv",
      "vcd   d  d   dcv",
      "vcd   d  d   dcv",
      "vcd   d  d   dcv",
      "vcd   d  d   dcv",
      "vccccccccccccccv",
      "vvvvvvvvvvvvvvvv"
    ],
    [
      "vvvvvvvvvvvvvvvv",
      "vccccccccccccccv",
      "vc           bcv",
      "vc           bcv",
      "vce          ecv",
      "vcd   d  d   dcv",
      "vcd   d  d   dcv",
      "vcd   d  d   dcv",
      "vcd          dcv",
      "vcd          dcv",
      "vcd   d  d   dcv",
      "vcd   d  d   dcv",
      "vcd   d  d   dcv",
      "vcd   d  d   dcv",
      "vccccccccccccccv",
      "vvvvvvvvvvvvvvvv"
    ],
    [
      "vvvvvvvvvvvvvvvv",
      "vccccccccccccccv",
      "vc           bcv",
      "vc           bcv",
      "vce          ecv",
      "vcd          dcv",
      "vcd          dcv",
      "vcd          dcv",
      "vcd          dcv",
      "vcd          dcv",
      "vcd          dcv",
      "vcd          dcv",
      "vcd          dcv",
      "vcd          dcv",
      "vccccccccccccccv",
      "vvvvvvvvvvvvvvvv"
    ],
    [
      "vvvvvvvvvvvvvvvv",
      "vccccccccccccccv",
      "vc           bcv",
      "vc           bcv",
      "vce          ecv",
      "vc            cv",
      "vc            cv",
      "vc            cv",
      "vc            cv",
      "vc            cv",
      "vc            cv",
      "vc            cv",
      "vc            cv",
      "vc            cv",
      "vccccccccccccccv",
      "vvvvvvvvvvvvvvvv"
    ],
    [
      "vvvvvvvvvvvvvvvv",
      "vccccccccccccccv",
      "vcgggggggggggbcv",
      "vcgggggggggggbcv",
      "vceggggggggggecv",
      "vcggggggggggggcv",
      "vcggggggggggggcv",
      "vcggggggggggggcv",
      "vcggggggggggggcv",
      "vcggggggggggggcv",
      "vcggggggggggggcv",
      "vcggggggggggggcv",
      "vcggggggggggggcv",
      "vcggggggggggggcv",
      "vccccccccccccccv",
      "vvvvvvvvvvvvvvvv"
    ]
  ]
}