{
  "name": "building_residential3_ground_90",
  "refpalette": "c70cities:building_residential3_ground_palette_90",
  "xsize": 16,
  "zsize": 16,
  "slices": [
    [
      "GGGGGGGGGGGGGGGG",
      "GGGGGGGGGGGGGGGG",
      "GGaaaaaaaaaaaaGG",
      "GGabbbbbbbbbbaGG",
      "GGabbbbbbbbbbaGG",
      "GGabbbbbbbbbbaGG",
      "GGabbbbbbbbbbaGG",
      "GGabbbbbbbbbaaGG",
      "GGabbbbbddddcGGG",
      "GGabbbbbddddcGGG",
      "GGabbbbbddddcGGG",
      "GGabbbbbddddcGGG",
      "GGabbbbacccccGGG",
      "GGaaaaaaGGGGGGGG",
      "GGGGGGGGGGGGGGGG",
      "GGGGGGGGGGGGGGGG"
    ],
    [
      "effffgffffeffffe",
      "f              f",
      "f hhhhhhhhhhhh f",
      "f hlnp ww BI i f",
      "f h  q       J f",
      "g hkkp       J g",
      "f h!      AA i f",
      "f h    uuhhhhh f",
      "f h        Fcy f",
      "f hj   t   Ecy f",
      "g h   rs   Dcy g",
      "f h   rsx  Ccy f",
      "f h    hcccccy f",
      "f himoih yyyyy f",
      "f              f",
      "effe  efffgffffe"
    ],
    [
      "effffgffffeffffe",
      "f              f",
      "f hhKhJhhJJJhh f",
      "f h  p PQ    i f",
      "f K  O       J f",
      "g hkkp       J g",
      "f J M     SS i f",
      "f h    uuhhhhh f",
      "f hj       Uc  f",
      "f J         R  f",
      "g J         R  g",
      "f J        Tc  f",
      "f h    hcRRcc  f",
      "f hiLNih       f",
      "f              f",
      "effe  efffgffffe"
    ],
    [
      "          W     ",
      "                ",
      "  hhYhYhhYYYhh  ",
      "  h  p       i  ",
      "  V  p       0  ",
      "  hkkp       0  ",
      "  V          i  ",
      "  hj   uuhhhhh  ",
      "  h         cZ  ",
      "  V         cZ  ",
      "  V         cZ  ",
      "  V         cZ  ",
      "  h    hcccccZ  ",
      "  hiXXihZZZZZZ  ",
      "                ",
      "   W            "
    ],
    [
      "                ",
      "                ",
      "  hhhhhhhhhhhh  ",
      "  hbbbbbbbbbbh  ",
      "  hbbbbbbbbbbh  ",
      "  hbbbbbbbbbbh  ",
      "  hjbbbbbbbbbh  ",
      "  h bbbbbbbbhh  ",
      "  h bbbb    41  ",
      "  h bbbb    41  ",
      "  hbbbbb    41  ",
      "  hbbbbb    41  ",
      "  hbbbbh222231  ",
      "  hhhhhh111111  ",
      "                ",
      "                "
    ],
    [
      "                ",
      "                ",
      "  hJJJJhhYYYhh  ",
      "  h7   &i@++ J  ",
      "  V   #^i())(J  ",
      "  V    %i((((J  ",
      "  V 8        J  ",
      "  h 8  $$$$$hh  ",
      "  h 8  $*   c1  ",
      "  V 8  $    c1  ",
      "  V6  @$    c1  ",
      "  V5  9$    c1  ",
      "  h5  9hccccc1  ",
      "  hJJJJh111111  ",
      "                ",
      "                "
    ]
  ]
}