{
  "name": "building_apartment1_floor1",
  "refpalette": "c70cities:building_apartment1_floor1_palette",
  "xsize": 16,
  "zsize": 16,
  "slices": [
    [
      "                ",
      " aaaaaaaaaaaaaa ",
      " abbbbbbbbbbbba ",
      " abbbbbbbbbbbba ",
      " abbbbbbbbbbbba ",
      " abbbbbbbbbbbba ",
      " abbbbbbbbbbbba ",
      " abbbbbbbbbbbba ",
      " abbbbbbbbbbbba ",
      " abbbbbbbbbbbba ",
      " abbbbbbbbcbbd  ",
      " abbbbbbbb bbe  ",
      " abbbbbbbb  fe  ",
      " abbbbbbbbdghi  ",
      " aaaaaaaaa      ",
      "                "
    ],
    [
      "                ",
      " jkkkkkkkkkkkkl ",
      " mnoo pqr p nos ",
      " m tt u   p  ts ",
      " m    pwxww   s ",
      " m yA p     yAs ",
      " mpppBpxpppppps ",
      " mrqC      pDDs ",
      " m  E      E  s ",
      " mppC FIIpppJps ",
      " mqK     p   d  ",
      " mL   M Np  Od  ",
      " mP   M Qp  Rd  ",
      " mS     !pTTdd  ",
      " UVVVVVVVV      ",
      "                "
    ],
    [
      "                ",
      " pppppppppppppp ",
      " WX   p Y p   W ",
      " W    Z   p   W ",
      " W    pw0ww   W ",
      " p    p       p ",
      " 1ppp2p0ppppppp ",
      " 34 C      p  p ",
      " 3  5      5  p ",
      " 1ppC    ppp6pp ",
      " 3 7     p   h  ",
      " 3      8p   T  ",
      " 39     8p @Od  ",
      " 3#      pdddd  ",
      " 13WWWWW3p      ",
      "                "
    ],
    [
      "                ",
      " ppWWppWWppWWpp ",
      " W$   p   p  %W ",
      " W^   p   p  &W ",
      " W*   pwwww  (W ",
      " p    p       p ",
      " 1ppppppppppppp ",
      " W  C      p  W ",
      " W  C      p  W ",
      " 1ppC )  pppppp ",
      " 3       p   d  ",
      " W      +p   d  ",
      " W      +pR- d  ",
      " W [[]{{ pdd}\\  ",
      " 13WWWWW3p      ",
      "                "
    ],
    [
      "                ",
      " ppkkppkkppkkpp ",
      " 3    p   p   3 ",
      " 3    p   p   3 ",
      " 3    pwwww   3 ",
      " p    p       p ",
      " 1ppppppppppppp ",
      " 3  C      p  3 ",
      " 3  C      pf 3 ",
      " 1ppC f  pppppp ",
      " 3       p   }  ",
      " 3       p|  }  ",
      " 3       p-  }  ",
      " 3       peTTd  ",
      " 13333333p      ",
      "                "
    ],
    [
      "                ",
      " pppppppppppppp ",
      " pddddp```ddddp ",
      " pddddp```ddddp ",
      " pddddpdddddddp ",
      " pddddpdddddddp ",
      " pppppppppppppp ",
      " p``dddddddpddp ",
      " p``dddddddpddp ",
      " pdddddddpppppp ",
      " pdddddddpR  d  ",
      " pdddddddpc  d  ",
      " pdddddddp   d  ",
      " pdddddddpdddd  ",
      " ppppppppp      ",
      "                "
    ]
  ]
}