{
  "name": "building_hotel3_floor1",
  "refpalette": "c70cities:building_hotel3_floor1_palette",
  "xsize": 16,
  "zsize": 16,
  "slices": [
    [
      "                ",
      "  a a a a a a   ",
      "  bbbbbbbbbbbba ",
      " abccccddccccb  ",
      "  bceeeeeeeecba ",
      " abceffffffecb  ",
      "  bceffffffecba ",
      " abceffffffecb  ",
      "  bceffffffecba ",
      " abceffffffecb  ",
      "  bceffffffecba ",
      " abceeeeeeeecb  ",
      "  bccccccccccba ",
      " abbbbbbbbbbbb  ",
      "   a a a a a a  ",
      "                "
    ],
    [
      "                ",
      "  a a a a a a   ",
      "  bbbbbbbbbbbba ",
      " ab    dd    b  ",
      "  b eeeeeege ba ",
      " ab ehhhih e b  ",
      "  b ej hkl m ba ",
      " ab ej nhh m b  ",
      "  b e      m ba ",
      " ab eo pqr m b  ",
      "  b e spqr m ba ",
      " ab tmmmmmmt b  ",
      "  b          ba ",
      " abbbbbbbbbbbb  ",
      "   a a a a a a  ",
      "                "
    ],
    [
      "                ",
      "  a a a a a a   ",
      "  bbbbbbbbbbbba ",
      " ab    dd    b  ",
      "  b eeeeeeue ba ",
      " ab ew h h e b  ",
      "  b x  h y   ba ",
      " ab x   hh   b  ",
      "  b x        ba ",
      " ab x  p     b  ",
      "  b eAAp     ba ",
      " ab t      t b  ",
      "  b          ba ",
      " abbbbbbbbbbbb  ",
      "   a a a a a a  ",
      "                "
    ],
    [
      "                ",
      "  a a a a a a   ",
      "  bbbbbbbbbbbba ",
      " ab    dd    b  ",
      "  b eeeeeeee ba ",
      " ab e  h h e b  ",
      "  b e  h h   ba ",
      " ab e   hh   b  ",
      "  b e        ba ",
      " ab e  p     b  ",
      "  b e  p     ba ",
      " ab t      t b  ",
      "  b          ba ",
      " abbbbbbbbbbbb  ",
      "   a a a a a a  ",
      "                "
    ],
    [
      "                ",
      "  a a a a a a   ",
      "  bbbbbbbbbbbba ",
      " ab    dd    b  ",
      "  b eeeeeeee ba ",
      " ab eAAh h e b  ",
      "  b e  h h   ba ",
      " ab e   hh   b  ",
      "  b e        ba ",
      " ab e  !     b  ",
      "  b e        ba ",
      " ab t      t b  ",
      "  b          ba ",
      " abbbbbbbbbbbb  ",
      "   a a a a a a  ",
      "                "
    ],
    [
      "                ",
      "  a a a a a a   ",
      "  bbbbbbbbbbbba ",
      " ab    dd    b  ",
      "  b eeeeeeee ba ",
      " ab eBBBBBBe b  ",
      "  b eBBBBBBe ba ",
      " ab eBBBBBBe b  ",
      "  b eBBBBBBe ba ",
      " ab eBBBBBBe b  ",
      "  b eBBBBBBe ba ",
      " ab eeeeeeee b  ",
      "  b          ba ",
      " abbbbbbbbbbbb  ",
      "   a a a a a a  ",
      "                "
    ]
  ]
}