{
  "name": "building_hotel3_base2",
  "refpalette": "c70cities:building_hotel3_base2_palette",
  "xsize": 16,
  "zsize": 16,
  "slices": [
    [
      "aaaaaaaaaaaaaaaa",
      "abcbbbbb!bbbbbba",
      "abbbbbbbbbbbcbba",
      "abbbbbbbbbbbbbba",
      "abbbdeeeeeedbbba",
      "acbbeeeeeeeebbba",
      "acbbeeeeeeeebbba",
      "abbbeeeeeeeebbba",
      "abbbeeeeeeeebbca",
      "abbbeeeeeeeebbba",
      "acbbeeeeeeeebbba",
      "abbfdeeeeeedbbba",
      "abbbbbbbbbbbbbba",
      "abbbbbbbbbbbbbba",
      "abbbbcbfbbbbcbba",
      "aaaaaaaaaaaaaaaa"
    ],
    [
      "aaaaaaaaaaaaaaaa",
      "aghijggjigigggga",
      "aiiiiigiiijihgga",
      "aiiiiiiiiiiijgga",
      "aggidkkddkkdijga",
      "ahiik  ll  kijia",
      "ahiik m  n kiiga",
      "aijik o  p kiiia",
      "aiiikko  p kijha",
      "aggikqr  s kiiga",
      "ahiiktk    kiija",
      "aiiidkkkkkkdijga",
      "agiiiiiiiijiiiga",
      "afgigiijijijigga",
      "agggihgigggghgga",
      "aaaaaaaaaaaaaaaa"
    ],
    [
      "aaaaaaaaaaaaaaaa",
      "aihijigjiiigjgga",
      "aiiiiijiiijihgga",
      "aiiiiiiiiiiijiga",
      "ajiidkkddkkdijga",
      "ahiik  ll  kijia",
      "ahiik      kiija",
      "aijik      kiiia",
      "aiiik      kijha",
      "ajiik      kiiia",
      "ahiikt     kiija",
      "aiiidkkkkkkdijia",
      "ajiiiiiiiijiiiia",
      "aiiiiiijijijijga",
      "ajjiihjiiggihgga",
      "aaaaaaaaaaaaaaaa"
    ],
    [
      "aaaaaaaaaaaaaaaa",
      "aihiuiuuiiiiuwga",
      "aiiiiiuiiiuihuga",
      "aiiiiiiiiiiiuiga",
      "auiidkkddkkdiuua",
      "ahiik  ll  kiuia",
      "ahiik      kiiua",
      "aiuik      kiiia",
      "aiiik      kiuha",
      "auiik      kiiia",
      "ahiiqx     kiiua",
      "aiiidkkkkkkdiuia",
      "auiiiiiiiiuiiiia",
      "aiiiiiiuiuiuiuua",
      "auuiihuiiugihiga",
      "aaaaaaaaaaaaaaaa"
    ],
    [
      "aaaaaaaaaaaaaaaa",
      "a             ga",
      "a              a",
      "a              a",
      "a   dkkddkkd   a",
      "a   k  ll  k   a",
      "a   k      k   a",
      "a   k      k   a",
      "a   k      k   a",
      "a          k   a",
      "a          k   a",
      "a   dkkkkkkd   a",
      "a              a",
      "a              a",
      "a              a",
      "aaaaaaaaaaaaaaaa"
    ],
    [
      "aaaaaaaaaaaaaaaa",
      "ayyyyyyyyyyyyyya",
      "ayyyyyyyyyyyyyya",
      "ayyyyyyyyyyyyyya",
      "ayyydAAddAAdyyya",
      "ayyyAAAllAAAyyya",
      "ayyyAAAAAAAAyyya",
      "ayyyAAAAAAAAyyya",
      "ayyyAAAAAAAAyyya",
      "ayyyAAAAAAAAyyya",
      "ayyyAAAAAAAAyyya",
      "ayyydAAAAAAdyyya",
      "ayyyyyyyyyyyyyya",
      "ayyyyyyyyyyyyyya",
      "ayyyyyyyyyyyyyya",
      "aaaaaaaaaaaaaaaa"
    ]
  ]
}