{
  "name": "building_carservice1_base1",
  "refpalette": "c70cities:building_carservice1_base1_palette",
  "xsize": 16,
  "zsize": 16,
  "slices": [
    [
      "vvvvvvvvvvvvvvvv",
      "vaaaaaaaaaaaaaav",
      "vaaaaaaaaaaaaaav",
      "vaaaaaaaaaaaaaav",
      "vaaaaaaaaaaaaaav",
      "vaaaaaaaaaaaaaav",
      "vaaaaaaaaaaaaaav",
      "vaaaaaaaaaaaaaav",
      "vaaaaaaaaaaaaaav",
      "vaaaaaaaa!aaaaav",
      "va==aaaaaaaaaaav",
      "va==aaaaaaaaaaav",
      "va==aaaaaaaaaaav",
      "va==aaaaaaaaaaav",
      "vaaaaaaaaaaaaaav",
      "vvvvvvvvvvvvvvvv"
    ],
    [
      "vvvvvvvvvvvvvvvv",
      "vvvvvvvvvbbbbbbv",
      "vvvvvvvvvb    bv",
      "vvvvvvvvvb cccbv",
      "vv===dd !befcfbv",
      "vv===d  db cgcbv",
      "vv==bb  bb cccbv",
      "vv==b    hefcfbv",
      "vv==b   ih cccbv",
      "vvjjb  kkb lmlbv",
      "vv  n         bv",
      "vv  n         bv",
      "vv  n    o    bv",
      "vvp b qq orsstbv",
      "vvvvbbbbbubbbbbv",
      "vvvvvvvvvvvvvvvv"
    ],
    [
      "vvvvvvvvvvvvvvvv",
      "vvvvvvvvvbbbbbbv",
      "vvvvvvvvvb    bv",
      "vvvvvvvvvb wwwbv",
      "vv===   db xyxbv",
      "vv===    b A Abv",
      "vv==bb  bb AAAbv",
      "vvjjb    h BCBbv",
      "vv  b    h BDBbv",
      "vv  b    b    bv",
      "vv  n         bv",
      "vv  n         bv",
      "vv  n    o    bv",
      "vvp b    o    bv",
      "vvvvbbbbbubbbbbv",
      "vvvvvvvvvvvvvvvv"
    ],
    [
      "vvvvvvvvvvvvvvvv",
      "vvvvvvvvvbbbbbbv",
      "vvvvvvvvvb    bv",
      "vvvvvvvvvb    bv",
      "vvjj=    b  D bv",
      "vvjj=    b BCBbv",
      "vv  bbbbbb BDBbv",
      "vv  b    h    bv",
      "vv  b    h    bv",
      "vv  b    b    bv",
      "vv  n         bv",
      "vv  n         bv",
      "vv  n    o    bv",
      "vvppb    o    bv",
      "vvvvbbbbbubbbbbv",
      "vvvvvvvvvvvvvvvv"
    ],
    [
      "vvvvvvvvvvvvvvvv",
      "vvvvvvvvvbbbbbbv",
      "vvvvvvvvvb    bv",
      "vvvvvvvvvb    bv",
      "vv   j===b    bv",
      "vv   j===b    bv",
      "vv  bbbbbb    bv",
      "vv  b    b    bv",
      "vv  b    b    bv",
      "vv  b    b    bv",
      "vv  b    b    bv",
      "vv  b    b    bv",
      "vv  b    b    bv",
      "vvppb    b    bv",
      "vvvvbbbbbbbbbbbv",
      "vvvvvvvvvvvvvvvv"
    ],
    [
      "vvvvvvvvvvvvvvvv",
      "vvvvvvvvvbbbbbbv",
      "vvvvvvvvvbEFF bv",
      "vvvvvvvvvbFFFFbv",
      "vv     j=bFFFFbv",
      "vv     j=bFFFFbv",
      "vv  bbbbbbFFFFbv",
      "vvIIbFFFFbEFFJbv",
      "vvIIbFFFFbFFFFbv",
      "vvIIbFFFFbFFFFbv",
      "vvIIbFFFFbFFFFbv",
      "vvIIbFFFFbFFFFbv",
      "vvIIbFFFFbFFFFbv",
      "vvIIbFFFFb FFEbv",
      "vvvvbbbbbbbbbbbv",
      "vvvvvvvvvvvvvvvv"
    ]
  ]
}