{
  "name": "building_apartment1_ground_270",
  "refpalette": "c70cities:building_apartment1_ground_palette_270",
  "xsize": 16,
  "zsize": 16,
  "slices": [
    [
      "GGGGGGGGGGGGGGGG",
      "GaaaaaaaaaaaaaaG",
      "GaaaaaaaaaaaaaaG",
      "GaaaaaaaaaaaaaaG",
      "GaaaaaaaaaaaaaaG",
      "GaaaaaaaaaaaaaaG",
      "GaaaaaaaaaaaaaaG",
      "GaaaaaaaaaaaaaaG",
      "GaaaaaaaaaaaaaaG",
      "GaaaaaaaaaaaaaaG",
      "GaaaaaaaaaaaaaaG",
      "GaaaaaaaaaaaaaaG",
      "GaaaaaaaaaaaaaaG",
      "GaaaaaaaaaaaaaaG",
      "GaaaaaaaaaaaaaaG",
      "GGGGGGGGGGGGGGGG"
    ],
    [
      "                ",
      " dddddqxtqbdddb ",
      " d   pruurp   b ",
      " d ID        ec ",
      " d  D        fc ",
      " d ID      nggc ",
      " d DD   w bbbbc ",
      " d         b hc ",
      " Kp        o ic ",
      " bbbEBb    bbbc ",
      "  J   b   kkk c ",
      "  J   by sllljc ",
      "  CrF bA sllljc ",
      "  CCCCbp  mmm b ",
      "      bdddddddb ",
      "                "
    ],
    [
      "                ",
      " dddddqONqbdddb ",
      " d   pr  rp   b ",
      " d            b ",
      " d            b ",
      " d  R        gb ",
      " d        bbbbb ",
      " d         b  b ",
      " Kp        M Lb ",
      " bbbSPb    bbbb ",
      "  C   b       b ",
      "  CT  b       b ",
      "  CF  b       b ",
      "  CCJQbp      b ",
      "      bdddddddb ",
      "                "
    ],
    [
      "                ",
      " dddddqVVqbdddb ",
      " d    r  r    b ",
      " d            d ",
      " d            d ",
      " d            b ",
      " d        bbbbb ",
      " d         b  d ",
      " K         U  d ",
      " bbbWWb    bbbb ",
      "  Cr  b       b ",
      "  CX  b       d ",
      "  Y   b       d ",
      "  ZCCCb       b ",
      "      bdddddddb ",
      "                "
    ],
    [
      "                ",
      " qKKKKq  qbKKKb ",
      " K    rrrr    b ",
      " K            c ",
      " K            c ",
      " K            b ",
      " K        bbbbb ",
      " K         b  c ",
      " K         b  c ",
      " bbbbbbbbbbbbbb ",
      "  1X0 b       b ",
      "  J   b       c ",
      "  J   b       c ",
      "  CYYYb       b ",
      "      bKKKKKKKb ",
      "                "
    ],
    [
      "                ",
      " bbbbbbbbbbbbbb ",
      " bCCCCCCCCCCCCb ",
      " bCCCCCCCCCCCCb ",
      " bCCCCCCCCCCCCb ",
      " bCCCCCw!CCCCCb ",
      " bCCCCC43Cbbbbb ",
      " bCCCCCCCCCb22b ",
      " bCCCCCCCCCb22b ",
      " bbbbbbbbbbbbbb ",
      "  C 5rbCCCCCCCb ",
      "  C   bCCCCCCCb ",
      "  C   bCCCCCCCb ",
      "  CCCCbCCCCCCCb ",
      "      bbbbbbbbb ",
      "                "
    ]
  ]
}