{
  "name": "building_office1_floor1",
  "refpalette": "c70cities:building_office1_floor1_palette",
  "xsize": 16,
  "zsize": 16,
  "slices": [
    [
      "                ",
      "                ",
      "  aaaaaaaaaaaa  ",
      "  abbbbbbbbbba  ",
      "  abbbbbbbbbba  ",
      "  abbbbbbbbbba  ",
      "  abbbbbbbbbba  ",
      "  abbbbbbbbbba  ",
      " ccbbbbbbbbbbcc ",
      "  dbbbbbbbbbbd  ",
      "  dbbbbbbbbbbd  ",
      " efgbbbbbbbbbfe ",
      " ebbbbbbbb!bbbe ",
      " ebbbbbbbbbbbbe ",
      " eeeeeeeeeeeeee ",
      "                "
    ],
    [
      "                ",
      "                ",
      "  hhhhhhhhhhhh  ",
      "  h          h  ",
      "  h  i i i   h  ",
      "  h j k  k l h  ",
      "  h   m m m  h  ",
      "  h         nh  ",
      " ccfopfffffffcc ",
      "  d    f     d  ",
      "  d    q     d  ",
      " rfg  sfi i  fr ",
      " rt   ufwww  xr ",
      " rt   yf A   xr ",
      " rrrrrrrrrrrrrr ",
      "                "
    ],
    [
      "                ",
      "                ",
      "  hhhhhhhhhhhh  ",
      "  h          h  ",
      "  h          h  ",
      "  h  BBBBBB  h  ",
      "  h          h  ",
      "  h          h  ",
      " ccfCDfffffffcc ",
      "  d    f     d  ",
      "  d    E     d  ",
      " rfg   f     fr ",
      " rt    fFIJ  Kr ",
      " rt    f      r ",
      " rrLddddddddLrr ",
      "                "
    ],
    [
      "                ",
      "                ",
      "  hhhhhhhhhhhh  ",
      "  h          h  ",
      "  h          h  ",
      "  h          h  ",
      "  h          h  ",
      "  h          h  ",
      " ccffffffffffcc ",
      "  d    f     d  ",
      "  d    f     d  ",
      " rfg   f     fr ",
      " rt    f      r ",
      " rt    f      r ",
      " rrLddddddddLrr ",
      "                "
    ],
    [
      "                ",
      "                ",
      "  hhhhhhhhhhhh  ",
      "  h          h  ",
      "  h          h  ",
      "  h          h  ",
      "  h          h  ",
      "  h          h  ",
      " ccffffffffffcc ",
      "  d    f     d  ",
      "  d    f     d  ",
      " rfg   f     fr ",
      " rM    f      r ",
      " rM    f      r ",
      " rrrrrrrrrrrrrr ",
      "                "
    ],
    [
      "                ",
      "                ",
      "  hhhhhhhhhhhh  ",
      "  hLLLLLLLLLLh  ",
      "  hLLLLLLLLLLh  ",
      "  hLLLLLLLLLLh  ",
      "  hLLLLLLLLLLh  ",
      "  hLLLLLLLLLLh  ",
      " ccffffffffffcc ",
      "  d LLLfLLLL d  ",
      "  d LLLfLLLL d  ",
      " rfgLLLfLLLL fr ",
      " rLLLLLfLLLLLLr ",
      " rLLLLLfLLLLLLr ",
      " rrrrrrrrrrrrrr ",
      "                "
    ]
  ]
}