{
  "name": "building_carservice1_base1_90",
  "refpalette": "c70cities:building_carservice1_base1_palette_90",
  "xsize": 16,
  "zsize": 16,
  "slices": [
    [
      "vvvvvvvvvvvvvvvv",
      "vaaaaaaaaaaaaaav",
      "vaaaaaaaaaaaaaav",
      "vaaaaaaaaaaaaaav",
      "vaaaaaaaaaaaaaav",
      "vaaaaaaaaaaaaaav",
      "vaaaaaaaa!aaaaav",
      "vaaaaaaaaaaaaaav",
      "vaaaaaaaaaaaaaav",
      "vaaaaaaaaaaaaaav",
      "vaaaaaaaaaaaaaav",
      "vaaaaaaaaaaaaaav",
      "vaaaaaaaaa====av",
      "vaaaaaaaaa====av",
      "vaaaaaaaaaaaaaav",
      "vvvvvvvvvvvvvvvv"
    ],
    [
      "vvvvvvvvvvvvvvvv",
      "vbbbbbbbbbbbbbbv",
      "vb cfccfcl   tbv",
      "vb ccgcccm   sbv",
      "vb cfccfcl   sbv",
      "vb  e  e     rbv",
      "vbbbbbbhhb  oouv",
      "vvvv!db ik    bv",
      "vvvv     k   qbv",
      "vvvvd        qbv",
      "vvvvddb       bv",
      "vvvv==bbbbnnnbbv",
      "vvvv=====j    vv",
      "vvvv=====j   pvv",
      "vvvvvvvvvvvvvvvv",
      "vvvvvvvvvvvvvvvv"
    ],
    [
      "vvvvvvvvvvvvvvvv",
      "vbbbbbbbbbbbbbbv",
      "vb wxAABB     bv",
      "vb wy ACD     bv",
      "vb wxAABB     bv",
      "vb            bv",
      "vbbbbbbhhb  oouv",
      "vvvvd b       bv",
      "vvvv          bv",
      "vvvv          bv",
      "vvvv  b       bv",
      "vvvv==bbbbnnnbbv",
      "vvvv===j      vv",
      "vvvv===j     pvv",
      "vvvvvvvvvvvvvvvv",
      "vvvvvvvvvvvvvvvv"
    ],
    [
      "vvvvvvvvvvvvvvvv",
      "vbbbbbbbbbbbbbbv",
      "vb   BB       bv",
      "vb  DCD       bv",
      "vb   BB       bv",
      "vb            bv",
      "vbbbbbbhhb  oouv",
      "vvvv  b       bv",
      "vvvv  b       bv",
      "vvvv  b       bv",
      "vvvv  b       bv",
      "vvvv==bbbbnnnbbv",
      "vvvvjj       pvv",
      "vvvvjj       pvv",
      "vvvvvvvvvvvvvvvv",
      "vvvvvvvvvvvvvvvv"
    ],
    [
      "vvvvvvvvvvvvvvvv",
      "vbbbbbbbbbbbbbbv",
      "vb            bv",
      "vb            bv",
      "vb            bv",
      "vb            bv",
      "vbbbbbbbbbbbbbbv",
      "vvvv==b       bv",
      "vvvv==b       bv",
      "vvvv==b       bv",
      "vvvvjjb       bv",
      "vvvv  bbbbbbbbbv",
      "vvvv         pvv",
      "vvvv         pvv",
      "vvvvvvvvvvvvvvvv",
      "vvvvvvvvvvvvvvvv"
    ],
    [
      "vvvvvvvvvvvvvvvv",
      "vbbbbbbbbbbbbbbv",
      "vb FFFFJFFFFFEbv",
      "vbFFFFFFFFFFFFbv",
      "vbFFFFFFFFFFFFbv",
      "vbEFFFFEFFFFF bv",
      "vbbbbbbbbbbbbbbv",
      "vvvv==bFFFFFFFbv",
      "vvvvjjbFFFFFFFbv",
      "vvvv  bFFFFFFFbv",
      "vvvv  bFFFFFFFbv",
      "vvvv  bbbbbbbbbv",
      "vvvv   IIIIIIIvv",
      "vvvv   IIIIIIIvv",
      "vvvvvvvvvvvvvvvv",
      "vvvvvvvvvvvvvvvv"
    ]
  ]
}