{
  "name": "building_residential4_floor1_90",
  "refpalette": "c70cities:building_residential4_floor1_palette_90",
  "xsize": 16,
  "zsize": 16,
  "slices": [
    [
      "                ",
      "   ab      no   ",
      "   accc  ccco   ",
      "   adddiidddo   ",
      "   ae    l  o   ",
      "   aefhj l  o   ",
      "   ae g  l  o   ",
      "   ae    l  o   ",
      "   ae    k  o   ",
      "   ae     mmo   ",
      "   ae       o   ",
      "   ae       o   ",
      "   adddiidddo   ",
      "   accc  ccco   ",
      "   ab      no   ",
      "                "
    ],
    [
      "                ",
      "    ab    no    ",
      "    accuucco    ",
      "    addiiddo    ",
      "    ab   lxo    ",
      "   qtb   lwo    ",
      "    eb   l o    ",
      "    s    l o    ",
      "    s    l o    ",
      "    eb    mo    ",
      "   prb     o    ",
      "    ab     o    ",
      "    addiiddo    ",
      "    accuucco    ",
      "    ab    no    ",
      "                "
    ],
    [
      "                ",
      "     ab  no     ",
      "     acccco     ",
      "     addddo     ",
      "     ab  no     ",
      "     ab  no     ",
      "   qqtb  no     ",
      "    eyb  no     ",
      "    eyb  no     ",
      "   pprb  no     ",
      "     ab  no     ",
      "     ab  no     ",
      "     addddo     ",
      "     acccco     ",
      "     ab  no     ",
      "                "
    ],
    [
      "                ",
      "      abno      ",
      "      acco      ",
      "      addo      ",
      "      a  o      ",
      "      a  o      ",
      "      a  o      ",
      "   qqqB  o      ",
      "   pppA  o      ",
      "      a  o      ",
      "      a  o      ",
      "      a  o      ",
      "      addo      ",
      "      acco      ",
      "      abno      ",
      "                "
    ],
    [
      "                ",
      "       ao       ",
      "       ao       ",
      "       ao       ",
      "       ao       ",
      "       ao       ",
      "       ao       ",
      "       ao       ",
      "       ao       ",
      "       ao       ",
      "       ao       ",
      "       ao       ",
      "       ao       ",
      "       ao       ",
      "       ao       ",
      "                "
    ],
    [
      "                ",
      "                ",
      "                ",
      "                ",
      "                ",
      "                ",
      "                ",
      "       ~~       ",
      "        ~       ",
      "                ",
      "                ",
      "                ",
      "                ",
      "                ",
      "                ",
      "                "
    ]
  ]
}