{
  "name": "building_hotel1_floor2_90",
  "refpalette": "c70cities:building_hotel1_floor2_palette_90",
  "xsize": 16,
  "zsize": 16,
  "slices": [
    [
      "                ",
      " aaaaaaaaffffaa ",
      " abbbcbbbbbbbba ",
      " abbbcbbbbbbbbg ",
      " abbbcbbbbbbbbg ",
      " abbbcdbbbbbbbg ",
      " abbbc   ecccbg ",
      " abbbc    cbbbg ",
      " abbbc    cbbba ",
      " abbbc    cbbba ",
      " abbbccccccbbba ",
      " abbbbbbbbbbbba ",
      " abbbbbbbbbbbba ",
      " abbbbbbbbbbbba ",
      " aaaaadddddddaa ",
      "                "
    ],
    [
      "                ",
      " aaaaaaaaffffaa ",
      " a   a  n    na ",
      " al  t      Eea ",
      " a   a      Eea ",
      " a  os ww   eea ",
      " ak pa   daaaaa ",
      " aj qa   eaADFa ",
      " aj qa   eayC a ",
      " ai pa    aff a ",
      " a  osaaaas   a ",
      " a   r=uu=axB a ",
      " ahn      axB a ",
      " a m          a ",
      " aaaaaaaaaaaaaa ",
      "                "
    ],
    [
      "                ",
      " aaaaaaaaffffaa ",
      " a   a  M    Ma ",
      " a   K        a ",
      " a   a        a ",
      " a  os        a ",
      " a   a    aaaaa ",
      " a  Ja    a   f ",
      " a   a   da   f ",
      " a   a  eeaff f ",
      " a  osaaaas   f ",
      " a    L  Na   f ",
      " a I      a   f ",
      " a            a ",
      " aaaaaffffaaaaa ",
      "                "
    ],
    [
      "                ",
      " aaaaaaaaffffaa ",
      " a   a  M    Ma ",
      " a   a        a ",
      " a   a        a ",
      " aO  s        a ",
      " a   a    aaaaa ",
      " a   a    a   a ",
      " a   a    a   a ",
      " a   aeed aff a ",
      " aO  saaaasO  a ",
      " a     EE a   a ",
      " a        a   a ",
      " a        a   a ",
      " aaaaaaaaaaaaaa ",
      "                "
    ],
    [
      "                ",
      " aaaaaaaaffffaa ",
      " a   a        a ",
      " a   a        a ",
      " a   a        a ",
      " aP  s        a ",
      " a   a    aaaaa ",
      " a   ae   a   f ",
      " a   ae   a   f ",
      " a   ad   afffa ",
      " aP  saaaasP  a ",
      " a        a   a ",
      " a        a   a ",
      " a        a   a ",
      " aaffaaaaaaaaaa ",
      "                "
    ],
    [
      "                ",
      " aaaaaaaaffffaa ",
      " aQQQaQQQQQQQQa ",
      " aQQQaQQQQQQQQa ",
      " aQQQaQQQQQQQQa ",
      " aQQQsQQQQQQQQa ",
      " aQQQae   aaaaa ",
      " aQQQad   aQQQa ",
      " aQQQa    aQQQa ",
      " aQQQa    aQQQa ",
      " aQQQsaaaasQQQa ",
      " aQQQQQQQQQQQQa ",
      " aQQQQQQQQQQQQa ",
      " aQQQQQQQQQQQQa ",
      " aaaaaaaaaaaaaa ",
      "                "
    ]
  ]
}