{
  "name": "building_office3_ground_90",
  "refpalette": "c70cities:building_office3_ground_palette_90",
  "xsize": 16,
  "zsize": 16,
  "slices": [
    [
      "GGGGGGGGGGGGGGGG",
      "GaaaaaaaaaaaaaaG",
      "GabbbbbbbbbbbbaG",
      "GabbbbbbbbbbbbaG",
      "GabbbbbbbbbbbbaG",
      "GabbbbbbbbbbbbaG",
      "GabbbbbbbbbbbbaG",
      "GabbbbbbbbbbbbaG",
      "GabbbbbbbbbbbbaG",
      "GabbbbbbbbbbbbaG",
      "GabbbbbbbbbbbbaG",
      "GabbbbbbbbbbbbaG",
      "Gab!bbbbbbbbbbaG",
      "GabbbbbbbbbbbbaG",
      "GaaaaaaaaaaaaaaG",
      "GGGGGGGGGGGGGGGG"
    ],
    [
      "                ",
      " ccdccdjkdccdcc ",
      " ceeeef  feeeec ",
      " deg        ged ",
      " ce          ec ",
      " ce          ec ",
      " df          fd ",
      " ce    ii    ec ",
      " ce    vv    ec ",
      " df    h     fd ",
      " ce          ec ",
      " ce          ec ",
      " deg        ged ",
      " ceeeefeefeeeec ",
      " ccdccdccdccdcc ",
      "                "
    ],
    [
      "                ",
      " ccdccdmndccdcc ",
      " c    l  l    c ",
      " d g        g d ",
      " c            c ",
      " c            c ",
      " dl          ld ",
      " c     ii     c ",
      " c     vv     c ",
      " dl          ld ",
      " c            c ",
      " c            c ",
      " d g        g d ",
      " c    l  l    c ",
      " ccdccdccdccdcc ",
      "                "
    ],
    [
      "                ",
      " oodoodoodoodoo ",
      " o            o ",
      " d g        g d ",
      " o            o ",
      " o            o ",
      " d            d ",
      " o     ii     o ",
      " o     vv     o ",
      " d            d ",
      " o            o ",
      " o            o ",
      " d g        g d ",
      " o            o ",
      " oodoodoodoodoo ",
      "                "
    ],
    [
      "                ",
      " ccdccdccdccdcc ",
      " cppppppppppppc ",
      " dpg        gpd ",
      " cp          pc ",
      " cp          pc ",
      " dp          pd ",
      " cp    ii    pc ",
      " cp    vv    pc ",
      " dp          pd ",
      " cp          pc ",
      " cp          pc ",
      " dpg        gpd ",
      " cppppppppppppc ",
      " ccdccdccdccdcc ",
      "                "
    ],
    [
      "                ",
      " qqqqqqqqqqqqqq ",
      " qaaaaaaaaaaaaq ",
      " qarddddddddraq ",
      " qaddddddddddaq ",
      " qaddddddddddaq ",
      " qaddddddddddaq ",
      " qaddddiiddddaq ",
      " qaddddvvddddaq ",
      " qaddddddddddaq ",
      " qaddddddddddaq ",
      " qaddddddddddaq ",
      " qarddddddddraq ",
      " qaaaaaaaaaaaaq ",
      " qqqqqqqqqqqqqq ",
      "                "
    ]
  ]
}