{
  "name": "building_office4_floor3",
  "refpalette": "c70cities:building_office4_floor3_palette",
  "xsize": 16,
  "zsize": 16,
  "slices": [
    [
      "                ",
      "    abaaaaba    ",
      "  cccdeeeedccc  ",
      "  ceeeeeeeeeec  ",
      " aceeeeeeeeeeca ",
      " bdeeeeeeeeeedb ",
      " aeeeeeeeeeeeea ",
      " afeeeeeeeeeeea ",
      " afeeeeeeeeeeea ",
      " aeee!eeeeeeeea ",
      " bdeeeeeeeeeedb ",
      " aceeeeeeeeeeca ",
      "  ceeeeeeeeeec  ",
      "  cccdeeeedccc  ",
      "    abaaaaba    ",
      "                "
    ],
    [
      "                ",
      "    abaaaaba    ",
      "  gggdhihhdggg  ",
      "  g          g  ",
      " ag          ga ",
      " bd          db ",
      " a   j j j    a ",
      " af   k  k l  a ",
      " af   k  k l  a ",
      " a   m m m    a ",
      " bd          db ",
      " ag          ga ",
      "  g          g  ",
      "  gggdnnondggg  ",
      "    abaaaaba    ",
      "                "
    ],
    [
      "                ",
      "    abaaaaba    ",
      "  gggd    dggg  ",
      "  g          g  ",
      " ag          ga ",
      " bd          db ",
      " a            a ",
      " af  pppppp   a ",
      " af  pppppp   a ",
      " a            a ",
      " bd          db ",
      " ag          ga ",
      "  g          g  ",
      "  gggd    dggg  ",
      "    abaaaaba    ",
      "                "
    ],
    [
      "                ",
      "    abaaaaba    ",
      "  gggd    dggg  ",
      "  g          g  ",
      " ag          ga ",
      " bd          db ",
      " a            a ",
      " af           a ",
      " af           a ",
      " a            a ",
      " bd          db ",
      " ag          ga ",
      "  g          g  ",
      "  gggd    dggg  ",
      "    abaaaaba    ",
      "                "
    ],
    [
      "                ",
      "    abaaaaba    ",
      "  gggd    dggg  ",
      "  g          g  ",
      " ag          ga ",
      " bd          db ",
      " a            a ",
      " af           a ",
      " af           a ",
      " a            a ",
      " bd          db ",
      " ag          ga ",
      "  g          g  ",
      "  gggd    dggg  ",
      "    abaaaaba    ",
      "                "
    ],
    [
      "                ",
      "    abaaaaba    ",
      "  gggdqqqqdggg  ",
      "  gqqqqqqqqqqg  ",
      " agqqqqqqqqqqga ",
      " bdqqqqqqqqqqdb ",
      " aqqqqqqqqqqqqa ",
      " afqqqqqqqqqqqa ",
      " afqqqqqqqqqqqa ",
      " aqqqqqqqqqqqqa ",
      " bdqqqqqqqqqqdb ",
      " agqqqqqqqqqqga ",
      "  gqqqqqqqqqqg  ",
      "  gggdqqqqdggg  ",
      "    abaaaaba    ",
      "                "
    ]
  ]
}