{
  "name": "building_policeoffice1_ground",
  "refpalette": "c70cities:building_policeoffice1_ground_palette",
  "xsize": 16,
  "zsize": 16,
  "slices": [
    [
      "GGGGGGGGGGGGGGGG",
      "GGaaaaaaaaaaGHHH",
      "GGabbbbbbbbaGHHH",
      "GGabbbbbbbbaGHHH",
      "GGabbbbbbbbaGHHH",
      "GGabbbb!bbbaGHHH",
      "GGabbbbbbbbaGGGG",
      "GGabbbbbbbbaccGc",
      "GGabbbbbbbbacccG",
      "GGabbbbbbbbaGGGG",
      "GGabbbbbbbbaGdGG",
      "Geebbbbbbbbeeeee",
      "GefbbbbbbbbbGGGe",
      "GefbbbbbbbbbgGGe",
      "Geeeeeeeeeeeeeee",
      "GGGGGGGGGgGGGgGG"
    ],
    [
      "                ",
      " haaaaaaaaaa    ",
      " hai jjjj ia    ",
      " ha        a    ",
      " ha  k  k  a    ",
      " ha  llll ma    ",
      " ha        a    ",
      " ha        n    ",
      " ha        o    ",
      " ha        a    ",
      " ha       mahhhh",
      " eepqa     eeree",
      " ef  astt  u   e",
      " ef  asssw ut  e",
      " exeeexeeeye  ye",
      "         t   e  "
    ],
    [
      "                ",
      "  aauaaaauaa    ",
      "  ai jjjj ia    ",
      "  a        u    ",
      "  a        u    ",
      "  a       Aa    ",
      "  a        a    ",
      "  a        B    ",
      "  a        C    ",
      "  a        a    ",
      "  a       Aa    ",
      " eeDEa     eeree",
      " ef  a         e",
      " ef  a         e",
      " exeeexeeey   xe",
      "                "
    ],
    [
      "                ",
      "  aauaaaauaa    ",
      "  ai j  j ia    ",
      "  a        a    ",
      "  a        a    ",
      "  a       Aa    ",
      "  a        a    ",
      "  a        a    ",
      "  a        a    ",
      "  a        a    ",
      "  a       Aa    ",
      " eeaaa     eeree",
      " ef  s         e",
      " ef  a         e",
      " exeeexeeexe yxe",
      "                "
    ],
    [
      "                ",
      "  aaaaaaaaaa    ",
      "  a  jjjj  a    ",
      "  a        a    ",
      "  a        u    ",
      "  a        u    ",
      "  a        u    ",
      "  a        u    ",
      "  a        a    ",
      "  a        a    ",
      "  a        a    ",
      " eeaaa     eeree",
      " ef  a         e",
      " ef  a         e",
      " exeeexeeexeyexe",
      "                "
    ],
    [
      "                ",
      "  FFFFFFFFFF    ",
      "  FIIIIIIIIF    ",
      "  FIIIIIIIIF    ",
      "  FIIIIIIIIF    ",
      "  FIIIIIIIIF    ",
      "  FIIIIIIIIF    ",
      "  FIIIIIIIIF    ",
      "  FIIIIIIIIF    ",
      "  FIIIIIIIIF    ",
      "  FIIIIIIIIF    ",
      " eeaaaIIIIIeeree",
      " efIIaIIIIII   e",
      " efIIaIIIIII   e",
      " exeeexeeexeeexe",
      "                "
    ]
  ]
}