{
  "name": "building_office4_floor2_270",
  "refpalette": "c70cities:building_office4_floor2_palette_270",
  "xsize": 16,
  "zsize": 16,
  "slices": [
    [
      "                ",
      "    abaaaaba    ",
      "  cccdeffedccc  ",
      "  ceeeeeeeeeec  ",
      " aceeeeeeeeeeca ",
      " bdeeeeeeeeeedb ",
      " aeeeeeeeeeeeea ",
      " aeeeeeeeeeeeea ",
      " aeeeeeeeeeeeea ",
      " aeeeeeeeeeeeea ",
      " bdeeeeeeeeeedb ",
      " aceeeeeeeeeeca ",
      "  ceeeeeeeeeec  ",
      "  cccdeeeedccc  ",
      "    abaaaaba    ",
      "                "
    ],
    [
      "                ",
      "    abaaaaba    ",
      "  gggd ff dggg  ",
      "  g          g  ",
      " ag   jllj   ga ",
      " bd    dd    db ",
      " a  h      h  a ",
      " a  iii  iii  a ",
      " a    k  k    a ",
      " a  h      h  a ",
      " bd iii  iii db ",
      " ag   k  k   ga ",
      "  g          g  ",
      "  gggd    dggg  ",
      "    abaaaaba    ",
      "                "
    ],
    [
      "                ",
      "    abaaaaba    ",
      "  gggd ff dggg  ",
      "  g          g  ",
      " ag   j  j   ga ",
      " bd    dd    db ",
      " am          ma ",
      " am          ma ",
      " am          ma ",
      " am          ma ",
      " bd          db ",
      " ag          ga ",
      "  g          g  ",
      "  gggd    dggg  ",
      "    abaaaaba    ",
      "                "
    ],
    [
      "                ",
      "    abaaaaba    ",
      "  gggd ff dggg  ",
      "  g          g  ",
      " ag   j  j   ga ",
      " bd    dd    db ",
      " a            a ",
      " a            a ",
      " a            a ",
      " a            a ",
      " bd          db ",
      " ag          ga ",
      "  g          g  ",
      "  gggd    dggg  ",
      "    abaaaaba    ",
      "                "
    ],
    [
      "                ",
      "    abaaaaba    ",
      "  gggd ff dggg  ",
      "  g          g  ",
      " ag   j  j   ga ",
      " bd    dd    db ",
      " a            a ",
      " a            a ",
      " a            a ",
      " a            a ",
      " bd          db ",
      " ag          ga ",
      "  g          g  ",
      "  gggd    dggg  ",
      "    abaaaaba    ",
      "                "
    ],
    [
      "                ",
      "    abaaaaba    ",
      "  gggdnffndggg  ",
      "  gnnnnnnnnnng  ",
      " agnnnnnnnnnnga ",
      " bdnnn!ddnnnndb ",
      " annnnnnnnnnnna ",
      " annnnnnnnnnnna ",
      " annnnnnnnnnnna ",
      " annnnnnnnnnnna ",
      " bdnnnnnnnnnndb ",
      " agnnnnnnnnnnga ",
      "  gnnnnnnnnnng  ",
      "  gggdnnnndggg  ",
      "    abaaaaba    ",
      "                "
    ]
  ]
}