{
  "name": "building_residential2_ground_90",
  "refpalette": "c70cities:building_residential2_ground_palette_90",
  "xsize": 16,
  "zsize": 16,
  "slices": [
    [
      "GGGGGGGGGGGGGGGG",
      "GGGGGGGGGGGGGGGG",
      "GGGGGGGGddddddGG",
      "GGGaaaaaeccccdGG",
      "GGGacccceccccdGG",
      "GGGacccceccccdGG",
      "GGGacccceccccdGG",
      "GGGacccceccccdGG",
      "GGGabbbbeccccdGG",
      "GGGabbbbeccccdGG",
      "GGGabbbbeccccdGG",
      "GGGabbbbeccccdGG",
      "GGGaaaaaeccccdGG",
      "GGGGGGGGddddddGG",
      "GGGGGGGGGGGGGGGG",
      "GGGGGGGGGGGGGGGG"
    ],
    [
      "fgggghgggghggggf",
      "g              g",
      "g iiiiiissssss g",
      "g iaaaaa  x  s g",
      "g iaq     w Fs g",
      "h iap   u wCCs h",
      "g iao   u  BBs g",
      "g iannnnn    s g",
      "g iam      AEs g",
      "g ial  r     s g",
      "h iak   t    s h",
      "g iaj   t    s g",
      "g iaaaaa     s g",
      "g iiiiiisssyDs g",
      "g              g",
      "fgggghggggf  fgf"
    ],
    [
      "fgggghgggghggggf",
      "g              g",
      "g       sNsRRs g",
      "g  aaaaa  O  s g",
      "g  aL     w Ts g",
      "h  a!  u  wCCs h",
      "g  a   u   QQs g",
      "g  annnnn    s g",
      "g  aK        s g",
      "g  a   M     N g",
      "h  aJ  M     N h",
      "g  aI  M     N g",
      "g  aaaaa     s g",
      "g       sNsPSs g",
      "g              g",
      "fgggghggggf  fgf"
    ],
    [
      "                ",
      "                ",
      "        sNsRRs  ",
      "   aaUUa  w  s  ",
      "   a      w  s  ",
      "   U  u   wCCs  ",
      "   U  u      s  ",
      "   annnnn    s  ",
      "   a         s  ",
      "   U         N  ",
      "   U         N  ",
      "   a         N  ",
      "   aaUUa     s  ",
      "        sNsNNs  ",
      "                ",
      "                "
    ],
    [
      "                ",
      "                ",
      "  VVVVVVsVVVVV  ",
      "  Vaaaaa WWWWV  ",
      "  Va     WWWWV  ",
      "  Va u   WWWWV  ",
      "  Va u   WWWWV  ",
      "  VannnnnWWWWV  ",
      "  Va     WWWWV  ",
      "  Va     WWWWV  ",
      "  Va     WWWWV  ",
      "  Va     WWWWV  ",
      "  Vaaaaa WWWWV  ",
      "  VVVVVVsVVVVV  ",
      "                ",
      "                "
    ],
    [
      "                ",
      "                ",
      "  ssssssssssss  ",
      "  sccccceZ23ns  ",
      "  sccccce   ns  ",
      "  scu   eY1  s  ",
      "  scu   e    s  ",
      "  sccccceX0 ns  ",
      "  sccccce   ns  ",
      "  sccccceu   s  ",
      "  sccccceu   s  ",
      "  sccccce   ns  ",
      "  sccccce   ns  ",
      "  ssssssssssss  ",
      "                ",
      "                "
    ]
  ]
}