{
  "name": "building_office1_floor1",
  "refpalette": "c70cities:building_office1_floor1_palette",
  "xsize": 16,
  "zsize": 16,
  "slices": [
    [
      "                ",
      "                ",
      "  aaaaaaaaaaaa  ",
      "  abbbbbbbbbba  ",
      "  abbbbbbbbbba  ",
      "  abbbbbbbbbba  ",
      "  abbbbbbbbbba  ",
      "  abbbbbbbbbba  ",
      " ccbbbbbbbbbbcc ",
      "  dbbbbbbbbbbd  ",
      "  dbbbbbbbbbbd  ",
      " efgbbbbbbbbbfe ",
      " ebbbbbbbb!bbbe ",
      " ebbbbbbbbbbbbe ",
      " eeeeeeeeeeeeee ",
      "                "
    ],
    [
      "                ",
      "                ",
      "  hhhhhhhhhhhh  ",
      "  h          h  ",
      "  h  i i i   h  ",
      "  h j k  k l h  ",
      "  h   m m m  h  ",
      "  h         nh  ",
      " ccfopfffffffcc ",
      "  d   qf     d  ",
      "  d    r     d  ",
      " sfg  tfu u  fs ",
      " sw   xfyyy  As ",
      " sw   Bf C   Ds ",
      " ssssssssssssss ",
      "                "
    ],
    [
      "                ",
      "                ",
      "  hhhhhhhhhhhh  ",
      "  h          h  ",
      "  h          h  ",
      "  h  EEEEEE  h  ",
      "  h          h  ",
      "  h         Fh  ",
      " ccfIJfffffffcc ",
      "  d   qf     d  ",
      "  d    K     d  ",
      " sfg   f     fs ",
      " sw    fLMN  Os ",
      " sw    f      s ",
      " ssPddddddddPss ",
      "                "
    ],
    [
      "                ",
      "                ",
      "  hhhhhhhhhhhh  ",
      "  h          h  ",
      "  h          h  ",
      "  h          h  ",
      "  h          h  ",
      "  h          h  ",
      " ccffffffffffcc ",
      "  d    f     d  ",
      "  d    f     d  ",
      " sfg   f     fs ",
      " sw    f      s ",
      " sw    f      s ",
      " ssPddddddddPss ",
      "                "
    ],
    [
      "                ",
      "                ",
      "  hhhhhhhhhhhh  ",
      "  h          h  ",
      "  h          h  ",
      "  h          h  ",
      "  h          h  ",
      "  h          h  ",
      " ccffffffffffcc ",
      "  d    f     d  ",
      "  d    f     d  ",
      " sfg   f     fs ",
      " sQ    f      s ",
      " sQ    f      s ",
      " ssssssssssssss ",
      "                "
    ],
    [
      "                ",
      "                ",
      "  hhhhhhhhhhhh  ",
      "  hPPPPPPPPPPh  ",
      "  hPPPPPPPPPPh  ",
      "  hPPPPPPPPPPh  ",
      "  hPPPPPPPPPPh  ",
      "  hPPPPPPPPPPh  ",
      " ccffffffffffcc ",
      "  d PPPfPPPP d  ",
      "  d PPPfPPPP d  ",
      " sfgPPPfPPPP fs ",
      " sPPPPPfPPPPPPs ",
      " sPPPPPfPPPPPPs ",
      " ssssssssssssss ",
      "                "
    ]
  ]
}