{
  "name": "building_office1_floor1",
  "refpalette": "c70cities:building_office1_floor1_palette",
  "xsize": 16,
  "zsize": 16,
  "slices": [
    [
      "                ",
      "                ",
      "  aaaaaaaaaaaa  ",
      "  abbbbbbbbbba  ",
      "  abbbbbbbbbba  ",
      "  abbbbbbbbbba  ",
      "  abbbbbbbbbba  ",
      "  abbbbbbbbbba  ",
      " ccbbbbbbbbbbcc ",
      "  dbbbbbbbbbbd  ",
      "  dbbbbbbbbbbd  ",
      " efgbbbbbbbbbfe ",
      " ebbbbbbbb!bbbe ",
      " ebbbbbbbbbbbbe ",
      " eeeeeeeeeeeeee ",
      "                "
    ],
    [
      "                ",
      "                ",
      "  hhhhhhhhhhhh  ",
      "  h          h  ",
      "  h  i i i   h  ",
      "  h j k  k l h  ",
      "  h   m m m  h  ",
      "  h         nh  ",
      " ccfopfffffffcc ",
      "  d   qf     d  ",
      "  d    r     d  ",
      " sfg  tfi i  fs ",
      " su   wfxxx  ys ",
      " su   Af B   Cs ",
      " ssssssssssssss ",
      "                "
    ],
    [
      "                ",
      "                ",
      "  hhhhhhhhhhhh  ",
      "  h          h  ",
      "  h          h  ",
      "  h  DDDDDD  h  ",
      "  h          h  ",
      "  h          h  ",
      " ccfEFfffffffcc ",
      "  d   qf     d  ",
      "  d    I     d  ",
      " sfg   f     fs ",
      " su    fJKL  Ms ",
      " su    f      s ",
      " ssNddddddddNss ",
      "                "
    ],
    [
      "                ",
      "                ",
      "  hhhhhhhhhhhh  ",
      "  h          h  ",
      "  h          h  ",
      "  h          h  ",
      "  h          h  ",
      "  h          h  ",
      " ccffffffffffcc ",
      "  d    f     d  ",
      "  d    f     d  ",
      " sfg   f     fs ",
      " su    f      s ",
      " su    f      s ",
      " ssNddddddddNss ",
      "                "
    ],
    [
      "                ",
      "                ",
      "  hhhhhhhhhhhh  ",
      "  h          h  ",
      "  h          h  ",
      "  h          h  ",
      "  h          h  ",
      "  h          h  ",
      " ccffffffffffcc ",
      "  d    f     d  ",
      "  d    f     d  ",
      " sfg   f     fs ",
      " sO    f      s ",
      " sO    f      s ",
      " ssssssssssssss ",
      "                "
    ],
    [
      "                ",
      "                ",
      "  hhhhhhhhhhhh  ",
      "  hNNNNNNNNNNh  ",
      "  hNNNNNNNNNNh  ",
      "  hNNNNNNNNNNh  ",
      "  hNNNNNNNNNNh  ",
      "  hNNNNNNNNNNh  ",
      " ccffffffffffcc ",
      "  d NNNfNNNN d  ",
      "  d NNNfNNNN d  ",
      " sfgNNNfNNNN fs ",
      " sNNNNNfNNNNNNs ",
      " sNNNNNfNNNNNNs ",
      " ssssssssssssss ",
      "                "
    ]
  ]
}