{
  "name": "building_office3_floor2_270",
  "refpalette": "c70cities:building_office3_floor2_palette_270",
  "xsize": 16,
  "zsize": 16,
  "slices": [
    [
      "                ",
      " aabaabaabaabaa ",
      " acccccccccccca ",
      " bccccccccccccb ",
      " acccccccccccca ",
      " acccccccc!ccca ",
      " bccccccccccccb ",
      " acccccvvccccca ",
      " acccccddccccca ",
      " bccccccccccccb ",
      " acccccccccccca ",
      " acccccccccccca ",
      " bccccccccccccb ",
      " acccccccccccca ",
      " aabaabaabaabaa ",
      "                "
    ],
    [
      "                ",
      " eebeebeebeebee ",
      " ef          fe ",
      " b g ih  ji g b ",
      " e   i    i   e ",
      " e  ji    ih  e ",
      " b     kk     b ",
      " e     vv     e ",
      " e     dd     e ",
      " b            b ",
      " e  ji    ih  e ",
      " e   i    i   e ",
      " b g ih  ji g b ",
      " ef          fe ",
      " eebeebeebeebee ",
      "                "
    ],
    [
      "                ",
      " llbllbllbllbll ",
      " lf          fl ",
      " b g        g b ",
      " l            l ",
      " l            l ",
      " b            b ",
      " l     vv     l ",
      " l     dd     l ",
      " b            b ",
      " l            l ",
      " l            l ",
      " b g        g b ",
      " lf          fl ",
      " llbllbllbllbll ",
      "                "
    ],
    [
      "                ",
      " llbllbllbllbll ",
      " l            l ",
      " b g        g b ",
      " l            l ",
      " l            l ",
      " b            b ",
      " l     vv     l ",
      " l     dd     l ",
      " b            b ",
      " l            l ",
      " l            l ",
      " b g        g b ",
      " l            l ",
      " llbllbllbllbll ",
      "                "
    ],
    [
      "                ",
      " llbllbllbllbll ",
      " l            l ",
      " b g        g b ",
      " l            l ",
      " l            l ",
      " b            b ",
      " l     vv     l ",
      " l     dd     l ",
      " b            b ",
      " l            l ",
      " l            l ",
      " b g        g b ",
      " l            l ",
      " llbllbllbllbll ",
      "                "
    ],
    [
      "                ",
      " llbllbllbllbll ",
      " lmmmmmmmmmmmml ",
      " bmgnnnnnnnngmb ",
      " lmnnnnnnnnnnml ",
      " lmnnnnnnnnnnml ",
      " bmnnnnnnnnnnmb ",
      " lmnnnnvvnnnnml ",
      " lmnnnnddnnnnml ",
      " bmnnnnnnnnnnmb ",
      " lmnnnnnnnnnnml ",
      " lmnnnnnnnnnnml ",
      " bmgnnnnnnnngmb ",
      " lmmmmmmmmmmmml ",
      " llbllbllbllbll ",
      "                "
    ]
  ]
}