{
  "name": "building_office3_floor3_90",
  "refpalette": "c70cities:building_office3_floor3_palette_90",
  "xsize": 16,
  "zsize": 16,
  "slices": [
    [
      "                ",
      " aabaabaabaabaa ",
      " acccccccccccca ",
      " bccccccccccccb ",
      " acccccccccccca ",
      " acccccccccccca ",
      " bccccccccccccb ",
      " acccccddccccca ",
      " acccccvvccccca ",
      " bccccccccccccb ",
      " acc!ccccccccca ",
      " acccccccccccca ",
      " bccccccccccccb ",
      " acccccccccccca ",
      " aabaabaabaabaa ",
      "                "
    ],
    [
      "                ",
      " eebeebeebeebee ",
      " e            e ",
      " b f  j  j  f b ",
      " e   iiiiik   e ",
      " e            e ",
      " b            b ",
      " e gg  dd  gg e ",
      " e gh  vv  hg e ",
      " b gh      hg b ",
      " e gg      gg e ",
      " e            e ",
      " b f        f b ",
      " e            e ",
      " eebeebeebeebee ",
      "                "
    ],
    [
      "                ",
      " llbllbllbllbll ",
      " l            l ",
      " b f        f b ",
      " l            l ",
      " l            l ",
      " b            b ",
      " l     dd     l ",
      " l     vv     l ",
      " b            b ",
      " l            l ",
      " l            l ",
      " b f        f b ",
      " l            l ",
      " llbllbllbllbll ",
      "                "
    ],
    [
      "                ",
      " llbllbllbllbll ",
      " l            l ",
      " b f        f b ",
      " l            l ",
      " l            l ",
      " b            b ",
      " l     dd     l ",
      " l     vv     l ",
      " b            b ",
      " l            l ",
      " l            l ",
      " b f        f b ",
      " l            l ",
      " llbllbllbllbll ",
      "                "
    ],
    [
      "                ",
      " llbllbllbllbll ",
      " l            l ",
      " b f        f b ",
      " l            l ",
      " l            l ",
      " b            b ",
      " l     dd     l ",
      " l     vv     l ",
      " b            b ",
      " l            l ",
      " l            l ",
      " b f        f b ",
      " l            l ",
      " llbllbllbllbll ",
      "                "
    ],
    [
      "                ",
      " llbllbllbllbll ",
      " lmmmmmmmmmmmml ",
      " bmfnnnnnnnnfmb ",
      " lmnnnnnnnnnnml ",
      " lmnnnnnnnnnnml ",
      " bmnnnnnnnnnnmb ",
      " lmnnnnddnnnnml ",
      " lmnnnnvvnnnnml ",
      " bmnnnnnnnnnnmb ",
      " lmnnnnnnnnnnml ",
      " lmnnnnnnnnnnml ",
      " bmfnnnnnnnnfmb ",
      " lmmmmmmmmmmmml ",
      " llbllbllbllbll ",
      "                "
    ]
  ]
}