{
  "name": "building_apartment1_ground_90",
  "refpalette": "c70cities:building_apartment1_ground_palette_90",
  "xsize": 16,
  "zsize": 16,
  "slices": [
    [
      "GGGGGGGGGGGGGGGG",
      "GaaaaaaaaaaaaaaG",
      "GaaaaaaaaaaaaaaG",
      "GaaaaaaaaaaaaaaG",
      "GaaaaaaaaaaaaaaG",
      "GaaaaaaaaaaaaaaG",
      "GaaaaaaaaaaaaaaG",
      "GaaaaaaaaaaaaaaG",
      "GaaaaaaaaaaaaaaG",
      "GaaaaaaaaaaaaaaG",
      "GaaaaaaaaaaaaaaG",
      "GaaaaaaaaaaaaaaG",
      "GaaaaaaaaaaaaaaG",
      "GaaaaaaaaaaaaaaG",
      "GaaaaaaaaaaaaaaG",
      "GGGGGGGGGGGGGGGG"
    ],
    [
      "                ",
      " bdddddddb      ",
      " b mmm  pbCCCC  ",
      " cjllls Ab FrC  ",
      " cjllls yb   J  ",
      " c kkk   b   J  ",
      " cbbb    bBEbbb ",
      " ci o        pK ",
      " ch b         d ",
      " cbbbb w   DD d ",
      " cggn      DI d ",
      " cf        D  d ",
      " ce        DI d ",
      " b   pruurp   d ",
      " bdddbqtxqddddd ",
      "                "
    ],
    [
      "                ",
      " bdddddddb      ",
      " b      pbPJCC  ",
      " b       b  FC  ",
      " b       b  SC  ",
      " b       b   C  ",
      " bbbb    bORbbb ",
      " b  L        pK ",
      " b  b         d ",
      " bbbbb        d ",
      " bg        Q  d ",
      " b            d ",
      " b            d ",
      " b   pr  rp   d ",
      " bdddbqMNqddddd ",
      "                "
    ],
    [
      "                ",
      " bdddddddb      ",
      " b       bCCCY  ",
      " d       b   X  ",
      " d       b  WC  ",
      " b       b  rC  ",
      " bbbb    bVVbbb ",
      " d  T         K ",
      " d  b         d ",
      " bbbbb        d ",
      " b            d ",
      " d            d ",
      " d            d ",
      " b    r  r    d ",
      " bdddbqUUqddddd ",
      "                "
    ],
    [
      "                ",
      " bKKKKKKKb      ",
      " b       bXXXC  ",
      " c       b   J  ",
      " c       b   J  ",
      " b       b ZW0  ",
      " bbbbbbbbbbbbbb ",
      " c  b         K ",
      " c  b         K ",
      " bbbbb        K ",
      " b            K ",
      " c            K ",
      " c            K ",
      " b    rrrr    K ",
      " bKKKbq  qKKKKq ",
      "                "
    ],
    [
      "                ",
      " bbbbbbbbb      ",
      " bCCCCCCCbCCCC  ",
      " bCCCCCCCb   C  ",
      " bCCCCCCCb   C  ",
      " bCCCCCCCbr4 C  ",
      " bbbbbbbbbbbbbb ",
      " b11bCCCCCCCCCb ",
      " b11bCCCCCCCCCb ",
      " bbbbbC23CCCCCb ",
      " bCCCCC!wCCCCCb ",
      " bCCCCCCCCCCCCb ",
      " bCCCCCCCCCCCCb ",
      " bCCCCCCCCCCCCb ",
      " bbbbbbbbbbbbbb ",
      "                "
    ]
  ]
}