{
  "name": "building_apartment1_floor1_180",
  "refpalette": "c70cities:building_apartment1_floor1_palette_180",
  "xsize": 16,
  "zsize": 16,
  "slices": [
    [
      "                ",
      "      aaaaaaaaa ",
      "  ihgdbbbbbbbba ",
      "  ef  bbbbbbbba ",
      "  ebb bbbbbbbba ",
      "  dbbcbbbbbbbba ",
      " abbbbbbbbbbbba ",
      " abbbbbbbbbbbba ",
      " abbbbbbbbbbbba ",
      " abbbbbbbbbbbba ",
      " abbbbbbbbbbbba ",
      " abbbbbbbbbbbba ",
      " abbbbbbbbbbbba ",
      " abbbbbbbbbbbba ",
      " aaaaaaaaaaaaaa ",
      "                "
    ],
    [
      "                ",
      "      YYYYYYYYX ",
      "  ddWWp!     Vm ",
      "  dU  pT P   Sm ",
      "  dR  pQ P   Om ",
      "  d   p     NMm ",
      " tpLpppKKJ Eppm ",
      " t  I      I  m ",
      " tFFp      Erqm ",
      " tppppppypDpppm ",
      " tCB     p CB m ",
      " tA  xxyxp    m ",
      " t  up   w uu m ",
      " ts op rqp oonm ",
      " lkkkkkkkkkkkkj ",
      "                "
    ],
    [
      "                ",
      "      p7ZZZZZ75 ",
      "  ddddp      ^7 ",
      "  dR% p#     $7 ",
      "  W   p#      7 ",
      "  h   p     @ 7 ",
      " pp9ppp    Epp5 ",
      " p  8      8  7 ",
      " p  p      E  7 ",
      " ppppppp3p6ppp5 ",
      " p4      p    p ",
      " Z   xx3xp    Z ",
      " Z  up   2    Z ",
      " Z  op1  p   0Z ",
      " pppppppppppppp ",
      "                "
    ],
    [
      "                ",
      "      p7ZZZZZ75 ",
      "  `|ddp \\\\}{{ Z ",
      "  d ]Up       Z ",
      "  d   p       Z ",
      "  d   p       7 ",
      " pppppp    Epp5 ",
      " Z  p      E  Z ",
      " Z  p      E  Z ",
      " ppppppppppppp5 ",
      " p       p    p ",
      " Z[  xxxxp   -Z ",
      " Z+  p   p   )Z ",
      " Z(  p*  p   &Z ",
      " ppZZppZZppZZpp ",
      "                "
    ],
    [
      "                ",
      "      p77777775 ",
      "  dWWep       7 ",
      "  |  ]p       7 ",
      "  |  :p       7 ",
      "  |   p       7 ",
      " pppppp    Epp5 ",
      " 7 fp      E  7 ",
      " 7  p      E  7 ",
      " ppppppppppppp5 ",
      " p       p    p ",
      " 7   xxxxp    7 ",
      " 7   p   p    7 ",
      " 7   p   p    7 ",
      " ppkkppkkppkkpp ",
      "                "
    ],
    [
      "                ",
      "      ppppppppp ",
      "  ddddpdddddddp ",
      "  d   pdddddddp ",
      "  d  cpdddddddp ",
      "  d  Updddddddp ",
      " ppppppdddddddp ",
      " pddpddddddd;;p ",
      " pddpddddddd;;p ",
      " pppppppppppppp ",
      " pdddddddpddddp ",
      " pdddddddpddddp ",
      " pdddd;;;pddddp ",
      " pdddd;;;pddddp ",
      " pppppppppppppp ",
      "                "
    ]
  ]
}