{
  "name": "building_office5_ground_90",
  "refpalette": "c70cities:building_office5_ground_palette_90",
  "xsize": 16,
  "zsize": 16,
  "slices": [
    [
      "GGGGGGGGGGGGGGGG",
      "GaaaaaaaaaaaaaaG",
      "GaaaaaaaaaaaaaaG",
      "GaaaaaaaaaaaaaaG",
      "GaaaaaaaaaaaaaaG",
      "GaaaaaaaaaaaaaaG",
      "Gaaaaa!aaaaaaaaG",
      "GaaGGaaaaaaaaaaG",
      "GaaGGaaaaaaaaaaG",
      "GaaaaaaaaaaaaaaG",
      "GaaaaaaaaaaaaaaG",
      "GaaaaaaaaaaaaaaG",
      "GaaaaaaaaaaaaaaG",
      "GaaaaaaaaaaaaaaG",
      "GaaaaaaaaaaaaaaG",
      "GGGGGGGGGGGGGGGG"
    ],
    [
      "                ",
      " bc  cc  cc  cb ",
      " cdeebdopddeedc ",
      "  e         xe  ",
      "  ef lm      e  ",
      " cdg lm   tw dc ",
      " cdhhb   qs ydc ",
      "  ejicn   s  e  ",
      "  eikcn   s  e  ",
      " cdhhb   qs ydc ",
      " cdg lm   ru dc ",
      "  ef lm      e  ",
      "  e         xe  ",
      " cdeebdeeddeedc ",
      " bc  cc  cc  cb ",
      "                "
    ],
    [
      "                ",
      " bc  cc  cc  cb ",
      " cdeebdBCddeedc ",
      "  e         me  ",
      "  e          e  ",
      " cd          dc ",
      " cd  b    D  dc ",
      "  e  cn      e  ",
      "  e Acn      e  ",
      " cd  b    D  dc ",
      " cd          dc ",
      "  e          e  ",
      "  e         me  ",
      " cdeebdeeddeedc ",
      " bc  cc  cc  cb ",
      "                "
    ],
    [
      "                ",
      " bc  cc  cc  cb ",
      " cdeebdeeddeedc ",
      "  e         me  ",
      "  e          e  ",
      " cd          dc ",
      " cd  b       dc ",
      "  e  cn E    e  ",
      "  e  cn      e  ",
      " cd  b       dc ",
      " cd          dc ",
      "  e          e  ",
      "  e         me  ",
      " cdeebdeeddeedc ",
      " bc  cc  cc  cb ",
      "                "
    ],
    [
      "                ",
      " bcFFccFFccFFcb ",
      " cdddcddddddddc ",
      " Fd  c       dF ",
      " Fd  c       dF ",
      " cd  c       dc ",
      " cd  c       dc ",
      " Fd  cnIE    dF ",
      " Fd  cnEI    dF ",
      " cd  c       dc ",
      " cd  c       dc ",
      " Fd  c       dF ",
      " Fd  c       dF ",
      " cdddcddddddddc ",
      " bcFFccFFccFFcb ",
      "                "
    ],
    [
      "                ",
      " bccccccccccccb ",
      " cccccccccccccc ",
      " cccccJJJJJJJcc ",
      " cccccJJJJJJJcc ",
      " cccccJJJJJJJcc ",
      " cccccK  KJJJcc ",
      " cccccnLL JJJcc ",
      " cccccnLL JJJcc ",
      " cccccK  KJJJcc ",
      " cccccJJJJJJJcc ",
      " cccccJJJJJJJcc ",
      " cccccJJJJJJJcc ",
      " cccccccccccccc ",
      " bccccccccccccb ",
      "                "
    ]
  ]
}