{
  "name": "building_hotel1_floor2_270",
  "refpalette": "c70cities:building_hotel1_floor2_palette_270",
  "xsize": 16,
  "zsize": 16,
  "slices": [
    [
      "                ",
      " aadddddddaaaaa ",
      " abbbbbbbbbbbba ",
      " abbbbbbbbbbbba ",
      " abbbbbbbbbbbba ",
      " abbbccccccbbba ",
      " abbbc    cbbba ",
      " abbbc    cbbba ",
      " gbbbc    cbbba ",
      " gbccce   cbbba ",
      " gbbbbbbbdcbbba ",
      " gbbbbbbbbcbbba ",
      " gbbbbbbbbcbbba ",
      " abbbbbbbbcbbba ",
      " aaffffaaaaaaaa ",
      "                "
    ],
    [
      "                ",
      " aaaaaaaaaaaaaa ",
      " a          m a ",
      " a Bxa      nha ",
      " a Bxa=uu=r   a ",
      " a   saaaaso  a ",
      " a ffa    ap ia ",
      " a  yae   aq ja ",
      " aECAae   aq ja ",
      " aaaaad   ap ka ",
      " aee   ww so  a ",
      " aeD      a   a ",
      " aeD      t  la ",
      " an    n  a   a ",
      " aaffffaaaaaaaa ",
      "                "
    ],
    [
      "                ",
      " aaaaaffffaaaaa ",
      " a            a ",
      " f   a      F a ",
      " f   aM  K    a ",
      " f   saaaaso  a ",
      " f ffaee  a   a ",
      " f   ad   a   a ",
      " f  Na    aI  a ",
      " aaaaa    a   a ",
      " a        so  a ",
      " a        a   a ",
      " a        J   a ",
      " aL    L  a   a ",
      " aaffffaaaaaaaa ",
      "                "
    ],
    [
      "                ",
      " aaaaaaaaaaaaaa ",
      " a   a        a ",
      " a   a        a ",
      " a   a DD     a ",
      " a  Osaaaas  Oa ",
      " a ffa deea   a ",
      " a   a    a   a ",
      " a  Pa    a   a ",
      " aaaaa    a   a ",
      " a        s  Oa ",
      " a        a   a ",
      " a        a   a ",
      " aL    L  a   a ",
      " aaffffaaaaaaaa ",
      "                "
    ],
    [
      "                ",
      " aaaaaaaaaaffaa ",
      " a   a        a ",
      " a   a        a ",
      " a   a        a ",
      " a  Qsaaaas  Qa ",
      " afffa   da   a ",
      " f   a   ea   a ",
      " f   a   ea   a ",
      " aaaaa    a   a ",
      " a        s  Qa ",
      " a        a   a ",
      " a        a   a ",
      " a        a   a ",
      " aaffffaaaaaaaa ",
      "                "
    ],
    [
      "                ",
      " aaaaaaaaaaaaaa ",
      " aRRRRRRRRRRRRa ",
      " aRRRRRRRRRRRRa ",
      " aRRRRRRRRRRRRa ",
      " aRRRsaaaasRRRa ",
      " aRRRa    aRRRa ",
      " aRRRa    aRRRa ",
      " aRRRa   daRRRa ",
      " aaaaa   eaRRRa ",
      " aRRRRRRRRsRRRa ",
      " aRRRRRRRRaRRRa ",
      " aRRRRRRRRaRRRa ",
      " aRRRRRRRRaRRRa ",
      " aaffffaaaaaaaa ",
      "                "
    ]
  ]
}