{
  "name": "building_office1_base1_90",
  "refpalette": "c70cities:building_office1_base1_palette_90",
  "xsize": 16,
  "zsize": 16,
  "slices": [
    [
      "vvvvvvvvvvvvvvvv",
      "vaaaaaaaaaaaaaav",
      "va!aaaaaaaaaaaav",
      "vaaaaaaaaaaaaaav",
      "vaaaaaaaaaaaaaav",
      "vaaaaaaaaaaaaaav",
      "vaaaaaaaaaaaaaav",
      "vaaaaaaaaaaaaaav",
      "vaaaaaaaaaaaaaav",
      "vaaaaaaaaaaaaaav",
      "vaaaaaaaaaaaaaav",
      "vaaaaaaaaaaaaaav",
      "vaaaaaaaaaaaaaav",
      "va!aaaaaaaaabbav",
      "vaaaaaaaaaaaaaav",
      "vvvvvvvvvvvvvvvv"
    ],
    [
      "vvvvvvvvvvvvvvvv",
      "vccccccccccccccv",
      "vcdddddddddeffcv",
      "vc            cv",
      "vc            cv",
      "vc            cv",
      "vcdddd  ddd   cv",
      "vc            cv",
      "vc            cv",
      "vcdddd  ddd   cv",
      "vc            cv",
      "vc            cv",
      "vc            cv",
      "vcdddddddddebbcv",
      "vccccccccccccccv",
      "vvvvvvvvvvvvvvvv"
    ],
    [
      "vvvvvvvvvvvvvvvv",
      "vccccccccccccccv",
      "vcddddddddde  cv",
      "vc            cv",
      "vc            cv",
      "vc            cv",
      "vcdddd  ddd   cv",
      "vc            cv",
      "vc            cv",
      "vcdddd  ddd   cv",
      "vc            cv",
      "vc            cv",
      "vc            cv",
      "vcdddddddddebbcv",
      "vccccccccccccccv",
      "vvvvvvvvvvvvvvvv"
    ],
    [
      "vvvvvvvvvvvvvvvv",
      "vccccccccccccccv",
      "vcddddddddde  cv",
      "vc            cv",
      "vc            cv",
      "vc            cv",
      "vc            cv",
      "vc            cv",
      "vc            cv",
      "vc            cv",
      "vc            cv",
      "vc            cv",
      "vc            cv",
      "vcdddddddddebbcv",
      "vccccccccccccccv",
      "vvvvvvvvvvvvvvvv"
    ],
    [
      "vvvvvvvvvvvvvvvv",
      "vccccccccccccccv",
      "vc         e  cv",
      "vc            cv",
      "vc            cv",
      "vc            cv",
      "vc            cv",
      "vc            cv",
      "vc            cv",
      "vc            cv",
      "vc            cv",
      "vc            cv",
      "vc            cv",
      "vc         ebbcv",
      "vccccccccccccccv",
      "vvvvvvvvvvvvvvvv"
    ],
    [
      "vvvvvvvvvvvvvvvv",
      "vccccccccccccccv",
      "vcgggggggggeggcv",
      "vcggggggggggggcv",
      "vcggggggggggggcv",
      "vcggggggggggggcv",
      "vcggggggggggggcv",
      "vcggggggggggggcv",
      "vcggggggggggggcv",
      "vcggggggggggggcv",
      "vcggggggggggggcv",
      "vcggggggggggggcv",
      "vcggggggggggggcv",
      "vcgggggggggebbcv",
      "vccccccccccccccv",
      "vvvvvvvvvvvvvvvv"
    ]
  ]
}