{
  "name": "building_residential4_floor1_180",
  "refpalette": "c70cities:building_residential4_floor1_palette_180",
  "xsize": 16,
  "zsize": 16,
  "slices": [
    [
      "                ",
      "                ",
      "                ",
      " oooooooooooooo ",
      " ncd     m  dcn ",
      "  cd     m  dc  ",
      "  cdllllk   dc  ",
      "   i        i   ",
      "   i j      i   ",
      "  cd hg     dc  ",
      "  cd f      dc  ",
      " bcdeeeeeeeedcb ",
      " aaaaaaaaaaaaaa ",
      "                ",
      "                ",
      "                "
    ],
    [
      "                ",
      "                ",
      "                ",
      "                ",
      " oooooooooooooo ",
      " ncdxw   m  dcn ",
      "  cdlllll   dc  ",
      "  ui        iu  ",
      "  ui        iu  ",
      "  cd        dc  ",
      " bcdbbb  bbbdcb ",
      " aaaatesseraaaa ",
      "     q    p     ",
      "                ",
      "                ",
      "                "
    ],
    [
      "                ",
      "                ",
      "                ",
      "                ",
      "                ",
      " oooooooooooooo ",
      " ncdnnnnnnnndcn ",
      "  cd        dc  ",
      "  cd        dc  ",
      " bcdbbbbbbbbdcb ",
      " aaaaatyyraaaaa ",
      "      qeep      ",
      "      q  p      ",
      "                ",
      "                ",
      "                "
    ],
    [
      "                ",
      "                ",
      "                ",
      "                ",
      "                ",
      "                ",
      " oooooooooooooo ",
      " ncd        dcn ",
      " bcd        dcb ",
      " aaaaaaBAaaaaaa ",
      "       qp       ",
      "       qp       ",
      "       qp       ",
      "                ",
      "                ",
      "                "
    ],
    [
      "                ",
      "                ",
      "                ",
      "                ",
      "                ",
      "                ",
      "                ",
      " oooooooooooooo ",
      " aaaaaaaaaaaaaa ",
      "                ",
      "                ",
      "                ",
      "                ",
      "                ",
      "                ",
      "                "
    ],
    [
      "                ",
      "                ",
      "                ",
      "                ",
      "                ",
      "                ",
      "                ",
      "       ~~       ",
      "       ~        ",
      "                ",
      "                ",
      "                ",
      "                ",
      "                ",
      "                ",
      "                "
    ]
  ]
}