{
  "name": "building_residential2_floor1_90",
  "refpalette": "c70cities:building_residential2_floor1_palette_90",
  "xsize": 16,
  "zsize": 16,
  "slices": [
    [
      "                ",
      "    mqu         ",
      "  ddddddd       ",
      "  d lptwx  BC   ",
      " cd  o  x   C   ",
      " bd kkkkx       ",
      " ad jjjjx       ",
      "  d     x   C   ",
      "  d     x   C   ",
      " cdffff A       ",
      " bdffff y       ",
      " adfiif x   C   ",
      "  dehhs x   C   ",
      "  ddddddd       ",
      "    gnr         ",
      "                "
    ],
    [
      "                ",
      "                ",
      "  dDEEEDd       ",
      "  D  I  x   C   ",
      "  E     x   C   ",
      "  E     x       ",
      "  E     x       ",
      "  E     x   C   ",
      "  E     x   C   ",
      "  E     K       ",
      "  E     J       ",
      "  E     x   C   ",
      "  DF    x   C   ",
      "  dDEEEDd       ",
      "                ",
      "                "
    ],
    [
      "                ",
      "           LDMN ",
      "  dDEEEDd  LDMN ",
      "  D     x  LDMN ",
      "  E     x  LDMN ",
      "  E     x  LDMN ",
      "  E     x  LDMN ",
      "  E     x  LDMN ",
      "  E     x  LDMN ",
      "  E     x  LDMN ",
      "  E     x  LDMN ",
      "  E     x  LDMN ",
      "  D     x  LDMN ",
      "  dDEEEDd  LDMN ",
      "           LDMN ",
      "                "
    ],
    [
      "                ",
      "        LDMN    ",
      "  dddddddDMN    ",
      "  d     DDMN    ",
      "  d     DDMN    ",
      "  d     DDMN    ",
      "  d     DDMN    ",
      "  d     DDMN    ",
      "  d     DDMN    ",
      "  d     DDMN    ",
      "  d     DDMN    ",
      "  d     DDMN    ",
      "  d     DDMN    ",
      "  dddddddDMN    ",
      "        LDMN    ",
      "                "
    ],
    [
      "                ",
      "     LDMN       ",
      "  CC LDMN       ",
      "     LDMN       ",
      "     LDMN       ",
      "  C  LDMN       ",
      "  C  LDMN       ",
      "     LDMN       ",
      "     LDMN       ",
      "  C  LDMN       ",
      "  C  LDMN       ",
      "     LDMN       ",
      "     LDMN       ",
      "  CC LDMN       ",
      "     LDMN       ",
      "                "
    ],
    [
      "                ",
      "  LDMN          ",
      "  DDMN          ",
      "  LDMN          ",
      "  LDMN          ",
      "  DDMN          ",
      "  DDMN          ",
      "  LDMN          ",
      "  LDMN ~        ",
      "  DDMN          ",
      "  DDMN          ",
      "  LDMN          ",
      "  LDMN          ",
      "  DDMN          ",
      "  LDMN          ",
      "                "
    ]
  ]
}