{
  "name": "building_hotel3_base1_180",
  "refpalette": "c70cities:building_hotel3_base1_palette_180",
  "xsize": 16,
  "zsize": 16,
  "slices": [
    [
      "vvvvvvvvvvvvvvvv",
      "vaaaaaaaaaaaaaav",
      "vabbbbbbbbbbbbav",
      "vabbbbbbbbbbbbav",
      "vabbcbbbbbbcbbav",
      "vabbbbbbbbbbbbav",
      "vabbbbbbbbbbbbav",
      "vabbbbbbbbbbbbav",
      "vabbbbbbbbbbbbav",
      "vabbbbbbbbbbbbav",
      "vabbbbbddbbbbbav",
      "vabbcbbccbbbbbav",
      "vabbbbbbbbbbbbav",
      "vabbbbbbbbbbbbav",
      "vaaaaaaaaaaaaaav",
      "vvvvvvvvvvvvvvvv"
    ],
    [
      "vvvvvvvvvvvvvvvv",
      "vaaaaaaaaaaaaaav",
      "vawut wuut!wutav",
      "va            av",
      "va  c      c  av",
      "vawut wuut wutav",
      "va            av",
      "vasssss       av",
      "vammmm     iiiav",
      "va            av",
      "va rqp dd i   av",
      "va jco cci    av",
      "va nml jik    av",
      "va     jihgffeav",
      "vaaaaaaaaaaaaaav",
      "vvvvvvvvvvvvvvvv"
    ],
    [
      "vvvvvvvvvvvvvvvv",
      "vaaaaaaaaaaaaaav",
      "va M   MM   M av",
      "va            av",
      "va  c      c  av",
      "va M   MM   M av",
      "va            av",
      "vasssss       av",
      "va LLL        av",
      "va            av",
      "va AKJ dd i   av",
      "va IcF cci    av",
      "va ED  Ci     av",
      "va     !i BAyxav",
      "vaaaaaaaaaaaaaav",
      "vvvvvvvvvvvvvvvv"
    ],
    [
      "vvvvvvvvvvvvvvvv",
      "vaaaaaaaaaaaaaav",
      "va            av",
      "va            av",
      "va  c      c  av",
      "va            av",
      "va            av",
      "vasssss       av",
      "va            av",
      "va            av",
      "va     dd i   av",
      "va  c  cci    av",
      "va      iO    av",
      "va      iN    av",
      "vaaaaaaaaaaaaaav",
      "vvvvvvvvvvvvvvvv"
    ],
    [
      "vvvvvvvvvvvvvvvv",
      "vaaaaaaaaaaaaaav",
      "va            av",
      "va            av",
      "va  c      c  av",
      "va            av",
      "va            av",
      "vasssss       av",
      "va            av",
      "va            av",
      "va     dd i   av",
      "va  c  cci    av",
      "va      iQ    av",
      "va      iP    av",
      "vaaaaaaaaaaaaaav",
      "vvvvvvvvvvvvvvvv"
    ],
    [
      "vvvvvvvvvvvvvvvv",
      "vaaaaaaaaaaaaaav",
      "vaRRRRRRRRRRRRav",
      "vaRRRRRRRRRRRRav",
      "vaRRcRRRRRRcRRav",
      "vaRRRRRRRRRRRRav",
      "vaRRRRRRRRRRRRav",
      "vaRRRRRRRRRRRRav",
      "vaRRRRRRRRRRRRav",
      "vaRRRRRRRRRRRRav",
      "vaRRRRRddRRRRRav",
      "vaRRcRRccRRcRRav",
      "vaRRRRRRRRRRRRav",
      "vaRRRRRRRRRRRRav",
      "vaaaaaaaaaaaaaav",
      "vvvvvvvvvvvvvvvv"
    ]
  ]
}