{
  "name": "building_residential1_floor1_90",
  "refpalette": "c70cities:building_residential1_floor1_palette_90",
  "xsize": 16,
  "zsize": 16,
  "slices": [
    [
      "                ",
      " abc            ",
      " abdffffdj      ",
      " abe    dj      ",
      " abe    ij      ",
      " abe    ij      ",
      " abe    ij      ",
      " abe    ij      ",
      " abe    ij      ",
      " abe    ij      ",
      " abe    ij      ",
      " abe    ij      ",
      " abegh  dj      ",
      " abdffffdj      ",
      " abc            ",
      "                "
    ],
    [
      "                ",
      "   abc          ",
      "   abdffd       ",
      "   abe  d       ",
      "   abe  k       ",
      "   abe  k       ",
      "   abe  k       ",
      "   abe  k       ",
      "   abe  k       ",
      "   abe  k       ",
      "   abe  k       ",
      "   abe  k       ",
      "   abe  d       ",
      "   abdffd       ",
      "   abc          ",
      "                "
    ],
    [
      "                ",
      "     abc        ",
      "     abdd       ",
      "     abed       ",
      "     abed       ",
      "     abed       ",
      "     abed       ",
      "     abed       ",
      "     abed       ",
      "     abed       ",
      "     abed       ",
      "     abed       ",
      "     abed       ",
      "     abdd       ",
      "     abc        ",
      "                "
    ],
    [
      "                ",
      "       abc      ",
      "       abc      ",
      "       abc      ",
      "       abc      ",
      "       abc      ",
      "       abc      ",
      "       abc      ",
      "       abc      ",
      "       abc      ",
      "       abc      ",
      "       abc      ",
      "       abc      ",
      "       abc      ",
      "       abc      ",
      "                "
    ],
    [
      "                ",
      "         a      ",
      "         a      ",
      "         a      ",
      "         a      ",
      "         a      ",
      "         a      ",
      "         a      ",
      "         a      ",
      "         a      ",
      "         a      ",
      "         a      ",
      "         a      ",
      "         a      ",
      "         a      ",
      "                "
    ],
    [
      "                ",
      "                ",
      "                ",
      "                ",
      "                ",
      "                ",
      "                ",
      "         ~      ",
      "                ",
      "                ",
      "                ",
      "                ",
      "                ",
      "                ",
      "                ",
      "                "
    ]
  ]
}