{
  "name": "building_factory2_ground_180",
  "refpalette": "c70cities:building_factory2_ground_palette_180",
  "xsize": 16,
  "zsize": 16,
  "slices": [
    [
      "zzzzzzzzzzzzzzzz",
      "zzzzzzzzzzzzzzzz",
      "zzzzzzzzzzzzzzzz",
      "zzzHHHHHHHHHzzzz",
      "zzzHHHHHHHHHzzzz",
      "zzzHHHHHHHHHzzaz",
      "zzHHHHHHHHHHzazz",
      "zzHHHHHHHHHHaaaz",
      "zzzHHHHHHHHHazaz",
      "zzzHHHHHHHHHaazz",
      "zzzHHHHHHHHHaaaz",
      "zzzHHHHHHHHHaaza",
      "zzzHHHHHHHHHzzzz",
      "zzzzzzzzzzzzzzzz",
      "zzzzzzzzzzzzzzzz",
      "zzzzzzzzzzzzzzzz"
    ],
    [
      " bbd c  b b b b ",
      "cec ccbcccdceb  ",
      "cfffffffffffccb ",
      "dffgg F Fg!fc d ",
      "bffE  D  ggocb  ",
      "eefCB    Agq b  ",
      "eefyxi    wqb   ",
      " ffkukt   gq    ",
      "cffnnnsr   q    ",
      "eefkkkp    o    ",
      "eefknnm i  f    ",
      "cffkkkf   il    ",
      "dffkkkfjihgfb b ",
      " fffffffffffcd  ",
      "beccc  b cccecb ",
      "  bcd b  bdc b  "
    ],
    [
      "                ",
      " e   c cc   e   ",
      " ffIIIffIIIfc   ",
      " ffj      Nfc   ",
      " ffO     Ngo    ",
      "eef        q    ",
      "eef        q    ",
      " fML L     q    ",
      " ffnnn     q    ",
      "eefKKK     o    ",
      "eefKnK     f    ",
      " ffKKK     J    ",
      " ff nu     f    ",
      " fffffffIIIfc   ",
      " ec       cce   ",
      "                "
    ],
    [
      "                ",
      " e          e   ",
      " ffIIIffIIIf    ",
      " ff        f    ",
      " ff        o    ",
      "eef        q    ",
      "eef        q    ",
      " fP        q    ",
      " ff O      q    ",
      "eefQQQ     o    ",
      "eefQQQ     f    ",
      " ffQQQ     P    ",
      " ffj       f    ",
      " fffffffIIIf    ",
      " e         ce   ",
      "                "
    ],
    [
      "                ",
      " e          e   ",
      " SfRRRffRRRf    ",
      " Sf        f    ",
      " SfV       o    ",
      "STf        oU   ",
      "STf        oU   ",
      " Sf        oU   ",
      " SfV       oU   ",
      "STf        o    ",
      "STf        f    ",
      " Sf        f    ",
      " Sfj       f    ",
      " SffffffRRRf    ",
      " e          e   ",
      "                "
    ],
    [
      "                ",
      " e          e   ",
      "  fWWWffWWWf    ",
      "  f        f    ",
      "  f        W    ",
      " Tf   YY   W    ",
      " Tf        W    ",
      "  f        W    ",
      "  f        W    ",
      " Tf        W    ",
      " Tf   YX   f    ",
      "  f        f    ",
      "  f        f    ",
      "  fWWWffWWWf    ",
      " e          e   ",
      "                "
    ]
  ]
}