{
  "name": "building_policeoffice1_top_90",
  "refpalette": "c70cities:building_policeoffice1_top_palette_90",
  "xsize": 16,
  "zsize": 16,
  "slices": [
    [
      "           cffc ",
      "           c  g ",
      "           d  c ",
      "           c  c ",
      " aaaaaaaaaacbbc ",
      " abbbbbbbbbcbbg ",
      " abb!bbbbbbcbbc ",
      " abbbbbbbbbcbbc ",
      " abbbbbbbbbcbbc ",
      " abbbbbbbbbcbbg ",
      " abb!bbbbbbcbbc ",
      " abbbbbbbbbbbbc ",
      " abbbbbbbbbcbbc ",
      " aaaaaaaaaaceeg ",
      "           cccc ",
      "                "
    ],
    [
      "           cccc ",
      "           c  g ",
      "           d  c ",
      "           c  c ",
      " aaaaaaaaaacllc ",
      " a  j     kc  g ",
      " a gg      c  c ",
      " ahgghhhhhhc  c ",
      " ah   h    c  c ",
      " ah j h    c  g ",
      " ahgg h    c  c ",
      " a gghh       c ",
      " a i       c  c ",
      " aaaaaaaaaac  g ",
      "           cccc ",
      "                "
    ],
    [
      "           cppc ",
      "           c  g ",
      "           d  c ",
      "           c  c ",
      "  oooooooooc  c ",
      " m         c  g ",
      " m gg      c  c ",
      " m gg      c  c ",
      " m         c  c ",
      " m         c  g ",
      " m gg      c  c ",
      " m gg         c ",
      " m         c  c ",
      "  nnnnnnnnnc  g ",
      "           cccc ",
      "                "
    ],
    [
      "           cppc ",
      "           c  g ",
      "           d  c ",
      "           c  c ",
      "           c  c ",
      "           c  g ",
      "           c  c ",
      "    q      c  c ",
      "           c  c ",
      "           c  g ",
      "           c  c ",
      "    q      c  c ",
      "           c  c ",
      "           c  g ",
      "           cccc ",
      "                "
    ],
    [
      "           cccc ",
      "           c  c ",
      "           c  c ",
      "           c  c ",
      "           c  c ",
      "           c  c ",
      "    q      c  c ",
      "   qq      c  c ",
      "           c  c ",
      "           c  c ",
      "           c  c ",
      "   qq      c  c ",
      "    q      c  c ",
      "           c  c ",
      "           cccc ",
      "                "
    ],
    [
      "           cccc ",
      "           cccc ",
      "           cccc ",
      "           cccc ",
      "           cccc ",
      "           cccc ",
      "    r      cccc ",
      "   r       cccc ",
      "           cccc ",
      "           cccc ",
      "           cccc ",
      "   r       cccc ",
      "    r      cccc ",
      "           cccc ",
      "           cccc ",
      "                "
    ]
  ]
}