{
  "name": "building_factory1_ground_270",
  "refpalette": "c70cities:building_factory1_ground_palette_270",
  "xsize": 16,
  "zsize": 16,
  "slices": [
    [
      "aaaazzaaaaazaaaa",
      "aaaaaaaazaaaaaaa",
      "azzaaaaaaaaaazaz",
      "zzbbbbbbbbbbbbzz",
      "zzbbbbbbbbbbbbzz",
      "zzbbbbbbbbbbbbzz",
      "zzbbbbbbbbbbbbzz",
      "zzbbbbbbbbbbbbzz",
      "zzbbbbbbbbbbbbzz",
      "zzbbbbbbbbbbbbzz",
      "zzbbbbbbbbbbbbzz",
      "zzbbbcbcbbbbbbzz",
      "zzbbbbbbbbbbbbzz",
      "zzbbbbbbbbbbbbzz",
      "zzzzzzzzzzzzzzzz",
      "zzzzzzzzzzzzzzzz"
    ],
    [
      "                ",
      "                ",
      "                ",
      " dhh        hh  ",
      "Odhix       ih d",
      "d hIx yt   njh  ",
      "ddhJxB     njhd ",
      " dhKx      n!h e",
      "ddhixA      ih  ",
      "N hLD Ar  okkh f",
      "ddhMEuuur p lh  ",
      "dNhMFCwwsqo mh d",
      "  hixxxx  o ihg ",
      "  hhhhhhhhhhhh d",
      "e d d    d    d ",
      "     d      d  d"
    ],
    [
      "                ",
      "                ",
      "                ",
      "  hhQQQQQQQQhh  ",
      "  hi        ih  ",
      "  h         nh  ",
      "  hW        nh  ",
      "  h          h  ",
      "  hiS       ih  ",
      "  h U     okkh  ",
      "  hM      R  h  ",
      "  hMV   TSo Ph  ",
      "  hixxxx  o ihg ",
      "  hhhhhhhhhhhh  ",
      "                ",
      "                "
    ],
    [
      "                ",
      "                ",
      "                ",
      "  hhQQQQQQQQhh  ",
      "  hi        ih  ",
      "  h1         h  ",
      "  h2         h  ",
      "  h3       Y h  ",
      "  hi        ih  ",
      "  h       okkh  ",
      "  hM0     o  h  ",
      "  hM  ZZ  o  h  ",
      "  hi xxx  o ihX ",
      "  hhhhhhhhhhhh  ",
      "                ",
      "                "
    ],
    [
      "                ",
      "                ",
      "    88888888    ",
      "  hhhhhhhhhhhh  ",
      "  hi    9999ih  ",
      "  47       @74  ",
      "  57   ^   #75  ",
      "  67       #76  ",
      "  hi      %$ih  ",
      "  47      ok74  ",
      "  57      o 75  ",
      "  67      o 76  ",
      "  hi      o ih  ",
      "  hhhhhhhhhhhh  ",
      "                ",
      "                "
    ],
    [
      "                ",
      "                ",
      "                ",
      "  &hhhhhhhhhh&  ",
      "  &*+7    7(*&  ",
      "  &* 7    7 *&  ",
      "  &* 7 )  7 *&  ",
      "  &* 7    7 *&  ",
      "  &*+7    7(*&  ",
      "  &* 7    7 *&  ",
      "  &* 7 )  7 *&  ",
      "  &* 7    7 *&  ",
      "  &*+7    7(*&  ",
      "  &hhhhhhhhhh&  ",
      "                ",
      "                "
    ]
  ]
}