{
  "name": "building_residential3_ground_270",
  "refpalette": "c70cities:building_residential3_ground_palette_270",
  "xsize": 16,
  "zsize": 16,
  "slices": [
    [
      "GGGGGGGGGGGGGGGG",
      "GGGGGGGGGGGGGGGG",
      "GGGGGGGGaaaaaaGG",
      "GGGcccccabbbbaGG",
      "GGGcddddbbbbbaGG",
      "GGGcddddbbbbbaGG",
      "GGGcddddbbbbbaGG",
      "GGGcddddbbbbbaGG",
      "GGaabbbbbbbbbaGG",
      "GGabbbbbbbbbbaGG",
      "GGabbbbbbbbbbaGG",
      "GGabbbbbbbbbbaGG",
      "GGabbbbbbbbbbaGG",
      "GGaaaaaaaaaaaaGG",
      "GGGGGGGGGGGGGGGG",
      "GGGGGGGGGGGGGGGG"
    ],
    [
      "effffgfffe  effe",
      "f              f",
      "f wwwww hinlih f",
      "f wccccch    h f",
      "f wcA   rq   h f",
      "g wcB   rq   h g",
      "f wcC   s   jh f",
      "f wcD        h f",
      "f hhhhhtt    h f",
      "f i xx      !h f",
      "g F       okkh g",
      "f F       p  h f",
      "f i Ey uu om h f",
      "f hhhhhhhhhhhh f",
      "f              f",
      "effffeffffgffffe"
    ],
    [
      "effffgfffe  effe",
      "f              f",
      "f       hiMJih f",
      "f  ccQQch    h f",
      "f  cS        F f",
      "g  Q         F g",
      "f  Q         F f",
      "f  cT       jh f",
      "f hhhhhtt    h f",
      "f i RR     K F f",
      "g F       okkh g",
      "f F       N  I f",
      "f i    PO oL h f",
      "f hhFFFhhFhIhh f",
      "f              f",
      "effffeffffgffffe"
    ],
    [
      "            V   ",
      "                ",
      "  YYYYYYhiWWih  ",
      "  Yccccch    h  ",
      "  Yc         U  ",
      "  Yc         U  ",
      "  Yc         U  ",
      "  Yc         h  ",
      "  hhhhhtt   jh  ",
      "  i          U  ",
      "  Z       okkh  ",
      "  Z       o  U  ",
      "  i       o  h  ",
      "  hhXXXhhXhXhh  ",
      "                ",
      "     V          "
    ],
    [
      "                ",
      "                ",
      "  000000hhhhhh  ",
      "  021111hbbbbh  ",
      "  03    bbbbbh  ",
      "  03    bbbbbh  ",
      "  03    bbbb h  ",
      "  03    bbbb h  ",
      "  hhbbbbbbbb h  ",
      "  hbbbbbbbbbjh  ",
      "  hbbbbbbbbbbh  ",
      "  hbbbbbbbbbbh  ",
      "  hbbbbbbbbbbh  ",
      "  hhhhhhhhhhhh  ",
      "                ",
      "                "
    ],
    [
      "                ",
      "                ",
      "  000000hFFFFh  ",
      "  0ccccch7  4h  ",
      "  0c    @7  4U  ",
      "  0c    @8  5U  ",
      "  0c    @  6 U  ",
      "  0c   ^@  6 h  ",
      "  hh@@@@@  6 h  ",
      "  F        6 U  ",
      "  F&&&&i#    U  ",
      "  F&**&i$9   U  ",
      "  F ((8i%    h  ",
      "  hhXXXhhFFFFh  ",
      "                ",
      "                "
    ]
  ]
}