{
  "name": "building_office1_top",
  "refpalette": "c70cities:building_office1_top_palette",
  "xsize": 16,
  "zsize": 16,
  "slices": [
    [
      "                ",
      "                ",
      "  aaaaaaaaaaaa  ",
      "  abbbbbbbbbba  ",
      "  abbbbbbbbbba  ",
      "  abbbbbbbbbba  ",
      "  abbbbbbbbbba  ",
      "  abbbbbbbbbba  ",
      " ccbbbbbbbbbbcc ",
      "  dbbbbbbbbbbd  ",
      "  dbbbbbbbbbbd  ",
      " efgbbbbbbbbbfe ",
      " ebbbbbbbbbbbbe ",
      " ebbbbbbbbbbbbe ",
      " eeeeeeeeeeeeee ",
      "                "
    ],
    [
      "                ",
      "                ",
      "  hhhhhhhhhhhh  ",
      "  h          h  ",
      "  h ii    ii h  ",
      "  h ij kk ji h  ",
      "  h ij kk ji h  ",
      "  h ii    ii h  ",
      " ccl        lcc ",
      "  d          d  ",
      "  d          d  ",
      " mf  kk  kk nfm ",
      " mo          pm ",
      " mo  qq  qq  pm ",
      " mmmmmmmmmmmmmm ",
      "                "
    ],
    [
      "                ",
      "                ",
      "                ",
      "  r          r  ",
      "                ",
      "  r          r  ",
      "                ",
      "  r          r  ",
      " ccs        scc ",
      "  d          d  ",
      "  d          d  ",
      " mf          fm ",
      " mo          pm ",
      " mo          pm ",
      " mmtddddddddtmm ",
      "                "
    ],
    [
      "                ",
      "                ",
      "                ",
      "  r          r  ",
      "                ",
      "  r          r  ",
      "                ",
      "  r          r  ",
      " cc          cc ",
      "  d          d  ",
      "  d          d  ",
      " mf          fm ",
      " mo           m ",
      " mo           m ",
      " mmtddddddddtmm ",
      "                "
    ],
    [
      "                ",
      "                ",
      "                ",
      "  r          r  ",
      "                ",
      "  r          r  ",
      "                ",
      "  r          r  ",
      " ccffffffffffcc ",
      "  fuuuuuuuuuuf  ",
      "  fuuuuuuuuuuf  ",
      " mffffffffffffm ",
      " m            m ",
      " m            m ",
      " mmmmmmmmmmmmmm ",
      "                "
    ],
    [
      "                ",
      "                ",
      "  wwwwwwwwwwww  ",
      "  weeeeeeeeeew  ",
      "  weeeeeeeeeew  ",
      "  weeeeeeeeeew  ",
      "  weeeeeeeeeew  ",
      "  weeeeeeeeeew  ",
      " ccwwwwwwwwwwcc ",
      "                ",
      "                ",
      " muuuuuuuuuuuum ",
      " muuuuuuuuuuuum ",
      " muuuuuuuuuuuum ",
      " mmmmmmmmmmmmmm ",
      "                "
    ]
  ]
}