{
  "name": "building_hotel3_floor1_90",
  "refpalette": "c70cities:building_hotel3_floor1_palette_90",
  "xsize": 16,
  "zsize": 16,
  "slices": [
    [
      "                ",
      "  a a a a a a   ",
      "  bbbbbbbbbbbba ",
      " abccccccccccb  ",
      "  bceeeeeeeecba ",
      " abceffffffecb  ",
      "  bceffffffecba ",
      " abdeffffffecb  ",
      "  bdeffffffecba ",
      " abceffffffecb  ",
      "  bceffffffecba ",
      " abceeeeeeeecb  ",
      "  bccccccccccba ",
      " abbbbbbbbbbbb  ",
      "   a a a a a a  ",
      "                "
    ],
    [
      "                ",
      "  a a a a a a   ",
      "  bbbbbbbbbbbba ",
      " ab          b  ",
      "  b eellllls ba ",
      " ab g      l b  ",
      "  b ehkh qql ba ",
      " abdei h ppl b  ",
      "  bdehhm ool ba ",
      " ab eh    rl b  ",
      "  b ehjj n l ba ",
      " ab eeeeeees b  ",
      "  b          ba ",
      " abbbbbbbbbbbb  ",
      "   a a a a a a  ",
      "                "
    ],
    [
      "                ",
      "  a a a a a a   ",
      "  bbbbbbbbbbbba ",
      " ab          b  ",
      "  b ee     s ba ",
      " ab t        b  ",
      "  b ehxh     ba ",
      " abde  h     b  ",
      "  bdehh  oo  ba ",
      " ab e     y  b  ",
      "  b eu    y  ba ",
      " ab eewwwwes b  ",
      "  b          ba ",
      " abbbbbbbbbbbb  ",
      "   a a a a a a  ",
      "                "
    ],
    [
      "                ",
      "  a a a a a a   ",
      "  bbbbbbbbbbbba ",
      " ab          b  ",
      "  b ee     s ba ",
      " ab e        b  ",
      "  b ehhh     ba ",
      " abde  h     b  ",
      "  bdehh  oo  ba ",
      " ab e        b  ",
      "  b e        ba ",
      " ab eeeeeees b  ",
      "  b          ba ",
      " abbbbbbbbbbbb  ",
      "   a a a a a a  ",
      "                "
    ],
    [
      "                ",
      "  a a a a a a   ",
      "  bbbbbbbbbbbba ",
      " ab          b  ",
      "  b ee     s ba ",
      " ab e        b  ",
      "  b ehhh     ba ",
      " abde  h     b  ",
      "  bdehh  !   ba ",
      " ab ey       b  ",
      "  b ey       ba ",
      " ab eeeeeees b  ",
      "  b          ba ",
      " abbbbbbbbbbbb  ",
      "   a a a a a a  ",
      "                "
    ],
    [
      "                ",
      "  a a a a a a   ",
      "  bbbbbbbbbbbba ",
      " ab          b  ",
      "  b eeeeeeee ba ",
      " ab eAAAAAAe b  ",
      "  b eAAAAAAe ba ",
      " abdeAAAAAAe b  ",
      "  bdeAAAAAAe ba ",
      " ab eAAAAAAe b  ",
      "  b eAAAAAAe ba ",
      " ab eeeeeeee b  ",
      "  b          ba ",
      " abbbbbbbbbbbb  ",
      "   a a a a a a  ",
      "                "
    ]
  ]
}