{
  "name": "building_lab1_ground_90",
  "refpalette": "c70cities:building_lab1_ground_palette_90",
  "xsize": 16,
  "zsize": 16,
  "slices": [
    [
      "zzzzzzzzzzzzzzzz",
      "zzzzzzzzzzzzzzzz",
      "zzzaazzzzzzzzzzz",
      "zzzaazazzzzzzzzz",
      "zzaazazaazzazzzz",
      "zzzaazzzzazazazz",
      "zzaaazazazazazzz",
      "zzzazazzzazazzzz",
      "zzazzzzzzzzzzzzz",
      "zzaazzzzzzzzzazz",
      "zzHHHHHHHHHzzzzz",
      "zzHHHHHHHHHzzzzz",
      "zzHHHHHHHHHzzzzz",
      "zzHHcHHHHHHzzzzz",
      "zzzbbbzzzzzzzzzz",
      "zzzzzzzzzzzzzzzz"
    ],
    [
      "d d dd e dd d  e",
      "dggggg      ggg ",
      " ghh dquyd  hhge",
      "e e      d dd  d",
      "d           d d ",
      "  hh            ",
      "d h      e d    ",
      "  k             ",
      "dgj d  sxs   d  ",
      "egh d dtwt      ",
      " f    pt!t fd   ",
      "d    i sts  d e ",
      "d  mn       ddg ",
      "  il norrA B  g ",
      "dfbbbbfbbbbf gg ",
      "deh hh dehhh  de"
    ],
    [
      "                ",
      "                ",
      "  h             ",
      "                ",
      "                ",
      "                ",
      "                ",
      "                ",
      "       JLJ      ",
      "       IFI      ",
      " f    pF F f    ",
      "       EKE      ",
      "                ",
      "   i CD  M      ",
      " fbbbbfbbbbf    ",
      "          h     "
    ],
    [
      "                ",
      "                ",
      "                ",
      "                ",
      "                ",
      "                ",
      "                ",
      "                ",
      "        ~       ",
      "        L       ",
      " p    pOLO p    ",
      "       OLO      ",
      "                ",
      "                ",
      " fNNNNfNNNNf    ",
      "                "
    ],
    [
      "                ",
      "                ",
      "                ",
      "                ",
      "                ",
      "                ",
      "                ",
      "                ",
      "        ~       ",
      "                ",
      " QQQQQQQQQQQ    ",
      " QNNNNQNNNNQ    ",
      " PRRRRPRRRRP    ",
      " PRRRRPRRRRP    ",
      " p    p    p    ",
      "                "
    ],
    [
      "                ",
      "                ",
      "                ",
      "                ",
      "                ",
      "                ",
      "                ",
      "                ",
      "        ~       ",
      "                ",
      "                ",
      "                ",
      "                ",
      "                ",
      " QNNNNQNNNNQ    ",
      " QQQQQQQQQQQ    "
    ]
  ]
}