{
  "name": "building_office2_top_90",
  "refpalette": "c70cities:building_office2_top_palette_90",
  "xsize": 16,
  "zsize": 16,
  "slices": [
    [
      "                ",
      " a            a ",
      " a dddddddddd a ",
      " abeeeeeeeeeeba ",
      " a!ccccccccccca ",
      " acccccccccccca ",
      " acccccccccccca ",
      " acccccccccccfa ",
      " acccccccccccfa ",
      " acccccccccccca ",
      " acccccccccccca ",
      " acccccccccccca ",
      " abeeeeeeeeeeba ",
      " a dddddddddd a ",
      " a            a ",
      "                "
    ],
    [
      "                ",
      " a            a ",
      " a dddddddddd a ",
      " ab          ba ",
      " ag          oa ",
      " a        n  oa ",
      " a  i        pa ",
      " a  i         a ",
      " a hi         a ",
      " a  i    l   pa ",
      " a           oa ",
      " ag     jkm  oa ",
      " ab          ba ",
      " a dddddddddd a ",
      " a            a ",
      "                "
    ],
    [
      "                ",
      " a            a ",
      " a dddddddddd a ",
      " ab          ba ",
      " ag          oa ",
      " a        r  oa ",
      " a           ga ",
      " a            a ",
      " a  q         a ",
      " a           ga ",
      " a           oa ",
      " ag          oa ",
      " ab          ba ",
      " a dddddddddd a ",
      " a            a ",
      "                "
    ],
    [
      "                ",
      " a            a ",
      " a dddddddddd a ",
      " ab          ba ",
      " a            a ",
      " a        r   a ",
      " a            a ",
      " a            a ",
      " a            a ",
      " a            a ",
      " a            a ",
      " a            a ",
      " ab          ba ",
      " a dddddddddd a ",
      " a            a ",
      "                "
    ],
    [
      "                ",
      " a            a ",
      " assssssssssssa ",
      " assssssssssssa ",
      " assssssssssssa ",
      " assssssssssssa ",
      " adddddddddddda ",
      " adddddddddddda ",
      " adddddddddddda ",
      " adddddddddddda ",
      " assssssssssssa ",
      " assssssssssssa ",
      " assssssssssssa ",
      " assssssssssssa ",
      " a            a ",
      "                "
    ],
    [
      "                ",
      " a            a ",
      " a            a ",
      " a            a ",
      " a            a ",
      " a            a ",
      " a            a ",
      " a            a ",
      " a            a ",
      " a            a ",
      " a            a ",
      " a            a ",
      " a            a ",
      " a            a ",
      " a            a ",
      "                "
    ]
  ]
}