{
  "name": "building_office3_top_180",
  "refpalette": "c70cities:building_office3_top_palette_180",
  "xsize": 16,
  "zsize": 16,
  "slices": [
    [
      "                ",
      " aabaabaabaabaa ",
      " acccccccccccca ",
      " bccccccccccccb ",
      " acccccccccccca ",
      " acccccccc!ccca ",
      " bccccccccccccb ",
      " acccccdvccccca ",
      " acccccdvccccca ",
      " bccccccccccccb ",
      " acccccccccccca ",
      " acccccccccccca ",
      " bccccccccccccb ",
      " acccccccccccca ",
      " aabaabaabaabaa ",
      "                "
    ],
    [
      "                ",
      " eebeebeebeebee ",
      " effffffffffffe ",
      " bf  h       fb ",
      " ef  hiiiigg fe ",
      " efiiii   ggife ",
      " bf  h     hifb ",
      " ef  h    iiife ",
      " efhhh    ih fe ",
      " bf  h    ih fb ",
      " ef  hhhhhgg fe ",
      " ef       gg fe ",
      " bf          fb ",
      " effffffffffffe ",
      " eebeebeebeebee ",
      "                "
    ],
    [
      "                ",
      " jjjjjjjjjjjjjj ",
      " j            j ",
      " j            j ",
      " j        gg  j ",
      " j        gg  j ",
      " j            j ",
      " j            j ",
      " j            j ",
      " j            j ",
      " j        gg  j ",
      " j        gg  j ",
      " j            j ",
      " j            j ",
      " jjjjjjjjjjjjjj ",
      "                "
    ],
    [
      "                ",
      "                ",
      "                ",
      "                ",
      "          k     ",
      "                ",
      "                ",
      "                ",
      "                ",
      "                ",
      "          k     ",
      "                ",
      "                ",
      "                ",
      "                ",
      "                "
    ],
    [
      "                ",
      "                ",
      "                ",
      "                ",
      "          l     ",
      "                ",
      "                ",
      "                ",
      "                ",
      "                ",
      "          l     ",
      "                ",
      "                ",
      "                ",
      "                ",
      "                "
    ],
    [
      "                ",
      "                ",
      "                ",
      "                ",
      "          m     ",
      "                ",
      "                ",
      "                ",
      "                ",
      "                ",
      "          m     ",
      "                ",
      "                ",
      "                ",
      "                ",
      "                "
    ]
  ]
}