{
  "name": "building_office2_floor1",
  "refpalette": "c70cities:building_office2_floor1_palette",
  "xsize": 16,
  "zsize": 16,
  "slices": [
    [
      "                ",
      " aaaaaaaaaaaaaa ",
      "   bccccccccb   ",
      "  decccccccced  ",
      "  decccccccced  ",
      "  decccccccced  ",
      "  decccccccced  ",
      "  decccccccced  ",
      "  decccccccced  ",
      "  decccccccced  ",
      "  decccccccced  ",
      "  decccccccced  ",
      "  decccccccced  ",
      "   bcccffcccb   ",
      " aaaaaaaaaaaaaa ",
      "                "
    ],
    [
      "                ",
      " aaaaaaaaaaaaaa ",
      "   bgghggghgb   ",
      "  d          d  ",
      "  d    ii    d  ",
      "  d  j    k  d  ",
      "  d   l  l   d  ",
      "  d  j    k  d  ",
      "  d   l  l   d  ",
      "  d  j    k  d  ",
      "  d   m  m   d  ",
      "  d          d  ",
      "  d          d  ",
      "   bnnoffonnb   ",
      " aaaaaaaaaaaaaa ",
      "                "
    ],
    [
      "                ",
      " aaaaaaaaaaaaaa ",
      "   bpp     pb   ",
      "  d          d  ",
      "  d          d  ",
      "  d   qqqq   d  ",
      "  d   q  q   d  ",
      "  d   q  q   d  ",
      "  d   q  q   d  ",
      "  d   qqqq   d  ",
      "  d          d  ",
      "  d          d  ",
      "  d          d  ",
      "   br sffs pb   ",
      " aaaaaaaaaaaaaa ",
      "                "
    ],
    [
      "                ",
      " aaaaaaaaaaaaaa ",
      "   bp       b   ",
      "  d          d  ",
      "  d          d  ",
      "  d          d  ",
      "  d          d  ",
      "  d          d  ",
      "  d          d  ",
      "  d          d  ",
      "  d          d  ",
      "  d          d  ",
      "  d          d  ",
      "   b   ff   b   ",
      " aaaaaaaaaaaaaa ",
      "                "
    ],
    [
      "                ",
      " aaaaaaaaaaaaaa ",
      "   b        b   ",
      "  d          d  ",
      "  d          d  ",
      "  d          d  ",
      "  d          d  ",
      "  d          d  ",
      "  d     !    d  ",
      "  d          d  ",
      "  d          d  ",
      "  d          d  ",
      "  d          d  ",
      "   b   ff   b   ",
      " aaaaaaaaaaaaaa ",
      "                "
    ],
    [
      "                ",
      " aaaaaaaaaaaaaa ",
      "   b        b   ",
      "  d tttttttt d  ",
      "  d tttttttt d  ",
      "  d tttttttt d  ",
      "  d tttttttt d  ",
      "  d tttuuttt d  ",
      "  d tttuuttt d  ",
      "  d tttttttt d  ",
      "  d tttttttt d  ",
      "  d tttttttt d  ",
      "  d tttttttt d  ",
      "   btttfftttb   ",
      " aaaaaaaaaaaaaa ",
      "                "
    ]
  ]
}