{
  "name": "building_office3_top_90",
  "refpalette": "c70cities:building_office3_top_palette_90",
  "xsize": 16,
  "zsize": 16,
  "slices": [
    [
      "                ",
      " aabaabaabaabaa ",
      " acccccccccccca ",
      " bccccccccccccb ",
      " acccccccccccca ",
      " acccccccccccca ",
      " bccccccccccccb ",
      " acccccddccccca ",
      " acccccvvccccca ",
      " bccccccccccccb ",
      " acccccccc!ccca ",
      " acccccccccccca ",
      " bccccccccccccb ",
      " acccccccccccca ",
      " aabaabaabaabaa ",
      "                "
    ],
    [
      "                ",
      " eebeebeebeebee ",
      " effffffffffffe ",
      " bf    h  i  fb ",
      " ef    h  i  fe ",
      " ef  hhhhhihhfe ",
      " bf  h    ii fb ",
      " ef  h     i fe ",
      " ef  h     i fe ",
      " bf  h     i fb ",
      " ef ggiii gg fe ",
      " ef gghhihgg fe ",
      " bf     iii  fb ",
      " effffffffffffe ",
      " eebeebeebeebee ",
      "                "
    ],
    [
      "                ",
      " jjjjjjjjjjjjjj ",
      " j            j ",
      " j            j ",
      " j            j ",
      " j            j ",
      " j            j ",
      " j            j ",
      " j            j ",
      " j            j ",
      " j  gg    gg  j ",
      " j  gg    gg  j ",
      " j            j ",
      " j            j ",
      " jjjjjjjjjjjjjj ",
      "                "
    ],
    [
      "                ",
      "                ",
      "                ",
      "                ",
      "                ",
      "                ",
      "                ",
      "                ",
      "                ",
      "                ",
      "     k     k    ",
      "                ",
      "                ",
      "                ",
      "                ",
      "                "
    ],
    [
      "                ",
      "                ",
      "                ",
      "                ",
      "                ",
      "                ",
      "                ",
      "                ",
      "                ",
      "                ",
      "     l     l    ",
      "                ",
      "                ",
      "                ",
      "                ",
      "                "
    ],
    [
      "                ",
      "                ",
      "                ",
      "                ",
      "                ",
      "                ",
      "                ",
      "                ",
      "                ",
      "                ",
      "     m     m    ",
      "                ",
      "                ",
      "                ",
      "                ",
      "                "
    ]
  ]
}