{
  "name": "building_hotel2_ground",
  "refpalette": "c70cities:building_hotel2_ground_palette",
  "xsize": 16,
  "zsize": 16,
  "slices": [
    [
      "GGGGGGGGGGGGGGGG",
      "GaaaaaaaaaaaaaaG",
      "GabccccccccdeeeG",
      "GabccccccccdGGGG",
      "Ga=ccccccccdfGfG",
      "Gacccccccccdffff",
      "GacccccccccdGGfG",
      "GaccccghhccdGGGf",
      "Gacc!cigjccdGGGG",
      "GaccccgihccdGGGG",
      "GaccccijjccdGGGG",
      "GacccccccccdGGGG",
      "GacccccccccdGGGG",
      "GaddddddddddGGGG",
      "GaGGGGGGGGGGGGGG",
      "GGGGGGGGGGGGGGGG"
    ],
    [
      "                ",
      " aaaaaaaaaaaaaa ",
      " ab  ==== klmmm ",
      " ab  =nn=  o    ",
      " a=        p    ",
      " ak        q    ",
      " a         o    ",
      " a rs      l    ",
      " a tu      l    ",
      " a  u      l    ",
      " a tu      l    ",
      " a         l    ",
      " ak        l    ",
      " allllllllll    ",
      " a              ",
      "                "
    ],
    [
      "                ",
      " aaaaaaaaaaaaaa ",
      " ab       wl    ",
      " ab        o    ",
      " a=        x    ",
      " aw        y    ",
      " a         o    ",
      " a         l    ",
      " a  A      l    ",
      " a         l    ",
      " a         l    ",
      " a         l    ",
      " aw        l    ",
      " allllllllll    ",
      " a              ",
      "                "
    ],
    [
      "                ",
      " aaaaaaaaaaaaaa ",
      " ab       wl    ",
      " ab        o    ",
      " a=        o    ",
      " aw        o    ",
      " a         o    ",
      " a         l    ",
      " a         l    ",
      " a         l    ",
      " a         l    ",
      " a         l    ",
      " aw        l    ",
      " allllllllll    ",
      " a              ",
      "                "
    ],
    [
      "                ",
      " aaaaaaaaaaaaaa ",
      " ab        l    ",
      " ab        l    ",
      " a=        l    ",
      " a         l    ",
      " a         l    ",
      " a         l    ",
      " a         l    ",
      " a         l    ",
      " a         l    ",
      " a         l    ",
      " a         l    ",
      " allllllllll    ",
      " a              ",
      "                "
    ],
    [
      "                ",
      " aaaaaaaaaaaaaa ",
      " abBBBBBBBBC    ",
      " abBBBBBBBBC    ",
      " a=BBBBBBBBC    ",
      " aBBBBBBBBBC    ",
      " aBBBBBBBBBC    ",
      " aBBBBBBBBBC    ",
      " aBBBBBBBBBC    ",
      " aBBBBBBBBBC    ",
      " aBBBBBBBBBC    ",
      " aBBBBBBBBBC    ",
      " aBBBBBBBBBC    ",
      " aCCCCCCCCCC    ",
      " a              ",
      "                "
    ]
  ]
}