{
  "name": "building_residential2_ground",
  "refpalette": "c70cities:building_residential2_ground_palette",
  "xsize": 16,
  "zsize": 16,
  "slices": [
    [
      "GGGGGGGGGGGGGGGG",
      "GGGGGGGGGGGGGGGG",
      "GGGGGGGGGGGGGGGG",
      "GGGaaaaaaaaaaGGG",
      "GGGabbbbccccaGGG",
      "GGGabbbbccccaGGG",
      "GGGabbbbccccaGGG",
      "GGGabbbbccccaGGG",
      "GGdeeeeeeeeeedGG",
      "GGdccccccccccdGG",
      "GGdccccccccccdGG",
      "GGdccccccccccdGG",
      "GGdccccccccccdGG",
      "GGddddddddddddGG",
      "GGGGGGGGGGGGGGGG",
      "GGGGGGGGGGGGGGGG"
    ],
    [
      "fgggghgggghggggf",
      "g              g",
      "g iiiiiiiiiiii g",
      "g iaaaaaaaaaai g",
      "g iajklmnopqai g",
      "h ia    n   ai h",
      "g ia    n   ai g",
      "g ia  r n   ai g",
      "g s tt  nuu  s g",
      "g s          s g",
      "f s       wwxs h",
      "  y    A BC  s g",
      "  D    E BCFIs g",
      "J ssssssssssss g",
      "f              g",
      "fgggghgggghggggf"
    ],
    [
      "fgggghgggghggggf",
      "g              g",
      "g              g",
      "g  aaaaaaaaaa  g",
      "g  aKL Mn !Na  g",
      "h  a    n   a  h",
      "g  a    n   a  g",
      "g  aOOO nuu a  g",
      "g s     n    s g",
      "g P          P g",
      "f s       wwQs h",
      "  R      SC  T g",
      "  U      SC  T g",
      "  ssPPPsssssss g",
      "f              g",
      "fgggghgggghggggf"
    ],
    [
      "                ",
      "                ",
      "                ",
      "   aaVVaaVVaa   ",
      "   a    n   a   ",
      "   V    n   V   ",
      "   V    nuu V   ",
      "   a    n   a   ",
      "  s     n    s  ",
      "  P          P  ",
      "  s       wwws  ",
      "  P       C  T  ",
      "  P       C  T  ",
      "  ssPPPsssssss  ",
      "                ",
      "                "
    ],
    [
      "                ",
      "                ",
      "  WWWWWWWWWWWW  ",
      "  WaaaaaaaaaaW  ",
      "  Wa    n   aW  ",
      "  Wa    nuu aW  ",
      "  Wa    n   aW  ",
      "  Wa    n   aW  ",
      "  s     n    s  ",
      "  WXXXXXXXXXXW  ",
      "  WXXXXXXXXXXW  ",
      "  WXXXXXXXXXXW  ",
      "  WXXXXXXXXXXW  ",
      "  WWWWWWWWWWWW  ",
      "                ",
      "                "
    ],
    [
      "                ",
      "                ",
      "  ssssssssssss  ",
      "  sccccccccccs  ",
      "  sccccccuuccs  ",
      "  scccccc  ccs  ",
      "  scccccc  ccs  ",
      "  scccccc  ccs  ",
      "  seeeeeeeeees  ",
      "  s  uu Y Z 0s  ",
      "  s     1 2 3s  ",
      "  s         4s  ",
      "  snn  nn  nns  ",
      "  ssssssssssss  ",
      "                ",
      "                "
    ]
  ]
}