{
  "name": "building_hotel3_floor1_90",
  "refpalette": "c70cities:building_hotel3_floor1_palette_90",
  "xsize": 16,
  "zsize": 16,
  "slices": [
    [
      "                ",
      "  a a a a a a   ",
      "  bbbbbbbbbbbba ",
      " abccccccccccb  ",
      "  bceeeeeeeecba ",
      " abceffffffecb  ",
      "  bceffffffecba ",
      " abdeffffffecb  ",
      "  bdeffffffecba ",
      " abceffffffecb  ",
      "  bceffffffecba ",
      " abceeeeeeeecb  ",
      "  bccccccccccba ",
      " abbbbbbbbbbbb  ",
      "   a a a a a a  ",
      "                "
    ],
    [
      "                ",
      "  a a a a a a   ",
      "  bbbbbbbbbbbba ",
      " ab          b  ",
      "  b eemmmmmt ba ",
      " ab g      m b  ",
      "  b ehlh rrm ba ",
      " abdeikh qqm b  ",
      "  bdehhn ppm ba ",
      " ab eh    sm b  ",
      "  b ehjj o m ba ",
      " ab eeeeeeet b  ",
      "  b          ba ",
      " abbbbbbbbbbbb  ",
      "   a a a a a a  ",
      "                "
    ],
    [
      "                ",
      "  a a a a a a   ",
      "  bbbbbbbbbbbba ",
      " ab          b  ",
      "  b ee     t ba ",
      " ab u        b  ",
      "  b ehyh     ba ",
      " abde  h     b  ",
      "  bdehh  pp  ba ",
      " ab e     A  b  ",
      "  b ew    A  ba ",
      " ab eexxxxet b  ",
      "  b          ba ",
      " abbbbbbbbbbbb  ",
      "   a a a a a a  ",
      "                "
    ],
    [
      "                ",
      "  a a a a a a   ",
      "  bbbbbbbbbbbba ",
      " ab          b  ",
      "  b ee     t ba ",
      " ab e        b  ",
      "  b ehhh     ba ",
      " abde  h     b  ",
      "  bdehh  pp  ba ",
      " ab e        b  ",
      "  b e        ba ",
      " ab eeeeeeet b  ",
      "  b          ba ",
      " abbbbbbbbbbbb  ",
      "   a a a a a a  ",
      "                "
    ],
    [
      "                ",
      "  a a a a a a   ",
      "  bbbbbbbbbbbba ",
      " ab          b  ",
      "  b ee     t ba ",
      " ab e        b  ",
      "  b ehhh     ba ",
      " abde  h     b  ",
      "  bdehh  !   ba ",
      " ab eA       b  ",
      "  b eA       ba ",
      " ab eeeeeeet b  ",
      "  b          ba ",
      " abbbbbbbbbbbb  ",
      "   a a a a a a  ",
      "                "
    ],
    [
      "                ",
      "  a a a a a a   ",
      "  bbbbbbbbbbbba ",
      " ab          b  ",
      "  b eeeeeeee ba ",
      " ab eBBBBBBe b  ",
      "  b eBBBBBBe ba ",
      " abdeBBBBBBe b  ",
      "  bdeBBBBBBe ba ",
      " ab eBBBBBBe b  ",
      "  b eBBBBBBe ba ",
      " ab eeeeeeee b  ",
      "  b          ba ",
      " abbbbbbbbbbbb  ",
      "   a a a a a a  ",
      "                "
    ]
  ]
}