{
  "name": "building_restaurant1_top",
  "refpalette": "c70cities:building_restaurant1_top_palette",
  "xsize": 16,
  "zsize": 16,
  "slices": [
    [
      "                ",
      "  aaaaaaa       ",
      "  abb bc        ",
      "  abbdbc        ",
      " ==bb======eeee ",
      " =bbbbbbbbbbbbe ",
      " =bbbbbbbbbbbbe ",
      " =bbbbbbbbbbbbe ",
      " =bbbbbbbb!bbb= ",
      " ============== ",
      "  fgggggggggh   ",
      "  fgggggggggh   ",
      "  fgggggggggh   ",
      "  fggggggggghc  ",
      "  iiiiiiiiiiii  ",
      "                "
    ],
    [
      "                ",
      "  aaaaaaa       ",
      "  a   jc        ",
      "  a   jc        ",
      " ==kl========== ",
      " =m  cccc no p= ",
      " =m       q  r= ",
      " =m       n  p= ",
      " =m       nsts= ",
      " ===      ===== ",
      "  fu w  x yA    ",
      "  fu B  B yA    ",
      "  fu w  x yAcc  ",
      "  iiiiiiiiiiii  ",
      "                ",
      "                "
    ],
    [
      "                ",
      "  CCCCCCC       ",
      "  a   jc        ",
      "  e   jc        ",
      " ==DE====cccc== ",
      " =F  eeee  I  = ",
      " =           J= ",
      " =        K  L= ",
      " =M           = ",
      " ===      ===== ",
      "  fuN      A    ",
      "  fu       Acc  ",
      "  ii      iiii  ",
      "                ",
      "                ",
      "                "
    ],
    [
      "                ",
      "                ",
      "  CCCCCCC       ",
      "  e   jc        ",
      " ============== ",
      " =   eeee     = ",
      " O   P        = ",
      " O            e ",
      " =            e ",
      " ===      ===== ",
      "  fuNNNNNN Acc  ",
      "  ii      iiii  ",
      "                ",
      "                ",
      "                ",
      "                "
    ],
    [
      "                ",
      "                ",
      "                ",
      "  CCCCCCC       ",
      " ============== ",
      " =   QQQQ     = ",
      " =   R  R   R = ",
      " =            = ",
      " =            = ",
      " ============== ",
      "  iiiiiiiiiiii  ",
      "                ",
      "                ",
      "                ",
      "                ",
      "                "
    ],
    [
      "                ",
      "                ",
      "                ",
      "                ",
      " ============== ",
      " ============== ",
      " ============== ",
      " ============== ",
      " ============== ",
      " ============== ",
      "                ",
      "                ",
      "                ",
      "                ",
      "                ",
      "                "
    ]
  ]
}