{
  "name": "building_hotel2_base1_270",
  "refpalette": "c70cities:building_hotel2_base1_palette_270",
  "xsize": 16,
  "zsize": 16,
  "slices": [
    [
      "vvvvvvvvvvvvvvvv",
      "vaaaaaaaaaaaaaav",
      "va!bbbbbbbbbbbav",
      "vabbbbbbbbbbbbav",
      "vabbbbbbbbbbbbav",
      "vabbbbbbbbbbbbav",
      "vabbbbbbbbbbbbav",
      "vabbbbbbbbbbbbav",
      "va!bbbbbbbbbbbav",
      "vabbbbbbbbbbbbav",
      "vabbbbbbbbbbbbav",
      "vabbbbbbbbbbbbav",
      "vabbbbbbbbbbbbav",
      "va!bbbbbbbbbbbav",
      "vaaaaaaaaaaaaaav",
      "vvvvvvvvvvvvvvvv"
    ],
    [
      "vvvvvvvvvvvvvvvv",
      "vcfffffffff=cccv",
      "vc ieg ieg =ddcv",
      "vc         e  cv",
      "vc i g i g    cv",
      "vc  e   e     cv",
      "vc i g i g    cv",
      "vc            cv",
      "vc ieg        cv",
      "vcfffff   e e cv",
      "vcmnmkf h=====cv",
      "vc      hbbbbbcv",
      "vc      hbbbbbcv",
      "vcolllfj=bbbbbcv",
      "vccccccccccccccv",
      "vvvvvvvvvvvvvvvv"
    ],
    [
      "vvvvvvvvvvvvvvvv",
      "vcfffffffff=cccv",
      "vc  j   j  =ddcv",
      "vc         r  cv",
      "vc  j   j     cv",
      "vc  j   j     cv",
      "vc  j   j     cv",
      "vc            cv",
      "vc  j         cv",
      "vcfffff   q q cv",
      "vcwu tf  =====cv",
      "vc           ocv",
      "vc        s  ocv",
      "vc    fj=pppppcv",
      "vccccccccccccccv",
      "vvvvvvvvvvvvvvvv"
    ],
    [
      "vvvvvvvvvvvvvvvv",
      "vcfffffffff=cccv",
      "vc         =ddcv",
      "vc         r  cv",
      "vc            cv",
      "vc            cv",
      "vc            cv",
      "vc            cv",
      "vc            cv",
      "vcfffff       cv",
      "vc    f      xcv",
      "vc            cv",
      "vc            cv",
      "vc yAyfj=ss sscv",
      "vccccccccccccccv",
      "vvvvvvvvvvvvvvvv"
    ],
    [
      "vvvvvvvvvvvvvvvv",
      "vcfffffffff=cccv",
      "vc         =ddcv",
      "vc            cv",
      "vc            cv",
      "vc            cv",
      "vc            cv",
      "vc            cv",
      "vc            cv",
      "vcfffff       cv",
      "vc    f       cv",
      "vc    f       cv",
      "vc    f       cv",
      "vc  A fj=s ssscv",
      "vccccccccccccccv",
      "vvvvvvvvvvvvvvvv"
    ],
    [
      "vvvvvvvvvvvvvvvv",
      "vcBBBBBBBBB=cccv",
      "vcBBBBBBBBB=ddcv",
      "vcBBBBBBBBBBBBcv",
      "vcBBBBBBBBBBBBcv",
      "vcBBBBBBBBBBBBcv",
      "vcBBBBBBBBBBBBcv",
      "vcBBBBBBBBBBBBcv",
      "vcBBBBBBBBBBBBcv",
      "vcfffffBBBBBBBcv",
      "vcBBBBfBBBBBBBcv",
      "vcBBBBfBBBBBBBcv",
      "vcBBBBfBBBBBBBcv",
      "vcBBBBfB=DCCDCcv",
      "vccccccccccccccv",
      "vvvvvvvvvvvvvvvv"
    ]
  ]
}