{
  "name": "building_residential2_ground_180",
  "refpalette": "c70cities:building_residential2_ground_palette_180",
  "xsize": 16,
  "zsize": 16,
  "slices": [
    [
      "GGGGGGGGGGGGGGGG",
      "GGGGGGGGGGGGGGGG",
      "GGddddddddddddGG",
      "GGdccccccccccdGG",
      "GGdccccccccccdGG",
      "GGdccccccccccdGG",
      "GGdccccccccccdGG",
      "GGdeeeeeeeeeedGG",
      "GGGaccccbbbbaGGG",
      "GGGaccccbbbbaGGG",
      "GGGaccccbbbbaGGG",
      "GGGaccccbbbbaGGG",
      "GGGaaaaaaaaaaGGG",
      "GGGGGGGGGGGGGGGG",
      "GGGGGGGGGGGGGGGG",
      "GGGGGGGGGGGGGGGG"
    ],
    [
      "fgggghgggghggggf",
      "g              f",
      "g ssssssssssss J",
      "g sIFCB E    D  ",
      "g s  CB A    y  ",
      "h sxww       s f",
      "g s          s g",
      "g s  uun  tt s g",
      "g ia   n r  ai g",
      "g ia   n    ai g",
      "h ia   n    ai h",
      "g iaqponmlkjai g",
      "g iaaaaaaaaaai g",
      "g iiiiiiiiiiii g",
      "g              g",
      "fgggghgggghggggf"
    ],
    [
      "fgggghgggghggggf",
      "g              f",
      "g sssssssPPPss  ",
      "g T  CS      U  ",
      "g T  CS      R  ",
      "h sQww       s f",
      "g P          P g",
      "g s    n     s g",
      "g  a uun OOOa  g",
      "g  a   n    a  g",
      "h  a   n    a  h",
      "g  aN! nM LKa  g",
      "g  aaaaaaaaaa  g",
      "g              g",
      "g              g",
      "fgggghgggghggggf"
    ],
    [
      "                ",
      "                ",
      "  sssssssPPPss  ",
      "  T  C       P  ",
      "  T  C       P  ",
      "  swww       s  ",
      "  P          P  ",
      "  s    n     s  ",
      "   a   n    a   ",
      "   V uun    V   ",
      "   V   n    V   ",
      "   a   n    a   ",
      "   aaVVaaVVaa   ",
      "                ",
      "                ",
      "                "
    ],
    [
      "                ",
      "                ",
      "  WWWWWWWWWWWW  ",
      "  WXXXXXXXXXXW  ",
      "  WXXXXXXXXXXW  ",
      "  WXXXXXXXXXXW  ",
      "  WXXXXXXXXXXW  ",
      "  s    n     s  ",
      "  Wa   n    aW  ",
      "  Wa   n    aW  ",
      "  Wa uun    aW  ",
      "  Wa   n    aW  ",
      "  WaaaaaaaaaaW  ",
      "  WWWWWWWWWWWW  ",
      "                ",
      "                "
    ],
    [
      "                ",
      "                ",
      "  ssssssssssss  ",
      "  snn  nn  nns  ",
      "  s4         s  ",
      "  s3 2 1     s  ",
      "  s0 Z Y uu  s  ",
      "  seeeeeeeeees  ",
      "  scc  ccccccs  ",
      "  scc  ccccccs  ",
      "  scc  ccccccs  ",
      "  sccuuccccccs  ",
      "  sccccccccccs  ",
      "  ssssssssssss  ",
      "                ",
      "                "
    ]
  ]
}