{
  "name": "building_gasstation1_ground_180",
  "refpalette": "c70cities:building_gasstation1_ground_palette_180",
  "xsize": 16,
  "zsize": 16,
  "slices": [
    [
      "GGGGGGGGGGGGGGGG",
      "GGGGGbHHHHHHHHHH",
      "GGGGGbHHHHHHHHHH",
      "GGaaaaaaaHHaHHHH",
      "GGaaaaaaaHHaHHHH",
      "GGaaaaaaaHHaHHHH",
      "GGaaaaaaaHHaHHHH",
      "GGaaaaaaaHHaHHHH",
      "GGaaaaaaaHHaHHHH",
      "GGaaaaaaaHHaHHHH",
      "GGaaaaaaaHHaHHHH",
      "GGaaaaaaaHHaHHHH",
      "GGaaaaaaaHHaHHHH",
      "GGGGGbHHHHHHHHHH",
      "GGGGGbHHHHHHHHHa",
      "GGGGGGGGGGGGGGGG"
    ],
    [
      "                ",
      "     fh g       ",
      "     fe d       ",
      "  jjjjjjj  its  ",
      "  j Fj EC       ",
      "  j Dj  C  mlk  ",
      "  jBjj Aj  its  ",
      "  j     q  y    ",
      "  j     x  wlk  ",
      "  jooo  u  its  ",
      "  jrr   q       ",
      "  jp!onnj  mlk  ",
      "  jjjjjjj  i    ",
      "     fh g       ",
      "     fe d      c",
      "                "
    ],
    [
      "                ",
      "                ",
      "                ",
      "  jjjjjjj  i    ",
      "  j Pj  O       ",
      "  j  j  O  I    ",
      "  jNjj Mj  i    ",
      "  j     q       ",
      "  j     L       ",
      "  joro  K  i    ",
      "  j     q       ",
      "  joopJJj  I    ",
      "  jjjjjjj  i    ",
      "                ",
      "               c",
      "                "
    ],
    [
      "                ",
      "                ",
      "                ",
      "  RRRRRRR  i    ",
      "  U  j  R       ",
      "  U  j  R       ",
      "  Rjjj  R  i    ",
      "  U     R       ",
      "  U     R       ",
      "  R     R  i    ",
      "  U     R       ",
      "  U r TSR       ",
      "  RRRRRRR  i    ",
      "                ",
      "               Q",
      "                "
    ],
    [
      "                ",
      "                ",
      "                ",
      "  jjjjjjj Vj    ",
      "  jYYj  j       ",
      "  jYYj  j       ",
      "  jjjjV j Xj    ",
      "  j  j  j       ",
      "  j  j  j       ",
      "  j  jX j Vj    ",
      "  j  j  j       ",
      "  jr jWrj       ",
      "  jjjjjjj Vj    ",
      "                ",
      "                ",
      "                "
    ],
    [
      "                ",
      "                ",
      " ZZZZZZZZZZZZZZ ",
      " ZaaaaaaaaaaffZ ",
      " ZaffaffaffaffZ ",
      " ZaffaffaffaffZ ",
      " ZaffaffaffaffZ ",
      " ZaffaffaffaffZ ",
      " ZaffaffaffaffZ ",
      " ZaffaffaffaffZ ",
      " ZaffaffaffaffZ ",
      " ZaffaffaffaffZ ",
      " ZaaaaaaaaaaffZ ",
      " ZZZZZZZZZZZZZZ ",
      "                ",
      "                "
    ]
  ]
}