{
  "name": "building_residential4_ground_180",
  "refpalette": "c70cities:building_residential4_ground_palette_180",
  "xsize": 16,
  "zsize": 16,
  "slices": [
    [
      "GGGGGGGGGGGGGGGG",
      "GGGGGGGGGGGGGGGG",
      "GGaaaaaaaaaaaaGG",
      "GGGdcccbbbbbbaGG",
      "GGGdcccbbbbbbaGG",
      "GGGdcccbbbbbbaGG",
      "GGGdcccbbbbbbaGG",
      "GGGdcccbbbbbbaGG",
      "GGGdcccbbbbbbaGG",
      "GGGdcccbbbbbbaGG",
      "GGGdcccbbbbbbaGG",
      "GGGdcccbbbbbbaGG",
      "GGGdcccbbbbbbaGG",
      "GGaaaaaaaaaaaaGG",
      "GGGGGGGGGGGGGGGG",
      "GGGGGGGGGGGGGGGG"
    ],
    [
      "effffgffffgffffe",
      "f              f",
      "f hhLLhLLhLLhh f",
      "f od  K  J  Ij f",
      "f odF E     Dj f",
      "g odCCC      j f",
      "f odw        h e",
      "f odB        A  ",
      "f ody    u   x  ",
      "f odw    u   h e",
      "g odt s  kq rj f",
      "f odn ml kq pj f",
      "f odn ml k   j f",
      "f hhiihiihiihh f",
      "f              f",
      "effffgffffgffffe"
    ],
    [
      "effffgffffgffffe",
      "f              f",
      "f hhZZhMMhMMhh f",
      "f  d  K   JY M f",
      "f  dX W      M f",
      "g  dCCC      M f",
      "f  dV        h e",
      "f  SU        T  ",
      "f  S     u   R  ",
      "f  d     u   h e",
      "g  dQ    NO  M f",
      "f  d  P  NO  M f",
      "f  d     N   M f",
      "f hhMMhMMhMMhh f",
      "f              f",
      "effffgffffgffffe"
    ],
    [
      "                ",
      "                ",
      "  hhhhhhhhhhhh  ",
      "  0d  K      M  ",
      "  0d  K    1 M  ",
      "  0dCCC      M  ",
      "  0d         h  ",
      "  0S         M  ",
      "  0S     u   M  ",
      "  0d     u   h  ",
      "  0d     N   M  ",
      "  0d     N   M  ",
      "  0d     N   M  ",
      "  hhhhhhhhhhhh  ",
      "                ",
      "                "
    ],
    [
      "                ",
      " 44444444444444 ",
      " ihhhhhhhhhhhhi ",
      "  3dbbbbb   bh  ",
      "  3dbbbbb   bh  ",
      "  3dbbbbb  1bh  ",
      "  3dbbbbbbbbbh  ",
      "   dbbbbbbbbbh  ",
      "   dbbbbbbbbbh  ",
      "  3dbbbbbbbbbh  ",
      "  3dbbbbbbbbbh  ",
      "  3dbbbbbbbbbh  ",
      "  3dbbbbbbbbbh  ",
      " LhhhhhhhhhhhhL ",
      " 22222222222222 ",
      "                "
    ],
    [
      "                ",
      "                ",
      " 44444444444444 ",
      " i3d {{! -  d3i ",
      "  3d]    -  d3  ",
      "  3d[    -  d3  ",
      "  3d++++)(( d3  ",
      "  *d        d&  ",
      "  ^d%88$ 77#d@  ",
      "  3d988  765d3  ",
      "  3d 88  765d3  ",
      "  3d33333333d3  ",
      " L3dhhhhhhhhd3L ",
      " 22222222222222 ",
      "                ",
      "                "
    ]
  ]
}