{
  "name": "building_office1_ground",
  "refpalette": "c70cities:building_office1_ground_palette",
  "xsize": 16,
  "zsize": 16,
  "slices": [
    [
      "GGGGaGGGGGGaGGGG",
      "GbbbbbbbbbbbbbbG",
      "GbccccccccccccbG",
      "GbcbbbbbbbbbbcbG",
      "GbcbbbbbbbbbbcbG",
      "GbcbbbbbbbbbbcbG",
      "Gbcbbbbb!bbbbcbG",
      "GbcbbbbbbbbbbcbG",
      "GbdbbbbbbbbbbdbG",
      "GbdbbbbbbbbbbdbG",
      "GbdbbbbbbbbbbdbG",
      "GbdbbbbbbbbbbdbG",
      "GbebbbbbbbbbbdbG",
      "GbebbbbbbbbbbdbG",
      "GbbbbbbbbbbbbbbG",
      "GGGGGGGGGGGGGGGG"
    ],
    [
      "ffffffffffffffff",
      "   g  g  g  g   ",
      " ghhhhhhhhhhhhg ",
      "  hi        ih  ",
      "  h   j  j   h  ",
      " gh  k    l  hg ",
      "  h  mlllll  h  ",
      "  h          h  ",
      " gd          dg ",
      "  h  n oo p  h  ",
      "  h  q oo r  h  ",
      " sdt u oo w  ds ",
      " sx           y ",
      " sx           A ",
      " ssssssssssssss ",
      "                "
    ],
    [
      "                ",
      "   g  g  g  g   ",
      " ghhhhhhhhhhhhg ",
      "  hB        Bh  ",
      "  h          h  ",
      " gh          hg ",
      "  h      CD  h  ",
      "  h          h  ",
      " gd          dg ",
      "  h          h  ",
      "  h          h  ",
      " sdt         ds ",
      " s            E ",
      " s            F ",
      " ssIhhhhhhhhIss ",
      "                "
    ],
    [
      "                ",
      "   g  g  g  g   ",
      " ghhhhhhhhhhhhg ",
      "  hB        Bh  ",
      "  h          h  ",
      " gh          hg ",
      "  h          h  ",
      "  h          h  ",
      " gd          dg ",
      "  h          h  ",
      "  h          h  ",
      " sdt         ds ",
      " sJ           s ",
      " sK           s ",
      " ssIhhhhhhhhIss ",
      "                "
    ],
    [
      "                ",
      "   g  g  g  g   ",
      " ghhhhhhhhhhhhg ",
      "  h          h  ",
      "  h          h  ",
      " gh          hg ",
      "  h          h  ",
      "  h          h  ",
      " gd          dg ",
      "  h          h  ",
      "  h          h  ",
      " sdt         ds ",
      " s            s ",
      " sL           s ",
      " ssssssssssssss ",
      "                "
    ],
    [
      "                ",
      " MMMMMMMMMMMMMM ",
      " MMMMMMMMMM MMM ",
      " MMIIIIIIIIIIMM ",
      " MMIIIIIIIIIIMM ",
      " MMIIIIIIIIIIMM ",
      " MMIIIIIIIIIIMM ",
      " MMIIIIIIIIIIMM ",
      " MMIIIIIIIIIIMM ",
      "  h IIIIIIII h  ",
      "  h IIIIIIII h  ",
      " sdtIIIIIIII ds ",
      " sIIIIIIIIIIIIs ",
      " sIIIIIIIIIIIIs ",
      " ssssssssssssss ",
      "                "
    ]
  ]
}