{
  "name": "building_residential2_ground_270",
  "refpalette": "c70cities:building_residential2_ground_palette_270",
  "xsize": 16,
  "zsize": 16,
  "slices": [
    [
      "GGGGGGGGGGGGGGGG",
      "GGGGGGGGGGGGGGGG",
      "GGddddddGGGGGGGG",
      "GGdcccceaaaaaGGG",
      "GGdccccebbbbaGGG",
      "GGdccccebbbbaGGG",
      "GGdccccebbbbaGGG",
      "GGdccccebbbbaGGG",
      "GGdcccceccccaGGG",
      "GGdcccceccccaGGG",
      "GGdcccceccccaGGG",
      "GGdcccceccccaGGG",
      "GGdcccceaaaaaGGG",
      "GGddddddGGGGGGGG",
      "GGGGGGGGGGGGGGGG",
      "GGGGGGGGGGGGGGGG"
    ],
    [
      "ffJ  fgggghggggf",
      "g              g",
      "g sDysssiiiiii g",
      "g s     aaaaai g",
      "g s    t   jai g",
      "h s    t   kai h",
      "g s     r  lai g",
      "g sEA      mai g",
      "g s    nnnnnai g",
      "g sBB  u   oai g",
      "h sCCw u   pai h",
      "g sF w     qai g",
      "g sI x  aaaaai g",
      "g ssssssiiiiii g",
      "g              g",
      "fgggghgggghggggf"
    ],
    [
      "ff   fgggghggggf",
      "g              g",
      "g sURsPs       g",
      "g s     aaaaa  g",
      "g P     O  Ka  g",
      "h P     O  La  h",
      "g P     O   a  g",
      "g s        Ma  g",
      "g s    nnnnna  g",
      "g sSS   u   a  g",
      "h sCCw  u  !a  h",
      "g s  w     Na  g",
      "g s  Q  aaaaa  g",
      "g sTTsPs       g",
      "g              g",
      "fgggghgggghggggf"
    ],
    [
      "                ",
      "                ",
      "  sPPsPs        ",
      "  s     aVVaa   ",
      "  P         a   ",
      "  P         V   ",
      "  P         V   ",
      "  s         a   ",
      "  s    nnnnna   ",
      "  s      u  V   ",
      "  sCCw   u  V   ",
      "  s  w      a   ",
      "  s  w  aVVaa   ",
      "  sTTsPs        ",
      "                ",
      "                "
    ],
    [
      "                ",
      "                ",
      "  WWWWWsWWWWWW  ",
      "  WXXXX aaaaaW  ",
      "  WXXXX     aW  ",
      "  WXXXX     aW  ",
      "  WXXXX     aW  ",
      "  WXXXX     aW  ",
      "  WXXXXnnnnnaW  ",
      "  WXXXX   u aW  ",
      "  WXXXX   u aW  ",
      "  WXXXX     aW  ",
      "  WXXXX aaaaaW  ",
      "  WWWWWsWWWWWW  ",
      "                ",
      "                "
    ],
    [
      "                ",
      "                ",
      "  ssssssssssss  ",
      "  sn   ecccccs  ",
      "  sn   ecccccs  ",
      "  s   uecccccs  ",
      "  s   uecccccs  ",
      "  sn   ecccccs  ",
      "  sn 1Yecccccs  ",
      "  s    e   ucs  ",
      "  s  2Ze   ucs  ",
      "  sn   ecccccs  ",
      "  sn430ecccccs  ",
      "  ssssssssssss  ",
      "                ",
      "                "
    ]
  ]
}