{
  "name": "building_hotel3_floor2_90",
  "refpalette": "c70cities:building_hotel3_floor2_palette_90",
  "xsize": 16,
  "zsize": 16,
  "slices": [
    [
      "                ",
      "  a a a a a a   ",
      "  bbbbbbbbbbbba ",
      " abccccccccccb  ",
      "  bceeeeeeeecba ",
      " abceffffffecb  ",
      "  bceffffffecba ",
      " abdeffffffecb  ",
      "  bdeff!fffecba ",
      " abceffffffecb  ",
      "  bceffffffecba ",
      " abceeeeeeeecb  ",
      "  bccccccccccba ",
      " abbbbbbbbbbbb  ",
      "   a a a a a a  ",
      "                "
    ],
    [
      "                ",
      "  a a a a a a   ",
      "  bbbbbbbbbbbba ",
      " ab          b  ",
      "  b eemmmmmr ba ",
      " ab g      m b  ",
      "  b eilinp m ba ",
      " abdejkinp m b  ",
      "  bdeii    m ba ",
      " ab eh    qm b  ",
      "  b eh   o m ba ",
      " ab eeeeeeer b  ",
      "  b          ba ",
      " abbbbbbbbbbbb  ",
      "   a a a a a a  ",
      "                "
    ],
    [
      "                ",
      "  a a a a a a   ",
      "  bbbbbbbbbbbba ",
      " ab          b  ",
      "  b ee     r ba ",
      " ab s        b  ",
      "  b eiui     ba ",
      " abde  i     b  ",
      "  bdeii      ba ",
      " ab e     w  b  ",
      "  b e     w  ba ",
      " ab eetttter b  ",
      "  b          ba ",
      " abbbbbbbbbbbb  ",
      "   a a a a a a  ",
      "                "
    ],
    [
      "                ",
      "  a a a a a a   ",
      "  bbbbbbbbbbbba ",
      " ab          b  ",
      "  b ee     r ba ",
      " ab e        b  ",
      "  b eiii     ba ",
      " abde  i     b  ",
      "  bdeii      ba ",
      " ab ew       b  ",
      "  b ew       ba ",
      " ab eeeeeeer b  ",
      "  b          ba ",
      " abbbbbbbbbbbb  ",
      "   a a a a a a  ",
      "                "
    ],
    [
      "                ",
      "  a a a a a a   ",
      "  bbbbbbbbbbbba ",
      " ab          b  ",
      "  b ee     r ba ",
      " ab e        b  ",
      "  b eiii     ba ",
      " abde  i     b  ",
      "  bdeiii     ba ",
      " ab e  i     b  ",
      "  b e  i     ba ",
      " ab eeeeeeer b  ",
      "  b          ba ",
      " abbbbbbbbbbbb  ",
      "   a a a a a a  ",
      "                "
    ],
    [
      "                ",
      "  a a a a a a   ",
      "  bbbbbbbbbbbba ",
      " ab          b  ",
      "  b eeeeeeee ba ",
      " ab exxxxxxe b  ",
      "  b exxxxxxe ba ",
      " abdexxxxxxe b  ",
      "  bdexxxxxxe ba ",
      " ab exxxxxxe b  ",
      "  b exxxxxxe ba ",
      " ab eeeeeeee b  ",
      "  b          ba ",
      " abbbbbbbbbbbb  ",
      "   a a a a a a  ",
      "                "
    ]
  ]
}