{
  "name": "building_apartment1_floor2_180",
  "refpalette": "c70cities:building_apartment1_floor2_palette_180",
  "xsize": 16,
  "zsize": 16,
  "slices": [
    [
      "                ",
      "      aaaaaaaaa ",
      "  ihgdbbbbbbbba ",
      "  ef  bbbbbbbba ",
      "  ebb bbbbbbbba ",
      "  dbbcbbbbbbbba ",
      " abbbbbbbbbbbba ",
      " abbbbbbbbbbbba ",
      " abbbbbbbbbbbba ",
      " abbbbbbbbbbbba ",
      " abbbbbbbbbbbba ",
      " abbbbbbbbbbbba ",
      " abbbbbbbbbbbba ",
      " abbbbbbbbbbbba ",
      " aaaaaaaaaaaaaa ",
      "                "
    ],
    [
      "                ",
      "      00000000Z ",
      "  ddYYq      Xm ",
      "  dW  qV R   Um ",
      "  dT  qS R   Qm ",
      "  d   q     POm ",
      " tqNqqqMML Iqqm ",
      " t  K      K  m ",
      " tJJq      IrFm ",
      " tqqqqqqAqEqqqm ",
      " tDC     q DC m ",
      " tB  yyAyq    m ",
      " tu  qx  w uu m ",
      " tos!q  rqpoonm ",
      " lkkkkkkkkkkkkj ",
      "                "
    ],
    [
      "                ",
      "      q91111197 ",
      "  ddddq      *9 ",
      "  dT& q%     ^9 ",
      "  Y   q%      9 ",
      "  h   q       9 ",
      " qq$qqq#   Iqq7 ",
      " q  @      @  9 ",
      " q  q      I  9 ",
      " qqqqqqq6q8qqq7 ",
      " q       q    q ",
      " 1   yy6yq    1 ",
      " 1   q  54    1 ",
      " 1   q3  q   21 ",
      " qqqqqqqqqqqqqq ",
      "                "
    ],
    [
      "                ",
      "      q91111197 ",
      "  .,ddq ';:`| 1 ",
      "  d \\Wq}      1 ",
      "  d   q}      1 ",
      "  d   q       9 ",
      " qqqqqq    Iqq7 ",
      " 1  q      I  1 ",
      " 1  q      I  1 ",
      " qqqqqqqqqqqqq7 ",
      " q       q    q ",
      " 1{  yyyyq   ]1 ",
      " 1[  q   q   -1 ",
      " 1+  q)  q   (1 ",
      " qq11qq11qq11qq ",
      "                "
    ],
    [
      "                ",
      "      q99999997 ",
      "  dYYeq       9 ",
      "  ,  \\q       9 ",
      "  ,  /q       9 ",
      "  ,   q       9 ",
      " qqqqqq    Iqq7 ",
      " 9 fq      I  9 ",
      " 9  q      I  9 ",
      " qqqqqqqqqqqqq7 ",
      " q       q    q ",
      " 9   yyyyq    9 ",
      " 9   q   q    9 ",
      " 9   q   q    9 ",
      " qqkkqqkkqqkkqq ",
      "                "
    ],
    [
      "                ",
      "      qqqqqqqqq ",
      "  ddddqdddddddq ",
      "  d   qdddddddq ",
      "  d  cqdddddddq ",
      "  d  Wqdddddddq ",
      " qqqqqqdddddddq ",
      " qddqddddddd<<q ",
      " qddqddddddd<<q ",
      " qqqqqqqqqqqqqq ",
      " qdddddddqddddq ",
      " qdddddddqddddq ",
      " qdddd<<<qddddq ",
      " qdddd<<<qddddq ",
      " qqqqqqqqqqqqqq ",
      "                "
    ]
  ]
}