{
  "name": "building_bunker1_ground",
  "refpalette": "c70cities:building_bunker1_ground_palette",
  "xsize": 16,
  "zsize": 16,
  "slices": [
    [
      "zzzzzzzzzzzzzzzz",
      "zzzzzzzzazaazazz",
      "zzzzzzzazazzaazz",
      "zzzzzzzzazzazazz",
      "zzzzzzzzzaazaaaz",
      "zzzzzzzzzazzzzaz",
      "zzzbvvzzzzzzzazz",
      "zzzvcvzzzzzzzzaz",
      "zzzbvvzzzzzzzzaz",
      "zzzzzzzzzzzzzzzz",
      "zzzzzzzzzzzzzzzz",
      "zzzzzzzzzzzzzzzz",
      "zzzzzzzzzzzzzzzz",
      "zzzzzzzzzzzzzzzz",
      "zzzzzzzzzzzzzzzz",
      "zzzzzzzzzzzzzzzz"
    ],
    [
      "   d            ",
      " eeee d     d   ",
      " eff gd   d     ",
      "def             ",
      "de f            ",
      "      h         ",
      " dgf hh       d ",
      "   ffhh         ",
      " d  fhh ~   d   ",
      "     hh      gd ",
      "  d  h      d ed",
      " e     i    dfe ",
      " ef g   d d ffed",
      " eff   fff g fe ",
      " eef dddfee eee ",
      "           d d d"
    ],
    [
      "                ",
      "                ",
      "                ",
      "  f             ",
      "                ",
      "                ",
      "                ",
      "    fh          ",
      "     h  ~       ",
      "                ",
      "                ",
      "                ",
      "                ",
      "  f          f  ",
      "                ",
      "                "
    ],
    [
      "                ",
      "                ",
      "                ",
      "                ",
      "                ",
      "                ",
      "                ",
      "                ",
      "        ~       ",
      "                ",
      "                ",
      "                ",
      "                ",
      "                ",
      "                ",
      "                "
    ],
    [
      "                ",
      "                ",
      "                ",
      "                ",
      "                ",
      "                ",
      "                ",
      "                ",
      "        ~       ",
      "                ",
      "                ",
      "                ",
      "                ",
      "                ",
      "                ",
      "                "
    ],
    [
      "                ",
      "                ",
      "                ",
      "                ",
      "                ",
      "                ",
      "                ",
      "                ",
      "        ~       ",
      "                ",
      "                ",
      "                ",
      "                ",
      "                ",
      "                ",
      "                "
    ]
  ]
}