{
  "name": "building_office2_top_180",
  "refpalette": "c70cities:building_office2_top_palette_180",
  "xsize": 16,
  "zsize": 16,
  "slices": [
    [
      "                ",
      " aaaaaaaaaaaaaa ",
      "   bcccffcccb   ",
      "  decccccccced  ",
      "  decccccccced  ",
      "  decccccccced  ",
      "  decccccccced  ",
      "  decccccccced  ",
      "  decccccccced  ",
      "  decccccccced  ",
      "  decccccccced  ",
      "  decccccccced  ",
      "  decccccccced  ",
      "   b!cccccccb   ",
      " aaaaaaaaaaaaaa ",
      "                "
    ],
    [
      "                ",
      " aaaaaaaaaaaaaa ",
      "   boop  poob   ",
      "  d          d  ",
      "  d          d  ",
      "  d  n     m d  ",
      "  d      l k d  ",
      "  d        j d  ",
      "  d          d  ",
      "  d          d  ",
      "  d          d  ",
      "  d   iiii   d  ",
      "  d     h    d  ",
      "   bg      gb   ",
      " aaaaaaaaaaaaaa ",
      "                "
    ],
    [
      "                ",
      " aaaaaaaaaaaaaa ",
      "   boog  goob   ",
      "  d          d  ",
      "  d          d  ",
      "  d  r       d  ",
      "  d          d  ",
      "  d          d  ",
      "  d          d  ",
      "  d          d  ",
      "  d          d  ",
      "  d     q    d  ",
      "  d          d  ",
      "   bg      gb   ",
      " aaaaaaaaaaaaaa ",
      "                "
    ],
    [
      "                ",
      " aaaaaaaaaaaaaa ",
      "   b        b   ",
      "  d          d  ",
      "  d          d  ",
      "  d  r       d  ",
      "  d          d  ",
      "  d          d  ",
      "  d          d  ",
      "  d          d  ",
      "  d          d  ",
      "  d          d  ",
      "  d          d  ",
      "   b        b   ",
      " aaaaaaaaaaaaaa ",
      "                "
    ],
    [
      "                ",
      " aaaaaaaaaaaaaa ",
      "  ssssddddssss  ",
      "  ssssddddssss  ",
      "  ssssddddssss  ",
      "  ssssddddssss  ",
      "  ssssddddssss  ",
      "  ssssddddssss  ",
      "  ssssddddssss  ",
      "  ssssddddssss  ",
      "  ssssddddssss  ",
      "  ssssddddssss  ",
      "  ssssddddssss  ",
      "  ssssddddssss  ",
      " aaaaaaaaaaaaaa ",
      "                "
    ],
    [
      "                ",
      " aaaaaaaaaaaaaa ",
      "                ",
      "                ",
      "                ",
      "                ",
      "                ",
      "                ",
      "                ",
      "                ",
      "                ",
      "                ",
      "                ",
      "                ",
      " aaaaaaaaaaaaaa ",
      "                "
    ]
  ]
}