{
  "name": "building_office1_base2",
  "refpalette": "c70cities:building_office1_base2_palette",
  "xsize": 16,
  "zsize": 16,
  "slices": [
    [
      "vvvvvvvvvvvvvvvv",
      "vaaaaaaaaaaaaaav",
      "vaaaaaaaaaaaaaav",
      "vaaaaaaaaaaaaaav",
      "vaaaaaaaaaaaaaav",
      "vaaaaaaaaaaaaaav",
      "vaaaaa!aa!aaaaav",
      "vaaaaaaaaaaaaaav",
      "vaaaaaaaaaaaaaav",
      "vaaaaaaaaaaaaaav",
      "vaaaaaaaaaaaaaav",
      "vaaaaaaaaaaaaaav",
      "vaaaaaaaaaaaaaav",
      "vaaaaaaaaaaaa!av",
      "vaaaaaaaaaaaaaav",
      "vvvvvvvvvvvvvvvv"
    ],
    [
      "vvvvvvvvvvvvvvvv",
      "vbbbbbbbbbbbbbbv",
      "vb            bv",
      "vb      c     bv",
      "vb            bv",
      "vb    d  d    bv",
      "vb   dd  d    bv",
      "vb    d   d   bv",
      "vb    d  d    bv",
      "vb            bv",
      "vb            bv",
      "vbefffeghefffebv",
      "vbi          jbv",
      "vbi          jbv",
      "vbbbbbbbbbbbbbbv",
      "vvvvvvvvvvvvvvvv"
    ],
    [
      "vvvvvvvvvvvvvvvv",
      "vbbbbbbbbbbbbbbv",
      "vb            bv",
      "vb            bv",
      "vb            bv",
      "vb            bv",
      "vb            bv",
      "vb            bv",
      "vb            bv",
      "vb            bv",
      "vb            bv",
      "vbefffeklefffebv",
      "vbi          mbv",
      "vbi          nbv",
      "vbbbbbbbbbbbbbbv",
      "vvvvvvvvvvvvvvvv"
    ],
    [
      "vvvvvvvvvvvvvvvv",
      "vbbbbbbbbbbbbbbv",
      "vb            bv",
      "vb            bv",
      "vb            bv",
      "vb            bv",
      "vb            bv",
      "vb            bv",
      "vb            bv",
      "vb            bv",
      "vb            bv",
      "vbefffeeeefffebv",
      "vbi           bv",
      "vbi          obv",
      "vbbbbbbbbbbbbbbv",
      "vvvvvvvvvvvvvvvv"
    ],
    [
      "vvvvvvvvvvvvvvvv",
      "vbbbbbbbbbbbbbbv",
      "vb            bv",
      "vb            bv",
      "vb            bv",
      "vb            bv",
      "vb            bv",
      "vb            bv",
      "vb            bv",
      "vb            bv",
      "vb            bv",
      "vbeffffffffffebv",
      "vbi           bv",
      "vbi           bv",
      "vbbbbbbbbbbbbbbv",
      "vvvvvvvvvvvvvvvv"
    ],
    [
      "vvvvvvvvvvvvvvvv",
      "vbbbbbbbbbbbbbbv",
      "vbppppppppppppbv",
      "vbpppppcqpppppbv",
      "vbppppppppppppbv",
      "vbppppppppppppbv",
      "vbpppppcrpppppbv",
      "vbppppppppppppbv",
      "vbppppppppppppbv",
      "vbppppprcpppppbv",
      "vbppppppppppppbv",
      "vbeppppppppppebv",
      "vbipppppppppppbv",
      "vbipppppppppppbv",
      "vbbbbbbbbbbbbbbv",
      "vvvvvvvvvvvvvvvv"
    ]
  ]
}