{
  "name": "building_policeoffice1_floor2",
  "refpalette": "c70cities:building_policeoffice1_floor2_palette",
  "xsize": 16,
  "zsize": 16,
  "slices": [
    [
      "                ",
      "  aaaaaaaaaa    ",
      "  abbbbbbbba    ",
      "  abbbbbbbba    ",
      "  abbbbbbbba    ",
      "  abbbbbbbba    ",
      "  ab!bbb!bba    ",
      "  abbbbbbbba    ",
      "  abbbbbbbba    ",
      "  abbbbbbbba    ",
      "  abbbbbbbba    ",
      " ccbbbbbbbbccdcc",
      " cebbbbbbbbb   c",
      " cebbbbbbbbb   c",
      " cfcccfcccfcccfc",
      "                "
    ],
    [
      "                ",
      "  aggggggggg    ",
      "  a        g    ",
      "  accc ccc g    ",
      "  ah h h h g    ",
      "  a        g    ",
      "  accc ccc g    ",
      "  ah h h h g    ",
      "  a        g    ",
      "  a    ccc g    ",
      "  a    h h a    ",
      " ccijk     ccdcc",
      " ce  k     l   c",
      " ce  kmmmm l   c",
      " cfcccfcccfcccfc",
      "                "
    ],
    [
      "                ",
      "  aggggggggg    ",
      "  a        g    ",
      "  an n n n g    ",
      "  a        g    ",
      "  a        g    ",
      "  an n n n g    ",
      "  a        g    ",
      "  a        g    ",
      "  a    n n g    ",
      "  a        a    ",
      " ccopk     ccdcc",
      " ce  k         c",
      " ce  kqr s     c",
      " cfcccfcccfcccfc",
      "                "
    ],
    [
      "                ",
      "  aggggggggg    ",
      "  a        g    ",
      "  a        g    ",
      "  a        g    ",
      "  a        g    ",
      "  a        g    ",
      "  a        g    ",
      "  a        g    ",
      "  a        g    ",
      "  a        a    ",
      " cckkk     ccdcc",
      " ce  m         c",
      " ce  k   s     c",
      " cfcccfcccfcccfc",
      "                "
    ],
    [
      "                ",
      "  aggggggggg    ",
      "  a        g    ",
      "  a        g    ",
      "  a        g    ",
      "  a        g    ",
      "  a        g    ",
      "  a        g    ",
      "  a        g    ",
      "  a        g    ",
      "  a        a    ",
      " cckkk     ccdcc",
      " ce  k         c",
      " ce  k   s     c",
      " cfcccfcccfcccfc",
      "                "
    ],
    [
      "                ",
      "  attttttttt    ",
      "  auuuuuuuut    ",
      "  auuuuuuuut    ",
      "  auuuuuuuut    ",
      "  auuuuuuuut    ",
      "  auuuuuuuut    ",
      "  auuuuuuuut    ",
      "  auuuuuuuut    ",
      "  auuuuuuuut    ",
      "  auuuuuuuua    ",
      " cckkkuuuuuccdcc",
      " ceuukuuuuuu   c",
      " ceuukuuuuuu   c",
      " cfcccfcccfcccfc",
      "                "
    ]
  ]
}