{
  "name": "building_residential2_ground_270",
  "refpalette": "c70cities:building_residential2_ground_palette_270",
  "xsize": 16,
  "zsize": 16,
  "slices": [
    [
      "GGGGGGGGGGGGGGGG",
      "GGGGGGGGGGGGGGGG",
      "GGddddddGGGGGGGG",
      "GGdcccceaaaaaGGG",
      "GGdccccebbbbaGGG",
      "GGdccccebbbbaGGG",
      "GGdccccebbbbaGGG",
      "GGdccccebbbbaGGG",
      "GGdcccceccccaGGG",
      "GGdcccceccccaGGG",
      "GGdcccceccccaGGG",
      "GGdcccceccccaGGG",
      "GGdcccceaaaaaGGG",
      "GGddddddGGGGGGGG",
      "GGGGGGGGGGGGGGGG",
      "GGGGGGGGGGGGGGGG"
    ],
    [
      "fgf  fgggghggggf",
      "g              g",
      "g sDysssiiiiii g",
      "g s     aaaaai g",
      "g s    t   jai g",
      "h s    t   kai h",
      "g s     r  lai g",
      "g sEA      mai g",
      "g s    nnnnnai g",
      "g sBB  u   oai g",
      "h sCCw u   pai h",
      "g sF w     qai g",
      "g s  x  aaaaai g",
      "g ssssssiiiiii g",
      "g              g",
      "fgggghgggghggggf"
    ],
    [
      "fgf  fgggghggggf",
      "g              g",
      "g sSPsNs       g",
      "g s     aaaaa  g",
      "g N     M  Ia  g",
      "h N     M  Ja  h",
      "g N     M   a  g",
      "g s        Ka  g",
      "g s    nnnnna  g",
      "g sQQ   u   a  g",
      "h sCCw  u  !a  h",
      "g sT w     La  g",
      "g s  O  aaaaa  g",
      "g sRRsNs       g",
      "g              g",
      "fgggghgggghggggf"
    ],
    [
      "                ",
      "                ",
      "  sNNsNs        ",
      "  s     aUUaa   ",
      "  N         a   ",
      "  N         U   ",
      "  N         U   ",
      "  s         a   ",
      "  s    nnnnna   ",
      "  s      u  U   ",
      "  sCCw   u  U   ",
      "  s  w      a   ",
      "  s  w  aUUaa   ",
      "  sRRsNs        ",
      "                ",
      "                "
    ],
    [
      "                ",
      "                ",
      "  VVVVVsVVVVVV  ",
      "  VWWWW aaaaaV  ",
      "  VWWWW     aV  ",
      "  VWWWW     aV  ",
      "  VWWWW     aV  ",
      "  VWWWW     aV  ",
      "  VWWWWnnnnnaV  ",
      "  VWWWW   u aV  ",
      "  VWWWW   u aV  ",
      "  VWWWW     aV  ",
      "  VWWWW aaaaaV  ",
      "  VVVVVsVVVVVV  ",
      "                ",
      "                "
    ],
    [
      "                ",
      "                ",
      "  ssssssssssss  ",
      "  sn   ecccccs  ",
      "  sn   ecccccs  ",
      "  s   uecccccs  ",
      "  s   uecccccs  ",
      "  sn   ecccccs  ",
      "  sn 0Xecccccs  ",
      "  s    e   ucs  ",
      "  s  1Ye   ucs  ",
      "  sn   ecccccs  ",
      "  sn32Zecccccs  ",
      "  ssssssssssss  ",
      "                ",
      "                "
    ]
  ]
}