{
  "name": "building_lab1_ground_270",
  "refpalette": "c70cities:building_lab1_ground_palette_270",
  "xsize": 16,
  "zsize": 16,
  "slices": [
    [
      "zzzzzzzzzzzzzzzz",
      "zzzzzzzzzzbbbzzz",
      "zzzzzHHHHHHcHHzz",
      "zzzzzHHHHHHHHHzz",
      "zzzzzHHHHHHHHHzz",
      "zzzzzHHHHHHHHHzz",
      "zzazzzzzzzzzaazz",
      "zzzzzzzzzzzzzazz",
      "zzzzazazzzazazzz",
      "zzzazazazazaaazz",
      "zzazazazzzzaazzz",
      "zzzzazzaazazaazz",
      "zzzzzzzzzazaazzz",
      "zzzzzzzzzzzaazzz",
      "zzzzzzzzzzzzzzzz",
      "zzzzzzzzzzzzzzzz"
    ],
    [
      "ed  hhhed hh hed",
      " gg fbbbbfbbbbfd",
      " g  B Arron li  ",
      " gdd       nm  d",
      " e d  sts i    d",
      "   df t!tp    f ",
      "      twtd d hge",
      "  d   sxs  d jgd",
      "             k  ",
      "    d e      h d",
      "            hh  ",
      " d d           d",
      "d  dd d      e e",
      "eghh  dyuqd hhg ",
      " ggg      gggggd",
      "e  d dd e dd d d"
    ],
    [
      "     h          ",
      "    fbbbbfbbbbf ",
      "      M  DC i   ",
      "                ",
      "      EKE       ",
      "    f F Fp    f ",
      "      IFI       ",
      "      JLJ       ",
      "                ",
      "                ",
      "                ",
      "                ",
      "                ",
      "             h  ",
      "                ",
      "                "
    ],
    [
      "                ",
      "    fNNNNfNNNNf ",
      "                ",
      "                ",
      "      OLO       ",
      "    p OLOp    p ",
      "       L        ",
      "       ~        ",
      "                ",
      "                ",
      "                ",
      "                ",
      "                ",
      "                ",
      "                ",
      "                "
    ],
    [
      "                ",
      "    p    p    p ",
      "    PRRRRPRRRRP ",
      "    PRRRRPRRRRP ",
      "    QNNNNQNNNNQ ",
      "    QQQQQQQQQQQ ",
      "                ",
      "       ~        ",
      "                ",
      "                ",
      "                ",
      "                ",
      "                ",
      "                ",
      "                ",
      "                "
    ],
    [
      "    QQQQQQQQQQQ ",
      "    QNNNNQNNNNQ ",
      "                ",
      "                ",
      "                ",
      "                ",
      "                ",
      "       ~        ",
      "                ",
      "                ",
      "                ",
      "                ",
      "                ",
      "                ",
      "                ",
      "                "
    ]
  ]
}