{
  "name": "building_office1_base2",
  "refpalette": "c70cities:building_office1_base2_palette",
  "xsize": 16,
  "zsize": 16,
  "slices": [
    [
      "vvvvvvvvvvvvvvvv",
      "vaaaaaaaaaaaaaav",
      "vaaaaaaaaaaaaaav",
      "vaaaaaaaaaaaaaav",
      "vaaaaaaaaaaaaaav",
      "vaaaaaaaaaaaaaav",
      "vaaaaa!aa!aaaaav",
      "vaaaaaaaaaaaaaav",
      "vaaaaaaaaaaaaaav",
      "vaaaaaaaaaaaaaav",
      "vaaaaaaaaaaaaaav",
      "vaaaaaaaaaaaaaav",
      "vaaaaaaaaaaaaaav",
      "vaaaaaaaaaaaa!av",
      "vaaaaaaaaaaaaaav",
      "vvvvvvvvvvvvvvvv"
    ],
    [
      "vvvvvvvvvvvvvvvv",
      "vbbbbbbbbbbbbbbv",
      "vbcd         ebv",
      "vbf d   g    hbv",
      "vbi         jkbv",
      "vbil  m  m d kbv",
      "vbf  mm  m   hbv",
      "vbin  m   m  kbv",
      "vbi   m  m  jkbv",
      "vbf          hbv",
      "vb           ebv",
      "vbopppoqropppobv",
      "vbs          tbv",
      "vbs          tbv",
      "vbbbbbbbbbbbbbbv",
      "vvvvvvvvvvvvvvvv"
    ],
    [
      "vvvvvvvvvvvvvvvv",
      "vbbbbbbbbbbbbbbv",
      "vb            bv",
      "vb           jbv",
      "vbd           bv",
      "vb            bv",
      "vbl           bv",
      "vb           jbv",
      "vb            bv",
      "vb           nbv",
      "vb            bv",
      "vbopppouwopppobv",
      "vbs          xbv",
      "vbs          ybv",
      "vbbbbbbbbbbbbbbv",
      "vvvvvvvvvvvvvvvv"
    ],
    [
      "vvvvvvvvvvvvvvvv",
      "vbbbbbbbbbbbbbbv",
      "vb            bv",
      "vb            bv",
      "vb            bv",
      "vb            bv",
      "vb            bv",
      "vb            bv",
      "vb            bv",
      "vb            bv",
      "vb            bv",
      "vbopppoooopppobv",
      "vbs           bv",
      "vbs          Abv",
      "vbbbbbbbbbbbbbbv",
      "vvvvvvvvvvvvvvvv"
    ],
    [
      "vvvvvvvvvvvvvvvv",
      "vbbbbbbbbbbbbbbv",
      "vbB          Bbv",
      "vbC          Cbv",
      "vbB          Bbv",
      "vbB          Bbv",
      "vbC          Cbv",
      "vbB          Bbv",
      "vbB          Bbv",
      "vbC          Cbv",
      "vbB          Bbv",
      "vboppppppppppobv",
      "vbs           bv",
      "vbs           bv",
      "vbbbbbbbbbbbbbbv",
      "vvvvvvvvvvvvvvvv"
    ],
    [
      "vvvvvvvvvvvvvvvv",
      "vbbbbbbbbbbbbbbv",
      "vbDDDDDDDDDDDDbv",
      "vbDDDDDgEDDDDDbv",
      "vbDDDDDDDDDDDDbv",
      "vbDDDDDDDDDDDDbv",
      "vbDDDDDgFDDDDDbv",
      "vbDDDDDDDDDDDDbv",
      "vbDDDDDDDDDDDDbv",
      "vbDDDDDFgDDDDDbv",
      "vbDDDDDDDDDDDDbv",
      "vboDDDDDDDDDDobv",
      "vbsDDDDDDDDDDDbv",
      "vbsDDDDDDDDDDDbv",
      "vbbbbbbbbbbbbbbv",
      "vvvvvvvvvvvvvvvv"
    ]
  ]
}