{
  "name": "building_bunker1_base1_270",
  "refpalette": "c70cities:building_bunker1_base1_palette_270",
  "xsize": 16,
  "zsize": 16,
  "slices": [
    [
      "vvvvvvvvvvvvvvvv",
      "v==============v",
      "v==============v",
      "v==============v",
      "vaa=aa=========v",
      "vaa=aa=========v",
      "vaa=aa=========v",
      "v=a=a==========v",
      "vaaaaa====aaaa=v",
      "vaaaaa====aaaa=v",
      "v=========aaaa=v",
      "v=========aaaa=v",
      "v=========aaaa=v",
      "v=========aaaa=v",
      "v==============v",
      "vvvvvvvvvvvvvvvv"
    ],
    [
      "vvvvvvvvvvvvvvvv",
      "vzzzzzbAs oljcbv",
      "vzzzzzbB     cbv",
      "vbbbbbbbbbb  bbv",
      "vJNbNJbowsb  dbv",
      "vK b Kb  sb  dbv",
      "vT b Lb   b  dbv",
      "vbObObEbxbbmbbbv",
      "vU   nbn tp  ebv",
      "vU    F      fbv",
      "vbRbbbbC     ebv",
      "vV bP     q  gbv",
      "vW bQ   y r  hbv",
      "vXSbIMIDyuqnkibv",
      "vbbbbbbbbbbbbbbv",
      "vvvvvvvvvvvvvvvv"
    ],
    [
      "vvvvvvvvvvvvvvvv",
      "vzzzzzEA@  o 0Ev",
      "vzzzzzE$     1Ev",
      "vEEEEEEEEEE  EEv",
      "v}-E&0E wsE   Ev",
      "v\\ E 1E   E   Ev",
      "vT E LE   E   Ev",
      "vE*E*EEE#EE5EEEv",
      "vT   6E6  7  LEv",
      "v     %      2Ev",
      "vE[EEEE      3Ev",
      "v|]E(         Yv",
      "v`]E)     8   Yv",
      "v: E+ ^   96  Yv",
      "v{{EEEEEEEEE44Zv",
      "vvvvvvvvvvvvvvvv"
    ],
    [
      "vvvvvvvvvvvvvvvv",
      "vzzzzzEA      Ev",
      "vzzzzzE!     ;Ev",
      "vEEEEEEEEEE  EEv",
      "vf E fE w E  'Ev",
      "v  E /E   E  'Ev",
      "v <E< E   E  'Ev",
      "vEEEEEEE{EEEEEEv",
      "v\u00a7   6E6     ,Ev",
      "v\u00a7    E      ,Ev",
      "vEEEEEE      ,Ev",
      "v \u00a4E>        ,Ev",
      "v\u00c0\u00a5E?        ,Ev",
      "v\u00c1 E\u00a3..    6 ,Ev",
      "vEEEEEEEEEEEEEEv",
      "vvvvvvvvvvvvvvvv"
    ],
    [
      "vvvvvvvvvvvvvvvv",
      "vzzzzzEA\u00c2\u00c2\u00c4\u00c2\u00c2\u00c2Ev",
      "vzzzzzE\u00c2\u00c2\u00c2\u00c4\u00c2\u00c2\u00c2Ev",
      "vEEEEEEEEEE\u00c4\u00c5EEv",
      "v\u00c4\u00c5E\u00c5\u00c4EEwEE\u00c2\u00c2\u00c3Ev",
      "v\u00c2\u00c2E\u00c2\u00c2EEEEE\u00c2\u00c2\u00c3Ev",
      "v\u00c2\u00c2E\u00c2\u00c2EEEEE\u00c2\u00c2\u00c3Ev",
      "vEEEEEEEEEEEEEEv",
      "v\u00c4\u00c2\u00c2\u00c2\u00c2E\u00c2\u00c2\u00c2\u00c2\u00c2\u00c2\u00c4Ev",
      "v\u00c4\u00c2\u00c2\u00c2\u00c2E\u00c2\u00c2\u00c2\u00c2\u00c2\u00c2\u00c4Ev",
      "vEEEEEE\u00c2\u00c2\u00c2\u00c2\u00c2\u00c2\u00c4Ev",
      "v\u00c2\u00c2EEEE\u00c2\u00c2\u00c2\u00c2\u00c2\u00c2\u00c4Ev",
      "v\u00c2\u00c2E\u00c4\u00c4\u00c4\u00c2\u00c2\u00c2\u00c2\u00c2\u00c2\u00c4Ev",
      "v\u00c4\u00c4EEEE\u00c2\u00c2\u00c2\u00c2\u00c2\u00c2\u00c4Ev",
      "vEEEEEEEEEEEEEEv",
      "vvvvvvvvvvvvvvvv"
    ],
    [
      "vvvvvvvvvvvvvvvv",
      "vzzzzzzzzzzzzzzv",
      "vzzzzzzzzzzzzzzv",
      "vzzzzzzzEzzzzzzv",
      "vzzzzzzEwEzzzzzv",
      "vzzzzzzzEzzzzzzv",
      "vzzzzzzzzzzzzzzv",
      "vzzzzzzzzzzzzzzv",
      "vzzzzzzzzzzzzzzv",
      "vzzzzzzzzzzzzzzv",
      "vzzzzzzzzzzzzzzv",
      "vzzzzzzzzzzzzzzv",
      "vzzzzzzzzzzzzzzv",
      "vzzzzzzzzzzzzzzv",
      "vzzzzzzzzzzzzzzv",
      "vvvvvvvvvvvvvvvv"
    ]
  ]
}