{
  "name": "building_office3_ground_90",
  "refpalette": "c70cities:building_office3_ground_palette_90",
  "xsize": 16,
  "zsize": 16,
  "slices": [
    [
      "GGGGGGGGGGGGGGGG",
      "GaaaaaaaaaaaaaaG",
      "GabbbbbbbbbbbbaG",
      "GabbbbbbbbbbbbaG",
      "GabbbbbbbbbbbbaG",
      "GabbbbbbbbbbbbaG",
      "GabbbbbbbbbbbbaG",
      "GabbbbbbbbbbbbaG",
      "GabbbbbbbbbbbbaG",
      "GabbbbbbbbbbbbaG",
      "GabbbbbbbbbbbbaG",
      "GabbbbbbbbbbbbaG",
      "Gab!bbbbbbbbbbaG",
      "GabbbbbbbbbbbbaG",
      "GaaaaaaaaaaaaaaG",
      "GGGGGGGGGGGGGGGG"
    ],
    [
      "                ",
      " ccdccdkldccdcc ",
      " ceeffg  gffeec ",
      " deh        hed ",
      " cf          fc ",
      " cf          fc ",
      " dg          gd ",
      " cf    jj    fc ",
      " cf    vv    fc ",
      " dg    i     gd ",
      " cf          fc ",
      " cf          fc ",
      " deh        hed ",
      " ceeffgffgffeec ",
      " ccdccdccdccdcc ",
      "                "
    ],
    [
      "                ",
      " ccdccdnodccdcc ",
      " c    m  m    c ",
      " d h        h d ",
      " c            c ",
      " c            c ",
      " dm          md ",
      " c     jj     c ",
      " c     vv     c ",
      " dm          md ",
      " c            c ",
      " c            c ",
      " d h        h d ",
      " c    m  m    c ",
      " ccdccdccdccdcc ",
      "                "
    ],
    [
      "                ",
      " ppdppdppdppdpp ",
      " p            p ",
      " d h        h d ",
      " p            p ",
      " p            p ",
      " d            d ",
      " p     jj     p ",
      " p     vv     p ",
      " d            d ",
      " p            p ",
      " p            p ",
      " d h        h d ",
      " p            p ",
      " ppdppdppdppdpp ",
      "                "
    ],
    [
      "                ",
      " ccdccdccdccdcc ",
      " cqqqqqqqqqqqqc ",
      " dqh        hqd ",
      " cq          qc ",
      " cq          qc ",
      " dq          qd ",
      " cq    jj    qc ",
      " cq    vv    qc ",
      " dq          qd ",
      " cq          qc ",
      " cq          qc ",
      " dqh        hqd ",
      " cqqqqqqqqqqqqc ",
      " ccdccdccdccdcc ",
      "                "
    ],
    [
      "                ",
      " rrrrrrrrrrrrrr ",
      " raaaaaaaaaaaar ",
      " rasddddddddsar ",
      " raddddddddddar ",
      " raddddddddddar ",
      " raddddddddddar ",
      " raddddjjddddar ",
      " raddddvvddddar ",
      " raddddddddddar ",
      " raddddddddddar ",
      " raddddddddddar ",
      " rasddddddddsar ",
      " raaaaaaaaaaaar ",
      " rrrrrrrrrrrrrr ",
      "                "
    ]
  ]
}