{
  "name": "building_hotel3_base2_270",
  "refpalette": "c70cities:building_hotel3_base2_palette_270",
  "xsize": 16,
  "zsize": 16,
  "slices": [
    [
      "aaaaaaaaaaaaaaaa",
      "abbbbcbbbccbbbba",
      "abbbbbbbbbbbbbca",
      "abbbfbbbbbbbbbba",
      "abbbdeeeeeedbbba",
      "acbbeeeeeeeebbba",
      "abbbeeeeeeeebbba",
      "afbbeeeeeeeebbba",
      "abbbeeeeeeeebb!a",
      "abbbeeeeeeeebbba",
      "abbbeeeeeeeebbba",
      "abbbdeeeeeedbbba",
      "acbbbbbbbbbbbcba",
      "abbbbbbbbbbbbbba",
      "abbbbbbcbbbbbbba",
      "aaaaaaaaaaaaaaaa"
    ],
    [
      "aaaaaaaaaaaaaaaa",
      "agfgihgiihhgiiga",
      "aggiiigijiigiiha",
      "agiiiiiiiiiiiiia",
      "aigidkkkkkkdiija",
      "ahiiktqk   kiiga",
      "agiikkroom kigga",
      "aijik     ldiija",
      "agiik     ldiiia",
      "agjik sppn kiiga",
      "agijk      kijia",
      "agjidkkkkkkdiiga",
      "ahiiiiiiiiiijhga",
      "aggijiijiijjggga",
      "aggggjghigigggga",
      "aaaaaaaaaaaaaaaa"
    ],
    [
      "aaaaaaaaaaaaaaaa",
      "ajijihjiihhjiiia",
      "ajiiiiiijiiiiiha",
      "aiiiiiiiiiiiiiia",
      "aiiidkkkkkkdiija",
      "ahiikt     kiiia",
      "ajiik      kijga",
      "aijik     ldiija",
      "aiiik     ldiiia",
      "agjik      kiiia",
      "agijk      kijia",
      "aijidkkkkkkdiiga",
      "ahiiiiiiiiiijhja",
      "agjijiijiijjigga",
      "aggiijihijigggga",
      "aaaaaaaaaaaaaaaa"
    ],
    [
      "aaaaaaaaaaaaaaaa",
      "auiuihuiihhuiiia",
      "auiiiiiiuiiiiiha",
      "aiiiiiiiiiiiiiia",
      "aiiidqkkkkkdiiua",
      "ahiikx     kiiia",
      "auiik      kiuua",
      "aiuik     ldiiua",
      "aiiik     ldiiia",
      "auuik      kiiia",
      "agiuk      kiuia",
      "aiuidkkkkkkdiiia",
      "ahiiiiiiiiiiuhua",
      "aiuiuiiuiiuuiuwa",
      "aguiiuihiuiuggga",
      "aaaaaaaaaaaaaaaa"
    ],
    [
      "aaaaaaaaaaaaaaaa",
      "a              a",
      "a              a",
      "a              a",
      "a   d  kkkkd   a",
      "a   k      k   a",
      "a   k      k   a",
      "a   k     ld   a",
      "a   k     ld   a",
      "a   k      k   a",
      "a   k      k   a",
      "a   dkkkkkkd   a",
      "a              a",
      "a              a",
      "a             ga",
      "aaaaaaaaaaaaaaaa"
    ],
    [
      "aaaaaaaaaaaaaaaa",
      "ayyyyyyyyyyyyyya",
      "ayyyyyyyyyyyyyya",
      "ayyyyyyyyyyyyyya",
      "ayyydAAAAAAdyyya",
      "ayyyAAAAAAAAyyya",
      "ayyyAAAAAAAAyyya",
      "ayyyAAAAAAldyyya",
      "ayyyAAAAAAldyyya",
      "ayyyAAAAAAAAyyya",
      "ayyyAAAAAAAAyyya",
      "ayyydAAAAAAdyyya",
      "ayyyyyyyyyyyyyya",
      "ayyyyyyyyyyyyyya",
      "ayyyyyyyyyyyyyya",
      "aaaaaaaaaaaaaaaa"
    ]
  ]
}