{
  "name": "building_policeoffice1_floor1_180",
  "refpalette": "c70cities:building_policeoffice1_floor1_palette_180",
  "xsize": 16,
  "zsize": 16,
  "slices": [
    [
      "                ",
      "cfcccfcccfcccfc ",
      "c   bbbbbbbbbec ",
      "c   bbbbbbbbbec ",
      "ccdccbbbbbbbbcc ",
      "    abbbbbbbba  ",
      "    abbbbbbbba  ",
      "    abbbbbbbba  ",
      "    abbbbbbbba  ",
      "    abbbbbbbba  ",
      "    abb!bbbbba  ",
      "    abbbbbbbba  ",
      "    abbbbbbbba  ",
      "    abbbbbbbba  ",
      "    aaaaaaaaaa  ",
      "                "
    ],
    [
      "                ",
      "cfcccfcccfcccfc ",
      "c   x yyyyw  ec ",
      "c   x     w  ec ",
      "ccdcc     wutcc ",
      "    a        a  ",
      "    g        a  ",
      "    g  s s   a  ",
      "    g  rqqpm a  ",
      "    g loccn  a  ",
      "    g  occnm a  ",
      "    g lkjji  a  ",
      "    g   h h  a  ",
      "    g        a  ",
      "    ggggggggga  ",
      "                "
    ],
    [
      "                ",
      "cfcccfcccfcccfc ",
      "c     E D w  ec ",
      "c         w  ec ",
      "ccdcc     wCBcc ",
      "    a        a  ",
      "    g        a  ",
      "    g        a  ",
      "    g    A   a  ",
      "    g  A     a  ",
      "    g     A  a  ",
      "    g   A    a  ",
      "    g        a  ",
      "    g        a  ",
      "    ggggggggga  ",
      "                "
    ],
    [
      "                ",
      "cfcccfcccfcccfc ",
      "c     E   w  ec ",
      "c         y  ec ",
      "ccdcc     wwwcc ",
      "    a        a  ",
      "    g        a  ",
      "    g        a  ",
      "    g        a  ",
      "    g   f    a  ",
      "    g    f   a  ",
      "    g        a  ",
      "    g        a  ",
      "    g        a  ",
      "    ggggggggga  ",
      "                "
    ],
    [
      "                ",
      "cfcccfcccfcccfc ",
      "c     E   w  ec ",
      "c         w  ec ",
      "ccdcc     wwwcc ",
      "    a        a  ",
      "    g        a  ",
      "    g        a  ",
      "    g        a  ",
      "    g   EE   a  ",
      "    g   EE   a  ",
      "    g        a  ",
      "    g        a  ",
      "    g        a  ",
      "    ggggggggga  ",
      "                "
    ],
    [
      "                ",
      "cfcccfcccfcccfc ",
      "c   IIIIIIwIIec ",
      "c   IIIIIIwIIec ",
      "ccdccIIIIIwwwcc ",
      "    aIIIIIIIIa  ",
      "    FIIIIIIIIa  ",
      "    FIIIIIIIIa  ",
      "    FIIIIIIIIa  ",
      "    FIIIIIIIIa  ",
      "    FIIIIIIIIa  ",
      "    FIIIIIIIIa  ",
      "    FIIIIIIIIa  ",
      "    FIIIIIIIIa  ",
      "    FFFFFFFFFa  ",
      "                "
    ]
  ]
}