{
  "name": "building_policeoffice1_top_180",
  "refpalette": "c70cities:building_policeoffice1_top_palette_180",
  "xsize": 16,
  "zsize": 16,
  "slices": [
    [
      "                ",
      "cgcccgcccgcccgc ",
      "f   bbbbbbbbbec ",
      "f   bbbbbbbbbec ",
      "ccdccccccccbccc ",
      "    abbbbbbbba  ",
      "    abbbbbbbba  ",
      "    abbbbbbbba  ",
      "    abbbbbbbba  ",
      "    abbbbbbbba  ",
      "    abbbbbbbba  ",
      "    ab!bbb!bba  ",
      "    abbbbbbbba  ",
      "    abbbbbbbba  ",
      "    aaaaaaaaaa  ",
      "                "
    ],
    [
      "                ",
      "cgcccgcccgcccgc ",
      "c   l         c ",
      "c   l         c ",
      "ccdcccccccc ccc ",
      "    ak h     a  ",
      "    a  h     a  ",
      "    a  h     a  ",
      "    a  h     a  ",
      "    a  hhhhh a  ",
      "    a  h   h a  ",
      "    ajgg jgg a  ",
      "    a gg  ggia  ",
      "    a  hhhh  a  ",
      "    aaaaaaaaaa  ",
      "                "
    ],
    [
      "                ",
      "cgcccgcccgcccgc ",
      "p             c ",
      "p             c ",
      "ccdcccccccc ccc ",
      "    o        n  ",
      "    o        n  ",
      "    o        n  ",
      "    o        n  ",
      "    o        n  ",
      "    o        n  ",
      "    o gg  gg n  ",
      "    o gg  gg n  ",
      "    o        n  ",
      "     mmmmmmmm   ",
      "                "
    ],
    [
      "                ",
      "cgcccgcccgcccgc ",
      "p             c ",
      "p             c ",
      "ccdcccccccccccc ",
      "                ",
      "                ",
      "                ",
      "                ",
      "                ",
      "                ",
      "       q   q    ",
      "                ",
      "                ",
      "                ",
      "                "
    ],
    [
      "                ",
      "ccccccccccccccc ",
      "c             c ",
      "c             c ",
      "ccccccccccccccc ",
      "                ",
      "                ",
      "                ",
      "                ",
      "                ",
      "                ",
      "      qq   qq   ",
      "       q   q    ",
      "                ",
      "                ",
      "                "
    ],
    [
      "                ",
      "ccccccccccccccc ",
      "ccccccccccccccc ",
      "ccccccccccccccc ",
      "ccccccccccccccc ",
      "                ",
      "                ",
      "                ",
      "                ",
      "                ",
      "                ",
      "      r     r   ",
      "       r   r    ",
      "                ",
      "                ",
      "                "
    ]
  ]
}