{
  "name": "building_hotel1_floor1_270",
  "refpalette": "c70cities:building_hotel1_floor1_palette_270",
  "xsize": 16,
  "zsize": 16,
  "slices": [
    [
      "                ",
      " aadddddddaaaaa ",
      " abbbbbbbbcbbba ",
      " abbbbbbbbcbbba ",
      " abbbbbbbbcbbba ",
      " abbbbbbbbcbbba ",
      " abbbb    cbbba ",
      " abbbb    cbbba ",
      " gbbbb    cbbba ",
      " gbbbbe   cbbba ",
      " gbbbbbbbdcbbba ",
      " gbbbbbbbbcbbba ",
      " gbbbbbbbbcbbba ",
      " abbbbbbbbcbbba ",
      " aaffffaaaaaaaa ",
      "                "
    ],
    [
      "                ",
      " aaaaaaaaaaaaaa ",
      " as   s s aj ha ",
      " aw    w  ak  a ",
      " at   t t al  a ",
      " a        am  a ",
      " as       an  a ",
      " aw   e   ao  a ",
      " at   e   ap  a ",
      " a    d   ak  a ",
      " as    uu a   a ",
      " aw          ia ",
      " at       rq ia ",
      " aw    w  r  ia ",
      " aaffffaaaaaaaa ",
      "                "
    ],
    [
      "                ",
      " aaaaaffffaaaaa ",
      " a        a   a ",
      " fB   BBB a   a ",
      " f        ax  a ",
      " f        a   a ",
      " f    ee  ay  a ",
      " fB   d   a   a ",
      " f        aA  a ",
      " a        a   a ",
      " a        a   a ",
      " aB           a ",
      " a            a ",
      " aC    C      a ",
      " aaffffaaaaaaaa ",
      "                "
    ],
    [
      "                ",
      " aaaaaaaaaaaaaa ",
      " a        a   a ",
      " a        a   a ",
      " a        a   a ",
      " a        a   a ",
      " a     deea   a ",
      " a        a   a ",
      " a        a   a ",
      " a        a   a ",
      " a        a   a ",
      " a            a ",
      " a            a ",
      " aC    C      a ",
      " aaffffaaaaaaaa ",
      "                "
    ],
    [
      "                ",
      " aaaaaaaaaaffaa ",
      " a        a   a ",
      " a        a   a ",
      " a        a   a ",
      " a        a   a ",
      " a       da   a ",
      " f       ea   a ",
      " f       ea   a ",
      " a        a   a ",
      " a        a   a ",
      " a        a   a ",
      " a        a   a ",
      " a        a   a ",
      " aaffffaaaaaaaa ",
      "                "
    ],
    [
      "                ",
      " aaaaaaaaaaaaaa ",
      " aDDDDDDDDaDDDa ",
      " aDDDDDDDDaDDDa ",
      " aDDDDDDDDaDDDa ",
      " aDDDDDDDDaDDDa ",
      " aDDDD    aDDDa ",
      " aDDDD    aDDDa ",
      " aDDDD   daDDDa ",
      " aDDDD   eaDDDa ",
      " aDDDDDDDDaDDDa ",
      " aDDDDDDDDaDDDa ",
      " aDDDDDDDDaDDDa ",
      " aDDDDDDDDaDDDa ",
      " aaffffaaaaaaaa ",
      "                "
    ]
  ]
}