{
  "name": "building_residential3_ground_270",
  "refpalette": "c70cities:building_residential3_ground_palette_270",
  "xsize": 16,
  "zsize": 16,
  "slices": [
    [
      "GGGGGGGGGGGGGGGG",
      "GGGGGGGGGGGGGGGG",
      "GGGGGGGGaaaaaaGG",
      "GGGcccccabbbbaGG",
      "GGGcddddbbbbbaGG",
      "GGGcddddbbbbbaGG",
      "GGGcddddbbbbbaGG",
      "GGGcddddbbbbbaGG",
      "GGaabbbbbbbbbaGG",
      "GGabbbbbbbbbbaGG",
      "GGabbbbbbbbbbaGG",
      "GGabbbbbbbbbbaGG",
      "GGabbbbbbbbbbaGG",
      "GGaaaaaaaaaaaaGG",
      "GGGGGGGGGGGGGGGG",
      "GGGGGGGGGGGGGGGG"
    ],
    [
      "effffgfffe  effe",
      "f              f",
      "f xxxxx hinlih f",
      "f xccccch    h f",
      "f xcB  wrq   h f",
      "g xcC   rq   h g",
      "f xcD   s   jh f",
      "f xcE        h f",
      "f hhhhhtt    h f",
      "f i yy      !h f",
      "g I       okkh g",
      "f I       p  h f",
      "f i FA uu om h f",
      "f hhhhhhhhhhhh f",
      "f              f",
      "effffeffffgffffe"
    ],
    [
      "effffgfffe  effe",
      "f              f",
      "f       hiNKih f",
      "f  ccRRch    h f",
      "f  cT        I f",
      "g  R         I g",
      "f  R         I f",
      "f  cU       jh f",
      "f hhhhhtt    h f",
      "f i SS     L I f",
      "g I       okkh g",
      "f I       O  J f",
      "f i    QP oM h f",
      "f hhIIIhhIhJhh f",
      "f              f",
      "effffeffffgffffe"
    ],
    [
      "            W   ",
      "                ",
      "  ZZZZZZhiXXih  ",
      "  Zccccch    h  ",
      "  Zc         V  ",
      "  Zc         V  ",
      "  Zc         V  ",
      "  Zc         h  ",
      "  hhhhhtt   jh  ",
      "  i          V  ",
      "  0       okkh  ",
      "  0       o  V  ",
      "  i       o  h  ",
      "  hhYYYhhYhYhh  ",
      "                ",
      "     W          "
    ],
    [
      "                ",
      "                ",
      "  111111hhhhhh  ",
      "  132222hbbbbh  ",
      "  14    bbbbbh  ",
      "  14    bbbbbh  ",
      "  14    bbbb h  ",
      "  14    bbbb h  ",
      "  hhbbbbbbbb h  ",
      "  hbbbbbbbbbjh  ",
      "  hbbbbbbbbbbh  ",
      "  hbbbbbbbbbbh  ",
      "  hbbbbbbbbbbh  ",
      "  hhhhhhhhhhhh  ",
      "                ",
      "                "
    ],
    [
      "                ",
      "                ",
      "  111111hIIIIh  ",
      "  1ccccch8  5h  ",
      "  1c    #8  5V  ",
      "  1c    #9  6V  ",
      "  1c    #  7 V  ",
      "  1c   &#  7 h  ",
      "  hh#####  7 h  ",
      "  I        7 V  ",
      "  I****i$    V  ",
      "  I*((*i%@   V  ",
      "  I ))9i^    h  ",
      "  hhYYYhhIIIIh  ",
      "                ",
      "                "
    ]
  ]
}