{
  "name": "building_hotel3_floor2_180",
  "refpalette": "c70cities:building_hotel3_floor2_palette_180",
  "xsize": 16,
  "zsize": 16,
  "slices": [
    [
      "                ",
      "  a a a a a a   ",
      "  bbbbbbbbbbbba ",
      " abccccccccccb  ",
      "  bceeeeeeeecba ",
      " abceffffffecb  ",
      "  bceffffffecba ",
      " abceffffffecb  ",
      "  bcefff!ffecba ",
      " abceffffffecb  ",
      "  bceffffffecba ",
      " abceeeeeeeecb  ",
      "  bccccddccccba ",
      " abbbbbbbbbbbb  ",
      "   a a a a a a  ",
      "                "
    ],
    [
      "                ",
      "  a a a a a a   ",
      "  bbbbbbbbbbbba ",
      " ab          b  ",
      "  b qllllllq ba ",
      " ab l    p e b  ",
      "  b l oo  ne ba ",
      " ab l mm   e b  ",
      "  b l ii   e ba ",
      " ab l k i  e b  ",
      "  b e ijihhe ba ",
      " ab egeeeeee b  ",
      "  b    dd    ba ",
      " abbbbbbbbbbbb  ",
      "   a a a a a a  ",
      "                "
    ],
    [
      "                ",
      "  a a a a a a   ",
      "  bbbbbbbbbbbba ",
      " ab          b  ",
      "  b q      q ba ",
      " ab      uue b  ",
      "  b        s ba ",
      " ab        s b  ",
      "  b   ii   s ba ",
      " ab   t i  s b  ",
      "  b e i i  e ba ",
      " ab ereeeeee b  ",
      "  b    dd    ba ",
      " abbbbbbbbbbbb  ",
      "   a a a a a a  ",
      "                "
    ],
    [
      "                ",
      "  a a a a a a   ",
      "  bbbbbbbbbbbba ",
      " ab          b  ",
      "  b q      q ba ",
      " ab        e b  ",
      "  b        e ba ",
      " ab        e b  ",
      "  b   ii   e ba ",
      " ab   i i  e b  ",
      "  b e i iuue ba ",
      " ab eeeeeeee b  ",
      "  b    dd    ba ",
      " abbbbbbbbbbbb  ",
      "   a a a a a a  ",
      "                "
    ],
    [
      "                ",
      "  a a a a a a   ",
      "  bbbbbbbbbbbba ",
      " ab          b  ",
      "  b q      q ba ",
      " ab        e b  ",
      "  b        e ba ",
      " ab        e b  ",
      "  b   iiiiie ba ",
      " ab   i i  e b  ",
      "  b e i i  e ba ",
      " ab eeeeeeee b  ",
      "  b    dd    ba ",
      " abbbbbbbbbbbb  ",
      "   a a a a a a  ",
      "                "
    ],
    [
      "                ",
      "  a a a a a a   ",
      "  bbbbbbbbbbbba ",
      " ab          b  ",
      "  b eeeeeeee ba ",
      " ab ewwwwwwe b  ",
      "  b ewwwwwwe ba ",
      " ab ewwwwwwe b  ",
      "  b ewwwwwwe ba ",
      " ab ewwwwwwe b  ",
      "  b ewwwwwwe ba ",
      " ab eeeeeeee b  ",
      "  b    dd    ba ",
      " abbbbbbbbbbbb  ",
      "   a a a a a a  ",
      "                "
    ]
  ]
}