{
  "name": "building_apartment1_floor1_270",
  "refpalette": "c70cities:building_apartment1_floor1_palette_270",
  "xsize": 16,
  "zsize": 16,
  "slices": [
    [
      "                ",
      " aaaaaaaaaaaaaa ",
      " abbbbbbbbbbbba ",
      " abbbbbbbbbbbba ",
      " abbbbbbbbbbbba ",
      " abbbbbbbbbbbba ",
      " abbbbbbbbbbbba ",
      " abbbbbbbbbbbba ",
      " abbbbbbbbbbbba ",
      " abbbbbbbbbbbba ",
      "  d  cbbbbbbbba ",
      "  g bbbbbbbbbba ",
      "  hfbbbbbbbbbba ",
      "  ieedbbbbbbbba ",
      "      aaaaaaaaa ",
      "                "
    ],
    [
      "                ",
      " Ummmmmmmmmmmmj ",
      " VSPLqp rp   nk ",
      " V   Kp qpy tok ",
      " V    CECpA tok ",
      " V       B    k ",
      " V MM F  pppupk ",
      " V    I  x w qk ",
      " V!QN I  p x rk ",
      " Vppppp  p w  k ",
      "  T   p  p wppk ",
      "  T   pEpp    k ",
      "  dRO J Dpy  nk ",
      "  ddddp DpA tok ",
      "      ssssssssl ",
      "                "
    ],
    [
      "                ",
      " 133331331pWWWp ",
      " 3#9  p 4p   Xp ",
      " W   7p  p    p ",
      " W    C5Cp    p ",
      " W       2    p ",
      " W       pppZpp ",
      " W       0 w  p ",
      " 3 88    p 0 Yp ",
      " pppppp  p w  p ",
      "  d   p  p wppp ",
      "  d@  p5pp    p ",
      "  dO  6  p    p ",
      "  ddThp  p    p ",
      "      pppppWWWp ",
      "                "
    ],
    [
      "                ",
      " 1WWW31WW1pWWWp ",
      " 3    p  p *^$p ",
      " W[   p  p    W ",
      " W[   CCCp    W ",
      " W]      p    p ",
      " W{   )  pppppp ",
      " W{      p w  W ",
      " 3 ++    p w  W ",
      " pppppp  p w  p ",
      "  dR  p  p wppp ",
      "  d-  pppp    W ",
      "  }   p  p    W ",
      "  \\dddp  p (&%p ",
      "      pWWppWWWp ",
      "                "
    ],
    [
      "                ",
      " 133331331p333p ",
      " 3    p  p    p ",
      " 3    p  p    k ",
      " 3    CCCp    k ",
      " 3       p    p ",
      " 3    f  pppppp ",
      " 3       p w  k ",
      " 3       p w  k ",
      " pppppp  p w  p ",
      "  e-| p  p wppp ",
      "  T   pppp    k ",
      "  T   pf p    k ",
      "  d}}}p  p    p ",
      "      p33pp333p ",
      "                "
    ],
    [
      "                ",
      " pppppppppppppp ",
      " pddddd``pddddp ",
      " pddddd``pddddp ",
      " pdddddddpddddp ",
      " pdddddddpddddp ",
      " pdddddddpppppp ",
      " pdddddddpdd``p ",
      " pdddddddpdd``p ",
      " ppppppddpdd``p ",
      "  d cRpddpddddp ",
      "  d   ppppddddp ",
      "  d   pddpddddp ",
      "  ddddpddpddddp ",
      "      ppppppppp ",
      "                "
    ]
  ]
}