{
  "name": "building_apartment1_floor2_270",
  "refpalette": "c70cities:building_apartment1_floor2_palette_270",
  "xsize": 16,
  "zsize": 16,
  "slices": [
    [
      "                ",
      " aaaaaaaaaaaaaa ",
      " abbbbbbbbbbbba ",
      " abbbbbbbbbbbba ",
      " abbbbbbbbbbbba ",
      " abbbbbbbbbbbba ",
      " abbbbbbbbbbbba ",
      " abbbbbbbbbbbba ",
      " abbbbbbbbbbbba ",
      " abbbbbbbbbbbba ",
      "  d  cbbbbbbbba ",
      "  g bbbbbbbbbba ",
      "  hfbbbbbbbbbba ",
      "  ieedbbbbbbbba ",
      "      aaaaaaaaa ",
      "                "
    ],
    [
      "                ",
      " Ymmmmmmmmmmmmj ",
      " ZWTPNq rq   nk ",
      " Z   Oq sqC wok ",
      " Z    FJFqD wok ",
      " Z       E   pk ",
      " Z QQ K  qqqxqk ",
      " Z    L  A y rk ",
      " Z UR L  q A sk ",
      " Zqqqqq  q y  k ",
      "  X   q  q yqqk ",
      "  X   qJqq   !k ",
      "  dVS M IqC  tk ",
      "  ddddq IqDBwok ",
      "      uuuuuuuul ",
      "                "
    ],
    [
      "                ",
      " 688886886q000q ",
      " 8*^  q  q   1q ",
      " 0    q  q    q ",
      " 0    F9Fq    q ",
      " 0       7    q ",
      " 0    @  qqq3qq ",
      " 0       5 y  q ",
      " 8 %% #  q 5  q ",
      " qqqqqq  q y42q ",
      "  d   q  q yqqq ",
      "  d&  q9qq    q ",
      "  dS  $  q    q ",
      "  ddXhq  q    q ",
      "      qqqqq000q ",
      "                "
    ],
    [
      "                ",
      " 600086006q000q ",
      " 8    q  q ]-(q ",
      " 0\\   q  q    0 ",
      " 0|   FFFq    0 ",
      " 0`      q    q ",
      " 0:      qqqqqq ",
      " 0;      q y  0 ",
      " 8       q y  0 ",
      " qqqqqq  q y )q ",
      "  dV  q  q yqqq ",
      "  d}  qqqq    0 ",
      "  '   q  q    0 ",
      "  ,dddq  q {[+q ",
      "      q00qq000q ",
      "                "
    ],
    [
      "                ",
      " 688886886q888q ",
      " 8    q  q    q ",
      " 8    q  q    k ",
      " 8    FFFq    k ",
      " 8       q    q ",
      " 8       qqqqqq ",
      " 8       q y  k ",
      " 8       q y  k ",
      " qqqqqq  q y  q ",
      "  e}. q  q yqqq ",
      "  X   qqqq    k ",
      "  X   qf q    k ",
      "  d'''q  q    q ",
      "      q88qq888q ",
      "                "
    ],
    [
      "                ",
      " qqqqqqqqqqqqqq ",
      " qddddd//qddddq ",
      " qddddd//qddddq ",
      " qdddddddqddddq ",
      " qdddddddqddddq ",
      " qdddddddqqqqqq ",
      " qdddddddqdd//q ",
      " qdddddddqdd//q ",
      " qqqqqqddqdd//q ",
      "  d cVqddqddddq ",
      "  d   qqqqddddq ",
      "  d   qddqddddq ",
      "  ddddqddqddddq ",
      "      qqqqqqqqq ",
      "                "
    ]
  ]
}