{
  "name": "building_residential2_floor1_180",
  "refpalette": "c70cities:building_residential2_floor1_palette_180",
  "xsize": 16,
  "zsize": 16,
  "slices": [
    [
      "                ",
      "                ",
      "                ",
      "   BB  BB  BB   ",
      "   A            ",
      "                ",
      "                ",
      "  dwwwwwwyxwwd  ",
      "  d  kj      d  ",
      " udt kj  fffsdr ",
      " qdpokj  ffihdn ",
      " mdl kj  ffihdg ",
      "  d      fffed  ",
      "  dddddddddddd  ",
      "    cba  cba    ",
      "                "
    ],
    [
      "                ",
      "                ",
      "                ",
      "   BB  BB  BB   ",
      "                ",
      "                ",
      "                ",
      "  dwwwwwwJIwwd  ",
      "  C          C  ",
      "  D          D  ",
      "  DF         D  ",
      "  D          D  ",
      "  C         EC  ",
      "  dCDDDDDDDDCd  ",
      "                ",
      "                "
    ],
    [
      "                ",
      " MMMMMMMMMMMMMM ",
      " LLLLLLLLLLLLLL ",
      " CCCCCCCCCCCCCC ",
      " KKKKKKKKKKKKKK ",
      "                ",
      "                ",
      "  dwwwwwwwwwwd  ",
      "  C          C  ",
      "  D          D  ",
      "  D          D  ",
      "  D          D  ",
      "  C          C  ",
      "  dCDDDDDDDDCd  ",
      "                ",
      "                "
    ],
    [
      "                ",
      " ~              ",
      "                ",
      "                ",
      " MMMMMMMMMMMMMM ",
      " LLLLLLLLLLLLLL ",
      " CCCCCCCCCCCCCC ",
      " KdCCCCCCCCCCdK ",
      "  d          d  ",
      "  d          d  ",
      "  d          d  ",
      "  d          d  ",
      "  d          d  ",
      "  dddddddddddd  ",
      "                ",
      "                "
    ],
    [
      "                ",
      " ~              ",
      "                ",
      "                ",
      "                ",
      "                ",
      "                ",
      " MMMMMMMMMMMMMM ",
      " LLLLLLLLLLLLLL ",
      " CCCCCCCCCCCCCC ",
      " KKKKKKKKKKKKKK ",
      "                ",
      "  B          B  ",
      "  B  BB  BB  B  ",
      "                ",
      "                "
    ],
    [
      "                ",
      " ~              ",
      "                ",
      "                ",
      "                ",
      "                ",
      "                ",
      "                ",
      "                ",
      "                ",
      " MMMMMMMMMMMMMM ",
      " LLLLLLLLLLLLLL ",
      " CCCCCCCCCCCCCC ",
      " KCKKCCKKCCKKCK ",
      "                ",
      "                "
    ]
  ]
}