{
  "name": "building_gasstation1_ground_270",
  "refpalette": "c70cities:building_gasstation1_ground_palette_270",
  "xsize": 16,
  "zsize": 16,
  "slices": [
    [
      "GHHHHHHHHHHHHHaG",
      "GHHHHHHHHHHHHHHG",
      "GHHHHHHHHHHHHHHG",
      "GHHHHHHHHHHHHHHG",
      "GHHaaaaaaaaaaHHG",
      "GHHHHHHHHHHHHHHG",
      "GHHHHHHHHHHHHHHG",
      "GHHaaaaaaaaaaHHG",
      "GHHaaaaaaaaaaHHG",
      "GHHaaaaaaaaaaHHG",
      "GbbaaaaaaaaaabbG",
      "GGGaaaaaaaaaaGGG",
      "GGGaaaaaaaaaaGGG",
      "GGGaaaaaaaaaaGGG",
      "GGGGGGGGGGGGGGGG",
      "GGGGGGGGGGGGGGGG"
    ],
    [
      "              c ",
      "                ",
      "   s ks ks k    ",
      "   t lt lt l    ",
      "   i miywi mi   ",
      "                ",
      "                ",
      " gdjCCjqxuqjjgd ",
      "   jE A    nj   ",
      " hej       njhe ",
      " ffjjjj  o ojff ",
      "   jFDj  or!j   ",
      "   j  B  orpj   ",
      "   jjjjjjjjjj   ",
      "                ",
      "                "
    ],
    [
      "              c ",
      "                ",
      "                ",
      "                ",
      "   i Ii  i Ii   ",
      "                ",
      "                ",
      "   jPPjqMLqjj   ",
      "   j  N    Jj   ",
      "   j       Jj   ",
      "   jjjj  o pj   ",
      "   jQ j  r Kj   ",
      "   j  O  o oj   ",
      "   jjjjjjjjjj   ",
      "                ",
      "                "
    ],
    [
      "              R ",
      "                ",
      "                ",
      "                ",
      "   i  i  i  i   ",
      "                ",
      "                ",
      "   SSSSSSSSSS   ",
      "   S       TS   ",
      "   S       US   ",
      "   Sjjj     S   ",
      "   S  j    rS   ",
      "   S  j     S   ",
      "   SVVSVVSVVS   ",
      "                ",
      "                "
    ],
    [
      "                ",
      "                ",
      "                ",
      "                ",
      "   j  j  j  j   ",
      "   W  Y  W  W   ",
      "                ",
      "   jjjjjjjjjj   ",
      "   j       rj   ",
      "   j  W  Y Xj   ",
      "   jjjjjjjjjj   ",
      "   jZZj     j   ",
      "   jZZj    rj   ",
      "   jjjjjjjjjj   ",
      "                ",
      "                "
    ],
    [
      "                ",
      "  000000000000  ",
      "  0ffffffffff0  ",
      "  0ffffffffff0  ",
      "  0aaaaaaaaaa0  ",
      "  0affffffffa0  ",
      "  0affffffffa0  ",
      "  0aaaaaaaaaa0  ",
      "  0affffffffa0  ",
      "  0affffffffa0  ",
      "  0aaaaaaaaaa0  ",
      "  0affffffffa0  ",
      "  0affffffffa0  ",
      "  0aaaaaaaaaa0  ",
      "  000000000000  ",
      "                "
    ]
  ]
}