{
  "name": "building_hotel3_base1_270",
  "refpalette": "c70cities:building_hotel3_base1_palette_270",
  "xsize": 16,
  "zsize": 16,
  "slices": [
    [
      "vvvvvvvvvvvvvvvv",
      "vaaaaaaaaaaaaaav",
      "vabbbbbbbbbbbbav",
      "vabbbbbbbbbbbbav",
      "vabbcbbbbbbbbbav",
      "vabbbbbbbbbbbbav",
      "vabbbbbbbbbbbbav",
      "vabbbbbbbbdcbbav",
      "vabbbbbbbbdcbbav",
      "vabbbbbbbbbbbbav",
      "vabbbbbbbbbbbbav",
      "vabbcbbbbbbcbbav",
      "vabbbbbbbbbbbbav",
      "vabbbbbbbbbbbbav",
      "vaaaaaaaaaaaaaav",
      "vvvvvvvvvvvvvvvv"
    ],
    [
      "vvvvvvvvvvvvvvvv",
      "vaaaaaaaaaaaaaav",
      "vat  t  i    eav",
      "vau  u  i    fav",
      "vaw cw  i    fav",
      "va!       i  gav",
      "vat  t     ikhav",
      "vau  u    dciiav",
      "vau  u    dcjjav",
      "vaw  w s      av",
      "va     sm pol av",
      "vat ct sm qcm av",
      "vau  u sm rjn av",
      "vaw  w sm     av",
      "vaaaaaaaaaaaaaav",
      "vvvvvvvvvvvvvvvv"
    ],
    [
      "vvvvvvvvvvvvvvvv",
      "vaaaaaaaaaaaaaav",
      "va           xav",
      "vaM  M       yav",
      "va  c        Aav",
      "va        i  Bav",
      "va         i  av",
      "vaM  M    dciiav",
      "vaM  M    dcC!av",
      "va     s      av",
      "va     sL JF  av",
      "va  c  sL KcD av",
      "vaM  M sL AIE av",
      "va     s      av",
      "vaaaaaaaaaaaaaav",
      "vvvvvvvvvvvvvvvv"
    ],
    [
      "vvvvvvvvvvvvvvvv",
      "vaaaaaaaaaaaaaav",
      "va            av",
      "va            av",
      "va  c         av",
      "va        i   av",
      "va         iONav",
      "va        dciiav",
      "va        dc  av",
      "va     s      av",
      "va     s      av",
      "va  c  s   c  av",
      "va     s      av",
      "va     s      av",
      "vaaaaaaaaaaaaaav",
      "vvvvvvvvvvvvvvvv"
    ],
    [
      "vvvvvvvvvvvvvvvv",
      "vaaaaaaaaaaaaaav",
      "va            av",
      "va            av",
      "va  c         av",
      "va        i   av",
      "va         iQPav",
      "va        dciiav",
      "va        dc  av",
      "va     s      av",
      "va     s      av",
      "va  c  s   c  av",
      "va     s      av",
      "va     s      av",
      "vaaaaaaaaaaaaaav",
      "vvvvvvvvvvvvvvvv"
    ],
    [
      "vvvvvvvvvvvvvvvv",
      "vaaaaaaaaaaaaaav",
      "vaRRRRRRRRRRRRav",
      "vaRRRRRRRRRRRRav",
      "vaRRcRRRRRRcRRav",
      "vaRRRRRRRRRRRRav",
      "vaRRRRRRRRRRRRav",
      "vaRRRRRRRRdcRRav",
      "vaRRRRRRRRdcRRav",
      "vaRRRRRRRRRRRRav",
      "vaRRRRRRRRRRRRav",
      "vaRRcRRRRRRcRRav",
      "vaRRRRRRRRRRRRav",
      "vaRRRRRRRRRRRRav",
      "vaaaaaaaaaaaaaav",
      "vvvvvvvvvvvvvvvv"
    ]
  ]
}