{
  "name": "building_office1_floor2_90",
  "refpalette": "c70cities:building_office1_floor2_palette_90",
  "xsize": 16,
  "zsize": 16,
  "slices": [
    [
      "                ",
      "        c  eeee ",
      "  aaaaaacddfbbe ",
      "  abbbbbbbbbbbe ",
      "  abbbbbbbbbbbe ",
      "  abbbbbb!bbbbe ",
      "  abbbbbbbbbbbe ",
      "  abbbbbbbbbbbe ",
      "  abbbbbbbbbbbe ",
      "  abbbbbbbbbbbe ",
      "  abbbbbbbbbbbe ",
      "  abbbbbbbbbbbe ",
      "  abbbbbbbbgbbe ",
      "  aaaaaacddfbbe ",
      "        c  eeee ",
      "                "
    ],
    [
      "                ",
      "        c  llll ",
      "  hhhhhhcddfnnl ",
      "  h           l ",
      "  h  jk  jk   l ",
      "  h  j   j    l ",
      "  h ij  ij    l ",
      "  h           l ",
      "  h           l ",
      "  h  jk  jk   l ",
      "  h  j   j    l ",
      "  h ij  ij    l ",
      "  h        g  l ",
      "  hhhhhhcddfmml ",
      "        c  llll ",
      "                "
    ],
    [
      "                ",
      "        c  llll ",
      "  hhhhhhcddf ql ",
      "  h           r ",
      "  h  o   o    d ",
      "  h  p   p    d ",
      "  h  o   o    d ",
      "  h           d ",
      "  h           d ",
      "  h  o   o    d ",
      "  h  p   p    d ",
      "  h  o   o    d ",
      "  h        g  r ",
      "  hhhhhhcddf  l ",
      "        c  llll ",
      "                "
    ],
    [
      "                ",
      "        c  llll ",
      "  hhhhhhcddf  l ",
      "  h           r ",
      "  h           d ",
      "  h           d ",
      "  h           d ",
      "  h           d ",
      "  h           d ",
      "  h           d ",
      "  h           d ",
      "  h           d ",
      "  h        g  r ",
      "  hhhhhhcddfssl ",
      "        c  llll ",
      "                "
    ],
    [
      "                ",
      "        c  llll ",
      "  hhhhhhcddf  l ",
      "  h           l ",
      "  h           l ",
      "  h           l ",
      "  h           l ",
      "  h           l ",
      "  h           l ",
      "  h           l ",
      "  h           l ",
      "  h           l ",
      "  h        g  l ",
      "  hhhhhhcddf  l ",
      "        c  llll ",
      "                "
    ],
    [
      "                ",
      "        c  llll ",
      "  hhhhhhcddfrrl ",
      "  hrrrrrr   rrl ",
      "  hrrrrrrrrrrrl ",
      "  hrrrrrrrrrrrl ",
      "  hrrrrrrrrrrrl ",
      "  hrrrrrrrrrrrl ",
      "  hrrrrrrrrrrrl ",
      "  hrrrrrrrrrrrl ",
      "  hrrrrrrrrrrrl ",
      "  hrrrrrrrrrrrl ",
      "  hrrrrrr  grrl ",
      "  hhhhhhcddfrrl ",
      "        c  llll ",
      "                "
    ]
  ]
}