{
  "name": "building_residential4_ground_180",
  "refpalette": "c70cities:building_residential4_ground_palette_180",
  "xsize": 16,
  "zsize": 16,
  "slices": [
    [
      "GGGGGGGGGGGGGGGG",
      "GGGGGGGGGGGGGGGG",
      "GGaaaaaaaaaaaaGG",
      "GGGdcccbbbbbbaGG",
      "GGGdcccbbbbbbaGG",
      "GGGdcccbbbbbbaGG",
      "GGGdcccbbbbbbaGG",
      "GGGdcccbbbbbbaGG",
      "GGGdcccbbbbbbaGG",
      "GGGdcccbbbbbbaGG",
      "GGGdcccbbbbbbaGG",
      "GGGdcccbbbbbbaGG",
      "GGGdcccbbbbbbaGG",
      "GGaaaaaaaaaaaaGG",
      "GGGGGGGGGGGGGGGG",
      "GGGGGGGGGGGGGGGG"
    ],
    [
      "effffgffffgffffe",
      "f              f",
      "f hhMMhMMhMMhh f",
      "f od  L  K  Jj f",
      "f odI F     Ej f",
      "g odDDD      j f",
      "f odC        h e",
      "f odB        A  ",
      "f ody    u   x  ",
      "f odw    u   h e",
      "g odt s  kq rj f",
      "f odn ml kq pj f",
      "f odn ml k   j f",
      "f hhiihiihiihh f",
      "f              f",
      "effffgffffgffffe"
    ],
    [
      "effffgffffgffffe",
      "f              f",
      "f hhZZhNNhNNhh f",
      "f  d  L   KY N f",
      "f  dX W      N f",
      "g  dDDD      N f",
      "f  dV        h e",
      "f  T         U  ",
      "f  T     u   S  ",
      "f  d     u   h e",
      "g  dR    OP  N f",
      "f  d  Q  OP  N f",
      "f  d     O   N f",
      "f hhNNhNNhNNhh f",
      "f              f",
      "effffgffffgffffe"
    ],
    [
      "                ",
      "                ",
      "  hhhhhhhhhhhh  ",
      "  0d  L      N  ",
      "  0d  L    1 N  ",
      "  0dDDD      N  ",
      "  0d         h  ",
      "  0T         N  ",
      "  0T     u   N  ",
      "  0d     u   h  ",
      "  0d     O   N  ",
      "  0d     O   N  ",
      "  0d     O   N  ",
      "  hhhhhhhhhhhh  ",
      "                ",
      "                "
    ],
    [
      "                ",
      " 44444444444444 ",
      " ihhhhhhhhhhhhi ",
      "  3dbbbbb   bh  ",
      "  3dbbbbb   bh  ",
      "  3dbbbbb  1bh  ",
      "  3dbbbbbbbbbh  ",
      "   dbbbbbbbbbh  ",
      "   dbbbbbbbbbh  ",
      "  3dbbbbbbbbbh  ",
      "  3dbbbbbbbbbh  ",
      "  3dbbbbbbbbbh  ",
      "  3dbbbbbbbbbh  ",
      " MhhhhhhhhhhhhM ",
      " 22222222222222 ",
      "                "
    ],
    [
      "                ",
      "                ",
      " 44444444444444 ",
      " i3d {{! -  d3i ",
      "  3d]    -  d3  ",
      "  3d[    -  d3  ",
      "  3d++++)(( d3  ",
      "  *d        d&  ",
      "  ^d%88$ 77#d@  ",
      "  3d988  765d3  ",
      "  3d 88  765d3  ",
      "  3d33333333d3  ",
      " M3dhhhhhhhhd3M ",
      " 22222222222222 ",
      "                ",
      "                "
    ]
  ]
}