{
  "name": "building_carservice1_top_180",
  "refpalette": "c70cities:building_carservice1_top_palette_180",
  "xsize": 16,
  "zsize": 16,
  "slices": [
    [
      "                ",
      "    eeaeeeaeeea ",
      "   ddgffffffffe ",
      "  ddcfffffffffe ",
      " edcffffffffffe ",
      " ecfffffffffffe ",
      " effffffffffffe ",
      " effffffffffffe ",
      " ecccccccccccce ",
      " eadddadddaccca ",
      "           bbb  ",
      "           bbb  ",
      "            bb  ",
      "            bb  ",
      "  a   a   a   a ",
      "                "
    ],
    [
      "                ",
      "    eeaeeeaeeea ",
      "   oo   y  y  e ",
      "  oo   wtuutsso ",
      " eo    sssxusso ",
      " e     wtuutsso ",
      " e  p   r  r  o ",
      " e qp         o ",
      " enm!mlkkk    e ",
      " eaeeeaeeeajjja ",
      "      i       i ",
      "      h       h ",
      "      h       h ",
      "      h       h ",
      "  a   ahhhahhha ",
      "                "
    ],
    [
      "                ",
      "    eeaeeeaeeea ",
      "   oo         e ",
      "  oo         Bo ",
      " eo      BCBuso ",
      " e           Bo ",
      " o            o ",
      " o            o ",
      " o mmmlA      e ",
      " eaeeeaeeeajjja ",
      "                ",
      "                ",
      "                ",
      "                ",
      "  a   a   a   a ",
      "                "
    ],
    [
      "                ",
      "    eeaeeeaeeea ",
      "   oo D   D   a ",
      "  oo  D   D   a ",
      " eo   D   D   a ",
      " e    D   D   a ",
      " e    D   D   a ",
      " e    D   D   a ",
      " e EEED   D   a ",
      " eaeeeaeeeajjja ",
      "  D   D   D   D ",
      "  D   D   D   D ",
      "  D   D   D   D ",
      "  D   D   D   D ",
      "  a   a   a   a ",
      "                "
    ],
    [
      "                ",
      "    eeeeeeeeeee ",
      "   FFFFFFFFFFFe ",
      "  FFFFFFFFFFFFe ",
      " eFFFFFFFFFFFFe ",
      " eFFFFFFFFFFFFe ",
      " eFFFFFFFFFFFFe ",
      " eFFFFFFFFFFFFe ",
      " eFFFFFFFFFFFFe ",
      " eeeeeeeeeeeeee ",
      "                ",
      "                ",
      "                ",
      "                ",
      "                ",
      "                "
    ],
    [
      "                ",
      "    eeeeeeeeeee ",
      "              e ",
      "              e ",
      " e            e ",
      " e            e ",
      " e            e ",
      " e            e ",
      " e            e ",
      " eeeeeeeeeeeeee ",
      "                ",
      "                ",
      "                ",
      "                ",
      "                ",
      "                "
    ]
  ]
}