{
  "name": "building_office1_floor1_180",
  "refpalette": "c70cities:building_office1_floor1_palette_180",
  "xsize": 16,
  "zsize": 16,
  "slices": [
    [
      "                ",
      " eeeeeeeeeeeeee ",
      " ebbbbbbbbbbbbe ",
      " ebbb!bbbbbbbbe ",
      " efbbbbbbbbbgfe ",
      "  dbbbbbbbbbbd  ",
      "  dbbbbbbbbbbd  ",
      " ccbbbbbbbbbbcc ",
      "  abbbbbbbbbba  ",
      "  abbbbbbbbbba  ",
      "  abbbbbbbbbba  ",
      "  abbbbbbbbbba  ",
      "  abbbbbbbbbba  ",
      "  aaaaaaaaaaaa  ",
      "                ",
      "                "
    ],
    [
      "                ",
      " rrrrrrrrrrrrrr ",
      " rx   A fy   tr ",
      " rx  wwwfu   tr ",
      " rf  i ifs  gfr ",
      "  d     q    d  ",
      "  d     f    d  ",
      " ccfffffffpofcc ",
      "  hn         h  ",
      "  h  m m m   h  ",
      "  h l k  k j h  ",
      "  h   i i i  h  ",
      "  h          h  ",
      "  hhhhhhhhhhhh  ",
      "                ",
      "                "
    ],
    [
      "                ",
      " rrLddddddddLrr ",
      " r      f    tr ",
      " rK  JIFf    tr ",
      " rf     f   gfr ",
      "  d     E    d  ",
      "  d     f    d  ",
      " ccfffffffDCfcc ",
      "  h          h  ",
      "  h          h  ",
      "  h  BBBBBB  h  ",
      "  h          h  ",
      "  h          h  ",
      "  hhhhhhhhhhhh  ",
      "                ",
      "                "
    ],
    [
      "                ",
      " rrLddddddddLrr ",
      " r      f    tr ",
      " r      f    tr ",
      " rf     f   gfr ",
      "  d     f    d  ",
      "  d     f    d  ",
      " ccffffffffffcc ",
      "  h          h  ",
      "  h          h  ",
      "  h          h  ",
      "  h          h  ",
      "  h          h  ",
      "  hhhhhhhhhhhh  ",
      "                ",
      "                "
    ],
    [
      "                ",
      " rrrrrrrrrrrrrr ",
      " r      f    Mr ",
      " r      f    Mr ",
      " rf     f   gfr ",
      "  d     f    d  ",
      "  d     f    d  ",
      " ccffffffffffcc ",
      "  h          h  ",
      "  h          h  ",
      "  h          h  ",
      "  h          h  ",
      "  h          h  ",
      "  hhhhhhhhhhhh  ",
      "                ",
      "                "
    ],
    [
      "                ",
      " rrrrrrrrrrrrrr ",
      " rLLLLLLfLLLLLr ",
      " rLLLLLLfLLLLLr ",
      " rf LLLLfLLLgfr ",
      "  d LLLLfLLL d  ",
      "  d LLLLfLLL d  ",
      " ccffffffffffcc ",
      "  hLLLLLLLLLLh  ",
      "  hLLLLLLLLLLh  ",
      "  hLLLLLLLLLLh  ",
      "  hLLLLLLLLLLh  ",
      "  hLLLLLLLLLLh  ",
      "  hhhhhhhhhhhh  ",
      "                ",
      "                "
    ]
  ]
}