{
  "name": "building_policeoffice1_floor1_270",
  "refpalette": "c70cities:building_policeoffice1_floor1_palette_270",
  "xsize": 16,
  "zsize": 16,
  "slices": [
    [
      "                ",
      " cccc           ",
      " feecaaaaaaaaaa ",
      " cbbbbbbbbbbbba ",
      " cbbbbbbbbbbbba ",
      " cbbbbbbbbbbbba ",
      " fbbbbbbbbbbbba ",
      " cbbbbbbbbbbbba ",
      " cbbbbbbbb!bbba ",
      " cbbbbbbbbbbbba ",
      " fbbbbbbbbbbbba ",
      " cbbcaaaaaaaaaa ",
      " c  c           ",
      " c  d           ",
      " f  c           ",
      " cccc           "
    ],
    [
      "                ",
      " cccc           ",
      " feecaaaaaaaaaa ",
      " c  t         g ",
      " c  u   m m   g ",
      " cwww   pnnih g ",
      " fy    sqccj  g ",
      " cy     qccjh g ",
      " cy    srook  g ",
      " cy      l l  g ",
      " f            g ",
      " cxxcaggggggggg ",
      " c  c           ",
      " c  d           ",
      " f  c           ",
      " cccc           "
    ],
    [
      "                ",
      " cccc           ",
      " feecaaaaaaaaaa ",
      " c  B         g ",
      " c  C         g ",
      " cwww     A   g ",
      " f      A     g ",
      " cD        A  g ",
      " c       A    g ",
      " cE           g ",
      " f            g ",
      " c  caggggggggg ",
      " c  c           ",
      " c  d           ",
      " f  c           ",
      " cccc           "
    ],
    [
      "                ",
      " cccc           ",
      " feecaaaaaaaaaa ",
      " c  w         g ",
      " c  w         g ",
      " cwyw         g ",
      " f        f   g ",
      " c       f    g ",
      " c            g ",
      " cE           g ",
      " f            g ",
      " c  caggggggggg ",
      " c  c           ",
      " c  d           ",
      " f  c           ",
      " cccc           "
    ],
    [
      "                ",
      " cccc           ",
      " feecaaaaaaaaaa ",
      " c  w         g ",
      " c  w         g ",
      " cwww         g ",
      " f       EE   g ",
      " c       EE   g ",
      " c            g ",
      " cE           g ",
      " f            g ",
      " c  caggggggggg ",
      " c  c           ",
      " c  d           ",
      " f  c           ",
      " cccc           "
    ],
    [
      "                ",
      " cccc           ",
      " feecaaaaaaaaaa ",
      " cIIwIIIIIIIIIF ",
      " cIIwIIIIIIIIIF ",
      " cwwwIIIIIIIIIF ",
      " fIIIIIIIIIIIIF ",
      " cIIIIIIIIIIIIF ",
      " cIIIIIIIIIIIIF ",
      " cIIIIIIIIIIIIF ",
      " fIIIIIIIIIIIIF ",
      " cIIcaFFFFFFFFF ",
      " c  c           ",
      " c  d           ",
      " f  c           ",
      " cccc           "
    ]
  ]
}