{
  "name": "building_residential4_ground_90",
  "refpalette": "c70cities:building_residential4_ground_palette_90",
  "xsize": 16,
  "zsize": 16,
  "slices": [
    [
      "GGGGGGGGGGGGGGGG",
      "GGGGGGGGGGGGGGGG",
      "GGaGGGGGGGGGGaGG",
      "GGaddddddddddaGG",
      "GGaccccccccccaGG",
      "GGaccccccccccaGG",
      "GGaccccccccccaGG",
      "GGabbbbbbbbbbaGG",
      "GGabbbbbbbbbbaGG",
      "GGabbbbbbbbbbaGG",
      "GGabbbbbbbbbbaGG",
      "GGabbbbbbbbbbaGG",
      "GGabbbbbbbbbbaGG",
      "GGaaaaaaaaaaaaGG",
      "GGGGGGGGGGGGGGGG",
      "GGGGGGGGGGGGGGGG"
    ],
    [
      "effffgffffgffffe",
      "f              f",
      "f hooooooooooh f",
      "f hddddddddddh f",
      "f inntwyBCDI M f",
      "g i       D  M g",
      "f hmms    DFLh f",
      "f ill        M f",
      "f i          M f",
      "f hkkkuu    Kh f",
      "g i qq       M g",
      "f i          M f",
      "f h pr     EJh f",
      "f hjjjhxAhjjjh f",
      "f              f",
      "efffffe  efffffe"
    ],
    [
      "effffgffffgffffe",
      "f              f",
      "f h          h f",
      "f hddddTTddddh f",
      "f N  R   VDX Z f",
      "g N       D  Z g",
      "f h Q     DWLh f",
      "f N          N f",
      "f N          N f",
      "f hOOOuu     h f",
      "g N PP      KN g",
      "f N         YN f",
      "f h          h f",
      "f hNNNhSUhNNNh f",
      "f              f",
      "efffffe  efffffe"
    ],
    [
      "                ",
      "                ",
      "  h0000000000h  ",
      "  hddddTTddddh  ",
      "  h       D  h  ",
      "  h       D  h  ",
      "  h       DLLh  ",
      "  h          h  ",
      "  h          h  ",
      "  hOOOuu     h  ",
      "  h          h  ",
      "  h        1 h  ",
      "  h          h  ",
      "  hNNNhNNhNNNh  ",
      "                ",
      "                "
    ],
    [
      "                ",
      " 2M          i4 ",
      " 2h3333  3333h4 ",
      " 2hddddddddddh4 ",
      " 2hbbbbbbbbbbh4 ",
      " 2hbbbbbbbbbbh4 ",
      " 2hbbbbbbbbbbh4 ",
      " 2hbbbbbbbbbbh4 ",
      " 2hbbbbbbbbbbh4 ",
      " 2hbbbbbbb   h4 ",
      " 2hbbbbbbb   h4 ",
      " 2hbbbbbbb1  h4 ",
      " 2hbbbbbbbbbbh4 ",
      " 2hhhhhhhhhhhh4 ",
      " 2M          i4 ",
      "                "
    ],
    [
      "                ",
      "  2M        i4  ",
      "  23333^*33334  ",
      "  2dddddddddd4  ",
      "  2h3 9% +[] 4  ",
      "  2h3888 +  {4  ",
      "  2h3888 +  {4  ",
      "  2h3  $ +  !4  ",
      "  2h3    )   4  ",
      "  2h3777 (---4  ",
      "  2h3667 (   4  ",
      "  2h355#     4  ",
      "  2dddddddddd4  ",
      "  23333@&33334  ",
      "  2M        i4  ",
      "                "
    ]
  ]
}