{
  "name": "building_apartment1_floor2_90",
  "refpalette": "c70cities:building_apartment1_floor2_palette_90",
  "xsize": 16,
  "zsize": 16,
  "slices": [
    [
      "                ",
      " aaaaaaaaa      ",
      " abbbbbbbbdeei  ",
      " abbbbbbbbbbfh  ",
      " abbbbbbbbbb g  ",
      " abbbbbbbbc  d  ",
      " abbbbbbbbbbbba ",
      " abbbbbbbbbbbba ",
      " abbbbbbbbbbbba ",
      " abbbbbbbbbbbba ",
      " abbbbbbbbbbbba ",
      " abbbbbbbbbbbba ",
      " abbbbbbbbbbbba ",
      " abbbbbbbbbbbba ",
      " aaaaaaaaaaaaaa ",
      "                "
    ],
    [
      "                ",
      " ltttttttt      ",
      " kou BqE qdddd  ",
      " kn  AqE K PSd  ",
      " k!   qqFq   U  ",
      " kqqx q  q   U  ",
      " k  x q  qqqqqW ",
      " ks y q  J OR W ",
      " kr x y  J    W ",
      " kqwqqq  I NN W ",
      " kp   C       W ",
      " kou BqDFD    W ",
      " kou Aqr qL   W ",
      " kn   qs qrMQTW ",
      " jmmmmmmmmmmmmV ",
      "                "
    ],
    [
      "                ",
      " qXXXqqqqq      ",
      " q    q  qhUdd  ",
      " q    q  7  Pd  ",
      " q    qq6q  @d  ",
      " qqqx q  q   d  ",
      " q  x q  qqqqqq ",
      " qZ 1 q    88 4 ",
      " q  x 1       X ",
      " qq0qqq       X ",
      " q    3       X ",
      " q    qD6D    X ",
      " q    q  q    X ",
      " qY   q5 q  9#4 ",
      " qXXXq244244442 ",
      "                "
    ],
    [
      "                ",
      " qXXXqqXXq      ",
      " q%&( q  qddd|  ",
      " X    q  q   \\  ",
      " X    qqqq  +d  ",
      " qqqx q  q  Sd  ",
      " q  x q  qqqqqq ",
      " X  x q    )) 4 ",
      " X  x q      }X ",
      " qqqqqq      {X ",
      " q    q      ]X ",
      " X    qDDD   [X ",
      " X    q  q   -X ",
      " q$^* q  q    4 ",
      " qXXXq2XX24XXX2 ",
      "                "
    ],
    [
      "                ",
      " q444qq44q      ",
      " q    q  q\\\\\\d  ",
      " k    q fq   U  ",
      " k    qqqq   U  ",
      " qqqx q  q :+e  ",
      " q  x q  qqqqqq ",
      " k  x q       4 ",
      " k  x q       4 ",
      " qqqqqq  `    4 ",
      " q    q       4 ",
      " k    qDDD    4 ",
      " k    q  q    4 ",
      " q    q  q    4 ",
      " q444q244244442 ",
      "                "
    ],
    [
      "                ",
      " qqqqqqqqq      ",
      " qddddqddqdddd  ",
      " qddddqddq   d  ",
      " qddddqqqq   d  ",
      " qddddqddqSc d  ",
      " q;;ddqddqqqqqq ",
      " q;;ddqdddddddq ",
      " q;;ddqdddddddq ",
      " qqqqqqdddddddq ",
      " qddddqdddddddq ",
      " qddddqdddddddq ",
      " qddddq;;dddddq ",
      " qddddq;;dddddq ",
      " qqqqqqqqqqqqqq ",
      "                "
    ]
  ]
}