{
  "name": "building_residential2_ground_90",
  "refpalette": "c70cities:building_residential2_ground_palette_90",
  "xsize": 16,
  "zsize": 16,
  "slices": [
    [
      "GGGGGGGGGGGGGGGG",
      "GGGGGGGGGGGGGGGG",
      "GGGGGGGGddddddGG",
      "GGGaaaaaeccccdGG",
      "GGGacccceccccdGG",
      "GGGacccceccccdGG",
      "GGGacccceccccdGG",
      "GGGacccceccccdGG",
      "GGGabbbbeccccdGG",
      "GGGabbbbeccccdGG",
      "GGGabbbbeccccdGG",
      "GGGabbbbeccccdGG",
      "GGGaaaaaeccccdGG",
      "GGGGGGGGddddddGG",
      "GGGGGGGGGGGGGGGG",
      "GGGGGGGGGGGGGGGG"
    ],
    [
      "fgggghgggghggggf",
      "g              g",
      "g iiiiiissssss g",
      "g iaaaaa  x Is g",
      "g iaq     w Fs g",
      "h iap   u wCCs h",
      "g iao   u  BBs g",
      "g iannnnn    s g",
      "g iam      AEs g",
      "g ial  r     s g",
      "h iak   t    s h",
      "g iaj   t    s g",
      "g iaaaaa     s g",
      "g iiiiiisssyDs g",
      "g              g",
      "fgggghggggf  Jff"
    ],
    [
      "fgggghgggghggggf",
      "g              g",
      "g       sPsTTs g",
      "g  aaaaa  Q  s g",
      "g  aN     w  s g",
      "h  a!  u  wCCs h",
      "g  a   u   SSs g",
      "g  annnnn    s g",
      "g  aM        s g",
      "g  a   O     P g",
      "h  aL  O     P h",
      "g  aK  O     P g",
      "g  aaaaa     s g",
      "g       sPsRUs g",
      "g              g",
      "fgggghggggf   ff"
    ],
    [
      "                ",
      "                ",
      "        sPsTTs  ",
      "   aaVVa  w  s  ",
      "   a      w  s  ",
      "   V  u   wCCs  ",
      "   V  u      s  ",
      "   annnnn    s  ",
      "   a         s  ",
      "   V         P  ",
      "   V         P  ",
      "   a         P  ",
      "   aaVVa     s  ",
      "        sPsPPs  ",
      "                ",
      "                "
    ],
    [
      "                ",
      "                ",
      "  WWWWWWsWWWWW  ",
      "  Waaaaa XXXXW  ",
      "  Wa     XXXXW  ",
      "  Wa u   XXXXW  ",
      "  Wa u   XXXXW  ",
      "  WannnnnXXXXW  ",
      "  Wa     XXXXW  ",
      "  Wa     XXXXW  ",
      "  Wa     XXXXW  ",
      "  Wa     XXXXW  ",
      "  Waaaaa XXXXW  ",
      "  WWWWWWsWWWWW  ",
      "                ",
      "                "
    ],
    [
      "                ",
      "                ",
      "  ssssssssssss  ",
      "  sccccce034ns  ",
      "  sccccce   ns  ",
      "  scu   eZ2  s  ",
      "  scu   e    s  ",
      "  sccccceY1 ns  ",
      "  sccccce   ns  ",
      "  sccccceu   s  ",
      "  sccccceu   s  ",
      "  sccccce   ns  ",
      "  sccccce   ns  ",
      "  ssssssssssss  ",
      "                ",
      "                "
    ]
  ]
}