{
  "name": "building_office4_floor3",
  "refpalette": "c70cities:building_office4_floor3_palette",
  "xsize": 16,
  "zsize": 16,
  "slices": [
    [
      "                ",
      "    abaaaaba    ",
      "  cccdeeeedccc  ",
      "  ceeeeeeeeeec  ",
      " aceeeeeeeeeeca ",
      " bdeeeeeeeeeedb ",
      " aeeeeeeeeeeeea ",
      " afeeeeeeeeeeea ",
      " afeeeeeeeeeeea ",
      " aeee!eeeeeeeea ",
      " bdeeeeeeeeeedb ",
      " aceeeeeeeeeeca ",
      "  ceeeeeeeeeec  ",
      "  cccdeeeedccc  ",
      "    abaaaaba    ",
      "                "
    ],
    [
      "                ",
      "    abaaaaba    ",
      "  gggdhihhdggg  ",
      "  g          g  ",
      " ag          ga ",
      " bd          db ",
      " a   j j j    a ",
      " af   k  k l  a ",
      " af   k  k l  a ",
      " a   m m m    a ",
      " bd          db ",
      " ag          ga ",
      "  g          g  ",
      "  gggdnnondggg  ",
      "    abaaaaba    ",
      "                "
    ],
    [
      "                ",
      "    abaaaaba    ",
      "  gggd   pdggg  ",
      "  g          g  ",
      " ag          ga ",
      " bd          db ",
      " a            a ",
      " af  qqqqqq   a ",
      " af  qqqqqq   a ",
      " a            a ",
      " bd          db ",
      " ag          ga ",
      "  g          g  ",
      "  gggd    dggg  ",
      "    abaaaaba    ",
      "                "
    ],
    [
      "                ",
      "    abaaaaba    ",
      "  gggd    dggg  ",
      "  g          g  ",
      " ag          ga ",
      " bd          db ",
      " a            a ",
      " af           a ",
      " af           a ",
      " a            a ",
      " bd          db ",
      " ag          ga ",
      "  g          g  ",
      "  gggd    dggg  ",
      "    abaaaaba    ",
      "                "
    ],
    [
      "                ",
      "    abaaaaba    ",
      "  gggd    dggg  ",
      "  g          g  ",
      " ag          ga ",
      " bd          db ",
      " a            a ",
      " af           a ",
      " af           a ",
      " a            a ",
      " bd          db ",
      " ag          ga ",
      "  g          g  ",
      "  gggd    dggg  ",
      "    abaaaaba    ",
      "                "
    ],
    [
      "                ",
      "    abaaaaba    ",
      "  gggdrrrrdggg  ",
      "  grrrrrrrrrrg  ",
      " agrrrrrrrrrrga ",
      " bdrrrrrrrrrrdb ",
      " arrrrrrrrrrrra ",
      " afrrrrrrrrrrra ",
      " afrrrrrrrrrrra ",
      " arrrrrrrrrrrra ",
      " bdrrrrrrrrrrdb ",
      " agrrrrrrrrrrga ",
      "  grrrrrrrrrrg  ",
      "  gggdrrrrdggg  ",
      "    abaaaaba    ",
      "                "
    ]
  ]
}