{
  "name": "building_residential1_ground_270",
  "refpalette": "c70cities:building_residential1_ground_palette_270",
  "xsize": 16,
  "zsize": 16,
  "slices": [
    [
      "GGGGGGGGGGGGGGGG",
      "GGGGGGGGGGGGGGGG",
      "GGGGGGGaaaaaaaGG",
      "GGGcccccbbbbbaGG",
      "GGGcddddbbbbbaGG",
      "GGGcddddbbbbbaGG",
      "GGGcddddbbbbbaGG",
      "GGGcddddbbbbbaGG",
      "GGGcddddbbbbbaGG",
      "GGGcddddbbbbbaGG",
      "GGGceeeebbbbbaGG",
      "GGGceeeebbbbbaGG",
      "GGGcccccbbbbbaGG",
      "GGGGGGGaaaaaaaGG",
      "GGGGGGGGGGGGGGGG",
      "GGGGGGGGGGGGGGGG"
    ],
    [
      "fgggghggggf  fgf",
      "g              g",
      "g yyyyyijjimki g",
      "g yccccctrn  i g",
      "g ycF Aw  n  j g",
      "h ycI Aw  n  j h",
      "g ycJ B      j g",
      "g ycK    so li g",
      "g ycI   usp li g",
      "g yc!    s   j g",
      "h ycEECx s   j h",
      "g ycL Dx s   j g",
      "g yccccc  q  i g",
      "g yyyyyijjijji g",
      "g              g",
      "fgggghggggfggggf"
    ],
    [
      "fgggghggggf  fgf",
      "g              g",
      "g      ijjiOMi g",
      "g  ccTcc  n  i g",
      "g  cV  Q  n  j g",
      "h  c      n  j h",
      "g  T  R      j g",
      "g  TW    s  Ni g",
      "g  T     s  Ni g",
      "g  T    us   j g",
      "h  cEESx s   j h",
      "g  c   x s   j g",
      "g  ccUcc  P  i g",
      "g      ijjijji g",
      "g              g",
      "fgggghggggfggggf"
    ],
    [
      "                ",
      "                ",
      "  1    iYYiYYi  ",
      "  1ccTcc  n  i  ",
      "  1c      n  X  ",
      "  1c      n  X  ",
      "  1c         X  ",
      "  1c     s   i  ",
      "  1c     s   i  ",
      "  1c     s   X  ",
      "  1cEEExus   X  ",
      "  1c   x s   X  ",
      "  1ccUcc     i  ",
      "  1    iZZiZZi  ",
      "                ",
      "          0     "
    ],
    [
      "                ",
      "                ",
      "  541  iiiiiii  ",
      "  54cccc bbbbi  ",
      "  541    bbbbi  ",
      "  541    bbbbi  ",
      "  541    bbbbi  ",
      "  541    bbbbi  ",
      "  541    bbbbi  ",
      "  541    bbbbi  ",
      "  54222x bbbbi  ",
      "  54333xubbbbi  ",
      "  54ccccbbbbbi  ",
      "  541  iiiiiii  ",
      "                ",
      "                "
    ],
    [
      "                ",
      "              6 ",
      "    541ijjjjji6 ",
      "    54cc+ YY7i6 ",
      "    541 +8$$8i6 ",
      "    541 +8%%8i6 ",
      "    541 +8888i6 ",
      "    541 +    i6 ",
      "    541 + (^9i6 ",
      "    541 + )&@i6 ",
      "    54Ex+  * i6 ",
      "    54-x+    i6 ",
      "    54cc    #i6 ",
      "    541ijjjjji6 ",
      "              6 ",
      "                "
    ]
  ]
}