{
  "name": "building_residential1_floor1",
  "refpalette": "c70cities:building_residential1_floor1_palette",
  "xsize": 16,
  "zsize": 16,
  "slices": [
    [
      "                ",
      " aaaaaaaaaaaaaa ",
      " bbbbbbbbbbbbbb ",
      " cdeeeeeeeeeedc ",
      "  fg         f  ",
      "  fh         f  ",
      "  f          f  ",
      "  f          f  ",
      "  ddiiiiiiiidd  ",
      "  jjjjjjjjjjjj  ",
      "                ",
      "                ",
      "                ",
      "                ",
      "                ",
      "                "
    ],
    [
      "                ",
      "                ",
      "                ",
      " aaaaaaaaaaaaaa ",
      " bbbbbbbbbbbbbb ",
      " cdeeeeeeeeeedc ",
      "  f          f  ",
      "  f          f  ",
      "  ddkkkkkkkkdd  ",
      "                ",
      "                ",
      "                ",
      "                ",
      "                ",
      "                ",
      "                "
    ],
    [
      "                ",
      "                ",
      "                ",
      "                ",
      "                ",
      " aaaaaaaaaaaaaa ",
      " bbbbbbbbbbbbbb ",
      " cdeeeeeeeeeedc ",
      "  dddddddddddd  ",
      "                ",
      "                ",
      "                ",
      "                ",
      "                ",
      "                ",
      "                "
    ],
    [
      "                ",
      "                ",
      "                ",
      "                ",
      "                ",
      "                ",
      "                ",
      " aaaaaaaaaaaaaa ",
      " bbbbbbbbbbbbbb ",
      " cccccccccccccc ",
      "                ",
      "                ",
      "                ",
      "                ",
      "                ",
      "                "
    ],
    [
      "                ",
      "                ",
      "                ",
      "                ",
      "                ",
      "                ",
      "                ",
      "                ",
      "                ",
      " aaaaaaaaaaaaaa ",
      "                ",
      "                ",
      "                ",
      "                ",
      "                ",
      "                "
    ],
    [
      "                ",
      "                ",
      "                ",
      "                ",
      "                ",
      "                ",
      "                ",
      "                ",
      "                ",
      "        ~       ",
      "                ",
      "                ",
      "                ",
      "                ",
      "                ",
      "                "
    ]
  ]
}