{
  "name": "building_office4_floor1_180",
  "refpalette": "c70cities:building_office4_floor1_palette_180",
  "xsize": 16,
  "zsize": 16,
  "slices": [
    [
      "                ",
      "    abaaaaba    ",
      "  cccdeeeedccc  ",
      "  ceeeeeeeeeec  ",
      " aceeeeeeeeeeca ",
      " bdeeeeeeeeeedb ",
      " aeeeee!eeeeeea ",
      " aeeeeeeeeeeefa ",
      " aeeeeeeeeeeefa ",
      " aeeeeeeeeeeeea ",
      " bdeeeeeeeeeedb ",
      " aceeeeeeeeeeca ",
      "  ceeeeeeeeeec  ",
      "  cccdeeeedccc  ",
      "    abaaaaba    ",
      "                "
    ],
    [
      "                ",
      "    abaaaaba    ",
      "  gggdwwwwdggg  ",
      "  g   u  u   g  ",
      " ag          ga ",
      " bd          db ",
      " aon  t sr    a ",
      " ao   q  p   fa ",
      " ao   q  p   fa ",
      " aon  ml k    a ",
      " bd          db ",
      " ag          ga ",
      "  g   j  j   g  ",
      "  gggdhhihdggg  ",
      "    abaaaaba    ",
      "                "
    ],
    [
      "                ",
      "    abaaaaba    ",
      "  gggd x  dggg  ",
      "  g          g  ",
      " ag          ga ",
      " bd          db ",
      " a            a ",
      " a           fa ",
      " a           fa ",
      " a            a ",
      " bd          db ",
      " ag          ga ",
      "  g          g  ",
      "  gggd    dggg  ",
      "    abaaaaba    ",
      "                "
    ],
    [
      "                ",
      "    abaaaaba    ",
      "  gggd    dggg  ",
      "  g          g  ",
      " ag          ga ",
      " bd          db ",
      " a            a ",
      " a           fa ",
      " a           fa ",
      " a            a ",
      " bd          db ",
      " ag          ga ",
      "  g          g  ",
      "  gggd    dggg  ",
      "    abaaaaba    ",
      "                "
    ],
    [
      "                ",
      "    abaaaaba    ",
      "  gggd    dggg  ",
      "  g          g  ",
      " ag          ga ",
      " bd          db ",
      " a            a ",
      " a           fa ",
      " a           fa ",
      " a            a ",
      " bd          db ",
      " ag          ga ",
      "  g          g  ",
      "  gggd    dggg  ",
      "    abaaaaba    ",
      "                "
    ],
    [
      "                ",
      "    abaaaaba    ",
      "  gggdyyyydggg  ",
      "  gyyyyyyyyyyg  ",
      " agyyyyyyyyyyga ",
      " bdyyyyyyyyyydb ",
      " ayyyyyyyyyyyya ",
      " ayyyyyyyyyyyfa ",
      " ayyyyyyyyyyyfa ",
      " ayyyyyyyyyyyya ",
      " bdyyyyyyyyyydb ",
      " agyyyyyyyyyyga ",
      "  gyyyyyyyyyyg  ",
      "  gggdyyyydggg  ",
      "    abaaaaba    ",
      "                "
    ]
  ]
}