{
  "name": "building_residential4_ground_270",
  "refpalette": "c70cities:building_residential4_ground_palette_270",
  "xsize": 16,
  "zsize": 16,
  "slices": [
    [
      "GGGGGGGGGGGGGGGG",
      "GGGGGGGGGGGGGGGG",
      "GGaaaaaaaaaaaaGG",
      "GGabbbbbbbbbbaGG",
      "GGabbbbbbbbbbaGG",
      "GGabbbbbbbbbbaGG",
      "GGabbbbbbbbbbaGG",
      "GGabbbbbbbbbbaGG",
      "GGabbbbbbbbbbaGG",
      "GGaccccccccccaGG",
      "GGaccccccccccaGG",
      "GGaccccccccccaGG",
      "GGaddddddddddaGG",
      "GGaGGGGGGGGGGaGG",
      "GGGGGGGGGGGGGGGG",
      "GGGGGGGGGGGGGGGG"
    ],
    [
      "efffffe  efffffe",
      "f              f",
      "f hjjjhAxhjjjh f",
      "f hJE     rp h f",
      "f M          i f",
      "g M       qq i g",
      "f hK    uukkkh f",
      "f M          i f",
      "f M        lli f",
      "f hLFD    smmh f",
      "g M  D       i g",
      "f M IDCBywtnni f",
      "f hddddddddddh f",
      "f hooooooooooh f",
      "f              f",
      "effffgffffgffffe"
    ],
    [
      "efffffe  efffffe",
      "f              f",
      "f hNNNhUShNNNh f",
      "f h          h f",
      "f NY         N f",
      "g NK      PP N g",
      "f h     uuOOOh f",
      "f N          N f",
      "f N          N f",
      "f hLWD     Q h f",
      "g Z  D       N g",
      "f Z XDV   R  N f",
      "f hddddTTddddh f",
      "f h          h f",
      "f              f",
      "effffgffffgffffe"
    ],
    [
      "                ",
      "                ",
      "  hNNNhNNhNNNh  ",
      "  h          h  ",
      "  h 1        h  ",
      "  h          h  ",
      "  h     uuOOOh  ",
      "  h          h  ",
      "  h          h  ",
      "  hLLD       h  ",
      "  h  D       h  ",
      "  h  D       h  ",
      "  hddddTTddddh  ",
      "  h0000000000h  ",
      "                ",
      "                "
    ],
    [
      "                ",
      " 4i          M2 ",
      " 4hhhhhhhhhhhh2 ",
      " 4hbbbbbbbbbbh2 ",
      " 4h  1bbbbbbbh2 ",
      " 4h   bbbbbbbh2 ",
      " 4h   bbbbbbbh2 ",
      " 4hbbbbbbbbbbh2 ",
      " 4hbbbbbbbbbbh2 ",
      " 4hbbbbbbbbbbh2 ",
      " 4hbbbbbbbbbbh2 ",
      " 4hbbbbbbbbbbh2 ",
      " 4hddddddddddh2 ",
      " 4h3333  3333h2 ",
      " 4i          M2 ",
      "                "
    ],
    [
      "                ",
      "  4i        M2  ",
      "  43333&@33332  ",
      "  4dddddddddd2  ",
      "  4     #553h2  ",
      "  4   ( 7663h2  ",
      "  4---( 7773h2  ",
      "  4   )    3h2  ",
      "  4!  + $  3h2  ",
      "  4{  + 8883h2  ",
      "  4{  + 8883h2  ",
      "  4 ][+ %9 3h2  ",
      "  4dddddddddd2  ",
      "  43333*^33332  ",
      "  4i        M2  ",
      "                "
    ]
  ]
}