{
  "name": "building_residential2_ground_180",
  "refpalette": "c70cities:building_residential2_ground_palette_180",
  "xsize": 16,
  "zsize": 16,
  "slices": [
    [
      "GGGGGGGGGGGGGGGG",
      "GGGGGGGGGGGGGGGG",
      "GGddddddddddddGG",
      "GGdccccccccccdGG",
      "GGdccccccccccdGG",
      "GGdccccccccccdGG",
      "GGdccccccccccdGG",
      "GGdeeeeeeeeeedGG",
      "GGGaccccbbbbaGGG",
      "GGGaccccbbbbaGGG",
      "GGGaccccbbbbaGGG",
      "GGGaccccbbbbaGGG",
      "GGGaaaaaaaaaaGGG",
      "GGGGGGGGGGGGGGGG",
      "GGGGGGGGGGGGGGGG",
      "GGGGGGGGGGGGGGGG"
    ],
    [
      "fgggghgggghggggf",
      "g              g",
      "g ssssssssssss f",
      "g sIFCB E    D  ",
      "g s  CB A    y  ",
      "h sxww       s f",
      "g s          s g",
      "g s  uun  tt s g",
      "g ia   n r  ai g",
      "g ia   n    ai g",
      "h ia   n    ai h",
      "g iaqponmlkjai g",
      "g iaaaaaaaaaai g",
      "g iiiiiiiiiiii g",
      "g              g",
      "fgggghgggghggggf"
    ],
    [
      "fgggghgggghggggf",
      "g              g",
      "g sssssssOOOss f",
      "g S  CR      T  ",
      "g S  CR      Q  ",
      "h sPww       s f",
      "g O          O g",
      "g s    n     s g",
      "g  a uun NNNa  g",
      "g  a   n    a  g",
      "h  a   n    a  h",
      "g  aM! nL KJa  g",
      "g  aaaaaaaaaa  g",
      "g              g",
      "g              g",
      "fgggghgggghggggf"
    ],
    [
      "                ",
      "                ",
      "  sssssssOOOss  ",
      "  S  C       O  ",
      "  S  C       O  ",
      "  swww       s  ",
      "  O          O  ",
      "  s    n     s  ",
      "   a   n    a   ",
      "   U uun    U   ",
      "   U   n    U   ",
      "   a   n    a   ",
      "   aaUUaaUUaa   ",
      "                ",
      "                ",
      "                "
    ],
    [
      "                ",
      "                ",
      "  VVVVVVVVVVVV  ",
      "  VWWWWWWWWWWV  ",
      "  VWWWWWWWWWWV  ",
      "  VWWWWWWWWWWV  ",
      "  VWWWWWWWWWWV  ",
      "  s    n     s  ",
      "  Va   n    aV  ",
      "  Va   n    aV  ",
      "  Va uun    aV  ",
      "  Va   n    aV  ",
      "  VaaaaaaaaaaV  ",
      "  VVVVVVVVVVVV  ",
      "                ",
      "                "
    ],
    [
      "                ",
      "                ",
      "  ssssssssssss  ",
      "  snn  nn  nns  ",
      "  s3         s  ",
      "  s2 1 0     s  ",
      "  sZ Y X uu  s  ",
      "  seeeeeeeeees  ",
      "  scc  ccccccs  ",
      "  scc  ccccccs  ",
      "  scc  ccccccs  ",
      "  sccuuccccccs  ",
      "  sccccccccccs  ",
      "  ssssssssssss  ",
      "                ",
      "                "
    ]
  ]
}