{
  "name": "building_office1_base1",
  "refpalette": "c70cities:building_office1_base1_palette",
  "xsize": 16,
  "zsize": 16,
  "slices": [
    [
      "vvvvvvvvvvvvvvvv",
      "vaaaaaaaaaaaaaav",
      "va!aaaaaaaaaa!av",
      "vaaaaaaaaaaaaaav",
      "vaaaaaaaaaaaaaav",
      "vaaaaaaaaaaaaaav",
      "vaaaaaaaaaaaaaav",
      "vaaaaaaaaaaaaaav",
      "vaaaaaaaaaaaaaav",
      "vaaaaaaaaaaaaaav",
      "vaaaaaaaaaaaaaav",
      "vaaaaaaaaaaaaaav",
      "vabaaaaaaaaaaaav",
      "vabaaaaaaaaaaaav",
      "vaaaaaaaaaaaaaav",
      "vvvvvvvvvvvvvvvv"
    ],
    [
      "vvvvvvvvvvvvvvvv",
      "vccccccccccccccv",
      "vcd   d  d   dcv",
      "vcde  df d gedcv",
      "vcd h d ei  jdcv",
      "vckg  d  d   dcv",
      "vcd  e     f icv",
      "vcd          lcv",
      "vcde  d  d   dcv",
      "vck h k  k  jdcv",
      "vcdg  de df  dcv",
      "vcm          mcv",
      "vcb          ncv",
      "vcb          ncv",
      "vccccccccccccccv",
      "vvvvvvvvvvvvvvvv"
    ],
    [
      "vvvvvvvvvvvvvvvv",
      "vccccccccccccccv",
      "vcd   d  d   dcv",
      "vco   d  o   lcv",
      "vcd   o  d   lcv",
      "vcd   d  d   dcv",
      "vco          dcv",
      "vco          dcv",
      "vcd   d  d   dcv",
      "vcd   d  d   lcv",
      "vco   d  d   dcv",
      "vcm          mcv",
      "vcb           cv",
      "vcb           cv",
      "vccccccccccccccv",
      "vvvvvvvvvvvvvvvv"
    ],
    [
      "vvvvvvvvvvvvvvvv",
      "vccccccccccccccv",
      "vc            cv",
      "vcp          qcv",
      "vcr          scv",
      "vcr          scv",
      "vcr          scv",
      "vcr          scv",
      "vcr          scv",
      "vct          ucv",
      "vc            cv",
      "vcm          mcv",
      "vcb           cv",
      "vcb           cv",
      "vccccccccccccccv",
      "vvvvvvvvvvvvvvvv"
    ],
    [
      "vvvvvvvvvvvvvvvv",
      "vccccccccccccccv",
      "vc            cv",
      "vc            cv",
      "vc            cv",
      "vc            cv",
      "vc            cv",
      "vc            cv",
      "vc            cv",
      "vc            cv",
      "vc            cv",
      "vcm          mcv",
      "vcb           cv",
      "vcb           cv",
      "vccccccccccccccv",
      "vvvvvvvvvvvvvvvv"
    ],
    [
      "vvvvvvvvvvvvvvvv",
      "vccccccccccccccv",
      "vcwwwwwwwwwwwwcv",
      "vcwwwwwwwwwwwwcv",
      "vcwwwwwwwwwwwwcv",
      "vcwwwwwwwwwwwwcv",
      "vcwwwwwwwwwwwwcv",
      "vcwwwwwwwwwwwwcv",
      "vcwwwwwwwwwwwwcv",
      "vcwwwwwwwwwwwwcv",
      "vcwwwwwwwwwwwwcv",
      "vcmwwwwwwwwwwmcv",
      "vcbwwwwwwwwwwwcv",
      "vcbwwwwwwwwwwwcv",
      "vccccccccccccccv",
      "vvvvvvvvvvvvvvvv"
    ]
  ]
}