{
  "name": "building_apartment1_top_180",
  "refpalette": "c70cities:building_apartment1_top_palette_180",
  "xsize": 16,
  "zsize": 16,
  "slices": [
    [
      "                ",
      "      aaaaaaaaa ",
      "  hgfbbbbbbbbba ",
      "  e   cccccccba ",
      "  e   cccccccba ",
      "  b  dcccccccba ",
      " abccccccccccba ",
      " abccccccccccba ",
      " abccccccccccba ",
      " abccccccccccba ",
      " abccccccccccba ",
      " abccccccccccba ",
      " abccccccccccba ",
      " abbbbbbbbbbbba ",
      " aaaaaaaaaaaaaa ",
      "                "
    ],
    [
      "                ",
      "                ",
      "  bbiibwllbbbb  ",
      "  b   qn  on b  ",
      "  b   qt  uoob  ",
      "  b   qtn on s  ",
      "  bqqrqn  o  l  ",
      "  p       o  l  ",
      "  i      no! m  ",
      "  i      oooob  ",
      "  b      o  nb  ",
      "  b      o   i  ",
      "  l     no  ni  ",
      "  mjiiblkbbjii  ",
      "                ",
      "                "
    ],
    [
      "                ",
      "                ",
      "  bbbbbbbbjiib  ",
      "  b   q      l  ",
      "  i   qy     l  ",
      "  g   qy     b  ",
      "  bqqxq      b  ",
      "  b          b  ",
      "  b          b  ",
      "  b          b  ",
      "  b          b  ",
      "  b          b  ",
      "  b          b  ",
      "  bbbbbbbiiibb  ",
      "                ",
      "                "
    ],
    [
      "                ",
      "                ",
      "  bbbbbllbbbbb  ",
      "  bAAAA      b  ",
      "  bAAAAn     b  ",
      "  bAAAA      b  ",
      "  bAAAA      b  ",
      "  b          b  ",
      "  b          l  ",
      "  s          l  ",
      "  l          l  ",
      "  l          b  ",
      "  l          b  ",
      "  bbbllkbbbbbb  ",
      "                ",
      "                "
    ],
    [
      "                ",
      "                ",
      "                ",
      "                ",
      "                ",
      "                ",
      "                ",
      "                ",
      "                ",
      "                ",
      "                ",
      "                ",
      "                ",
      "                ",
      "                ",
      "                "
    ],
    [
      "                ",
      "                ",
      "                ",
      "                ",
      "                ",
      "                ",
      "                ",
      "                ",
      "                ",
      "                ",
      "                ",
      "                ",
      "                ",
      "                ",
      "                ",
      "                "
    ]
  ]
}