{
  "name": "building_factory1_ground",
  "refpalette": "c70cities:building_factory1_ground_palette",
  "xsize": 16,
  "zsize": 16,
  "slices": [
    [
      "aazzzzzzzzzzzzzz",
      "aaazzzzzzzzzzzzz",
      "aazbbbbbbbbbbbzz",
      "aaabbbbbbbbbbbzz",
      "zaabbbbbbbbbbbzz",
      "aaabbbbbbbbbbbzz",
      "aaabbbbbbbbbbbzz",
      "azabbbbbbbbbbbzz",
      "aaabbbbbbbbcbbzz",
      "aaabbbbbbbbbbbzz",
      "zaabbbbbbbbcbbzz",
      "zaabbbbbbbbbbbzz",
      "aaabbbbbbbbbbbzz",
      "aazbbbbbbbbbbbzz",
      "aazzzzzzzzzzzzzz",
      "aaazzzzzzzzzzzzz"
    ],
    [
      "    d  e f d d d",
      "      d     g d ",
      "   hhhhhhhhhhh  ",
      "   hijj!iklmih d",
      "     nnn k   h  ",
      "         opooh  ",
      "           q hd ",
      "          rs h  ",
      "     t   ruwxh  ",
      "     y   Auwxh  ",
      "      B A uCxh d",
      "    xxxxxDEFxhd ",
      "   hiIJKiLMMih  ",
      "   hhhhhhhhhhhd ",
      "   dd ddd dN    ",
      "    Odd dNdd  e "
    ],
    [
      "                ",
      "            g   ",
      "   hhhhhhhhhhh  ",
      "   hinn ik Pih  ",
      "   Q     k   h  ",
      "   Q     oRooh  ",
      "   Q       S h  ",
      "   Q       T h  ",
      "   Q        xh  ",
      "   Q        xh  ",
      "   Q        xh  ",
      "   Q    SU Vxh  ",
      "   hi W i MMih  ",
      "   hhhhhhhhhhh  ",
      "                ",
      "                "
    ],
    [
      "                ",
      "            X   ",
      "   hhhhhhhhhhh  ",
      "   hi   ik  ih  ",
      "   Q   Y k   h  ",
      "   Q     ooooh  ",
      "   Q         h  ",
      "   Q         h  ",
      "   Q       Zxh  ",
      "   Q       Zxh  ",
      "   Q        xh  ",
      "   Q      0  h  ",
      "   hi123i MMih  ",
      "   hhhhhhhhhhh  ",
      "                ",
      "                "
    ],
    [
      "                ",
      "                ",
      "   hh456h456hh  ",
      "   hi777i777ih  ",
      "  8h9@##$k   h  ",
      "  8h9   %ooooh  ",
      "  8h9        h  ",
      "  8h9        h  ",
      "  8h  ^      h  ",
      "  8h         h  ",
      "  8h         h  ",
      "  8h         h  ",
      "   hi777i777ih  ",
      "   hh456h456hh  ",
      "                ",
      "                "
    ],
    [
      "                ",
      "                ",
      "   &&&&&&&&&&&  ",
      "   h*********h  ",
      "   h(   (   (h  ",
      "   h777777777h  ",
      "   h         h  ",
      "   h         h  ",
      "   h  )   )  h  ",
      "   h         h  ",
      "   h777777777h  ",
      "   h+   +   +h  ",
      "   h*********h  ",
      "   &&&&&&&&&&&  ",
      "                ",
      "                "
    ]
  ]
}