{
  "name": "building_hotel3_top_270",
  "refpalette": "c70cities:building_hotel3_top_palette_270",
  "xsize": 16,
  "zsize": 16,
  "slices": [
    [
      "                ",
      "  a a a a a a   ",
      "  bbbbbbbbbbbba ",
      " abccccccccccb  ",
      "  bceeeeeeeecba ",
      " abceffffffecb  ",
      "  bceffffffecba ",
      " abceffffffedb  ",
      "  bceffffffedba ",
      " abceffffffecb  ",
      "  bceffffffecba ",
      " abceeeeeeeecb  ",
      "  bccccccccccba ",
      " abbbbbbbbbbbb  ",
      "   a a a a a a  ",
      "                "
    ],
    [
      "                ",
      "      a a a a   ",
      "     bbbbbbbbba ",
      "             b  ",
      "    jeeeeeee ba ",
      "    i!hgggge b  ",
      "    i hgggge ba ",
      "    i hgggge b  ",
      "    i hhhhhe ba ",
      "    i        b  ",
      "    i        ba ",
      "    jiiiiiee b  ",
      "             ba ",
      "     bbbbbbbbb  ",
      "     a a a a a  ",
      "                "
    ],
    [
      "                ",
      "        a a a   ",
      "        bbbbbba ",
      "             b  ",
      "    jekkkkee ba ",
      "           e b  ",
      "           e ba ",
      "           e b  ",
      "           e ba ",
      "             b  ",
      "             ba ",
      "    j     ee b  ",
      "             ba ",
      "        bbbbbb  ",
      "         a a a  ",
      "                "
    ],
    [
      "                ",
      "            a   ",
      "           bbba ",
      "             b  ",
      "    jeeeeeee ba ",
      "           e b  ",
      "           e ba ",
      "           e b  ",
      "           e ba ",
      "             b  ",
      "             ba ",
      "    j     ee b  ",
      "             ba ",
      "           bbb  ",
      "           a a  ",
      "                "
    ],
    [
      "                ",
      "                ",
      "                ",
      "                ",
      "    jeeeeeee    ",
      "           e    ",
      "           e    ",
      "           e    ",
      "           e    ",
      "           l    ",
      "           l    ",
      "    j     ee    ",
      "                ",
      "                ",
      "                ",
      "                "
    ],
    [
      "                ",
      "                ",
      "                ",
      "                ",
      "    hhhhhhhh    ",
      "    hccccchh    ",
      "    hccccchh    ",
      "    hccccchh    ",
      "    hccccchh    ",
      "    hccccchh    ",
      "    hccccchh    ",
      "    hhhhhhhh    ",
      "                ",
      "                ",
      "                ",
      "                "
    ]
  ]
}