{
  "name": "building_carfactory1_floor1_90",
  "refpalette": "c70cities:building_carfactory1_floor1_palette_90",
  "xsize": 16,
  "zsize": 16,
  "slices": [
    [
      "                ",
      "   aeeeeeeeeeea ",
      "   bddddddddddk ",
      "   bd g    g dk ",
      "   bdfg    g dk ",
      "   bd h    h dk ",
      "   bd h    j dk ",
      "   bd g    g dk ",
      "   bd g    g dk ",
      "   bd i    h dk ",
      "   bd h    h dk ",
      "   bd g    g dl ",
      "   bdfg    gfdl ",
      "   bddddddddddk ",
      "   acccccccccca ",
      "                "
    ],
    [
      "                ",
      "  mmnn        a ",
      "  mmoooooooooo  ",
      "  mmpqqq    fo  ",
      "  mmpqqq   ! o  ",
      "  mmprs    t o  ",
      "  mmprs    t o  ",
      "  mmpqqq     o  ",
      "  mmpqqq     o  ",
      "  mmprs    t o  ",
      "  mmprs    t o  ",
      "  mmpqqq     ol ",
      "  mmpqqq ff  ol ",
      "  mmoooooooooo  ",
      "  mmnn        a ",
      "                "
    ],
    [
      "                ",
      "      mmnn    a ",
      "      mmoooooo  ",
      "        qqq fo  ",
      "        qqq  o  ",
      "      uurr t o  ",
      "      uurr t o  ",
      "        qqq fo  ",
      "        qqq fo  ",
      "      uurr t o  ",
      "      uurr t o  ",
      "        qqq  ol ",
      "        qqq  ol ",
      "      mmoooooo  ",
      "      mmnn    a ",
      "                "
    ],
    [
      "                ",
      "          mmnna ",
      "          mmook ",
      "           urpk ",
      "           urpk ",
      "          uurpk ",
      "          uurpk ",
      "         ~ urpk ",
      "           urpk ",
      "          uurpk ",
      "          uurpk ",
      "           urpl ",
      "           urpl ",
      "          mmook ",
      "          mmnna ",
      "                "
    ],
    [
      "                ",
      "              mm",
      "              mm",
      "              mm",
      "              mm",
      "              mm",
      "              mm",
      "         ~    mm",
      "              mm",
      "              mm",
      "              mm",
      "            lllm",
      "            lllm",
      "              mm",
      "              mm",
      "                "
    ],
    [
      "                ",
      "                ",
      "                ",
      "                ",
      "                ",
      "                ",
      "                ",
      "         ~      ",
      "                ",
      "                ",
      "                ",
      "             xy ",
      "             wl ",
      "                ",
      "                ",
      "                "
    ]
  ]
}