{
  "name": "building_hotel3_base1",
  "refpalette": "c70cities:building_hotel3_base1_palette",
  "xsize": 16,
  "zsize": 16,
  "slices": [
    [
      "vvvvvvvvvvvvvvvv",
      "vaaaaaaaaaaaaaav",
      "vabbbbbbbbbbbbav",
      "vabbbbbbbbbbbbav",
      "vabbbbbccbbcbbav",
      "vabbbbbddbbbbbav",
      "vabbbbbbbbbbbbav",
      "vabbbbbbbbbbbbav",
      "vabbbbbbbbbbbbav",
      "vabbbbbbbbbbbbav",
      "vabbbbbbbbbbbbav",
      "vabbcbbbbbbcbbav",
      "vabbbbbbbbbbbbav",
      "vabbbbbbbbbbbbav",
      "vaaaaaaaaaaaaaav",
      "vvvvvvvvvvvvvvvv"
    ],
    [
      "vvvvvvvvvvvvvvvv",
      "vaaaaaaaaaaaaaav",
      "vaeffghij     av",
      "va    kij lmn av",
      "va    icc ocj av",
      "va   i dd pqr av",
      "va            av",
      "vaiii     mmmmav",
      "va       sssssav",
      "va            av",
      "vatuw tuuw tuwav",
      "va  c      c  av",
      "va            av",
      "vatuw!tuuw!tuwav",
      "vaaaaaaaaaaaaaav",
      "vvvvvvvvvvvvvvvv"
    ],
    [
      "vvvvvvvvvvvvvvvv",
      "vaaaaaaaaaaaaaav",
      "vaxyAB i      av",
      "va     i      av",
      "va    icc  c  av",
      "va   i dd     av",
      "va            av",
      "va            av",
      "va       sssssav",
      "va            av",
      "va C   CC   C av",
      "va  c      c  av",
      "va            av",
      "va C   CC   C av",
      "vaaaaaaaaaaaaaav",
      "vvvvvvvvvvvvvvvv"
    ],
    [
      "vvvvvvvvvvvvvvvv",
      "vaaaaaaaaaaaaaav",
      "va    Di      av",
      "va     i      av",
      "va    icc  c  av",
      "va   i dd     av",
      "va            av",
      "va            av",
      "va       sssssav",
      "va            av",
      "va            av",
      "va  c      c  av",
      "va            av",
      "va            av",
      "vaaaaaaaaaaaaaav",
      "vvvvvvvvvvvvvvvv"
    ],
    [
      "vvvvvvvvvvvvvvvv",
      "vaaaaaaaaaaaaaav",
      "va    Ei      av",
      "va     i      av",
      "va    icc  c  av",
      "va   i dd     av",
      "va            av",
      "va            av",
      "va       sssssav",
      "va            av",
      "va            av",
      "va  c      c  av",
      "va            av",
      "va            av",
      "vaaaaaaaaaaaaaav",
      "vvvvvvvvvvvvvvvv"
    ],
    [
      "vvvvvvvvvvvvvvvv",
      "vaaaaaaaaaaaaaav",
      "vaFFFFFFFFFFFFav",
      "vaFFFFFFFFFFFFav",
      "vaFFcFFccFFcFFav",
      "vaFFFFFddFFFFFav",
      "vaFFFFFFFFFFFFav",
      "vaFFFFFFFFFFFFav",
      "vaFFFFFFFFFFFFav",
      "vaFFFFFFFFFFFFav",
      "vaFFFFFFFFFFFFav",
      "vaFFcFFFFFFcFFav",
      "vaFFFFFFFFFFFFav",
      "vaFFFFFFFFFFFFav",
      "vaaaaaaaaaaaaaav",
      "vvvvvvvvvvvvvvvv"
    ]
  ]
}