{
  "name": "building_carservice1_top_90",
  "refpalette": "c70cities:building_carservice1_top_palette_90",
  "xsize": 16,
  "zsize": 16,
  "slices": [
    [
      "                ",
      "      eeeeee    ",
      " a    acffcdd   ",
      "      dcfffcdd  ",
      "      dcffffcde ",
      "      dcfffffge ",
      " a    acffffffa ",
      "      dcffffffe ",
      "      dcffffffe ",
      "      dcffffffe ",
      " a    acffffffa ",
      "    bbccffffffe ",
      "  bbbbccffffffe ",
      "  bbbbccffffffe ",
      " a    aeeeeeeea ",
      "                "
    ],
    [
      "                ",
      "      eeeeee    ",
      " a    an   oo   ",
      "      emq   oo  ",
      "      e!pp   oe ",
      "      em      e ",
      " ahhhial      a ",
      " h    ek  wsw e ",
      " h    ek rtstye ",
      " h    ek  usu e ",
      " a    a   uxu a ",
      " h    j  rtutye ",
      " h    j   sss e ",
      " h    j   sss e ",
      " ahhhiaeoooooea ",
      "                "
    ],
    [
      "                ",
      "      eoooee    ",
      " a    a    oo   ",
      "      em    oo  ",
      "      em     oe ",
      "      em      e ",
      " a    al      a ",
      "      eA      e ",
      "      e       e ",
      "      e    B  e ",
      " a    a    C  a ",
      "      j    B  e ",
      "      j    u  e ",
      "      j   BsB e ",
      " a    aeoooooea ",
      "                "
    ],
    [
      "                ",
      "      eeeeee    ",
      " aDDDDa    oo   ",
      "      eE    oo  ",
      "      eE     oe ",
      "      eE      e ",
      " aDDDDaDDDDDDDa ",
      "      e       e ",
      "      e       e ",
      "      e       e ",
      " aDDDDaDDDDDDDa ",
      "      j       e ",
      "      j       e ",
      "      j       e ",
      " aDDDDaaaaaaaaa ",
      "                "
    ],
    [
      "                ",
      "      eeeeee    ",
      "      eFFFFFF   ",
      "      eFFFFFFF  ",
      "      eFFFFFFFe ",
      "      eFFFFFFFe ",
      "      eFFFFFFFe ",
      "      eFFFFFFFe ",
      "      eFFFFFFFe ",
      "      eFFFFFFFe ",
      "      eFFFFFFFe ",
      "      eFFFFFFFe ",
      "      eFFFFFFFe ",
      "      eFFFFFFFe ",
      "      eeeeeeeee ",
      "                "
    ],
    [
      "                ",
      "      eeeeee    ",
      "      e         ",
      "      e         ",
      "      e       e ",
      "      e       e ",
      "      e       e ",
      "      e       e ",
      "      e       e ",
      "      e       e ",
      "      e       e ",
      "      e       e ",
      "      e       e ",
      "      e       e ",
      "      eeeeeeeee ",
      "                "
    ]
  ]
}