{
  "name": "building_hotel3_base1_270",
  "refpalette": "c70cities:building_hotel3_base1_palette_270",
  "xsize": 16,
  "zsize": 16,
  "slices": [
    [
      "vvvvvvvvvvvvvvvv",
      "vaaaaaaaaaaaaaav",
      "vabbbbbbbbbbbbav",
      "vabbbbbbbbbbbbav",
      "vabbcbbbbbbbbbav",
      "vabbbbbbbbbbbbav",
      "vabbbbbbbbbbbbav",
      "vabbbbbbbbdcbbav",
      "vabbbbbbbbdcbbav",
      "vabbbbbbbbbbbbav",
      "vabbbbbbbbbbbbav",
      "vabbcbbbbbbcbbav",
      "vabbbbbbbbbbbbav",
      "vabbbbbbbbbbbbav",
      "vaaaaaaaaaaaaaav",
      "vvvvvvvvvvvvvvvv"
    ],
    [
      "vvvvvvvvvvvvvvvv",
      "vaaaaaaaaaaaaaav",
      "vat  t  i    eav",
      "vau  u  i    fav",
      "vaw cw  i    fav",
      "va!       i  gav",
      "vat  t     ikhav",
      "vau  u    dciiav",
      "vau  u    dcjjav",
      "vaw  w s      av",
      "va!    sm pol av",
      "vat ct sm qcm av",
      "vau  u sm rjn av",
      "vaw  w sm     av",
      "vaaaaaaaaaaaaaav",
      "vvvvvvvvvvvvvvvv"
    ],
    [
      "vvvvvvvvvvvvvvvv",
      "vaaaaaaaaaaaaaav",
      "va           xav",
      "vaC  C       yav",
      "va  c        Aav",
      "va        i  Bav",
      "va         i  av",
      "vaC  C    dciiav",
      "vaC  C    dc  av",
      "va     s      av",
      "va     s      av",
      "va  c  s   c  av",
      "vaC  C s      av",
      "va     s      av",
      "vaaaaaaaaaaaaaav",
      "vvvvvvvvvvvvvvvv"
    ],
    [
      "vvvvvvvvvvvvvvvv",
      "vaaaaaaaaaaaaaav",
      "va            av",
      "va            av",
      "va  c         av",
      "va        i   av",
      "va         i Dav",
      "va        dciiav",
      "va        dc  av",
      "va     s      av",
      "va     s      av",
      "va  c  s   c  av",
      "va     s      av",
      "va     s      av",
      "vaaaaaaaaaaaaaav",
      "vvvvvvvvvvvvvvvv"
    ],
    [
      "vvvvvvvvvvvvvvvv",
      "vaaaaaaaaaaaaaav",
      "va            av",
      "va            av",
      "va  c         av",
      "va        i   av",
      "va         i Eav",
      "va        dciiav",
      "va        dc  av",
      "va     s      av",
      "va     s      av",
      "va  c  s   c  av",
      "va     s      av",
      "va     s      av",
      "vaaaaaaaaaaaaaav",
      "vvvvvvvvvvvvvvvv"
    ],
    [
      "vvvvvvvvvvvvvvvv",
      "vaaaaaaaaaaaaaav",
      "vaFFFFFFFFFFFFav",
      "vaFFFFFFFFFFFFav",
      "vaFFcFFFFFFcFFav",
      "vaFFFFFFFFFFFFav",
      "vaFFFFFFFFFFFFav",
      "vaFFFFFFFFdcFFav",
      "vaFFFFFFFFdcFFav",
      "vaFFFFFFFFFFFFav",
      "vaFFFFFFFFFFFFav",
      "vaFFcFFFFFFcFFav",
      "vaFFFFFFFFFFFFav",
      "vaFFFFFFFFFFFFav",
      "vaaaaaaaaaaaaaav",
      "vvvvvvvvvvvvvvvv"
    ]
  ]
}