{
  "name": "building_residential1_ground_90",
  "refpalette": "c70cities:building_residential1_ground_palette_90",
  "xsize": 16,
  "zsize": 16,
  "slices": [
    [
      "GGGGGGGGGGGGGGGG",
      "GGGGGGGGGGGGGGGG",
      "GGaaaaaaaGGGGGGG",
      "GGabbbbbcccccGGG",
      "GGabbbbbeeeecGGG",
      "GGabbbbbeeeecGGG",
      "GGabbbbbddddcGGG",
      "GGabbbbbddddcGGG",
      "GGabbbbbddddcGGG",
      "GGabbbbbddddcGGG",
      "GGabbbbbddddcGGG",
      "GGabbbbbddddcGGG",
      "GGabbbbbcccccGGG",
      "GGaaaaaaaGGGGGGG",
      "GGGGGGGGGGGGGGGG",
      "GGGGGGGGGGGGGGGG"
    ],
    [
      "fggggfgggghggggf",
      "g              g",
      "g jkkjkkjAAAAA g",
      "g j  r  cccccA g",
      "g k   t yE McA g",
      "h k   t yDFFcA h",
      "g k   t    !cA g",
      "g jm qtw   JcA g",
      "g jm pt    LcA g",
      "g k      C KcA g",
      "h k  o  xB JcA h",
      "g k  o  xB IcA g",
      "g j  osucccccA g",
      "g jlnjkkjAAAAA g",
      "g              g",
      "ffi  fgggghggggf"
    ],
    [
      "fggggfgggghggggf",
      "g              g",
      "g jkkjkkj      g",
      "g j  Q  ccVcc  g",
      "g k   t y   c  g",
      "h k   t yTFFc  h",
      "g k   tw    U  g",
      "g jO  t     U  g",
      "g jO  t    XU  g",
      "g k      S  U  g",
      "h k  o      c  h",
      "g k  o  R  Wc  g",
      "g j  o  ccUcc  g",
      "g jNPjkkj      g",
      "g              g",
      "ff   fgggghggggf"
    ],
    [
      "     1          ",
      "                ",
      "  j00j00j    2  ",
      "  j     ccVcc2  ",
      "  Y   t y   c2  ",
      "  Y   twyFFFc2  ",
      "  Y   t     c2  ",
      "  j   t     c2  ",
      "  j   t     c2  ",
      "  Y         c2  ",
      "  Y  o      c2  ",
      "  Y  o      c2  ",
      "  j  o  ccUcc2  ",
      "  jZZjZZj    2  ",
      "                ",
      "                "
    ],
    [
      "                ",
      "                ",
      "  jjjjjjj  256  ",
      "  jbbbbbcccc56  ",
      "  jbbbbwy44456  ",
      "  jbbbb y33356  ",
      "  jbbbb    256  ",
      "  jbbbb    256  ",
      "  jbbbb    256  ",
      "  jbbbb    256  ",
      "  jbbbb    256  ",
      "  jbbbb    256  ",
      "  jbbbb cccc56  ",
      "  jjjjjjj  256  ",
      "                ",
      "                "
    ],
    [
      "                ",
      " 7              ",
      " 7jkkkkkj256    ",
      " 7j$    cc56    ",
      " 7j    -y[56    ",
      " 7j (  -yF56    ",
      " 7j#*+ - 256    ",
      " 7j@&) - 256    ",
      " 7j    - 256    ",
      " 7j9999- 256    ",
      " 7j9^^9- 256    ",
      " 7j9%%9- 256    ",
      " 7j8ZZ -cc56    ",
      " 7jkkkkkj256    ",
      " 7              ",
      "                "
    ]
  ]
}