{
  "name": "building_office4_top_270",
  "refpalette": "c70cities:building_office4_top_palette_270",
  "xsize": 16,
  "zsize": 16,
  "slices": [
    [
      "                ",
      "    abaaaaba    ",
      "  cccdeggedccc  ",
      "  cfeeeeeeeefc  ",
      " aceeeeeeeeeeca ",
      " bdeeeGeeGeeedb ",
      " aeeeeGGGGeeeea ",
      " aeeeeGGGGeeeea ",
      " aeeeeeGGeeeeea ",
      " aeeeGGeeGGeeea ",
      " bdeeGGeeGGeedb ",
      " aceeeeeeeeeeca ",
      "  cheeeeeeeefc  ",
      "  cccdeeeedccc  ",
      "    abaaaaba    ",
      "                "
    ],
    [
      "                ",
      "    abaaaaba    ",
      "  iiiji  ijiii  ",
      "  ikkk    kkki  ",
      " aik        kia ",
      " bjk        kjb ",
      " ai          ia ",
      " aip        lia ",
      " aiq        mia ",
      " ai          ia ",
      " bjk        kjb ",
      " aik        kia ",
      "  ikkk on kkki  ",
      "  iiijiiiijiii  ",
      "    abaaaaba    ",
      "                "
    ],
    [
      "                ",
      "    ab    ba    ",
      "  iiiji  ijiii  ",
      "  i          i  ",
      " ai          ia ",
      " bj          jb ",
      "  i          i  ",
      "  i          i  ",
      "  i          i  ",
      "  i          i  ",
      " bj          jb ",
      " ai          ia ",
      "  i          i  ",
      "  iiijiiiijiii  ",
      "    ab    ba    ",
      "                "
    ],
    [
      "                ",
      "    a      a    ",
      "   iijiiiijii   ",
      "  i          i  ",
      " ai          ia ",
      "  j          j  ",
      "  i          i  ",
      "  i          i  ",
      "  i          i  ",
      "  i          i  ",
      "  j          j  ",
      " ai          ia ",
      "  i          i  ",
      "   iijiiiijii   ",
      "    a      a    ",
      "                "
    ],
    [
      "                ",
      "                ",
      "   iijiiiijii   ",
      "  i          i  ",
      "  i          i  ",
      "  j          j  ",
      "  i          i  ",
      "  i          i  ",
      "  i          i  ",
      "  i          i  ",
      "  j          j  ",
      "  i          i  ",
      "  i          i  ",
      "   iijiiiijii   ",
      "                ",
      "                "
    ],
    [
      "                ",
      "                ",
      "                ",
      "   iijiiiijii   ",
      "   iijiiiijii   ",
      "   jjrjjjjrjj   ",
      "   iijjjjjjii   ",
      "   iijjjjjjii   ",
      "   iijjjjjjii   ",
      "   iijjjjjjii   ",
      "   jjsjjjjrjj   ",
      "   iijiiiijii   ",
      "   iijiiiijii   ",
      "                ",
      "                ",
      "                "
    ]
  ]
}