{
  "name": "cabin_1",
  "refpalette": "c70cities:cabin_1_palette",
  "xsize": 16,
  "zsize": 16,
  "slices": [
    [
      "aaaaaaaaaaaaaaaa",
      "aaaaaaaaaaaaaaaa",
      "aaaaaaaaaaaaaaaa",
      "aaaaaaaaaaaaaaaa",
      "aaaaaaaaaaaaaaaa",
      "aaaaaaaaaaaaaaaa",
      "aaaaaaaaaaaaaaaa",
      "aaaaaaaaaaaaaaaa",
      "aaaaaaaaaaaaaaaa",
      "aaaaaaaaaaaaaaaa",
      "aaaaaaaaaaaaaaaa",
      "aaaaaaaaaaaaaaaa",
      "aaaaaaaaaaaaaaaa",
      "aaaaaaaaaaaaaaaa",
      "aaaaaaaaaaaaaaaa",
      "aaaaaaaaaaaaaaaa"
    ],
    [
      "aaaaaaaaaaaaaaaa",
      "aaaaaaaaaaaaaaaa",
      "aaaaaaaaaaaaaaaa",
      "aaaaaaaaaaaaaaaa",
      "aaaaaaaaaaaaaaaa",
      "aaaaaaaaaaaaaaaa",
      "aaaaaaaaaaaaaaaa",
      "aaaaaaaaaaaaaaaa",
      "aaaaaaaaaaaaaaaa",
      "aaaaaaaaaaaaaaaa",
      "aaaaaaaaaaaaaaaa",
      "aaaaaaaaaaaaaaaa",
      "aaaaaaaaaaaaaaaa",
      "aaaaaaaaaaaaaaaa",
      "aaaaaaaaaaaaaaaa",
      "aaaaaaaaaaaaaaaa"
    ],
    [
      "GGGGGGGGGGGGGGGG",
      "GGGGGGGGGGGGGGGG",
      "GGGGGGGGGGGaaaGG",
      "GGGGGGGGGGGaaaGG",
      "GGGGGGGGGGGaaaGG",
      "GGGGGGGGGGGaaaGG",
      "GGGGGGGGGGGaaaGG",
      "GGGGGGGGGGGGGGGG",
      "GGGGGGGGGGGGbbGG",
      "bbGGGGGGGGGbbGGG",
      "bGbbGbGGGGGbbbGG",
      "GbbbbGbbGGbbbGGG",
      "GGbGbbbbbbbbbGGG",
      "GGGGGGbbGbcbGGGG",
      "GGGGGGGGbbbbGGGG",
      "GGGGGGGGGGGGGGGG"
    ],
    [
      " dee    fegde g ",
      "  e he  e ijklim",
      "ef ee efe innnio",
      " eedeeee einnnie",
      "egeefedf  innnie",
      "  fe m    innnid",
      " e de   d innnio",
      "ef ee fmepiqqqi ",
      " e ef e e      d",
      "  e  d  e     de",
      "      eeed     f",
      "e            eee",
      "ee           fd ",
      "ee ef     r s   ",
      " dfm de     t he",
      "  ed egf   d e  "
    ],
    [
      "        ~       ",
      "    ~     u   wx",
      " ~     ~  uyAyw ",
      "          uB Cw ",
      "    ~  ~  uD Ew ",
      "  ~  x    uF Iw ",
      "          uJKJw ",
      " ~    ~x  u   w ",
      "    ~           ",
      "                ",
      "               ~",
      "                ",
      "             ~  ",
      "    ~           ",
      "  ~x          ~ ",
      "       ~        "
    ],
    [
      "                ",
      "          LM LM ",
      "          LyAyM ",
      "          LN OM ",
      "          L  OM ",
      "          LO  M ",
      "          LJPJM ",
      "          LM LM ",
      "                ",
      "                ",
      "                ",
      "                ",
      "                ",
      "                ",
      "                ",
      "                "
    ],
    [
      "                ",
      "           Q R  ",
      "           SyS  ",
      "           Q R  ",
      "           Q R  ",
      "           Q R  ",
      "           STS  ",
      "           Q R  ",
      "                ",
      "                ",
      "                ",
      "                ",
      "                ",
      "                ",
      "                ",
      "                "
    ],
    [
      "                ",
      "           u w  ",
      "           uyw  ",
      "           uUw  ",
      "           uVw  ",
      "           uOw  ",
      "           uTw  ",
      "           u w  ",
      "                ",
      "                ",
      "                ",
      "                ",
      "                ",
      "                ",
      "                ",
      "                "
    ],
    [
      "                ",
      "           LSM  ",
      "           LSM  ",
      "           LSM  ",
      "           LSM  ",
      "           LSM  ",
      "           LSM  ",
      "           LSM  ",
      "                ",
      "                ",
      "                ",
      "                ",
      "                ",
      "                ",
      "                ",
      "                "
    ],
    [
      "                ",
      "            S   ",
      "            S   ",
      "            S   ",
      "            S   ",
      "            S   ",
      "            S   ",
      "            S   ",
      "                ",
      "                ",
      "                ",
      "                ",
      "                ",
      "                ",
      "                ",
      "                "
    ],
    [
      "                ",
      "            W   ",
      "            X   ",
      "            X   ",
      "            X   ",
      "            X   ",
      "            X   ",
      "            W   ",
      "                ",
      "                ",
      "                ",
      "                ",
      "                ",
      "                ",
      "                ",
      "                "
    ]
  ]
}