{
  "name": "cabin_4_0",
  "refpalette": "c70cities:cabin_4_0_palette",
  "xsize": 16,
  "zsize": 16,
  "slices": [
    [
      "aaaaaaaaaaaaaaaa",
      "aaaaaaaaaaaaaaaa",
      "aaaaaaaaaaaaaaaa",
      "aaaaaaaaaaaaaaaa",
      "aaaaaaaaaaaaaaaa",
      "aaaaaaaaaaaaaaaa",
      "aaaaaaaaaaaaaaaa",
      "aaaaaaaaaaaaaaaa",
      "aaaaaaaaaaaaaaaa",
      "aaaaaaaaaaaaaaaa",
      "aaaaaaaaaaaaaaaa",
      "aaaaaaaaaaaaaaaa",
      "aaaaaaaaaaaaaaaa",
      "aaaaaaaaaaaaaaaa",
      "aaaaaaaaaaaaaaaa",
      "aaaaaaaaaaaaaaaa"
    ],
    [
      "aaaaaaaaaaaaaaaa",
      "aaaaaaaaaaaaaaaa",
      "aaaaaaaaaaaaaaaa",
      "aaaaaaaaaaaaaaaa",
      "aaaaaaaaaaaaaaaa",
      "aaaaaaaaaaaaaaaa",
      "aaaaaaaaaaaaaaaa",
      "aaaaaaaaaaaaaaaa",
      "aaaaaaaaaaaaaaaa",
      "aaaaaaaaaaaaaaaa",
      "aaaaaaaaaaaaaaaa",
      "aaaaaaaaaaaaaaaa",
      "aaaaaaaaaaaaaaaa",
      "aaaaaaaaaaaaaaaa",
      "aaaaaaaaaaaaaaaa",
      "aaaaaaaaaaaaaaaa"
    ],
    [
      "GGGGGGGGGGGGGGGG",
      "GGGGbGbGbGGGGGGG",
      "GGbbbbbbGGGGGGGG",
      "GGbbGGbbbGGGGGGG",
      "GbbGvvvvvvvvGGGG",
      "GGbGvvvvvvvvGGGG",
      "GbGGvccccccvGGGG",
      "GbbGvccccccvGGGG",
      "GbbGvccccccvGGGG",
      "GbGGvccccccvGGGG",
      "bGbGvccccccvGGGG",
      "GbbGvGcccccvGGGG",
      "bbbbvccccccvGGGG",
      "GbGbvccccccvGGGG",
      "GGbbvGcccccvGGGG",
      "GGGbvvvvvvvvGGGG"
    ],
    [
      "                ",
      "                ",
      "             d  ",
      "                ",
      "   efvffffvfe   ",
      "   gvvvvvvvve   ",
      "   evhhhhhhve  d",
      "   evij  jiv    ",
      "    v k  k ve   ",
      "   ev      ve   ",
      "   evvl  lvv    ",
      "   evm    nv  d ",
      "    o     pve   ",
      "    q     pve   ",
      "    vm    rv    ",
      " sstvvl  lvve d "
    ],
    [
      "                ",
      "                ",
      "             ~  ",
      "                ",
      "                ",
      "     f    f     ",
      "    fvffffvf   ~",
      "    vuuuuuuv    ",
      "    v      v    ",
      "    v      v    ",
      "    vvl  lvv    ",
      "    vm     v  ~ ",
      "    w      x    ",
      "    y      x    ",
      "    vm     v    ",
      "    vvl  lvv  ~ "
    ],
    [
      "                ",
      "                ",
      "                ",
      "                ",
      "                ",
      "                ",
      "                ",
      "     f    f     ",
      "    fvffffvf    ",
      "    vuuuuuuv    ",
      "    vvl  lvv    ",
      "    v      v    ",
      "    v      v    ",
      "    v      v    ",
      "    v      v    ",
      "    vvl  lvv    "
    ],
    [
      "                ",
      "                ",
      "                ",
      "                ",
      "                ",
      "                ",
      "                ",
      "                ",
      "                ",
      "     f    f     ",
      "    fvffffvf    ",
      "    vuuuuuuv    ",
      "    v      v    ",
      "    v      v    ",
      "    v      v    ",
      "    vvvvvvvv    "
    ],
    [
      "                ",
      "                ",
      "                ",
      "                ",
      "                ",
      "                ",
      "                ",
      "                ",
      "                ",
      "                ",
      "                ",
      "     f    f     ",
      "    fvffffvf    ",
      "    vuuuuuuv    ",
      "    vAuuuuAv    ",
      "    vvBBBBvv    "
    ],
    [
      "                ",
      "                ",
      "                ",
      "                ",
      "                ",
      "                ",
      "                ",
      "                ",
      "                ",
      "                ",
      "                ",
      "                ",
      "                ",
      "     f    f     ",
      "    fvffffvf    ",
      "    vvffffvv    "
    ]
  ]
}