{
  "name": "cabin_3_1",
  "refpalette": "c70cities:cabin_3_1_palette",
  "xsize": 16,
  "zsize": 16,
  "slices": [
    [
      "aaaaaaaaaaaaaaaa",
      "aaaaaaaaaaaaaaaa",
      "aaaaaaaaaaaaaaaa",
      "aaaaaaaaaaaaaaaa",
      "aaaaaaaaaaaaaaaa",
      "aaaaaaaaaaaaaaaa",
      "aaaaaaaaaaaaaaaa",
      "aaaaaaaaaaaaaaaa",
      "aaaaaaaaaaaaaaaa",
      "aaaaaaaaaaaaaaaa",
      "aaaaaaaaaaaaaaaa",
      "aaaaaaaaaaaaaaaa",
      "aaaaaaaaaaaaaaaa",
      "aaaaaaaaaaaaaaaa",
      "aaaaaaaaaaaaaaaa",
      "aaaaaaaaaaaaaaaa"
    ],
    [
      "aaaaaaaaaaaaaaaa",
      "aaaaaaaaaaaaaaaa",
      "aaaaaaaaaaaaaaaa",
      "aaaaaaaaaaaaaaaa",
      "aaaaaaaaaaaaaaaa",
      "aaaaaaaaaaaaaaaa",
      "aaaaaaaaaaaaaaaa",
      "aaaaaaaaaaaaaaaa",
      "aaaaaaaaaaaaaaaa",
      "aaaaaaaaaaaaaaaa",
      "aaaaaaaaaaaaaaaa",
      "aaaaaaaaaaaaaaaa",
      "aaaaaaaaaaaaaaaa",
      "aaaaaaaaaaaaaaaa",
      "aaaaaaaaaaaaaaaa",
      "aaaaaaaaaaaaaaaa"
    ],
    [
      "GGGGGGGGGGGGGGGG",
      "bGGGGGGGGGGGGGGG",
      "bGcGGGGcGGGGcGGG",
      "ddddddddddddGGGG",
      "eeeeeeeeeeedGGGG",
      "eeeeeeeeeeedGGGG",
      "ddddddddddddGGGG",
      "bGcaaaGcGGGGcGGG",
      "GbGGGGGGGGGGGGGG",
      "bbbGGGGGGGGGGGGG",
      "bbGGGGGGGGGGGGGG",
      "bGGGGGGGGGGGGGGG",
      "bGGGGGGGGGGGGGGG",
      "GGaGGGGaGGGGaGGG",
      "GGGGGGGGGGGGGGGG",
      "GGGGGGGGGGGGGGGG"
    ],
    [
      "                ",
      "                ",
      " fcffffcffffc   ",
      "ghihhhhjhhhh    ",
      "        klmh    ",
      "        klmh    ",
      "nhohhhhphhhh    ",
      " fcqrrsctuw c   ",
      "  x         x   ",
      "  y         x   ",
      "  x         x   ",
      " Ax         x   ",
      " Bx         x   ",
      "xxcxxxxcxxxxc   ",
      "                ",
      "                "
    ],
    [
      "                ",
      "         CCDEE  ",
      "  c    c CCDEE  ",
      "FhIhJJh KKKLEE  ",
      "         MMLEE  ",
      "         MMLEE  ",
      "Nh hJJhOKKKLEE  ",
      "  c    c CCDEE  ",
      "         CCDEE  ",
      "                ",
      "                ",
      "                ",
      "                ",
      "  P    P    P   ",
      "                ",
      "                "
    ],
    [
      "                ",
      "    CCDEE       ",
      "  c CCDEE       ",
      "hhIKQQLRR       ",
      "    MMLRR       ",
      "    MMLRR       ",
      "hhOKSSLRR       ",
      "  c CCDEE       ",
      "    CCDEE       ",
      "                ",
      "                ",
      "                ",
      "                ",
      "                ",
      "                ",
      "                "
    ],
    [
      "                ",
      "CDEE            ",
      "CDEE            ",
      "KLRR            ",
      "MLRR            ",
      "MLRR            ",
      "KLRR            ",
      "CDEE            ",
      "CDEE            ",
      "                ",
      "                ",
      "                ",
      "                ",
      "                ",
      "                ",
      "                "
    ]
  ]
}