{
  "name": "cabin_3_0",
  "refpalette": "c70cities:cabin_3_0_palette",
  "xsize": 16,
  "zsize": 16,
  "slices": [
    [
      "aaaaaaaaaaaaaaaa",
      "aaaaaaaaaaaaaaaa",
      "aaaaaaaaaaaaaaaa",
      "aaaaaaaaaaaaaaaa",
      "aaaaaaaaaaaaaaaa",
      "aaaaaaaaaaaaaaaa",
      "aaaaaaaaaaaaaaaa",
      "aaaaaaaaaaaaaaaa",
      "aaaaaaaaaaaaaaaa",
      "aaaaaaaaaaaaaaaa",
      "aaaaaaaaaaaaaaaa",
      "aaaaaaaaaaaaaaaa",
      "aaaaaaaaaaaaaaaa",
      "aaaaaaaaaaaaaaaa",
      "aaaaaaaaaaaaaaaa",
      "aaaaaaaaaaaaaaaa"
    ],
    [
      "aaaaaaaaaaaaaaaa",
      "aaaaaaaaaaaaaaaa",
      "aaaaaaaaaaaaaaaa",
      "aaaaaaaaaaaaaaaa",
      "aaaaGbbbaaaaaaaa",
      "aaaaaabbaaaaaaaa",
      "aaaaaaaaaaaaaaaa",
      "aaaaaaaaaaaaaaaa",
      "aaaaaaaaaaaaaaaa",
      "aaaaaaaaaaaaaaaa",
      "aaaaaaaaaaaaaaaa",
      "aaaaaaaaaaaaaaaa",
      "aaaaaaaaaaaaaaaa",
      "aaaaaaaaaaaaaaaa",
      "aaaaaaaaaaaaaaaa",
      "aaaaaaaaaaaaaaaa"
    ],
    [
      "GGGGGGGGGGcGccGc",
      "GGGGGGGGGGGccGcc",
      "GGGGGGGGGGccGdGc",
      "GGGGbbbbGGGcGGbb",
      "GGGGefghGGccGGbi",
      "GGGGGbhhGGcGGGbi",
      "GGGGbbbbGGGcGGbb",
      "GGGGGGbGGGccGdGc",
      "GGGGGGGGGGGcGGcc",
      "GGGGGGGGGcccccGc",
      "GGGGaGGGGGccGGGc",
      "GGGGaaGGGGGcGGGG",
      "GGGGaaaGGGcGGGGc",
      "GGGGGGGGGGGGGaGG",
      "GGGGGGGGGGGcGGGG",
      "GGGGGGGGGcGGGGGG"
    ],
    [
      "                ",
      "                ",
      "   jjjjjj    dk ",
      "  lj   lj    kmn",
      "   jo pqj     r ",
      "   j   sj     r ",
      "  ljt  lj    kmu",
      "   j    j    dk ",
      "   j    j    j  ",
      "   j    j    w  ",
      "   jx   j    j  ",
      "   jyy  j    jA ",
      "   jyyy j    jB ",
      "  Cjjjjjj    djj",
      "                ",
      "                "
    ],
    [
      "                ",
      "                ",
      "             d  ",
      "  l    l      mD",
      "    o Eo      r ",
      "       F      r ",
      "  l    l      mI",
      "             d  ",
      "                ",
      "                ",
      "                ",
      "                ",
      "    yy          ",
      "             J  ",
      "                ",
      "                "
    ],
    [
      "                ",
      "                ",
      "             d  ",
      "  l    l      mm",
      "    K KK      r ",
      "    f         r ",
      "  l L  l      mm",
      "             d  ",
      "                ",
      "                ",
      "                ",
      "                ",
      "                ",
      "                ",
      "                ",
      "                "
    ],
    [
      "                ",
      "               M",
      "             d M",
      " NNNNNNNNNNNNNOO",
      " NNNNNNNNNNNNNOP",
      " NNNNNNNNNNNNNOP",
      " NNNNNNNNNNNNNOO",
      "             d M",
      "               M",
      "                ",
      "                ",
      "                ",
      "                ",
      "                ",
      "                ",
      "                "
    ],
    [
      "                ",
      "          MMQRR ",
      "          MMQRR ",
      "          MMSTT ",
      "          MMSTT ",
      "          MMSTT ",
      "          MMSTT ",
      "          MMQRR ",
      "          MMQRR ",
      "                ",
      "                ",
      "                ",
      "                ",
      "                ",
      "                ",
      "                "
    ]
  ]
}