{
  "name": "cabin_6_0",
  "refpalette": "c70cities:cabin_6_0_palette",
  "xsize": 16,
  "zsize": 16,
  "slices": [
    [
      "aaaaaaaaaaaaaaaa",
      "aaaaaaaaaaaaaaaa",
      "aaaaaaaaaaaaaaaa",
      "aaaaaaaaaaaaaaaa",
      "aaaaaaaaaaaaaaaa",
      "aaaaaaaaaaaaaaaa",
      "aaaaaaaaaaaaaaaa",
      "aaaaaaaaaaaaaaaa",
      "aaaaaaaaaaaaaaaa",
      "aaaaaaaaaaaaaaaa",
      "aaaaaaaaaaaaaaaa",
      "aaaaaaaaaaaaaaaa",
      "aaaaaaaaaaaaaaaa",
      "aaaaaaaaaaaaaaaa",
      "aaaaaaaaaaaaaaaa",
      "aaaaaaaaaaaaaaaa"
    ],
    [
      "aGGGGGGGGGGGGaaG",
      "GaGGaaaaaGGGGaaa",
      "GaaaaaaaaaaGGGaG",
      "aaaaaaaaaaaaGGGa",
      "aaaaaaaaaaaaaGGG",
      "aaaaaaaaaaaaaaGG",
      "aaaaaaaaaaaaaaaG",
      "aaaaaaaaaaaaaaaG",
      "aaaaaaaaaaaaaaaG",
      "Gaaaaaaaaaaaaaaa",
      "Gaaaaaaaaaaaaaaa",
      "Gaaaaaaaaaaaaaaa",
      "aaaaaaaaaaaaaaaa",
      "aaaaaaaaaaaaaaaG",
      "aaaaaaaaaaaaaaaa",
      "aaaaaaaaaaaaaaaa"
    ],
    [
      "G            GG ",
      " G  GGGGG    GGG",
      " GGGGaaGGGG   G ",
      "GGGGaaaaaGGG   G",
      "GGGaaaaaaaGGG   ",
      "GGGaaaaaaaaaGG  ",
      "GGGaaaaaaaaaaGG ",
      "GGaaaaaaaaaaaGG ",
      "GGaaaaaaaaaaaaG ",
      " GaaaaaaaaaaaaGG",
      " GaaaaaaaaaaaaGG",
      " GaaaaaaaaaaaaGG",
      "GGaaaaaaaaaaaGGG",
      "GGaaaaaaaaaaaGG ",
      "GGGaaaaaaaaaaGGG",
      "GGGaaaaaaaaaaaGG"
    ],
    [
      "                ",
      "              b ",
      "     GG         ",
      "    GGGGG       ",
      " b GGGaaaG      ",
      "   GGaaaaGGG    ",
      "   GaaaaaaaGG   ",
      "  GGaaaaaaaaG   ",
      "  GccaaaaaaccG  ",
      "  GGGaaaaaaaGG  ",
      "  GGGaaaaaaaGG  ",
      "  GGaaaaaaaaGG  ",
      "  GGaaaaaaaaG   ",
      "  GGaaaaaaaGG   ",
      "   GGaaaaaaGG   ",
      "   GGaaaaaaaGG  "
    ],
    [
      "                ",
      "              ~ ",
      "                ",
      "                ",
      " ~    GGG       ",
      "     GdGG       ",
      "    GGaaGGG     ",
      "    GaaaaaGG    ",
      "   ccaaaaaacc   ",
      "     aaaaaaa    ",
      "     aaaaaaG    ",
      "    GaaaaaaG    ",
      "    GGaaaaGG    ",
      "    GGaaaaG     ",
      "     GaaaaG     ",
      "     GGaaaGG    "
    ],
    [
      "                ",
      "                ",
      "                ",
      "                ",
      "                ",
      "                ",
      "      Gd        ",
      "     GdGdG      ",
      "     GGdGdG     ",
      "   eeGGddGGee   ",
      "   ffaaggaaff   ",
      "     ahggha     ",
      "      aaaa      ",
      "      aaaa      ",
      "      GGGG      ",
      "       GGG      "
    ],
    [
      "                ",
      "                ",
      "                ",
      "                ",
      "                ",
      "                ",
      "                ",
      "                ",
      "                ",
      "                ",
      "     iijkii     ",
      "   eeil  liee   ",
      "   ffigmmgiff   ",
      "   ffiggggiff   ",
      "     innnni     ",
      "     innnni     "
    ],
    [
      "                ",
      "                ",
      "                ",
      "                ",
      "                ",
      "                ",
      "                ",
      "                ",
      "                ",
      "                ",
      "     iiopii     ",
      "     il  li     ",
      "     iq  qi     ",
      "     i    i     ",
      "   eeir  riee   ",
      "   eeis  tiee   "
    ],
    [
      "                ",
      "                ",
      "                ",
      "                ",
      "                ",
      "                ",
      "                ",
      "                ",
      "                ",
      "                ",
      "     iiuuii     ",
      "     iq  qi     ",
      "     i    i     ",
      "     i    i     ",
      "     i    i     ",
      "     iw  xi     "
    ],
    [
      "                ",
      "                ",
      "                ",
      "                ",
      "                ",
      "                ",
      "                ",
      "     gggggg     ",
      "     gnnnng     ",
      "     gnnnng     ",
      "     gqggqg     ",
      "     g    g     ",
      "     g    g     ",
      "     g    g     ",
      "     g    g     ",
      "     g    g     "
    ],
    [
      "                ",
      "                ",
      "                ",
      "                ",
      "                ",
      "                ",
      "                ",
      "     gggggg     ",
      "     gyAAyg     ",
      "     g BB g     ",
      "     g CC g     ",
      "     g    g     ",
      "     g    g     ",
      "     g    g     ",
      "     g    g     ",
      "     g    g     "
    ],
    [
      "                ",
      "                ",
      "                ",
      "                ",
      "                ",
      "                ",
      "                ",
      "     gDDDDg     ",
      "     g   Eg     ",
      "     g    g     ",
      "     g    g     ",
      "     gCCCCg     ",
      "    fmFFFFmf    ",
      "    fmFFFFmf    ",
      "    fmFFFFmf    ",
      "    e FFFF e    "
    ],
    [
      "                ",
      "                ",
      "                ",
      "                ",
      "                ",
      "                ",
      "    ffffffff    ",
      "    fmmmmmmf    ",
      "    fmFFFFmf    ",
      "    e FFFF e    ",
      "    e FFFF e    ",
      "    e FFFF e    ",
      "                ",
      "                ",
      "                ",
      "                "
    ]
  ]
}