{
  "name": "cabin_1",
  "refpalette": "c70cities:cabin_1_palette",
  "xsize": 16,
  "zsize": 16,
  "slices": [
    [
      "aaaaaaaaaaaaaaaa",
      "aaaaaaaaaaaaaaaa",
      "aaaaaaaaaaaaaaaa",
      "aaaaaaaaaaaaaaaa",
      "aaaaaaaaaaaaaaaa",
      "aaaaaaaaaaaaaaaa",
      "aaaaaaaaaaaaaaaa",
      "aaaaaaaaaaaaaaaa",
      "aaaaaaaaaaaaaaaa",
      "aaaaaaaaaaaaaaaa",
      "aaaaaaaaaaaaaaaa",
      "aaaaaaaaaaaaaaaa",
      "aaaaaaaaaaaaaaaa",
      "aaaaaaaaaaaaaaaa",
      "aaaaaaaaaaaaaaaa",
      "aaaaaaaaaaaaaaaa"
    ],
    [
      "aaaaaaaaaaaaaaaa",
      "aaaaaaaaaaaaaaaa",
      "aaaaaaaaaaaaaaaa",
      "aaaaaaaaaaaaaaaa",
      "aaaaaaaaaaaaaaaa",
      "aaaaaaaaaaaaaaaa",
      "aaaaaaaaaaaaaaaa",
      "aaaaaaaaaaaaaaaa",
      "aaaaaaaaaaaaaaaa",
      "aaaaaaaaaaaaaaaa",
      "aaaaaaaaaaaaaaaa",
      "aaaaaaaaaaaaaaaa",
      "aaaaaaaaaaaaaaaa",
      "aaaaaaaaaaaaaaaa",
      "aaaaaaaaaaaaaaaa",
      "aaaaaaaaaaaaaaaa"
    ],
    [
      "GGGGGGGGGGGGGGGG",
      "GGGGGGGGGGGGGGGG",
      "GGGGGGGGGGGaaaGG",
      "GGGGGGGGGGGaaaGG",
      "GGGGGGGGGGGaaaGG",
      "GGGGGGGGGGGaaaGG",
      "GGGGGGGGGGGaaaGG",
      "GGGGGGGGGGGGGGGG",
      "GGGGGGGGGGGGbbGG",
      "bbGGGGGGGGGbbGGG",
      "bGbbGbGGGGGbbbGG",
      "GbbbbGbbGGbbbGGG",
      "GGbGbbbbbbbbbGGG",
      "GGGGGGbbGbcbGGGG",
      "GGGGGGGGbbbbGGGG",
      "GGGGGGGGGGGGGGGG"
    ],
    [
      "                ",
      "    d   e fghif ",
      " e        fjjjfk",
      "          fjjjf ",
      " l        fjjjf ",
      "          fjjjf ",
      "          fjjjfk",
      " e    e  mfnnnf ",
      "                ",
      "                ",
      "               e",
      "                ",
      "                ",
      "          o p   ",
      "  e         q d ",
      "      le        "
    ],
    [
      "                ",
      "    ~   ~ r   s ",
      " ~        rtuts ",
      "          rw xs ",
      "          ry As ",
      "          rB Cs ",
      "          rDEDs ",
      " ~    ~   r   s ",
      "                ",
      "                ",
      "               ~",
      "                ",
      "                ",
      "                ",
      "  ~           ~ ",
      "       ~        "
    ],
    [
      "                ",
      "          FI FI ",
      "          FtutI ",
      "          FJ KI ",
      "          F  KI ",
      "          FK  I ",
      "          FDLDI ",
      "          FI FI ",
      "                ",
      "                ",
      "                ",
      "                ",
      "                ",
      "                ",
      "                ",
      "                "
    ],
    [
      "                ",
      "           M N  ",
      "           OtO  ",
      "           M N  ",
      "           M N  ",
      "           M N  ",
      "           OPO  ",
      "           M N  ",
      "                ",
      "                ",
      "                ",
      "                ",
      "                ",
      "                ",
      "                ",
      "                "
    ],
    [
      "                ",
      "           r s  ",
      "           rts  ",
      "           rQs  ",
      "           rRs  ",
      "           rKs  ",
      "           rPs  ",
      "           r s  ",
      "                ",
      "                ",
      "                ",
      "                ",
      "                ",
      "                ",
      "                ",
      "                "
    ],
    [
      "                ",
      "           FOI  ",
      "           FOI  ",
      "           FOI  ",
      "           FOI  ",
      "           FOI  ",
      "           FOI  ",
      "           FOI  ",
      "                ",
      "                ",
      "                ",
      "                ",
      "                ",
      "                ",
      "                ",
      "                "
    ],
    [
      "                ",
      "            O   ",
      "            O   ",
      "            O   ",
      "            O   ",
      "            O   ",
      "            O   ",
      "            O   ",
      "                ",
      "                ",
      "                ",
      "                ",
      "                ",
      "                ",
      "                ",
      "                "
    ],
    [
      "                ",
      "            S   ",
      "            T   ",
      "            T   ",
      "            T   ",
      "            T   ",
      "            T   ",
      "            S   ",
      "                ",
      "                ",
      "                ",
      "                ",
      "                ",
      "                ",
      "                ",
      "                "
    ]
  ]
}