{
  "name": "cabin_5",
  "refpalette": "c70cities:cabin_5_palette",
  "xsize": 16,
  "zsize": 16,
  "slices": [
    [
      "aaaaaaaaaaaaaaaa",
      "aaaaaaaaaaaaaaaa",
      "aaaaaaaaaaaaaaaa",
      "aaaaaaaaaaaaaaaa",
      "aaaaaaaaaaaaaaaa",
      "aaaaaaaaaaaaaaaa",
      "aaaaaaaaaaaaaaaa",
      "aaaaaaaaaaaaaaaa",
      "aaaaaaaaaaaaaaaa",
      "aaaaaaaaaaaaaaaa",
      "aaaaaaaaaaaaaaaa",
      "aaaaaaaaaaaaaaaa",
      "aaaaaaaaaaaaaaaa",
      "aaaaaaaaaaaaaaaa",
      "aaaaaaaaaaaaaaaa",
      "aaaaaaaaaaaaaaaa"
    ],
    [
      "aaaaaaaaaaaaaaGG",
      "aaaaaaaaaaaaaaaG",
      "aaaaaaaaaaaaaaaG",
      "aaaaaaaaaaaaaaaa",
      "aaaaaaaaaaaaaaaa",
      "aaaaaaaaaaaaaaaa",
      "aaaaaaaaaaaaaaaa",
      "aaaaaaaaaaaaaaaa",
      "aaaaaaaaaaaaaaaa",
      "aaaaaaaaaaaaaaaa",
      "aaaaaaaaaaaaaaaa",
      "aaaaaaaaaaaaaaaa",
      "aaaaaaaaaaaaaaaa",
      "aaaaaaaaaaaaaaaa",
      "aaaaaaaaaaaaaaGa",
      "aaaaaaaaaaaaaGGG"
    ],
    [
      "GGGGGGGGGGGGGGbc",
      "GGGdGGdeGGGGGGG ",
      "GGdedGGGGddGGGGc",
      "GGddddeGddGGeGGG",
      "GGeddddddddGGGGG",
      "GdGddddddeGaGGGG",
      "GGGGddffgggeGdGG",
      "GGGdddfffggdeGGG",
      "heGehdffgggdGGGG",
      "GheGhhfggggdGGGG",
      "hGhhGefggggeGGGG",
      "GGeGGdgfgggGdGGG",
      "GGGGGGgggggGdGGG",
      "GGGGeaGGdeGaGGGG",
      "GGGeGGGGGGGGGG G",
      "GGGGGGeGGGGGG bc"
    ],
    [
      " cbc ccbcb bcci ",
      "bbb b    cbbb c ",
      "cc j cb   kc lb ",
      "bclm n! ommc b c",
      "cc ommlmpqr cbb ",
      "blc psrm mltccbb",
      "ccccmouwwxxm lcc",
      "c b ymuAnBxy lbc",
      "  c   u C uk c  ",
      "c  b  D  Extccbb",
      "    cFo  Ixkccb ",
      "bc cbmunkFJ pccc",
      "bccbcbJJ xJlm cb",
      "c c lKbcmycKc  c",
      "blc cbcccccccc b",
      "bbb cbmcb blb i "
    ],
    [
      "  i    i i i    ",
      "iii i     iii   ",
      "   j  i       i ",
      "i            i  ",
      "             ii ",
      "i    s     s  ii",
      "      LLn wn    ",
      "  i   MN  u   i ",
      "      u   J     ",
      "   i  O   ut  ii",
      "         Px   i ",
      "i   i M   u     ",
      "i  i ixxMnJ    i",
      "     Ki    K    ",
      "i    i         i",
      "iii  i  i i i   "
    ],
    [
      "                ",
      "                ",
      "   N            ",
      "                ",
      "                ",
      "     sn   ns    ",
      "     nuwLnLn    ",
      "     nuQQRun    ",
      "      uQQnun    ",
      "      uQQ xt    ",
      "       QQ u     ",
      "      uRQ x     ",
      "      xLxLx     ",
      "     t   nnK    ",
      "                ",
      "                "
    ],
    [
      "                ",
      "                ",
      "                ",
      "                ",
      "    qqqq  qqq   ",
      "     sSSSSSsT   ",
      "     UkFy AV    ",
      "     UWFX oV    ",
      "     Uk F  V    ",
      "     UWrX  V    ",
      "     UY k  V    ",
      "     VnF  oZ    ",
      "     VYC BCZ    ",
      "    0t11112K0   ",
      "    343443333   ",
      "                "
    ],
    [
      "                ",
      "                ",
      "                ",
      "                ",
      "                ",
      "    qPPPPnPPq   ",
      "    Twn   nxT   ",
      "     u          ",
      "     u     x    ",
      "     sk    t    ",
      "     u     x    ",
      "     u     x    ",
      "    5un   nJ0   ",
      "    466666673   ",
      "                ",
      "                "
    ],
    [
      "                ",
      "                ",
      "                ",
      "                ",
      "                ",
      "                ",
      "    qP PPPEE8   ",
      "    nL    nxT   ",
      "     u     J    ",
      "     s     K    ",
      "     u    n     ",
      "    5u    nx    ",
      "    396677764   ",
      "                ",
      "                ",
      "                "
    ],
    [
      "                ",
      "                ",
      "                ",
      "                ",
      "                ",
      "                ",
      "                ",
      "    qPPn PPE8   ",
      "    Tu    nJ@   ",
      "     s     K    ",
      "    0xn   nJ0   ",
      "    466 99663   ",
      "                ",
      "                ",
      "                ",
      "                "
    ],
    [
      "                ",
      "                ",
      "                ",
      "                ",
      "                ",
      "                ",
      "                ",
      "                ",
      "    qPn   EE8   ",
      "    #s    nK$   ",
      "    4999  674   ",
      "                ",
      "                ",
      "                ",
      "                ",
      "                "
    ],
    [
      "                ",
      "                ",
      "                ",
      "                ",
      "                ",
      "                ",
      "                ",
      "                ",
      "                ",
      "    pFF  %%^p   ",
      "                ",
      "                ",
      "                ",
      "                ",
      "                ",
      "                "
    ]
  ]
}