{
  "name": "cabin_3_0",
  "refpalette": "c70cities:cabin_3_0_palette",
  "xsize": 16,
  "zsize": 16,
  "slices": [
    [
      "aaaaaaaaaaaaaaaa",
      "aaaaaaaaaaaaaaaa",
      "aaaaaaaaaaaaaaaa",
      "aaaaaaaaaaaaaaaa",
      "aaaaaaaaaaaaaaaa",
      "aaaaaaaaaaaaaaaa",
      "aaaaaaaaaaaaaaaa",
      "aaaaaaaaaaaaaaaa",
      "aaaaaaaaaaaaaaaa",
      "aaaaaaaaaaaaaaaa",
      "aaaaaaaaaaaaaaaa",
      "aaaaaaaaaaaaaaaa",
      "aaaaaaaaaaaaaaaa",
      "aaaaaaaaaaaaaaaa",
      "aaaaaaaaaaaaaaaa",
      "aaaaaaaaaaaaaaaa"
    ],
    [
      "aaaaaaaaaaaaaaaa",
      "aaaaaaaaaaaaaaaa",
      "aaaaaaaaaaaaaaaa",
      "aaaaaaaaaaaaaaaa",
      "aaaaGbbbaaaaaaaa",
      "aaaaaabbaaaaaaaa",
      "aaaaaaaaaaaaaaaa",
      "aaaaaaaaaaaaaaaa",
      "aaaaaaaaaaaaaaaa",
      "aaaaaaaaaaaaaaaa",
      "aaaaaaaaaaaaaaaa",
      "aaaaaaaaaaaaaaaa",
      "aaaaaaaaaaaaaaaa",
      "aaaaaaaaaaaaaaaa",
      "aaaaaaaaaaaaaaaa",
      "aaaaaaaaaaaaaaaa"
    ],
    [
      "GGGGGGGGGGcGccGc",
      "GGGGGGGGGGGccGcc",
      "GGGGGGGGGGccGdGc",
      "GGGGbbbbGGGcGGbb",
      "GGGGeeffGGccGGbg",
      "GGGGGbffGGcGGGbg",
      "GGGGbbbbGGGcGGbb",
      "GGGGGGbGGGccGdGc",
      "GGGGGGGGGGGcGGcc",
      "GGGGGGGGGcccccGc",
      "GGGGaGGGGGccGGGc",
      "GGGGaaGGGGGcGGGG",
      "GGGGaaaGGGcGGGGc",
      "GGGGGGGGGGGGGaGG",
      "GGGGGGGGGGGcGGGG",
      "GGGGGGGGGcGGGGGG"
    ],
    [
      "  hhhhh h  h    ",
      "  h h  h        ",
      "h  iiiiii    dj ",
      "hhki   kih   jlm",
      "  hienopi     q ",
      "hh ir  oi     q ",
      " hki   ki h  jls",
      "hhhih   i    dj ",
      "hh i    i   hi  ",
      "h  i    i    t  ",
      " h iu   i    ih ",
      " h iww  i   hix ",
      "   iwwwhih   iy ",
      "AhBiiiiii   hdii",
      "h    h h     h h",
      "hhh   h h   h h "
    ],
    [
      "                ",
      "                ",
      "             d  ",
      "  k    k      lC",
      "    eD e      q ",
      "       E      q ",
      "  k    k      lF",
      "             d  ",
      "                ",
      "                ",
      "                ",
      "                ",
      "    ww          ",
      "I            J  ",
      "                ",
      "                "
    ],
    [
      "                ",
      "                ",
      "             d  ",
      "  k    k      ll",
      "    KKKK      q ",
      "    L         q ",
      "  k    k      ll",
      "             d  ",
      "                ",
      "                ",
      "                ",
      "                ",
      "                ",
      "                ",
      "                ",
      "                "
    ],
    [
      "                ",
      "               M",
      "             d M",
      " NNNNNNNNNNNNNOO",
      " NNNNNNNNNNNNNOP",
      " NNNNNNNNNNNNNOP",
      " NNNNNNNNNNNNNOO",
      "             d M",
      "               M",
      "                ",
      "                ",
      "                ",
      "                ",
      "                ",
      "                ",
      "                "
    ],
    [
      "                ",
      "          MMQRR ",
      "          MMQRR ",
      "          MMSTT ",
      "          MMSTT ",
      "          MMSTT ",
      "          MMSTT ",
      "          MMQRR ",
      "          MMQRR ",
      "                ",
      "                ",
      "                ",
      "                ",
      "                ",
      "                ",
      "                "
    ]
  ]
}