{
  "name": "cabin_2",
  "refpalette": "c70cities:cabin_2_palette",
  "xsize": 16,
  "zsize": 16,
  "slices": [
    [
      "vvvvvvvvvvvvvvvv",
      "vvvvvvvvvvvvvvvv",
      "vvvvvvvvvvvvvvvv",
      "vvvvvvvvvvvvvvvv",
      "vvvvvvvvvvvvvvvv",
      "vvvvvvvvvvvvvvvv",
      "vvvvvvvvvvvvvvvv",
      "vvvvvvvvvvvvvvvv",
      "vvvvvvvvvvvvvvvv",
      "vvvvvvvvvvvvvvvv",
      "vvvvvvvvvvvvvvvv",
      "vvvvvvvvvvvvvvvv",
      "vvvvvvvvvvvvvvvv",
      "vvvvvvvvvvvvvvvv",
      "vvvvvvvvvvvvvvvv",
      "vvvvvvvvvvvvvvvv"
    ],
    [
      "vvvvvvvvvvvvvvvv",
      "vvvvvvvvvvvvvvvv",
      "vvvvvvvvvvvvvvvv",
      "vvvvvvvvvvvvvvvv",
      "vvvvvvvvvvvvvvvv",
      "vvvvvvvvvvvvvvvv",
      "vvvvvvvvvvvvvvvv",
      "vvvvvvvvvvvvvvvv",
      "vvvvvvvvvvvvvvvv",
      "vvvvvvvvvvvvvvvv",
      "vvvvvvvvvvvvvvvv",
      "vvvvvvvvvvvvvvvv",
      "vvvvvvvvvvvvvvvv",
      "vvvvvvvvvvvvvvvv",
      "vvvvvvvvvvvvvvvv",
      "vvvvvvvvvvvvvvvv"
    ],
    [
      "avbvvabavvbvbvvv",
      "vGGGGGGGGGGGGGGa",
      "vGGGGGGGGGGGGGGb",
      "vGGGGGGGGGGGGGGv",
      "bcccccccGGGGGGGv",
      "bdcecccccccccccb",
      "vcdccccccccccccb",
      "accccdcccccccccv",
      "vdcdcccccccccccv",
      "vccccdcccccccccv",
      "vcccccccccccccca",
      "bGGcccccccccccca",
      "vGGGcccccccccccb",
      "bGGGcccccccccccv",
      "aGGGcccccccccccv",
      "vvvvbvabbvvbvavb"
    ],
    [
      "f              f",
      "                ",
      "     g          ",
      "          g     ",
      "                ",
      "   h            ",
      "                ",
      "       i  j i   ",
      "       kllllk   ",
      "       m   nl   ",
      "       o   pl   ",
      "  q    l   rl   ",
      " s     lt  ul   ",
      " qq    lwxllk   ",
      "  sq   kllki    ",
      "f              y"
    ],
    [
      "                ",
      "                ",
      "     ~          ",
      "          ~     ",
      "                ",
      "                ",
      "                ",
      "       i  A i   ",
      "       kllllk   ",
      "       B    l   ",
      "       C    D   ",
      "       l    D   ",
      "       D    l   ",
      "       D  llk   ",
      "       kllki    ",
      "                "
    ],
    [
      "                ",
      "                ",
      "                ",
      "                ",
      "                ",
      "                ",
      "                ",
      "       i  A i   ",
      "       kllllk   ",
      "       l    l   ",
      "       l  E l   ",
      "       l    l   ",
      "       l    l   ",
      "       l  llk   ",
      "       kllki    ",
      "                "
    ],
    [
      "                ",
      "                ",
      "                ",
      "                ",
      "                ",
      "                ",
      "      FIIIFFII  ",
      "      IIFIIIII  ",
      "      IIIIIIIF  ",
      "      FIFIIIFI  ",
      "      FIIJFIII  ",
      "      IFIJJIII  ",
      "      IIJIIFII  ",
      "      IIIIFIIF  ",
      "      IFFIIIII  ",
      "      IIIIIIF   "
    ]
  ]
}