{
  "name": "cabin_5",
  "refpalette": "c70cities:cabin_5_palette",
  "xsize": 16,
  "zsize": 16,
  "slices": [
    [
      "aaaaaaaaaaaaaaaa",
      "aaaaaaaaaaaaaaaa",
      "aaaaaaaaaaaaaaaa",
      "aaaaaaaaaaaaaaaa",
      "aaaaaaaaaaaaaaaa",
      "aaaaaaaaaaaaaaaa",
      "aaaaaaaaaaaaaaaa",
      "aaaaaaaaaaaaaaaa",
      "aaaaaaaaaaaaaaaa",
      "aaaaaaaaaaaaaaaa",
      "aaaaaaaaaaaaaaaa",
      "aaaaaaaaaaaaaaaa",
      "aaaaaaaaaaaaaaaa",
      "aaaaaaaaaaaaaaaa",
      "aaaaaaaaaaaaaaaa",
      "aaaaaaaaaaaaaaaa"
    ],
    [
      "aaaaaaaaaaaaaaGG",
      "aaaaaaaaaaaaaaaG",
      "aaaaaaaaaaaaaaaG",
      "aaaaaaaaaaaaaaaa",
      "aaaaaaaaaaaaaaaa",
      "aaaaaaaaaaaaaaaa",
      "aaaaaaaaaaaaaaaa",
      "aaaaaaaaaaaaaaaa",
      "aaaaaaaaaaaaaaaa",
      "aaaaaaaaaaaaaaaa",
      "aaaaaaaaaaaaaaaa",
      "aaaaaaaaaaaaaaaa",
      "aaaaaaaaaaaaaaaa",
      "aaaaaaaaaaaaaaaa",
      "aaaaaaaaaaaaaaGa",
      "aaaaaaaaaaaaaGGG"
    ],
    [
      "GGGGGGGGGGGGGG  ",
      "GGGbGGbcGGGGGGG ",
      "GGbcbGGGGbbGGGG ",
      "GGbbbbcGbbGGcGGG",
      "GGcbbbbbbbbGGGGG",
      "GbGbbbbbbcGaGGGG",
      "GGGGbbddeeecGbGG",
      "GGGbbbdddeebcGGG",
      "GcGcfbddeeebGGGG",
      "GfcGffdeeeebGGGG",
      "fGffGcdeeeecGGGG",
      "GGcGGbedeeeGbGGG",
      "GGGGGGeeeeeGbGGG",
      "GGGGcaGGbcGaGGGG",
      "GGGcGGGGGGGGGG G",
      "GGGGGGcGGGGGG   "
    ],
    [
      "                ",
      "                ",
      "   g      h  i  ",
      "  ij k! ljj     ",
      "   ljjijmno     ",
      " i  mpoj jiq    ",
      "    jlrssttj i  ",
      "    ujrwkxtu i  ",
      "      r y rh    ",
      "      A  Btq    ",
      "     Cl  Dth    ",
      "     jrkhCE m   ",
      "      EE tEij   ",
      "    iF  juIF    ",
      " i              ",
      "      j    i    "
    ],
    [
      "                ",
      "                ",
      "   g            ",
      "                ",
      "                ",
      "     p     p    ",
      "      JJk sk    ",
      "      KL  r     ",
      "      r   E     ",
      "      M   rq    ",
      "         Nt     ",
      "      K   r     ",
      "      ttKkE     ",
      "     F     F    ",
      "                ",
      "                "
    ],
    [
      "                ",
      "                ",
      "   L            ",
      "                ",
      "                ",
      "     pk   kp    ",
      "     krsJkJk    ",
      "     krOOPrk    ",
      "      rOOkrk    ",
      "      rOO tq    ",
      "       OO r     ",
      "      rPO t     ",
      "      tJtJt     ",
      "     q   kkF    ",
      "                ",
      "                "
    ],
    [
      "                ",
      "                ",
      "                ",
      "                ",
      "    nnnn  nnn   ",
      "     pQQQQQpR   ",
      "     ShCu wT    ",
      "     SUCV lT    ",
      "     Sh C  T    ",
      "     SUoV  T    ",
      "     SW h  T    ",
      "     TkC  lX    ",
      "     TWy xyX    ",
      "    YqZZZZ0FY   ",
      "    121221111   ",
      "                "
    ],
    [
      "                ",
      "                ",
      "                ",
      "                ",
      "                ",
      "    nNNNNkNNn   ",
      "    Rsk   ktR   ",
      "     r          ",
      "     r     t    ",
      "     ph    q    ",
      "     r     t    ",
      "     r     t    ",
      "    3rk   kEY   ",
      "    244444451   ",
      "                ",
      "                "
    ],
    [
      "                ",
      "                ",
      "                ",
      "                ",
      "                ",
      "                ",
      "    nN NNNBB6   ",
      "    kJ    ktR   ",
      "     r     E    ",
      "     p     F    ",
      "     r    k     ",
      "    3r    kt    ",
      "    174455542   ",
      "                ",
      "                ",
      "                "
    ],
    [
      "                ",
      "                ",
      "                ",
      "                ",
      "                ",
      "                ",
      "                ",
      "    nNNk NNB6   ",
      "    Rr    kE8   ",
      "     p     F    ",
      "    Ytk   kEY   ",
      "    244 77441   ",
      "                ",
      "                ",
      "                ",
      "                "
    ],
    [
      "                ",
      "                ",
      "                ",
      "                ",
      "                ",
      "                ",
      "                ",
      "                ",
      "    nNk   BB6   ",
      "    9p    kF@   ",
      "    2777  452   ",
      "                ",
      "                ",
      "                ",
      "                ",
      "                "
    ],
    [
      "                ",
      "                ",
      "                ",
      "                ",
      "                ",
      "                ",
      "                ",
      "                ",
      "                ",
      "    mCC  ##$m   ",
      "                ",
      "                ",
      "                ",
      "                ",
      "                ",
      "                "
    ]
  ]
}