{
  "name": "cabin_3_1",
  "refpalette": "c70cities:cabin_3_1_palette",
  "xsize": 16,
  "zsize": 16,
  "slices": [
    [
      "aaaaaaaaaaaaaaaa",
      "aaaaaaaaaaaaaaaa",
      "aaaaaaaaaaaaaaaa",
      "aaaaaaaaaaaaaaaa",
      "aaaaaaaaaaaaaaaa",
      "aaaaaaaaaaaaaaaa",
      "aaaaaaaaaaaaaaaa",
      "aaaaaaaaaaaaaaaa",
      "aaaaaaaaaaaaaaaa",
      "aaaaaaaaaaaaaaaa",
      "aaaaaaaaaaaaaaaa",
      "aaaaaaaaaaaaaaaa",
      "aaaaaaaaaaaaaaaa",
      "aaaaaaaaaaaaaaaa",
      "aaaaaaaaaaaaaaaa",
      "aaaaaaaaaaaaaaaa"
    ],
    [
      "aaaaaaaaaaaaaaaa",
      "aaaaaaaaaaaaaaaa",
      "aaaaaaaaaaaaaaaa",
      "aaaaaaaaaaaaaaaa",
      "aaaaaaaaaaaaaaaa",
      "aaaaaaaaaaaaaaaa",
      "aaaaaaaaaaaaaaaa",
      "aaaaaaaaaaaaaaaa",
      "aaaaaaaaaaaaaaaa",
      "aaaaaaaaaaaaaaaa",
      "aaaaaaaaaaaaaaaa",
      "aaaaaaaaaaaaaaaa",
      "aaaaaaaaaaaaaaaa",
      "aaaaaaaaaaaaaaaa",
      "aaaaaaaaaaaaaaaa",
      "aaaaaaaaaaaaaaaa"
    ],
    [
      "GbGGGGGGGGGGGGGG",
      "bGGGGGGGGGGGGGGG",
      "bGcGGGGcGGGGcGGG",
      "ddddddddddddGGGG",
      "eeeeeeeeeeedGGGG",
      "eeeeeeeeeeedGGGG",
      "ddddddddddddGGGG",
      "bGcaaaGcGGGGcGGG",
      "GbGGGGGGGGGGGGGG",
      "bbbGGGGGGGGGGGGG",
      "bbGGGGGGGGGGGGGG",
      "bGGGGGGGGGGGGGGG",
      "bGGGGGGGGGGGGGGG",
      "GGaGGGGaGGGGaGGG",
      "GGGGGGGGGGGGGGGG",
      "GGGGGGGGGGGGGGGG"
    ],
    [
      "   f       f  ff",
      "   fff  ff ff  f",
      " gcggggcggggc   ",
      "hijiiiikiiii  ff",
      "        lmni   f",
      "        lmnif   ",
      "oipiiiiqiiii  ff",
      " gcrsstcuwx c  f",
      "  y         y   ",
      "  A         y ff",
      "  y         y f ",
      " By         y   ",
      " Cy         y   ",
      "yycyyyycyyyyc  f",
      " fff  f f  f f  ",
      "ff     f      ff"
    ],
    [
      "                ",
      "         DDEFF  ",
      "  c    c DDEFF  ",
      "IiJiKKi LLLMFF  ",
      "         NNMFF  ",
      "         NNMFF  ",
      "Oi iKKiPLLLMFF  ",
      "  c    c DDEFF  ",
      "         DDEFF  ",
      "                ",
      "                ",
      "                ",
      "                ",
      "  Q    Q    Q   ",
      "                ",
      "                "
    ],
    [
      "                ",
      "    DDEFF       ",
      "  c DDEFF       ",
      "iiJLRRMSS       ",
      "    NNMSS       ",
      "    NNMSS       ",
      "iiPLTTMSS       ",
      "  c DDEFF       ",
      "    DDEFF       ",
      "                ",
      "                ",
      "                ",
      "                ",
      "                ",
      "                ",
      "                "
    ],
    [
      "                ",
      "DEFF            ",
      "DEFF            ",
      "LMSS            ",
      "NMSS            ",
      "NMSS            ",
      "LMSS            ",
      "DEFF            ",
      "DEFF            ",
      "                ",
      "                ",
      "                ",
      "                ",
      "                ",
      "                ",
      "                "
    ]
  ]
}