{
  "name": "cabin_4_0",
  "refpalette": "c70cities:cabin_4_0_palette",
  "xsize": 16,
  "zsize": 16,
  "slices": [
    [
      "aaaaaaaaaaaaaaaa",
      "aaaaaaaaaaaaaaaa",
      "aaaaaaaaaaaaaaaa",
      "aaaaaaaaaaaaaaaa",
      "aaaaaaaaaaaaaaaa",
      "aaaaaaaaaaaaaaaa",
      "aaaaaaaaaaaaaaaa",
      "aaaaaaaaaaaaaaaa",
      "aaaaaaaaaaaaaaaa",
      "aaaaaaaaaaaaaaaa",
      "aaaaaaaaaaaaaaaa",
      "aaaaaaaaaaaaaaaa",
      "aaaaaaaaaaaaaaaa",
      "aaaaaaaaaaaaaaaa",
      "aaaaaaaaaaaaaaaa",
      "aaaaaaaaaaaaaaaa"
    ],
    [
      "aaaaaaaaaaaaaaaa",
      "aaaaaaaaaaaaaaaa",
      "aaaaaaaaaaaaaaaa",
      "aaaaaaaaaaaaaaaa",
      "aaaaaaaaaaaaaaaa",
      "aaaaaaaaaaaaaaaa",
      "aaaaaaaaaaaaaaaa",
      "aaaaaaaaaaaaaaaa",
      "aaaaaaaaaaaaaaaa",
      "aaaaaaaaaaaaaaaa",
      "aaaaaaaaaaaaaaaa",
      "aaaaaaaaaaaaaaaa",
      "aaaaaaaaaaaaaaaa",
      "aaaaaaaaaaaaaaaa",
      "aaaaaaaaaaaaaaaa",
      "aaaaaaaaaaaaaaaa"
    ],
    [
      "GGGGGGGGGGGGGGGG",
      "GGGGbGbGbGGGGGGG",
      "GGbbbbbbGGGGGGGG",
      "GGbbGGbbbGGGGGGG",
      "GbbGvvvvvvvvGGGG",
      "GGbGvvvvvvvvGGGG",
      "GbGGvccccccvGGGG",
      "GbbGvccccccvGGGG",
      "GbbGvccccccvGGGG",
      "GbGGvccccccvGGGG",
      "bGbGvccccccvGGGG",
      "GbbGvGcccccvGGGG",
      "bbbbvccccccvGGGG",
      "GbGbvccccccvGGGG",
      "GGbbvGcccccvGGGG",
      "GGGbvvvvvvvvGGGG"
    ],
    [
      " de        e    ",
      "e             d ",
      "d          e f  ",
      "          e   d ",
      "   ghvhhhhvhg   ",
      "   dvvvvvvvvgd  ",
      "   gviiiiiivg  f",
      "   gvjk  kjv d e",
      "    v l  l vg   ",
      "   gv      vg d ",
      "   gvvm  mvvd   ",
      "   gvn    ov  f ",
      "    p     qvg   ",
      "    r     qvge  ",
      "    vn    sve   ",
      " ttuvvm  mvvg f "
    ],
    [
      "                ",
      "                ",
      "             ~  ",
      "                ",
      "                ",
      "     h    h     ",
      "    hvhhhhvh   ~",
      "    vwwwwwwv    ",
      "    v      v    ",
      "    v      v    ",
      "    vvm  mvv    ",
      "    vn     v  ~ ",
      "    x      y    ",
      "    A      y    ",
      "    vn     v    ",
      "    vvm  mvv  ~ "
    ],
    [
      "                ",
      "                ",
      "                ",
      "                ",
      "                ",
      "                ",
      "                ",
      "     h    h     ",
      "    hvhhhhvh    ",
      "    vwwwwwwv    ",
      "    vvm  mvv    ",
      "    v      v    ",
      "    v      v    ",
      "    v      v    ",
      "    v      v    ",
      "    vvm  mvv    "
    ],
    [
      "                ",
      "                ",
      "                ",
      "                ",
      "                ",
      "                ",
      "                ",
      "                ",
      "                ",
      "     h    h     ",
      "    hvhhhhvh    ",
      "    vwwwwwwv    ",
      "    v      v    ",
      "    v      v    ",
      "    v      v    ",
      "    vvvvvvvv    "
    ],
    [
      "                ",
      "                ",
      "                ",
      "                ",
      "                ",
      "                ",
      "                ",
      "                ",
      "                ",
      "                ",
      "                ",
      "     h    h     ",
      "    hvhhhhvh    ",
      "    vwwwwwwv    ",
      "    vBwwwwBv    ",
      "    vvCCCCvv    "
    ],
    [
      "                ",
      "                ",
      "                ",
      "                ",
      "                ",
      "                ",
      "                ",
      "                ",
      "                ",
      "                ",
      "                ",
      "                ",
      "                ",
      "     h    h     ",
      "    hvhhhhvh    ",
      "    vvhhhhvv    "
    ]
  ]
}