{
  "name": "cabin_4_0",
  "refpalette": "c70cities:cabin_4_0_palette",
  "xsize": 16,
  "zsize": 16,
  "slices": [
    [
      "aaaaaaaaaaaaaaaa",
      "aaaaaaaaaaaaaaaa",
      "aaaaaaaaaaaaaaaa",
      "aaaaaaaaaaaaaaaa",
      "aaaaaaaaaaaaaaaa",
      "aaaaaaaaaaaaaaaa",
      "aaaaaaaaaaaaaaaa",
      "aaaaaaaaaaaaaaaa",
      "aaaaaaaaaaaaaaaa",
      "aaaaaaaaaaaaaaaa",
      "aaaaaaaaaaaaaaaa",
      "aaaaaaaaaaaaaaaa",
      "aaaaaaaaaaaaaaaa",
      "aaaaaaaaaaaaaaaa",
      "aaaaaaaaaaaaaaaa",
      "aaaaaaaaaaaaaaaa"
    ],
    [
      "aaaaaaaaaaaaaaaa",
      "aaaaaaaaaaaaaaaa",
      "aaaaaaaaaaaaaaaa",
      "aaaaaaaaaaaaaaaa",
      "aaaaaaaaaaaaaaaa",
      "aaaaaaaaaaaaaaaa",
      "aaaaaaaaaaaaaaaa",
      "aaaaaaaaaaaaaaaa",
      "aaaaaaaaaaaaaaaa",
      "aaaaaaaaaaaaaaaa",
      "aaaaaaaaaaaaaaaa",
      "aaaaaaaaaaaaaaaa",
      "aaaaaaaaaaaaaaaa",
      "aaaaaaaaaaaaaaaa",
      "aaaaaaaaaaaaaaaa",
      "aaaaaaaaaaaaaaaa"
    ],
    [
      "GGGGGGGGGGGGGGGG",
      "GGGGbGbGbGGGGGGG",
      "GGbbbbbbGGGGGGGG",
      "GGbbGGbbbGGGGGGG",
      "GbbGvvvvvvvvGGGG",
      "GGbGvvvvvvvvGGGG",
      "GbGGvccccccvGGGG",
      "GbbGvccccccvGGGG",
      "GbbGvccccccvGGGG",
      "GbGGvccccccvGGGG",
      "bGbGvccccccvGGGG",
      "GbbGvGcccccvGGGG",
      "bbbbvccccccvGGGG",
      "GbGbvccccccvGGGG",
      "GGbbvGcccccvGGGG",
      "GGGbvvvvvvvvGGGG"
    ],
    [
      "                ",
      "                ",
      "             d  ",
      "                ",
      "   efvffffvfe   ",
      "   gvvvvvvvve   ",
      "   evhhhhhhve  d",
      "   evij  jiv    ",
      "    v k  k ve   ",
      "   ev     lve   ",
      "   evvm  mvv    ",
      "   evn    ov  d ",
      "    p     qve   ",
      "    r     sve   ",
      "    vn    tv    ",
      " uuwvvm  mvve d "
    ],
    [
      "                ",
      "                ",
      "             ~  ",
      "                ",
      "                ",
      "     f    f     ",
      "    fvffffvf   ~",
      "    vxxxxxxv    ",
      "    v      v    ",
      "    v      v    ",
      "    vvm  mvv    ",
      "    vn     v  ~ ",
      "    y      A    ",
      "    B      A    ",
      "    vn     v    ",
      "    vvm  mvv  ~ "
    ],
    [
      "                ",
      "                ",
      "                ",
      "                ",
      "                ",
      "                ",
      "                ",
      "     f    f     ",
      "    fvffffvf    ",
      "    vxxxxxxv    ",
      "    vvm  mvv    ",
      "    v      v    ",
      "    v      v    ",
      "    v      v    ",
      "    v      v    ",
      "    vvm  mvv    "
    ],
    [
      "                ",
      "                ",
      "                ",
      "                ",
      "                ",
      "                ",
      "                ",
      "                ",
      "                ",
      "     f    f     ",
      "    fvffffvf    ",
      "    vxxxxxxv    ",
      "    v      v    ",
      "    v      v    ",
      "    v      v    ",
      "    vvvvvvvv    "
    ],
    [
      "                ",
      "                ",
      "                ",
      "                ",
      "                ",
      "                ",
      "                ",
      "                ",
      "                ",
      "                ",
      "                ",
      "     f    f     ",
      "    fvffffvf    ",
      "    vxxxxxxv    ",
      "    vCxxxxCv    ",
      "    vvDDDDvv    "
    ],
    [
      "                ",
      "                ",
      "                ",
      "                ",
      "                ",
      "                ",
      "                ",
      "                ",
      "                ",
      "                ",
      "                ",
      "                ",
      "                ",
      "     f    f     ",
      "    fvffffvf    ",
      "    vvffffvv    "
    ]
  ]
}