{
  "name": "cabin_4_1",
  "refpalette": "c70cities:cabin_4_1_palette",
  "xsize": 16,
  "zsize": 16,
  "slices": [
    [
      "aaaaaaaaaaaaaaaa",
      "aaaaaaaaaaaaaaaa",
      "aaaaaaaaaaaaaaaa",
      "aaaaaaaaaaaaaaaa",
      "aaaaaaaaaaaaaaaa",
      "aaaaaaaaaaaaaaaa",
      "aaaaaaaaaaaaaaaa",
      "aaaaaaaaaaaaaaaa",
      "aaaaaaaaaaaaaaaa",
      "aaaaaaaaaaaaaaaa",
      "aaaaaaaaaaaaaaaa",
      "aaaaaaaaaaaaaaaa",
      "aaaaaaaaaaaaaaaa",
      "aaaaaaaaaaaaaaaa",
      "aaaaaaaaaaaaaaaa",
      "aaaaaaaaaaaaaaaa"
    ],
    [
      "aaaaaaaaaaaaaaaa",
      "aaaaaaaaaaaaaaaa",
      "aaaaaaaaaaaaaaaa",
      "aaaaaaaaaaaaaaaa",
      "aaaaaaaaaaaaaaaa",
      "aaaaaaaaaaaaaaaa",
      "aaaaaaaaaaaaaaaa",
      "aaaaaaaaaaaaaaaa",
      "aaaaaaaaaaaaaaaa",
      "aaaaaaaaaaaaaaaa",
      "aaaaaaaaaaaaaaaa",
      "aaaaaaaaaaaaaaaa",
      "aaaaaaaaaaaaaaaa",
      "aaaaaaaaaaaaaaaa",
      "aaaaaaaaaaaaaaaa",
      "aaaaaaaaaaaaaaaa"
    ],
    [
      "GGGbcdeeeedcGGGG",
      "GGGbcdeeeedcGGGG",
      "GGGbcdeeeedcGGGG",
      "GGGbcdeeeedcGGGG",
      "GGGbcdeeeedcGGGG",
      "GGGbcdeeeedcGGGG",
      "GGGbcdeeeedcGGGG",
      "GGGbcdeeeedcGGGG",
      "GGGbcdeeeedcGGGG",
      "GGGbcdeeeedcGGGG",
      "GGGbcddddddcGGGG",
      "GGGGccccccccGGGG",
      "GGGGGGGGGGGGGGGG",
      "GGGGGGGGGGGGGGGG",
      "GGGGGGGGGGGGGGGG",
      "GGGGGGGGGGGGGGGG"
    ],
    [
      " fg  h   ijf    ",
      " fg  k   ljf    ",
      " fg mk   njf    ",
      " fg ok   pjf    ",
      " fg  k   pjf   q",
      " fg  h  rsjf    ",
      " fg  k  tujf    ",
      " fg mk   wjf    ",
      " fg ok   wjf q  ",
      " fg  k    jf    ",
      " fg  xkkkkjf    ",
      " fffffffffff    ",
      "                ",
      "     q  q     q ",
      "  q        q    ",
      "                "
    ],
    [
      "     h   yj     ",
      "     k    k     ",
      "     k    k     ",
      "     k    k     ",
      "     k    k    ~",
      "     h    j     ",
      "     k   Ak     ",
      "     k    k     ",
      "     k    k  ~  ",
      "     k    k     ",
      "     xkkkkj     ",
      "                ",
      "                ",
      "     ~  ~     ~ ",
      "  ~        ~    ",
      "                "
    ],
    [
      "     h    j     ",
      "     k    j     ",
      "     k    j     ",
      "     k    j     ",
      "     k    j     ",
      "     h    j     ",
      "     k    j     ",
      "     k    j     ",
      "     k    j     ",
      "     k    j     ",
      "     xkkkkj     ",
      "                ",
      "                ",
      "                ",
      "                ",
      "                "
    ],
    [
      "     BCCCCD     ",
      "     BCCCCD     ",
      "     BCCCCD     ",
      "     BCCCCD     ",
      "     BCCCCD     ",
      "     BCCCCD     ",
      "     BCCCCD     ",
      "     BCCCCD     ",
      "     BCCCCD     ",
      "     BCCCCD     ",
      "     EFFFFI     ",
      "                ",
      "                ",
      "                ",
      "                ",
      "                "
    ],
    [
      "    JjKKKKjJ    ",
      "    JjKKKKjJ    ",
      "    JjKKKKjJ    ",
      "    JjKKKKjJ    ",
      "    JjKKKKjJ    ",
      "    JjKKKKjJ    ",
      "    JjKKKKjJ    ",
      "    JjKKKKjJ    ",
      "    JjLLLLjJ    ",
      "    JjGGGGjJ    ",
      "    JjjjjjjJ    ",
      "    JJJJJJJJ    ",
      "                ",
      "                ",
      "                ",
      "                "
    ],
    [
      "     f    f     ",
      "     f    f     ",
      "     f    f     ",
      "     f    f     ",
      "     f    f     ",
      "     f    f     ",
      "     f    f     ",
      "     f    f     ",
      "     f    f     ",
      "     fggggf     ",
      "     ffffff     ",
      "                ",
      "                ",
      "                ",
      "                ",
      "                "
    ]
  ]
}