{
  "name": "cabin_2",
  "refpalette": "c70cities:cabin_2_palette",
  "xsize": 16,
  "zsize": 16,
  "slices": [
    [
      "vvvvvvvvvvvvvvvv",
      "vvvvvvvvvvvvvvvv",
      "vvvvvvvvvvvvvvvv",
      "vvvvvvvvvvvvvvvv",
      "vvvvvvvvvvvvvvvv",
      "vvvvvvvvvvvvvvvv",
      "vvvvvvvvvvvvvvvv",
      "vvvvvvvvvvvvvvvv",
      "vvvvvvvvvvvvvvvv",
      "vvvvvvvvvvvvvvvv",
      "vvvvvvvvvvvvvvvv",
      "vvvvvvvvvvvvvvvv",
      "vvvvvvvvvvvvvvvv",
      "vvvvvvvvvvvvvvvv",
      "vvvvvvvvvvvvvvvv",
      "vvvvvvvvvvvvvvvv"
    ],
    [
      "vvvvvvvvvvvvvvvv",
      "vvvvvvvvvvvvvvvv",
      "vvvvvvvvvvvvvvvv",
      "vvvvvvvvvvvvvvvv",
      "vvvvvvvvvvvvvvvv",
      "vvvvvvvvvvvvvvvv",
      "vvvvvvvvvvvvvvvv",
      "vvvvvvvvvvvvvvvv",
      "vvvvvvvvvvvvvvvv",
      "vvvvvvvvvvvvvvvv",
      "vvvvvvvvvvvvvvvv",
      "vvvvvvvvvvvvvvvv",
      "vvvvvvvvvvvvvvvv",
      "vvvvvvvvvvvvvvvv",
      "vvvvvvvvvvvvvvvv",
      "vvvvvvvvvvvvvvvv"
    ],
    [
      "avbvvabavvbvbvvv",
      "vGGGGGGGGGGGGGGa",
      "vGGGGGGGGGGGGGGb",
      "vGGGGGGGGGGGGGGv",
      "bcccccccGGGGGGGv",
      "bdcecccccccccccb",
      "vcdccccccccccccb",
      "accccdcccccccccv",
      "vdcdcccccccccccv",
      "vccccdcccccccccv",
      "vcccccccccccccca",
      "bGGcccccccccccca",
      "vGGGcccccccccccb",
      "bGGGcccccccccccv",
      "aGGGcccccccccccv",
      "vvvvbvabbvvbvavb"
    ],
    [
      "f              f",
      " gg gg gh gg gh ",
      "  gghi g  g h g ",
      " g h g   gi  h  ",
      "        g h     ",
      "   j            ",
      "                ",
      "       k  l k   ",
      "       mnnnnm   ",
      "       o   pn   ",
      "       q   rn   ",
      " gs    n   tn   ",
      " u g   nw  xn   ",
      " ss    nyAnnm   ",
      " hus   mnnmk    ",
      "f              B"
    ],
    [
      "                ",
      "                ",
      "     ~          ",
      "          ~     ",
      "                ",
      "                ",
      "                ",
      "       k  C k   ",
      "       mnnnnm   ",
      "       D    n   ",
      "       E    F   ",
      "       n    F   ",
      "       F    n   ",
      "       F  nnm   ",
      "       mnnmk    ",
      "                "
    ],
    [
      "                ",
      "                ",
      "                ",
      "                ",
      "                ",
      "                ",
      "                ",
      "       k  C k   ",
      "       mnnnnm   ",
      "       n    n   ",
      "       n  I n   ",
      "       n    n   ",
      "       n    n   ",
      "       n  nnm   ",
      "       mnnmk    ",
      "                "
    ],
    [
      "                ",
      "                ",
      "                ",
      "                ",
      "                ",
      "                ",
      "      JKKKJJKK  ",
      "      KKJKKKKK  ",
      "      KKKKKKKJ  ",
      "      JKJKKKJK  ",
      "      JKKLJKKK  ",
      "      KJKLLKKK  ",
      "      KKLKKJKK  ",
      "      KKKKJKKJ  ",
      "      KJJKKKKK  ",
      "      KKKKKKJ   "
    ]
  ]
}