{
  "name": "cabin_6_1",
  "refpalette": "c70cities:cabin_6_1_palette",
  "xsize": 16,
  "zsize": 16,
  "slices": [
    [
      "aaaaaaaaaaaaaaaa",
      "aaaaaaaaaaaaaaaa",
      "aaaaaaaaaaaaaaaa",
      "aaaaaaaaaaaaaaaa",
      "aaaaaaaaaaaaaaaa",
      "aaaaaaaaaaaaaaaa",
      "aaaaaaaaaaaaaaaa",
      "aaaaaaaaaaaaaaaa",
      "aaaaaaaaaaaaaaaa",
      "aaaaaaaaaaaaaaaa",
      "aaaaaaaaaaaaaaaa",
      "aaaaaaaaaaaaaaaa",
      "aaaaaaaaaaaaaaaa",
      "aaaaaaaaaaaaaaaa",
      "aaaaaaaaaaaaaaaa",
      "aaaaaaaaaaaaaaaa"
    ],
    [
      "Gaaaaaaaaaaaaaaa",
      "Gaaaaaaaaaaaaaaa",
      "Gaaaaaaaaaaaaaaa",
      "GGaaaaaaaaaaaaaG",
      "GGaaaaaaaaaaaaaG",
      "GGaaaaaaaaaaaaaG",
      "GGGaaaaaaaaaaaGG",
      "GGGaaaaaaaaaaaGG",
      "GGGGaaaaaaaaaGGG",
      "GGGGGGaaaaaaGGGG",
      "GGGGGGGGGGGGGGGG",
      "GGGGGGGGGGGGGGGG",
      "GGGGGGGGGGGGGGGG",
      "GGGGGGGGGGGGGGGG",
      "GGGGGGGGGGGGGGGG",
      "GGGGGGGGGGGGGGGG"
    ],
    [
      " GGaaaaaaaaaaaGG",
      " GGaaaaaaaaaaaGG",
      " GGaaaaaaaaaGGGG",
      "  GGaaaaaaaaGGG ",
      "  GGGaaaaaaGGGG ",
      "  GGGGbGGbGGGGG ",
      "   GGGGGGGGGGG  ",
      "   GGGGGGGGGGG  ",
      "    GGGGGGGGG   ",
      "      GGGGGG    ",
      "                ",
      "                ",
      "                ",
      "                ",
      "                ",
      "                "
    ],
    [
      "   GaaaaaaaaGG  ",
      "   GaaaaaaaGGG  ",
      "   GGaaaaaaG    ",
      "    GGaaaaGG    ",
      "     GGGGGG     ",
      "      c  c      ",
      "                ",
      "                ",
      "                ",
      "                ",
      "                ",
      "                ",
      "                ",
      "                ",
      "                ",
      "                "
    ],
    [
      "    GGGGGGGG    ",
      "    GGGGGGG     ",
      "     GGGGGG     ",
      "      GGGG      ",
      "                ",
      "      c  c      ",
      "                ",
      "                ",
      "                ",
      "                ",
      "                ",
      "                ",
      "                ",
      "                ",
      "                ",
      "                "
    ],
    [
      "                ",
      "                ",
      "                ",
      "                ",
      "                ",
      "      c  c      ",
      "                ",
      "                ",
      "                ",
      "                ",
      "                ",
      "                ",
      "                ",
      "                ",
      "                ",
      "                "
    ],
    [
      "     deeeed     ",
      "     deeeed     ",
      "     deeeed     ",
      "     deeeed     ",
      "     deeeed     ",
      "     dfeefd     ",
      "     deeeed     ",
      "     deeeed     ",
      "     deeeed     ",
      "     dddddd     ",
      "                ",
      "                ",
      "                ",
      "                ",
      "                ",
      "                "
    ],
    [
      "   ggdh  idgg   ",
      "   ggdh  jdgg   ",
      "     dk  kd     ",
      "     dl   d     ",
      "     dkmmkd     ",
      "     dnmmod     ",
      "     dpmmqd     ",
      "     drmmsd     ",
      "     dttttd     ",
      "     dddddd     ",
      "                ",
      "                ",
      "                ",
      "                ",
      "                ",
      "                "
    ],
    [
      "     du  wd     ",
      "     dx  yd     ",
      "   AAd    dAA   ",
      "   AAd    dAA   ",
      "   AAdB  CdAA   ",
      "   ggd    dgg   ",
      "   ggd    dgg   ",
      "   ggdD  Edgg   ",
      "     dttttd     ",
      "     dddddd     ",
      "                ",
      "                ",
      "                ",
      "                ",
      "                ",
      "                "
    ],
    [
      "     F    F     ",
      "     F    F     ",
      "     F    F     ",
      "     F    F     ",
      "     F    F     ",
      "     F    F     ",
      "     F    F     ",
      "     FIIIIF     ",
      "   AbJKKKKJbA   ",
      "   AbJJJJJJbA   ",
      "   AbbbbbbbbA   ",
      "   AAAAAAAAAA   ",
      "                ",
      "                ",
      "                ",
      "                "
    ],
    [
      "     F    F     ",
      "     FIIIIF     ",
      "    gJLLLLJg    ",
      "    gJLLLLJg    ",
      "    gJLLLLJg    ",
      "    A LLLL A    ",
      "    A LLLL A    ",
      "    A LLLL A    ",
      "                ",
      "                ",
      "                ",
      "                ",
      "                ",
      "                ",
      "                ",
      "                "
    ],
    [
      "    A LLLL A    ",
      "    A LLLL A    ",
      "                ",
      "                ",
      "                ",
      "                ",
      "                ",
      "                ",
      "                ",
      "                ",
      "                ",
      "                ",
      "                ",
      "                ",
      "                ",
      "                "
    ]
  ]
}