{
  "name": "cabin_3_0",
  "refpalette": "c70cities:cabin_3_0_palette",
  "xsize": 16,
  "zsize": 16,
  "slices": [
    [
      "aaaaaaaaaaaaaaaa",
      "aaaaaaaaaaaaaaaa",
      "aaaaaaaaaaaaaaaa",
      "aaaaaaaaaaaaaaaa",
      "aaaaaaaaaaaaaaaa",
      "aaaaaaaaaaaaaaaa",
      "aaaaaaaaaaaaaaaa",
      "aaaaaaaaaaaaaaaa",
      "aaaaaaaaaaaaaaaa",
      "aaaaaaaaaaaaaaaa",
      "aaaaaaaaaaaaaaaa",
      "aaaaaaaaaaaaaaaa",
      "aaaaaaaaaaaaaaaa",
      "aaaaaaaaaaaaaaaa",
      "aaaaaaaaaaaaaaaa",
      "aaaaaaaaaaaaaaaa"
    ],
    [
      "aaaaaaaaaaaaaaaa",
      "aaaaaaaaaaaaaaaa",
      "aaaaaaaaaaaaaaaa",
      "aaaaaaaaaaaaaaaa",
      "aaaaGbbbaaaaaaaa",
      "aaaaaabbaaaaaaaa",
      "aaaaaaaaaaaaaaaa",
      "aaaaaaaaaaaaaaaa",
      "aaaaaaaaaaaaaaaa",
      "aaaaaaaaaaaaaaaa",
      "aaaaaaaaaaaaaaaa",
      "aaaaaaaaaaaaaaaa",
      "aaaaaaaaaaaaaaaa",
      "aaaaaaaaaaaaaaaa",
      "aaaaaaaaaaaaaaaa",
      "aaaaaaaaaaaaaaaa"
    ],
    [
      "GGGGGGGGGGcGccGc",
      "GGGGGGGGGGGccGcc",
      "GGGGGGGGGGccGdGc",
      "GGGGbbbbGGGcGGbb",
      "GGGGeeffGGccGGbg",
      "GGGGGbffGGcGGGbg",
      "GGGGbbbbGGGcGGbb",
      "GGGGGGbGGGccGdGc",
      "GGGGGGGGGGGcGGcc",
      "GGGGGGGGGcccccGc",
      "GGGGaGGGGGccGGGc",
      "GGGGaaGGGGGcGGGG",
      "GGGGaaaGGGcGGGGc",
      "GGGGGGGGGGGGGaGG",
      "GGGGGGGGGGGcGGGG",
      "GGGGGGGGGcGGGGGG"
    ],
    [
      "                ",
      "                ",
      "   hhhhhh    di ",
      "  jh   jh    ikl",
      "   hemnoh     p ",
      "   hq  nh     p ",
      "  jh   jh    ikr",
      "   h    h    di ",
      "   h    h    h  ",
      "   h    h    s  ",
      "   ht   h    h  ",
      "   huu  h    hw ",
      "   huuu h    hx ",
      "  yhhhhhh    dhh",
      "                ",
      "                "
    ],
    [
      "                ",
      "                ",
      "             d  ",
      "  j    j      kA",
      "    eB e      p ",
      "       C      p ",
      "  j    j      kD",
      "             d  ",
      "                ",
      "                ",
      "                ",
      "                ",
      "    uu          ",
      "             E  ",
      "                ",
      "                "
    ],
    [
      "                ",
      "                ",
      "             d  ",
      "  j    j      kk",
      "    FFFF      p ",
      "    I         p ",
      "  j    j      kk",
      "             d  ",
      "                ",
      "                ",
      "                ",
      "                ",
      "                ",
      "                ",
      "                ",
      "                "
    ],
    [
      "                ",
      "               J",
      "             d J",
      " KKKKKKKKKKKKKLL",
      " KKKKKKKKKKKKKLM",
      " KKKKKKKKKKKKKLM",
      " KKKKKKKKKKKKKLL",
      "             d J",
      "               J",
      "                ",
      "                ",
      "                ",
      "                ",
      "                ",
      "                ",
      "                "
    ],
    [
      "                ",
      "          JJNOO ",
      "          JJNOO ",
      "          JJPQQ ",
      "          JJPQQ ",
      "          JJPQQ ",
      "          JJPQQ ",
      "          JJNOO ",
      "          JJNOO ",
      "                ",
      "                ",
      "                ",
      "                ",
      "                ",
      "                ",
      "                "
    ]
  ]
}