{
  "name": "cabin_3_0",
  "refpalette": "c70cities:cabin_3_0_palette",
  "xsize": 16,
  "zsize": 16,
  "slices": [
    [
      "aaaaaaaaaaaaaaaa",
      "aaaaaaaaaaaaaaaa",
      "aaaaaaaaaaaaaaaa",
      "aaaaaaaaaaaaaaaa",
      "aaaaaaaaaaaaaaaa",
      "aaaaaaaaaaaaaaaa",
      "aaaaaaaaaaaaaaaa",
      "aaaaaaaaaaaaaaaa",
      "aaaaaaaaaaaaaaaa",
      "aaaaaaaaaaaaaaaa",
      "aaaaaaaaaaaaaaaa",
      "aaaaaaaaaaaaaaaa",
      "aaaaaaaaaaaaaaaa",
      "aaaaaaaaaaaaaaaa",
      "aaaaaaaaaaaaaaaa",
      "aaaaaaaaaaaaaaaa"
    ],
    [
      "aaaaaaaaaaaaaaaa",
      "aaaaaaaaaaaaaaaa",
      "aaaaaaaaaaaaaaaa",
      "aaaaaaaaaaaaaaaa",
      "aaaaGbbbaaaaaaaa",
      "aaaaaabbaaaaaaaa",
      "aaaaaaaaaaaaaaaa",
      "aaaaaaaaaaaaaaaa",
      "aaaaaaaaaaaaaaaa",
      "aaaaaaaaaaaaaaaa",
      "aaaaaaaaaaaaaaaa",
      "aaaaaaaaaaaaaaaa",
      "aaaaaaaaaaaaaaaa",
      "aaaaaaaaaaaaaaaa",
      "aaaaaaaaaaaaaaaa",
      "aaaaaaaaaaaaaaaa"
    ],
    [
      "GGGGGGGGGGcGccGc",
      "GGGGGGGGGGGccGcc",
      "GGGGGGGGGGccGdGc",
      "GGGGbbbbGGGcGGbb",
      "GGGGefghGGccGGbi",
      "GGGGGbhhGGcGGGbi",
      "GGGGbbbbGGGcGGbb",
      "GGGGGGbGGGccGdGc",
      "GGGGGGGGGGGcGGcc",
      "GGGGGGGGGcccccGc",
      "GGGGaGGGGGccGGGc",
      "GGGGaaGGGGGcGGGG",
      "GGGGaaaGGGcGGGGc",
      "GGGGGGGGGGGGGaGG",
      "GGGGGGGGGGGcGGGG",
      "GGGGGGGGGcGGGGGG"
    ],
    [
      "                ",
      "                ",
      "   jjjjjj    dk ",
      "  lj   lj    kmn",
      "   jo pqj     r ",
      "   j   sj     r ",
      "  ljt  lj    kmu",
      "   j    j    dk ",
      "   j    j    j  ",
      "   j    j    w  ",
      "   jx   j    j  ",
      "   jyy  j    jA ",
      "   jyyy j    jB ",
      "  Cjjjjjj    djj",
      "                ",
      "                "
    ],
    [
      "                ",
      "                ",
      "             d  ",
      "  l    l      mD",
      "    oEFo      r ",
      "       I      r ",
      "  l    l      mJ",
      "             d  ",
      "                ",
      "                ",
      "                ",
      "                ",
      "    yy          ",
      "             K  ",
      "                ",
      "                "
    ],
    [
      "                ",
      "                ",
      "             d  ",
      "  l    l      mm",
      "    L LL      r ",
      "    f         r ",
      "  l M  l      mm",
      "             d  ",
      "                ",
      "                ",
      "                ",
      "                ",
      "                ",
      "                ",
      "                ",
      "                "
    ],
    [
      "                ",
      "               N",
      "             d N",
      " OOOOOOOOOOOOOPP",
      " OOOOOOOOOOOOOPQ",
      " OOOOOOOOOOOOOPQ",
      " OOOOOOOOOOOOOPP",
      "             d N",
      "               N",
      "                ",
      "                ",
      "                ",
      "                ",
      "                ",
      "                ",
      "                "
    ],
    [
      "                ",
      "          NNRSS ",
      "          NNRSS ",
      "          NNTUU ",
      "          NNTUU ",
      "          NNTUU ",
      "          NNTUU ",
      "          NNRSS ",
      "          NNRSS ",
      "                ",
      "                ",
      "                ",
      "                ",
      "                ",
      "                ",
      "                "
    ]
  ]
}