{
  "name": "cabin_3_0",
  "refpalette": "c70cities:cabin_3_0_palette",
  "xsize": 16,
  "zsize": 16,
  "slices": [
    [
      "aaaaaaaaaaaaaaaa",
      "aaaaaaaaaaaaaaaa",
      "aaaaaaaaaaaaaaaa",
      "aaaaaaaaaaaaaaaa",
      "aaaaaaaaaaaaaaaa",
      "aaaaaaaaaaaaaaaa",
      "aaaaaaaaaaaaaaaa",
      "aaaaaaaaaaaaaaaa",
      "aaaaaaaaaaaaaaaa",
      "aaaaaaaaaaaaaaaa",
      "aaaaaaaaaaaaaaaa",
      "aaaaaaaaaaaaaaaa",
      "aaaaaaaaaaaaaaaa",
      "aaaaaaaaaaaaaaaa",
      "aaaaaaaaaaaaaaaa",
      "aaaaaaaaaaaaaaaa"
    ],
    [
      "aaaaaaaaaaaaaaaa",
      "aaaaaaaaaaaaaaaa",
      "aaaaaaaaaaaaaaaa",
      "aaaaaaaaaaaaaaaa",
      "aaaaGbbbaaaaaaaa",
      "aaaaaabbaaaaaaaa",
      "aaaaaaaaaaaaaaaa",
      "aaaaaaaaaaaaaaaa",
      "aaaaaaaaaaaaaaaa",
      "aaaaaaaaaaaaaaaa",
      "aaaaaaaaaaaaaaaa",
      "aaaaaaaaaaaaaaaa",
      "aaaaaaaaaaaaaaaa",
      "aaaaaaaaaaaaaaaa",
      "aaaaaaaaaaaaaaaa",
      "aaaaaaaaaaaaaaaa"
    ],
    [
      "GGGGGGGGGGcGccGc",
      "GGGGGGGGGGGccGcc",
      "GGGGGGGGGGccGdGc",
      "GGGGbbbbGGGcGGbb",
      "GGGGefghGGccGGbi",
      "GGGGGbhhGGcGGGbi",
      "GGGGbbbbGGGcGGbb",
      "GGGGGGbGGGccGdGc",
      "GGGGGGGGGGGcGGcc",
      "GGGGGGGGGcccccGc",
      "GGGGaGGGGGccGGGc",
      "GGGGaaGGGGGcGGGG",
      "GGGGaaaGGGcGGGGc",
      "GGGGGGGGGGGGGaGG",
      "GGGGGGGGGGGcGGGG",
      "GGGGGGGGGcGGGGGG"
    ],
    [
      "                ",
      "                ",
      "   jjjjjj    dk ",
      "  lj   lj    kmn",
      "   je opj     q ",
      "   j   rj     q ",
      "  ljs  lj    kmt",
      "   j    j    dk ",
      "   j    j    j  ",
      "   j    j    u  ",
      "   jw   j    j  ",
      "   jxx  j    jy ",
      "   jxxx j    jA ",
      "  Bjjjjjj    djj",
      "                ",
      "                "
    ],
    [
      "                ",
      "                ",
      "             d  ",
      "  l    l      mC",
      "    eDEe      q ",
      "       F      q ",
      "  l    l      mI",
      "             d  ",
      "                ",
      "                ",
      "                ",
      "                ",
      "    xx          ",
      "             J  ",
      "                ",
      "                "
    ],
    [
      "                ",
      "                ",
      "             d  ",
      "  l    l      mm",
      "    f ff      q ",
      "    f         q ",
      "  l K  l      mm",
      "             d  ",
      "                ",
      "                ",
      "                ",
      "                ",
      "                ",
      "                ",
      "                ",
      "                "
    ],
    [
      "                ",
      "               L",
      "             d L",
      " MMMMMMMMMMMMMNN",
      " MMMMMMMMMMMMMNO",
      " MMMMMMMMMMMMMNO",
      " MMMMMMMMMMMMMNN",
      "             d L",
      "               L",
      "                ",
      "                ",
      "                ",
      "                ",
      "                ",
      "                ",
      "                "
    ],
    [
      "                ",
      "          LLPQQ ",
      "          LLPQQ ",
      "          LLRSS ",
      "          LLRSS ",
      "          LLRSS ",
      "          LLRSS ",
      "          LLPQQ ",
      "          LLPQQ ",
      "                ",
      "                ",
      "                ",
      "                ",
      "                ",
      "                ",
      "                "
    ]
  ]
}