{
  "name": "cabin_4_1",
  "refpalette": "c70cities:cabin_4_1_palette",
  "xsize": 16,
  "zsize": 16,
  "slices": [
    [
      "aaaaaaaaaaaaaaaa",
      "aaaaaaaaaaaaaaaa",
      "aaaaaaaaaaaaaaaa",
      "aaaaaaaaaaaaaaaa",
      "aaaaaaaaaaaaaaaa",
      "aaaaaaaaaaaaaaaa",
      "aaaaaaaaaaaaaaaa",
      "aaaaaaaaaaaaaaaa",
      "aaaaaaaaaaaaaaaa",
      "aaaaaaaaaaaaaaaa",
      "aaaaaaaaaaaaaaaa",
      "aaaaaaaaaaaaaaaa",
      "aaaaaaaaaaaaaaaa",
      "aaaaaaaaaaaaaaaa",
      "aaaaaaaaaaaaaaaa",
      "aaaaaaaaaaaaaaaa"
    ],
    [
      "aaaaaaaaaaaaaaaa",
      "aaaaaaaaaaaaaaaa",
      "aaaaaaaaaaaaaaaa",
      "aaaaaaaaaaaaaaaa",
      "aaaaaaaaaaaaaaaa",
      "aaaaaaaaaaaaaaaa",
      "aaaaaaaaaaaaaaaa",
      "aaaaaaaaaaaaaaaa",
      "aaaaaaaaaaaaaaaa",
      "aaaaaaaaaaaaaaaa",
      "aaaaaaaaaaaaaaaa",
      "aaaaaaaaaaaaaaaa",
      "aaaaaaaaaaaaaaaa",
      "aaaaaaaaaaaaaaaa",
      "aaaaaaaaaaaaaaaa",
      "aaaaaaaaaaaaaaaa"
    ],
    [
      "GGGbcdeeeedcGGGG",
      "GGGbcdeeeedcGGGG",
      "GGGbcdeeeedcGGGG",
      "GGGbcdeeeedcGGGG",
      "GGGbcdeeeedcGGGG",
      "GGGbcdeeeedcGGGG",
      "GGGbcdeeeedcGGGG",
      "GGGbcdeeeedcGGGG",
      "GGGbcdeeeedcGGGG",
      "GGGbcdeeeedcGGGG",
      "GGGbcddddddcGGGG",
      "GGGGccccccccGGGG",
      "GGGGGGGGGGGGGGGG",
      "GGGGGGGGGGGGGGGG",
      "GGGGGGGGGGGGGGGG",
      "GGGGGGGGGGGGGGGG"
    ],
    [
      " fg  h   ijfk  l",
      " fg  m   njf k  ",
      " fg om   pjf    ",
      " fg qm   rjf  k ",
      " fg  m   rjf l s",
      " fg  h  tujf  l ",
      " fg  m  wxjf    ",
      " fg om   yjf  k ",
      " fg qm   yjf s  ",
      " fg  m    jf  kl",
      "kfg  Ammmmjf    ",
      " fffffffffffk   ",
      "   l        l k ",
      " k k sl s l   s ",
      " ks l kk  ks k  ",
      "     k  k   l   "
    ],
    [
      "     h   Bj     ",
      "     m    m     ",
      "     m    m     ",
      "     m    m     ",
      "     m    m    ~",
      "     h    j     ",
      "     m   Cm     ",
      "     m    m     ",
      "     m    m  ~  ",
      "     m    m     ",
      "     Ammmmj     ",
      "                ",
      "                ",
      "     ~  ~     ~ ",
      "  ~        ~    ",
      "                "
    ],
    [
      "     h    j     ",
      "     m    j     ",
      "     m    j     ",
      "     m    j     ",
      "     m    j     ",
      "     h    j     ",
      "     m    j     ",
      "     m    j     ",
      "     m    j     ",
      "     m    j     ",
      "     Ammmmj     ",
      "                ",
      "                ",
      "                ",
      "                ",
      "                "
    ],
    [
      "     DEEEEF     ",
      "     DEEEEF     ",
      "     DEEEEF     ",
      "     DEEEEF     ",
      "     DEEEEF     ",
      "     DEEEEF     ",
      "     DEEEEF     ",
      "     DEEEEF     ",
      "     DEEEEF     ",
      "     DEEEEF     ",
      "     IJJJJK     ",
      "                ",
      "                ",
      "                ",
      "                ",
      "                "
    ],
    [
      "    LjMMMMjL    ",
      "    LjMMMMjL    ",
      "    LjMMMMjL    ",
      "    LjMMMMjL    ",
      "    LjMMMMjL    ",
      "    LjMMMMjL    ",
      "    LjMMMMjL    ",
      "    LjMMMMjL    ",
      "    LjNNNNjL    ",
      "    LjGGGGjL    ",
      "    LjjjjjjL    ",
      "    LLLLLLLL    ",
      "                ",
      "                ",
      "                ",
      "                "
    ],
    [
      "     f    f     ",
      "     f    f     ",
      "     f    f     ",
      "     f    f     ",
      "     f    f     ",
      "     f    f     ",
      "     f    f     ",
      "     f    f     ",
      "     f    f     ",
      "     fggggf     ",
      "     ffffff     ",
      "                ",
      "                ",
      "                ",
      "                ",
      "                "
    ]
  ]
}