{
  "name": "campsite_1_1",
  "refpalette": "c70cities:campsite_1_1_palette",
  "xsize": 16,
  "zsize": 16,
  "slices": [
    [
      "aaaaaaaaaaaaaaaa",
      "aaaaaaaaaaaaaaaa",
      "aaaaaaaaaaaaaaaa",
      "aaaaaaaaaaaaaaaa",
      "aaaaaaaaaaaaaaaa",
      "aaaaaaaaaaaaaaaa",
      "aaaaaaaaaaaaaaaa",
      "aaaaaaaaaaaaaaaa",
      "aaaaaaaaaaaaaaaa",
      "aaaaaaaaaaaaaaaa",
      "aaaaaaaaaaaaaaaa",
      "aaaaaaaaaaaaaaaa",
      "aaaaaaaaaaaaaaaa",
      "aaaaaaaaaaaaaaaa",
      "aaaaaaaaaaaaaaaa",
      "aaaaaaaaaaaaaaaa"
    ],
    [
      "aaaaaaaaaaaaaaaa",
      "aaaGaaaaaaaaaaaa",
      "aaaaaaaaaaaaaaaa",
      "aaaaaaaaaaaaaaaa",
      "aaaaaaaaaaaaaaaa",
      "Gaaaaaaaaaaaaaaa",
      "GGGaaaaaaaaaaaaa",
      "GGaaaaaaaaaaaaaa",
      "Gaaaaaaaaaaaaaaa",
      "aaaaaaaaaaaaaaaa",
      "aaaaaaaaaaaaaaaa",
      "aaaaaaaaaaaaaaaa",
      "aaaaaaaaaaaaaaaa",
      "Gaaaaaaaaaaaaaaa",
      "aaaaaaaaaaaaaaaa",
      "aaaaaaaaaaaaaaaa"
    ],
    [
      "GbGGGGbbbGGGGGGG",
      "GGG GGGbbbGGGGGG",
      "GGGGGbGGbbGGaaaG",
      "GGGGGGGGbGbbbbbG",
      "GGGGGGGGbbGbbbbG",
      " GGGGGGbbbGGaaaG",
      "   GGGGGbGGGGGGG",
      "  GGGGGbGbGGGGGG",
      " GGGGGGGbbGGGGGG",
      "GGGGGGbGbbGGGGGG",
      "GGGGGGGabbaGGGGG",
      "GGGGGGGabbaGGGGG",
      "GGGGGGGabbaGGGGG",
      " GGGGGGGGGGGGGGG",
      "GGGGGGGGGGGGGGGG",
      "GGGGGGGGGGGGGGGG"
    ],
    [
      "                ",
      "     c          ",
      "            ddd ",
      "      e    fggh ",
      "           iggh ",
      "            ddd ",
      "                ",
      "                ",
      "    e           ",
      "        jk      ",
      " l     mnnm     ",
      "       mnom     ",
      "       mppm     ",
      "  e  e        e ",
      "      l         ",
      "          q     "
    ],
    [
      "                ",
      "                ",
      "            rrr ",
      "           s  h ",
      "           t  h ",
      "            uuu ",
      "                ",
      "                ",
      "                ",
      "        wx      ",
      " ~     y  A     ",
      "       y  A     ",
      "       yppA     ",
      "                ",
      "      ~         ",
      "                "
    ],
    [
      "                ",
      "                ",
      "                ",
      "            rrr ",
      "            uuu ",
      "                ",
      "                ",
      "                ",
      "                ",
      "                ",
      "        yA      ",
      "        yA      ",
      "        yA      ",
      "                ",
      "                ",
      "                "
    ]
  ]
}