{
  "name": "campsite_1_0",
  "refpalette": "c70cities:campsite_1_0_palette",
  "xsize": 16,
  "zsize": 16,
  "slices": [
    [
      "aaaaaaaaaaaaaaaa",
      "aaaaaaaaaaaaaaaa",
      "aaaaaaaaaaaaaaaa",
      "aaaaaaaaaaaaaaaa",
      "aaaaaaaaaaaaaaaa",
      "aaaaaaaaaaaaaaaa",
      "aaaaaaaaaaaaaaaa",
      "aaaaaaaaaaaaaaaa",
      "aaaaaaaaaaaaaaaa",
      "aaaaaaaaaaaaaaaa",
      "aaaaaaaaaaaaaaaa",
      "aaaaaaaaaaaaaaaa",
      "aaaaaaaaaaaaaaaa",
      "aaaaaaaaaaaaaaaa",
      "aaaaaaaaaaaaaaaa",
      "aaaaaaaaaaaaaaaa"
    ],
    [
      "GGaaaaaGGGGaaaaa",
      "aaaaaaaaaaGGGaaa",
      "aaaaaaaaaaGGGaaa",
      "aaaaaaaaaaGGGGaa",
      "aaaaaaaaaaaGGaaa",
      "aaaaaaaaaaGaaaaa",
      "aaaaaaaaaaaaaaaa",
      "aaaaaaaaaaaaaaaa",
      "aaaaaaaaaaaaaaaa",
      "Gaaaaaaaaaaaaaaa",
      "Gaaaaaaaaaaaaaaa",
      "aaaaaaaaaaaaaaaG",
      "aaaaaaaaaaaaaaaG",
      "aaaaaaaaaaaaaaGG",
      "aaaaaaaaaaaaaaaa",
      "aaaaaaaaaaaaaaaa"
    ],
    [
      "  GGGGG    GGGGG",
      "GGGGGGGGGG   GGG",
      "GabbaGGGGG   GGG",
      "GabbaGGGGG    GG",
      "GabbaGGGGGG  GGG",
      "GGbbGGGGGG GGGGG",
      "GGGbbGGGGGGGGGGG",
      "GGbGbGbGGGaaaGGG",
      "GbGbbbGbbbbbbGGG",
      " GGGbbbGbbbbbGGG",
      " GGbbGbbGGaaaGGG",
      "GGbGbbGGGGGGGGG ",
      "GGbbbbGGGGGGGGG ",
      "GbbbbbbGGGGGGG  ",
      "GGbbbbGbGGGGGGGG",
      "GbbbGbbGGbGGGGGG"
    ],
    [
      "  cd d        d ",
      " ddcdedddc   df ",
      "dghhg dfd    dde",
      "dgiigccd d    dd",
      " giigdccd    dc ",
      "ddjkd d  d d d  ",
      "d d     dd   dd ",
      " c   d    lllddd",
      "d m      noopced",
      "         qoopdd ",
      "        d lll dd",
      " d      ddcdddf ",
      "   r   ddmd ddd ",
      "   st    c ddd  ",
      "   u    d d edd ",
      "           ddfdd"
    ],
    [
      "  w             ",
      "   w     w    ~ ",
      " xhhy  ~        ",
      " x  yww         ",
      " x  y ww      w ",
      "  AB            ",
      "                ",
      " w        CCC   ",
      "         D  pw  ",
      "         E  p   ",
      "          FFF   ",
      "          w   ~ ",
      "                ",
      "         w      ",
      "                ",
      "             ~  "
    ],
    [
      "                ",
      "                ",
      "  xy            ",
      "  xy            ",
      "  xy            ",
      "                ",
      "                ",
      "                ",
      "          CCC   ",
      "          FFF   ",
      "                ",
      "                ",
      "                ",
      "                ",
      "                ",
      "                "
    ]
  ]
}