{
  "name": "campsite_1_1",
  "refpalette": "c70cities:campsite_1_1_palette",
  "xsize": 16,
  "zsize": 16,
  "slices": [
    [
      "aaaaaaaaaaaaaaaa",
      "aaaaaaaaaaaaaaaa",
      "aaaaaaaaaaaaaaaa",
      "aaaaaaaaaaaaaaaa",
      "aaaaaaaaaaaaaaaa",
      "aaaaaaaaaaaaaaaa",
      "aaaaaaaaaaaaaaaa",
      "aaaaaaaaaaaaaaaa",
      "aaaaaaaaaaaaaaaa",
      "aaaaaaaaaaaaaaaa",
      "aaaaaaaaaaaaaaaa",
      "aaaaaaaaaaaaaaaa",
      "aaaaaaaaaaaaaaaa",
      "aaaaaaaaaaaaaaaa",
      "aaaaaaaaaaaaaaaa",
      "aaaaaaaaaaaaaaaa"
    ],
    [
      "aaaaaaaaaaaaaaaa",
      "aaaGaaaaaaaaaaaa",
      "aaaaaaaaaaaaaaaa",
      "aaaaaaaaaaaaaaaa",
      "aaaaaaaaaaaaaaaa",
      "Gaaaaaaaaaaaaaaa",
      "GGGaaaaaaaaaaaaa",
      "GGaaaaaaaaaaaaaa",
      "Gaaaaaaaaaaaaaaa",
      "aaaaaaaaaaaaaaaa",
      "aaaaaaaaaaaaaaaa",
      "aaaaaaaaaaaaaaaa",
      "aaaaaaaaaaaaaaaG",
      "GaaaaaaaaaaaGaaG",
      "aaaGGaaaaaaGGaGG",
      "aaaGaaaaaaaaaaGa"
    ],
    [
      "GbGGGGbbbGGGGGGG",
      "GGG GGGbbbGGGGGG",
      "GGGGGbGGbbGGaaaG",
      "GGGGGGGGbGbbbbbG",
      "GGGGGGGGbbGbbbbG",
      " GGGGGGbbbGGaaaG",
      "   GGGGGbGGGGGGG",
      "  GGGGGbGbGGGGGG",
      " GGGGGGGbbGGGGGG",
      "GGGGGGbGbbGGGGGG",
      "GGGGGGGabbaGGGGG",
      "GGGGGGGabbaGGGGG",
      "GGGGGGGabbaGGGG ",
      " GGGGGGGGGGG GG ",
      "GGG  GGGGGG  G  ",
      "GGG GGGGGGGGGG G"
    ],
    [
      "    c         dc",
      "cc   e     ccdfc",
      " c c        gggc",
      "  c   h    ijjkc",
      "cccccc     ljjkd",
      " cc dcc     gggc",
      "   cccc        c",
      "  c c c    c cmc",
      " ccch     ccccdc",
      "   c c  no   ccc",
      "cmccdc pqqp cccc",
      "c d c  pqrp c c ",
      "cdcccccpssp  m  ",
      " chc hcc  c  ch ",
      " cc  cmccd   d  ",
      "c    cccdctc c  "
    ],
    [
      "              u ",
      "             u  ",
      "            www ",
      "           x  k ",
      "           y  ku",
      "    u       AAA ",
      "                ",
      "              ~ ",
      "              u ",
      "        BC      ",
      " ~  u  D  E     ",
      "  u    D  E     ",
      " u     DssE  ~  ",
      "                ",
      "      ~  u   u  ",
      "        u       "
    ],
    [
      "                ",
      "                ",
      "                ",
      "            www ",
      "            AAA ",
      "                ",
      "                ",
      "                ",
      "                ",
      "                ",
      "        DE      ",
      "        DE      ",
      "        DE      ",
      "                ",
      "                ",
      "                "
    ]
  ]
}