{
  "name": "campsite_1_1",
  "refpalette": "c70cities:campsite_1_1_palette",
  "xsize": 16,
  "zsize": 16,
  "slices": [
    [
      "aaaaaaaaaaaaaaaa",
      "aaaaaaaaaaaaaaaa",
      "aaaaaaaaaaaaaaaa",
      "aaaaaaaaaaaaaaaa",
      "aaaaaaaaaaaaaaaa",
      "aaaaaaaaaaaaaaaa",
      "aaaaaaaaaaaaaaaa",
      "aaaaaaaaaaaaaaaa",
      "aaaaaaaaaaaaaaaa",
      "aaaaaaaaaaaaaaaa",
      "aaaaaaaaaaaaaaaa",
      "aaaaaaaaaaaaaaaa",
      "aaaaaaaaaaaaaaaa",
      "aaaaaaaaaaaaaaaa",
      "aaaaaaaaaaaaaaaa",
      "aaaaaaaaaaaaaaaa"
    ],
    [
      "aaaaaaaaaaaaaaaa",
      "aaaGaaaaaaaaaaaa",
      "aaaaaaaaaaaaaaaa",
      "aaaaaaaaaaaaaaaa",
      "aaaaaaaaaaaaaaaa",
      "Gaaaaaaaaaaaaaaa",
      "GGGaaaaaaaaaaaaa",
      "GGaaaaaaaaaaaaaa",
      "Gaaaaaaaaaaaaaaa",
      "aaaaaaaaaaaaaaaa",
      "aaaaaaaaaaaaaaaa",
      "aaaaaaaaaaaaaaaa",
      "aaaaaaaaaaaaaaaG",
      "GaaaaaaaaaaaGaaG",
      "aaaGGaaaaaaGGaGG",
      "aaaGaaaaaaaaaaGa"
    ],
    [
      "GbGGGGbbbGGGGGGG",
      "GGG GGGbbbGGGGGG",
      "GGGGGbGGbbGGaaaG",
      "GGGGGGGGbGbbbbbG",
      "GGGGGGGGbbGbbbbG",
      " GGGGGGbbbGGaaaG",
      "   GGGGGbGGGGGGG",
      "  GGGGGbGbGGGGGG",
      " GGGGGGGbbGGGGGG",
      "GGGGGGbGbbGGGGGG",
      "GGGGGGGabbaGGGGG",
      "GGGGGGGabbaGGGGG",
      "GGGGGGGabbaGGGG ",
      " GGGGGGGGGGG GG ",
      "GGG  GGGGGG  G  ",
      "GGG GGGGGGGGGG G"
    ],
    [
      "    c         dc",
      "cc   e     ccdfc",
      " c c        gggc",
      "  c   h    ijjkc",
      "cccccc     ljjkd",
      " cc dcc     gggc",
      "   cccc        c",
      "  c c c    c cmc",
      " ccch     ccccdc",
      "   c c  no   ccc",
      "cmccdc pqqp cccc",
      "c d c  pqqp c c ",
      "cdcccccprrp  m  ",
      " chc hcc  c  ch ",
      " cc  cmccd   d  ",
      "c    cccdcsc c  "
    ],
    [
      "              t ",
      "             t  ",
      "            uuu ",
      "           w  k ",
      "           x  kt",
      "    t       yyy ",
      "                ",
      "              ~ ",
      "              t ",
      "        AB      ",
      " ~  t  C  D     ",
      "  t    C  D     ",
      " t     CrrD  ~  ",
      "                ",
      "      ~  t   t  ",
      "        t       "
    ],
    [
      "                ",
      "                ",
      "                ",
      "            uuu ",
      "            yyy ",
      "                ",
      "                ",
      "                ",
      "                ",
      "                ",
      "        CD      ",
      "        CD      ",
      "        CD      ",
      "                ",
      "                ",
      "                "
    ]
  ]
}