{
  "name": "campsite_1_0",
  "refpalette": "c70cities:campsite_1_0_palette",
  "xsize": 16,
  "zsize": 16,
  "slices": [
    [
      "aaaaaaaaaaaaaaaa",
      "aaaaaaaaaaaaaaaa",
      "aaaaaaaaaaaaaaaa",
      "aaaaaaaaaaaaaaaa",
      "aaaaaaaaaaaaaaaa",
      "aaaaaaaaaaaaaaaa",
      "aaaaaaaaaaaaaaaa",
      "aaaaaaaaaaaaaaaa",
      "aaaaaaaaaaaaaaaa",
      "aaaaaaaaaaaaaaaa",
      "aaaaaaaaaaaaaaaa",
      "aaaaaaaaaaaaaaaa",
      "aaaaaaaaaaaaaaaa",
      "aaaaaaaaaaaaaaaa",
      "aaaaaaaaaaaaaaaa",
      "aaaaaaaaaaaaaaaa"
    ],
    [
      "GGaaaaaGGGGaaaaa",
      "aaaaaaaaaaGGGaaa",
      "aaaaaaaaaaGGGaaa",
      "aaaaaaaaaaGGGGaa",
      "aaaaaaaaaaaGGaaa",
      "aaaaaaaaaaGaaaaa",
      "aaaaaaaaaaaaaaaa",
      "aaaaaaaaaaaaaaaa",
      "aaaaaaaaaaaaaaaa",
      "Gaaaaaaaaaaaaaaa",
      "Gaaaaaaaaaaaaaaa",
      "aaaaaaaaaaaaaaaG",
      "aaaaaaaaaaaaaaaG",
      "aaaaaaaaaaaaaaGG",
      "aaaaaaaaaaaaaaaa",
      "aaaaaaaaaaaaaaaa"
    ],
    [
      "  GGGGG    GGGGG",
      "GGGGGGGGGG   GGG",
      "GabbaGGGGG   GGG",
      "GabbaGGGGG    GG",
      "GabbaGGGGGG  GGG",
      "GGbbGGGGGG GGGGG",
      "GGGbbGGGGGGGGGGG",
      "GGbGbGbGGGaaaGGG",
      "GbGbbbGbbbbbbGGG",
      " GGGbbbGbbbbbGGG",
      " GGbbGbbGGaaaGGG",
      "GGbGbbGGGGGGGGG ",
      "GGbbbbGGGGGGGGG ",
      "GbbbbbbGGGGGGG  ",
      "GGbbbbGbGGGGGGGG",
      "GbbbGbbGGbGGGGGG"
    ],
    [
      "  cd d        d ",
      " ddcdedddc   df ",
      "dghhg dfd    dde",
      "dgijgccd d    dd",
      " giigdccd    dc ",
      "ddkld d  d d d  ",
      "d d     dd   dd ",
      " c   d    mmmddd",
      "d n      oppqced",
      "         rppqdd ",
      "        d mmm dd",
      " d      ddcdddf ",
      "   s   ddnd ddd ",
      "   tu    c ddd  ",
      "   w    d d edd ",
      "           ddfdd"
    ],
    [
      "  x             ",
      "   x     x    ~ ",
      " yhhA  ~        ",
      " y  Axx         ",
      " y  A xx      x ",
      "  BC            ",
      "                ",
      " x        DDD   ",
      "         E  qx  ",
      "         F  q   ",
      "          III   ",
      "          x   ~ ",
      "                ",
      "         x      ",
      "                ",
      "             ~  "
    ],
    [
      "                ",
      "                ",
      "  yA            ",
      "  yA            ",
      "  yA            ",
      "                ",
      "                ",
      "                ",
      "          DDD   ",
      "          III   ",
      "                ",
      "                ",
      "                ",
      "                ",
      "                ",
      "                "
    ]
  ]
}