{
  "name": "campsite_1_0",
  "refpalette": "c70cities:campsite_1_0_palette",
  "xsize": 16,
  "zsize": 16,
  "slices": [
    [
      "aaaaaaaaaaaaaaaa",
      "aaaaaaaaaaaaaaaa",
      "aaaaaaaaaaaaaaaa",
      "aaaaaaaaaaaaaaaa",
      "aaaaaaaaaaaaaaaa",
      "aaaaaaaaaaaaaaaa",
      "aaaaaaaaaaaaaaaa",
      "aaaaaaaaaaaaaaaa",
      "aaaaaaaaaaaaaaaa",
      "aaaaaaaaaaaaaaaa",
      "aaaaaaaaaaaaaaaa",
      "aaaaaaaaaaaaaaaa",
      "aaaaaaaaaaaaaaaa",
      "aaaaaaaaaaaaaaaa",
      "aaaaaaaaaaaaaaaa",
      "aaaaaaaaaaaaaaaa"
    ],
    [
      "GGaaaaaGGGGaaaaa",
      "aaaaaaaaaaGGGaaa",
      "aaaaaaaaaaGGGaaa",
      "aaaaaaaaaaGGGGaa",
      "aaaaaaaaaaaGGaaa",
      "aaaaaaaaaaGaaaaa",
      "aaaaaaaaaaaaaaaa",
      "aaaaaaaaaaaaaaaa",
      "aaaaaaaaaaaaaaaa",
      "Gaaaaaaaaaaaaaaa",
      "Gaaaaaaaaaaaaaaa",
      "aaaaaaaaaaaaaaaG",
      "aaaaaaaaaaaaaaaG",
      "aaaaaaaaaaaaaaGG",
      "aaaaaaaaaaaaaaaa",
      "aaaaaaaaaaaaaaaa"
    ],
    [
      "  GGGGG    GGGGG",
      "GGGGGGGGGG   GGG",
      "GabbaGGGGG   GGG",
      "GabbaGGGGG    GG",
      "GabbaGGGGGG  GGG",
      "GGbbGGGGGG GGGGG",
      "GGGbbGGGGGGGGGGG",
      "GGbGbGbGGGaaaGGG",
      "GbGbbbGbbbbbbGGG",
      " GGGbbbGbbbbbGGG",
      " GGbbGbbGGaaaGGG",
      "GGbGbbGGGGGGGGG ",
      "GGbbbbGGGGGGGGG ",
      "GbbbbbbGGGGGGG  ",
      "GGbbbbGbGGGGGGGG",
      "GbbbGbbGGbGGGGGG"
    ],
    [
      "                ",
      "     c        d ",
      " effe  d       c",
      " eghe           ",
      " egge           ",
      "  ij            ",
      "                ",
      "          kkk   ",
      "  l      mnno c ",
      "         pnno   ",
      "          kkk   ",
      "              d ",
      "   q     l      ",
      "   rs           ",
      "   t        c   ",
      "             d  "
    ],
    [
      "                ",
      "              ~ ",
      " uffw  ~        ",
      " u  w           ",
      " u  w           ",
      "  xy            ",
      "                ",
      "          AAA   ",
      "         B  o   ",
      "         C  o   ",
      "          DDD   ",
      "              ~ ",
      "                ",
      "                ",
      "                ",
      "             ~  "
    ],
    [
      "                ",
      "                ",
      "  uw            ",
      "  uw            ",
      "  uw            ",
      "                ",
      "                ",
      "                ",
      "          AAA   ",
      "          DDD   ",
      "                ",
      "                ",
      "                ",
      "                ",
      "                ",
      "                "
    ]
  ]
}