{
  "name": "farmhouse_1_5",
  "refpalette": "c70cities:farmhouse_1_5_palette",
  "xsize": 16,
  "zsize": 16,
  "slices": [
    [
      "aaaaaaaaaaaaaaaa",
      "aaaaaaaaaaaaaaaa",
      "aaaaaaaaaaaabaaa",
      "aaaaaaaaaaabaaaa",
      "aaaaaaaaaaabbaaa",
      "aaaaaaaaaaaaaaaa",
      "aaaaaaaaaaaaaaaa",
      "aaaaaaaaaaaaaaaa",
      "aaaaaaaaaaaaaaaa",
      "aaaaaaaaaaaaaaaa",
      "aaaaaaaaaaaaaaaa",
      "aaaaaaaaaaaaaaaa",
      "aaaaaaaaaaaaaaaa",
      "aaaaaaaaaaaaaaaa",
      "aaaaaaaaaaaaaaaa",
      "aaaaaaaaaaaaaaaa"
    ],
    [
      "aaaaaaaaaaaaaaaa",
      "aaaaaaaaaaabccaa",
      "aaaaaaaaabbcdaaa",
      "aaaaaaaaabcdccaa",
      "aaaaaaaaaabddcaa",
      "aaaaaaaaaaabcbGa",
      "aaaaaaaaaaabbcaa",
      "aaaaaaaaaaacbbaa",
      "aaaaaaaaaaaGaaaa",
      "aaaaaaaaaaaaaaaa",
      "aaaaaaaaaaaaaaaa",
      "aaaaaaaaaaaaaaaa",
      "aaaaaaaaaaaaaaaa",
      "aaaaaaaaaaaaaaaa",
      "aaaaaaaaaaaaaaaa",
      "aaaaaaaaaaaaaaaa"
    ],
    [
      "GGGGGGGGGGGGGGGG",
      "GeGeeGeGGGGddGGG",
      "GGeeGeGGGddddGGG",
      "GeeGGGGGGdddddGG",
      "GGeeeGGGGGddddGG",
      "GeGeGGGGGGGddddG",
      "GGeeGGGGGGGdddGG",
      "GGeGGGGGGGGdddGG",
      "GGGGeGGGGGGdGGGG",
      "GGGeGGeGGGGGGGGe",
      "GGGGGGGGGGGGGGGe",
      "GeGGGGGGGeGGGeeG",
      "GGGeGGGeeeeeeeee",
      "GGeGGeGGeeeGeGGG",
      "GGGGGGeGGeGeGGGe",
      "GGGGGGGGeGeGGGGG"
    ],
    [
      "ffffffffffffffff",
      "f              f",
      "f              f",
      "f              f",
      "f              f",
      "f              f",
      "f             gf",
      "f             gf",
      "ff            ff",
      "hff        g ff ",
      " hffffffi jffj  ",
      "h  hh hk   i    ",
      "hhh h           ",
      "hh  h           ",
      "  h h           ",
      "hfhf h       l i"
    ],
    [
      "                ",
      "                ",
      "                ",
      "                ",
      "                ",
      "                ",
      "              g ",
      "              g ",
      "                ",
      "m          g    ",
      " m              ",
      "m  mm m         ",
      "mmm m           ",
      "mm  m           ",
      "  m m           ",
      "m m  m       ~  "
    ],
    [
      "                ",
      "                ",
      "                ",
      "                ",
      "                ",
      "                ",
      "              g ",
      "              g ",
      "                ",
      "           g    ",
      "                ",
      "                ",
      "                ",
      "                ",
      "                ",
      "                "
    ],
    [
      "                ",
      "                ",
      "                ",
      "                ",
      "                ",
      "                ",
      "              g ",
      "                ",
      "                ",
      "                ",
      "                ",
      "                ",
      "                ",
      "                ",
      "                ",
      "                "
    ]
  ]
}