{
  "name": "farmhouse_1_7",
  "refpalette": "c70cities:farmhouse_1_7_palette",
  "xsize": 16,
  "zsize": 16,
  "slices": [
    [
      "aaaaaaaaaaaaaaaa",
      "aaaaaaaaaaaaaaaa",
      "aaaaaaaaaaaaaaaa",
      "aaaaaaaaaaaaaaaa",
      "aaaaaaaaaaaaaaaa",
      "aaaaaaaaaaaaaaaa",
      "aaaaaaaaaaaaaaaa",
      "aaaaaaaaaaaaaaaa",
      "aaaaaaaaaaaaaaaa",
      "aaaaaaaaaaaaaaaa",
      "aaaaaaaaaaaaaaaa",
      "aaaaaaaaaaaaaaaa",
      "aaaaaaaaaaaaaaaa",
      "aaaaaaaaaaaaaaaa",
      "aaaaaaaaaaaaaaaa",
      "aaaaaaaaaaaaaaaa"
    ],
    [
      "aaaaaaaaaaaaaaaa",
      "aaaaaaaaaaaaaaaa",
      "aaaaaaaaaaaaaaaa",
      "aaaaaaaaaaaaaaaa",
      "aaaaaaaaaaaaaaaa",
      "aaaaaaaaaaaaaaaa",
      "aaaaaaaaaaaaaaaa",
      "aaaaaaaaaaaaaaaa",
      "aaaaaaaaaaaaaaaa",
      "aaaaaaaaaaaaaaaa",
      "aaaaaaaaaaaaaaaa",
      "aaaaaaaaaaaaaaaa",
      "aaaaaaaaaaaaaaaa",
      "aaaaaaaaaaaaaaaa",
      "aaaaaaaaaaaaaaaa",
      "aaaaaaaaaaaaaaaa"
    ],
    [
      "GGGGGGGGGGGGGGGG",
      "aaGGGGGGGGGGGGGG",
      "aaaaGGGGGGGGGGGG",
      "aaaaGGGGGGGGGGGG",
      "aaaaaGGGGGGGGGGG",
      "aaaaabGGGGGGGGGG",
      "aaaaabGGGGGGGGGG",
      "aaaaaGGGGGGGGGGG",
      "aaaabbGGGGGGGGGG",
      "aaaabbbGGGGGGGGG",
      "aaaGGbbbGGGGGGGG",
      "aaaGGbbbbGGGGGGG",
      "aaaGGbbGGGGcGGGG",
      "GGGGGbbcbGGGGGcG",
      "GGGGbbbbGccGcGGG",
      "GGGGbbGbcGGcGcGG"
    ],
    [
      "      d  ddd   e",
      "GG     dd  dddd ",
      "GGGG d d dd d  e",
      "GGGG    d  d  d ",
      "ffGGb      d   e",
      "ffbbG           ",
      "ffbbb          g",
      "ffbGb           ",
      "ffGG           h",
      "ffGG           g",
      "ffG            g",
      "ffG           ee",
      "GGG            g",
      "                ",
      "               g",
      "              eg"
    ],
    [
      "      i  iii    ",
      "       ii  iiii ",
      "     i i ii i   ",
      "        i  i  i ",
      "           i    ",
      "                ",
      "                ",
      "                ",
      "                ",
      "                ",
      "                ",
      "                ",
      "                ",
      "                ",
      "                ",
      "                "
    ]
  ]
}