{
  "name": "farmhouse_1_2",
  "refpalette": "c70cities:farmhouse_1_2_palette",
  "xsize": 16,
  "zsize": 16,
  "slices": [
    [
      "aaaaaaaaaaaaaaaa",
      "aaaaaaaaaaaaaaaa",
      "aaaaaaaaaaaaaaaa",
      "aaaaaaaaaaaaaaaa",
      "aaaaaaaaaaaaaaaa",
      "aaaaaaaaaaaaaaaa",
      "aaaaaaaaaaaaaaaa",
      "aaaaaaaaaaaaaaaa",
      "aaaaaaaaaaaaaaaa",
      "aaaaaaaaaaaaaaaa",
      "aaaaaaaaaaaaaaaa",
      "aaaaaaaaaaaaaaaa",
      "aaaaaaaaaaaaaaaa",
      "aaaaaaaaaaaaaaaa",
      "aaaaaaaaaaaaaaaa",
      "aaaaaaaaaaaaaaaa"
    ],
    [
      "aaaaaaaaaaaaaaaa",
      "aaaaaaaaaaaaaaaa",
      "aaaaaaaaaaaaaaaa",
      "aaaaaaaaaaaaaaaa",
      "aaaaaaaaaaaaaaaa",
      "aaaaaaaaaaaaaaaa",
      "aaaaaaaaaaaaaaaa",
      "aaaaaaaaaaaaaaaa",
      "Gaaaaaaaaaaaaaaa",
      "Gaaaaaaaaaaaaaaa",
      "aaaaaaaaaaaaaaaa",
      "Gaaaaaaaaaaaaaaa",
      "Gaaaaaaaaaaaaaaa",
      "GGaaaaaaaaaaaaaa",
      "GGGGGaaaaaaaaaaa",
      "GGGGGGGaaaaaaaaa"
    ],
    [
      "GGGGGGGGGGGGGGGG",
      "GGGGGGGGGGGGGGGG",
      "GGGGGGGGGGGGGGGG",
      "GGGGGGGGGGGGGGGG",
      "GGGGGGGGGGGGGGGG",
      "GGGGGGGGGGGGGGGG",
      "GGGGGGGGGGGGGGGG",
      "GGGGGGGGGGGGGGGG",
      " GGGGGGGGGGGGGGG",
      " GGGGGGGGGGGGGGG",
      "GGGGGGGGGGGGGGGG",
      " GGGGGGGGGGGGGGG",
      " GGGGGGGGGGGGGGG",
      "  GGGGGGGGGGGGGG",
      "     GGGGGGGGGGG",
      "       GGGGGGGGG"
    ],
    [
      "b ccc ccccccccc ",
      "b c cccccccccccc",
      "dcc  cccce ccccc",
      "b cccccccccccccc",
      "ccc ccccccecccc ",
      "bc ccccccccccccc",
      "bccccccccccccccc",
      "c ccccccccccccc ",
      " b  c cccccccccc",
      " bfcccc ccccccc ",
      "  bc  c cccccccc",
      "  db ccccccccccc",
      "   bb c   c c cc",
      "    bb fc ccccc ",
      "      fb c  c cc",
      "       bbbfb cbb"
    ],
    [
      "  ggg ggggggggg ",
      "  g gggggggggggg",
      " gg  ggggh ggggg",
      "  gggggggggggggg",
      "ggg ggggggegggg ",
      " g ggggggggggggg",
      " ggggggggggggggg",
      "g ggggggggggggg ",
      "    g gggggggggg",
      "   gggg ggggggg ",
      "   g  g gggggggg",
      "     ggggggggggg",
      "      g   g g gg",
      "        g ggggg ",
      "         g  g gg",
      "             g  "
    ],
    [
      "                ",
      "                ",
      "                ",
      "                ",
      "          i     ",
      "                ",
      "                ",
      "                ",
      "                ",
      "                ",
      "                ",
      "                ",
      "                ",
      "                ",
      "                ",
      "                "
    ]
  ]
}