{
  "name": "farmhouse_1_4",
  "refpalette": "c70cities:farmhouse_1_4_palette",
  "xsize": 16,
  "zsize": 16,
  "slices": [
    [
      "aaaaaaaaaaaaaaaa",
      "aaaaaaaaaaaaaaaa",
      "aaaaaaaaaaaaaaaa",
      "aaaaaaaaaaaaaaaa",
      "aaaaaaaaaaaaaaaa",
      "aaaaaaaaaaaaaaaa",
      "aaaaaaaaaaaaaaaa",
      "aaaaaaaaaaaaaaaa",
      "aaaaaaaaaaaaaaaa",
      "aaaaaaaaaaaaaaaa",
      "aaaaaaaaaaaaaaaa",
      "aaaaaaaaaaaaaaaa",
      "aaaaaaaaaaaaaaaa",
      "aaaaaaaaaaaaaaaa",
      "aaaaaaaaaaaaaaaa",
      "aaaaaaaaaaaaaaaa"
    ],
    [
      "aaaaaaaaaaaaaaaa",
      "aaaaaaaaaaaaaaaa",
      "aaaaaaaaaaaaaaaa",
      "aaaaaaaaaaaaaaaa",
      "aaaaaaaaaaaaaaaa",
      "aaaaaaaaaaaaaaaa",
      "aaaaaaaaaaaaaaaa",
      "aaaaaaaaaaaaaaaa",
      "aaaaaaaaaaaaaaaa",
      "aaaaaaaaaaaaaaaa",
      "aaaaaaaaaaaaaaaa",
      "aaaaaaaaaaaaaaaa",
      "aaaaaaaaaaaaaaaa",
      "aaaaaaaaaaaaaaaa",
      "aaaaaaaaaaaaaaaa",
      "aaaaaaaaaaaaaaaa"
    ],
    [
      "aaaaaaaaaaaaaaaa",
      "aaaaaaaaaaaaaaaa",
      "aaaaaaaaaaaaaaaa",
      "aaaaaaaaaaaaaaaa",
      "aaaaaaaaaaaaaaaa",
      "aaaaaaaaaaaaaaaa",
      "aaaaaaaaaaaaaaaa",
      "aaaaaaaaaaaaaaaa",
      "aaaaaaaaaaaaaaaa",
      "aaaaaaaaaaaaaaaa",
      "aaaaaaaaaaaaaaaa",
      "aaaaaaaaaaaaaaaa",
      "aaaaaaaaaaaaaaaa",
      "aaaaaaaaaaaaaaaa",
      "GGGGaaaaaaaGGGGG",
      "GGGGGGGGGGGGGGGG"
    ],
    [
      "GGGGaGGaGGGGGGGG",
      "GGGaGaaGaGGGGGGG",
      "GGGGaaaaaaGGGGGG",
      "GGGGGGGGGGGGGGGG",
      "Gaaaaaaaaaaaaaab",
      "Gaaaaaaaaaaaaaab",
      "Gaaaaaaaaaaaaaab",
      "Gaaaaaaaaaaaaaab",
      "Gaaaaaaaaaaaaaab",
      "Gaaaaaaaaaaaaaab",
      "Gaaaaaaaaaaaaaab",
      "Gaaaaaaaaaaaaaab",
      "GGGGGGGGGGGGGGGG",
      "GGGGGGGGGGGGGGGG",
      "    GGGGGGG     ",
      "                "
    ],
    [
      "    c  c    d   ",
      "   c ee c       ",
      "    ccccec      ",
      "ffffffffffffffff",
      " bbbbbbbbbbbbbgh",
      " bbbbbbbbbbbbbgh",
      " bbbbbbbbbbbbbgh",
      " bbbbbbbbbbbbbgh",
      " bbbbbbbbbbbbbgh",
      " bbbbbbbbbbbbbgh",
      " bbbbbbbbbbbbbgh",
      " bbbbbbbbbbbbbgh",
      "iiiiiiiiiiiiiiii",
      "                ",
      "                ",
      "                "
    ],
    [
      "            ~   ",
      "                ",
      "     cc         ",
      "ffffffffffffffff",
      "  jkllmnmlojj   ",
      "  j        p    ",
      "  jq       r    ",
      "  j        jj   ",
      "  js  e    tju  ",
      "  jccs     tjw  ",
      "  jc!c xx  tjy  ",
      "  jcccexxx tju  ",
      "iiiiiiiiiiiiiiii",
      "                ",
      "                ",
      "                "
    ],
    [
      "                ",
      "                ",
      "                ",
      "ffffffffffffffff",
      "  j l mn   jj   ",
      "  j        A    ",
      "  jq       B    ",
      "  j        jj   ",
      "  j        Cju  ",
      "  jD        j   ",
      "  jcs       j   ",
      "  jEcD x   Fju  ",
      "iiiiiiiiiiiiiiii",
      "                ",
      "                ",
      "                "
    ],
    [
      "                ",
      "                ",
      "                ",
      "ffffffffffffffff",
      "  j   m    jj   ",
      "  j        I    ",
      "  jq       I    ",
      "  j        jj   ",
      "  j        Jj   ",
      "  j        Kj   ",
      "  jD       Lj   ",
      "  jDc      Fj   ",
      "iiiiiiiiiiiiiiii",
      "                ",
      "                ",
      "                "
    ],
    [
      "                ",
      "                ",
      "                ",
      "ffffffffffffffff",
      "iijMMMMMMMMjjiii",
      "  j        I    ",
      "  jq       I    ",
      "  jNNNNNNNNjj   ",
      "  jMMMMMMMMOj   ",
      "  jMMMMMMMMOj   ",
      "  jMMMMMMMMOj   ",
      "ffjMMMMMMMMPjfff",
      "iiiiiiiiiiiiiiii",
      "                ",
      "                ",
      "                "
    ],
    [
      "                ",
      "                ",
      "                ",
      "                ",
      "QQQQQQQQQQQQQQQQ",
      "iijD      DIiiii",
      "  j RRRRRRRI    ",
      "  j       Djj   ",
      "  jSTS    Ujj   ",
      "  jV WDX  Yjj   ",
      "ffjDZW0D12!jjfff",
      "33333333333P3333",
      "                ",
      "                ",
      "                ",
      "                "
    ],
    [
      "                ",
      "                ",
      "                ",
      "                ",
      "                ",
      "QQQQQQ4444QQQQQQ",
      "iij        Iiiii",
      "  j        jj   ",
      "  jS5S     jj   ",
      "ffj6 W    Djjfff",
      "3333333333333333",
      "           P    ",
      "                ",
      "                ",
      "                ",
      "                "
    ],
    [
      "                ",
      "                ",
      "                ",
      "                ",
      "                ",
      "                ",
      "QQQQQQ4444QQQQQQ",
      "iij      DDjjiii",
      "ffjSSS    Djjfff",
      "3333333333333333",
      "                ",
      "           F    ",
      "                ",
      "                ",
      "                ",
      "                "
    ],
    [
      "                ",
      "                ",
      "                ",
      "                ",
      "                ",
      "                ",
      "                ",
      "QQQQQQQQQQQQQQQQ",
      "3333333333333333",
      "                ",
      "                ",
      "           F    ",
      "                ",
      "                ",
      "                ",
      "                "
    ],
    [
      "                ",
      "                ",
      "                ",
      "                ",
      "                ",
      "                ",
      "                ",
      "                ",
      "                ",
      "                ",
      "                ",
      "           F    ",
      "                ",
      "                ",
      "                ",
      "                "
    ]
  ]
}