{
  "name": "farmhouse_1_1",
  "refpalette": "c70cities:farmhouse_1_1_palette",
  "xsize": 16,
  "zsize": 16,
  "slices": [
    [
      "aaaaaaaaaaaaaaaa",
      "aaaaaaaaaaaaaaaa",
      "aaaaaaaaaaaaaaaa",
      "aaaaaaaaaaaaaaaa",
      "aaaaaaaaaaaaaaaa",
      "aaaaaaaaaaaaaaaa",
      "aaaaaaaaaaaaaaaa",
      "aaaaaaaaaaaaaaaa",
      "aaaaaaaaaaaaaaaa",
      "aaaaaaaaaaaaaaaa",
      "aaaaaaaaaaaaaaaa",
      "aaaaaaaaaaaaaaaa",
      "aaaaaaaaaaaaaaaa",
      "aaaaaaaaaaaaaaaa",
      "aaaaaaaaaaaaaaaa",
      "aaaaaaaaaaaaaaaa"
    ],
    [
      "aaaaaaaaaaaaaaaa",
      "aaaaaaaaaaaaaaaa",
      "aaaaaaaaaaaaaaaa",
      "aaaaaaaaaaaaaaaa",
      "aaaaaaaaaaaaaaaa",
      "aaaaaaaaaaaaaaaa",
      "aaaaaaaaaaaaaaaa",
      "aaaaaaaaaaaaaaaa",
      "aaaaaaaaaaaaaaaa",
      "aaaaaaaaaaaaaaaa",
      "aaaaaaaaaaaaaaaa",
      "aaaaaaaaaaaaaaaa",
      "aaaaaaaaaaaaaaaa",
      "aaaaaaaaaaaaaaaa",
      "aaaaaaaaaaaaaaaa",
      "aaaaaaaaaaaaaaaa"
    ],
    [
      "GGGGGGGGGGGGGGGG",
      "GGGGGGGGGGGGGGGa",
      "GGGGGGGGGGGGGGaa",
      "GGGGGGGGGGGGGGaa",
      "GGGGGGGGGGGGGGaa",
      "GGGGGGGGGGGGGGaa",
      "GGGGGGGGGGGGGGaa",
      "GGGGGGGGGGGGGGaa",
      "GGGGGGGGGGGGGGaa",
      "GGGGGGGGGGGGGGaa",
      "GGGGGGGGGGGGGGGa",
      "GGGGGGGGGGGGGGGa",
      "GGGGGGGGGGGGGGGa",
      "GGGGGGGGGGGGGGGG",
      "GGGGGGGGGGGGGGGG",
      "GGGGGGGGGGGGGGGG"
    ],
    [
      "b cccccccccccccc",
      "dcc ccccc cccccG",
      "c cc cccccccccGG",
      "b c ccccccccccGG",
      "bccccccccc cccGG",
      "b cc c c eccccGG",
      "dcccccccccccccGG",
      "bcc cccccc cccGG",
      "c  cc ccccccccGG",
      " dccccccccccccGG",
      "bcc  ccccccccccG",
      "bcccc cccceccccG",
      " f ccccccccccccG",
      "b ce cc ccccccc ",
      "b ccccccccccccc ",
      "bcc cccccccccccc"
    ],
    [
      "  gggggggggggggg",
      " gg ggggg ggggg ",
      "g gg ggggggggg  ",
      "  g gggggggggg  ",
      " ggggggggg ggg  ",
      "  gg g g egggg  ",
      " ggggggggggggg  ",
      " gg gggggg ggg  ",
      "g  gg gggggggg  ",
      "  gggggggggggg  ",
      " gg  gggggggggg ",
      " gggg gggg gggg ",
      "   gggggggggggg ",
      "  gh gg ggggggg ",
      "  ggggggggggggg ",
      " gg gggggggggggg"
    ],
    [
      "                ",
      "                ",
      "                ",
      "                ",
      "                ",
      "         i      ",
      "                ",
      "                ",
      "                ",
      "                ",
      "                ",
      "                ",
      "                ",
      "                ",
      "                ",
      "                "
    ]
  ]
}