{
  "name": "farmhouse_1_6",
  "refpalette": "c70cities:farmhouse_1_6_palette",
  "xsize": 16,
  "zsize": 16,
  "slices": [
    [
      "aaaaaaaaaaaaaaaa",
      "aaaaaaaaaaaaaaaa",
      "aaaaaaaaaaaaaaaa",
      "aaaaaaaaaaaaaaaa",
      "aaaaaaaaaaaaaaaa",
      "aaaaaaaaaaaaaaaa",
      "aaaaaaaaaaaaaaaa",
      "aaaaaaaaaaaaaaaa",
      "aaaaaaaaaaaaaaaa",
      "aaaaaaaaaaaaaaaa",
      "aaaaaaaaaaaaaaaa",
      "aaaaaaaaaaaaaaaa",
      "aaaaaaaaaaaaaaaa",
      "aaaaaaaaaaaaaaaa",
      "aaaaaaaaaaaaaaaa",
      "aaaaaaaaaaaaaaaa"
    ],
    [
      "aaaaaaaaaaaaaaaa",
      "aaaaaaaaaaaaaaaa",
      "aaaaaaaaaaaaaaaa",
      "aaaaaaaaaaaaaaaa",
      "aaaaaaaaaaaaaaaa",
      "aaaaaaaaaaaaaaaa",
      "aaaaaaaaaaaaaaaa",
      "aaaaaaaaaaaaaaaa",
      "aaaaaaaaaaaaaaaa",
      "aaaaaaaaaaaaaaaa",
      "aaaaaaaaaaaaaaaa",
      "aaaaaaaaaaaaaaaa",
      "aaaaaaaaaaaaaaaa",
      "aaaaaaaaaaaaaaaa",
      "aaaaaaaaaaaaaaaa",
      "aaaaaaaaaaaaaaaa"
    ],
    [
      "GGGGGGGGGGGGGGGG",
      "GGGGGGGGGGGGGGGG",
      "GGGGGGGGGGGGGGGG",
      "GGGGGGGGGGGGGGGG",
      "GGGGGGGGGGGGGGGG",
      "GGGGGGGGGGGGGGGG",
      "GGGGGGGGGGGGGGGG",
      "GGGGGGGGGGGGGGGG",
      "GGGGGGGGGGGGGGGG",
      "GGGGGGGGGGGGGGGG",
      "GGGGGGGGGGGGGGGG",
      "GGGGGGGGGGGGGGGG",
      "GGGGGGGGGGGGGGGG",
      "GGGGGGGGGGGGGGGG",
      "GGGGGGGGGGGGGGGG",
      "GGGGGGGGGGGGGGGG"
    ],
    [
      "bb  b  bb       ",
      " b bbb b bb b  b",
      " bbbb bbb   bb  ",
      " bb  bbbb bb b  ",
      " bbbbbb bbbb  b ",
      "bbbbbbbbbbbbbb  ",
      "bbbb bbbbb bb  b",
      "bbbbbb bbbbbb b ",
      "bbbbbbbbbbbbb   ",
      "bbbbbbbbbb b  b ",
      "bbbbbbbbbbbbbb  ",
      "bbbbbbbbbbbb b b",
      "bbbbbbbbbbbbb b ",
      "b bb bb bbbbbbbc",
      "  b  bbbbbbb b  ",
      "   d  bbbbb b bc"
    ],
    [
      "ee  e  ee       ",
      " e eee e ee e  e",
      " eeee eee   ee  ",
      " ee  eeee ee e  ",
      " eeeeee eeee  e ",
      "eeeeeeeeeeeeee  ",
      "eeee eeeee ee  e",
      "eeeeee eeeeee e ",
      "eeeeeeeeeeeee   ",
      "eeeeeeeeee e  e ",
      "eeeeeeeeeeeeee  ",
      "eeeeeeeeeeee e e",
      "eeeeeeeeeeeee e ",
      "e ee ee eeeeeee ",
      "  e  eeeeeee e  ",
      "   ~  eeeee e e "
    ]
  ]
}