{
  "name": "farmhouse_1_0",
  "refpalette": "c70cities:farmhouse_1_0_palette",
  "xsize": 16,
  "zsize": 16,
  "slices": [
    [
      "aaaaaaaaaaaaaaaa",
      "aaaaaaaaaaaaaaaa",
      "aaaaaaaaaaaaaaaa",
      "aaaaaaaaaaaaaaaa",
      "aaaaaaaaaaaaaaaa",
      "aaaaaaaaaaaaaaaa",
      "aaaaaaaaaaaaaaaa",
      "aaaaaaaaaaaaaaaa",
      "aaaaaaaaaaaaaaaa",
      "aaaaaaaaaaaaaaaa",
      "aaaaaaaaaaaaaaaa",
      "aaaaaaaaaaaaaaaa",
      "aaaaaaaaaaaaaaaa",
      "aaaaaaaaaaaaaaaa",
      "aaaaaaaaaaaaaaaa",
      "aaaaaaaaaaaaaaaa"
    ],
    [
      "GGGaaaaaaaaaaaaa",
      "Gaaaaaaaaaaaaaaa",
      "aaaaaaaaaaaaaaaa",
      "aaaaaaaaaaaaaaaa",
      "aaaaaaaaaaaaaaaa",
      "Gaaaaaaaaaaaaaaa",
      "Gaaaaaaaaaaaaaaa",
      "aaaaaaaaaaaaaaaa",
      "aaaaaaaaaaaaaaaa",
      "aaaaaaaaaaaaaaaa",
      "aaaaaaaaaaaaaaaa",
      "aaaaaaaaaaaaaaaa",
      "aaaaaaaaaaaaaaaa",
      "aaaaaaaaaaaaaaaa",
      "aaaaaaaaaaaaaaaa",
      "aaaaaaaaaaaaaaaa"
    ],
    [
      "   GGGGGGGGGGGGG",
      " GGGGGGGGGGGGGGG",
      "GGGGGGGGGGGGGGGG",
      "GGGGGGGGGGGGGGGG",
      "GGGGGGGGGGGGGGGG",
      " GGGGGGGGGGGGGGG",
      "bGGGGGcGGGGGGGGG",
      "GGGGGGGGGGGGGGGG",
      "GGGGGGGGGGGGGGGG",
      "GGGGGGGGGGGGGGGG",
      "GGGGGGGGGGGGGGGG",
      "GGGGGGGGGGGGGGGG",
      "GGGGGGGGGGGGGGGG",
      "GGGGGGGGGGGGGGGG",
      "GGGGGGGGGGGGGGGG",
      "GGGGGGGGGGGGGGGG"
    ],
    [
      "   d    d   d d ",
      "     d    d     ",
      "  d   d dddd   d",
      "   ddddd  d dd d",
      " d dd dd  dd ddd",
      "  d dd ddd d ddd",
      "  dd deddddddddd",
      " dd dddddddddddd",
      "b dddddd dddd dd",
      " ddd  dddddddddd",
      "fdd dddddddddddd",
      " gdddddddddddddd",
      "dddd dddddd dddd",
      "fd ddddd ddddddd",
      " ddd dddddddddd ",
      "d d dddddddddddd"
    ],
    [
      "   h    h   h h ",
      "     h    h     ",
      "  h   h hhhh   h",
      "   hhhhh  h hh h",
      " h hh hh  hh hhh",
      "  h hh hhh h hhh",
      "  hh hihhhhhhhhh",
      " hh hhhhhhhhhhhh",
      "  hhhhhh hhhh hh",
      " hhh  hhhhhhhhhh",
      " hh hhhhhhhhhhhh",
      "  hhhhhhhhhhhhhh",
      "hhhh hhhhhh hhhh",
      " h hhhhh hhhhhhh",
      " hhh hhhhhhhhhh ",
      "h h hhhhhhhhhhhh"
    ],
    [
      "                ",
      "                ",
      "                ",
      "                ",
      "                ",
      "                ",
      "     jkj        ",
      "                ",
      "                ",
      "                ",
      "                ",
      "                ",
      "                ",
      "                ",
      "                ",
      "                "
    ],
    [
      "                ",
      "                ",
      "                ",
      "                ",
      "                ",
      "                ",
      "      l         ",
      "                ",
      "                ",
      "                ",
      "                ",
      "                ",
      "                ",
      "                ",
      "                ",
      "                "
    ],
    [
      "                ",
      "                ",
      "                ",
      "                ",
      "                ",
      "      m         ",
      "     mnm        ",
      "      m         ",
      "                ",
      "                ",
      "                ",
      "                ",
      "                ",
      "                ",
      "                ",
      "                "
    ]
  ]
}