{
  "name": "farmhouse_1_5",
  "refpalette": "c70cities:farmhouse_1_5_palette",
  "xsize": 16,
  "zsize": 16,
  "slices": [
    [
      "aaaaaaaaaaaaaaaa",
      "aaaaaaaaaaaaaaaa",
      "aaaaaaaaaaaabaaa",
      "aaaaaaaaaaabaaaa",
      "aaaaaaaaaaabbaaa",
      "aaaaaaaaaaaaaaaa",
      "aaaaaaaaaaaaaaaa",
      "aaaaaaaaaaaaaaaa",
      "aaaaaaaaaaaaaaaa",
      "aaaaaaaaaaaaaaaa",
      "aaaaaaaaaaaaaaaa",
      "aaaaaaaaaaaaaaaa",
      "aaaaaaaaaaaaaaaa",
      "aaaaaaaaaaaaaaaa",
      "aaaaaaaaaaaaaaaa",
      "aaaaaaaaaaaaaaaa"
    ],
    [
      "aaaaaaaaaaaaaaaa",
      "aaaaaaaaaaabccaa",
      "aaaaaaaaabbcdaaa",
      "aaaaaaaaabcdccaa",
      "aaaaaaaaaabddcaa",
      "aaaaaaaaaaabcbaa",
      "aaaaaaaaaaabbcaa",
      "aaaaaaaaaaacbbaa",
      "aaaaaaaaaaaaaaaa",
      "aaaaaaaaaaaaaaaa",
      "aaaaaaaaaaaaaaaa",
      "aaaaaaaaaaaaaaaa",
      "aaaaaaaaaaaaaaaa",
      "aaaaaaaaaaaaaaaa",
      "aaaaaaaaaaaaaaaa",
      "aaaaaaaaaaaaaaaa"
    ],
    [
      "GGGGGGGGGGGGGGGG",
      "GeGeeGeGGGGddGGG",
      "GGeeGeGGGddddGGG",
      "GeeGGGGGGdddddGG",
      "GGeeeGGGGGddddGG",
      "GeGeGGGGGGGddddG",
      "GGeeGGGGGGGdddGG",
      "GGeGGGGGGGGdddGG",
      "GGGGeGGGGGGdGGGG",
      "GGGeGGeGGGGGGGGe",
      "GGGGGGGGGGGGGGGe",
      "GeGGGGGGGeGGGeeG",
      "GGGeGGGeeeeeeeee",
      "GGeGGeGGeeeGeGGG",
      "GGGGGGeGGeGeGGGe",
      "GGGGGGGGeGeGGGGG"
    ],
    [
      "ffffffffffffffff",
      "f        g   g f",
      "f            g f",
      "f             gf",
      "f              f",
      "f              f",
      "f             gf",
      "f             gf",
      "ff           gff",
      "hff        g ff ",
      " hffffffi jffj  ",
      "h  hh hk   i    ",
      "hhh h           ",
      "hh  h           ",
      "  h h           ",
      "hfhf h       l i"
    ],
    [
      "                ",
      "         ~   ~  ",
      "             g  ",
      "              ~ ",
      "                ",
      "                ",
      "              g ",
      "              g ",
      "             g  ",
      "m          ~    ",
      " m              ",
      "m  mm m         ",
      "mmm m           ",
      "mm  m           ",
      "  m m           ",
      "m m  m       ~  "
    ],
    [
      "                ",
      "                ",
      "             g  ",
      "                ",
      "                ",
      "                ",
      "              g ",
      "              g ",
      "             ~  ",
      "                ",
      "                ",
      "                ",
      "                ",
      "                ",
      "                ",
      "                "
    ],
    [
      "                ",
      "                ",
      "             ~  ",
      "                ",
      "                ",
      "                ",
      "              g ",
      "              ~ ",
      "                ",
      "                ",
      "                ",
      "                ",
      "                ",
      "                ",
      "                ",
      "                "
    ],
    [
      "                ",
      "                ",
      "                ",
      "                ",
      "                ",
      "                ",
      "              ~ ",
      "                ",
      "                ",
      "                ",
      "                ",
      "                ",
      "                ",
      "                ",
      "                ",
      "                "
    ]
  ]
}