{
  "name": "farmhouse_1_8",
  "refpalette": "c70cities:farmhouse_1_8_palette",
  "xsize": 16,
  "zsize": 16,
  "slices": [
    [
      "aaaaaaaaaaaaaaaa",
      "aaaaaaaaaaaaaaaa",
      "aaaaaaaaaaaaaaaa",
      "aaaaaaaaaaaaaaaa",
      "aaaaaaaaaaaaaaaa",
      "aaaaaaaaaaaaaaaa",
      "aaaaaaaaaaaaaaaa",
      "aaaaaaaaaaaaaaaa",
      "aaaaaaaaaaaaaaaa",
      "aaaaaaaaaaaaaaaa",
      "aaaaaaaaaaaaaaaa",
      "aaaaaaaaaaaaaaaa",
      "aaaaaaaaaaaaaaaa",
      "aaaaaaaaaaaaaaaa",
      "aaaaaaaaaaaaaaaa",
      "aaaaaaaaaaaaaaaa"
    ],
    [
      "aaaaaaaaaaaaaaaa",
      "aaaaaaaaaaaaaaaa",
      "aaaaaaaaaaaaaaaa",
      "aaaaaaaaaaaaaaaa",
      "aaaaaaaaaaaaaaaa",
      "aaaaaaaaaaaaaaaa",
      "aaaaaaaaaaaaaaaa",
      "aaaaaaaaaaaaaaaa",
      "aaaaaaaaaaaaaaaa",
      "aaaaaaaaaaaaaaaa",
      "aaaaaaaaaaaaaaaa",
      "aaaaaaaaaaaaaaaa",
      "aaaaaaaaaaaaaaaa",
      "aaaaaaaaaaaaaaaa",
      "aaaaaaaaaaaaaaaa",
      "aaaaaaaaaaaaaaaa"
    ],
    [
      "bGGbbbbGGccccGGG",
      "bbbbbGbGccccccGG",
      "GbbGbGGcccccccGG",
      "bbGbGGGcccccccGG",
      "GbbbGGGcccccccGG",
      "bGbGGGGcccccccGG",
      "GbbGGGGcccccccGG",
      "GbGGGGGcccccccGG",
      "bbGGGGGcccccccGG",
      "bGbGGGGcccccccGG",
      "bbGGGGGcccccccGG",
      "bbGGGGGcccccccGG",
      "bGGGGGGcccccccGG",
      "GGGGGGGcccccccGG",
      "GGGGGGGGGGGGGGGG",
      "GGGGGGGGGGGGGGGG"
    ],
    [
      "               d",
      "               d",
      "      e       fd",
      "      eghhhhhgfd",
      "      e       fd",
      "      e ijjji fd",
      "      e  jjj  f ",
      "      e  jjj  fd",
      "      e kjjjk fd",
      "      e ljjjl fm",
      "      e   n   fd",
      "      e nnnnn fd",
      "   o  e       fd",
      "      egggggggfd",
      "   p  e       fd",
      " d ddddddmd dddd"
    ],
    [
      "                ",
      "                ",
      "      e       f ",
      "      eghhhhhgf ",
      "      e  q q  f ",
      "      e rstsu f ",
      "      e  sss  f ",
      "      e wsss  f ",
      "      e xysyx f ",
      "      e AysyA f ",
      "      e  BnB  f ",
      "      e   n   f ",
      "   ~  e       f ",
      "      egggggggf ",
      "      e       f ",
      "                "
    ],
    [
      "                ",
      "                ",
      "      e       f ",
      "      eghhhhhgf ",
      "      e       f ",
      "      e  CCC  f ",
      "      e  sDE  f ",
      "      e  F I  f ",
      "      e rIJIu f ",
      "      e rKLKu f ",
      "      e  BBB  f ",
      "      e       f ",
      "      e       f ",
      "      egggggggf ",
      "      e       f ",
      "                "
    ],
    [
      "                ",
      "                ",
      "      ef     ef ",
      "      eghhhhhgf ",
      "      ef     ef ",
      "      ef     ef ",
      "      ef MMN ef ",
      "      ef O I ef ",
      "      ef I I ef ",
      "      ef I I ef ",
      "      ef PPP ef ",
      "      ef     ef ",
      "      ef     ef ",
      "      egggggggf ",
      "      ef     ef ",
      "                "
    ],
    [
      "                ",
      "                ",
      "       Qf   eR  ",
      "       QhhhhhR  ",
      "       Qf   eR  ",
      "       Qf   eR  ",
      "       Qf  NeR  ",
      "       QfSSSeR  ",
      "       QfSSSeR  ",
      "       QfSSSeR  ",
      "       Qf   eR  ",
      "       Qf   eR  ",
      "       Qf   eR  ",
      "       QgghggR  ",
      "       Qf   eR  ",
      "                "
    ],
    [
      "                ",
      "                ",
      "        Qf eR   ",
      "        QgggR   ",
      "        Qf eR   ",
      "        Qf eR   ",
      "        Qf eR   ",
      "        Qf eR   ",
      "        Qf eR   ",
      "        Qf eR   ",
      "        Qf eR   ",
      "        Qf eR   ",
      "        Qf eR   ",
      "        QgggR   ",
      "        Qf eR   ",
      "                "
    ],
    [
      "                ",
      "                ",
      "         QTR    ",
      "         QgR    ",
      "         QTR    ",
      "         QTR    ",
      "         QTR    ",
      "         QTR    ",
      "         QTR    ",
      "         QTR    ",
      "         QTR    ",
      "         QTR    ",
      "         QTR    ",
      "         QgR    ",
      "         QTR    ",
      "                "
    ],
    [
      "                ",
      "                ",
      "          U     ",
      "          U     ",
      "          U     ",
      "          U     ",
      "          U     ",
      "          U     ",
      "          U     ",
      "          U     ",
      "          U     ",
      "          U     ",
      "          U     ",
      "          U     ",
      "          U     ",
      "                "
    ]
  ]
}