{
  "name": "foodtruck_1",
  "refpalette": "c70cities:foodtruck_1_palette",
  "xsize": 16,
  "zsize": 16,
  "slices": [
    [
      "aaaaaaaaaaaaaaaa",
      "aaaaaaaaaaaaaaaa",
      "aaaaaaaaaaaaaaaa",
      "aaaaaaaaaaaaaaaa",
      "aaaaaaaaaaaaaaaa",
      "aaaaaaaaaaaaaaaa",
      "aaaaaaaaaaaaaaaa",
      "aaaaaaaaaaaaaaaa",
      "aaaaaaaaaaaaaaaa",
      "aaaaaaaaaaaaaaaa",
      "aaaaaaaaaaaaaaaa",
      "aaaaaaaaaaaaaaaa",
      "aaaaaaaaaaaaaaaa",
      "aaaaaaaaaaaaaaaa",
      "aaaaaaaaaaaaaaaa",
      "aaaaaaaaaaaaaaaa"
    ],
    [
      "aaaaaaaaaaaaaaaa",
      "aaaaaaaaaaaaaaaa",
      "aaaaaaaaaaaaaaaa",
      "aaaaaaaaaaaaaaaa",
      "aaaaaaaaaaaaaaaa",
      "aaaaaaaaaaaaaaaa",
      "aaaaaaaaaaaaaaaa",
      "aaaaaaaaaaaaaaaa",
      "aaaaaaaaaaaaaaaa",
      "aaaaaaaaaaaaaaaa",
      "aaaaaaaaaaaaaaaa",
      "aaaaaaaaaaaaaaaa",
      "aaaaaaaaaaaaaaaa",
      "aaaaaaaaaaaaaaaa",
      "aaaaaaaaaaaaaaaa",
      "aaaaaaaaaaaaaaaa"
    ],
    [
      "GGGGGGGGbGGbbbGb",
      "GGGGGGGGGGcbbbbG",
      "GGGGGGGGGbbbbbbc",
      "GGGGGGGGGGbdbbdb",
      "GGGGGGGGGGGdbbdb",
      "GGGGGGGGGGcdbbdb",
      "GGGGGGGGGcbdbbdb",
      "GGGbGGGGGcGdbbdG",
      "GcGGGGGcGGbdbbcb",
      "GGGGGbcbGbGdbbdG",
      "bGGcbbbbbcbdbbdb",
      "GGGbbbbbbbbdbbdb",
      "GGbGbbbbbGbdbbdb",
      "cGGbbbbbGbbdbbdb",
      "GcGGbbbGbGbdbbdb",
      "GbGGGGcGGcGdbbdG"
    ],
    [
      "          e     ",
      "                ",
      "           ffff ",
      "          ghffhi",
      "         e ffff ",
      "           ffff ",
      "           ffff ",
      "          ghffhi",
      "      e     jj  ",
      "           kkkke",
      "     l m  nkook ",
      "      p q  kook ",
      "        r ghsshi",
      "     tume ghsshi",
      "                ",
      "          e     "
    ],
    [
      "                ",
      "           w  w ",
      "           xyyA ",
      "           BCCD ",
      "          EFIIF ",
      "            JJK ",
      "           LMMK ",
      "           BNOD ",
      "           PPPP ",
      "           QRRQ ",
      "       m   S  T ",
      "           U  T ",
      "           VWWX ",
      "       m   VYYX ",
      "           ZZZZ ",
      "                "
    ],
    [
      "                ",
      "                ",
      "            00  ",
      "           0000 ",
      "          12332 ",
      "              4 ",
      "           5  4 ",
      "           F  F ",
      "           P66P ",
      "           Q66Q ",
      "       m   7  4 ",
      "           U  T ",
      "           5  4 ",
      "       m   5  4 ",
      "           Z66Z ",
      "                "
    ],
    [
      "                ",
      "                ",
      "                ",
      "                ",
      "            00  ",
      "           0000 ",
      "           0000 ",
      "           0000 ",
      "                ",
      "           8QQ8 ",
      "      9@@@@QkkQ ",
      "      9@@@@QkkQ ",
      "      9@@@@#QQ# ",
      "      9@@@@$$$$ ",
      "                ",
      "                "
    ]
  ]
}