{
  "name": "foodtruck_1",
  "refpalette": "c70cities:foodtruck_1_palette",
  "xsize": 16,
  "zsize": 16,
  "slices": [
    [
      "aaaaaaaaaaaaaaaa",
      "aaaaaaaaaaaaaaaa",
      "aaaaaaaaaaaaaaaa",
      "aaaaaaaaaaaaaaaa",
      "aaaaaaaaaaaaaaaa",
      "aaaaaaaaaaaaaaaa",
      "aaaaaaaaaaaaaaaa",
      "aaaaaaaaaaaaaaaa",
      "aaaaaaaaaaaaaaaa",
      "aaaaaaaaaaaaaaaa",
      "aaaaaaaaaaaaaaaa",
      "aaaaaaaaaaaaaaaa",
      "aaaaaaaaaaaaaaaa",
      "aaaaaaaaaaaaaaaa",
      "aaaaaaaaaaaaaaaa",
      "aaaaaaaaaaaaaaaa"
    ],
    [
      "aaaaaaaaaaaaaaGG",
      "aaaaaaaaaaaaaaaG",
      "aaaaaaaaaaaaaaaG",
      "aaaaaaaaaaaaaaaa",
      "aaaaaaaaaaaaaaaa",
      "aaaaaaaaaaaaaaaa",
      "aaaaaaaaaaaaaaaa",
      "aaaaaaaaaaaaaaaa",
      "aaaaaaaaaaaaaaaa",
      "aaaaaaaaaaaaaaaa",
      "aaaaaaaaaaaaaaaa",
      "aaaaaaaaaaaaaaaa",
      "aaaaaaaaaaaaaaaa",
      "aaaaaaaaaaaaaaaa",
      "aaaaaaaaaaaaaaGa",
      "aaaaaaaaaaaaaGGG"
    ],
    [
      "GGGGGGGGGGGGGG  ",
      "GGGbGGbcGGGGGGG ",
      "GGbcbGGGGbbGGGG ",
      "GGbbbbcGbbGGcGGG",
      "GGcbbbbbbbbGGGGG",
      "GbGbbbbbbcGaGGGG",
      "GGGGbbddeeecGbGG",
      "GGGbbbdddeebcGGG",
      "GcGcfbddeeebGGGG",
      "GfcGffdeeeebGGGG",
      "fGffGcdeeeecGGGG",
      "GGcGGbedeeeGbGGG",
      "GGGGGGeeeeeGbGGG",
      "GGGGcaGGbcGaGGGG",
      "GGGcGGGGGGGGGG G",
      "GGGGGGcGGGGGG   "
    ],
    [
      "                ",
      "                ",
      "   g      h  i  ",
      "  ij k  ljj     ",
      "   ljjijmno     ",
      " i  mpoj jiq    ",
      "    jlrssttj i  ",
      "    ujrwkxtu i  ",
      "      r y rh    ",
      "      A  Btq    ",
      "     Cl  Dth    ",
      "     jrkhCE m   ",
      "      EE tEij   ",
      "    iF  juIF    ",
      " i              ",
      "      j    i    "
    ],
    [
      "                ",
      "                ",
      "   g            ",
      "                ",
      "                ",
      "     p     p    ",
      "      JJk sk    ",
      "      K   r     ",
      "      r   E     ",
      "      L   rq    ",
      "         Mt     ",
      "      K   r     ",
      "      ttKkE     ",
      "     F     F    ",
      "                ",
      "                "
    ],
    [
      "                ",
      "                ",
      "                ",
      "                ",
      "                ",
      "     pk   kp    ",
      "     krsJkJk    ",
      "     krNNOrk    ",
      "      rNNkrk    ",
      "      rNN tq    ",
      "       NN r     ",
      "      rON t     ",
      "      tJtJt     ",
      "     q   kkF    ",
      "                ",
      "                "
    ],
    [
      "                ",
      "                ",
      "                ",
      "                ",
      "    nnnn  nnn   ",
      "     pPPPPPpQ   ",
      "     RhCu wS    ",
      "     RTCU lS    ",
      "     Rh C  S    ",
      "     RToU  S    ",
      "     RV h  S    ",
      "     SkC  lW    ",
      "     SVy xyW    ",
      "    XqYYYYZFX   ",
      "    010110000   ",
      "                "
    ],
    [
      "                ",
      "                ",
      "                ",
      "                ",
      "                ",
      "    nMMMMkMMn   ",
      "    Qsk   ktQ   ",
      "     r          ",
      "     r     t    ",
      "     ph    q    ",
      "     r     t    ",
      "     r     t    ",
      "    2rk   kEX   ",
      "    133333340   ",
      "                ",
      "                "
    ],
    [
      "                ",
      "                ",
      "                ",
      "                ",
      "                ",
      "                ",
      "    nM MMMBB5   ",
      "    kJ    ktQ   ",
      "     r     E    ",
      "     p     F    ",
      "     r    k     ",
      "    2r    kt    ",
      "    063344431   ",
      "                ",
      "                ",
      "                "
    ],
    [
      "                ",
      "                ",
      "                ",
      "                ",
      "                ",
      "                ",
      "                ",
      "    nMMk MMB5   ",
      "    Qr    kE7   ",
      "     p     F    ",
      "    Xtk   kEX   ",
      "    133 66330   ",
      "                ",
      "                ",
      "                ",
      "                "
    ],
    [
      "                ",
      "                ",
      "                ",
      "                ",
      "                ",
      "                ",
      "                ",
      "                ",
      "    nMk   BB5   ",
      "    8p    kF9   ",
      "    1666  341   ",
      "                ",
      "                ",
      "                ",
      "                ",
      "                "
    ],
    [
      "                ",
      "                ",
      "                ",
      "                ",
      "                ",
      "                ",
      "                ",
      "                ",
      "                ",
      "    mCC  @@#m   ",
      "                ",
      "                ",
      "                ",
      "                ",
      "                ",
      "                "
    ]
  ]
}