{
  "name": "foodtruck_1",
  "refpalette": "c70cities:foodtruck_1_palette",
  "xsize": 16,
  "zsize": 16,
  "slices": [
    [
      "aaaaaaaaaaaaaaaa",
      "aaaaaaaaaaaaaaaa",
      "aaaaaaaaaaaaaaaa",
      "aaaaaaaaaaaaaaaa",
      "aaaaaaaaaaaaaaaa",
      "aaaaaaaaaaaaaaaa",
      "aaaaaaaaaaaaaaaa",
      "aaaaaaaaaaaaaaaa",
      "aaaaaaaaaaaaaaaa",
      "aaaaaaaaaaaaaaaa",
      "aaaaaaaaaaaaaaaa",
      "aaaaaaaaaaaaaaaa",
      "aaaaaaaaaaaaaaaa",
      "aaaaaaaaaaaaaaaa",
      "aaaaaaaaaaaaaaaa",
      "aaaaaaaaaaaaaaaa"
    ],
    [
      "aaaaaaaaaaaaaaaa",
      "aaaaaaaaaaaaaaaa",
      "aaaaaaaaaaaaaaaa",
      "aaaaaaaaaaaaaaaa",
      "aaaaaaaaaaaaaaaa",
      "aaaaaaaaaaaaaaaa",
      "aaaaaaaaaaaaaaaa",
      "aaaaaaaaaaaaaaaa",
      "aaaaaaaaaaaaaaaa",
      "aaaaaaaaaaaaaaaa",
      "aaaaaaaaaaaaaaaa",
      "aaaaaaaaaaaaaaaa",
      "aaaaaaaaaaaaaaaa",
      "aaaaaaaaaaaaaaaa",
      "aaaaaaaaaaaaaaaa",
      "aaaaaaaaaaaaaaaa"
    ],
    [
      "GGGGGGGGbGGbbbGb",
      "GGGGGGGGGGcbbbbG",
      "GGGGGGGGGbbbbbbc",
      "GGGGGGGGGGbdbbdb",
      "GGGGGGGGGGGdbbdb",
      "GGGGGGGGGGcdbbdb",
      "GGGGGGGGGcbdbbdb",
      "GGGbGGGGGcGdbbdG",
      "GcGGGGGcGGbdbbcb",
      "GGGGGbcbGbGdbbdG",
      "bGGcbbbbbcbdbbdb",
      "GGGbbbbbbbbdbbdb",
      "GGbGbbbbbGbdbbdb",
      "cGGbbbbbGbbdbbdb",
      "GcGGbbbGbGbdbbdb",
      "GbGGGGcGGcGdbbdG"
    ],
    [
      "   e   f  g     ",
      " e   e  e       ",
      " ef eehee  iiii ",
      "eeee ee f jkiikl",
      "  hef    g iiii ",
      "f     fe   iiii ",
      " ee  e     iiii ",
      " e    e   jkiikl",
      "   f  g     mm  ",
      "fe e       nnnng",
      " e   o p  qnrrn ",
      "e e   s t  nrrn ",
      "ef      u jkwwkl",
      "     xypg jkwwkl",
      "  f             ",
      "   ee     g     "
    ],
    [
      "                ",
      "           A  A ",
      "      B    CDDE ",
      "           FIIJ ",
      "  B       KLMML ",
      "            NNO ",
      "           PQQO ",
      "           FRSJ ",
      "           TTTT ",
      "           UVVU ",
      "       p   W  X ",
      "           Y  X ",
      "           Z001 ",
      "       p   Z221 ",
      "           3333 ",
      "                "
    ],
    [
      "                ",
      "                ",
      "            44  ",
      "           4444 ",
      "          56776 ",
      "              8 ",
      "           9  8 ",
      "           L  L ",
      "           T@@T ",
      "           U@@U ",
      "       p   #  8 ",
      "           Y  X ",
      "           9  8 ",
      "       p   9  8 ",
      "           3@@3 ",
      "                "
    ],
    [
      "                ",
      "                ",
      "                ",
      "                ",
      "            44  ",
      "           4444 ",
      "           4444 ",
      "           4444 ",
      "                ",
      "           $UU$ ",
      "      %^^^^UnnU ",
      "      %^^^^UnnU ",
      "      %^^^^&UU& ",
      "      %^^^^**** ",
      "                ",
      "                "
    ]
  ]
}