{
  "name": "fountain_4",
  "refpalette": "c70cities:fountain_4_palette",
  "xsize": 16,
  "zsize": 16,
  "slices": [
    [
      "aaaaaaaaaaaaaaaa",
      "aGGGbbbbbbbbbGGa",
      "aGccbdddddddbcca",
      "aeeeeeddddddbcca",
      "aedddeddddddbcca",
      "aedddfddddfdbcca",
      "aedddeddddddbcca",
      "aedgggggddddbcca",
      "aedgdddgeeeeeeca",
      "aeegdddgdddddeca",
      "aGhgdfdgddfddeca",
      "aGfgdddgdddddeca",
      "aGfgggggdddddeGa",
      "aGfddddedddddeGa",
      "aGhfffheeeeeeeGa",
      "aaaaaaaaaaaaaaaa"
    ],
    [
      "                ",
      "    bbbbbbbbb   ",
      "    biiiijiib   ",
      " keeeeiiiiiib   ",
      " kdddliiiiiib   ",
      " kdddfiiiifib   ",
      " kdddeiiiiiib   ",
      " kdgggggiiiib   ",
      " kdgdddgeleeee  ",
      " kkgdddgddddde  ",
      "  mgdfdgddfdde  ",
      "  mgdddgddddde  ",
      "  mgggggdddddk  ",
      "  m    kdddddk  ",
      "  mmmmmkkkkkkk  ",
      "                "
    ],
    [
      "                ",
      "                ",
      "                ",
      " eeeee          ",
      " eiiiii         ",
      " eiiif    f     ",
      " eiiie          ",
      " eiglggg i      ",
      " eigdddgeieeee  ",
      " eegdddgiiiiie  ",
      "   gdfdgiifiie  ",
      "   gdddliiiiie  ",
      "   gggggiiiije  ",
      "       eiiijje  ",
      "       eeeeeee  ",
      "                "
    ],
    [
      "                ",
      "                ",
      "                ",
      "                ",
      "                ",
      "     f    f     ",
      "    i           ",
      "   giggg        ",
      "   giiigkkkkkk  ",
      "   giiig     k  ",
      "   gifig  f  k  ",
      "   giiiii    k  ",
      "   ggggg     k  ",
      "       k     k  ",
      "       kkkkkkk  ",
      "                "
    ],
    [
      "                ",
      "                ",
      "                ",
      "                ",
      "                ",
      "     f    f     ",
      "                ",
      "                ",
      "                ",
      "                ",
      "     f    f     ",
      "                ",
      "                ",
      "                ",
      "                ",
      "                "
    ],
    [
      "                ",
      "                ",
      "                ",
      "                ",
      "                ",
      "     nnnnnn     ",
      "     n    n     ",
      "     n    n     ",
      "     n    n     ",
      "     n    n     ",
      "     nnnnnn     ",
      "                ",
      "                ",
      "                ",
      "                ",
      "                "
    ]
  ]
}