{
  "name": "fountain_4",
  "refpalette": "c70cities:fountain_4_palette",
  "xsize": 16,
  "zsize": 16,
  "slices": [
    [
      "aaaaaaaaaaaaaaaa",
      "aGGGbbbbbbbbbGGa",
      "aGccbdddddddbcca",
      "aeeeeeddddddbcca",
      "aedddeddddddbcca",
      "aedddfddddfdbcca",
      "aedddeddddddbcca",
      "aedgggggddddbcca",
      "aedgdddgeeeeeeca",
      "aeegdddgdddddeca",
      "aGhgdfdgddfddeca",
      "aGfgdddgdddddeca",
      "aGfgggggdddddeGa",
      "aGfddddedddddeGa",
      "aGhfffheeeeeeeGa",
      "aaaaaaaaaaaaaaaa"
    ],
    [
      "                ",
      "    bbbbbbbbb   ",
      "    biiiiiiib   ",
      " jeeeeiiiiiib   ",
      " jdddkiiiiiib   ",
      " jdddfiiiifib   ",
      " jdddeiiiiiib   ",
      " jdgggggiiiib   ",
      " jdgdddgekeeee  ",
      " jjgdddgddddde  ",
      "  lgdfdgddfdde  ",
      "  lgdddgddddde  ",
      "  lgggggdddddj  ",
      "  l    jdddddj  ",
      "  llllljjjjjjj  ",
      "                "
    ],
    [
      "                ",
      "                ",
      "                ",
      " eeeee          ",
      " eiiiii         ",
      " eiiif    f     ",
      " eiiie          ",
      " eigkggg i      ",
      " eigdddgeieeee  ",
      " eegdddgiiiiie  ",
      "   gdfdgiifiie  ",
      "   gdddkiiiiie  ",
      "   gggggiiiime  ",
      "       eiiiiie  ",
      "       eeeeeee  ",
      "                "
    ],
    [
      "                ",
      "                ",
      "                ",
      "                ",
      "                ",
      "     f    f     ",
      "    i           ",
      "   giggg        ",
      "   giiigjjjjjj  ",
      "   giiig     j  ",
      "   gifig  f  j  ",
      "   giiiii    j  ",
      "   ggggg     j  ",
      "       j     j  ",
      "       jjjjjjj  ",
      "                "
    ],
    [
      "                ",
      "                ",
      "                ",
      "                ",
      "                ",
      "     f    f     ",
      "                ",
      "                ",
      "                ",
      "                ",
      "     f    f     ",
      "                ",
      "                ",
      "                ",
      "                ",
      "                "
    ],
    [
      "                ",
      "                ",
      "                ",
      "                ",
      "                ",
      "     nnnnnn     ",
      "     n    n     ",
      "     n    n     ",
      "     n    n     ",
      "     n    n     ",
      "     nnnnnn     ",
      "                ",
      "                ",
      "                ",
      "                ",
      "                "
    ]
  ]
}