{
  "name": "front_1",
  "refpalette": "c70cities:front_1_palette",
  "xsize": 16,
  "zsize": 16,
  "slices": [
    [
      "abba            ",
      "abbc            ",
      "abbc            ",
      "abba            ",
      "abba            ",
      "abbc            ",
      "cbba            ",
      "cbba            ",
      "dbba            ",
      "abba            ",
      "abba            ",
      "cbba            ",
      "abba            ",
      "abbc            ",
      "abbc            ",
      "abba            "
    ],
    [
      "cccc            ",
      "cccc            ",
      "cccc            ",
      "cccc            ",
      "cccc            ",
      "cccc            ",
      "cccc            ",
      "cccc            ",
      "eccc            ",
      "cccc            ",
      "cccc            ",
      "cccc            ",
      "cccc            ",
      "cccc            ",
      "cccc            ",
      "cccc            "
    ],
    [
      "cccc            ",
      "cccc            ",
      "cccc            ",
      "cccc            ",
      "cccc            ",
      "cccc            ",
      "cccc            ",
      "cccc            ",
      "eccc            ",
      "cccc            ",
      "cccc            ",
      "cccc            ",
      "cccc            ",
      "cccc            ",
      "cccc            ",
      "cccc            "
    ],
    [
      "cccc            ",
      "cccc            ",
      "cccc            ",
      "cccc            ",
      "cccc            ",
      "cccc            ",
      "cccc            ",
      "cccc            ",
      "eccc            ",
      "cccc            ",
      "cccc            ",
      "cccc            ",
      "cccc            ",
      "cccc            ",
      "cccc            ",
      "cccc            "
    ],
    [
      "cccc            ",
      "cccc            ",
      "cccc            ",
      "cccc            ",
      "cccc            ",
      "cccc            ",
      "cccc            ",
      "cccc            ",
      "ffcg            ",
      "cccc            ",
      "cccc            ",
      "cccc            ",
      "cccc            ",
      "cccc            ",
      "cccc            ",
      "cccc            "
    ],
    [
      "cccc            ",
      "cccc            ",
      "cccc            ",
      "cccc            ",
      "cccc            ",
      "cccc            ",
      "cccc            ",
      "cccc            ",
      "chhi            ",
      "cccc            ",
      "cccc            ",
      "cccc            ",
      "cccc            ",
      "cccc            ",
      "cccc            ",
      "cccc            "
    ],
    [
      "cccc            ",
      "cccc            ",
      "cccc            ",
      "cccc            ",
      "cccc            ",
      "cccc            ",
      "cccc            ",
      "cccc            ",
      "cccc            ",
      "cccc            ",
      "cccc            ",
      "cccc            ",
      "cccc            ",
      "cccc            ",
      "cccc            ",
      "cccc            "
    ]
  ]
}