{
  "name": "front_1",
  "refpalette": "c70cities:front_1_palette",
  "xsize": 16,
  "zsize": 16,
  "slices": [
    [
      "abba            ",
      "abb~            ",
      "abb~            ",
      "abba            ",
      "abba            ",
      "abb~            ",
      "~bba            ",
      "~bba            ",
      "cbba            ",
      "abba            ",
      "abba            ",
      "~bba            ",
      "abba            ",
      "abb~            ",
      "abb~            ",
      "abba            "
    ],
    [
      "~~~~            ",
      "~~~~            ",
      "~~~~            ",
      "~~~~            ",
      "~~~~            ",
      "~~~~            ",
      "~~~~            ",
      "~~~~            ",
      "d~~~            ",
      "~~~~            ",
      "~~~~            ",
      "~~~~            ",
      "~~~~            ",
      "~~~~            ",
      "~~~~            ",
      "~~~~            "
    ],
    [
      "~~~~            ",
      "~~~~            ",
      "~~~~            ",
      "~~~~            ",
      "~~~~            ",
      "~~~~            ",
      "~~~~            ",
      "~~~~            ",
      "d~~~            ",
      "~~~~            ",
      "~~~~            ",
      "~~~~            ",
      "~~~~            ",
      "~~~~            ",
      "~~~~            ",
      "~~~~            "
    ],
    [
      "~~~~            ",
      "~~~~            ",
      "~~~~            ",
      "~~~~            ",
      "~~~~            ",
      "~~~~            ",
      "~~~~            ",
      "~~~~            ",
      "d~~~            ",
      "~~~~            ",
      "~~~~            ",
      "~~~~            ",
      "~~~~            ",
      "~~~~            ",
      "~~~~            ",
      "~~~~            "
    ],
    [
      "~~~~            ",
      "~~~~            ",
      "~~~~            ",
      "~~~~            ",
      "~~~~            ",
      "~~~~            ",
      "~~~~            ",
      "~~~~            ",
      "ee~f            ",
      "~~~~            ",
      "~~~~            ",
      "~~~~            ",
      "~~~~            ",
      "~~~~            ",
      "~~~~            ",
      "~~~~            "
    ],
    [
      "                ",
      "                ",
      "                ",
      "                ",
      "                ",
      "                ",
      "                ",
      "                ",
      " ggh            ",
      "                ",
      "                ",
      "                ",
      "                ",
      "                ",
      "                ",
      "                "
    ]
  ]
}