{
  "name": "front_4",
  "refpalette": "c70cities:front_4_palette",
  "xsize": 16,
  "zsize": 16,
  "slices": [
    [
      "aaaaaa          ",
      "abbbba          ",
      "abccba          ",
      "ddaaea          ",
      "aadfga          ",
      "aaaaaa          ",
      "adaaaa          ",
      "aaaaaa          ",
      "aaadaa          ",
      "aaaaaa          ",
      "adaaaa          ",
      "aahdga          ",
      "aiaaja          ",
      "dbccba          ",
      "abbbba          ",
      "aadada          "
    ],
    [
      "aaaaaa          ",
      "aaaaaa          ",
      "aaaaaa          ",
      "aaaaaa          ",
      "aaaaga          ",
      "aaaaaa          ",
      "aaaaaa          ",
      "aaaaaa          ",
      "aaaaaa          ",
      "aaaaaa          ",
      "aaaaaa          ",
      "aaaaga          ",
      "aaaaaa          ",
      "aaaaaa          ",
      "aaaaaa          ",
      "aaaaaa          "
    ],
    [
      "aaaaaa          ",
      "aaaaaa          ",
      "aaaaaa          ",
      "aaaaaa          ",
      "aaaaga          ",
      "aaaaaa          ",
      "aaaaaa          ",
      "aaaaaa          ",
      "aaaaaa          ",
      "aaaaaa          ",
      "aaaaaa          ",
      "aaaaga          ",
      "aaaaaa          ",
      "aaaaaa          ",
      "aaaaaa          ",
      "aaaaaa          "
    ],
    [
      "aaaaaa          ",
      "aaaaaa          ",
      "aaaaaa          ",
      "aaaaaa          ",
      "aaaagk          ",
      "aaaaaa          ",
      "aaaaaa          ",
      "aaaaaa          ",
      "aaaaaa          ",
      "aaaaaa          ",
      "aaaaaa          ",
      "aaaagk          ",
      "aaaaaa          ",
      "aaaaaa          ",
      "aaaaaa          ",
      "aaaaaa          "
    ],
    [
      "aaaaaa          ",
      "aaaaaa          ",
      "aaaaaa          ",
      "aaaaaa          ",
      "aaaagg          ",
      "aaaaaa          ",
      "aaaaaa          ",
      "aaaaaa          ",
      "aaaaaa          ",
      "aaaaaa          ",
      "aaaaaa          ",
      "aaaagg          ",
      "aaaaaa          ",
      "aaaaaa          ",
      "aaaaaa          ",
      "aaaaaa          "
    ],
    [
      "aaaaaa          ",
      "aaaaaa          ",
      "aaaaaa          ",
      "aaaaaa          ",
      "aaaaaa          ",
      "aaaaaa          ",
      "aaaaaa          ",
      "aaaaaa          ",
      "aaaaaa          ",
      "aaaaaa          ",
      "aaaaaa          ",
      "aaaaaa          ",
      "aaaaaa          ",
      "aaaaaa          ",
      "aaaaaa          ",
      "aaaaaa          "
    ]
  ]
}