{
  "name": "front_3",
  "refpalette": "c70cities:front_3_palette",
  "xsize": 16,
  "zsize": 16,
  "slices": [
    [
      "aaaaaa          ",
      "aabaca          ",
      "aaaaaa          ",
      "adddda          ",
      "aeeeaa          ",
      "aeefaa          ",
      "aeefaa          ",
      "aeefaa          ",
      "aeefaa          ",
      "aeefaa          ",
      "aeefaa          ",
      "aeeega          ",
      "adddda          ",
      "aaaaaa          ",
      "aabaaa          ",
      "aaaaaa          "
    ],
    [
      "aaaaaa          ",
      "aahaaa          ",
      "aaaaaa          ",
      "aaaaaa          ",
      "aiaiaa          ",
      "aajaaa          ",
      "aajaaa          ",
      "aaaaaa          ",
      "aaaaaa          ",
      "aajaaa          ",
      "aajaaa          ",
      "aiaiaa          ",
      "aaaaaa          ",
      "aaaaaa          ",
      "aahaaa          ",
      "aaaaaa          "
    ],
    [
      "aaaaaa          ",
      "aadaaa          ",
      "aaaaaa          ",
      "aaaaaa          ",
      "aikiaa          ",
      "aiaaaa          ",
      "aiaaaa          ",
      "aiaaaa          ",
      "aiaaaa          ",
      "aiaaaa          ",
      "aiaaaa          ",
      "aikiaa          ",
      "aaaaaa          ",
      "aaaaaa          ",
      "aadaaa          ",
      "aaaaaa          "
    ],
    [
      "aaaaaa          ",
      "aadaaa          ",
      "aaaaaa          ",
      "almaaa          ",
      "aniiaa          ",
      "anaiaa          ",
      "anaiaa          ",
      "anaiaa          ",
      "anaiaa          ",
      "anaiaa          ",
      "anaiaa          ",
      "aniiaa          ",
      "almaaa          ",
      "aaaaaa          ",
      "aadaaa          ",
      "aaaaaa          "
    ],
    [
      "aaaaaa          ",
      "aahaaa          ",
      "aaaaaa          ",
      "aaoooa          ",
      "aappoa          ",
      "aappoa          ",
      "aappoa          ",
      "aappoa          ",
      "aappoa          ",
      "aappoa          ",
      "aappoa          ",
      "aappoa          ",
      "aaoooa          ",
      "aaaaaa          ",
      "aahaaa          ",
      "aaaaaa          "
    ],
    [
      "aaaaaa          ",
      "aaaaaa          ",
      "aaaaaa          ",
      "aaaaaa          ",
      "aaaaaa          ",
      "aaaaaa          ",
      "aaaaaa          ",
      "aaaaaa          ",
      "aaaaaa          ",
      "aaaaaa          ",
      "aaaaaa          ",
      "aaaaaa          ",
      "aaaaaa          ",
      "aaaaaa          ",
      "aaaaaa          ",
      "aaaaaa          "
    ]
  ]
}