{
  "name": "front_4",
  "refpalette": "c70cities:front_4_palette",
  "xsize": 16,
  "zsize": 16,
  "slices": [
    [
      "~~~~~~          ",
      "~aaaa~          ",
      "~abba~          ",
      "cc~~d~          ",
      "~~cef~          ",
      "~~~~~~          ",
      "~c~~~~          ",
      "~~~~~~          ",
      "~~~c~~          ",
      "~~~~~~          ",
      "~c~~~~          ",
      "~~gcf~          ",
      "~h~~i~          ",
      "cabba~          ",
      "~aaaa~          ",
      "~~c~c~          "
    ],
    [
      "~~~~~~          ",
      "~~~~~~          ",
      "~~~~~~          ",
      "~~~~~~          ",
      "~~~~f~          ",
      "~~~~~~          ",
      "~~~~~~          ",
      "~~~~~~          ",
      "~~~~~~          ",
      "~~~~~~          ",
      "~~~~~~          ",
      "~~~~f~          ",
      "~~~~~~          ",
      "~~~~~~          ",
      "~~~~~~          ",
      "~~~~~~          "
    ],
    [
      "~~~~~~          ",
      "~~~~~~          ",
      "~~~~~~          ",
      "~~~~~~          ",
      "~~~~f~          ",
      "~~~~~~          ",
      "~~~~~~          ",
      "~~~~~~          ",
      "~~~~~~          ",
      "~~~~~~          ",
      "~~~~~~          ",
      "~~~~f~          ",
      "~~~~~~          ",
      "~~~~~~          ",
      "~~~~~~          ",
      "~~~~~~          "
    ],
    [
      "~~~~~~          ",
      "~~~~~~          ",
      "~~~~~~          ",
      "~~~~~~          ",
      "~~~~fj          ",
      "~~~~~~          ",
      "~~~~~~          ",
      "~~~~~~          ",
      "~~~~~~          ",
      "~~~~~~          ",
      "~~~~~~          ",
      "~~~~fj          ",
      "~~~~~~          ",
      "~~~~~~          ",
      "~~~~~~          ",
      "~~~~~~          "
    ],
    [
      "~~~~~~          ",
      "~~~~~~          ",
      "~~~~~~          ",
      "~~~~~~          ",
      "~~~~ff          ",
      "~~~~~~          ",
      "~~~~~~          ",
      "~~~~~~          ",
      "~~~~~~          ",
      "~~~~~~          ",
      "~~~~~~          ",
      "~~~~ff          ",
      "~~~~~~          ",
      "~~~~~~          ",
      "~~~~~~          ",
      "~~~~~~          "
    ]
  ]
}