{
  "name": "hideout_1",
  "refpalette": "c70cities:hideout_1_palette",
  "xsize": 16,
  "zsize": 16,
  "slices": [
    [
      "aaaaaaaaaaaaaaaa",
      "aaaaaaaaaaaaaaaa",
      "aaaaaaaaaaaaaaaa",
      "aaaaaaaaaaaaaaaa",
      "aaaaaaaaaaaaaaaa",
      "aaaaaaaaaaaaaaaa",
      "aaaaaaaaaaaaaaaa",
      "aaaaaaaaaaaaaaaa",
      "aaaaaaaaaaaaaaaa",
      "aaaaaaaaaaaaaaaa",
      "aaaaaaaaaaaaaaaa",
      "aaaaaaaaaaaaaaaa",
      "aaaaaaaaaaaaaaaa",
      "aaaaaaaaaaaaaaaa",
      "aaaaaaaaaaaaaaaa",
      "aaaaaaaaaaaaaaaa"
    ],
    [
      "GaaaaaaaaaaaaGGG",
      "GaaaaaaaaaaaaaaG",
      "aaaaaaaaaaaaaaaa",
      "aaaaaaaaaaaaaaaa",
      "aaaaaaaaaaaaaaaa",
      "aaaaaaaaaaaaaaaa",
      "aaaaaaaaaaaaaaaa",
      "aaaaaaaaaaaaaaaa",
      "aaaaaaaaaaaaaaaa",
      "aaaaaaaaaaaaaaaa",
      "Gaaaaaaaaaaaaaaa",
      "Gaaaaaaaaaaaaaaa",
      "GGaaaaaaaaaaaaaa",
      "GGaaaaaaaaaaaaaa",
      "GGaaaaaaaaaaaaaa",
      "GGGaaaaaaaaaaaaG"
    ],
    [
      " GGGGaaaaaGGG   ",
      " GGaaaaaaaaaGGG ",
      "GGaaaaaaaaaaaaGG",
      "GGaaaaaaaaaaaaGG",
      "GaaaabbbbbaaaaaG",
      "GaaaabcddcbaaaaG",
      "GaaabbddddbbaaaG",
      "GaaabbddddbbaaaG",
      "GGabbbddddbbaaaG",
      "GGGbbbddddbbaaGG",
      " GGbbbcddcbaaaGG",
      " GGGbbbbbbbaaaGG",
      "  GGbbbbbbbaaaGG",
      "  GGGbbbbbaaaGGG",
      "  GGGGbbbaaaGGGG",
      "   GGGGGGGGGGGG "
    ],
    [
      "     GGGGG      ",
      "   GGGGaaGGG    ",
      "  GGGGaaaaaGGG  ",
      "  GGaaaaaaaaGG  ",
      " GGaaaaeeaaaGGG ",
      " GGaaacffcaaaGG ",
      " GGaaghiijvaaGG ",
      " GGGagk lmnaaGG ",
      "  GGank  ogaaGG ",
      "   Gavp  ogaaG  ",
      "   GGacqrcaaaG  ",
      "    Gab  baaaG  ",
      "    Gbbs baaGG  ",
      "    tGu  baaG   ",
      "      t wGGG    ",
      "                "
    ],
    [
      "                ",
      "       GG       ",
      "      GGGGG     ",
      "    GGGGGGGG    ",
      "   GGaaeeaGG    ",
      "   GGacl caGG   ",
      "   GGgx  ynaG   ",
      "    Gvx  AgaG   ",
      "    Ggx  lvaG   ",
      "    Gnx  BgaG   ",
      "     acCDcaaG   ",
      "     GbEEbaGG   ",
      "     ubEEbGG    ",
      "         GGG    ",
      "                ",
      "                "
    ],
    [
      "                ",
      "                ",
      "                ",
      "                ",
      "     GGGGG      ",
      "     GFFFFG     ",
      "     GFIIFGG    ",
      "     GFIIFGG    ",
      "     GFIIFGG    ",
      "     GFIIFGG    ",
      "     GFFFFGG    ",
      "      GGGGG     ",
      "      tGGG      ",
      "                ",
      "                ",
      "                "
    ],
    [
      "                ",
      "                ",
      "                ",
      "                ",
      "                ",
      "      JJJJ      ",
      "      J  J      ",
      "      J  J      ",
      "      J  J      ",
      "      J  J      ",
      "      JJJJ      ",
      "                ",
      "                ",
      "                ",
      "                ",
      "                "
    ]
  ]
}