{
  "name": "hideout_1",
  "refpalette": "c70cities:hideout_1_palette",
  "xsize": 16,
  "zsize": 16,
  "slices": [
    [
      "aaaaaaaaaaaaaaaa",
      "aaaaaaaaaaaaaaaa",
      "aaaaaaaaaaaaaaaa",
      "aaaaaaaaaaaaaaaa",
      "aaaaaaaaaaaaaaaa",
      "aaaaaaaaaaaaaaaa",
      "aaaaaaaaaaaaaaaa",
      "aaaaaaaaaaaaaaaa",
      "aaaaaaaaaaaaaaaa",
      "aaaaaaaaaaaaaaaa",
      "aaaaaaaaaaaaaaaa",
      "aaaaaaaaaaaaaaaa",
      "aaaaaaaaaaaaaaaa",
      "aaaaaaaaaaaaaaaa",
      "aaaaaaaaaaaaaaaa",
      "aaaaaaaaaaaaaaaa"
    ],
    [
      "GaaaaaaaaaaaaGGG",
      "GaaaaaaaaaaaaaaG",
      "aaaaaaaaaaaaaaaa",
      "aaaaaaaaaaaaaaaa",
      "aaaaaaaaaaaaaaaa",
      "aaaaaaaaaaaaaaaa",
      "aaaaaaaaaaaaaaaa",
      "aaaaaaaaaaaaaaaa",
      "aaaaaaaaaaaaaaaa",
      "aaaaaaaaaaaaaaaa",
      "Gaaaaaaaaaaaaaaa",
      "Gaaaaaaaaaaaaaaa",
      "GGaaaaaaaaaaaaaa",
      "GGaaaaaaaaaaaaaa",
      "GGaaaaaaaaaaaaaa",
      "GGGaaaaaaaaaaaaG"
    ],
    [
      " GGGGaaaaaGGG   ",
      "bGGaaaaaaaaaGGGb",
      "GGaaaaaaaaaaaaGG",
      "GGaaaaaaaaaaaaGG",
      "GaaaacccccaaaaaG",
      "GaaaacdeedcaaaaG",
      "GaaacceeeeccaaaG",
      "GaaacceeeeccaaaG",
      "GGaccceeeeccaaaG",
      "GGGccceeeeccaaGG",
      "bGGcccdeedcaaaGG",
      " GGGcccccccaaaGG",
      " bGGcccccccaaaGG",
      "  GGGcccccaaaGGG",
      "b GGGGcccaaaGGGG",
      " b GGGGGGGGGGGG "
    ],
    [
      " bbf GGGGGfb    ",
      " bbGGGGaaGGG bb ",
      "bfGGGGaaaaaGGGb ",
      "bbGGaaaaaaaaGGbb",
      " GGaaaaggaaaGGGb",
      " GGaaadhhdaaaGG ",
      " GGaaijkklvaaGG ",
      "bGGGaim nopaaGG ",
      " bGGapm  qiaaGG ",
      "bbfGavr  qiaaG b",
      " bbGGadstdaaaGbb",
      " bbfGac  caaaGfb",
      "  bfGccu caaGGbb",
      "  bbwGx  caaG b ",
      "  bbfbw yGGGbb b",
      "    b  bf  fbf  "
    ],
    [
      "   A bb   A     ",
      "   bbfbGG b     ",
      " AffbbGGGGGbfb  ",
      "  bfGGGGGGGGbb  ",
      " b GGaaggaGG  b ",
      " b GGadn daGGbb ",
      "   GGiB  CpaG b ",
      " bfbGvB  DiaGb  ",
      "  bbGiB  nvaG   ",
      "  AbGpB  EiaG   ",
      "   bfadFIdaaGb  ",
      "   AbGcJJcaGGfA ",
      "   A xcJJcGGbb  ",
      "     b   GGGb   ",
      "    A    b      ",
      "        A  A A  "
    ],
    [
      "                ",
      "     A fb       ",
      "  AA  b bb  A   ",
      "   Abbbbb b     ",
      "   bbGGGGGbb    ",
      "   bbGKKKKGbb   ",
      "   b GKLLKGGf   ",
      "  A bGKLLKGGb   ",
      "    fGKLLKGG    ",
      "    bGKLLKGG    ",
      "    AGKKKKGG    ",
      "      GGGGG  A  ",
      "      wGGG      ",
      "         b b    ",
      "                ",
      "                "
    ],
    [
      "                ",
      "       A        ",
      "                ",
      "                ",
      "      bbb       ",
      "     bMMMMb     ",
      "      M  M  A   ",
      "     bM  Mb     ",
      "    A M  M b    ",
      "     bM  Mb     ",
      "      MMMM      ",
      "      bbbb      ",
      "        b       ",
      "                ",
      "                ",
      "                "
    ]
  ]
}