{
  "name": "multi_clubhouse1_7_base2",
  "refpalette": "c70cities:multi_clubhouse1_7_base2_palette",
  "xsize": 16,
  "zsize": 16,
  "slices": [
    [
      "vvvvvvvvvvvvvvvv",
      "vvvvvvvvvvvvvvvv",
      "vvvvvvvvvvvvvvvv",
      "vvvvvvvvvvvvvvvv",
      "vvvvvvvvvvvvvvvv",
      "vvvvvvvvvvvvvvvv",
      "vvvvvvvvvvvvvvvv",
      "vvvvvvvvvvvvvvvv",
      "vvvvvvvvvvvvvvvv",
      "vvvvvvvvvvvvvvvv",
      "vvvvvvvvvvvvvvvv",
      "vvvvvvvvvvvvvvvv",
      "vvvvvvvvvvvvvvvv",
      "vvvvvvvvvvvvvvvv",
      "vvvvvvvvvvvvvvvv",
      "vvvvvvvvvvvvvvvv"
    ],
    [
      "aaaaaaaaaaaaaaav",
      "aaaaaaaaaaaaaaav",
      "aaaaaaaaaaaaaaav",
      "aaaaaaaaaaaaaaav",
      "aaaaaaaaaaaaaaav",
      "aaaaaaaaaaaaaabv",
      "aaaaaaaaaaaaaabv",
      "ccccccccccccccbv",
      "ccccccccccdccGbv",
      "cccccccccccdcGbv",
      "ccccccccccGccGbv",
      "cceccccccedGc!fv",
      "cccccccccccdcGbv",
      "GcccccccccddcGbv",
      "GcccccccccdGcGbv",
      "GcccccccccddcGbv"
    ],
    [
      "aaaaaaaaaaaaaaav",
      "aaaaaaaaaaaaaaav",
      "aaaaaaaaaaaaaaav",
      "aaaaaaaaaaaaaaav",
      "cceccccccecccgfv",
      "ccccccccccddcchv",
      "cccccccccccdcchv",
      "i  ii cccccccchv",
      "   ii      ijkhv",
      "i   ii i    l hv",
      "  i         jkhv",
      "  e    i e  m fv",
      "nn i ii   i lkhv",
      "on     i    jkhv",
      "kn ii i     l hv",
      "pn      i   jkhv"
    ],
    [
      "aaaaaaaaaaacdabv",
      "ccccccccccccadbv",
      "ccccccccccccdcbv",
      "cccccccccccdccbv",
      "ccecccccceccc fv",
      "   i  ii    mkhv",
      "     i i    l hv",
      "            jkhv",
      "             qhv",
      "              rv",
      "             qhv",
      "  e      e    fv",
      "             qhv",
      "s            qrv",
      "q             hv",
      "             qhv"
    ],
    [
      "ccccccccccc   hv",
      "ccccccccc     hv",
      "ccccc         hv",
      "              hv",
      "  e      e    fv",
      "             qhv",
      "              hv",
      "             qhv",
      "              hv",
      "              rv",
      "              hv",
      "  e      e    fv",
      "              hv",
      "              rv",
      "              hv",
      "              hv"
    ],
    [
      "cccccc        rv",
      "              hv",
      "              rv",
      "              hv",
      "  e      e    fv",
      "              rv",
      "              rv",
      "              hv",
      "               v",
      "              rv",
      "              rv",
      "  e      e    fv",
      "               v",
      "              rv",
      "              hv",
      "               v"
    ]
  ]
}