{
  "name": "multi_laboratory1_9_base3",
  "refpalette": "c70cities:multi_laboratory1_9_base3_palette",
  "xsize": 16,
  "zsize": 16,
  "slices": [
    [
      "aaaaaaaaaaaaaaaa",
      "aaaaaaaaaabaaaaa",
      "aaaaaaacaaaaaaaa",
      "aacaaaaaaaaaaaaa",
      "acaaaaaaaaaaaaaa",
      "bcdbaaaaaaaaaaaa",
      "a  aaaaaaaaa!aaa",
      "dddaaaaaaaaaaaaa",
      "baaaa!aaaaaaaaaa",
      "aaacaaaeaaaaaaaa",
      "aaaaaaaacaaaaaaa",
      "aaaaaaaaaaaaaaaa",
      "aaaaaaaaaaaaaaaa",
      "ffffffffffffffff",
      "gggggggggggggggg",
      "zzzzzzzzzzzzzzzz"
    ],
    [
      "hi    jk  l    j",
      "h m  lni o     n",
      "o    pn  h p   j",
      "qpr stnuuhw     ",
      "ix   r          ",
      " y   p ABCDE    ",
      "      FIIIIJKL  ",
      "dMpNMddddddddddd",
      "  p OOOcPuuQR SS",
      "   xqki  TUV N  ",
      "qk i    xq     S",
      "SWq        q W  ",
      " S WSX o WSq i  ",
      "ffffffffffffffff",
      "gggggggggggggggg",
      "zzzzzzzzzzzzzzzz"
    ],
    [
      "                ",
      "                ",
      "         k      ",
      "                ",
      "                ",
      "                ",
      "        EYZ 0   ",
      "d  1cddddddddddd",
      "       c   Q    ",
      "       2        ",
      "                ",
      "                ",
      "                ",
      "ffffffffffffffff",
      "gggggggggggggggg",
      "zzzzzzzzzzzzzzzz"
    ],
    [
      "                ",
      "                ",
      "                ",
      "     1          ",
      "                ",
      "    c           ",
      "   2c       0   ",
      "r  ce33dd33ddddd",
      "     44e5666    ",
      "                ",
      "                ",
      "                ",
      "                ",
      "ffffffffffffffff",
      "gggggggggggggggg",
      "zzzzzzzzzzzzzzzz"
    ],
    [
      "                ",
      "                ",
      "                ",
      "     7          ",
      "    c           ",
      "    e2          ",
      "    8           ",
      "9 @c#3d333dddddd",
      "   2cmmc2mmm    ",
      "      1c        ",
      "                ",
      "                ",
      "                ",
      "ffffffffffffffff",
      "gggggggggggggggg",
      "zzzzzzzzzzzzzzzz"
    ],
    [
      "$%%d%%$%%^%%d%%^",
      "^%%d%%^%%^%%d%%^",
      "^%%d%%c%%$%%d%%^",
      "^%%d%c^^&&%%d%%^",
      "%%%dc%%%%%%%d%%%",
      "%%%d%%%%%%%%d%%%",
      "%%%d%%%%%%%%d%%%",
      "dddddddddddddddd",
      "@@@@c@@@@@@@@@@@",
      "@^@@@ecc@@^@@@^@",
      "@$@@@$@@@@$@@@$@",
      "@$@@@^@@@@&@@@$@",
      "@@@@@@@@@@@@@@@@",
      "ffffffffffffffff",
      "gggggggggggggggg",
      "zzzzzzzzzzzzzzzz"
    ]
  ]
}