{
  "name": "multi_communitycenter_4_base1",
  "refpalette": "c70cities:multi_communitycenter_4_base1_palette",
  "xsize": 16,
  "zsize": 16,
  "slices": [
    [
      "HHHHHHHHHHHHHHHH",
      "HHHHHHHHHHHHHHHH",
      "HHHHHHHHHHHHHHHH",
      "HHHHHHHHHHHaHHHH",
      "HHHHHHHHHHHHHHHH",
      "HHHHHHHHHHHHHHHH",
      "HHHHHHHHHHHHHHHH",
      "HHHHHHHHHHHHHHHH",
      "HHHHHHHHHHHHHHHH",
      "HHHHHHHHHHHHHHHH",
      "HHHHHHHHHHHHHHHH",
      "HHHHHHHHHHHHHHHH",
      "HHHHHHHHHHHHHHHH",
      "HHHHHHHHHHHHHHHH",
      "HHHHHHHHHHHHHHHH",
      "HHHHHHHHHHHHHHHH"
    ],
    [
      "                ",
      "bcbc bcbc bcbc b",
      "dede dede dede d",
      "                ",
      "bcbcfbcbcfbcbcfb",
      "                ",
      "                ",
      "                ",
      "                ",
      "                ",
      "                ",
      "dedefdedefdedefd",
      "                ",
      "bcbc bcbc bcbc b",
      "dede dede dede d",
      "                "
    ],
    [
      "                ",
      "                ",
      "                ",
      "                ",
      "    f    f    f ",
      "                ",
      "                ",
      "                ",
      "                ",
      "                ",
      "                ",
      "    f    f    f ",
      "                ",
      "                ",
      "                ",
      "                "
    ],
    [
      "                ",
      "                ",
      "                ",
      "                ",
      "    f    f    f ",
      "                ",
      "                ",
      "                ",
      "                ",
      "                ",
      "                ",
      "    f    f    f ",
      "                ",
      "                ",
      "                ",
      "                "
    ],
    [
      "    f    f    f ",
      "    f    f    f ",
      "    f    f    f ",
      "    f    f    f ",
      "ggggfggggfggggfg",
      "    f    f    f ",
      "    f    f    f ",
      "    f    f    f ",
      "    f    f    f ",
      "    f    f    f ",
      "    f    f    f ",
      "ggggfggggfggggfg",
      "    f    f    f ",
      "    f    f    f ",
      "    f    f    f ",
      "    f    f    f "
    ],
    [
      "hhhhhhhhhhhhhhhh",
      "hhhhhhhhhhhhhhhh",
      "hhhhhhhhhhhhhhhh",
      "hhhhhhhhhhhhhhhh",
      "hhhhhhhhhhhhhhhh",
      "hhhhhhhhhhhhhhhh",
      "hhhhhhhhhhhhhhhh",
      "hhhhhhhhhhhhhhhh",
      "hhhhhhhhhhhhhhhh",
      "hhhhhhhhhhhhhhhh",
      "hhhhhhhhhhhhhhhh",
      "hhhhhhhhhhhhhhhh",
      "hhhhhhhhhhhhhhhh",
      "hhhhhhhhhhhhhhhh",
      "hhhhhhhhhhhhhhhh",
      "hhhhhhhhhhhhhhhh"
    ]
  ]
}