{
  "name": "multi_hospital_0_ground",
  "refpalette": "c70cities:multi_hospital_0_ground_palette",
  "xsize": 16,
  "zsize": 16,
  "slices": [
    [
      "GGGGGGGGGGGGGGGG",
      "GGGGGGGGGaaaaaaa",
      "GGGbbbbbGaaaaaaa",
      "GGGbbbbbGacccccc",
      "GGGbbGbbGa  cccc",
      "GGGbbbbbGa  cccc",
      "GGGbbbbbGad cccc",
      "GGGGGGGGGadecccc",
      "GGfaaaaaafgggccc",
      "GGavvvvvvh  hccc",
      "GGavvvvvvh  hccc",
      "GGavvvvvvg ggccc",
      "GGavvvvvvaiccccc",
      "GGavvvvvvacccccc",
      "GGavvvvvva!ccccc",
      "GGavvvvvvacccccc"
    ],
    [
      "    j   j      j",
      " jkkk jkkl      ",
      "j k     km n n n",
      " jk    okpgggggg",
      " j   q rkp  st t",
      "j j     kpd s u ",
      " jk wx  kpy s   ",
      " jkkkkkkkp      ",
      "j fAAAAAAfgggs  ",
      "  BCCCCC D  E   ",
      " jB      F  I   ",
      "  B JJJ  g gg   ",
      "j BKLJLM NOPQ   ",
      "  B JJJ  NRP    ",
      "j B JJJ  N P    ",
      "  B JSJ  NRPT   "
    ],
    [
      "                ",
      "         l      ",
      "         m n n n",
      "         pggpppg",
      "     ~   pd     ",
      "         py     ",
      "         p      ",
      "         p      ",
      "  fAAAAAAfgggs  ",
      "  B UU U V  W   ",
      "  B      X  Y   ",
      "  BZ01023g gg4  ",
      "  BZ5 62 NO     ",
      "  BZ7 82 N      ",
      "  BZ9 @2 N      ",
      "  BZ0002 N      "
    ],
    [
      "                ",
      "         l      ",
      "         m n n n",
      "         pggpppg",
      "         ped    ",
      "         p d    ",
      "         p      ",
      "         p      ",
      "  f      fgggs  ",
      "  s      #  $   ",
      "  s      #  $   ",
      "  s%^&^* g gg   ",
      "  s%   * NO     ",
      "  s%   * N      ",
      "  s%( )* N      ",
      "  s%0+0* N      "
    ],
    [
      "                ",
      "         l      ",
      "         m n n n",
      "         pgggggg",
      "         p      ",
      "         p -    ",
      "         p d  [ ",
      "         p      ",
      "  f      fgggs  ",
      "  s      g  g   ",
      "  s      g  g   ",
      "  sZ0002 g gg   ",
      "  sZ  ]2 NO     ",
      "  sZ  ]2 N      ",
      "  sZ]]]2 N      ",
      "  sZ0002 N      "
    ],
    [
      "                ",
      "         l      ",
      "         m n n n",
      "         pgggggg",
      "         p      ",
      "         p      ",
      "         p -  { ",
      "         p d    ",
      "  fAAAAAAfgggsss",
      "  B      g  g   ",
      "  B      g  g   ",
      "  B }]}  g gg   ",
      "  B }]}  NO     ",
      "  B }]}  N      ",
      "  B }}}  N      ",
      "  B \\ |  N      "
    ]
  ]
}