{
  "name": "multi_condo1_2_floor2",
  "refpalette": "c70cities:multi_condo1_2_floor2_palette",
  "xsize": 16,
  "zsize": 16,
  "slices": [
    [
      "   abcccccdeffff",
      "   abcccccdddddd",
      " gggbhhhhhG!GGGh",
      "  ijbhhhhhhhhhhh",
      "  ijbhhhhhhhhhhh",
      "  ijbhhhhhhhhhhh",
      "  ijbhhhhhhhhhhh",
      "  ijbhhhhhhhhhhh",
      "  ijbhhhhhdddddd",
      "  ijbhhhhhdddddd",
      "  ijbhhhhhdddddd",
      "  ijbbbbbbdddddd",
      "  ijjjjjjjgkkkkk",
      "  iiiiiiiiglllll",
      "          g     ",
      "                "
    ],
    [
      "    m     bn    ",
      "    booopobbbbbb",
      " gggbq    rrrrr ",
      "   jbs          ",
      "   jbs   tuw  x ",
      "   jbs   tuw  y ",
      "   jbA          ",
      "   jbA    BC  DE",
      "   jbF    bbIIII",
      "   jbJ KK L     ",
      "   jb!MMMNbC OP ",
      "   jbbQQQbbb    ",
      "   jjjjjjjg     ",
      "          glllll",
      "          g     ",
      "                "
    ],
    [
      "    l     bj    ",
      "    boooRobbbbbb",
      " gggbS    rrrrr ",
      "    bT          ",
      "    bU          ",
      "    b           ",
      "    bV          ",
      "    b      W  X ",
      "    bY    bbIIII",
      "    b     Z     ",
      "    b0    bW    ",
      "    bbIIIbbb    ",
      "          g     ",
      "          g     ",
      "          g     ",
      "                "
    ],
    [
      "    l     bj    ",
      "    booooobbbbbb",
      " gggb1    r rr  ",
      "    b2          ",
      "    b2          ",
      "    b2          ",
      "    b3          ",
      "    b3     W    ",
      "    b4    bbIIII",
      "    b4    5     ",
      "    b4    b     ",
      "    bbIIIbbb    ",
      "          g     ",
      "          g     ",
      "          g     ",
      "                "
    ],
    [
      "    b     b6    ",
      "    booooobbbbbb",
      " gggb           ",
      "   7b           ",
      "   7b           ",
      "   7b           ",
      "   7b8          ",
      "   7b8          ",
      "   7b     bbIIII",
      "   7b     b     ",
      "   7b     b     ",
      "   7bbbbbbbbbbbb",
      "   7777777g     ",
      "          g     ",
      "          g     ",
      "                "
    ],
    [
      "    b99999b     ",
      "    b99999bbbbbb",
      " gggb99999999999",
      "   @b99999999999",
      "   @b99999999999",
      "   @b99999999999",
      "   @b99999999999",
      "   @b99999999999",
      "   @b99999bb####",
      "   @b99999bfffff",
      "   @b99999bfffff",
      "   @bbbbbbbbbbbb",
      "   @@@@@@@g     ",
      "          g$$$$$",
      "          g     ",
      "                "
    ]
  ]
}