{
  "name": "multi_laboratory1_2_ground",
  "refpalette": "c70cities:multi_laboratory1_2_ground_palette",
  "xsize": 16,
  "zsize": 16,
  "slices": [
    [
      "zzzzzaavbbbcddce",
      "zzazaafvbbbcddce",
      "azzazafvbbbcddce",
      "zzzazavvbbbcddcc",
      "zazzaavvbbbcdddc",
      "zzaazafvbbbcdddc",
      "zaaaazffbbbcdddd",
      "zzzzzafvbbbcdddd",
      "zzzzzzfvbbbcdddd",
      "azzzaaafbbbcdddd",
      "zzzaaafvbbbcdddd",
      "zazazaafbbbcdddd",
      "zzazaffvbbbcdddd",
      "zzzzzafvbbbcdddd",
      "zzaaazfvbbbcdddd",
      "zzzazaffbbbcdddd"
    ],
    [
      "  gg    h  i  j ",
      "gg      k  i  j ",
      "        k  i  j ",
      "g g     h  i  jj",
      "   g    l  cm  j",
      "        l  i   j",
      "        l  i    ",
      "g  n    l  op   ",
      " g   g  l  iqp  ",
      " r s    l  ottpm",
      "        l  i  up",
      "g   g   l  c   t",
      "s       l  i   t",
      " n      l  i ttt",
      "g       l  i    ",
      "  w     l  i    "
    ],
    [
      "        h  x    ",
      "        k  x    ",
      "        h  x    ",
      "        k  x    ",
      "        l  cy   ",
      "        A  x    ",
      "        l  i    ",
      "   ~    l  op   ",
      "        l  iBp  ",
      "        l  ottpy",
      "        l  x  up",
      "        l  c   t",
      "        l  i   t",
      " ~      l  i ttt",
      "        l  i    ",
      "        l  i    "
    ],
    [
      "        k  x    ",
      "        k  x    ",
      "        k  x    ",
      "        k  x    ",
      "        A  cy   ",
      "        C  x    ",
      "        A  i    ",
      "        C  op   ",
      "        A  i p  ",
      "        C  ottpy",
      "        A  x  up",
      "        A  c   t",
      "        A  i   t",
      "        C  i ttt",
      "        A  i    ",
      "        C  i    "
    ],
    [
      "        k  x    ",
      "        k  x    ",
      "        k  x    ",
      "        k  x    ",
      "        A  c    ",
      "        A  x    ",
      "        C  i    ",
      "        C  op   ",
      "        C  iDp  ",
      "        C  i Dp ",
      "        A  x  up",
      "        C  c   E",
      "        C  i   F",
      "        C  i  IJ",
      "        C  i    ",
      "        C  i    "
    ],
    [
      "        k  iK   ",
      "        k  iK   ",
      "        k  iK   ",
      "        h  iK   ",
      "        C  cK   ",
      "        C  iK   ",
      "        C  iK   ",
      "        A  op   ",
      "        C  iKp  ",
      "        C  iKKp ",
      "        C  iKKup",
      "        C  cKKKK",
      "        A  iKLLK",
      "        C  iKLLK",
      "        C  iKKKK",
      "        A  iKKKK"
    ]
  ]
}