{
  "name": "multi_hospital_3_floor1",
  "refpalette": "c70cities:multi_hospital_3_floor1_palette",
  "xsize": 16,
  "zsize": 16,
  "slices": [
    [
      "aaaaaaaaaaaaaab ",
      "aaaaaaaaaaaaaab ",
      "cdeeeeeeeeeeeeb ",
      "fbbbbbbbbbbbbbb ",
      "fbg             ",
      "fbg             ",
      "fbg             ",
      "fbg             ",
      "fbg             ",
      "fbg             ",
      "fbg    ~~       ",
      "fbg             ",
      "fbg             ",
      "bbg             ",
      "bbg             ",
      "                "
    ],
    [
      " hi   ji   kle  ",
      " hmn ojmn   peq ",
      "edeeeeeeeeeeeeq ",
      " rq qq qq qq q  ",
      " r              ",
      "sr              ",
      "tr              ",
      " r              ",
      " r              ",
      "sr              ",
      "tr      ~       ",
      " r              ",
      " r              ",
      "rr              ",
      "                ",
      "                "
    ],
    [
      " u    w      x  ",
      " u   !w      eq ",
      "edexeexeexeexeq ",
      " rq qq qq qq q  ",
      " r              ",
      " r              ",
      " r              ",
      " r              ",
      " r              ",
      " r              ",
      " r      ~       ",
      " r              ",
      " r              ",
      "rr              ",
      "                ",
      "                "
    ],
    [
      " u    w      x  ",
      " u    w      eq ",
      "edexeexeexeexeq ",
      " rq qq qq qq q  ",
      " r              ",
      " r              ",
      " r              ",
      " r              ",
      " r              ",
      " r              ",
      " r      ~       ",
      " r              ",
      " r              ",
      "rr              ",
      "                ",
      "                "
    ],
    [
      " u    w      x  ",
      " u    w      eq ",
      "edexeexeexeexeq ",
      " rq qq qq qq q  ",
      " r              ",
      " r              ",
      " r              ",
      " r              ",
      " r              ",
      " r              ",
      " r     ~~       ",
      " r              ",
      " r              ",
      "rr              ",
      "                ",
      "                "
    ],
    [
      " eyyyeyyyeyyye  ",
      " eyyyeyyyeyyyeq ",
      "edeeeeeeeeeeeeq ",
      " rq qq qq qq q  ",
      " r              ",
      " r              ",
      " r              ",
      " r              ",
      " r              ",
      " r              ",
      " r      ~       ",
      " r              ",
      " r              ",
      "rr              ",
      "                ",
      "                "
    ]
  ]
}