{
  "name": "multi_laboratory1_3_ground",
  "refpalette": "c70cities:multi_laboratory1_3_ground_palette",
  "xsize": 16,
  "zsize": 16,
  "slices": [
    [
      "zaazzavvbbbcdddd",
      "zzzaaaevbbbcdddd",
      "zazzzaevbbbcdddd",
      "zzzzaaaebbbcdddd",
      "azzazzavbbbcdddd",
      "zzaaaaevbbbcdddd",
      "zazfaaevbbbcdddd",
      "zzfazaavbbbcdddd",
      "azzaaaevbbbcdddd",
      "zzzazeeebbbcdddd",
      "zazzaaevbbbcdddd",
      "zzzazaevbbbcdddd",
      "zzaaaaeebbbcdddd",
      "zzzazaavbbbcdddd",
      "azazazvvbbbcdddd",
      "zzzazzevbbbcdddd"
    ],
    [
      "g   h   i  j klm",
      " g      i  j    ",
      "g  g    i  cn o ",
      "g g     i  j    ",
      " h      i  pqqqq",
      "gr hs   t  juwww",
      "g xy r     pAwBC",
      " xxx D     pqqqq",
      " xEF       j    ",
      "    g      c   I",
      "           j  JK",
      "g          j LJ!",
      "g          j  JM",
      "  N g      j  JM",
      "           j LJM",
      "     g     j  JO"
    ],
    [
      "        i  j    ",
      "        i  j    ",
      "        i  c    ",
      "        P  Q    ",
      "        i  pqRRR",
      "        i  j www",
      "        t  j S  ",
      "  x        pqqqq",
      "           Q    ",
      "           c    ",
      "           j    ",
      "           j  T ",
      "           j  U ",
      "  ~        j    ",
      "           j    ",
      "           j    "
    ],
    [
      "        P  j    ",
      "        P  j    ",
      "        V  c    ",
      "        P  Q    ",
      "        P  pqWWW",
      "        P  jSw w",
      "        i  j    ",
      "  x     t  pqqqq",
      "           Q    ",
      "           c    ",
      "           j    ",
      "           j    ",
      "           j    ",
      "           j    ",
      "           j    ",
      "           j    "
    ],
    [
      "        V  j    ",
      "        V  j    ",
      "        P  c    ",
      "        V  Q    ",
      "        V  pqqqq",
      "        P  jS   ",
      "        V  j    ",
      "        i  pqqqq",
      "        t  Q    ",
      "           c    ",
      "           j    ",
      "           j    ",
      "           j    ",
      "           j    ",
      "           j    ",
      "           j    "
    ],
    [
      "        V  jXYYY",
      "        V  jXYYY",
      "        V  cXXXX",
      "        V  jXXXX",
      "        P  pqqqq",
      "        P  j S  ",
      "        P  jS   ",
      "        P  pqqqq",
      "        i  jXXXX",
      "        t  cXXXX",
      "           jXYYY",
      "           jXYYY",
      "           jXXXX",
      "           jXXXX",
      "           jXYYY",
      "           jXYYY"
    ]
  ]
}