{
  "name": "multi_gallery_1_floor1",
  "refpalette": "c70cities:multi_gallery_1_floor1_palette",
  "xsize": 16,
  "zsize": 16,
  "slices": [
    [
      "    a     b     ",
      "    a c   b     ",
      "    a !  db     ",
      "  e a     b     ",
      "  efg     g     ",
      "  ehijjjihklllll",
      "  eijiiijik     ",
      "  ejjihijjm  nop",
      "  eijiiijiq     ",
      "  ehijjjihr     ",
      "  e  gssssm  tup",
      "  e       k     ",
      "  elllllllklllll",
      "  efffffffg     ",
      "  e             ",
      "                "
    ],
    [
      "    a     b     ",
      "    a     b     ",
      "    a     b     ",
      "  e a     b     ",
      "  efg     g     ",
      "  e       k     ",
      "  e       k     ",
      "  e       m    w",
      "  e       x     ",
      "  e       y     ",
      "  e  g    m    w",
      "  e       k     ",
      "  e       k     ",
      "  efffffffg     ",
      "  e             ",
      "                "
    ],
    [
      "    a     b     ",
      "    A     b     ",
      "    a     b     ",
      "  e a     b     ",
      "  efg     g     ",
      "  e       k     ",
      "  e       k     ",
      "  e       m    B",
      "  e       k     ",
      "  e       k     ",
      "  e  g    m    B",
      "  e       k     ",
      "  e       k     ",
      "  efffffffg     ",
      "  e             ",
      "                "
    ],
    [
      "    C     b     ",
      "    a     b     ",
      "    a     b     ",
      "  e a     b     ",
      "  efg     g     ",
      "  e       k     ",
      "  e       k     ",
      "  e       m    D",
      "  e       k     ",
      "  e       k     ",
      "  e  g    m    D",
      "  e       k     ",
      "  e       k     ",
      "  efffffffg     ",
      "  e             ",
      "                "
    ],
    [
      "    C     b     ",
      "    C     b     ",
      "    a     b     ",
      "  e a     b     ",
      "  efgEEEEEg     ",
      "  e       k     ",
      "  e       k     ",
      "  e       m    D",
      "  e       k     ",
      "  e       k     ",
      "  e  g    m    D",
      "  e       k     ",
      "  e       k     ",
      "  efffffffg     ",
      "  e             ",
      "                "
    ],
    [
      "   Fa     IJJF  ",
      "   Fa     IJJF  ",
      "   Fa     IJJF  ",
      "  eFa     IJJFF ",
      "  eIIIIIIIIJJJJ ",
      "  e       IJJJJ ",
      "  e       IJJJJ ",
      "  e       IJJJJK",
      "  e       IJJJJ ",
      "  e       IJJJJ ",
      "  e       IJJJJK",
      "  e       IJJJJ ",
      "  e       IJJJJ ",
      "  eIIIIIIIIJJJJ ",
      "  eFFFFFFFFFFFF ",
      "                "
    ]
  ]
}