{
  "name": "multi_laboratory1_7_base5",
  "refpalette": "c70cities:multi_laboratory1_7_base5_palette",
  "xsize": 16,
  "zsize": 16,
  "slices": [
    [
      " ~~~~~~~~~~~~~~ ",
      " ~~~~~~~~~~~~~~ ",
      " ~~~~~~~~~~~~~~ ",
      " a~~~~~~~~~~~~~ ",
      " ~~~~~~~~~~~~~~ ",
      "b~~~~~~~~~~~~~~b",
      "b~~~~~~~~~~~~~~b",
      "bc~~~~~~~~~~~~cb",
      " bbb        bbb ",
      "   bbc    cbb   ",
      "     bbbbbb     ",
      "                ",
      "                ",
      "                ",
      "                ",
      "                "
    ],
    [
      " ~~~~~~~~~~~~~~ ",
      " ~~~~~~~~~~~~~~ ",
      " ~~~~~~~~~~~~~~ ",
      " d~~~~~~~~~~~~~ ",
      " ~~~~~~~~~~~~~~ ",
      "b~~~~~~~~~~~~~~b",
      "b~~~~~~~~~~~~~~b",
      "bc~~~~~~~~~~~~cb",
      " bbb        bbb ",
      "   bbc    cbb   ",
      "     bbbbbb     ",
      "                ",
      "                ",
      "                ",
      "                ",
      "                "
    ],
    [
      " ~~~~~~~~~~~~~~ ",
      " ~~~~~~~~~~~~~~ ",
      " ~~~~~~~~~~~~~~ ",
      " d~~~e~~~~~~~~~ ",
      " ~~~~f~~~~~~~~~ ",
      "b~~~~g~~~~~~~~~b",
      "b~~~~f~~~~~~~~~b",
      "bc~~~h~~~~~~~~cb",
      " bbb i      bbb ",
      "   bbc    cbb   ",
      "     bbbbbb     ",
      "                ",
      "                ",
      "                ",
      "                ",
      "                "
    ],
    [
      " ~~~~~~~~~~~~~~ ",
      " ~~~~~~~~~~~~~~ ",
      " ~~~~~~~~~~~~~~ ",
      " d~~~~~~~~~~~~~ ",
      " ~~~~~~~~~~~~~~ ",
      "b~~~~j~~~~~~~~~b",
      "b~~~~~~~~~~~~~~b",
      "bc~~~~~~~~~~~~cb",
      " bbb        bbb ",
      "   bbc    cbb   ",
      "     bbbbbb     ",
      "                ",
      "                ",
      "                ",
      "                ",
      "                "
    ],
    [
      " ~~~~~~~~~~~~~~ ",
      " ~~~~~~~~~~~~~~ ",
      " ~~~~~~~~~~~~~~ ",
      " d~~~~~~~~~~~~~ ",
      " ~~~~~~~~~~~~~~ ",
      "b~~~~d~~~~~~~~~b",
      "b~~~~~~~~~~~~~~b",
      "bc~~~~~~~~~~~~cb",
      " bbb        bbb ",
      "   bbc    cbb   ",
      "     bbbbbb     ",
      "                ",
      "                ",
      "                ",
      "                ",
      "                "
    ],
    [
      " ~~~~~~~~~~~~~~ ",
      " ~~~~~~~~~~~~~~ ",
      " ~~~~~~~~~~~~~~ ",
      " d~~~~~~~~~~~~~ ",
      " ~~~~~~~~~~~~~~ ",
      "b~~~~d~~~~~~~~~b",
      "b~~~~~~~~~~~~~~b",
      "bc~~~~~~~~~~~~cb",
      "kbbb        bbbk",
      "kkkbbc    cbbkkk",
      "kkkkkbbbbbbkkkkk",
      "kkkkkkkkkkkkkkkk",
      "kkkkkkkkkkkkkkkk",
      "kkkkkkkkkkkkkkkk",
      "kkkkkkkkkkkkkkkk",
      "kkkkkkkkkkkkkkkk"
    ]
  ]
}