{
  "name": "multi_megatower1_1_base2",
  "refpalette": "c70cities:multi_megatower1_1_base2_palette",
  "xsize": 16,
  "zsize": 16,
  "slices": [
    [
      "vaavvHHHHHHHHvvv",
      "vaavvHHHHHHHHvvv",
      "vaavvHHHHHHHHvvv",
      "vaavvHHHHHHHHvvv",
      "vaavvHbHHHHHHbvv",
      "vaavvHHHHHHHHvvv",
      "vaavvHHHHHHHHvvv",
      "vaavvHHHHHHHHvvv",
      "vaavvHHHHHHHHvvv",
      "vaavvHHHHHHHHvvv",
      "vaavvHHHHHHHHvvv",
      "vaavvHbHHHHHHbHH",
      "vaavvHHHHHHHHHHH",
      "vaavvHHHHHHHHHHH",
      "vaavvHHHHHHHHHHH",
      "vaavvHHHHHHHHHHH"
    ],
    [
      "vaavcd e     f  ",
      "vaavcg h     fi ",
      "vaavcd e     fj ",
      "vaavcg h     f  ",
      "vaavc bk    lbmn",
      "vaavcd e        ",
      "vaavcg h        ",
      "vaavcd e        ",
      "vaavcg h        ",
      "vaavcd e        ",
      "vaavcg h     ovv",
      "vaavc bk    lb! ",
      "vaavcd e        ",
      "vaavcg h    d e ",
      "vaavcd e    g h ",
      "vaavcg h    d e "
    ],
    [
      "vaav         fp ",
      "vaav         fj ",
      "vaav         f  ",
      "vaav         f  ",
      "vaav  b      bqr",
      "vaav            ",
      "vaav            ",
      "vaav            ",
      "vaav            ",
      "vaav            ",
      "vaav         ovv",
      "vaav  b      b  ",
      "vaav            ",
      "vaav            ",
      "vaav            ",
      "vaav            "
    ],
    [
      "vaav         fjs",
      "vaav         f  ",
      "vaav         f  ",
      "vaav         ftt",
      "vaav  b      buu",
      "vaav            ",
      "vaav            ",
      "vaav            ",
      "vaav            ",
      "vaav            ",
      "vaav         ovv",
      "vaav  b      bw ",
      "vaav            ",
      "vaav            ",
      "vaav            ",
      "vaav            "
    ],
    [
      "vaav         x y",
      "vaav         x s",
      "vaav         x  ",
      "vaav         x  ",
      "vaav Ab      buu",
      "vaav            ",
      "vaav            ",
      "vaav            ",
      "vaav            ",
      "vaav            ",
      "vaav         ovv",
      "vaav Ab      bww",
      "vaav         w  ",
      "vaav         w  ",
      "vaav            ",
      "vaav            "
    ],
    [
      "vaavvBbBBBBBBb  ",
      "vaavvBbBBBBBBb y",
      "vaavvBbBBBBBBb p",
      "vaavvBbBBBBBBbip",
      "vaavvBbbbbbbbbbb",
      "vaavvBbBBBBBBbBB",
      "vaavvBbBBBBBBbBB",
      "vaavvBbBBBBBBbBB",
      "vaavvBbBBBBBBbBB",
      "vaavvBbBBBBBBbBB",
      "vaavvBbBBBBBBbvv",
      "vaavvBbbbbbbbbbb",
      "vaavvBbBBBBBBbB ",
      "vaavvBbBBBBBBbB ",
      "vaavvBbBBBBBBbB ",
      "vaavvBbBBBBBBbB "
    ]
  ]
}