{
  "name": "multi_laboratory1_5_ground",
  "refpalette": "c70cities:multi_laboratory1_5_ground_palette",
  "xsize": 16,
  "zsize": 16,
  "slices": [
    [
      "zzzzzzzzzzzzzzzz",
      "aabaaaazzaaaaaaa",
      "cccccccccccccccc",
      "cccccccccccccccc",
      "cccccccccccccccc",
      "dddddddddddddddd",
      "e    e    f    e",
      "eg  geg  gfg  ge",
      "eeeeeeeeeeeeeeee",
      "e    ehhhhe    e",
      "e    ehhhhe    e",
      "e    ehhhhe    e",
      "e    ehhhhe    e",
      "e    ehhhhe    e",
      "e    ehhhie    e",
      "eeeejkeeeeeeeebl"
    ],
    [
      "    m         nn",
      "       n        ",
      "oooopppppppppppp",
      "                ",
      "                ",
      "qrrrrdrrrrdrrrrq",
      "f    f    f    f",
      "fssssfssssfssssf",
      "effffeffffeffffe",
      "f    fhtthf    f",
      "f    fu  wf    f",
      "f    fu  wf    f",
      "f    fu  xf    f",
      "f    fu  wf    f",
      "f    fhyAhf    f",
      "efBBfefBBfefBBfe"
    ],
    [
      "                ",
      "                ",
      "oooopppppppppppp",
      "                ",
      "                ",
      "qrrrrdrrrrdrrrrq",
      "f C  f D  f  D f",
      "fssssfssssfssssf",
      "effffeffffeffffe",
      "f    fhtthf    f",
      "f    fu  wf    f",
      "f    fu  wf    f",
      "f    fu  wf    f",
      "f    fu  wf    f",
      "f    fhEFhf    f",
      "ef  fef  fef  fe"
    ],
    [
      "                ",
      "                ",
      "ooooIIIIJIIIIJII",
      "                ",
      "                ",
      "qrrrrdrrrrdrrrrq",
      "fC D f  CCfCC  f",
      "fssssfssssfssssf",
      "effffeffffeffffe",
      "f    fhtthf    f",
      "f    fu  wf    f",
      "f    fu  wf    f",
      "f    fu  wf    f",
      "f    fu  wf    f",
      "f    fhtthf    f",
      "efhhfefhhfefhhfe"
    ],
    [
      "                ",
      "                ",
      "IJJIJIIIIJIIJIII",
      "KKKK            ",
      "                ",
      "qrrrrdrrrrdrrrrq",
      "fCC  f CC f  D f",
      "fssssfssssfssssf",
      "effffeffffeffffe",
      "f    fhtthf    f",
      "f    fuLLwf    f",
      "f    fuLLwf    f",
      "f    fuLLwf    f",
      "f    fuLLwf    f",
      "f    fhtthf    f",
      "effffeffffeffffe"
    ],
    [
      "                ",
      "                ",
      "IJJIIIIJIIJIIJJJ",
      "                ",
      "                ",
      "qrrrrdrrrrdrrrrq",
      "f C  f C  f C  f",
      "fssssfssssfssssf",
      "effffeffffeffffe",
      "f    fhhhhf    f",
      "f    fhtthf    f",
      "f    fhtthf    f",
      "f    fhtthf    f",
      "f    fhtthf    f",
      "f    fhhhhf    f",
      "effffeffffeffffe"
    ]
  ]
}