{
  "name": "multi_condo1_0_floor7",
  "refpalette": "c70cities:multi_condo1_0_floor7_palette",
  "xsize": 16,
  "zsize": 16,
  "slices": [
    [
      "                ",
      "          a     ",
      "  bbbbbbbbaccccc",
      "  bdddddddaeeeee",
      "  bdffffffgggggg",
      "  bdfhhhhhfhhhhh",
      "  bdfhhhhhfhhhhh",
      "  bdfhhhhhfhhhhh",
      "  bdfhhhhhfhhhhh",
      "  bdfhhhhhfhhhhh",
      "  bdfhhhhhfhhhhh",
      "  bdfhhhhhfhhhhh",
      "  bdfhhhhhfhhhhh",
      " aaafhhhhhfhhhhh",
      "   ifggggggggggg",
      "   ifjjjjjjjjjjj"
    ],
    [
      "                ",
      "          a     ",
      "          accccc",
      "   ddddddda     ",
      "   dffkkkfff    ",
      "   df           ",
      "   df           ",
      "   df           ",
      "   df           ",
      "   df           ",
      "   df           ",
      "   df           ",
      "   df           ",
      " aaaf           ",
      "    f           ",
      "    l           "
    ],
    [
      "                ",
      "          a     ",
      "          a     ",
      "          a     ",
      "    ffmmmfff    ",
      "    f           ",
      "    f           ",
      "    f           ",
      "    f           ",
      "    f           ",
      "    f           ",
      "    f           ",
      "    f           ",
      " aaaf           ",
      "    f           ",
      "    c           "
    ],
    [
      "                ",
      "          a     ",
      "          a     ",
      "          a     ",
      "    ffmmmfff    ",
      "    f           ",
      "    f           ",
      "    f           ",
      "    f           ",
      "    f           ",
      "    f           ",
      "    f           ",
      "    f           ",
      " aaaf           ",
      "    f           ",
      "    c           "
    ],
    [
      "                ",
      "          a     ",
      "          a     ",
      "   nnnnnnna     ",
      "   nffffffffffff",
      "   nf           ",
      "   nf           ",
      "   nf           ",
      "   nf           ",
      "   nf           ",
      "   nf           ",
      "   nf           ",
      "   nf           ",
      " aaaf           ",
      "    f           ",
      "    f           "
    ],
    [
      "                ",
      "          a     ",
      "          aooooo",
      "   pppppppa     ",
      "   pffffffffffff",
      "   pf           ",
      "   pf           ",
      "   pf           ",
      "   pf           ",
      "   pf           ",
      "   pf           ",
      "   pf           ",
      "   pf           ",
      " aaaf           ",
      "    f           ",
      "    f           "
    ]
  ]
}