{
  "name": "multi_convenientstore_2_ground",
  "refpalette": "c70cities:multi_convenientstore_2_ground_palette",
  "xsize": 16,
  "zsize": 16,
  "slices": [
    [
      "GGGGGGGGGGGaHHHG",
      "GGGGGGGGGGGaHHHG",
      "aaaaaaaaaaaaHHHG",
      "HHHHHHHHHHHHHHHG",
      "HHHHHHHHHHHHHHHG",
      "HHHHHHHHHHHHHHHG",
      "HHHHHHHHHHHHHHHG",
      "HHHHHHHHHHHHHHHG",
      "HHHHHHHHHHHHHHHG",
      "HHHHHHHHHHHHHHHG",
      "HHHHHHHHHHHHHHHG",
      "HHHHHHHHHHHHHHHG",
      "HHHHHHHHHHHHHHHG",
      "HHHHHHHHHHHHHHHb",
      "HHHHHHHHHHHHHHHb",
      "HHHHHHHHHHHHHHHb"
    ],
    [
      " c     c  cd    ",
      "           d    ",
      "ddddd ddd dd    ",
      "efefefefefe gh  ",
      "        i       ",
      "jkjkjkjkjkj l   ",
      "        h      c",
      "                ",
      "    m           ",
      " l              ",
      "efefefefefe     ",
      "             n  ",
      "jkjkjkjkjkj     ",
      "dddddddddddd   o",
      "aaaaaaaaaaaapppo",
      "aaaaaaaaaaaapppo"
    ],
    [
      "                ",
      "                ",
      "                ",
      "                ",
      "                ",
      "                ",
      "                ",
      "                ",
      "                ",
      "                ",
      "                ",
      "                ",
      "                ",
      "                ",
      "       q        ",
      " rs s sqtutt    "
    ],
    [
      "                ",
      "                ",
      "                ",
      "                ",
      "                ",
      "                ",
      "                ",
      "                ",
      "                ",
      "                ",
      "                ",
      "                ",
      "                ",
      "                ",
      "       q        ",
      " rs s sqtwtt    "
    ],
    [
      "                ",
      "                ",
      "                ",
      "                ",
      "                ",
      "                ",
      "                ",
      "                ",
      "                ",
      "                ",
      "                ",
      "                ",
      "                ",
      "                ",
      "       q        ",
      "xys s sqt tt    "
    ],
    [
      "                ",
      "                ",
      "                ",
      "                ",
      "                ",
      "                ",
      "                ",
      "                ",
      "                ",
      "                ",
      "                ",
      "                ",
      "                ",
      "                ",
      "       q        ",
      "  s s sqt tt    "
    ]
  ]
}