{
  "name": "multi_clubhouse1_8_base2",
  "refpalette": "c70cities:multi_clubhouse1_8_base2_palette",
  "xsize": 16,
  "zsize": 16,
  "slices": [
    [
      "vvvvvvvvvvvvvvvv",
      "vvvvvvvvvvvvvvvv",
      "vvvvvvvvvvvvvvvv",
      "aaaaaaaaavvvvvvv",
      "aaaaaaaaavvvvvvv",
      "aaaaaaaaavvvvvvv",
      "aaaaaaaaavvvvvvv",
      "aaaaaaaaavvvvvvv",
      "aaaaaaaaavvvvvvv",
      "vvvvvvvvvvvvvvvv",
      "vvvvvvvvvvvvvvvv",
      "vvvvvvvvvvvvvvvv",
      "vvvvvvvvvvvvvvvv",
      "vvvvvvvvvvvvvvvv",
      "vvvvvvvvvvvvvvvv",
      "vvvvvvvvvvvvvvvv"
    ],
    [
      "GbbbbbbbbbbcbGdv",
      "bbbbbbbbbbGcbGdv",
      "aaeaaaaaaecbbfgv",
      "hhihhiihiaccbGdv",
      "ihhhihhhiaccbGdv",
      "hhhhhhhhhacGbGdv",
      "hhhhhhhhiaccbGdv",
      "hhhhihhhhaccbGdv",
      "hihihhihiaGcbGdv",
      "aaeaaaaaaeccbjgv",
      "cccccGcbccccbGdv",
      "cGbcccGcccGbbGdv",
      "bbbbbbbbbbbbbGdv",
      "GGjGGGGGGfGGGGdv",
      "ddgddddddgdddddv",
      "vvvvvvvvvvvvvvvv"
    ],
    [
      "kl          mnov",
      "ll p p      qrov",
      "  e      e pm gv",
      "     s      mrov",
      "            trov",
      "   s   s    qnov",
      "s s         muov",
      "            mnov",
      "s    s      qrov",
      "  e      e  m gv",
      "            qrov",
      "  p        ptnov",
      "mqmmmtmtmqmmmuov",
      "rr rrnrwn urnrov",
      "oogoooooogooooov",
      "vvvvvvvvvvvvvvvv"
    ],
    [
      "x            yov",
      "             Aov",
      "  e      e    gv",
      "             Aov",
      "             Aov",
      "             yBv",
      "              ov",
      "             yov",
      "             Aov",
      "  e      e    gv",
      "             ACv",
      "             yov",
      "              ov",
      "AA AAyA y  AyAov",
      "oBgooBooogooooov",
      "vvvvvvvvvvvvvvvv"
    ],
    [
      "              Bv",
      "              ov",
      "  e      e    gv",
      "              ov",
      "              Bv",
      "              Bv",
      "              ov",
      "              ov",
      "              Bv",
      "  e      e    gv",
      "              Bv",
      "              ov",
      "              ov",
      "              ov",
      "oBgBooooogBoooov",
      "vvvvvvvvvvvvvvvv"
    ],
    [
      "              Bv",
      "              ov",
      "  e      e    gv",
      "              ov",
      "              Bv",
      "              Bv",
      "              Bv",
      "              ov",
      "              Bv",
      "  e      e    gv",
      "              ov",
      "              ov",
      "              ov",
      "              ov",
      "oogBoooBogBoooov",
      "vvvvvvvvvvvvvvvv"
    ]
  ]
}