{
  "name": "multi_megatower1_1_base1",
  "refpalette": "c70cities:multi_megatower1_1_base1_palette",
  "xsize": 16,
  "zsize": 16,
  "slices": [
    [
      "vaavvHHHHHHHHv  ",
      "vaavvHHHHHHHHv  ",
      "vaavvHHHHHHHHvbc",
      "vaavvHHHHHHHHvdd",
      "vaavvHeHHHHHHevv",
      "vaavvHHHHHHHHvvv",
      "vaavvHHHHHHHHHHH",
      "vaavvHHHHHHHHHHH",
      "vaavvHHHHHHHHHHH",
      "vaavvHHHHHHHHHHH",
      "vaavvHHHHHHHHvvv",
      "vaavvHeHHHHHHeHv",
      "vaavvHHHHHHHHHHv",
      "vaavvHHHHHHHHHHv",
      "vaavvHHHHHHHHHHv",
      "vaavvHHHHHHHHHHv"
    ],
    [
      "vaavfg h     i  ",
      "vaavfj k     ib ",
      "vaavfg h     il ",
      "vaavfj k     i  ",
      "vaavf em    neop",
      "vaavfg h        ",
      "vaavfj k        ",
      "vaavfg h        ",
      "vaavfj k        ",
      "vaavfg h        ",
      "vaavfj k     qvv",
      "vaavf em    re s",
      "vaavfg h       s",
      "vaavfj k    g hs",
      "vaavfg h    j ks",
      "vaavfj k    g hs"
    ],
    [
      "vaav         id ",
      "vaav         il ",
      "vaav         i  ",
      "vaav         i  ",
      "vaav  e      etu",
      "vaav            ",
      "vaav            ",
      "vaav            ",
      "vaav            ",
      "vaav            ",
      "vaav         qvv",
      "vaav  e      e  ",
      "vaav            ",
      "vaav            ",
      "vaav            ",
      "vaav            "
    ],
    [
      "vaav         ilw",
      "vaav         i  ",
      "vaav         i  ",
      "vaav         ixx",
      "vaav  e      eyy",
      "vaav            ",
      "vaav            ",
      "vaav            ",
      "vaav            ",
      "vaav            ",
      "vaav         qvv",
      "vaav  e      e  ",
      "vaav            ",
      "vaav            ",
      "vaav            ",
      "vaav            "
    ],
    [
      "vaav         A c",
      "vaav         A w",
      "vaav         A  ",
      "vaav         A  ",
      "vaav  e      eyy",
      "vaav            ",
      "vaav            ",
      "vaav            ",
      "vaav            ",
      "vaav            ",
      "vaav         qvv",
      "vaav  e      e  ",
      "vaav            ",
      "vaav            ",
      "vaav            ",
      "vaav            "
    ],
    [
      "vaavvBeBBBBBBe  ",
      "vaavvBeBBBBBBe c",
      "vaavvBeBBBBBBe w",
      "vaavvBeBBBBBBebd",
      "vaavvBeeeeeeeeee",
      "vaavvBeBBBBBBeBB",
      "vaavvBeBBBBBBeBB",
      "vaavvBeBBBBBBeBB",
      "vaavvBeBBBBBBeBB",
      "vaavvBeBBBBBBeBB",
      "vaavvBeBBBBBBevv",
      "vaavvBeeeeeeeeee",
      "vaavvBeBBBBBBeB ",
      "vaavvBeBBBBBBeB ",
      "vaavvBeBBBBBBeB ",
      "vaavvBeBBBBBBeB "
    ]
  ]
}