{
  "name": "multi_laboratory1_3_base1",
  "refpalette": "c70cities:multi_laboratory1_3_base1_palette",
  "xsize": 16,
  "zsize": 16,
  "slices": [
    [
      "zabccccccccccccc",
      "zabccccccccccccc",
      "zabccccccccdcccc",
      "zabcccccccccceee",
      "zabcccccccccceee",
      "zabcccccccccceee",
      "zabcccccccccceee",
      "zabcccccccccceee",
      "zabccccccccccc!c",
      "zabccccccccdcccc",
      "zabccccccccccccc",
      "zabccccccccccccc",
      "zabccccccccccccc",
      "zabccccccccccccc",
      "zabccccccccccccc",
      "zabccccccccccccc"
    ],
    [
      "zabf       g    ",
      "zab   hhii g    ",
      "zabjjjjjjjjdklll",
      "zabm  noppqjl   ",
      "zabm  rpsoqjt   ",
      "zabuw rxxxqjl y ",
      "zabA       jlBB ",
      "zabf C     jl y ",
      "zabjiiD EFEjkllI",
      "zabjjjjJjjjdjjjj",
      "zabf     KKL BBy",
      "zabfw      L y  ",
      "zabf  w w  L    ",
      "zabA  DMD  L    ",
      "zabf  NON  L    ",
      "zabu  P P  L    "
    ],
    [
      "zabQ       g    ",
      "zab     RS g    ",
      "zabjjjjjjjjdT   ",
      "zab   U    L    ",
      "zab        L    ",
      "zabV       L    ",
      "zabW       L    ",
      "zabX       L    ",
      "zabjYZ0  F LT   ",
      "zabjjjj1jjjdj222",
      "zabV    3  L  4 ",
      "zabX       L    ",
      "zab0       L    ",
      "zab        L    ",
      "zab5   6   L    ",
      "zabV       L    "
    ],
    [
      "zabF       g    ",
      "zabF       g    ",
      "zabjjjjjjjjdT   ",
      "zab7  n    L    ",
      "zab7       L    ",
      "zab8       L    ",
      "zab        L    ",
      "zab5       L    ",
      "zab7    777LT   ",
      "zabjjjjjjjjdj999",
      "zab!       L    ",
      "zabS       L    ",
      "zab        L    ",
      "zab        L    ",
      "zab        L    ",
      "zab@       L    "
    ],
    [
      "zab        g    ",
      "zab        g    ",
      "zabjjjjjjjjd    ",
      "zab   n    L    ",
      "zab        L    ",
      "zab        L    ",
      "zab        L    ",
      "zab        L    ",
      "zab        L    ",
      "zabjjjjjjjjdj###",
      "zab        L    ",
      "zab        L    ",
      "zab        L    ",
      "zab        L    ",
      "zab        L    ",
      "zab        L    "
    ],
    [
      "zab$$%$$$^$&$$$$",
      "zab$$$$$$$$&$$$$",
      "zab***jjjjjd****",
      "zab$$$n$$$$&$$$$",
      "zab$$^$$$^$&$$$$",
      "zab$$%$$$^$&$$$$",
      "zab$$^$$$^$&$$$$",
      "zab$$^$$$^$&$$$$",
      "zab$$$$$$$$&$$$$",
      "zab***jjjjjdjjjj",
      "zab$$$$$$$$&$$$$",
      "zab$$^$$$^$&$$$$",
      "zab$$^$$$^$&$$$$",
      "zab$$^$$$^$&$$$$",
      "zab$$^$$$^$&$$$$",
      "zab$$$$$$$$&$$$$"
    ]
  ]
}