{
  "name": "multi_laboratory1_4_floor1",
  "refpalette": "c70cities:multi_laboratory1_4_floor1_palette",
  "xsize": 16,
  "zsize": 16,
  "slices": [
    [
      "        abcdeeee",
      "        affdeeee",
      "        affdeeee",
      "        affdeeee",
      "        affdeeee",
      "        affdeeee",
      "        affdeeee",
      "        abcdeeee",
      "        affdee!e",
      "        affdeeee",
      "        affddddd",
      "         agggghg",
      "         aagggbg",
      "           aaaaa",
      "                ",
      "                "
    ],
    [
      "        i  j    ",
      "        i  kl   ",
      "        i  km   ",
      "        n  ko   ",
      "        i  k    ",
      "        i  k    ",
      "        i  k    ",
      "        i  jp qq",
      "        i  k  r ",
      "        i  ks r ",
      "        i  kkkjk",
      "         i      ",
      "         ii     ",
      "           iiiii",
      "                ",
      "                "
    ],
    [
      "        t  j    ",
      "        t       ",
      "        t   u   ",
      "        t       ",
      "        t       ",
      "        n       ",
      "        t       ",
      "        n  jw xy",
      "        t       ",
      "        t       ",
      "        n     j ",
      "         n      ",
      "         nt     ",
      "           ntttn",
      "                ",
      "                "
    ],
    [
      "        t  j    ",
      "        t       ",
      "        n       ",
      "        t       ",
      "        n       ",
      "        t       ",
      "        t       ",
      "        t  jw   ",
      "        t       ",
      "        t       ",
      "        t     j ",
      "         t      ",
      "         nt     ",
      "           ttntt",
      "                ",
      "                "
    ],
    [
      "        t  j    ",
      "        n       ",
      "        t       ",
      "        t       ",
      "        t       ",
      "        t       ",
      "        t       ",
      "        t  j    ",
      "        t       ",
      "        t       ",
      "        n     j ",
      "         t      ",
      "         tt     ",
      "           ntttt",
      "                ",
      "                "
    ],
    [
      "        t  d    ",
      "        t  b    ",
      "        t  b    ",
      "        t  b    ",
      "        t  b    ",
      "        t  b    ",
      "        n  b    ",
      "        t  d    ",
      "        t  b    ",
      "        t  b    ",
      "        t  bbbdb",
      "         t      ",
      "         nn     ",
      "           ttntt",
      "                ",
      "                "
    ]
  ]
}