{
  "name": "multi_megatower1_7_floor8",
  "refpalette": "c70cities:multi_megatower1_7_floor8_palette",
  "xsize": 16,
  "zsize": 16,
  "slices": [
    [
      "==abc           ",
      "==abd           ",
      "==abd           ",
      "==abd           ",
      "==efg           ",
      "==abc           ",
      "==abc           ",
      "==abc           ",
      "==abd           ",
      "==abd           ",
      "==abd           ",
      "==efg           ",
      "==abc           ",
      "==abc           ",
      "==abc           ",
      "==abd           "
    ],
    [
      "zzh c           ",
      "iih d           ",
      "jjh d           ",
      " jh d           ",
      " jefg           ",
      " kh c           ",
      " lh c           ",
      "mnh c           ",
      " nh d           ",
      "koh d           ",
      " oh d           ",
      " eefg           ",
      " ph c           ",
      "qrh c           ",
      " fh c           ",
      "qsh d           "
    ],
    [
      "tth c           ",
      " uh d           ",
      "  h d           ",
      " jh d           ",
      " wefg           ",
      " xh c           ",
      " yh c           ",
      "  h c           ",
      " Ah d           ",
      " qh d           ",
      " qh d           ",
      " eefg           ",
      " ph c           ",
      " kh c           ",
      " qh c           ",
      "Bsh d           "
    ],
    [
      "  h c           ",
      "  h d           ",
      "  h d           ",
      "  h d           ",
      "wwefg           ",
      "  h c           ",
      " Ch c           ",
      "  h c           ",
      "  h d           ",
      " qh d           ",
      " Dh d           ",
      " eefg           ",
      "Eph c           ",
      " Eh c           ",
      " Bh c           ",
      " qh d           "
    ],
    [
      "  h c           ",
      "  h d           ",
      "  h d           ",
      " jh d           ",
      "wwefg           ",
      "  h c           ",
      "  h c           ",
      "  h c           ",
      " ph d           ",
      " ph d           ",
      " ph d           ",
      "peefg           ",
      "pph c           ",
      "Eph c           ",
      "Eph c           ",
      "pph d           "
    ],
    [
      "FFI c           ",
      "FFI d           ",
      "FFI d           ",
      "FFI d           ",
      "JJefg           ",
      "ppI c           ",
      "ppI c           ",
      "ppI c           ",
      "ppI d           ",
      "ppI d           ",
      "ppI d           ",
      "peefg           ",
      "ppI c           ",
      "ppI c           ",
      "ppI c           ",
      "ppI d           "
    ]
  ]
}