{
  "name": "multi_gallery_1_ground",
  "refpalette": "c70cities:multi_gallery_1_ground_palette",
  "xsize": 16,
  "zsize": 16,
  "slices": [
    [
      "GGGGaaaaaaabbGGc",
      "GGGGaaaaaaabbGGG",
      "GGGGaaaaaaabbGGG",
      "GGdGaaaaaaabbGGG",
      "GGdaaaaaaaabbGGG",
      "GGdeeeeeeeefffff",
      "GGdghfffffffffff",
      "GGdi fffffffffff",
      "GGdg fffffffffff",
      "GGdi fffffffffff",
      "GGdg fffffffffff",
      "GGdi fffffffffff",
      "GGdeeeeeeeefffff",
      "GGdGGGGGGGGGGGGG",
      "GGdGGGGGGGGGGGGG",
      "GGGGGGGGGGGGGGGG"
    ],
    [
      "   jkj    lm  no",
      "  pjkq    l     ",
      "  rjkj    l     ",
      "  djkj    l   ss",
      "s dt j    u     ",
      "  deee   eewwwww",
      "  dx         yy ",
      " sdA j          ",
      "  dx j          ",
      "  dA j     jq  B",
      "s dx j     jq  B",
      "  dA j!hh  jCDDE",
      "  deeeeeeeewwwww",
      "s dFIFIFIFI s  s",
      "  d     s     s ",
      " s  s  s        "
    ],
    [
      "    J     l   K ",
      "    J     l     ",
      "    k     l     ",
      "  d k     l     ",
      "  dt      u     ",
      "  deee   eewwwww",
      "  dg            ",
      "  di            ",
      "  dg            ",
      "  di            ",
      "  dg            ",
      "  di  hh        ",
      "  deeeeeeeewwwww",
      "  dFIFIFIFI     ",
      "  d             ",
      "                "
    ],
    [
      "    k     l     ",
      "    k     l     ",
      "    k     l     ",
      "  d k     l     ",
      "  dt      u     ",
      "  deee   eeewwww",
      "  dx            ",
      "  dA            ",
      "  dx            ",
      "  dA            ",
      "  dx            ",
      "  dA hh         ",
      "  deeeeeeeeewwww",
      "  dFIFIFIFI     ",
      "  d             ",
      "                "
    ],
    [
      "    k     l     ",
      "    k     l     ",
      "    J     l     ",
      "  d k     l     ",
      "  dt      u     ",
      "  deeeeeeeeewwww",
      "  dg            ",
      "  di            ",
      "  dg            ",
      "  di            ",
      "  dg            ",
      "  dihh          ",
      "  deeeeeeeeewwww",
      "  dFIFIFIFI     ",
      "  d             ",
      "                "
    ],
    [
      "    LMMMMMN     ",
      "    LMOMMON     ",
      "    kMOMMON     ",
      "  d kMMMMMN     ",
      "  dddddddddddddd",
      "  dddddddddddddd",
      "  dddddddddddddd",
      "  dddddddddddddd",
      "  dddddddddddddd",
      "  dddddddddddddd",
      "  dddddddddddddd",
      "  ddP     dddddd",
      "  dddddddddddddd",
      "  dddddddddddddd",
      "  d             ",
      "                "
    ]
  ]
}