{
  "name": "multi_laboratory1_5_base7",
  "refpalette": "c70cities:multi_laboratory1_5_base7_palette",
  "xsize": 16,
  "zsize": 16,
  "slices": [
    [
      "vvvvvvvvvvvvvvvv",
      "abaaaaaaaaaaaaaa",
      "abcaaaaaaaaaaaaa",
      "baacaabaaaaaaaaa",
      "aaaaaaaaaaaaaaaa",
      "baacacaaaaaaaaab",
      "daeaeeaaaaaaaaaa",
      "aeeeeeaaaaaaaaaa",
      "eeeeaeeaaaaaaaaa",
      "aeaaaaaaaaaaaaaa",
      "aaaaaaaaaaaaaaaa",
      "aaaaaaaaaaaaaaaa",
      "aaaaaaaaaaaaaaaa",
      "aaaaaaaaaaaaaaaa",
      "aaaaaaaaaaaaaaaa",
      "aaaaaaaaaaaaaaaa"
    ],
    [
      "vvvvvvvvvvvvvvvv",
      "aaaaaaaaaaaaaaaa",
      "ffffffffffffffff",
      "   agghiddj  dda",
      " k   l       gmd",
      "n   hno   nd   n",
      "   o p a dba ggd",
      "  qq reaaaaaa ga",
      "p  peeeaaaaaaaaa",
      "ereeeeeaaaaaaaaa",
      "eeeeeeeaaaaaaaaa",
      "eeeaaaaaaaaaaaaa",
      "eaaaaaaaaaaaaaaa",
      "aaaaaaaaaaaaadad",
      "aaaaaaaaaaaaaaad",
      "aaaaaaaaaaaaaaaa"
    ],
    [
      "vvvvvvvvvvvvvvvv",
      "aaaaaaaaaaaaaaaa",
      "ffffffffffffffff",
      "     g         s",
      "  k             ",
      "n    n    n    n",
      "           d  g ",
      " g   pt  daau  d",
      "    wredcaaaaaaa",
      "pprxeeeaaaaaydaa",
      "rxeeeeeaaaaacyya",
      "eeeeaaaaaaaadAAA",
      "eeaaaaaaaaaaau d",
      "eaaaaaaaaaaaa   ",
      "aaaaaaaaaaaaaa  ",
      "aaaaaaaaaaaaaaa "
    ],
    [
      "vvvvvvvvvvvvvvvv",
      "aaaaaaaaaaaaaaaa",
      "ffffffffffffffff",
      "                ",
      "   k            ",
      "n    n    n    n",
      "                ",
      " t    t         ",
      "     B   aaaadaa",
      "  pCpeeaaaaaDDaa",
      "BCeeeeeaaaaayyya",
      "eeaaaaaaaaaaAA A",
      "eaaaaaaaaaaaa   ",
      "aaaaaaaaaaaaa   ",
      "aaaaaaaaaaaaaa  ",
      "aaaaaaaaaaaaaaa "
    ],
    [
      "vvvvvvvvvvvvvvvv",
      "aaaaaaaaaaaaaaaa",
      "ffffffffffffffff",
      "                ",
      "    k           ",
      "n    n    n    n",
      "                ",
      " t    t       ts",
      "     EeF  dd Faa",
      "   eeeeaaaayFDaa",
      "EeeeeeeaaaaayFya",
      "eaaaaaaaaaaaAAca",
      "aaaaaaaaaaaaaFFa",
      "aaaaaaaaaaaaa Fa",
      "aaaaaaaaaaaaaaaa",
      "aaaaaaaaaaaaaaaa"
    ],
    [
      "vvvvvvvvvvvvvvvv",
      "aaaaaaaaaaaaaaaa",
      "ffffffffffffffff",
      "                ",
      "     k          ",
      "n    n    n    n",
      "               F",
      "Ft  t t       ta",
      "cF  eeeaaFFccaaa",
      "effffeffffaffffa",
      "effffeffffaffffa",
      "affffaffffaffffa",
      "affffaffffaffffa",
      "affffaffffaffffa",
      "affffaffffaffffa",
      "aaaaaaaaaaaaaaaa"
    ]
  ]
}