{
  "name": "multi_militarybase_5_base3",
  "refpalette": "c70cities:multi_militarybase_5_base3_palette",
  "xsize": 16,
  "zsize": 16,
  "slices": [
    [
      " abbbcccccccccvv",
      "dabbbcccccccccvv",
      "avaaaaaaavaaavvv",
      "babbbccccaccccvv",
      "babbbccccaccccvv",
      "babbcccccaccccvv",
      "evcccccccaccccvv",
      "cacccccccaccccvv",
      "cacccccccaccccvv",
      "cacccccccaccccvv",
      "avaaaaaaavaaavvv",
      "cacccccccaccccvv",
      "cacccccccaccccvv",
      "cacccccccaccccvv",
      "cvcccccccvccccvv",
      "vvvvvvvvvvvvvvvv"
    ],
    [
      " f   ghg ihi jvv",
      " f   ghg ihi jvv",
      "fv       vkkkvvv",
      "     ghg lmnnovv",
      "     ghg l   pvv",
      "             qvv",
      " vr          qvv",
      "             qvv",
      " ihi ihg ls  pvv",
      " ihi ihg ls  ovv",
      " v       vktkvvv",
      " uhu ghg kw  xvv",
      " ihu ghi kw  xvv",
      "         kwyyxvv",
      " vAABuhg vwCxxvv",
      "vvvvvvvvvvvvvvvv"
    ],
    [
      "          D   vv",
      "              vv",
      " v       vkkkvvv",
      "         lm   vv",
      "         l   Evv",
      "             Fvv",
      " vr          Fvv",
      "             Fvv",
      "         l    vv",
      "      I  l    vv",
      " v       vkJkvvv",
      "  !      kw   vv",
      "         k   xvv",
      "         kwyKLvv",
      " v       vw!xxvv",
      "vvvvvvvvvvvvvvvv"
    ],
    [
      "              vv",
      "             Kvv",
      " v       vkkkvvv",
      "         lM  Nvv",
      "         l   Ovv",
      "         l   Pvv",
      " vr      l   Pvv",
      "         l   Pvv",
      "         l   Ovv",
      "         l   Nvv",
      " v       vkkkvvv",
      "         k    vv",
      "         k   Kvv",
      "         k    vv",
      " v       vwKQQvv",
      "vvvvvvvvvvvvvvvv"
    ],
    [
      " R            vv",
      " R            vv",
      "Rv       vkkkvvv",
      "         f    vv",
      "         f    vv",
      "         f   Svv",
      " vr      f   Svv",
      "         f   Svv",
      "         f    vv",
      "         f    vv",
      "fvfffffffvkkkvvv",
      "         k    vv",
      "         k    vv",
      "         k    vv",
      " v       v   Kvv",
      "vvvvvvvvvvvvvvvv"
    ],
    [
      " TUUUUUUUUUUUSvv",
      " TUUUUUUUUUUUSvv",
      "Tvaaaaaaavaaavvv",
      "UaUUUUUUUaUUUSvv",
      "UaUUUUUUUaUUUSvv",
      "UaUUUUUUUaUUUSvv",
      "UvrUUUUUUaUUUSvv",
      "UaUUUUUUUaUUUSvv",
      "UaUUUUUUUaUUUSvv",
      "UaUUUUUUUaUUUSvv",
      "avaaaaaaavaaavvv",
      "UaUUUUUUUaUUUSvv",
      "UaUUUUUUUaUUUSvv",
      "UaUUUUUUUaUUUSvv",
      "SvSSSSSSSvSSSSvv",
      "vvvvvvvvvvvvvvvv"
    ]
  ]
}