{
  "name": "multi_militarybase_4_base2",
  "refpalette": "c70cities:multi_militarybase_4_base2_palette",
  "xsize": 16,
  "zsize": 16,
  "slices": [
    [
      "vvvvvvvvvvvvvvvv",
      "avaaaaaaavaaaavv",
      "abaaaaaaabaaaavv",
      "abaaaaaaabaaaavv",
      "abaaaaaaabaaaavv",
      "bvbbbbbbbvbbbvvv",
      "abaaaaaaabaaaavv",
      "abaaaaaaabaaaavv",
      "abaaaaaaabaaaavv",
      "cvdaaaaaabaaaavv",
      "ebeeaaaaabaaaavv",
      "ebeeeaaaabaaaavv",
      "ebeeeaaaabaaaavv",
      "bvbbbbbbbvbbbvvv",
      " beeeaaaaaaaaavv",
      " beeeaaaaaaaaavv"
    ],
    [
      "vvvvvvvvvvvvvvvv",
      "!vf f f fvghghvv",
      " ij j j ji   hvv",
      " i       k   lvv",
      " i       i   lvv",
      "mvmmmnmmmvioivvv",
      "         p  qrvv",
      "         p    vv",
      "         p  qrvv",
      "mvd      s    vv",
      "         p  qrvv",
      "         p    vv",
      "         p  qrvv",
      "tv       viiivvv",
      " t        uwx vv",
      " t           yvv"
    ],
    [
      "vvvvvvvvvvvvvvvv",
      " vf f f fv A hvv",
      " ij j j ji   Bvv",
      " i       C    vv",
      " i       i    vv",
      "mvmmmDmmmviEivvv",
      "         p  qrvv",
      "         p    vv",
      "         p  qrvv",
      "mvd      F    vv",
      "         p  qrvv",
      "         p    vv",
      "         p  qrvv",
      " v       viiivvv",
      "            I vv",
      "              vv"
    ],
    [
      "vvvvvvvvvvvvvvvv",
      " v       v    vv",
      " i       i    vv",
      " i       i    vv",
      " i       i    vv",
      "mvmmmmmmmviiivvv",
      "         p    vv",
      "         p    vv",
      "         p    vv",
      "mvd      p    vv",
      "         p    vv",
      "         p    vv",
      "         p    vv",
      " v       viiivvv",
      "              vv",
      "              vv"
    ],
    [
      "vvvvvvvvvvvvvvvv",
      " v       v    vv",
      " i       i    vv",
      " i       i    vv",
      " i       i    vv",
      "mvtttttttviiivvv",
      " t       t    vv",
      " t       t    vv",
      " t       t    vv",
      "tvd      t    vv",
      "         t    vv",
      "         t    vv",
      "         t    vv",
      "Jv       viiivvv",
      " J            vv",
      " J            vv"
    ],
    [
      "vvvvvvvvvvvvvvvv",
      "KvKKKKKKKvKKKKvv",
      "LbLLLLLLLbLLLKvv",
      "LbLLLLLLLbLLLKvv",
      "LbLLLLLLLbLLLKvv",
      "bvbbbbbbbvbbbvvv",
      "LbLLLLLLLbLLL!vv",
      "LbLLLLLLLbLLLKvv",
      "LbLLLLLLLbLLLKvv",
      "LvdLLLLLLbLLLKvv",
      "LbLLLLLLLbLLLKvv",
      "LbLLLLLLLbLLLKvv",
      "LbLLLLLLLbLLLKvv",
      "Mvbbbbbbbvbbbvvv",
      " MLLLLLLLLLLLKvv",
      " MLLLLLLLLLLLKvv"
    ]
  ]
}