{
  "name": "multi_laboratory1_14_base1",
  "refpalette": "c70cities:multi_laboratory1_14_base1_palette",
  "xsize": 16,
  "zsize": 16,
  "slices": [
    [
      "aaaabaaaaaaaacdv",
      "aaaaaaaaaaaaacdv",
      "aaaaaaaaaaaaacdv",
      "aaaaaaaaaaaaacdv",
      "aaaaaaaaaaaaacdv",
      "aaaaaaaaaaaaacdv",
      "aaaaaaaaaaaaacdv",
      "aaaabaaaaaaaacdv",
      "aaaaaeeeeeeeecdv",
      "aaaaaeeeeeeeecdv",
      "aaaaaeeeeeeeecdv",
      "aaaaaeeeeeeeecdv",
      "aaaaaee!eeeeecdv",
      "ccccccccccccccdv",
      "dddddddddddddddv",
      "vvvvvvvvvvvvvvvv"
    ],
    [
      "    b       fcdv",
      "    g   h   fcdv",
      "    g  iii  jcdv",
      "    k       lcdv",
      "    g  mmm  jcdv",
      "    g  h h  lcdv",
      "    g      nlcdv",
      "o   bppppppppcdv",
      "q   prrssssrrcdv",
      "q   t        cdv",
      "q   puwuwxwuwcdv",
      "q   p y y y ycdv",
      "!qqopAyAyAyAycdv",
      "ccccccccccccccdv",
      "dddddddddddddddv",
      "vvvvvvvvvvvvvvvv"
    ],
    [
      "    b        cdv",
      "    g        cdv",
      "    g  B C  Dcdv",
      "    E        cdv",
      "    g  F I   cdv",
      "    g       Jcdv",
      "    g K     Dcdv",
      "L   bppppppppcdv",
      "    pM NNNNNMcdv",
      "    O        cdv",
      "    pPwPwQwPwcdv",
      "R   p y y y ycdv",
      "LSTLp y y y ycdv",
      "ccccccccccccccdv",
      "dddddddddddddddv",
      "vvvvvvvvvvvvvvvv"
    ],
    [
      "    b        cdv",
      "    g        cdv",
      "    g       Ucdv",
      "    g       Vcdv",
      "    g        cdv",
      "    g       Ucdv",
      "    g       Vcdv",
      "M   bppppppppcdv",
      "    p N  NN  cdv",
      "    p        cdv",
      "    pwwwwwwwwcdv",
      "    p y y y ycdv",
      "MW Mp y y y ycdv",
      "ccccccccccccccdv",
      "dddddddddddddddv",
      "vvvvvvvvvvvvvvvv"
    ],
    [
      "    b        cdv",
      "    g        cdv",
      "    g        cdv",
      "    g       Xcdv",
      "    g        cdv",
      "    g       Ycdv",
      "    g       !cdv",
      "    bppppppppcdv",
      "    pZZZZZZZZcdv",
      "    pZZZZZZZZcdv",
      "    pZZZZZZZZcdv",
      "    pZZZZZZZZcdv",
      "    p0Z0Z0Z0Zcdv",
      "ccccccccccccccdv",
      "dddddddddddddddv",
      "vvvvvvvvvvvvvvvv"
    ],
    [
      "1111b11111111cdv",
      "1111211111111cdv",
      "1111213111311cdv",
      "1111213111311cdv",
      "1111213111311cdv",
      "1111213111311cdv",
      "1111211111111cdv",
      "1111bppppppppcdv",
      "1111p44444444cdv",
      "1111p4 4 4 4ccdv",
      "1111p4 4 4 4ccdv",
      "1111p4 4 4 4ccdv",
      "1111p4 4 4 4ccdv",
      "ccccccccccccccdv",
      "dddddddddddddddv",
      "vvvvvvvvvvvvvvvv"
    ]
  ]
}