{
  "name": "multi_megatower1_4_ground",
  "refpalette": "c70cities:multi_megatower1_4_ground_palette",
  "xsize": 16,
  "zsize": 16,
  "slices": [
    [
      "a   vvvvvvvvvvvv",
      "a   vvvvvvvvvvvv",
      "a   vvvvvvvvvvvv",
      "bcddvvvvvvvvvvvv",
      "vvvvevvvvvvevvvv",
      "vvvvfvvvvvvvvvvv",
      "HHghi           ",
      "HHghi           ",
      "HHghi           ",
      "HHghi           ",
      "vvvvjvvvvvvvvvvv",
      "    e      e    ",
      "                ",
      "                ",
      "                ",
      "                "
    ],
    [
      "a   kl     mannn",
      "a   ko     pannn",
      "a   kqrs   tannn",
      "aduukqs    mannn",
      "wxyAeBCqstreannn",
      "    Dvvvvvvvvvvv",
      "                ",
      "                ",
      "                ",
      "                ",
      "EEEFDvvvvvvvvvvv",
      "    e      eeeee",
      "                ",
      "                ",
      "                ",
      "                "
    ],
    [
      "a   k       annn",
      "a   k      Iannn",
      "a   k       annn",
      "ad  kr      annn",
      "w JKeLq r reannn",
      "     vvvvvvvvvvv",
      "             MMa",
      "             MMa",
      "             MMa",
      "             MMa",
      "     vvvvvvvvvvv",
      "    e      e MMa",
      "             MMa",
      "             MMa",
      "             MMa",
      "             MMa"
    ],
    [
      "a   k    MMennnn",
      "a   k    MMennnn",
      "a   k    MMennnn",
      "adddk    MMennnn",
      "wN  eeeeeeeennnn",
      "     vvvvvvevnnn",
      "         MMeaann",
      "         MMeaann",
      "         MMeaann",
      "         MMeaann",
      "     vvvvvvevnnn",
      "    eeeeeeeeannn",
      "         MMeannn",
      "         MMeannn",
      "         MMeannn",
      "         MMeannn"
    ],
    [
      "a   OMMaannnn   ",
      "a   OMMaannnn   ",
      "a   OMMaannnn   ",
      "adddOMMaannnn   ",
      "wwwweMMaannenP  ",
      "     vvvvnnnn   ",
      "     MMaannnnQ  ",
      "     MMaannnnQ  ",
      "     MMaannnnQ  ",
      "     MMaannnnQ  ",
      "     vvvvnnnn   ",
      "    eMMaannen   ",
      "     MMaannnn   ",
      "     MMaannnn   ",
      "     MMaannnn   ",
      "     MMaannnn   "
    ],
    [
      "e   ennnn       ",
      "e   ennnn       ",
      "e   ennnn       ",
      "edRSennnnT P    ",
      "eeeeennnn  e    ",
      "MMMMennnn P T   ",
      "MMMMennnnQ      ",
      "MMMMennnnQ      ",
      "MMMMennnnQ      ",
      "MMMMennnnQ      ",
      "MMMMennnn       ",
      "eeeeennnn  e    ",
      "MMMMennnn T     ",
      "MMMMennnn       ",
      "MMMMennnn       ",
      "MMMMennnn       "
    ]
  ]
}