{
  "name": "multi_militarybase_3_ground",
  "refpalette": "c70cities:multi_militarybase_3_ground_palette",
  "xsize": 16,
  "zsize": 16,
  "slices": [
    [
      "aaaaaaaaaaaaaaaa",
      "aaaaaaaaaaaaaaaa",
      "bbbbbbbbaaaaaaaa",
      "bbbcdbbbaaaaaaaa",
      "bbbbbbbbaaaaaaaa",
      "bbbbbbbbaaaaaaaa",
      "bbbeeeebaaaaaaaa",
      "eeeeeeebaaffaffa",
      "eeeeeeebaaffaffa",
      "eeeeeeebaaffaffa",
      "eeeeeeebaaaaaaaa",
      "bbbbbbbbzaaaaaaa",
      "aaaazaaaaazzzzaz",
      "zzazzzzaazazzaaz",
      "gggggggggggggggg",
      "hhhhhhhhhhhhhhhh"
    ],
    [
      "     i          ",
      "                ",
      "  jjjjjjkkkkk kk",
      "  jclmmjn   o  k",
      "  j   pj        ",
      "  j   qj o      ",
      "rjjstusj  wx wx ",
      " y    Aj  f! ff ",
      "      Bj  ff ff ",
      "      Bj nff ffC",
      "DE    !j    o   ",
      "jjjjjjjjkkkkkkkk",
      "                ",
      "   F F I F FJ   ",
      "gggggggggggggggg",
      "                "
    ],
    [
      "                ",
      "                ",
      "  KKKKKKkkkkk kk",
      "  Kc LLK       k",
      "  M    M        ",
      "  K    M        ",
      "NKKsOPsK  QR QR ",
      " S     K  ff ff ",
      "       M  ffcffc",
      "       M  TT TT ",
      " U    VK        ",
      "KKKMMMMKkkkkkkkk",
      "                ",
      "       I   J    ",
      "gggggggggggggggg",
      "                "
    ],
    [
      "                ",
      "                ",
      "  KKKKKKkkkkk kk",
      "  Kc llKW      k",
      "  M    KW       ",
      "  K    KW       ",
      "KKKssssKW       ",
      "       KW ff ff ",
      "       KW ff ff ",
      "       KW       ",
      "      VKW       ",
      "KKKKKKKKkkkkkkkk",
      "   WWWW         ",
      "       I  J     ",
      "gggggggggggggggg",
      "                "
    ],
    [
      "                ",
      "                ",
      "  KKKKKKXXXXXXXX",
      "  Kc pYK       X",
      "  Kp  YZ        ",
      "  K   YZ        ",
      "ZKKYYYYK        ",
      "YY    YK  00 00 ",
      "      YZ  00 00 ",
      "      YZ        ",
      "1 YYYYYK        ",
      "KKKZZZZKXXXXXXXX",
      "                ",
      "       I J      ",
      "gggggggggggggggg",
      "                "
    ],
    [
      "  j2222j        ",
      "  j2222j        ",
      "  jhhhhj        ",
      "  jchhhj        ",
      "  jhhhhj        ",
      "  jhhhhj        ",
      "jjjhhhhj        ",
      "hhhhhhhj        ",
      "hhhhhhhj        ",
      "hhhhhhhj        ",
      " 1hhhhhj        ",
      "jjjjjjjj        ",
      "      3         ",
      "444444544       ",
      "6666666786666966",
      "                "
    ]
  ]
}