{
  "name": "multi_communitycenter_8_ground",
  "refpalette": "c70cities:multi_communitycenter_8_ground_palette",
  "xsize": 16,
  "zsize": 16,
  "slices": [
    [
      "aaaaaabbbbbbbbGc",
      "aaaaaabbbbbbbbGc",
      "dddddabbbbbbbbGc",
      "eaaaaabbbbbbbbGc",
      "eaaaaabbbbbbbbGc",
      "aaaaaabbbbbbbbGc",
      "aaaaaabbbbbbbbGc",
      "bbbbbbbbbbbbbbGc",
      "  fggbcccGGGGGGc",
      "  f  bcccGGGGGGc",
      "  h  bcccGGGGGGc",
      "     bcccGGGGGGc",
      "     bcccGGGGGGc",
      "bbbbbbcccccccccc",
      "cccccccccccccccc",
      "cccccccccccccccc"
    ],
    [
      "  i jk   lmmmnh ",
      "oopqqk  p    rs ",
      "tttuuk  w xyArs ",
      "BC   k  p  y rs ",
      "BC   k   lxyAnh ",
      "D    E  p  y ns ",
      "     F  pIxyAns ",
      "ttt  knJnnnnnns ",
      "  f  k   hK LKh ",
      "  f  k   sKKK s ",
      "  h  k   sL LKs ",
      "     k   sKLKKs ",
      "     k   hssssh ",
      "kkkkkk          ",
      "                ",
      "                "
    ],
    [
      "  M Nk   lOOOn  ",
      "  pqqk  p    r  ",
      "tPP  k  Q  R r  ",
      " BC  k  p    r  ",
      " BC  k   l R n  ",
      "SD   T  pU   n  ",
      "     V  pW   n  ",
      "tPP  knXnnnnnn  ",
      "  f  k    Y ZY  ",
      "  f  k    YYY   ",
      "  h  k    Z ZY  ",
      "     k    YZYY  ",
      "     0          ",
      "0kk000          ",
      "                ",
      "                "
    ],
    [
      "  p11k   lmmmn  ",
      "  p22k  p    3  ",
      "tPP  k  p    3  ",
      "  BC k  p    3  ",
      "  BC k   l   n  ",
      " SD  k  pU   n  ",
      "     k  pW   n  ",
      "tPP  knnnnnnnn  ",
      "  f  k          ",
      "  f  k          ",
      "  h  k          ",
      "     k          ",
      "     0          ",
      "0kk000          ",
      "                ",
      "                "
    ],
    [
      "    Ik  4lmmmn  ",
      "     k  p    r  ",
      "tPPPPk  p    r  ",
      "   BCk  p    r  ",
      "   BCk   l   n  ",
      "  SD k  p5   n  ",
      "     k  p    n  ",
      "tPPPPknnnnnnnn  ",
      "  f  k          ",
      "  f  k          ",
      "  h  k          ",
      "     k          ",
      "     k          ",
      "kkkkkk          ",
      "                ",
      "                "
    ],
    [
      "66666kbbbbbbb7  ",
      "66666kbbbbbbb7  ",
      "tttttkbbbbbbb7  ",
      "    Bebbbbbbb7  ",
      "    Bebbbbbbbn  ",
      "   SDkbbbbbbb7  ",
      "     kbbbbbbb7  ",
      "tttttk777n7777  ",
      "66666k          ",
      "66666k          ",
      "66666k          ",
      "66666k          ",
      "66666k          ",
      "kkkkkk          ",
      "                ",
      "                "
    ]
  ]
}