{
  "name": "multi_militarybase_1_base3",
  "refpalette": "c70cities:multi_militarybase_1_base3_palette",
  "xsize": 16,
  "zsize": 16,
  "slices": [
    [
      "vaaaaaaaabcccb  ",
      "vaaaaaaaabcccbdd",
      "vvaaaaaaabbbbvbb",
      "vaaaaaaaabcccbcc",
      "vaaaaaaaabcccbcc",
      "vaaaaaaaabaccbcc",
      "vaaaaaaaabaaavee",
      "vaaaaaaaabaaabaa",
      "vaaaaaaaabaaabaa",
      "vaaaaaaaabaaabaa",
      "vvbbbvbbbvbbbvbb",
      "vaaaabaaabaaabff",
      "vaaaabaaabaaabff",
      "vaaaabaaabaaabff",
      "vaaaavaaavaaavff",
      "vvvvvvvvvvvvvvvv"
    ],
    [
      "vg  hij      k  ",
      "vg lhijm     k  ",
      "vv  hij      vk ",
      "vj lh!jm        ",
      "vj  hij         ",
      "vj lnnnm        ",
      "vj   o      pv  ",
      "v               ",
      "v               ",
      "v             qr",
      "vvsssvsssv   vtt",
      "vuw      x   xy ",
      "vuw      A   xtt",
      "vuw  x B x   xy ",
      "vCDDEvFFFvIIIvtt",
      "vvvvvvvvvvvvvvvv"
    ],
    [
      "vJ   K          ",
      "vL  MKN         ",
      "vv   K       v  ",
      "vO  NKP         ",
      "v    K          ",
      "vO   M          ",
      "v           pv  ",
      "v               ",
      "v               ",
      "v               ",
      "vvsssvsssv   vtt",
      "v        x   x  ",
      "vQ       R   xtt",
      "v    xS  x   x  ",
      "vT  UvLVWvIIXvtt",
      "vvvvvvvvvvvvvvvv"
    ],
    [
      "v               ",
      "v               ",
      "vv           v  ",
      "v               ",
      "v               ",
      "v               ",
      "v           pv  ",
      "v               ",
      "v               ",
      "v               ",
      "vvsssvsssv   vtt",
      "vQ       x   x  ",
      "vQ       x   xtt",
      "vQ   x   x   x  ",
      "v  Y v   vZIIvtt",
      "vvvvvvvvvvvvvvvv"
    ],
    [
      "v        k   s  ",
      "v        k   s  ",
      "vv       k   vss",
      "v        k      ",
      "v        k      ",
      "v        k      ",
      "v        k  pv  ",
      "v        k      ",
      "v        k      ",
      "v        k      ",
      "vvsssvsssvkkkvtt",
      "v0   x   x   x11",
      "v    x   x   x11",
      "v2   x   x   x11",
      "v    v   v   v11",
      "vvvvvvvvvvvvvvvv"
    ],
    [
      "v34444444b4445  ",
      "v34444444b4445  ",
      "vv4444444b444v55",
      "v34444444b444b44",
      "v34444444b444b44",
      "v34444444b444b44",
      "v34444444b44pv44",
      "v34444444b444b44",
      "v34444444b444b44",
      "v34444444b444b44",
      "vvbbbvbbbvbbbvbb",
      "v3444b444b444b  ",
      "v3444b444b444b0 ",
      "v3444b444b444b0 ",
      "v3333v333v333v33",
      "vvvvvvvvvvvvvvvv"
    ]
  ]
}