{
  "name": "multi_laboratory1_3_base5",
  "refpalette": "c70cities:multi_laboratory1_3_base5_palette",
  "xsize": 16,
  "zsize": 16,
  "slices": [
    [
      "vab             ",
      "vac             ",
      "vdeeeeeeeeedffff",
      "vb         g    ",
      "vb         g    ",
      "vb         g    ",
      "vb         g    ",
      "vb         g    ",
      "vb         g    ",
      "vdddddddddddh   ",
      "vbiiiid    g    ",
      "vbiiiidj   g    ",
      "vbiiiid    g    ",
      "vbiiiid    g    ",
      "vbiiikd    g    ",
      "vbiiiid    g    "
    ],
    [
      "vab             ",
      "vac             ",
      "vdeeeeeeeeedffff",
      "vb         g    ",
      "vb         g    ",
      "vb         g    ",
      "vb         g    ",
      "vb         g    ",
      "vb         g    ",
      "vdlllleeeeed    ",
      "vb    emm  g    ",
      "vbn  oe m  g    ",
      "vbp   e m  g    ",
      "vbn   e m  g    ",
      "vb    e m  g    ",
      "vbqqq e m  g    "
    ],
    [
      "vab             ",
      "vac             ",
      "vdeeeeeeeeedffff",
      "vb         g    ",
      "vb         g    ",
      "vb         g    ",
      "vb         g    ",
      "vb         g    ",
      "vb         g    ",
      "vdlllleeeeed    ",
      "vb    e    g    ",
      "vb    e    g    ",
      "vbr   e    g    ",
      "vb   se    g    ",
      "vb    e    g    ",
      "vb    e    g    "
    ],
    [
      "vab             ",
      "vac             ",
      "vdeeeeeeeeedffff",
      "vb         g    ",
      "vb         g    ",
      "vb         g    ",
      "vb         g    ",
      "vb         g    ",
      "vb         g    ",
      "vdlllleeeeed    ",
      "vb    e    g    ",
      "vb    e    g    ",
      "vb    e    g    ",
      "vb    e    g    ",
      "vb    e    g    ",
      "vbtuw e    g    "
    ],
    [
      "vab             ",
      "vac             ",
      "vdeeeeeeeeedxxxx",
      "vb         e    ",
      "vb         e    ",
      "vb         e    ",
      "vb         e    ",
      "vb         e    ",
      "vb         e    ",
      "vdlllleeeeed    ",
      "vb    e    e    ",
      "vb    e    e    ",
      "vb    e    e    ",
      "vb    e    e    ",
      "vb    e    e    ",
      "vb    e    e    "
    ],
    [
      "vabcyyyyyyyyyyyy",
      "vaccyyyyyyyyyyyy",
      "vdeeeeeeeeedAAAA",
      "vbBBBBBBBBBeBBBB",
      "vbBBBBBBBBBeBBBB",
      "vbBBCCCCCBBeBBBB",
      "vbBBCCCCCBBeBBBB",
      "vbBBBBBBBBBeBBBB",
      "vbBBBBBBBBBeBBBB",
      "vdDDDDeeeeeeBBBB",
      "vbyyyyeBBBBeBBBB",
      "vbyyyyeBBBBeBBBB",
      "vbyyyyeBCEBeBBBB",
      "vbyyyyeBCEBeBBBB",
      "vbyyyyeBBBBeBBBB",
      "vbyyyyeBBBBeBBBB"
    ]
  ]
}