{
  "name": "multi_cafe_2_ground",
  "refpalette": "c70cities:multi_cafe_2_ground_palette",
  "xsize": 16,
  "zsize": 16,
  "slices": [
    [
      "GGGGGGGGGGGGGGGG",
      "GGGGGGGGGGGGGGGG",
      "aaaaaaaaaaaaaaGG",
      "aaaaaaaaaaaaaaGG",
      "bbbbbaaaabbbaaGG",
      "cc============GG",
      "cc=dddddddddddeG",
      "cc=dddddddddddGG",
      "cc=dddddddddddeG",
      "cc=dddddddddddGG",
      "cc=dddddddddddGG",
      "cc=dddddddddddGG",
      "cc=dddddddddddGG",
      "cc=dddddddddddeG",
      "cc=dddddddddddGG",
      "cc=dddddddddddGG"
    ],
    [
      "f gh i    gf gii",
      "ififj   ifjk k  ",
      "              li",
      "             ml ",
      "nnnnno  pnnn mli",
      "  qqqrstrqqq==li",
      "u qw        xyAi",
      "  qBC       xyli",
      "  qBD   EFIJKKA ",
      "u qB    L L Myl ",
      "  qBC   L L Nyl ",
      "  qB    LOLO yli",
      "u qBC   L LIIyl ",
      "  qwD   EPPQKKAi",
      " RR       S Tyl ",
      "          S Uyli"
    ],
    [
      "                ",
      "                ",
      "              l ",
      "             ml ",
      "     o  p    ml ",
      "  qqqrVWrqqq==l ",
      "  q          XA ",
      "  q          Xl ",
      "  q Y   EZI0KKA ",
      "  q     L L  yl ",
      "  q     L L  yl ",
      "  q     L1L1 yl ",
      "  q     LrLrIyl ",
      "  q2Y   EPP3KKA ",
      " RR       4 5yl ",
      "             yl "
    ],
    [
      "                ",
      "                ",
      "              l ",
      "             ml ",
      "     6778    ml ",
      "  qqqrrrrqqq==l ",
      "  q          XA ",
      "  q          Xl ",
      "  q Y   EIIIKKA ",
      "  q     L L  yl ",
      "  q     L L  q  ",
      "  q     L L  q  ",
      "  q     L LIIyl ",
      "  q Y   EPPPKKA ",
      " 99         @yl ",
      " 77         @q  "
    ],
    [
      "                ",
      "                ",
      "              l ",
      "             ml ",
      "             ml ",
      "  qqqqqqqqqq==l ",
      "  q          yA ",
      "  q          y# ",
      "  q Y   E$$$KKA ",
      "  q     % %  y# ",
      "  q     % %  y# ",
      "  q     % %  y# ",
      "  q     %$%$$y# ",
      "  q Y   E^^^KKA ",
      "  q         &y# ",
      "  q         &y# "
    ],
    [
      "                ",
      "                ",
      "              l ",
      "             ml ",
      "             ml ",
      "  qqqqqqqqqq==l ",
      "  q          yA ",
      "  q          yl ",
      "  q Y   EIIIKKA ",
      "  q     Lrrrryl ",
      "  q     Lrrrryl ",
      "  q     Lrrrryl ",
      "  q     Lrrrryl ",
      "  q Y   EPPPKKA ",
      "  q          yl ",
      "  q          yl "
    ]
  ]
}