{
  "name": "multi_megatower1_7_base2",
  "refpalette": "c70cities:multi_megatower1_7_base2_palette",
  "xsize": 16,
  "zsize": 16,
  "slices": [
    [
      "HHHHHHHHHHHvvaav",
      "HHHHHHHHHHHvvaav",
      "HHHHHHHHHHHvvaav",
      "HHHHHHHHHHHvvaav",
      "HHbHHHHHHbHvvaav",
      "vvHHHHHHHHHvvaav",
      "vvHHHHHHHHHvvaav",
      "vvHHHHHHHHHvvaav",
      "vvHHHHHHHHHvvaav",
      "vvHHHHHHHHHvvaav",
      "vvHHHHHHHHHvvaav",
      "HHbHHHHHHbHvvaav",
      "HHHHHHHHHHHvvaav",
      "HHHHHHHHHHHvvaav",
      "HHHHHHHHHHHvvaav",
      "HHHHHHHHHHHvvaav"
    ],
    [
      "        c devaav",
      "        f gevaav",
      "        c devaav",
      " d      f gevaav",
      " gbh    ib evaav",
      "vvj     c devaav",
      "Hkj     f gevaav",
      "Hkj     c devaav",
      "Hkj     f gevaav",
      "Hkj     c devaav",
      "vvj     f gevaav",
      " !bh    ib evaav",
      "        c devaav",
      " c d    f gevaav",
      " f g    c devaav",
      " c d    f gevaav"
    ],
    [
      "            vaav",
      "            vaav",
      "            vaav",
      "            vaav",
      "  b      b  vaav",
      "vv          vaav",
      "            vaav",
      "            vaav",
      "            vaav",
      "            vaav",
      "vv          vaav",
      "  b      b  vaav",
      "            vaav",
      "            vaav",
      "            vaav",
      "            vaav"
    ],
    [
      "            vaav",
      "            vaav",
      "            vaav",
      "            vaav",
      "  b      b  vaav",
      "vv          vaav",
      "            vaav",
      "            vaav",
      "            vaav",
      "            vaav",
      "vv          vaav",
      "l b      b  vaav",
      "            vaav",
      "            vaav",
      "            vaav",
      "            vaav"
    ],
    [
      "            vaav",
      "            vaav",
      "            vaav",
      "            vaav",
      "  b      bm vaav",
      "vv          vaav",
      "            vaav",
      "            vaav",
      "            vaav",
      "            vaav",
      "vv          vaav",
      "llb      bm vaav",
      "  l         vaav",
      "            vaav",
      "            vaav",
      "            vaav"
    ],
    [
      "nnbnnnnnnbnvvaav",
      "nnbnnnnnnbnvvaav",
      "nnbnnnnnnbnvvaav",
      "nnbnnnnnnbnvvaav",
      "bbbbbbbbbbnvvaav",
      "vvbnnnnnnbnvvaav",
      "  bnnnnnnbnvvaav",
      "  bnnnnnnbnvvaav",
      "  bnnnnnnbnvvaav",
      "  bnnnnnnbnvvaav",
      "vvbnnnnnnbnvvaav",
      "bbbbbbbbbbnvvaav",
      " nbnnnnnnbnvvaav",
      " nbnnnnnnbnvvaav",
      " nbnnnnnnbnvvaav",
      " nbnnnnnnbnvvaav"
    ]
  ]
}