{
  "name": "multi_convenientstore_3_ground",
  "refpalette": "c70cities:multi_convenientstore_3_ground_palette",
  "xsize": 16,
  "zsize": 16,
  "slices": [
    [
      "aaaaaaaaaaaaHHHb",
      "cccccccccccaHHHb",
      "cccccccccccaHHHb",
      "cccccccccccaHHHb",
      "cccccccccccaHHHb",
      "cccccccccccaHHHb",
      "cccccccccccaHHHb",
      "cccccccccccaHHHb",
      "cccccccccccaHHHb",
      "cccccccccccaHHHb",
      "cccccccccccaHHHb",
      "cccccccccccaHHHb",
      "aaaaaaaaaaaaHHHb",
      "HHHHHHHHHHHHHHHb",
      "HHHHHHHHHHHHHHHb",
      "bbbbbbbbbbbbbbbb"
    ],
    [
      "aaaaaaaaaaaaddde",
      "cccccccccccaddde",
      "cccccccccccaddde",
      "cccccccccccaddde",
      "cccccccccccaHHHb",
      "cccccccccccaHHHb",
      "cccccccccccaHHHb",
      "cccccccccccaHHHb",
      "cccccccccccaHHHb",
      "cccccccccccaHHHb",
      "cccccccccccaHHHb",
      "cccccccc!ccaHHHb",
      "aaaaaaaaaaaaHHHb",
      "HHHHHHHHHHHHHHHb",
      "HHHHHHHHHHHHHHHb",
      "HHHHHHHHHHHHHHHb"
    ],
    [
      "fghhhhhiiiij    ",
      "       k  lj    ",
      "       k  mj    ",
      "       k  nj   e",
      "  oppp k qnj   e",
      "  r    s  nj   e",
      " t     uwxwj   e",
      "  yyyyyu       e",
      "  ABBCDy       e",
      "     EFk       e",
      "I    J k  Kj   e",
      " L!ILEMkNOOj   e",
      "jjjjjjjjjjjj   e",
      "  P   PN N     e",
      "               e",
      "               e"
    ],
    [
      "Qghhhhhiihij    ",
      "       k  Dj    ",
      "       k   j    ",
      "       k   h    ",
      "   RS  k   h    ",
      "  T    UV  h    ",
      " tW   XuwYwj    ",
      "  ZZZ 0u   1    ",
      "   A2CCy   1    ",
      "     E3k   1    ",
      "     4 k   j    ",
      " 5667E k  8j    ",
      "jjjjjjjjjjjj    ",
      "  9  N9N        ",
      "                ",
      "                "
    ],
    [
      "gghhhhhiihij    ",
      "       k   j    ",
      "       k   j    ",
      "       k   h    ",
      "       k   h    ",
      "       k   h    ",
      " t56667uwwwj    ",
      "  ZZZ@@u   1    ",
      "    ACCy   1    ",
      "     E k   1    ",
      "     E#k   j    ",
      "  $I%E kN  j    ",
      "jjjjjjjjjjjj    ",
      "99^999^         ",
      "                ",
      "                "
    ],
    [
      "hhhhhhhiihij    ",
      "       k   j    ",
      "       k   j    ",
      "       k  &j    ",
      "       k  &j    ",
      "       k  &j    ",
      "*()))))uwwwj    ",
      "+ iiiiiuN  c    ",
      "+    -Cy   c    ",
      "     CCy   c    ",
      "     CCyN Nj    ",
      "[99[99[9999j    ",
      "jjjjjjjjjjjj    ",
      "     N9         ",
      "                ",
      "                "
    ]
  ]
}