{
  "name": "multi_laboratory1_10_base6",
  "refpalette": "c70cities:multi_laboratory1_10_base6_palette",
  "xsize": 16,
  "zsize": 16,
  "slices": [
    [
      "vvvvvvvvvvvvvvvv",
      "aaaaaaaaaaaaaaav",
      "bbbbccccccccccav",
      "  dde========cav",
      "   de========cav",
      "eeeee========cav",
      "====e========cav",
      "====effffffffcav",
      "====effffffffcav",
      "====effffffffcav",
      "====effffffffcav",
      "====effffffffcav",
      "====effffffffcav",
      "====effffffffcav",
      "====effffffffcav",
      "eeeeeffffffffcav"
    ],
    [
      "vvvvvvvvvvvvvvvv",
      "aaaaaaaaaaaaaaav",
      "bbbbcbbbbbbbbcav",
      "   dghhhiij kcav",
      "   lghh     mcav",
      "ggggehh     ncav",
      "opqrgh      scav",
      "t r guuuwxuuucav",
      " yAogBB     Ccav",
      "AtD g     E Fcav",
      "p  tg       Fcav",
      "IIJtgK      Lcav",
      "MMNOg      EFcav",
      "  P g  E  Q Fcav",
      "   Rg  SSSSSScav",
      "TgggeUgggggggcav"
    ],
    [
      "vvvvvvvvvvvvvvvv",
      "aaaaaaaaaaaaaaav",
      "bbbbcbbbbbbbbcav",
      "   dghh     Vcav",
      "    gh      Wcav",
      "ggggeh      Wcav",
      "p   g       Xcav",
      "    guuuYZuuucav",
      "!   g       0cav",
      "II  g        cav",
      "MMN gK      1cav",
      "  N g        cav",
      "    g       1cav",
      "    g        cav",
      "    g   2 234cav",
      "5ggge6gggggggcav"
    ],
    [
      "vvvvvvvvvvvvvvvv",
      "aaaaaaaaaaaaaaav",
      "bbbbcbbbbbbbbcav",
      "    gh      7cav",
      "    gh      8cav",
      "gggge       9cav",
      "IIIIg       @cav",
      "IIIIguuuuuuuucav",
      "MMN g #      cav",
      "  N gK      $cav",
      "    g       %cav",
      "    g       %cav",
      "    g       %cav",
      "    g       ^cav",
      "&   g        cav",
      "*ggge*gggggggcav"
    ],
    [
      "vvvvvvvvvvvvvvvv",
      "aaaaaaaaaaaaaaav",
      "bbbbcbbbbbbbbcav",
      "    g        cav",
      "    g        cav",
      "gggge        cav",
      "    g        cav",
      "    guuuuuuuucav",
      " (MMg)+      cav",
      "  IIg       %cav",
      "   pg       %cav",
      "    g       ^cav",
      "    g       $cav",
      "    g       %cav",
      "    g        cav",
      "ggggeggggggggcav"
    ],
    [
      "vvvvvvvvvvvvvvvv",
      "aaaaaaaaaaaaaaav",
      "bbbbcbbbbbbbbcav",
      "    g--------cav",
      "    g--------cav",
      "gggge--------cav",
      "    g--------cav",
      "    guuuuuuuucav",
      "    g  +     cav",
      " (  g       %cav",
      " (MMg       $cav",
      "  IIg       %cav",
      "    g       ^cav",
      "    g       $cav",
      "    g        cav",
      "ggggeggggggggcav"
    ]
  ]
}