{
  "name": "multi_laboratory1_11_base5",
  "refpalette": "c70cities:multi_laboratory1_11_base5_palette",
  "xsize": 16,
  "zsize": 16,
  "slices": [
    [
      "             abv",
      "             cbv",
      "             cbv",
      "            acbv",
      "             cbv",
      "           deebv",
      "   fg     dhicbv",
      "           deebv",
      "             cbv",
      "            acbv",
      "             cbv",
      "             cbv",
      "d          deebv",
      "d  !g     dhicbv",
      "jd         deebv",
      " d           cbv"
    ],
    [
      "             abv",
      "             cbv",
      "             cbv",
      "            aabv",
      "             abv",
      "           deebv",
      "    g     dhicbv",
      "           deebv",
      "             cbv",
      "            aabv",
      "             abv",
      "             abv",
      "d          deebv",
      "d   g     dhicbv",
      "jd         deebv",
      " d           abv"
    ],
    [
      "             abv",
      "             cbv",
      "             cbv",
      "            acbv",
      "             cbv",
      "           deebv",
      "    g     dhicbv",
      "           deebv",
      "             cbv",
      "            acbv",
      "             cbv",
      "             cbv",
      "d          deebv",
      "d   g     dhicbv",
      "jd         deebv",
      " d           cbv"
    ],
    [
      "             abv",
      "             cbv",
      "             cbv",
      "            acbv",
      "             cbv",
      "           deebv",
      "    g     dhicbv",
      "           deebv",
      "            acbv",
      "            acbv",
      "            acbv",
      "             cbv",
      "d          deebv",
      "d   g     dhicbv",
      "jd         deebv",
      " d           cbv"
    ],
    [
      "            kabv",
      "             cbv",
      "             cbv",
      "            acbv",
      "             cbv",
      "           deebv",
      "    g     dhicbv",
      "           deebv",
      "             cbv",
      "             cbv",
      "            acbv",
      "             cbv",
      "d          deebv",
      "d   g     dhicbv",
      "jd         deebv",
      " d          kcbv"
    ],
    [
      "llllllllllllaabv",
      "llllllllllllacbv",
      "llllllllllllacbv",
      "llllllllllllmcbv",
      "llllllllllllacbv",
      "lllllllllleeeebv",
      "llllglllllenicbv",
      "lllllllllleeeebv",
      "llllllllllllacbv",
      "llllllllllllacbv",
      "llllllllllllmcbv",
      "llllllllllllacbv",
      "dllllllllleeeebv",
      "dlllglllllenicbv",
      "jdlllllllleeeebv",
      " dllllllllllacbv"
    ]
  ]
}