{
  "name": "multi_laboratory1_10_base6",
  "refpalette": "c70cities:multi_laboratory1_10_base6_palette",
  "xsize": 16,
  "zsize": 16,
  "slices": [
    [
      "zzzzzzzzzzzzzzzz",
      "aaaaaaaaaaaaaaaz",
      "bbbbccccccccccaz",
      "  dde========caz",
      "   de========caz",
      "eeeee========caz",
      "====e========caz",
      "====effffffffcaz",
      "====effffffffcaz",
      "====effffffffcaz",
      "====effffffffcaz",
      "====effffffffcaz",
      "====effffffffcaz",
      "====effffffffcaz",
      "====effffffffcaz",
      "eeeeeffffffffcaz"
    ],
    [
      "zzzzzzzzzzzzzzzz",
      "aaaaaaaaaaaaaaaz",
      "bbbbcbbbbbbbbcaz",
      "   dghhhiij kcaz",
      "   lghh     mcaz",
      "ggggehh     ncaz",
      "opqrgh      scaz",
      "t r guuuwxuuucaz",
      " yAogBB     Ccaz",
      "AtD g     E Fcaz",
      "p  tg       Fcaz",
      "IIJtgK      Lcaz",
      "MMNOg      EFcaz",
      "  P g  E  Q Fcaz",
      "   Rg  SSSSSScaz",
      "TgggeUgggggggcaz"
    ],
    [
      "zzzzzzzzzzzzzzzz",
      "aaaaaaaaaaaaaaaz",
      "bbbbcbbbbbbbbcaz",
      "   dghh     Vcaz",
      "    gh      Wcaz",
      "ggggeh      Wcaz",
      "p   g       Xcaz",
      "    guuuYZuuucaz",
      "!   g       0caz",
      "II  g        caz",
      "MMN gK      1caz",
      "  N g        caz",
      "    g       1caz",
      "    g        caz",
      "    g   2 234caz",
      "5ggge6gggggggcaz"
    ],
    [
      "zzzzzzzzzzzzzzzz",
      "aaaaaaaaaaaaaaaz",
      "bbbbcbbbbbbbbcaz",
      "    gh      7caz",
      "    gh      8caz",
      "gggge       9caz",
      "IIIIg       @caz",
      "IIIIguuuuuuuucaz",
      "MMN g #      caz",
      "  N gK      $caz",
      "    g       %caz",
      "    g       %caz",
      "    g       %caz",
      "    g       ^caz",
      "&   g        caz",
      "*ggge*gggggggcaz"
    ],
    [
      "zzzzzzzzzzzzzzzz",
      "aaaaaaaaaaaaaaaz",
      "bbbbcbbbbbbbbcaz",
      "    g        caz",
      "    g        caz",
      "gggge        caz",
      "    g        caz",
      "    guuuuuuuucaz",
      " (MMg)+      caz",
      "  IIg       %caz",
      "   pg       %caz",
      "    g       ^caz",
      "    g       $caz",
      "    g       %caz",
      "    g        caz",
      "ggggeggggggggcaz"
    ],
    [
      "zzzzzzzzzzzzzzzz",
      "aaaaaaaaaaaaaaaz",
      "bbbbcbbbbbbbbcaz",
      "    g--------caz",
      "    g--------caz",
      "gggge--------caz",
      "    g--------caz",
      "    guuuuuuuucaz",
      "    g  +     caz",
      " (  g       %caz",
      " (MMg       $caz",
      "  IIg       %caz",
      "    g       ^caz",
      "    g       $caz",
      "    g        caz",
      "ggggeggggggggcaz"
    ]
  ]
}