{
  "name": "multi_laboratory1_13_base5",
  "refpalette": "c70cities:multi_laboratory1_13_base5_palette",
  "xsize": 16,
  "zsize": 16,
  "slices": [
    [
      "             abv",
      "             cbv",
      "ddddefffffffffev",
      "    g         hv",
      "    g         hv",
      "    g         hv",
      "    g         hv",
      "    g         hv",
      "    g         hv",
      "   ie         jv",
      "    g    k    hv",
      "    g   klk   hv",
      "    g     l   hv",
      "    g     m   hv",
      "    g   mnm   hv",
      "    g   mom   hv"
    ],
    [
      "             abv",
      "             cbv",
      "ddddefffffffffev",
      "    g         hv",
      "    g         hv",
      "    g         hv",
      "    g         hv",
      "    g         hv",
      "    g         hv",
      "    e         jv",
      "    g         hv",
      "    g    p    hv",
      "    g         hv",
      "    g         hv",
      "    g         hv",
      "    g         hv"
    ],
    [
      "             abv",
      "             cbv",
      "ddddefffffffffev",
      "    g         hv",
      "    g         hv",
      "    g         hv",
      "    g         hv",
      "    g         hv",
      "    g         hv",
      "    e         jv",
      "    g         hv",
      "    g         hv",
      "    g         hv",
      "    g         hv",
      "    g         hv",
      "    g         hv"
    ],
    [
      "            qabv",
      "             cbv",
      "ddddefffffffffev",
      "    g         hv",
      "    g         hv",
      "    g         hv",
      "    g         hv",
      "    g         hv",
      "    g         hv",
      "    e         jv",
      "    g         hv",
      "    g         hv",
      "    g         hv",
      "    g         hv",
      "    g         hv",
      "    g         hv"
    ],
    [
      "            rabv",
      "             cbv",
      "ssssesssssssssev",
      "    t         hv",
      "    t         hv",
      "    t         hv",
      "    t         hv",
      "    t         hv",
      "    t         hv",
      "    e         jv",
      "    t         hv",
      "    t         hv",
      "    t         hv",
      "    t         hv",
      "    t         hv",
      "    t         hv"
    ],
    [
      "uuuuuuuuuuuuwabv",
      "uuuuuuuuuuuuwcbv",
      "xxxxexxxxxxxxxav",
      "jjjjtjjjjjjjjjav",
      "jjjjtjjjjjjjjjav",
      "jjjjtjjyAyAAjjav",
      "jjjjtjjyAyAAjjav",
      "jjjjtjjjjjjjjjav",
      "jjjjtjjjjjjjjjav",
      "jjjjtjjjjjjjjjav",
      "jjjjtjjjjjjjjjav",
      "jjjjtjjjjjjjjjav",
      "jjjjtjjyyyAyjjav",
      "jjjjtjjyyyAyjjav",
      "jjjjtjjjjjjjjjav",
      "jjjjtjjjjjjjjjav"
    ]
  ]
}