{
  "name": "multi_communitycenter_0_base1",
  "refpalette": "c70cities:multi_communitycenter_0_base1_palette",
  "xsize": 16,
  "zsize": 16,
  "slices": [
    [
      "vvvvvvvvvvvvvvvv",
      "vHHHHHHHHHHHHHHH",
      "vHHHHHHHHHHHHHHH",
      "vHHHHHHHHHHHHHHH",
      "vHHHHHHHHHHHHHHH",
      "vHHHHHHHHHHHHHHH",
      "vHHHHHHHHHHHHHHH",
      "vHHHHHHHHHHHHHab",
      "vHHHHHHHHHHHHHHH",
      "vHHHHHHHHHHHHHHH",
      "vHHHHHHHHHHHHHHH",
      "vHHHHHHHHHHHHHHH",
      "vHHHHHHHHHHHHHHH",
      "vHHHHHHHHHHHHHHH",
      "vHHHHHHHHHHHHHHH",
      "vHHHHHHHHHHHHHHH"
    ],
    [
      "vvvvvvvvvvvvvvvv",
      "vccccccccccccccc",
      "vccccccccccccccc",
      "vccccccccccccccc",
      "vccccccccccccccc",
      "vccccccccccccccc",
      "vcccc dede dede ",
      "vcccc           ",
      "vccccfghghfghghf",
      "vcccc           ",
      "vcccc           ",
      "vcccc           ",
      "vcccc           ",
      "vcccc           ",
      "vcccc           ",
      "vccccfdedef    f"
    ],
    [
      "vvvvvvvvvvvvvvvv",
      "vccccccccccccccc",
      "vccccccccccccccc",
      "vccccccccccccccc",
      "vccccccccccccccc",
      "vccccccccccccccc",
      "vcccc           ",
      "vcccc           ",
      "vccccf    f    f",
      "vcccc           ",
      "vcccc           ",
      "vcccc           ",
      "vcccc           ",
      "vcccc           ",
      "vcccc           ",
      "vccccf    f    f"
    ],
    [
      "vvvvvvvvvvvvvvvv",
      "vccccccccccccccc",
      "vccccccccccccccc",
      "vccccccccccccccc",
      "vccccccccccccccc",
      "vccccccccccccccc",
      "vcccc!          ",
      "vcccc           ",
      "vccccf    f    f",
      "vcccc           ",
      "vcccc           ",
      "vcccc           ",
      "vcccc           ",
      "vcccc           ",
      "vcccc           ",
      "vccccf    f    f"
    ],
    [
      "vvvvvvvvvvvvvvvv",
      "vccccccccccccccc",
      "vccccccccccccccc",
      "vccccccccccccccc",
      "vccccccccccccccc",
      "vccccccccccccccc",
      "vccccf    f    f",
      "vccccf    f    f",
      "vccccfiiiifiiiif",
      "vccccf    f    f",
      "vccccf    f    f",
      "vccccf    f    f",
      "vccccf    f    f",
      "vccccf    f    f",
      "vccccf    f    f",
      "vccccfiiiifiiiif"
    ],
    [
      "vvvvvvvvvvvvvvvv",
      "vccccccccccccccc",
      "vccccccccccccccc",
      "vccccccccccccccc",
      "vccccccccccccccc",
      "vccccccccccccccc",
      "vccccccccccccccc",
      "vccccccccccccccc",
      "vccccccccccccccc",
      "vccccccccccccccc",
      "vccccccccccccccc",
      "vccccccccccccccc",
      "vccccccccccccccc",
      "vccccccccccccccc",
      "vccccccccccccccc",
      "vccccccccccccccc"
    ]
  ]
}