{
  "name": "multi_cafe_3_ground",
  "refpalette": "c70cities:multi_cafe_3_ground_palette",
  "xsize": 16,
  "zsize": 16,
  "slices": [
    [
      "aa=bbbbbbbbbbbGG",
      "aa=bbbbbbbbbbbGG",
      "aa=bbbbbbbbbbbcG",
      "aa=bbbbbbbbbbbGG",
      "aa=bbbbbbbbbbbGG",
      "aa=bbbbbbbbbbbGG",
      "aa=bbbbbbbbbbbGG",
      "aa=bbbbbbbbbbbcG",
      "aa=bbbbbbbbbbbGG",
      "aa=bbbbbbbbbbbcG",
      "aa============GG",
      "dddddeeeedddeeGG",
      "eeeeeeeeeeeeeeGG",
      "eeeeeeeeeeeeeeGG",
      "GGGGGGGGGGGGGGGG",
      "GGGGGGGGGGGGGGGG"
    ],
    [
      "          f ghij",
      " kk       f ghi ",
      "  lmn   o fpqqr ",
      "s ltu       whi ",
      "  lt        ghi ",
      "  lt        whij",
      "s ltu       xhi ",
      "  ltn   o   qqrj",
      "  ltu      yAhi ",
      "s lm       yBhrj",
      "  lllCDEClll==i ",
      "FFFFFI  JFFF Kij",
      "             Kij",
      "              i ",
      "LjMj j  N OP PPj",
      "N PL   j M LOMOj"
    ],
    [
      "            Qhi ",
      " kk       R Shi ",
      "  lTU   o   qqr ",
      "  l         Vhi ",
      "  l          hi ",
      "  l         Whi ",
      "  l         xhi ",
      "  l U   o   qqr ",
      "  l        yXhi ",
      "  l        yYhr ",
      "  lllCZ0Clll==i ",
      "     I  J    Ki ",
      "             Ki ",
      "              i ",
      "                ",
      "                "
    ],
    [
      " 11         2l  ",
      " 33         2hi ",
      "  l U   o   qqr ",
      "  l          hi ",
      "  l          l  ",
      "  l          l  ",
      "  l          hi ",
      "  l U   o   qqr ",
      "  l         4hi ",
      "  l         4hr ",
      "  lllCCCClll==i ",
      "     5116    Ki ",
      "             Ki ",
      "              i ",
      "                ",
      "                "
    ],
    [
      "  l         7h8 ",
      "  l         Sh8 ",
      "  l U   o   qqr ",
      "  l          h8 ",
      "  l          h8 ",
      "  l          h8 ",
      "  l         xh8 ",
      "  l U   o   qqr ",
      "  l          h8 ",
      "  l          hr ",
      "  llllllllll==i ",
      "             Ki ",
      "             Ki ",
      "              i ",
      "                ",
      "                "
    ],
    [
      "  l          hi ",
      "  l          hi ",
      "  l U   o   qqr ",
      "  l          hi ",
      "  l          hi ",
      "  l          hi ",
      "  l         xhi ",
      "  l U   o   qqr ",
      "  l          hi ",
      "  l          hr ",
      "  llllllllll==i ",
      "             Ki ",
      "             Ki ",
      "              i ",
      "                ",
      "                "
    ]
  ]
}