{
  "name": "multi_laboratory1_7_base1",
  "refpalette": "c70cities:multi_laboratory1_7_base1_palette",
  "xsize": 16,
  "zsize": 16,
  "slices": [
    [
      "     a    a     ",
      "     a    a     ",
      "     a    a     ",
      "abaaaaaaaaaaaaaa",
      "     a    a     ",
      "c    b    a    c",
      "c    a    a    c",
      "cd   a    a   dc",
      "eccc a    a ccce",
      "eeeccf    fcceee",
      "eeeeecccccceeeee",
      "eeeeeeeeeeeeeeee",
      "eeeeeeeeeeeeeeee",
      "eeeeeeeeeeeeeeee",
      "eeeeeeeeeeeeeeee",
      "eeeeeegeegeeeeee"
    ],
    [
      "                ",
      "                ",
      "                ",
      " h              ",
      "                ",
      "i    h         i",
      "i              i",
      "id            di",
      " iii        iii ",
      " j iid    dii  j",
      "kk ldiiiiiidm kk",
      "kkj          jkk",
      "j               ",
      "                ",
      "                ",
      "     n on o     "
    ],
    [
      "                ",
      "                ",
      "                ",
      "                ",
      "                ",
      "i              i",
      "i              i",
      "id            di",
      " iii        iii ",
      "   iid    dii   ",
      "    piiiiiip  qr",
      "                ",
      "                ",
      "                ",
      "                ",
      "                "
    ],
    [
      "                ",
      "                ",
      "                ",
      "                ",
      "                ",
      "i              i",
      "i              i",
      "id            di",
      " iii        iii ",
      "   iid    dii   ",
      "    piiiiiip    ",
      "                ",
      "                ",
      "                ",
      "                ",
      "                "
    ],
    [
      "                ",
      "                ",
      "                ",
      "                ",
      "                ",
      "i              i",
      "i              i",
      "id            di",
      " iii        iii ",
      "   iid    dii   ",
      "     iiiiii     ",
      "                ",
      "                ",
      "                ",
      "                ",
      "                "
    ],
    [
      "                ",
      "                ",
      "                ",
      "                ",
      "                ",
      "s              s",
      "s              s",
      "st            ts",
      "usss        sssu",
      "uuusst    tssuuu",
      "uuuuussssssuuuuu",
      "uuuuuuuuuuuuuuuu",
      "uuuuuuuuuuuuuuuu",
      "uuuuuuuuuuuuuuuu",
      "uuuu        uuuu",
      "uuuu        uuuu"
    ]
  ]
}