{
  "name": "multi_condo1_5_floor1",
  "refpalette": "c70cities:multi_condo1_5_floor1_palette",
  "xsize": 16,
  "zsize": 16,
  "slices": [
    [
      "aaaaabccccccde  ",
      "ffffffffffffde  ",
      "ggggggggggggdhhh",
      "ggggggggggggdf  ",
      "ggggggggggggdf  ",
      "ggggggggggggdf  ",
      "ggggggggggggdf  ",
      "ggggggggggggdf  ",
      "ggggggggggggdf  ",
      "ggggggggggggdf  ",
      "ggggggggggggdf  ",
      "iiiiiiiiiiiijf  ",
      "kkkkkkhfffffff  ",
      "      h         ",
      "      h         ",
      "                "
    ],
    [
      "            l   ",
      "            l   ",
      "            lmhh",
      "            lnhh",
      "            lnhh",
      "            lnhh",
      "        ~   lnhh",
      "            lnhh",
      "            lnhh",
      "            lnhh",
      "            lnhh",
      "lllllllllllllnhh",
      "      onnnnnnnhh",
      "      hhhhhhhhhh",
      "      hhhhhhhhhh",
      "                "
    ],
    [
      "            l   ",
      "            l   ",
      "            l   ",
      "            l   ",
      "            l   ",
      "            l   ",
      "        ~   l   ",
      "            l   ",
      "            l   ",
      "            l   ",
      "            l   ",
      "lllllllllllll   ",
      "                ",
      "                ",
      "                ",
      "                "
    ],
    [
      "                ",
      "                ",
      "                ",
      "                ",
      "                ",
      "                ",
      "        ~       ",
      "                ",
      "                ",
      "                ",
      "                ",
      "            p   ",
      "                ",
      "                ",
      "                ",
      "                "
    ],
    [
      "                ",
      "                ",
      "                ",
      "                ",
      "                ",
      "                ",
      "        ~       ",
      "                ",
      "                ",
      "                ",
      "                ",
      "            q   ",
      "                ",
      "                ",
      "                ",
      "                "
    ],
    [
      "                ",
      "                ",
      "                ",
      "                ",
      "                ",
      "                ",
      "        ~       ",
      "                ",
      "                ",
      "                ",
      "                ",
      "                ",
      "                ",
      "                ",
      "                ",
      "                "
    ]
  ]
}