{
  "name": "multi_militarycamp1_1_ground",
  "refpalette": "c70cities:multi_militarycamp1_1_ground_palette",
  "xsize": 16,
  "zsize": 16,
  "slices": [
    [
      "aazaazzzzzzzzzzz",
      "abbbzzzHzzHHzzzz",
      "zHzbHHHHHczHHczz",
      "czzbHHHHHH=HHz=z",
      "H!zbHHHHHHHzzzzz",
      "=HzbHHHHHHH=zHzz",
      "HHzbHHHHHHHHczzz",
      "H=zbHHHHHHHHzz=z",
      "c=zbHHHHHHHHHzzz",
      "HzzbHHHHHHHHHHzz",
      "HHHHHHHHHHHHczzz",
      "HHHHHHHHHHHH=zzz",
      "HHHHH=HHHHH=zzzz",
      "z=HHHz=HH=zczz=z",
      "zabbzzzHzzzHHzzz",
      "zzaaazzzzzzzzzzz"
    ],
    [
      "         dd     ",
      "eefghh  gghh  h ",
      "  e    hhi   jk ",
      "l e mmmno    pq ",
      " re smst      u ",
      " wf mmmx      y ",
      "lie m!mx      y ",
      "  e mmm A~    y ",
      "  e sms       k ",
      "  fBmmmnB     k ",
      "  l          BC ",
      "  l          yC ",
      "             y  ",
      "  lnDEEFhh  Iiq ",
      "eef JJJK uLLJJK ",
      "                "
    ],
    [
      "                ",
      "eef             ",
      "  e MNM         ",
      "l e OPQ         ",
      "  e R S         ",
      "  f TTT         ",
      "l e TUTV        ",
      "  e T T  ~      ",
      "  e R S         ",
      "  f T T         ",
      "  l W W         ",
      "                ",
      "                ",
      "  l   X         ",
      "eef             ",
      "                "
    ],
    [
      "                ",
      "YYZ             ",
      "  0             ",
      "1 0  1          ",
      "1 0 111         ",
      "1 Z 222         ",
      "1 0 T T         ",
      "  0 2 2  ~      ",
      "  0 T T         ",
      "  Z T T         ",
      "    W W         ",
      "                ",
      "                ",
      "                ",
      "33Z             ",
      "                "
    ],
    [
      "                ",
      "                ",
      "                ",
      "                ",
      "                ",
      "    111         ",
      "    111         ",
      "    111  ~      ",
      "     1          ",
      "     1          ",
      "                ",
      "                ",
      "                ",
      "                ",
      "                ",
      "                "
    ],
    [
      "                ",
      "                ",
      "                ",
      "                ",
      "                ",
      "                ",
      "                ",
      "         ~      ",
      "                ",
      "                ",
      "                ",
      "                ",
      "                ",
      "                ",
      "                ",
      "                "
    ]
  ]
}