{
  "name": "multi_hospital_0_base1",
  "refpalette": "c70cities:multi_hospital_0_base1_palette",
  "xsize": 16,
  "zsize": 16,
  "slices": [
    [
      "vvvvvvvvvvvvvvvv",
      "vaaaaaaaaaaaaaaa",
      "vaaaaaaaaaaaaaaa",
      "vaaaaaaaabbbbbbb",
      "vaaaaaaaabbbbbbb",
      "vaaaaaaaabbbbbbb",
      "vaaaaaaaabbbbbbb",
      "vaaaaaaaabbbbbbb",
      "vacddddddceeebbb",
      "vadffffff   gbbb",
      "vadffffff   gbbb",
      "vadffffffeheebbb",
      "vadffffffbbbbbbb",
      "vadffffffbbbbbbb",
      "vadffffffbbbbbbb",
      "vadffffffbbbbbbb"
    ],
    [
      "vvvvvvvvvvvvvvvv",
      "vaaaaaaaaaaaaaaa",
      "vaaaaaaaaaaaaaaa",
      "vaaaaaaaaiiiiiii",
      "vaaaaaaaai  j   ",
      "vaaaaaaaaik j   ",
      "vaaaaaaaail jj  ",
      "vaaaaaaaai      ",
      "vacddddddceee   ",
      "vad      m  n   ",
      "vadoo    p  q   ",
      "vadr     e ee   ",
      "vads   tdbuuuuwx",
      "vads k ydA      ",
      "vad  B  dA      ",
      "vad CDE dboo   o"
    ],
    [
      "vvvvvvvvvvvvvvvv",
      "vaaaaaaaaaaaaaaa",
      "vaaaaaaaaaaaaaaa",
      "vaaaaaaaaiiiiiii",
      "vaaaaaaaaik j   ",
      "vaaaaaaaail j   ",
      "vaaaaaaaai  jj  ",
      "vaaaaaaaai      ",
      "vacddddddceee   ",
      "vad      F  I   ",
      "vadJ     K  L   ",
      "vad     Me eeN  ",
      "vadO   jdbuuuuPQ",
      "vad  R  dA      ",
      "vad  R  dA      ",
      "vad SRT dbJ     "
    ],
    [
      "vvvvvvvvvvvvvvvv",
      "vaaaaaaaaaaaaaaa",
      "vaaaaaaaaaaaaaaa",
      "vaaaaaaaaiiiiiii",
      "vaaaaaaaaiUkj   ",
      "vaaaaaaaai kj   ",
      "vaaaaaaaai  j   ",
      "vaaaaaaaai  j   ",
      "vacddddddceee   ",
      "vad      V  W   ",
      "vad      V  W   ",
      "vad      e ee   ",
      "vad    jdbuuuuXX",
      "vad     dA      ",
      "vad     dA      ",
      "vad E C db      "
    ],
    [
      "vvvvvvvvvvvvvvvv",
      "vaaaaaaaaaaaaaaa",
      "vaaaaaaaaaaaaaaa",
      "vaaaaaaaaiiiiiii",
      "vaaaaaaaai  j   ",
      "vaaaaaaaai Yj   ",
      "vaaaaaaaai kj   ",
      "vaaaaaaaai  j   ",
      "vacddddddceee   ",
      "vad      e  e   ",
      "vad      e  e   ",
      "vad      e ee   ",
      "vad     dbuuuuuu",
      "vad     dA      ",
      "vad     dA      ",
      "vad  U  db      "
    ],
    [
      "vvvvvvvvvvvvvvvv",
      "vaaaaaaaaaaaaaaa",
      "vaaaaaaaaaaaaaaa",
      "vaaaaaaaaiiiiiii",
      "vaaaaaaaai  jZZZ",
      "vaaaaaaaai  jZZZ",
      "vaaaaaaaai YjZZZ",
      "vaaaaaaaai kjZZZ",
      "vacddddddceeebbb",
      "vadkkkkkke  eZZZ",
      "vadkkkkkke  eZZZ",
      "vadkkkkkke eebbb",
      "vadkkkkkdb000000",
      "vadkkkkkdbssssss",
      "vadkkkkkdbssssss",
      "vadkkkkkdbssssss"
    ]
  ]
}