{
  "name": "multi_hospital_3_base2",
  "refpalette": "c70cities:multi_hospital_3_base2_palette",
  "xsize": 16,
  "zsize": 16,
  "slices": [
    [
      "vvvvvvvvvvvvvvvv",
      "vvvvvvvvvvvvvvvv",
      "vvvvvvvvvvvvvvvv",
      "vvvvvvvvvvvvvvvv",
      "vvvvvvvvvvvvvvvv",
      "vvvvvvvvvvvvvvvv",
      "vvvvvvvvvvvvvvvv",
      "vvvvvvvvvvvvvvvv",
      "vvvvvvvvvvvvvvvv",
      "vvvvvvvvvvvvvvvv",
      "vvvvvvvvvvvvvvvv",
      "vvvvvvvvvvvvvvvv",
      "vvvvvvvvvvvvvvvv",
      "vvvvvvvvvvvvvvvv",
      "vvvvvvvvvvvvvvvv",
      "vvvvvvvvvvvvvvvv"
    ],
    [
      "abv  cvdeeeeeeev",
      "abv  cvdeeeeeeev",
      "abvvvvvdeeeeeeev",
      "abvf fvdeeeeeeev",
      "abv  fvdeeeeeeev",
      "abvf  vdeeeeeeev",
      "abvf  vdeeeeeeev",
      "abv   vdeeeeeeev",
      "abvf fvdeeeeeeev",
      "abvvvvvdeeeeeeev",
      "ddddddddeeeeeeev",
      "eeeeeeeeeeeeeeev",
      "eeeeeeeeeeeeeeev",
      "eeeeeeeeeeeeeeev",
      "eeeeeeeeeeeeeeev",
      "vvvvvvvvvvvvvvvv"
    ],
    [
      " g     deeeeeeev",
      " g     deeeeeeev",
      " b     deeeeeeev",
      " g   h deeeeeeev",
      " g   h deeeeeeev",
      " g     deeeeeeev",
      " g h   deeeeeeev",
      " g     deeeeeeev",
      " g   h deeeeeeev",
      "db     deeeeeeev",
      "ddddddddeeeeeeev",
      "eeeeeeeeeeeeeeev",
      "eeeeeeeeeeeeeeev",
      "eeeeeeeeeeeeeeev",
      "eeeeeeeeeeeeeeev",
      "vvvvvvvvvvvvvvvv"
    ],
    [
      " g     deeeeeeev",
      " g     deeeeeeev",
      " b     deeeeeeev",
      " g     deeeeeeev",
      " g     deeeeeeev",
      " g     deeeeeeev",
      " g     deeeeeeev",
      " g     deeeeeeev",
      " g     deeeeeeev",
      "db     deeeeeeev",
      "ddddddddeeeeeeev",
      "eeeeeeeeeeeeeeev",
      "eeeeeeeeeeeeeeev",
      "eeeeeeeeeeeeeeev",
      "eeeeeeeeeeeeeeev",
      "vvvvvvvvvvvvvvvv"
    ],
    [
      " g     deeeeeeev",
      " g     deeeeeeev",
      " b     ieeeeeeev",
      " g     deeeeeeev",
      " g     deeeeeeev",
      " g     deeeeeeev",
      " g     deeeeeeev",
      " g     deeeeeeev",
      " g     deeeeeeev",
      "db     deeeeeeev",
      "ddddddddeeeeeeev",
      "eeeeeeeeeeeeeeev",
      "eeeeeeeeeeeeeeev",
      "eeeeeeeeeeeeeeev",
      "eeeeeeeeeeeeeeev",
      "vvvvvvvvvvvvvvvv"
    ],
    [
      "dbjjjjjdeeeeeeev",
      "dbjjjjjdeeeeeeev",
      "dbjjjjjdeeeeeeev",
      "dbjjjjjdeeeeeeev",
      "dbjjjjjdeeeeeeev",
      "dbjjjjjdeeeeeeev",
      "dbjjjjjdeeeeeeev",
      "dbjjjjjdeeeeeeev",
      "dbjjjjjdeeeeeeev",
      "dbjjjjjdeeeeeeev",
      "ddddddddeeeeeeev",
      "eeeeeeeeeeeeeeev",
      "eeeeeeeeeeeeeeev",
      "eeeeeeeeeeeeeeev",
      "eeeeeeeeeeeeeeev",
      "vvvvvvvvvvvvvvvv"
    ]
  ]
}