{
  "name": "multi_flatapartment_0_ground",
  "refpalette": "c70cities:multi_flatapartment_0_ground_palette",
  "xsize": 16,
  "zsize": 16,
  "slices": [
    [
      "GGGGGGGGGGGGGGGa",
      "HHHHHaaaaaaaaaaa",
      "HHHHHaaaaaaaaaaa",
      "HHHHHaaaaaaaaaaa",
      "HHHHHaaaaaaaaaaa",
      "HHHHHaaaaaaaaaaa",
      "HHHbcaaaaaaaaaaa",
      "HHHHHaaaaaaaaaaa",
      "HHHHHaaaaaaaaaaa",
      "HHHHHaaaaaaaaaaa",
      "HHHHHaaaaaaaaaaa",
      "HHHHHaaaaaaaaaaa",
      "HHHHHaaaaaaaaaaa",
      "HHHHHaaaaaaaaaaa",
      "HHHHHaaaaaaaaaaa",
      "GGGGGGGGGGGGGGGa"
    ],
    [
      "     dddddddddd ",
      "  e fghhhhghhhg ",
      "  i jef         ",
      "  e f           ",
      "  i jij    e f  ",
      "  e fg    gi jg ",
      "  i jef  e fke f",
      "  e f    i jki j",
      "  i j    e fke f",
      "  e fij  i jki j",
      "  i jg    ge fg ",
      "  e fef    i j  ",
      "  i j           ",
      "  e fij         ",
      "  i jgllllglllg ",
      "m    dddddddddd "
    ],
    [
      "                ",
      "     n    n   n ",
      "                ",
      "                ",
      "                ",
      "     n    n   n ",
      "                ",
      "                ",
      "                ",
      "                ",
      "     n    n   n ",
      "                ",
      "                ",
      "                ",
      "     n    n   n ",
      "o               "
    ],
    [
      "                ",
      "     np  pnp pnp",
      "     p          ",
      "                ",
      "     p          ",
      "     n    n   n ",
      "     p          ",
      "                ",
      "                ",
      "     p          ",
      "     n    n   n ",
      "     p          ",
      "                ",
      "     p          ",
      "     np  pnp pnp",
      "q               "
    ],
    [
      "                ",
      "     n rr n r n ",
      "          s   s ",
      "     r          ",
      "                ",
      "     ns   n   n ",
      "                ",
      "     r          ",
      "     r          ",
      "                ",
      "     ns   n   n ",
      "                ",
      "     r          ",
      "          s   s ",
      "     n rr n r n ",
      "                "
    ],
    [
      "                ",
      "     rrrrrrrrrrr",
      "     raaaaaaaaaa",
      "     ra   a   a ",
      "     ra   a   a ",
      "     raaaaaaaaaa",
      "     ra   a   a ",
      "     ra   a   a ",
      "     ra   a   a ",
      "     ra   a   a ",
      "     raaaaaaaaaa",
      "     ra   a   a ",
      "     ra   a   a ",
      "     raaaaaaaaaa",
      "     rrrrrrrrrrr",
      "                "
    ]
  ]
}