{
  "name": "multi_hospital_2_ground",
  "refpalette": "c70cities:multi_hospital_2_ground_palette",
  "xsize": 16,
  "zsize": 16,
  "slices": [
    [
      "GGGGGGGGGGGGGGGG",
      "aaaaaaaaaaaaaaaG",
      "aaaabbbbbbbbbbaG",
      "caaabbbbbbbbbbaG",
      "daaadGGdGGdGGdaG",
      "caaaaaaaaaaaaaaG",
      "caaaaaaaaaaaaaaG",
      "caaaaaaaaaaaaaaG",
      "caaaaaaaaaaaaaaG",
      "cceeeeeeeeeeeeaG",
      "cceeee!eeeeeeeaG",
      "cceeeeeeeeeeeeaG",
      "cceeeeeeeeeeeeaG",
      "cceeeeeeeeeeeeaG",
      "ccccccccccccccaG",
      "ccccccccccccccaG"
    ],
    [
      "  f    f  f  f  ",
      "                ",
      " g              ",
      "hi   jk jk jk   ",
      "li  mmmmmmmmmm f",
      " i              ",
      " n             f",
      " i              ",
      "ohhhhhhhhhhhhhp ",
      " q   q   q   rp ",
      " r s r s r s rpf",
      "truuiruuiruu rp ",
      "trww rww r w rp ",
      "trx  rx  ry  rpf",
      "ArBBCBBBDBBBCBp ",
      "            EGF "
    ],
    [
      "                ",
      "                ",
      " g              ",
      "hi              ",
      "li              ",
      " i              ",
      " I              ",
      " i              ",
      "ohhJJhhJJhhJJhp ",
      " K   K   K   rp ",
      " r   r   r   rp ",
      " rLM rNM rO  rp ",
      " r   r   rP  rp ",
      " rO  rO  r   rp ",
      " rBBQBBBRBBBQBp ",
      "             ST "
    ],
    [
      "                ",
      "                ",
      " g              ",
      "hi              ",
      "li              ",
      " i              ",
      " i              ",
      " i              ",
      "ohhJJhhJJhhJJhp ",
      " U   U   U   rp ",
      " r   r   r   rp ",
      " r   r   r   rp ",
      " r   r   r   rp ",
      " r   r   r   rp ",
      " rBBVBBBVBBBVBp ",
      "             WT "
    ],
    [
      "                ",
      "                ",
      " g              ",
      "hi              ",
      " i              ",
      " i              ",
      " i              ",
      " i              ",
      "ohhhhhhhhhhhhhp ",
      " r   r   r   rp ",
      " r   r   r   rp ",
      " r   r   r   rp ",
      " r   r   r   rp ",
      " r   r   r   rp ",
      " rBBBBBBBBBBBBp ",
      "              T "
    ],
    [
      "                ",
      "                ",
      " g              ",
      "hi              ",
      " i              ",
      " i              ",
      " i              ",
      " i              ",
      "oXYYYYYYYYYYYYp ",
      " r           rp ",
      " r           rp ",
      " r           rp ",
      " r           rp ",
      " r           rp ",
      " rBBBBBBBBBBBBp ",
      "              T "
    ]
  ]
}