{
  "name": "multi_laboratory1_10_floor1",
  "refpalette": "c70cities:multi_laboratory1_10_floor1_palette",
  "xsize": 16,
  "zsize": 16,
  "slices": [
    [
      "                ",
      "                ",
      "abbba           ",
      "cdcccbb         ",
      "ceccccb         ",
      "fffffgga        ",
      "    fggb        ",
      "    fggb        ",
      "    fhdb        ",
      "    fggb        ",
      "    fggb        ",
      "    fggb        ",
      "  iifggb        ",
      "jjjjfgga        ",
      "jjjjfggb        ",
      "kkkkfhdl        "
    ],
    [
      "                ",
      "                ",
      "bbbbb           ",
      "     ba         ",
      "      b         ",
      "mfmmn  b        ",
      "    m  b        ",
      "    m  b        ",
      "    f  b        ",
      "    m  a        ",
      "    m  b        ",
      "    m  b        ",
      "    m  b        ",
      "    m  b        ",
      "    m  a        ",
      "opppf  b        "
    ],
    [
      "                ",
      "                ",
      "bbabb           ",
      "     ba         ",
      "      b         ",
      "qfmmn  b        ",
      "    m  b        ",
      "    m  b        ",
      "    f  b        ",
      "    q  b        ",
      "    m  b        ",
      "    m  b        ",
      "    m  b        ",
      "    m  b        ",
      "    q  b        ",
      "rpppf  b        "
    ],
    [
      "                ",
      "                ",
      "bbbbb           ",
      "     bb         ",
      "      b         ",
      "qfmmn  b        ",
      "    m  b        ",
      "    m  b        ",
      "    f  b        ",
      "    q  b        ",
      "    m  b        ",
      "    m  a        ",
      "    m  b        ",
      "    m  b        ",
      "s   q  b        ",
      "tpppf  b        "
    ],
    [
      "                ",
      "                ",
      "bbbba           ",
      "     bb         ",
      "      b         ",
      "qfmmn  b        ",
      "    m  b        ",
      "    m  b        ",
      "    f  b        ",
      "    q  b        ",
      "    m  b        ",
      "    m  b        ",
      "    m  b        ",
      "    m  b        ",
      "    q  b        ",
      "ppppf  b        "
    ],
    [
      "                ",
      "                ",
      "babbb           ",
      "     bb         ",
      "      b         ",
      "fffff  b        ",
      "uuuuf  b        ",
      "uuuuf  b        ",
      "uuuuf  b        ",
      "uuuuf  b        ",
      "uuuuf  b        ",
      "uuuuf  b        ",
      "uuuuf  b        ",
      "uuuuf  b        ",
      "uuuuf  b        ",
      "fffff  b        "
    ]
  ]
}