{
  "name": "multi_derrick_1_base1",
  "refpalette": "c70cities:multi_derrick_1_base1_palette",
  "xsize": 16,
  "zsize": 16,
  "slices": [
    [
      "vvvvvvvvvvvvvvvv",
      "zzzzzzzzzzzzzzzv",
      "zzzzzzzzzzzzzzzv",
      "zzzzzzzzzzzzzzzv",
      "zzzzzzzzzzzzzzzv",
      "zzzzzzzzzzzzzzzv",
      "zzzzzzzzzzzzzzzv",
      "zzzzzzzzzzzzzzzv",
      "zzzzzzzzzzzzzzzv",
      "zzzzzzzzzzzzzzzv",
      "zzzzzzzzzzzzzzzv",
      "zzzzzzzzzzzzzzzv",
      "zzzzzzzzzzzzzzzv",
      "zzzzzzzzzzzzzzzv",
      "zzzzzzzzzzzzzzzv",
      "vvvvvvvvvvvvvvvv"
    ],
    [
      "vvvvvvvvvvvvvvvv",
      "zzzzzzzzzzzzzzzv",
      "zzzzzzzzzzzzzzzv",
      "zzzzzzzzzzzzzzzv",
      "zzzzzzzzzzzzzzzv",
      "zzzzzzzzzzzzzzzv",
      "zzzzzzzzzzzzzzzv",
      "zzzzzzzzzzzzzzzv",
      "zzzzzzzzzzzzzzzv",
      "zzzzzzzzzzzzzzzv",
      "zzzzzzzzzzzzzzzv",
      "zzzzzzzzzzzzzzzv",
      "zzzzzzzzzzzzzzzv",
      "zzzzzzzzzzzzzzzv",
      "zzzzzzzzzzzzzzzv",
      "vvvvvvvvvvvvvvvv"
    ],
    [
      "vvvvvvvvvvvvvvvv",
      "zzzzzzzzzzzzzzzv",
      "zzzzzzzzzzzzzzzv",
      "zzzzzzzzzzzzzzzv",
      "zzzzzzzzzzzzzzzv",
      "zzzzzzzzzzzzzzzv",
      "zzzzzzzzzzzzzzzv",
      "zzzzzzzzzzzzzzzv",
      "zzzzzzzzzzzzzzzv",
      "zzzzzzzzzzzzzzzv",
      "zzzzzzzzzzzzzzzv",
      "zzzzzzzzzzzzzzzv",
      "zzzzzzzzzzzzzzzv",
      "zzzzzzzzzzzzzzzv",
      "zzzzzzzzzzzzzzzv",
      "vvvvvvvvvvvvvvvv"
    ],
    [
      "vvvvvvvvvvvvvvvv",
      "zzzzzzzzzzzzzzzv",
      "zzzzzzzzzzzzzzzv",
      "zzzzzzzzzzzzzzzv",
      "zzzzzzzzzzzzzzzv",
      "zzzzzzzzzzzzzzzv",
      "zzzzzzzzzzzzzzzv",
      "zzzzzzzzzzzzzzzv",
      "zzzzzzzzzzzzzzzv",
      "zzzzzzzzzzzzzzzv",
      "zzzzzzzzzzzzzzzv",
      "zzzzzzzzzzzzzzzv",
      "zzzzzzzzzzzzzzzv",
      "zzzzzzzzzzzzzzzv",
      "zzzzzzzzzzzzzzzv",
      "vvvvvvvvvvvvvvvv"
    ],
    [
      "vvvvvvvvvvvvvvvv",
      "zzzzzzzzzzzzzzzv",
      "zzzzzzzzzzzzzzzv",
      "zzzzzzzzzzzzzzzv",
      "zzzzzzzzzzzzzzzv",
      "zzzzzzzzzzzzzzzv",
      "zzzzzzzzzzzzzzzv",
      "zzzzzzzzzzzzzzzv",
      "zzzzzzzzzzzzzzzv",
      "zzzzzzzzzzzzzzzv",
      "zzzzzzzzzzzzzzzv",
      "zzzzzzzzzzzzzzzv",
      "zzzzzzzzzzzzzzzv",
      "zzzzzzzzzzzzzzzv",
      "zzzzzzzzzzzzzzzv",
      "vvvvvvvvvvvvvvvv"
    ],
    [
      "vvvvvvvvvvvvvvvv",
      "zzzzzzzzzzzzzzzv",
      "zzzzzzzzzzzzzzzv",
      "zzzzzzzzzzzzzzzv",
      "zzzzzzzzzzzzzzzv",
      "zzzzzzzzzzzzzzzv",
      "zzzzzzzzzzzzzzzv",
      "zzzzzzzzzzzzzzzv",
      "zzzzzzzzzzzzzzzv",
      "zzzzzzzzzzzzzzzv",
      "zzzzzzzzzzzzzzzv",
      "zzzzzzzaazzzzzzv",
      "zzzzzzzaazzzzzzv",
      "zzzzzzzaazzzzzzv",
      "zzzzzzzzzzzzzzzv",
      "vvvvvvvvvvvvvvvv"
    ]
  ]
}