{
  "name": "multi_laboratory1_12_base2",
  "refpalette": "c70cities:multi_laboratory1_12_base2_palette",
  "xsize": 16,
  "zsize": 16,
  "slices": [
    [
      " abbbbbbbbbbbcdv",
      " abbbbbbbbbbbcdv",
      " abbbbbbbbbbbcdv",
      "eabbbbbbbbbbbcdv",
      "abbbfbbbbbbbbcdv",
      "abbbbbbbbbbbbcdv",
      "bbbbbbbbbbbbbcdv",
      "bbbbbbbbbbbbbcdv",
      "bbbbbbbbbbbbbcdv",
      "bbbbbbbbbbbbbcdv",
      "bbbbbbbbbbbbbcdv",
      "bbbbfbbbbbbbbcdv",
      "bbbbbbbbbbbbbcdv",
      "bbbbbbbbbbbbbcdv",
      "bbbbbbbbbbbbbcdv",
      "bbbbbbbbbbbbbcdv"
    ],
    [
      " g  h    i jkldv",
      " g  m     njkldv",
      " g  o       jjdv",
      "eg  p        cdv",
      "ge  f q     rcdv",
      "gs  p tu    jjdv",
      "    pwxxx  jyldv",
      "    pAxxxB jyldv",
      "    p  C  D jjdv",
      "    pE   qB  cdv",
      "    p!FII I rcdv",
      "J  efppppppppcdv",
      "    p       Kcdv",
      "    o        cdv",
      "    L    i  Mcdv",
      "    N     BOMcdv"
    ],
    [
      " g  P      gkldv",
      " g  Q      gkldv",
      " g  o       gjdv",
      "eg  p       Rcdv",
      "gS  f       rcdv",
      "g   p       gjdv",
      "    T UV   gyldv",
      "    TV WV  gyldv",
      "    T       gjdv",
      "    T       Rcdv",
      "    p       rcdv",
      "   Sfppppppppcdv",
      "    p        cdv",
      "    o        cdv",
      "    X       Ycdv",
      "    Z       0cdv"
    ],
    [
      " g  o      gkldv",
      " g  o      gkldv",
      " g  o       gjdv",
      "eg  p        cdv",
      "gS  f       rcdv",
      "g   p       gjdv",
      "    T      gyldv",
      "    T      gyldv",
      "    T       gjdv",
      "    T        cdv",
      "    p       rcdv",
      "   Sfppppppppcdv",
      "    p        cdv",
      "    o        cdv",
      "    o        cdv",
      "    o        cdv"
    ],
    [
      " g  p      g1ldv",
      " g  p      g1ldv",
      " g  p       gjdv",
      "eg  p       Rcdv",
      "g   f       2cdv",
      "g   p       gjdv",
      "    p      g3ldv",
      "    p      g3ldv",
      "    p       gjdv",
      "    p       Rcdv",
      "    p  4  5 2cdv",
      "    fppppppppcdv",
      "    p        cdv",
      "    p       6cdv",
      "    p        cdv",
      "    p        cdv"
    ],
    [
      " g77899@99@j#ldv",
      " g77899@99$j#ldv",
      " g77899@99@9jjdv",
      "eg77899999999cdv",
      "g777f99999999cdv",
      "g777899$99$9jjdv",
      "7777899@99@j#ldv",
      "7777899@99@j#ldv",
      "7777899@99$9jjdv",
      "7777899999999cdv",
      "77778%%%%%%%%cdv",
      "7777fppppppppcdv",
      "77778%999999%cdv",
      "77@78%999999%cdv",
      "77@78%9@99@9%cdv",
      "77@78%9$99@9%cdv"
    ]
  ]
}