{
  "name": "multi_cafe_3_floor1",
  "refpalette": "c70cities:multi_cafe_3_floor1_palette",
  "xsize": 16,
  "zsize": 16,
  "slices": [
    [
      " ab          cd ",
      " ab          cd ",
      " ab e  fg   hhi ",
      " ab         !cd ",
      " ab          cd ",
      " ab          cd ",
      " ab          cd ",
      " ab e   g   hhi ",
      " ab          cd ",
      " ab          ci ",
      " abbbbbbbbbb==d ",
      " aaaaaaaaaaaajd ",
      "             jd ",
      "              d ",
      "                ",
      "                "
    ],
    [
      "  =     aaaaacd ",
      " k=     aaaaacd ",
      " l=mmmmmgggghhi ",
      " n=     aaaaacd ",
      " o=     aaaaacd ",
      " l=     aaaaacd ",
      " k=     aaaapcd ",
      "  =mmmmmgggghhi ",
      "  =     aaaaacd ",
      "  =     aaaaaci ",
      "  ============d ",
      "             jd ",
      "             jd ",
      "              d ",
      "                ",
      "                "
    ],
    [
      "  =     h   qrd ",
      " o=     hs  trd ",
      " n=     g  shhi ",
      " n=     h  s rd ",
      " o=     h s urd ",
      " n=     h   urd ",
      " w=     h   srd ",
      "  =     g   hhi ",
      "  =     hs  srd ",
      "  =     h  rrri ",
      "  ============d ",
      "           xxyd ",
      "           xxyd ",
      "              d ",
      "                ",
      "                "
    ],
    [
      "  =AAAAAhsBBBBC ",
      "  =AAAAAh BBBBC ",
      "  =     g   hhi ",
      "  =AAAAAhsBBBBC ",
      "  =AAAAAh BBBBC ",
      "  =AAAAAh BBBBC ",
      "  =AAAAAh BBBBC ",
      "  =     g   hhi ",
      "  =AAAAAh BBBBC ",
      "  =AAAAAhs    i ",
      "  ========BBBBC ",
      "   xxxxxxyDBBBC ",
      "   xxxxxxyDEEEd ",
      "          BBBBd ",
      "                ",
      "                "
    ],
    [
      "xyiBBBEFFFF     ",
      "xyiBBBFFFF      ",
      "xyiIIIIIiiJJJJJ ",
      "xyiBBBFFFF      ",
      "xyiBBBEFFFF     ",
      "xyiBBBEFFFF     ",
      "xyiBBBFFFF      ",
      "xyiIIIIIiiJJJJJ ",
      "xyiBBBFFFF      ",
      "xyiiiiKKLKJJJJJ ",
      "xyBBBBFFFF      ",
      "xyDBBBEFFFF     ",
      "xyDEEEEFFFF     ",
      "  BBBBFFFF      ",
      "                ",
      "                "
    ],
    [
      "FFJ             ",
      "FFJ             ",
      "FFJ             ",
      "FFJ             ",
      "FFJ             ",
      "FFJ             ",
      "FFJ             ",
      "FFJ             ",
      "FFJ             ",
      "FFJJJJ          ",
      "FF              ",
      "FFF             ",
      "FFF             ",
      "FF              ",
      "                ",
      "                "
    ]
  ]
}