{
  "name": "multi_hospital_0_base1",
  "refpalette": "c70cities:multi_hospital_0_base1_palette",
  "xsize": 16,
  "zsize": 16,
  "slices": [
    [
      "vvvvvvvvvvvvvvvv",
      "vaaaaaaaaaaaaaaa",
      "vaaaaaaaaaaaaaaa",
      "vaaaaaaaabbbbbbb",
      "vaaaaaaaabbbbbbb",
      "vaaaaaaaabbbbbbb",
      "vaaaaaaaabbbbbbb",
      "vaaaaaaaabbbbbbb",
      "vacddddddceeebbb",
      "vadffffff   gbbb",
      "vadffffff   gbbb",
      "vadffffffe eebbb",
      "vadffffffbbbbbbb",
      "vadffffffbbbbbbb",
      "vadffffffbbbbbbb",
      "vadffffffbbbbbbb"
    ],
    [
      "vvvvvvvvvvvvvvvv",
      "vaaaaaaaaaaaaaaa",
      "vaaaaaaaaaaaaaaa",
      "vaaaaaaaahhhhhhh",
      "vaaaaaaaah  i   ",
      "vaaaaaaaahj i   ",
      "vaaaaaaaahk ii  ",
      "vaaaaaaaah      ",
      "vacddddddceee   ",
      "vad      l  m   ",
      "vadnn    o  p   ",
      "vadq     e ee   ",
      "vadr   sdbttttuw",
      "vadr j xdy      ",
      "vad  A  dy      ",
      "vad BCD dbnn   n"
    ],
    [
      "vvvvvvvvvvvvvvvv",
      "vaaaaaaaaaaaaaaa",
      "vaaaaaaaaaaaaaaa",
      "vaaaaaaaahhhhhhh",
      "vaaaaaaaahj i   ",
      "vaaaaaaaahk i   ",
      "vaaaaaaaah  ii  ",
      "vaaaaaaaah      ",
      "vacddddddceee   ",
      "vad      E  F   ",
      "vadI     J  K   ",
      "vad     Le eeM  ",
      "vadN   idbttttOP",
      "vad  Q  dy      ",
      "vad  Q  dy      ",
      "vad RQS dbI     "
    ],
    [
      "vvvvvvvvvvvvvvvv",
      "vaaaaaaaaaaaaaaa",
      "vaaaaaaaaaaaaaaa",
      "vaaaaaaaahhhhhhh",
      "vaaaaaaaahTji   ",
      "vaaaaaaaah ji   ",
      "vaaaaaaaah  i   ",
      "vaaaaaaaah  i   ",
      "vacddddddceee   ",
      "vad      U  V   ",
      "vad      U  V   ",
      "vad      e ee   ",
      "vad    idbttttWW",
      "vad     dy      ",
      "vad     dy      ",
      "vad D B db      "
    ],
    [
      "vvvvvvvvvvvvvvvv",
      "vaaaaaaaaaaaaaaa",
      "vaaaaaaaaaaaaaaa",
      "vaaaaaaaahhhhhhh",
      "vaaaaaaaah  i   ",
      "vaaaaaaaah Xi   ",
      "vaaaaaaaah ji   ",
      "vaaaaaaaah  i   ",
      "vacddddddceee   ",
      "vad      e  e   ",
      "vad      e  e   ",
      "vad      e ee   ",
      "vad     dbtttttt",
      "vad     dy      ",
      "vad     dy      ",
      "vad  T  db      "
    ],
    [
      "vvvvvvvvvvvvvvvv",
      "vaaaaaaaaaaaaaaa",
      "vaaaaaaaaaaaaaaa",
      "vaaaaaaaahhhhhhh",
      "vaaaaaaaah  iYYY",
      "vaaaaaaaah  iYYY",
      "vaaaaaaaah XiYYY",
      "vaaaaaaaah jiYYY",
      "vacddddddceeebbb",
      "vadjjjjjje  eYYY",
      "vadjjjjjje  eYYY",
      "vadjjjjjje Zebbb",
      "vadjjjjjdb000000",
      "vadjjjjjdbrrrrrr",
      "vadjjjjjdbrrrrrr",
      "vadjjjjjdbrrrrrr"
    ]
  ]
}