{
  "name": "multi_laboratory1_14_base2",
  "refpalette": "c70cities:multi_laboratory1_14_base2_palette",
  "xsize": 16,
  "zsize": 16,
  "slices": [
    [
      "aaaabaaaaaaaacdz",
      "aaaaaaaaaaaaacdz",
      "aaaaaaaaaaaaacdz",
      "aaaaaaaaaaaaacdz",
      "aaaaaaaaaaaaacdz",
      "aaaaaaaaaaaaacdz",
      "aaaaaaaaaaaaacdz",
      "aaaabaaaaaaaacdz",
      "aaaaaeeeeeeeecdz",
      "aaaaaeeeeeeeecdz",
      "aaaaaeeeeeeeecdz",
      "aaaaaeeeeeeeecdz",
      "aa!aa!eeeeeeecdz",
      "ccccccccccccccdz",
      "dddddddddddddddz",
      "zzzzzzzzzzzzzzzz"
    ],
    [
      "f   bggggggggcdz",
      "f   g h    h cdz",
      "i   g        cdz",
      "jj  g k ll m cdz",
      "    g   no pqcdz",
      "    r     st cdz",
      "    guuuuuuuucdz",
      "    bggggggggcdz",
      "    gwwxxxxwwcdz",
      "    y        cdz",
      "    gABCBABABcdz",
      "    g D D D Dcdz",
      " EEFgIDIDIDIDcdz",
      "ccccccccccccccdz",
      "dddddddddddddddz",
      "zzzzzzzzzzzzzzzz"
    ],
    [
      "    bggJJJJggcdz",
      "    g h    h cdz",
      "K   g        cdz",
      "    g        cdz",
      "    g        cdz",
      "    L        cdz",
      "    gMN   O Mcdz",
      "    bggggggggcdz",
      "    gMPPPPPPMcdz",
      "    Q        cdz",
      "    gRBSBRBRBcdz",
      "    g D D D Dcdz",
      "    g D D D Dcdz",
      "ccccccccccccccdz",
      "dddddddddddddddz",
      "zzzzzzzzzzzzzzzz"
    ],
    [
      "    bggTTTTggcdz",
      "    g        cdz",
      "   Ug        cdz",
      "   Ug        cdz",
      "    g        cdz",
      "    V        cdz",
      "    g        cdz",
      "    bggggggggcdz",
      "    g PPPPPP cdz",
      "    g        cdz",
      "    gBBBBBBBBcdz",
      "    g D D D Dcdz",
      "    g D D D Dcdz",
      "ccccccccccccccdz",
      "dddddddddddddddz",
      "zzzzzzzzzzzzzzzz"
    ],
    [
      "    bggggggggcdz",
      "    g        cdz",
      "    g        cdz",
      "    g        cdz",
      "    g        cdz",
      "    g        cdz",
      "    g        cdz",
      "    bggggggggcdz",
      "    gWWWWWWWWcdz",
      "    gWWWWWWWWcdz",
      "    gWWWWWWWWcdz",
      "    gWWWWWWWWcdz",
      "    gXWXWXWXWcdz",
      "ccccccccccccccdz",
      "dddddddddddddddz",
      "zzzzzzzzzzzzzzzz"
    ],
    [
      "Y YYbggggggggcdz",
      "YZYYV00000000cdz",
      "YZYYV01000010cdz",
      "22YYV00000000cdz",
      "YYYYV00000000cdz",
      "YYYYV030000Z0cdz",
      "YYYYV00000000cdz",
      "ggggbggggggggcdz",
      "4444g55555555cdz",
      "4424g5 5 5 5ccdz",
      "4424g5 5 5 5ccdz",
      "4424g5 5 5 5ccdz",
      "4444g5 5 5 5ccdz",
      "ccccccccccccccdz",
      "dddddddddddddddz",
      "zzzzzzzzzzzzzzzz"
    ]
  ]
}