{
  "name": "multi_convenientstore_1_ground",
  "refpalette": "c70cities:multi_convenientstore_1_ground_palette",
  "xsize": 16,
  "zsize": 16,
  "slices": [
    [
      "GGHHHHHHaaaaaaaa",
      "GGHHHHHHabbbbbbb",
      "GGHHHHHHabbbbbbb",
      "GGHHHHHHabbbbbbb",
      "GGHHHHHHabbbbbbb",
      "GGHHHHHHabbbbbbb",
      "GGHHHHHHabbbbbbb",
      "GGHHHHHHabbbbbbb",
      "GGHHHHHHabbbbbbb",
      "GGHHHHHHabbbbbbb",
      "GGHHHHHHabbbbbbb",
      "GGHHHHHHabbbbbbb",
      "GGHHHHHHaaaaaaaa",
      "GGHHHHHHHHHHHHHH",
      "GGHHHHHHHHHHHHHH",
      "GGHHHHHccccccccc"
    ],
    [
      " d   eaaaaaaaaaa",
      "     eaaabbbbbbb",
      "   f eaaabbbbbbb",
      "   g eaaabbbbbbb",
      "     eaaabbbbbbb",
      "d    eaaabbbbbbb",
      "     eaaabbbbbbb",
      "     eaaabbbbbbb",
      "     eaaabbbbbbb",
      "     eaaabbbbbbb",
      "d  h eaaabbbbbbb",
      "     eaaabbbbbbb",
      "     eaaaaaaaaaa",
      "     vvvvHHHHHHH",
      "      iiiHHHHHHH",
      " d    iiiHHHHHHH"
    ],
    [
      " ~     jjj  jjkl",
      "        m     n ",
      "        j  o    ",
      "        p  qrqs ",
      "        p ot    ",
      "~       p   t u ",
      "       wk  qsqs ",
      "        x       ",
      "        y       ",
      "       Ak       ",
      "~       p       ",
      "        pBCCBDDD",
      "        pEEEEEEE",
      "     vvvvF IIIJF",
      "                ",
      " ~              "
    ],
    [
      "        jj  jjkK",
      "        j       ",
      "        j       ",
      "        p  L M  ",
      "        j       ",
      "        p       ",
      "       wk  rMNO ",
      "        P       ",
      "        Q       ",
      "       Ak       ",
      "        p       ",
      "        jRRRR   ",
      "        pEEEEEEE",
      "     vvvv     I ",
      "                ",
      "                "
    ],
    [
      "        jj jjjkk",
      "        j       ",
      "        j       ",
      "        p       ",
      "        j       ",
      "        p       ",
      "       Sk       ",
      "       Tk       ",
      "       Tk       ",
      "       Uk       ",
      "        p       ",
      "        j       ",
      "        pEEEEEEE",
      "     vvvv     II",
      "                ",
      "                "
    ],
    [
      "        jjjjjjjj",
      "        j       ",
      "        j       ",
      "        p       ",
      "        p       ",
      "        p       ",
      "        pVVVVVVV",
      "        p       ",
      "        p       ",
      "        p       ",
      "        p       ",
      "        pIWIIWII",
      "        pEEEEEEE",
      "     vvvv       ",
      "                ",
      "                "
    ]
  ]
}