{
  "name": "multi_militarybase_3_base2",
  "refpalette": "c70cities:multi_militarybase_3_base2_palette",
  "xsize": 16,
  "zsize": 16,
  "slices": [
    [
      "                ",
      "  a    a    a   ",
      "bbvbbbbvbbbbvbbb",
      "cccccccbcccccccc",
      "cccccccbcccccccc",
      "cccccccbcccccccc",
      "dddddddvdddddddd",
      "eeeeeeebeeeeeeee",
      "eeeeeeebeeeeeeee",
      "eeeeeeebeeeeeeee",
      "bbbbbbbvbbbbbbbb",
      "fffffffbffffffff",
      "fffffffbffffffff",
      "fffffffbffffffff",
      "fffffffvffffffff",
      "vvvvvvvvvvvvvvvv"
    ],
    [
      "                ",
      "                ",
      "ggvggggvggggvggg",
      "                ",
      "                ",
      "                ",
      "hhhhhhivihjhhhhh",
      "klmlll   llkmkll",
      "                ",
      "                ",
      "iiniiiiviiiioiii",
      "p  qrsst        ",
      "u   w xt        ",
      "p   rsst y y y y",
      "u A w xv y y y!y",
      "vvvvvvvvvvvvvvvv"
    ],
    [
      "                ",
      "                ",
      "  v    v    v   ",
      "                ",
      "                ",
      "                ",
      "hB!hChivihhhDhhh",
      "E F        IFJ  ",
      "                ",
      "                ",
      "iiKiiiiviiiiLiii",
      "M   rsstN N   N ",
      "u   O  t        ",
      "M   rsst y y y y",
      "u P O  vQyQyQyQy",
      "vvvvvvvvvvvvvvvv"
    ],
    [
      "                ",
      "                ",
      "  v    v    v   ",
      "                ",
      "                ",
      "                ",
      "iiiiiiiviiiiiiii",
      "                ",
      "                ",
      "                ",
      "iiiiiiiviiiiiiii",
      "u   rsst        ",
      "u   r  t        ",
      "u   rsst        ",
      "u P r  vR R R R ",
      "vvvvvvvvvvvvvvvv"
    ],
    [
      "                ",
      "                ",
      "SSvSSSSvSSSSvSSS",
      "                ",
      "                ",
      "                ",
      "gggggggvgggggggg",
      "       g        ",
      "       g        ",
      "       g        ",
      "iiiiiiiviiiiiiii",
      "TTTTTTTtTTTTTTTT",
      "TTTTTTTtTTTTTTTT",
      "TTTTTTTtTTTTTTTT",
      "TTTTTTTvTTTTTTTT",
      "vvvvvvvvvvvvvvvv"
    ],
    [
      "                ",
      "                ",
      "UUvUUUUvUUUUvUUU",
      "VVVVVVVbVVVVVVVV",
      "VVVVVVVbVVVVVVVV",
      "VVVVVVVbVVVVVVVV",
      "VVVVVVVvVVVVVVVV",
      "VVVVVVVbVVVVVVVV",
      "VVVVVVVbVVVVVVVV",
      "VVVVVVVbVVVVVVVV",
      "bbbbbbbvbbbbbbbb",
      "WX  W XbX W  XW ",
      "W   W  b  W   WX",
      "W   W Xb  W  XWX",
      "WWWWWWWvWWWWWWWW",
      "vvvvvvvvvvvvvvvv"
    ]
  ]
}