{
  "name": "multi_megatower1_7_floor12",
  "refpalette": "c70cities:multi_megatower1_7_floor12_palette",
  "xsize": 16,
  "zsize": 16,
  "slices": [
    [
      "aaabc           ",
      "aaabd           ",
      "aaabd           ",
      "aaabd           ",
      "aaefgh          ",
      "aaabc           ",
      "aaabc           ",
      "aaabc           ",
      "aaabd           ",
      "aaabd           ",
      "aaabd           ",
      "aaefgh          ",
      "aaabc           ",
      "aaabc           ",
      "aaabc           ",
      "aaabd           "
    ],
    [
      "i j c           ",
      "  j d           ",
      "k j d           ",
      "lmj d           ",
      "nne gh          ",
      "  j c           ",
      " oj c           ",
      "ppj c           ",
      " oj d           ",
      "ppj d           ",
      " oj d           ",
      "nne gh          ",
      "  j c           ",
      "  j c           ",
      "q j c           ",
      "  j d           "
    ],
    [
      "  r c           ",
      "  r d           ",
      "  r d           ",
      " sj d           ",
      "nne gh          ",
      "  j c           ",
      " tj c           ",
      "ppj c           ",
      " tj d           ",
      "ppj d           ",
      " tj d           ",
      "nne gh          ",
      "  j c           ",
      "  r c           ",
      "  r c           ",
      "  r d           "
    ],
    [
      "  u c           ",
      "  u d           ",
      "  u d           ",
      " sj d           ",
      "nne gh          ",
      "  j c           ",
      "  j c           ",
      "ppj c           ",
      "  j d           ",
      "ppj d           ",
      "  j d           ",
      "nne gh          ",
      "  j c           ",
      "  u c           ",
      "  u c           ",
      "  u d           "
    ],
    [
      "wwj c           ",
      "wwj d           ",
      "wwj d           ",
      "wwj d           ",
      "nne gh          ",
      "xxj c           ",
      "x!j c           ",
      "xxj c           ",
      "xyj d           ",
      "xxj d           ",
      "xyj d           ",
      "nne gh          ",
      "wwj c           ",
      "wwj c           ",
      "wwj c           ",
      "wwj d           "
    ],
    [
      " AB c           ",
      "CAB d           ",
      " AB d           ",
      " AB d           ",
      "DDeEgh          ",
      "CAB c           ",
      "AAB c           ",
      "CAB c           ",
      "AAB d           ",
      " AB d           ",
      "AAB d           ",
      "DDeEgh          ",
      "CAB c           ",
      " AB c           ",
      " AB c           ",
      "CAB d           "
    ]
  ]
}