{
  "name": "multi_hospital_0_ground",
  "refpalette": "c70cities:multi_hospital_0_ground_palette",
  "xsize": 16,
  "zsize": 16,
  "slices": [
    [
      "GGGGGGGGGGGGGGGG",
      "GGGGGGGGGaaaaaaa",
      "GGGbbbbbGaaaaaaa",
      "GGGbbbbbGacccccc",
      "GGGbbGbbGa  cccc",
      "GGGbbbbbGa  cccc",
      "GGGbbbbbGad cccc",
      "GGGGGGGGGadecccc",
      "GGfaaaaaafgggccc",
      "GGavvvvvvh  hccc",
      "GGavvvvvvh  hccc",
      "GGavvvvvvg ggccc",
      "GGavvvvvvaiccccc",
      "GGavvvvvvacccccc",
      "GGavvvvvva!ccccc",
      "GGavvvvvvacccccc"
    ],
    [
      "                ",
      "  jjj  jjk      ",
      "  j     jl m m m",
      "  j    njogggggg",
      "     p qjo  rs s",
      "        jod r t ",
      "  j uw  jox r   ",
      "  jjjjjjjo      ",
      "  fyyyyyyfgggr  ",
      "  ABBBBB C  D   ",
      "  A      E  F   ",
      "  A III  g gg   ",
      "  AJKIKL MNOP   ",
      "  A III  MQO    ",
      "  A III  M O    ",
      "  A IRI  MQOS   "
    ],
    [
      "                ",
      "         k      ",
      "         l m m m",
      "         oggooog",
      "     ~   od     ",
      "         ox     ",
      "         o      ",
      "         o      ",
      "  fyyyyyyfgggr  ",
      "  A TT T U  V   ",
      "  A      W  X   ",
      "  AYZ0Z12g gg3  ",
      "  AY4 51 MN     ",
      "  AY6 71 M      ",
      "  AY8 91 M      ",
      "  AYZZZ1 M      "
    ],
    [
      "                ",
      "         k      ",
      "         l m m m",
      "         oggooog",
      "         oed    ",
      "         o d    ",
      "         o      ",
      "         o      ",
      "  frrrrrrfgggr  ",
      "  r      @  #   ",
      "  r      @  #   ",
      "  r$%^%& g gg   ",
      "  r$   & MN     ",
      "  r$   & M      ",
      "  r$* (& M      ",
      "  r$Z)Z& M      "
    ],
    [
      "                ",
      "         k      ",
      "         l m m m",
      "         ogggggg",
      "         o      ",
      "         o +    ",
      "         o d  - ",
      "         o      ",
      "  frrrrrrfgggr  ",
      "  r      g  g   ",
      "  r      g  g   ",
      "  rYZZZ1 g gg   ",
      "  rY  [1 MN     ",
      "  rY  [1 M      ",
      "  rY[[[1 M      ",
      "  rYZZZ1 M      "
    ],
    [
      "                ",
      "         k      ",
      "         l m m m",
      "         ogggggg",
      "         o      ",
      "         o      ",
      "         o +  ] ",
      "         o d    ",
      "  fyyyyyyfgggrrr",
      "  A      g  g   ",
      "  A      g  g   ",
      "  A {[{  g }g   ",
      "  A {[{  MN     ",
      "  A {[{  M      ",
      "  A {{{  M      ",
      "  A \\ |  M      "
    ]
  ]
}