{
  "name": "multi_communitycenter_6_ground",
  "refpalette": "c70cities:multi_communitycenter_6_ground_palette",
  "xsize": 16,
  "zsize": 16,
  "slices": [
    [
      "aaaaaaaaaaaaaaaa",
      "aaaaabbbbbbbbbbb",
      "GGGGbHHHHHHHHHHH",
      "GGGbHHHHHHHHHHHH",
      "GGGbHHHHHHHHHHHH",
      "GGGbHHHHHHHHHHHH",
      "GGGbHHHHbbbbbbbb",
      "GGGbccccbGGGGGGa",
      "dddbeeeebdddddGa",
      "dddb    bdddddGa",
      "dddb    bdddddGa",
      "dddb    bdddddGa",
      "dddb    bdddddGa",
      "dddb    bdddddGa",
      "dddb    bdddddGa",
      "dddb    bdddddGa"
    ],
    [
      "                ",
      "     fffffffffff",
      "ggggf           ",
      "g hf            ",
      "iihf            ",
      " hif            ",
      "h hf    ffffffff",
      "hihf    fggggg  ",
      "jjkf    fkjjjkl ",
      " mnf    fn  opg ",
      " qnf    fn rrpg ",
      " snf    fn   pg ",
      "  tf    ft uwkl ",
      " mnf    fn  xpg ",
      " qnf    fn rrpg ",
      " snf    fn u pg "
    ],
    [
      "                ",
      "                ",
      "                ",
      "  y             ",
      "AAy             ",
      " yA             ",
      "y y             ",
      "yAy             ",
      "jjk      kjjjk  ",
      "  n      n   p  ",
      "  n      n B p  ",
      "  n      n   p  ",
      "  t      t   k  ",
      "  n      n   p  ",
      "  n      n   p  ",
      "  n      n   p  "
    ],
    [
      "                ",
      "                ",
      "                ",
      "                ",
      "                ",
      "                ",
      "                ",
      "                ",
      "jjk      kjjjk  ",
      "  n      n   j  ",
      "  n      n   j  ",
      "  n      n   j  ",
      "  t      t   k  ",
      "  n      n   j  ",
      "  n      n   j  ",
      "  n      n   j  "
    ],
    [
      "                ",
      "                ",
      "                ",
      "                ",
      "                ",
      "                ",
      "                ",
      "                ",
      "CCkCCCCCCkCCCk  ",
      "  n      n   p  ",
      "  n      n   p  ",
      "  n      n   p  ",
      "  t      tD  k  ",
      "  n      n   p  ",
      "  n      n   p  ",
      "  n      n   p  "
    ],
    [
      "                ",
      "                ",
      "                ",
      "                ",
      "                ",
      "                ",
      "                ",
      "                ",
      "EEkEEEEEEkEEEE  ",
      "dddddddddddddE  ",
      "dddddddddddddE  ",
      "dddddddddddddE  ",
      "dddddddddddddk  ",
      "dddddddddddddE  ",
      "dddddddddddddE  ",
      "dddddddddddddE  "
    ]
  ]
}