{
  "name": "multi_clubhouse1_5_base1",
  "refpalette": "c70cities:multi_clubhouse1_5_base1_palette",
  "xsize": 16,
  "zsize": 16,
  "slices": [
    [
      "                ",
      "                ",
      "aaaaaaaaaaaaaaaa",
      "bbbbabbbbbbabbbb",
      "   bab    bab   ",
      "   bab    bab   ",
      "   bab    bab   ",
      "   bab    bab   ",
      "bbbbabbbbbbabbbb",
      "aaaaaaaaaaaaaaaa",
      "                ",
      "                ",
      "                ",
      "                ",
      "  ccd e  ecdc ec",
      "vvvvvvvvvvvvvvvv"
    ],
    [
      "            ffgg",
      "ffffffffffffgggh",
      "ggggggggggggghhh",
      "hhhhhhhhhhhhhhhh",
      "hhhhhhhhhhhhhhhh",
      "hhhhhhhhhhhhhhhh",
      "hhhhhhhhhhhhhhhh",
      "hhhhhhhhhhhhhhhh",
      "hhhhhhhhhhhhhhhh",
      "gggggggggggggggg",
      "                ",
      "                ",
      "                ",
      "                ",
      "  c d e  eed  c ",
      "vvvvvvvvvvvvvvvv"
    ],
    [
      "              ii",
      "            iii ",
      "iiiijiiiiiiji   ",
      "                ",
      "                ",
      "            k   ",
      "  l m      n l  ",
      "  okpkq  olmkq  ",
      "  rsmlt  rkm t  ",
      "uuuuduuuuuuduuuu",
      "                ",
      "                ",
      "                ",
      "                ",
      "  c d     ed  c ",
      "vvvvvvvvvvvvvvvv"
    ],
    [
      "              ii",
      "            iii ",
      "iiiijiiiiiiji   ",
      "                ",
      "                ",
      "                ",
      "    m      s    ",
      "                ",
      "    w      x    ",
      "    d      d    ",
      "                ",
      "                ",
      "                ",
      "                ",
      "    d      d    ",
      "vvvvvvvvvvvvvvvv"
    ],
    [
      "              ii",
      "            iii ",
      "iiiijiiiiiiji   ",
      "                ",
      "                ",
      "                ",
      "                ",
      "                ",
      "                ",
      "    d      d    ",
      "                ",
      "                ",
      "                ",
      "                ",
      "    d      d    ",
      "vvvvvvvvvvvvvvvv"
    ],
    [
      "              ii",
      "            iiib",
      "iiiijiiiiiijibbb",
      "bbbbbbbbbbbbbbbb",
      "bbbbybbbbbbAbbbb",
      "bbbbbbbbbbbbbbbb",
      "bbbbbbbbbbbbbbbb",
      "bbbbybbbbbbybbbb",
      "bbbbbbbbbbbbbbbb",
      "    d      d    ",
      "                ",
      "                ",
      "                ",
      "                ",
      "    d      d    ",
      "vvvvvvvvvvvvvvvv"
    ]
  ]
}