{
  "name": "multi_laboratory1_11_base4",
  "refpalette": "c70cities:multi_laboratory1_11_base4_palette",
  "xsize": 16,
  "zsize": 16,
  "slices": [
    [
      "aaaaaaaaaaaaabcz",
      "aaaaaaaaaaaaabcz",
      "aaaaaaaaaaaaabcz",
      "aaaaaaaaaaaaabcz",
      "aaaaaaaaaaaaabcz",
      "aaaaaaaaaaaaabcz",
      "aaaadaaaaaaaabcz",
      "aaaaaaaaaaaaabcz",
      "aaaaaaaaaaaaabcz",
      "aaaaaaaaaaaaabcz",
      "aaaaaaaaaaaaabcz",
      "aaaaaaaaaaaaabcz",
      "eaaaaaaaaaaaabcz",
      "eaaadaaaaaaaabcz",
      "feaaaaaaaaaaabcz",
      " eaaaaaaaaaaabcz"
    ],
    [
      "    ghiiiiiihbcz",
      "    gj      ibcz",
      "    gk      ibcz",
      "    g       ibcz",
      "    l       ibcz",
      "    gmnnnnnnhbcz",
      "   fdggggggggbcz",
      "o   gpp p p qbcz",
      "    g        bcz",
      "    g  r    sscz",
      "    gtuuu wsxycz",
      "    gAuuu BCxycz",
      "DE  g FI   ~sscz",
      "Df  dJw    Kqbcz",
      "fD  g        bcz",
      " D  L       sscz"
    ],
    [
      "    ghiiiiiihbcz",
      "    M       ibcz",
      "    MN      ibcz",
      "    g       ibcz",
      "    O       ibcz",
      "    gP     Qhbcz",
      "   Rdggggggggbcz",
      "    g       qbcz",
      "    M       Sbcz",
      "    M       Dscz",
      "    M TTU  Dxycz",
      "    MVTwT   xycz",
      "D   g       Kscz",
      "DR  d       qbcz",
      "fD  g       Sbcz",
      " D  L       Dscz"
    ],
    [
      "    ghWWWWWWhbcz",
      "    X       Ybcz",
      "    X       Zbcz",
      "    g       0bcz",
      "    X       1bcz",
      "    g       hbcz",
      "   Rdggggggggbcz",
      "    g       qbcz",
      "    M        bcz",
      "    M       Dscz",
      "    M      Dxycz",
      "    M      2xycz",
      "D   g       Dscz",
      "DR  d       qbcz",
      "fD  g        bcz",
      " D  L       Dscz"
    ],
    [
      "    gh      hbcz",
      "    g        bcz",
      "    g        bcz",
      "    g        bcz",
      "    g        bcz",
      "    g       hbcz",
      "    dggggggggbcz",
      "    g  3  3 4bcz",
      "    g       Sbcz",
      "    g       Dscz",
      "    g      D5ycz",
      "    g      D5ycz",
      "D   g       Dscz",
      "D   d       4bcz",
      "fD  g       Sbcz",
      " D  g       Dscz"
    ],
    [
      "6666X77777777bcz",
      "6686X797777!7bcz",
      "6686X77777777bcz",
      "6686X77777777bcz",
      "6686X79777797bcz",
      "6666X77777777bcz",
      "6666dggggggggbcz",
      "6666X@@@@@@@@bcz",
      "6666X########bcz",
      "6666X##8##8#sscz",
      "6666X##8##$s%ycz",
      "6666X##8##8s%ycz",
      "D666X##$##$#sscz",
      "D666d########bcz",
      "fD66X########bcz",
      " D66X##8##8#sscz"
    ]
  ]
}