{
  "name": "multi_communitycenter_0_ground",
  "refpalette": "c70cities:multi_communitycenter_0_ground_palette",
  "xsize": 16,
  "zsize": 16,
  "slices": [
    [
      "aaaaaaaaaaaaaaaa",
      "aaaaaaaaaaaaaaaa",
      "aabccccccccccccc",
      "aabccccccccccccc",
      "aabccccccccccccc",
      "aabddddddddddddd",
      "aabddddddddddddd",
      "aabddddddddddddd",
      "aabddddddddddddd",
      "aabddddddddddddd",
      "aabddddddddddddd",
      "aabddddddddddddd",
      "aabeeeeeeeeeeeee",
      "aafegggghgggghgg",
      "aafijjjjjjjjjjjj",
      "aafikjjjjjjjjjjj"
    ],
    [
      "                ",
      "                ",
      "  lm            ",
      "  lm            ",
      "  fmnnn o    nnn",
      "  fccccccccccccc",
      "  fccccccccccccc",
      "  fccccccccccccc",
      "  fccccccccccccc",
      "  fddddddddddddd",
      "  fddddddddddddd",
      "  fddddddddddddd",
      "  fepppppppppppp",
      "  fe!q r s  t u ",
      "  fq            ",
      "  fw            "
    ],
    [
      "                ",
      "                ",
      "                ",
      "                ",
      "   m            ",
      "   m            ",
      "  lm            ",
      "  lmo     ~     ",
      "  fm    nnnnnnno",
      "  fccccccccccccc",
      "  fxcccccccccccc",
      "  fxcccccccccccc",
      "  fccccccccccccc",
      "  feeeeeeeeeeeee",
      "  fyyyyyyyyyyyyy",
      "  Ayyyyyyyyyyyyy"
    ],
    [
      "                ",
      "                ",
      "                ",
      "                ",
      "                ",
      "                ",
      "                ",
      "          ~     ",
      "   m            ",
      "   m            ",
      "  lm            ",
      "  lm       o    ",
      "  fm nnnnnnn    ",
      "  fccccccccccccc",
      "  fccccccccccccc",
      "  fccccccccccccc"
    ],
    [
      "                ",
      "                ",
      "                ",
      "                ",
      "                ",
      "                ",
      "                ",
      "          ~     ",
      "                ",
      "                ",
      "                ",
      "                ",
      "   m            ",
      "   mo           ",
      "  lm            ",
      "  lm            "
    ],
    [
      "                ",
      "                ",
      "                ",
      "                ",
      "                ",
      "                ",
      "                ",
      "          ~     ",
      "                ",
      "                ",
      "                ",
      "                ",
      "                ",
      "                ",
      "                ",
      "                "
    ]
  ]
}