{
  "name": "multi_condo1_3_floor2",
  "refpalette": "c70cities:multi_condo1_3_floor2_palette",
  "xsize": 16,
  "zsize": 16,
  "slices": [
    [
      "                ",
      "      a         ",
      "bbbbbbacccccccc ",
      "ddddddaeeeeeeec ",
      "fffffffggggggec ",
      "fffffffhhhhhgec ",
      "fffffffhhhhhgec ",
      "fffffffhhhhhgec ",
      "hhhhhhhhhhhhgec ",
      "hhhhhhhhhhhhgec ",
      "hhhhhhhhhhhhgec ",
      "hhhhhhhhhhhhgec ",
      "hhhhhhhhhhhhgec ",
      "hhhhhhhhhhhhgaaa",
      "fffffffiiiiigj  ",
      "kkkkklfiiiiigj  "
    ],
    [
      "                ",
      "      a         ",
      "bbbbbba         ",
      "      aeeeeeee  ",
      "     gggmmmgge  ",
      "  no pgpqrspge  ",
      "      t     ge  ",
      "uuuuugg  ww ge  ",
      "xxy  pA BCCBge  ",
      "      A DEEEge  ",
      "F I   J    Kge  ",
      "F L   AM  NOge  ",
      "      AM   Pge  ",
      "  QQQ!AM   !gaaa",
      "RggggggAASAAg   ",
      "     TgU   VW   "
    ],
    [
      "                ",
      "      a         ",
      "      a         ",
      "      a         ",
      "     ggguuugg   ",
      "     XgXYZ Xg   ",
      "      0     g   ",
      "uuuuugg     g   ",
      "1    XA     g   ",
      "      A 2222g   ",
      "      3     g   ",
      "      AM   4g   ",
      "      AM    g   ",
      "  567 AM   8gaaa",
      "9ggggggAA@AAg   ",
      "     eg   # b   "
    ],
    [
      "                ",
      "      a         ",
      "      a         ",
      "      a         ",
      "     ggguuugg   ",
      "      g     g   ",
      "      $     g   ",
      "uuuuugg     g   ",
      "     XA     g   ",
      "      A 2222g   ",
      "      A     g   ",
      "      A     g   ",
      "      A     g   ",
      "   %  A^    gaaa",
      "&ggggggAAAAAg   ",
      "     eg     b   "
    ],
    [
      "                ",
      "      a         ",
      "      a         ",
      "      a*******  ",
      "ggggggggggggg*  ",
      "      g     g*  ",
      "      g     g*  ",
      "uuuuugg     g*  ",
      "      A     g*  ",
      "      A 2222g*  ",
      "      A     g*  ",
      "      A     g*  ",
      "      A     g*  ",
      "      A     gaaa",
      "gggggggAAAAAg   ",
      "     (g     g   "
    ],
    [
      "                ",
      "      a         ",
      "))))))a         ",
      "      a+++++++  ",
      "ggggggggggggg+  ",
      "kkkkkkg-----g+  ",
      "kkkkkkg-----g+  ",
      "[[[[[gg-----g+  ",
      "------------g+  ",
      "------------g+  ",
      "------------g+  ",
      "------------g+  ",
      "------------g+  ",
      "------------gaaa",
      "ggggggg-----g   ",
      "      g-----g   "
    ]
  ]
}