{
  "name": "multi_factory_0_ground",
  "refpalette": "c70cities:multi_factory_0_ground_palette",
  "xsize": 16,
  "zsize": 16,
  "slices": [
    [
      "zaazzzzzzzzzzzzz",
      "aaazzzzzzzzzzzzz",
      "aazbbbbbbbbbbbzz",
      "aaabbbbbbbbbbbzz",
      "aaabbbbbbbbbbbzz",
      "zaabbbbbbbbbbbzz",
      "zaabbbbbbbbbbbzz",
      "aaabbbbbbbbbbbzz",
      "zaabbbbbbbbbbbzz",
      "aaabbbbbbbbbbbzz",
      "aaabbbbbbbbbbbzz",
      "aaabbbbbbbbbbbzz",
      "zaabbbbbbbbbbbzz",
      "aaabbbbbbbbbbbzz",
      "zaabbbbbbbbbbbzz",
      "aaabbbbbbbbbbbzz"
    ],
    [
      "                ",
      "                ",
      "   ccccccccccc  ",
      "   cdeffdgh dc  ",
      "   ij    k  lc  ",
      "   c     mnnnc  ",
      "   co    p  lc  ",
      "   coq   gr  c  ",
      "   co    ssssc  ",
      "   co t     uc  ",
      "   c wxxye j c  ",
      "   cmmmmmmmAmc  ",
      "   cBBddC C dc  ",
      "            dc  ",
      "           DEc  ",
      "            dc  "
    ],
    [
      "                ",
      "                ",
      "   ccccccccccc  ",
      "   cd ffdg  dc  ",
      "   F     I  Jc  ",
      "   c     mnnnc  ",
      "   KL    M  Jc  ",
      "   KN    g   c  ",
      "   KN    ssssc  ",
      "   K        uc  ",
      "   c   O     c  ",
      "   cmKKKKmmPmc  ",
      "   cd       ec  ",
      "            Qc  ",
      "           RSc  ",
      "            Qc  "
    ],
    [
      "                ",
      "                ",
      "   ccTUVcTUVcc  ",
      "   cd   dg  dc  ",
      "   K     g   c  ",
      "   c     mnnnc  ",
      "   K     g   c  ",
      "   K     g   c  ",
      "   K     ssssc  ",
      "   K        uc  ",
      "   c         c  ",
      "   cmKKKKmmmmc  ",
      "   c         c  ",
      "   W         c  ",
      "   W        Xc  ",
      "   W         c  "
    ],
    [
      "                ",
      "                ",
      "   ccccccccccc  ",
      "   cd   dg  dc  ",
      "  Yc     g   c  ",
      "  Yc     mnnnc  ",
      "  Yc     g   c  ",
      "  Yc     g   c  ",
      "  Yc     ssssc  ",
      "  Yc        uc  ",
      "   c         c  ",
      "   cmmmmmmmmmc  ",
      "   c         c  ",
      "  YcZ        c  ",
      "  YcZ       0c  ",
      "  YcZ        c  "
    ],
    [
      "                ",
      "                ",
      "   ccccccccccc  ",
      "   cd   dbbbdc  ",
      "   c    1bbbbc  ",
      "   c    1bbbbc  ",
      "   c    1bbbbc  ",
      "   c    1bbbbc  ",
      "   c    1bbbbc  ",
      "   c    1bbbuc  ",
      "   c    1bbbbc  ",
      "   cmmmmmmmmmc  ",
      "   c        Cc  ",
      "   c         c  ",
      "   c         c  ",
      "   c         c  "
    ]
  ]
}