{
  "name": "multi_laboratory1_8_base6",
  "refpalette": "c70cities:multi_laboratory1_8_base6_palette",
  "xsize": 16,
  "zsize": 16,
  "slices": [
    [
      "aaaaaaabbaaaaaaa",
      "aaaaaaaaaaaaaaaa",
      "cccdccccccccdccc",
      "aaaaaaaaaaaaaaaa",
      "aaaaaaaaaaaaaaaa",
      "aaaaaaaaaaaaaaaa",
      "aaaaaaaaaaaaaaaa",
      "aaaaaaaaaaaaaaae",
      "aaaaaaaaaaaaaaae",
      "aaaaaaaaaaaaaaaa",
      "aaaaaaaaaaaaaaaa",
      "aaaaaafaaaaaaaaa",
      "aaaaaaaaaaaaaaaa",
      "aaaaaaaaaaaaaaaa",
      "aaaaaaaaaaaaaaaa",
      "aaaaaaaaaaaaaaaa"
    ],
    [
      "             g  ",
      "            h gi",
      "jjjdjjjjjjjjdjj ",
      "                ",
      "                ",
      "                ",
      "                ",
      "      kkkk    l ",
      "  mccccccccccc n",
      "  mffffffffffcol",
      "  cffpfffqrffcs ",
      " tcfp!rfffqffcu ",
      " tcfffffpffffcu ",
      " tcfeffwxweffcu ",
      " tcffppxy!fffcu ",
      "  cffeffqffffcAp"
    ],
    [
      "                ",
      "                ",
      "BBBdBBBBBBBBdBB ",
      "                ",
      "                ",
      "                ",
      "                ",
      "                ",
      "  CCCCCCCCCCCC  ",
      "  Cpepe      C  ",
      "  CDppp    i C  ",
      "  Cpe        C  ",
      "  Cpp   nE   C  ",
      "  C  E    F  C  ",
      "  C   F  sI  C  ",
      "  C   E  A   CAn"
    ],
    [
      "                ",
      "                ",
      "BBBdBBBBBBBBdB  ",
      "                ",
      "                ",
      "                ",
      "                ",
      "                ",
      "  CCCCCCCCCCCC  ",
      "  Cp F       C  ",
      "  Cpe        C  ",
      "  C          C  ",
      "  CF         C  ",
      "  C          C  ",
      "  C          C  ",
      "  C     JA   Cn "
    ],
    [
      "                ",
      "                ",
      "BBBdBBBBBBBBdBB ",
      "                ",
      "                ",
      "                ",
      "                ",
      "                ",
      "  CCCCCCCCCCCC  ",
      "  CK         C  ",
      "  Cp         C  ",
      "  C          C  ",
      "  C          C  ",
      "  C          C  ",
      "  C      LJ  C  ",
      "  C     nA   C  "
    ],
    [
      "                ",
      "                ",
      "BBBdBBBBBBBBdBBM",
      "                ",
      "                ",
      "                ",
      "                ",
      "                ",
      "  CCCCCCCCCCCC  ",
      "  Cp         C  ",
      "  CA         C  ",
      "  C          C  ",
      "  C          C  ",
      "  C          C  ",
      "  C       n  C  ",
      "  C      A   C  "
    ]
  ]
}