{
  "name": "multi_carservice_0_ground",
  "refpalette": "c70cities:multi_carservice_0_ground_palette",
  "xsize": 16,
  "zsize": 16,
  "slices": [
    [
      "GGGGGGGGGGGGGGGG",
      "GGGGGGGGGGGGGGGG",
      "GGGGGGGGGGGGGGGG",
      "GGGGGGGGGGGGGGGG",
      "GGGGGGGGGGGGGGGG",
      "GGGGGGGGGGGGGGGG",
      "GGGGaabaaabaaabG",
      "GGGcccc!ccccccaG",
      "GGccccccccccccaG",
      "GaccccdedcfgecaG",
      "GacccceddchijcaG",
      "Gacccceedc!klcaG",
      "GacccceeeceeecaG",
      "GmccccccccccccaG",
      "GaccccccccccccaG",
      "GaccccccccccccaG"
    ],
    [
      "                ",
      "             n  ",
      "       n        ",
      "                ",
      "    oo oooo ooo ",
      "                ",
      "    aabaaabaaab ",
      "   pp  qr  q  a ",
      "  pp          p ",
      " ap           p ",
      " as           p ",
      " a            p ",
      " at           p ",
      " au           p ",
      " aw           p ",
      " aw           p "
    ],
    [
      "                ",
      "             ~  ",
      "       ~        ",
      "                ",
      "                ",
      "                ",
      "    aabaaabaaab ",
      "   pp  x   x  a ",
      "  pp          p ",
      " ap           p ",
      " as           p ",
      " b            p ",
      " p            p ",
      " p            p ",
      " p            p ",
      " p            p "
    ],
    [
      "                ",
      "                ",
      "                ",
      "                ",
      "                ",
      "                ",
      "    aabaaabaaab ",
      "   pp         a ",
      "  pp          p ",
      " ap           p ",
      " as           p ",
      " a            p ",
      " a            p ",
      " a            p ",
      " a            p ",
      " a            p "
    ],
    [
      "                ",
      "                ",
      "                ",
      "                ",
      "                ",
      "                ",
      "    aabaaabaaab ",
      "   pp         a ",
      "  pp          y ",
      " ap           y ",
      " as           y ",
      " a            y ",
      " a            y ",
      " a            y ",
      " a            y ",
      " a            y "
    ],
    [
      "                ",
      "                ",
      "                ",
      "                ",
      "                ",
      "                ",
      "    aabaaabaaab ",
      "   pp  AAAAAAAa ",
      "  pp   AAAAAAAa ",
      " ap    AAAAAAAa ",
      " as    AAAAAAAa ",
      " a     AAAAAAAa ",
      " aAAAAAAAAAAAAa ",
      " aAAAAAAAAAAAAa ",
      " aAAAAAAAAAAAAa ",
      " aAAAAAAAAAAAAa "
    ]
  ]
}