{
  "name": "multi_militarybase_1_base1",
  "refpalette": "c70cities:multi_militarybase_1_base1_palette",
  "xsize": 16,
  "zsize": 16,
  "slices": [
    [
      "vaaaaaaaaabbbc  ",
      "vaaaaaaaaabbbc  ",
      "vvcccvcccccccvcc",
      "vaaaacaaaabbbcbb",
      "vaaaacaaaabbbcbb",
      "vaaaacaaaaabbcbb",
      "vaaaacaaaaaadvee",
      "vaaaacaaaaaaacaa",
      "vaaaacaaaaaaacaa",
      "vaaaacaaaaaaacaa",
      "vvcccvcccccccvcc",
      "vaaaacaaaaaaacff",
      "vaaaacaaaaaaacff",
      "vaaaacaaaaaaacff",
      "vaaaavaaaaaaavff",
      "vvvvvvvvvvvvvvvv"
    ],
    [
      "vgh          i  ",
      "vjh          i  ",
      "vvk  v       vii",
      "vlm  n          ",
      "voo  n   p      ",
      "v q  n          ",
      "voo rn   s  dv  ",
      "v tr n   u      ",
      "voo  n          ",
      "vw   n        xy",
      "vvk  vnnnnnnnvAA",
      "vB           kC ",
      "vB     oD Eo kAA",
      "vFI Jk ol Ko kC ",
      "vLMMLv NO PN vAA",
      "vvvvvvvvvvvvvvvv"
    ],
    [
      "v!              ",
      "vj              ",
      "vvk  v       v  ",
      "v    n          ",
      "vQ   n          ",
      "vR   n   p      ",
      "vQ   n   s   v  ",
      "vR   n   u      ",
      "vQ   n          ",
      "v    n          ",
      "vvk  vnnnnnnnvAA",
      "vS           k  ",
      "v      T   U kAA",
      "v    k V   W k  ",
      "v    v X   X vAA",
      "vvvvvvvvvvvvvvvv"
    ],
    [
      "vg              ",
      "vj              ",
      "vvk  v       v  ",
      "v    n          ",
      "v    n          ",
      "v    n          ",
      "v    n   p  Yv  ",
      "v    n   u      ",
      "v    n          ",
      "v    n          ",
      "vvk  vnnnnnnnvAA",
      "v            k  ",
      "v            kAA",
      "v    k       k  ",
      "vZ00Zv       vAA",
      "vvvvvvvvvvvvvvvv"
    ],
    [
      "v            n  ",
      "vh           n  ",
      "vvkkkv       vnn",
      "v    i          ",
      "v    i          ",
      "v    i          ",
      "v    i       v  ",
      "v    i   p      ",
      "v    i          ",
      "v    i          ",
      "vvkkkviiiiiiivAA",
      "v    k       k11",
      "v    k       k11",
      "v    k       k11",
      "vZ  Zv       v11",
      "vvvvvvvvvvvvvvvv"
    ],
    [
      "v233333333333c44",
      "v233333333333c44",
      "vvcccvcccccccvcc",
      "v2333c3333333c33",
      "v2333c3333333c33",
      "v2333c333 333c33",
      "v2333c333 333v33",
      "v2333c333 333c33",
      "v2333c333p333c33",
      "v2333c333 333c33",
      "vvcccvcccccccvcc",
      "v!333c3333333c h",
      "v2333c3533353c  ",
      "v2333c3333333ch ",
      "v2222v2222222v22",
      "vvvvvvvvvvvvvvvv"
    ]
  ]
}