{
  "name": "multi_laboratory1_2_base5",
  "refpalette": "c70cities:multi_laboratory1_2_base5_palette",
  "xsize": 16,
  "zsize": 16,
  "slices": [
    [
      "vab           c ",
      "vadd          c ",
      "vad           c ",
      "vaeec         cf",
      "vabg c     hi  c",
      "vaeec          c",
      "vabd            ",
      "vabd            ",
      "vabd            ",
      "vab             ",
      "vaeec           ",
      "vabjkc     hl   ",
      "vaeec           ",
      "vab             ",
      "vabd            ",
      "vab             "
    ],
    [
      "vab           c ",
      "vabd          c ",
      "vab           c ",
      "vaeec         cf",
      "vabg c     h   c",
      "vaeec          c",
      "vab             ",
      "vab             ",
      "vabd            ",
      "vab             ",
      "vaeec           ",
      "vabjkc     h    ",
      "vaeec           ",
      "vabd            ",
      "vabd            ",
      "vab             "
    ],
    [
      "vabd          c ",
      "vabd          c ",
      "vab           c ",
      "vaeec         cf",
      "vabg c     h   c",
      "vaeec          c",
      "vab             ",
      "vab             ",
      "vabd            ",
      "vab             ",
      "vaeec           ",
      "vabgkc     h    ",
      "vaeec           ",
      "vab             ",
      "vabd            ",
      "vab             "
    ],
    [
      "vab           c ",
      "vabd          c ",
      "vab           c ",
      "vaeec         cf",
      "vabg c     h   c",
      "vaeec          c",
      "vab             ",
      "vab             ",
      "vadd            ",
      "vad             ",
      "vaeec           ",
      "vabgkc     h    ",
      "vaeec           ",
      "vab             ",
      "vabd            ",
      "vab             "
    ],
    [
      "vab           c ",
      "vabd          c ",
      "vab           c ",
      "vaeec         cf",
      "vabg c     h   c",
      "vaeec          c",
      "vab             ",
      "vab             ",
      "vabd            ",
      "vab             ",
      "vaeec           ",
      "vabgkc     h    ",
      "vaeec           ",
      "vab             ",
      "vabd            ",
      "vab             "
    ],
    [
      "vabdmmmmmmmmmmc ",
      "vabnmmmmmmmmmmc ",
      "vabdmmmmmmmmmmc ",
      "vaeeeemmmmmmmmcf",
      "vabgoemmmmmhmmmc",
      "vaeeeemmmmmmmmmc",
      "vabdmmmmmmmmmmmm",
      "vabdmmmmmmmmmmmm",
      "vabnmmmmmmmmmmmm",
      "vabdmmmmmmmmmmmm",
      "vaeeeemmmmmmmmmm",
      "vabgpemmmmmhmmmm",
      "vaeeeemmmmmmmmmm",
      "vabdmmmmmmmmmmmm",
      "vabnmmmmmmmmmmmm",
      "vabdmmmmmmmmmmmm"
    ]
  ]
}