{
  "name": "multi_condo1_5_floor4",
  "refpalette": "c70cities:multi_condo1_5_floor4_palette",
  "xsize": 16,
  "zsize": 16,
  "slices": [
    [
      "aaaaabcddeeefg  ",
      "cccccccddeeefg  ",
      "dddddddddeeefhhh",
      "dddddddddeeefij ",
      "ddddddddddddfij ",
      "ddddddddddddfij ",
      "ddddddddddddfij ",
      "ddddddddddddfij ",
      "ddddddddddddfij ",
      "ddddddddddddfij ",
      "ddddddddddddfij ",
      "ffkkkffffffffij ",
      "fggggghiiiiiiij ",
      "llllllhjjjjjjjj ",
      "      h         ",
      "                "
    ],
    [
      "      m  n  o   ",
      "fffffff  p qf   ",
      "prstuwxy p Afhhh",
      "pB    x  pCpfi  ",
      "pB    xy p Dfi  ",
      "pE       F Dfi  ",
      "pI   Ipppp Dfi  ",
      "pJ    pK   Lfi  ",
      "pK M NpOP  Qfi  ",
      "pK M RpOP STfi  ",
      "p     pK   Ufi  ",
      "ffV VfffWWWffi  ",
      "f     hiiiiiii  ",
      "llllllh         ",
      "      h         ",
      "                "
    ],
    [
      "      X  Y  l   ",
      "fffffff  pZ f   ",
      "p  012   p 3fhhh",
      "p4    5  p6pf   ",
      "p        p Df   ",
      "p        7 Df   ",
      "p8   8pppp Df   ",
      "p     p9   @f   ",
      "p#    p     f   ",
      "p$    p     f   ",
      "p     p%   ^f   ",
      "ffV VfffVVVff   ",
      "f     h         ",
      "      h         ",
      "      h         ",
      "                "
    ],
    [
      "      &  p  l   ",
      "fffffff  p  f   ",
      "p        p *fhhh",
      "p        pppf   ",
      "p        p !f   ",
      "p        p  f   ",
      "p     pppp  f   ",
      "p     p     f   ",
      "p     p     f   ",
      "p     p     f   ",
      "p     p     f   ",
      "ffVVVfffVVVff   ",
      "f     h         ",
      "      h         ",
      "      h         ",
      "                "
    ],
    [
      "      f  p  f   ",
      "fffffff  p  f   ",
      "p        p  fhhh",
      "p        pppf(  ",
      "p        p  f(  ",
      "p        p  f(  ",
      "p     pppp  f(  ",
      "p     p     f(  ",
      "p     p     f(  ",
      "p     p     f(  ",
      "p     p     f(  ",
      "fffffffffffff(  ",
      "f     h(((((((  ",
      "      h         ",
      "      h         ",
      "                "
    ],
    [
      "      f)))))f   ",
      "fffffff)))))f   ",
      "))))))))))))fhhh",
      "))))))))))))f+  ",
      "))))))))))))f+  ",
      "))))))))))))f+  ",
      "))))))))))))f+  ",
      "))))))))))))f+  ",
      "))))))))))))f+  ",
      "))))))))))))f+  ",
      "))))))))))))f+  ",
      "fffffffffffff+  ",
      "f     h+++++++  ",
      "------h         ",
      "      h         ",
      "                "
    ]
  ]
}