{
  "name": "multi_megatower1_1_floor1",
  "refpalette": "c70cities:multi_megatower1_1_floor1_palette",
  "xsize": 16,
  "zsize": 16,
  "slices": [
    [
      "            ab  ",
      "            cb  ",
      "            cbde",
      "            cbff",
      "           ghibb",
      "            abbb",
      "            abbb",
      "            abbb",
      "            cbbb",
      "            cbbb",
      "            cbbb",
      "           ghibb",
      "            abbb",
      "            abbb",
      "            abbb",
      "            cbbb"
    ],
    [
      "            aj  ",
      "            cj  ",
      "            cj  ",
      "            cj  ",
      "           ghick",
      "            alm ",
      "            aln ",
      "            alop",
      "            clqp",
      "            cln ",
      "            clm ",
      "           ghir ",
      "            als ",
      "            alt ",
      "            alu ",
      "            clu "
    ],
    [
      "            aj  ",
      "            cj  ",
      "            cj  ",
      "            cj  ",
      "           ghicw",
      "            alx ",
      "            al  ",
      "            al  ",
      "            cl  ",
      "            cl  ",
      "            clx ",
      "           ghi  ",
      "            al  ",
      "            al  ",
      "            al  ",
      "            cl  "
    ],
    [
      "            aj  ",
      "            cj  ",
      "            cj  ",
      "            cj y",
      "           ghicc",
      "            alx ",
      "            al  ",
      "            al  ",
      "            cl  ",
      "            cl  ",
      "            clx ",
      "           ghiA ",
      "            al  ",
      "            al  ",
      "            al  ",
      "            cl  "
    ],
    [
      "             B  ",
      "             B  ",
      "             B  ",
      "             B  ",
      "             icc",
      "             C  ",
      "             D  ",
      "             C  ",
      "             D  ",
      "             C  ",
      "             D  ",
      "             iDC",
      "             C  ",
      "             D  ",
      "             C  ",
      "             D  "
    ],
    [
      "             EFF",
      "             EFF",
      "             EFF",
      "             EFF",
      "             iII",
      "             EJJ",
      "             EJJ",
      "             EJJ",
      "             EJJ",
      "             EJJ",
      "             EJJ",
      "             iII",
      "             EJJ",
      "             EJJ",
      "             EJJ",
      "             EJJ"
    ]
  ]
}