{
  "name": "multi_laboratory1_9_top",
  "refpalette": "c70cities:multi_laboratory1_9_top_palette",
  "xsize": 16,
  "zsize": 16,
  "slices": [
    [
      "aazbbccccccbbzaa",
      "aazzbbbccbbbzzaa",
      "aaazzzbbbbzzzaaa",
      "aaaaazzzzzzaaaaa",
      "aaaaaaaaaaaaaaaa",
      "aaaaaaaaaaaaaaaa",
      "aaaaaaaaaaaaaaaa",
      "aaaaaaaaaaaaaaaa",
      "aaaaaaaaaaaaaaaa",
      "aaaaaaaaaaaaaaaa",
      "dddddddddddddddd",
      "e    f    f    g",
      "e    h    h    g",
      "ijjjjjjjjjjjjjji",
      "                ",
      "                "
    ],
    [
      "  k             ",
      "   k        k   ",
      "    kl    l     ",
      "      kl  k     ",
      "                ",
      "                ",
      "                ",
      "                ",
      "  m   m  m   m  ",
      " no  no  on  on ",
      "pppppppppppppppp",
      "                ",
      "                ",
      "jjjjjjjjjjjjjjjj",
      "                ",
      "                "
    ],
    [
      "                ",
      "                ",
      "                ",
      "                ",
      "                ",
      "                ",
      "                ",
      "                ",
      "                ",
      " n   n    n   n ",
      "                ",
      "                ",
      "                ",
      "jjjjjjjijjjjjjjj",
      "                ",
      "                "
    ],
    [
      "                ",
      "                ",
      "                ",
      "                ",
      "                ",
      "                ",
      "                ",
      "                ",
      "                ",
      " q   r    q   q ",
      "                ",
      "                ",
      "                ",
      "jjjjjjjjjjjjjjjj",
      "                ",
      "                "
    ],
    [
      "                ",
      "                ",
      "                ",
      "                ",
      "                ",
      "                ",
      "                ",
      "                ",
      "sts sts  sts sts",
      "tut tut  tut tut",
      "sts sts  sts sts",
      "                ",
      "                ",
      "jjjjjjjjjjjjjjjj",
      "                ",
      "                "
    ],
    [
      "                ",
      "                ",
      "                ",
      "                ",
      "                ",
      "                ",
      "                ",
      "                ",
      "                ",
      "                ",
      "                ",
      "                ",
      "                ",
      "                ",
      "                ",
      "                "
    ]
  ]
}