{
  "name": "multi_convenientstore_3_ground",
  "refpalette": "c70cities:multi_convenientstore_3_ground_palette",
  "xsize": 16,
  "zsize": 16,
  "slices": [
    [
      "aaaaaaaaaaaaHHHb",
      "cccccccccccaHHHb",
      "cccccccccccaHHHb",
      "cccccccccccaHHHb",
      "cccccccccccaHHHb",
      "cccccccccccaHHHb",
      "cccccccccccaHHHb",
      "cccccccccccaHHHb",
      "cccccccccccaHHHb",
      "cccccccccccaHHHb",
      "cccccccccccaHHHb",
      "cccccccccccaHHHb",
      "aaaaaaaaaaaaHHHb",
      "HHHHHHHHHHHHHHHb",
      "HHHHHHHHHHHHHHHb",
      "bbbbbbbbbbbbbbbb"
    ],
    [
      "aaaaaaaaaaaaddde",
      "cccccccccccaddde",
      "cccccccccccaddde",
      "cccccccccccaddde",
      "cccccccccccaHHHb",
      "cccccccccccaHHHb",
      "cccccccccccaHHHb",
      "cccccccccccaHHHb",
      "cccccccccccaHHHb",
      "cccccccccccaHHHb",
      "cccccccccccaHHHb",
      "cccccccc!ccaHHHb",
      "aaaaaaaaaaaaHHHb",
      "HHHHHHHHHHHHHHHb",
      "HHHHHHHHHHHHHHHb",
      "HHHHHHHHHHHHHHHb"
    ],
    [
      "fghhhhhiiiij    ",
      "       k  lj    ",
      "       k  mj    ",
      "       k  nj   e",
      "  oppp k qnj   e",
      "  r    s  nj   e",
      " t     uwxwj   e",
      "  yyyyyu       e",
      "  ABBCCy       e",
      "     DEk       e",
      "F    I k  Jj   e",
      " K!FKDLkMNNj   e",
      "jjjjjjjjjjjj   e",
      "  O   OM M     e",
      "               e",
      "               e"
    ],
    [
      "Pghhhhhiihij    ",
      "       k  Qj    ",
      "       k   j    ",
      "       k   h    ",
      "   RS  k   h    ",
      "  T    UV  h    ",
      " tW   XuwYwj    ",
      "  ZZZ 0u   1    ",
      "   A2CCy   1    ",
      "     D k   1    ",
      "     3 k   j    ",
      " 4556D k  7j    ",
      "jjjjjjjjjjjj    ",
      "  8  M8M        ",
      "                ",
      "                "
    ],
    [
      "gghhhhhiihij    ",
      "       k   j    ",
      "       k   j    ",
      "       k   h    ",
      "       k   h    ",
      "       k   h    ",
      " t45556uwwwj    ",
      "  ZZZ99u   1    ",
      "    ACCy   1    ",
      "     D k   1    ",
      "     D@k   j    ",
      "  #F$D kM  j    ",
      "jjjjjjjjjjjj    ",
      "88%888%         ",
      "                ",
      "                "
    ],
    [
      "hhhhhhhiihij    ",
      "       k   j    ",
      "       k   j    ",
      "       k  ^j    ",
      "       k  ^j    ",
      "       k  ^j    ",
      "&*(((((uwwwj    ",
      ") iiiiiuM  c    ",
      ")    +Cy   c    ",
      "     CCy   c    ",
      "     CCyM Mj    ",
      "-88-88-8888j    ",
      "jjjjjjjjjjjj    ",
      "     M8         ",
      "                ",
      "                "
    ]
  ]
}