{
  "name": "multi_laboratory1_3_base1",
  "refpalette": "c70cities:multi_laboratory1_3_base1_palette",
  "xsize": 16,
  "zsize": 16,
  "slices": [
    [
      "vabccccccccccccc",
      "vabccccccccccccc",
      "vabccccccccdcccc",
      "vabcccccccccceee",
      "vabcccccccccceee",
      "vabcccccccccceee",
      "vabcccccccccceee",
      "vabcccccccccceee",
      "vabccccccccccc!c",
      "vabccccccccdcccc",
      "vabccccccccccccc",
      "vabccccccccccccc",
      "vabccccccccccccc",
      "vabccccccccccccc",
      "vabccccccccccccc",
      "vabccccccccccccc"
    ],
    [
      "vabf       g    ",
      "vab   hhii g    ",
      "vabjjjjjjjjdklll",
      "vabm  noppqjl   ",
      "vabm  rpsoqjt   ",
      "vabuw rxxxqjl y ",
      "vabA       jlBB ",
      "vabf C     jl y ",
      "vabjiiD EFEjkllI",
      "vabjjjjJjjjdjjjj",
      "vabf     KKL BBy",
      "vabfw      L y  ",
      "vabf  w w  L    ",
      "vabA  DMD  L    ",
      "vabf  NON  L    ",
      "vabu  P P  L    "
    ],
    [
      "vabQ       g    ",
      "vab     RS g    ",
      "vabjjjjjjjjdT   ",
      "vab   U    L    ",
      "vab        L    ",
      "vabV       L    ",
      "vabW       L    ",
      "vabX       L    ",
      "vabjYZ0  F LT   ",
      "vabjjjj1jjjdj222",
      "vabV    3  L  4 ",
      "vabX       L    ",
      "vab0       L    ",
      "vab        L    ",
      "vab5   6   L    ",
      "vabV       L    "
    ],
    [
      "vabF       g    ",
      "vabF       g    ",
      "vabjjjjjjjjdT   ",
      "vab7  n    L    ",
      "vab7       L    ",
      "vab8       L    ",
      "vab        L    ",
      "vab5       L    ",
      "vab7    777LT   ",
      "vabjjjjjjjjdj999",
      "vab!       L    ",
      "vabS       L    ",
      "vab        L    ",
      "vab        L    ",
      "vab        L    ",
      "vab@       L    "
    ],
    [
      "vab        g    ",
      "vab        g    ",
      "vabjjjjjjjjd    ",
      "vab   n    L    ",
      "vab        L    ",
      "vab        L    ",
      "vab        L    ",
      "vab        L    ",
      "vab        L    ",
      "vabjjjjjjjjdj###",
      "vab        L    ",
      "vab        L    ",
      "vab        L    ",
      "vab        L    ",
      "vab        L    ",
      "vab        L    "
    ],
    [
      "vab$$%$$$^$&$$$$",
      "vab$$$$$$$$&$$$$",
      "vab***jjjjjd****",
      "vab$$$n$$$$&$$$$",
      "vab$$^$$$^$&$$$$",
      "vab$$%$$$^$&$$$$",
      "vab$$^$$$^$&$$$$",
      "vab$$^$$$^$&$$$$",
      "vab$$$$$$$$&$$$$",
      "vab***jjjjjdjjjj",
      "vab$$$$$$$$&$$$$",
      "vab$$^$$$^$&$$$$",
      "vab$$^$$$^$&$$$$",
      "vab$$^$$$^$&$$$$",
      "vab$$^$$$^$&$$$$",
      "vab$$$$$$$$&$$$$"
    ]
  ]
}