{
  "name": "multi_factory_0_ground",
  "refpalette": "c70cities:multi_factory_0_ground_palette",
  "xsize": 16,
  "zsize": 16,
  "slices": [
    [
      "zaazzzzzzzzzzzzz",
      "aaazzzzzzzzzzzzz",
      "aazbbbbbbbbbbbzz",
      "aaabbbbbbbbbbbzz",
      "aaabbbbbbbbbbbzz",
      "zaabbbbbbbbbbbzz",
      "zaabbbbbbbbbbbzz",
      "aaabbbbbbbbbbbzz",
      "zaabbbbbbbbbbbzz",
      "aaabbbbbbbbbbbzz",
      "aaabbbbbbbbbbbzz",
      "aaabbbbbbbbbbbzz",
      "zaabbbbbbbbbbbzz",
      "aaabbbbbbbbbbbzz",
      "zaabbbbbbbbbbbzz",
      "aaabbbbbbbbbbbzz"
    ],
    [
      "                ",
      "                ",
      "   ccccccccccc  ",
      "   cdeffdgh dc  ",
      "   ij    k  lc  ",
      "   c     mnnnc  ",
      "   co    p  lc  ",
      "   coq   gr  c  ",
      "   co    ssssc  ",
      "   co t     uc  ",
      "   c wxxye j c  ",
      "   cmmmmmmmAmc  ",
      "   cBBddC C Cc  ",
      "             c  ",
      "             c  ",
      "     ddd    Dc  "
    ],
    [
      "                ",
      "                ",
      "   ccccccccccc  ",
      "   cd ffdg  dc  ",
      "   E     F  Ic  ",
      "   c     mnnnc  ",
      "   JK    L  Ic  ",
      "   JM    g   c  ",
      "   JM    ssssc  ",
      "   J        uc  ",
      "   c   N     c  ",
      "   cmJJJJmmOmc  ",
      "   cd        c  ",
      "             c  ",
      "             c  ",
      "      PPP   Dc  "
    ],
    [
      "                ",
      "                ",
      "   ccQRScQRScc  ",
      "   cd   dg  dc  ",
      "   J     g   c  ",
      "   c     mnnnc  ",
      "   J     g   c  ",
      "   J     g   c  ",
      "   J     ssssc  ",
      "   J        uc  ",
      "   c         c  ",
      "   cmJJJJmmmmc  ",
      "   c         c  ",
      "   T         c  ",
      "   T         c  ",
      "   T  UUU   Dc  "
    ],
    [
      "                ",
      "                ",
      "   ccccccccccc  ",
      "   cd   dg  dc  ",
      "  Vc     g   c  ",
      "  Vc     mnnnc  ",
      "  Vc     g   c  ",
      "  Vc     g   c  ",
      "  Vc     ssssc  ",
      "  Vc        uc  ",
      "   c         c  ",
      "   cmmmmmmmmmc  ",
      "   c         c  ",
      "  VcW        c  ",
      "  VcW        c  ",
      "  VcW        c  "
    ],
    [
      "                ",
      "                ",
      "   ccccccccccc  ",
      "   cd   dbbbdc  ",
      "   c    Xbbbbc  ",
      "   c    Xbbbbc  ",
      "   c    Xbbbbc  ",
      "   c    Xbbbbc  ",
      "   c    Xbbbbc  ",
      "   c    Xbbbuc  ",
      "   c    Xbbbbc  ",
      "   cmmmmmmmmmc  ",
      "   c        Cc  ",
      "   c         c  ",
      "   c         c  ",
      "   c         c  "
    ]
  ]
}