{
  "name": "multi_gasstation_0_ground",
  "refpalette": "c70cities:multi_gasstation_0_ground_palette",
  "xsize": 16,
  "zsize": 16,
  "slices": [
    [
      "GGGGGGGGGGGGGGGG",
      "HHHHHHHHHHHHHaGG",
      "HHHHHHHHHHHHHaGG",
      "HHHHHHHHHHHHHaGG",
      "bHHHHHHHHHHHHaGG",
      "bHHHHHHHHHHHHaGG",
      "HHHHHHHHHHHHHaGG",
      "HHHHbHHbbbbbbbGG",
      "HHHHbHHbbbbbbbGG",
      "HHHHbHHbbbbbbbGG",
      "HHHHbHHbbbbbbbGG",
      "HHHHbHHbbbbbbbGG",
      "HHHHbHHbbbbbbbGG",
      "HHHHbHHbbbbbbbGG",
      "HHHHbHHbbbbbbbGG",
      "HHHHbHHbbbbbbbGG"
    ],
    [
      "                ",
      "             c  ",
      "             c  ",
      "             c  ",
      "d      efefefc  ",
      "g            c  ",
      " g     hihihic  ",
      "    j  kkkkkkk  ",
      "  lmn  k okp k  ",
      "       k qkr k  ",
      "  stj  kukkkwk  ",
      "  lmc  k xxx k  ",
      "       k     k  ",
      "  stj  k     k  ",
      "  lmc  kkykkkk  ",
      "       AB CCDk  "
    ],
    [
      "                ",
      "                ",
      "                ",
      "                ",
      "g               ",
      "d               ",
      "                ",
      "    j  kkkkkkk  ",
      "    E  k  k  k  ",
      "       k  k  k  ",
      "    j  kFkkkIk  ",
      "       k     k  ",
      "       k     k  ",
      "    j  k     k  ",
      "       kkJkkkk  ",
      "       A    Kk  "
    ],
    [
      "                ",
      "                ",
      "                ",
      "                ",
      "g               ",
      "                ",
      "                ",
      "    j  LLLLLLL  ",
      "       M  L  M  ",
      "       M  L  M  ",
      "    j  LLLLLLL  ",
      "       L     L  ",
      "       M     M  ",
      "    j  M     M  ",
      "       LLLLLLL  ",
      "       L  NOPM  "
    ],
    [
      "                ",
      "                ",
      "                ",
      "                ",
      "                ",
      "                ",
      "                ",
      "    kQ kkkkkkk  ",
      "       kRRkRRk  ",
      "       kRRkRRk  ",
      "    kS kkkkkkk  ",
      "       kRRRRRk  ",
      "       kRRRRRk  ",
      "    kQ kRRSRRk  ",
      "       kkkkkkk  ",
      "       k  T Uk  "
    ],
    [
      "                ",
      "                ",
      "                ",
      "                ",
      "                ",
      "                ",
      " VVVVVVVVVVVVVV ",
      " VccbbbbbbbbbbV ",
      " VccbccccccccbV ",
      " VccbccccccccbV ",
      " VccbccccccccbV ",
      " VccbccccccccbV ",
      " VccbccccccccbV ",
      " VccbccccccccbV ",
      " VccbbbbbbbbbbV ",
      " VccbccccccccbV "
    ]
  ]
}