{
  "name": "multi_flatapartment_0_ground",
  "refpalette": "c70cities:multi_flatapartment_0_ground_palette",
  "xsize": 16,
  "zsize": 16,
  "slices": [
    [
      "GGGGGGGGGGGGGGGa",
      "HHHHHaaaaaaaaaaa",
      "HHHHHaaaaaaaaaaa",
      "HHHHHaaaaaaaaaaa",
      "HHHHHaaaaaaaaaaa",
      "HHHHHaaaaaaaaaaa",
      "HHHHHaaaaaaaaaaa",
      "HHHHHaaaaaaaaaaa",
      "HHHHHaaaaaaaaaaa",
      "HHHHHaaaaaaaaaaa",
      "HHHHHaaaaaaaaaaa",
      "HHHHHaaaaaaaaaaa",
      "HHHHHaaaaaaaaaaa",
      "HHHHHaaaaaaaaaaa",
      "HHHHHaaaaaaaaaaa",
      "GGGGGGGGGGGGGGGa"
    ],
    [
      "     bbbbbbbbbb ",
      "  c deffffefffe ",
      "  g hcd         ",
      "  c d           ",
      "  g hgh    c d  ",
      "  c de    eg he ",
      "  gi cd  c djc d",
      "  c d    g hjg h",
      "  g h    c djc d",
      "  c dgh  g hjg h",
      "  g he    ec de ",
      "  c dcd    g h  ",
      "  g h           ",
      "  c dgh         ",
      "  g hekkkkekkke ",
      "l    bbbbbbbbbb "
    ],
    [
      "                ",
      "     m    m   m ",
      "                ",
      "                ",
      "                ",
      "     m    m   m ",
      "                ",
      "                ",
      "                ",
      "                ",
      "     m    m   m ",
      "                ",
      "                ",
      "                ",
      "     m    m   m ",
      "n               "
    ],
    [
      "                ",
      "     mo  omo omo",
      "     o          ",
      "                ",
      "     o          ",
      "     m    m   m ",
      "     o          ",
      "                ",
      "                ",
      "     o          ",
      "     m    m   m ",
      "     o          ",
      "                ",
      "     o          ",
      "     mo  omo omo",
      "p               "
    ],
    [
      "                ",
      "     m qq m q m ",
      "          r   r ",
      "     q          ",
      "                ",
      "     mr   m   m ",
      "                ",
      "     q          ",
      "     q          ",
      "                ",
      "     mr   m   m ",
      "                ",
      "     q          ",
      "          r   r ",
      "     m qq m q m ",
      "                "
    ],
    [
      "                ",
      "     qqqqqqqqqqq",
      "     qaaaaaaaaaa",
      "     qa   a   a ",
      "     qa   a   a ",
      "     qaaaaaaaaaa",
      "     qa   a   a ",
      "     qa   a   a ",
      "     qa   a   a ",
      "     qa   a   a ",
      "     qaaaaaaaaaa",
      "     qa   a   a ",
      "     qa   a   a ",
      "     qaaaaaaaaaa",
      "     qqqqqqqqqqq",
      "                "
    ]
  ]
}