{
  "name": "multi_laboratory1_7_base6",
  "refpalette": "c70cities:multi_laboratory1_7_base6_palette",
  "xsize": 16,
  "zsize": 16,
  "slices": [
    [
      "                ",
      "                ",
      "                ",
      "                ",
      "                ",
      "a              a",
      "a              a",
      "ab            ba",
      "caaa        aaac",
      "cccaab    baaccc",
      "cccccaaaaaacc!cc",
      "cccccccccccccccc",
      "cccccccddccccccc",
      "cccccccccccccccc",
      "cccccccddccccccc",
      "cccccccccccccccc"
    ],
    [
      "                ",
      "                ",
      "                ",
      "                ",
      "                ",
      "e              e",
      "e              e",
      "eb            be",
      " eee        eee ",
      "   eeb    beefg ",
      "     eeeeeeh i  ",
      "                ",
      "jjk           jj",
      "l           m n ",
      "             o  ",
      "              p "
    ],
    [
      "                ",
      "                ",
      "                ",
      "                ",
      "                ",
      "e              e",
      "e              e",
      "eb            be",
      " eee        eee ",
      "   eeb    bee   ",
      "     eeeeee     ",
      "                ",
      "qrs            q",
      "                ",
      "                ",
      "                "
    ],
    [
      "                ",
      "                ",
      "                ",
      "!tuuw           ",
      "                ",
      "e              e",
      "e              e",
      "eb            be",
      " eee        eee ",
      "   eeb    bee   ",
      "     eeeeee     ",
      "                ",
      "                ",
      "                ",
      "                ",
      "                "
    ],
    [
      "                ",
      "                ",
      "                ",
      " x              ",
      "                ",
      "e              e",
      "e              e",
      "eb            be",
      " eee        eee ",
      "   eeb    bee   ",
      "     eeeeee     ",
      "                ",
      "                ",
      "                ",
      "                ",
      "                "
    ],
    [
      "                ",
      "                ",
      "                ",
      " y              ",
      "                ",
      "e              e",
      "e              e",
      "eb            be",
      " eee        eee ",
      "   eeb    bee   ",
      "     eeeeee     ",
      "                ",
      "                ",
      "                ",
      "                ",
      "                "
    ]
  ]
}