{
  "name": "multi_laboratory1_10_base2",
  "refpalette": "c70cities:multi_laboratory1_10_base2_palette",
  "xsize": 16,
  "zsize": 16,
  "slices": [
    [
      "zzzzzzzzzzzzzzzz",
      "aaaaaaaaaaaaaaaz",
      "bbbbbbbbbbbbbcaz",
      "    d========caz",
      "  e d========caz",
      "ddddd========caz",
      "    d========caz",
      "    d========caz",
      "    d========caz",
      "    d========caz",
      "    d========caz",
      " f  d========caz",
      " fggd========caz",
      "hhhhd========caz",
      "hhhhd========caz",
      "dddddiiiiiiiicaz"
    ],
    [
      "zzzzzzzzzzzzzzzz",
      "aaaaaaaaaaaaaaaz",
      "bbbbbbbbbbbbbcaz",
      "  jklmnooo pqbaz",
      "   klr      sbaz",
      "lllldtu     !baz",
      "    lw      qbaz",
      "    lx yyy  sbaz",
      "    lx ABA  wbaz",
      "    lC ABA pqbaz",
      "    lD ABA  Ebaz",
      "hh  lF BsB Cwbaz",
      "ggI l   J    baz",
      "    l       Kbaz",
      "    L       Kbaz",
      "Mllldllllllllcaz"
    ],
    [
      "zzzzzzzzzzzzzzzz",
      "aaaaaaaaaaaaaaaz",
      "bbbbbbbbbbbbbcaz",
      " j  l      pqbaz",
      "    l       Ebaz",
      "lllldt      wbaz",
      "    lw     pqbaz",
      "    lw yyy  sbaz",
      "    l  NNN  wbaz",
      "hh  l  NNO  qbaz",
      "ggI l  NNN  sbaz",
      "  I l  sss  wbaz",
      "    l   P    baz",
      "    l        baz",
      "    Q       Rbaz",
      "Sllldllllllllcaz"
    ],
    [
      "zzzzzzzzzzzzzzzz",
      "aaaaaaaaaaaaaaaz",
      "bbbbbbbbbbbbbcaz",
      "j   l       tbaz",
      "    l       sbaz",
      "lllldt      wbaz",
      "hhhhlw      tbaz",
      "hhhhl  yyy  sbaz",
      "ggI l   N   wbaz",
      "  I l  NNN  tbaz",
      "    l   N   sbaz",
      "    l       wbaz",
      "    l        baz",
      "    l        baz",
      "T   l       Ubaz",
      "Vllldllllllllcaz"
    ],
    [
      "zzzzzzzzzzzzzzzz",
      "aaaaaaaaaaaaaaaz",
      "bbbbbbbbbbbbbcaz",
      "    lt      Wbaz",
      "e   lt      tbaz",
      "lllldt      tbaz",
      "    lt      Wbaz",
      "    lXY     tbaz",
      " fgglXY     tbaz",
      "  hhlXY     Wbaz",
      "    lXY     tbaz",
      "    lt      tbaz",
      "    lttttttttbaz",
      "    l       tbaz",
      "    l       tbaz",
      "lllldllllllllcaz"
    ],
    [
      "zzzzzzzzzzzzzzzz",
      "aaaaaaaaaaaaaaaz",
      "bbbbbbbbbbbbbcaz",
      "    lZZZZZZZZbaz",
      " e  lZZZZZZZZbaz",
      "lllldZZZZZZZZbaz",
      "    lZZZZZZZZbaz",
      "    lZZZZZZZZbaz",
      "    lZZZZZZZZbaz",
      " f  lZZZZZZZZbaz",
      " fgglZZZZZZZZbaz",
      "  hhlZZZZZZZZbaz",
      "    lZZZZZZZZbaz",
      "    lZZZZZZZZbaz",
      "    lZZZZZZZZbaz",
      "lllldllllllllcaz"
    ]
  ]
}