{
  "name": "multi_cafe_1_ground",
  "refpalette": "c70cities:multi_cafe_1_ground_palette",
  "xsize": 16,
  "zsize": 16,
  "slices": [
    [
      "GGaabccccccccccc",
      "GGaabcccccccbccc",
      "GGaabcccccccbccc",
      "GGaabcccccccGccc",
      "GGaabcccccccGccc",
      "GGaabcccccccGccc",
      "GGaabcccccccbccc",
      "GGaabcccccccGccc",
      "GGaabcccccccGccc",
      "GGaabcccccccGccc",
      "GGaabcccccccbccc",
      "GGaabbbbbbbbbbbb",
      "GGaaaaaaaaaaaaaa",
      "GGaaaaaaaaaaaaaa",
      "GGGGGGGGGGGGGGGG",
      "GGGGGGGGGGGGGGGG"
    ],
    [
      "    deeeed      ",
      "f   deeeed  g   ",
      " f  heeeed  g   ",
      "ij  keeeed  l mn",
      " f  keeeed  o   ",
      "jp  keeeed  l   ",
      "qf  beeeed  g mn",
      "rj  keeeed      ",
      " j  keeeed  o   ",
      "p   keeeed  l mn",
      "qj  keeeed  g   ",
      "i   bssssbttgttt",
      "rp              ",
      "jq              ",
      "f  rj rfqri q j ",
      " jqj qj j p jfpf"
    ],
    [
      "                ",
      "            g   ",
      "    u       g   ",
      "    tw w    x   ",
      "    tyyy    A   ",
      "    tB B    x   ",
      "    t       g   ",
      "    tw w        ",
      "    tyyy    A   ",
      "    tB B    x   ",
      "    t       g   ",
      "    ttttttt g   ",
      "                ",
      "                ",
      "                ",
      "                "
    ],
    [
      "                ",
      "            g   ",
      "            g   ",
      "                ",
      "                ",
      "                ",
      "            g   ",
      "                ",
      "                ",
      "                ",
      "            g   ",
      "            g   ",
      "                ",
      "                ",
      "                ",
      "                "
    ],
    [
      "                ",
      "            g   ",
      "            g   ",
      "                ",
      "                ",
      "                ",
      "            g   ",
      "                ",
      "                ",
      "                ",
      "            g   ",
      "            g   ",
      "                ",
      "                ",
      "                ",
      "                "
    ],
    [
      "                ",
      "            g   ",
      "            g   ",
      "                ",
      "                ",
      "                ",
      "            g   ",
      "                ",
      "                ",
      "                ",
      "            g   ",
      "            g   ",
      "                ",
      "                ",
      "                ",
      "                "
    ]
  ]
}