{
  "name": "multi_clubhouse1_8_base2",
  "refpalette": "c70cities:multi_clubhouse1_8_base2_palette",
  "xsize": 16,
  "zsize": 16,
  "slices": [
    [
      "vvvvvvvvvvvvvvvv",
      "vvvvvvvvvvvvvvvv",
      "vvvvvvvvvvvvvvvv",
      "aaaaaaaaavvvvvvv",
      "aaaaaaaaavvvvvvv",
      "aaaaaaaaavvvvvvv",
      "aaaaaaaaavvvvvvv",
      "aaaaaaaaavvvvvvv",
      "aaaaaaaaavvvvvvv",
      "vvvvvvvvvvvvvvvv",
      "vvvvvvvvvvvvvvvv",
      "vvvvvvvvvvvvvvvv",
      "vvvvvvvvvvvvvvvv",
      "vvvvvvvvvvvvvvvv",
      "vvvvvvvvvvvvvvvv",
      "vvvvvvvvvvvvvvvv"
    ],
    [
      "GbbbbbbbbbbcbGdv",
      "bbbbbbbbbbGcbGdv",
      "aaeaaaaaaecbbfgv",
      "hhihhiihiaccbGdv",
      "ihhhihhhiaccbGdv",
      "hhhhhhhhhacGbGdv",
      "hhhhhhhhiaccbGdv",
      "hhhhihhhhaccbGdv",
      "hihihhihiaGcbGdv",
      "aaeaaaaaaeccbjgv",
      "cccccGcbccccbGdv",
      "cGbcccGcccGbbGdv",
      "bbbbbbbbbbbbbGdv",
      "GGjGGGGGGfGGGGdv",
      "ddgddddddgdddddv",
      "vvvvvvvvvvvvvvvv"
    ],
    [
      "kl          mnov",
      "ll p p      qnov",
      "  e      e pm gv",
      "     r      m ov",
      "            snov",
      "   r   r    qnov",
      "r r         m ov",
      "            mnov",
      "r    r      qnov",
      "  e      e  m gv",
      "            qtov",
      "  p        psnov",
      "mqmmmsmsmqmmm ov",
      "nn n nnnn n nnov",
      "oogoooooogooooov",
      "vvvvvvvvvvvvvvvv"
    ],
    [
      "u            wov",
      "             wov",
      "  e      e    gv",
      "              ov",
      "             wov",
      "             wxv",
      "              ov",
      "             wov",
      "             wov",
      "  e      e    gv",
      "             yAv",
      "             wov",
      "              ov",
      "ww w wwww w wwov",
      "oxgooxooogooooov",
      "vvvvvvvvvvvvvvvv"
    ],
    [
      "              xv",
      "              ov",
      "  e      e    gv",
      "              ov",
      "              xv",
      "              xv",
      "              ov",
      "              ov",
      "              xv",
      "  e      e    gv",
      "              xv",
      "              ov",
      "              ov",
      "              ov",
      "oxgxooooogxoooov",
      "vvvvvvvvvvvvvvvv"
    ],
    [
      "              xv",
      "              ov",
      "  e      e    gv",
      "              ov",
      "              xv",
      "              xv",
      "              xv",
      "              ov",
      "              xv",
      "  e      e    gv",
      "              ov",
      "              ov",
      "              ov",
      "              ov",
      "oogxoooxogxoooov",
      "vvvvvvvvvvvvvvvv"
    ]
  ]
}