{
  "name": "multi_laboratory1_10_base1",
  "refpalette": "c70cities:multi_laboratory1_10_base1_palette",
  "xsize": 16,
  "zsize": 16,
  "slices": [
    [
      "zzzzzzzzzzzzzzzz",
      "aaaaaaaaaaaaaaaz",
      "bbbbbbbbbbbbbcaz",
      "    d========caz",
      "  e d========caz",
      "ddddd========caz",
      "    d========caz",
      "    d========caz",
      "    d========caz",
      "    d========caz",
      "    d========caz",
      " f  d========caz",
      " fggd========caz",
      "hhhhd========caz",
      "hhhhd========caz",
      "dddddiiiiiiiicaz"
    ],
    [
      "zzzzzzzzzzzzzzzz",
      "aaaaaaaaaaaaaaaz",
      "bbbbbbbbbbbbbcaz",
      "    jkkkkl mnbaz",
      "   opqlkk   rbaz",
      "ssssdtk     rbaz",
      "    sru    mnbaz",
      "    s!u     rbaz",
      "    su      rbaz",
      "    sw     mnbaz",
      "    sw      rbaz",
      "hh  sx      rbaz",
      "ggy s       Abaz",
      "    s       Bbaz",
      "    C    DE Bbaz",
      "Fsssdsssssssscaz"
    ],
    [
      "zzzzzzzzzzzzzzzz",
      "aaaaaaaaaaaaaaaz",
      "bbbbbbbbbbbbbcaz",
      "    jqkl   mnbaz",
      "    pIJ     rbaz",
      "ssssdt      rbaz",
      "    srr    mnbaz",
      "    s       rbaz",
      "    s       rbaz",
      "hh  s      mnbaz",
      "ggy s       rbaz",
      "  y s       rbaz",
      "    s        baz",
      "    s        baz",
      "    K        baz",
      "Lsssdsssssssscaz"
    ],
    [
      "zzzzzzzzzzzzzzzz",
      "aaaaaaaaaaaaaaaz",
      "bbbbbbbbbbbbbcaz",
      "    pI      tbaz",
      "    j       rbaz",
      "ssssdt      rbaz",
      "hhhhsr      tbaz",
      "hhhhs       rbaz",
      "ggy s       rbaz",
      "  y s       tbaz",
      "    s       rbaz",
      "    s       rbaz",
      "    s        baz",
      "    s        baz",
      "M   s        baz",
      "Nsssdsssssssscaz"
    ],
    [
      "zzzzzzzzzzzzzzzz",
      "aaaaaaaaaaaaaaaz",
      "bbbbbbbbbbbbbcaz",
      "    st      Obaz",
      "    st      tbaz",
      "ssssdt      tbaz",
      "    st      Obaz",
      "    sPQ     tbaz",
      " fggsPQ     tbaz",
      "  hhsPQ     Obaz",
      "    sPQ     tbaz",
      "    st      tbaz",
      "    sttttttttbaz",
      "    s       tbaz",
      "    s       tbaz",
      "ssssdsssssssscaz"
    ],
    [
      "zzzzzzzzzzzzzzzz",
      "aaaaaaaaaaaaaaaz",
      "bbbbbbbbbbbbbcaz",
      "RRRRsRRRRRRRRbaz",
      "RRRRsRRRRRRRRbaz",
      "ssssdRRRRRRRRbaz",
      "    sRRRRRRRRbaz",
      "    sRRRRRRRRbaz",
      "    sRRRRRRRRbaz",
      " f  sRRRRRRRRbaz",
      " fggsRRRRRRRRbaz",
      "  hhsRRRRRRRRbaz",
      "    sRRRRRRRRbaz",
      "    sRRRRRRRRbaz",
      "    sRRRRRRRRbaz",
      "ssssdsssssssscaz"
    ]
  ]
}