{
  "name": "multi_megatower1_3_floor3",
  "refpalette": "c70cities:multi_megatower1_3_floor3_palette",
  "xsize": 16,
  "zsize": 16,
  "slices": [
    [
      "                ",
      "                ",
      "                ",
      "                ",
      "                ",
      "                ",
      "                ",
      "                ",
      "                ",
      "                ",
      "                ",
      "    a      a    ",
      "bcccdbbbcccdbbbc",
      "eeeefeeeeeefeeee",
      "ghhheeeeeeeeeeee",
      "g   eeeeeeeeeeee"
    ],
    [
      "                ",
      "                ",
      "                ",
      "                ",
      "                ",
      "                ",
      "                ",
      "                ",
      "                ",
      "                ",
      "                ",
      "    a      a    ",
      "bcccdbbbcccdbbbc",
      "ijklfmmmmmmfmmmm",
      "ghhhg no  pqr  o",
      "g   gs   tuqwxy "
    ],
    [
      "                ",
      "                ",
      "                ",
      "                ",
      "                ",
      "                ",
      "                ",
      "                ",
      "                ",
      "                ",
      "                ",
      "    a      a    ",
      "bcccdbbbcccdbbbc",
      "i   fmAAAAmfmAAA",
      "ghhhg     BqC   ",
      "g   g      q    "
    ],
    [
      "                ",
      "                ",
      "                ",
      "                ",
      "                ",
      "                ",
      "                ",
      "                ",
      "                ",
      "                ",
      "                ",
      "    a      a    ",
      "bcccdbbbcccdbbbc",
      "i   fmDDDDmfmDDD",
      "ghhhg EFIJ q IJE",
      "g   g      q    "
    ],
    [
      "                ",
      "                ",
      "                ",
      "                ",
      "                ",
      "                ",
      "                ",
      "                ",
      "                ",
      "                ",
      "                ",
      "    a      a    ",
      "bcccdbbbcccdbbbc",
      "i   fmmmmmmfmmmm",
      "ghhhg      q    ",
      "g   g      q    "
    ],
    [
      "                ",
      "                ",
      "                ",
      "                ",
      "                ",
      "                ",
      "                ",
      "                ",
      "                ",
      "                ",
      "                ",
      "    a      a    ",
      "bcccdbbbcccdbbbc",
      "KKKKfKKKKKKfKKKK",
      "LMMML      L    ",
      "L   L      L    "
    ]
  ]
}