{
  "name": "multi_condo1_5_ground",
  "refpalette": "c70cities:multi_condo1_5_ground_palette",
  "xsize": 16,
  "zsize": 16,
  "slices": [
    [
      "aaaaaabHHHHHHHHH",
      "aaaaaabccbbbbGGG",
      "aaaaaabccb  bddd",
      "aaaaaab  e  baGG",
      "aaaaaab  e  baGG",
      "aaaaaab     bffG",
      "aaaaaab     bGGG",
      "aaaaaab     bGGG",
      "aaaaaab     bGGG",
      "aaaaaab     bGGG",
      "aaaaaab     bGGG",
      "aaaaaab     bGGG",
      "aaaaaab     bGGG",
      "bbbbbbbbbbbbbGGG",
      "GGGGGGGGGGGGGGGG",
      "GGGGGGGGGGGGGGGG"
    ],
    [
      "     gb         ",
      "hhhhhab  bbbb   ",
      "i    jb     bddd",
      "kkk  jb     b   ",
      "     jb     b   ",
      "lll  jb     bff ",
      "     gb     b   ",
      "kkk  mb     b n ",
      "     mb     b   ",
      "lll  mb     b n ",
      "     ob     b   ",
      "bbbbbbb     b n ",
      "ppppppb     b   ",
      "bbbbbbbbbbbbb n ",
      "                ",
      "                "
    ],
    [
      "     qb         ",
      "hhhhhab  bbbb   ",
      "      b     bddd",
      "rst   b     b   ",
      "      b     b   ",
      " ur   b     bff ",
      "     qb         ",
      "twt   b       q ",
      "      b         ",
      "txt   b       q ",
      "      b         ",
      "hhhhhhb       q ",
      "      b         ",
      "              q ",
      "                ",
      "                "
    ],
    [
      "      b         ",
      "hhhhhab  bbbb   ",
      "      b     bddd",
      "     yb     b   ",
      "      b     b   ",
      "  A  Bb     bff ",
      "      b         ",
      "C     b       D ",
      "      b         ",
      "  E   b       D ",
      "      b         ",
      "hhhhhhb       D ",
      "      b         ",
      "              D ",
      "                ",
      "                "
    ],
    [
      "      b     bF  ",
      "hhhhhabbbbbbb   ",
      "      b     bddd",
      "      b     b   ",
      "      b     b   ",
      "      b     bff ",
      "      b         ",
      "      b       D ",
      "      b         ",
      "      b       D ",
      "      b         ",
      "hhhhhhb       D ",
      "      b         ",
      "              D ",
      "                ",
      "                "
    ],
    [
      "      bIIIIIb   ",
      "hhhhhabbbbbbb   ",
      "      b     bddd",
      "      b     b   ",
      "      b     b   ",
      "      b     bff ",
      "      b         ",
      "      b       J ",
      "      b         ",
      "      b       J ",
      "      b         ",
      "hhhhhhb       J ",
      "      b         ",
      "              J ",
      "                ",
      "                "
    ]
  ]
}