{
  "name": "multi_laboratory1_0_base3",
  "refpalette": "c70cities:multi_laboratory1_0_base3_palette",
  "xsize": 16,
  "zsize": 16,
  "slices": [
    [
      "vvvvvvvvvvvvvvvv",
      "vaaaaaaaaaaaaaaa",
      "vabbbbbbbbbbcccc",
      "vabddeeedddf    ",
      "vabddeegeddf    ",
      "vabddddehidfffff",
      "vabdddg!eedjjjjj",
      "vabddddhdedjjjjj",
      "vabjjjeejjjfjjjj",
      "vabddeeddddjjjjj",
      "vabddkeddehejjjj",
      "vabdde!hehdjeejj",
      "vabddddehedjjejj",
      "vabddhdddddjjjjj",
      "vabddddddddjjjjj",
      "vabjjjjjjjjfjjjj"
    ],
    [
      "vvvvvvvvvvvvvvvv",
      "vaaaaaaaaaaaaaaa",
      "vabbbbbbbbbbcccc",
      "vablml!lhlmn    ",
      "vabl lelolpn    ",
      "vabqrqsp   nnnnn",
      "vab tp  su w  x ",
      "vabyyhpAByyn   C",
      "vabnne ennnf   D",
      "vabhh  EEFFnn  I",
      "vabeJ Apuu ee KI",
      "vab eu  J eLuAMI",
      "vabNONOeePOKp  I",
      "vab QAQ Q QnKt D",
      "vabRQhQRQRQn  p ",
      "vabnnnnnnnnf    "
    ],
    [
      "vvvvvvvvvvvvvvvv",
      "vaaaaaaaaaaaaaaa",
      "vabbbbbbbbbbcccc",
      "vabl lSlAl n    ",
      "vabl lul   n    ",
      "vabqT      nnnnn",
      "vab        U    ",
      "vabVW    W n    ",
      "vabnnS Jhnnf   X",
      "vabeY    YZL   0",
      "vabeu      t    ",
      "vab A   u 1    2",
      "vab3O3OAh4O    5",
      "vab Q Q Q Qn   X",
      "vab QSQ Q Qn    ",
      "vabnnnnnnnnf    "
    ],
    [
      "vvvvvvvvvvvvvvvv",
      "vaaaaaaaaaaaaaaa",
      "vabbbbbbbbbbcccc",
      "vabl lelSl n    ",
      "vabl l   l n    ",
      "vabqq  S  qnnnnn",
      "vab        n    ",
      "vab W   WW n    ",
      "vabnnh Jnnnf   Z",
      "vabuY6  YY 7    ",
      "vab             ",
      "vab S    S 7   8",
      "vabOOOOOOOOn   9",
      "vab Q Q Q Qn   Z",
      "vab Q@Q Q Qn    ",
      "vabnnnnnnnnf    "
    ],
    [
      "vvvvvvvvvvvvvvvv",
      "vaaaaaaaaaaaaaaa",
      "vabbbbbbbbbbcccc",
      "vab#$#e#h#$n    ",
      "vab####  ##n    ",
      "vab####@ ##nnnnn",
      "vab#####S##n    ",
      "vab########n    ",
      "vabnneennnnf    ",
      "vab##J#####n    ",
      "vab#S #####n    ",
      "vab#@####@#n    ",
      "vab######S#n    ",
      "vab########n    ",
      "vab$#h#$#$#n    ",
      "vabnnnnnnnnf    "
    ],
    [
      "vvvvvvvvvvvvvvvv",
      "vaaaaaaaaaaaaaaa",
      "vabbbbbbbbbbcccc",
      "vab % e e %n    ",
      "vab % eee %n    ",
      "vab % hhe %nnnnn",
      "vab % h e %n7777",
      "vab %%%%e%%n7777",
      "vabnnnnnnnnf7777",
      "vab%%h%%%%%n7777",
      "vab%he % % n7777",
      "vab%eh^%^e^n7777",
      "vab%&e^%^e^n7777",
      "vab%^%^%^%^n7777",
      "vab%^%^%^%^n7777",
      "vabnnnnnnnnf****"
    ]
  ]
}