{
  "name": "multi_condo1_4_floor5",
  "refpalette": "c70cities:multi_condo1_4_floor5_palette",
  "xsize": 16,
  "zsize": 16,
  "slices": [
    [
      "aaaaabcddeeefg  ",
      "hhhiabcffffffjj ",
      "   kabclllllfg  ",
      "   kabclllllfg  ",
      "   kabclllllfg  ",
      "   kabclllllfjj ",
      "   kabcffffffg  ",
      "   kabc     cg  ",
      "   kabc     cg  ",
      "   kabc     fg  ",
      "   kabm     fjj ",
      "   kabnffffffg  ",
      "   kabcck   fg  ",
      "   kabcco   fg  ",
      "pppqabcffffffjj ",
      "aaaaabcddeeefg  "
    ],
    [
      "      frrstuf   ",
      "wwww  fffffffjj ",
      "   w  x     f   ",
      "   w  f     y   ",
      "   w  f  AB f   ",
      "   w  f CDD fjj ",
      "   w  fffffff   ",
      "   w  f     E   ",
      "   w  F     E   ",
      "   w  I     f   ",
      "   w Jf     fjj ",
      "   w  fffffff   ",
      "   w  f     y   ",
      "   w  K Lo  f   ",
      "wwww  fffffffjj ",
      "      fMMsNOf   "
    ],
    [
      "      fPQs  f   ",
      "      fffffffjj ",
      "      R     f   ",
      "      fS    T   ",
      "      f  UV f   ",
      "      fWWDD fjj ",
      "      fffffff   ",
      "      f     E   ",
      "      X     E   ",
      "      Y     f   ",
      "      f     fjj ",
      "      fffffff   ",
      "      f     T   ",
      "      Z  Lo f   ",
      "      fffffffjj ",
      "      f01s  f   "
    ],
    [
      "      f23s  f   ",
      "      fffffffjj ",
      "      4     f   ",
      "      f     T   ",
      "      f     f   ",
      "      fW 55 fjj ",
      "      fffffff   ",
      "      f     E   ",
      "      4     E   ",
      "      4     f   ",
      "     6f     fjj ",
      "      fffffff   ",
      "      f   4oT   ",
      "      4   Lcf   ",
      "      fffffffjj ",
      "      f 7s  f   "
    ],
    [
      "      f  s  f   ",
      "      fffffffjj ",
      "      f     f   ",
      "      f     f   ",
      "      f     f   ",
      "      fW    fjj ",
      "      fffffff   ",
      "     8f     E   ",
      "      f     E   ",
      "      f     f   ",
      "     8f     fjj ",
      "      fffffff   ",
      "      f  4k f   ",
      "      f     f   ",
      "      fffffffjj ",
      "      f  s  f   "
    ],
    [
      "      flllllf   ",
      "      fffffffjj ",
      "      fW    f   ",
      "      fW  9 f   ",
      "      fW    f   ",
      "      fWWWWWfjj ",
      "      fffffff   ",
      "      f     E   ",
      "      f     E   ",
      "      f     f   ",
      "      f     fjj ",
      "      fffffff   ",
      "      f 4k  f   ",
      "      f     f   ",
      "      fffffffjj ",
      "      flllllf   "
    ]
  ]
}