{
  "name": "multi_laboratory1_6_base7",
  "refpalette": "c70cities:multi_laboratory1_6_base7_palette",
  "xsize": 16,
  "zsize": 16,
  "slices": [
    [
      "aaaaaaaaaaaaaabc",
      "aaaaaaaaaaaaaaca",
      "aaaaaaaaaaaaaaaa",
      "aaaaaaaaaaaaaaaa",
      "aaaaaaaaaaaaaaaa",
      "aaaaaaaaaaaaaaaa",
      "aaaaaaaaaaaaaaaa",
      "aaaaaddddddaaaaa",
      "aaadddaaaadddaaa",
      "adddaaaaaaaaddda",
      "ddaaaaaeaaaaaadd",
      "daaaaaaaaaaaaaad",
      "daaaaaaaaaaaaaad",
      "aaaaffffffffaaaa",
      "aaaafggggggfaaaa",
      "aaaafggggggfaaaa"
    ],
    [
      "aaaaaaaaaaaaaahi",
      "aaaaaaaaaaaaaajc",
      "aaaaaaaaaaaaaakc",
      "aaaaaaaaaaaaaala",
      "aaaaaaaaaaaaaama",
      "aaaaaaaaaaaaaaaa",
      "aaaaaaaaaaaaaaaa",
      "aaaaaaaaaaaaaaaa",
      "aaaaanoooonabaaa",
      "aaaaaoo   obaaaa",
      "anaaa     p bcna",
      "aaaa       qbeaa",
      "aaa r    q s baa",
      "bet uwwwwwwu xby",
      "aa AB      Bp yb",
      "aaC B      B Dbb"
    ],
    [
      "aaaaaaaaaaaaaaa ",
      "aaaaaaaaaaaaaaai",
      "aaaaaaaaaaaaaaac",
      "aaaaaaaaaaaaaaaa",
      "aaaaaaaaaaaaaaaa",
      "aaaaaaaaaaaaaaaa",
      "aaaaaaaaaaaaaaaa",
      "aaaaaaaaaaaaaaaa",
      "aaaaano  onaaaaa",
      "aaaa        aaaa",
      "anaa         Dna",
      "a!yp          ba",
      "aa           Dba",
      "a         E   Dy",
      "FIF            y",
      "at             y"
    ],
    [
      "aaaaaaaaaaaaaaaJ",
      "aaaaaaaaaaaaaaaJ",
      "aaaaaaaaaaaaaaaa",
      "aaaaaaaaaaaaaaaa",
      "aaaaaaaaaaaaaaaa",
      "aaaaaaaaaaaaaaaa",
      "aaaaaaaaaaaaaaaa",
      "aaaaaaaaaaaaaaaa",
      "aaaaan    naaaaa",
      "aaaa        aaaa",
      "ana           na",
      "K D           ba",
      "               a",
      "L             D ",
      " M             D",
      "                "
    ],
    [
      "aaaaaaaaaaaaaaaa",
      "aaaaaaaaaaaaaaaa",
      "aaaaaaaaaaaaaaaa",
      "aaaaaaaaaaaaaaaa",
      "aaaaaaaaaaaaaaaa",
      "aaaaaaaaaaaaaaaa",
      "aaaaaaaaaaaaaaaa",
      "aaaaabaaaaaaaaaa",
      "aaaaan    naaaaa",
      "aaaa        aaaa",
      "Kn~~~~~~~~~~~~na",
      "K~~~  ~~~~~~~~~a",
      " ~~~~~~~~~~~~~~a",
      " ~~~~~~~~~~~~~~ ",
      " ~~~~~~~~~~~~~~D",
      " ~~~~~~~~~~~~~~ "
    ],
    [
      "aaaaaaaaaaaaaaaa",
      "aaaaaaaaaaaaaaaa",
      "aaaaaaaaaaaaaaaa",
      "aaaaaaaaaaaaaaaa",
      "aaaaaaaaaaaaaaaa",
      "aaaaaaaaaaaaaaaa",
      "aaaaaaaaaaaaaaaa",
      "aaaaaaaaaaaaaaaa",
      "aaaaan    naaaaa",
      "aaaa        aaaa",
      "Kn~~~~~~~~~~~~na",
      "K~~~~~~~~~~~~~~a",
      " ~~~~~~~~~~~~~~a",
      " ~~~~~~~~~~~~~~ ",
      " ~~~~~~~~~~~~~~D",
      " ~~~~~~~~~~~~~~ "
    ]
  ]
}