{
  "name": "multi_laboratory1_11_floor1",
  "refpalette": "c70cities:multi_laboratory1_11_floor1_palette",
  "xsize": 16,
  "zsize": 16,
  "slices": [
    [
      "abzzcdde        ",
      "abzzcddf        ",
      "abzzcddf        ",
      "abzzcddf        ",
      "abzzcddf        ",
      "abzzcddf        ",
      "aabbcghf        ",
      "aaaacddf        ",
      "aaaacddf        ",
      "aaaacddf        ",
      " aaacddf        ",
      " aaacddf        ",
      " aaacddf        ",
      "  aacghf        ",
      "  aacd          ",
      "  aacd          "
    ],
    [
      " ijkl  m        ",
      " inkl  m        ",
      " ikol  m        ",
      " j nl  m        ",
      " pk l  m        ",
      " innl  m        ",
      "  iiq  m        ",
      "    l  r        ",
      "    l  m        ",
      "s   l  m        ",
      "ts  l  m        ",
      " s  l  r        ",
      " s  l  m        ",
      " ts q  m        ",
      "  s l  u        ",
      "  s l  w        "
    ],
    [
      "       r        ",
      "       x        ",
      "       x        ",
      "       r        ",
      "       r        ",
      "       x        ",
      "       r        ",
      "       x        ",
      "       x        ",
      "       x        ",
      "       x        ",
      "       x        ",
      "       x        ",
      "       r        ",
      "       w        ",
      "       w        "
    ],
    [
      "       x        ",
      "       x        ",
      "       x        ",
      "       r        ",
      "       x        ",
      "       x        ",
      "       x        ",
      "       x        ",
      "       r        ",
      "       x        ",
      "       x        ",
      "       x        ",
      "       x        ",
      "       x        ",
      "       w        ",
      "       w        "
    ],
    [
      "       x        ",
      "       x        ",
      "       x        ",
      "       x        ",
      "       x        ",
      "       x        ",
      "       x        ",
      "       y        ",
      "       y        ",
      "       y        ",
      "                ",
      "                ",
      "                ",
      "                ",
      "                ",
      "                "
    ],
    [
      "   ~   x        ",
      "       y        ",
      "       y        ",
      "       y        ",
      "                ",
      "                ",
      "                ",
      "                ",
      "                ",
      "                ",
      "                ",
      "                ",
      "                ",
      "                ",
      "                ",
      "                "
    ]
  ]
}