{
  "name": "multi_laboratory1_4_base5",
  "refpalette": "c70cities:multi_laboratory1_4_base5_palette",
  "xsize": 16,
  "zsize": 16,
  "slices": [
    [
      "zabbbba    ac   ",
      "zdbbbba    e    ",
      "zdbbbba    e    ",
      "zdbbbba    e    ",
      "zdbbbba    e    ",
      "zdbbbba    e    ",
      "zdbbbba    e    ",
      "zabbbba    ac   ",
      "zdbbbba    f    ",
      "zdbbbba    f    ",
      "zdbbbba    g    ",
      "zdbbbba    g    ",
      "zdbbbba    f    ",
      "zdbbbba    fdddd",
      "zdddddddddddhhhh",
      "zzzzzzzzzzzzzzzz"
    ],
    [
      "zaffffaii  a    ",
      "zdjjk fii  e    ",
      "zd l  fii  e    ",
      "zdm   fii  e    ",
      "zdnn  fii  e    ",
      "zdjj  fii  e    ",
      "zd l  fii  e    ",
      "zao   aii  a    ",
      "zdnn  fii  f    ",
      "zd    gii  f    ",
      "zd    pii  g    ",
      "zdm   qii  g    ",
      "zd  o gii  f    ",
      "zdnrrnfii  fdddd",
      "zdddddddddddhhhh",
      "zzzzzzzzzzzzzzzz"
    ],
    [
      "zaffffa    a    ",
      "zd s  f    e    ",
      "zd    e    e    ",
      "zd    e    e    ",
      "zdt   e    e    ",
      "zdus  e    e    ",
      "zd    f    e    ",
      "za    a    a    ",
      "zdk   f    f    ",
      "zd    g    f    ",
      "zd    w    g    ",
      "zd    x    g    ",
      "zd    g    f    ",
      "zd y Af    fdddd",
      "zdddddddddddhhhh",
      "zzzzzzzzzzzzzzzz"
    ],
    [
      "zaffffa    a    ",
      "zd    f    e    ",
      "zd    e    e    ",
      "zd    e    e    ",
      "zd    e    e    ",
      "zd    e    e    ",
      "zd    f    e    ",
      "za    a    a    ",
      "zd    f    f    ",
      "zd    g    f    ",
      "zd    g    g    ",
      "zd    g    g    ",
      "zd    g    f    ",
      "zd    f    fdddd",
      "zdddddddddddhhhh",
      "zzzzzzzzzzzzzzzz"
    ],
    [
      "zaffffa    a    ",
      "zd    f    f    ",
      "zd    f    f    ",
      "zd    f    f    ",
      "zd    f    f    ",
      "zd    f    f    ",
      "zd    f    f    ",
      "za    a    a    ",
      "zd    f    f    ",
      "zd    f    f    ",
      "zd    f    f    ",
      "zd    f    f    ",
      "zd    f    f    ",
      "zd    f    fdddd",
      "zdddddddddddhhhh",
      "zzzzzzzzzzzzzzzz"
    ],
    [
      "zaffffaBBBBfBBBB",
      "zdCCCCfBBBBfBBBB",
      "zdCDDCfBBBBfBBBB",
      "zdCCCCfBEEBfBBBB",
      "zdCCCCfBEEBfBBBB",
      "zdCDDCfBBBBfBBBB",
      "zdCCCCfBBBBfBBBB",
      "zaffffaBBBBfBBBB",
      "zdCCCCfBBBBfBBBB",
      "zdCDFCfBBBBfBBBB",
      "zdCCCCfBEIBfBBBB",
      "zdCCCCfBEIBfBBBB",
      "zdCDDCfBBBBfBBBB",
      "zdCCCCfBBBBfdddd",
      "zdddddddddddhhhh",
      "zzzzzzzzzzzzzzzz"
    ]
  ]
}