{
  "name": "multi_laboratory1_2_base1",
  "refpalette": "c70cities:multi_laboratory1_2_base1_palette",
  "xsize": 16,
  "zsize": 16,
  "slices": [
    [
      "zabcccccccccccd ",
      "zabcccccccccccd ",
      "zabcccccccccccd ",
      "zabcccccccccccde",
      "zabccccccccfcc!d",
      "zabccccccccccccd",
      "zabccccccccccccc",
      "zabccccccccccccc",
      "zabccccccccccccc",
      "zabccccccccccccc",
      "zabccccccccccccc",
      "zabccccccccfcccc",
      "zabccccccccccccc",
      "zabccccccccccccc",
      "zabccccccccccccc",
      "zabccccccccccccc"
    ],
    [
      "zabg      hi  j ",
      "zabk      hi  j ",
      "zabk    lmhi  j ",
      "zabnopo qrhi  js",
      "zabiiiitiiif  sj",
      "zabuuu l wwx   j",
      "zabuu      x  y ",
      "zabAABC C  x    ",
      "zabA  qDq  x    ",
      "zabEB FIF  x    ",
      "zabk  C C  x    ",
      "zabkJ      fs   ",
      "zabg  C C  K    ",
      "zabg  qrq  K    ",
      "zabL  FMF  N    ",
      "zabOC C C  K    "
    ],
    [
      "zabP       x  j ",
      "zab       Qx  j ",
      "zab        x  j ",
      "zab! p  RS x  js",
      "zabiiiiTiiif  Uj",
      "zab!uQ     x   j",
      "zabEl      x    ",
      "zabA       x    ",
      "zab   B    x    ",
      "zab     J  x    ",
      "zab        x    ",
      "zab        fU   ",
      "zabV       K    ",
      "zabW   Q   K    ",
      "zabX  l    Y    ",
      "zabZ       K    "
    ],
    [
      "zabA       x  j ",
      "zab        x  j ",
      "zab        x  j ",
      "zab0122    x  js",
      "zabiiiiiiiif  Uj",
      "zabE     22x   j",
      "zab        x    ",
      "zab3       x    ",
      "zab        x    ",
      "zab        x    ",
      "zab        x    ",
      "zab        fU   ",
      "zab        K    ",
      "zab        K    ",
      "zab4       K    ",
      "zab5       K    "
    ],
    [
      "zab        x  j ",
      "zab        x  j ",
      "zab        x  j ",
      "zabn       x  js",
      "zabiiiiiiiif   j",
      "zab        x   j",
      "zab        x    ",
      "zab        x    ",
      "zab        x    ",
      "zab        x    ",
      "zab        x    ",
      "zab        f    ",
      "zab        K    ",
      "zab        K    ",
      "zab        K    ",
      "zab        K    "
    ],
    [
      "zab667666768669 ",
      "zab667666768669 ",
      "zab667666768669 ",
      "zabn66666668669@",
      "zabiiii#iiif6669",
      "zab6666666686669",
      "zab6676667686666",
      "zab6676667686666",
      "zab6676667686666",
      "zab6676667686666",
      "zab6666666686666",
      "zab66666666f6666",
      "zab6666666686666",
      "zab6676667686666",
      "zab6676667686666",
      "zab6676667686666"
    ]
  ]
}