{
  "name": "multi_laboratory1_4_base1",
  "refpalette": "c70cities:multi_laboratory1_4_base1_palette",
  "xsize": 16,
  "zsize": 16,
  "slices": [
    [
      "zabccccccccdcccc",
      "zabccccccccccccc",
      "zabccccccccccccc",
      "zabccccccccccccc",
      "zabccccccccccccc",
      "zabccccccccccccc",
      "zabccccccccccccc",
      "zabccccccccdcccc",
      "zabeeeeeeeeccccc",
      "zabeeeeeeeeccccc",
      "zabeeeeeeeeccccc",
      "zabeeeeeeeeccccc",
      "zabeeeeeeeeccccc",
      "zabbbbbbbbbbbbbb",
      "zaaaaaaaaaaaaaaa",
      "zzzzzzzzzzzzzzzz"
    ],
    [
      "zabfg      d    ",
      "zabf  h h  i    ",
      "zabj  klk  i    ",
      "zabm  non  p    ",
      "zabj  h h  i    ",
      "zabfg      i    ",
      "zabf  qqrssi    ",
      "zabttttttttd   u",
      "zabwwxxxxwwt   y",
      "zab        A   y",
      "zabBCDCBCBCt   y",
      "zab E E E Et   y",
      "zabFEFEFEFEtuyy!",
      "zabbbbbbbbbbbbbb",
      "zaaaaaaaaaaaaaaa",
      "zzzzzzzzzzzzzzzz"
    ],
    [
      "zabI       d    ",
      "zabJ       i    ",
      "zabK  L    i    ",
      "zab     M  N    ",
      "zabO       i    ",
      "zabP       i    ",
      "zabI       i    ",
      "zabttttttttd   Q",
      "zabR S SSSRt   T",
      "zab        U    ",
      "zabVCWCVCVCt    ",
      "zab E E E Et    ",
      "zab E E E EtQXYQ",
      "zabbbbbbbbbbbbbb",
      "zaaaaaaaaaaaaaaa",
      "zzzzzzzzzzzzzzzz"
    ],
    [
      "zab        d    ",
      "zab        Z    ",
      "zab        i    ",
      "zab        i    ",
      "zab        i    ",
      "zab0       i    ",
      "zab0       i    ",
      "zabttttttttd   R",
      "zab S SSSS t    ",
      "zab        t    ",
      "zabCCCCCCCCt    ",
      "zab E E E Et    ",
      "zab E E E EtR 1R",
      "zabbbbbbbbbbbbbb",
      "zaaaaaaaaaaaaaaa",
      "zzzzzzzzzzzzzzzz"
    ],
    [
      "zab        d    ",
      "zab        i    ",
      "zab        i    ",
      "zab        Z    ",
      "zab        Z    ",
      "zab        Z    ",
      "zab        Z    ",
      "zabttttttttd    ",
      "zab222 2222t    ",
      "zab2 222222t    ",
      "zab32222222t    ",
      "zab22222222t    ",
      "zab42424242t    ",
      "zabbbbbbbbbbbbbb",
      "zaaaaaaaaaaaaaaa",
      "zzzzzzzzzzzzzzzz"
    ],
    [
      "zab55555555d5555",
      "zab5555555565555",
      "zab5575558565555",
      "zab5575557565555",
      "zab5575557565555",
      "zab5575557565555",
      "zab5555555565555",
      "zab99999999d5555",
      "zab@@@@@@@@95555",
      "zab@ @ @ @ 95555",
      "zab@ @ @ @ 95555",
      "zab@!@ @ @ 95555",
      "zab@ @ @ @ 95555",
      "zabbbbbbbbbbbbbb",
      "zaaaaaaaaaaaaaaa",
      "zzzzzzzzzzzzzzzz"
    ]
  ]
}