{
  "name": "multi_condo1_3_floor1",
  "refpalette": "c70cities:multi_condo1_3_floor1_palette",
  "xsize": 16,
  "zsize": 16,
  "slices": [
    [
      "                ",
      "      a         ",
      "      a         ",
      "bbbbbbaccccccc  ",
      "ddddddddddddec  ",
      "ffffffffffffgc  ",
      "ffffffffffffgc  ",
      "ffffffffffffgc  ",
      "ffffffffffffgc  ",
      "ffffffffffffgc  ",
      "ffffffffffffgc  ",
      "ffffffffffffgc  ",
      "ffffffffffffgc  ",
      "ffffffffffffgaaa",
      "ccccccccccccgh  ",
      "iiiiijkkkkkkgh  "
    ],
    [
      "                ",
      "      aaaaaaaaaa",
      "      aaaaaaaaaa",
      "      lmmmmmmmaa",
      "nnnnnnnnnnnnnmaa",
      "            nmaa",
      "            nmaa",
      "            nmaa",
      "            nmaa",
      "            nmaa",
      "      ~     nmaa",
      "            nmaa",
      "            nmaa",
      "            noaa",
      "            n   ",
      "            n   "
    ],
    [
      "                ",
      "                ",
      "                ",
      "                ",
      "nnnnnnnnnnnnn   ",
      "            n   ",
      "            n   ",
      "            n   ",
      "            n   ",
      "            n   ",
      "      ~     n   ",
      "            n   ",
      "            n   ",
      "            n   ",
      "            n   ",
      "            n   "
    ],
    [
      "                ",
      "                ",
      "                ",
      "                ",
      "            p   ",
      "                ",
      "                ",
      "                ",
      "                ",
      "                ",
      "      ~         ",
      "                ",
      "                ",
      "                ",
      "                ",
      "                "
    ],
    [
      "                ",
      "                ",
      "                ",
      "                ",
      "            q   ",
      "                ",
      "                ",
      "                ",
      "                ",
      "                ",
      "      ~         ",
      "                ",
      "                ",
      "                ",
      "                ",
      "                "
    ],
    [
      "                ",
      "                ",
      "                ",
      "                ",
      "                ",
      "                ",
      "                ",
      "                ",
      "                ",
      "                ",
      "      ~         ",
      "                ",
      "                ",
      "                ",
      "                ",
      "                "
    ]
  ]
}