{
  "name": "multi_militarybase_1_base4",
  "refpalette": "c70cities:multi_militarybase_1_base4_palette",
  "xsize": 16,
  "zsize": 16,
  "slices": [
    [
      "vaaaaaaaaaaaabcc",
      "vaaaaaaaaaaaabcc",
      "vvbbbbbbbbbbbvbb",
      "vvvvvvvvvvvvvvzz",
      "vzzzzzzzzzzzzzzz",
      "vzzzzzzzzzzzzzzz",
      "vzzzzzzzzzzzzzzz",
      "vzzzzzzzzzzzzzzz",
      "vzzzzzzzzzzzzzzz",
      "vzzzzzzzzzzzzzzz",
      "vzzzzzzzzzzzzzzz",
      "vzzzzzzzzzzzzzzz",
      "vzzzzzzzzzzzzzzz",
      "vzzzzzzzzzzzzzzz",
      "vzzzzzzzzzzzzzzz",
      "vvvvvvvvvvvvvvvv"
    ],
    [
      "v               ",
      "v             de",
      "vv fggh fggh vii",
      "vvvvvvvvvvvvvvzz",
      "vzzzzzzzzzzzzzzz",
      "vzzzzzzzzzzzzzzz",
      "vzzzzzzzzzzzzzzz",
      "vzzzzzzzzzzzzzzz",
      "vzzzzzzzzzzzzzzz",
      "vzzzzzzzzzzzzzzz",
      "vzzzzzzzzzzzzzzz",
      "vzzzzzzzzzzzzzzz",
      "vzzzzzzzzzzzzzzz",
      "vzzzzzzzzzzzzzzz",
      "vzzzzzzzzzzzzzzz",
      "vvvvvvvvvvvvvvvv"
    ],
    [
      "vj              ",
      "v               ",
      "vv           vii",
      "vvvvvvvvvvvvvvzz",
      "vzzzzzzzzzzzzzzz",
      "vzzzzzzzzzzzzzzz",
      "vzzzzzzzzzzzzzzz",
      "vzzzzzzzzzzzzzzz",
      "vzzzzzzzzzzzzzzz",
      "vzzzzzzzzzzzzzzz",
      "vzzzzzzzzzzzzzzz",
      "vzzzzzzzzzzzzzzz",
      "vzzzzzzzzzzzzzzz",
      "vzzzzzzzzzzzzzzz",
      "vzzzzzzzzzzzzzzz",
      "vvvvvvvvvvvvvvvv"
    ],
    [
      "vk              ",
      "v               ",
      "vv           vii",
      "vvvvvvvvvvvvvvzz",
      "vzzzzzzzzzzzzzzz",
      "vzzzzzzzzzzzzzzz",
      "vzzzzzzzzzzzzzzz",
      "vzzzzzzzzzzzzzzz",
      "vzzzzzzzzzzzzzzz",
      "vzzzzzzzzzzzzzzz",
      "vzzzzzzzzzzzzzzz",
      "vzzzzzzzzzzzzzzz",
      "vzzzzzzzzzzzzzzz",
      "vzzzzzzzzzzzzzzz",
      "vzzzzzzzzzzzzzzz",
      "vvvvvvvvvvvvvvvv"
    ],
    [
      "v               ",
      "v               ",
      "vv           vii",
      "vvvvvvvvvvvvvvzz",
      "vzzzzzzzzzzzzzzz",
      "vzzzzzzzzzzzzzzz",
      "vzzzzzzzzzzzzzzz",
      "vzzzzzzzzzzzzzzz",
      "vzzzzzzzzzzzzzzz",
      "vzzzzzzzzzzzzzzz",
      "vzzzzzzzzzzzzzzz",
      "vzzzzzzzzzzzzzzz",
      "vzzzzzzzzzzzzzzz",
      "vzzzzzzzzzzzzzzz",
      "vzzzzzzzzzzzzzzz",
      "vvvvvvvvvvvvvvvv"
    ],
    [
      "vllllllllllllmnn",
      "vllllllllllllmoo",
      "vvbbbbbbbbbbbvbb",
      "vvvvvvvvvvvvvvzz",
      "vzzzzzzzzzzzzzzz",
      "vzzzzzzzzzzzzzzz",
      "vzzzzzzzzzzzzzzz",
      "vzzzzzzzzzzzzzzz",
      "vzzzzzzzzzzzzzzz",
      "vzzzzzzzzzzzzzzz",
      "vzzzzzzzzzzzzzzz",
      "vzzzzzzzzzzzzzzz",
      "vzzzzzzzzzzzzzzz",
      "vzzzzzzzzzzzzzzz",
      "vzzzzzzzzzzzzzzz",
      "vvvvvvvvvvvvvvvv"
    ]
  ]
}