{
  "name": "multi_factory_1_ground",
  "refpalette": "c70cities:multi_factory_1_ground_palette",
  "xsize": 16,
  "zsize": 16,
  "slices": [
    [
      "aaabbbbbbbbbbbzz",
      "zaabbbbbbbbbbbzz",
      "azabbbbbbbbbbbzz",
      "aaabbbbbbbbbbbzz",
      "aaabbbbbbbbbbbzz",
      "aaabbbbbbbbbbbzz",
      "zaabbbbbbbbbbbzz",
      "aaabbbbbbbbbbbzz",
      "zaabbbbbbbbbbbzz",
      "zaabbbbbbbbbbbzz",
      "aaabbbbbbbbbbbzz",
      "aaabbbbbbbbbbbzz",
      "azabbbbbbbbbbbzz",
      "aaabbbbbbbbbbbzz",
      "zaazzzzzzzzzzzzz",
      "aazzzzzzzzzzzzzz"
    ],
    [
      "     cc  d  ef  ",
      "     ccdcd  ef  ",
      "         g   f  ",
      "   f        gf  ",
      "   fc   c   cf  ",
      "   f         f  ",
      "   h       igf  ",
      "   h     jjj f  ",
      "   h    ij!jif  ",
      "   h   igjjj f  ",
      "   h     i   f  ",
      "   hg     kk f  ",
      "   fcllmcnopcf  ",
      "   fffffffffff  ",
      "                ",
      "                "
    ],
    [
      "     d  qd   f  ",
      "     rq qd  ef  ",
      "             f  ",
      "   f         f  ",
      "   fc   c   cf  ",
      "   f         f  ",
      "   h         f  ",
      "   h     jjj f  ",
      "   h       j f  ",
      "   h     jjj f  ",
      "   h         f  ",
      "   hg        f  ",
      "   fc   c kkcf  ",
      "   fffffffffff  ",
      "                ",
      "                "
    ],
    [
      "   h        ef  ",
      "   h  s s    f  ",
      "   h         f  ",
      "   f         f  ",
      "   fc   c   cf  ",
      "   f         f  ",
      "   hg        f  ",
      "   h     jj  f  ",
      "   h       j f  ",
      "   h     ijj f  ",
      "   h         f  ",
      "   h         f  ",
      "   fcg  c  gcf  ",
      "   fftuwftuwff  ",
      "                ",
      "                "
    ],
    [
      "  xfy        f  ",
      "  xfy        f  ",
      "  xfy        f  ",
      "   f         f  ",
      "   fc   c   cf  ",
      "   fg        f  ",
      "  xfy        f  ",
      "  xfy    AAA f  ",
      "  xfy    A A f  ",
      "  xfy    AAA f  ",
      "  xfy        f  ",
      "  xfy   B   Bf  ",
      "   fcBBBcBBBcf  ",
      "   fffffffffff  ",
      "                ",
      "                "
    ],
    [
      "   f         f  ",
      "   f         f  ",
      "   f         f  ",
      "   f         f  ",
      "   fc   c   cf  ",
      "   f         f  ",
      "   f         f  ",
      "   fB   BAAABf  ",
      "   fBBBBBA ABf  ",
      "   fB   BAAABf  ",
      "   fC   C   Cf  ",
      "   fDDDDDDDDDf  ",
      "   fDDDDDDDDDf  ",
      "   EEEEEEEEEEE  ",
      "                ",
      "                "
    ]
  ]
}