{
  "name": "multi_laboratory1_2_base6",
  "refpalette": "c70cities:multi_laboratory1_2_base6_palette",
  "xsize": 16,
  "zsize": 16,
  "slices": [
    [
      "vabcccccccccccd ",
      "vabcccccccccccd ",
      "vabcccccccccccde",
      "vabcccccccccccdf",
      "vabccccccccgcccd",
      "vabccccccccccccd",
      "vabccccccccccccc",
      "vabccccccccccccc",
      "vabccccccccccccc",
      "vabccccccccccccc",
      "vabccccccccccccc",
      "vabccccccccgcccc",
      "vabccccccccccc!c",
      "vabccccccccccccc",
      "vabccccccccccccc",
      "vabccccccccccccc"
    ],
    [
      "vabh      ij  k ",
      "vabh       j  k ",
      "vab   l    jm k ",
      "vannnn o   h  kf",
      "vabpqn   r g   k",
      "vannnnso   t   k",
      "vab   u   wj    ",
      "vabh       j    ",
      "vabh      ij    ",
      "vab        j    ",
      "vannnn     xw   ",
      "vabyAn     g    ",
      "vannnn       BBB",
      "vab             ",
      "vabh         C  ",
      "vabh            "
    ],
    [
      "vabDE      F  k ",
      "vabDE      I  k ",
      "vabJ       K  k ",
      "vannks     w  kf",
      "vabp       g   k",
      "vannk      L   k",
      "vabM            ",
      "vabN       F    ",
      "vabNE      m    ",
      "vabJ       h    ",
      "vannk           ",
      "vabyAk     g    ",
      "vannk        OP ",
      "vabM            ",
      "vabNE           ",
      "vab!E           "
    ],
    [
      "vab           k ",
      "vab           k ",
      "vab           k ",
      "vannk         kf",
      "vabp       g   k",
      "vannQ          k",
      "vab             ",
      "vab             ",
      "vab             ",
      "vab             ",
      "vannk           ",
      "vabyAk     g    ",
      "vannk           ",
      "vab             ",
      "vab             ",
      "vab             "
    ],
    [
      "vabR          k ",
      "vabR          k ",
      "vab           k ",
      "vannk         kf",
      "vabp S     g   k",
      "vannk          k",
      "vab             ",
      "vabR            ",
      "vabR            ",
      "vab             ",
      "vannk           ",
      "vabyAk     g    ",
      "vannk           ",
      "vab             ",
      "vabR            ",
      "vabR            "
    ],
    [
      "vab           k ",
      "vabT          k ",
      "vab           k ",
      "vannk         kf",
      "vabp k     g   k",
      "vannk          k",
      "vab             ",
      "vabT            ",
      "vab             ",
      "vab             ",
      "vannk           ",
      "vabyAk     g    ",
      "vannk           ",
      "vab             ",
      "vabT            ",
      "vab             "
    ]
  ]
}