{
  "name": "multi_residential1_1_ground",
  "refpalette": "c70cities:multi_residential1_1_ground_palette",
  "xsize": 16,
  "zsize": 16,
  "slices": [
    [
      "GGabbbbbbbbbbaGG",
      "GGabbbbbbbbbbaGG",
      "GGabbbbbbbbbbaGG",
      "GGabbbbbbbbbbaGG",
      "GGabbbbbbbbbbaGG",
      "GGabbbbbbbbbbaGG",
      "GGabbbbbbbbbbaGG",
      "GGaaaaaaaaaaaaGG",
      "GGcGGGGGGdGGGcGG",
      "GGcGGGddGGGGGcGG",
      "GGcGGdGGGdGddcGG",
      "GGccccccccccccGG",
      "GGGGGGGGGGGGGGGG",
      "GGGGGGGGGGGGGGGG",
      "GGGGGGGGGGGGGGGG",
      "GGGGGGGGGGGGGGGG"
    ],
    [
      "  eeeee  f !ee g",
      "  c hh    ii c g",
      "  e          e j",
      "  c kl     mnc g",
      "  e        ooe g",
      "  p        q c g",
      "  r        stc j",
      "  eccuuwxuucce g",
      "  yABCBD  ADBy g",
      "  yCAA  CACACy g",
      "  yDA DAB B  y g",
      "  eEEEEEEEEEEe j",
      "               g",
      "F              g",
      "g              g",
      "FggggjggggjggggF"
    ],
    [
      "  eeeee  IIIee g",
      "  J KK      LJ g",
      "  e         Me j",
      "  J          J g",
      "  e        ooe g",
      "  N        O c g",
      "  P        sQc j",
      "  eccuuRSuucce g",
      "               g",
      "               g",
      "               g",
      " TeeeeeeeeeeeeTj",
      " ccccccccccccccg",
      "F              g",
      "g              g",
      "FggggjggggjggggF"
    ],
    [
      "  eeeee     ee  ",
      "  J        U J  ",
      "  e          e  ",
      "  J          J  ",
      "  e        ooe  ",
      "  J        s V  ",
      "  J        s V  ",
      "  eccuuuuuucce  ",
      "                ",
      " TTT        TTT ",
      " cccccccccccccc ",
      " WWWWWWWWWWWWWW ",
      "                ",
      "X               ",
      "                ",
      "                "
    ],
    [
      "  eeeeeeeeeeee  ",
      "  JbbbbbbbU  J  ",
      "  ebbbbbbb   e  ",
      "  Jbbbbbbb   J  ",
      "  ebbbbbbbbbbe  ",
      "  ebbbbbbbbbbe  ",
      "  ebbbbbbbbbbe  ",
      " TeeeeeeeeeeeeT ",
      " ccc        ccc ",
      " WWW        WWW ",
      "   E  E  E  E   ",
      "                ",
      "                ",
      "                ",
      "                ",
      "                "
    ],
    [
      "  eeeeeeeeeeee  ",
      "  JYZZY0     J  ",
      "  e 11 234   e  ",
      "  J    5 46  J  ",
      "  e       777e  ",
      " TeT  48  9 TeT ",
      " cccJ 48  9Jccc ",
      " WWWJJJJJJJJWWW ",
      "   E        E   ",
      "                ",
      "   E  E  E  E   ",
      "                ",
      "                ",
      "                ",
      "                ",
      "                "
    ]
  ]
}