{
  "name": "multi_communitycenter_4_base1",
  "refpalette": "c70cities:multi_communitycenter_4_base1_palette",
  "xsize": 16,
  "zsize": 16,
  "slices": [
    [
      "HHHHHHHHHHHHHHHH",
      "HHHHHHHHHHHHHHHH",
      "HHHHHHHHHHHHHHHH",
      "HHHHHHHHHHHabHHH",
      "HHHHHHHHHHHHHHHH",
      "HHHHHHHHHHHHHHHH",
      "HHHHHHHHHHHHHHHH",
      "HHHHHHHHHHHHHHHH",
      "HHHHHHHHHHHHHHHH",
      "HHHHHHHHHHHHHHHH",
      "HHHHHHHHHHHHHHHH",
      "HHHHHHHHHHHHHHHH",
      "HHHHHHHHHHHHHHHH",
      "HHHHHHHHHHHHHHHH",
      "HHHHHHHHHHHHHHHH",
      "HHHHHHHHHHHHHHHH"
    ],
    [
      "                ",
      "cdcd cdcd cdcd c",
      "efef efef efef e",
      "                ",
      "cdcdgcdcdgcdcdgc",
      "                ",
      "                ",
      "                ",
      "                ",
      "                ",
      "                ",
      "efefgefefgefefge",
      "                ",
      "cdcd cdcd cdcd c",
      "efef efef efef e",
      "                "
    ],
    [
      "                ",
      "                ",
      "                ",
      "                ",
      "    g    g    g ",
      "                ",
      "                ",
      "                ",
      "                ",
      "                ",
      "                ",
      "    g    g    g ",
      "                ",
      "                ",
      "                ",
      "                "
    ],
    [
      "                ",
      "                ",
      "                ",
      "                ",
      "    g    g    g ",
      "                ",
      "                ",
      "                ",
      "                ",
      "                ",
      "                ",
      "    g    g    g ",
      "                ",
      "                ",
      "                ",
      "                "
    ],
    [
      "    g    g    g ",
      "    g    g    g ",
      "    g    g    g ",
      "    g    g    g ",
      "hhhhghhhhghhhhgh",
      "    g    g    g ",
      "    g    g    g ",
      "    g    g    g ",
      "    g    g    g ",
      "    g    g    g ",
      "    g    g    g ",
      "hhhhghhhhghhhhgh",
      "    g    g    g ",
      "    g    g    g ",
      "    g    g    g ",
      "    g    g    g "
    ],
    [
      "iiiiiiiiiiiiiiii",
      "iiiiiiiiiiiiiiii",
      "iiiiiiiiiiiiiiii",
      "iiiiiiiiiiiiiiii",
      "iiiiiiiiiiiiiiii",
      "iiiiiiiiiiiiiiii",
      "iiiiiiiiiiiiiiii",
      "iiiiiiiiiiiiiiii",
      "iiiiiiiiiiiiiiii",
      "iiiiiiiiiiiiiiii",
      "iiiiiiiiiiiiiiii",
      "iiiiiiiiiiiiiiii",
      "iiiiiiiiiiiiiiii",
      "iiiiiiiiiiiiiiii",
      "iiiiiiiiiiiiiiii",
      "iiiiiiiiiiiiiiii"
    ]
  ]
}