{
  "name": "multi_laboratory1_5_floor1",
  "refpalette": "c70cities:multi_laboratory1_5_floor1_palette",
  "xsize": 16,
  "zsize": 16,
  "slices": [
    [
      "                ",
      "                ",
      "aababaaaababaaba",
      "cccccdccccdccccc",
      "cccccecccceccccc",
      "ffffffffffffffff",
      "g  h g  h g ii g",
      "gjjjjgjjjjgjjjjg",
      "gggggggggggggggg",
      "g    g    g    g",
      "g    g    g    g",
      "g    g    g    g",
      "g    g    g    g",
      "g    g    g    g",
      "g    k    g    g",
      "gggglmggglmgggng"
    ],
    [
      "                ",
      "                ",
      "aaaaaabaaaaaabaa",
      "                ",
      "                ",
      "oppppfppppfppppo",
      "qii  qii  q  iiq",
      "qjjjjqjjjjqjjjjq",
      "gqqqqgqqqqgqqqqg",
      "q    q    q    q",
      "q    q    q    q",
      "q    q    q    q",
      "q    q    q    q",
      "q    q    q    q",
      "q    q    q    q",
      "gqrrqgqrrqgqrrqg"
    ],
    [
      "                ",
      "                ",
      "aabaaaabaaaaaaab",
      "                ",
      "                ",
      "oppppfppppfppppo",
      "qi iiq  h q h iq",
      "qjjjjqjjjjqjjjjq",
      "gqqqqgqqqqgqqqqg",
      "q    q    q    q",
      "q    q    q    q",
      "q    q    q    q",
      "q    q    q    q",
      "q    q    q    q",
      "q    q    q    q",
      "gq  qgq  qgq  qg"
    ],
    [
      "                ",
      "                ",
      "baaaaaaaaaaaaaaa",
      "                ",
      "                ",
      "oppppfppppfppppo",
      "q h  q i  q  i q",
      "qjjjjqjjjjqjjjjq",
      "gqqqqgqqqqgqqqqg",
      "q    q    q    q",
      "q    q    q    q",
      "q    q    q    q",
      "q    q    q    q",
      "q    q    q    q",
      "q    q    q    q",
      "gqssqgqssqgqssqg"
    ],
    [
      "                ",
      "                ",
      "aaaaaaaaaaabaaaa",
      "                ",
      "                ",
      "oppppfppppfppppo",
      "q    q    q    q",
      "qt  tqt  tqt  tq",
      "gqqqqgqqqqgqqqqg",
      "q    q    q    q",
      "q    q    q    q",
      "q    q    q    q",
      "q    q    q    q",
      "q    q    q    q",
      "q    q    q    q",
      "gqqqqgqqqqgqqqqg"
    ],
    [
      "                ",
      "                ",
      "aaaaaaaaaaaaaaaa",
      "                ",
      "                ",
      "ffffffffffffffff",
      "uuuuuuuuuuuuuuuu",
      "uuuuuuuuuuuuuuuu",
      "uuuuuuuuuuuuuuuu",
      "uwwwwuwwwwuwwwwu",
      "xw  wxw  wxw  wx",
      "uwwwwuwwwwuwwwwu",
      "uwwwwuwwwwuwwwwu",
      "uwwwwuwwwwuwwwwu",
      "uwwwwuwwwwuwwwwu",
      "ffffffffffffffff"
    ]
  ]
}