{
  "name": "multi_flatapartment_2_floor2",
  "refpalette": "c70cities:multi_flatapartment_2_floor2_palette",
  "xsize": 16,
  "zsize": 16,
  "slices": [
    [
      "                ",
      "abbbbabbbabbbba ",
      "ccccccccccccccb ",
      "dddddddddddddcb ",
      "dddddddddddddcb ",
      "dddddddddddddca ",
      "dddddddddddddcb ",
      "dddddddddddddcb ",
      "dddddddddddddcb ",
      "dddddddddddddcb ",
      "dddddddddddddca ",
      "dddddddddddddcb ",
      "dddddddddddddcb ",
      "ccccccccccccccb ",
      "abbbbabbbabbbba ",
      "                "
    ],
    [
      "                ",
      "abeebabebabeeba ",
      "         f    b ",
      " g g hii hj   e ",
      " kkk h   h  lmb ",
      "hhhhhh   hhhhha ",
      "hn  ohpp q    b ",
      "hn  ohhhhh    e ",
      "h    r  sh tt e ",
      "hg g h uwhxyyAb ",
      "hkkk h uwhhhhha ",
      "BCDD h   f   Eb ",
      "     hhhhhj  Fe ",
      "         I  lmb ",
      "abeebabebabeeba ",
      "                "
    ],
    [
      "                ",
      "abJJbabJbabJJba ",
      "         K    b ",
      "     h   h    J ",
      "     h   h L Mb ",
      "hhhhhh   hhhhha ",
      "hN   hNN O    b ",
      "hN   hhhhh    J ",
      "h    P   h    J ",
      "h    h   h    b ",
      "h    h   hhhhha ",
      "     h   K Q Rb ",
      "     hhhhh    J ",
      "         S    b ",
      "abJJbabJbabJJba ",
      "                "
    ],
    [
      "                ",
      "abJJbabJbabJJba ",
      "         h    b ",
      "     h   h    J ",
      "     h   h T  b ",
      "hhhhhh   hhhhha ",
      "hN   hNN h    b ",
      "hN   hhhhh    J ",
      "h    h   h    J ",
      "h    h   h    b ",
      "h    h   hhhhha ",
      "     h   h   Ub ",
      "     hhhhh    J ",
      "         h    b ",
      "abJJbabJbabJJba ",
      "                "
    ],
    [
      "                ",
      "abbbbabbbabbbba ",
      "h    h   hVVVVb ",
      "h    h   hVVVVb ",
      "h    h W hVVVVb ",
      "hhhhhh   hhhhha ",
      "hX   h   h    b ",
      "h  Y hhhhh    b ",
      "h    h   h    b ",
      "h    h   h    b ",
      "h    h   hhhhha ",
      "h    h   hVVVVb ",
      "h    hhhhhVVVVb ",
      "h    h   hVVVVb ",
      "abbbbabbbabbbba ",
      "                "
    ],
    [
      "                ",
      "Z0000Z000Z0000Z ",
      "cccccccccccccc0 ",
      "dddddddddddddc0 ",
      "dddddddddddddc0 ",
      "dddddddddddddcZ ",
      "dddddddddddddc0 ",
      "dddddddddddddc0 ",
      "dddddddddddddc0 ",
      "dddddddddddddc0 ",
      "dddddddddddddcZ ",
      "dddddddddddddc0 ",
      "dddddddddddddc0 ",
      "cccccccccccccc0 ",
      "Z0000Z000Z0000Z ",
      "                "
    ]
  ]
}