{
  "name": "multi_derrick_0_ground",
  "refpalette": "c70cities:multi_derrick_0_ground_palette",
  "xsize": 16,
  "zsize": 16,
  "slices": [
    [
      "zzzzzzzzzzzzzzzz",
      "zzzzzzzzzzzzzzzz",
      "zzzzzzzzzzzzzzzz",
      "zzzzzzaazzzzzzzz",
      "zzzzzabbbzzzzaaz",
      "zzzzabbbazzabbbz",
      "zzzabbbzazabbbba",
      "zzzaabbzaabbbbba",
      "zzzzzzzzzbbbbbba",
      "zzzzzzzzzbbbbbaz",
      "zzzzzzzzzzbbbbaz",
      "zzzzzzzzaaabbbzz",
      "zzzzzzzzaaabzzzz",
      "zzzzzzzzzzzzzzzz",
      "zzzzzzzzzzzzzzzz",
      "zzzzzzzzzzzzzzzz"
    ],
    [
      "   c    c      c",
      " deeedeeedfeedee",
      " egggggghii  ihh",
      "cegjggjg ikc    ",
      " egggggg        ",
      " d             h",
      " eh      h      ",
      " ehh            ",
      " ehlmmmlh       ",
      " e lllll        ",
      " d llnoo o     h",
      " e lloll o      ",
      "ce llmll  o hh c",
      " e   p    hh    ",
      " deeedeeedeeedee",
      "      c        c"
    ],
    [
      "                ",
      " dqqqdqqqdqqqdqq",
      " q       i      ",
      " q j  j         ",
      " q o  o         ",
      " d o            ",
      " q              ",
      " q              ",
      " q rmmmr        ",
      " q s            ",
      " d l n          ",
      " q              ",
      " q r m r        ",
      " q   t          ",
      " dqqqdqqqdqqqdqq",
      "                "
    ],
    [
      "                ",
      " u   u   u   u  ",
      "                ",
      "   j  j         ",
      "                ",
      " u              ",
      "                ",
      "                ",
      "   r   r        ",
      "                ",
      " u l o          ",
      "                ",
      "   r   r        ",
      "                ",
      " u   u   u   u  ",
      "                "
    ],
    [
      "                ",
      "                ",
      "                ",
      "   j  j         ",
      "                ",
      "                ",
      "                ",
      "                ",
      "   rrrrr        ",
      "   r   r        ",
      "   l o r        ",
      "   r   r        ",
      "   rrrrr        ",
      "                ",
      "                ",
      "                "
    ],
    [
      "                ",
      "                ",
      "                ",
      "   w  w         ",
      "                ",
      "                ",
      "                ",
      "                ",
      "   r r r        ",
      "                ",
      "   l o r        ",
      "                ",
      "   r r r        ",
      "                ",
      "                ",
      "                "
    ]
  ]
}