{
  "name": "multi_residential2_1_ground",
  "refpalette": "c70cities:multi_residential2_1_ground_palette",
  "xsize": 16,
  "zsize": 16,
  "slices": [
    [
      "GGGGabaccGcbGGGG",
      "GGGGcGGccabGGGGG",
      "GGGGGGcbcbcbGGGG",
      "GGGGcbGcabbcGGGG",
      "GGddddddddddddGG",
      "ddddddddddddddGG",
      "dddddHHHeeedddGG",
      "dddddHfHghidddGG",
      "dddddHHHjkldddGG",
      "dddddHHHmnodddGG",
      "ddddddddddddddGG",
      "GGddddddddddddGG",
      "GGGGGGGGGGGGGGGG",
      "GGGGGGGGGGGGGGGG",
      "GGGGGGGGGGGGGGGG",
      "GGGGGGGGGGGGGGGG"
    ],
    [
      "  pq     rs qp t",
      "  pqs r    rqp t",
      "  pq  s     qp u",
      "  pq r   r sqp t",
      " wvvvvv  vvvvv t",
      "w v        xyv t",
      "            Av u",
      "            Bv t",
      "            Bv t",
      " w          Cv t",
      "D v       EFIv t",
      "  vvvvvvvvvvvv u",
      "               t",
      "J              t",
      "t              t",
      "JttttuttttuttttJ"
    ],
    [
      "   q        q  t",
      "   q        q  t",
      "   q        q  u",
      "   q        q  t",
      "  vvvvv  vvvvv t",
      "  v         yv t",
      "  K         Lv u",
      "  K         Mv t",
      "  K         Nv t",
      "  K          v t",
      "  v         Ov t",
      "  vvvvvvvvvvvv u",
      "               t",
      "J              t",
      "t              t",
      "JttttuttttuttttJ"
    ],
    [
      "  Pq        qQ  ",
      "  Pq        qQ  ",
      "  Pq        qQ  ",
      "  Pq        qQ  ",
      "  vvvvvvvvvvvv  ",
      "  v          v  ",
      "  K          v  ",
      "  K          v  ",
      "  K          v  ",
      "  K        R v  ",
      "  v        SOv  ",
      "  vvTTTvvTTTvv  ",
      "                ",
      "                ",
      "                ",
      "                "
    ],
    [
      "   PUUUUUUUUQ   ",
      "   PUUUUUUUUQ   ",
      "   PUUUUUUUUQ   ",
      "   PUUUUUUUUQ   ",
      "  vvvvvvvvvvvv  ",
      "  v          v  ",
      "  vV         v  ",
      "  vV         v  ",
      "  vV         v  ",
      "  vV         v  ",
      "  v         Ov  ",
      "  vvvvvvvvvvvv  ",
      "                ",
      "                ",
      "                ",
      "                "
    ],
    [
      "    PWX  YWQ    ",
      "    PWZ012WQ    ",
      "    PWZ  3WQ    ",
      "    P444444Q    ",
      "  vvvvvvvvvvvv  ",
      "  v5555555555v  ",
      "  v5555555555v  ",
      "  v5555555555v  ",
      "  v5555555555v  ",
      "  v5555555555v  ",
      "  v5555555555v  ",
      "  vvvvvvvvvvvv  ",
      "                ",
      "                ",
      "                ",
      "                "
    ]
  ]
}