{
  "name": "multi_pumpjack_2_floor1",
  "refpalette": "c70cities:multi_pumpjack_2_floor1_palette",
  "xsize": 16,
  "zsize": 16,
  "slices": [
    [
      "~~~~~~~~~~~~~~~~",
      "a~~~~~~~~~~~~~~~",
      "a~~~~~~~~~~~~~~~",
      "~~~~~~~~~~~~~~~~",
      "~~~~~~~~~~~~~~~~",
      "~~~~~~~~~~~~~~~~",
      "~~~~~~~~~~~~~~~~",
      "~~~~~~~~~~~~~~~~",
      "~~~~~~~~~~~~~~~~",
      "~~~~~~~~~~~~~~~~",
      "~~~~~~~~~~~~~~~~",
      "~~~~~~~~~~~~~~~~",
      "~~~~~~~~~~~~~~~~",
      "~~~~~~~~~~~~~~~~",
      "~~~~~~~~~~~~~~~~",
      "~~~~~~~~~~~~~~~~"
    ],
    [
      "~~~~~~~~~~~~~~~~",
      "a~~~~~~~~~~~~~~~",
      "a~~~~~~~~~~~~~~~",
      "b~~~~~~~~~~~~~~~",
      "b~~~~~~~~~~~~~~~",
      "b~~~~~~~~~~~~~~~",
      "b~~~~~~~~~~~~~~~",
      "b~~~~~~~~~~~~~~~",
      "b~~~~~~~~~~~~~~~",
      "b~~~~~~~~~~~~~~~",
      "b~~~~~~~~~~~~~~~",
      "b~~~~~~~~~~~~~~~",
      "b~~~~~~~~~~~~~~~",
      "b~~~~~~~~~~~~~~~",
      "b~~~~~~~~~~~~~~~",
      "b~~~~~~~~~~~~~~~"
    ],
    [
      "~~~~~~~~~~~~~~~~",
      "a~~~~~~~~~~~~~~~",
      "a~~~~~~~~~~~~~~~",
      "~~~~~~~~~~~~~~~~",
      "~~~~~~~~~~~~~~~~",
      "~~~~~~~~~~~~~~~~",
      "~~~~~~~~~~~~~~~~",
      "~~~~~~~~~~~~~~~~",
      "~~~~~~~~~~~~~~~~",
      "~~~~~~~~~~~~~~~~",
      "~~~~~~~~~~~~~~~~",
      "~~~~~~~~~~~~~~~~",
      "~~~~~~~~~~~~~~~~",
      "~~~~~~~~~~~~~~~~",
      "~~~~~~~~~~~~~~~~",
      "~~~~~~~~~~~~~~~~"
    ],
    [
      "~~~~~~~~~~~~~~~~",
      "a~~~~~~~~~~~~~~~",
      "a~~~~~~~~~~~~~~~",
      "a~~~~~~~~~~~~~~~",
      "a~~~~~~~~~~~~~~~",
      "a~~~~~~~~~~~~~~~",
      "a~~~~~~~~~~~~~~~",
      "a~~~~~~~~~~~~~~~",
      "a~~~~~~~~~~~~~~~",
      "a~~~~~~~~~~~~~~~",
      "a~~~~~~~~~~~~~~~",
      "a~~~~~~~~~~~~~~~",
      "a~~~~~~~~~~~~~~~",
      "a~~~~~~~~~~~~~~~",
      "a~~~~~~~~~~~~~~~",
      "a~~~~~~~~~~~~~~~"
    ],
    [
      "cc~~~~~~~~~~~~~~",
      "cc~~~~~~~~~~~~~~",
      "cc~~~~~~~~~~~~~~",
      "cc~~~~~~~~~~~~~~",
      "cc~~~~~~~~~~~~~~",
      "cc~~~~~~~~~~~~~~",
      "cc~~~~~~~~~~~~~~",
      "cc~~~~~~~~~~~~~~",
      "cc~~~~~~~~~~~~~~",
      "cc~~~~~~~~~~~~~~",
      "cc~~~~~~~~~~~~~~",
      "cc~~~~~~~~~~~~~~",
      "cc~~~~~~~~~~~~~~",
      "cc~~~~~~~~~~~~~~",
      "cc~~~~~~~~~~~~~~",
      "cc~~~~~~~~~~~~~~"
    ],
    [
      "~~~~~~~~~~~~~~~~",
      "~~~~~~~~~~~~~~~~",
      "~~~~~~~~~~~~~~~~",
      "~~~~~~~~~~~~~~~~",
      "~~~~~~~~~~~~~~~~",
      "~~~~~~~~~~~~~~~~",
      "~~~~~~~~~~~~~~~~",
      "~~~~~~~~~~~~~~~~",
      "~~~~~~~~~~~~~~~~",
      "~~~~~~~~~~~~~~~~",
      "~~~~~~~~~~~~~~~~",
      "~~~~~~~~~~~~~~~~",
      "~~~~~~~~~~~~~~~~",
      "~~~~~~~~~~~~~~~~",
      "~~~~~~~~~~~~~~~~",
      "~~~~~~~~~~~~~~~~"
    ]
  ]
}