{
  "name": "multi_laboratory1_3_base7",
  "refpalette": "c70cities:multi_laboratory1_3_base7_palette",
  "xsize": 16,
  "zsize": 16,
  "slices": [
    [
      "zaaaaaaaaaaaaaaa",
      "zaaaaaaaaaaaaaaa",
      "zaaaaaaaaaaaaaaa",
      "zaaaaaaaaaaaaaaa",
      "zaaaaaaaaaaaaaaa",
      "zaaaaaaaaaaaaaaa",
      "zaaaaaaaaaaaaaaa",
      "zaaaaaaaaaaaaaaa",
      "zaaaaaaaaaaaaaaa",
      "zaaaaaaaaaaaaaaa",
      "zaaaaaaaaaaaaaaa",
      "zaaaaaaaaaaaaaaa",
      "zaaaaaaaaaaaaaaa",
      "zaaaaaaaaaaaaaaa",
      "zaaaaaaaaaaaaaaa",
      "zaaaaaaaaaaaaaaa"
    ],
    [
      "zaaaaaaaaaaaaaaa",
      "zaaaaaaaaaaaaaaa",
      "zaaaaaaaaaaaaaaa",
      "zaaaaaaaaaaaaaaa",
      "zaaaaaaaaaaaaaaa",
      "zaaaaaaaaaaaaaaa",
      "zaaaaaaaaaaaaaaa",
      "zaaaaaaaaaaaaaaa",
      "zaaaaaaaaaaaaaaa",
      "zaaaaaaaaaaaaaaa",
      "zaaaaaaaaaaaaaaa",
      "zaaaaaaaaaaaaaaa",
      "zaaaaaaaaaaaaaaa",
      "zaaaaaaaaaaaaaaa",
      "zaaaaaaaaaaaaaaa",
      "zaaaaaaaaaaaaaaa"
    ],
    [
      "zaaaaaaaaaaaaaaa",
      "zaaaaaaaaaaaaaaa",
      "zaaaaaaaaaaaaaaa",
      "zaaaaabbcbbbcbbb",
      "zaaaaabddddddddd",
      "zaaaaaefffffffff",
      "zaaaaaefffffffff",
      "zaaaaabggggggggg",
      "zaaaaabbcbbbcbbb",
      "zaaaaaaaaaaaaaaa",
      "zaaaaaaaaaaaaaaa",
      "zaaaaaaaaaaaaaaa",
      "zaaaaaaaaaaaaaaa",
      "zaaaaaaaaaaaaaaa",
      "zaaaaaaaaaaaaaaa",
      "zaaaaaaaaaaaaaaa"
    ],
    [
      "zaaaaaaaaaaaaaaa",
      "zaaaaaaaaaaaaaaa",
      "zaaaaaaaaaaaaaaa",
      "zaaaaabbhbbbhbbb",
      "zaaaaab         ",
      "zaaaaaei        ",
      "zaaaaaei        ",
      "zaaaaab         ",
      "zaaaaabbjbbbjbbb",
      "zaaaaaaaaaaaaaaa",
      "zaaaaaaaaaaaaaaa",
      "zaaaaaaaaaaaaaaa",
      "zaaaaaaaaaaaaaaa",
      "zaaaaaaaaaaaaaaa",
      "zaaaaaaaaaaaaaaa",
      "zaaaaaaaaaaaaaaa"
    ],
    [
      "zaaaaaaaaaaaaaaa",
      "zaaaaaaaaaaaaaaa",
      "zaaaaaaaaaaaaaaa",
      "zaaaaabbhbbbhbbb",
      "zaaaaab         ",
      "zaaaaaei        ",
      "zaaaaaei        ",
      "zaaaaab         ",
      "zaaaaabbjbbbjbbb",
      "zaaaaaaaaaaaaaaa",
      "zaaaaaaaaaaaaaaa",
      "zaaaaaaaaaaaaaaa",
      "zaaaaaaaaaaaaaaa",
      "zaaaaaaaaaaaaaaa",
      "zaaaaaaaaaaaaaaa",
      "zaaaaaaaaaaaaaaa"
    ],
    [
      "zaaaaaaaaaaaaaaa",
      "zaaaaaaaaaaaaaaa",
      "zaaaaaaaaaaaaaaa",
      "zaaaaabbbbbbbbbb",
      "zaaaaabkkkkkkkkk",
      "zaaaaaei lllllll",
      "zaaaaaei lllllll",
      "zaaaaabmmmmmmmmm",
      "zaaaaabbbbbbbbbb",
      "zaaaaaaaaaaaaaaa",
      "zaaaaaaaaaaaaaaa",
      "zaaaaaaaaaaaaaaa",
      "zaaaaaaaaaaaaaaa",
      "zaaaaaaaaaaaaaaa",
      "zaaaaaaaaaaaaaaa",
      "zaaaaaaaaaaaaaaa"
    ]
  ]
}