{
  "name": "multi_megatower1_1_floor9",
  "refpalette": "c70cities:multi_megatower1_1_floor9_palette",
  "xsize": 16,
  "zsize": 16,
  "slices": [
    [
      "           abc  ",
      "           dbc  ",
      "           dbcef",
      "           dbcgg",
      "          hijkcc",
      "           abccc",
      "           abccc",
      "           abccc",
      "           dbccc",
      "           dbccc",
      "           dbccc",
      "          hijkcc",
      "           abccc",
      "           abccc",
      "           abccc",
      "           dbccc"
    ],
    [
      "           a l  ",
      "           d le ",
      "           d lm ",
      "           d l  ",
      "           h kdn",
      "           a o  ",
      "           a o  ",
      "           a o  ",
      "           d op ",
      "           d oqr",
      "           d os ",
      "           h kt ",
      "           a op ",
      "           a oqr",
      "           a os ",
      "           d opu"
    ],
    [
      "           a lg ",
      "           d lm ",
      "           d l  ",
      "           d l  ",
      "           h kdw",
      "           a o  ",
      "           a o  ",
      "           a o  ",
      "           d o  ",
      "           d ox ",
      "           d o  ",
      "           h ky ",
      "           a o  ",
      "           a o  ",
      "           a o  ",
      "           d o  "
    ],
    [
      "           a lmA",
      "           d l  ",
      "           d l  ",
      "           d l B",
      "           h kdd",
      "           a o  ",
      "           a o  ",
      "           a o  ",
      "           d o  ",
      "           d o  ",
      "           d o  ",
      "           h ky ",
      "           a o  ",
      "           a o  ",
      "           a o  ",
      "           d o  "
    ],
    [
      "           a C f",
      "           d C A",
      "           d C  ",
      "           d C  ",
      "           h kdd",
      "           a D  ",
      "           a E  ",
      "           a D  ",
      "           d E  ",
      "           d D  ",
      "           d E  ",
      "           h k  ",
      "           a D  ",
      "           a E  ",
      "           a D  ",
      "           d E  "
    ],
    [
      "           a F  ",
      "           d F f",
      "           d F g",
      "           d Feg",
      "           hikII",
      "           a FJJ",
      "           a FJK",
      "           a FJJ",
      "           d FJJ",
      "           d FJK",
      "           d FJJ",
      "           hikII",
      "           a FJJ",
      "           a FJK",
      "           a FJJ",
      "           d FJJ"
    ]
  ]
}