{
  "name": "multi_factory_1_ground",
  "refpalette": "c70cities:multi_factory_1_ground_palette",
  "xsize": 16,
  "zsize": 16,
  "slices": [
    [
      "aaabbbbbbbbbbbzz",
      "zaabbbbbbbbbbbzz",
      "azabbbbbbbbbbbzz",
      "aaabbbbbbbbbbbzz",
      "aaabbbbbbbbbbbzz",
      "aaabbbbbbbbbbbzz",
      "zaabbbbbbbbbbbzz",
      "aaabbbbbbbbbbbzz",
      "zaabbbbbbbbbbbzz",
      "zaabbbbbbbbbbbzz",
      "aaabbbbbbbbbbbzz",
      "aaabbbbbbbbbbbzz",
      "azabbbbbbbbbbbzz",
      "aaabbbbbbbbbbbzz",
      "zaazzzzzzzzzzzzz",
      "aazzzzzzzzzzzzzz"
    ],
    [
      "     ccccd  ce  ",
      "     ccdcd fge  ",
      "     ccdcd fhe  ",
      "   e   i   fje  ",
      "   ec   c   ce  ",
      "   e         e  ",
      "   k       lme  ",
      "   k     nnn e  ",
      "   k    ln!nle  ",
      "   k   lmnnn e  ",
      "   k     l   e  ",
      "   km     oo e  ",
      "   ecppqcrstce  ",
      "   eeeeeeeeeee  ",
      "                ",
      "                "
    ],
    [
      "      uuud  we  ",
      "     dudud   e  ",
      "     xuuud  ye  ",
      "   e   A     e  ",
      "   ec   c   ce  ",
      "   e         e  ",
      "   k         e  ",
      "   k     nnn e  ",
      "   k       n e  ",
      "   k     nnn e  ",
      "   k         e  ",
      "   km        e  ",
      "   ec   c ooce  ",
      "   eeeeeeeeeee  ",
      "                ",
      "                "
    ],
    [
      "   k  BBBy   e  ",
      "   k  BBBy   e  ",
      "   k  BBBy  Ce  ",
      "   e         e  ",
      "   ec   c   ce  ",
      "   e         e  ",
      "   km        e  ",
      "   k     nn  e  ",
      "   k       n e  ",
      "   k     lnn e  ",
      "   k         e  ",
      "   k         e  ",
      "   ecm  c  mce  ",
      "   eeDEFeDEFee  ",
      "                ",
      "                "
    ],
    [
      "  IeJ        e  ",
      "  IeJ       Ke  ",
      "  IeJ      LMe  ",
      "   e         e  ",
      "   ec   c   ce  ",
      "   em        e  ",
      "  IeJ        e  ",
      "  IeJ    NNN e  ",
      "  IeJ    N N e  ",
      "  IeJ    NNN e  ",
      "  IeJ        e  ",
      "  IeJ   O   Oe  ",
      "   ecOOOcOOOce  ",
      "   eeeeeeeeeee  ",
      "                ",
      "                "
    ],
    [
      "   e         e  ",
      "   e         e  ",
      "   e         e  ",
      "   e         e  ",
      "   ec   c   ce  ",
      "   e         e  ",
      "   e         e  ",
      "   eO   ONNNOe  ",
      "   eOOOOON NOe  ",
      "   eO   ONNNOe  ",
      "   eP   P   Pe  ",
      "   eQQQQQQQQQe  ",
      "   eQQQQQQQQQe  ",
      "   RRRRRRRRRRR  ",
      "                ",
      "                "
    ]
  ]
}