{
  "name": "multi_clubhouse1_2_base1",
  "refpalette": "c70cities:multi_clubhouse1_2_base1_palette",
  "xsize": 16,
  "zsize": 16,
  "slices": [
    [
      "vaa   bccccccb  ",
      "vaa   bccccccb  ",
      "vdbbbbbbbbbbbbbb",
      "vebf  bggggggbgg",
      "vebf  bg    gbg ",
      "vebf  bg    gbg ",
      "vebf  bg    gbg ",
      "vebf  bg    gbg ",
      "vebf  bggggggbgg",
      "vdbbbbbbbbbbbbbb",
      "vaahij          ",
      "vaahij          ",
      "vaa             ",
      "vaa             ",
      "vaa  klm  m klkm",
      "vvvvvvvvvvvvvvvv"
    ],
    [
      "vaa             ",
      "vaannnnnnnnnnnnn",
      "vopppppppppppppp",
      "vqprrrrrrrrrrrrr",
      "vqprrrrrrrrrrrrr",
      "vqprrrrrrrrrrrrr",
      "vqprrrrrrrrrrrrr",
      "vqprrrrrrrrrrrrr",
      "vqprrrrrrrrrrrrr",
      "vopssppppppppppp",
      "vaa             ",
      "vaa             ",
      "vaa             ",
      "vaa             ",
      "vaa  klm    klmm",
      "vvvvvvvvvvvvvvvv"
    ],
    [
      "vaa             ",
      "vaa             ",
      "voltttuttttttutt",
      "vq              ",
      "vq              ",
      "vq     w      w ",
      "vq   xy    x y  ",
      "vq   wyxA  BxC A",
      "vq    D E  F y E",
      "vol  IlIIIIIIlII",
      "vaa             ",
      "vaa             ",
      "vaa             ",
      "vaa             ",
      "vaa   lk     lm ",
      "vvvvvvvvvvvvvvvv"
    ],
    [
      "vaf             ",
      "va              ",
      "voltttuttttttutt",
      "vq              ",
      "vq              ",
      "vq              ",
      "vq    J      y  ",
      "vq    y      w  ",
      "vq    y      K  ",
      "vol   l      l  ",
      "va              ",
      "va              ",
      "va              ",
      "va              ",
      "va    lk     l  ",
      "vvvvvvvvvvvvvvvv"
    ],
    [
      "va              ",
      "va              ",
      "voltttuttttttutt",
      "vqg             ",
      "vqg             ",
      "vqg             ",
      "vqg             ",
      "vqg             ",
      "vqg             ",
      "vol   l      l  ",
      "va              ",
      "va              ",
      "va              ",
      "va              ",
      "va    l      l  ",
      "vvvvvvvvvvvvvvvv"
    ],
    [
      "va              ",
      "va              ",
      "voltttuttttttutt",
      "vLgggggggggggggg",
      "vLggggMggggggMgg",
      "vLgggggggggggggg",
      "vLgggggggggggggg",
      "vLggggNggggggMgg",
      "vLgggggggggggggg",
      "volOOOl      l  ",
      "va              ",
      "va              ",
      "va              ",
      "va              ",
      "va    l      l  ",
      "vvvvvvvvvvvvvvvv"
    ]
  ]
}