{
  "name": "multi_laboratory1_10_base2",
  "refpalette": "c70cities:multi_laboratory1_10_base2_palette",
  "xsize": 16,
  "zsize": 16,
  "slices": [
    [
      "vvvvvvvvvvvvvvvv",
      "aaaaaaaaaaaaaaav",
      "bbbbbbbbbbbbbcav",
      "    d========cav",
      "  e d========cav",
      "ddddd========cav",
      "    d========cav",
      "    d========cav",
      "    d========cav",
      "    d========cav",
      "    d========cav",
      " f  d========cav",
      " fggd========cav",
      "hhhhd========cav",
      "hhhhd========cav",
      "dddddiiiiiiiicav"
    ],
    [
      "vvvvvvvvvvvvvvvv",
      "aaaaaaaaaaaaaaav",
      "bbbbbbbbbbbbbcav",
      "  jklmnooo pqbav",
      "   klr      sbav",
      "lllldtu     !bav",
      "    lw      qbav",
      "    lx yyy  sbav",
      "    lx ABA  wbav",
      "    lC ABA pqbav",
      "    lD ABA  Ebav",
      "hh  lF BsB Cwbav",
      "ggI l   J    bav",
      "    l       Kbav",
      "    L       Kbav",
      "Mllldllllllllcav"
    ],
    [
      "vvvvvvvvvvvvvvvv",
      "aaaaaaaaaaaaaaav",
      "bbbbbbbbbbbbbcav",
      " j  l      pqbav",
      "    l       Ebav",
      "lllldt      wbav",
      "    lw     pqbav",
      "    lw yyy  sbav",
      "    l  NNN  wbav",
      "hh  l  NNO  qbav",
      "ggI l  NNN  sbav",
      "  I l  sss  wbav",
      "    l   P    bav",
      "    l        bav",
      "    Q       Rbav",
      "Sllldllllllllcav"
    ],
    [
      "vvvvvvvvvvvvvvvv",
      "aaaaaaaaaaaaaaav",
      "bbbbbbbbbbbbbcav",
      "j   l       tbav",
      "    l       sbav",
      "lllldt      wbav",
      "hhhhlw      tbav",
      "hhhhl  yyy  sbav",
      "ggI l   N   wbav",
      "  I l  NNN  tbav",
      "    l   N   sbav",
      "    l       wbav",
      "    l        bav",
      "    l        bav",
      "T   l       Ubav",
      "Vllldllllllllcav"
    ],
    [
      "vvvvvvvvvvvvvvvv",
      "aaaaaaaaaaaaaaav",
      "bbbbbbbbbbbbbcav",
      "    lt      Wbav",
      "e   lt      tbav",
      "lllldt      tbav",
      "    lt      Wbav",
      "    lXY     tbav",
      " fgglXY     tbav",
      "  hhlXY     Wbav",
      "    lXY     tbav",
      "    lt      tbav",
      "    lttttttttbav",
      "    l       tbav",
      "    l       tbav",
      "lllldllllllllcav"
    ],
    [
      "vvvvvvvvvvvvvvvv",
      "aaaaaaaaaaaaaaav",
      "bbbbbbbbbbbbbcav",
      "    lZZZZZZZZbav",
      " e  lZZZZZZZZbav",
      "lllldZZZZZZZZbav",
      "    lZZZZZZZZbav",
      "    lZZZZZZZZbav",
      "    lZZZZZZZZbav",
      " f  lZZZZZZZZbav",
      " fgglZZZZZZZZbav",
      "  hhlZZZZZZZZbav",
      "    lZZZZZZZZbav",
      "    lZZZZZZZZbav",
      "    lZZZZZZZZbav",
      "lllldllllllllcav"
    ]
  ]
}