{
  "name": "multi_laboratory1_0_base6",
  "refpalette": "c70cities:multi_laboratory1_0_base6_palette",
  "xsize": 16,
  "zsize": 16,
  "slices": [
    [
      "vvvvvvvvvvvvvvvv",
      "vaaaaaaaaaaaaaaa",
      "vabbbbbbbbbbcccc",
      "vabdddddddde    ",
      "vabdddddddde    ",
      "vabddddddddeeeee",
      "vabddddddddffff!",
      "vabddddddddfffff",
      "vabffffffffeffff",
      "vabddddddddfffff",
      "vabddddddddfffff",
      "vabddddddddfffff",
      "vabddddddddfffff",
      "vabddddddddfffff",
      "vabddddddddfffff",
      "vabffffffffeffff"
    ],
    [
      "vvvvvvvvvvvvvvvv",
      "vaaaaaaaaaaaaaaa",
      "vabbbbbbbbbbcccc",
      "vabghghghghi    ",
      "vabg g g g i    ",
      "vabjkjkjkjkeiiii",
      "vab        l   m",
      "vabnnoooonni    ",
      "vabiiiiiiiiep   ",
      "vabqqrrrrqqi   s",
      "vab        t    ",
      "vab        i    ",
      "vabuwuwuwuwix   ",
      "vab y y y yix   ",
      "vabAyAyAyAyi!B  ",
      "vaeiiiiiiiieiiiC"
    ],
    [
      "vvvvvvvvvvvvvvvv",
      "vaaaaaaaaaaaaaaa",
      "vabbbbbbbbbbcccc",
      "vabg g g g i    ",
      "vabg g g g i    ",
      "vabjDjDjDjDeiiii",
      "vab        E FIm",
      "vabJKKKKKKJi    ",
      "vabiiiiiiiie   s",
      "vabJLLLLLLMi    ",
      "vab        N    ",
      "vab        i    ",
      "vabOwOwOwOwi    ",
      "vab y y y yi    ",
      "vab y y y yi    ",
      "vaeiiiiiiiieiiiP"
    ],
    [
      "vvvvvvvvvvvvvvvv",
      "vaaaaaaaaaaaaaaa",
      "vabbbbbbbbbbcccc",
      "vabg g g g i    ",
      "vabg g g g i    ",
      "vabjjjjjjjjiiiii",
      "vab        i QRm",
      "vab KKKKKK i   s",
      "vabiiiiiiiie    ",
      "vab LLLLLL i    ",
      "vab        i    ",
      "vab        i    ",
      "vabwwwwwwwwi    ",
      "vab y y y yi    ",
      "vab y y y yi    ",
      "vaeiiiiiiiieiiiS"
    ],
    [
      "vvvvvvvvvvvvvvvv",
      "vaaaaaaaaaaaaaaa",
      "vabbbbbbbbbbcccc",
      "vabTUTUTUTUi    ",
      "vabTTTTTTTTi    ",
      "vabTTTTTTTTiiiii",
      "vabTTTTTTTTi  VW",
      "vabTTTTTTTTi    ",
      "vabiiiiiiiie    ",
      "vabTTTTTTTTi    ",
      "vabTTTTTTTTi    ",
      "vabTTTTTTTTi    ",
      "vabTTTTTTTTi    ",
      "vabTTTTTTTTi    ",
      "vabUTUTUTUTi    ",
      "vaeiiiiiiiieiiii"
    ],
    [
      "vvvvvvvvvvvvvvvv",
      "vaaaaaaaaaaaaaaa",
      "vabbbbbbbbbbcccc",
      "vab X X X Xi    ",
      "vab X X X Xi    ",
      "vab X X X Xiiiii",
      "vab X X X Xi V  ",
      "vabXXXXXXXXi    ",
      "vabiiiiiiiie    ",
      "vabXXXXXXXXi    ",
      "vabX X X X i    ",
      "vabX X X X i    ",
      "vabX X X X i    ",
      "vabX X X X i    ",
      "vabX X X X i    ",
      "vaeiiiiiiiieiiii"
    ]
  ]
}