{
  "name": "multi_laboratory1_4_base7",
  "refpalette": "c70cities:multi_laboratory1_4_base7_palette",
  "xsize": 16,
  "zsize": 16,
  "slices": [
    [
      "zaaaaaaaaaaaaaaa",
      "zaaaaaaaaaaaaaaa",
      "zaaaaaaaaaaaaaaa",
      "zaaaaaaaaaaaaaaa",
      "zaaaaaaaaaaaaaaa",
      "zaaaaaaaaaaaaaaa",
      "zaaaaaaaaaaaaaaa",
      "zaaaaaaaaaaaaaaa",
      "zaaaaaaaaaaaaaaa",
      "zaaaaaaaaaaaaaaa",
      "zaaaaaaaaaaaaaaa",
      "zaaaaaaaaaaaaaaa",
      "zaaaaaaaaaaaaaaa",
      "zaaaaaaaaaaaaaaa",
      "zaaaaaaaaaaaaaaa",
      "zzzzzzzzzzzzzzzz"
    ],
    [
      "zaaaaaaaaaaaaaaa",
      "zaaaaaaaaaaaaaaa",
      "zaaaaaaaaaaaaaaa",
      "zaaaaaaaaaaaaaaa",
      "zaaaaaaaaaaaaaaa",
      "zaaaaaaaaaaaaaaa",
      "zaaaaaaaaaaaaaaa",
      "zaaaaaaaaaaaaaaa",
      "zaaaaaaaaaaaaaaa",
      "zaaaaaaaaaaaaaaa",
      "zaaaaaaaaaaaaaaa",
      "zaaaaaaaaaaaaaaa",
      "zaaaaaaaaaaaaaaa",
      "zaaaaaaaaaaaaaaa",
      "zaaaaaaaaaaaaaaa",
      "zzzzzzzzzzzzzzzz"
    ],
    [
      "zaaaaaaaaaaaaaaa",
      "zaaaaaaaaaaaaaaa",
      "zaaaaaaaaaaaaaaa",
      "zaaaaaaaaaaaaaaa",
      "zaaaaaaaaaaaaaaa",
      "zaaaaaaaaaaaaaaa",
      "zaaaaaaaaaaaaaaa",
      "zaaaaaaaaaaaaaaa",
      "zaaaaaaaaaaaaaaa",
      "zaaaaaaaaaaaaaaa",
      "zaaaaaaaaaaaaaaa",
      "zaaaaaaaaaaaaaaa",
      "zaaaaaaaaaaaaaaa",
      "zaaaaaaaaaaaaaaa",
      "zaaaaaaaaaaaaaaa",
      "zzzzzzzzzzzzzzzz"
    ],
    [
      "zaaaaaaaaaaaaaaa",
      "zaaaaaaaaaaaaaaa",
      "zaaaaaaaaaaaaaaa",
      "zaaaaaaaaaaaaaaa",
      "zaaaaaaaaaaaaaaa",
      "zaaaaaaaaaaaaaaa",
      "zaaaaaaaaaaaaaaa",
      "zaaaaaaaaaaaaaaa",
      "zaaaaaaaaaaaaaaa",
      "zaaaaaaaaaaaaaaa",
      "zaaaaaaaaaaaaaaa",
      "zaaaaaaaaaaaaaaa",
      "zaaaaaaaaaaaaaaa",
      "zaaaaaaaaaaaaaaa",
      "zaaaaaaaaaaaaaaa",
      "zzzzzzzzzzzzzzzz"
    ],
    [
      "zaaaaaaaaaaaaaaa",
      "zaaaaaaaaaaaaaaa",
      "zaaaaaaaaaaaaaaa",
      "zaaaaaaaaaaaaaaa",
      "zaaaaaaaaaaaaaaa",
      "zaaaaaaaaaaaaaaa",
      "zaaaaaaaaaaaaaaa",
      "zaaaaaaaaaaaaaaa",
      "zaaaaaaaaaaaaaaa",
      "zaaaaaaaaaaaaaaa",
      "zaaaaaaaaaaaaaaa",
      "zaaaaaaaaaaaaaaa",
      "zaaaaaaaaaaaaaaa",
      "zaaaaaaaaaaaaaaa",
      "zaaaaaaaaaaaaaaa",
      "zzzzzzzzzzzzzzzz"
    ],
    [
      "zaaaaaaaaaaaaaaa",
      "zaaaaaaaaaaaaaaa",
      "zaaaaaaaaaaaaaaa",
      "zaaaaaaaaaaaaaaa",
      "zaaaaaaaaaaaaaaa",
      "zaaaaaaaaaaaaaaa",
      "zaaaaaaaaaaaaaaa",
      "zaaaaaaaaaaaaaaa",
      "zaaaaaaaaaaaaaaa",
      "zaaaaaaaaaaaaaaa",
      "zaaaaaaaaaaaaaaa",
      "zaaaaaaaaaaaaaaa",
      "zaaaaaaaaaaaaaaa",
      "zaaaaaaaaaaaaaaa",
      "zaaaaaaaaaaaaaaa",
      "zzzzzzzzzzzzzzzz"
    ]
  ]
}