{
  "name": "multi_megatower1_4_base1",
  "refpalette": "c70cities:multi_megatower1_4_base1_palette",
  "xsize": 16,
  "zsize": 16,
  "slices": [
    [
      "a   vHHHHHHHHHHH",
      "a   vHHHHHHHHHHH",
      "a   vHHHHHHHHHHH",
      "bcddvHHHHHHHHHHH",
      "vvvveHHHHHHeHHHH",
      "vvvvfvvvvvvvvvvv",
      "HHghi           ",
      "HHghi           ",
      "HHghi           ",
      "HHghi           ",
      "vvvvjvvvvvvvvvvv",
      "    e      e    ",
      "                ",
      "                ",
      "                ",
      "                "
    ],
    [
      "a   k           ",
      "a   k           ",
      "a   k           ",
      "adllkm nmon m nm",
      "pqrset ut uet ut",
      "     vvvvvvvvvvv",
      "             wwa",
      "             wwa",
      "             wwa",
      "             wwa",
      "vvvvvvvvvvvvvvvv",
      "    e      e    ",
      "                ",
      "                ",
      "                ",
      "                "
    ],
    [
      "a   k           ",
      "a   k           ",
      "a   k           ",
      "ad  k           ",
      "p xye      e    ",
      "     vvvvvvvvvvv",
      "          wwaHgh",
      "          wwaHgh",
      "          wwaHgh",
      "          wwaHgh",
      "vvvvvvvvvvvvvvvv",
      "    e      e    ",
      "                ",
      "                ",
      "                ",
      "                "
    ],
    [
      "a   k           ",
      "a   k           ",
      "a   k           ",
      "adddk           ",
      "pA  e      e    ",
      "     vvvvvvvvvvv",
      "       wwaHgh   ",
      "       wwaHgh   ",
      "       wwaHgh   ",
      "       wwaHgh   ",
      "vvvvvvvvvvvvvvvv",
      "    e      e    ",
      "                ",
      "                ",
      "                ",
      "                "
    ],
    [
      "a   k           ",
      "a   k           ",
      "a   k           ",
      "adddk           ",
      "ppppe      e    ",
      "     vvvvvvvvvvv",
      "     waHgh      ",
      "     waHgh      ",
      "     waHgh      ",
      "     waHgh      ",
      "vvvvvvvvvvvvvvvv",
      "    e      e    ",
      "                ",
      "                ",
      "                ",
      "                "
    ],
    [
      "e   ewwwwwwwwwww",
      "e   ewwwwwwwwwww",
      "e   ewwwwwwwwwww",
      "edBCewwwwwwwwwww",
      "eeeeeeeeeeeeeeee",
      "wwwwevvvvvvvvvvv",
      "wwwwegh         ",
      "wwwwegh         ",
      "wwwwegh         ",
      "wwwwegh         ",
      "vvvvevvvvvvvvvvv",
      "eeeeeeeeeeeeeeee",
      "    e      e    ",
      "    e      e    ",
      "    e      e    ",
      "    e      e    "
    ]
  ]
}