{
  "name": "multi_condo1_2_floor4",
  "refpalette": "c70cities:multi_condo1_2_floor4_palette",
  "xsize": 16,
  "zsize": 16,
  "slices": [
    [
      "   abcccddefgggg",
      "   abcccddeeeeee",
      " hhhbcccdddddddd",
      "  ijbcccdddddddd",
      "  ijbddddddddddd",
      "  ijbddddddddddd",
      "  ijbddddddddddd",
      "  ijbddddddddddd",
      "  ijbddddddddddd",
      "  ijbddddddddddd",
      "  ijbddddddddddd",
      "  ijbbbbbbbbkkkb",
      "  ijjjjjjjhaaaaa",
      "  iiiiiiiihlllll",
      "          h     ",
      "                "
    ],
    [
      "    m  n  o     ",
      "    bp q  bbbbbb",
      " hhhbr q  stuwx!",
      "   jbqyq As    B",
      "   jbC q As    B",
      "   jbC n       D",
      "   jbC qqqqE   E",
      "   jbF   Iq     ",
      "   jbJ  KLqM N I",
      "   jbOP KLqQ N I",
      "   jbR   IqS    ",
      "   jbbTTTbbbU Ub",
      "   jjjjjjjh     ",
      "          hlllll",
      "          h     ",
      "                "
    ],
    [
      "    l  V  W     ",
      "    b Xq  bbbbbb",
      " hhhbY q   Z 0 1",
      "    bq2q        ",
      "    bC q       3",
      "    bC V  4     ",
      "    bC qqqq5   5",
      "    b    !q     ",
      "    b     q    6",
      "    b7    q     ",
      "    b     q     ",
      "    bbUUUbbbU Ub",
      "          h     ",
      "          h     ",
      "          h     ",
      "                "
    ],
    [
      "    l  q  8     ",
      "    b  q  bbbbbb",
      " hhhb9 q        ",
      "    bqqq        ",
      "    b@ q        ",
      "    b  q        ",
      "    b  qqqq     ",
      "    b     q     ",
      "    b     q     ",
      "    b     q     ",
      "    b     q     ",
      "    bbUUUbbbUUUb",
      "          h     ",
      "          h     ",
      "          h     ",
      "                "
    ],
    [
      "    b  q  b     ",
      "    b  q  bbbbbb",
      " hhhb  q        ",
      "   #bqqq        ",
      "   #b  q        ",
      "   #b  q        ",
      "   #b  qqqq     ",
      "   #b     q     ",
      "   #b     q     ",
      "   #b     q     ",
      "   #b     q     ",
      "   #bbbbbbbbbbbb",
      "   #######h     ",
      "          h     ",
      "          h     ",
      "                "
    ],
    [
      "    b$$$$$b     ",
      "    b$$$$$bbbbbb",
      " hhhb$$$$$$$$$$$",
      "   %b$$$$$$$$$$$",
      "   %b$$$$$$$$$$$",
      "   %b$$$$$$$$$$$",
      "   %b$$$$$$$$$$$",
      "   %b$$$$$$$$$$$",
      "   %b$$$$$$$$$$$",
      "   %b$$$$$$$$$$$",
      "   %b$$$$$$$$$$$",
      "   %bbbbbbbbbbbb",
      "   %%%%%%%h     ",
      "          h^^^^^",
      "          h     ",
      "                "
    ]
  ]
}