{
  "name": "multi_communitycenter_1_base1",
  "refpalette": "c70cities:multi_communitycenter_1_base1_palette",
  "xsize": 16,
  "zsize": 16,
  "slices": [
    [
      "vHHHHHHHHHHHHHHH",
      "vHHHHHHHHHHHHHHH",
      "vHHHHHHHHHHHHHHH",
      "vHHHHHHHHHHHHHHH",
      "vHHHHHHHHHHHHHHH",
      "vHHHHHHHHHHHHHHH",
      "vHHHHHHHHHHHHHHH",
      "vHHHHHHHHHHHHHHH",
      "vHHHHHHHHHHHHHHH",
      "vHHHHHHHHHHHHHHH",
      "vHHHHHHHHHHHHHHH",
      "vHHHHHHHHHHHHHHH",
      "vHHHHHHHHHHHHHHH",
      "vHHHHHHHHHHHHHHH",
      "vHHHHHHHHHHHHHHH",
      "vHHHHHHabHHHHHHH"
    ],
    [
      "vcccc     d    e",
      "vcccc fgfgd    e",
      "vcccc hihid    e",
      "vcccc     d    e",
      "vccccjfgfgj    j",
      "vcccc           ",
      "vcccc           ",
      "vcccc           ",
      "vcccc           ",
      "vcccc           ",
      "vcccc           ",
      "vccccjhihij    j",
      "vcccc     d    e",
      "vcccc fgfgd    e",
      "vcccc hihid    e",
      "vcccc     d    e"
    ],
    [
      "vcccc           ",
      "vcccc           ",
      "vcccc           ",
      "vcccc           ",
      "vccccj    j    j",
      "vcccc           ",
      "vcccc           ",
      "vcccc           ",
      "vcccc           ",
      "vcccc           ",
      "vcccc           ",
      "vccccj    j    j",
      "vcccc           ",
      "vcccc           ",
      "vcccc           ",
      "vcccc           "
    ],
    [
      "vcccc           ",
      "vcccc           ",
      "vcccc           ",
      "vcccc           ",
      "vccccj    j    j",
      "vcccc           ",
      "vcccc           ",
      "vcccc           ",
      "vcccc           ",
      "vcccc           ",
      "vcccc           ",
      "vccccj    j    j",
      "vcccc           ",
      "vcccc           ",
      "vcccc           ",
      "vcccc           "
    ],
    [
      "vccccj    j    j",
      "vccccj    j    j",
      "vccccj    j    j",
      "vccccj    j    j",
      "vccccjkkkkjkkkkj",
      "vccccj    j    j",
      "vccccj    j    j",
      "vccccj    j    j",
      "vccccj    j    j",
      "vccccj    j    j",
      "vccccj    j    j",
      "vccccjkkkkjkkkkj",
      "vccccj    j    j",
      "vccccj    j    j",
      "vccccj    j    j",
      "vccccj    j    j"
    ],
    [
      "vccccccccccccccc",
      "vccccccccccccccc",
      "vccccccccccccccc",
      "vccccccccccccccc",
      "vccccccccccccccc",
      "vccccccccccccccc",
      "vccccccccccccccc",
      "vccccccccccccccc",
      "vccccccccccccccc",
      "vccccccccccccccc",
      "vccccccccccccccc",
      "vccccccccccccccc",
      "vccccccccccccccc",
      "vccccccccccccccc",
      "vccccccccccccccc",
      "vccccccccccccccc"
    ]
  ]
}