{
  "name": "multi_flatapartment_0_floor2",
  "refpalette": "c70cities:multi_flatapartment_0_floor2_palette",
  "xsize": 16,
  "zsize": 16,
  "slices": [
    [
      "                ",
      "     abbbbabbbab",
      "     bcccccccccc",
      "     bcddddddddd",
      "     bcddddddddd",
      "     acddddddddd",
      "     bcddddddddd",
      "     bcddddddddd",
      "     bcddddddddd",
      "     bcddddddddd",
      "     acddddddddd",
      "     bcddddddddd",
      "     bcddddddddd",
      "     bcccccccccc",
      "     abbbbabbbab",
      "                "
    ],
    [
      "                ",
      "     abeebabebab",
      "     b    f     ",
      "     e    g hhg ",
      "     b ij g   gk",
      "     aggglg   gg",
      "     b    m nngo",
      "     e    gggggo",
      "     e pp gq  r ",
      "     b sstguw g ",
      "     aggggguw g ",
      "     b xy A   g ",
      "     e    ggggg ",
      "     b    f     ",
      "     abeebabebab",
      "                "
    ],
    [
      "                ",
      "     abBBbabBbab",
      "     b    C     ",
      "     B    g   g ",
      "     b D  g   g ",
      "     agggEg   gg",
      "     b    F IIg ",
      "     B    ggggg ",
      "     B    g!  J ",
      "     b    g   g ",
      "     aggggg   g ",
      "     b K  L   g ",
      "     B    ggggg ",
      "     b    C     ",
      "     abBBbabBbab",
      "                "
    ],
    [
      "                ",
      "     abBBbabBbab",
      "     b    g     ",
      "     B    g   g ",
      "     b    g   g ",
      "     aggggg   gg",
      "     b    g IIg ",
      "     B    ggggg ",
      "     B    g   g ",
      "     b    g   g ",
      "     aggggg   g ",
      "     b    g   g ",
      "     B    ggggg ",
      "     b    g     ",
      "     abBBbabBbab",
      "                "
    ],
    [
      "                ",
      "     abbbbabbbab",
      "     bMMMMg   g ",
      "     bMMMMg   g ",
      "     bMMMMg N g ",
      "     aggggg   gg",
      "     b    g   g ",
      "     b    ggggg ",
      "     b    g   g ",
      "     b    g   g ",
      "     aggggg   gg",
      "     bMMMMg   g ",
      "     bMMMMggggg ",
      "     bMMMMg   g ",
      "     abbbbabbbab",
      "                "
    ],
    [
      "                ",
      "     OPPPPOPPPOP",
      "     Pcccccccccc",
      "     Pcddddddddd",
      "     Pcddddddddd",
      "     Ocddddddddd",
      "     Pcddddddddd",
      "     Pcddddddddd",
      "     Pcddddddddd",
      "     Pcddddddddd",
      "     Ocddddddddd",
      "     Pcddddddddd",
      "     Pcddddddddd",
      "     Pcccccccccc",
      "     OPPPPOPPPOP",
      "                "
    ]
  ]
}