{
  "name": "multi_laboratory1_11_base1",
  "refpalette": "c70cities:multi_laboratory1_11_base1_palette",
  "xsize": 16,
  "zsize": 16,
  "slices": [
    [
      "aaaaaaaaaaaaabcz",
      "aaaaaaaaaaaaabcz",
      "aaaaaaaaaaaaabcz",
      "aaaaaaaaaaaaabcz",
      "aaaaaaaaaaaaabcz",
      "aaaaaaaaaaaaabcz",
      "aaaadaaaaaaaabcz",
      "aaaaaaaaaaaaabcz",
      "aaaaaaaaaaaaabcz",
      "aaaaaaaaaaaaabcz",
      "aaaaaaaaaaaaabcz",
      "aaaaaaaaaaaaabcz",
      "eaaaaaaaaaaaabcz",
      "eaaadaaaaaaaabcz",
      "feaaaaaaaaaaabcz",
      " eaaaaaaaaaaabcz"
    ],
    [
      "    ghiijkiihbcz",
      "    g       ibcz",
      "    g       ibcz",
      "    l  iii  mbcz",
      "    g       nbcz",
      "    g       ibcz",
      "   od  iii  ibcz",
      "p   q       hbcz",
      "    q       ibcz",
      "    q  iii  mbcz",
      "    q       nbcz",
      "    qr      !bcz",
      "st  quw    xhbcz",
      "so  dyy    yybcz",
      "os  yA      Bbcz",
      " s  yAC  D  Bbcz"
    ],
    [
      "    ghiiEFiihbcz",
      "    g       ibcz",
      "    g       ibcz",
      "    I  iii  Jbcz",
      "    g       Kbcz",
      "    g       ibcz",
      "   Ld  iii  ibcz",
      "    q       hbcz",
      "    q       ibcz",
      "    q  iii  Jbcz",
      "    q       Kbcz",
      "    q       ibcz",
      "s   q M     hbcz",
      "sL  dyy    yybcz",
      "os  qNO     Pbcz",
      " s  q       Pbcz"
    ],
    [
      "    ghQQR QQhbcz",
      "    g       Qbcz",
      "    g       Qbcz",
      "    g  QQQ  Rbcz",
      "    g       Sbcz",
      "    g       Qbcz",
      "   Ld  QQQ  Qbcz",
      "    q       hbcz",
      "    q       Qbcz",
      "    q  QQQ  Tbcz",
      "    q        bcz",
      "    q       Qbcz",
      "s   q       hbcz",
      "sL  dyy    yybcz",
      "os  q       Ubcz",
      " s  q       Ubcz"
    ],
    [
      "    gV      Vbcz",
      "    g        bcz",
      "    g        bcz",
      "    g        bcz",
      "    g        bcz",
      "    g        bcz",
      "    d        bcz",
      "    q       Vbcz",
      "    q        bcz",
      "    q        bcz",
      "    q        bcz",
      "    q        bcz",
      "s   q       Vbcz",
      "s   dyy    yybcz",
      "os  q        bcz",
      " s  q        bcz"
    ],
    [
      "WWWWXWWWWWWWWbcz",
      "WWWWXWYWWWYWWbcz",
      "WWWWXWYWWWYWWbcz",
      "WWWWXWYWWWZWWbcz",
      "WWWWXWYWWWYWWbcz",
      "WWWWXWWWWWWWWbcz",
      "WWWWdWWWWWWWWbcz",
      "WWWWXWWWWWWWWbcz",
      "WWWWXWYWWWYWWbcz",
      "WWWWXWYWWWYWWbcz",
      "WWWWXWYWWWYWWbcz",
      "WWWWXWYWWWYWWbcz",
      "0WWWXWWWWWWWWbcz",
      "0WWWdyyyyyyyybcz",
      "10WWXWWWWWWWWbcz",
      " 0WWXWYWWWYWWbcz"
    ]
  ]
}