{
  "name": "multi_laboratory1_12_base2",
  "refpalette": "c70cities:multi_laboratory1_12_base2_palette",
  "xsize": 16,
  "zsize": 16,
  "slices": [
    [
      " abbbbbbbbbbbcdz",
      " abbbbbbbbbbbcdz",
      " abbbbbbbbbbbcdz",
      "eabbbbbbbbbbbcdz",
      "abbbfbbbbbbbbcdz",
      "abbbbbbbbbbbbcdz",
      "bbbbbbbbbbbbbcdz",
      "bbbbbbbbbbbbbcdz",
      "bbbbbbbbbbbbbcdz",
      "bbbbbbbbbbbbbcdz",
      "bbbbbbbbbbbbbcdz",
      "bbbbfbbbbbbbbcdz",
      "bbbbbbbbbbbbbcdz",
      "bbbbbbbbbbbbbcdz",
      "bbbbbbbbbbbbbcdz",
      "bbbbbbbbbbbbbcdz"
    ],
    [
      " g  h    i jkldz",
      " g  m     njkldz",
      " g  o       jjdz",
      "eg  p        cdz",
      "ge  f q     rcdz",
      "gs  p tu    jjdz",
      "    pwxxx  jyldz",
      "    pAxxxB jyldz",
      "    p  C  D jjdz",
      "    pE   qB  cdz",
      "    p!FII I rcdz",
      "J  efppppppppcdz",
      "    p       Kcdz",
      "    o        cdz",
      "    L    i  Mcdz",
      "    N     BOMcdz"
    ],
    [
      " g  P      gkldz",
      " g  Q      gkldz",
      " g  o       gjdz",
      "eg  p       Rcdz",
      "gS  f       rcdz",
      "g   p       gjdz",
      "    T UV   gyldz",
      "    TV WV  gyldz",
      "    T       gjdz",
      "    T       Rcdz",
      "    p       rcdz",
      "   Sfppppppppcdz",
      "    p        cdz",
      "    o        cdz",
      "    X       Ycdz",
      "    Z       0cdz"
    ],
    [
      " g  o      gkldz",
      " g  o      gkldz",
      " g  o       gjdz",
      "eg  p        cdz",
      "gS  f       rcdz",
      "g   p       gjdz",
      "    T      gyldz",
      "    T      gyldz",
      "    T       gjdz",
      "    T        cdz",
      "    p       rcdz",
      "   Sfppppppppcdz",
      "    p        cdz",
      "    o        cdz",
      "    o        cdz",
      "    o        cdz"
    ],
    [
      " g  p      g1ldz",
      " g  p      g1ldz",
      " g  p       gjdz",
      "eg  p       Rcdz",
      "g   f       2cdz",
      "g   p       gjdz",
      "    p      g3ldz",
      "    p      g3ldz",
      "    p       gjdz",
      "    p       Rcdz",
      "    p  4  5 2cdz",
      "    fppppppppcdz",
      "    p        cdz",
      "    p       6cdz",
      "    p        cdz",
      "    p        cdz"
    ],
    [
      " g77899@99@j#ldz",
      " g77899@99$j#ldz",
      " g77899@99@9jjdz",
      "eg77899999999cdz",
      "g777f99999999cdz",
      "g777899$99$9jjdz",
      "7777899@99@j#ldz",
      "7777899@99@j#ldz",
      "7777899@99$9jjdz",
      "7777899999999cdz",
      "77778%%%%%%%%cdz",
      "7777fppppppppcdz",
      "77778%999999%cdz",
      "77@78%999999%cdz",
      "77@78%9@99@9%cdz",
      "77@78%9$99@9%cdz"
    ]
  ]
}