{
  "name": "multi_clubhouse1_5_base2",
  "refpalette": "c70cities:multi_clubhouse1_5_base2_palette",
  "xsize": 16,
  "zsize": 16,
  "slices": [
    [
      "vvvvvvvvvvvvvvvv",
      "vvvvvvvvvvvvvvvv",
      "vvvvvvvvvvvvvvvv",
      "aaaaaaaaaaaaaaaa",
      "aaaaaaaaaaaaaaaa",
      "aaaaaaaaaaaaaaaa",
      "aaaaaaaaaaaaaaaa",
      "aaaaaaaaaaaaaaaa",
      "aaaaaaaaaaaaaaaa",
      "vvvvvvvvvvvvvvvv",
      "vvvvvvvvvvvvvvvv",
      "vvvvvvvvvvvvvvvv",
      "vvvvvvvvvvvvvvvv",
      "vvvvvvvvvvvvvvvv",
      "vvvvvvvvvvvvvvvv",
      "vvvvvvvvvvvvvvvv"
    ],
    [
      "bbbbbcbaacbbbGGG",
      "bbbbcccaaccbbbbb",
      "aaaadaaaaaadaaaa",
      "effefffggfffefff",
      "fffffeffffffffff",
      "fffffffggffffefe",
      "fffffffggfffffff",
      "ffffffffffffffff",
      "fefefffggeffffee",
      "aaaadaaaaaadaaaa",
      "bcccccbcccGccccb",
      "cccbGccccbcccGcc",
      "bbbbbbbbbbbbbbbb",
      "GGGGhGGGGGG!GGGG",
      "iiiijiiiiiijiiii",
      "vvvvvvvvvvvvvvvv"
    ],
    [
      "klmn  o p   nmqm",
      "nnnn   o    nnnn",
      "    d      d    ",
      "     r ss       ",
      "  r       r   r ",
      "r      ss  r    ",
      "    r  ss       ",
      "r               ",
      "  r    ss r r   ",
      "    d      d    ",
      "               t",
      "   t     t      ",
      "ququuuquwwuuququ",
      " m m m m mm mm m",
      "xxxxjxxxxxxjxxxx",
      "vvvvvvvvvvvvvvvv"
    ],
    [
      " yA          A A",
      "                ",
      "    d      d    ",
      "                ",
      "                ",
      "                ",
      "                ",
      "                ",
      "                ",
      "    d      d    ",
      "                ",
      "                ",
      "                ",
      " A A A A AA AA A",
      "xxxxjxxxxxxjxxxx",
      "vvvvvvvvvvvvvvvv"
    ],
    [
      "                ",
      "                ",
      "    d      d    ",
      "                ",
      "                ",
      "                ",
      "                ",
      "                ",
      "                ",
      "    d      d    ",
      "                ",
      "                ",
      "                ",
      "                ",
      "x BxjBxxxxxjBxxx",
      "vvvvvvvvvvvvvvvv"
    ],
    [
      "                ",
      "                ",
      "    d      d    ",
      "                ",
      "                ",
      "                ",
      "                ",
      "                ",
      "                ",
      "    d      d    ",
      "                ",
      "                ",
      "                ",
      "                ",
      "x BBjBxxxxBjBxxx",
      "vvvvvvvvvvvvvvvv"
    ]
  ]
}