{
  "name": "multi_laboratory1_14_base6",
  "refpalette": "c70cities:multi_laboratory1_14_base6_palette",
  "xsize": 16,
  "zsize": 16,
  "slices": [
    [
      "aaaabacdddddcaez",
      "faaaaacdddddcaez",
      "aaaaaacdddddcaez",
      "aaaaaacdddddcaez",
      "aaaaaacdddddcaez",
      "aaaaaacdddddcaez",
      "aaaaaacdddddcaez",
      "aaaabacdddddcaez",
      "aaaaaacccccccaez",
      "aaaaaaaaaaaaaaez",
      "aaaaaaaaaaaaaaez",
      "aaaaaaaaaaaaaaez",
      "aaaaaaaaaaaaaaez",
      "eeeeeaaaaaaaaaez",
      "ggggeeeeeeeeeeez",
      "zzzzzzzzzzzzzzzz"
    ],
    [
      "hijkb     l   dz",
      " mnop q rs    tz",
      "h   p    us   tz",
      "w  np   s   q tz",
      " n  p  x  rx  tz",
      "y ABp         tz",
      "C yhp   l  s  tz",
      " nhhb         dz",
      " m  p         tz",
      "    p       D tz",
      "    E  F      tz",
      "    I         tz",
      "    p        Jtz",
      "eeeepKKLLM NL!tz",
      "ggggetttttttttez",
      "zzzzzzzzzzzzzzzz"
    ],
    [
      "    b         dz",
      "    O q       tz",
      "    O         tz",
      "    O       q tz",
      "    O  xP Qx  tz",
      "    O         tz",
      "    O         tz",
      "  RSb         dz",
      "    p       D tz",
      "    p         tz",
      "    T         tz",
      "    U         tz",
      "    p         tz",
      "eeeep         tz",
      "ggggetttttttttez",
      "zzzzzzzzzzzzzzzz"
    ],
    [
      "    b    V    dz",
      "    O q  V    tz",
      "    O   WXW   tz",
      "    O    V  q tz",
      "    O  QxxxP  tz",
      "    O         tz",
      "    O    X    tz",
      "   Yb   V V D dz",
      "    p   V V   tz",
      "    p         tz",
      "    Z         tz",
      "    Z         tz",
      "    p         tz",
      "eeeep         tz",
      "ggggetttttttttez",
      "zzzzzzzzzzzzzzzz"
    ],
    [
      "   0b 11232   dz",
      "      113 3   tz",
      "    O  43 35  tz",
      "    O   363 q tz",
      "    O   232   tz",
      "    O   7 7   tz",
      "    O   838 D tz",
      "    b  9@V@#  dz",
      "    p  9$  #  tz",
      "    p         tz",
      "    Z         tz",
      "    Z         tz",
      "    p         tz",
      "eeeep         tz",
      "ggggetttttttttez",
      "zzzzzzzzzzzzzzzz"
    ],
    [
      "   %b  9383#  dz",
      "    O  ^&8&*  tz",
      "    o  4&7&5  tz",
      "    O  ^&8&*q tz",
      "    O  9323#  tz",
      "    O  9 ( #D tz",
      "    O  93@3#  tz",
      "    b   9$#   dz",
      "    p         tz",
      "    p         tz",
      "    Z         tz",
      "    Z         tz",
      "    p         tz",
      "eeeep         tz",
      "ggggetttttttttez",
      "zzzzzzzzzzzzzzzz"
    ]
  ]
}