{
  "name": "multi_laboratory1_2_floor1",
  "refpalette": "c70cities:multi_laboratory1_2_floor1_palette",
  "xsize": 16,
  "zsize": 16,
  "slices": [
    [
      "        a bcdd  ",
      "        e bcdd  ",
      "        a bcdd  ",
      "        a bcdd  ",
      "        fghcdd  ",
      "        fbbcddd ",
      "        fbbcddd ",
      "        fbbcddd ",
      "        fbbcdddd",
      "        fbbcdddd",
      "        fbbcdddd",
      "        fghciidd",
      "        fbbczzid",
      "        fbbczzid",
      "        jbbczzid",
      "        fbbczzid"
    ],
    [
      "        a  k l  ",
      "        a  k l  ",
      "        a  k l  ",
      "        a  k l  ",
      "        j  m ln ",
      "        f  k  l ",
      "        f  k  l ",
      "        f  k  ln",
      "        f  k   l",
      "        f  k    ",
      "        f  k    ",
      "        f  moo  ",
      "        f  kpqo ",
      "        f  kqpo ",
      "        f  kpqo ",
      "        f  k ro "
    ],
    [
      "        a       ",
      "        e       ",
      "        e       ",
      "        a       ",
      "        f       ",
      "        f       ",
      "        f       ",
      "        f       ",
      "        j       ",
      "        f       ",
      "        f       ",
      "        f       ",
      "        j       ",
      "        f       ",
      "        f       ",
      "        f       "
    ],
    [
      "        a       ",
      "        a       ",
      "        a       ",
      "        e       ",
      "        f       ",
      "        f       ",
      "        f       ",
      "        f       ",
      "        f       ",
      "        f       ",
      "        f       ",
      "        f       ",
      "        f       ",
      "        f       ",
      "        f       ",
      "        f       "
    ],
    [
      "                ",
      "                ",
      "                ",
      "                ",
      "        s       ",
      "        s       ",
      "        s       ",
      "        f       ",
      "        f       ",
      "        f       ",
      "        f       ",
      "        f       ",
      "        f       ",
      "        f       ",
      "        f       ",
      "        f       "
    ],
    [
      "                ",
      "                ",
      "                ",
      "                ",
      "                ",
      "                ",
      "                ",
      "                ",
      "                ",
      "        ~       ",
      "        s       ",
      "        s       ",
      "        s       ",
      "        f       ",
      "        f       ",
      "        f       "
    ]
  ]
}