{
  "name": "multi_megatower1_3_floor2",
  "refpalette": "c70cities:multi_megatower1_3_floor2_palette",
  "xsize": 16,
  "zsize": 16,
  "slices": [
    [
      "                ",
      "                ",
      "                ",
      "                ",
      "                ",
      "                ",
      "                ",
      "                ",
      "                ",
      "                ",
      "                ",
      "    a      a    ",
      "bcccdbbbcccdbbbc",
      "eeeefeeeeeefeeee",
      "ghhheeeeeeeeeeee",
      "g   eeeeeeeeeeee"
    ],
    [
      "                ",
      "                ",
      "                ",
      "                ",
      "                ",
      "                ",
      "                ",
      "                ",
      "                ",
      "                ",
      "                ",
      "    a      a    ",
      "bcccdbbbcccdbbbc",
      "ijklfmmmmmmfmmmm",
      "ghhhgn  o  pqrss",
      "g   gn tut pqqrr"
    ],
    [
      "                ",
      "                ",
      "                ",
      "                ",
      "                ",
      "                ",
      "                ",
      "                ",
      "                ",
      "                ",
      "                ",
      "    a      a    ",
      "bcccdbbbcccdbbbc",
      "i   fmmmmmmfmmmm",
      "ghhhgn  w  pqx  ",
      "g   gn uuu pqryr"
    ],
    [
      "                ",
      "                ",
      "                ",
      "                ",
      "                ",
      "                ",
      "                ",
      "                ",
      "                ",
      "                ",
      "                ",
      "    a      a    ",
      "bcccdbbbcccdbbbc",
      "i   fmmmmmmfmmmm",
      "ghhhgn     ABBBB",
      "g   gC     A DEx"
    ],
    [
      "                ",
      "                ",
      "                ",
      "                ",
      "                ",
      "                ",
      "                ",
      "                ",
      "                ",
      "                ",
      "                ",
      "    a      a    ",
      "bcccdbbbcccdbbbc",
      "i   fAAAAAAfFFFF",
      "ghhhg      pBBBB",
      "g   g      p xx "
    ],
    [
      "                ",
      "                ",
      "                ",
      "                ",
      "                ",
      "                ",
      "                ",
      "                ",
      "                ",
      "                ",
      "                ",
      "    a      a    ",
      "bcccdbbbcccdbbbc",
      "IIIIfIIIIIIf    ",
      "JKKKJLMLLLLJBBBB",
      "J   J      JBBBB"
    ]
  ]
}