{
  "name": "multi_militarybase_1_base4",
  "refpalette": "c70cities:multi_militarybase_1_base4_palette",
  "xsize": 16,
  "zsize": 16,
  "slices": [
    [
      "vaaaaaaaaaaaabcc",
      "vaaaaaaaaaaaabcc",
      "vvbbbbbbbbbbbvbb",
      "vvvvvvvvvvvvvvzz",
      "vzzzzzzzzzzzzzzz",
      "vzzzzzzzzzzzzzzz",
      "vzzzzzzzzzzzzzzz",
      "vzzzzzzzzzzzzzzz",
      "vzzzzzzzzzzzzzzz",
      "vzzzzzzzzzzzzzzz",
      "vzzzzzzzzzzzzzzz",
      "vzzzzzzzzzzzzzzz",
      "vzzzzzzzzzzzzzzz",
      "vzzzzzzzzzzzzzzz",
      "vzzzzzzzzzzzzzzz",
      "vvvvvvvvvvvvvvvv"
    ],
    [
      "v               ",
      "v             dd",
      "vv effg effg vhh",
      "vvvvvvvvvvvvvvzz",
      "vzzzzzzzzzzzzzzz",
      "vzzzzzzzzzzzzzzz",
      "vzzzzzzzzzzzzzzz",
      "vzzzzzzzzzzzzzzz",
      "vzzzzzzzzzzzzzzz",
      "vzzzzzzzzzzzzzzz",
      "vzzzzzzzzzzzzzzz",
      "vzzzzzzzzzzzzzzz",
      "vzzzzzzzzzzzzzzz",
      "vzzzzzzzzzzzzzzz",
      "vzzzzzzzzzzzzzzz",
      "vvvvvvvvvvvvvvvv"
    ],
    [
      "vi              ",
      "v               ",
      "vv           vhh",
      "vvvvvvvvvvvvvvzz",
      "vzzzzzzzzzzzzzzz",
      "vzzzzzzzzzzzzzzz",
      "vzzzzzzzzzzzzzzz",
      "vzzzzzzzzzzzzzzz",
      "vzzzzzzzzzzzzzzz",
      "vzzzzzzzzzzzzzzz",
      "vzzzzzzzzzzzzzzz",
      "vzzzzzzzzzzzzzzz",
      "vzzzzzzzzzzzzzzz",
      "vzzzzzzzzzzzzzzz",
      "vzzzzzzzzzzzzzzz",
      "vvvvvvvvvvvvvvvv"
    ],
    [
      "vj              ",
      "v               ",
      "vv           vhh",
      "vvvvvvvvvvvvvvzz",
      "vzzzzzzzzzzzzzzz",
      "vzzzzzzzzzzzzzzz",
      "vzzzzzzzzzzzzzzz",
      "vzzzzzzzzzzzzzzz",
      "vzzzzzzzzzzzzzzz",
      "vzzzzzzzzzzzzzzz",
      "vzzzzzzzzzzzzzzz",
      "vzzzzzzzzzzzzzzz",
      "vzzzzzzzzzzzzzzz",
      "vzzzzzzzzzzzzzzz",
      "vzzzzzzzzzzzzzzz",
      "vvvvvvvvvvvvvvvv"
    ],
    [
      "v               ",
      "v               ",
      "vv           vhh",
      "vvvvvvvvvvvvvvzz",
      "vzzzzzzzzzzzzzzz",
      "vzzzzzzzzzzzzzzz",
      "vzzzzzzzzzzzzzzz",
      "vzzzzzzzzzzzzzzz",
      "vzzzzzzzzzzzzzzz",
      "vzzzzzzzzzzzzzzz",
      "vzzzzzzzzzzzzzzz",
      "vzzzzzzzzzzzzzzz",
      "vzzzzzzzzzzzzzzz",
      "vzzzzzzzzzzzzzzz",
      "vzzzzzzzzzzzzzzz",
      "vvvvvvvvvvvvvvvv"
    ],
    [
      "vkkkkkkkkkkkklmm",
      "vkkkkkkkkkkkklnn",
      "vvbbbbbbbbbbbvbb",
      "vvvvvvvvvvvvvvzz",
      "vzzzzzzzzzzzzzzz",
      "vzzzzzzzzzzzzzzz",
      "vzzzzzzzzzzzzzzz",
      "vzzzzzzzzzzzzzzz",
      "vzzzzzzzzzzzzzzz",
      "vzzzzzzzzzzzzzzz",
      "vzzzzzzzzzzzzzzz",
      "vzzzzzzzzzzzzzzz",
      "vzzzzzzzzzzzzzzz",
      "vzzzzzzzzzzzzzzz",
      "vzzzzzzzzzzzzzzz",
      "vvvvvvvvvvvvvvvv"
    ]
  ]
}