{
  "name": "multi_laboratory1_10_base5",
  "refpalette": "c70cities:multi_laboratory1_10_base5_palette",
  "xsize": 16,
  "zsize": 16,
  "slices": [
    [
      "zzzzzzzzzzzzzzzz",
      "aaaaaaaaaaaaaaaz",
      "bbbbccccccccccaz",
      "    deeeeeeeecaz",
      "    deeeeeeeecaz",
      "fffffeeeeeeeecaz",
      "    feeeeeeeecaz",
      "    fggggggggcaz",
      "    f   h    caz",
      "    f        caz",
      "    f        caz",
      " i  f        caz",
      " ijjf        caz",
      "kkkkf        caz",
      "kkkkf        caz",
      "ddddfddddddddcaz"
    ],
    [
      "zzzzzzzzzzzzzzzz",
      "aaaaaaaaaaaaaaaz",
      "bbbbccccccccccaz",
      "    dglm lm ncaz",
      "    dgo   o pcaz",
      "ddddfg q q  ncaz",
      "    dglm lm ncaz",
      "    dggggggrgcaz",
      "    d    sssscaz",
      "    d        caz",
      "    d        caz",
      "kk  d        caz",
      "jjt d        caz",
      "    d        caz",
      "    d        caz",
      "ddddfddddddddcaz"
    ],
    [
      "zzzzzzzzzzzzzzzz",
      "aaaaaaaaaaaaaaaz",
      "bbbbccccccccccaz",
      "    dglm lm  caz",
      "    dgu   u wcaz",
      "ddddfg x x   caz",
      "    dglm lm  caz",
      "    dggggggygcaz",
      "    d        caz",
      "kk  d        caz",
      "jjt d        caz",
      "  t d        caz",
      "    d        caz",
      "    d        caz",
      "    d        caz",
      "ddddfddddddddcaz"
    ],
    [
      "zzzzzzzzzzzzzzzz",
      "aaaaaaaaaaaaaaaz",
      "bbbbccccccccccaz",
      "    dg      Acaz",
      "    dg       caz",
      "ddddfg      Bcaz",
      "kkkkdg      Ccaz",
      "kkkkdggggggggcaz",
      "jjt d        caz",
      "  t d        caz",
      "    d        caz",
      "    d        caz",
      "    d        caz",
      "    d        caz",
      "    d        caz",
      "ddddfddddddddcaz"
    ],
    [
      "zzzzzzzzzzzzzzzz",
      "aaaaaaaaaaaaaaaz",
      "bbbbccccccccccaz",
      "    dg       caz",
      "h   dg       caz",
      "ddddfg      Bcaz",
      "    dg     BBcaz",
      "    dggggggggcaz",
      " ijjd        caz",
      "  kkd        caz",
      "    d        caz",
      "    d        caz",
      "    d        caz",
      "    d        caz",
      "    d        caz",
      "ddddfddddddddcaz"
    ],
    [
      "zzzzzzzzzzzzzzzz",
      "aaaaaaaaaaaaaaaz",
      "bbbbccccccccccaz",
      "    dDDDDDDDDcaz",
      " h  dDDDDDDDDcaz",
      "ddddfDDDDDDDDcaz",
      "    dDDDDDDDDcaz",
      "    dddddddddcaz",
      "    dDDDDDDDDcaz",
      " i  dDDDDDDDDcaz",
      " ijjdDDDDDDDDcaz",
      "  kkdDDDDDDDDcaz",
      "    dDDDDDDDDcaz",
      "    dDDDDDDDDcaz",
      "    dDDDDDDDDcaz",
      "ddddfddddddddcaz"
    ]
  ]
}