{
  "name": "multi_megatower1_2_floor14",
  "refpalette": "c70cities:multi_megatower1_2_floor14_palette",
  "xsize": 16,
  "zsize": 16,
  "slices": [
    [
      "   abGccdeeeffff",
      "   abGcceedeffff",
      "   gbGcdceeefhff",
      "   abGcccdedffff",
      "   abGcdcecdccdc",
      "   abGccedeeedcc",
      "   abGccccedcdec",
      "   abGccdddcecce",
      "   abGccdecccdcc",
      "   gbGcdccecdccc",
      "   abGccdccccccc",
      "   abGcccccccccc",
      "   aaagaaaaaagaa",
      "                ",
      "                ",
      "                "
    ],
    [
      "   aijk    l mnn",
      "   aijo    p m!n",
      "   giqo    r hss",
      "   aijo    t    ",
      "   aiuk         ",
      "   aiqo         ",
      "   aijk         ",
      "   aijo         ",
      "   aiqo         ",
      "   giuo         ",
      "   aijk         ",
      "   aijw      w  ",
      "   aaagaaaaaagaa",
      "                ",
      "                ",
      "                "
    ],
    [
      "   aix     l myy",
      "   aix       myy",
      "   giA       hss",
      "   aBx          ",
      "   ai           ",
      "   aiA          ",
      "   aix          ",
      "   aBx          ",
      "   aiA          ",
      "   gB           ",
      "   aix          ",
      "   aix          ",
      "   aaagaaaaaagaa",
      "                ",
      "                ",
      "                "
    ],
    [
      "   ai        m  ",
      "   a         m  ",
      "   gi        hss",
      "   aB           ",
      "   aB           ",
      "   ai           ",
      "   ai           ",
      "   a            ",
      "   ai           ",
      "   gi           ",
      "   ai           ",
      "   aB           ",
      "   aaagaaaaaCD  ",
      "                ",
      "                ",
      "                "
    ],
    [
      "   aB        E  ",
      "   a         E  ",
      "   gi        hss",
      "   a            ",
      "   a            ",
      "   a            ",
      "   ai           ",
      "   a            ",
      "   a            ",
      "   g            ",
      "   ai           ",
      "   a            ",
      "   aaagaCC      ",
      "                ",
      "                ",
      "                "
    ],
    [
      "   C       F h  ",
      "   C       F h  ",
      "   D      IJKhhh",
      "   C       L K  ",
      "   C        MJNN",
      "   C         I  ",
      "   C            ",
      "   C            ",
      "   C            ",
      "   D            ",
      "   C            ",
      "   C            ",
      "   CCC          ",
      "                ",
      "                ",
      "                "
    ]
  ]
}