{
  "name": "multi_laboratory1_2_base2",
  "refpalette": "c70cities:multi_laboratory1_2_base2_palette",
  "xsize": 16,
  "zsize": 16,
  "slices": [
    [
      "zabcccccccccccd ",
      "zabcccccccccccd ",
      "zabcccccccccccd ",
      "zabcccccccccccde",
      "zabccccccccfcccd",
      "zabccccccccccccd",
      "zabccccccccccccc",
      "zabccccccccccccc",
      "zabccccccccccccc",
      "zabccccccccccccc",
      "zabccccccccccccc",
      "zabccccccccfcccc",
      "zabccccccccccccc",
      "zabccccccccccccc",
      "zabccccccccccccc",
      "zabccccccccccccc"
    ],
    [
      "zabghiiii  j  k ",
      "zabl mmmm  n  k ",
      "zabo  h p  q  k ",
      "zabr       s  ke",
      "zab  ttttu f  ek",
      "zab wx  xqys  Ak",
      "zab w   Bu s    ",
      "zab w  y q s    ",
      "zab wx  xq s    ",
      "zab  CCCC  s    ",
      "zab    B   s  D ",
      "zabsssEFsssfe   ",
      "zabI    y  s    ",
      "zabJK      q    ",
      "zabLL    M j    ",
      "zabKN  OP  n    "
    ],
    [
      "zab  QRS   T  k ",
      "zab   UV   W  k ",
      "zab        q  k ",
      "zab        s  ke",
      "zab  tttt  f  Xk",
      "zab wY  Z  s   k",
      "zab w      0    ",
      "zab w    q 0    ",
      "zab wZ  Zq 0    ",
      "zab  CCCC  0    ",
      "zab        s    ",
      "zabsss12sssfX   ",
      "zab        s    ",
      "zab        q    ",
      "zab3       T    ",
      "zab4       W    "
    ],
    [
      "zab        q  k ",
      "zab        q  k ",
      "zab        q  k ",
      "zab        s  ke",
      "zab  tttt  f  Xk",
      "zab w5  6q s   k",
      "zab w    q 0    ",
      "zab w    q 0    ",
      "zab w6  6q 0    ",
      "zab  CCCC  0    ",
      "zab        s    ",
      "zabssssssssfX   ",
      "zab        s    ",
      "zab        q    ",
      "zab        q    ",
      "zab        q    "
    ],
    [
      "zab        s  k ",
      "zab        s  k ",
      "zab77777777s  k ",
      "zab     7  s  ke",
      "zab     7  f   k",
      "zab  7  7  s   k",
      "zab  7  7  s    ",
      "zab  7  7  s    ",
      "zab77777777s    ",
      "zab        s    ",
      "zab        s    ",
      "zabssssssssf    ",
      "zab        s    ",
      "zab        s    ",
      "zab        s    ",
      "zab        s    "
    ],
    [
      "zab88988@88#$$k ",
      "zab88%88@88#$$k ",
      "zab88@88@88#$$k ",
      "zab88888888#$$ke",
      "zab88888888f$$$k",
      "zab88%88@88#$$$k",
      "zab88988%88#$$$$",
      "zab88@88%88#$$$$",
      "zab88%88%88#$$$$",
      "zab88888888#$$$$",
      "zab88888888#$$$$",
      "zabssssssssf$$$$",
      "zab88888888#$$$$",
      "zab88888888#$%$$",
      "zab88%88%88#$%$$",
      "zab88%88988#$%$$"
    ]
  ]
}