{
  "name": "multi_megatower1_4_floor5",
  "refpalette": "c70cities:multi_megatower1_4_floor5_palette",
  "xsize": 16,
  "zsize": 16,
  "slices": [
    [
      "a   bbbbbbbbbbbb",
      "a   bbbbbbbbbbbb",
      "a   bbbbbbbbbbbb",
      "cdeebbbbbbbbbbbb",
      "bbbbfbbbbbbfbbbb",
      "bbbbbbbbbbbbbbbb",
      "bbbbbbbbbbbbbbbb",
      "bbbbbbbbbbbbbbbb",
      "bbbbbbbbbbbbbbbb",
      "bbbbbbbbbbbbbbbb",
      "bbbbbbbbbbbbbbbb",
      "ggggfbbbbbbfbbbb",
      "    hbbbbbbbbbbb",
      "    hbbbbbbbbbbb",
      "    hbbbbbbbbbbb",
      "    hbbbbbbbbbbb"
    ],
    [
      "a   ij kk lmn  o",
      "a   ip kk qm    ",
      "a   i      r   s",
      "aetti      m   u",
      "wxyAf      fBCBB",
      "        eeDm   B",
      "        e EmF  I",
      "J       e  mK  B",
      "D       e  mK  I",
      "        e EmF  B",
      "D       eeDm   I",
      "LLLLf      fBMBB",
      "    L      m    ",
      "    L      N   O",
      "    Lj kk lm  PQ",
      "    Lp kk qm   R"
    ],
    [
      "a   i      mn   ",
      "a   i      m    ",
      "a   i      S    ",
      "ae  i      m    ",
      "w TUf      fBVBB",
      "        W Xm   B",
      "        Y  Z   0",
      "           Z   B",
      "X       1  Z   0",
      "        Y  Z   B",
      "X         Xm   0",
      "    f      fB2BB",
      "    L      m    ",
      "    L      3    ",
      "    L      m    ",
      "    L      m    "
    ],
    [
      "a   i      m    ",
      "a   i      m    ",
      "a   i      4    ",
      "aeeei      m    ",
      "w5  f      fBBBB",
      "          Xm   B",
      "           Z   B",
      "           Z   B",
      "X          Z   B",
      "           Z   B",
      "X         Xm   B",
      "    f      fBBBB",
      "    L      m    ",
      "    L      4    ",
      "    L      m    ",
      "    L      m    "
    ],
    [
      "a   i      m6666",
      "a   i      m6666",
      "a   i      m6766",
      "aeeei      m6666",
      "wwwwf      fBBBB",
      "           m8888",
      "           m8888",
      "           m8888",
      "           m8888",
      "           m8888",
      "           m8888",
      "    f      fBBBB",
      "    m      m6666",
      "    m      m6966",
      "    m      m6666",
      "    m      m6666"
    ],
    [
      "@   @666666@    ",
      "@   @666666@## #",
      "@   @676676@ $# ",
      "@e%^@666666@## #",
      "&&&&f&&&&&&f&&&&",
      "6666@666666@ #  ",
      "6676@676696@****",
      "6666@666666@# *#",
      "6666@666666@  **",
      "6676@676696@  *#",
      "6666@666666@##**",
      "&&&&f&&&&&&f&&&&",
      "    @666666@ # #",
      "    @676676@ $  ",
      "    @666666@ #  ",
      "    @666666@    "
    ]
  ]
}