{
  "name": "multi_flatapartment_1_floor1",
  "refpalette": "c70cities:multi_flatapartment_1_floor1_palette",
  "xsize": 16,
  "zsize": 16,
  "slices": [
    [
      "                ",
      "aaabaaabaaaabaaa",
      "cccccccccccccccc",
      "dddddddddddddddd",
      "dddddddddddddddd",
      "dddddddccccccddd",
      "dddddddc  edcddd",
      "dddddddc   dcddd",
      "dddddddc   dcddd",
      "dddddddcddddcddd",
      "dddddddccccccddd",
      "dddddddcddddcddd",
      "dddddddcddddcddd",
      "cccccccccccccccc",
      "aaabaaabaaaabaaa",
      "                "
    ],
    [
      "                ",
      "ffabafabaggabafa",
      "      hijk kil  ",
      "m m   nio   ip  ",
      "qqq   riok  is  ",
      "iiii  tbuuuwbx  ",
      "  yi  tA    Bx  ",
      "  yi   A   CB!  ",
      "   i   ADDE B   ",
      "m mi   F    I   ",
      "qqqiiiib    biii",
      "JJKLMN O    P  Q",
      "       A    B   ",
      "       A    B   ",
      "ffabafabaRRabafa",
      "                "
    ],
    [
      "                ",
      "SSabaSabaSSabaSa",
      "      Ti    iU  ",
      "       iV   i   ",
      "       iV   i   ",
      "iiii   buuuWb   ",
      "  Xi   A    B   ",
      "  Xi   A    B   ",
      "   i   AdE  B   ",
      "   i   Y    Z   ",
      "   iiiib    biii",
      "       0    1  2",
      "       A    B   ",
      "       A    B   ",
      "SSabaSabaSSabaSa",
      "                "
    ],
    [
      "                ",
      "SSabaSabaSSabaSa",
      "       i    i   ",
      "       i    i   ",
      "       ik   i   ",
      "iiii   buuuub   ",
      "  Xi   A    B   ",
      "  Xi   Ad   B   ",
      "   i   AE   B   ",
      "   i   A    B   ",
      "   iiiib    biii",
      "       A    B  3",
      "       A    B   ",
      "       A    B   ",
      "SSabaSabaSSabaSa",
      "                "
    ],
    [
      "                ",
      "aaabaaabaaaabaaa",
      "   i   i4444i   ",
      "   i   i4444i   ",
      "   i   i4444i   ",
      "iiiiiiibuuuub   ",
      "   i   Ad5  B   ",
      "6  i   A7   B   ",
      "   i   A    B   ",
      "   i   A 6  B   ",
      "iiiiiiib8888biii",
      "   i   A    B  9",
      "   i   A    B   ",
      "   i   A    B   ",
      "aaabaaabaaaabaaa",
      "                "
    ],
    [
      "                ",
      "@@@#@@@#@@@@#@@@",
      "cccccccccccccccc",
      "dddddddddddddddd",
      "dddddddddddddddd",
      "dddddddddddddddd",
      "dddddddd edddddd",
      "dddddddd   ddddd",
      "dddddddd   ddddd",
      "dddddddddddddddd",
      "dddddddddddddddd",
      "dddddddddddddddd",
      "dddddddddddddddd",
      "cccccccccccccccc",
      "@@@#@@@#@@@@#@@@",
      "                "
    ]
  ]
}