{
  "name": "multi_flatapartment_0_floor1",
  "refpalette": "c70cities:multi_flatapartment_0_floor1_palette",
  "xsize": 16,
  "zsize": 16,
  "slices": [
    [
      "                ",
      "     abbbbabbbab",
      "     bcccccccccc",
      "     bcddddddddd",
      "     bcddddddddd",
      "     acddddddddd",
      "     bcddddddddd",
      "     bcddddddddd",
      "     bcddddddddd",
      "     bcddddddddd",
      "     acddddddddd",
      "     bcddddddddd",
      "     bcddddddddd",
      "     bcccccccccc",
      "     abbbbabbbab",
      "                "
    ],
    [
      "                ",
      "     abeebabebab",
      "     b    f     ",
      "     e    g hhg ",
      "     b ij g   gk",
      "     aggglg   gg",
      "     bm   n oogp",
      "     e    gggggp",
      "     e qq gr  s ",
      "     b ttugwx g ",
      "     agggggwx g ",
      "     b yA B   g ",
      "     e    ggggg ",
      "     b    f     ",
      "     abeebabebab",
      "                "
    ],
    [
      "                ",
      "     abCCbabCbab",
      "     b    D     ",
      "     C    g   g ",
      "     b E  g   g ",
      "     agggFg   gg",
      "     b    I JJg ",
      "     C    ggggg ",
      "     C    g!  K ",
      "     b    g   g ",
      "     aggggg   g ",
      "     b L  M   g ",
      "     C    ggggg ",
      "     b    D     ",
      "     abCCbabCbab",
      "                "
    ],
    [
      "                ",
      "     abCCbabCbab",
      "     b    g     ",
      "     C    g   g ",
      "     b    g   g ",
      "     aggggg   gg",
      "     b    g JJg ",
      "     C    ggggg ",
      "     C    g   g ",
      "     b    g   g ",
      "     aggggg   g ",
      "     b    g   g ",
      "     C    ggggg ",
      "     b    g     ",
      "     abCCbabCbab",
      "                "
    ],
    [
      "                ",
      "     abbbbabbbab",
      "     bNNNNg   g ",
      "     bNNNNg   g ",
      "     bNNNNg O g ",
      "     aggggg   gg",
      "     b    g   g ",
      "     b    ggggg ",
      "     b    g   g ",
      "     b    g   g ",
      "     aggggg   gg",
      "     bNNNNg   g ",
      "     bNNNNggggg ",
      "     bNNNNg   g ",
      "     abbbbabbbab",
      "                "
    ],
    [
      "                ",
      "     PQQQQPQQQPQ",
      "     Qcccccccccc",
      "     Qcddddddddd",
      "     Qcddddddddd",
      "     Pcddddddddd",
      "     Qcddddddddd",
      "     Qcddddddddd",
      "     Qcddddddddd",
      "     Qcddddddddd",
      "     Pcddddddddd",
      "     Qcddddddddd",
      "     Qcddddddddd",
      "     Qcccccccccc",
      "     PQQQQPQQQPQ",
      "                "
    ]
  ]
}