{
  "name": "multi_laboratory1_2_base1",
  "refpalette": "c70cities:multi_laboratory1_2_base1_palette",
  "xsize": 16,
  "zsize": 16,
  "slices": [
    [
      "zabcccccccccccd ",
      "zabcccccccccccd ",
      "zabcccccccccccd ",
      "zabcccccccccccde",
      "zabccccccccfcc!d",
      "zabccccccccccccd",
      "zabccccccccccccc",
      "zabccccccccccccc",
      "zabccccccccccccc",
      "zabccccccccccccc",
      "zabccccccccccccc",
      "zabccccccccfcccc",
      "zabccccccccccccc",
      "zabccccccccccccc",
      "zabccccccccccccc",
      "zabccccccccccccc"
    ],
    [
      "zabg      hi  j ",
      "zabk      hi  j ",
      "zabk    lmhi  j ",
      "zabnopo qrhi  js",
      "zabiiiitiiif  sj",
      "zabuuu l wwx   j",
      "zabuu      x  y ",
      "zabAABC C  x    ",
      "zabA  qDq  x    ",
      "zab B EFE  x    ",
      "zabk  C C  x    ",
      "zabkI      fs   ",
      "zabg  C C  J    ",
      "zabg  qrq  J    ",
      "zabK  ELE  M    ",
      "zabNC C C  J    "
    ],
    [
      "zabO       x  j ",
      "zab       Px  j ",
      "zab        x  j ",
      "zab! p  QR x  js",
      "zabiiiiSiiif  Tj",
      "zab!uP     x   j",
      "zabP       x    ",
      "zabA       x    ",
      "zab   B    x    ",
      "zab     I  x    ",
      "zab        x    ",
      "zab        fT   ",
      "zabU       J    ",
      "zabV   P   J    ",
      "zabW  l    X    ",
      "zabY       J    "
    ],
    [
      "zabA       x  j ",
      "zab        x  j ",
      "zab        x  j ",
      "zabZ000    x  js",
      "zabiiiiiiiif  Tj",
      "zab      00x   j",
      "zab        x    ",
      "zab1       x    ",
      "zab        x    ",
      "zab        x    ",
      "zab        x    ",
      "zab        fT   ",
      "zab        J    ",
      "zab        J    ",
      "zab2       J    ",
      "zab3       J    "
    ],
    [
      "zab        x  j ",
      "zab        x  j ",
      "zab        x  j ",
      "zabn       x  js",
      "zabiiiiiiiif   j",
      "zab        x   j",
      "zab        x    ",
      "zab        x    ",
      "zab        x    ",
      "zab        x    ",
      "zab        x    ",
      "zab        f    ",
      "zab        J    ",
      "zab        J    ",
      "zab        J    ",
      "zab        J    "
    ],
    [
      "zab445444546447 ",
      "zab445444546447 ",
      "zab445444546447 ",
      "zabn444444464478",
      "zabiiii9iiif4447",
      "zab4444444464447",
      "zab4454445464444",
      "zab4454445464444",
      "zab4454445464444",
      "zab4454445464444",
      "zab4444444464444",
      "zab44444444f4444",
      "zab4444444464444",
      "zab4454445464444",
      "zab4454445464444",
      "zab4454445464444"
    ]
  ]
}