{
  "name": "multi_laboratory1_9_base4",
  "refpalette": "c70cities:multi_laboratory1_9_base4_palette",
  "xsize": 16,
  "zsize": 16,
  "slices": [
    [
      "aaaaaaaaaaaaaaaa",
      "aaaaaaaaaaaaaaaa",
      "aaaaaaaaaaaaaaaa",
      "aaaaaaaaaaaaaaaa",
      "aaaaaaaaaaaaaaaa",
      "aaaaaaaaaaaaaaaa",
      "aaaaaaaaaaaaaaaa",
      "aaaaaaaaaaaaaaaa",
      "aaaaa!aaaaaaaaaa",
      "aaaaaaaaaaaaaaaa",
      "aaaaaaaaaaaaaaaa",
      "aaaaaaaaaaaaaaaa",
      "aaaaaaaaaaaaaaaa",
      "bbbbbbbbbbbbbbbb",
      "cccccccccccccccc",
      "vvvvvvvvvvvvvvvv"
    ],
    [
      "d     e  d    fe",
      "dg   fe  d g   e",
      "d     e  d     e",
      "hg    hhhhg   gh",
      "     f          ",
      "           i    ",
      "  jklmmmmmmlk   ",
      "nnnnnnnnnnnnnnnn",
      "  okpppqqhhrks  ",
      "                ",
      " t   t    t     ",
      " uw tu w  ut wuw",
      "wt   t   wt   w ",
      "bbbbbbbbbbbbbbbb",
      "cccccccccccccccc",
      "vvvvvvvvvvvvvvvv"
    ],
    [
      "      i         ",
      "                ",
      "x               ",
      "                ",
      "                ",
      "                ",
      "   yA Bx CDEy   ",
      "nnnnnnnnnnnnnnnn",
      "   y F     ry   ",
      "                ",
      "                ",
      "                ",
      "                ",
      "bbbbbbbbbbbbbbbb",
      "cccccccccccccccc",
      "vvvvvvvvvvvvvvvv"
    ],
    [
      "                ",
      "                ",
      "                ",
      "                ",
      "                ",
      "                ",
      "   y        y   ",
      "nnnnnInInIInnnnn",
      "    JJJKKLLL    ",
      "                ",
      "                ",
      "                ",
      "                ",
      "bbbbbbbbbbbbbbbb",
      "cccccccccccccccc",
      "vvvvvvvvvvvvvvvv"
    ],
    [
      "                ",
      "                ",
      "                ",
      "                ",
      "                ",
      "                ",
      "                ",
      "nnnnnnIIInInnnnn",
      "    MMMMMMMM    ",
      "                ",
      "                ",
      "                ",
      "                ",
      "bbbbbbbbbbbbbbbb",
      "cccccccccccccccc",
      "vvvvvvvvvvvvvvvv"
    ],
    [
      "NOOnOONOOPOOnOOP",
      "NOOnOONOOPOOnOOP",
      "POOnOOPOONOOnOON",
      "POOnOOPPNNOOnOON",
      "OOOnOOOOOOOOnOOO",
      "OOOnOOOOOOOOnOOO",
      "OOOnOOOOOOOOnOOO",
      "nnnnnnnnnnnnnnnn",
      "QQQQQQQQQQQQQQQQ",
      "QPQQQPQQQQNQQQPQ",
      "QNQQQPQQQQPQQQPQ",
      "QPQQQPQQQQPQQQPQ",
      "QQQQQQQQQQQQQQQQ",
      "bbbbbbbbbbbbbbbb",
      "cccccccccccccccc",
      "vvvvvvvvvvvvvvvv"
    ]
  ]
}