{
  "name": "multi_communitycenter_6_base1",
  "refpalette": "c70cities:multi_communitycenter_6_base1_palette",
  "xsize": 16,
  "zsize": 16,
  "slices": [
    [
      "vvvvvvvvvvvvvvvv",
      "HHHHHHHHHHHHHHHv",
      "HHHHHHHHHHHHHHHv",
      "HHHHHHHHHHHHHHHv",
      "HHHHHHHHHHHHHHHv",
      "HHHHHHHHHHHHHHHv",
      "HHHHHHHHHHHHHHHv",
      "HHHHHHHHHHHHHHHv",
      "HHHHHHHHHHHHHHHv",
      "HHHHHHHHHHHHHHHv",
      "HHHHHHHHHHHHHHHv",
      "HHHHHHHHHHHHHHHv",
      "HHHHHHHHHHHHHHHv",
      "HHHHHHHHHHHHHHHv",
      "HHHHHHHHHHHHHHHv",
      "HHHHHHHHHHHHHHHv"
    ],
    [
      "vvvvvvvvvvvvvvvv",
      "aaaaaaaaaaaaaaav",
      "aaaaaaaaaaaaaaav",
      "aaaaaaaaaaaaaaav",
      "aaaaaaaaaaaaaaav",
      "aaaaaaaaaaaaaaav",
      "bcb cbcbdcbcb!av",
      "   d          av",
      "efegfefegfefegav",
      "              av",
      "              av",
      "              av",
      "              av",
      "              av",
      "      dd      av",
      "bcbgHhhHg    gav"
    ],
    [
      "vvvvvvvvvvvvvvvv",
      "aaaaaaaaaaaaaaav",
      "aaaaaaaaaaaaaaav",
      "aaaaaaaaaaaaaaav",
      "aaaaaaaaaaaaaaav",
      "aaaaaaaaaaaaaaav",
      "              av",
      "              av",
      "   g    g    gav",
      "              av",
      "              av",
      "              av",
      "              av",
      "              av",
      "             dav",
      "   gHhhHg    gav"
    ],
    [
      "vvvvvvvvvvvvvvvv",
      "aaaaaaaaaaaaaaav",
      "aaaaaaaaaaaaaaav",
      "aaaaaaaaaaaaaaav",
      "aaaaaaaaaaaaaaav",
      "aaaaaaaaaaaaaaav",
      "   d         dav",
      "        d    dav",
      "   g    g    gav",
      "        d     av",
      "             dav",
      "              av",
      "              av",
      "             dav",
      "    d   d    dav",
      "   gHHHHg    gav"
    ],
    [
      "vvvvvvvvvvvvvvvv",
      "aaaaaaaaaaaaaaav",
      "aaaaaaaaaaaaaaav",
      "aaaaaaaaaaaaaaav",
      "aaaaaaaaaaaaaaav",
      "aaaaaaaaaaaaaaav",
      "d dg d dgd  dgav",
      "  dgd   g    gav",
      "iiigiiiigiiiigav",
      "   gd  dg   dgav",
      "   g    g    gav",
      "   gd ddg    gav",
      "  dgHHHHg   dgav",
      "   gjjjjg    gav",
      "  dgkkkkg d dgav",
      "iiig    giiiigav"
    ],
    [
      "vvvvvvvvvvvvvvvv",
      "aaaaaaaaaaaaaaav",
      "aaaaaaaaaaaaaaav",
      "aaaaaaaaaaaaaaav",
      "aaaaaaaaaaaaaaav",
      "aaaaaaaaaaaaaaav",
      "aaaaaaaaaaaaaaav",
      "aaagaaaaaaaaaaav",
      "aaagHHHHgaaaaaav",
      "aaahHHHHhaaaaaav",
      "aaahjjjjhaaaaaav",
      "aaahkkkkhaaaaaav",
      "aaah    haaaaaav",
      "aaah    haaaaaav",
      "aaah    haaaaaav",
      "aaah    haaaaaav"
    ]
  ]
}