{
  "name": "multi_laboratory1_2_base3",
  "refpalette": "c70cities:multi_laboratory1_2_base3_palette",
  "xsize": 16,
  "zsize": 16,
  "slices": [
    [
      "vabcccccccccccd ",
      "vabcccccccccccd ",
      "vabcccccccccccd ",
      "vabcccccccccccde",
      "vabccccccccfcccd",
      "vabccccccccccccd",
      "vabccccccccccccc",
      "vabccccccccccccc",
      "vabccccccccccccc",
      "vabccccccccccccc",
      "vabccccccccccccc",
      "vabccccccccfcccc",
      "vabccccccccccccc",
      "vabccccccccccccc",
      "vab!cccccccccccc",
      "vabccccccccccccc"
    ],
    [
      "vab ghhhhi j  k ",
      "vab  lg m no  k ",
      "vabpiq     r  k ",
      "vabs       t  ke",
      "vab uwwwwx f  ek",
      "vab uyAABx t  Ck",
      "vab uyAABx t    ",
      "vab uyAABx t    ",
      "vab uyDABx t    ",
      "vab !yAEBx t   F",
      "vab uIIIIx t  J ",
      "vabttttttttfe   ",
      "vab     K  t    ",
      "vabLMi i   r    ",
      "vabNNO  n  P    ",
      "vabMQ   l  R    "
    ],
    [
      "vab  STTU  V  k ",
      "vab        W  k ",
      "vab        r  k ",
      "vab        t  ke",
      "vab XwwwwY f  Zk",
      "vab X0  1Y t   k",
      "vab X2  3Y 4    ",
      "vab X0  1Y 4    ",
      "vab X2  3Y 4    ",
      "vab X0E51Y 4    ",
      "vab XIIIIY t    ",
      "vabttttttttfZ   ",
      "vab        t    ",
      "vab        r    ",
      "vab6       7    ",
      "vab8       9    "
    ],
    [
      "vab        r  k ",
      "vab        r  k ",
      "vab        r  k ",
      "vab        t  ke",
      "vab XwwwwY f  Zk",
      "vab X0  1Y t   k",
      "vab X0  1Y 4    ",
      "vab X0 @1Y 4    ",
      "vab X05 1Y 4    ",
      "vab X0  1Y 4    ",
      "vab XIIIIY t    ",
      "vabttttttttfZ   ",
      "vab        t    ",
      "vab        r    ",
      "vab        r    ",
      "vab        r    "
    ],
    [
      "vab        t  k ",
      "vab        t  k ",
      "vab        t  k ",
      "vab        t  ke",
      "vab  #$$%  f   k",
      "vab  #$$%  t   k",
      "vab  #$$%  t    ",
      "vab  #$$%  t    ",
      "vab  #$$%  t    ",
      "vab  #$$%  t    ",
      "vab  #$$%  t    ",
      "vabttttttttf    ",
      "vab        t    ",
      "vab        t    ",
      "vab        t    ",
      "vab        t    "
    ],
    [
      "vab^^&^^*^^())k ",
      "vab^^*^^&^^())k ",
      "vab^^&^^&^^())k ",
      "vab^^^^^^^^())ke",
      "vab^^^^^^^^f)))k",
      "vab^^&^^&^^()))k",
      "vab^^&^^&^^())))",
      "vab^^&^^&^^())))",
      "vab^^&^^&^^())))",
      "vab^^^^^^^^())))",
      "vab^^^^^^^^())))",
      "vabttttttttf))))",
      "vab^^^^^^^^())))",
      "vab^^^^^^^^()&))",
      "vab^^*^^&^^()&))",
      "vab^^&^^*^^()&))"
    ]
  ]
}