{
  "name": "multi_militarybase_2_base1",
  "refpalette": "c70cities:multi_militarybase_2_base1_palette",
  "xsize": 16,
  "zsize": 16,
  "slices": [
    [
      "vvvvvvvvvvvvvvvv",
      "aaaaaaavaaaaaaaa",
      "aaaaaaabaaaaaaaa",
      "aaaaaaabaaaaaaaa",
      "aaaaaaabaaaaaaaa",
      "bbbbbbbvbbbbbbbb",
      "aaaaaaabaaaaaaaa",
      "aaaaaaabaaaaaaaa",
      "aaaaaaabaaaaaaaa",
      "cccccccvcccccccc",
      "dddddddbdddddddd",
      "dddddddbdddddddd",
      "dddddddbdddddddd",
      "bbvbbbbvbbbbvbbb",
      "  e    e    e   ",
      "                "
    ],
    [
      "vvvvvvvvvvvvvvvv",
      "fffffffvffffffff",
      "g h   i       i ",
      " j  i           ",
      "  i      j      ",
      "kkkkkkkvkkkkkkkk",
      "l j             ",
      " i i            ",
      " j   j          ",
      "kkkkkkkvkkkkkkkk",
      "                ",
      "                ",
      "                ",
      "mmvmmmmvmmmmvmmm",
      "                ",
      "                "
    ],
    [
      "vvvvvvvvvvvvvvvv",
      "fffffffvffffffff",
      "                ",
      "                ",
      "                ",
      "kkkkkkkvkkkkkkkk",
      "                ",
      "                ",
      "                ",
      "kkkkkkkvkkkkkkkk",
      "                ",
      "                ",
      "                ",
      "  v    v    v   ",
      "                ",
      "                "
    ],
    [
      "vvvvvvvvvvvvvvvv",
      "fffffffvffffffff",
      "                ",
      "                ",
      "                ",
      "kkkkkkkvkkkkkkkk",
      "                ",
      "                ",
      "                ",
      "kkkkkkkvkkkkkkkk",
      "                ",
      "                ",
      "                ",
      "  v    v    v   ",
      "                ",
      "                "
    ],
    [
      "vvvvvvvvvvvvvvvv",
      "fffffffvffffffff",
      "                ",
      "                ",
      "                ",
      "kkkkkkkvkkkkkkkk",
      "                ",
      "                ",
      "                ",
      "kkkkkkkvkkkkkkkk",
      "                ",
      "                ",
      "                ",
      "nnvnnnnvnnnnvnnn",
      "                ",
      "                "
    ],
    [
      "vvvvvvvvvvvvvvvv",
      "ooooooovoooooooo",
      "pppppppbpppppppp",
      "pppppppbpppppppp",
      "pppppppbpppppppp",
      "bbbbbbbvbbbbbbbb",
      "pppppppbpppppppp",
      "pppppppbpppppppp",
      "pppppppbpppppppp",
      "pppppppvpppppppp",
      "pppppppbpppppppp",
      "pppppppbpppppppp",
      "pppppppbpppppppp",
      "bbvbbbbvbbbbvbbb",
      "qqqqqqqqqqqqqqqq",
      "qqqqqqqqqqqqqqqq"
    ]
  ]
}