{
  "name": "multi_laboratory1_2_base4",
  "refpalette": "c70cities:multi_laboratory1_2_base4_palette",
  "xsize": 16,
  "zsize": 16,
  "slices": [
    [
      "zabcccccccccccd ",
      "zabcccccccccccd ",
      "zabcccccccccccd ",
      "zabcccccccccccde",
      "zabccccccccfcccd",
      "zabccccccccccccd",
      "zabccccccccccccc",
      "zabccccccccccccc",
      "zabcccc!cccccccc",
      "zabccccccccccccc",
      "zabccccccccccccc",
      "zabccccccccfcccc",
      "zabccccccccccccc",
      "zabccccccccccccc",
      "zabccccccccccccc",
      "zabccccccccccccc"
    ],
    [
      "zabghiiii  j  k ",
      "zablmnnnno p  k ",
      "zablqrstru u  k ",
      "zab  wwww  x  ke",
      "zab  nnnn  f  ek",
      "zab qrysru x  Ak",
      "zab  wwww  x    ",
      "zab  nnnn  x    ",
      "zab qr Bru x    ",
      "zab  wwww  x    ",
      "zab    C  Dx  E ",
      "zabxxxFIxxxfe   ",
      "zab     J  x    ",
      "zabKL  M   u    ",
      "zabNN      j    ",
      "zabLOM     p    "
    ],
    [
      "zab  P QD  R  k ",
      "zab  nnnn  S  k ",
      "zab qT  Tu u  k ",
      "zab  wwww  x  ke",
      "zab  nnnn  f  Uk",
      "zab qV  Vu x   k",
      "zab  wwww  W    ",
      "zab  nnnn  W    ",
      "zab qV  Vu W    ",
      "zab  wwww  W    ",
      "zab        x    ",
      "zabxxxXYxxxfU   ",
      "zab        x    ",
      "zab        u    ",
      "zabZ       R    ",
      "zab        S    "
    ],
    [
      "zab        u  k ",
      "zab  nnnn  u  k ",
      "zab q0  0u u  k ",
      "zab  wwww  x  ke",
      "zab  nnnn  f  Uk",
      "zab q1  1u x   k",
      "zab  wwww  W    ",
      "zab  nnnn  W    ",
      "zab q1  1u W    ",
      "zab  wwww  W    ",
      "zab        x    ",
      "zabxxxxxxxxfU   ",
      "zab        x    ",
      "zab        u    ",
      "zab        u    ",
      "zab        u    "
    ],
    [
      "zab        x  k ",
      "zab        x  k ",
      "zab22222222x  k ",
      "zab     2  x  ke",
      "zab     2  f   k",
      "zab  2  2  x   k",
      "zab  2  2  x    ",
      "zab  2  2  x    ",
      "zab22222222x    ",
      "zab        x    ",
      "zab        x    ",
      "zabxxxxxxxxf    ",
      "zab        x    ",
      "zab        x    ",
      "zab        x    ",
      "zab        x    "
    ],
    [
      "zab33433533677k ",
      "zab33533433677k ",
      "zab33433433677k ",
      "zab33333333677ke",
      "zab33333333f777k",
      "zab334334336777k",
      "zab3343343367777",
      "zab3343343367777",
      "zab3343343367777",
      "zab3333333367777",
      "zab3333333367777",
      "zabxxxxxxxxf7777",
      "zab3333333367777",
      "zab3333333367477",
      "zab3343343367477",
      "zab3343343367477"
    ]
  ]
}