{
  "name": "multi_condo1_4_floor2",
  "refpalette": "c70cities:multi_condo1_4_floor2_palette",
  "xsize": 16,
  "zsize": 16,
  "slices": [
    [
      "aaaaabcdddddef  ",
      "ggghabceeeeeeii ",
      "   jabckkkkkef  ",
      "   jabckkkkkef  ",
      "   jabckkkkkef  ",
      "   jabckkkkkeii ",
      "   jabceeeeeef  ",
      "   jabc     cf  ",
      "   jabc     cf  ",
      "   jabc     ef  ",
      "   jabl     eii ",
      "   jabmeeeeeef  ",
      "   jabccj   ef  ",
      "   jabccn   ef  ",
      "ooopabceeeeeeii ",
      "aaaaabcdddddef  "
    ],
    [
      "      eqrs te   ",
      "uuuu  eeeeeeeii ",
      "   u  w     e   ",
      "   u  e     x   ",
      "   u  e  yA e   ",
      "   u  e BCC eii ",
      "   u  eeeeeee   ",
      "   u  e     D   ",
      "   u  E     D   ",
      "   u  F     e   ",
      "   u Ie     eii ",
      "   u  eeeeeee   ",
      "   u  e     x   ",
      "   u  J Kn  e   ",
      "uuuu  eeeeeeeii ",
      "      eLMN Oe   "
    ],
    [
      "      e   P e   ",
      "      eeeeeeeii ",
      "      Q     e   ",
      "      eR    S   ",
      "      e  TU e   ",
      "      eVVCC eii ",
      "      eeeeeee   ",
      "      e     D   ",
      "      W     D   ",
      "      X     e   ",
      "      e     eii ",
      "      eeeeeee   ",
      "      e     S   ",
      "      Y  Kn e   ",
      "      eeeeeeeii ",
      "      e   Z e   "
    ],
    [
      "      e   0 e   ",
      "      eeeeeeeii ",
      "      1     e   ",
      "      e     S   ",
      "      e     e   ",
      "      eV 22 eii ",
      "      eeeeeee   ",
      "     3e     D   ",
      "      1     D   ",
      "      1     e   ",
      "     4e     eii ",
      "      eeeeeee   ",
      "      e   1nS   ",
      "      1   Kce   ",
      "      eeeeeeeii ",
      "      e   5 e   "
    ],
    [
      "      e     e   ",
      "      eeeeeeeii ",
      "      e     e   ",
      "      e     e   ",
      "      e     e   ",
      "      eV    eii ",
      "      eeeeeee   ",
      "     6e     D   ",
      "      e     D   ",
      "      e     e   ",
      "     6e     eii ",
      "      eeeeeee   ",
      "      e  1j e   ",
      "      e     e   ",
      "      eeeeeeeii ",
      "      e     e   "
    ],
    [
      "      ekkkkke   ",
      "      eeeeeeeii ",
      "      eV    e   ",
      "      eV  7 e   ",
      "      eV    e   ",
      "      eVVVVVeii ",
      "      eeeeeee   ",
      "      e     D   ",
      "      e     D   ",
      "      e     e   ",
      "      e     eii ",
      "      eeeeeee   ",
      "      e 1j  e   ",
      "      e     e   ",
      "      eeeeeeeii ",
      "      ekkkkke   "
    ]
  ]
}