{
  "name": "multi_laboratory1_4_base1",
  "refpalette": "c70cities:multi_laboratory1_4_base1_palette",
  "xsize": 16,
  "zsize": 16,
  "slices": [
    [
      "zabccccccccdcccc",
      "zabccccccccccccc",
      "zabccccccccccccc",
      "zabccccccccccccc",
      "zabccccccccccccc",
      "zabccccccccccccc",
      "zabccccccccccccc",
      "zabccccccccdcccc",
      "zabeeeeeeeeccccc",
      "zabeeeeeeeeccccc",
      "zabeeeeeeeeccccc",
      "zabeeeeeeeeccccc",
      "zabeeeeeeeeccccc",
      "zabbbbbbbbbbbbbb",
      "zaaaaaaaaaaaaaaa",
      "zzzzzzzzzzzzzzzz"
    ],
    [
      "zabfg      d    ",
      "zabf  h h  i    ",
      "zabj  klk  i    ",
      "zabm  non  p    ",
      "zabj  h h  i    ",
      "zabfg      i    ",
      "zabf  qqrssi    ",
      "zabttttttttd   u",
      "zabwwxxxxwwt   y",
      "zab        A   y",
      "zabBCDCBCBCt   y",
      "zab E E E Et   y",
      "zabFEFEFEFEtuyy!",
      "zabbbbbbbbbbbbbb",
      "zaaaaaaaaaaaaaaa",
      "zzzzzzzzzzzzzzzz"
    ],
    [
      "zabI       d    ",
      "zabJ       i    ",
      "zabK  L    i    ",
      "zab     M  N    ",
      "zabO       i    ",
      "zabP       i    ",
      "zabI       i    ",
      "zabttttttttd   Q",
      "zabR S SSSRt   T",
      "zab        U    ",
      "zabVCWCVCVCt   X",
      "zab E E E Et    ",
      "zab E E E EtQYZQ",
      "zabbbbbbbbbbbbbb",
      "zaaaaaaaaaaaaaaa",
      "zzzzzzzzzzzzzzzz"
    ],
    [
      "zab        d    ",
      "zab        0    ",
      "zab        i    ",
      "zab        i    ",
      "zab        i    ",
      "zab1       i    ",
      "zab1       i    ",
      "zabttttttttd   R",
      "zab S SSSS t    ",
      "zab        t    ",
      "zabCCCCCCCCt    ",
      "zab E E E Et    ",
      "zab E E E EtR 2R",
      "zabbbbbbbbbbbbbb",
      "zaaaaaaaaaaaaaaa",
      "zzzzzzzzzzzzzzzz"
    ],
    [
      "zab        d    ",
      "zab        i    ",
      "zab        i    ",
      "zab        0    ",
      "zab        0    ",
      "zab        0    ",
      "zab        0    ",
      "zabttttttttd    ",
      "zab333 3333t    ",
      "zab3 333333t    ",
      "zab43333333t    ",
      "zab33333333t    ",
      "zab53535353t    ",
      "zabbbbbbbbbbbbbb",
      "zaaaaaaaaaaaaaaa",
      "zzzzzzzzzzzzzzzz"
    ],
    [
      "zab66666666d6666",
      "zab6666666676666",
      "zab6686669676666",
      "zab6686668676666",
      "zab6686668676666",
      "zab6686668676666",
      "zab6666666676666",
      "zab@@@@@@@@d6666",
      "zab########@6666",
      "zab# # # # @6666",
      "zab# # # # @6666",
      "zab#!# # # @6666",
      "zab# # # # @6666",
      "zabbbbbbbbbbbbbb",
      "zaaaaaaaaaaaaaaa",
      "zzzzzzzzzzzzzzzz"
    ]
  ]
}