{
  "name": "multi_militarybase_5_ground",
  "refpalette": "c70cities:multi_militarybase_5_ground_palette",
  "xsize": 16,
  "zsize": 16,
  "slices": [
    [
      "aaaaabbbabbaazcz",
      "aaaaaaaaaaaazzcz",
      "aaaaaaaaaaaazacz",
      "aaaababbbbbaazcz",
      "aaaaaaaaaaaazzcz",
      "aaaaaaaaaaaaaacz",
      "aaaaaaaaaaaazacz",
      "aaaaaaaaaaaazzcz",
      "daaaaaaaaaaaazcz",
      "aaaaaaaaaaaazzcz",
      "aaaaaaaaaaaaazcz",
      "aaaaaaaaaaaazacz",
      "azzzaazzazazzzcz",
      "aazzzzazaazzaacz",
      "cccccccccccccccz",
      "zzzzzzzzzzzzzzzz"
    ],
    [
      "             ec ",
      "              c ",
      "              c ",
      "f             c ",
      "ff           ec ",
      "gff    hhh    c ",
      "  f   ijjji  kc ",
      " lf  mjnjnjo ec ",
      "d f  mjnnnjo ec ",
      "  f  mjnjnjo  c ",
      " lf   ijjji  ec ",
      "fff    ppp    c ",
      "             ec ",
      " q ee k   e  kc ",
      "ccccccccccccccc ",
      "                "
    ],
    [
      "              c ",
      "              c ",
      "              c ",
      "f             c ",
      "ff            c ",
      " ff           c ",
      "  f          kc ",
      "  f           c ",
      "d f     r     c ",
      "  f           c ",
      "  f     ~     c ",
      "fff           c ",
      "              c ",
      "  q   k      kc ",
      "ccccccccccccccc ",
      "                "
    ],
    [
      "              c ",
      "              c ",
      "              c ",
      "f             c ",
      "ff            c ",
      " ff           c ",
      "  f          kc ",
      "  f           c ",
      "  f           c ",
      "  f           c ",
      "  f    ~~     c ",
      "fff           c ",
      "              c ",
      "   q  k      kc ",
      "ccccccccccccccc ",
      "                "
    ],
    [
      "              c ",
      "              c ",
      "              c ",
      "s             c ",
      "ss            c ",
      " ss           c ",
      "  s          kc ",
      "  s           c ",
      "  s           c ",
      "  s           c ",
      "  s     ~     c ",
      "sss           c ",
      "              c ",
      "    q k      kc ",
      "ccccccccccccccc ",
      "                "
    ],
    [
      "             tu ",
      "             tu ",
      "             tu ",
      "             tu ",
      "             tu ",
      "             tu ",
      "             tw ",
      "             tx ",
      "             tu ",
      "             tu ",
      "        ~    tu ",
      "             tu ",
      "             tu ",
      "     yyyyyyyyAB ",
      "CCCCCC!CCCCCCBB ",
      "                "
    ]
  ]
}