{
  "name": "multi_hospital_0_top",
  "refpalette": "c70cities:multi_hospital_0_top_palette",
  "xsize": 16,
  "zsize": 16,
  "slices": [
    [
      "                ",
      "         a      ",
      "         b c c c",
      "         deeeeee",
      "         f  ghhh",
      "         d  ghhh",
      "         f  ghhh",
      "         d ighhh",
      "         jeeehhh",
      "        ke  lhhh",
      "        ke  lhhh",
      "        ke eehhh",
      "        kbhhhhhh",
      "        kbhhhhhh",
      "        kbhhhhhh",
      "        kbhhhhhh"
    ],
    [
      "                ",
      "         a      ",
      "         b c c c",
      "         meeeeee",
      "         m  nooo",
      "         m  n   ",
      "         m  n pp",
      "         m      ",
      "         jeee   ",
      "         l  q   ",
      "         l  r   ",
      "         l ee   ",
      "         ls     ",
      "         l      ",
      "         ltt    ",
      "         l      "
    ],
    [
      "                ",
      "         a      ",
      "         b c c c",
      "         meemmme",
      "         m      ",
      "         m      ",
      "         m      ",
      "         m      ",
      "         jeee   ",
      "         l  u   ",
      "         l  w   ",
      "         lxeey  ",
      "         lsA    ",
      "         f      ",
      "         fB     ",
      "         f      "
    ],
    [
      "                ",
      "         a      ",
      "         b c c c",
      "         meeeeee",
      "         m      ",
      "         m      ",
      "         m      ",
      "         m      ",
      "         jeee   ",
      "         l  C   ",
      "         l  C   ",
      "         lxee   ",
      "         ls     ",
      "         l      ",
      "         l      ",
      "         l      "
    ],
    [
      "                ",
      "         a      ",
      "         bDDDDDD",
      "         bllllll",
      "         b      ",
      "         b      ",
      "         b      ",
      "         b      ",
      "         jeee   ",
      "        El  e   ",
      "        El  e   ",
      "        ElFee   ",
      "        Els     ",
      "        El      ",
      "        El      ",
      "        El      "
    ],
    [
      "                ",
      "                ",
      "                ",
      "                ",
      "        D DDDDDD",
      "        D DDDDDD",
      "        D DDDDDD",
      "        D DDDDDD",
      "        D DDDDDD",
      "        D DDDDDD",
      "        D DDDDDD",
      "        D DDDDDD",
      "        D DDDDDD",
      "        D DDDDDD",
      "        D DDDDDD",
      "        D DDDDDD"
    ]
  ]
}