{
  "name": "multi_megatower1_2_base1",
  "refpalette": "c70cities:multi_megatower1_2_base1_palette",
  "xsize": 16,
  "zsize": 16,
  "slices": [
    [
      "vaavvHHHHHHHHHHv",
      "vaavvHHHHHHHHHHH",
      "vaavvHbHHHHHHbHH",
      "vaavvHHHHHHHHHHH",
      "vaavvHHHHHHHHHHH",
      "vaavvHHHHHHHHHHH",
      "vaavvHHHHHHHHHHH",
      "vaavvHHHHHHHHHHH",
      "vaavvHHHHHHHHHHH",
      "vaavvHbHHHHHHbHH",
      "vaavvHHHHHHHHHHH",
      "vaavvvvvvvvvvvvv",
      "vaavvvvvvvvvvvvv",
      "vaaaaaaaaaaaaaaa",
      "vaaaaaaaaaaaaaaa",
      "vvvvvvvvvvvvvvvv"
    ],
    [
      "vaavcd e    f gh",
      "vaavcf g      de",
      "vaavc bi    jb  ",
      "vaavcd e     kfg",
      "vaavcf g        ",
      "vaavcd e        ",
      "vaavcf g        ",
      "vaavclll        ",
      "vaavc   mdedende",
      "vaavc b m    b  ",
      "vaavc   mfgfg fg",
      "vaavcccccccccccc",
      "vaavvvvvvvvvvvvv",
      "vaaaaaaaaaaaaaaa",
      "vaaaaaaaaaaaaaaa",
      "vvvvvvvvvvvvvvvv"
    ],
    [
      "vaav            ",
      "vaav            ",
      "vaav  b      b  ",
      "vaav            ",
      "vaav            ",
      "vaav            ",
      "vaav            ",
      "vaav            ",
      "vaav            ",
      "vaav  b      b  ",
      "vaav            ",
      "vaav            ",
      "vaavvvvvvvvvvvvv",
      "vaaaaaaaaaaaaaaa",
      "vaaaaaaaaaaaaaaa",
      "vvvvvvvvvvvvvvvv"
    ],
    [
      "vaav            ",
      "vaav            ",
      "vaav  b      b  ",
      "vaav            ",
      "vaav            ",
      "vaav            ",
      "vaav            ",
      "vaav            ",
      "vaav            ",
      "vaav  b      b  ",
      "vaav            ",
      "vaav            ",
      "vaavvvvvvvvvvvvv",
      "vaaaaaaaaaaaaaaa",
      "vaaaaaaaaaaaaaaa",
      "vvvvvvvvvvvvvvvv"
    ],
    [
      "vaav            ",
      "vaav            ",
      "vaav  b      b  ",
      "vaav            ",
      "vaav            ",
      "vaav            ",
      "vaav            ",
      "vaav            ",
      "vaav            ",
      "vaav  b      b  ",
      "vaav            ",
      "vaav            ",
      "vaavvvvvvvvvvvvv",
      "vaaaaaaaaaaaaaaa",
      "vaaaaaaaaaaaaaaa",
      "vvvvvvvvvvvvvvvv"
    ],
    [
      "vaavvoboooooobo ",
      "vaavvobooooooboo",
      "vaavvobbbbbbbbbb",
      "vaavvobooooooboo",
      "vaavvobooooooboo",
      "vaavvobooooooboo",
      "vaavvobooooooboo",
      "vaavvobooooooboo",
      "vaavvobooooooboo",
      "vaavvobbbbbbbbbb",
      "vaavvooooooooooo",
      "vaavvvvvvvvvvvvv",
      "vaavvvvvvvvvvvvv",
      "vaaaaaaaaaaaaaaa",
      "vaaaaaaaaaaaaaaa",
      "vvvvvvvvvvvvvvvv"
    ]
  ]
}