{
  "name": "multi_laboratory1_14_base4",
  "refpalette": "c70cities:multi_laboratory1_14_base4_palette",
  "xsize": 16,
  "zsize": 16,
  "slices": [
    [
      "aaaabaaaaaaaaccz",
      "aaaaaaaaaaaaaccz",
      "aaaaaaaaaaaaaccz",
      "aaaaaaaaaaaaaccz",
      "aaaaaaaaaaaaaccz",
      "aaaaaaaaaaaaaccz",
      "aaaaaaaaaaaa!ccz",
      "aaaabaaaaaaaaccz",
      "aaaaaddddddddccz",
      "aaaaaddddddddccz",
      "aaaaaddddddddccz",
      "aaaaaddddddddccz",
      "aaaaaddddddddccz",
      "cccccccccccccccz",
      "eeeecccccccccccz",
      "zzzzzzzzzzzzzzzz"
    ],
    [
      "fg  bhhhhhhhhccz",
      "f   hijjklm nccz",
      "o   hjpq    rccz",
      "ss  hj   tt uccz",
      "    hw   tt uccz",
      "    x       yccz",
      "    h    AB nccz",
      "    bhhhhhhhhccz",
      "    hCCDDDDCCccz",
      "    E        ccz",
      "    hFIFIFIFIccz",
      "    h J J J Jccz",
      "KLLMhNJNJNJNJccz",
      "cccccccccccccccz",
      "eeeecccccccccccz",
      "zzzzzzzzzzzzzzzz"
    ],
    [
      "    bhhhhhhhhccz",
      "    hiOjk   Pccz",
      "Q   hj       ccz",
      "    hj       ccz",
      "    hw       ccz",
      "    R        ccz",
      "    h       Pccz",
      "    bhhhhhhhhccz",
      "    hPSSSSSSPccz",
      "    T        ccz",
      "    hUIUIUIUIccz",
      "    h J J J Jccz",
      "    h J J J Jccz",
      "cccccccccccccccz",
      "eeeecccccccccccz",
      "zzzzzzzzzzzzzzzz"
    ],
    [
      "    bhhhhhhhhccz",
      "    hiVq    Pccz",
      "   Whp       ccz",
      "   Wh        ccz",
      "    h        ccz",
      "    X        ccz",
      "    h       Pccz",
      "    bhhhhhhhhccz",
      "    h SSSSSS ccz",
      "    h        ccz",
      "    hIIIIIIIIccz",
      "    h J J J Jccz",
      "    h J J J Jccz",
      "cccccccccccccccz",
      "eeeecccccccccccz",
      "zzzzzzzzzzzzzzzz"
    ],
    [
      "    bhhhhhhhhccz",
      "    hi       ccz",
      "    h        ccz",
      "    h        ccz",
      "    h        ccz",
      "    h        ccz",
      "    h        ccz",
      "    bhhhhhhhhccz",
      "    hYYYYYYYYccz",
      "    hYYYYYYYYccz",
      "    hYYYYYYYYccz",
      "    hYYYYYYYYccz",
      "    hZY!YZYZYccz",
      "cccccccccccccccz",
      "eeeecccccccccccz",
      "zzzzzzzzzzzzzzzz"
    ],
    [
      "0100bhhhhhhhhcez",
      "0100X22222222cez",
      "0300X24222242cez",
      "3300X22222222cez",
      "0000X22222222cez",
      "0000X24222242cez",
      "0000X22222222cez",
      "hhhhbhhhhhhhhcez",
      "5555h66666666cez",
      "5535h6 6 6 6ccez",
      "5515h6 6 6 6ccez",
      "5515h6 6 6 6ccez",
      "5555h6 6 6 6ccez",
      "ccccccccccccccez",
      "eeeeeeeeeeeeeeez",
      "zzzzzzzzzzzzzzzz"
    ]
  ]
}