{
  "name": "multi_hospital_2_base1",
  "refpalette": "c70cities:multi_hospital_2_base1_palette",
  "xsize": 16,
  "zsize": 16,
  "slices": [
    [
      "vvvvvvvvvvvvvvvv",
      "aaaaaaaaaaaaaaav",
      "aaaaaaaaaaaaaaav",
      "bbaaaaaaaaaaaaav",
      "bbaaaaaaaaaaaaav",
      "bbaaaaaaaaaaaaav",
      "bbaaaaaaaaaaaaav",
      "bbaaaaaaaaaaaaav",
      "bbbbbbbbbbbbbbbv",
      "bbcccccccccccccv",
      "bbcccccccccccccv",
      "bbcccccccccccccv",
      "bbdddddddddddddv",
      "bbdddddddddddddv",
      "bbdddddddddddddv",
      "bbcccccccccccccv"
    ],
    [
      "vvvvvvvvvvvvvvvv",
      "aaaaaaaaaaaaaaav",
      "aaaaaaaaaaaaaaav",
      "eeaaaaaaaaaaaaav",
      "feaaaaaaaaaaaaav",
      " eaaaaaaaaaaaaav",
      " eaaaaaaaaaaaaav",
      " eaaaaaaaaaaaaav",
      " bvvvvvvvvvvvvvv",
      "ghc c c c c c cv",
      "ghc c c c c c cv",
      " bc c c c c c cv",
      "ii             v",
      "               v",
      "               v",
      "jbc c c c c c cv"
    ],
    [
      "vvvvvvvvvvvvvvvv",
      "aaaaaaaaaaaaaaav",
      "aaaaaaaaaaaaaaav",
      "eeaaaaaaaaaaaaav",
      " eaaaaaaaaaaaaav",
      " eaaaaaaaaaaaaav",
      " eaaaaaaaaaaaaav",
      " eaaaaaaaaaaaaav",
      " bvvvvvvvvvvvvvv",
      " hckckckckckckcv",
      "lhckckckckckckcv",
      " bckckckckckckcv",
      "ii             v",
      "               v",
      "               v",
      "mbckckckckckckcv"
    ],
    [
      "vvvvvvvvvvvvvvvv",
      "aaaaaaaaaaaaaaav",
      "aaaaaaaaaaaaaaav",
      "eeaaaaaaaaaaaaav",
      " eaaaaaaaaaaaaav",
      " eaaaaaaaaaaaaav",
      " eaaaaaaaaaaaaav",
      " eaaaaaaaaaaaaav",
      " bvvvvvvvvvvvvvv",
      " hcncncncncncncv",
      " hcncncncncncncv",
      " bcncncncncncncv",
      "ii             v",
      "               v",
      "               v",
      " bcncncncncncncv"
    ],
    [
      "vvvvvvvvvvvvvvvv",
      "aaaaaaaaaaaaaaav",
      "aaaaaaaaaaaaaaav",
      "eeaaaaaaaaaaaaav",
      " eaaaaaaaaaaaaav",
      " eaaaaaaaaaaaaav",
      " eaaaaaaaaaaaaav",
      " eaaaaaaaaaaaaav",
      " bvvvvvvvvvvvvvv",
      " hc c c c c c cv",
      " hc c c c c!c cv",
      " bc c c c c c cv",
      "ii             v",
      "               v",
      "               v",
      " bc c c c c c cv"
    ],
    [
      "vvvvvvvvvvvvvvvv",
      "aaaaaaaaaaaaaaav",
      "aaaaaaaaaaaaaaav",
      "eeaaaaaaaaaaaaav",
      "oeaaaaaaaaaaaaav",
      "oeaaaaaaaaaaaaav",
      "oeaaaaaaaaaaaaav",
      "oeaaaaaaaaaaaaav",
      "bbvvvvvvvvvvvvvv",
      "obcccccccccccccv",
      "obcccccccccccccv",
      "bbcccccccccccccv",
      "pbqqqqqqqqqqqqqv",
      "qbqqqqqqqqqqqqqv",
      "qbqqqqqqqqqqqqqv",
      "qbcccccccccccccv"
    ]
  ]
}