{
  "name": "multi_militarybase_2_floor1",
  "refpalette": "c70cities:multi_militarybase_2_floor1_palette",
  "xsize": 16,
  "zsize": 16,
  "slices": [
    [
      "                ",
      "                ",
      "                ",
      "                ",
      "aaaaaaaa        ",
      "       a        ",
      "       a        ",
      "       a        ",
      "       a        ",
      "aaa    a        ",
      "  a    a        ",
      "  a    a        ",
      "  a    a        ",
      "  a    a        ",
      "  a    a        ",
      "  a    a        "
    ],
    [
      "                ",
      "                ",
      "                ",
      "                ",
      "                ",
      "                ",
      "                ",
      "                ",
      "                ",
      "                ",
      "                ",
      "                ",
      "                ",
      "                ",
      "                ",
      "                "
    ],
    [
      "                ",
      "                ",
      "                ",
      "                ",
      "                ",
      "                ",
      "                ",
      "                ",
      "                ",
      "                ",
      "                ",
      "                ",
      "                ",
      "                ",
      "                ",
      "                "
    ],
    [
      "                ",
      "~~~~~~~~~~~~~~~ ",
      "~~~~~~~~~~~~~~~ ",
      "~~~~~~~~~~~~~~~ ",
      "~~~~~~~~~~~~~~~ ",
      "~~~~~~~~~~~~~~~ ",
      "~~~~~~~~~~~~~~~ ",
      "~~~~~~~~~~~~~~~ ",
      "~~~~~~~~~~~~~~~ ",
      "~~~~~~~~~~~~~~~ ",
      "~~~~~~~~~~~~~~~ ",
      "~~~~~~~~~~~~~~~ ",
      "~~~~~~~~~~~~~~~ ",
      "~~~~~~~~~~~~~~~ ",
      "~~~~~~~~~~~~~~~ ",
      "~~~~~~~~~~~~~~~ "
    ],
    [
      "                ",
      "~~~~~~~~~~~~~~~ ",
      "~~~~~~~~~~~~~~~ ",
      "~~~~~~ ~~~~~~~~ ",
      "~~~~~~~~~~~~~~~ ",
      "~~~~~~~~~~~~~~~ ",
      "~~~~~~~~~~~~~~~ ",
      "~~~~~~~~~~~~~~~ ",
      "~~~~~~~~~~~~~~~ ",
      "~~~~~~~~~~~~~~~ ",
      "~~~~~~~~~~~~~~~ ",
      "~~~~~~~~~~~~~~~ ",
      "~~~~~~~~~~~~~~~ ",
      "~~~~~~~~~~~~~~~ ",
      "~~~~~~~~~~~~~~~ ",
      "~~~~~~~~~~~~~~~ "
    ],
    [
      "                ",
      "~~~~~~~~~~~~~~~ ",
      "~~~~~~~~~~~~~~~ ",
      "~~~~~~~~~~~~~~~ ",
      "~~~~~~~~~~~~~~~ ",
      "~~~~~~~~~~~~~~~ ",
      "~~~~~~~~~~~~~~~ ",
      "~~~~~~~~~~~~~~~ ",
      "~~~~~~~~~~~~~~~ ",
      "~~~~~~~~~~~~~~~ ",
      "~~~~~~~~~~~~~~~ ",
      "~~~~~~~~~~~~~~~ ",
      "~~~~~~~~~~~~~~~ ",
      "~~~~~~~~~~~~~~~ ",
      "~~~~~~~~~~~~~~~ ",
      "~~~~~~~~~~~~~~~ "
    ]
  ]
}