{
  "name": "multi_communitycenter_7_ground",
  "refpalette": "c70cities:multi_communitycenter_7_ground_palette",
  "xsize": 16,
  "zsize": 16,
  "slices": [
    [
      "aaab    baaaaaGc",
      "aaab    baaaaaGc",
      "aaab    baaaaaGc",
      "aaabddddbaaaaaGc",
      "aaabbbbbbaaaaaGc",
      "aaaaaaaaaaaaaaGc",
      "aaaaaaaaaaaaaaGc",
      "aaaaaaaaaaaaaaGc",
      "aaaaaaaaaaaaaaGc",
      "aaaaaaaaaaaaaaGc",
      "aaaaaaaaaaaaaaGc",
      "aaaaaaaaaaaaaaGc",
      "eeeeeeaaaaaaaaGc",
      "ffffffaaaaaaaaGc",
      "ffffffaaaaaaaaGc",
      "ffffffaaaaaaaaGc"
    ],
    [
      "  gh    hg   ij ",
      " klh    hl  mno ",
      " plh    hl qqno ",
      " rlhhhhhhl s no ",
      "  gllllllg  mij ",
      "   ttuuwx    no ",
      "        y  qqno ",
      "        x  s no ",
      "  uA B   gCCCij ",
      "   D B  x m mno ",
      "   E  B y qqqno ",
      "   F!B  x s sno ",
      "IJKKKK   gCCCij ",
      "  x  K  x m mno ",
      "  L MK  y qqqno ",
      "  xNNK  x s sno "
    ],
    [
      "  g      g   i  ",
      "  l      l   n  ",
      "  l      l  !n  ",
      "  l      l   n  ",
      "  gllllllg   i  ",
      "       Ox    n  ",
      "        P  Q n  ",
      "        x    n  ",
      "    R    gSSSi  ",
      "    R   x    n  ",
      "    R   P    n  ",
      "    R   x    n  ",
      "TUKKKK   gSSSi  ",
      "  x  K  x    n  ",
      "  V WK  P    n  ",
      "  xNNK  x    n  "
    ],
    [
      "  g      g   i  ",
      "  l      l   X  ",
      "  l      l   X  ",
      "  l      l   X  ",
      "  gllllllg   i  ",
      "        x    X  ",
      "        x    X  ",
      "        x    X  ",
      "         gCCCi  ",
      "        x    X  ",
      "        x    X  ",
      "        x    X  ",
      "KKKKKK   gCCCi  ",
      "  xYYK  x    X  ",
      "  xYYK  x    X  ",
      "  xZZK  x    X  "
    ],
    [
      "  g      g   i  ",
      "  l      l   n  ",
      "  l      l   n  ",
      "  l      l   n  ",
      " 0gllllllg0  i  ",
      "   11111x    n  ",
      "        x    n  ",
      "        x    n  ",
      "  2     0gCCCi  ",
      "        x    n  ",
      "        x    n  ",
      "        x    n  ",
      "KKKKKK   gCCCi  ",
      "   34K  x    n  ",
      "    4K  x    n  ",
      "   33K  x    n  "
    ],
    [
      "aaaaaaaaaaaaa5  ",
      "aaaaaaaaaaaaa5  ",
      "aaaaaaaaaaaaa5  ",
      "aaaaaaaaaaaaa5  ",
      "aaaaaaaaaaaaai  ",
      "aaaaaaaaaaaaa5  ",
      "aaaaaaaaaaaaa5  ",
      "aaaaaaaaaaaaa5  ",
      "aaaaaaaaaaaaa5  ",
      "aaaaaaaaaaaaa5  ",
      "aaaaaaaaaaaaa5  ",
      "aaaaaaaaaaaaa5  ",
      "KKKKKKaaaaaaai  ",
      "bbbbbKaaaaaaa5  ",
      "bbbbbKaaaaaaa5  ",
      "bbbbbKaaaaaaa5  "
    ]
  ]
}