{
  "name": "multi_laboratory1_1_base7",
  "refpalette": "c70cities:multi_laboratory1_1_base7_palette",
  "xsize": 16,
  "zsize": 16,
  "slices": [
    [
      "zaaaaabbbcaaacaa",
      "zaaaaabbbaaaacaa",
      "zaaaaabaaaaaacaa",
      "zaaaaaaaaaaaacaa",
      "zaaaaabaabaaacaa",
      "zaaaaabaaaaaacaa",
      "zaaaaaaaaaaaacaa",
      "zaaaaaaaaaaaacaa",
      "zaaaaaaaaaaaacaa",
      "zaaaaaaaabaaacaa",
      "zaaaaaaaaaaaacaa",
      "zaaaaaaaaaaaacaa",
      "zaaaaaaaaaaaacad",
      "zaaaaaaaaaaaccad",
      "zaaaaaaaaaaaaadd",
      "zaaaaaaaaaaaaada"
    ],
    [
      "zaaaabe effaaaaa",
      "zaaaabg hfaaaaaa",
      "zaaaai  caaaaaaa",
      "zaaaah  baaaaaaa",
      "zaaaaa  jhaaaaaa",
      "zaaaaae  iaaaaaa",
      "zaaaaai   caaaaa",
      "zaaaaaah   iacaa",
      "zaaaaaaaeg ifbaa",
      "zaaaaaaab iaffaa",
      "zaaaaaaaaaafffaa",
      "zaaaaaaaaaaaffaa",
      "zaaaaaaaaaaaa aa",
      "zaaaaaaaaaaaaaaa",
      "zaaaaaaaaaaaaaak",
      "zaaaaaaaaaaaaaaa"
    ],
    [
      "zaaaae  efffaaaa",
      "zaaaaa  hfaaaaaa",
      "zaaaa   aaaaaaaa",
      "zaaaah  baaaaaaa",
      "zaaaa    haaaaaa",
      "zaaaai    laaaaa",
      "zaaaal     aaaaa",
      "zaaaaaah    haaa",
      "zaaaaaaa     eba",
      "zaaaaaaab    iih",
      "zaaaaaaaaahiiffi",
      "zaaaaaaaaaaflcaa",
      "zaaaaaaaaaaafbba",
      "zaaaaaaaaaaaaaba",
      "zaaaaaaaaaaaaaak",
      "zaaaaaaaaaaaaaaa"
    ],
    [
      "zaaaae  maffaaaa",
      "zaaaaa  aaaaaaaa",
      "zaaaac  baaaaaaa",
      "zaaaah  baaaaaaa",
      "zaaaa   mhaaaaaa",
      "zaaaa    faaaaaa",
      "zaaaaa   maaaaaa",
      "zaaaaaah    haaa",
      "zaaaaaaaa    eba",
      "zaaaaaaaaa     h",
      "zaaaaaaaaah     ",
      "zaaaaaaaaaaa    ",
      "zaaaaaaaaaaaae  ",
      "zaaaaaaaaaaaabbn",
      "zaaaaaaaaaaaaaak",
      "zaaaaaaaaaaaaaaf"
    ],
    [
      "zaaaaa maaaaaaaa",
      "zaaaaaaaaaaaaaaa",
      "zaaaaaamaaaaaaaa",
      "zaaaaammaaaaaaaa",
      "zaaaala aaaaaaaa",
      "zaaaaaaaaaaaaaaa",
      "zaaaaaaaaaaaaaaa",
      "zaaaaaaamaa haaa",
      "zaaaaaaaaam   ca",
      "zaaaaaaaaa     h",
      "zaaaaaaaaaaa    ",
      "zaaaaaaaaaaaa   ",
      "zaaaaaaaaaaaaf  ",
      "zaaaaaaaaaaaaabn",
      "zaaaaaaaaaaaaaak",
      "zaaaaaaaaaaaaaa "
    ],
    [
      "zaaaaaaaaaaaaaaa",
      "zaaaaaaaaaaaaaaa",
      "zaaaaaaaaaaaaaaa",
      "zaaaaaaaaaaaaaaa",
      "zaaaaaaaaaaaaaaa",
      "zaaaaaaaaaaaaaaa",
      "zaaaaaaaaaaaaaaa",
      "zaaaaaaaaaaaafaa",
      "zaaaaaaaaaaaacca",
      "zaaaaaaaaaaammma",
      "zaaaaaaaaaaaammm",
      "zaaaaaaaaaaaammm",
      "zaaaaaaaaaaaafom",
      "zaaaaaaaaaaaafan",
      "zaaaaaaaaaaaaaak",
      "zaaaaaaaaaaaaaa "
    ]
  ]
}