{
  "name": "multi_megatower1_5_floor3",
  "refpalette": "c70cities:multi_megatower1_5_floor3_palette",
  "xsize": 16,
  "zsize": 16,
  "slices": [
    [
      "aaaaaaaaaaaaaaaa",
      "aaaaaaaaaaaaaaaa",
      "aaaabaaaaaabaaaa",
      "cdddecccdddecccd",
      "    f      f    ",
      "                ",
      "                ",
      "                ",
      "                ",
      "                ",
      "                ",
      "                ",
      "                ",
      "                ",
      "                ",
      "                "
    ],
    [
      "g  hijg  klimn  ",
      " op i po  qiq  o",
      "rrrrbrrrrrrbrrrr",
      "cdddecccdddecccd",
      "    f      f    ",
      "                ",
      "                ",
      "                ",
      "                ",
      "                ",
      "                ",
      "                ",
      "                ",
      "                ",
      "                ",
      "                "
    ],
    [
      "    i      i    ",
      "  s i     tiu   ",
      "wwwrbrwwwwrbrwww",
      "cdddecccdddecccd",
      "    f      f    ",
      "                ",
      "                ",
      "                ",
      "                ",
      "                ",
      "                ",
      "                ",
      "                ",
      "                ",
      "                ",
      "                "
    ],
    [
      "    i      i    ",
      "xyA i yAyA i yAy",
      "BBBrbrBBBBrbrBBB",
      "cdddecccdddecccd",
      "    f      f    ",
      "                ",
      "                ",
      "                ",
      "                ",
      "                ",
      "                ",
      "                ",
      "                ",
      "                ",
      "                ",
      "                "
    ],
    [
      "    i      i    ",
      "    i      i    ",
      "rrrrbrrrrrrbrrrr",
      "cdddecccdddecccd",
      "    f      f    ",
      "                ",
      "                ",
      "                ",
      "                ",
      "                ",
      "                ",
      "                ",
      "                ",
      "                ",
      "                ",
      "                "
    ],
    [
      "    CD     C    ",
      "    C      C    ",
      "EEEEbEEEEEEbEEEE",
      "cdddecccdddecccd",
      "    f      f    ",
      "                ",
      "                ",
      "                ",
      "                ",
      "                ",
      "                ",
      "                ",
      "                ",
      "                ",
      "                ",
      "                "
    ]
  ]
}