{
  "name": "multi_laboratory1_9_base3",
  "refpalette": "c70cities:multi_laboratory1_9_base3_palette",
  "xsize": 16,
  "zsize": 16,
  "slices": [
    [
      "aaaaaaaaaaaaaaaa",
      "aaaaaaaaaabaaaaa",
      "aaaaaaacaaaaaaaa",
      "aacaaaaaaaaaaaaa",
      "acaaaaaaaaaaaaaa",
      "bcdbaaaaaaaaaaaa",
      "a  aaaaaaaaa!aaa",
      "dddaaaaaaaaaaaaa",
      "baaaa!aaaaaaaaaa",
      "aaacaaaeaaaaaaaa",
      "aaaaaaaacaaaaaaa",
      "aaaaaaaaaaaaaaaa",
      "aaaaaaaaaaaaaaaa",
      "ffffffffffffffff",
      "gggggggggggggggg",
      "vvvvvvvvvvvvvvvv"
    ],
    [
      "hi    jk  l    j",
      "h m  lni o     n",
      "o    pn  h p   j",
      "qpr stnuuhw     ",
      "ix   r          ",
      " y   p ABCDE    ",
      "      FIIIIJKL  ",
      "dMpNMddddddddddd",
      "  p OOOcPuuQR SS",
      "   xqki  TUV N  ",
      "qk i    xq     S",
      "SWq        q W  ",
      " S WSX o WSq i  ",
      "ffffffffffffffff",
      "gggggggggggggggg",
      "vvvvvvvvvvvvvvvv"
    ],
    [
      "                ",
      "                ",
      "         k      ",
      "                ",
      "                ",
      "                ",
      "        EY Z0   ",
      "d  1cddddddddddd",
      "       c   Q    ",
      "       2        ",
      "                ",
      "                ",
      "                ",
      "ffffffffffffffff",
      "gggggggggggggggg",
      "vvvvvvvvvvvvvvvv"
    ],
    [
      "                ",
      "                ",
      "                ",
      "     1          ",
      "                ",
      "    c           ",
      "   2c       0   ",
      "r  ce33dd33ddddd",
      "     44e5666    ",
      "                ",
      "                ",
      "                ",
      "                ",
      "ffffffffffffffff",
      "gggggggggggggggg",
      "vvvvvvvvvvvvvvvv"
    ],
    [
      "                ",
      "                ",
      "                ",
      "     7          ",
      "    c           ",
      "    e2          ",
      "                ",
      "8 9c@3d333dddddd",
      "   2cmmc2mmm    ",
      "      1c        ",
      "                ",
      "                ",
      "                ",
      "ffffffffffffffff",
      "gggggggggggggggg",
      "vvvvvvvvvvvvvvvv"
    ],
    [
      "#$$d$$#$$%$$d$$%",
      "%$$d$$%$$%$$d$$%",
      "%$$d$$c$$#$$d$$%",
      "%$$d$c%%^^$$d$$%",
      "$$$dc$$$$$$$d$$$",
      "$$$d$$$$$$$$d$$$",
      "$$$d$$$$$$$$d$$$",
      "dddddddddddddddd",
      "9999c99999999999",
      "9%999ecc99%999%9",
      "9#999#9999#999#9",
      "9#999%9999^999#9",
      "9999999999999999",
      "ffffffffffffffff",
      "gggggggggggggggg",
      "vvvvvvvvvvvvvvvv"
    ]
  ]
}