{
  "name": "multi_laboratory1_14_base6",
  "refpalette": "c70cities:multi_laboratory1_14_base6_palette",
  "xsize": 16,
  "zsize": 16,
  "slices": [
    [
      "aaaabacdddddcaev",
      "faaaaacdddddcaev",
      "aaaaaacdddddcaev",
      "aaaaaacdddddcaev",
      "aaaaaacdddddcaev",
      "aaaaaacdddddcaev",
      "aaaaaacdddddcaev",
      "aaaabacdddddcaev",
      "aaaaaacccccccaev",
      "aaaaaaaaaaaaaaev",
      "aaaaaaaaaaaaaaev",
      "aaaaaaaaaaaaaaev",
      "aaaaaaaaaaaaaaev",
      "eeeeeaaaaaaaaaev",
      "ggggeeeeeeeeeeev",
      "vvvvvvvvvvvvvvvv"
    ],
    [
      "hijkb     l   dv",
      " mnop q rs    tv",
      "h   p    us   tv",
      "w  np   s   q tv",
      " n  p  x  rx  tv",
      "y ABp         tv",
      "C yhp   l  s  tv",
      " nhhb         dv",
      " m  p         tv",
      "    p       D tv",
      "    E  F      tv",
      "    I         tv",
      "    p        Jtv",
      "eeeepKKLLMNOL!tv",
      "ggggetttttttttev",
      "vvvvvvvvvvvvvvvv"
    ],
    [
      "    b         dv",
      "    P q       tv",
      "    P         tv",
      "    P       q tv",
      "    P  xQ Rx  tv",
      "    P         tv",
      "    P         tv",
      "  STb         dv",
      "    p       D tv",
      "    p         tv",
      "    U         tv",
      "    V         tv",
      "    p         tv",
      "eeeep         tv",
      "ggggetttttttttev",
      "vvvvvvvvvvvvvvvv"
    ],
    [
      "    b    W    dv",
      "    P q  W    tv",
      "    P   XYX   tv",
      "    P    W  q tv",
      "    P  RxxxQ  tv",
      "    P         tv",
      "    P    Y    tv",
      "   Zb   W W D dv",
      "    p   W W   tv",
      "    p         tv",
      "    0         tv",
      "    0         tv",
      "    p         tv",
      "eeeep         tv",
      "ggggetttttttttev",
      "vvvvvvvvvvvvvvvv"
    ],
    [
      "   1b 22343   dv",
      "      224 4   tv",
      "    P  54 46  tv",
      "    P   474 q tv",
      "    P   343   tv",
      "    P   8 8   tv",
      "    P   949 D tv",
      "    b  @#W#$  dv",
      "    p  @%  $  tv",
      "    p         tv",
      "    0         tv",
      "    0         tv",
      "    p         tv",
      "eeeep         tv",
      "ggggetttttttttev",
      "vvvvvvvvvvvvvvvv"
    ],
    [
      "   ^b  @494$  dv",
      "    P  &*9*(  tv",
      "    o  5*8*6  tv",
      "    P  &*9*(q tv",
      "    P  @434$  tv",
      "    P  @ ) $D tv",
      "    P  @4#4$  tv",
      "    b   @%$   dv",
      "    p         tv",
      "    p         tv",
      "    0         tv",
      "    0         tv",
      "    p         tv",
      "eeeep         tv",
      "ggggetttttttttev",
      "vvvvvvvvvvvvvvvv"
    ]
  ]
}