{
  "name": "multi_condo1_2_floor1",
  "refpalette": "c70cities:multi_condo1_2_floor1_palette",
  "xsize": 16,
  "zsize": 16,
  "slices": [
    [
      "   abccccccdeeee",
      "   abfffffffffff",
      " gggbhhhhhhhhhhh",
      "  ifbhhhhhhhhhhh",
      "  ifbhhhhhhhhhhh",
      "  ifbhhhhhhhhhhh",
      "  ifbhhhhhhhhhhh",
      "  ifbhhhhhhhhhhh",
      "  ifbhhhhhhhhhhh",
      "  ifbhhhhhhhhhhh",
      "  ifbhhhhhhhhhhh",
      "  ifjkkkkkkkkkkk",
      "  ifffffffglllll",
      "  iiiiiiiig     ",
      "          g     ",
      "                "
    ],
    [
      "    m           ",
      "    m           ",
      " ggnm           ",
      " ggom   pqp     ",
      " ggom  prrrp    ",
      " ggom prsrsrp   ",
      " ggom trsssru   ",
      " ggom prsrsrp   ",
      " ggom  prrrp    ",
      " ggom   pwp     ",
      " ggom           ",
      " ggommmmmmmmmmmm",
      " ggooooooox     ",
      " gggggggggg     ",
      " gggggggggg     ",
      "                "
    ],
    [
      "    m           ",
      "    m           ",
      "    m           ",
      "    m           ",
      "    m           ",
      "    m           ",
      "    m    ~~     ",
      "    m           ",
      "    m           ",
      "    m           ",
      "    m           ",
      "    mmmmmmmmmmmm",
      "                ",
      "                ",
      "                ",
      "                "
    ],
    [
      "                ",
      "                ",
      "                ",
      "                ",
      "                ",
      "                ",
      "          ~     ",
      "                ",
      "                ",
      "                ",
      "                ",
      "    y           ",
      "                ",
      "                ",
      "                ",
      "                "
    ],
    [
      "                ",
      "                ",
      "                ",
      "                ",
      "                ",
      "                ",
      "          ~     ",
      "                ",
      "                ",
      "                ",
      "                ",
      "    A           ",
      "                ",
      "                ",
      "                ",
      "                "
    ],
    [
      "                ",
      "                ",
      "                ",
      "                ",
      "                ",
      "                ",
      "                ",
      "                ",
      "                ",
      "                ",
      "                ",
      "                ",
      "                ",
      "                ",
      "                ",
      "                "
    ]
  ]
}