{
  "name": "multi_laboratory1_0_ground",
  "refpalette": "c70cities:multi_laboratory1_0_ground_palette",
  "xsize": 16,
  "zsize": 16,
  "slices": [
    [
      "zzzzzzzzzzzzzzzz",
      "zzzzazzaazaaabza",
      "zzzzzaavbbbccccc",
      "zazzaabvvccccccc",
      "zzzzaaavbccccccc",
      "azzazabvcccddddd",
      "zzazzzbbcccdeeee",
      "zaazaabvcccdeeee",
      "zazaaabvcccdeeee",
      "zzaazbbvcccdeeee",
      "zazzaavbcccdeee!",
      "zzzaaabbcccdeeee",
      "azazzbbvcccdeeee",
      "zzazaaabcccdeeee",
      "zazazabvcccdeeee",
      "zzzzzabvcccdeeee"
    ],
    [
      "  f  f  f   f   ",
      " ff   g       f ",
      "   f       hhhhh",
      "         hh     ",
      "f i      h      ",
      "    j   h  klmdn",
      " f o    h  npqrs",
      "   f    h  ntpqr",
      "f f     h  dutpw",
      "f       h  nxutu",
      "  y     h  nxAuw",
      " f      h  nxBAB",
      "   f    h  n  Bw",
      "        h  nx   ",
      "        h  nx   ",
      "f f     h  dCCCD"
    ],
    [
      "                ",
      "                ",
      "           hhhhh",
      "         hh     ",
      "  ~      E      ",
      "        h  kFIdJ",
      "        h  n   w",
      "        h  n    ",
      "        h  d   K",
      "        h  J    ",
      "        h  n   K",
      "        E  n   L",
      "        E  n   K",
      "        h  n    ",
      "        h  J    ",
      "        h  dCCCM"
    ],
    [
      "                ",
      "                ",
      "           EEEEE",
      "         EN     ",
      "         N      ",
      "        E  knndJ",
      "        E  n   O",
      "        E  n   L",
      "        E  d   P",
      "        N  J    ",
      "        E  n   P",
      "        E  n    ",
      "        N  n   P",
      "        E  n    ",
      "        E  J    ",
      "        E  dCCCQ"
    ],
    [
      "                ",
      "                ",
      "           NNENE",
      "         NN     ",
      "         N      ",
      "        N  knndJ",
      "        E  n    ",
      "        N  n    ",
      "        E  d   w",
      "        E  J   L",
      "        N  n   w",
      "        N  n    ",
      "        N  n   w",
      "        E  n    ",
      "        N  J    ",
      "        N  dCCCC"
    ],
    [
      "                ",
      "                ",
      "           ENNEN",
      "         EN     ",
      "         N      ",
      "        E  knndn",
      "        N  nRRRR",
      "        N  nRRRR",
      "        N  dRRRw",
      "        E  nRRRR",
      "        N  nRRRw",
      "        N  nRRRR",
      "        E  nRRRw",
      "        N  nRRRR",
      "        N  nRRRR",
      "        N  dCCCC"
    ]
  ]
}