{
  "name": "multi_condo1_1_floor2",
  "refpalette": "c70cities:multi_condo1_1_floor2_palette",
  "xsize": 16,
  "zsize": 16,
  "slices": [
    [
      "   abcccccdeffff",
      "  ggbbbbbbdefhii",
      "   ab     defj  ",
      "   ab    kdefj  ",
      "   ajddddddefj  ",
      "   ajddddddefj  ",
      "   ajddddddefj  ",
      "   ajddddddefj  ",
      "   ajddddddefj  ",
      "   ajddddddefj  ",
      "   ajddddddefj  ",
      "   ajddddddefj  ",
      "   abddddddefj  ",
      "   abddddddefj  ",
      "  ggbbbbbbdeflmm",
      "   abcccccdeffff"
    ],
    [
      "    b nopqb     ",
      "  ggbbbbbbb  rrr",
      "    b    st  r  ",
      "    buuuuu   r  ",
      "    w        r  ",
      "    w xy     r  ",
      "    w    A   r  ",
      "    w BB C   r  ",
      "    w BB C   r  ",
      "    w    D   r  ",
      "    w EF     r  ",
      "    w        r  ",
      "    b        r  ",
      "    bIIIIIt  r  ",
      "  ggbbbbbbb  rrr",
      "    bJK LMb     "
    ],
    [
      "    bNn   b     ",
      "  ggbbbbbbb     ",
      "    bO  O P     ",
      "    b           ",
      "    w           ",
      "    w           ",
      "    w           ",
      "    w           ",
      "    w           ",
      "    w           ",
      "    w           ",
      "    w           ",
      "    b           ",
      "    bIIIIIP     ",
      "  ggbbbbbbb     ",
      "    b     b     "
    ],
    [
      "    bQ    b     ",
      "  ggbbbbbbb     ",
      "    bR ORO      ",
      "    b           ",
      "    w           ",
      "    w           ",
      "    w           ",
      "    w           ",
      "    w           ",
      "    w           ",
      "    w           ",
      "    w           ",
      "    b           ",
      "    bO SO       ",
      "  ggbbbbbbb     ",
      "    b     b     "
    ],
    [
      "    b     b     ",
      "  ggbbbbbbb     ",
      "    bRORRR      ",
      "    b           ",
      "    w           ",
      "    w           ",
      "    w           ",
      "    w           ",
      "    w           ",
      "    w           ",
      "    w           ",
      "    w           ",
      "    b           ",
      "    bRO RO      ",
      "  ggbbbbbbb     ",
      "    b     b     "
    ],
    [
      "    bTTTTTb     ",
      "  ggbbbbbbb     ",
      "    bRRRRR      ",
      "    b           ",
      "    U           ",
      "    U           ",
      "    U           ",
      "    U           ",
      "    U           ",
      "    U           ",
      "    U           ",
      "    U           ",
      "    b           ",
      "    bRRORR      ",
      "  ggbbbbbbb     ",
      "    bTTTTTb     "
    ]
  ]
}