{
  "name": "multi_megatower1_7_floor12",
  "refpalette": "c70cities:multi_megatower1_7_floor12_palette",
  "xsize": 16,
  "zsize": 16,
  "slices": [
    [
      "aaabc           ",
      "aaabd           ",
      "aaabd           ",
      "aaabd           ",
      "eefghi          ",
      "eeabc           ",
      "eeabc           ",
      "eeabc           ",
      "eeabd           ",
      "eeabd           ",
      "eeabd           ",
      "eefghi          ",
      "aaabc           ",
      "aaabc           ",
      "aaabc           ",
      "aaabd           "
    ],
    [
      "j k c           ",
      "  k d           ",
      "l k d           ",
      "mnk d           ",
      "oof hi          ",
      "ppk c           ",
      " qk c           ",
      "ppk c           ",
      " qk d           ",
      "ppk d           ",
      " qk d           ",
      "oof hi          ",
      " rk c           ",
      " sk c           ",
      "t k c           ",
      "  k d           "
    ],
    [
      "  u c           ",
      "  u d           ",
      "  u d           ",
      " wk d           ",
      "oof hi          ",
      "ppk c           ",
      "  k c           ",
      "ppk c           ",
      "  k d           ",
      "ppk d           ",
      "  k d           ",
      "oof hi          ",
      "  k c           ",
      "  u c           ",
      "  u c           ",
      "  u d           "
    ],
    [
      "  x c           ",
      "  x d           ",
      "  x d           ",
      " wk d           ",
      "oof hi          ",
      "ppk c           ",
      "  k c           ",
      "ppk c           ",
      "  k d           ",
      "ppk d           ",
      "  k d           ",
      "oof hi          ",
      "  k c           ",
      "  x c           ",
      "  x c           ",
      "  x d           "
    ],
    [
      "yyk c           ",
      "yyk d           ",
      "yyk d           ",
      "yyk d           ",
      "oof hi          ",
      "AAk c           ",
      "A!k c           ",
      "AAk c           ",
      "ABk d           ",
      "AAk d           ",
      "ABk d           ",
      "oof hi          ",
      "yyk c           ",
      "yyk c           ",
      "yyk c           ",
      "yyk d           "
    ],
    [
      " CD c           ",
      "ECD d           ",
      " CD d           ",
      " CD d           ",
      "FFfIhi          ",
      "ECD c           ",
      "CCD c           ",
      "ECD c           ",
      "CCD d           ",
      " CD d           ",
      "CCD d           ",
      "FFfIhi          ",
      "ECD c           ",
      " CD c           ",
      " CD c           ",
      "ECD d           "
    ]
  ]
}