{
  "name": "multi_laboratory1_4_base5",
  "refpalette": "c70cities:multi_laboratory1_4_base5_palette",
  "xsize": 16,
  "zsize": 16,
  "slices": [
    [
      "zabbbba    ac   ",
      "zdbbbba    e    ",
      "zdbbbba    e    ",
      "zdbbbba    e    ",
      "zdbbbba    e    ",
      "zdbbbba    e    ",
      "zdbbbba    e    ",
      "zabbbba    ac   ",
      "zdbbbba    f    ",
      "zdbbbba    f    ",
      "zdbbbba    g    ",
      "zdbbbba    g    ",
      "zdbbbba    f    ",
      "zdbbbba    fdddd",
      "zdddddddddddhhhh",
      "zzzzzzzzzzzzzzzz"
    ],
    [
      "zaffffaii  a    ",
      "zdjjklfii  e    ",
      "zd m  fii  e    ",
      "zdn   fii  e    ",
      "zdoo  fii  e    ",
      "zdjj  fii  e    ",
      "zd m  fii  e    ",
      "zap   aii  a    ",
      "zdoo  fii  f    ",
      "zd    gii  f    ",
      "zd    qii  g    ",
      "zdn   rii  g    ",
      "zd  p gii  f    ",
      "zdossofii  fdddd",
      "zdddddddddddhhhh",
      "zzzzzzzzzzzzzzzz"
    ],
    [
      "zaffffa    a    ",
      "zd t  f    e    ",
      "zd    e    e    ",
      "zd    e    e    ",
      "zdu   e    e    ",
      "zdwt  e    e    ",
      "zd    f    e    ",
      "za    a    a    ",
      "zdk   f    f    ",
      "zd    g    f    ",
      "zd    x    g    ",
      "zd    y    g    ",
      "zd    g    f    ",
      "zd A Bf    fdddd",
      "zdddddddddddhhhh",
      "zzzzzzzzzzzzzzzz"
    ],
    [
      "zaffffa    a    ",
      "zd    f    e    ",
      "zd    e    e    ",
      "zd    e    e    ",
      "zd    e    e    ",
      "zd    e    e    ",
      "zd    f    e    ",
      "za    a    a    ",
      "zd    f    f    ",
      "zd    g    f    ",
      "zd    g    g    ",
      "zd    g    g    ",
      "zd    g    f    ",
      "zd    f    fdddd",
      "zdddddddddddhhhh",
      "zzzzzzzzzzzzzzzz"
    ],
    [
      "zaffffa    a    ",
      "zd    f    f    ",
      "zd    f    f    ",
      "zd    f    f    ",
      "zd    f    f    ",
      "zd    f    f    ",
      "zd    f    f    ",
      "za    a    a    ",
      "zd    f    f    ",
      "zd    f    f    ",
      "zd    f    f    ",
      "zd    f    f    ",
      "zd    f    f    ",
      "zd    f    fdddd",
      "zdddddddddddhhhh",
      "zzzzzzzzzzzzzzzz"
    ],
    [
      "zaffffaCCCCfCCCC",
      "zdDDDDfCCCCfCCCC",
      "zdDEEDfCCCCfCCCC",
      "zdDDDDfCFFCfCCCC",
      "zdDDDDfCFFCfCCCC",
      "zdDEEDfCCCCfCCCC",
      "zdDDDDfCCCCfCCCC",
      "zaffffaCCCCfCCCC",
      "zdDDDDfCCCCfCCCC",
      "zdDEIDfCCCCfCCCC",
      "zdDDDDfCFJCfCCCC",
      "zdDDDDfCFJCfCCCC",
      "zdDEEDfCCCCfCCCC",
      "zdDDDDfCCCCfdddd",
      "zdddddddddddhhhh",
      "zzzzzzzzzzzzzzzz"
    ]
  ]
}