{
  "name": "multi_laboratory1_8_base6",
  "refpalette": "c70cities:multi_laboratory1_8_base6_palette",
  "xsize": 16,
  "zsize": 16,
  "slices": [
    [
      "aaaaaaabbaaaaaaa",
      "aaaaaaaaaaaaaaaa",
      "cccdccccccccdccc",
      "aaaaaaaaaaaaaaaa",
      "aaaaaaaaaaaaaaaa",
      "aaaaaaaaaaaaaaaa",
      "aaaaaaaaaaaaaaaa",
      "aaaaaaaaaaaaaaae",
      "aaaaaaaaaaaaaaae",
      "aaaaaaaaaaaaaaaa",
      "aaaaaaaaaaaaaaaa",
      "aaaaaafaaaaaaaaa",
      "aaaaaaaaaaaaaaaa",
      "aaaaaaaaaaaaaaaa",
      "aaaaaaaaaaaaaaaa",
      "aaaaaaaaaaaaaaaa"
    ],
    [
      "             g  ",
      "            h gi",
      "jjjdjjjjjjjjdjj ",
      "                ",
      "                ",
      "                ",
      "      kkkk      ",
      "      kkkk    l ",
      "  mccccccccccc n",
      "  mffffffffffcol",
      "  cffpfffqrffcs ",
      "ttcfpqrfffqffcuu",
      "ttcfffffpffffcuu",
      "ttcfeffwxweffcuu",
      "ttcffppxy!fffcuu",
      "  cffeffqffffcAp"
    ],
    [
      "                ",
      "                ",
      "BBBdBBBBBBBBdBB ",
      "                ",
      "                ",
      "                ",
      "                ",
      "                ",
      "  CCCCCCCCCCCC  ",
      "  Cpepe      C  ",
      "  CDppp    i C  ",
      "  Cpe        C  ",
      "  Cpp   nE   C  ",
      "  C  E    F  C  ",
      "  C   F  sI  C  ",
      "  C   E  A   CAn"
    ],
    [
      "                ",
      "                ",
      "BBBdBBBBBBBBdB  ",
      "                ",
      "                ",
      "                ",
      "                ",
      "                ",
      "  CCCCCCCCCCCC  ",
      "  Cp F       C  ",
      "  Cpe        C  ",
      "  CJ         C  ",
      "  CF         C  ",
      "  C          C  ",
      "  C          C  ",
      "  C     KA   Cn "
    ],
    [
      "                ",
      "                ",
      "BBBdBBBBBBBBdBB ",
      "                ",
      "                ",
      "                ",
      "                ",
      "                ",
      "  CCCCCCCCCCCC  ",
      "  CL         C  ",
      "  Cp         C  ",
      "  C          C  ",
      "  C          C  ",
      "  C          C  ",
      "  C      MK  C  ",
      "  C     nA   C  "
    ],
    [
      "                ",
      "                ",
      "BBBdBBBBBBBBdBBN",
      "                ",
      "                ",
      "                ",
      "                ",
      "                ",
      "  CCCCCCCCCCCC  ",
      "  Cp         C  ",
      "  CA         C  ",
      "  C          C  ",
      "  C          C  ",
      "  C          C  ",
      "  C       n  C  ",
      "  C      A   C  "
    ]
  ]
}