{
  "name": "multi_militarybase_4_ground",
  "refpalette": "c70cities:multi_militarybase_4_ground_palette",
  "xsize": 16,
  "zsize": 16,
  "slices": [
    [
      "zzzzzzzzzzzzzzzz",
      "aaaaaaaaaaaaaaaz",
      "bzzzzzbzzzzbbbaz",
      "bbzbbzzbzbzzbbaz",
      "bbbbcccbccczzzaz",
      "bbbbbbbbbbbzzbaz",
      "bbbbbbbbbbbbzzaz",
      "bbbcccccbccbzzaz",
      "bbbbbbbbbbbbbzaz",
      "bbbbbbbbbbbbbbaz",
      "bbcbcccccccbzzaz",
      "bbbbbbbbbbbbbzaz",
      "bbbbbbbbbbbbzzaz",
      "bbbbcccccbcbzbaz",
      "bbbbbbbbbbbbbzaz",
      "bbbbbbbbbbbbbzaz"
    ],
    [
      "                ",
      "aaaaaaaaaaaaaaa ",
      " de e f e e  fa ",
      "      g   g   a ",
      "     hihhhih ea ",
      "     hjjjjjhe a ",
      "     hjjjjjh  a ",
      "     hihhhih ea ",
      "      k   k   a ",
      "      g   g  fa ",
      "     hihhhihe a ",
      "     hjjjjjh ea ",
      "     hjjjjjh ea ",
      "     hihhhih  a ",
      "      k   k  ea ",
      "              a "
    ],
    [
      "                ",
      "aaaaaaaaaaaaaaa ",
      "  d   f      fa ",
      "        l     a ",
      "    mnopqpors a ",
      "     tuwxyABC a ",
      "     DEwxyABC a ",
      "    mpFpInFJs a ",
      "        K     a ",
      "        L    fa ",
      "    mMNMqOPQs a ",
      "     R wxyABC a ",
      "     SEwxyABC a ",
      "    mOTMIMUVs a ",
      "        W     a ",
      "              a "
    ],
    [
      "                ",
      "aaaaaaaaaaaaaaa ",
      "   d  f      fa ",
      "     X        a ",
      "    mpYYZ01   a ",
      "     2   034  a ",
      "     5   036  a ",
      "    mnYY708   a ",
      "     9        a ",
      "             fa ",
      "    mMYYZ0@   a ",
      "     #   0$%  a ",
      "     ^   0$&  a ",
      "    mMYY70*   a ",
      "              a ",
      "              a "
    ],
    [
      "                ",
      "aaaaaaaaaaaaaaa ",
      "    d f      fa ",
      "              a ",
      "       636    a ",
      "     64pw6    a ",
      "     66pw4    a ",
      "       436    a ",
      "              a ",
      "             fa ",
      "       &$&    a ",
      "     &&O(&    a ",
      "     %&M(&    a ",
      "       &$%    a ",
      "              a ",
      "              a "
    ],
    [
      "                ",
      ")))))+-))))))[[ ",
      "     ]]]]]]]]{[ ",
      "             }\\ ",
      "             }\\ ",
      "       |     }\\ ",
      "       |     }\\ ",
      "             }\\ ",
      "             }\\ ",
      "             }- ",
      "             }\\ ",
      "       | ~   }\\ ",
      "       |     }\\ ",
      "             }\\ ",
      "             }\\ ",
      "             }\\ "
    ]
  ]
}