{
  "name": "multi_carservice_1_floor2",
  "refpalette": "c70cities:multi_carservice_1_floor2_palette",
  "xsize": 16,
  "zsize": 16,
  "slices": [
    [
      " abbbbbbbbbbbba ",
      " abbbbbbbbbbbba ",
      " abbbbbbbbbbbba ",
      " acdeecdeecbbbc ",
      "         Hffffe ",
      "         Hffffe ",
      "         Hffffe ",
      "            ffe ",
      "            ffe ",
      "            ffe ",
      "  c   c   ceeec ",
      "                ",
      "                ",
      "                ",
      "                ",
      "                "
    ],
    [
      " ag   h       i ",
      " aj kl k      i ",
      " a!mnopqqq    a ",
      " acaaacaaac   c ",
      "      rHf     r ",
      "      sHf     s ",
      "      sHf     s ",
      "              s ",
      "              s ",
      "              s ",
      "  c   cssscsssc ",
      "                ",
      "                ",
      "                ",
      "                ",
      "                "
    ],
    [
      " i            i ",
      " i            i ",
      " ctl  uqq     a ",
      " acaaacaaac   c ",
      "     Hf         ",
      "     Hf         ",
      "     Hf         ",
      "      w         ",
      "      w         ",
      "      c         ",
      "  c   c   c   c ",
      "                ",
      "                ",
      "                ",
      "                ",
      "                "
    ],
    [
      " a            i ",
      " a            i ",
      " a      q     a ",
      " acaaacaaacxxxc ",
      "  eff           ",
      "  eff           ",
      "  eff           ",
      "  effffH        ",
      "  effffH        ",
      "  effffH        ",
      "  ceeeceeec   c ",
      "                ",
      "                ",
      "                ",
      "                ",
      "                "
    ],
    [
      " a            y ",
      " a            y ",
      " a            a ",
      " acaaacaaacAAAc ",
      "  s       s     ",
      "  s       s     ",
      "  s       s     ",
      "  s     fHs     ",
      "  s     fHs     ",
      "  B     fHB     ",
      "  cssscsssc   c ",
      "                ",
      "                ",
      "                ",
      "                ",
      "                "
    ],
    [
      " assssssssssssa ",
      " assssssssssssa ",
      " aCCCCCCCCDCCCa ",
      " acaaacaaacaaac ",
      "          c     ",
      "          w     ",
      "          w     ",
      "          fH    ",
      "          fH    ",
      "          fH    ",
      "  c   c   c   c ",
      "                ",
      "                ",
      "                ",
      "                ",
      "                "
    ]
  ]
}