{
  "name": "multi_laboratory1_7_ground",
  "refpalette": "c70cities:multi_laboratory1_7_ground_palette",
  "xsize": 16,
  "zsize": 16,
  "slices": [
    [
      "aaaaaaaaaaaaaaaa",
      "aaaaaaaaaaaaaaaa",
      "aaaaaaaaaaaaaaaa",
      "aaaaaaaaaaaaaaaa",
      "aaaaaaaaaaaaaaaa",
      "baaaaaaaaaaaaaab",
      "baaaaaaaaaaaaaab",
      "bbaaaaaaaaaaaabb",
      "cbbbaaaaaaaabbbc",
      "cccbbbaaaabbbccc",
      "cccccbbbbbbccccc",
      "cccccccccccccccc",
      "cccccccccccccccc",
      "cccccccccccccccc",
      "cccccccccccccccc",
      "ccccc      ccccc"
    ],
    [
      "                ",
      "                ",
      "                ",
      "                ",
      "                ",
      "d              d",
      "d              d",
      "dd            dd",
      " ddd        ddd ",
      "   ddd    ddd   ",
      "     dddddd     ",
      "e              e",
      "fe            eg",
      "hhe  ij  ij  ehk",
      "  lm nnnnnn o h ",
      "  pmq      ros  "
    ],
    [
      "                ",
      "                ",
      "                ",
      "                ",
      "                ",
      "                ",
      "                ",
      "                ",
      "                ",
      "                ",
      "                ",
      "e              e",
      "!e            eg",
      "hhe          eh ",
      "  tm        o h ",
      "   m        o   "
    ],
    [
      "                ",
      "                ",
      "                ",
      "                ",
      "                ",
      "                ",
      "                ",
      "                ",
      "                ",
      "                ",
      "                ",
      "e              e",
      "ue            eg",
      "hhe          eh ",
      "  tm        o h ",
      "  wm        o   "
    ],
    [
      "                ",
      "                ",
      "                ",
      "                ",
      "                ",
      "                ",
      "                ",
      "                ",
      "                ",
      "                ",
      "                ",
      "e              e",
      " e            eg",
      "xye          eAg",
      "   m        o  g",
      "   m        o B "
    ],
    [
      "                ",
      "                ",
      "                ",
      "                ",
      "                ",
      "                ",
      "                ",
      "                ",
      "                ",
      "                ",
      "                ",
      "e              e",
      "Ce            eC",
      "CCe          eCC",
      "CCCm        oCCC",
      "CCCm D    D oCCC"
    ]
  ]
}