{
  "name": "multi_residential1_0_ground",
  "refpalette": "c70cities:multi_residential1_0_ground_palette",
  "xsize": 16,
  "zsize": 16,
  "slices": [
    [
      "GGGGGGGGGGGGGGGG",
      "GGGGGGGGGGGGGGGG",
      "GGGGGGGGGGGGGGGG",
      "GGGGGGGGGGGGGGGG",
      "GGaaaaaaaaaaaaGG",
      "aaaaaaaaaaaaaaGG",
      "aaaaaaaaaaaaaaGG",
      "aaaaaaaaaaaaaaGG",
      "aaaaaaaaaaaaaaGG",
      "aaaaaaaaaaaaaaGG",
      "aaaaaaaaaaaaaaGG",
      "GGaaaaaaaaaaaaGG",
      "GGGbccccccccbGGG",
      "GGGbccccccccbGGG",
      "GGGbccccccccbGGG",
      "GGGbccccccccbGGG"
    ],
    [
      "deeeefeeeefeeeed",
      "e              e",
      "d              e",
      "               e",
      "g vvvvvvvvvvvv f",
      "h v   i  i  jv e",
      " gklmnopqor sv e",
      "  ktnunwxnr yv e",
      "  ktnnnwxnr Av e",
      "g klmnoBCor Dv f",
      " hv   E  E  Fv e",
      " gvvvvvIJvvvvv e",
      "  KbLL   MNObK e",
      "  Kb       PbK f",
      "  KbQ      ObK e",
      "  KbQR     SbK e"
    ],
    [
      "deeeefeeeefeeeed",
      "e              e",
      "d              e",
      "               e",
      "  vvvvvvvvvvvv f",
      "  v          v e",
      "  k  TTUUVU  v e",
      "  k TWUXXnY  v e",
      "  k TWUXXnU  v e",
      "  k  TTUUZU  v f",
      "  v         0v e",
      "  vvvvv12vvvvv e",
      "   b3       b  e",
      "   b4      5b  f",
      "   b4       b  e",
      "   b6      7b  e"
    ],
    [
      "                ",
      "                ",
      "                ",
      "                ",
      "  vv888vv888vv  ",
      "  v         9v  ",
      "  k       @#$v  ",
      "  k    TT@@#%v  ",
      "  k    TT@@  v  ",
      "  k       @  v  ",
      "  v         !v  ",
      "  vvvvvvvvvvvv  ",
      "   b^  &&   b   ",
      "   8        8   ",
      "   8        8   ",
      "   b*       b   "
    ],
    [
      "                ",
      "                ",
      "                ",
      "                ",
      "  vvvvvvvvvvvv  ",
      "  v          v  ",
      "  v(         v  ",
      "  v(         v  ",
      "  v(         v  ",
      "  v(         v  ",
      "  v          v  ",
      "  vvvvvvvvvvvv  ",
      "   b        b   ",
      "   b        b   ",
      "   b        b   ",
      "   b        b   "
    ],
    [
      "                ",
      "                ",
      "                ",
      "                ",
      "  vvvvvvvvvvvv  ",
      "  v))))))))))v  ",
      "  v))))))))))v  ",
      "  v))))))))))v  ",
      "  v))))))))))v  ",
      "  v))))))))))v  ",
      "  v))))))))))v  ",
      "  vvvvvvvvvvvv  ",
      "  ))))))))))))  ",
      "  ))))))))))))  ",
      "  ))))))))))))  ",
      "  ))))))))))))  "
    ]
  ]
}