{
  "name": "multi_gallery_2_ground",
  "refpalette": "c70cities:multi_gallery_2_ground_palette",
  "xsize": 16,
  "zsize": 16,
  "slices": [
    [
      "GGGGGGGGGGGGGGGG",
      "GGGaaGaaaaGaaaaa",
      "GGaaaaaaGaaaaGaa",
      "GGaaGGGGGGaaGGGG",
      "bbaabbbGGaaGGvcG",
      "ccccccbGGaGGGvcG",
      "ccddccbGGaaGGvcG",
      "ccccccbGGaaGGvcG",
      "ccddcdbGGaaGGvcG",
      "cccccdbGGaGGGvcG",
      "ccddddbeGGaGGvcG",
      "ccccddbGGaaGGvcG",
      "ccddddbGGaaGGvcG",
      "ccddddbGGaGGGvcG",
      "ccddddbGGaGGGvcG",
      "cccccdbGGaaGGvcG"
    ],
    [
      " f  f   f     f ",
      "f               ",
      "                ",
      "     f       f  ",
      "gg  gggh    ivjf",
      " j    gik  liv  ",
      "  mm jgi    iv  ",
      "j     gin  nivj ",
      "  mm  gil  fiv  ",
      "    j gin  oiv  ",
      " jmm  gp   kivj ",
      "    j gil  livj ",
      "j mm  gin  qiv  ",
      "      gio  kivj ",
      "  mm jgi   niv q",
      "j     gik   iv  "
    ],
    [
      "                ",
      "                ",
      "                ",
      "                ",
      "                ",
      "             r  ",
      "             s  ",
      "             t  ",
      "             s  ",
      "             u  ",
      "       p     t  ",
      "             s  ",
      "             w  ",
      "             x  ",
      "             t  ",
      "             r  "
    ],
    [
      "                ",
      "                ",
      "                ",
      "                ",
      "             y  ",
      "             s  ",
      "             w  ",
      "      AAA    w  ",
      "     AAAAA   B  ",
      "     AApAA      ",
      "     AApAA   r  ",
      "      AAA    y  ",
      "             s  ",
      "             t  ",
      "             C  ",
      "             r  "
    ],
    [
      "                ",
      "                ",
      "                ",
      "                ",
      "                ",
      "                ",
      "                ",
      "                ",
      "      AAA       ",
      "      AAA       ",
      "      ApA       ",
      "                ",
      "                ",
      "                ",
      "                ",
      "                "
    ],
    [
      "                ",
      "                ",
      "                ",
      "                ",
      "                ",
      "                ",
      "                ",
      "                ",
      "                ",
      "                ",
      "                ",
      "       p        ",
      "                ",
      "                ",
      "                ",
      "                "
    ]
  ]
}