{
  "name": "multi_communitycenter_5_ground",
  "refpalette": "c70cities:multi_communitycenter_5_ground_palette",
  "xsize": 16,
  "zsize": 16,
  "slices": [
    [
      "aabcccbaaaaaaaab",
      "aaabbbbaaaGGaaab",
      "aaaaaaaaaGGGGaab",
      "aaaaaaaaaGGGGaad",
      "baaaaaaaaaGGaaad",
      "ebbaaaaaaaaaaaaa",
      "eeebbbaaaaaaaaaa",
      "eeeeebbbbbbbbbbf",
      "eeeeeagggggggggf",
      "eeeeeagggggggggf",
      "eeeeeagggggggggf",
      "aaeeeagggggggggf",
      "haaaaagggggggggf",
      "hhhhaaaaaaaaaaaf",
      "hhhhhhhhhhhhhhhh",
      "hhhhhhhhhhhhhhhh"
    ],
    [
      "  ijkjl        l",
      "   imnn   oo   n",
      "         oppo  n",
      "         oppo   ",
      "          oo    ",
      "               q",
      "   lnn          ",
      " r   nls sttssln",
      " r  rnuw  xx xxn",
      " r  rnyA       n",
      "    nnBB  xx xxn",
      "CC  Dn E       n",
      " CCCCn F  xx xxn",
      "    CCCCCCCCCCCC",
      "                ",
      "                "
    ],
    [
      "  i   l        l",
      "   imnn        n",
      "          II   n",
      "          II    ",
      "                ",
      "                ",
      "   lnn          ",
      " J   nls sttssln",
      " J  KnLL   L MNn",
      " J  Kn L       n",
      "    JnBB  O  PQn",
      "ss   nRS       n",
      " CCssnRF  TN QUn",
      "    sssCCsssCCss",
      "                ",
      "                "
    ],
    [
      "  i   l V    V l",
      "   imnn        n",
      "               n",
      "                ",
      "                ",
      "                ",
      "   lnn          ",
      " W  Xnls sttssln",
      " W  Wn         n",
      " W  Wn         n",
      "    WnBB       n",
      "ss   n F       n",
      " CCssn F       n",
      "    sssCCsssCCss",
      "                ",
      "                "
    ],
    [
      "  l   l YV  VY l",
      "   lmnn        n",
      "               n",
      "                ",
      "l               ",
      " ll             ",
      "   lnn          ",
      "    Xnllllllllln",
      "    Xn         n",
      "     n         n",
      "     n         n",
      "CC   n         n",
      " CCCCn         n",
      "    CCCCCCCCCCCC",
      "                ",
      "                "
    ],
    [
      "  nnZZn0YY VYY0n",
      "   nnnn00000000n",
      "      nnnnnnnnnn",
      "      1        1",
      "n     1        1",
      "nnn   1        1",
      "ZZnnnn1        1",
      "ZZZZZnnnnnnnnnnn",
      "ZZZZZnZZZZZZZZZn",
      "ZZZZZnZZZZZZZZZn",
      "ZZZZZnZZZZZZZZZn",
      "CCZZZnZZZZZZZZZn",
      " CCCCnZZZZZZZZZn",
      "    CCCCCCCCCCCC",
      "                ",
      "                "
    ]
  ]
}