{
  "name": "multi_carservice_1_floor1",
  "refpalette": "c70cities:multi_carservice_1_floor1_palette",
  "xsize": 16,
  "zsize": 16,
  "slices": [
    [
      " abbbbbbbbbbbba ",
      " abbbbbbbbbbbba ",
      " abbbbbbbbbbbba ",
      " acdeecdeecbbbc ",
      "         Hffffe ",
      "         Hffffe ",
      "         Hffffe ",
      "            ffe ",
      "            ffe ",
      "            ffe ",
      "  c   c   ceeec ",
      "                ",
      "                ",
      "                ",
      "                ",
      "                "
    ],
    [
      " aghi j   j   k ",
      " al  mnom     k ",
      " apqqqrooo    a ",
      " acaaacaaacsssc ",
      "      tHf     t ",
      "      uHf     u ",
      "      uHf     u ",
      "              u ",
      "              u ",
      "              u ",
      "  c   cuuucuuuc ",
      "                ",
      "                ",
      "                ",
      "                ",
      "                "
    ],
    [
      " k            k ",
      " k www        k ",
      " cxqqq        a ",
      " acaaacaaacsssc ",
      "     Hf         ",
      "     Hf         ",
      "     Hf         ",
      "      y         ",
      "      y         ",
      "      c         ",
      "  c   c   c   c ",
      "                ",
      "                ",
      "                ",
      "                ",
      "                "
    ],
    [
      " a            k ",
      " a            k ",
      " a            a ",
      " acaaacaaacsssc ",
      "  eff           ",
      "  eff           ",
      "  eff           ",
      "  effffH        ",
      "  effffH        ",
      "  effffH        ",
      "  ceeeceeec   c ",
      "                ",
      "                ",
      "                ",
      "                ",
      "                "
    ],
    [
      " a            A ",
      " a            A ",
      " a            a ",
      " acaaacaaacBBBc ",
      "  u       u     ",
      "  u       u     ",
      "  u       u     ",
      "  u     fHu     ",
      "  u     fHu     ",
      "  C     fHC     ",
      "  cuuucuuuc   c ",
      "                ",
      "                ",
      "                ",
      "                ",
      "                "
    ],
    [
      " auuuuuuuuuuuua ",
      " auuuuuuuuuuuua ",
      " aDDDDDDDDEDDDa ",
      " acaaacaaacaaac ",
      "          c     ",
      "          y     ",
      "          y     ",
      "          fH    ",
      "          fH    ",
      "          fH    ",
      "  c   c   c   c ",
      "                ",
      "                ",
      "                ",
      "                ",
      "                "
    ]
  ]
}