{
  "name": "multi_megatower1_1_floor2",
  "refpalette": "c70cities:multi_megatower1_1_floor2_palette",
  "xsize": 16,
  "zsize": 16,
  "slices": [
    [
      "            ab  ",
      "            cb  ",
      "            cbde",
      "            cbff",
      "           ghibb",
      "            abbb",
      "            abbb",
      "            abbb",
      "            cbbb",
      "            cbbb",
      "            cbbb",
      "           ghibb",
      "            abbb",
      "            abbb",
      "            abbb",
      "            cbbb"
    ],
    [
      "            aj  ",
      "            cjd ",
      "            cjk ",
      "            cj  ",
      "           ghicl",
      "            am  ",
      "            am  ",
      "            am  ",
      "            cm  ",
      "            cm  ",
      "            cm  ",
      "           ghinn",
      "            amo ",
      "            amp ",
      "            amq ",
      "            cmq "
    ],
    [
      "            ajf ",
      "            cjk ",
      "            cj  ",
      "            cj  ",
      "           ghicr",
      "            am  ",
      "            am  ",
      "            am  ",
      "            cm  ",
      "            cm  ",
      "            cm  ",
      "           ghinn",
      "            am  ",
      "            am  ",
      "            am  ",
      "            cms "
    ],
    [
      "            ajkt",
      "            cj  ",
      "            cj  ",
      "            cj u",
      "           ghicc",
      "            am  ",
      "            am  ",
      "            am  ",
      "            cm  ",
      "            cm  ",
      "            cm  ",
      "           ghinn",
      "            am  ",
      "            am  ",
      "            am  ",
      "            cm  "
    ],
    [
      "            aw e",
      "            cw t",
      "            cw  ",
      "            cw  ",
      "           ghicc",
      "            aw  ",
      "            aw  ",
      "            aw  ",
      "            cw  ",
      "            cw  ",
      "            cw  ",
      "           ghinn",
      "            aw  ",
      "            aw  ",
      "            aw  ",
      "            cw  "
    ],
    [
      "            ax  ",
      "            cx e",
      "            cx f",
      "            cxdf",
      "           ghiyy",
      "            ax  ",
      "            ax  ",
      "            ax  ",
      "            cx  ",
      "            cx  ",
      "            cxAA",
      "           ghiyy",
      "            axBB",
      "            ax  ",
      "            ax  ",
      "            cx  "
    ]
  ]
}