{
  "name": "multi_communitycenter_4_floor1",
  "refpalette": "c70cities:multi_communitycenter_4_floor1_palette",
  "xsize": 16,
  "zsize": 16,
  "slices": [
    [
      "              a ",
      "              a ",
      "              ab",
      "              ab",
      "  c           a ",
      "  c           a ",
      " dce          a ",
      "  ce          ab",
      "ffcgg         ab",
      "hhhhg         a ",
      "hhhhgg        a ",
      "hhhhhggg      a ",
      "hhhhhhhggggggggg",
      "ihhhhhhhjjhhhhhh",
      "iihhhhhhhhhhhhhh",
      "kiihhhhhhhhhhhhh"
    ],
    [
      "                ",
      "                ",
      "               b",
      "               b",
      "                ",
      "                ",
      "                ",
      "               b",
      "  c e          b",
      "  cce           ",
      " dlcee          ",
      "   cceee        ",
      "l  mccceeeeeeeeb",
      "fd    cccccccccb",
      "ffn    l d  l dl",
      " ffd     d l    "
    ],
    [
      "                ",
      "                ",
      "               b",
      "               b",
      "                ",
      "                ",
      "                ",
      "               b",
      "               b",
      "                ",
      "                ",
      "                ",
      "               b",
      "               b",
      "  ~             ",
      "                "
    ],
    [
      "                ",
      "                ",
      "               o",
      "               o",
      "                ",
      "                ",
      "                ",
      "               o",
      "               o",
      "                ",
      "                ",
      "                ",
      "               o",
      "               o",
      "                ",
      "                "
    ],
    [
      "             ppi",
      "             ppi",
      "             ppi",
      "             ppi",
      "             ppi",
      "             ppi",
      "             ppi",
      "             ppi",
      "             ppi",
      "             ppi",
      "             ppi",
      "             ppi",
      "             ppi",
      "             ppi",
      "             ppi",
      "             ppi"
    ],
    [
      "                ",
      "                ",
      "                ",
      "                ",
      "                ",
      "                ",
      "                ",
      "                ",
      "                ",
      "                ",
      "                ",
      "                ",
      "                ",
      "                ",
      "                ",
      "                "
    ]
  ]
}