{
  "name": "multi_laboratory1_2_base6",
  "refpalette": "c70cities:multi_laboratory1_2_base6_palette",
  "xsize": 16,
  "zsize": 16,
  "slices": [
    [
      "zabcccccccccccd ",
      "zabcccccccccccd ",
      "zabcccccccccccde",
      "zabcccccccccccdf",
      "zabccccccccgcccd",
      "zabccccccccccccd",
      "zabccccccccccccc",
      "zabccccccccccccc",
      "zabccccccccccccc",
      "zabccccccccccccc",
      "zabccccccccccccc",
      "zabccccccccgcccc",
      "zabccccccccccc!c",
      "zabccccccccccccc",
      "zabccccccccccccc",
      "zabccccccccccccc"
    ],
    [
      "zabh      ij  k ",
      "zabh       j  k ",
      "zab   l    jm k ",
      "zannnn o   h  kf",
      "zabpqn   r g   k",
      "zannnnso   t   k",
      "zab   u   wj    ",
      "zabh       j    ",
      "zabh      ij    ",
      "zab        j    ",
      "zannnn     xw   ",
      "zabyAn     g    ",
      "zannnn       BBB",
      "zab             ",
      "zabh         C  ",
      "zabh            "
    ],
    [
      "zabDE      F  k ",
      "zabDE      I  k ",
      "zabJ       K  k ",
      "zannks     w  kf",
      "zabp       g   k",
      "zannk      L   k",
      "zabM            ",
      "zabN       F    ",
      "zabNE      m    ",
      "zabJ       h    ",
      "zannk           ",
      "zabyAk     g    ",
      "zannk        OP ",
      "zabM            ",
      "zabNE           ",
      "zab!E           "
    ],
    [
      "zab           k ",
      "zab           k ",
      "zab           k ",
      "zannk         kf",
      "zabp       g   k",
      "zannQ          k",
      "zab             ",
      "zab             ",
      "zab             ",
      "zab             ",
      "zannk           ",
      "zabyAk     g    ",
      "zannk           ",
      "zab             ",
      "zab             ",
      "zab             "
    ],
    [
      "zabR          k ",
      "zabR          k ",
      "zab           k ",
      "zannk         kf",
      "zabp S     g   k",
      "zannk          k",
      "zab             ",
      "zabR            ",
      "zabR            ",
      "zab             ",
      "zannk           ",
      "zabyAk     g    ",
      "zannk           ",
      "zab             ",
      "zabR            ",
      "zabR            "
    ],
    [
      "zab           k ",
      "zabT          k ",
      "zab           k ",
      "zannk         kf",
      "zabp k     g   k",
      "zannk          k",
      "zab             ",
      "zabT            ",
      "zab             ",
      "zab             ",
      "zannk           ",
      "zabyAk     g    ",
      "zannk           ",
      "zab             ",
      "zabT            ",
      "zab             "
    ]
  ]
}