{
  "name": "multi_flatapartment_1_top",
  "refpalette": "c70cities:multi_flatapartment_1_top_palette",
  "xsize": 16,
  "zsize": 16,
  "slices": [
    [
      "                ",
      "                ",
      "aaabaaabaaaabaaa",
      "cccccccccccccccc",
      "cccccccccccccccc",
      "cccccccddddddccc",
      "cccccccd  ecdccc",
      "cccccccd   cdccc",
      "cccccccd   cdccc",
      "cccccccdccccdccc",
      "cccccccddddddccc",
      "cccccccccccccccc",
      "cccccccccccccccc",
      "aaabaaabaaaabaaa",
      "                ",
      "                "
    ],
    [
      "                ",
      "                ",
      "fffgfffgffffgfff",
      "   g   g    g   ",
      "                ",
      "       hiiiih   ",
      "       i    j   ",
      "       i   ki   ",
      "       illlki   ",
      "       m    i   ",
      "       hiiiih   ",
      "                ",
      "   g   g    g   ",
      "fffgfffgffffgfff",
      "                ",
      "                "
    ],
    [
      "                ",
      "                ",
      "                ",
      "                ",
      "                ",
      "       hinnih   ",
      "       i    o   ",
      "       i    i   ",
      "       i    i   ",
      "       p    i   ",
      "       hinnih   ",
      "                ",
      "                ",
      "                ",
      "                ",
      "                "
    ],
    [
      "                ",
      "                ",
      "                ",
      "                ",
      "                ",
      "       hiiiih   ",
      "       iaaaai   ",
      "       iaaaai   ",
      "       iaaaai   ",
      "       iaaaai   ",
      "       hiiiih   ",
      "                ",
      "                ",
      "                ",
      "                ",
      "                "
    ],
    [
      "                ",
      "                ",
      "                ",
      "                ",
      "                ",
      "       q    q   ",
      "        !       ",
      "                ",
      "                ",
      "                ",
      "       q    q   ",
      "                ",
      "                ",
      "                ",
      "                ",
      "                "
    ],
    [
      "                ",
      "                ",
      "                ",
      "                ",
      "                ",
      "                ",
      "                ",
      "                ",
      "                ",
      "                ",
      "                ",
      "                ",
      "                ",
      "                ",
      "                ",
      "                "
    ]
  ]
}