{
  "name": "multi_convenientstore_0_ground",
  "refpalette": "c70cities:multi_convenientstore_0_ground_palette",
  "xsize": 16,
  "zsize": 16,
  "slices": [
    [
      "GGGHHHaGGGGGGGGG",
      "GGGHHHaGGGGGGGGG",
      "GGHHHHaaaaaaaaaa",
      "GGHHHHHHHHHHHHHH",
      "GGHHHHHHHHHHHHHH",
      "GGHHHHHHHHHHHHHH",
      "GGHHHHHHHHHHHHHH",
      "GGHHHHHHHHHHHHHH",
      "GGHHHHHHHHHHHHHH",
      "GGHHHHHHHHHHHHHH",
      "GGHHHHHHHHHHHHHH",
      "GGHHHHHHbHHHHHHH",
      "GGHHHHHHHHHHHHHH",
      "GGHHHHHHHHHHHHHH",
      "GGHHHHHHHHHHHHHH",
      "GGHHHHHHHHHHHHHH"
    ],
    [
      "c     d  c      ",
      "cec   d         ",
      "      ddddd dddd",
      "c      fgfgfgfgf",
      "                ",
      "       hihihihih",
      "e               ",
      "c               ",
      "                ",
      "                ",
      "       fgfgfgfgf",
      " e              ",
      " c     hihihihih",
      "     ddddddddddd",
      "c    daaaaaaaaaa",
      "     daaaaaaaaaa"
    ],
    [
      "                ",
      " ~              ",
      "                ",
      "                ",
      "                ",
      "                ",
      "~               ",
      "                ",
      "                ",
      "                ",
      "                ",
      " ~              ",
      "                ",
      "                ",
      "                ",
      "         j  j k "
    ],
    [
      "                ",
      "                ",
      "                ",
      "                ",
      "                ",
      "                ",
      "                ",
      "                ",
      "                ",
      "                ",
      "                ",
      "                ",
      "                ",
      "                ",
      "                ",
      "              k "
    ],
    [
      "                ",
      "                ",
      "                ",
      "                ",
      "                ",
      "                ",
      "                ",
      "                ",
      "                ",
      "                ",
      "                ",
      "                ",
      "                ",
      "                ",
      "                ",
      "              lm"
    ],
    [
      "                ",
      "                ",
      "                ",
      "                ",
      "                ",
      "                ",
      "                ",
      "                ",
      "                ",
      "                ",
      "                ",
      "                ",
      "                ",
      "                ",
      "                ",
      "                "
    ]
  ]
}