{
  "name": "multi_hospital_1_floor1",
  "refpalette": "c70cities:multi_hospital_1_floor1_palette",
  "xsize": 16,
  "zsize": 16,
  "slices": [
    [
      "  a      bcccccc",
      "  a      bcccccc",
      "  b      bdccccc",
      "        efgggggg",
      "        efgggggg",
      "        efgggggg",
      "        efgggggg",
      "        efgggggg",
      "        efgggggg",
      "        efgggggg",
      "        efgggggg",
      "        efgggggg",
      "        efgggggg",
      "        efffffff",
      "        efffffff",
      "                "
    ],
    [
      "  hccijccf   k  ",
      "  hccccccfl !k  ",
      "  bmmmmmmbnonn  ",
      "        efp  q  ",
      "        efp  q  ",
      "        efr  s  ",
      "        eft  q  ",
      "        efuuuq  ",
      "        ef  wq  ",
      "        ef xxq  ",
      "        ef   y  ",
      "        ef AAq  ",
      "        ef B q  ",
      "        efACCbDD",
      "        efffff  ",
      "                "
    ],
    [
      "         f   k  ",
      "         f   k  ",
      "  bbbbbbbbnEnn  ",
      "        efF  q  ",
      "        efF  q  ",
      "        ef   I  ",
      "        ef   q  ",
      "        efJJJq  ",
      "        ef   q  ",
      "        ef  Kq  ",
      "        ef   L  ",
      "        ef M q  ",
      "        ef   q  ",
      "        efNCCbDD",
      "        efffff  ",
      "                "
    ],
    [
      "         J   k  ",
      "        ef   k  ",
      "        ebnnnn  ",
      "        ef   q  ",
      "         J   q  ",
      "         J   q  ",
      "         J   q  ",
      "        ef   q  ",
      "        ef   q  ",
      "         J   q  ",
      "         J   q  ",
      "         J   q  ",
      "        ef   q  ",
      "        ef  ObDD",
      "        effPff  ",
      "                "
    ],
    [
      "        eQ   k  ",
      "        ef   k  ",
      "        ebnnnnnn",
      "        ef   q  ",
      "        eQ   q  ",
      "        eQ   q  ",
      "        eQ   q  ",
      "        ef   q  ",
      "        ef   q  ",
      "        eQ   q  ",
      "        eQ   q  ",
      "        eQ   q  ",
      "        ef   q  ",
      "        ef   bDD",
      "        efPPPf  ",
      "                "
    ],
    [
      "        efvRRk  ",
      "        efvRRk  ",
      "        ebnnnnnn",
      "        ef   q  ",
      "        ef   q  ",
      "        ef   q  ",
      "        ef   q  ",
      "        ef   q  ",
      "        ef   q  ",
      "        ef   q  ",
      "        ef   q  ",
      "        ef   q  ",
      "        ef   q  ",
      "        ef   bDD",
      "        effPff  ",
      "                "
    ]
  ]
}