{
  "name": "multi_megatower1_5_floor9",
  "refpalette": "c70cities:multi_megatower1_5_floor9_palette",
  "xsize": 16,
  "zsize": 16,
  "slices": [
    [
      "aaaaaaaaaaaaaaaa",
      "aaaaaaaaaaaaaaaa",
      "aaaabaaaaaabaaaa",
      "ccccdccccccdcccc",
      "efffgeeefffgeeef",
      "    h      h    ",
      "                ",
      "                ",
      "                ",
      "                ",
      "                ",
      "                ",
      "                ",
      "                ",
      "                ",
      "                "
    ],
    [
      " ijklmjn ioon io",
      " ijklmjn pqq   q",
      "rrrrbrrrrrrbrrrr",
      "                ",
      "efffheeefffheeef",
      "                ",
      "                ",
      "                ",
      "                ",
      "                ",
      "                ",
      "                ",
      "                ",
      "                ",
      "                ",
      "                "
    ],
    [
      "  s t p         ",
      "    u           ",
      "rrrrbrrrrrrbrrrr",
      "                ",
      "efffheeefffheeef",
      "                ",
      "                ",
      "                ",
      "                ",
      "                ",
      "                ",
      "                ",
      "                ",
      "                ",
      "                ",
      "                "
    ],
    [
      "                ",
      "                ",
      "rrrrbrrrrrrbrrrr",
      "                ",
      "efffheeefffheeef",
      "                ",
      "                ",
      "                ",
      "                ",
      "                ",
      "                ",
      "                ",
      "                ",
      "                ",
      "                ",
      "                "
    ],
    [
      "                ",
      "                ",
      "wxwxbwxwxwxbwxwx",
      "                ",
      "efffheeefffheeef",
      "                ",
      "                ",
      "                ",
      "                ",
      "                ",
      "                ",
      "                ",
      "                ",
      "                ",
      "                ",
      "                "
    ],
    [
      "yyAyByAyyCyByCyy",
      "yyyyByyyyyyByyyy",
      "DDDDbDDDDDDbDDDD",
      "    g      g    ",
      "efffheeefffheeef",
      "                ",
      "                ",
      "                ",
      "                ",
      "                ",
      "                ",
      "                ",
      "                ",
      "                ",
      "                ",
      "                "
    ]
  ]
}