{
  "name": "multi_hospital_2_base1",
  "refpalette": "c70cities:multi_hospital_2_base1_palette",
  "xsize": 16,
  "zsize": 16,
  "slices": [
    [
      "vvvvvvvvvvvvvvvv",
      "aaaaaaaaaaaaaaav",
      "aaaaaaaaaaaaaaav",
      "bbaaaaaaaaaaaaav",
      "bbaaaaaaaaaaaaav",
      "bbaaaaaaaaaaaaav",
      "bbaaaaaaaaaaaaav",
      "bbaaaaaaaaaaaaav",
      "bbbbbbbbbbbbbbbv",
      "bbcccccccccccccv",
      "bbcccccccccccccv",
      "bbcccccccccccccv",
      "bbdddddddddddddv",
      "bbdddddddddddddv",
      "bbdddddddddddddv",
      "bbcccccccccccccv"
    ],
    [
      "vvvvvvvvvvvvvvvv",
      "aaaaaaaaaaaaaaav",
      "aaaaaaaaaaaaaaav",
      "eeaaaaaaaaaaaaav",
      "feaaaaaaaaaaaaav",
      " eaaaaaaaaaaaaav",
      " eaaaaaaaaaaaaav",
      " eaaaaaaaaaaaaav",
      " bvvvvvvvvvvvvvv",
      "ghc c c cic c cv",
      "ghc c c c c c cv",
      " bc c c c c c cv",
      "jj             v",
      "               v",
      "               v",
      "kbc c c c c c cv"
    ],
    [
      "vvvvvvvvvvvvvvvv",
      "aaaaaaaaaaaaaaav",
      "aaaaaaaaaaaaaaav",
      "eeaaaaaaaaaaaaav",
      " eaaaaaaaaaaaaav",
      " eaaaaaaaaaaaaav",
      " eaaaaaaaaaaaaav",
      " eaaaaaaaaaaaaav",
      " bvvvvvvvvvvvvvv",
      " hclclclclclclcv",
      "mhclclclclclclcv",
      " bclclclclclclcv",
      "jj             v",
      "               v",
      "               v",
      "nbclclclclclclcv"
    ],
    [
      "vvvvvvvvvvvvvvvv",
      "aaaaaaaaaaaaaaav",
      "aaaaaaaaaaaaaaav",
      "eeaaaaaaaaaaaaav",
      " eaaaaaaaaaaaaav",
      " eaaaaaaaaaaaaav",
      " eaaaaaaaaaaaaav",
      " eaaaaaaaaaaaaav",
      " bvvvvvvvvvvvvvv",
      " hcococococococv",
      " hcococococococv",
      " bcococococococv",
      "jj             v",
      "               v",
      "               v",
      " bcococococococv"
    ],
    [
      "vvvvvvvvvvvvvvvv",
      "aaaaaaaaaaaaaaav",
      "aaaaaaaaaaaaaaav",
      "eeaaaaaaaaaaaaav",
      " eaaaaaaaaaaaaav",
      " eaaaaaaaaaaaaav",
      " eaaaaaaaaaaaaav",
      " eaaaaaaaaaaaaav",
      " bvvvvvvvvvvvvvv",
      " hc c c c c cpcv",
      " hc c c c c!c cv",
      " bc c c c c c cv",
      "jj             v",
      "               v",
      "               v",
      " bc c c c c c cv"
    ],
    [
      "vvvvvvvvvvvvvvvv",
      "aaaaaaaaaaaaaaav",
      "aaaaaaaaaaaaaaav",
      "eeaaaaaaaaaaaaav",
      "qeaaaaaaaaaaaaav",
      "qeaaaaaaaaaaaaav",
      "qeaaaaaaaaaaaaav",
      "qeaaaaaaaaaaaaav",
      "bbvvvvvvvvvvvvvv",
      "qbcccccccccccccv",
      "qbcccccccccccccv",
      "bbcccccccccccccv",
      "rbsssssssssssssv",
      "sbsssssssssssssv",
      "sbsssssssssssssv",
      "sbcccccccccccccv"
    ]
  ]
}