{
  "name": "multi_laboratory1_14_base3",
  "refpalette": "c70cities:multi_laboratory1_14_base3_palette",
  "xsize": 16,
  "zsize": 16,
  "slices": [
    [
      "aaaabaaaaaaaacdz",
      "aaaaaaaaaaaaacdz",
      "aaeaaaaaaaaaacdz",
      "aaaaaaaaaaaaacdz",
      "aaafaaaaaaaaacdz",
      "aghaaaaaaaaaacdz",
      "aagaaaaaaaaaacdz",
      "aaaabaaaaaaaacdz",
      "aafaai!iiiiiicdz",
      "aajgafiiiiiffcdz",
      "aagaaiiiiifficdz",
      "aaaaaiiiiiiiicdz",
      "aaaaaiiii!iiicdz",
      "ccccccccccccccdz",
      "dddddddddddddddz",
      "zzzzzzzzzzzzzzzz"
    ],
    [
      "k   bllllllllcdz",
      "kmnolpqr stupcdz",
      "w xylA     BCcdz",
      "DE FlI JK  LMcdz",
      "  n lNOPQ  RScdz",
      "   nTUmVWXYZ0cdz",
      "   1l23445546cdz",
      "7 89bllllllllcdz",
      "   @l##$$$$##cdz",
      " %  f ^  E  &cdz",
      "   *lf()(+()(cdz",
      "    l^- -8-e-cdz",
      "  8 l[-[-[-e-cdz",
      "ccccccccccccccdz",
      "dddddddddddddddz",
      "zzzzzzzzzzzzzzzz"
    ],
    [
      "    bllllllllcdz",
      "    l]      ]cdz",
      "    l        cdz",
      "    l        cdz",
      "    l{       cdz",
      "    }\\ |     cdz",
      "    l234`4446cdz",
      "    bllllllllcdz",
      "   fl]:::::8]cdz",
      "             cdz",
      "    l;('(,('(cdz",
      "    l - - -@-cdz",
      "    l - - -e-cdz",
      "ccccccccccccccdz",
      "dddddddddddddddz",
      "zzzzzzzzzzzzzzzz"
    ],
    [
      "    bllllllllcdz",
      "    l]      ]cdz",
      "    l        cdz",
      "    l{       cdz",
      "    l        cdz",
      "    .        cdz",
      "    l /  Y< 6cdz",
      " @  bllllllllcdz",
      "   fl  :: :: cdz",
      "    l        cdz",
      "    l((((((((cdz",
      "    l - - ->-cdz",
      "    l - -@-efcdz",
      "ccccccccccccccdz",
      "dddddddddddddddz",
      "zzzzzzzzzzzzzzzz"
    ],
    [
      "    bllllllllcdz",
      "    l        cdz",
      "    l        cdz",
      "  @ l        cdz",
      "    l        cdz",
      "    l        cdz",
      "    l       6cdz",
      " > fbllllllllcdz",
      "    l????????cdz",
      "    l????????cdz",
      "    l????????cdz",
      "    l??????e@cdz",
      "    l\u00a3?\u00a3?f?eecdz",
      "ccccccccccccccdz",
      "dddddddddddddddz",
      "zzzzzzzzzzzzzzzz"
    ],
    [
      "\u00a4\u00a5\u00a4\u00a4bllllllllcdz",
      "\u00a4\u00a7\u00a4\u00a4.\u00c0\u00c0\u00c0\u00c0\u00c0\u00c0\u00c0\u00c0cdz",
      "\u00a4\u00a7\u00a4\u00a4.\u00c0\u00c1\u00c0\u00c0\u00c0\u00c0\u00c2\u00c0cdz",
      "\u00c3\u00a5f\u00a4.\u00c0\u00c0\u00c0\u00c0\u00c0\u00c0\u00c0\u00c0cdz",
      "\u00a4\u00a4f\u00a4.\u00c0\u00c0\u00c0\u00c0\u00c0\u00c0\u00c0\u00c0cdz",
      "\u00a4f\u00a4\u00a4.\u00c0\u00a7\u00c0\u00c0\u00c0\u00c0\u00c1\u00c0cdz",
      "\u00a4\u00a4ff.\u00c0\u00c0\u00c0\u00c0\u00c0\u00c0\u00c0\u00c0cdz",
      "lffebllllllllcdz",
      "\u00c4\u00c4\u00c4\u00c4l\u00c5\u00c5\u00c5eeff\u00c5cdz",
      "\u00c4\u00c4\u00a5\u00c4l\u00c5 \u00c5 e f cdz",
      "\u00c4\u00c4\u00a5\u00c4l\u00c5 \u00c5 f f cdz",
      "\u00c4\u00c4\u00a5\u00c4l\u00c5 \u00c5 f efcdz",
      "\u00c4\u00c4\u00c4\u00c4l\u00c5 \u00c5 f e\u00c6cdz",
      "ccccccccccccccdz",
      "dddddddddddddddz",
      "zzzzzzzzzzzzzzzz"
    ]
  ]
}