{
  "name": "multi_megatower1_3_base1",
  "refpalette": "c70cities:multi_megatower1_3_base1_palette",
  "xsize": 16,
  "zsize": 16,
  "slices": [
    [
      "vvvvvvvvvvvvvvvv",
      "aaaaaaaaaaaaaaaa",
      "aaaaaaaaaaaaaaaa",
      "vvvvvvvvvvvvvvvv",
      "vvvvvvvvvvvvvvvv",
      "HHHHHHHHHHHHHHHH",
      "HHHHbHHHHHHbHHHH",
      "HHHHHHHHHHHHHHHH",
      "HHHHHHHHHHHHHHHH",
      "HHHHHHHHHHHHHHHH",
      "HHHHHHHHHHHHHHHH",
      "HHHHHHHHHHHHHHHH",
      "HHHHHHHHHHHHHHHH",
      "vvvvbHHHHHHbHHHH",
      "cdddvHHHHHHHHHHH",
      "c   vHHHHHHHHHHH"
    ],
    [
      "vvvvvvvvvvvvvvvv",
      "aaaaaaaaaaaaaaaa",
      "aaaaaaaaaaaaaaaa",
      "vvvvvvvvvvvvvvvv",
      "eeeeeeeeeeeeeeee",
      "fgfg fgfgfg fgfg",
      "    b      b    ",
      "hihijhihihijhihi",
      "                ",
      "                ",
      "                ",
      "                ",
      "    kfgfgfgkfgfg",
      "llllb      b    ",
      "cdddmhihihi hihi",
      "c   m           "
    ],
    [
      "vvvvvvvvvvvvvvvv",
      "aaaaaaaaaaaaaaaa",
      "aaaaaaaaaaaaaaaa",
      "vvvvvvvvvvvvvvvv",
      "                ",
      "                ",
      "    b      b    ",
      "                ",
      "                ",
      "                ",
      "                ",
      "                ",
      "                ",
      "llllb      b    ",
      "cdddm           ",
      "c   m           "
    ],
    [
      "vvvvvvvvvvvvvvvv",
      "aaaaaaaaaaaaaaaa",
      "aaaaaaaaaaaaaaaa",
      "vvvvvvvvvvvvvvvv",
      "                ",
      "                ",
      "    b      b    ",
      "                ",
      "                ",
      "                ",
      "                ",
      "                ",
      "                ",
      "llllb      b    ",
      "cdddm           ",
      "c   m           "
    ],
    [
      "vvvvvvvvvvvvvvvv",
      "aaaaaaaaaaaaaaaa",
      "aaaaaaaaaaaaaaaa",
      "vvvvvvvvvvvvvvvv",
      "                ",
      "                ",
      "    b      b    ",
      "                ",
      "                ",
      "                ",
      "                ",
      "                ",
      "                ",
      "llllb      b    ",
      "cdddm           ",
      "c   m           "
    ],
    [
      "vvvvvvvvvvvvvvvv",
      "aaaaaaaaaaaaaaaa",
      "aaaaaaaaaaaaaaaa",
      "vvvvvvvvvvvvvvvv",
      "vvvvvvvvvvvvvvvv",
      "nnnnnnnnnnnnnnnn",
      "bbbbbbbbbbbbbbbb",
      "nnnnbnnnnnnbnnnn",
      "nnnnbnnnnnnbnnnn",
      "nnnnbnnnnnnbnnnn",
      "nnnnbnnnnnnbnnnn",
      "nnnnbnnnnnnbnnnn",
      "nnnnbnnnnnnbnnnn",
      "bbbbbbbbbbbbbbbb",
      "bdddbnnnnnnnnnnn",
      "b   bnnnnnnnnnnn"
    ]
  ]
}