{
  "name": "multi_condo1_3_floor7",
  "refpalette": "c70cities:multi_condo1_3_floor7_palette",
  "xsize": 16,
  "zsize": 16,
  "slices": [
    [
      "                ",
      "                ",
      "                ",
      "      a         ",
      "bbbbbbabbbbbb   ",
      "      a     b   ",
      "      a     b   ",
      "      a     b   ",
      "      a     b   ",
      "      a     b   ",
      "      a     acc ",
      "      a     a   ",
      "      a     a   ",
      "      a     addd",
      "eeeeeeaaaaaaaf  ",
      "ggggghiiiiiiaf  "
    ],
    [
      "                ",
      "                ",
      "                ",
      "jjjjjjajjjjjjj  ",
      "aaaaaaaaaaaaaj  ",
      "      a     aj  ",
      "      a     aj  ",
      "      a     aj  ",
      "      a     aj  ",
      "      a     aj  ",
      "      a     acc ",
      "      a     a   ",
      "      a     a   ",
      "      a     addd",
      "kkkkkkaaaaaaa   ",
      "      l  m no   "
    ],
    [
      "                ",
      "                ",
      "                ",
      "      a         ",
      "aaaaaaaaaaaaa   ",
      "      a     a   ",
      "      a     a   ",
      "      a     a   ",
      "      a     a   ",
      "      a     a   ",
      "      a     acc ",
      "      a     a   ",
      "      a     a   ",
      "      a     addd",
      "      aaaaaaa   ",
      "      p  q  b   "
    ],
    [
      "                ",
      "                ",
      "ccccccccccccccc ",
      "ccccccccccccccc ",
      "aaaaaaaaaaaaacc ",
      "      a     acc ",
      "      a     acc ",
      "      a     acc ",
      "      a     acc ",
      "      a     acc ",
      "      a     acc ",
      "      a     a   ",
      "      a     a   ",
      "      a     addd",
      "      aaaaaaa   ",
      "      a  r  b   "
    ],
    [
      "                ",
      "                ",
      "                ",
      "                ",
      "aaaaaaaaaaaaa   ",
      "ssstssa     a   ",
      "      a     a   ",
      "      a     a   ",
      "      a     a   ",
      "      a     a   ",
      "      a     a   ",
      "      a     a   ",
      "      a     a   ",
      "      a     addd",
      "      aaaaaaa   ",
      "      a  a  a   "
    ],
    [
      "                ",
      "                ",
      "                ",
      "kkkkkkkkkkkkkk  ",
      "aaaaaaaaaaaaak  ",
      "uuuuuuawwwwwak  ",
      "uuuuuuawwwwwak  ",
      "uuuuuuawxxxwak  ",
      "uuuuuuawwwwwak  ",
      "uuuuuuawwwwwak  ",
      "uuuuuuawwwwwak  ",
      "uuuuuuawxxxwak  ",
      "uuuuuuawwwwwak  ",
      "uuuuuuawwwwwaddd",
      "kkkkkkaaaaaaa   ",
      "      awwwwwa   "
    ]
  ]
}