{
  "name": "multi_hospital_0_base2",
  "refpalette": "c70cities:multi_hospital_0_base2_palette",
  "xsize": 16,
  "zsize": 16,
  "slices": [
    [
      "vvvvvvvvvvvvvvvv",
      "vvvvvvvvvvvvvvvv",
      "vvvvvvvvvvvvvvvv",
      "vvvvvvvvvvvvvvvv",
      "vvvvvvvvvvvvvvvv",
      "vvvvvvvvvvvvvvvv",
      "vvvvvvvvvvvvvvvv",
      "vvvvvvvvvvvvvvvv",
      "vvvvvvvvvaaaavvv",
      "vvvvvvvvvavvavvv",
      "vvvvvvvvvavvavvv",
      "vvvvvvvvvaaaavvv",
      "vvvvvvvvvvvvvvvv",
      "vvvvvvvvvvvvvvvv",
      "vvvvvvvvvvvvvvvv",
      "vvvvvvvvvvvvvvvv"
    ],
    [
      "vvvvvvvvvvvvvvvv",
      "vbbbbbbbbbbbbbbb",
      "vbbbbbbbbbbbbbbb",
      "vbbbbbbbbccccccc",
      "vbbbbbbbbcdddddd",
      "vbbbbbbbbcdddddd",
      "vbbbbbbbbcdddddd",
      "vbbbbbbbbcdddddd",
      "vbbbbbbbbdaaaddd",
      "vbbbbbbbba  eddd",
      "vbbbbbbbba  eddd",
      "vbbbbbbbba aaddd",
      "vbbbbbbbbcvvcddd",
      "vbbbbbbbbcdddddd",
      "vbbbbbbbbcdddddd",
      "vbbbbbbbbcdddddd"
    ],
    [
      "vvvvvvvvvvvvvvvv",
      "vbbbbbbbbbbbbbbb",
      "vbbbbbbbbbbbbbbb",
      "vbbbbbbbbccccccc",
      "vbbbbbbbbc  f f ",
      "vbbbbbbbbcghhhh ",
      "vbbbbbbbbc hhhhi",
      "vbbbbbbbbc j j  ",
      "vbbbbbbbbdaaa   ",
      "vbbbbbbbba  k   ",
      "vbbbbbbbba  l   ",
      "vbbbbbbbba aa   ",
      "vbbbbbbbbcvvm   ",
      "vbbbbbbbbcmmm   ",
      "vbbbbbbbbc      ",
      "vbbbbbbbbchi  h "
    ],
    [
      "vvvvvvvvvvvvvvvv",
      "vbbbbbbbbbbbbbbb",
      "vbbbbbbbbbbbbbbb",
      "vbbbbbbbbccccccc",
      "vbbbbbbbbc n    ",
      "vbbbbbbbbc o  p ",
      "vbbbbbbbbc q o  ",
      "vbbbbbbbbc      ",
      "vbbbbbbbbdaaa   ",
      "vbbbbbbbba  r   ",
      "vbbbbbbbba  s   ",
      "vbbbbbbbba aat  ",
      "vbbbbbbbbcvvm   ",
      "vbbbbbbbbcmmm   ",
      "vbbbbbbbbc      ",
      "vbbbbbbbbc    u "
    ],
    [
      "vvvvvvvvvvvvvvvv",
      "vbbbbbbbbbbbbbbb",
      "vbbbbbbbbbbbbbbb",
      "vbbbbbbbbccccccc",
      "vbbbbbbbbc      ",
      "vbbbbbbbbc      ",
      "vbbbbbbbbc      ",
      "vbbbbbbbbc      ",
      "vbbbbbbbbdaaa   ",
      "vbbbbbbbba  w   ",
      "vbbbbbbbba  w   ",
      "vbbbbbbbba aa   ",
      "vbbbbbbbbcvvm   ",
      "vbbbbbbbbcmmm   ",
      "vbbbbbbbbc      ",
      "vbbbbbbbbc      "
    ],
    [
      "vvvvvvvvvvvvvvvv",
      "vbbbbbbbbbbbbbbb",
      "vbbbbbbbbbbbbbbb",
      "vbbbbbbbbccccccc",
      "vbbbbbbbbcxxxxxx",
      "vbbbbbbbbcxxxxxx",
      "vbbbbbbbbcxxxxxx",
      "vbbbbbbbbcxxxxxx",
      "vbbbbbbbbdaaaxxx",
      "vbbbbbbbba  axxx",
      "vbbbbbbbba  axxx",
      "vbbbbbbbba aaxxx",
      "vbbbbbbbbcvvmxxx",
      "vbbbbbbbbcmmmxxx",
      "vbbbbbbbbcxxxxxx",
      "vbbbbbbbbcxxxxxx"
    ]
  ]
}