{
  "name": "multi_flatapartment_0_floor2",
  "refpalette": "c70cities:multi_flatapartment_0_floor2_palette",
  "xsize": 16,
  "zsize": 16,
  "slices": [
    [
      "                ",
      "     abbbbabbbab",
      "     bcccccccccc",
      "     bcddddddddd",
      "     bcddddddddd",
      "     acddddddddd",
      "     bcddddddddd",
      "     bcddddddddd",
      "     bcddddddddd",
      "     bcddddddddd",
      "     acddddddddd",
      "     bcddddddddd",
      "     bcddddddddd",
      "     bcccccccccc",
      "     abbbbabbbab",
      "                "
    ],
    [
      "                ",
      "     abeebabebab",
      "     b    f     ",
      "     e   gh iih ",
      "     b jk h   hl",
      "     ahhhmh   hh",
      "     b    n oohp",
      "     e    hhhhhp",
      "     e qq hr  s ",
      "     b ttuhwx h ",
      "     ahhhhhwx h ",
      "     byA  B   h ",
      "     eC  ghhhhh ",
      "     bD   f     ",
      "     abeebabebab",
      "                "
    ],
    [
      "                ",
      "     abEEbabEbab",
      "     b    F     ",
      "     E    h   h ",
      "     bI   h   h ",
      "     ahhhJh   hh",
      "     b    K LLh ",
      "     E    hhhhh ",
      "     E    h!  M ",
      "     b    h   h ",
      "     ahhhhh   h ",
      "     b  N O   h ",
      "     E    hhhhh ",
      "     bI   F     ",
      "     abEEbabEbab",
      "                "
    ],
    [
      "                ",
      "     abEEbabEbab",
      "     b    h     ",
      "     E    h   h ",
      "     bP   h   h ",
      "     ahhhhh   hh",
      "     b    h LLh ",
      "     E    hhhhh ",
      "     E    h   h ",
      "     b    h   h ",
      "     ahhhhh   h ",
      "     b    h   h ",
      "     E    hhhhh ",
      "     bP   h     ",
      "     abEEbabEbab",
      "                "
    ],
    [
      "                ",
      "     abbbbabbbab",
      "     bQQQQh   h ",
      "     bQQQQh   h ",
      "     bQQQQh R h ",
      "     ahhhhh   hh",
      "     b    h   h ",
      "     b    hhhhh ",
      "     b    h   h ",
      "     b    h   h ",
      "     ahhhhh   hh",
      "     bQQQQh   h ",
      "     bQQQQhhhhh ",
      "     bQQQQh   h ",
      "     abbbbabbbab",
      "                "
    ],
    [
      "                ",
      "     STTTTSTTTST",
      "     Tcccccccccc",
      "     Tcddddddddd",
      "     Tcddddddddd",
      "     Scddddddddd",
      "     Tcddddddddd",
      "     Tcddddddddd",
      "     Tcddddddddd",
      "     Tcddddddddd",
      "     Scddddddddd",
      "     Tcddddddddd",
      "     Tcddddddddd",
      "     Tcccccccccc",
      "     STTTTSTTTST",
      "                "
    ]
  ]
}