{
  "name": "multi_communitycenter_2_ground",
  "refpalette": "c70cities:multi_communitycenter_2_ground_palette",
  "xsize": 16,
  "zsize": 16,
  "slices": [
    [
      "aaaabbccccccdbbb",
      "aaaaabccccccdbbb",
      "aaaaabbcccccbdbb",
      "aaaaaabcccccbbdd",
      "aaaaaabbcccbeeee",
      "aaGaaaabbcbeeeee",
      "aaGfaaaabbeeeeee",
      "aaGffaaaabbeeeee",
      "aaGGffaaaabbeeee",
      "aaGGGGGaaaabbbee",
      "aaaaaaGGaaaaabbb",
      "aagggaGffaaaaaab",
      "aagggaGfGfaaaaaa",
      "aagggaGGGGGaaaaa",
      "aaaaaaaaaaaaaaaa",
      "aaaaaaaaaaaaaaaa"
    ],
    [
      "    hhi         ",
      "     hjjj   k   ",
      "     hh l   mm  ",
      "      h     mmk ",
      " n    hhjjjmo   ",
      " np    hh!mqr   ",
      " np     hhs r t ",
      " uw      hh   t ",
      " uxp      hh  t ",
      " uyABpp    hhh  ",
      " uuuuu p     hhh",
      " uGGGuw        h",
      " uGgGux p       ",
      " uGGGuyABpp     ",
      " uuuuuuuunnn    ",
      "                "
    ],
    [
      "    CC          ",
      "     C D    k   ",
      "     hh     mm  ",
      "      C     mmk ",
      "      CCE Fm    ",
      "       CCqm     ",
      "        hh  I r ",
      "         hC   o ",
      "          CC  r ",
      "  J        CCh  ",
      " nnnnn       hCC",
      " npppn         C",
      " n Kpn          ",
      " np pnJ         ",
      " nnnnn          ",
      "                "
    ],
    [
      "    CC          ",
      "     C      k   ",
      "     hh     mm  ",
      "      C     mmk ",
      "      CC   m    ",
      "       CC m     ",
      "        hh    I ",
      "         hC   I ",
      "          CC  I ",
      "           CCh  ",
      "             hCC",
      "               C",
      "   K            ",
      "                ",
      "                ",
      "                "
    ],
    [
      "    hh      L   ",
      "     h      k   ",
      "     hh     mm  ",
      "      h     mmkk",
      "      hh   m    ",
      "       hhqm     ",
      "        hh      ",
      "         hh     ",
      "          hh    ",
      "           hhh  ",
      "  MMM        hhh",
      " MMMMM         h",
      " MMKMM          ",
      " MMMMM          ",
      "  MMM           ",
      "                "
    ],
    [
      "    hhNNNNNmmOO ",
      "     hNNNNNNmO  ",
      "     hhNNNNNmm  ",
      "      hNNNNNmmmm",
      "      hhNNNmNNNm",
      "       hhNmNNNNN",
      "        hhNNNNNN",
      "         hhNNNNN",
      "          hhNNNN",
      "           hhhNN",
      "             hhh",
      "   M           h",
      "  MKM           ",
      "   M            ",
      "                ",
      "                "
    ]
  ]
}