{
  "name": "multi_laboratory1_6_base2",
  "refpalette": "c70cities:multi_laboratory1_6_base2_palette",
  "xsize": 16,
  "zsize": 16,
  "slices": [
    [
      "aaaaaaaaaaaaaaaa",
      "aaaaaaaaaaaaaaaa",
      "aaaaaaaaaaaaaaaa",
      "aaaaaaaaaaaaaaaa",
      "aaaaaaaaaaaaaaaa",
      "aaaaaaaaaaaaaaaa",
      "aaaaaaaaaaaaaaaa",
      "aaaaabbbbbbaaaaa",
      "aaabbc    cbbaaa",
      "abbb        bbba",
      "bc            cb",
      "b              b",
      "b         d    b",
      "                ",
      " d              ",
      "                "
    ],
    [
      "e fg e fg e fg e",
      "                ",
      "                ",
      "                ",
      "h    iijjii     ",
      "     k  l m    h",
      "nnh          hnn",
      "nn ocppppppcq nn",
      " h ppc    cpp  h",
      " ppp        ppp ",
      "pc            cp",
      "p              p",
      "p         d    p",
      "                ",
      " d              ",
      "                "
    ],
    [
      "  rs   rs   rs  ",
      "                ",
      "                ",
      "                ",
      "      tu  w     ",
      "                ",
      " x              ",
      " y  AppppppA   B",
      "   ppc    cpp   ",
      " ppp        ppp ",
      "pc            cp",
      "p              p",
      "p         d    p",
      "                ",
      " d              ",
      "                "
    ],
    [
      "                ",
      "                ",
      "                ",
      "                ",
      "                ",
      "                ",
      "                ",
      "    AppppppA    ",
      "   ppc    cpp   ",
      " ppp        ppp ",
      "pc            cp",
      "p              p",
      "p         d    p",
      "                ",
      " d              ",
      "                "
    ],
    [
      "                ",
      "                ",
      "                ",
      "                ",
      "                ",
      "                ",
      "                ",
      "     pppppp     ",
      "   ppc    cpp   ",
      " ppp        ppp ",
      "pc            cp",
      "p              p",
      "p         C    p",
      "                ",
      " d              ",
      "                "
    ],
    [
      "DDDDDDDDDDDDDDDD",
      "DEDDDEDDDDEDDDED",
      "DEDDDEDDDDEDDDFD",
      "DEDDDEDDDDEDDDED",
      "D!DDDEDDDDEDDDED",
      "DDDDDDDDDDDDDDDD",
      "DDDDDDDDDDDDDDDD",
      "DDDDDppppppDDDDD",
      "DDDppc    cppDDD",
      "Dppp        pppD",
      "pc            cp",
      "p              p",
      "p         d    p",
      "                ",
      " d              ",
      "                "
    ]
  ]
}