{
  "name": "multi_megatower1_5_base2",
  "refpalette": "c70cities:multi_megatower1_5_base2_palette",
  "xsize": 16,
  "zsize": 16,
  "slices": [
    [
      "HHHHHHHHHHHHHHHH",
      "HHHHHHHHHHHHHHHH",
      "HHHHaHHHHHHaHHHH",
      "HHHHHHHHHHHHHHHH",
      "HHHHHHHHHHHHHHHH",
      "HHHHHHHHHHHHHHHH",
      "HHHHHHHHHHHHHHHH",
      "HHHHHHHHHHHHHHHH",
      "HHHHHHHHHHHHHHHH",
      "HHHHaHHHHHHaHHHH",
      "HHHHHHHHHHHHHHHH",
      "vvvvvvvvvvvvvvvv",
      "vvvvvvvvvvvvvvvv",
      "bb              ",
      "bbbbbbbbbbbbbbbb",
      "vvvvvvvvvvvvvvvv"
    ],
    [
      "                ",
      "cdcd cdcdcd cdcd",
      "    a      a  e ",
      "fgfghfgfgfghfgfg",
      "                ",
      "                ",
      "                ",
      "                ",
      "cdcdicdcdcdjcdcd",
      "    a      a    ",
      "fgfg fgfgfg fgfg",
      "kkkkkkkkkkkkkkkk",
      "vvvvvvvvvvvvvvvv",
      "bbbbbbbbbbbbbbbb",
      "bbbbbbbbbbbbbbbb",
      "vvvvvvvvvvvvvvvv"
    ],
    [
      "                ",
      "                ",
      "    a      a    ",
      "                ",
      "                ",
      "                ",
      "                ",
      "                ",
      "                ",
      "    a      a    ",
      "                ",
      "                ",
      "vvvvvvvvvvvvvvvv",
      "bbbbbbbbbbbbbbbb",
      "bbbbbbbbbbbbbbbb",
      "vvvvvvvvvvvvvvvv"
    ],
    [
      "                ",
      "                ",
      "    a      a    ",
      "                ",
      "                ",
      "                ",
      "                ",
      "                ",
      "                ",
      "    a      a    ",
      "                ",
      "                ",
      "vvvvvvvvvvvvvvvv",
      "bbbbbbbbbbbbbbbb",
      "bbbbbbbbbbbbbbbb",
      "vvvvvvvvvvvvvvvv"
    ],
    [
      "                ",
      "                ",
      "    a      a    ",
      "                ",
      "                ",
      "                ",
      "                ",
      "                ",
      "                ",
      "    a      a    ",
      "    l      l    ",
      "                ",
      "vvvvvvvvvvvvvvvv",
      "bbbbbbbbbbbbbbbb",
      "bbbbbbbbbbbbbbbb",
      "vvvvvvvvvvvvvvvv"
    ],
    [
      "    a      a    ",
      "mmmmammmmmmammmm",
      "aaaaaaaaaaaaaaaa",
      "mmmmammmmmmammmm",
      "mmmmammmmmmammmm",
      "mmmmammmmmmammmm",
      "mmmmammmmmmammmm",
      "mmmmammmmmmammmm",
      "mmmmammmmmmammmm",
      "aaaaaaaaaaaaaaaa",
      "mmmmmmmmmmmmmmmm",
      "vvvvvvvvvvvvvvvv",
      "vvvvvvvvvvvvvvvv",
      "bbbbbbbbbbbbbbbb",
      "bbbbbbbbbbbbbbbb",
      "vvvvvvvvvvvvvvvv"
    ]
  ]
}