{
  "name": "multi_militarybase_4_base2",
  "refpalette": "c70cities:multi_militarybase_4_base2_palette",
  "xsize": 16,
  "zsize": 16,
  "slices": [
    [
      "vvvvvvvvvvvvvvvv",
      "avaaaaaaavaaaavv",
      "abaaaaaaabaaaavv",
      "abaaaaaaabaaaavv",
      "abaaaaaaabaaaavv",
      "bvbbbbbbbvbbbvvv",
      "abaaaaaaabaaaavv",
      "abaaaaaaabaaaavv",
      "abaaaaaaabaaaavv",
      "cvdaaaaaabaaaavv",
      "ebeeaaaaabaaaavv",
      "ebeeeaaaabaaaavv",
      "ebeeeaaaabaaaavv",
      "bvbbbbbbbvbbbvvv",
      " beeeaaaaaaaaavv",
      " beeeaaaaaaaaavv"
    ],
    [
      "vvvvvvvvvvvvvvvv",
      "!vf f f fvghghvv",
      " ij j j ji   hvv",
      " ik k k  l   mvv",
      " i       i   mvv",
      "nvnnnonnnvipivvv",
      "         q rstvv",
      "         q    vv",
      "         q rstvv",
      "nvd      u    vv",
      "         q rstvv",
      "         q    vv",
      "         q rstvv",
      "wv       viiivvv",
      " w        xyA vv",
      " w           Bvv"
    ],
    [
      "vvvvvvvvvvvvvvvv",
      " vf f f fv C hvv",
      " ij j j ji   Dvv",
      " iE E E  F    vv",
      " i       i    vv",
      "nvnnnInnnviJivvv",
      "         q Kstvv",
      "         q    vv",
      "         q Kstvv",
      "nvd      L    vv",
      "         q Kstvv",
      "         q    vv",
      "         q Kstvv",
      " v       viiivvv",
      "            M vv",
      "              vv"
    ],
    [
      "vvvvvvvvvvvvvvvv",
      " v       v    vv",
      " i       i    vv",
      " i       i    vv",
      " i       i    vv",
      "nvnnnnnnnviiivvv",
      "         q    vv",
      "         q    vv",
      "         q    vv",
      "nvd      q    vv",
      "         q    vv",
      "         q    vv",
      "         q    vv",
      " v       viiivvv",
      "              vv",
      "              vv"
    ],
    [
      "vvvvvvvvvvvvvvvv",
      " v       v    vv",
      " i       i    vv",
      " i       i    vv",
      " i       i    vv",
      "nvwwwwwwwviiivvv",
      " w       w    vv",
      " w       w    vv",
      " w       w    vv",
      "wvd      w    vv",
      "         w    vv",
      "         w    vv",
      "         w    vv",
      "Nv       viiivvv",
      " N            vv",
      " N            vv"
    ],
    [
      "vvvvvvvvvvvvvvvv",
      "OvOOOOOOOvOOOOvv",
      "PbPPPPPPPbPPPOvv",
      "PbPPPPPPPbPPPOvv",
      "PbPPPPPPPbPPPOvv",
      "bvbbbbbbbvbbbvvv",
      "PbPPPPPPPbPPP!vv",
      "PbPPPPPPPbPPPOvv",
      "PbPPPPPPPbPPPOvv",
      "PvdPPPPPPbPPPOvv",
      "PbPPPPPPPbPPPOvv",
      "PbPPPPPPPbPPPOvv",
      "PbPPPPPPPbPPPOvv",
      "Qvbbbbbbbvbbbvvv",
      " QPPPPPPPPPPPOvv",
      " QPPPPPPPPPPPOvv"
    ]
  ]
}