{
  "name": "multi_militarybase_2_ground",
  "refpalette": "c70cities:multi_militarybase_2_ground_palette",
  "xsize": 16,
  "zsize": 16,
  "slices": [
    [
      "aaaaaaaaaaaaaaaa",
      "bbbbbbbbbbbbbbba",
      "ccccccccccccccba",
      "ccccccccccccccba",
      "ccccccccccHdccba",
      "ceafcccccdHH=cba",
      "ccccccccc=HHHcba",
      "cccccccccHHHHcba",
      "ccccc!cccHHHHcba",
      "cccccccccHHHdcba",
      "cccccccccHHHHcba",
      "cccccccccHHHHcba",
      "cccccccccHHHdcba",
      "cccccccccdHHHcba",
      "HHd=HHHHH=HHHcba",
      "HHHHHHHHHHHH=cba"
    ],
    [
      "                ",
      "bbbbbbbbbbbbbbb ",
      "              b ",
      "              b ",
      "gggggggg      b ",
      "    hiii  jjj b ",
      "         kljlmb ",
      "          jjj b ",
      " no   p   jjj b ",
      "qggrsrrg  jjj b ",
      "  gt   g kljlmb ",
      "  gu  wg  jjj b ",
      "  gx yAg      b ",
      "  gggggg      b ",
      "              b ",
      "              b "
    ],
    [
      "                ",
      "bbbbbbbbbbbbbbb ",
      "              b ",
      "              b ",
      "BBBBCCBB  D D b ",
      "E   F i   I I b ",
      "          J K b ",
      "         LI IMb ",
      " N        IOI b ",
      "PBBrQrr  LIIIMb ",
      "  B    C  J K b ",
      "  C    C  RST b ",
      "  B   xB  UVU b ",
      "  BBCCBB      b ",
      "              b ",
      "              b "
    ],
    [
      "                ",
      "bbbbbbbbbbbbbbb ",
      "              b ",
      "   WWWW       b ",
      "BBBBBBBB  D D b ",
      "XE        I I b ",
      "          I I b ",
      "              b ",
      "          I I b ",
      "BBBrrrrBW     b ",
      "  B    BW YYY b ",
      "  C    BW  Y  b ",
      "  B    BW     b ",
      "  BBCCBB      b ",
      "              b ",
      "              b "
    ],
    [
      "                ",
      "bbbbbbbbbbbbbbb ",
      "              b ",
      "              b ",
      "BBBBZZBB      b ",
      " XEnnnn    Y  b ",
      "      n    Y  b ",
      "      n   YYY b ",
      "nn    n   YYY b ",
      "ZBBnnnnB  YYY b ",
      "  B   nZ      b ",
      "  B   nZ      b ",
      "  B   nB      b ",
      "  BBBBBB      b ",
      "              b ",
      "              b "
    ],
    [
      "                ",
      "00000000000000N ",
      "              1 ",
      "              1 ",
      "gggggggg      1 ",
      "  aaaaag      1 ",
      "aaaaaaag      1 ",
      "aaaaaaag      1 ",
      "aaaaaaag      1 ",
      "gggaaaag      1 ",
      "  gaaaag      1 ",
      "  gaaaag      1 ",
      "  gaaaag      1 ",
      "  gaaaag      1 ",
      "  gXXXXg      1 ",
      "  gXXXXg      1 "
    ]
  ]
}