{
  "name": "multi_gasstation_1_ground",
  "refpalette": "c70cities:multi_gasstation_1_ground_palette",
  "xsize": 16,
  "zsize": 16,
  "slices": [
    [
      "HHHHaHHaaaaaaaGG",
      "HHHHHHHaaaaaaaGG",
      "HHHHHHHaaaaaaaGG",
      "HHHHaHHaaaaaaaGG",
      "HHHHaHHaaaaaaaGG",
      "HHbcaHHaaaaaaaGG",
      "HHHHaHHaaaaaaaGG",
      "HHHHaHHaaaaaaaGG",
      "HHHHaHHaaaaaaaGG",
      "HHHHaHHaaaaaaaGG",
      "HHHHaHHaaaaaaaGG",
      "HHHHaHHaaaaaaaGG",
      "HHHHaHHaaaaaaaGG",
      "HHHHHHHHHHdGGGGG",
      "HHHHHHHHHHdGGGGG",
      "GGGGGGGGGGGGGGGG"
    ],
    [
      "  efg  h    ij  ",
      "       k  l lj  ",
      "       m  l nj  ",
      "    g  h  l lj  ",
      "  opq  h     j  ",
      "       j  llnj  ",
      "  efg  h    rj  ",
      "  opq  h    rj  ",
      "       k    rj  ",
      "  efg  jst jjj  ",
      "  opu  wx  yij  ",
      "       w   jAj  ",
      "  efg  jjjjjjj  ",
      "       B Cu     ",
      "       D Eu     ",
      "                "
    ],
    [
      "    g  h     j  ",
      "       F  n ij  ",
      "       I  l lj  ",
      "    g  h    nj  ",
      "    J  h     j  ",
      "       j  lilj  ",
      "    g  h     j  ",
      "    J  h     j  ",
      "       F     j  ",
      "    g  jK  jjj  ",
      "       L   M j  ",
      "       L NOjij  ",
      "    g  jjjjjjj  ",
      "                ",
      "                ",
      "                "
    ],
    [
      "    g  P     Q  ",
      "       P     P  ",
      "       P     P  ",
      "    g  P     Q  ",
      "       P     Q  ",
      "       P    iP  ",
      "    g  P     Q  ",
      "       P     Q  ",
      "       P     P  ",
      "    g  P   jjP  ",
      "       P   j Q  ",
      "       P  !j Q  ",
      "    g  PPPPPPP  ",
      "                ",
      "                ",
      "                "
    ],
    [
      "    jR j  S  j  ",
      "       j     j  ",
      "       j     j  ",
      "    jR j  R  j  ",
      "       j     j  ",
      "       jjjjjjj  ",
      "    jS j  S  j  ",
      "       j     j  ",
      "       j    ij  ",
      "    jS j  Sjjj  ",
      "       j   j j  ",
      "       j  ijij  ",
      "    jR jjjjjjj  ",
      "                ",
      "                ",
      "                "
    ],
    [
      " TuuauuuuuuuuaT ",
      " TuuauuuuuuuuaT ",
      " TuuauuuuuuuuaT ",
      " TuuauuuuuuuuaT ",
      " TuuauuuuuuuuaT ",
      " TuuaaaaaaaaaaT ",
      " TuuauuuuuuuuaT ",
      " TuuauuuuuuuuaT ",
      " TuuauuuuuuuuaT ",
      " TuuauuuuuuuuaT ",
      " TuuauuuuuuuuaT ",
      " TuuauuuuuuuuaT ",
      " TuuaaaaaaaaaaT ",
      " TTTTTTTTTTTTTT ",
      "                ",
      "                "
    ]
  ]
}