{
  "name": "multi_militarybase_2_ground",
  "refpalette": "c70cities:multi_militarybase_2_ground_palette",
  "xsize": 16,
  "zsize": 16,
  "slices": [
    [
      "aaaaaaaaaaaaaaaa",
      "bbbbbbbbbbbbbbbb",
      "cczzzzcczczzzccz",
      "zcczccccczczcczc",
      "ddddddddcccccccc",
      "eeeeeeedcccccccc",
      "eeeeeeedcccccccc",
      "eeeeeeedcccccccc",
      "eeeeeeedcccccccc",
      "dddeeeedcccccccc",
      "dddeeeedcccccccc",
      "dddeeeedcccccccc",
      "dddfeeedcccccccc",
      "ddddddddcccccccc",
      "cccccccccccccccc",
      "cccccccccccccccc"
    ],
    [
      "                ",
      "bbbbbbbbbbbbbbbb",
      "  gg g hg g i   ",
      "                ",
      "jjjjjjjj        ",
      "kk     l        ",
      "       l        ",
      "       l        ",
      " m     l        ",
      "njjopqoj rs s   ",
      "  jt  ujrswrs r ",
      "  ju  xjrrrrrs  ",
      "  jfxx!jrrsrr   ",
      "  jjjjjj ss     ",
      "  y             ",
      "                "
    ],
    [
      "                ",
      "bbbbbbbbbbbbbbbb",
      "       h   i    ",
      "                ",
      "AAABBBBA        ",
      "       l        ",
      "       l        ",
      "       l        ",
      " C     l        ",
      "DAAoEFoA        ",
      "  A    B  rr    ",
      "  B    B srrs   ",
      "  Af tIAs   J   ",
      "  AAAAAA        ",
      "                ",
      "                "
    ],
    [
      "                ",
      "bbbbbbbbbbbbbbbb",
      "       h  i     ",
      "   KKKK         ",
      "AAAAAAAA        ",
      "       l        ",
      "       l        ",
      "       l        ",
      "       l        ",
      "AAAooooAK       ",
      "  A    AK       ",
      "  B    AK       ",
      "  Af  IAK       ",
      "  AAAAAA        ",
      "                ",
      "                "
    ],
    [
      "                ",
      "bbbbbbbbbbbbbbbb",
      "       h i      ",
      "                ",
      "AAALLLLA        ",
      "M NNNNNO        ",
      "      NO        ",
      "      NO        ",
      "NN    NO        ",
      "LAANNNNA        ",
      "  A   NL        ",
      "  AI  NL        ",
      "  AfI NA        ",
      "  AAAAAA        ",
      "                ",
      "                "
    ],
    [
      "                ",
      "PPPPPPPQRPPPPPPP",
      "SSSSSSSSS       ",
      "      T         ",
      "jjjjjjjj        ",
      " Maaaaaj        ",
      "aaaaaaaj        ",
      "aaaaaaaj        ",
      "aaaaaaaj        ",
      "jjjaaaaj        ",
      "  jaaaaj        ",
      "  jaaaaj        ",
      "  jfaaaj        ",
      "  jaaaaj        ",
      "  jUUUUj        ",
      "  jUUUUj        "
    ]
  ]
}