{
  "name": "multi_condo1_4_floor6",
  "refpalette": "c70cities:multi_condo1_4_floor6_palette",
  "xsize": 16,
  "zsize": 16,
  "slices": [
    [
      "aaaaabccccccde  ",
      "fffgabcddddddhh ",
      "iiijabckkkkkde  ",
      "iiijabckkkkkde  ",
      "iiijabckkkkkde  ",
      "iiijabckkkkkdhh ",
      "iiijabcdddddde  ",
      "iiijabc     ce  ",
      "iiijabc     ce  ",
      "iiijabc     de  ",
      "iiijabl     dhh ",
      "iiijabmdddddde  ",
      "iiijabccj   de  ",
      "iiijabccn   de  ",
      "ooopabcddddddhh ",
      "aaaaabcccqqqde  "
    ],
    [
      "      r  stud   ",
      "wwww  dddddddhh ",
      "   w  x     d   ",
      "   w  d     y   ",
      "   w  d  AB d   ",
      "   w  d CDD dhh ",
      "   w  ddddddd   ",
      "   w  d     E   ",
      "   w  F     E   ",
      "   w  I     d   ",
      "   w  d     dhh ",
      "   w  ddddddd   ",
      "   w  d     y   ",
      "   w  J Kn  d   ",
      "wwww  dddddddhh ",
      "      r LdMNd   "
    ],
    [
      "      O PQ  d   ",
      "      dddddddhh ",
      "      R     d   ",
      "      dS    T   ",
      "      d  UV d   ",
      "      dWWDD dhh ",
      "      ddddddd   ",
      "      d     E   ",
      "      X     E   ",
      "      Y     d   ",
      "      d     dhh ",
      "      ddddddd   ",
      "      d     T   ",
      "      Z  Kn d   ",
      "      dddddddhh ",
      "      O  d  d   "
    ],
    [
      "            d   ",
      "      dddddddhh ",
      "      0     d   ",
      "      d     T   ",
      "      d     d   ",
      "      dW 11 dhh ",
      "      ddddddd   ",
      "      d     E   ",
      "      0     E   ",
      "      0     d   ",
      "      d     dhh ",
      "      ddddddd   ",
      "      d   0nT   ",
      "      0   Kcd   ",
      "      dddddddhh ",
      "         d  d   "
    ],
    [
      "            d   ",
      "      dddddddhh ",
      "      d     d   ",
      "      d     d   ",
      "      d     d   ",
      "      dW    dhh ",
      "      ddddddd   ",
      "      d     E   ",
      "      d     E   ",
      "      d     d   ",
      "      d     dhh ",
      "      ddddddd   ",
      "      d  0j d   ",
      "      d     d   ",
      "      dddddddhh ",
      "         d  d   "
    ],
    [
      "      222222d   ",
      "      dddddddhh ",
      "      dW    d   ",
      "      dW    d   ",
      "      dW    d   ",
      "      dWWWWWdhh ",
      "      ddddddd   ",
      "      d     E   ",
      "      d     E   ",
      "      d     d   ",
      "      d     dhh ",
      "      ddddddd   ",
      "      d 0j  d   ",
      "      d     d   ",
      "      dddddddhh ",
      "      222dkkd   "
    ]
  ]
}