{
  "name": "multi_megatower1_8_ground",
  "refpalette": "c70cities:multi_megatower1_8_ground_palette",
  "xsize": 16,
  "zsize": 16,
  "slices": [
    [
      "vvvvaaaaabbbbGGG",
      "vvvvaaaaabbbbGGG",
      "vvcvaaaaabbbbGGG",
      "vvvvaaaaabbbbGGG",
      "vvvvaaaaabbbbGGG",
      "vvvvaaaaabbbbGGG",
      "vvvvaaaaabbbbGGG",
      "vvvvaaaaabbbbGGG",
      "vvvvaaaaabbbbGGG",
      "vvcvaaaaabbbbGGG",
      "vvvvaaaaabbbbGGG",
      "vvvvaaaaabbbbGGG",
      "vvvvvvvvvvvvvvGG",
      "GGdGGGGGGdGGGGGG",
      "ddGddGdGdddGddGG",
      "dGGGGdGGdGGGGGdG"
    ],
    [
      "efcaabbbb       ",
      " fcaabbbb       ",
      "cccaabbbb       ",
      " fcaabbbb       ",
      "gfcaabbbb       ",
      " fcaabbbb       ",
      " fcaabbbb       ",
      "gfcaabbbb       ",
      " fcaabbbb       ",
      "cccaabbbb       ",
      " fcaabbbb       ",
      " fcaabbbbh      ",
      "iijiiiiiijiikk  ",
      "ll lmllll lm    ",
      "                ",
      "                "
    ],
    [
      "nbbbb           ",
      "nbbbb           ",
      "nbcbb           ",
      "nbbbb           ",
      "nbbbb           ",
      "nbbbb           ",
      "nbbbb           ",
      "nbbbb           ",
      "nbbbb           ",
      "nbbbb           ",
      "nbbbb           ",
      "nbbbb           ",
      "iijiiiiiko      ",
      "                ",
      "                ",
      "                "
    ],
    [
      "b               ",
      "b p             ",
      "b qr            ",
      "b               ",
      "b               ",
      "b               ",
      "b               ",
      "b               ",
      "b               ",
      "b               ",
      "b               ",
      "b h             ",
      "iijikk          ",
      "  s             ",
      "                ",
      "                "
    ],
    [
      "                ",
      "                ",
      "r q             ",
      "                ",
      "                ",
      "                ",
      "                ",
      "                ",
      "                ",
      "                ",
      "                ",
      "                ",
      "kk              ",
      "                ",
      "                ",
      "                "
    ],
    [
      "                ",
      "                ",
      "  c             ",
      "                ",
      "                ",
      "                ",
      "                ",
      "                ",
      "                ",
      "                ",
      "                ",
      "                ",
      "                ",
      "                ",
      "                ",
      "                "
    ]
  ]
}