{
  "name": "multi_condo1_1_ground",
  "refpalette": "c70cities:multi_condo1_1_ground_palette",
  "xsize": 16,
  "zsize": 16,
  "slices": [
    [
      "GGGabbGGGG      ",
      "GGccbbbbbbbbbbbb",
      "GGGGbddddddddddd",
      "GGGGbddddddddddd",
      "GGGGaddddddddddd",
      "GGGGaddddddddddd",
      "GGGGaddddddddddd",
      "GGGGaddddddddddd",
      "GGGGaddddddddddd",
      "GGGGaddddddddddd",
      "GGGGaddddddddddd",
      "GGGGaddddddddddd",
      "GGGGbddddddddddd",
      "GGGGbddddddddddd",
      "GGccbbbbbbbbbbbb",
      "GGGab           "
    ],
    [
      "    b           ",
      "  ccb           ",
      "    b           ",
      "    b           ",
      "                ",
      "                ",
      "                ",
      "                ",
      "                ",
      "                ",
      "                ",
      "                ",
      "    b           ",
      "    b           ",
      "  ccb           ",
      "    b           "
    ],
    [
      "    b           ",
      "  ccb           ",
      "    b           ",
      "    b           ",
      "                ",
      "                ",
      "                ",
      "                ",
      "                ",
      "                ",
      "                ",
      "                ",
      "    b           ",
      "    b           ",
      "  ccb           ",
      "    b           "
    ],
    [
      "    b           ",
      "  ccb           ",
      "    b           ",
      "    b           ",
      "                ",
      "                ",
      "                ",
      "                ",
      "                ",
      "                ",
      "                ",
      "                ",
      "    b           ",
      "    b           ",
      "  ccb           ",
      "    b           "
    ],
    [
      "    b           ",
      "  ccb           ",
      "    b           ",
      "    b           ",
      "                ",
      "                ",
      "                ",
      "                ",
      "                ",
      "                ",
      "                ",
      "                ",
      "    b           ",
      "    b           ",
      "  ccb           ",
      "    b           "
    ],
    [
      "    b           ",
      "  ccb           ",
      "    b           ",
      "    b           ",
      "                ",
      "                ",
      "                ",
      "                ",
      "                ",
      "                ",
      "                ",
      "                ",
      "    b           ",
      "    b           ",
      "  ccb           ",
      "    b           "
    ]
  ]
}