{
  "name": "multi_condo1_4_base2",
  "refpalette": "c70cities:multi_condo1_4_base2_palette",
  "xsize": 16,
  "zsize": 16,
  "slices": [
    [
      "HHHHHHHHHHHHabbv",
      "HHHaaaaaaaaaabbv",
      "HHHaccdeeeeeabbv",
      "HHHaccdeeeeeabbv",
      "HHHaccdeeeeeabbv",
      "HHHaccdeeeeeabbv",
      "HHHcccdaaaaaabbv",
      "HHHcccd     abbv",
      "HHHcccd     abbv",
      "HHHcccd     abbv",
      "HHHaccf     abbv",
      "HHHaccgaaaaaabbv",
      "HHHaccddddddabbv",
      "HHHaccddddddabbv",
      "HHHaaaaaaaaaabbv",
      "HHHHHHHHHHHHabbv"
    ],
    [
      "            abbv",
      " hhaaaaaaaaaabbv",
      " ija  k     abbv",
      "   a  a     abbv",
      " lma  a  no abbv",
      "  pa  aqrss abbv",
      "   t uaaaaaaabbv",
      "   w  a     abbv",
      "   x  y     abbv",
      "   t  A     abbv",
      "  Ba Ca     abbv",
      " ija  aaaaaaabbv",
      "   a  a   ddabbv",
      " lma  D Edddabbv",
      " hhaaaaaaaaaabbv",
      "            abbv"
    ],
    [
      "            abbv",
      "  Faaaaaaaaaabbv",
      "   a  I     abbv",
      "   a  aJ    abbv",
      "   a  a  KL abbv",
      "  pa  aqqss abbv",
      "   t  aaaaaaabbv",
      "   M  a     abbv",
      "   N  O     abbv",
      "   t  P     abbv",
      "  Ba  a     abbv",
      "   a  aaaaaaabbv",
      "   a  a   ddabbv",
      "   a  Q  Eddabbv",
      "   aaaaaaaaaabbv",
      "            abbv"
    ],
    [
      "      R     abbv",
      "   aaaaaaaaaabbv",
      "   a  S     abbv",
      "   a  a     abbv",
      "   a  a     abbv",
      "  pa  aq TT abbv",
      "  Ut  aaaaaaabbv",
      "  Ut Va     abbv",
      "  Ut  S     abbv",
      "  Ut  S     abbv",
      "  Ba Wa     abbv",
      "   a  aaaaaaabbv",
      "   a  a   ddabbv",
      "   a  S   Edabbv",
      "   aaaaaaaaaabbv",
      "      R     abbv"
    ],
    [
      "     qa     abbv",
      "aaaaaaaaaaaaabbv",
      "   a  a     abbv",
      "   a  a     abbv",
      "   a  a     abbv",
      "   a  aq    abbv",
      "   a  aaaaaaabbv",
      "   a Xa     abbv",
      "   a  a     abbv",
      "   a  a     abbv",
      "   a Xa     abbv",
      "   a  aaaaaaabbv",
      "   a  a  SY abbv",
      "   a  a     abbv",
      "aaaaaaaaaaaaabbv",
      "     qa     abbv"
    ],
    [
      "eeeeeea     abbv",
      "aaaaaaaaaaaaabbv",
      "eeeaeeaq    abbv",
      "eeeaeeaq    abbv",
      "eeeaeeaq    abbv",
      "eeeaeeaqqqqqabbv",
      "eeeaeeaaaaaaabbv",
      "eeeaeea     abbv",
      "eeeaeea     abbv",
      "eeeaeea     abbv",
      "eeeaeea     abbv",
      "eeeaeeaaaaaaabbv",
      "eeeaeea SY  abbv",
      "eeeaeea     abbv",
      "aaaaaaaaaaaaabbv",
      "eeeeeea     abbv"
    ]
  ]
}