{
  "name": "multi_condo1_3_floor3",
  "refpalette": "c70cities:multi_condo1_3_floor3_palette",
  "xsize": 16,
  "zsize": 16,
  "slices": [
    [
      "                ",
      "      a         ",
      "bbbbbbacccccccc ",
      "deeeeeafffffffc ",
      "ddgggddddddddfc ",
      "hhhhhhhhhhhhdfc ",
      "hhhhhhhhhhhhdfc ",
      "hhhhhhhhhhhhdfc ",
      "hhhhhhhhhhhhdfc ",
      "hhhhhhhhhhhhdfc ",
      "hhhhhhhhhhhhdfc ",
      "hhhhhhhhhhhhdfc ",
      "hhhhhhhhhiiidfc ",
      "hhhhhhhhhiiidaaa",
      "jjjjjjjhhiiide  ",
      "kkkkkljhhiiide  "
    ],
    [
      "                ",
      "      a         ",
      "bbbbbba         ",
      "d     afffffff  ",
      "ddm mdddnnnddf  ",
      "oppq rosstuwdf  ",
      "opp  ros x ydf  ",
      "opA  BoCDE Fdf  ",
      "oIJ  KoCCDLMdf  ",
      "oN   Ooooo Pdf  ",
      "oN    Q  LRPdf  ",
      "oST    UVo Pdf  ",
      "oS    WXYoZodf  ",
      "o0123 456o Ndaaa",
      "dddddddW7o8Nd   ",
      "      93W78 @   "
    ],
    [
      "                ",
      "      a         ",
      "      a         ",
      "d     a         ",
      "ddm mdddmmmdd   ",
      "op#   o####$d   ",
      "opJ   os   %d   ",
      "o^    oC&  *d   ",
      "o     oCx  (d   ",
      "o)    oooo Pd   ",
      "o+         Pd   ",
      "o-       o Pd   ",
      "oT    [  o]od   ",
      "o{ }\\ |  o  daaa",
      "ddddddd`:o; d   ",
      "      '8,.8/b   "
    ],
    [
      "                ",
      "      a         ",
      "      a         ",
      "d     a         ",
      "ddmmmdddmmmdd   ",
      "o< ## o ####d   ",
      "o     o     d   ",
      "o     oC    d   ",
      "o     oC    d   ",
      "o>    oooo ?d   ",
      "o        o [d   ",
      "o\u00a3       o \u00a4d   ",
      "o        oood   ",
      "o        o \u00a5daaa",
      "ddddddd  o  d   ",
      "      \u00a7  o /b   "
    ],
    [
      "                ",
      "      a         ",
      "      a         ",
      "d     a\u00c0\u00c0\u00c0\u00c0\u00c0\u00c0\u00c0  ",
      "ddddddddddddd\u00c0  ",
      "o     o     d\u00c0  ",
      "o     o     d\u00c0  ",
      "o     o     d\u00c0  ",
      "o     o     d\u00c0  ",
      "o     oooo  d\u00c0  ",
      "o        o  d\u00c0  ",
      "o        o  d\u00c0  ",
      "o        oood\u00c0  ",
      "o        o  daaa",
      "ddddddd  o  d   ",
      "      d  o  d   "
    ],
    [
      "                ",
      "      a         ",
      "\u00c1\u00c1\u00c1\u00c1\u00c1\u00c1a         ",
      "d     a\u00c2\u00c2\u00c2\u00c2\u00c2\u00c2\u00c2  ",
      "ddddddddddddd\u00c2  ",
      "\u00c3\u00c3\u00c3\u00c3\u00c3\u00c3\u00c3\u00c3\u00c3\u00c3\u00c3\u00c3d\u00c2  ",
      "\u00c3\u00c3\u00c3\u00c3\u00c3\u00c3\u00c3\u00c3\u00c3\u00c3\u00c3\u00c3d\u00c2  ",
      "\u00c3\u00c3\u00c3\u00c3\u00c3\u00c3\u00c3\u00c3\u00c3\u00c3\u00c3\u00c3d\u00c2  ",
      "\u00c3\u00c3\u00c3\u00c3\u00c3\u00c3\u00c3\u00c3\u00c3\u00c3\u00c3\u00c3d\u00c2  ",
      "\u00c3\u00c3\u00c3\u00c3\u00c3\u00c3\u00c3\u00c3\u00c3\u00c3\u00c3\u00c3d\u00c2  ",
      "\u00c3\u00c3\u00c3\u00c3\u00c3\u00c3\u00c3\u00c3\u00c3\u00c3\u00c3\u00c3d\u00c2  ",
      "\u00c3\u00c3\u00c3\u00c3\u00c3\u00c3\u00c3\u00c3\u00c3\u00c3\u00c3\u00c3d\u00c2  ",
      "\u00c3\u00c3\u00c3\u00c3\u00c3\u00c3\u00c3\u00c3\u00c3\u00c3\u00c3\u00c3d\u00c2  ",
      "\u00c3\u00c3\u00c3\u00c3\u00c3\u00c3\u00c3\u00c3\u00c3\u00c3\u00c3\u00c3daaa",
      "ddddddd\u00c3\u00c3\u00c3\u00c3\u00c3d   ",
      "      d\u00c3\u00c3\u00c3\u00c3\u00c3d   "
    ]
  ]
}