{
  "name": "multi_communitycenter_3_ground",
  "refpalette": "c70cities:multi_communitycenter_3_ground_palette",
  "xsize": 16,
  "zsize": 16,
  "slices": [
    [
      "aaaaaaaaaaaaaaaa",
      "aaaaaaaaaaaaaaaa",
      "bbbcaaaaaaaaaaaa",
      "bbbcaaaaaaaaaaaG",
      "bbbcaaaaaaaaaaGG",
      "dddcaaaaaaaaaaGG",
      "dddcaaaaaaaaaaGG",
      "dddcaaaaeeaaaaGG",
      "dddcaaaeffeaaaag",
      "dddcaaeffffeaaGg",
      "dddcaaeffffeaaGg",
      "dddcaaeffffeaaGg",
      "hhhcaaeffffeaaag",
      "iihjaaeffffeaaGg",
      "kkljaaeffffeaaGg",
      "kmljaaeffffeaaGg"
    ],
    [
      "                ",
      "                ",
      "  no            ",
      " pno           q",
      "rrnj          qq",
      "bbbj          qs",
      "bbbj          q ",
      "bbbj   teet   qu",
      "bbbj  teffet  wx",
      "dddj  effffe  qy",
      "dddj  effffe  qx",
      "dddj  effffe  qy",
      "AAhj  effffe  wy",
      "  hj  effffe  qy",
      "   j  effffe  qx",
      "  Bj  effffe  qy"
    ],
    [
      "                ",
      "                ",
      "                ",
      "                ",
      "  n             ",
      "  n            C",
      "  no            ",
      "  no    ~      D",
      "  nj          wx",
      "bbbj           y",
      "bbEj           x",
      "bbEj           y",
      "bbbj          wy",
      "hhhj           y",
      "FFFj           x",
      "FFFI           y"
    ],
    [
      "                ",
      "                ",
      "                ",
      "                ",
      "                ",
      "                ",
      "                ",
      "        ~       ",
      "  n           wx",
      "  n            y",
      "  no           x",
      "  no           y",
      " pnj          wy",
      "bbbj           y",
      "bbbj           x",
      "bbbj           y"
    ],
    [
      "                ",
      "                ",
      "                ",
      "                ",
      "                ",
      "                ",
      "                ",
      "        ~       ",
      "              wJ",
      "               y",
      "               y",
      "               y",
      "  n           wy",
      "  n            y",
      "p no           y",
      "  no           y"
    ],
    [
      "                ",
      "                ",
      "                ",
      "                ",
      "                ",
      "                ",
      "                ",
      "        ~       ",
      "              KK",
      "              Kg",
      "              Kg",
      "              Kg",
      "              wg",
      "              Kg",
      "              Kg",
      "              Kg"
    ]
  ]
}