{
  "name": "multi_condo1_0_floor5",
  "refpalette": "c70cities:multi_condo1_0_floor5_palette",
  "xsize": 16,
  "zsize": 16,
  "slices": [
    [
      "                ",
      "          a     ",
      "  bbbbbbbbaccccc",
      "  bdddddddaeeeee",
      "  bdffffffffgggf",
      "  bdfhhhhhhhhhhh",
      "  bdfhhhhhhhhhhh",
      "  bdfhhhhhhhhhhh",
      "  bdfhhhhhhhhhhh",
      "  bdfhhhhhhhhhhh",
      "  bdfhhhhhhhhhhh",
      "  bdfhhhhhhhhiii",
      "  bdfhhhhhhhhiii",
      " aaafhhhhhhhhiii",
      "   efiiihhjjjjjj",
      "   efiiihhjkllll"
    ],
    [
      "                ",
      "          a     ",
      "          accccc",
      "   ddddddda     ",
      "   dffmmmfffn nf",
      "   dfop   qrs  t",
      "   df     qrs  u",
      "   df  rs qw xx ",
      "   dfxxrs qy qqq",
      "   dfqqqw qA B C",
      "   dfC D  qE q F",
      "   dfF qy qI qJq",
      "   dfK qA qL B M",
      " aaafN qE qL q O",
      "    fqPqI ffQfff",
      "    R  D  S     "
    ],
    [
      "                ",
      "          a     ",
      "          a     ",
      "          a     ",
      "    ffnnnfffn nf",
      "    f     q     ",
      "    f     q!    ",
      "    f  T  qU  V ",
      "    fWXY  qZ qqq",
      "    fqqqU q0 1 2",
      "    f  3  q  q 4",
      "    f  qZ q5 q6q",
      "    f  q0 q  1  ",
      " aaaf! q  q  q7 ",
      "    fq8q 9ff@fff",
      "    c# 3  $     "
    ],
    [
      "                ",
      "          a     ",
      "          a     ",
      "          a     ",
      "    ffnnnfffnnnf",
      "    f     q     ",
      "    f     q     ",
      "    f     q     ",
      "    f     q  qqq",
      "    fqqq  q  q  ",
      "    f  q  q  q %",
      "    f  q  q  qqq",
      "    f  q  q  q  ",
      " aaaf  q  q  q^ ",
      "    fqqq  ff&fff",
      "    c* q  (     "
    ],
    [
      "                ",
      "          a     ",
      "          a     ",
      "   )))))))a     ",
      "   )ffffffffffff",
      "   )f     q     ",
      "   )f     q     ",
      "   )f     q     ",
      "   )f     q  qqq",
      "   )fqqq  q  q  ",
      "   )f  q  q  q  ",
      "   )f  q  q  qqq",
      "   )f  q  q  q  ",
      " aaaf  q  q  q  ",
      "    fqqq  ffffff",
      "    f  q  f     "
    ],
    [
      "                ",
      "          a     ",
      "          a+++++",
      "   -------a     ",
      "   -ffffffffffff",
      "   -f[[[[[[[[[[[",
      "   -f[[[[[[[[[[[",
      "   -f[[[[[[[[[[[",
      "   -f[[[[[[[[[[[",
      "   -f[[[[[[[[[[[",
      "   -f[[[[[[[[[[[",
      "   -f[[[[[[[[[[[",
      "   -f[[[[[[[[[[[",
      " aaaf[[[[[[[[[[[",
      "    f[[[[[ffffff",
      "    f[[[[[f     "
    ]
  ]
}