{
  "name": "multi_laboratory1_10_base5",
  "refpalette": "c70cities:multi_laboratory1_10_base5_palette",
  "xsize": 16,
  "zsize": 16,
  "slices": [
    [
      "vvvvvvvvvvvvvvvv",
      "aaaaaaaaaaaaaaav",
      "bbbbccccccccccav",
      "    deeeeeeeecav",
      "    deeeeeeeecav",
      "fffffeeeeeeeecav",
      "    feeeeeeeecav",
      "    fggggggggcav",
      "    f   h    cav",
      "    f        cav",
      "    f        cav",
      " i  f        cav",
      " ijjf        cav",
      "kkkkf        cav",
      "kkkkf        cav",
      "ddddfddddddddcav"
    ],
    [
      "vvvvvvvvvvvvvvvv",
      "aaaaaaaaaaaaaaav",
      "bbbbccccccccccav",
      "    dglm lm ncav",
      "    dg      ocav",
      "ddddfg      ncav",
      "    dglm lm ncav",
      "    dggggggpgcav",
      "    d    qqqqcav",
      "    d        cav",
      "    d        cav",
      "kk  d        cav",
      "jjr d        cav",
      "    d        cav",
      "    d        cav",
      "ddddfddddddddcav"
    ],
    [
      "vvvvvvvvvvvvvvvv",
      "aaaaaaaaaaaaaaav",
      "bbbbccccccccccav",
      "    dglm lm  cav",
      "    dg      scav",
      "ddddfg       cav",
      "    dglm lm  cav",
      "    dggggggtgcav",
      "    d        cav",
      "kk  d        cav",
      "jjr d        cav",
      "  r d        cav",
      "    d        cav",
      "    d        cav",
      "    d        cav",
      "ddddfddddddddcav"
    ],
    [
      "vvvvvvvvvvvvvvvv",
      "aaaaaaaaaaaaaaav",
      "bbbbccccccccccav",
      "    dg      ucav",
      "    dg       cav",
      "ddddfg      wcav",
      "kkkkdg      xcav",
      "kkkkdggggggggcav",
      "jjr d        cav",
      "  r d        cav",
      "    d        cav",
      "    d        cav",
      "    d        cav",
      "    d        cav",
      "    d        cav",
      "ddddfddddddddcav"
    ],
    [
      "vvvvvvvvvvvvvvvv",
      "aaaaaaaaaaaaaaav",
      "bbbbccccccccccav",
      "    dg       cav",
      "h   dg       cav",
      "ddddfg      wcav",
      "    dg     wwcav",
      "    dggggggggcav",
      " ijjd        cav",
      "  kkd        cav",
      "    d        cav",
      "    d        cav",
      "    d        cav",
      "    d        cav",
      "    d        cav",
      "ddddfddddddddcav"
    ],
    [
      "vvvvvvvvvvvvvvvv",
      "aaaaaaaaaaaaaaav",
      "bbbbccccccccccav",
      "    dyyyyyyyycav",
      " h  dyyyyyyyycav",
      "ddddfyyyyyyyycav",
      "    dyyyyyyyycav",
      "    dddddddddcav",
      "    dyyyyyyyycav",
      " i  dyyyyyyyycav",
      " ijjdyyyyyyyycav",
      "  kkdyyyyyyyycav",
      "    dyyyyyyyycav",
      "    dyyyyyyyycav",
      "    dyyyyyyyycav",
      "ddddfddddddddcav"
    ]
  ]
}