{
  "name": "multi_laboratory1_5_ground",
  "refpalette": "c70cities:multi_laboratory1_5_ground_palette",
  "xsize": 16,
  "zsize": 16,
  "slices": [
    [
      "zzzzzzzzzzzzzzzz",
      "aabaaaazzaaaaaaa",
      "cccccccccccccccc",
      "cccccccccccccccc",
      "cccccccccccccccc",
      "dddddddddddddddd",
      "e    e    f    e",
      "eg  geg  gfg  ge",
      "eeeeeeeeeeeeeeee",
      "e    ehhhhe    e",
      "e    ehhhhe    e",
      "e    ehhhhe    e",
      "e    ehhhhe    e",
      "e    ehhhhe    e",
      "e    ehhhhe    e",
      "eeeeeeeeeeeeeeee"
    ],
    [
      "    i         jj",
      "       j        ",
      "kkkkllllllllllll",
      "                ",
      "                ",
      "mnnnndnnnndnnnnm",
      "f    f    f    f",
      "foooofoooofoooof",
      "effffeffffeffffe",
      "f    fhpphf    f",
      "f    fq  rf    f",
      "f    fq  rf    f",
      "f    fq  sf    f",
      "f    fq  rf    f",
      "f    fhtuhf    f",
      "efwwfefwwfefwwfe"
    ],
    [
      "                ",
      "                ",
      "kkkkllllllllllll",
      "                ",
      "                ",
      "mnnnndnnnndnnnnm",
      "f x  f y  f  y f",
      "foooofoooofoooof",
      "effffeffffeffffe",
      "f    fhpphf    f",
      "f    fq  rf    f",
      "f    fq  rf    f",
      "f    fq  rf    f",
      "f    fq  rf    f",
      "f    fhABhf    f",
      "ef  fef  fef  fe"
    ],
    [
      "                ",
      "                ",
      "kkkkCCCCDCCCCDCC",
      "                ",
      "                ",
      "mnnnndnnnndnnnnm",
      "fx y f  xxfxx  f",
      "foooofoooofoooof",
      "effffeffffeffffe",
      "f    fhpphf    f",
      "f    fq  rf    f",
      "f    fq  rf    f",
      "f    fq  rf    f",
      "f    fq  rf    f",
      "f    fhpphf    f",
      "efhhfefhhfefhhfe"
    ],
    [
      "                ",
      "                ",
      "CDDCDCCCCDCCDCCC",
      "EEEE            ",
      "                ",
      "mnnnndnnnndnnnnm",
      "fxx  f xx f  y f",
      "foooofoooofoooof",
      "effffeffffeffffe",
      "f    fhpphf    f",
      "f    fqFFrf    f",
      "f    fqFFrf    f",
      "f    fqFFrf    f",
      "f    fqFFrf    f",
      "f    fhpphf    f",
      "effffeffffeffffe"
    ],
    [
      "                ",
      "                ",
      "CDDCCCCDCCDCCDDD",
      "                ",
      "                ",
      "mnnnndnnnndnnnnm",
      "f x  f x  f x  f",
      "foooofoooofoooof",
      "effffeffffeffffe",
      "f    fhhhhf    f",
      "f    fhpphf    f",
      "f    fhpphf    f",
      "f    fhpphf    f",
      "f    fhpphf    f",
      "f    fhhhhf    f",
      "effffeffffeffffe"
    ]
  ]
}