{
  "name": "multi_laboratory1_10_ground",
  "refpalette": "c70cities:multi_laboratory1_10_ground_palette",
  "xsize": 16,
  "zsize": 16,
  "slices": [
    [
      "zzzzzzzzzzzzzzzz",
      "zazaaaaaazzzzzzz",
      "bbbbbcvccaazzzzz",
      "bbbbbbbvvcaczzzz",
      "bbbbbbbvvazaazzz",
      "dddddbbbvcaaaaza",
      "    dbbbccaazazz",
      "    dbbbvvcaaaaz",
      "    dbbbvcazazzz",
      "    dbbbvccaazaz",
      "    dbbbvaaaaaza",
      " e  dbbbvcacaazz",
      " effdbbbvcaaazza",
      "ggggdbbbvccaaaaz",
      "ggggdbbbvcaazaaz",
      "hhhhdbbbvvaaaaaz"
    ],
    [
      " i     i  i  i  ",
      "  i      j  i ki",
      "lllll       ii  ",
      "     ll        i",
      "      l   i   i ",
      "mdmmn  l        ",
      "    m  l       i",
      "    m  l  op    ",
      "    d  l   i    ",
      "    m  l        ",
      "    m  l  pqr   ",
      "gg  m  s        ",
      "ff  m           ",
      "    m     ptuo  ",
      "    m          i",
      "wxxxd           "
    ],
    [
      "                ",
      "                ",
      "lllyl           ",
      "     yl         ",
      "      l         ",
      "Admmn  l        ",
      "    m  l        ",
      "    m  l        ",
      "    d  l        ",
      "gg  A  l        ",
      "ff  m  y        ",
      "    m  l        ",
      "    m  s        ",
      "    m           ",
      "    A           ",
      "Bxxxd           "
    ],
    [
      "                ",
      "                ",
      "yyyyC           ",
      "     yy         ",
      "      C         ",
      "Admmn  y        ",
      "ggggm  y        ",
      "ggggm  C        ",
      "ff  d  y        ",
      "    A  y        ",
      "    m  C        ",
      "    m  C        ",
      "    m  l        ",
      "    m  s        ",
      "D   A           ",
      "Exxxd           "
    ],
    [
      "                ",
      "                ",
      "yyCCy           ",
      "     yC         ",
      "      y         ",
      "Admmn  C        ",
      "    m  y        ",
      "    m  C        ",
      "  ffd  C        ",
      "  ggA  C        ",
      "    m  y        ",
      "    m  C        ",
      "    m  y        ",
      "    m  l        ",
      "    A  s        ",
      "xxxxd           "
    ],
    [
      "                ",
      "                ",
      "yCyCy           ",
      "     Cy         ",
      "      y         ",
      "mdmmn  C        ",
      "    m  C        ",
      "    m  y        ",
      "    d  C        ",
      "    m  y        ",
      "  ffm  C        ",
      "  ggm  C        ",
      "    m  C        ",
      "    m  y        ",
      "    m  l        ",
      "xxxxd  s        "
    ]
  ]
}