{
  "name": "multi_laboratory1_12_base3",
  "refpalette": "c70cities:multi_laboratory1_12_base3_palette",
  "xsize": 16,
  "zsize": 16,
  "slices": [
    [
      " abbbbbbbbbbbcdv",
      " abbbbbbbbbbbcdv",
      " abbbbbbbbbbbcdv",
      "eabbbbbbbbbbbcdv",
      "abbbfbbbbbbbbcdv",
      "abbbbbbbbbbbbcdv",
      "bbbbbbbbbbbbbcdv",
      "bbbbbbbbbbbbbcdv",
      "bbbbbbbbbbbbbcdv",
      "bbbbbbbbbbbbbcdv",
      "bbbbbbbbbbbbbcdv",
      "bbbbfbbbbbbbbcdv",
      "bbbbbbbbbbbbbcdv",
      "bbbbbbbbbbbbbcdv",
      "bbbbbbbbbbbbbcdv",
      "bbbbbbbbbbbbbcdv"
    ],
    [
      " g  h    i jkldv",
      " g  m     njkldv",
      " g  o      pjjdv",
      "eg  qr       cdv",
      "ge  fr      scdv",
      "gt  q      u cdv",
      "    q     p wcdv",
      "    q xxyxx wcdv",
      "    q AAAAA  cdv",
      "    q xxBxx  cdv",
      "C   q   D    cdv",
      "   efqqqqqqqqcdv",
      "    qEE E  FFcdv",
      "    o       Icdv",
      "    h      JKcdv",
      "    m       Kcdv"
    ],
    [
      " g  L      gkldv",
      " g  M      gkldv",
      " g  o       gjdv",
      "eg  q       Ncdv",
      "gO  f       scdv",
      "g   q        cdv",
      "    P        cdv",
      "    P QQyQQ  cdv",
      "    P QQ QQ  cdv",
      "    P   B R  cdv",
      "    q   S    cdv",
      "   Ofqqqqqqqqcdv",
      "    q        cdv",
      "    o        cdv",
      "    L       Tcdv",
      "    M       Ucdv"
    ],
    [
      " g  o      gkldv",
      " g  o      gkldv",
      " g  o       gjdv",
      "eg  q        cdv",
      "gO  f       scdv",
      "g   q        cdv",
      "    P       Vcdv",
      "    P QQ QQ Vcdv",
      "    P QQ QQ  cdv",
      "    P        cdv",
      "    q        cdv",
      "   Ofqqqqqqqqcdv",
      "    q        cdv",
      "    o        cdv",
      "    o        cdv",
      "    o        cdv"
    ],
    [
      " g  q      gWldv",
      " g  q      gWldv",
      " g  q       gjdv",
      "eg  q       Ncdv",
      "g   f       Xcdv",
      "g   q       Ncdv",
      "    q       Xcdv",
      "    q       Xcdv",
      "    q        cdv",
      "    q        cdv",
      "    q  Y  Z  cdv",
      "    fqqqqqqqqcdv",
      "    q        cdv",
      "    q       0cdv",
      "    q        cdv",
      "    q        cdv"
    ],
    [
      " g112334334j5ldv",
      " g112334336j5ldv",
      " g1123343343jjdv",
      "eg11233333333cdv",
      "g111f33333333cdv",
      "g111233433433cdv",
      "1111233433633cdv",
      "1111233433433cdv",
      "1111233433433cdv",
      "1111233333333cdv",
      "111127777777!cdv",
      "1111fqqqqqqqqcdv",
      "1111273333337cdv",
      "1141273333337cdv",
      "1141273433437cdv",
      "1141273833437cdv"
    ]
  ]
}