{
  "name": "multi_hospital_2_base1",
  "refpalette": "c70cities:multi_hospital_2_base1_palette",
  "xsize": 16,
  "zsize": 16,
  "slices": [
    [
      "vvvvvvvvvvvvvvvv",
      "aaaaaaaaaaaaaaav",
      "aaaaaaaaaaaaaaav",
      "bbaaaaaaaaaaaaav",
      "bbaaaaaaaaaaaaav",
      "bbaaaaaaaaaaaaav",
      "bbaaaaaaaaaaaaav",
      "bbaaaaaaaaaaaaav",
      "bbbbbbbbbbbbbbbv",
      "bbcccccccccccccv",
      "bbcccccccccccccv",
      "bbcccccccccccccv",
      "bbdddddddddddddv",
      "bbdddddddddddddv",
      "bbdddddddddddddv",
      "bbcccccccccccccv"
    ],
    [
      "vvvvvvvvvvvvvvvv",
      "aaaaaaaaaaaaaaav",
      "aaaaaaaaaaaaaaav",
      "eeaaaaaaaaaaaaav",
      "feaaaaaaaaaaaaav",
      " eaaaaaaaaaaaaav",
      " eaaaaaaaaaaaaav",
      " eaaaaaaaaaaaaav",
      " bvvvvvvvvvvvvvv",
      "ghc c c cic c cv",
      "ghc cjcjc ckc cv",
      " bc c c c c c cv",
      "ll             v",
      "               v",
      "               v",
      "mbc c c c c c cv"
    ],
    [
      "vvvvvvvvvvvvvvvv",
      "aaaaaaaaaaaaaaav",
      "aaaaaaaaaaaaaaav",
      "eeaaaaaaaaaaaaav",
      " eaaaaaaaaaaaaav",
      " eaaaaaaaaaaaaav",
      " eaaaaaaaaaaaaav",
      " eaaaaaaaaaaaaav",
      " bvvvvvvvvvvvvvv",
      " hcncncncncncncv",
      "ohcncncncncncncv",
      " bcncncncncncncv",
      "ll             v",
      "               v",
      "               v",
      "pbcncncncncncncv"
    ],
    [
      "vvvvvvvvvvvvvvvv",
      "aaaaaaaaaaaaaaav",
      "aaaaaaaaaaaaaaav",
      "eeaaaaaaaaaaaaav",
      " eaaaaaaaaaaaaav",
      " eaaaaaaaaaaaaav",
      " eaaaaaaaaaaaaav",
      " eaaaaaaaaaaaaav",
      " bvvvvvvvvvvvvvv",
      " hcqcqcqcqcqcqcv",
      " hcqcqcqcqcqcqcv",
      " bcqcqcqcqcqcqcv",
      "ll             v",
      "               v",
      "               v",
      " bcqcqcqcqcqcqcv"
    ],
    [
      "vvvvvvvvvvvvvvvv",
      "aaaaaaaaaaaaaaav",
      "aaaaaaaaaaaaaaav",
      "eeaaaaaaaaaaaaav",
      " eaaaaaaaaaaaaav",
      " eaaaaaaaaaaaaav",
      " eaaaaaaaaaaaaav",
      " eaaaaaaaaaaaaav",
      " bvvvvvvvvvvvvvv",
      " hc c c c c crcv",
      " hc ckc cjc!c cv",
      " bc c c c c c cv",
      "ll             v",
      "               v",
      "               v",
      " bc c c c c c cv"
    ],
    [
      "vvvvvvvvvvvvvvvv",
      "aaaaaaaaaaaaaaav",
      "aaaaaaaaaaaaaaav",
      "eeaaaaaaaaaaaaav",
      "seaaaaaaaaaaaaav",
      "seaaaaaaaaaaaaav",
      "seaaaaaaaaaaaaav",
      "seaaaaaaaaaaaaav",
      "bbvvvvvvvvvvvvvv",
      "sbcccccccccccccv",
      "sbcccccccccccccv",
      "bbcccccccccccccv",
      "tbuuuuuuuuuuuuuv",
      "ubuuuuuuuuuuuuuv",
      "ubuuuuuuuuuuuuuv",
      "ubcccccccccccccv"
    ]
  ]
}