{
  "name": "multi_militarybase_3_base1",
  "refpalette": "c70cities:multi_militarybase_3_base1_palette",
  "xsize": 16,
  "zsize": 16,
  "slices": [
    [
      "                ",
      "  a    a    a   ",
      "bbvbbbbvbbbbvbbb",
      "cccccccbcccccccc",
      "cccccccbcccccccc",
      "cccccccbcccccccc",
      "dddddddvdddddddd",
      "eeeeeeebeeeeeeee",
      "eeeeeeebeeeeeeee",
      "eeeeeeebeeeeeeee",
      "bbbbbbbvbbbbbbbb",
      "fffffffbeeeeeeee",
      "fffffffbeeeeeeee",
      "fffffffbeeeeeeee",
      "fffffffveeeeeeee",
      "vvvvvvvvvvvvvvvv"
    ],
    [
      "                ",
      "                ",
      "ggvggggvggggvggg",
      "                ",
      "                ",
      "                ",
      "       vhhhhhhhh",
      "       i        ",
      "       i  jj jj ",
      "k   lmki  jj jj ",
      "hhnhhhhv        ",
      "o  pqrri        ",
      "s   t uiw w w w ",
      "o   qrriw w w w ",
      "s x t uvw w w w ",
      "vvvvvvvvvvvvvvvv"
    ],
    [
      "                ",
      "                ",
      "  v    v    v   ",
      "                ",
      "                ",
      "                ",
      "       vhhhhhhhh",
      "       i        ",
      "       i  jj jj ",
      "       i  jj jj ",
      "hhyhhhhv        ",
      "A   qrri        ",
      "s   B  iC D E E ",
      "A   qrriD C D E ",
      "s F B  vD C E E ",
      "vvvvvvvvvvvvvvvv"
    ],
    [
      "                ",
      "                ",
      "  v    v    v   ",
      "                ",
      "                ",
      "                ",
      "       vhhhhhhhh",
      "       i        ",
      "       i  jj jj ",
      "       i  jj jj ",
      "hhhhhhhv        ",
      "s   qrri        ",
      "s   q  i        ",
      "s   qrri        ",
      "s F q  v        ",
      "vvvvvvvvvvvvvvvv"
    ],
    [
      "                ",
      "                ",
      "IIvIIIIvIIIIvIII",
      "                ",
      "                ",
      "                ",
      "       vhhhhhhhh",
      "       i        ",
      "       i  JJ JJ ",
      "       i  JJ !J ",
      "hhhhhhhv  KK KK ",
      "LLLLLLLi        ",
      "LLLLLLLi        ",
      "LLLLLLLi        ",
      "LLLLLLLv        ",
      "vvvvvvvvvvvvvvvv"
    ],
    [
      "MMMMMMMMMMMMMMMM",
      "MMMMMMMMMMMMMMMM",
      "bbvbbbbvbbbbvbbb",
      "NNNNNNNbNNNNNNNN",
      "NNNNNNNbNNNNNNNN",
      "NNNNNNNbNNNNNNNN",
      "NNNNNNNvOOOOOOOO",
      "NNNNNNNbNNPPNPPN",
      "NNNNNNNbNNJJNJJN",
      "NNNNNNNbNNJJNJJN",
      "bbbbbbbvbbbbbbbb",
      "QR  Q RbNNNNNNNN",
      "Q   Q  bNNNNNNNN",
      "QR RQ RbNNNNNNNN",
      "QQQQQQQvQQQQQQQQ",
      "vvvvvvvvvvvvvvvv"
    ]
  ]
}