{
  "name": "multi_megatower1_4_floor12",
  "refpalette": "c70cities:multi_megatower1_4_floor12_palette",
  "xsize": 16,
  "zsize": 16,
  "slices": [
    [
      "a   bbbbbbbbbbbb",
      "a   bbbbbbbbbbbb",
      "a   bbbbbbbbbbbb",
      "cdeebbbbbbbbbbbb",
      "bbbbfbbbbbbfgggg",
      "bbbbbbbbbbbbgggg",
      "bbbbbbbbbbbbgggg",
      "bbbbbbbbbbbbgggg",
      "bbbbbbbbbbbbgggg",
      "bbbbbbbbbbbbgggg",
      "bbbbbbbbbbbbgggg",
      "bbbbfbbbbbbfgggg",
      "bbbbbbbbbbbbbbbb",
      "bbbbbbbbbbbbbbbb",
      "bbbbbbbbbbbbbbbb",
      "bbbbbbbbbbbbbbbb"
    ],
    [
      "a   hi jkkjl   m",
      "a   hijkkk n    ",
      "a   ho kk kp   q",
      "aerrhs    tp   u",
      "wxyAfBCyACBfDEDD",
      "   Ft      pI  D",
      "           pJ  K",
      "L          pM  D",
      "    Nm     pM  K",
      " mO N OP OPpJ  D",
      "P OPN O QO p   K",
      "N  tft  NNNfDRDD",
      " mO N OP OPp    ",
      "P OPNmO mO p   S",
      "    N      T  UV",
      "           W   X"
    ],
    [
      "a   h      Y    ",
      "a   h      Z    ",
      "a   h      p    ",
      "ae  h     0p    ",
      "w 12fBC12CBfD3DD",
      "    0      p   D",
      "           45  6",
      "           45  D",
      "           45  6",
      "    N      45  D",
      "           p   6",
      "N  0f0  N NfD7DD",
      "    N      p    ",
      "           p    ",
      "    !      8    ",
      "           9    "
    ],
    [
      "a   h      @    ",
      "a   h      @    ",
      "a   h      p    ",
      "aeeeh     0p    ",
      "w#  fBCCCCBfDDDD",
      "    0      p   D",
      "           45  D",
      "           45  D",
      "           45  D",
      "           45  D",
      "           p   D",
      "   0f0     fDDDD",
      "           p    ",
      "           p    ",
      "           @    ",
      "           @    "
    ],
    [
      "a   $%% %% ^%%%%",
      "a   $% %%%%^%%%%",
      "a   $%&%%!%^%!%%",
      "aeee$%%%%%%^%%%%",
      "wwwwf******fDDDD",
      "           ^((((",
      "           ^((((",
      "           ^((((",
      "           ^((((",
      "           ^((((",
      "           ^((((",
      "    f      fDDDD",
      "           ^%%%%",
      "           ^%&%%",
      "           ^%%%%",
      "           ^%%%%"
    ],
    [
      ")   )    +-)    ",
      ")   ) ++  -)++ +",
      ")   ) [  [-) [+ ",
      ")eF])+ ++ {)++ +",
      "}}}}f}}}}}}f}}}}",
      "%%%%)%%%%%%) +  ",
      "%%&%)%\\%%&%)----",
      "%%%%)%%%%%%)+ -+",
      "%%%%)%%%%%%)  --",
      "%%&%)%&%%&%)  -+",
      "%%%%)%%%%%%)++--",
      "}}}}f}}}}}}f}}}}",
      "    )%%%%%%) + +",
      "    )%&%%\\%) [  ",
      "    )%%%%%%) +  ",
      "    )%%%%%%)    "
    ]
  ]
}