{
  "name": "multi_laboratory1_13_base1",
  "refpalette": "c70cities:multi_laboratory1_13_base1_palette",
  "xsize": 16,
  "zsize": 16,
  "slices": [
    [
      "aaaaaaaaaaaaabcv",
      "aaaaaaaaaaaaabcv",
      "aaaadaaaaaaaabcv",
      "eeeaaaaaaaaaabcv",
      "eeeaaaaaaaaaabcv",
      "eeeaaaaaaaaaabcv",
      "eeeaaaaaaaaaabcv",
      "eeeaaaaaaaaaabcv",
      "aaa!aaaaaaaaabcv",
      "aaaadaaaaaaaabcv",
      "aaaaaaaaaaaaabcv",
      "aaaaaaaaaaaaabcv",
      "aaaaaaaaaaaaabcv",
      "aaaaaaaaaaaaabcv",
      "aaaaaaaaaaaaabcv",
      "aaaaaaaaaaaaabcv"
    ],
    [
      "    fghi  ghjbcv",
      "    fgggk gggbcv",
      "lllmdnnnnnnnnbcv",
      "   ln       obcv",
      "   pn  q q  rbcv",
      "  sln  ttt  obcv",
      " ggln  ttt  ubcv",
      " s ln  w w  ubcv",
      "lllmn   x   !bcv",
      "nnnndnnn nnnnbcv",
      "s  yA   B   obcv",
      "    A  C C  obcv",
      "    A  ttt  rbcv",
      "    A       obcv",
      "    A  DDD  rbcv",
      "    A  C    obcv"
    ],
    [
      "    f        bcv",
      "    fEF    FIbcv",
      "   Jdnnnnnnnnbcv",
      "    A       Kbcv",
      "    A        bcv",
      "    A    L   bcv",
      "    A   L    bcv",
      "    A        bcv",
      "   JA E M   Nbcv",
      "OOOndnnn nnnnbcv",
      "    A   P   Qbcv",
      "    A        bcv",
      "    A    R   bcv",
      "    A        bcv",
      "    A   S   Tbcv",
      "    A       Ubcv"
    ],
    [
      "    f        bcv",
      "    f        bcv",
      "   Jdnnnnnnnnbcv",
      "    A        bcv",
      "    A        bcv",
      "    A        bcv",
      "    A        bcv",
      "    A        bcv",
      "   JA        bcv",
      "VVVndnnnnnnnnbcv",
      "    A        bcv",
      "    A       Wbcv",
      "    A       Xbcv",
      "    A        bcv",
      "    A        bcv",
      "    A        bcv"
    ],
    [
      "    f        bcv",
      "    f        bcv",
      "    dnnnnnnnnbcv",
      "    A        bcv",
      "    A        bcv",
      "    A        bcv",
      "    A        bcv",
      "    A        bcv",
      "    A        bcv",
      "YYYndnnnnnnnnbcv",
      "    A        bcv",
      "    A        bcv",
      "    A       Zbcv",
      "    A        bcv",
      "    A        bcv",
      "    A        bcv"
    ],
    [
      "0000102000300bcv",
      "0000100000000bcv",
      "4444dnnnnnnnnbcv",
      "0000100000000bcv",
      "0000102000200bcv",
      "0000102000200bcv",
      "0000102000200bcv",
      "0000102000200bcv",
      "0000100000000bcv",
      "nnnndnnnnnnnnbcv",
      "0000100000000bcv",
      "0000103000200bcv",
      "0000102000200bcv",
      "0000102000200bcv",
      "0000102000200bcv",
      "0000100000000bcv"
    ]
  ]
}