{
  "name": "multi_condo1_4_floor3",
  "refpalette": "c70cities:multi_condo1_4_floor3_palette",
  "xsize": 16,
  "zsize": 16,
  "slices": [
    [
      "aaaaabcddeeefg  ",
      "hhhiabcffffffjj ",
      "   kabclllllfg  ",
      "   kabclllllfg  ",
      "   kabclllllfg  ",
      "   kabclllllfjj ",
      "   kabcffffffg  ",
      "   kabc     cg  ",
      "   kabc     cg  ",
      "   kabc     fg  ",
      "   kabm     fjj ",
      "   kabnffffffg  ",
      "   kabcck   fg  ",
      "   kabcco   fg  ",
      "pppqabcffffffjj ",
      "aaaaabcddeeefg  "
    ],
    [
      "      frrstuf   ",
      "wwww  fffffffjj ",
      "   w  x     f   ",
      "   w  f     y   ",
      "   w  f  AB f   ",
      "   w  f CDD fjj ",
      "   w  fffffff   ",
      "   w  f     E   ",
      "   w  F     E   ",
      "   w  I     f   ",
      "   w  f     fjj ",
      "   w  fffffff   ",
      "   w  f     y   ",
      "   w  J Ko  f   ",
      "wwww  fffffffjj ",
      "      fLLsMNf   "
    ],
    [
      "      fOPs  f   ",
      "      fffffffjj ",
      "      Q     f   ",
      "      fR    S   ",
      "      f  TU f   ",
      "      fVVDD fjj ",
      "      fffffff   ",
      "      f     E   ",
      "      W     E   ",
      "      X     f   ",
      "      f     fjj ",
      "      fffffff   ",
      "      f     S   ",
      "      Y  Ko f   ",
      "      fffffffjj ",
      "      fZ0s  f   "
    ],
    [
      "      f  s  f   ",
      "      fffffffjj ",
      "      1     f   ",
      "      f     S   ",
      "      f     f   ",
      "      fV 22 fjj ",
      "      fffffff   ",
      "      f     E   ",
      "      1     E   ",
      "      1     f   ",
      "      f     fjj ",
      "      fffffff   ",
      "      f   1oS   ",
      "      1   Kcf   ",
      "      fffffffjj ",
      "      f !s  f   "
    ],
    [
      "      f  s  f   ",
      "      fffffffjj ",
      "      f     f   ",
      "      f     f   ",
      "      f     f   ",
      "      fV    fjj ",
      "      fffffff   ",
      "      f     E   ",
      "      f     E   ",
      "      f     f   ",
      "      f     fjj ",
      "      fffffff   ",
      "      f  1k f   ",
      "      f     f   ",
      "      fffffffjj ",
      "      f  s  f   "
    ],
    [
      "      flllllf   ",
      "      fffffffjj ",
      "      fV    f   ",
      "      fV    f   ",
      "      fV    f   ",
      "      fVVVVVfjj ",
      "      fffffff   ",
      "      f     E   ",
      "      f     E   ",
      "      f     f   ",
      "      f     fjj ",
      "      fffffff   ",
      "      f 1k  f   ",
      "      f     f   ",
      "      fffffffjj ",
      "      flllllf   "
    ]
  ]
}