{
  "name": "multi_megatower1_0_base1",
  "refpalette": "c70cities:multi_megatower1_0_base1_palette",
  "xsize": 16,
  "zsize": 16,
  "slices": [
    [
      "vvvvvvvvvvvvvvvv",
      "vaaaaaaaaaaaaaaa",
      "vaaaaaaaaaaaaaaa",
      "vaavvvvvvvvvvvvv",
      "vaavvvvvvvvvvvvv",
      "vaavvHHHHHHHHHHH",
      "vaavvHbHHHHHHbHH",
      "vaavvHHHHHHHHHHH",
      "vaavvHHHHHHHHHHH",
      "vaavvHHHHHHHHHHH",
      "vaavvHHHHHHHHHHH",
      "vaavvHHHHHHHHHHH",
      "vaavvHHHHHHHHHHH",
      "vaavvHbHHHHHHbvv",
      "vaavvHHHHHHHHv  ",
      "vaavvHHHHHHHHv  "
    ],
    [
      "vvvvvvvvvvvvvvvv",
      "vaaaaaaaaaaaaaaa",
      "vaaaaaaaaaaaaaaa",
      "vaavvvvvvvvvvvvv",
      "vaavcccccccccccc",
      "vaavc   defef ef",
      "vaavc b d    b  ",
      "vaavc   dghghigh",
      "vaavcjjj        ",
      "vaavce f        ",
      "vaavcg h        ",
      "vaavce f        ",
      "vaavcg h     k  ",
      "vaavc bl    mbnn",
      "vaavce f     o  ",
      "vaavcg h     o  "
    ],
    [
      "vvvvvvvvvvvvvvvv",
      "vaaaaaaaaaaaaaaa",
      "vaaaaaaaaaaaaaaa",
      "vaavvvvvvvvvvvvv",
      "vaav            ",
      "vaav            ",
      "vaav  b      b  ",
      "vaav            ",
      "vaav            ",
      "vaav            ",
      "vaav            ",
      "vaav            ",
      "vaav            ",
      "vaav  b      bnn",
      "vaav         opp",
      "vaav         opq"
    ],
    [
      "vvvvvvvvvvvvvvvv",
      "vaaaaaaaaaaaaaaa",
      "vaaaaaaaaaaaaaaa",
      "vaavvvvvvvvvvvvv",
      "vaav            ",
      "vaav            ",
      "vaav  b      b  ",
      "vaav            ",
      "vaav            ",
      "vaav            ",
      "vaav            ",
      "vaav            ",
      "vaav            ",
      "vaav  b      bnn",
      "vaav         opp",
      "vaav         opp"
    ],
    [
      "vvvvvvvvvvvvvvvv",
      "vaaaaaaaaaaaaaaa",
      "vaaaaaaaaaaaaaaa",
      "vaavvvvvvvvvvvvv",
      "vaav            ",
      "vaav         !  ",
      "vaav  b      b  ",
      "vaav            ",
      "vaav            ",
      "vaav            ",
      "vaav            ",
      "vaav            ",
      "vaav            ",
      "vaav  b      bnn",
      "vaav         r  ",
      "vaav         r  "
    ],
    [
      "vvvvvvvvvvvvvvvv",
      "vaaaaaaaaaaaaaaa",
      "vaaaaaaaaaaaaaaa",
      "vaavvvvvvvvvvvvv",
      "vaavvvvvvvvvvvvv",
      "vaavvsssssssssss",
      "vaavvsbbbbbbbbbb",
      "vaavvsbssssssbss",
      "vaavvsbssssssbss",
      "vaavvsbssssssbss",
      "vaavvsbssssssbss",
      "vaavvsbssssssbss",
      "vaavvsbssssssbss",
      "vaavvsbbbbbbbbbb",
      "vaavvsbssssssb  ",
      "vaavvsbssssssb  "
    ]
  ]
}