{
  "name": "multi_militarybase_5_base4",
  "refpalette": "c70cities:multi_militarybase_5_base4_palette",
  "xsize": 16,
  "zsize": 16,
  "slices": [
    [
      "abccccccccccccvv",
      "abccccccccccccvv",
      "bvbbbbbbbbbbbvvv",
      "zvvvvvvvvvvvvvvv",
      "zzzzzzzzzzzzzzvv",
      "zzzzzzzzzzzzzzvv",
      "zzzzzzzzzzzzzzvv",
      "zzzzzzzzzzzzzzvv",
      "zzzzzzzzzzzzzzvv",
      "zzzzzzzzzzzzzzvv",
      "zzzzzzzzzzzzzzvv",
      "zzzzzzzzzzzzzzvv",
      "zzzzzzzzzzzzzzvv",
      "zzzzzzzzzzzzzzvv",
      "zzzzzzzzzzzzzzvv",
      "vvvvvvvvvvvvvvvv"
    ],
    [
      "              vv",
      "d             vv",
      "ev fggh fggh vvv",
      "zvvvvvvvvvvvvvvv",
      "zzzzzzzzzzzzzzvv",
      "zzzzzzzzzzzzzzvv",
      "zzzzzzzzzzzzzzvv",
      "zzzzzzzzzzzzzzvv",
      "zzzzzzzzzzzzzzvv",
      "zzzzzzzzzzzzzzvv",
      "zzzzzzzzzzzzzzvv",
      "zzzzzzzzzzzzzzvv",
      "zzzzzzzzzzzzzzvv",
      "zzzzzzzzzzzzzzvv",
      "zzzzzzzzzzzzzzvv",
      "vvvvvvvvvvvvvvvv"
    ],
    [
      "             ivv",
      "              vv",
      "ev           vvv",
      "zvvvvvvvvvvvvvvv",
      "zzzzzzzzzzzzzzvv",
      "zzzzzzzzzzzzzzvv",
      "zzzzzzzzzzzzzzvv",
      "zzzzzzzzzzzzzzvv",
      "zzzzzzzzzzzzzzvv",
      "zzzzzzzzzzzzzzvv",
      "zzzzzzzzzzzzzzvv",
      "zzzzzzzzzzzzzzvv",
      "zzzzzzzzzzzzzzvv",
      "zzzzzzzzzzzzzzvv",
      "zzzzzzzzzzzzzzvv",
      "vvvvvvvvvvvvvvvv"
    ],
    [
      "             !vv",
      "              vv",
      "ev           vvv",
      "zvvvvvvvvvvvvvvv",
      "zzzzzzzzzzzzzzvv",
      "zzzzzzzzzzzzzzvv",
      "zzzzzzzzzzzzzzvv",
      "zzzzzzzzzzzzzzvv",
      "zzzzzzzzzzzzzzvv",
      "zzzzzzzzzzzzzzvv",
      "zzzzzzzzzzzzzzvv",
      "zzzzzzzzzzzzzzvv",
      "zzzzzzzzzzzzzzvv",
      "zzzzzzzzzzzzzzvv",
      "zzzzzzzzzzzzzzvv",
      "vvvvvvvvvvvvvvvv"
    ],
    [
      "              vv",
      "              vv",
      "ev           vvv",
      "zvvvvvvvvvvvvvvv",
      "zzzzzzzzzzzzzzvv",
      "zzzzzzzzzzzzzzvv",
      "zzzzzzzzzzzzzzvv",
      "zzzzzzzzzzzzzzvv",
      "zzzzzzzzzzzzzzvv",
      "zzzzzzzzzzzzzzvv",
      "zzzzzzzzzzzzzzvv",
      "zzzzzzzzzzzzzzvv",
      "zzzzzzzzzzzzzzvv",
      "zzzzzzzzzzzzzzvv",
      "zzzzzzzzzzzzzzvv",
      "vvvvvvvvvvvvvvvv"
    ],
    [
      "jkllllllllllllvv",
      "mkllllllllllllvv",
      "bvbbbbbbbbbbbvvv",
      "zvvvvvvvvvvvvvvv",
      "zzzzzzzzzzzzzzvv",
      "zzzzzzzzzzzzzzvv",
      "zzzzzzzzzzzzzzvv",
      "zzzzzzzzzzzzzzvv",
      "zzzzzzzzzzzzzzvv",
      "zzzzzzzzzzzzzzvv",
      "zzzzzzzzzzzzzzvv",
      "zzzzzzzzzzzzzzvv",
      "zzzzzzzzzzzzzzvv",
      "zzzzzzzzzzzzzzvv",
      "zzzzzzzzzzzzzzvv",
      "vvvvvvvvvvvvvvvv"
    ]
  ]
}