{
  "name": "multi_hospital_1_base2",
  "refpalette": "c70cities:multi_hospital_1_base2_palette",
  "xsize": 16,
  "zsize": 16,
  "slices": [
    [
      "vvvvvvvvvvvvvvvv",
      "vvvvvvvvvvvvvvvv",
      "vvvvvvvvvvvvvvvv",
      "vvvvvvvvvvvvvvvv",
      "vvvvvvvvvvvvvvvv",
      "vvvvvvvvvvvvvvvv",
      "vvvvvvvvvvvvvvvv",
      "vvvvvvvvvvvvvvvv",
      "vvvvvvvvvvvvvvvv",
      "vvvvvvvvvvvvvvvv",
      "vvvvvvvvvvvvvvvv",
      "vvvvvvvvvvvvvvvv",
      "vvvvvvvvvvvvvvvv",
      "vvvvvvvvvvvvvvvv",
      "vvvvvvvvvvvvvvvv",
      "vvvvvvvvvvvvvvvv"
    ],
    [
      "vaaaaaaaabcccccc",
      "vaaaaaaaabcccccc",
      "vaaaaaaaabcccccc",
      "vaaaaaaaabcccccc",
      "vaaaaaaaabcccccc",
      "vaaaaaaaabcccccc",
      "vaaaaaaaabcccccc",
      "vaaaaaaaabcccccc",
      "vaaaaaaaabcccccc",
      "vaaaaaaaabcccccc",
      "vaaaaaaaabbbbbbb",
      "vaaaaaaaaaaaaaaa",
      "vaaaaaaaaaaaaaaa",
      "vaaaaaaaaaaaaaaa",
      "vaaaaaaaaaaaaaaa",
      "vvvvvvvvvvvvvvvv"
    ],
    [
      "vaaaaaaaabd  ed ",
      "vaaaaaaaab      ",
      "vaaaaaaaabdf  d ",
      "vaaaaaaaabd  ed ",
      "vaaaaaaaabg     ",
      "vaaaaaaaabdf  d ",
      "vaaaaaaaabd  ed ",
      "vaaaaaaaab      ",
      "vaaaaaaaabhihih ",
      "vaaaaaaaabj   k ",
      "vaaaaaaaabbbbbbb",
      "vaaaaaaaaaaaaaaa",
      "vaaaaaaaaaaaaaaa",
      "vaaaaaaaaaaaaaaa",
      "vaaaaaaaaaaaaaaa",
      "vvvvvvvvvvvvvvvv"
    ],
    [
      "vaaaaaaaabl   m ",
      "vaaaaaaaabn     ",
      "vaaaaaaaab    o ",
      "vaaaaaaaabp   p ",
      "vaaaaaaaabn     ",
      "vaaaaaaaab      ",
      "vaaaaaaaabp   m ",
      "vaaaaaaaabn     ",
      "vaaaaaaaabhihih ",
      "vaaaaaaaab   k  ",
      "vaaaaaaaabbbbbbb",
      "vaaaaaaaaaaaaaaa",
      "vaaaaaaaaaaaaaaa",
      "vaaaaaaaaaaaaaaa",
      "vaaaaaaaaaaaaaaa",
      "vvvvvvvvvvvvvvvv"
    ],
    [
      "vaaaaaaaab      ",
      "vaaaaaaaab      ",
      "vaaaaaaaab      ",
      "vaaaaaaaab      ",
      "vaaaaaaaab      ",
      "vaaaaaaaab      ",
      "vaaaaaaaab      ",
      "vaaaaaaaab      ",
      "vaaaaaaaabhihih ",
      "vaaaaaaaab  k   ",
      "vaaaaaaaabbbbbbb",
      "vaaaaaaaaaaaaaaa",
      "vaaaaaaaaaaaaaaa",
      "vaaaaaaaaaaaaaaa",
      "vaaaaaaaaaaaaaaa",
      "vvvvvvvvvvvvvvvv"
    ],
    [
      "vaaaaaaaabqqqqqq",
      "vaaaaaaaabqqqqqq",
      "vaaaaaaaabqqqqqq",
      "vaaaaaaaabqqqqqq",
      "vaaaaaaaabqqqqqq",
      "vaaaaaaaabqqqqqq",
      "vaaaaaaaabqqqqqq",
      "vaaaaaaaabqqqqqq",
      "vaaaaaaaabhihih ",
      "vaaaaaaaab k    ",
      "vaaaaaaaabbbbbbb",
      "vaaaaaaaaaaaaaaa",
      "vaaaaaaaaaaaaaaa",
      "vaaaaaaaaaaaaaaa",
      "vaaaaaaaaaaaaaaa",
      "vvvvvvvvvvvvvvvv"
    ]
  ]
}