{
  "name": "multi_condo1_2_floor7",
  "refpalette": "c70cities:multi_condo1_2_floor7_palette",
  "xsize": 16,
  "zsize": 16,
  "slices": [
    [
      "   abccccccccccc",
      "   abddddddddddd",
      " eeebfffffd     ",
      "    bfffffd     ",
      "    bfffffd     ",
      "  ggbfffffd     ",
      "    bfffffd     ",
      "    hfffffd     ",
      "    hfffffd     ",
      "    hfffffd     ",
      "    hfffffd     ",
      "    hhhhhbbb    ",
      "          b     ",
      "                ",
      "                ",
      "                "
    ],
    [
      "    i           ",
      "    b           ",
      " eeeb           ",
      "    b           ",
      "    b           ",
      "  ggb           ",
      "   jb           ",
      "   jb           ",
      "   jb           ",
      "   jb           ",
      "   jb           ",
      "   jbbbbbbbb    ",
      "   jjjjjjjb     ",
      "                ",
      "                ",
      "                "
    ],
    [
      "    h           ",
      "    b           ",
      " eeeb           ",
      "    b           ",
      "    b           ",
      "  ggb           ",
      "    b           ",
      "    b           ",
      "    b           ",
      "    b           ",
      "    b           ",
      "    bbbbbbbb    ",
      "          b     ",
      "                ",
      "                ",
      "                "
    ],
    [
      "    h           ",
      "    b           ",
      " eeeb           ",
      "    b           ",
      "    b           ",
      "  ggb           ",
      "  ggb           ",
      "  ggb           ",
      "  ggb           ",
      "  ggb           ",
      "  ggb           ",
      "  ggbbbbbbbbbbbb",
      "  gggggggggggggg",
      "  gggggggggggggg",
      "                ",
      "                "
    ],
    [
      "    b           ",
      "    b           ",
      " eeeb           ",
      "    b           ",
      "    b           ",
      "    b           ",
      "    b           ",
      "    b           ",
      "    b           ",
      "    b           ",
      "    b           ",
      "    bbbbbbbbbbbb",
      "                ",
      "                ",
      "                ",
      "                "
    ],
    [
      "    b           ",
      "    b           ",
      " eeeb           ",
      "   kb           ",
      "   kb           ",
      "   kb           ",
      "   kb           ",
      "   kb           ",
      "   kb           ",
      "   kb           ",
      "   kb           ",
      "   kbbbbbbbbbbbb",
      "   kkkkkkkkkkkkk",
      "                ",
      "                ",
      "                "
    ]
  ]
}