{
  "name": "multi_convenientstore_0_ground",
  "refpalette": "c70cities:multi_convenientstore_0_ground_palette",
  "xsize": 16,
  "zsize": 16,
  "slices": [
    [
      "GGGHHHaGGGGGGGGG",
      "GGGHHHaGGGGGGGGG",
      "GGHHHHaaaaaaaaaa",
      "GGHHHHHHHHHHHHHH",
      "GGHHHHHHHHHHHHHH",
      "GGHHHHHHHHHHHHHH",
      "GGHHHHHHHHHHHHHH",
      "GGHHHHHHHHHHHHHH",
      "GGHHHHHHHHHHHHHH",
      "GGHHHHHHHHHHHHHH",
      "GGHHHHHHHHHHHHHH",
      "GGHHHHHHHHHHHHHH",
      "GGHHHHHHHHHHHHHH",
      "GGHHHHHHHHHHHHHH",
      "GGHHHHHHHHHHHHHH",
      "GGHHHHHHHHHHHHHH"
    ],
    [
      "      b         ",
      " c    b         ",
      "      bbbbb bbbb",
      "       dedededed",
      "    f           ",
      "       ghghghghg",
      "c    i          ",
      "        ~ f     ",
      "    j           ",
      "                ",
      "       dedededed",
      " c      k       ",
      "    i  ghghghghg",
      "     bbbbbbbbbbb",
      "     baaaaaaaaaa",
      "     baaaaaaaaaa"
    ],
    [
      "                ",
      " ~              ",
      "                ",
      "                ",
      "                ",
      "                ",
      "~               ",
      "        ~       ",
      "                ",
      "                ",
      "                ",
      " ~              ",
      "                ",
      "                ",
      "                ",
      "         l  l m "
    ],
    [
      "                ",
      "                ",
      "                ",
      "                ",
      "                ",
      "                ",
      "                ",
      "        ~       ",
      "                ",
      "                ",
      "                ",
      "                ",
      "                ",
      "                ",
      "                ",
      "              m "
    ],
    [
      "                ",
      "                ",
      "                ",
      "                ",
      "                ",
      "                ",
      "                ",
      "        ~       ",
      "                ",
      "                ",
      "                ",
      "                ",
      "                ",
      "                ",
      "                ",
      "              no"
    ],
    [
      "                ",
      "                ",
      "                ",
      "                ",
      "                ",
      "                ",
      "                ",
      "        ~       ",
      "                ",
      "                ",
      "                ",
      "                ",
      "                ",
      "                ",
      "                ",
      "                "
    ]
  ]
}