{
  "name": "multi_laboratory1_1_base5",
  "refpalette": "c70cities:multi_laboratory1_1_base5_palette",
  "xsize": 16,
  "zsize": 16,
  "slices": [
    [
      "vab             ",
      "vac             ",
      "vacb            ",
      "vac             ",
      "vac             ",
      "vadde           ",
      "vacfge     hi   ",
      "vadde           ",
      "vacj            ",
      "vacb            ",
      "vac             ",
      "vac             ",
      "vadde          e",
      "vacfge     hk  e",
      "vadde         el",
      "vac           e "
    ],
    [
      "vab             ",
      "vac             ",
      "vabb            ",
      "vab             ",
      "vab             ",
      "vadde           ",
      "vacfge     h    ",
      "vadde           ",
      "vacb            ",
      "vacb            ",
      "vac             ",
      "vac             ",
      "vadde          e",
      "vacfge     h   e",
      "vadde         el",
      "vac           e "
    ],
    [
      "vab             ",
      "vac             ",
      "vacb            ",
      "vac             ",
      "vac             ",
      "vadde           ",
      "vacfge     h    ",
      "vadde           ",
      "vac             ",
      "vabb            ",
      "vab             ",
      "vab             ",
      "vadde          e",
      "vacfge     h   e",
      "vadde         el",
      "vacb          e "
    ],
    [
      "vab             ",
      "vac             ",
      "vacb            ",
      "vacj            ",
      "vac             ",
      "vadde           ",
      "vacfge     h    ",
      "vadde           ",
      "vac             ",
      "vacb            ",
      "vacj            ",
      "vac             ",
      "vadde          e",
      "vacfge     h   e",
      "vadde         el",
      "vac           e "
    ],
    [
      "vab             ",
      "vac             ",
      "vacb            ",
      "vacj            ",
      "vacj            ",
      "vadde           ",
      "vacfge     h    ",
      "vadde           ",
      "vacj            ",
      "vacb            ",
      "vacj            ",
      "vac             ",
      "vadde          e",
      "vacfge     h   e",
      "vadde         el",
      "vac           e "
    ],
    [
      "vabbmmmmmmmmmmmm",
      "vacbmmmmmmmmmmmm",
      "vacnmmmmmmmmmmmm",
      "vacbmmmmmmmmmmmm",
      "vacbmmmmmmmmmmmm",
      "vaddddmmmmmmmmmm",
      "vacfodmmmmmhmmmm",
      "vaddddmmmmmmmmmm",
      "vacbmmmmmmmmmmmm",
      "vacnmmmmmmmmmmmm",
      "vacbmmmmmmmmmmmm",
      "vacbmmmmmmmmmmmm",
      "vaddddmmmmmmmmme",
      "vacfodmmmmmhmmme",
      "vaddddmmmmmmmmel",
      "vacbmmmmmmmmmme "
    ]
  ]
}