{
  "name": "multi_laboratory1_4_base4",
  "refpalette": "c70cities:multi_laboratory1_4_base4_palette",
  "xsize": 16,
  "zsize": 16,
  "slices": [
    [
      "vaabbbbbbbbcbbbb",
      "vaabbbbbbbbbbbbb",
      "vaabbbbbbbbbbbbb",
      "vaabbbbbbbbbbbbb",
      "vaabbbbbbbbbbbbb",
      "vaabbbbbbbbbbbbb",
      "vaabbbbbbbbbbbbb",
      "vaabbbbbbbbcbbbb",
      "vaaddddddddbbbbb",
      "vaaddddddddbbbbb",
      "vaaddddddddbbbbb",
      "vaaddddddddbbbbb",
      "vaaddddddddbbb!b",
      "vaaaaaaaaaaaaaaa",
      "vaaaaaaaaaaaeeee",
      "vvvvvvvvvvvvvvvv"
    ],
    [
      "vaaffffffffc   g",
      "vaah ij  klf   g",
      "vaam    knof   p",
      "vaaq rr  kof  ss",
      "vaaq rr t  f    ",
      "vaau       w    ",
      "vaah xy    f    ",
      "vaaffffffffc    ",
      "vaaAABBBBAAf    ",
      "vaa        C    ",
      "vaaDEDEFEDEf    ",
      "vaa I I I If    ",
      "vaaJIJIJIJIfKLL ",
      "vaaaaaaaaaaaaaaa",
      "vaaaaaaaaaaaeeee",
      "vvvvvvvvvvvvvvvv"
    ],
    [
      "vaaffffffffc    ",
      "vaaM       f    ",
      "vaa        f    ",
      "vaa        f   N",
      "vaa        f    ",
      "vaa        O    ",
      "vaaM       f    ",
      "vaaffffffffc    ",
      "vaaMPPPPPPMf    ",
      "vaa        Q    ",
      "vaaRERESEREf    ",
      "vaa I I I If    ",
      "vaa I I I If    ",
      "vaaaaaaaaaaaaaaa",
      "vaaaaaaaaaaaeeee",
      "vvvvvvvvvvvvvvvv"
    ],
    [
      "vaaffffffffc    ",
      "vaaM       f    ",
      "vaa        fT   ",
      "vaa        fT   ",
      "vaa        f    ",
      "vaa        U    ",
      "vaaM       f    ",
      "vaaffffffffc    ",
      "vaa PPPPPP f    ",
      "vaa        f    ",
      "vaaEEEEEEEEf    ",
      "vaa I I I If    ",
      "vaa I I I If    ",
      "vaaaaaaaaaaaaaaa",
      "vaaaaaaaaaaaeeee",
      "vvvvvvvvvvvvvvvv"
    ],
    [
      "vaaffffffffc    ",
      "vaa        f    ",
      "vaa        f    ",
      "vaa        f    ",
      "vaa        f    ",
      "vaa        f    ",
      "vaa        f    ",
      "vaaffffffffc    ",
      "vaaVVVVVVVVf    ",
      "vaaVVVVVVVVf    ",
      "vaaVVVVVVVVf    ",
      "vaaVVVVVVVVf    ",
      "vaaWV!VWVWVf    ",
      "vaaaaaaaaaaaaaaa",
      "vaaaaaaaaaaaeeee",
      "vvvvvvvvvvvvvvvv"
    ],
    [
      "veaffffffffcXXYX",
      "veaZZZZZZZZUXXYX",
      "veaZ0ZZZZ1ZUXX2X",
      "veaZZZZZZZZUXX22",
      "veaZZZZZZZZUXXXX",
      "veaZ3ZZZZ3ZUXXXX",
      "veaZZZZZZZZUXXXX",
      "veaffffffffcffff",
      "vea44444444f5555",
      "vea4 4 4 4 f5Y55",
      "vea4 4 4 4 f5Y55",
      "vea4 4 4 4 f5255",
      "vea4 4 4 4 f5555",
      "veaaaaaaaaaaaaaa",
      "veeeeeeeeeeeeeee",
      "vvvvvvvvvvvvvvvv"
    ]
  ]
}