{
  "name": "multi_militarybase_2_base2",
  "refpalette": "c70cities:multi_militarybase_2_base2_palette",
  "xsize": 16,
  "zsize": 16,
  "slices": [
    [
      "vvvvvvvvvvvvvvvv",
      "aaaaaaavaaaaaaaa",
      "aaaaaaabaaaaaaaa",
      "aaaaaaabaaaaaaaa",
      "aaaaaaabaaaaaaaa",
      "bbbbbbbvbbbbbbbb",
      "aaaaaaabaaaaaaaa",
      "aaaaaaabaaaaaaaa",
      "aaaaaaabaaaaaaaa",
      "cccccccvcccccccd",
      "eeeeeeebeeeeeeee",
      "eeeeeeebeeeeeeee",
      "eeeeeeebeeeeeeee",
      "bbvbbbbvbbbbvbbb",
      "  f    f    f   ",
      "                "
    ],
    [
      "vvvvvvvvvvvvvvvv",
      " g g g v g g g g",
      " h h h   h h h h",
      " i i i   i i i i",
      "                ",
      "jjkjjjjvjjjljjjj",
      "                ",
      "                ",
      "mnonmn   nmmonnn",
      "ppppppjvjppppppp",
      "                ",
      "                ",
      "                ",
      "qqvqqqqvqqqqvqqq",
      "                ",
      "                "
    ],
    [
      "vvvvvvvvvvvvvvvv",
      " g g g v g g g g",
      " h h h   h h h h",
      " r r r   r r r r",
      "                ",
      "jjsjjjjvjjjtjjjj",
      "                ",
      "                ",
      "u w x     yAw   ",
      "ppBppCjvjDpE!ppF",
      "                ",
      "                ",
      "                ",
      "  v    v    v   ",
      "                ",
      "                "
    ],
    [
      "vvvvvvvvvvvvvvvv",
      "       v        ",
      "                ",
      "                ",
      "                ",
      "jjjjjjjvjjjjjjjj",
      "                ",
      "                ",
      "                ",
      "jjjjjjjvjjjjjjjj",
      "                ",
      "                ",
      "                ",
      "  v    v    v   ",
      "                ",
      "                "
    ],
    [
      "vvvvvvvvvvvvvvvv",
      "       v        ",
      "                ",
      "                ",
      "                ",
      "jjjjjjjvjjjjjjjj",
      "       q        ",
      "       q        ",
      "       q        ",
      "qqqqqqqvqqqqqqqq",
      "                ",
      "                ",
      "                ",
      "IIvIIIIvIIIIvIII",
      "                ",
      "                "
    ],
    [
      "vvvvvvvvvvvvvvvv",
      "JJ!JJJJvJJJJJJJJ",
      "KKKKKKKbKKKKKKKK",
      "KKKKKKKbKKKKKKKK",
      "KKKKKKKbKKKKKKKK",
      "bbbbbbbvbbbbbbbb",
      "KKKKKKKbKKKKKKKK",
      "KKKKKKKbKKKKKKKK",
      "KKKKKKKbKKKKKKKK",
      "KKKKKKKvKKKKKKKK",
      "KKKKKKKbKKKKKKKK",
      "KKKKKKKbKKKKKKKK",
      "KKKKKKKbKKKKKKKK",
      "LLvLLLLvLLLLvLLL",
      "                ",
      "                "
    ]
  ]
}