{
  "name": "multi_condo1_5_floor1",
  "refpalette": "c70cities:multi_condo1_5_floor1_palette",
  "xsize": 16,
  "zsize": 16,
  "slices": [
    [
      "aaaaabccccccde  ",
      "ffffffffffffde  ",
      "ggggggggggggdhhh",
      "ggggggggggggdf  ",
      "ggggggggggggdf  ",
      "ggggggggggggdf  ",
      "ggggggggggggdf  ",
      "ggggggggggggdf  ",
      "ggggggggggggdf  ",
      "ggggggggggggdf  ",
      "ggggggggggggdf  ",
      "iiiiiiiiiiiijf  ",
      "kkkkkkhfffffff  ",
      "      h         ",
      "      h         ",
      "                "
    ],
    [
      "        llllm   ",
      "            m   ",
      "        nnn mohh",
      "       pqqqrmshh",
      "       pqqqrmshh",
      "       pqqqrmshh",
      "            mshh",
      "       pqqqrmshh",
      "       pq!qrmshh",
      "       pqqqrmshh",
      "        ttt mshh",
      "mmmmmmmmmmmmmshh",
      "      ussssssshh",
      "      hhhhhhhhhh",
      "      hhhhhhhhhh",
      "                "
    ],
    [
      "            m   ",
      "            m   ",
      "            m   ",
      "        w w m   ",
      "       x y  m   ",
      "        w w m   ",
      "        ~   m   ",
      "        w w m   ",
      "       x y  m   ",
      "        w w m   ",
      "            m   ",
      "mmmmmmmmmmmmm   ",
      "                ",
      "                ",
      "                ",
      "                "
    ],
    [
      "                ",
      "                ",
      "                ",
      "        yyy     ",
      "       Ay y     ",
      "        yyy     ",
      "        ~       ",
      "        yyy     ",
      "       Ay y     ",
      "        yyy     ",
      "                ",
      "            B   ",
      "                ",
      "                ",
      "                ",
      "                "
    ],
    [
      "                ",
      "                ",
      "                ",
      "        yyy     ",
      "        y y     ",
      "        yyy     ",
      "        ~       ",
      "        yyy     ",
      "        y y     ",
      "        yyy     ",
      "                ",
      "            C   ",
      "                ",
      "                ",
      "                ",
      "                "
    ],
    [
      "                ",
      "                ",
      "                ",
      "        yyy     ",
      "        y y     ",
      "        yyy     ",
      "        ~       ",
      "        yyy     ",
      "        y y     ",
      "        yyy     ",
      "                ",
      "                ",
      "                ",
      "                ",
      "                ",
      "                "
    ]
  ]
}