{
  "name": "multi_hospital_3_ground",
  "refpalette": "c70cities:multi_hospital_3_ground_palette",
  "xsize": 16,
  "zsize": 16,
  "slices": [
    [
      "aaaaaaaaaaaaaabG",
      "aaaaaaaaaaaaaabG",
      "acaaaaaaaaaaaabG",
      "dbGGGGGGGGGGGGGG",
      "GGGGGGGGGGGGGGGG",
      "eeeeeeeeeeeeGGGG",
      "eeeeeeeeeeeeeGGG",
      "eeeeeeeeeeeeeeGG",
      "eeeeeeeeeeeeeeGG",
      "GGGGGGGGGeeeeeGG",
      "fcGGGGGGGGeeeeGG",
      "ggGGGGGGGGeeeeGG",
      "hgGGGGGGGGeeeeGG",
      "hgGGGGGGGGeeeeGG",
      "ggGGGGGGGGeeeeGG",
      "GGGGGGGGGGeeeeGG"
    ],
    [
      "            iGj ",
      "    k  k  k iGjl",
      "mcnnonnonnonnoj ",
      "pbpppppppppppppl",
      "   l   ll   llll",
      "                ",
      "             l l",
      "                ",
      "              ll",
      "l l l  l        ",
      "qrl l lll      l",
      "   ssssssl      ",
      "   stulws       ",
      "  lsuwtlsl    l ",
      "   ssssssl     l",
      "ll  ll  l     l "
    ],
    [
      "             xy ",
      "             Ay ",
      "mcBBBBBBBBBBBBy ",
      "pb              ",
      "                ",
      "                ",
      "                ",
      "                ",
      "                ",
      "                ",
      " r              ",
      "                ",
      "    CD E        ",
      "    DEC         ",
      "                ",
      "                "
    ],
    [
      "              y ",
      "             Fy ",
      "mcBBBBBBBBBBBBy ",
      "pb              ",
      "                ",
      "                ",
      "                ",
      "                ",
      "                ",
      "                ",
      " r              ",
      "                ",
      "                ",
      "                ",
      "                ",
      "                "
    ],
    [
      "              y ",
      "              y ",
      "mcBBBBBBBBBBBBy ",
      "pb              ",
      "                ",
      "                ",
      "                ",
      "                ",
      "                ",
      "                ",
      " r              ",
      "                ",
      "                ",
      "                ",
      "                ",
      "                "
    ],
    [
      "              y ",
      "              y ",
      "mcBBBBBBBBBBBBy ",
      "pb              ",
      "                ",
      "                ",
      "                ",
      "                ",
      "                ",
      "                ",
      " r              ",
      "                ",
      "                ",
      "                ",
      "                ",
      "                "
    ]
  ]
}