{
  "name": "multi_communitycenter_5_ground",
  "refpalette": "c70cities:multi_communitycenter_5_ground_palette",
  "xsize": 16,
  "zsize": 16,
  "slices": [
    [
      "aabcccbaaaaaaaab",
      "aaabbbbaaaGGaaab",
      "aaaaaaaaaGGGGaab",
      "aaaaaaaaaGGGGaad",
      "baaaaaaaaaGGaaad",
      "ebbaaaaaaaaaaaaa",
      "eeebbbaaaaaaaaaa",
      "eeeeebbbbbbbbbbf",
      "eeeeeagggggggggf",
      "eeeeeagggggggggf",
      "eeeeeagggggggggf",
      "aaeeeagggggggggf",
      "haaaaagggggggggf",
      "hhhhaaaaaaaaaaaf",
      "hhhhhhhhhhhhhhhh",
      "hhhhhhhhhhhhhhhh"
    ],
    [
      "  ijkjl        l",
      "   imnn   oo   n",
      "         oppo  n",
      "         oppo   ",
      "          oo    ",
      "               q",
      "   lnn          ",
      " r   nls sttssln",
      " r  rnuw  xx xxn",
      " r  rnyA       n",
      "    nnBB  xx xxn",
      "CC  Dn E       n",
      " CCCCn F  xx xxn",
      "    CCCCCCCCCCCC",
      "                ",
      "                "
    ],
    [
      "  i   l        l",
      "   imnn        n",
      "          II   n",
      "          II    ",
      "                ",
      "                ",
      "   lnn          ",
      " J   nls sttssln",
      " J  KnLL   L MNn",
      " J  Kn L       n",
      "    JnBB  O  PQn",
      "ss   nRS       n",
      " CCssnRF  TN QUn",
      "    sssCCsssCCss",
      "                ",
      "                "
    ],
    [
      "  i   l V    V l",
      "   imnn        n",
      "               n",
      "                ",
      "                ",
      "                ",
      "   lnn          ",
      " W  Xnls sttssln",
      " W  Yn         n",
      " W  Wn         n",
      "    ZnBB       n",
      "ss   n F       n",
      " CCssn F       n",
      "    sssCCsssCCss",
      "                ",
      "                "
    ],
    [
      "  l   l 0V  V0 l",
      "   lmnn        n",
      "               n",
      "                ",
      "l               ",
      " ll             ",
      "   lnn          ",
      "    Xnllllllllln",
      "    Xn         n",
      "     n         n",
      "     n         n",
      "CC   n         n",
      " CCCCn         n",
      "    CCCCCCCCCCCC",
      "                ",
      "                "
    ],
    [
      "  nn11n200 V002n",
      "   nnnn22222222n",
      "      nnnnnnnnnn",
      "      3        3",
      "n     3        3",
      "nnn   3        3",
      "11nnnn3        3",
      "11111nnnnnnnnnnn",
      "11111n111111111n",
      "11111n111111111n",
      "11111n111111111n",
      "CC111n111111111n",
      " CCCCn111111111n",
      "    CCCCCCCCCCCC",
      "                ",
      "                "
    ]
  ]
}