{
  "name": "multi_laboratory1_13_base3",
  "refpalette": "c70cities:multi_laboratory1_13_base3_palette",
  "xsize": 16,
  "zsize": 16,
  "slices": [
    [
      "aaaaaaaaaaaaabcv",
      "aaaaaaaaaaaaabcv",
      "aaaadaaaaaaaabcv",
      "aaaaaaaaaaaaabcv",
      "aaaaaaaaaaaaabcv",
      "aaaaaaaaaaaaabcv",
      "aaaaaaaaaaaaabcv",
      "aaaaaaaaaaaaabcv",
      "aaaaaaaaaaaaabcv",
      "aaaadaaaaaaaabcv",
      "aaaaaaaaaaaaabcv",
      "aaaaaaaaaaaaabcv",
      "aaaaaaaaaaaaabcv",
      "aaaaaaaaaaaaabcv",
      "aaaaaaaaaaaaabcv",
      "aaaaaaaaaaaaabcv"
    ],
    [
      "ef  g  h  i fbcv",
      " f  jk   hl fbcv",
      " f  dmn    opbcv",
      "qr  jsh     pbcv",
      " f  js i hi fbcv",
      "    j h  o ofbcv",
      "    j     ltfbcv",
      "    j  l    fbcv",
      "    jk  uuu  bcv",
      "jjjjdmn uuu  bcv",
      "   wjx  uuu  bcv",
      "    jxxouyy  bcv",
      "    jxxl A   bcv",
      "BB  jxo      bcv",
      "C   j!xD  D  bcv",
      "E   jxx     Fbcv"
    ],
    [
      "    g        bcv",
      " I  jk      Ibcv",
      " I  dmJ      bcv",
      "    j        bcv",
      "    K       Lbcv",
      "    K       Ibcv",
      "    K       Ibcv",
      "    K       Lbcv",
      "    jk  MMM  bcv",
      "KKKjdmJ MMM  bcv",
      "    jx  MMM  bcv",
      "    Nx  OyP  bcv",
      "    Nx   Q   bcv",
      "    Nx       bcv",
      "    N        bcv",
      "    jx       bcv"
    ],
    [
      "    g        bcv",
      "    j        bcv",
      "    dR       bcv",
      "    j        bcv",
      "    K        bcv",
      "    K        bcv",
      "    K        bcv",
      "    K        bcv",
      "    j    MM  bcv",
      "KKKjdR   MM  bcv",
      "    j    MM  bcv",
      "    Sx   yP  bcv",
      "    Sx       bcv",
      "    S        bcv",
      "    S        bcv",
      "    jx       bcv"
    ],
    [
      "    j        bcv",
      "    j        bcv",
      "    dR       bcv",
      "    j       Tbcv",
      "    j        bcv",
      "    j        bcv",
      "    j        bcv",
      "    j        bcv",
      "    j        bcv",
      "jjjjdR       bcv",
      "    j        bcv",
      "    j        bcv",
      "    j        bcv",
      "    j        bcv",
      "    j        bcv",
      "    j        bcv"
    ],
    [
      "UUVUWRXVXXYXRbcv",
      "UUUUWRXVXXYXRbcv",
      "UUUUdRXXXXXXRbcv",
      "UUUUWRXXXXXXRbcv",
      "UUVUWRXYXXYXRbcv",
      "UUVUWRXVXXVXRbcv",
      "UUVUWRXYXXYXRbcv",
      "UUVUWRXYXXVXRbcv",
      "UUUUWRXXXXXXRbcv",
      "ZZZZdRXXXXXXRbcv",
      "XXXXWRXVXXVXRbcv",
      "XXXXWRXVXXVXRbcv",
      "XXXXWRXYXXVXRbcv",
      "VVXXWRXVXXVXRbcv",
      "XVXXWRXXXXXXRbcv",
      "XVXXWRXXXXXXRbcv"
    ]
  ]
}