{
  "name": "multi_laboratory1_8_base1",
  "refpalette": "c70cities:multi_laboratory1_8_base1_palette",
  "xsize": 16,
  "zsize": 16,
  "slices": [
    [
      "aaaaaabaabaaaaaa",
      "aaaaaacaacaaaaaa",
      "aaadaaaaaaaadaaa",
      "eeaaaaaaaaaaaaee",
      "eeaaaaaaaaaaaaee",
      "eeaaaaaaaaaaaaee",
      "eeaaaaaaaaaaaaee",
      "eeaaaaaaaaaaaaee",
      "aaaaaaaaaaaaaaaa",
      "aaadaaaaaaaadaaa",
      "aaaaaaaaaaaaaaaa",
      "aaaaaaaaaaaaaaaa",
      "aaaaaaaaaaaaaaaa",
      "aaaaaaaaaaaaaaaa",
      "aaaaaaaaaaaaaaaa",
      "aaaaaaaaaaaaaaaa"
    ],
    [
      "     fghfgh     ",
      "      b  b      ",
      "iijd        djii",
      "  i          ik ",
      "  i          i  ",
      " li          il ",
      "mmi          imm",
      "l i          il ",
      "iijn        njii",
      "oood        dooo",
      " p           lmm",
      "                ",
      "                ",
      "                ",
      "                ",
      "jqqn        nqqj"
    ],
    [
      "                ",
      "     fghfgh     ",
      "  rd  b  b  dr  ",
      "                ",
      "                ",
      "                ",
      "               s",
      "                ",
      "  r          r  ",
      "ttod        dott",
      "              u ",
      "                ",
      "                ",
      "                ",
      "                ",
      "r              r"
    ],
    [
      "                ",
      "                ",
      "  rd fghfgh dr  ",
      "      b  b      ",
      "                ",
      "                ",
      "                ",
      "                ",
      "  r          r  ",
      "wwod        doww",
      "                ",
      "                ",
      "                ",
      "                ",
      "                ",
      "r              r"
    ],
    [
      "                ",
      "                ",
      "   d        d   ",
      "     fghfgh     ",
      "      b  b      ",
      "                ",
      "                ",
      "                ",
      "                ",
      "xxod        doxx",
      "                ",
      "                ",
      "                ",
      "                ",
      "                ",
      "                "
    ],
    [
      "yyyy        yyyy",
      "yyyy        yyyy",
      "AAAd        dAAA",
      "yyyy        yyyy",
      "yyyy fghfgh yyyy",
      "yyyy  b  b  yyyy",
      "yyyy bb  bb yyyy",
      "yyyy        yyyy",
      "yyyyyyyyyyyyyyyy",
      "ooodyyyyyyyydooo",
      "yyyyyyyyyyyyyyyy",
      "yByyyyByyByyyyBy",
      "yByyyyByyByyyyBy",
      "yByyyyByyByyyyBy",
      "yByyyyByyByyyycy",
      "yyyyyyyyyyyyyyyy"
    ]
  ]
}