{
  "name": "multi_condo1_2_floor7",
  "refpalette": "c70cities:multi_condo1_2_floor7_palette",
  "xsize": 16,
  "zsize": 16,
  "slices": [
    [
      "   abccccccccccc",
      "   abddddddddddd",
      " eeebfffffgh    ",
      "    bfffffg     ",
      "    bfffffg     ",
      "  iibfffffg     ",
      "    jfffffg     ",
      "    jfffffg     ",
      "    jfffffg     ",
      "    jfffffg     ",
      "    jfffffg     ",
      "    jjjjjjbjjjjj",
      "          b     ",
      "                ",
      "                ",
      "                "
    ],
    [
      "    k           ",
      "    bl    lmmmmm",
      " eeeb           ",
      "    bn  n o     ",
      "    bp npno     ",
      "  iibn  n o     ",
      "   qb     o     ",
      "   qbn  n o     ",
      "   qbp npno     ",
      "   qbn  n o     ",
      "   qb     o     ",
      "   qbbbbbbbbbbbb",
      "   qqqqqqqbqqqqq",
      "                ",
      "                ",
      "                "
    ],
    [
      "    j           ",
      "    br    r     ",
      " eeeb           ",
      "    b           ",
      "    b           ",
      "  iib           ",
      "    b           ",
      "    b           ",
      "    b           ",
      "    b           ",
      "    b sttu      ",
      "    bbbbbbbbbbbb",
      "          b     ",
      "                ",
      "                ",
      "                "
    ],
    [
      "    j           ",
      "    b           ",
      " eeeb           ",
      "    b           ",
      "    bw          ",
      "  iib           ",
      "  iib           ",
      "  iib           ",
      "  iibx          ",
      "  iib           ",
      "  iib  ! y      ",
      "  iibbbbbbbbbbbb",
      "  iiiiiiiiiiiiii",
      "  iiiiiiiiiiiiii",
      "                ",
      "                "
    ],
    [
      "    b           ",
      "    b           ",
      " eeeb           ",
      "    b           ",
      "    b           ",
      "    b           ",
      "    b           ",
      "    b           ",
      "    b           ",
      "    b           ",
      "    b        ABB",
      "    bbbbbbbbbbbb",
      "                ",
      "                ",
      "                ",
      "                "
    ],
    [
      "    b           ",
      "    bmmmmmmmmmmm",
      " eeebCCCCCCCCCCC",
      "   mbCCCCCCCCCCC",
      "   mbCCCCCCCCCCC",
      "   mbCCCCCCCCCCC",
      "   mbCCCCCCCCCCC",
      "   mbCCCCCCCCCCC",
      "   mbCCCCCCCCCCC",
      "   mbCCCCCCCCCCC",
      "   mbCCCCCCCCCCC",
      "   mbbbbbbbbbbbb",
      "   mmmmmmmmmmmmm",
      "                ",
      "                ",
      "                "
    ]
  ]
}