{
  "name": "multi_megatower1_4_floor3",
  "refpalette": "c70cities:multi_megatower1_4_floor3_palette",
  "xsize": 16,
  "zsize": 16,
  "slices": [
    [
      "a   bbbbbbbbbbbb",
      "a   bbbbbbbbbbbb",
      "a   bbbbbbbbbbbb",
      "cdeebbbbbbbbbbbb",
      "bbbbfbbbbbbfbbbb",
      "bbbbbbbbbbbbbbbb",
      "gggggggggggggggg",
      "gggggggggggggggg",
      "gggggggggggggggg",
      "gggggggggggggggg",
      "bbbbbbbbbbbbbbbb",
      "bbbbfbbbbbbfbbbb",
      "bbbbbbbbbbbbbbbb",
      "bbbbbbbbbbbbbbbb",
      "bbbbbbbbbbbbbbbb",
      "bbbbbbbbbbbbbbbb"
    ],
    [
      "a   ah  ijklmn  ",
      "a   aoi  iplpq  ",
      "a   arr srrlrrt ",
      "aeuuawx s ylA t ",
      "BCDEfFI J sft K ",
      "     LI sMsNtMt ",
      "     OOPOOO OOOQ",
      "                ",
      "                ",
      "RSRR RRTRRR RRRU",
      "t VWNLI sXsNtXt ",
      "Y VFfFI Z sft Y ",
      "tixwlwx s ylA t ",
      "t 00l00 s00l00ti",
      "   1lo    plpi i",
      " ii2lh   jklmn  "
    ],
    [
      "a   a      l    ",
      "a   a     3l4   ",
      "a   arr srrlrrt ",
      "ae  a   s 5l6 t ",
      "B 78f9I @ sft # ",
      "     LI s sNt t ",
      "     OO$OOO OOO%",
      "                ",
      "                ",
      "R^RR RR&RRR RRR*",
      "t VWNLI s sNt t ",
      "( V9f9I ) sft ( ",
      "t  !l   s 5l6 t ",
      "t 00l00 s00l00t ",
      "    l     +l-   ",
      "    l      l    "
    ],
    [
      "a   a      l    ",
      "a   a      l    ",
      "a   arr srrlrrt ",
      "aeeea   s  l  t ",
      "B[  fL  s sft t ",
      "     L] s sNt t ",
      "     OO{OOO OOO{",
      "                ",
      "                ",
      "R}RR RR}RRR RRR}",
      "t  WNL  s sNt t ",
      "t  WfL  s sft t ",
      "t  ]l]  s  l  t ",
      "t 00l00 s00l00t ",
      "    l      l    ",
      "    l      l    "
    ],
    [
      "a   a      l    ",
      "a   a]     l]   ",
      "a   arr srrlrrt ",
      "aeeea   s ]l  t ",
      "BBBBfL  s sft t ",
      "     L] s s\\t t ",
      "     OOOOOO|OOOO",
      "                ",
      "                ",
      "RRRR`RRRRRR`RRRR",
      "t ]W\\L  s]s\\t t]",
      "t  WfL  s sft t ",
      "t ]]l]  s ]l] t ",
      "t 00l00 s00l00t ",
      "    l      l    ",
      "    l      l    "
    ],
    [
      ":   :]     :    ",
      ":   :]     :    ",
      ":   :bbbbbb:bbbb",
      ":e;;:bbbbbb:bbbb",
      "''''f''''''f''''",
      ",,,,:bbbbbb:bbbb",
      ",,,,:......:....",
      ",,,,:,,,,,,:,,,,",
      ",,,,:,,,,,,:,,,,",
      "////://////:////",
      "bbbb:bbbbbb:bbbb",
      "''''f''''''f''''",
      "bbbb:bbbbbb:bbbb",
      "bbbb:bbbbbb:bbbb",
      "   ]:      :]   ",
      "    :      :    "
    ]
  ]
}