{
  "name": "multi_militarybase_4_base3",
  "refpalette": "c70cities:multi_militarybase_4_base3_palette",
  "xsize": 16,
  "zsize": 16,
  "slices": [
    [
      "vvvvvvvvvvvvvvvv",
      " vaaaaaaavaaaavv",
      " baaaaaaabaaaavv",
      " baaaaaaabaaaavv",
      " baaaaaaabaaaavv",
      " vbbbbbbbvbbbvvv",
      " bcccaaaabaaaavv",
      " bcccaaaabaaaavv",
      " bcccaaaabaaaavv",
      " vdccaaaabaaaavv",
      " bcccaaaabaaaavv",
      " bcccaaaabaaaavv",
      " bcccaaaabaaaavv",
      " vbbbbbbbvbbbvvv",
      " bcccaaaaaaaaavv",
      " bcccaaaaaaaaavv"
    ],
    [
      "vvvvvvvvvvvvvvvv",
      " ve fgh eviiiivv",
      " j      klimnivv",
      " j  ooo plqmnivv",
      " j      rli sivv",
      " v       vltlvvv",
      " j       uw wwvv",
      " j       u    vv",
      " j           wvv",
      " vd           vv",
      " j           wvv",
      " j       u  wwvv",
      " j       u!wwwvv",
      " v       vlllvvv",
      " j   xyx AyA Bvv",
      " j           Bvv"
    ],
    [
      "vvvvvvvvvvvvvvvv",
      " ve     evisssvv",
      "         lq  ivv",
      "         lq  qvv",
      "         li  ivv",
      " v       vlClvvv",
      "         u  wDvv",
      "         u    vv",
      "              vv",
      " vd           vv",
      "             wvv",
      "         u   Evv",
      "         u  wwvv",
      " v       vlllvvv",
      "              vv",
      "              vv"
    ],
    [
      "vvvvvvvvvvvvvvvv",
      " v      Fvi qivv",
      "         l   svv",
      "         lq   vv",
      "         l   svv",
      " v       vlllvvv",
      "         u    vv",
      "         u    vv",
      "         u    vv",
      " vd      u    vv",
      "         u    vv",
      "         u    vv",
      "         u    vv",
      " v       vlllvvv",
      "             Ivv",
      "              vv"
    ],
    [
      "vvvvvvvvvvvvvvvv",
      " v       vq  svv",
      " J       l    vv",
      " J       l    vv",
      " J       l    vv",
      " vjjjjjjjvlllvvv",
      " J       j    vv",
      " J       j    vv",
      " J       j    vv",
      " vd      j    vv",
      " J       j    vv",
      " J       j    vv",
      " J       j    vv",
      "Jv       vlllvvv",
      " J            vv",
      " J            vv"
    ],
    [
      "vvvvvvvvvvvvvvvv",
      "KvKKKKKKKvKKKKvv",
      "LbLLLLLLLbLLLKvv",
      "LbLLLLLLLbLLLKvv",
      "LbLLLLLLLbLLLKvv",
      "Lvbbbbbbbvbbbvvv",
      "LbLLLLLLLbLLLKvv",
      "LbLLLLLLLbLLLKvv",
      "LbLLLLLLLbLLLKvv",
      "LvdLLLLLLbLLLKvv",
      "LbLLLLLLLbLLLKvv",
      "LbLLLLLLLbLLLKvv",
      "LbLLLLLLLbLLLKvv",
      "Mvbbbbbbbvbbbvvv",
      " MLLLLLLLLLLLKvv",
      " MLLLLLLLLLLLKvv"
    ]
  ]
}