{
  "name": "multi_laboratory1_13_base4",
  "refpalette": "c70cities:multi_laboratory1_13_base4_palette",
  "xsize": 16,
  "zsize": 16,
  "slices": [
    [
      "aaaaaaaaaaaaabcz",
      "aaaaaaaaaaaaabcz",
      "aaaadaaaaaaaabbz",
      "aaaaaaaaaaaaabbz",
      "aaaaaaaaaaaaabbz",
      "aaaaaaaaaaaaabbz",
      "aaaaaaaaaaaaabbz",
      "aaaaaaaaaaaaabbz",
      "aaaaaeeeeeeeebbz",
      "aaaadffffffffbbz",
      "aaaaafghhhhifbbz",
      "aaaaafhhhghgfbbz",
      "aaaaafghhhggfbbz",
      "aaaaafhghgggfbbz",
      "aaaaafhhhghgfbbz",
      "aaaaaffffffffbbz"
    ],
    [
      " j  k  l    mbcz",
      "  n op      qbcz",
      "r   dst    uqbbz",
      " j  ow l    qbbz",
      " mxyoA B lxCDbbz",
      "  x oAll u lDbbz",
      "B   oE     CDbbz",
      "    oA     uDbbz",
      "    o       Fbbz",
      "oooodIIIIIIIIbbz",
      "   Joh KLKMNgbbz",
      "    ogKOKPKPhbbz",
      "    ohPKOOPKgbbz",
      "QQ  ogK KPK gbbz",
      "R   oggSgK ggbbz",
      "T   ofgghhggfbbz"
    ],
    [
      "    k       Ubcz",
      "    op      qbcz",
      "    d!V     Wbbz",
      " B  o       pbbz",
      " X  Y      CZbbz",
      "    Y      CZbbz",
      "    Y      C!bbz",
      "    Y      CZbbz",
      "    o       Fbbz",
      "YYYodIIIIIIIIbbz",
      "    oh   0  hbbz",
      "    1h0     gbbz",
      "    1g     Lgbbz",
      "    1g  0 L hbbz",
      "2   1hg     gbbz",
      "    ofhihghgfbbz"
    ],
    [
      "    k        bcz",
      "    o       qbcz",
      "    dq       bbz",
      "    o        bbz",
      "    Y        bbz",
      "    Y        bbz",
      "    Y        bbz",
      "    Y        bbz",
      "    o3      3bbz",
      "YYYodIIIIIIIIbbz",
      "    oh      ibbz",
      "    4i      hbbz",
      "    4h      hbbz",
      "    4h      gbbz",
      "    4g      hbbz",
      "    ofhhhhggfbbz"
    ],
    [
      "    o        bcz",
      "    o       qbcz",
      "    dq       bbz",
      "    o5       bbz",
      "    o6       bbz",
      "    o7       bbz",
      "    o8       bbz",
      "    o9       bbz",
      "    o@       bbz",
      "oooodIIIIIIIIbbz",
      "    og      hbbz",
      "    oh      gbbz",
      "    og      hbbz",
      "    oh      hbbz",
      "    oh      gbbz",
      "    ofhhihhhfbbz"
    ],
    [
      "## #$q%^%%^%qbcz",
      "####$q%^%%^%qbcz",
      "####dq%%%%%%qbcz",
      "####$q%%%%%%qbcz",
      "##&#$q%&%%&%*bcz",
      "##&#$q%^%%^%*bcz",
      "##^#$q%^%%^%*bcz",
      "##^#$q%^%%^%*bcz",
      "####$q%%%%%%qbcz",
      "((((dqIIIIIIqbcz",
      "%%%%$hhihhihhbcz",
      "%%%%$hhhhihhhbcz",
      "%%%%$hhhhhhhhbcz",
      "^)%%$hhhihhhhbcz",
      "%^%%$hiihhhhhbcz",
      "%^%%$fhhhhhhfbcz"
    ]
  ]
}