{
  "name": "multi_laboratory1_13_base2",
  "refpalette": "c70cities:multi_laboratory1_13_base2_palette",
  "xsize": 16,
  "zsize": 16,
  "slices": [
    [
      "aaaaaaaaaaaaabcv",
      "aaaaaaaaaaaaabcv",
      "aaaadaaaaaaaabcv",
      "aaaaaaaaaaaaabcv",
      "aaaaaaaaaaaaabcv",
      "aaaaaaaaaaaaabcv",
      "aaaaaaaaaaaaabcv",
      "aaaaaaaaaaaaabcv",
      "aaaaaeeeeeeeebcv",
      "aaaadaaaaaaaabcv",
      "aaaaaaaaaaaaabcv",
      "aaaaaaaaaaaaabcv",
      "aaaaaaaaaaaaabcv",
      "aaaaaaaaaaaaabcv",
      "aaaaaaaaaaaaabcv",
      "aaaaaaaaaaaaabcv"
    ],
    [
      " f  g  h  ijkbcv",
      "lf  mn   jo kbcv",
      " f  dpq hh jrbcv",
      " f  ms      rbcv",
      "tf  ms i ho kbcv",
      "    m h  j jkbcv",
      "    m      tkbcv",
      "    m       kbcv",
      "    m       ubcv",
      "mmmmdw  xx  wbcv",
      "   ymw AAAA wbcv",
      "    mwBACCADwbcv",
      "    mwBAEEADwbcv",
      "FF  mw AAAA wbcv",
      "I   mw  JJ  wbcv",
      "K   mwwwwwwwwbcv"
    ],
    [
      "    g        bcv",
      " L  mn      Mbcv",
      "    dpN      bcv",
      "    m        bcv",
      " L  O       Mbcv",
      "    O       Lbcv",
      "    O       Lbcv",
      "    O       Mbcv",
      "    m        bcv",
      "OOOmdw      wbcv",
      "    mw  PP  wbcv",
      "    Qw P  P wbcv",
      "    QRRPSEPRRbcv",
      " T  Qw  PP  wbcv",
      "    Qw      wbcv",
      "    mw!wwwwwwbcv"
    ],
    [
      "    g        bcv",
      "    m        bcv",
      "    dU       bcv",
      "    m        bcv",
      "    O        bcv",
      "    O        bcv",
      "    O        bcv",
      "    O        bcv",
      "    mV      Vbcv",
      "OOOmdw      wbcv",
      "    mw  PP  wbcv",
      "    Ww P  P wbcv",
      "    Ww PX P wbcv",
      "    Ww  PPR wbcv",
      "    Ww  R Y wbcv",
      "    mwwwRwwwwbcv"
    ],
    [
      "    m        bcv",
      "    m        bcv",
      "    dU       bcv",
      "    m       Zbcv",
      "    m        bcv",
      "    m        bcv",
      "    m        bcv",
      "    m        bcv",
      "    m        bcv",
      "mmmmdw      wbcv",
      "    mw  PP  wbcv",
      "    mw P  P wbcv",
      "    mw PXEP wbcv",
      "    mw  PP  wbcv",
      "    mw    0RRbcv",
      "    mwwwwwwwwbcv"
    ],
    [
      "11 12U343353Ubcv",
      "11112U343353Ubcv",
      "1111dU333333Ubcv",
      "11112U333333Ubcv",
      "11412U353353Ubcv",
      "11412U343343Ubcv",
      "11412U343343Ubcv",
      "11412U343363Ubcv",
      "11112U333333Ubcv",
      "7777dw      wbcv",
      "33332w  PP  wbcv",
      "33332w P EP wbcv",
      "33332w PCCP wbcv",
      "44332w  PP  wbcv",
      "34332w      wbcv",
      "36332wwwwwwwwbcv"
    ]
  ]
}