{
  "name": "multi_megatower1_1_floor12",
  "refpalette": "c70cities:multi_megatower1_1_floor12_palette",
  "xsize": 16,
  "zsize": 16,
  "slices": [
    [
      "           abc  ",
      "           dbc  ",
      "           dbcef",
      "           dbcgg",
      "          hijkcc",
      "           abccc",
      "           abccc",
      "           abccc",
      "           dbccc",
      "           dbccc",
      "           dbccc",
      "          hijkcc",
      "           abccc",
      "           abccc",
      "           abccc",
      "           dbccc"
    ],
    [
      "           a l  ",
      "           d le ",
      "           d lm ",
      "           d l  ",
      "          hi kdn",
      "           a o  ",
      "           a o  ",
      "           a oaa",
      "           d op ",
      "           d o q",
      "           d o q",
      "          hi krr",
      "           a opq",
      "           a o q",
      "           a o  ",
      "           d op "
    ],
    [
      "           a lg ",
      "           d lm ",
      "           d l  ",
      "           d l  ",
      "          hi kds",
      "           a o  ",
      "           a o  ",
      "           a o  ",
      "           d o  ",
      "           d o  ",
      "           d o  ",
      "          hi k r",
      "           a o  ",
      "           a o  ",
      "           a o  ",
      "           d o  "
    ],
    [
      "           a lmt",
      "           d l  ",
      "           d l  ",
      "           d l u",
      "          hi kdd",
      "           a o  ",
      "           a o  ",
      "           a o  ",
      "           d o  ",
      "           d o  ",
      "           d o  ",
      "          hi k  ",
      "           a o  ",
      "           a o  ",
      "           a o  ",
      "           d o  "
    ],
    [
      "           a w f",
      "           d w t",
      "           d w  ",
      "           d w  ",
      "          hi kdd",
      "           a x  ",
      "           a y  ",
      "           a x  ",
      "           d y  ",
      "           d x  ",
      "           d y  ",
      "          hi k  ",
      "           a x  ",
      "           a y  ",
      "           a x  ",
      "           d y  "
    ],
    [
      "           a A  ",
      "           d A f",
      "           d A g",
      "           d Aeg",
      "          hiBkCC",
      "           a ADD",
      "           a ADE",
      "           a ADD",
      "           d ADD",
      "           d ADE",
      "           d ADD",
      "          hiBkCC",
      "           a A  ",
      "           a A  ",
      "           a A  ",
      "           d A  "
    ]
  ]
}