{
  "name": "multi_laboratory1_4_base3",
  "refpalette": "c70cities:multi_laboratory1_4_base3_palette",
  "xsize": 16,
  "zsize": 16,
  "slices": [
    [
      "zabccccccccdcccc",
      "zabccccccccccccc",
      "zabccccccccccccc",
      "zabccccccefcfccc",
      "zabccccccccfgccc",
      "zabccccccchccccc",
      "zabccccccccccccc",
      "zabccccccccdcccc",
      "zabiiiiiiiiccccc",
      "zabiiiiiiiiccccc",
      "zabiiiiiiiiccccc",
      "zabjiiiiiiiccccc",
      "zab!kiiiiiiccccc",
      "zabbbbbbbbbbbbbb",
      "zaaaaaaaaaaaaaaa",
      "zzzzzzzzzzzzzzzz"
    ],
    [
      "zablllllllld   m",
      "zab! nnopnql r m",
      "zabstuuu wql   x",
      "zabyABBBo  r  Cx",
      "zabyDBBBBEF     ",
      "zabs IIII  Jr   ",
      "zabK   LM ol   r",
      "zablllllllld   N",
      "zabOOPPPPOOlQ   ",
      "zabQ       R    ",
      "zabSTUTUTUTl    ",
      "zab V V V Vl   W",
      "zabXVYVYVYVlZ00 ",
      "zabbbbbbbbbbbbbb",
      "zaaaaaaaaaaaaaaa",
      "zzzzzzzzzzzzzzzz"
    ],
    [
      "zablllllllld    ",
      "zab       1l    ",
      "zab w     1    W",
      "zab2 ooo        ",
      "zab3 oooo       ",
      "zab        4    ",
      "zab   55   l    ",
      "zablllllllld   6",
      "zab7 888896l    ",
      "zab        @    ",
      "zab#T$T$T$Tl    ",
      "zab V V V Vl    ",
      "zab%V V V Vl    ",
      "zabbbbbbbbbbbbbb",
      "zaaaaaaaaaaaaaaa",
      "zzzzzzzzzzzzzzzz"
    ],
    [
      "zablllllllld    ",
      "zab       1l    ",
      "zab       1^    ",
      "zab             ",
      "zab             ",
      "zab        &    ",
      "zab        l    ",
      "zablllllllld    ",
      "zab 8 8 88 l    ",
      "zab        l    ",
      "zabTTTTTTTTl    ",
      "zab V V V Vl    ",
      "zabjV V%V Vl    ",
      "zabbbbbbbbbbbbbb",
      "zaaaaaaaaaaaaaaa",
      "zzzzzzzzzzzzzzzz"
    ],
    [
      "zablllllllld    ",
      "zab        l    ",
      "zab        l    ",
      "zab        l    ",
      "zab        l    ",
      "zab        l    ",
      "zab        l    ",
      "zablllllllld    ",
      "zab********l    ",
      "zab********l    ",
      "zab********l    ",
      "zab********l    ",
      "zabX*(*X*(*l    ",
      "zabbbbbbbbbbbbbb",
      "zaaaaaaaaaaaaaaa",
      "zzzzzzzzzzzzzzzz"
    ],
    [
      "zablllllllld))+)",
      "zab--------&))+)",
      "zab-[----t-&))+)",
      "zab--------&))++",
      "zab--------&))))",
      "zab-t----[-&))))",
      "zab--------&))))",
      "zablllllllldllll",
      "zab]]]]]]]]l^^^^",
      "zab] ] ] ] l^+^^",
      "zab] ] ] ] l^+^^",
      "zabX ] ] ] l^+^^",
      "zabX ] ] ] l^^^^",
      "zabbbbbbbbbbbbbb",
      "zaaaaaaaaaaaaaaa",
      "zzzzzzzzzzzzzzzz"
    ]
  ]
}