{
  "name": "multi_laboratory1_14_base4",
  "refpalette": "c70cities:multi_laboratory1_14_base4_palette",
  "xsize": 16,
  "zsize": 16,
  "slices": [
    [
      "aaaabaaaaaaaaccv",
      "aaaaaaaaaaaaaccv",
      "aaaaaaaaaaaaaccv",
      "aaaaaaaaaaaaaccv",
      "aaaaaaaaaaaaaccv",
      "aaaaaaaaaaaaaccv",
      "aaaaaaaaaaaa!ccv",
      "aaaabaaaaaaaaccv",
      "aaaaaddddddddccv",
      "aaaaaddddddddccv",
      "aaaaaddddddddccv",
      "aaaaaddddddddccv",
      "aaaaaddddddddccv",
      "cccccccccccccccv",
      "eeeecccccccccccv",
      "vvvvvvvvvvvvvvvv"
    ],
    [
      "fg  bhhhhhhhhccv",
      "f   hijjklm nccv",
      "o   hjpq    rccv",
      "ss  hj   tt uccv",
      "    hw   tt uccv",
      "    x       yccv",
      "    h    AB nccv",
      "    bhhhhhhhhccv",
      "    hCCDDDDCCccv",
      "    E        ccv",
      "    hFIFIFIFIccv",
      "    h J J J Jccv",
      "KLLMhNJNJNJNJccv",
      "cccccccccccccccv",
      "eeeecccccccccccv",
      "vvvvvvvvvvvvvvvv"
    ],
    [
      "    bhhhhhhhhccv",
      "    hiOjk   Pccv",
      "Q   hj       ccv",
      "    hj       ccv",
      "    hw       ccv",
      "    R        ccv",
      "    h       Pccv",
      "    bhhhhhhhhccv",
      "    hPSSSSSSPccv",
      "    T        ccv",
      "    hUIUIUIUIccv",
      "    h J J J Jccv",
      "    h J J J Jccv",
      "cccccccccccccccv",
      "eeeecccccccccccv",
      "vvvvvvvvvvvvvvvv"
    ],
    [
      "    bhhhhhhhhccv",
      "    hiVq    Pccv",
      "   Whp       ccv",
      "   Wh        ccv",
      "    h        ccv",
      "    X        ccv",
      "    h       Pccv",
      "    bhhhhhhhhccv",
      "    h SSSSSS ccv",
      "    h        ccv",
      "    hIIIIIIIIccv",
      "    h J J J Jccv",
      "    h J J J Jccv",
      "cccccccccccccccv",
      "eeeecccccccccccv",
      "vvvvvvvvvvvvvvvv"
    ],
    [
      "    bhhhhhhhhccv",
      "    hi       ccv",
      "    h        ccv",
      "    h        ccv",
      "    h        ccv",
      "    h        ccv",
      "    h        ccv",
      "    bhhhhhhhhccv",
      "    hYYYYYYYYccv",
      "    hYYYYYYYYccv",
      "    hYYYYYYYYccv",
      "    hYYYYYYYYccv",
      "    hZY!YZYZYccv",
      "cccccccccccccccv",
      "eeeecccccccccccv",
      "vvvvvvvvvvvvvvvv"
    ],
    [
      "0100bhhhhhhhhcev",
      "0100X22222222cev",
      "0300X24222242cev",
      "3300X22222222cev",
      "0000X22222222cev",
      "0000X24222242cev",
      "0000X22222222cev",
      "hhhhbhhhhhhhhcev",
      "5555h66666666cev",
      "5535h6 6 6 6ccev",
      "5515h6 6 6 6ccev",
      "5515h6 6 6 6ccev",
      "5555h6 6 6 6ccev",
      "ccccccccccccccev",
      "eeeeeeeeeeeeeeev",
      "vvvvvvvvvvvvvvvv"
    ]
  ]
}