{
  "name": "multi_convenientstore_1_floor1",
  "refpalette": "c70cities:multi_convenientstore_1_floor1_palette",
  "xsize": 16,
  "zsize": 16,
  "slices": [
    [
      "       abbbbbbbb",
      "       ab       ",
      "       ab       ",
      "       ab       ",
      "       ab       ",
      "       abccccccc",
      "       abddddddd",
      "       abddddddd",
      "       abddddddd",
      "       abddddddd",
      "       abddddddd",
      "       abddddddd",
      "       abeeeeeee",
      "     vvvv       ",
      "                ",
      "                "
    ],
    [
      "       fbbbbbbbb",
      "       fb       ",
      "       fb       ",
      "       fb       ",
      "       fb       ",
      "       fbggggggg",
      "       fbhi jhi ",
      "       fbk      ",
      "       fb       ",
      "       fb       ",
      "       fb       ",
      "       fblmmmlmm",
      "       fbeeeeeee",
      "     vvvv       ",
      "                ",
      "                "
    ],
    [
      "      nnbbbbbbbb",
      "      nnb       ",
      "      nnb       ",
      "      nnb       ",
      "      nnb       ",
      "      nnb       ",
      "      nnb       ",
      "      nnb       ",
      "      nnb       ",
      "      nnb       ",
      "      nnb       ",
      "      nnblo  lo ",
      "      nnbeeppeep",
      "     vvvv       ",
      "                ",
      "                "
    ],
    [
      "       ebbbbbbbb",
      "       eb       ",
      "       eb       ",
      "       eb       ",
      "       eb       ",
      "       eb       ",
      "       eb       ",
      "       eb       ",
      "       eb       ",
      "       eb       ",
      "       eb       ",
      "       eb       ",
      "       eeeeeeeee",
      "     vvvv       ",
      "                ",
      "                "
    ],
    [
      "       eqqqqqqqq",
      "       eqqqqqqqq",
      "       eqqqqqqqq",
      "       eqqqqqqqq",
      "       eqqqqqqqq",
      "       eqqqqqqqq",
      "       eqqqqqqqq",
      "       eqqqqqqqq",
      "       eqqqqqqqq",
      "       eqqqqqqqq",
      "       eqqqqqqqq",
      "       eqqqqqqqq",
      "       eeeeeeeee",
      "     vvvv       ",
      "                ",
      "                "
    ],
    [
      "                ",
      "                ",
      "                ",
      "                ",
      "                ",
      "                ",
      "           ~    ",
      "                ",
      "                ",
      "                ",
      "                ",
      "                ",
      "                ",
      "     vvvv       ",
      "                ",
      "                "
    ]
  ]
}