{
  "name": "multi_laboratory1_8_base2",
  "refpalette": "c70cities:multi_laboratory1_8_base2_palette",
  "xsize": 16,
  "zsize": 16,
  "slices": [
    [
      "aaaaaaaaaaaaaaaa",
      "aaaaaaaaaaaaaaaa",
      "aaabaaaaaaaabaaa",
      "aaaa!aaaaaaaaaaa",
      "aaaaaaaaaaaaaaaa",
      "aaaaaaaaaaaaaaaa",
      "aaaaaaaaaaaaaaaa",
      "aaaaaaaaaaaaaaaa",
      "aaaaaaaaaaaaaaaa",
      "aaabaaaaaaaabaaa",
      "aaaaaaaaaaaaaaaa",
      "aaaaaaaaaaaaaaaa",
      "aaaaaaaaaaaaaaaa",
      "aaaaaaaaaaaaaaaa",
      "aaaaaaaaaaaaaaaa",
      "aaaaaaaaaaaaaaaa"
    ],
    [
      "  c d      c d  ",
      " ec df    ec df ",
      "  cbd      cbd  ",
      " ec d f   gc d f",
      "  c d      c d  ",
      "                ",
      "                ",
      "                ",
      "   h        h   ",
      "iiibijjkljjibiii",
      "   h        h   ",
      "                ",
      "                ",
      "m    nmmmmo    m",
      "do  p c  d    nc",
      "d    qc  dr    c"
    ],
    [
      "    s      t    ",
      "  t          s  ",
      "   b       tb   ",
      "    s        s  ",
      "  t             ",
      "                ",
      "                ",
      "                ",
      "   u        u   ",
      "wwibijjxyjjibiww",
      "   u        u   ",
      "                ",
      "                ",
      "      A         ",
      "      A        B",
      "B     B  C     D"
    ],
    [
      "                ",
      "                ",
      "   b        b   ",
      "                ",
      "                ",
      "                ",
      "                ",
      "                ",
      "   u        u   ",
      "wwibijjjjjjibiww",
      "   u        u   ",
      "                ",
      "                ",
      "                ",
      "                ",
      "                "
    ],
    [
      "                ",
      "                ",
      "   b        b   ",
      "                ",
      "                ",
      "                ",
      "                ",
      "                ",
      "                ",
      "iiibiiiiiiiibiii",
      "                ",
      "                ",
      "                ",
      "                ",
      "                ",
      "                "
    ],
    [
      "EFEEEFEEEEFEEEFE",
      "EEEEEEEEEEEEEEEE",
      "EEEbEEEEEEEEbEEE",
      "EEEEEEEEEEEEEEEE",
      "EFEEEFEEEEFEEEFE",
      "EFEEEFEEEEFEEEFE",
      "EFEEEFEEEEFEEEFE",
      "EFEEEFEEEEFEEEFE",
      "EEEEEEEEEEEEEEEE",
      "IIIbIIIIIIIIbIII",
      "JJJiJJJJJJJJiJJJ",
      "JJJiJJJJJJJJiJJJ",
      "JJJiJJJJJJJJiJJJ",
      "FJJiJJ FFFJJiJJK",
      "KJJiJJFJJFJJiJJK",
      " JJiJJKJJFJJiJJF"
    ]
  ]
}