{
  "name": "multi_condo1_3_floor1",
  "refpalette": "c70cities:multi_condo1_3_floor1_palette",
  "xsize": 16,
  "zsize": 16,
  "slices": [
    [
      "                ",
      "      a         ",
      "      a         ",
      "bbbbbbaccccccc  ",
      "ddddddddddddec  ",
      "ffffffffffffgc  ",
      "ffffffffffffgc  ",
      "ffffffffffffgc  ",
      "ffffffffffffgc  ",
      "ffffffffffffgc  ",
      "ffffffffffffgc  ",
      "ffffffffffffgc  ",
      "ffffffffffffgc  ",
      "ffffffffffffgaaa",
      "ccccccccccccgh  ",
      "iiiiijkkkkkkgh  "
    ],
    [
      "                ",
      "      aaaaaaaaaa",
      "      aaaaaaaaaa",
      "      lmmmmmmmaa",
      "nnnnnnnnnnnnnmaa",
      "        ooo nmaa",
      "       pqqqrnmaa",
      "   s   pqqqrnmaa",
      "   t   pqqqrnmaa",
      "   t    uuu nmaa",
      "   t  ~     nmaa",
      "tttwttttttt nmaa",
      "          t nmaa",
      "          t nxaa",
      "          t n   ",
      "          t n   "
    ],
    [
      "                ",
      "                ",
      "                ",
      "                ",
      "nnnnnnnnnnnnn   ",
      "            n   ",
      "        qyq n   ",
      "       AyBy n   ",
      "        qyq n   ",
      "            n   ",
      "            n   ",
      "   C        n   ",
      "            n   ",
      "            n   ",
      "            n   ",
      "            n   "
    ],
    [
      "                ",
      "                ",
      "                ",
      "                ",
      "            D   ",
      "                ",
      "        EFE     ",
      "       IFBF     ",
      "        EFE     ",
      "                ",
      "      ~         ",
      "                ",
      "                ",
      "                ",
      "                ",
      "                "
    ],
    [
      "                ",
      "                ",
      "                ",
      "                ",
      "            J   ",
      "                ",
      "        KKK     ",
      "        KBK     ",
      "        KKK     ",
      "                ",
      "      ~         ",
      "                ",
      "                ",
      "                ",
      "                ",
      "                "
    ],
    [
      "                ",
      "                ",
      "                ",
      "                ",
      "                ",
      "                ",
      "                ",
      "         L      ",
      "                ",
      "                ",
      "      ~         ",
      "                ",
      "                ",
      "                ",
      "                ",
      "                "
    ]
  ]
}