{
  "name": "multi_megatower1_4_floor11",
  "refpalette": "c70cities:multi_megatower1_4_floor11_palette",
  "xsize": 16,
  "zsize": 16,
  "slices": [
    [
      "a   bbbbbbbbbbbb",
      "a   bbbbbbbbbbbb",
      "a   bbbbbbbbbbbb",
      "cdeebbbbbbbbbbbb",
      "bbbbfbbbbbbfbbbb",
      "bbbbbbbbbbbbbbbb",
      "bbbbbbbbbbbbbbbb",
      "bbbbbbbbbbbbbbbb",
      "bbbbbbbbbbbbbbbb",
      "bbbbbbbbbbbbbbbb",
      "bbbbbbbbbbbbbbbb",
      "ggggfbbbbbbfbbbb",
      "    hbbbbbbbbbbb",
      "    hbbbbbbbbbbb",
      "    hbbbbbbbbbbb",
      "    hbbbbbbbbbbb"
    ],
    [
      "a   ij klk m   n",
      "a   ij kkk o    ",
      "a   ip kkk q   r",
      "aessit    uq   w",
      "xyABfu  CCCfDEDD",
      "    F   IJ q   D",
      "    K    JLqM  N",
      "O   P      qQ  D",
      "u   R      qQ  N",
      "    K    JLqM  D",
      "u   F   nJ q   N",
      "FFFFful CCCfDSDD",
      "    F    JLq    ",
      "    F   nJ q   T",
      "    F      U  VW",
      "    FI   l X   Y"
    ],
    [
      "a   i      Z    ",
      "a   i      0    ",
      "a   i      q    ",
      "ae  i     1q    ",
      "x 23f1  CCCfD4DD",
      "    F      q   D",
      "    K      5   6",
      "    7      5   D",
      "1   8      5   6",
      "    K      5   D",
      "1   F      q   6",
      "    f1   CCfD9DD",
      "    F      q    ",
      "    F      q    ",
      "    F      @    ",
      "    F      #    "
    ],
    [
      "a   i      $    ",
      "a   i      $    ",
      "a   i      q    ",
      "aeeei     1q    ",
      "x%  f1   l fDDDD",
      "    F      q   D",
      "    K      5   D",
      "    K      5   D",
      "1   K      5   D",
      "    K      5   D",
      "1   F      q   D",
      "    f1     fDDDD",
      "    F      q    ",
      "    F      q    ",
      "    F      $    ",
      "    F      $    "
    ],
    [
      "a   ^&&& & *&&&&",
      "a   ^&&&&&&*&&&&",
      "a   ^&( &(&*&(&&",
      "aeee^&&&&&&*&&&&",
      "xxxxf&&&& &fDDDD",
      "    q&&&&&&*))))",
      "    q&(&&+&*))))",
      "    q&&&&&&*))))",
      "    q&&&&&&*))))",
      "    q& &&(&*))))",
      "    q&&&&&&*))))",
      "    f  &&&&fDDDD",
      "    q&&&&&&*&&&&",
      "    q&( &(&*&(&&",
      "    q&&&&&&*&&&&",
      "    q&&&& &*&&&&"
    ],
    [
      "-   -     [-    ",
      "-   -    ][-]] ]",
      "-   -]{  {[- {] ",
      "-e}\\- | ] `-]] ]",
      "::::f::::::f::::",
      "&&&&- ]   `- ]  ",
      "&&(&- { ]{[-[[[[",
      "&&&&-];   [-] []",
      "&&&&-  ] ][-  [[",
      "&&(&- {  {[-  []",
      "&&&&-   ] `-]][[",
      "::::f::::::f::::",
      "    - ]   `- ] ]",
      "    - { ]{[- {  ",
      "    -]!]  [- ]  ",
      "    -]  ]][-    "
    ]
  ]
}