{
  "name": "multi_hospital_1_base2",
  "refpalette": "c70cities:multi_hospital_1_base2_palette",
  "xsize": 16,
  "zsize": 16,
  "slices": [
    [
      "vvvvvvvvvvvvvvvv",
      "vvvvvvvvvvvvvvvv",
      "vvvvvvvvvvvvvvvv",
      "vvvvvvvvvvvvvvvv",
      "vvvvvvvvvvvvvvvv",
      "vvvvvvvvvvvvvvvv",
      "vvvvvvvvvvvvvvvv",
      "vvvvvvvvvvvvvvvv",
      "vvvvvvvvvvvvvvvv",
      "vvvvvvvvvvvvvvvv",
      "vvvvvvvvvvvvvvvv",
      "vvvvvvvvvvvvvvvv",
      "vvvvvvvvvvvvvvvv",
      "vvvvvvvvvvvvvvvv",
      "vvvvvvvvvvvvvvvv",
      "vvvvvvvvvvvvvvvv"
    ],
    [
      "vaaaaaaaabcccccc",
      "vaaaaaaaabcccccc",
      "vaaaaaaaabcccccc",
      "vaaaaaaaabcccccc",
      "vaaaaaaaabcccccc",
      "vaaaaaaaabcccccc",
      "vaaaaaaaabcccccc",
      "vaaaaaaaabcccccc",
      "vaaaaaaaabcccccc",
      "vaaaaaaaabcccccc",
      "vaaaaaaaabbbbbbb",
      "vaaaaaaaaaaaaaaa",
      "vaaaaaaaaaaaaaaa",
      "vaaaaaaaaaaaaaaa",
      "vaaaaaaaaaaaaaaa",
      "vvvvvvvvvvvvvvvv"
    ],
    [
      "vaaaaaaaabd  ed ",
      "vaaaaaaaab      ",
      "vaaaaaaaabdf  d ",
      "vaaaaaaaabd  ed ",
      "vaaaaaaaab      ",
      "vaaaaaaaabdf  d ",
      "vaaaaaaaabd  ed ",
      "vaaaaaaaab      ",
      "vaaaaaaaabghghg ",
      "vaaaaaaaabi   j ",
      "vaaaaaaaabbbbbbb",
      "vaaaaaaaaaaaaaaa",
      "vaaaaaaaaaaaaaaa",
      "vaaaaaaaaaaaaaaa",
      "vaaaaaaaaaaaaaaa",
      "vvvvvvvvvvvvvvvv"
    ],
    [
      "vaaaaaaaabk   l ",
      "vaaaaaaaabm     ",
      "vaaaaaaaab    n ",
      "vaaaaaaaabo   o ",
      "vaaaaaaaabm     ",
      "vaaaaaaaab      ",
      "vaaaaaaaabo   l ",
      "vaaaaaaaab      ",
      "vaaaaaaaabghghg ",
      "vaaaaaaaab   j  ",
      "vaaaaaaaabbbbbbb",
      "vaaaaaaaaaaaaaaa",
      "vaaaaaaaaaaaaaaa",
      "vaaaaaaaaaaaaaaa",
      "vaaaaaaaaaaaaaaa",
      "vvvvvvvvvvvvvvvv"
    ],
    [
      "vaaaaaaaab      ",
      "vaaaaaaaab      ",
      "vaaaaaaaab      ",
      "vaaaaaaaab      ",
      "vaaaaaaaab      ",
      "vaaaaaaaab      ",
      "vaaaaaaaab      ",
      "vaaaaaaaab      ",
      "vaaaaaaaabghghg ",
      "vaaaaaaaab  j   ",
      "vaaaaaaaabbbbbbb",
      "vaaaaaaaaaaaaaaa",
      "vaaaaaaaaaaaaaaa",
      "vaaaaaaaaaaaaaaa",
      "vaaaaaaaaaaaaaaa",
      "vvvvvvvvvvvvvvvv"
    ],
    [
      "vaaaaaaaabpppppp",
      "vaaaaaaaabpppppp",
      "vaaaaaaaabpppppp",
      "vaaaaaaaabpppppp",
      "vaaaaaaaabpppppp",
      "vaaaaaaaabpppppp",
      "vaaaaaaaabpppppp",
      "vaaaaaaaabpppppp",
      "vaaaaaaaabghghg ",
      "vaaaaaaaab j    ",
      "vaaaaaaaabbbbbbb",
      "vaaaaaaaaaaaaaaa",
      "vaaaaaaaaaaaaaaa",
      "vaaaaaaaaaaaaaaa",
      "vaaaaaaaaaaaaaaa",
      "vvvvvvvvvvvvvvvv"
    ]
  ]
}