{
  "name": "multi_laboratory1_2_base2",
  "refpalette": "c70cities:multi_laboratory1_2_base2_palette",
  "xsize": 16,
  "zsize": 16,
  "slices": [
    [
      "vabcccccccccccd ",
      "vabcccccccccccd ",
      "vabcccccccccccd ",
      "vabcccccccccccde",
      "vabccccccccfcccd",
      "vabccccccccccccd",
      "vabccccccccccccc",
      "vabccccccccccccc",
      "vabccccccccccccc",
      "vabccccccccccccc",
      "vabccccccccccccc",
      "vabccccccccfcccc",
      "vabccccccccccccc",
      "vabccccccccccccc",
      "vabccccccccccccc",
      "vabccccccccccccc"
    ],
    [
      "vabghiiii  j  k ",
      "vabl mmmm  n  k ",
      "vabo  h p  q  k ",
      "vabr       s  ke",
      "vab  ttttu f  ek",
      "vab wx  xqys  Ak",
      "vab w   Bu s    ",
      "vab w  y q s    ",
      "vab wx  xq s    ",
      "vab  CCCC  s    ",
      "vab    B   s  D ",
      "vabsssEFsssfe   ",
      "vabI    y  s    ",
      "vabJK      q    ",
      "vabLL    M j    ",
      "vabKN  OP  n    "
    ],
    [
      "vab  QRS   T  k ",
      "vab   UV   W  k ",
      "vab        q  k ",
      "vab        s  ke",
      "vab  tttt  f  Xk",
      "vab wY  Z  s   k",
      "vab w      0    ",
      "vab w    q 0    ",
      "vab wZ  Zq 0    ",
      "vab  CCCC  0    ",
      "vab        s    ",
      "vabsss12sssfX   ",
      "vab        s    ",
      "vab        q    ",
      "vab3       T    ",
      "vab4       W    "
    ],
    [
      "vab        q  k ",
      "vab        q  k ",
      "vab        q  k ",
      "vab        s  ke",
      "vab  tttt  f  Xk",
      "vab w5  6q s   k",
      "vab w    q 0    ",
      "vab w    q 0    ",
      "vab w6  6q 0    ",
      "vab  CCCC  0    ",
      "vab        s    ",
      "vabssssssssfX   ",
      "vab        s    ",
      "vab        q    ",
      "vab        q    ",
      "vab        q    "
    ],
    [
      "vab        s  k ",
      "vab        s  k ",
      "vab77777777s  k ",
      "vab     7  s  ke",
      "vab     7  f   k",
      "vab  7  7  s   k",
      "vab  7  7  s    ",
      "vab  7  7  s    ",
      "vab77777777s    ",
      "vab        s    ",
      "vab        s    ",
      "vabssssssssf    ",
      "vab        s    ",
      "vab        s    ",
      "vab        s    ",
      "vab        s    "
    ],
    [
      "vab88988@88#$$k ",
      "vab88%88@88#$$k ",
      "vab88@88@88#$$k ",
      "vab88888888#$$ke",
      "vab88888888f$$$k",
      "vab88%88@88#$$$k",
      "vab88988%88#$$$$",
      "vab88@88%88#$$$$",
      "vab88%88%88#$$$$",
      "vab88888888#$$$$",
      "vab88888888#$$$$",
      "vabssssssssf$$$$",
      "vab88888888#$$$$",
      "vab88888888#$%$$",
      "vab88%88%88#$%$$",
      "vab88%88988#$%$$"
    ]
  ]
}