{
  "name": "multi_clubhouse1_7_ground",
  "refpalette": "c70cities:multi_clubhouse1_7_ground_palette",
  "xsize": 16,
  "zsize": 16,
  "slices": [
    [
      "~~abbbccbaddddaG",
      "~~abbccbbaddddaG",
      "~~abcbbbbaddddaG",
      "~~abccbbbaddddaG",
      "~~abbbcbGaeeeeaG",
      "~~abbcbbba~~~~aG",
      "~~abbcbcbaffffaG",
      "~~abcbcbca~~~~aG",
      "~~abbbccca~~~~aG",
      "~~abbcbcbaffffaG",
      "~~abbccbba~~~~aG",
      "~~abcbcbGaeeeeaG",
      "~aabbccbbaddddaG",
      "~abbbcbbbaddddaG",
      "aabbbbcbbaddddaG",
      "abbcbcbbbaddddaG"
    ],
    [
      "~gh~~~~~ihg~~gh~",
      "~gh~~~~~jhg~~gh~",
      "~gh~~~~~~hg~~gh~",
      "~gh~~~~~~hg~~gh~",
      "~gk~~~~~lkg~~gk~",
      "~gh~~~~~~hggggh~",
      "~gh~~~~~~hhhhhh~",
      "~ghm~~~~~noooop~",
      "~ghq~~~~~noooop~",
      "~gh~~~~~~hhhhhh~",
      "~gh~~~~~~hggggh~",
      "~gk~~~~~lkg~~gk~",
      "ggh~~~~~~hg~~gh~",
      "gh~~~~~~~hg~~gh~",
      "gh~~~~~~ihg~~gh~",
      "h~~~~~~~jhg~~gh~"
    ],
    [
      "~~~~~~~~~~~~~~~~",
      "~~~~~~~~~~~~~~~~",
      "~~~~~~~~~~~~~~~~",
      "~~~~~~~~~~~~~~~~",
      "~~r~~~~~~r~~~~ ~",
      "~~~~~~~~~~~~~~~~",
      "~~~~~~~~~hhhhhh~",
      "~~~~~~~~~~~~~~~~",
      "~~~~~~~~~~~~~~~~",
      "~~~~~~~~~hhhhhh~",
      "~~~~~~~~~~~~~~~~",
      "~~ ~~~~~~r~~~~r~",
      "~~~~~~~~~~~~~~~~",
      "~~~~~~~~~~~~~~~~",
      "~~~~~~~~~~~~~~~~",
      "~~~~~~~~~~~~~~~~"
    ],
    [
      "~~~~~~~~~~~~~~~~",
      "~~~~~~~~~~~~~~~~",
      "~~~~~~~~~~~~~~~~",
      "~~~~~~~~~~~~~~~~",
      "~~~~~~~~~~~~~~~~",
      "~~~~~~~~~~~~~~~~",
      "~~~~~~~~~~~~~~~~",
      "~~~~~~~~~~~~~~~~",
      "~~~~~~~~~~~~~~~~",
      "~~~~~~~~~~~~~~~~",
      "~~~~~~~~~~~~~~~~",
      "~~~~~~~~~~~~~~~~",
      "~~~~~~~~~~~~~~~~",
      "~~~~~~~~~~~~~~~~",
      "~~~~~~~~~~~~~~~~",
      "~~~~~~~~~~~~~~~~"
    ],
    [
      "~~~~~~~~~~~~~~~~",
      "~~~~~~~~~~~~~~~~",
      "~~~~~~~~~~~~~~~~",
      "~~~~~~~~~~~~~~~~",
      "~~~~~~~~~~~~~~~~",
      "~~~~~~~~~~~~~~~~",
      "~~~~~~~~~~~~~~~~",
      "~~~~~~~~~~~~~~~~",
      "~~~~~~~~~~~~~~~~",
      "~~~~~~~~~~~~~~~~",
      "~~~~~~~~~~~~~~~~",
      "~~~~~~~~~~~~~~~~",
      "~~~~~~~~~~~~~~~~",
      "~~~~~~~~~~~~~~~~",
      "~~~~~~~~~~~~~~~~",
      "~~~~~~~~~~~~~~~~"
    ],
    [
      "~~~~~~~~~~~~~~~~",
      "~~~~~~~~~~~~~~~~",
      "~~~~~~~~~~~~~~~~",
      "~~~~~~~~~~~~~~~~",
      "~~~~~~~~~~~~~~~~",
      "~~~~~~~~~~~~~~~~",
      "~~~~~~~~~~~~~~~~",
      "~~~~~~~~~~~~~~~~",
      "~~~~~~~~~~~~~~~~",
      "~~~~~~~~~~~~~~~~",
      "~~~~~~~~~~~~~~~~",
      "~~~~~~~~~~~~~~~~",
      "~~~~~~~~~~~~~~~~",
      "~~~~~~~~~~~~~~~~",
      "~~~~~~~~~~~~~~~~",
      "~~~~~~~~~~~~~~~~"
    ]
  ]
}