{
  "name": "multi_condo1_0_base2",
  "refpalette": "c70cities:multi_condo1_0_base2_palette",
  "xsize": 16,
  "zsize": 16,
  "slices": [
    [
      "vvvvvvvvvvvvvvvv",
      "vaaaaaaaaaaaaaaa",
      "vbbbbbbbbbbbbbbb",
      "vbHHHHHHHHHHHHHH",
      "vbHHHHHHHHHHHHHH",
      "vbHHHHHHHHHHHHHH",
      "vbHHHHHHHHHHHHHH",
      "vbHHHHHHHHHHHHHH",
      "vbHHHHHHHHHHHHHH",
      "vbHHHHHHHHHHHHHH",
      "vbHHHHHHHHHHHHHH",
      "vbHHHHHHHHHHHHHH",
      "vbHHHHHHHHHHHHHH",
      "vbHHHHHHHHHHHHHH",
      "vbHHHHHHHHHHHHHH",
      "vbHHHHHHHHHHHHHH"
    ],
    [
      "vvvvvvvvvvvvvvvv",
      "vaaaaaaaaaaaaaaa",
      "vbbbbbbbbbbbbbbb",
      "vbccc           ",
      "vbd e           ",
      "vbf g  ccccccc  ",
      "vbd e  d ehd e  ",
      "vbf g  f ghf g  ",
      "vbd e  d ehd e  ",
      "vbf g  f ghf g  ",
      "vbd e  d ehd e  ",
      "vbf g  f ghf g  ",
      "vbd e  d ehd e  ",
      "vbf g  f ghf g  ",
      "vbd e  iiiiiii  ",
      "vbf g           "
    ],
    [
      "vvvvvvvvvvvvvvvv",
      "vaaaaaaaaaaaaaaa",
      "vbbbbbbbbbbbbbbb",
      "vb              ",
      "vb              ",
      "vb              ",
      "vb              ",
      "vb              ",
      "vb              ",
      "vb              ",
      "vb              ",
      "vb              ",
      "vb              ",
      "vb              ",
      "vb              ",
      "vb              "
    ],
    [
      "vvvvvvvvvvvvvvvv",
      "vaaaaaaaaaaaaaaa",
      "vbbbbbbbbbbbbbbb",
      "vb              ",
      "vb              ",
      "vb              ",
      "vb              ",
      "vb              ",
      "vb              ",
      "vb              ",
      "vb              ",
      "vb              ",
      "vb              ",
      "vb              ",
      "vb              ",
      "vb              "
    ],
    [
      "vvvvvvvvvvvvvvvv",
      "vaaaaaaaaaaaaaaa",
      "vbbbbbbbbbbbbbbb",
      "vbjjjjjjjjbjjjjj",
      "vbj       b     ",
      "vbj       b     ",
      "vbj       b     ",
      "vbj       b     ",
      "vbj       b     ",
      "vbj       b     ",
      "vbj       b     ",
      "vbj       b     ",
      "vbj       b     ",
      "vbjjjjjjjjbjjjjj",
      "vbj       b     ",
      "vbj       b     "
    ],
    [
      "vvvvvvvvvvvvvvvv",
      "vaaaaaaaaaaaaaaa",
      "vbbbbbbbbbbbbbbb",
      "vbkkkkkkkkbkkkkk",
      "vbkkkkkkkkbkkkkk",
      "vbkkkkkkkkbkkkkk",
      "vbkkkkkkkkbkkkkk",
      "vbkkkkkkkkbkkkkk",
      "vbkkkkkkkkbkkkkk",
      "vbkkkkkkkkbkkkkk",
      "vbkkkkkkkkbkkkkk",
      "vbkkkkkkkkbkkkkk",
      "vbkkkkkkkkbkkkkk",
      "vbkkkkkkkkbkkkkk",
      "vbkkkkkkkkbkkkkk",
      "vbkkkkkkkkbkkkkk"
    ]
  ]
}