{
  "name": "multi_laboratory1_13_base4",
  "refpalette": "c70cities:multi_laboratory1_13_base4_palette",
  "xsize": 16,
  "zsize": 16,
  "slices": [
    [
      "aaaaaaaaaaaaabcz",
      "aaaaaaaaaaaaabcz",
      "aaaadaaaaaaaabbz",
      "aaaaaaaaaaaaabbz",
      "aaaaaaaaaaaaabbz",
      "aaaaaaaaaaaaabbz",
      "aaaaaaaaaaaaabbz",
      "aaaaaaaaaaaaabbz",
      "aaaaaeeeeeeeebbz",
      "aaaadffffffffbbz",
      "aaaaafghhhhifbbz",
      "aaaaafhhhghgfbbz",
      "aaaaafghhhggfbbz",
      "aaaaafhghgggfbbz",
      "aaaaafhhhghgfbbz",
      "aaaaaffffffffbbz"
    ],
    [
      " j  k  l    mbcz",
      "  n op      qbcz",
      "r   dst    uqbbz",
      " j  ow l    qbbz",
      " mxyoA B lxCDbbz",
      "  x oAll u lDbbz",
      "B   oE     CDbbz",
      "    oA     uDbbz",
      "    o       Fbbz",
      "oooodIIIIIIIIbbz",
      "   Joh KLK ~gbbz",
      "    ogKMKNKNhbbz",
      "    ohNKMMNKgbbz",
      "OO  ogK KNK gbbz",
      "P   oggQgK ggbbz",
      "R   ofgghhggfbbz"
    ],
    [
      "    k       Sbcz",
      "    op      qbcz",
      "    d!T     Ubbz",
      " B  o       pbbz",
      " V  W      CXbbz",
      "    W      CXbbz",
      "    W      C!bbz",
      "    W      CXbbz",
      "    o       Fbbz",
      "WWWodIIIIIIIIbbz",
      "    oh   Y  hbbz",
      "    ZhY     gbbz",
      "    Zg     Lgbbz",
      "    Zg  Y L hbbz",
      "0   Zhg     gbbz",
      "    ofhihghgfbbz"
    ],
    [
      "    k        bcz",
      "    o       qbcz",
      "    dq       bbz",
      "    o        bbz",
      "    W        bbz",
      "    W        bbz",
      "    W        bbz",
      "    W        bbz",
      "    o1      1bbz",
      "WWWodIIIIIIIIbbz",
      "    oh      ibbz",
      "    2i      hbbz",
      "    2h      hbbz",
      "    2h      gbbz",
      "    2g      hbbz",
      "    ofhhhhggfbbz"
    ],
    [
      "    o        bcz",
      "    o       qbcz",
      "    dq       bbz",
      "    o3       bbz",
      "    o4       bbz",
      "    o5       bbz",
      "    o6       bbz",
      "    o7       bbz",
      "    o8       bbz",
      "oooodIIIIIIIIbbz",
      "    og      hbbz",
      "    oh      gbbz",
      "    og      hbbz",
      "    oh      hbbz",
      "    oh      gbbz",
      "    ofhhihhhfbbz"
    ],
    [
      "99 9@q#$##$#qbcz",
      "9999@q#$##$#qbcz",
      "9999dq######qbcz",
      "9999@q######qbcz",
      "99%9@q#%##%#^bcz",
      "99%9@q#$##$#^bcz",
      "99$9@q#$##$#^bcz",
      "99$9@q#$##$#^bcz",
      "9999@q######qbcz",
      "&&&&dqIIIIIIqbcz",
      "####@hhihhihhbcz",
      "####@hhhhihhhbcz",
      "####@hhhhhhhhbcz",
      "$*##@hhhihhhhbcz",
      "#$##@hiihhhhhbcz",
      "#$##@fhhhhhhfbcz"
    ]
  ]
}