{
  "name": "multi_laboratory1_12_base4",
  "refpalette": "c70cities:multi_laboratory1_12_base4_palette",
  "xsize": 16,
  "zsize": 16,
  "slices": [
    [
      " abbbbbbbbbbbcdv",
      " abbbbbbbbbbbcdv",
      " abbbbbbbbbbbcdv",
      "eabbbbbbbbbbbcdv",
      "abbbfbbbbbbbbcdv",
      "abbbbbbbbbbbbcdv",
      "bbbbbbbbbbbbbcdv",
      "bbbbbbbbbbbbbcdv",
      "bbbbbbbbbbbbbcdv",
      "bbbbbbbbbbbbbcdv",
      "bbbbbbbbbbbbbcdv",
      "bbbbfbbbbbbbbcdv",
      "bbbbbbbbbbbbbcdv",
      "bbbbbbbbbbbbbcdv",
      "bbbbbbbbbbbbbcdv",
      "bbbbbbbbbbbbbcdv"
    ],
    [
      " g  h    ijklmdv",
      " g  n     jklmdv",
      " g  o    pqklmdv",
      "eg  r     jklmdv",
      "ge  f ps p klmdv",
      "gt  r  u  wklmdv",
      "    rxyyy jklmdv",
      "    rAyyyjqklmdv",
      "    r B i wjkkdv",
      "    rCD   j  cdv",
      "    rEFIJIF Kcdv",
      "   efrrrrrrrrcdv",
      "    rLLL LLM!cdv",
      "    o        cdv",
      "    h    i BNcdv",
      "    n     wjNcdv"
    ],
    [
      " g  O      glmdv",
      " g  P      glmdv",
      " g  o      glmdv",
      "eg  r      glmdv",
      "gQ  f      glmdv",
      "g   r      glmdv",
      "    RS T   glmdv",
      "    R S U  glmdv",
      "    R       gkdv",
      "    R       Vcdv",
      "    r       Kcdv",
      "   Qfrrrrrrrrcdv",
      "    r        cdv",
      "    o        cdv",
      "    O        cdv",
      "    P       Wcdv"
    ],
    [
      " g  o      glmdv",
      " g  o      glmdv",
      " g  o      glmdv",
      "eg  r      glmdv",
      "gQ  f      glmdv",
      "g   r      glmdv",
      "    R      glmdv",
      "    R      glmdv",
      "    R       gkdv",
      "    R        cdv",
      "    r       Kcdv",
      "   Qfrrrrrrrrcdv",
      "    r        cdv",
      "    o        cdv",
      "    o        cdv",
      "    o        cdv"
    ],
    [
      " g  r      gXmdv",
      " g  r      gXmdv",
      " g  r      gXmdv",
      "eg  r      gXmdv",
      "g   f      gXmdv",
      "g   r      gXmdv",
      "    r      gXmdv",
      "    r      gXmdv",
      "    r       gkdv",
      "    r       Vcdv",
      "    r  Y  Z 0cdv",
      "    frrrrrrrrcdv",
      "    r        cdv",
      "    r       1cdv",
      "    r        cdv",
      "    r        cdv"
    ],
    [
      " g223445445k6mdv",
      " g223445445k!mdv",
      " g223445447k6mdv",
      "eg223444444k6mdv",
      "g222f444444k6mdv",
      "g2223445445k6mdv",
      "22223445445k6mdv",
      "22223448445k6mdv",
      "222234484454kkdv",
      "2222344444444cdv",
      "2222399999999cdv",
      "2222frrrrrrrrcdv",
      "2222394444449cdv",
      "2252394444449cdv",
      "2252394544549cdv",
      "2252394744749cdv"
    ]
  ]
}