{
  "name": "multi_laboratory1_3_base4",
  "refpalette": "c70cities:multi_laboratory1_3_base4_palette",
  "xsize": 16,
  "zsize": 16,
  "slices": [
    [
      "zabccccccccccccc",
      "zabccccccccccccc",
      "zbbccccccccdcccc",
      "zbbccccccccccccc",
      "zbbccccccccccccc",
      "zbbccccccccccccc",
      "zbbccccccccccccc",
      "zbbccccccccccccc",
      "zbbccccccccccccc",
      "zbbccccccccdcccc",
      "zbbccccccccccccc",
      "zbbccccccccccccc",
      "zbbccccccccccccc",
      "zbbccccccccccccc",
      "zbbccccccccccccc",
      "zbbccccccccccccc"
    ],
    [
      "zabe fg    h  i ",
      "zabjjk     l mno",
      "zbb k p   qd  n ",
      "zbbr    g sl t  ",
      "zbbiug  fwql fn ",
      "zbbskx g  sly  x",
      "zbbr k   wAl    ",
      "zbbiuf k  Al    ",
      "zbbB  gC DAl    ",
      "zbbEF    IEdllll",
      "zbbEi    JElB   ",
      "zbbEK    LEl    ",
      "zbbEK    LEl    ",
      "zbbEr    MEl  NN",
      "zbbEiOPP AEl   A",
      "zbbEEEEEEEEl   Q"
    ],
    [
      "zab        h    ",
      "zabR       l    ",
      "zbb        d    ",
      "zbb       sl    ",
      "zbbS       T    ",
      "zbbs       T    ",
      "zbbU      VT    ",
      "zbbS      mT    ",
      "zbb        l    ",
      "zbbE     WEdlTTT",
      "zbbE     XEl    ",
      "zbbE      EY    ",
      "zbbE      EY    ",
      "zbbE     ZEY   0",
      "zbbE     1EY    ",
      "zbbEEEEEEEEl    "
    ],
    [
      "zab        h    ",
      "zab        l    ",
      "zbb        d    ",
      "zbb        l    ",
      "zbb        T    ",
      "zbb        T    ",
      "zbb        T    ",
      "zbb        T    ",
      "zbb        l    ",
      "zbbE      EdlTTT",
      "zbbY      El    ",
      "zbbY     2E3    ",
      "zbbY     2E3    ",
      "zbbY      E3    ",
      "zbbE  44  E3    ",
      "zbbEEEEEEEEl    "
    ],
    [
      "zab        l    ",
      "zab        l    ",
      "zbb        d    ",
      "zbb        l    ",
      "zbb        l    ",
      "zbb        l    ",
      "zbb        l    ",
      "zbb        l    ",
      "zbb        l    ",
      "zbbE      Edllll",
      "zbb3      El    ",
      "zbb3      El    ",
      "zbb3      El    ",
      "zbb3      El    ",
      "zbbE      El    ",
      "zbbEEEEEEEEl    "
    ],
    [
      "zab5565575589799",
      "zab5565575589999",
      "zab55555555d9999",
      "zab5555555589999",
      "zab5575565589699",
      "zab5565575589799",
      "zab5575565589799",
      "zab5565575589@99",
      "zab5555555589999",
      "zabE@@@@@@Ed####",
      "zabE@    @E85555",
      "zabE@$  $@E85555",
      "zabE@    @E85555",
      "zabE@    @E85577",
      "zabE@@@@@@E85575",
      "zabEEEEEEEE855@5"
    ]
  ]
}