{
  "name": "multi_megatower1_1_floor4",
  "refpalette": "c70cities:multi_megatower1_1_floor4_palette",
  "xsize": 16,
  "zsize": 16,
  "slices": [
    [
      "            ab  ",
      "            cb  ",
      "            cbde",
      "            cbff",
      "           ghibb",
      "            abbb",
      "            abjj",
      "            abjj",
      "            cbjj",
      "            cbjj",
      "            cbbb",
      "           ghibb",
      "            abbb",
      "            abbb",
      "            abbb",
      "            cbbb"
    ],
    [
      "            ak  ",
      "            ckd ",
      "            ckl ",
      "            ck  ",
      "           ghicm",
      "            an  ",
      "            an  ",
      "            an  ",
      "            cn  ",
      "            cnoo",
      "            cnpq",
      "           ghip ",
      "            anr ",
      "            anss",
      "            ant ",
      "            cnuw"
    ],
    [
      "            akf ",
      "            ckl ",
      "            ck  ",
      "            ck  ",
      "           ghicx",
      "            an  ",
      "            an  ",
      "            ay  ",
      "            cy  ",
      "            cnoo",
      "            cnp ",
      "           ghip ",
      "            anA ",
      "            anss",
      "            anB ",
      "            cn  "
    ],
    [
      "            aklC",
      "            ck  ",
      "            ck  ",
      "            ck D",
      "           ghicc",
      "            an  ",
      "            an  ",
      "            aE  ",
      "            cE  ",
      "            cnoo",
      "            cnpF",
      "           ghip ",
      "            an  ",
      "            anss",
      "            an  ",
      "            cn  "
    ],
    [
      "            aI e",
      "            cI C",
      "            cI  ",
      "            cI  ",
      "           ghicc",
      "            an  ",
      "            an  ",
      "            an  ",
      "            cn  ",
      "            cnoo",
      "            cnpJ",
      "           ghip ",
      "            anK ",
      "            anss",
      "            anK ",
      "            cn  "
    ],
    [
      "            aL  ",
      "            cL e",
      "            cL f",
      "            cLdf",
      "           ghiMM",
      "            aLNN",
      "            aLNN",
      "            aLNN",
      "            cLNN",
      "            cLOO",
      "            cLbb",
      "           ghiMM",
      "            aLbb",
      "            aLbb",
      "            aLKK",
      "            cL  "
    ]
  ]
}