{
  "name": "multi_laboratory1_2_base4",
  "refpalette": "c70cities:multi_laboratory1_2_base4_palette",
  "xsize": 16,
  "zsize": 16,
  "slices": [
    [
      "vabcccccccccccd ",
      "vabcccccccccccd ",
      "vabcccccccccccd ",
      "vabcccccccccccde",
      "vabccccccccfcccd",
      "vabccccccccccccd",
      "vabccccccccccccc",
      "vabccccccccccccc",
      "vabcccc!cccccccc",
      "vabccccccccccccc",
      "vabccccccccccccc",
      "vabccccccccfcccc",
      "vabccccccccccccc",
      "vabccccccccccccc",
      "vabccccccccccccc",
      "vabccccccccccccc"
    ],
    [
      "vabghiiii  j  k ",
      "vablmnnnno p  k ",
      "vablqrstru u  k ",
      "vab  wwww  x  ke",
      "vab  nnnn  f  ek",
      "vab qrysru x  Ak",
      "vab  wwww  x    ",
      "vab  nnnn  x    ",
      "vab qr Bru x    ",
      "vab  wwww  x    ",
      "vab    C  Dx  E ",
      "vabxxxFIxxxfe   ",
      "vab     J  x    ",
      "vabKL  M   u    ",
      "vabNN      j    ",
      "vabLOM     p    "
    ],
    [
      "vab  P QD  R  k ",
      "vab  nnnn  S  k ",
      "vab qT  Tu u  k ",
      "vab  wwww  x  ke",
      "vab  nnnn  f  Uk",
      "vab qV  Vu x   k",
      "vab  wwww  W    ",
      "vab  nnnn  W    ",
      "vab qV  Vu W    ",
      "vab  wwww  W    ",
      "vab        x    ",
      "vabxxxXYxxxfU   ",
      "vab        x    ",
      "vab        u    ",
      "vabZ       R    ",
      "vab        S    "
    ],
    [
      "vab        u  k ",
      "vab  nnnn  u  k ",
      "vab q0  0u u  k ",
      "vab  wwww  x  ke",
      "vab  nnnn  f  Uk",
      "vab q1  1u x   k",
      "vab  wwww  W    ",
      "vab  nnnn  W    ",
      "vab q1  1u W    ",
      "vab  wwww  W    ",
      "vab        x    ",
      "vabxxxxxxxxfU   ",
      "vab        x    ",
      "vab        u    ",
      "vab        u    ",
      "vab        u    "
    ],
    [
      "vab        x  k ",
      "vab        x  k ",
      "vab22222222x  k ",
      "vab     2  x  ke",
      "vab     2  f   k",
      "vab  2  2  x   k",
      "vab  2  2  x    ",
      "vab  2  2  x    ",
      "vab22222222x    ",
      "vab        x    ",
      "vab        x    ",
      "vabxxxxxxxxf    ",
      "vab        x    ",
      "vab        x    ",
      "vab        x    ",
      "vab        x    "
    ],
    [
      "vab33433533677k ",
      "vab33533433677k ",
      "vab33433433677k ",
      "vab33333333677ke",
      "vab33333333f777k",
      "vab334334336777k",
      "vab3343343367777",
      "vab3343343367777",
      "vab3343343367777",
      "vab3333333367777",
      "vab3333333367777",
      "vabxxxxxxxxf7777",
      "vab3333333367777",
      "vab3333333367477",
      "vab3343343367477",
      "vab3343343367477"
    ]
  ]
}