{
  "name": "multi_convenientstore_2_ground",
  "refpalette": "c70cities:multi_convenientstore_2_ground_palette",
  "xsize": 16,
  "zsize": 16,
  "slices": [
    [
      "GGGGGGGGGGGaHHHG",
      "GGGGGGGGGGGaHHHG",
      "aaaaaaaaaaaaHHHG",
      "HHHHHHHHHHHHHHHG",
      "HHHHHHHHHHHHHHHG",
      "HHHHHHHHHHHHHHHG",
      "HHHHHHHHHHHHHHHG",
      "HHHHHHHHHHHHHHHG",
      "HHHHHHHHHHHHHHHG",
      "HHHHHHHHHHHHHHHG",
      "HHHHHHHHHHHHHHHG",
      "HHHHHHHHHHHHHHHG",
      "HHHHHHHHHHHHHHHG",
      "HHHHHHHHHHHHHHHb",
      "HHHHHHHHHHHHHHHb",
      "HHHHHHHHHHHHHHHb"
    ],
    [
      " c     c  cd    ",
      "           d    ",
      "ddddd ddd dd    ",
      "efefefefefe     ",
      "        g       ",
      "hihihihihih     ",
      "               c",
      "                ",
      "                ",
      "                ",
      "efefefefefe     ",
      "                ",
      "hihihihihih     ",
      "dddddddddddd   j",
      "aaaaaaaaaaaakkkj",
      "aaaaaaaaaaaakkkj"
    ],
    [
      "                ",
      "                ",
      "                ",
      "                ",
      "                ",
      "                ",
      "                ",
      "                ",
      "                ",
      "                ",
      "                ",
      "                ",
      "                ",
      "                ",
      "       l        ",
      " mn n nlopoo    "
    ],
    [
      "                ",
      "                ",
      "                ",
      "                ",
      "                ",
      "                ",
      "                ",
      "                ",
      "                ",
      "                ",
      "                ",
      "                ",
      "                ",
      "                ",
      "       l        ",
      " mn n nloqoo    "
    ],
    [
      "                ",
      "                ",
      "                ",
      "                ",
      "                ",
      "                ",
      "                ",
      "                ",
      "                ",
      "                ",
      "                ",
      "                ",
      "                ",
      "                ",
      "       l        ",
      "rsn n nlo oo    "
    ],
    [
      "                ",
      "                ",
      "                ",
      "                ",
      "                ",
      "                ",
      "                ",
      "                ",
      "                ",
      "                ",
      "                ",
      "                ",
      "                ",
      "                ",
      "       l        ",
      "  n n nlo oo    "
    ]
  ]
}