{
  "name": "multi_cafe_0_ground",
  "refpalette": "c70cities:multi_cafe_0_ground_palette",
  "xsize": 16,
  "zsize": 16,
  "slices": [
    [
      "GGGGGGGGGGGGGGGG",
      "GGGGGGGGGGGGGGGG",
      "GGaaaaaaaaaaaaaa",
      "GGaaaaaaaaaaaaaa",
      "GGaabbbbbbbbbbbb",
      "GGaabcccccccbccc",
      "GGaabcccccccGccc",
      "GGaabcccccccGccc",
      "GGaabcccccccGccc",
      "GGaabcccccccbccc",
      "GGaabcccccccGccc",
      "GGaabcccccccGccc",
      "GGaabcccccccGccc",
      "GGaabcccccccbccc",
      "GGaabcccccccbccc",
      "GGaabccccccccccc"
    ],
    [
      " de e fe gee  hi",
      "eiegifh   hfdgif",
      "hd              ",
      "de              ",
      "ig  bjjjjbkklkkk",
      "f   mnnnno  l   ",
      "e   mnnnno  p qr",
      " d  mnnnno      ",
      "gf  mnnnno  s   ",
      "i   bnnnno  l qr",
      "d   mnnnno      ",
      " h  mnnnno  s   ",
      "ig  mnnnno  p qr",
      " e  tnnnno  l   ",
      "e   onnnno  l   ",
      "    onnnno      "
    ],
    [
      "                ",
      "                ",
      "                ",
      "                ",
      "    kkkkkkk l   ",
      "    k       l   ",
      "    ku u    w   ",
      "    kxxx        ",
      "    ky y    A   ",
      "    k       l   ",
      "    ku u        ",
      "    kxxx    A   ",
      "    ky y    w   ",
      "    B       l   ",
      "            l   ",
      "                "
    ],
    [
      "                ",
      "                ",
      "                ",
      "                ",
      "            l   ",
      "            l   ",
      "                ",
      "                ",
      "                ",
      "            l   ",
      "                ",
      "                ",
      "                ",
      "            l   ",
      "            l   ",
      "                "
    ],
    [
      "                ",
      "                ",
      "                ",
      "                ",
      "            l   ",
      "            l   ",
      "                ",
      "                ",
      "                ",
      "            l   ",
      "                ",
      "                ",
      "                ",
      "            l   ",
      "            l   ",
      "                "
    ],
    [
      "                ",
      "                ",
      "                ",
      "                ",
      "            l   ",
      "            l   ",
      "                ",
      "                ",
      "                ",
      "            l   ",
      "                ",
      "                ",
      "                ",
      "            l   ",
      "            l   ",
      "                "
    ]
  ]
}