{
  "name": "multi_hospital_0_base2",
  "refpalette": "c70cities:multi_hospital_0_base2_palette",
  "xsize": 16,
  "zsize": 16,
  "slices": [
    [
      "vvvvvvvvvvvvvvvv",
      "vvvvvvvvvvvvvvvv",
      "vvvvvvvvvvvvvvvv",
      "vvvvvvvvvvvvvvvv",
      "vvvvvvvvvvvvvvvv",
      "vvvvvvvvvvvvvvvv",
      "vvvvvvvvvvvvvvvv",
      "vvvvvvvvvvvvvvvv",
      "vvvvvvvvvaaaavvv",
      "vvvvvvvvvabbavvv",
      "vvvvvvvvvabbavvv",
      "vvvvvvvvvaacavvv",
      "vvvvvvvvvvvvvvvv",
      "vvvvvvvvvvvvvvvv",
      "vvvvvvvvvvvvvvvv",
      "vvvvvvvvvvvvvvvv"
    ],
    [
      "vvvvvvvvvvvvvvvv",
      "vddddddddddddddd",
      "vddddddddddddddd",
      "vddddddddeeeeeee",
      "vddddddddeffffff",
      "vddddddddeffffff",
      "vddddddddeffffff",
      "vddddddddeffffff",
      "vddddddddfaaafff",
      "vddddddddabbgfff",
      "vddddddddabbgfff",
      "vddddddddabaafff",
      "vddddddddevvefff",
      "vddddddddeffffff",
      "vddddddddeffffff",
      "vddddddddeffffff"
    ],
    [
      "vvvvvvvvvvvvvvvv",
      "vddddddddddddddd",
      "vddddddddddddddd",
      "vddddddddeeeeeee",
      "vdddddddde  h h ",
      "vddddddddeijjjj ",
      "vdddddddde jjjjk",
      "vdddddddde l l  ",
      "vddddddddfaaa   ",
      "vddddddddam n   ",
      "vdddddddda  o   ",
      "vdddddddda aa   ",
      "vddddddddevvp   ",
      "vddddddddeppp   ",
      "vdddddddde      ",
      "vddddddddejk  j "
    ],
    [
      "vvvvvvvvvvvvvvvv",
      "vddddddddddddddd",
      "vddddddddddddddd",
      "vddddddddeeeeeee",
      "vdddddddde q    ",
      "vdddddddde r  s ",
      "vdddddddde t r  ",
      "vdddddddde      ",
      "vddddddddfaaa   ",
      "vdddddddda  u   ",
      "vdddddddda  w   ",
      "vdddddddda aax  ",
      "vddddddddevvp   ",
      "vddddddddeppp   ",
      "vdddddddde      ",
      "vdddddddde    y "
    ],
    [
      "vvvvvvvvvvvvvvvv",
      "vddddddddddddddd",
      "vddddddddddddddd",
      "vddddddddeeeeeee",
      "vdddddddde      ",
      "vdddddddde      ",
      "vdddddddde      ",
      "vdddddddde      ",
      "vddddddddfaaa   ",
      "vdddddddda  A   ",
      "vdddddddda  A   ",
      "vdddddddda aa   ",
      "vddddddddevvp   ",
      "vddddddddeppp   ",
      "vdddddddde      ",
      "vdddddddde      "
    ],
    [
      "vvvvvvvvvvvvvvvv",
      "vddddddddddddddd",
      "vddddddddddddddd",
      "vddddddddeeeeeee",
      "vddddddddeBBBBBB",
      "vddddddddeBBBBBB",
      "vddddddddeBBBBBB",
      "vddddddddeBBBBBB",
      "vddddddddfaaaBBB",
      "vdddddddda  aBBB",
      "vdddddddda  aBBB",
      "vdddddddda caBBB",
      "vddddddddevvpBBB",
      "vddddddddepppBBB",
      "vddddddddeBBBBBB",
      "vddddddddeBBBBBB"
    ]
  ]
}