{
  "name": "multi_megatower1_4_floor2",
  "refpalette": "c70cities:multi_megatower1_4_floor2_palette",
  "xsize": 16,
  "zsize": 16,
  "slices": [
    [
      "a   bbbbbbbbbbbb",
      "a   bbbbbbbbbbbb",
      "a   bbbbbbbbbbbb",
      "cdeebbbbbbbbbbbb",
      "bbbbfbbbbbbfbbbb",
      "bbbbbbbbbbbbbbbb",
      "bbbbbbbbbbbbbbbb",
      "bbbbbbbbbbbbbbbb",
      "bbbbbbbbbbbbbbbb",
      "bbbbbbbbbbbbbbbb",
      "bbbbbbbbbbbbbbbb",
      "bbbbfbbbbbbfbbbb",
      "bbbbbbbbbbbbbbbb",
      "bbbbbbbbbbbbbbbb",
      "bbbbbbbbbbbbbbbb",
      "bbbbbbbbbbbbbbbb"
    ],
    [
      "a   ag hih jkkl ",
      "a   am hih jk ll",
      "a   am hih j    ",
      "aenna  ooopj    ",
      "qrstf    ppf    ",
      "    u   pppj    ",
      "    wwwxywwA    ",
      "           B    ",
      "           C    ",
      "    DDDEFDDA    ",
      "    uI    Jj    ",
      "EKDDfI    Jf    ",
      "   Lu      j    ",
      "   Lu M  N j    ",
      "   LuO OO Oj   P",
      "   Lu Q  Q j RRR"
    ],
    [
      "a   am mmm j  ST",
      "a   am gmm j  SS",
      "a   a  mmm j    ",
      "ae  a  ooo j    ",
      "q UVf     pf    ",
      "    uW   ppj    ",
      "    wwwXYwwA    ",
      "           Z    ",
      "           0    ",
      "    DDD12DDA    ",
      "    uI    Jj    ",
      "13DDf      f    ",
      "    u      j    ",
      "   iu 4  4 j    ",
      "    uQQQQQQj    ",
      "    uQQQQ Qj    "
    ],
    [
      "a   am  m  5   T",
      "a   a  mmm 5    ",
      "a   a   m  5    ",
      "aeeea  ooo 5    ",
      "q6  f      f7777",
      "    u     p89777",
      "    wwwwwwwA7777",
      "           A7777",
      "           A7777",
      "    DDDDDDDA7777",
      "    u      89777",
      "DDDDf      f7777",
      "   @u      57777",
      "   #u      57777",
      "    uQQQQQQ57777",
      "    uQQQQ Q57777"
    ],
    [
      "a   a      j   R",
      "a   a      j    ",
      "a   a      j    ",
      "aeeea      j    ",
      "qqqqf$9$$9$f%%%%",
      "    ^$$$$$$&%***",
      "    wwwwwwwA(***",
      "           A%***",
      "           A%***",
      "    DDDDDDDA(***",
      "    ^$$$$$$&%***",
      "DDDDf$9$$9$f%***",
      "    u      j%***",
      "    u      j(***",
      "    uQQQQQQj%***",
      "    uQQQQ Qj%***"
    ],
    [
      ")   )      )%%%%",
      ")   )      )%%%%",
      ")   )      )%%%%",
      ")e++)------)%%%%",
      "[[[[f[[[[[[f%%%%",
      "    )]]]]]])%***",
      "    ) ]  ] )%***",
      "    ) ]  ] )%***",
      "    ) ]  ] )%***",
      "    ) ]  ] )%***",
      "]]{])]]]]]])%***",
      "[[[[f[[[[[[f%***",
      "}}}})}}}}}})%***",
      "    )      )%***",
      "    )QQQQQQ)%***",
      "    )QQQQQQ)%***"
    ]
  ]
}