{
  "name": "multi_laboratory1_9_base1",
  "refpalette": "c70cities:multi_laboratory1_9_base1_palette",
  "xsize": 16,
  "zsize": 16,
  "slices": [
    [
      "aaaaaaaaaaaaaaaa",
      "aaaaaaaaaaaaaaaa",
      "aaaaaaaaaaaaaaaa",
      "aaaaaaaaaaaaaaaa",
      "aaaaaaaaaaaaaaaa",
      "aaaaaaaaaaaaaaaa",
      "aaaaaaaaaaaaaaaa",
      "aaaaaaaaaaaaaaaa",
      "aaaaaaaaaaaaaaaa",
      "aaaaaaaaaaaaaaaa",
      "aaaaaaaaaaaaaaaa",
      "aaaaaaaaaaaaaaaa",
      "aaaaaaaaaaaaaaaa",
      "bbbbbbbbbbbbbbbb",
      "cccccccccccccccc",
      "vvvvvvvvvvvvvvvv"
    ],
    [
      "deeedfgeefgeeeed",
      "ehhi        jhhe",
      "ehk          khe",
      "ek            ke",
      "e  lm  lm  lm  e",
      "e              e",
      "e  lm  lm  lm  e",
      "d              d",
      "e    nnnnnn    e",
      "e  nnnnddnnnn  e",
      "eo nnnnnnnnnn oe",
      "ehonnnnnnnnnnohe",
      "ehhddddddddddhhe",
      "bbbbbbbbbbbbbbbb",
      "cccccccccccccccc",
      "vvvvvvvvvvvvvvvv"
    ],
    [
      "deeedpqeepqeeeed",
      "e!r          rre",
      "er            re",
      "e              e",
      "e              e",
      "e              e",
      "e              e",
      "d              d",
      "e              e",
      "e      ss      e",
      "e              e",
      "er            re",
      "e!rdttttttttdr!e",
      "bbbbbbbbbbbbbbbb",
      "cccccccccccccccc",
      "vvvvvvvvvvvvvvvv"
    ],
    [
      "deeeduueeuueeeed",
      "err          rre",
      "e              e",
      "e              e",
      "e              e",
      "e              e",
      "e              e",
      "d              d",
      "e              e",
      "e              e",
      "e              e",
      "e              e",
      "errdwwwwwwwwdrre",
      "bbbbbbbbbbbbbbbb",
      "cccccccccccccccc",
      "vvvvvvvvvvvvvvvv"
    ],
    [
      "deeedeeeeeeeeeed",
      "er            re",
      "e              e",
      "e              e",
      "e              e",
      "e              e",
      "e              e",
      "d              d",
      "e              e",
      "e              e",
      "e  x        x  e",
      "e              e",
      "er dyyyyyyyyd re",
      "bbbbbbbbbbbbbbbb",
      "cccccccccccccccc",
      "vvvvvvvvvvvvvvvv"
    ],
    [
      "deeedeeeeeedeeed",
      "eAAAAAAAAAAAAAAe",
      "eAAAAAAAAAAAAAAe",
      "eAAABAAAAAABAAAe",
      "eAAABAAAAAABAAAe",
      "eAAABAAAAAACAAAe",
      "eAAABAAAAAABAAAe",
      "dAAABAAAAAABAAAd",
      "eAAAAAAAAAAAAAAe",
      "eAAAAAAAAAAAAAAe",
      "eAAxAAAAAAAAxAAe",
      "eAAAAAAAAAAAAAAe",
      "eAADDDDDDDDDDAAe",
      "bbbbbbbbbbbbbbbb",
      "cccccccccccccccc",
      "vvvvvvvvvvvvvvvv"
    ]
  ]
}