{
  "name": "multi_communitycenter_0_ground",
  "refpalette": "c70cities:multi_communitycenter_0_ground_palette",
  "xsize": 16,
  "zsize": 16,
  "slices": [
    [
      "aaaaaaaaaaaaaaaa",
      "aaaaaaaaaaaaaaaa",
      "aabccccccccccccc",
      "aabccccccccccccc",
      "aabccccccccccccc",
      "aabddddddddddddd",
      "aabddddddddddddd",
      "aabddddddddddddd",
      "aabddddddddddddd",
      "aabddddddddddddd",
      "aabddddddddddddd",
      "aabddddddddddddd",
      "aabeeeeeeeeeeeee",
      "aafegggghgggghgg",
      "aafijjjjjjjjjjjj",
      "aafikjjjjjjjjjjj"
    ],
    [
      "                ",
      "                ",
      "  lmno n  o     ",
      "  lmnn  o   o   ",
      "  fmppp qo o ppp",
      "  fccccccccccccc",
      "  fccccccccccccc",
      "  fccccccccccccc",
      "  fccccccccccccc",
      "  fddddddddddddd",
      "  fddddddddddddd",
      "  fddddddddddddd",
      "  ferrrrrrrrrrrr",
      "  fe!s   t    t ",
      "  fs            ",
      "  fu            "
    ],
    [
      "                ",
      "                ",
      "                ",
      "                ",
      "   m            ",
      "   m n  n       ",
      "  lmo        n  ",
      "  lmqo          ",
      "  fmo o pppppppq",
      "  fccccccccccccc",
      "  fwcccccccccccc",
      "  fwcccccccccccc",
      "  fccccccccccccc",
      "  feeeeeeeeeeeee",
      "  fxxxxxxxxxxxxx",
      "  yxxxxxxxxxxxxx"
    ],
    [
      "                ",
      "                ",
      "                ",
      "                ",
      "                ",
      "                ",
      "                ",
      "                ",
      "   m            ",
      "   mn       n   ",
      "  lm      n  n  ",
      "  lm o     q   n",
      "  fmoppppppp n o",
      "  fccccccccccccc",
      "  fccccccccccccc",
      "  fccccccccccccc"
    ],
    [
      "                ",
      "                ",
      "                ",
      "                ",
      "                ",
      "                ",
      "                ",
      "                ",
      "                ",
      "                ",
      "                ",
      "                ",
      "   m            ",
      "   mqn          ",
      "  lmo n n      n",
      "  lmn ~         "
    ],
    [
      "                ",
      "                ",
      "                ",
      "                ",
      "                ",
      "                ",
      "                ",
      "                ",
      "                ",
      "                ",
      "                ",
      "                ",
      "                ",
      "                ",
      "                ",
      "     ~~         "
    ]
  ]
}