{
  "name": "multi_condo1_3_ground",
  "refpalette": "c70cities:multi_condo1_3_ground_palette",
  "xsize": 16,
  "zsize": 16,
  "slices": [
    [
      "GGGGGGGGGGGGGGGG",
      "GGGGGGGGGGGGGGGG",
      "aaaaaaaaaaaaaGGG",
      "bbbbbba     aGGG",
      "bbbbbba     aGGG",
      "bbbbbba     aGGG",
      "bbbbbba     aGGG",
      "bbbbbba     aGGG",
      "bbbbbba     aGGG",
      "bbbbbba     aGGG",
      "bbbbbba     accG",
      "bbbbbba  d  abGG",
      "bbbbbba  d  abGG",
      "bbbbbbaeea  afff",
      "bbbbbbaeeaaaaGGG",
      "bbbbbbaHHHHHHHHH"
    ],
    [
      "                ",
      "                ",
      "aaaaaaaaaaaaa g ",
      "hhhhhha     a   ",
      "aaaaaaa     a g ",
      " ijk la     a   ",
      " imk la     a g ",
      " imk na     a   ",
      " iok pa     a g ",
      " i!k qa     a   ",
      " imk la     acc ",
      " irk la     a   ",
      "  s  ta     a   ",
      "u    wa     afff",
      "xxxxxba  aaaa   ",
      "     ya         "
    ],
    [
      "                ",
      "                ",
      "              A ",
      "      a         ",
      "BBBBBBa       A ",
      "  C   a         ",
      "  D  Ea       A ",
      "  F  Ia         ",
      "  C  Ja       A ",
      "  C  Ka         ",
      "  L  Ma     acc ",
      "  C  Na     a   ",
      "      a     a   ",
      "      a     afff",
      "OOOOOba  aaaa   ",
      "     Aa         "
    ],
    [
      "                ",
      "                ",
      "              O ",
      "      a         ",
      "BBBBBBa       O ",
      "     Pa         ",
      "    QRa       O ",
      "    QSa         ",
      "    QTa       O ",
      "     Ua         ",
      "     Va     acc ",
      "     Va     a   ",
      "     Va     a   ",
      "     Va     afff",
      "     ba  aaaa   ",
      "      a         "
    ],
    [
      "                ",
      "                ",
      "              O ",
      "      a         ",
      "BBBBBBa       O ",
      "      a         ",
      "     Wa       O ",
      "     Wa         ",
      "     Wa       O ",
      "      a         ",
      "      a     acc ",
      "      a     a   ",
      "      a     a   ",
      "      a     afff",
      "     baaaaaaa   ",
      "      a     aX  "
    ],
    [
      "                ",
      "                ",
      "              Y ",
      "      a         ",
      "BBBBBBa       Y ",
      "      a         ",
      "      a       Y ",
      "      a         ",
      "      a       Y ",
      "      a         ",
      "      a     acc ",
      "      a     a   ",
      "      a     a   ",
      "      a     afff",
      "     baaaaaaa   ",
      "      aZZZZZa   "
    ]
  ]
}