{
  "name": "multi_condo1_4_floor3",
  "refpalette": "c70cities:multi_condo1_4_floor3_palette",
  "xsize": 16,
  "zsize": 16,
  "slices": [
    [
      "aaaaabcddeeefg  ",
      "hhhiabcffffffjj ",
      "   kabclllllfg  ",
      "   kabclllllfg  ",
      "   kabclllllfg  ",
      "   kabclllllfjj ",
      "   kabcffffffg  ",
      "   kabc     cg  ",
      "   kabc     cg  ",
      "   kabc     fg  ",
      "   kabm     fjj ",
      "   kabnffffffg  ",
      "   kabcck   fg  ",
      "   kabcco   fg  ",
      "pppqabcffffffjj ",
      "aaaaabcddeeefg  "
    ],
    [
      "      frrstuf   ",
      "wwww  fffffffjj ",
      "   w  x     f   ",
      "   w  f     y   ",
      "   w  f  AB f   ",
      "   w  f CDD fjj ",
      "   w  fffffff   ",
      "   w  f     E   ",
      "   w  F     E   ",
      "   w  I     f   ",
      "   w Jf     fjj ",
      "   w  fffffff   ",
      "   w  f     y   ",
      "   w  K Lo  f   ",
      "wwww  fffffffjj ",
      "      fMMsNOf   "
    ],
    [
      "      fPQs  f   ",
      "      fffffffjj ",
      "      R     f   ",
      "      fS    T   ",
      "      f  UV f   ",
      "      fWWDD fjj ",
      "      fffffff   ",
      "      f     E   ",
      "      X     E   ",
      "      Y     f   ",
      "      f     fjj ",
      "      fffffff   ",
      "      f     T   ",
      "      Z  Lo f   ",
      "      fffffffjj ",
      "      f01s  f   "
    ],
    [
      "      f  s  f   ",
      "      fffffffjj ",
      "      2     f   ",
      "      f     T   ",
      "      f     f   ",
      "      fW 33 fjj ",
      "      fffffff   ",
      "     !f     E   ",
      "      2     E   ",
      "      2     f   ",
      "     4f     fjj ",
      "      fffffff   ",
      "      f   2oT   ",
      "      2   Lcf   ",
      "      fffffffjj ",
      "      f !s  f   "
    ],
    [
      "      f  s  f   ",
      "      fffffffjj ",
      "      f     f   ",
      "      f     f   ",
      "      f     f   ",
      "      fW5   fjj ",
      "      fffffff   ",
      "     6f     E   ",
      "      f     E   ",
      "      f     f   ",
      "     6f     fjj ",
      "      fffffff   ",
      "      f  2k f   ",
      "      f     f   ",
      "      fffffffjj ",
      "      f  s  f   "
    ],
    [
      "      flllllf   ",
      "      fffffffjj ",
      "      fW    f   ",
      "      fW    f   ",
      "      fW    f   ",
      "      fWWWWWfjj ",
      "      fffffff   ",
      "      f     E   ",
      "      f     E   ",
      "      f     f   ",
      "      f     fjj ",
      "      fffffff   ",
      "      f 2k  f   ",
      "      f     f   ",
      "      fffffffjj ",
      "      flllllf   "
    ]
  ]
}