{
  "name": "multi_condo1_4_floor4",
  "refpalette": "c70cities:multi_condo1_4_floor4_palette",
  "xsize": 16,
  "zsize": 16,
  "slices": [
    [
      "aaaaabcddeeefg  ",
      "hhhiabcffffffjj ",
      "   kabclllllfg  ",
      "   kabclllllfg  ",
      "   kabclllllfg  ",
      "   kabclllllfjj ",
      "   kabcffffffg  ",
      "   kabc     cg  ",
      "   kabc     cg  ",
      "   kabc     fg  ",
      "   kabm     fjj ",
      "   kabnffffffg  ",
      "   kabcck   fg  ",
      "   kabcco   fg  ",
      "pppqabcffffffjj ",
      "aaaaabcddeeefg  "
    ],
    [
      "      frrstuf   ",
      "wwww  fffffffjj ",
      "   w  x     f   ",
      "   w  f     y   ",
      "   w  f  ABCf   ",
      "   w  f DEE!fjj ",
      "   w  fffffff   ",
      "   w  f     F   ",
      "   w  I     F   ",
      "   w  J     f   ",
      "   w Kf     fjj ",
      "   w  fffffff   ",
      "   w  f     y   ",
      "   w  L Mo  f   ",
      "wwww  fffffffjj ",
      "      fNNsOPf   "
    ],
    [
      "      fQRs  f   ",
      "      fffffffjj ",
      "      S     f   ",
      "      fT    U   ",
      "      f  VW f   ",
      "      fXXEE fjj ",
      "      fffffff   ",
      "      f     F   ",
      "      Y     F   ",
      "      Z     f   ",
      "      f     fjj ",
      "      fffffff   ",
      "      f     U   ",
      "      0  Mo f   ",
      "      fffffffjj ",
      "      f12s  f   "
    ],
    [
      "      f 3s4 f   ",
      "      fffffffjj ",
      "      5     f   ",
      "      f     U   ",
      "      f     f   ",
      "      fX 66 fjj ",
      "      fffffff   ",
      "     7f     F   ",
      "      5     F   ",
      "      5     f   ",
      "     8f     fjj ",
      "      fffffff   ",
      "      f   5oU   ",
      "      5   Mcf   ",
      "      fffffffjj ",
      "      f !s9 f   "
    ],
    [
      "      f  s  f   ",
      "      fffffffjj ",
      "      f     f   ",
      "      f     f   ",
      "      f     f   ",
      "      fX    fjj ",
      "      fffffff   ",
      "     @f     F   ",
      "      f     F   ",
      "      f     f   ",
      "     @f     fjj ",
      "      fffffff   ",
      "      f  5k f   ",
      "      f     f   ",
      "      fffffffjj ",
      "      f  s  f   "
    ],
    [
      "      flllllf   ",
      "      fffffffjj ",
      "      fX  CCf   ",
      "      fX   Cf   ",
      "      fXC   f   ",
      "      fXXXXXfjj ",
      "      fffffff   ",
      "      f     F   ",
      "      f     F   ",
      "      f     f   ",
      "      f     fjj ",
      "      fffffff   ",
      "      f#5k  f   ",
      "      f     f   ",
      "      fffffffjj ",
      "      flllllf   "
    ]
  ]
}