{
  "name": "multi_laboratory1_11_base4",
  "refpalette": "c70cities:multi_laboratory1_11_base4_palette",
  "xsize": 16,
  "zsize": 16,
  "slices": [
    [
      "aaaaaaaaaaaaabcz",
      "aaaaaaaaaaaaabcz",
      "aaaaaaaaaaaaabcz",
      "aaaaaaaaaaaaabcz",
      "aaaaaaaaaaaaabcz",
      "aaaaaaaaaaaaabcz",
      "aaaadaaaaaaaabcz",
      "aaaaaaaaaaaaabcz",
      "aaaaaaaaaaaaabcz",
      "aaaaaaaaaaaaabcz",
      "aaaaaaaaaaaaabcz",
      "aaaaaaaaaaaaabcz",
      "eaaaaaaaaaaaabcz",
      "eaaadaaaaaaaabcz",
      "feaaaaaaaaaaabcz",
      " eaaaaaaaaaaabcz"
    ],
    [
      "    ghiiiiiihbcz",
      "    gj      ibcz",
      "    gk      ibcz",
      "    g       ibcz",
      "    l       ibcz",
      "    gmnnnnnnhbcz",
      "   fdggggggggbcz",
      "o   gpp p p qbcz",
      "    g        bcz",
      "    g  r    sscz",
      "    gtuuu wsxycz",
      "    gAuuu BCxycz",
      "DE  g FI   ~sscz",
      "Df  dJw    Kqbcz",
      "fD  g        bcz",
      " D  L       sscz"
    ],
    [
      "    ghiiiiiihbcz",
      "    M       ibcz",
      "    MN      ibcz",
      "    g       ibcz",
      "    O       ibcz",
      "    g      Phbcz",
      "   Qdggggggggbcz",
      "    g       qbcz",
      "    M       Rbcz",
      "    M       Dscz",
      "    M SST  Dxycz",
      "    MUSwS   xycz",
      "D   g       Kscz",
      "DQ  d       qbcz",
      "fD  g       Rbcz",
      " D  L       Dscz"
    ],
    [
      "    ghVVVVVVhbcz",
      "    W       Xbcz",
      "    W       Ybcz",
      "    g       Zbcz",
      "    W        bcz",
      "    g       hbcz",
      "   Qdggggggggbcz",
      "    g       qbcz",
      "    M        bcz",
      "    M       Dscz",
      "    M      Dxycz",
      "    M      0xycz",
      "D   g       Dscz",
      "DQ  d       qbcz",
      "fD  g        bcz",
      " D  L       Dscz"
    ],
    [
      "    gh      hbcz",
      "    g        bcz",
      "    g        bcz",
      "    g        bcz",
      "    g        bcz",
      "    g       hbcz",
      "    dggggggggbcz",
      "    g  1  1 2bcz",
      "    g       Rbcz",
      "    g       Dscz",
      "    g      D3ycz",
      "    g      D3ycz",
      "D   g       Dscz",
      "D   d       2bcz",
      "fD  g       Rbcz",
      " D  g       Dscz"
    ],
    [
      "4444W55555555bcz",
      "4464W575555!5bcz",
      "4464W55555555bcz",
      "4464W55555555bcz",
      "4464W57555575bcz",
      "4444W55555555bcz",
      "4444dggggggggbcz",
      "4444W88888888bcz",
      "4444W99999999bcz",
      "4444W9969969sscz",
      "4444W99699@s#ycz",
      "4444W996996s#ycz",
      "D444W99@99@9sscz",
      "D444d99999999bcz",
      "fD44W99999999bcz",
      " D44W9969969sscz"
    ]
  ]
}