{
  "name": "multi_laboratory1_12_base7",
  "refpalette": "c70cities:multi_laboratory1_12_base7_palette",
  "xsize": 16,
  "zsize": 16,
  "slices": [
    [
      "abaaaaaaaaaaaaaz",
      "abaaaaaaaaaaaaaz",
      "abaaaaaaaaaaaaaz",
      "bbaaaaaaaaaaaaaz",
      "baaaaaaaaaaaaaaz",
      "baaaaaaaaaaaaaaz",
      "aaaaaaaaaaaaaaaz",
      "aaaaaaaaaaaaaaaz",
      "aaaaaaaaaaaaaaaz",
      "aaaaaaaaaaaaaaaz",
      "aaaaaaaaaaaaaaaz",
      "aaaaaaaaaaaaaaaz",
      "aaaaaaaaaaaaaaaz",
      "aaaaaaaaaaaaaaaz",
      "aaaaaaaaaaaaaaaz",
      "aaaaaaaaaaaaaaaz"
    ],
    [
      "caaaaaaaaaaaaaaz",
      "daaaaaaaaaaaaaaz",
      "daaaaaaaaaaaaaaz",
      "eaaaaaaaaaaaaaaz",
      "aaaaaaaaaaaaaaaz",
      "daaaaaaaaaaaaaaz",
      "aaaaaaaaaaaaaaaz",
      "aaaaaaaaaaaaaaaz",
      "aaaaaaaaaaaaaaaz",
      "aaaaaaaaaaaaaaaz",
      "aaaaaaaaaaaaaaaz",
      "aaaaaaaaaaaaaaaz",
      "aaaaaaaaaaaaaaaz",
      "aaaaaaaaaaaaaaaz",
      "aaaaaaaaaaaaaaaz",
      "aaaaaaaaaaaaaaaz"
    ],
    [
      "dfaaaaaaaaaaaaaz",
      "caaaaaaaaaaaaaaz",
      "daaaaaaaaaaaaaaz",
      "eaaaaaaaaaaaaaaz",
      "aaaaaaaaaaaaaaaz",
      "aaaaaaaaaaaaaaaz",
      "aaaaaaaaaaaaaaaz",
      "aaaaaaaaaaaaaaaz",
      "aaaaaaaaaaaaaaaz",
      "aaaaaaaaaaaaaaaz",
      "aaaaaaaaaaaaaaaz",
      "aaaaaaaaaaaaaaaz",
      "aaaaaaaaaaaaaaaz",
      "aaaaaaaaaaaaaaaz",
      "aaaaaaaaaaaaaaaz",
      "aaaaaaaaaaaaaaaz"
    ],
    [
      " aaaaaaaaaaaaaaz",
      " faaaaaaaaaaaaaz",
      "!aaaaaaaaaaaaaaz",
      "eaaaaaaaaaaaaaaz",
      "aaaaaaaaaaaaaaaz",
      "aaaaaaaaaaaaaaaz",
      "aaaaaaaaaaaaaaaz",
      "aaaaaaaaaaaaaaaz",
      "aaaaaaaaaaaaaaaz",
      "aaaaaaaaaaaaaaaz",
      "aaaaaaaaaaaaaaaz",
      "aaaaaaaaaaaaaaaz",
      "aaaaaaaaaaaaaaaz",
      "aaaaaaaaaaaaaaaz",
      "aaaaaaaaaaaaaaaz",
      "aaaaaaaaaaaaaaaz"
    ],
    [
      " aaaaaaaaaaaaaaz",
      " aaaaaaaaaaaaaaz",
      "daaaaaaaaaaaaaaz",
      "eaaaaaaaaaaaaaaz",
      "aaaaaaaaaaaaaaaz",
      "aaaaaaaaaaaaaaaz",
      "aaaaaaaaaaaaaaaz",
      "aaaaaaaaaaaaaaaz",
      "aaaaaaaaaaaaaaaz",
      "aaaaaaaaaaaaaaaz",
      "aaaaaaaaaaaaaaaz",
      "aaaaaaaaaaaaaaaz",
      "aaaaaaaaaaaaaaaz",
      "aaaaaaaaaaaaaaaz",
      "aaaaaaaaaaaaaaaz",
      "aaaaaaaaaaaaaaaz"
    ],
    [
      " aaaaaaaaaaaaaaz",
      " aaaaaaaaaaaaaaz",
      " aaaaaaaaaaaaaaz",
      "eaaaaaaaaaaaaaaz",
      "faaaaaaaaaaaaaaz",
      "aaaaaaaaaaaaaaaz",
      "aaaaaaaaaaaaaaaz",
      "aaaaaaaaaaaaaaaz",
      "aaaaaaaaaaaaaaaz",
      "aaaaaaaaaaaaaaaz",
      "aaaaaaaaaaaaaaaz",
      "aaaaaaaaaaaaaaaz",
      "aaaaaaaaaaaaaaaz",
      "aaaaaaaaaaaaaaaz",
      "aaaaaaaaaaaaaaaz",
      "aaaaaaaaaaaaaaaz"
    ]
  ]
}