{
  "name": "multi_militarybase_1_ground",
  "refpalette": "c70cities:multi_militarybase_1_ground_palette",
  "xsize": 16,
  "zsize": 16,
  "slices": [
    [
      "abcccccccccccccc",
      "abcccccccccccccc",
      "deczczzcffffffff",
      "gezzzzccfhhhhfff",
      "gezzzzzzfhhhhfff",
      "gezczzzcfhhhhfff",
      "geczzzzcf hhhfff",
      "gezzczzcf hhhhhh",
      "gezzzzzcf hhhhhh",
      "gezzzzczfihhhhhh",
      "gezzzzzcfhhhhhhh",
      "gezzczzcffffffff",
      "geczzzczcccczzcc",
      "gecczzzcczzzzczz",
      "geeeeeeeeeeeeeee",
      "gggggggggggggggg"
    ],
    [
      "j k  k   k   k  ",
      "j  k            ",
      " e      llllll  ",
      " emm m  lnnnnl  ",
      " em   mmlo p l  ",
      " e    m lq   l  ",
      " er m   l s  llt",
      " e m  m l s  uw ",
      " e m    l s     ",
      " em     l s     ",
      " e    m lx   y A",
      " em  m  llllllll",
      " e              ",
      " er mm  r m m  m",
      " eeeeeeeeeeeeeee",
      "                "
    ],
    [
      "                ",
      "                ",
      " e      BBCCBB  ",
      " e      BDE FB  ",
      " e      C    C  ",
      " e      C    B  ",
      " er     B    BBI",
      " e      B    uF ",
      " e      C       ",
      " e      C       ",
      " e      B     y ",
      " e      BCCCCBBB",
      " e              ",
      " er     r       ",
      " eeeeeeeeeeeeeee",
      "                "
    ],
    [
      "                ",
      "                ",
      " e      BBCCBB  ",
      " e     JB    B  ",
      " e     JB    C  ",
      " e     JB    B  ",
      " er    JB    BBB",
      " e     JB    u  ",
      " e     JB       ",
      " e     JB       ",
      " e     JB      y",
      " e      BBBBBBBB",
      " e       JJJJ   ",
      " er     r       ",
      " eeeeeeeeeeeeeee",
      "                "
    ],
    [
      "                ",
      "                ",
      " e      BBBBBB  ",
      " e      BK   B  ",
      " e      LK   B  ",
      " e      LK   B  ",
      " er     BK   BBL",
      " e      BK   uKK",
      " e      LK      ",
      " e      LK      ",
      " e      BKKKKK  ",
      " e      BLLLLBBB",
      " e              ",
      " er     r       ",
      " eeeeeeeeeeeeeee",
      "                "
    ],
    [
      "        lMMMMl  ",
      "        lMMMMl  ",
      " j      lggggl  ",
      " j      lggggl  ",
      " j      lggggl  ",
      " jx     lggggl  ",
      "NOx     lgggglll",
      " Px     lggggugg",
      " jx     lggggggg",
      " jx     lggggggg",
      " jx     lggggg  ",
      " jx     llllllll",
      " jx      Q      ",
      " Rxxxxxxxxxxxxxx",
      " RRSSSSSTSSSSSSS",
      "                "
    ]
  ]
}