{
  "name": "multi_condo1_0_ground",
  "refpalette": "c70cities:multi_condo1_0_ground_palette",
  "xsize": 16,
  "zsize": 16,
  "slices": [
    [
      "GGGGGGGGGGGGGGGG",
      "GGGGGGGGGGaGGGGG",
      "GGbbbbbbbbaccccc",
      "GGbdddddddaeeeee",
      "GGbdffffffgggggg",
      "GGbdffGGGGGGGGGG",
      "GGbdffGGGGGGGGGG",
      "GGbdffGGGGGGGGGG",
      "GGbdffGGGGGGGGGG",
      "GGbdffGGGGGGGGGG",
      "GGbdffGGGGGGGGGG",
      "GGbdffGGGGGGGGGG",
      "GGbdffGGGGGGGGGG",
      "GaaaffGGGGGGGGGG",
      "GGGgffGGGGffffff",
      "GGGgffGGGG      "
    ],
    [
      "                ",
      "          a     ",
      "          accccc",
      "   ddddddda     ",
      "   dffhhhfff    ",
      "   df           ",
      "   df           ",
      "   df           ",
      "   df           ",
      "   df           ",
      "   df           ",
      "   df           ",
      "   df           ",
      " aaaf           ",
      "    f           ",
      "    i           "
    ],
    [
      "                ",
      "          a     ",
      "          a     ",
      "          a     ",
      "    ffjjjfff    ",
      "    f           ",
      "    f           ",
      "    f           ",
      "    f           ",
      "    f           ",
      "    f           ",
      "    f           ",
      "    f           ",
      " aaaf           ",
      "    f           ",
      "    c           "
    ],
    [
      "                ",
      "          a     ",
      "          a     ",
      "          a     ",
      "    ffjjjfff    ",
      "    f           ",
      "    f           ",
      "    f           ",
      "    f           ",
      "    f           ",
      "    f           ",
      "    f           ",
      "    f           ",
      " aaaf           ",
      "    f           ",
      "    c           "
    ],
    [
      "                ",
      "          a     ",
      "          a     ",
      "   kkkkkkka     ",
      "   kffffffffffff",
      "   kf           ",
      "   kf           ",
      "   kf           ",
      "   kf           ",
      "   kf           ",
      "   kf           ",
      "   kf           ",
      "   kf           ",
      " aaaf           ",
      "    f           ",
      "    f           "
    ],
    [
      "                ",
      "          a     ",
      "          alllll",
      "   mmmmmmma     ",
      "   mffffffffffff",
      "   mf           ",
      "   mf           ",
      "   mf           ",
      "   mf           ",
      "   mf           ",
      "   mf           ",
      "   mf           ",
      "   mf           ",
      " aaaf           ",
      "    f           ",
      "    f           "
    ]
  ]
}