{
  "name": "multi_convenientstore_0_ground",
  "refpalette": "c70cities:multi_convenientstore_0_ground_palette",
  "xsize": 16,
  "zsize": 16,
  "slices": [
    [
      "GGGHHHaGGGGGGGGG",
      "GGGHHHaGGGGGGGGG",
      "GGHHHHaaaaaaaaaa",
      "GGHHHHHHHHHHHHHH",
      "GGHHHHHHHHHHHHHH",
      "GGHHHHHHHHHHHHHH",
      "GGHHHHHHHHHHHHHH",
      "GGHHHHHHHHHHHHHH",
      "GGHHHHHHHHHHHHHH",
      "GGHHHHHHHHHHHHHH",
      "GGHHHHHHHHHHHHHH",
      "GGHHHHHHbcHHHHHH",
      "GGHHHHHHHHHHHHHH",
      "GGHHHHHHHHHHHHHH",
      "GGHHHHHHHHHHHHHH",
      "GGHHHHHHHHHHHHHH"
    ],
    [
      "d     e  d      ",
      "dfd   e         ",
      "      eeeee eeee",
      "d      ghghghghg",
      "                ",
      "       ijijijiji",
      "f               ",
      "d               ",
      "                ",
      "                ",
      "       ghghghghg",
      " f              ",
      " d     ijijijiji",
      "     eeeeeeeeeee",
      "d    eaaaaaaaaaa",
      "     eaaaaaaaaaa"
    ],
    [
      "                ",
      " ~              ",
      "                ",
      "                ",
      "                ",
      "                ",
      "~               ",
      "                ",
      "                ",
      "                ",
      "                ",
      " ~              ",
      "                ",
      "                ",
      "                ",
      "         k  k l "
    ],
    [
      "                ",
      "                ",
      "                ",
      "                ",
      "                ",
      "                ",
      "                ",
      "                ",
      "                ",
      "                ",
      "                ",
      "                ",
      "                ",
      "                ",
      "                ",
      "              l "
    ],
    [
      "                ",
      "                ",
      "                ",
      "                ",
      "                ",
      "                ",
      "                ",
      "                ",
      "                ",
      "                ",
      "                ",
      "                ",
      "                ",
      "                ",
      "                ",
      "              mn"
    ],
    [
      "                ",
      "                ",
      "                ",
      "                ",
      "                ",
      "                ",
      "                ",
      "                ",
      "                ",
      "                ",
      "                ",
      "                ",
      "                ",
      "                ",
      "                ",
      "                "
    ]
  ]
}