{
  "name": "multi_hospital_1_floor1",
  "refpalette": "c70cities:multi_hospital_1_floor1_palette",
  "xsize": 16,
  "zsize": 16,
  "slices": [
    [
      "  a      bcccccc",
      "  a      bcccccc",
      "  bddddddbeccccc",
      "        fghhhhhh",
      "        fghhhhhh",
      "        fghhhhhh",
      "        fghhhhhh",
      "        fghhhhhh",
      "        fghhhhhh",
      "        fghhhhhh",
      "        fghhhhhh",
      "        fghhhhhh",
      "        fghhhhhh",
      "        fggggggg",
      "        fggggggg",
      "                "
    ],
    [
      "  iccjkccg   l  ",
      "  iccccccgm !l  ",
      "  bnnnnnnbopoo  ",
      "        fgq  r  ",
      "        fgq  r  ",
      "        fgs  t  ",
      "        fgu  r  ",
      "        fgwwwr  ",
      "        fg  xr  ",
      "        fg yyr  ",
      "        fg   A  ",
      "        fg BBr  ",
      "        fg C r  ",
      "        fgBDDbEE",
      "        fggggg  ",
      "                "
    ],
    [
      "    FFcccg   l  ",
      "    FFcccg   l  ",
      "  bbbbbbbboIoo  ",
      "        fgJ  r  ",
      "        fgJ  r  ",
      "        fg   K  ",
      "        fg   r  ",
      "        fgLLLr  ",
      "        fg   r  ",
      "        fg  Mr  ",
      "        fg   N  ",
      "        fg O r  ",
      "        fg   r  ",
      "        fgPDDbEE",
      "        fggggg  ",
      "                "
    ],
    [
      "         L   l  ",
      "        fg   l  ",
      "        fboooo  ",
      "        fg   r  ",
      "         L   r  ",
      "         L   r  ",
      "         L   r  ",
      "        fg   r  ",
      "        fg   r  ",
      "         L   r  ",
      "         L   r  ",
      "         L   r  ",
      "        fg   r  ",
      "        fg  QbEE",
      "        fggRgg  ",
      "                "
    ],
    [
      "        fS   l  ",
      "        fg   l  ",
      "        fboooooo",
      "        fg   r  ",
      "        fS   r  ",
      "        fS   r  ",
      "        fS   r  ",
      "        fg   r  ",
      "        fg   r  ",
      "        fS   r  ",
      "        fS   r  ",
      "        fS   r  ",
      "        fg   r  ",
      "        fg   bEE",
      "        fgRRRg  ",
      "                "
    ],
    [
      "        fgvTTl  ",
      "        fgvTTl  ",
      "        fboooooo",
      "        fg   r  ",
      "        fg   r  ",
      "        fg   r  ",
      "        fg   r  ",
      "        fg   r  ",
      "        fg   r  ",
      "        fg   r  ",
      "        fg   r  ",
      "        fg   r  ",
      "        fg   r  ",
      "        fg   bEE",
      "        fggRgg  ",
      "                "
    ]
  ]
}