{
  "name": "multi_laboratory1_4_base5",
  "refpalette": "c70cities:multi_laboratory1_4_base5_palette",
  "xsize": 16,
  "zsize": 16,
  "slices": [
    [
      "vabbbba    ac   ",
      "vdbbbba    e    ",
      "vdbbbba    e    ",
      "vdbbbba    e    ",
      "vdbbbba    e    ",
      "vdbbbba    e    ",
      "vdbbbba    e    ",
      "vabbbba    ac   ",
      "vdbbbba    f    ",
      "vdbbbba    f    ",
      "vdbbbba    g    ",
      "vdbbbba    g    ",
      "vdbbbba    f    ",
      "vdbbbba    fdddd",
      "vdddddddddddhhhh",
      "vvvvvvvvvvvvvvvv"
    ],
    [
      "vaffffaii  a    ",
      "vdjjklfii  e    ",
      "vd m  fii  e    ",
      "vdn   fii  e    ",
      "vdoo  fii  e    ",
      "vdjj  fii  e    ",
      "vd m  fii  e    ",
      "vap   aii  a    ",
      "vdoo  fii  f    ",
      "vd    gii  f    ",
      "vd    qii  g    ",
      "vdn   rii  g    ",
      "vd  p gii  f    ",
      "vdossofii  fdddd",
      "vdddddddddddhhhh",
      "vvvvvvvvvvvvvvvv"
    ],
    [
      "vaffffa    a    ",
      "vd t  f    e    ",
      "vd    e    e    ",
      "vd    e    e    ",
      "vdu   e    e    ",
      "vdwt  e    e    ",
      "vd    f    e    ",
      "va    a    a    ",
      "vdk   f    f    ",
      "vd    g    f    ",
      "vd    x    g    ",
      "vd    y    g    ",
      "vd    g    f    ",
      "vd A Bf    fdddd",
      "vdddddddddddhhhh",
      "vvvvvvvvvvvvvvvv"
    ],
    [
      "vaffffa    a    ",
      "vd    f    e    ",
      "vd    e    e    ",
      "vd    e    e    ",
      "vd    e    e    ",
      "vd    e    e    ",
      "vd    f    e    ",
      "va    a    a    ",
      "vd    f    f    ",
      "vd    g    f    ",
      "vd    g    g    ",
      "vd    g    g    ",
      "vd    g    f    ",
      "vd    f    fdddd",
      "vdddddddddddhhhh",
      "vvvvvvvvvvvvvvvv"
    ],
    [
      "vaffffa    a    ",
      "vd    f    f    ",
      "vd    f    f    ",
      "vd    f    f    ",
      "vd    f    f    ",
      "vd    f    f    ",
      "vd    f    f    ",
      "va    a    a    ",
      "vd    f    f    ",
      "vd    f    f    ",
      "vd    f    f    ",
      "vd    f    f    ",
      "vd    f    f    ",
      "vd    f    fdddd",
      "vdddddddddddhhhh",
      "vvvvvvvvvvvvvvvv"
    ],
    [
      "vaffffaCCCCfCCCC",
      "vdDDDDfCCCCfCCCC",
      "vdDEEDfCCCCfCCCC",
      "vdDDDDfCFFCfCCCC",
      "vdDDDDfCFFCfCCCC",
      "vdDEEDfCCCCfCCCC",
      "vdDDDDfCCCCfCCCC",
      "vaffffaCCCCfCCCC",
      "vdDDDDfCCCCfCCCC",
      "vdDEIDfCCCCfCCCC",
      "vdDDDDfCFJCfCCCC",
      "vdDDDDfCFJCfCCCC",
      "vdDEEDfCCCCfCCCC",
      "vdDDDDfCCCCfdddd",
      "vdddddddddddhhhh",
      "vvvvvvvvvvvvvvvv"
    ]
  ]
}