{
  "name": "multi_pumpjack_0_floor1",
  "refpalette": "c70cities:multi_pumpjack_0_floor1_palette",
  "xsize": 16,
  "zsize": 16,
  "slices": [
    [
      "                ",
      "  aa           a",
      "  abbbbbbbbbbbbb",
      "   bc deebf   gb",
      "   bc    bf   hi",
      "   bc j  bf    i",
      "   bkkkk bf    i",
      "   b!    bf    i",
      "   blm   bf    i",
      "   bbbnopnf    b",
      "   b     bf    i",
      "   b q  rbf    i",
      "   b qsstbf    i",
      "   b qsstbf    i",
      "   b qssubf    i",
      "   b q   wf    b"
    ],
    [
      "                ",
      "  aaxxxxxxxxxxxa",
      "  abbbbbbbbbbbbb",
      "  xby  Aeb    gb",
      "  xbB    C    hb",
      "  xb     C    hb",
      "  xb    Db     b",
      "  xb     b     b",
      "  xbE    b     b",
      "  xbCCnFIn     b",
      "  xb     b     b",
      "  xb     C     b",
      "  xb     C     b",
      "  xb     b     b",
      "  xb     b     b",
      "  xb     J     b"
    ],
    [
      "                ",
      "  aa           a",
      "  abbbbbbbbbbbbb",
      "   bKhL  bh   gb",
      "   bh    M    gb",
      "   b     M  N gb",
      "   b     b  N gb",
      "   b     b    Ob",
      "   bE L  b    gb",
      "   bMMnbbn  N gb",
      "   b  L  b  N gb",
      "   b     M    gb",
      "   b     M    Ob",
      "   b     b  N gb",
      "   b     b  N gb",
      "   b     b   ggb"
    ],
    [
      "                ",
      "  aaaaaaaaaaaaaa",
      "  aaaaaaaabbbbbb",
      "  aaPQQQQabbbbbb",
      "  aaRRRRRabbbbbb",
      "  aaRRRRRabbbbbb",
      "  aaRRRRRabbbbbb",
      "  aaRRRRRabbbbbb",
      "  aaQQQQQabbbbbb",
      "  aaaaaaaabbbbbb",
      "  aaQQQQQabbbbbb",
      "  aaRRRRRabbbbbb",
      "  aaRRRRRabbbbbb",
      "  aaRRRRRabbbbbb",
      "  aaRRRRRabbbbbb",
      "  aaRRRRRabbbbbb"
    ],
    [
      " SSSSSSSSSSSSSSS",
      " SSSSSSSSSSSSSSS",
      " SSaaaaaaa    gg",
      " SSaTgbbba    gg",
      " SSabbbbba      ",
      " SSabbbbba    gg",
      " SSabbbbba    gg",
      " SSabbbbba      ",
      " SSabbbbba      ",
      " SSabbbbba      ",
      " SSabbbbba      ",
      " SSabbbbba      ",
      " SSabbbbba      ",
      " SSabbbbba      ",
      " SSabbbbba      ",
      " SSabbbbba      "
    ],
    [
      "                ",
      "                ",
      "               K",
      "    PU          ",
      "    K           ",
      "               K",
      "                ",
      "                ",
      "                ",
      "    gggV        ",
      "    ggWV        ",
      "                ",
      "                ",
      "    gggV        ",
      "    ggWV        ",
      "                "
    ]
  ]
}