{
  "name": "multi_pumpjack_0_ground",
  "refpalette": "c70cities:multi_pumpjack_0_ground_palette",
  "xsize": 16,
  "zsize": 16,
  "slices": [
    [
      "zzzzzzzzzzzzzzzz",
      "zzzzzzzzzzzzzzzz",
      "zzzzzzzzzzzzzzzz",
      "zzzzzaazzzzzzzzz",
      "zzzzzaazzzzzzzzz",
      "zzzzzzzzzzzzzzzz",
      "zzzzzzzzzzzzzzzz",
      "zzzzaaaaazzzzzzz",
      "zzzzaaaaazzzzzzz",
      "zzzzzzzzzzzzzzzz",
      "zzzzzzzzzzzzzzzz",
      "zzzzzzzzzzzzzzzz",
      "zzzzzzzzzzzzzzzz",
      "zzzzzzzzzzzzzzzz",
      "zzzzzzzzzzzzzzzz",
      "zzzzzzzzzzzzzzzz"
    ],
    [
      "                ",
      "  bb           b",
      "  bccccccccccccc",
      "   cdddddddddddc",
      "   cdddddddddddc",
      "   cdddddbdddddc",
      "   cdddddddddddc",
      "   cdddddddddddc",
      "   cdddddddddddc",
      "   cdddddddddddc",
      "   ceeeeeedddddc",
      "   ceeeeeedddddc",
      "   ceeeeeedddddc",
      "   ceeeeeedddddc",
      "   ceeeeeedddddc",
      "   ceeeeebdddddc"
    ],
    [
      "                ",
      "  bb           b",
      "  bccccccccccccc",
      "   cfgghfci j!kc",
      "   c     c    lm",
      "   c     n    op",
      "   c     cq   op",
      "   crcrcsct   up",
      "   cwcxcwct   up",
      "   ccccccmi   ym",
      "   cABCDCcE     ",
      "   cFI   cJ     ",
      "   cK   Lcu     ",
      "   cM   Ncu     ",
      "   cOPP Pc    Qm",
      "   c     R    Qc"
    ],
    [
      "                ",
      "  bb           b",
      "  bccccccccccccc",
      "   cSTTTUci  jkc",
      "   c     c     m",
      "   c     V     p",
      "   c     c     p",
      "   cWcWcXcY    p",
      "   cZcZcZc0    p",
      "   ccccccmi    m",
      "   c12 3 c4     ",
      "   c5    6      ",
      "   c7    6      ",
      "   cO    cu     ",
      "   c  8 9c     m",
      "   c     @    Qc"
    ],
    [
      "                ",
      "  bb           b",
      "  bcc###ccc###cc",
      "   c $ $ ci   kc",
      "   #     c     m",
      "   #     c     p",
      "   #     c     p",
      "   c % % c     p",
      "   c!%$% cy    p",
      "   ccccccmi    m",
      "   cyy%%%c     p",
      "   c7    ^     p",
      "   #O    ^     p",
      "   #     c     p",
      "   #     c     m",
      "   c     c     c"
    ],
    [
      "                ",
      "  bb           b",
      "  bccccccccccccc",
      "   c&&&&&ci   kc",
      "   c*****c(    m",
      "   c*****c     m",
      "   c*****c     m",
      "   c*****c     m",
      "   c&&&&&c(    m",
      "   ccccmmmi    m",
      "   c&&&&&c(    m",
      "   cO****c     m",
      "   c ****c     m",
      "   c ****c     m",
      "   c ****c     m",
      "   c ****c(    c"
    ]
  ]
}