{
  "name": "multi_communitycenter_4_floor1",
  "refpalette": "c70cities:multi_communitycenter_4_floor1_palette",
  "xsize": 16,
  "zsize": 16,
  "slices": [
    [
      "              a ",
      "              a ",
      "              ab",
      "              ab",
      "  c           a ",
      "  c     ~     a ",
      "  cd          a ",
      "  cd          ab",
      "eecff         ab",
      "ggggf         a ",
      "ggggff        a ",
      "gggggfff      a ",
      "gggggggfffffffff",
      "hgggggggiigggggg",
      "hhgggggggggggggg",
      "jhhggggggggggggg"
    ],
    [
      "                ",
      "                ",
      "               b",
      "               b",
      "                ",
      "        ~       ",
      "                ",
      "               b",
      "  c d          b",
      "  ccd           ",
      "   cdd          ",
      "   ccddd        ",
      "   kcccddddddddb",
      "e     cccccccccb",
      "eel             ",
      " ee             "
    ],
    [
      "                ",
      "                ",
      "               b",
      "               b",
      "                ",
      "        ~       ",
      "                ",
      "               b",
      "               b",
      "                ",
      "                ",
      "                ",
      "               b",
      "               b",
      "  ~             ",
      "                "
    ],
    [
      "                ",
      "                ",
      "               m",
      "               m",
      "                ",
      "        ~       ",
      "                ",
      "               m",
      "               m",
      "                ",
      "                ",
      "                ",
      "               m",
      "               m",
      "                ",
      "                "
    ],
    [
      "             nnh",
      "             nnh",
      "             nnh",
      "             nnh",
      "             nnh",
      "        ~    nnh",
      "             nnh",
      "             nnh",
      "             nnh",
      "             nnh",
      "             nnh",
      "             nnh",
      "             nnh",
      "             nnh",
      "             nnh",
      "             nnh"
    ],
    [
      "                ",
      "                ",
      "                ",
      "                ",
      "                ",
      "        ~       ",
      "                ",
      "                ",
      "                ",
      "                ",
      "                ",
      "                ",
      "                ",
      "                ",
      "                ",
      "                "
    ]
  ]
}