{
  "name": "multi_militarybase_0_base4",
  "refpalette": "c70cities:multi_militarybase_0_base4_palette",
  "xsize": 16,
  "zsize": 16,
  "slices": [
    [
      "vvvvvvvvvvvvvvvv",
      "vaaaavaaaaaaavaa",
      "vaaaabaaaaaaabaa",
      "vaaaabaaaaaaabaa",
      "vaaaabaaaaaaabaa",
      "vvbbbvbbbbbbbvbb",
      "vaaaabaaaaaaabaa",
      "vaaaabaaaaaaabaa",
      "vaaaabaaaaaaabaa",
      "vaaaabaaaaaaavaa",
      "vaaaabaaaaaaabaa",
      "vaaaabaaaaaaabaa",
      "vaaaabaaaaaaabaa",
      "vvbbbbbbbbbbbvbb",
      "vccccccccccccbdd",
      "vccccccccccccbdd"
    ],
    [
      "vvvvvvvvvvvvvvvv",
      "veeffvgggggggvhh",
      "vi   jklmnkklohh",
      "vi   p       ohh",
      "vi   j       ohh",
      "vvqqqv       vhh",
      "v!r          ohh",
      "vgs          ohh",
      "vgt     uwu  oxx",
      "vgr     yAB Cv x",
      "vgD     uEu  o  ",
      "vgF          I  ",
      "vgt          o  ",
      "vv           vhh",
      "v             ff",
      "v               "
    ],
    [
      "vvvvvvvvvvvvvvvv",
      "veJ  vlKlklLnvMM",
      "v    j       o  ",
      "v    N       o  ",
      "v    j       oOO",
      "vvqqqv       vhh",
      "vD           ohh",
      "vt           ohh",
      "vt      PPP  o  ",
      "vQ      PRP Cv  ",
      "vt      PPP  o  ",
      "vr           I  ",
      "vD           o  ",
      "vv           vhh",
      "v               ",
      "vS              "
    ],
    [
      "vvvvvvvvvvvvvvvv",
      "v    v       v T",
      "v    j       o  ",
      "v    j       o  ",
      "v    j       o  ",
      "vvqqqv       v  ",
      "v            o  ",
      "v            oOO",
      "v            ohh",
      "v           Cvhh",
      "v            oUU",
      "v            o  ",
      "v            oVV",
      "vv           vhh",
      "v               ",
      "v               "
    ],
    [
      "vvvvvvvvvvvvvvvv",
      "v    v       v  ",
      "v    j       o  ",
      "v    j       o  ",
      "v    j       o  ",
      "vvqqqvWWWWWWWv  ",
      "v    W       o  ",
      "v    W       o  ",
      "v    W       o  ",
      "v    W      Cv  ",
      "v    W       oOO",
      "v    W       ohh",
      "v    W       ohh",
      "vvWWWWWWWWWWWvhh",
      "v               ",
      "v               "
    ],
    [
      "vvvvvvvvvvvvvvvv",
      "vXXXXvXXXXXXXv  ",
      "vXXXXbXXXXXXXY  ",
      "vXXXXbXXXXXXXY  ",
      "vXXXXbXXXXXXXY  ",
      "vvbbbvbbbbbbbv  ",
      "vXXXXbXXXXXXXY  ",
      "vXXXXbXXXXXXXY  ",
      "vXXXXbXXXXXXXY  ",
      "vXXXXbXXXXXXCv  ",
      "vXXXXbXXXXXXXY  ",
      "vXXXXbXXXXXXXY  ",
      "vXXXXbXXXXXXXY  ",
      "vvbbbbbbbbbbbvOO",
      "vXXXXXXXXXXXXYUU",
      "vXXXXXXXXXXXXYZZ"
    ]
  ]
}