{
  "name": "multi_pumpjack_3_ground",
  "refpalette": "c70cities:multi_pumpjack_3_ground_palette",
  "xsize": 16,
  "zsize": 16,
  "slices": [
    [
      "zzzzzzzzzzzzzzzz",
      "zzzzzzzzzzzzzzzz",
      "zzzzzzzzaazzzzzz",
      "zzzzzbzzazzzzzzz",
      "zbzzzzzbzzzzzzzz",
      "zzzzzzzzzzzzzzzz",
      "zazzzzzbzzzzzzzz",
      "zazzzzzzzzzzzzzz",
      "zbzzzbzzzzzzzzzz",
      "zzzzaaz!zzzzzzzz",
      "zzzzzzzzzzzzzzzz",
      "zzzzzzzzzzzzzzzz",
      "zccczczczcczcczz",
      "czccczccczcczzcz",
      "ccccccczzzzzcczz",
      "zzzzzzzzzzzzzzzz"
    ],
    [
      "de        fghf  ",
      "dee        gij  ",
      "e          gd   ",
      " k l     lkkh   ",
      "  lglk  lglgh   ",
      " kggggkgggggh   ",
      "k lllm  lllkd   ",
      "  lll kmlllkh   ",
      "m lln mmlln h   ",
      "mk o  k  okph   ",
      "dhhidhhhdihhd   ",
      "                ",
      "                ",
      "                ",
      "                ",
      "                "
    ],
    [
      "d               ",
      "d           q   ",
      "            d   ",
      "            q   ",
      "            q   ",
      "  r r   r r q   ",
      "            d   ",
      "   s     s  q   ",
      "  t n   t n q   ",
      "m  u     u  q   ",
      "dqqqdqqqdqqqd   ",
      "                ",
      "                ",
      "                ",
      "                ",
      "                "
    ],
    [
      "d               ",
      "d           q   ",
      "            d   ",
      "   w     w  q   ",
      "            q   ",
      "  r r   r r q   ",
      "            d   ",
      "   s     s  q   ",
      "    x       q   ",
      "            q   ",
      "dqqqdqqqdqqqd   ",
      "                ",
      "                ",
      "                ",
      "                ",
      "                "
    ],
    [
      "d               ",
      "d               ",
      "            y   ",
      "   w     w      ",
      "   A     A      ",
      "  rAr   rAr     ",
      "   A     A  y   ",
      "   A     A      ",
      "                ",
      "                ",
      "y   y   y   y   ",
      "                ",
      "                ",
      "                ",
      "                ",
      "                "
    ],
    [
      "d               ",
      "d               ",
      "                ",
      "                ",
      "                ",
      "                ",
      "                ",
      "                ",
      "                ",
      "                ",
      "        ~       ",
      "                ",
      "                ",
      "                ",
      "                ",
      "                "
    ]
  ]
}