{
  "name": "multi_carservice_1_ground",
  "refpalette": "c70cities:multi_carservice_1_ground_palette",
  "xsize": 16,
  "zsize": 16,
  "slices": [
    [
      "GabbbbbbbbbbbbaG",
      "GabbbbbbbbbbbbaG",
      "GabbbbbbbbbbbbaG",
      "GacaaacaaacaaaaG",
      "HH=ddef       cG",
      "HH=ddef       cG",
      "HH=ddef       cG",
      "HHvccccccccccccG",
      "HHvvvvvvvvvvvvvG",
      "HHvvvvvvvvvvvvvG",
      "HHcccccccccccccG",
      "HHHHHHHHHHHHHHHG",
      "HHHHHHHHHHHHHHHG",
      "GHHHHHHHHHHHHHHG",
      "GHHHHHHHHHHHHHHG",
      "GHHHHHHHHHHHHHHG"
    ],
    [
      " ag           h ",
      " a            h ",
      " ai   jkkk llla ",
      " ac   caaacaaac ",
      "              m ",
      "              m ",
      "              m ",
      "  nHmmmmmmmmmmm ",
      "  nH            ",
      "  nH            ",
      "  c   cooocoooc ",
      "                ",
      "                ",
      " pqpqpqpqpqpqpq ",
      "            r   ",
      " ststststststst "
    ],
    [
      " h            h ",
      " h            h ",
      " cu        w xa ",
      " acyyycaaacaaac ",
      "      A       A ",
      "      o       o ",
      "      o       o ",
      "    nHo       o ",
      "    nHo       o ",
      "    nHo       o ",
      "  c   c   c   c ",
      "                ",
      "                ",
      "                ",
      "                ",
      "                "
    ],
    [
      " a            h ",
      " a            h ",
      " a            a ",
      " acyyycaaacaaac ",
      "                ",
      "                ",
      "                ",
      "      nH        ",
      "      nH        ",
      "      nH        ",
      "  cBBBcBBBc   c ",
      "                ",
      "                ",
      "                ",
      "                ",
      "                "
    ],
    [
      " a            C ",
      " a            C ",
      " a            a ",
      " acDDDcaaacaaac ",
      "  o       o     ",
      "  o       o     ",
      "  o       o     ",
      "  o     nHo     ",
      "  o     nHo     ",
      "  E     nHE     ",
      "  cooocoooc   c ",
      "                ",
      "                ",
      "                ",
      "                ",
      "                "
    ],
    [
      " aooooooooooooa ",
      " aooooooooooooa ",
      " aFFFFFFFFIFFFa ",
      " acaaacaaacaaac ",
      "          c     ",
      "          J     ",
      "          J     ",
      "          nH    ",
      "          nH    ",
      "          nH    ",
      "  c   c   c   c ",
      "                ",
      "                ",
      "                ",
      "                ",
      "                "
    ]
  ]
}