{
  "name": "multi_laboratory1_12_ground",
  "refpalette": "c70cities:multi_laboratory1_12_ground_palette",
  "xsize": 16,
  "zsize": 16,
  "slices": [
    [
      "abccbdddvefffffz",
      "abccbdddveffzffz",
      "abccbdddvefffzzz",
      "bbccbdddvefffzfz",
      "bcccbdddevffffff",
      "bcccbdddvefzfffz",
      "ccccbdddvvefffzz",
      "ccccbdddveffzfzf",
      "ccccbdddveffffzf",
      "ccccbdddvffffffz",
      "ccccbdddvefffzzz",
      "ccccbdddeefefffz",
      "ccccbdddvefffffz",
      "ccccbdddveffffzz",
      "ccccbdddvvefffzf",
      "ccccbdddvefffffz"
    ],
    [
      " g  h           ",
      " g  h          i",
      " g  h     jkli  ",
      "gg  h           ",
      "g  mb           ",
      "g   h     l jn  ",
      "    h          i",
      "   op           ",
      "  oqh     jk l  ",
      "mor h           ",
      "oqr h        i  ",
      "rsr b     lktn  ",
      "r r h          i",
      "rurwh           ",
      "r r h     jtln  ",
      "    h           "
    ],
    [
      "    x           ",
      "    x           ",
      "    x           ",
      "    x           ",
      "   yb           ",
      "    x           ",
      "    h           ",
      "   op           ",
      "  oqh           ",
      "yor h           ",
      "oqr x           ",
      "r r b           ",
      "r r h           ",
      "r r h           ",
      "r r h           ",
      "    h           "
    ],
    [
      "    x           ",
      "    x           ",
      "    x           ",
      "    x           ",
      "   yb           ",
      "    x           ",
      "    h           ",
      "   op           ",
      "  oqh           ",
      "yor h           ",
      "oqr x           ",
      "rAr b           ",
      "r r h           ",
      "r r h           ",
      "r r h           ",
      "    h           "
    ],
    [
      "    x           ",
      "    x           ",
      "    x           ",
      "    x           ",
      "    b           ",
      "    x           ",
      "    h           ",
      "   op           ",
      "  oqh           ",
      " oAqh           ",
      "oqAqx           ",
      " q qb           ",
      " qBqh           ",
      "Cq qh           ",
      "AqDqh           ",
      "E E h           "
    ],
    [
      "   Fh           ",
      "   Fh           ",
      "   Fh           ",
      "   Fh           ",
      "   Fb           ",
      "   Fh           ",
      "   Fh           ",
      "   op           ",
      "  oFh           ",
      " oFFh           ",
      "oFFFh           ",
      "FFFFb           ",
      "FIIFh           ",
      "FIIFh           ",
      "FFFFh           ",
      "FFFFh           "
    ]
  ]
}