{
  "name": "multi_laboratory1_3_base6",
  "refpalette": "c70cities:multi_laboratory1_3_base6_palette",
  "xsize": 16,
  "zsize": 16,
  "slices": [
    [
      "zabccccccccccccc",
      "zabccccccccccccc",
      "zbcccccccccdeeee",
      "zbfffffffffccccc",
      "zbffffbbbbfccccc",
      "zbffffbg bfccccc",
      "zbffffbg bfccccc",
      "zbffffbbbbfccccc",
      "zbfffffffffccccc",
      "zbhiiiiiiiidcccc",
      "zbjjjjcccccccccc",
      "zbjjjjcccccccccc",
      "zbjjjjcccccccccc",
      "zbjjjjcccccccccc",
      "zbjjjjcccccccccc",
      "zbjjjjcccccccccc"
    ],
    [
      "zab             ",
      "zak             ",
      "zdllllllllldmmmm",
      "zb     nn  l    ",
      "zbo   pppp l    ",
      "zb   qpg prl    ",
      "zb   qpg prl    ",
      "zbo   pppp l    ",
      "zb st  uu  l wx ",
      "zdy  ydyyyyd  x ",
      "zb AB l    lC x ",
      "zbD   E    l    ",
      "zbF   l    l    ",
      "zbFI  l    l    ",
      "zb   Jl    l    ",
      "zbKLLKl    lM x "
    ],
    [
      "zab             ",
      "zak             ",
      "zdllllllllldNNNN",
      "zb         O    ",
      "zb         O    ",
      "zb     PP  O    ",
      "zb     QQ  O    ",
      "zb         O    ",
      "zb RS      O    ",
      "zdy  ydyyyyd  T ",
      "zb UV l    O  W ",
      "zb    X    O    ",
      "zb    lY   O    ",
      "zbZ  0l    O    ",
      "zb   Jl    O    ",
      "zb1   l2   O  3 "
    ],
    [
      "zab             ",
      "zak             ",
      "zdllllllllldNNNN",
      "zb         O    ",
      "zb         O    ",
      "zb         O    ",
      "zb         O    ",
      "zb         O    ",
      "zb         O    ",
      "zdyyyydyyyyd    ",
      "zb    l    O    ",
      "zb    4    O    ",
      "zb    l    O    ",
      "zb    l    O    ",
      "zb   Jl2   O    ",
      "zb    l    O    "
    ],
    [
      "zab             ",
      "zak             ",
      "zdllllllllldNNNN",
      "zb         O    ",
      "zb         O    ",
      "zb         O    ",
      "zb         O    ",
      "zb         O    ",
      "zb         O    ",
      "zdyyyydyyyyd    ",
      "zb    l    O    ",
      "zb    l    O    ",
      "zb    l    O    ",
      "zb    l2   O    ",
      "zb   Jl    O    ",
      "zb    l    O    "
    ],
    [
      "zab             ",
      "zak             ",
      "zdllllllllldNNNN",
      "zb         O    ",
      "zb         O    ",
      "zb         O    ",
      "zb         O    ",
      "zb         O    ",
      "zb         O    ",
      "zdyyyydyyyyd    ",
      "zb5555l    O    ",
      "zb5555l    O    ",
      "zb5555l2   O    ",
      "zb5555l    O    ",
      "zb555Jl    O    ",
      "zb5555l    O    "
    ]
  ]
}