{
  "name": "multi_megatower1_7_floor4",
  "refpalette": "c70cities:multi_megatower1_7_floor4_palette",
  "xsize": 16,
  "zsize": 16,
  "slices": [
    [
      "aaab            ",
      "aaac            ",
      "aaac            ",
      "aaac            ",
      "aadef           ",
      "aaab            ",
      "ggab            ",
      "ggab            ",
      "ggac            ",
      "ggac            ",
      "aaac            ",
      "aadef           ",
      "aaab            ",
      "aaab            ",
      "aaab            ",
      "aaac            "
    ],
    [
      "hijb            ",
      "  jc            ",
      "kkjc            ",
      "lmjc            ",
      "nedef           ",
      "nojb            ",
      "ppjb            ",
      "  jb            ",
      "  jc            ",
      "qqjc            ",
      "nojc            ",
      "nedef           ",
      "lmjb            ",
      "rrjb            ",
      " sjb            ",
      " ijc            "
    ],
    [
      "  jb            ",
      "  jc            ",
      "kkjc            ",
      "  jc            ",
      "ntdef           ",
      "n!jb            ",
      "ppjb            ",
      "  ub            ",
      "  uc            ",
      "qqjc            ",
      "nojc            ",
      "ntdef           ",
      "  jb            ",
      "rrjb            ",
      "  jb            ",
      "  jc            "
    ],
    [
      "  jb            ",
      "  jc            ",
      "kkjc            ",
      " wjc            ",
      " odef           ",
      " ojb            ",
      "ppjb            ",
      "  xb            ",
      "  xc            ",
      "qqjc            ",
      " ojc            ",
      " odef           ",
      "  jb            ",
      "rrjb            ",
      "  jb            ",
      "  jc            "
    ],
    [
      "  jb            ",
      " wjc            ",
      "kkjc            ",
      "wwjc            ",
      " odef           ",
      "wojb            ",
      "ppjb            ",
      "  jb            ",
      "  jc            ",
      "qqjc            ",
      "wojc            ",
      " odef           ",
      "  jb            ",
      "rrjb            ",
      "  jb            ",
      "  jc            "
    ],
    [
      "  yb            ",
      " wyc            ",
      "aayc            ",
      "aayc            ",
      "AAdef           ",
      "aayb            ",
      "BByb            ",
      "CCyb            ",
      "CCyc            ",
      "DDyc            ",
      "aayc            ",
      "AAdef           ",
      "aayb            ",
      "aayb            ",
      "  yb            ",
      "  yc            "
    ]
  ]
}