{
  "name": "multi_flatapartment_2_ground",
  "refpalette": "c70cities:multi_flatapartment_2_ground_palette",
  "xsize": 16,
  "zsize": 16,
  "slices": [
    [
      "GaaaaGGGGGGGGGGG",
      "aaaaaaaaaaaaaaaG",
      "aaaaaaaaaaaaaaaG",
      "aaaaaaaaaaaaaaaG",
      "aaaaaaaaaaaaaaaG",
      "aaaaaaaaaaaaaaaG",
      "aaaaaaaaaaaaaaaG",
      "aaaaaaaaaaaaaaaG",
      "aaaaaaaaaaaaaaaG",
      "aaaaaaaaaaaaaaaG",
      "aaaaaaaaaaaaaaaG",
      "aaaaaaaaaaaaaaaG",
      "aaaaaaaaaaaaaaaG",
      "aaaaaaaaaaaaaaaG",
      "aaaaaaaaaaaaaaaG",
      "GaaaaGGGGGGGGGGG"
    ],
    [
      "b    bbbbbbbbbbc",
      "d    deeedeeeedb",
      "             fgb",
      "               b",
      "      f g    hib",
      "d    dh id    db",
      " g  f gjf g  fgb",
      " i  h ijh i    b",
      " g  f gjf g    b",
      " i  h ijh i  hib",
      "d    df gd    db",
      "      h i    fgb",
      "               b",
      "             hib",
      "d    dkkkdkkkkdb",
      "b    bbbbbbbbbb "
    ],
    [
      "               l",
      "m    m   m    m ",
      "                ",
      "                ",
      "                ",
      "m    m   m    m ",
      "                ",
      "                ",
      "                ",
      "                ",
      "m    m   m    m ",
      "                ",
      "                ",
      "                ",
      "m    m   m    m ",
      "                "
    ],
    [
      "               n",
      "mo  omo omo  om ",
      "              o ",
      "                ",
      "              o ",
      "m    m   m    m ",
      "              o ",
      "                ",
      "                ",
      "              o ",
      "m    m   m    m ",
      "              o ",
      "                ",
      "              o ",
      "mo  omo omo  om ",
      "                "
    ],
    [
      "                ",
      "m pp m p m pp m ",
      "q    q   q      ",
      "              p ",
      "                ",
      "m    m   m   qm ",
      "                ",
      "              p ",
      "              p ",
      "                ",
      "m    m   m   qm ",
      "                ",
      "              p ",
      "q    q   q      ",
      "m pp m p m pp m ",
      "                "
    ],
    [
      "                ",
      "ppppppppppppppp ",
      "aaaaaaaaaaaaaap ",
      "a    a   a   ap ",
      "a    a   a   ap ",
      "aaaaaaaaaaaaaap ",
      "a    a   a   ap ",
      "a    a   a   ap ",
      "a    a   a   ap ",
      "a    a   a   ap ",
      "aaaaaaaaaaaaaap ",
      "a    a   a   ap ",
      "a    a   a   ap ",
      "aaaaaaaaaaaaaap ",
      "ppppppppppppppp ",
      "                "
    ]
  ]
}