{
  "name": "multi_megatower1_3_ground",
  "refpalette": "c70cities:multi_megatower1_3_ground_palette",
  "xsize": 16,
  "zsize": 16,
  "slices": [
    [
      "GaGGGGGGaGaGGGGG",
      "GGaaaGaaGGaaaaGa",
      "GGGGaGGGGGGaGGGG",
      "vvvvvvvvvvvvvvvv",
      "vvvvvvvvvvvvvvvv",
      "vvvvvvvvvvvvvvvv",
      "vvvvbvvvvvvbvvvv",
      "vvvvvvvvvvvvvvvv",
      "vvvvvvvvvvvvvvvv",
      "vvvvvvvvvvvvvvvv",
      "vvvvvvvvvvvvvvvv",
      "vvvvvvvvvvvvvvvv",
      "vvvvvvvvvvvvvvvv",
      "vvvvbvvvvvvbvvvv",
      "cdddvvvvvvvvvvvv",
      "c   vvvvvvvvvvvv"
    ],
    [
      "                ",
      "                ",
      "e fe eef ee efe ",
      "gggghgggggghgggg",
      "ijklmnopio qcrrr",
      "so lt on inucrrr",
      "ccccb n o  bcrrr",
      "w x yk   nkAcrrr",
      "w   yBC  D Acrrr",
      "wE  yCFD  k crrr",
      "IIJIy      Acrrr",
      " kKLm      Acrrr",
      " MNMykO    kcrrr",
      "PPPPbO O  kbcrrr",
      "cdddyOO   k!crrr",
      "c   yOOkO kAcrrr"
    ],
    [
      "                ",
      "                ",
      "                ",
      "gggghgggggghgggg",
      "    Q   R  Scrrr",
      "T  kU      Scrrr",
      "ccccb     Vbcrrr",
      "w W y       crrr",
      "w   yX      crrr",
      "w   yk     kcrrr",
      "IIYIy       crrr",
      "  kMQ       crrr",
      " ZkLy       crrr",
      "PPPPb0 k   bcrrr",
      "cdddyO1    kcrrr",
      "c   y2      crrr"
    ],
    [
      "                ",
      "                ",
      "    3      3    ",
      "gggghgggggghgggg",
      "   ky   R44brrrr",
      "    y    44brrrr",
      "ccccbbbbbbbbrrrr",
      "w   y    44brrrr",
      "w   y    44brrrr",
      "w   y    44brrrr",
      "IIIIy    44brrrr",
      "   5y    44brrrr",
      "   ky   k44brrrr",
      "PPPPbbbbbbbbrrrr",
      "cdddyk   44brrrr",
      "c   y    44brrrr"
    ],
    [
      "                ",
      "                ",
      "                ",
      "gggghgggggghgggg",
      "  kk644ccrrrr   ",
      " k k644ccrrrr   ",
      "ccccb44ccrrrr   ",
      "    644ccrrrr   ",
      "    644ccrrrr   ",
      "    644ccrrrr   ",
      "7777644ccrrrr   ",
      "   k644ccrrrr   ",
      "  kk644ccrrrr   ",
      "PPPPb44ccrrbr   ",
      "cddd644ccrrrr   ",
      "c   644ccrrrr   "
    ],
    [
      "                ",
      "                ",
      "                ",
      "gggghggggggh88  ",
      "4444brrrr  9    ",
      "4444brrrr       ",
      "bbbbbrrrr       ",
      "ccccbrrrr       ",
      "ccccbrrrr       ",
      "ccccbrrrr       ",
      "ccccbrrrr       ",
      "4444brrrr       ",
      "4444brrrr       ",
      "bbbbbrrrr  @    ",
      "bdddbrrrr       ",
      "b   brrrr       "
    ]
  ]
}