{
  "name": "multi_laboratory1_1_base4",
  "refpalette": "c70cities:multi_laboratory1_1_base4_palette",
  "xsize": 16,
  "zsize": 16,
  "slices": [
    [
      "vabccccccccccccc",
      "vabccccccccccccc",
      "vabccccccccccccc",
      "vabccccccccccccc",
      "vabccccccccccccc",
      "vabccccccccccccc",
      "vabccccccccdcccc",
      "vabccccccccccccc",
      "vabccccccccccccc",
      "vabccccccccccccc",
      "vabcc!cccccccccc",
      "vabccccccccccccc",
      "vabcccccccccccce",
      "vabccccccccdccce",
      "vabcccccccccccef",
      "vabccccccccccce "
    ],
    [
      "vabghhhhhhgi    ",
      "vabjk l mn i    ",
      "vabhl    omi    ",
      "vabhkp     i    ",
      "vabh       q    ",
      "vabgrstrurwi    ",
      "vabiiiiiiiidf   ",
      "vabxyAAAA xi    ",
      "vabB  C    i    ",
      "vabD nt    i    ",
      "vab tE FI  i    ",
      "vabJoKKKKt i    ",
      "vabJ AAAA  i  LM",
      "vab    C   d  fM",
      "vab o o    i  Mf",
      "vabD nN I  O  M "
    ],
    [
      "vabghhhhhhgi    ",
      "vabh       P    ",
      "vabQ       P    ",
      "vabQ       i    ",
      "vabh       R    ",
      "vabg       i    ",
      "vabiiiiiiiidS   ",
      "vab   TUV  i    ",
      "vab        P    ",
      "vab        P    ",
      "vab        P    ",
      "vab  tWXn  P    ",
      "vab  V T   i   M",
      "vab        d  SM",
      "vab        i  Mf",
      "vab        O  M "
    ],
    [
      "vabgYYYYYYgi    ",
      "vab        Z    ",
      "vab0       Z    ",
      "vab1       i    ",
      "vab        Z    ",
      "vabg       i    ",
      "vabiiiiiiiidS   ",
      "vab        i    ",
      "vab        P    ",
      "vab        P    ",
      "vab        P    ",
      "vab        P    ",
      "vab        i   M",
      "vab        d  SM",
      "vab        i  Mf",
      "vab        O  M "
    ],
    [
      "vabg      gi    ",
      "vab        i    ",
      "vab        i    ",
      "vab2       i    ",
      "vab        i    ",
      "vabg       i    ",
      "vabiiiiiiiid    ",
      "vab        i    ",
      "vab        i    ",
      "vab        i    ",
      "vab        i    ",
      "vab        i    ",
      "vab        i   M",
      "vab        d   M",
      "vab        i  Mf",
      "vab        i  M "
    ],
    [
      "vabg333333gZ4444",
      "vab35333363Z4744",
      "vab33333333Z4744",
      "vab33333333Z4744",
      "vab35333353Z4744",
      "vabg3333333Z4444",
      "vabiiiiiiiid4444",
      "vab88888888Z4444",
      "vab88888888Z4444",
      "vab88688788Z4444",
      "vab88688788Z4444",
      "vab88788688Z4444",
      "vab88788788Z444M",
      "vab88888888d444M",
      "vab88888888Z44Mf",
      "vab88688788Z44M "
    ]
  ]
}