{
  "name": "multi_laboratory1_4_base2",
  "refpalette": "c70cities:multi_laboratory1_4_base2_palette",
  "xsize": 16,
  "zsize": 16,
  "slices": [
    [
      "vabccccccccdcccc",
      "vabccccccccccccc",
      "vabccccccccccccc",
      "vabccccccccccccc",
      "vabccccccccccccc",
      "vabccccccccccccc",
      "vabccccccccccccc",
      "vabccccccccdcccc",
      "vabeeeeeeeeccccc",
      "vabeeeeeeeeccccc",
      "vabeeeeeeeeccccc",
      "vabeeeeeeeeccccc",
      "vabeeee!eeeccccc",
      "vabbbbbbbbbbbbbb",
      "vaaaaaaaaaaaaaaa",
      "vvvvvvvvvvvvvvvv"
    ],
    [
      "vabffffffffd   g",
      "vabGGGhij kf  lg",
      "vabGmGGij nf opq",
      "vabGGGGij kf  rr",
      "vabGGGGij  f    ",
      "vabGGGhij  s    ",
      "vabmGhhij  f    ",
      "vabffffffffd    ",
      "vabttuuuuttf    ",
      "vab        w    ",
      "vabxyAyAyAyf    ",
      "vab B B B Bf    ",
      "vabCBCBCBCBfDEE ",
      "vabbbbbbbbbbbbbb",
      "vaaaaaaaaaaaaaaa",
      "vvvvvvvvvvvvvvvv"
    ],
    [
      "vabffffffffd    ",
      "vab FIJK   f    ",
      "vabLLM K  Nf   O",
      "vabIP PK   f  o ",
      "vabFQ  K   f    ",
      "vabIRI K   S    ",
      "vabLFTUK   f    ",
      "vabffffffffd    ",
      "vabVWWWWWWVf    ",
      "vab        X    ",
      "vabYyZyZyZyf    ",
      "vab B B B Bf    ",
      "vab B B B Bf    ",
      "vabbbbbbbbbbbbbb",
      "vaaaaaaaaaaaaaaa",
      "vvvvvvvvvvvvvvvv"
    ],
    [
      "vabffffffffd    ",
      "vab    K   f    ",
      "vab L  K   f0   ",
      "vab    K   f0   ",
      "vabF   K   f    ",
      "vab    K   1    ",
      "vabL   K   f    ",
      "vabffffffffd    ",
      "vab WWWWWW f    ",
      "vab        f    ",
      "vabyyyyyyyyf    ",
      "vab B B B Bf    ",
      "vab B B B Bf    ",
      "vabbbbbbbbbbbbbb",
      "vaaaaaaaaaaaaaaa",
      "vvvvvvvvvvvvvvvv"
    ],
    [
      "vabffffffffd    ",
      "vab    K   f    ",
      "vab    K   f    ",
      "vab    K   f    ",
      "vab    K   f    ",
      "vab    K   f    ",
      "vab    K   f    ",
      "vabffffffffd    ",
      "vab22222222f    ",
      "vab22 22222f    ",
      "vab2 222222f    ",
      "vab22222222f    ",
      "vab32323232f    ",
      "vabbbbbbbbbbbbbb",
      "vaaaaaaaaaaaaaaa",
      "vvvvvvvvvvvvvvvv"
    ],
    [
      "vabffffffffd4454",
      "vab6666777714484",
      "vab666677!714484",
      "vab6666777714455",
      "vab6666777714444",
      "vab6666779714444",
      "vab6666777714444",
      "vabffffffffdffff",
      "vab@@@@@@@@f####",
      "vab@ @ @$@ f#5##",
      "vab@$@ @ @ f#5##",
      "vab@$@ @ @ f#5##",
      "vab@ @ @ @ f####",
      "vabbbbbbbbbbbbbb",
      "vaaaaaaaaaaaaaaa",
      "vvvvvvvvvvvvvvvv"
    ]
  ]
}