{
  "name": "multi_hospital_2_floor1",
  "refpalette": "c70cities:multi_hospital_2_floor1_palette",
  "xsize": 16,
  "zsize": 16,
  "slices": [
    [
      "                ",
      "                ",
      " a              ",
      "bc              ",
      "db              ",
      "dc              ",
      "db              ",
      "dc              ",
      "deeeeeeeeeeeeee ",
      "dddddddddddddde ",
      "dddddddddddddde ",
      "dddddddddddddde ",
      "dddddddddddddde ",
      "dddddddddddddde ",
      "dddddddddddddde ",
      "dddddddddddddde "
    ],
    [
      "                ",
      "                ",
      " a              ",
      "ff              ",
      " f              ",
      "gf              ",
      "hf              ",
      "if              ",
      "jeeeeeeeeeeeeee ",
      "klmn op  q  rst ",
      "klu   p  q wxs  ",
      " lmn  pyA   ust ",
      " BBBBCBBBq wxst ",
      "         D  us  ",
      " EEEEFEEEq wxst ",
      " lmn  pmn   ust "
    ],
    [
      "                ",
      "                ",
      " a              ",
      "ff              ",
      " f              ",
      " f              ",
      " f              ",
      " f              ",
      "jeeeeeeeeeeeeee ",
      "IJ    KLMN   st ",
      " J    K  N   j  ",
      " J    K O    st ",
      " PPPPQPPPN   st ",
      "         R   j  ",
      " SSSSTSSSN   st ",
      " J    K      st "
    ],
    [
      "                ",
      "                ",
      " a              ",
      "ff              ",
      " f              ",
      " f              ",
      " f              ",
      " f              ",
      "jeecceecceeccee ",
      " J    K  N   st ",
      " J    K  N   j  ",
      " J    K  N   st ",
      " PPPPPPPPN   st ",
      "         N   j  ",
      " SSSSSSSSN   st ",
      " J    K      st "
    ],
    [
      "                ",
      "                ",
      " a              ",
      "ff              ",
      " f              ",
      " f              ",
      " f              ",
      " f              ",
      "jeeeeeeeeeeeeee ",
      " J    K  N   st ",
      " J    K  N   j  ",
      " J    K  N   st ",
      " PPPPPPPPN   st ",
      " U   U   N   j  ",
      " SSSSSSSSN   st ",
      " J    K      st "
    ],
    [
      "                ",
      "                ",
      " a              ",
      "ff              ",
      " f              ",
      " f              ",
      " f              ",
      " f              ",
      "jeeeeeeeeeeeeee ",
      " sVVVsVVVsVVVst ",
      " sVVVsVVVsVVVs  ",
      " sVVVsVVVsVVVst ",
      " sVVVsVVVsVVVst ",
      " sVVVsVVVsVVVs  ",
      " sVVVsVVVsVVVst ",
      " sVVVsVVVsVVVst "
    ]
  ]
}