{
  "name": "multi_megatower1_1_floor10",
  "refpalette": "c70cities:multi_megatower1_1_floor10_palette",
  "xsize": 16,
  "zsize": 16,
  "slices": [
    [
      "           abc  ",
      "           dbc  ",
      "           dbcef",
      "           dbcgg",
      "          hijkcc",
      "           abccc",
      "           abccc",
      "           abccc",
      "           dbccc",
      "           dbccc",
      "           dbccc",
      "          hijkbb",
      "           abb  ",
      "           abb  ",
      "           abb  ",
      "           dbb  "
    ],
    [
      "           a l  ",
      "           d le ",
      "           d lm ",
      "           d l  ",
      "          hi kdn",
      "           a o  ",
      "           a o  ",
      "           a oaa",
      "           d opq",
      "           d o  ",
      "           d ors",
      "          hi koo",
      "           a o  ",
      "           a o  ",
      "           a o  ",
      "           d o  "
    ],
    [
      "           a lg ",
      "           d lm ",
      "           d l  ",
      "           d l  ",
      "          hi kdt",
      "           a o  ",
      "           a o  ",
      "           a o  ",
      "           d o  ",
      "           d o  ",
      "           d o  ",
      "          hi k  ",
      "           a o  ",
      "           a o  ",
      "           a o  ",
      "           d o  "
    ],
    [
      "           a lmu",
      "           d l  ",
      "           d l  ",
      "           d l w",
      "          hi kdd",
      "           a o  ",
      "           a o  ",
      "           a o  ",
      "           d o  ",
      "           d o  ",
      "           d o  ",
      "          hi k  ",
      "           a o  ",
      "           a o  ",
      "           a o  ",
      "           d o  "
    ],
    [
      "           a x f",
      "           d x u",
      "           d x  ",
      "           d x  ",
      "          hi kdd",
      "           a y  ",
      "           a A  ",
      "           a y  ",
      "           d A  ",
      "           d y  ",
      "           d A  ",
      "          hi k  ",
      "           a y  ",
      "           a A  ",
      "           a y  ",
      "           d A  "
    ],
    [
      "           a B  ",
      "           d B f",
      "           d B g",
      "           d Beg",
      "          hiCkDD",
      "           a BEE",
      "           a BEF",
      "           a BEE",
      "           d BEE",
      "           d BEF",
      "           d BEE",
      "          hiCkDD",
      "           a B  ",
      "           a B  ",
      "           a B  ",
      "           d B  "
    ]
  ]
}