{
  "name": "multi_megatower1_1_floor14",
  "refpalette": "c70cities:multi_megatower1_1_floor14_palette",
  "xsize": 16,
  "zsize": 16,
  "slices": [
    [
      "   abGcdceeeff  ",
      "   abGcceeeeff  ",
      "   abGccdcdeffgh",
      "   abGccedeeffii",
      "   jbGccdeeefkff",
      "   abGcceeeeffff",
      "   abGccdceeffff",
      "   abGcccedeffff",
      "   abGccdeeeffff",
      "   abGcccdeeffff",
      "   abGccddeeffff",
      "   jbGcdeeeefkff",
      "   abGccedeeffff",
      "   abGcdeeeeffff",
      "   abGccdcdeffff",
      "   abGcceeeeffff"
    ],
    [
      "   almn      o  ",
      "   alpq      og ",
      "   alrn    s ot ",
      "   almq    u o  ",
      "   jlmq    w kxy",
      "   alrn    A    ",
      "   alpn         ",
      "   alrn         ",
      "   almq         ",
      "   alpn         ",
      "   alrq    u    ",
      "   jlmn    w kB ",
      "   alrn    A oCC",
      "   alpq    s oD ",
      "   almq      o  ",
      "   alrn      oE "
    ],
    [
      "   alF       oi ",
      "   al        ot ",
      "   aIJ     s o  ",
      "   alF       o  ",
      "   jlF       kxK",
      "   aIJ          ",
      "   al           ",
      "   alJ          ",
      "   alF          ",
      "   a            ",
      "   alJ          ",
      "   jlF       k  ",
      "   aIJ       oLM",
      "   al      s oN ",
      "   alF       o  ",
      "   alJ       o  "
    ],
    [
      "   al        otO",
      "   a         o  ",
      "   al        o  ",
      "   al        o P",
      "   jI        kxx",
      "   aI           ",
      "   al           ",
      "   al           ",
      "   al           ",
      "   a            ",
      "   aI           ",
      "   jl        k  ",
      "   al        o  ",
      "   al        o  ",
      "   aI        o  ",
      "   al        oQQ"
    ],
    [
      "   aI        R h",
      "   a         R O",
      "   a         R  ",
      "   a         R  ",
      "   j         kxx",
      "   al        R  ",
      "   al        R  ",
      "   a         R  ",
      "   aI        R  ",
      "   a         R  ",
      "   a         R  ",
      "   j         kS ",
      "   a         R  ",
      "   aI        R  ",
      "   aI        RQQ",
      "   a         R  "
    ],
    [
      "   T       U k  ",
      "   T       x k h",
      "   T       x k i",
      "   T       x kgi",
      "   V      WXYkkk",
      "   T       U k  ",
      "   T       U k  ",
      "   T       U k  ",
      "   T       x k  ",
      "   T       x k  ",
      "   T       x k  ",
      "   V      WXYkkk",
      "   T       U k  ",
      "   T       U kQQ",
      "   T       U k  ",
      "   T       x k  "
    ]
  ]
}