{
  "name": "multi_warehouse_1_ground",
  "refpalette": "c70cities:multi_warehouse_1_ground_palette",
  "xsize": 16,
  "zsize": 16,
  "slices": [
    [
      "zzaabbccccccccbz",
      "zaaabbccccccccbz",
      "aaaabbccccccccbz",
      "azaadbccccccccbz",
      "zazabbccccccccbz",
      "zaaabbccccccccbz",
      "zaaabbccccccccbz",
      "zaaadbccccccccbz",
      "zaaabbccccccccbz",
      "zaaabbbbbbbbbbbz",
      "zzaabdbbbbbbbbdz",
      "zaaabbbbbbbbbbbz",
      "azaabbbbbbbbbbbz",
      "aaazdbbbbbbbbbdz",
      "aazadbbbdbbbdbdz",
      "zzzzzzzzzzzzzzzz"
    ],
    [
      "           effgh",
      "     g   eieeeg ",
      "     j    klemnh",
      "     j  k eemeg ",
      "     j     keigh",
      "     n   o    g ",
      "          ipppgh",
      "          q ppg ",
      "h            rn ",
      "     ggg    ggnh",
      "      s     s   ",
      "      s     s  h",
      "     ggtu   gn  ",
      "     ggngwxgng h",
      "                ",
      " h h  h   h  y y"
    ],
    [
      "           kefg ",
      "     g     eefg ",
      "     j     eemg ",
      "     j    eeeeg ",
      "     j       in ",
      "     g        g ",
      "     j      ppg ",
      "     j      ppg ",
      "     j       rg ",
      "     gggAAAAngg ",
      "      s     s   ",
      "      s     s   ",
      "     gn B   gg  ",
      "     ggggCDggg  ",
      "                ",
      "                "
    ],
    [
      "     j      kkg ",
      "     n     eeeg ",
      "     j     eeeg ",
      "     j     keeg ",
      "     j        g ",
      "     g        g ",
      "     j      pqg ",
      "     j      ppg ",
      "     j       rg ",
      "     gggAAAAngg ",
      "      s     s   ",
      "      s     s   ",
      "     gg     ng  ",
      "     gggnEEggg  ",
      "                ",
      "                "
    ],
    [
      "    FgI       g ",
      "    Fg  J     n ",
      "    FgI       g ",
      "    FgI       g ",
      "    FgI       g ",
      "    Fgi J     g ",
      "    FgI       g ",
      "    FgI      ig ",
      "    FgIiEEEEirg ",
      "    Fngnggggggn ",
      "    FFI     IFF ",
      "    FFI     IFF ",
      "    Fgg K  JggF ",
      "    FgggggggggF ",
      "    FFFFFFFFFFF ",
      "                "
    ],
    [
      "     gLLLLLLLLg ",
      "     gLLbLLLLLg ",
      "     gLLLLLLLLg ",
      "     gLLLLLLLLg ",
      "     gLLLLLLLLg ",
      "     nLLbLLLLLg ",
      "     gLLLLLLLLg ",
      "     gLLLLLLLLg ",
      "     gLLLLLLLrg ",
      "     gggggggggg ",
      "     MMMMMMMMM  ",
      "     MMMMMMMMM  ",
      "     MMMMMMMMM  ",
      "     MMMMMMMMM  ",
      "                ",
      "                "
    ]
  ]
}