{
  "name": "multi_laboratory1_6_base5",
  "refpalette": "c70cities:multi_laboratory1_6_base5_palette",
  "xsize": 16,
  "zsize": 16,
  "slices": [
    [
      "                ",
      "                ",
      "                ",
      "                ",
      "                ",
      "                ",
      "                ",
      "     aaaaaa     ",
      "   aab    baa   ",
      " aaa        aaa ",
      "ab~~~~~~~~~~~~ba",
      "a~~~~~~~~~~~~~~a",
      "a~~~~~~~~~c~~~~a",
      " ~~~~~~~~~~~~~~ ",
      " ~~~~~~~~~~~~~~ ",
      " ~~~~~~~~~~~~~~ "
    ],
    [
      "                ",
      "                ",
      "                ",
      "                ",
      "                ",
      "                ",
      "                ",
      "     aaaaaa     ",
      "   aab    baa   ",
      " aaa        aaa ",
      "ab~~~~~~~~~~~~ba",
      "a~~~~~~~~~~~~~~a",
      "a~~~~~~~~~c~~~~a",
      " ~~~~~~~~~~~~~~ ",
      " !~~~~~~~~~~~~~ ",
      " ~~~~~~~~~~~~~~ "
    ],
    [
      "                ",
      "                ",
      "                ",
      "                ",
      "                ",
      "                ",
      "                ",
      "     aaaaaa     ",
      "   aab    baa   ",
      " aaa        aaa ",
      "ab~~~~~~~~~~~~ba",
      "a~~~~~~~~~~~~~~a",
      "a~~~~~~~~~c~~~~a",
      " ~~~~~~~~~~~~~~ ",
      " d~~~~~~~~~~~~~ ",
      " ~~~~~~~~~~~~~~ "
    ],
    [
      "                ",
      "                ",
      "                ",
      "                ",
      "                ",
      "                ",
      "                ",
      "     aaaaaa     ",
      "   aab    baa   ",
      " aaa        aaa ",
      "ab~~~~~~~~~~~~ba",
      "a~~~~~~~~~~~~~~a",
      "a~~~~~~~~~c~~~~a",
      " ~~~~~~~~~~~~~~ ",
      " d~~~~~~~~~~~~~ ",
      " ~~~~~~~~~~~~~~ "
    ],
    [
      "                ",
      "                ",
      "                ",
      "                ",
      "                ",
      "                ",
      "                ",
      "     aaaaaa     ",
      "   aab    baa   ",
      " aaa        aaa ",
      "ab~~~~~~~~~~~~ba",
      "a~~~~~~~~~~~~~~a",
      "a~~~~~~~~~c~~~~a",
      " ~~~~~~~~~~~~~~ ",
      " d~~~~~~~~~~~~~ ",
      " ~~~~~~~~~~~~~~ "
    ],
    [
      "eeeeeeeeeeeeeeee",
      "eeeeeeeeeeeeeeee",
      "eeeeeeeeeeeeeeee",
      "eeeeeeeeeeeeeeee",
      "eeeeeeeeeeeeeeee",
      "eeeeeeeeeeeeeeee",
      "eeeeeeeeeeeeeeee",
      "eeeeeaaaaaaeeeee",
      "eeeaab    baaeee",
      "eaaa        aaae",
      "ab~~~~~~~~~~~~ba",
      "a~~~~~~~~~~~~~~a",
      "a~~~~~~~~~c~~~~a",
      " ~~~~~~~~~~~~~~ ",
      " c~~~~~~~~~~~~~ ",
      " ~~~~~~~~~~~~~~ "
    ]
  ]
}