{
  "name": "multi_laboratory1_10_base7",
  "refpalette": "c70cities:multi_laboratory1_10_base7_palette",
  "xsize": 16,
  "zsize": 16,
  "slices": [
    [
      "zzzzzzzzzzzzzzzz",
      "aaaaaaaaaaaaaaaz",
      "aaaaaaaaaaaaaaaz",
      "aaaaaaaaaaaaaaaz",
      "aaaaaaaaaaaaaaaz",
      "aaaaaaaaaaaaaaaz",
      "aaaaaaaaaaaaaaaz",
      "aaaaaaaaaaaaaaaz",
      "aaaaaaaaaaaaaaaz",
      "aaaaaaaaaaaaaaaz",
      "aaaaaaaaaaaaaaaz",
      "aaaaaaaaaaaaaaaz",
      "aaaaaaaaaaaaaaaz",
      "aaaaaaaaaaaaaaaz",
      "aaaaaaaaaaaaaaaz",
      "aaaaaaaaaaaaaaaz"
    ],
    [
      "zzzzzzzzzzzzzzzz",
      "aaaaaaaaaaaaaaaz",
      "bbbbaaaaaaaaaaaz",
      "cacaaaaaaaaaaaaz",
      "aaacaaaaaaaaaaaz",
      "adcaaaaaaaaaaaaz",
      "aaaaaaaaaaaaaaaz",
      "aaaaaaaaaaaaaaaz",
      "aaaaaaaaaaaaaaaz",
      "aaaaaaaaaaaaaaaz",
      "aaaaaaaaaaaaaaaz",
      "aaaaaaaaaaaaaaaz",
      "aaaaaaaaaaaaaaaz",
      "aaaaaaaaaaaaaaaz",
      "eaaaaaaaaaaaaaaz",
      "   aaaaaaaaaaaaz"
    ],
    [
      "zzzzzzzzzzzzzzzz",
      "aaaaaaaaaaaaaaaz",
      "bbbbaaaaaaaaaaaz",
      "daacaaaaaaaaaaaz",
      "ecccaaaaaaaaaaaz",
      "fddaaaaaaaaaaaaz",
      "eaaaaaaaaaaaaaaz",
      "aaaaaaaaaaaaaaaz",
      "aaaaaaaaaaaaaaaz",
      "aaaaaaaaaaaaaaaz",
      "aaaaaaaaaaaaaaaz",
      "aaaaaaaaaaaaaaaz",
      "aaaaaaaaaaaaaaaz",
      " aaaaaaaaaaaaaaz",
      "  aaaaaaaaaaaaaz",
      "   eaagghaaaaaaz"
    ],
    [
      "zzzzzzzzzzzzzzzz",
      "aaaaaaaaaaaaaaaz",
      "bbbbaaaaaaaaaaaz",
      "faacaaaaaaaaaaaz",
      " cccaaaaaaaaaaaz",
      "  !aaaaaaaaaaaaz",
      "faaaaaaaaaaaaaaz",
      "caaaaaaaaaaaaaaz",
      "aaaaaaaaaaaaaaaz",
      "aaaaaaaaaaaaaaaz",
      "aaaaaaaaaaaaaaaz",
      "aaaaaaaaaaaaaaaz",
      "aaaaaaaaaaaaaaaz",
      " aaaaaaaaaaaaaaz",
      " aaaaaaaaaaaaaaz",
      "    aa aaaaaaaaz"
    ],
    [
      "zzzzzzzzzzzzzzzz",
      "aaaaaaaaaaaaaaaz",
      "bbbbaaaaaaaaaaaz",
      " ecaaaaaaaaaaaaz",
      " fccaaaaaaaaaaaz",
      "  aaaaaaaaaaaaaz",
      "faaaaaaaaaaaaaaz",
      "aaaaaaaaaaaaaaaz",
      "aaaaaaaaaaaaaaaz",
      "aaaaaaaaaaaaaaaz",
      "aaaaaaaaaaaaaaaz",
      "aaaaaaaaaaaaaaaz",
      "aaaaaaaaaaaaaaaz",
      "aaaaaaaaaaaaaaaz",
      "aaaaaaaaaaaaaaaz",
      "iaaaa iaaaaaaaaz"
    ],
    [
      "zzzzzzzzzzzzzzzz",
      "aaaaaaaaaaaaaaaz",
      "bbbbaaaaaaaaaaaz",
      "  ccaaaaaaaaaaaz",
      "   caaaaaaaaaaaz",
      " iaaaaaaaaaaaaaz",
      "aaaaaaaaaaaaaaaz",
      "aaaaaaaaaaaaaaaz",
      "aaaaaaaaaaaaaaaz",
      "aaaaaaaaaaaaaaaz",
      "aaaaaaaaaaaaaaaz",
      "aaaaaaaaaaaaaaaz",
      "aaaaaaaaaaaaaaaz",
      "aaaaaaaaaaaaaaaz",
      "aaaaaaaaaaaaaaaz",
      "aaaaaaaaaaaaaaaz"
    ]
  ]
}