{
  "name": "multi_laboratory1_0_base5",
  "refpalette": "c70cities:multi_laboratory1_0_base5_palette",
  "xsize": 16,
  "zsize": 16,
  "slices": [
    [
      "vvvvvvvvvvvvvvvv",
      "vaaaaaaaaaaaaaaa",
      "vabbbbbbbbbbcccc",
      "vab===!====d    ",
      "vab========d    ",
      "vab========ddddd",
      "vab========de   ",
      "vabfg======d    ",
      "vab========d    ",
      "vabfg==hh==d    ",
      "vabg=======d    ",
      "vab========d    ",
      "vab========d    ",
      "vab====i===d    ",
      "vabf=======d    ",
      "vadjjjjjjjjdjjjj"
    ],
    [
      "vvvvvvvvvvvvvvvv",
      "vaaaaaaaaaaaaaaa",
      "vabbbbbbbbbbcccc",
      "vabklmnnnnmj    ",
      "vabk mmmmmmj    ",
      "vabo  pppp jjjjj",
      "vab        q    ",
      "vabfg      q    ",
      "vabk  pppp d    ",
      "vabfg p  p q    ",
      "vabr  pppp q    ",
      "vabst  u  wq    ",
      "vabxy mmmm q    ",
      "vab  Amhhm q    ",
      "vabfg mmmm q    ",
      "vadjjjjjjjjdjjjj"
    ],
    [
      "vvvvvvvvvvvvvvvv",
      "vaaaaaaaaaaaaaaa",
      "vabbbbbbbbbbcccc",
      "vabB   CnC j    ",
      "vabB       j    ",
      "vab        jjjjj",
      "vab             ",
      "vabfg           ",
      "vabB       d    ",
      "vabfg           ",
      "vab             ",
      "vabDE           ",
      "vabFI   A       ",
      "vab J K         ",
      "vabfr  w        ",
      "vadjjjjjjjjdjjjj"
    ],
    [
      "vvvvvvvvvvvvvvvv",
      "vaaaaaaaaaaaaaaa",
      "vabbbbbbbbbbcccc",
      "vab     g  j    ",
      "vab        j    ",
      "vab        jjjjj",
      "vablL           ",
      "vabfr           ",
      "vab        d    ",
      "vabfg           ",
      "vab             ",
      "vab g           ",
      "vab             ",
      "vab             ",
      "vabf            ",
      "vadjjjjjjjjdjjjj"
    ],
    [
      "vvvvvvvvvvvvvvvv",
      "vaaaaaaaaaaaaaaa",
      "vabbbbbbbbbbcccc",
      "vabl    g  j    ",
      "vab        j    ",
      "vabl       jjjjj",
      "vablg           ",
      "vabf            ",
      "vab        d    ",
      "vabfg           ",
      "vab             ",
      "vab g           ",
      "vab             ",
      "vab             ",
      "vabf            ",
      "vadjjjjjjjjdjjjj"
    ],
    [
      "vvvvvvvvvvvvvvvv",
      "vaaaaaaaaaaaaaaa",
      "vabbbbbbbbbbcccc",
      "vabfMMMMgMMj    ",
      "vabfMMMMMMMj    ",
      "vabfMMMMMMMjjjjj",
      "vabfMMMMMMMMMMMM",
      "vabfMMMMMMMMMMMM",
      "vabNMMMMMMMdMMMM",
      "vabfMMMMMMMMMMMM",
      "vabfMMMMMMMMMMMM",
      "vabfMMMMMMMMMMMM",
      "vabfMMMMMMMMMMMM",
      "vabfMMMMMMMMMMMM",
      "vabfMMMMMMMMMMMM",
      "vadjjjjjjjjdjjjj"
    ]
  ]
}