{
  "name": "multi_communitycenter_8_floor1",
  "refpalette": "c70cities:multi_communitycenter_8_floor1_palette",
  "xsize": 16,
  "zsize": 16,
  "slices": [
    [
      "aaaaabc    d e  ",
      "aaaaab   ffdge  ",
      "hhhhhb   iidge  ",
      "j          d e  ",
      "j          d e  ",
      "j   kbdddddd e  ",
      "j    bg    gge  ",
      "hhhhhbeeeeeeee  ",
      "aaaaab          ",
      "aaaaab          ",
      "aaaaab          ",
      "aaaaab          ",
      "aaaalb          ",
      "bbbbbb          ",
      "                ",
      "                "
    ],
    [
      " m              ",
      "m  m        g   ",
      "nnnnn       g   ",
      "                ",
      "                ",
      "                ",
      "g    gg    gg   ",
      "nnnnno          ",
      "mpqmro          ",
      "     o          ",
      "     o          ",
      "    mo          ",
      "ssssso          ",
      "oooooo          ",
      "                ",
      "                "
    ],
    [
      "                ",
      "            g   ",
      "            g   ",
      "                ",
      "                ",
      "                ",
      "g    gg    gg   ",
      "                ",
      "                ",
      "                ",
      "                ",
      "                ",
      "                ",
      "                ",
      "                ",
      "                "
    ],
    [
      "                ",
      "            t   ",
      "            t   ",
      "                ",
      "                ",
      "                ",
      "t    tt    tt   ",
      "                ",
      "                ",
      "                ",
      "                ",
      "                ",
      "                ",
      "                ",
      "                ",
      "                "
    ],
    [
      "uuuuuuuuuuuuhww ",
      "uuuuuuuuuuuuhww ",
      "uuuuuuuuuuuuhww ",
      "uuuuuuuuuuuuhww ",
      "uuuuuuuuuuuuhww ",
      "uuuuuuuuuuuuhww ",
      "hhhhhhhhhhhhhww ",
      "wwwwwwwwwwwwwww ",
      "wwwwwwwwwwwwwww ",
      "                ",
      "                ",
      "                ",
      "                ",
      "                ",
      "                ",
      "                "
    ],
    [
      "                ",
      "                ",
      "                ",
      "                ",
      "                ",
      "                ",
      "     ~          ",
      "                ",
      "                ",
      "                ",
      "                ",
      "                ",
      "                ",
      "                ",
      "                ",
      "                "
    ]
  ]
}