{
  "name": "multi_megatower1_5_floor3",
  "refpalette": "c70cities:multi_megatower1_5_floor3_palette",
  "xsize": 16,
  "zsize": 16,
  "slices": [
    [
      "aaaaaaaaaaaaaaaa",
      "aaaaaaaaaaaaaaaa",
      "aaaabaaaaaabaaaa",
      "cdddecccdddecccd",
      "    f      f    ",
      "                ",
      "                ",
      "                ",
      "                ",
      "                ",
      "                ",
      "                ",
      "                ",
      "                ",
      "                ",
      "                "
    ],
    [
      "g  hijg  klimn  ",
      " opqirpo  sis  o",
      "ttttbttttttbtttt",
      "cdddecccdddecccd",
      "    f      f    ",
      "                ",
      "                ",
      "                ",
      "                ",
      "                ",
      "                ",
      "                ",
      "                ",
      "                ",
      "                ",
      "                "
    ],
    [
      "    i      i    ",
      "  u i     wix   ",
      "yyytbtyyyytbtyyy",
      "cdddecccdddecccd",
      "    f      f    ",
      "                ",
      "                ",
      "                ",
      "                ",
      "                ",
      "                ",
      "                ",
      "                ",
      "                ",
      "                ",
      "                "
    ],
    [
      "    i      i    ",
      "ABC i BCBC i BCB",
      "DDDtbtDDDDtbtDDD",
      "cdddecccdddecccd",
      "    f      f    ",
      "                ",
      "                ",
      "                ",
      "                ",
      "                ",
      "                ",
      "                ",
      "                ",
      "                ",
      "                ",
      "                "
    ],
    [
      "    i      i    ",
      "    i      i    ",
      "ttttbttttttbtttt",
      "cdddecccdddecccd",
      "    f      f    ",
      "                ",
      "                ",
      "                ",
      "                ",
      "                ",
      "                ",
      "                ",
      "                ",
      "                ",
      "                ",
      "                "
    ],
    [
      "    EF     E    ",
      "    E      E    ",
      "IIIIbIIIIIIbIIII",
      "cdddecccdddecccd",
      "    f      f    ",
      "                ",
      "                ",
      "                ",
      "                ",
      "                ",
      "                ",
      "                ",
      "                ",
      "                ",
      "                ",
      "                "
    ]
  ]
}