{
  "name": "multi_cafe_3_floor1",
  "refpalette": "c70cities:multi_cafe_3_floor1_palette",
  "xsize": 16,
  "zsize": 16,
  "slices": [
    [
      " ab          cd ",
      " ab          cd ",
      " ab e   f   ggh ",
      " ab         !cd ",
      " ab          cd ",
      " ab          cd ",
      " ab          cd ",
      " ab e   f   ggh ",
      " ab          cd ",
      " ab          ch ",
      " abbbbbbbbbb==d ",
      " aaaaaaaaaaaaid ",
      "             id ",
      "              d ",
      "                ",
      "                "
    ],
    [
      "  =     aaaaacd ",
      " j=     aaaaacd ",
      " k=lllllffffggh ",
      " m=     aaaaacd ",
      " n=     aaaaacd ",
      " k=     aaaaacd ",
      " j=     aaaaocd ",
      "  =lllllffffggh ",
      "  =     aaaaacd ",
      "  =     aaaaach ",
      "  ============d ",
      "             id ",
      "             id ",
      "              d ",
      "                ",
      "                "
    ],
    [
      "  =     g   pqd ",
      " n=     gr  sqd ",
      " m=     f  rggh ",
      " m=     g  r qd ",
      " n=     g r tqd ",
      " m=     g   tqd ",
      " u=     g   rqd ",
      "  =     f   ggh ",
      "  =     gr  rqd ",
      "  =     g  qqqh ",
      "  ============d ",
      "           wwxd ",
      "           wwxd ",
      "              d ",
      "                ",
      "                "
    ],
    [
      "  =yyyyygrAAAAB ",
      "  =yyyyyg AAAAB ",
      "  =     f   ggh ",
      "  =yyyyygrAAAAB ",
      "  =yyyyyg AAAAB ",
      "  =yyyyyg AAAAB ",
      "  =yyyyyg AAAAB ",
      "  =     f   ggh ",
      "  =yyyyyg AAAAB ",
      "  =yyyyygr    h ",
      "  ========AAAAB ",
      "   wwwwwwxCAAAB ",
      "   wwwwwwxCDDDd ",
      "          AAAAd ",
      "                ",
      "                "
    ],
    [
      "wxhAAADEEEE     ",
      "wxhAAAEEEE      ",
      "wxhFFFFFhhIIIII ",
      "wxhAAAEEEE      ",
      "wxhAAADEEEE     ",
      "wxhAAADEEEE     ",
      "wxhAAAEEEE      ",
      "wxhFFFFFhhIIIII ",
      "wxhAAAEEEE      ",
      "wxhhhhJJKJIIIII ",
      "wxAAAAEEEE      ",
      "wxCAAADEEEE     ",
      "wxCDDDDEEEE     ",
      "  AAAAEEEE      ",
      "                ",
      "                "
    ],
    [
      "EEI             ",
      "EEI             ",
      "EEI             ",
      "EEI             ",
      "EEI             ",
      "EEI             ",
      "EEI             ",
      "EEI             ",
      "EEI             ",
      "EEIIII~         ",
      "EE              ",
      "EEE             ",
      "EEE             ",
      "EE              ",
      "                ",
      "                "
    ]
  ]
}