{
  "name": "multi_convenientstore_3_ground",
  "refpalette": "c70cities:multi_convenientstore_3_ground_palette",
  "xsize": 16,
  "zsize": 16,
  "slices": [
    [
      "aaaaaaaaaaaaHHHb",
      "cccccccccccaHHHb",
      "cccccccccccaHHHb",
      "cccccccccccaHHHb",
      "cccccccccccaHHHb",
      "cccccccccccaHHHb",
      "cccccccccccaHHHb",
      "cccccccccccaHHHb",
      "cccccccccccaHHHb",
      "cccccccccccaHHHb",
      "cccccccccccaHHHb",
      "cccccccccccaHHHb",
      "aaaaaaaaaaaaHHHb",
      "HHHHHHHHHHHHHHHb",
      "HHHHHHHHHHHHHHHb",
      "bbbbbbbbbbbbbbbb"
    ],
    [
      "aaaaaaaaaaaaddde",
      "cccccccccccaddde",
      "cccccccccccaddde",
      "cccccccccccaddde",
      "cccccccccccaHHHb",
      "cccccccccccaHHHb",
      "cccccccccccaHHHb",
      "cccccccccccaHHHb",
      "cccccccccccaHHHb",
      "cccccccccccaHHHb",
      "cccccccccccaHHHb",
      "cccccccc!ccaHHHb",
      "aaaaaaaaaaaaHHHb",
      "HHHHHHHHHHHHHHHb",
      "HHHHHHHHHHHHHHHb",
      "HHHHHHHHHHHHHHHb"
    ],
    [
      "fghhhhhiiiij    ",
      "       k  lj    ",
      "       k  mj    ",
      "       k  nj   e",
      "  oppp k qnj   e",
      "  r    s  nj   e",
      " t     uwxwj y e",
      "  AAAAAu       e",
      "  BCCDDA       e",
      "     EFk       e",
      "I    J k  Kj   e",
      " L!ILEMkNOOj   e",
      "jjjjjjjjjjjj   e",
      "  P   PN N     e",
      "               e",
      "               e"
    ],
    [
      "Qghhhhhiihij    ",
      "       k  Rj    ",
      "       k   j    ",
      "       k   h    ",
      "   ST  k   h    ",
      "  U    VW  h    ",
      " tX   YuwZwj    ",
      "  00012u   3    ",
      "   B4DDA   3    ",
      "     E k   3    ",
      "     5 k   j    ",
      " 6778E k  9j    ",
      "jjjjjjjjjjjj    ",
      "  @  N@N        ",
      "                ",
      "                "
    ],
    [
      "gghhhhhiihij    ",
      "       k   j    ",
      "       k   j    ",
      "       k   h    ",
      "       k   h    ",
      "       k   h    ",
      " t67778uwwwj    ",
      "  000##u   3    ",
      "    BDDA   3    ",
      "     E k   3    ",
      "     E$k   j    ",
      "  %I^E kN  j    ",
      "jjjjjjjjjjjj    ",
      "@@&@@@&         ",
      "                ",
      "                "
    ],
    [
      "hhhhhhhiihij    ",
      "       k   j    ",
      "       k   j    ",
      "       k  *j    ",
      "       k  *j    ",
      "       k  *j    ",
      "()+++++uwwwj    ",
      "  iiiiiuN  c    ",
      "     -DA   c    ",
      "     DDA   c    ",
      "     DDAN Nj    ",
      "[@@[@@[@@@@j    ",
      "jjjjjjjjjjjj    ",
      "     N@         ",
      "                ",
      "                "
    ]
  ]
}