{
  "name": "multi_megatower1_4_floor11",
  "refpalette": "c70cities:multi_megatower1_4_floor11_palette",
  "xsize": 16,
  "zsize": 16,
  "slices": [
    [
      "a   bbbbbbbbbbbb",
      "a   bbbbbbbbbbbb",
      "a   bbbbbbbbbbbb",
      "cdeebbbbbbbbbbbb",
      "bbbbfbbbbbbfgggg",
      "bbbbbbbbbbbbgggg",
      "bbbbbbbbbbbbgggg",
      "bbbbbbbbbbbbgggg",
      "bbbbbbbbbbbbgggg",
      "bbbbbbbbbbbbgggg",
      "bbbbbbbbbbbbgggg",
      "hhhhfbbbbbbfgggg",
      "    ibbbbbbbbbbb",
      "    ibbbbbbbbbbb",
      "    ibbbbbbbbbbb",
      "    ibbbbbbbbbbb"
    ],
    [
      "a   jk lml n   o",
      "a   jk lll p    ",
      "a   jq lll rs  t",
      "aeuujw    xry AB",
      "CDEFfx  yyyfIJII",
      "    K   LM rN  I",
      "    O    MPrQ  R",
      "S   T      rU  I",
      "x   V      rU  R",
      "    O    MPrQ  I",
      "x   K   oM r   R",
      "KKKKfxm yyyfIWII",
      "    K    MPr    ",
      "    K   oM r   X",
      "    K      Y  Z0",
      "    KL   m 1   2"
    ],
    [
      "a   j      3    ",
      "a   j      4    ",
      "a   j      r    ",
      "ae  j     5ry   ",
      "C 67f5  yyyfI8II",
      "    K      r   I",
      "    O      9@  #",
      "    $      9@  I",
      "5   %      9@  #",
      "    O      9@  I",
      "5   K      r   #",
      "    f5   yyfI^II",
      "    K      r    ",
      "    K      r    ",
      "    K      &    ",
      "    K      *    "
    ],
    [
      "a   j      (    ",
      "a   j      (    ",
      "a   j      r    ",
      "aeeej     5r    ",
      "C)  f5   m fIIII",
      "    K      r   I",
      "    O      9@  I",
      "    O      9@  I",
      "5   O      9@  I",
      "    O      9@  I",
      "5   K      r   I",
      "    f5     fIIII",
      "    K      r    ",
      "    K      r    ",
      "    K      (    ",
      "    K      (    "
    ],
    [
      "a   +--- - [----",
      "a   +------[----",
      "a   +-] -]-[-]--",
      "aeee+------[----",
      "CCCCf---- -fIIII",
      "    r------[{{{{",
      "    r-]--}-[{{{{",
      "    r------[{{{{",
      "    r------[{{{{",
      "    r- --]-[{{{{",
      "    r------[{{{{",
      "    f  ----fIIII",
      "    r------[----",
      "    r-] -]-[-]--",
      "    r------[----",
      "    r---- -[----"
    ],
    [
      "\\   \\     |\\    ",
      "\\   \\    `|\\`` `",
      "\\   \\`:  :|\\ :` ",
      "\\e;'\\ , ` .\\`` `",
      "////f//////f////",
      "----\\ `   .\\ `  ",
      "--]-\\ : `:|\\||||",
      "----\\`<   |\\` |`",
      "----\\  ` `|\\  ||",
      "--]-\\ :  :|\\  |`",
      "----\\   ` .\\``||",
      "////f//////f////",
      "    \\ `   .\\ ` `",
      "    \\ : `:|\\ :  ",
      "    \\`!`  |\\ `  ",
      "    \\`  ``|\\    "
    ]
  ]
}