{
  "name": "multi_communitycenter_7_base1",
  "refpalette": "c70cities:multi_communitycenter_7_base1_palette",
  "xsize": 16,
  "zsize": 16,
  "slices": [
    [
      "HHHHHHHHHHHHHHHv",
      "HHHHHHHHHHHHHHHv",
      "HHHHHHHHHHHHHHHv",
      "HHHHHHHHHHHHHHHv",
      "HHHHHHHHHHHHHHHv",
      "HHHHHHHHHHHHHHHv",
      "HHHHHHHHHHHHHHHv",
      "HHHHHHHHHHHHHHHv",
      "HHHHHHHHHHHHHHHv",
      "HHHHHHHHHHHHHHHv",
      "HHHHHHHHHHHHHHHv",
      "HHHHHHHHHHHHHHHv",
      "HHHHHHHHHHHHHHHv",
      "HHHHHHHHHHHHHHHv",
      "HHHHHHHHHHHHHHHv",
      "HHHHHHHHHHaHHHHv"
    ],
    [
      "   bH  Hc    dev",
      "fgfbHhiHc     ev",
      "jkjbHHHHc     ev",
      "   bHHHHc     ev",
      "fgflHHHHl    lev",
      "   bHHHHc     ev",
      "   bmmmmc     ev",
      "   bnnnnc     ev",
      "              ev",
      "              ev",
      "              ev",
      "jkjl    lkjkjlev",
      "   c    b     ev",
      "fgfc    bgfgf ev",
      "jkjc    bkjkj ev",
      "   c    b     ev"
    ],
    [
      "    H  H      ev",
      "    HooH      ev",
      "    HHHH      ev",
      "    mmmm      ev",
      "   lnnnnl    lev",
      "              ev",
      "              ev",
      "              ev",
      "              ev",
      "              ev",
      "              ev",
      "   l    l    lev",
      "              ev",
      "              ev",
      "              ev",
      "              ev"
    ],
    [
      "    mmmmd    dev",
      "    nnnn      ev",
      "              ev",
      "              ev",
      "   l    l    lev",
      "              ev",
      "              ev",
      "              ev",
      "              ev",
      "              ev",
      "              ev",
      "   l    l    lev",
      "              ev",
      "              ev",
      "              ev",
      "              ev"
    ],
    [
      "   l    ld  dlev",
      "   l    l   dlev",
      "   l    l    lev",
      "   l    l   dlev",
      "pppl    lpppplev",
      "   l    l    lev",
      "   l    l    lev",
      "   l    l    lev",
      "   l    l    lev",
      "   l    l    lev",
      "   l    l    lev",
      "ppplpppplpppplev",
      "   l    l    lev",
      "   l    l    lev",
      "   l    l    lev",
      "   l    l    lev"
    ],
    [
      "eeeq    qeeeeeev",
      "eeeq    qeeeeeev",
      "eeeq    qeeeeeev",
      "eeeq    qeeeeeev",
      "eeel    leeeeeev",
      "eeeerrrreeeeeeev",
      "eeeeeeeeeeeeeeev",
      "eeeeeeeeeeeeeeev",
      "eeeeeeeeeeeeeeev",
      "eeeeeeeeeeeeeeev",
      "eeeeeeeeeeeeeeev",
      "eeeeeeeeeeeeeeev",
      "eeeeeeeeeeeeeeev",
      "eeeeeeeeeeeeeeev",
      "eeeeeeeeeeeeeeev",
      "eeeeeeeeeeeeeeev"
    ]
  ]
}