{
  "name": "multi_megatower1_6_base2",
  "refpalette": "c70cities:multi_megatower1_6_base2_palette",
  "xsize": 16,
  "zsize": 16,
  "slices": [
    [
      "vvvvvvvvvvvvvvvv",
      "aaaaaaaaaaaaaaav",
      "aaaaaaaaaaaaaaav",
      "vvvvvvvvvvvvvaav",
      "vvvvvvvvvvvvvaav",
      "HHHHHHHHHHHvvaav",
      "HHbHHHHHHbHvvaav",
      "HHHHHHHHHHHvvaav",
      "HHHHHHHHHHHvvaav",
      "HHHHHHHHHHHvvaav",
      "HHHHHHHHHHHvvaav",
      "HHHHHHHHHHHvvaav",
      "HHHHHHHHHHHvvaav",
      "HHbHHHHHHbHvvaav",
      "HHHHHHHHHHHvvaav",
      "HHHHHHHHHHHvvaav"
    ],
    [
      "vvvvvvvvvvvvvvvv",
      "aaaaaaaaaaaaaaav",
      "aaaaaaaaaaaaaaav",
      "vvvvvvvvvvvvvaav",
      "ccccccccccccvaav",
      "de dedef   cvaav",
      "  b    f b cvaav",
      "ghighghf   cvaav",
      "        jjjcvaav",
      "        d ecvaav",
      "        g hcvaav",
      "        d ecvaav",
      "dek     g hcvaav",
      "  bl    mb cvaav",
      "gh      d ecvaav",
      "        g hcvaav"
    ],
    [
      "vvvvvvvvvvvvvvvv",
      "aaaaaaaaaaaaaaav",
      "aaaaaaaaaaaaaaav",
      "vvvvvvvvvvvvvaav",
      "            vaav",
      "            vaav",
      "  b      b  vaav",
      "            vaav",
      "            vaav",
      "            vaav",
      "            vaav",
      "            vaav",
      "            vaav",
      "  b      b  vaav",
      "            vaav",
      "            vaav"
    ],
    [
      "vvvvvvvvvvvvvvvv",
      "aaaaaaaaaaaaaaav",
      "aaaaaaaaaaaaaaav",
      "vvvvvvvvvvvvvaav",
      "            vaav",
      "            vaav",
      "  b      b  vaav",
      "            vaav",
      "            vaav",
      "            vaav",
      "            vaav",
      "            vaav",
      "            vaav",
      "  b      b  vaav",
      "            vaav",
      "            vaav"
    ],
    [
      "vvvvvvvvvvvvvvvv",
      "aaaaaaaaaaaaaaav",
      "aaaaaaaaaaaaaaav",
      "vvvvvvvvvvvvvaav",
      "            vaav",
      "  n      n  vaav",
      "  b      bo vaav",
      "            vaav",
      "            vaav",
      "            vaav",
      "            vaav",
      "            vaav",
      "            vaav",
      "  b      bo vaav",
      "            vaav",
      "            vaav"
    ],
    [
      "vvvvvvvvvvvvvvvv",
      "aaaaaaaaaaaaaaav",
      "aaaaaaaaaaaaaaav",
      "vvvvvvvvvvvvvaav",
      "vvvvvvvvvvvvvaav",
      "pppppppppppvvaav",
      "bbbbbbbbbbpvvaav",
      "ppbppppppbpvvaav",
      "ppbppppppbpvvaav",
      "ppbppppppbpvvaav",
      "ppbppppppbpvvaav",
      "ppbppppppbpvvaav",
      "ppbppppppbpvvaav",
      "bbbbbbbbbbpvvaav",
      "ppbppppppbpvvaav",
      "ppbppppppbpvvaav"
    ]
  ]
}