{
  "name": "multi_militarycamp1_1_ground",
  "refpalette": "c70cities:multi_militarycamp1_1_ground_palette",
  "xsize": 16,
  "zsize": 16,
  "slices": [
    [
      "aazaazzzzzzzzzzz",
      "abbbzzzHzzHHzzzz",
      "zHzbHHHHHczHHczz",
      "czzbHHHHHH=HHz=z",
      "HzzbHHHHHHHzzzzz",
      "=HzbHHHHHHH=zHzz",
      "HHzbHHHHHHHHczzz",
      "H=zbHHHHHHHHzz=z",
      "c=zbHHHHHHHHHzzz",
      "HzzbHHHHHHHHHHzz",
      "HHHHHHHHHHHHczzz",
      "HHHHHHHHHHHH=zzz",
      "HHHHH=HHHHH=zzzz",
      "z=HHHz=HH=zczz=z",
      "zabbzzzHzzzHHzzz",
      "zzaaazzzzzzzzzzz"
    ],
    [
      "         dd     ",
      "eefghh  gghh  h ",
      "  e    hhi   jk ",
      "l e mmmno    pq ",
      " re smst      u ",
      " wf mmmx      y ",
      "lie mmmx      y ",
      "  e mmm A     y ",
      "  e sms       k ",
      "  fBmmmnB     k ",
      "  l          BC ",
      "  l          yC ",
      "             yD ",
      "  lnEFFIhh  Jiq ",
      "eef KKKL uMMKKL ",
      "                "
    ],
    [
      "                ",
      "eef             ",
      "  e NON         ",
      "l e PQR         ",
      "  e S T         ",
      "  f UUU         ",
      "l e UVUW        ",
      "  e U U         ",
      "  e S T         ",
      "  f U U         ",
      "  l X X         ",
      "                ",
      "                ",
      "  l   Y         ",
      "eef             ",
      "                "
    ],
    [
      "                ",
      "ZZ0             ",
      "  1             ",
      "2 1  2          ",
      "2 1 222         ",
      "2 0 333         ",
      "2 1 U U         ",
      "  1 3 3         ",
      "  1 U U         ",
      "  0 U U         ",
      "    X X         ",
      "                ",
      "                ",
      "                ",
      "440             ",
      "                "
    ],
    [
      "                ",
      "                ",
      "                ",
      "                ",
      "                ",
      "    222         ",
      "    222         ",
      "    222         ",
      "     2          ",
      "     2          ",
      "                ",
      "                ",
      "                ",
      "                ",
      "                ",
      "                "
    ],
    [
      "                ",
      "                ",
      "                ",
      "                ",
      "                ",
      "                ",
      "                ",
      "     ~          ",
      "                ",
      "                ",
      "                ",
      "                ",
      "                ",
      "                ",
      "                ",
      "                "
    ]
  ]
}