{
  "name": "multi_gallery_0_floor1",
  "refpalette": "c70cities:multi_gallery_0_floor1_palette",
  "xsize": 16,
  "zsize": 16,
  "slices": [
    [
      "                ",
      "                ",
      "   aaaaaaaaaaa  ",
      "    b     c     ",
      "    b     d     ",
      "    e f  gd     ",
      "    e h  id     ",
      "    b     d     ",
      "    b     d     ",
      "    b j  kd     ",
      "    e l  md     ",
      "    e     d     ",
      "    e     d     ",
      "    b n  od     ",
      "    b p  qd     ",
      "    b     d     "
    ],
    [
      "                ",
      "                ",
      "   aaaaaaaaaaa  ",
      "    b     c     ",
      "    e     d     ",
      "    b     d     ",
      "    b     d     ",
      "    e     d     ",
      "    b     d     ",
      "    r     d     ",
      "    r     d     ",
      "    b     d     ",
      "    b     d     ",
      "    e     d     ",
      "    e     d     ",
      "    e     d     "
    ],
    [
      "                ",
      "                ",
      "   aaaaaaaaaaa  ",
      "    b     c     ",
      "    b     d     ",
      "    b     d     ",
      "    b     d     ",
      "    r     d     ",
      "    r     d     ",
      "    b     d     ",
      "    b     d     ",
      "    b     d     ",
      "    b     d     ",
      "    b     d     ",
      "    b     d     ",
      "    b     d     "
    ],
    [
      "                ",
      "                ",
      "   aaaaaaaaaaa  ",
      "    b     c     ",
      "    r     d     ",
      "    r     d     ",
      "    b     d     ",
      "    b     d     ",
      "    b     d     ",
      "    b     d     ",
      "    e     d     ",
      "    e     d     ",
      "    e     d     ",
      "    b     d     ",
      "    b     d     ",
      "    r     d     "
    ],
    [
      "                ",
      "                ",
      "   aaaaaaaaaaa  ",
      "    b     c     ",
      "    b     d     ",
      "    b     d     ",
      "    r     d     ",
      "    r     d     ",
      "    b     d     ",
      "    b     d     ",
      "    b     d     ",
      "    b     d     ",
      "    e     d     ",
      "    e     d     ",
      "    b     d     ",
      "    b     d     "
    ],
    [
      "                ",
      "                ",
      "   aaaaaaaaaaa  ",
      "   sb     tuus  ",
      "   sb     tuus  ",
      "   sb     tuus  ",
      "   sb     tuus  ",
      "   sb     tuus  ",
      "   sb     tuus  ",
      "   sb     tuus  ",
      "   sb     tuus  ",
      "   sb     tuus  ",
      "   sb     tuus  ",
      "   sb     tuus  ",
      "   sb     tuus  ",
      "   sb     tuus  "
    ]
  ]
}