{
  "name": "multi_militarybase_2_base2",
  "refpalette": "c70cities:multi_militarybase_2_base2_palette",
  "xsize": 16,
  "zsize": 16,
  "slices": [
    [
      "vvvvvvvvvvvvvvvv",
      "aaaaaaavaaaaaaaa",
      "aaaaaaabaaaaaaaa",
      "aaaaaaabaaaaaaaa",
      "aaaaaaabaaaaaaaa",
      "bbbbbbbvbbbbbbbb",
      "aaaaaaabaaaaaaaa",
      "aaaaaaabaaaaaaaa",
      "aaaaaaabaaaaaaaa",
      "cccccccvcccccccd",
      "eeeeeeebeeeeeeee",
      "eeeeeeebeeeeeeee",
      "eeeeeeebeeeeeeee",
      "bbvbbbbvbbbbvbbb",
      "  f    f    f   ",
      "                "
    ],
    [
      "vvvvvvvvvvvvvvvv",
      " g g g v g g g g",
      " h h h   h h h h",
      "                ",
      "                ",
      "iijiiiiviiikiiii",
      "                ",
      "                ",
      "lmnmlm   mllnmmm",
      "ooooooiviooooooo",
      "                ",
      "                ",
      "                ",
      "ppvppppvppppvppp",
      "                ",
      "                "
    ],
    [
      "vvvvvvvvvvvvvvvv",
      " g g g v g g g g",
      " h h h   h h h h",
      "                ",
      "                ",
      "iiqiiiiviiiriiii",
      "                ",
      "                ",
      "s t u     wxt   ",
      "ooyooAiviBoC!ooD",
      "                ",
      "                ",
      "                ",
      "  v    v    v   ",
      "                ",
      "                "
    ],
    [
      "vvvvvvvvvvvvvvvv",
      "       v        ",
      "                ",
      "                ",
      "                ",
      "iiiiiiiviiiiiiii",
      "                ",
      "                ",
      "                ",
      "iiiiiiiviiiiiiii",
      "                ",
      "                ",
      "                ",
      "  v    v    v   ",
      "                ",
      "                "
    ],
    [
      "vvvvvvvvvvvvvvvv",
      "       v        ",
      "                ",
      "                ",
      "                ",
      "iiiiiiiviiiiiiii",
      "       p        ",
      "       p        ",
      "       p        ",
      "pppppppvpppppppp",
      "                ",
      "                ",
      "                ",
      "EEvEEEEvEEEEvEEE",
      "                ",
      "                "
    ],
    [
      "vvvvvvvvvvvvvvvv",
      "FF!FFFFvFFFFFFFF",
      "IIIIIIIbIIIIIIII",
      "IIIIIIIbIIIIIIII",
      "IIIIIIIbIIIIIIII",
      "bbbbbbbvbbbbbbbb",
      "IIIIIIIbIIIIIIII",
      "IIIIIIIbIIIIIIII",
      "IIIIIIIbIIIIIIII",
      "IIIIIIIvIIIIIIII",
      "IIIIIIIbIIIIIIII",
      "IIIIIIIbIIIIIIII",
      "IIIIIIIbIIIIIIII",
      "JJvJJJJvJJJJvJJJ",
      "                ",
      "                "
    ]
  ]
}