{
  "name": "multi_militarybase_0_ground",
  "refpalette": "c70cities:multi_militarybase_0_ground_palette",
  "xsize": 16,
  "zsize": 16,
  "slices": [
    [
      "zzzzzzzzzzzzzzzz",
      "zaaaaaaaaaaaaaaa",
      "zabzzbzbbzbzzzzz",
      "zazzzzbbbbzbbbbb",
      "zazbzzzbcccccccc",
      "zazzzzbbcddddddd",
      "zazzzzbzcedddddd",
      "zazzzzzbc dddddd",
      "zazzbzzbc dddddd",
      "zabbzzbbc dddccc",
      "zazzzzzbcddddccc",
      "zazbzzbzcddddccc",
      "zazzzzzbcddddccc",
      "fabzzbbbcccccccc",
      "ghbbbbzbbbbbbbbb",
      "ghbbbbbbbbbbbbbb"
    ],
    [
      "                ",
      " aaaaaaaaaaaaaaa",
      " ai j j ij j j j",
      " a  j           ",
      " aj  j  kkkkkkkk",
      " a   j  kl   m n",
      " a jj   k o     ",
      " a j j  k o     ",
      " a    j k o  pq ",
      " ai  j  k o  kkr",
      " aj j j ks   k  ",
      " aj  j  k  tuk  ",
      " a  j   kwwwwk  ",
      "xa      kkkkkk  ",
      "x y             ",
      "      y        y"
    ],
    [
      "                ",
      " aaaaaaaaaaaaaaa",
      " ai     i       ",
      " a              ",
      " a      ABBBBAAA",
      " a      A     m ",
      " a      B       ",
      " a      B       ",
      " a      A    pC ",
      " ai     A    AAD",
      " a      B    A  ",
      " a      B    B  ",
      " a      AEFI A  ",
      " a      AABBAA  ",
      "                ",
      "                "
    ],
    [
      "                ",
      " aaaaaaaaaaaaaaa",
      " ai     i       ",
      " a       JJJJ   ",
      " a      AAAAAAAA",
      " a     JA      m",
      " a     JA       ",
      " a     JA       ",
      " a     JA    p  ",
      " ai    JA    AAA",
      " a     JA    A  ",
      " a     JA    B  ",
      " a     JA    A  ",
      " a      AABBAA  ",
      "                ",
      "                "
    ],
    [
      "                ",
      " aaaaaaaaaaaaaaa",
      " ai     i       ",
      " a              ",
      " a      AKKKKAAA",
      " a      ALLLLL  ",
      " a      KL      ",
      " a      KL      ",
      " a      AL   pLL",
      " ai     AL   AAK",
      " a      KL   A  ",
      " a      KL   A  ",
      " a      AL   A  ",
      " a      AAAAAA  ",
      "                ",
      "                "
    ],
    [
      "                ",
      " MMNNNNNONNNNNNN",
      " MPQQQQQQPQQQQQQ",
      " xR      S      ",
      " xR     kkkkkkkk",
      " xR     kTTTTT  ",
      " xR     kTTTTTTT",
      " xR     kTTTTTTT",
      " UR     kTTTTpTT",
      "VWR     kTTTTkkk",
      " xR     kTTTTk  ",
      " x      kTTTTk  ",
      " x      kTTTTk  ",
      " x      kTTTTk  ",
      "        kXXXXk  ",
      "        kXXXXk  "
    ]
  ]
}