{
  "name": "multi_flatapartment_2_ground",
  "refpalette": "c70cities:multi_flatapartment_2_ground_palette",
  "xsize": 16,
  "zsize": 16,
  "slices": [
    [
      "GaaaaGGGGGGGGGGG",
      "aaaaaaaaaaaaaaaG",
      "aaaaaaaaaaaaaaaG",
      "aaaaaaaaaaaaaaaG",
      "aaaaaaaaaaaaaaaG",
      "aaaaaaaaaaaaaaaG",
      "aaaaaaaaaaaaaaaG",
      "aaaaaaaaaaaaaaaG",
      "aaaaaaaaaaaaaaaG",
      "aaaaaaaaaaaaaaaG",
      "aaaaaaaaaaaaaaaG",
      "aaaaaaaaaaaaaaaG",
      "aaaaaaaaaaaaaaaG",
      "aaaaaaaaaaaaaaaG",
      "aaaaaaaaaaaaaaaG",
      "GaaaaGGGGGGGGGGG"
    ],
    [
      "b    bbbbbbbbbbc",
      "d    deeedeeeedb",
      "             fgb",
      "               b",
      "      f g    hib",
      "d    dh id    db",
      " g  f gjf g  fgb",
      " i kh ijh i    b",
      " g  f gjf g    b",
      " i  h ijh i  hib",
      "d    df gd    db",
      "      h i    fgb",
      "               b",
      "             hib",
      "d    dllldlllldb",
      "b    bbbbbbbbbb "
    ],
    [
      "               m",
      "n    n   n    n ",
      "                ",
      "                ",
      "                ",
      "n    n   n    n ",
      "                ",
      "                ",
      "                ",
      "                ",
      "n    n   n    n ",
      "                ",
      "                ",
      "                ",
      "n    n   n    n ",
      "                "
    ],
    [
      "               o",
      "np  pnp pnp  pn ",
      "              p ",
      "                ",
      "              p ",
      "n    n   n    n ",
      "              p ",
      "                ",
      "                ",
      "              p ",
      "n    n   n    n ",
      "              p ",
      "                ",
      "              p ",
      "np  pnp pnp  pn ",
      "                "
    ],
    [
      "                ",
      "n qq n q n qq n ",
      "r    r   r      ",
      "              q ",
      "                ",
      "n    n   n   rn ",
      "                ",
      "              q ",
      "              q ",
      "                ",
      "n    n   n   rn ",
      "                ",
      "              q ",
      "r    r   r      ",
      "n qq n q n qq n ",
      "                "
    ],
    [
      "                ",
      "qqqqqqqqqqqqqqq ",
      "aaaaaaaaaaaaaaq ",
      "a    a   a   aq ",
      "a    a   a   aq ",
      "aaaaaaaaaaaaaaq ",
      "a    a   a   aq ",
      "a    a   a   aq ",
      "a    a   a   aq ",
      "a    a   a   aq ",
      "aaaaaaaaaaaaaaq ",
      "a    a   a   aq ",
      "a    a   a   aq ",
      "aaaaaaaaaaaaaaq ",
      "qqqqqqqqqqqqqqq ",
      "                "
    ]
  ]
}