{
  "name": "multi_laboratory1_14_base7",
  "refpalette": "c70cities:multi_laboratory1_14_base7_palette",
  "xsize": 16,
  "zsize": 16,
  "slices": [
    [
      "aaaaaaaaaaaaaaaz",
      "aaaaaaaaaaaaaaaz",
      "aaaaaaaaaaaaaaaz",
      "aaaaaaaaaaaaaaaz",
      "aaaaaaaaaaaaaaaz",
      "aaaaaaaaaaaaaaaz",
      "aaaaaaaaaaaaaaaz",
      "aaaaaaaaaaaaaaaz",
      "aaaaaaaaaaaaaaaz",
      "aaaaaaaaaaaaaaaz",
      "aaaaaaaaaaaaaaaz",
      "aaaaaaaaaaaaaaaz",
      "aaaaaaaaaaaaaaaz",
      "aaaaaaaaaaaaaaaz",
      "aaaaaaaaaaaaaaaz",
      "zzzzzzzzzzzzzzzz"
    ],
    [
      "aaaaaaaaaaaaaaaz",
      "aaaaaaaaaaaaaaaz",
      "aaaaaaaaaaaaaaaz",
      "aaaaaaaaaaaaaaaz",
      "aaaaaaaaaaaaaaaz",
      "aaaaaaaaaaaaaaaz",
      "aaaaaaaaaaaaaaaz",
      "aaaaaaaaaaaaaaaz",
      "aaaaaaaaaaaaaaaz",
      "aaaaaaaaaaaaaaaz",
      "aaaaaaaaaaaaaaaz",
      "aaaaaaaaaaaaaaaz",
      "aaaaaaaaaaaaaaaz",
      "aaaaaaaaaaaaaaaz",
      "aaaaaaaaaaaaaaaz",
      "zzzzzzzzzzzzzzzz"
    ],
    [
      "aaaaaaaaaaaaaaaz",
      "aaaaaaaaaaaaaaaz",
      "aaaaaaaaaaaaaaaz",
      "aaaaaaaaaaaaaaaz",
      "aaaaaaaaaaaaaaaz",
      "aaaaaaaaaaaaaaaz",
      "aaaaaaaaaaaaaaaz",
      "aaaaaaaaaaaaaaaz",
      "aaaaaaaaaaaaaaaz",
      "aaaaaaaaaaaaaaaz",
      "aaaaaaaaaaaaaaaz",
      "aaaaaaaaaaaaaaaz",
      "aaaaaaaaaaaaaaaz",
      "aaaaaaaaaaaaaaaz",
      "aaaaaaaaaaaaaaaz",
      "zzzzzzzzzzzzzzzz"
    ],
    [
      "aaaaaaaaaaaaaaaz",
      "aaaaaaaaaaaaaaaz",
      "aaaaaaaaaaaaaaaz",
      "aaaaaaaaaaaaaaaz",
      "aaaaaaaaaaaaaaaz",
      "aaaaaaaaaaaaaaaz",
      "aaaaaaaaaaaaaaaz",
      "aaaaaaaaaaaaaaaz",
      "aaaaaaaaaaaaaaaz",
      "aaaaaaaaaaaaaaaz",
      "aaaaaaaaaaaaaaaz",
      "aaaaaaaaaaaaaaaz",
      "aaaaaaaaaaaaaaaz",
      "aaaaaaaaaaaaaaaz",
      "aaaaaaaaaaaaaaaz",
      "zzzzzzzzzzzzzzzz"
    ],
    [
      "aaaaaaaaaaaaaaaz",
      "aaaaaaaaaaaaaaaz",
      "aaaaaaaaaaaaaaaz",
      "aaaaaaaaaaaaaaaz",
      "aaaaaaaaaaaaaaaz",
      "aaaaaaaaaaaaaaaz",
      "aaaaaaaaaaaaaaaz",
      "aaaaaaaaaaaaaaaz",
      "aaaaaaaaaaaaaaaz",
      "aaaaaaaaaaaaaaaz",
      "aaaaaaaaaaaaaaaz",
      "aaaaaaaaaaaaaaaz",
      "aaaaaaaaaaaaaaaz",
      "aaaaaaaaaaaaaaaz",
      "aaaaaaaaaaaaaaaz",
      "zzzzzzzzzzzzzzzz"
    ],
    [
      "aaaaaaaaaaaaaaaz",
      "aaaaaaaaaaaaaaaz",
      "aaaaaaaaaaaaaaaz",
      "aaaaaaaaaaaaaaaz",
      "aaaaaaaaaaaaaaaz",
      "aaaaaaaaaaaaaaaz",
      "aaaaaaaaaaaaaaaz",
      "aaaaaaaaaaaaaaaz",
      "aaaaaaaaaaaaaaaz",
      "aaaaaaaaaaaaaaaz",
      "aaaaaaaaaaaaaaaz",
      "aaaaaaaaaaaaaaaz",
      "aaaaaaaaaaaaaaaz",
      "aaaaaaaaaaaaaaaz",
      "aaaaaaaaaaaaaaaz",
      "zzzzzzzzzzzzzzzz"
    ]
  ]
}