{
  "name": "multi_gasstation_1_ground",
  "refpalette": "c70cities:multi_gasstation_1_ground_palette",
  "xsize": 16,
  "zsize": 16,
  "slices": [
    [
      "HHHHaHHaaaaaaaGG",
      "HHHHHHHaaaaaaaGG",
      "HHHHHHHaaaaaaaGG",
      "HHHHaHHaaaaaaaGG",
      "HHHHaHHaaaaaaaGG",
      "HHHHaHHaaaaaaaGG",
      "HHHHaHHaaaaaaaGG",
      "HHHHaHHaaaaaaaGG",
      "HHHHaHHaaaaaaaGG",
      "HHHHaHHaaaaaaaGG",
      "HHHHaHHaaaaaaaGG",
      "HHHHaHHaaaaaaaGG",
      "HHHHaHHaaaaaaaGG",
      "HHHHHHHHHHbGGGGG",
      "HHHHHHHHHHbGGGGG",
      "GGGGGGGGGGGGGGGG"
    ],
    [
      "  cde  f    gh  ",
      "       i  j jh  ",
      "       k  j lh  ",
      "    e  f  j jh  ",
      "  mno  f     h  ",
      "  p    h  jjlh  ",
      "  cde  f    qh  ",
      "  mno  f    qh  ",
      "       i    qh  ",
      "  cde  hrs hhh  ",
      "  mnt  uw  xgh  ",
      "       u   hyh  ",
      "  cde  hhhhhhh  ",
      "       A Bt     ",
      "       C Dt     ",
      "                "
    ],
    [
      "    e  f     h  ",
      "       E  l gh  ",
      "       F  j jh  ",
      "    e  f    lh  ",
      "    I  f     h  ",
      "       h  jgjh  ",
      "    e  f     h  ",
      "    I  f     h  ",
      "       E     h  ",
      "    e  hJ  hhh  ",
      "       K   L h  ",
      "       K MNhgh  ",
      "    e  hhhhhhh  ",
      "                ",
      "                ",
      "                "
    ],
    [
      "    e  O     P  ",
      "       O     O  ",
      "       O     O  ",
      "    e  O     P  ",
      "       O     P  ",
      "       O    gO  ",
      "    e  O     P  ",
      "       O     P  ",
      "       O     O  ",
      "    e  O   hhO  ",
      "       O   h P  ",
      "       O  !h P  ",
      "    e  OOOOOOO  ",
      "                ",
      "                ",
      "                "
    ],
    [
      "    hQ h  R  h  ",
      "       h     h  ",
      "       h     h  ",
      "    hQ h  Q  h  ",
      "       h     h  ",
      "       hhhhhhh  ",
      "    hR h  R  h  ",
      "       h     h  ",
      "       h    gh  ",
      "    hR h  Rhhh  ",
      "       h   h h  ",
      "       h  ghgh  ",
      "    hQ hhhhhhh  ",
      "                ",
      "                ",
      "                "
    ],
    [
      " SttattttttttaS ",
      " SttattttttttaS ",
      " SttattttttttaS ",
      " SttattttttttaS ",
      " SttattttttttaS ",
      " SttaaaaaaaaaaS ",
      " SttattttttttaS ",
      " SttattttttttaS ",
      " SttattttttttaS ",
      " SttattttttttaS ",
      " SttattttttttaS ",
      " SttattttttttaS ",
      " SttaaaaaaaaaaS ",
      " SSSSSSSSSSSSSS ",
      "                ",
      "                "
    ]
  ]
}