{
  "name": "multi_laboratory1_8_base3",
  "refpalette": "c70cities:multi_laboratory1_8_base3_palette",
  "xsize": 16,
  "zsize": 16,
  "slices": [
    [
      "aaaaaaaaaaaaaaaa",
      "aaaaaaaaaaaaaaaa",
      "aaabaaaaaaaabaaa",
      "aa!aaaaaaaaaaaaa",
      "aaaaaaaaaaaacaaa",
      "aaaaaaaaaacaaaaa",
      "aaaaaaaaaadaaaaa",
      "aaaaaaaaaadaaaaa",
      "aaaaaaddacaaaaaa",
      "aaabaaadddaabaaa",
      "aaaaaaaa!aaaaaaa",
      "aaaaaaadcdaaaaaa",
      "aaaeaacdadaaaaaa",
      "aaafeaaadaaaafaa",
      "aaaaaaeaaafaaeaa",
      "aaaaeaaaaaeaaaaa"
    ],
    [
      "  g h      g i  ",
      " jg h     kg hl ",
      " mnbh j   lnbh  ",
      " opliq     ndi  ",
      "  g ho    rdsh t",
      "   tm     r   m ",
      " o    u w p  ow ",
      " mt jw  x yqu j ",
      "   Audr  rddA   ",
      "BBBbBCDy rDBbBBB",
      "EFIAJKLdsLIgFJLM",
      "MNJOPFhMrrQFFP  ",
      " to MxR S TFU t ",
      "i    VWdyquM    ",
      "iJ   X         t",
      "h     nMxi     n"
    ],
    [
      "  l Y      Z    ",
      "           0    ",
      "   bw       b1  ",
      "            d2  ",
      "  Z m       rt  ",
      "                ",
      "                ",
      "                ",
      "   3 y     d3   ",
      "4 BbBCC   CBbB44",
      " 5 6 7Ksr   F7  ",
      "      h    F8   ",
      "           J    ",
      "       r        ",
      "                ",
      "                "
    ],
    [
      "                ",
      "           1    ",
      "   b        bc  ",
      "             r  ",
      "                ",
      "                ",
      "                ",
      "                ",
      "           r    ",
      "44BbBC1  C cbB 4",
      "  7  9 s1   K   ",
      "                ",
      "                ",
      "                ",
      "                ",
      "                "
    ],
    [
      "                ",
      "           @cd  ",
      "   b        bd# ",
      "                ",
      "                ",
      "                ",
      "                ",
      "                ",
      "                ",
      "BBBbBdcBBBBBbBBB",
      "       cc       ",
      "                ",
      "                ",
      "                ",
      "                ",
      "                "
    ],
    [
      "$%$$$%$$$$%d$$%$",
      "$$$$$$$$$$$dd$$$",
      "$$$b$$$$$$$$b$$$",
      "$$$$$$$$$$$$$$$$",
      "$%$$$^$$$$%$$$&$",
      "$%$$$^$$$$%$$$^$",
      "$%$$$&$$$$%$$$^$",
      "$ $$$&$$$$%$$$%$",
      "$$$$$$$$$$$$$$$$",
      "***b********b***",
      "(((B((((dd((B(((",
      "(((B((((((((B(((",
      "(((B((((((((B(((",
      "%((B((%%&&((B((%",
      "%((B((%((&((B((^",
      "^((B((^((%((B((%"
    ]
  ]
}