{
  "name": "multi_communitycenter_1_base1",
  "refpalette": "c70cities:multi_communitycenter_1_base1_palette",
  "xsize": 16,
  "zsize": 16,
  "slices": [
    [
      "vHHHHHHHHHHHHHHH",
      "vHHHHHHHHHHHHHHH",
      "vHHHHHHHHHHHHHHH",
      "vHHHHHHHHHHHHHHH",
      "vHHHHHHHHHHHHHHH",
      "vHHHHHHHHHHHHHHH",
      "vHHHHHHHHHHHHHHH",
      "vHHHHHHHHHHHHHHH",
      "vHHHHHHHHHHHHHHH",
      "vHHHHHHHHHHHHHHH",
      "vHHHHHHHHHHHHHHH",
      "vHHHHHHHHHHHHHHH",
      "vHHHHHHHHHHHHHHH",
      "vHHHHHHHHHHHHHHH",
      "vHHHHHHHHHHHHHHH",
      "vHHHHHHHaHHHHHHH"
    ],
    [
      "vbbbb     c    d",
      "vbbbb efefc    d",
      "vbbbb ghghc    d",
      "vbbbb     c    d",
      "vbbbbiefefi    i",
      "vbbbb           ",
      "vbbbb           ",
      "vbbbb           ",
      "vbbbb           ",
      "vbbbb           ",
      "vbbbb           ",
      "vbbbbighghi    i",
      "vbbbb     c    d",
      "vbbbb efefc    d",
      "vbbbb ghghc    d",
      "vbbbb     c    d"
    ],
    [
      "vbbbb           ",
      "vbbbb           ",
      "vbbbb           ",
      "vbbbb           ",
      "vbbbbi    i    i",
      "vbbbb           ",
      "vbbbb           ",
      "vbbbb           ",
      "vbbbb           ",
      "vbbbb           ",
      "vbbbb           ",
      "vbbbbi    i    i",
      "vbbbb           ",
      "vbbbb           ",
      "vbbbb           ",
      "vbbbb           "
    ],
    [
      "vbbbb           ",
      "vbbbb           ",
      "vbbbb           ",
      "vbbbb           ",
      "vbbbbi    i    i",
      "vbbbb           ",
      "vbbbb           ",
      "vbbbb           ",
      "vbbbb           ",
      "vbbbb           ",
      "vbbbb           ",
      "vbbbbi    i    i",
      "vbbbb           ",
      "vbbbb           ",
      "vbbbb           ",
      "vbbbb           "
    ],
    [
      "vbbbbi    i    i",
      "vbbbbi    i    i",
      "vbbbbi    i    i",
      "vbbbbi    i    i",
      "vbbbbijjjjijjjji",
      "vbbbbi    i    i",
      "vbbbbi    i    i",
      "vbbbbi    i    i",
      "vbbbbi    i    i",
      "vbbbbi    i    i",
      "vbbbbi    i    i",
      "vbbbbijjjjijjjji",
      "vbbbbi    i    i",
      "vbbbbi    i    i",
      "vbbbbi    i    i",
      "vbbbbi    i    i"
    ],
    [
      "vbbbbbbbbbbbbbbb",
      "vbbbbbbbbbbbbbbb",
      "vbbbbbbbbbbbbbbb",
      "vbbbbbbbbbbbbbbb",
      "vbbbbbbbbbbbbbbb",
      "vbbbbbbbbbbbbbbb",
      "vbbbbbbbbbbbbbbb",
      "vbbbbbbbbbbbbbbb",
      "vbbbbbbbbbbbbbbb",
      "vbbbbbbbbbbbbbbb",
      "vbbbbbbbbbbbbbbb",
      "vbbbbbbbbbbbbbbb",
      "vbbbbbbbbbbbbbbb",
      "vbbbbbbbbbbbbbbb",
      "vbbbbbbbbbbbbbbb",
      "vbbbbbbbbbbbbbbb"
    ]
  ]
}