{
  "name": "multi_megatower1_4_floor12",
  "refpalette": "c70cities:multi_megatower1_4_floor12_palette",
  "xsize": 16,
  "zsize": 16,
  "slices": [
    [
      "a   bbbbbbbbbbbb",
      "a   bbbbbbbbbbbb",
      "a   bbbbbbbbbbbb",
      "cdeebbbbbbbbbbbb",
      "bbbbfbbbbbbfbbbb",
      "bbbbbbbbbbbbbbbb",
      "bbbbbbbbbbbbbbbb",
      "bbbbbbbbbbbbbbbb",
      "bbbbbbbbbbbbbbbb",
      "bbbbbbbbbbbbbbbb",
      "bbbbbbbbbbbbbbbb",
      "bbbbfbbbbbbfbbbb",
      "bbbbbbbbbbbbbbbb",
      "bbbbbbbbbbbbbbbb",
      "bbbbbbbbbbbbbbbb",
      "bbbbbbbbbbbbbbbb"
    ],
    [
      "a   gh ijjik   l",
      "a   ghijjj m    ",
      "a   gn jj jo   p",
      "aeqqgr    so   t",
      "uwxyfABCDBAfEFEE",
      "   Is      o   E",
      "           oJ  K",
      "L          oM  E",
      "    Nl     oM  K",
      " lO N OP OPoJ  E",
      "P OPN O QO o   K",
      "N  sfs  NNNfEREE",
      " lO N OP OPo    ",
      "P OPNlO lO o   S",
      "    N      T  UV",
      "           W   X"
    ],
    [
      "a   g      Y    ",
      "a   g      Z    ",
      "a   g      o    ",
      "ae  g     0o    ",
      "u 12fAB34BAfE5EE",
      "    0      o   E",
      "           6   7",
      "           6   E",
      "           6   7",
      "    N      6   E",
      "           o   7",
      "N  0f0  N NfE8EE",
      "    N      o    ",
      "           o    ",
      "    !      9    ",
      "           @    "
    ],
    [
      "a   g      #    ",
      "a   g      #    ",
      "a   g      o    ",
      "aeeeg     0o    ",
      "u$  fABBBBAfEEEE",
      "    0      o   E",
      "           6   E",
      "           6   E",
      "           6   E",
      "           6   E",
      "           o   E",
      "   0f0     fEEEE",
      "           o    ",
      "           o    ",
      "           #    ",
      "           #    "
    ],
    [
      "a   %^^ ^^ &^^^^",
      "a   %^ ^^^^&^^^^",
      "a   %^*^^!^&^!^^",
      "aeee%^^^^^^&^^^^",
      "uuuuf((((((fEEEE",
      "           &))))",
      "           &))))",
      "           &))))",
      "           &))))",
      "           &))))",
      "           &))))",
      "    f      fEEEE",
      "           &^^^^",
      "           &^*^^",
      "           &^^^^",
      "           &^^^^"
    ],
    [
      "+   +    -[+    ",
      "+   + --  [+-- -",
      "+   + ]  ][+ ]- ",
      "+eI{+- -- }+-- -",
      "\\\\\\\\f\\\\\\\\\\\\f\\\\\\\\",
      "^^^^+^^^^^^+ -  ",
      "^^*^+^|^^*^+[[[[",
      "^^^^+^^^^^^+- [-",
      "^^^^+^^^^^^+  [[",
      "^^*^+^*^^*^+  [-",
      "^^^^+^^^^^^+--[[",
      "\\\\\\\\f\\\\\\\\\\\\f\\\\\\\\",
      "    +^^^^^^+ - -",
      "    +^*^^|^+ ]  ",
      "    +^^^^^^+ -  ",
      "    +^^^^^^+    "
    ]
  ]
}