{
  "name": "multi_militarybase_0_base1",
  "refpalette": "c70cities:multi_militarybase_0_base1_palette",
  "xsize": 16,
  "zsize": 16,
  "slices": [
    [
      "vvvvvvvvvvvvvvvv",
      "vaaaaaavbbbbbbbb",
      "vaaaaaavbbbbbbbb",
      "vaaaaaavbbbbbbbb",
      "vvvvvvvvbbbbbbbb",
      "vccccccccccccccc",
      "vcbbbbbbdddddddd",
      "vcbbbbbbdddddddd",
      "vcbbbbbbdddddddd",
      "vcbbbbbbbbbddccc",
      "vcbbbbbbbbbddc  ",
      "vcbbbeebeebddc  ",
      "vcbbbebbbebddc  ",
      "vcbbbbbbbbbddc  ",
      "vcbbbbeeebbddc  ",
      "vcbbbbbbbbbddc  "
    ],
    [
      "vvvvvvvvvvvvvvvv",
      "vaaaaaav fg gfg ",
      "vaaaaaav  h h h ",
      "vaaaaaav  i j j ",
      "vvvvvvvvkkkkkkkl",
      "vmmvnnnnvoooov  ",
      "v       p       ",
      "v       p       ",
      "v       q       ",
      "vrrvrrrrv    vss",
      "vt           s  ",
      "v            s  ",
      "vt           s  ",
      "v  v         v  ",
      "vt           s  ",
      "v            s  "
    ],
    [
      "vvvvvvvvvvvvvvvv",
      "vaaaaaav fg gfg ",
      "vaaaaaav  h h h ",
      "vaaaaaav  u w w ",
      "vvvvvvvvkkkkkkkx",
      "vy vn Anvoooov  ",
      "v       p       ",
      "v       p       ",
      "v       B       ",
      "vrrvrrrrv    v  ",
      "vC              ",
      "v               ",
      "vt              ",
      "v  v         v  ",
      "vC              ",
      "v               "
    ],
    [
      "vvvvvvvvvvvvvvvv",
      "vaaaaaav        ",
      "vaaaaaav        ",
      "vaaaaaav        ",
      "vvvvvvvvkkkkkkkk",
      "v  vD   voooov  ",
      "v       p       ",
      "v       p       ",
      "v       p       ",
      "vrrvrrrrv    v  ",
      "v               ",
      "v               ",
      "vC              ",
      "v  v         v  ",
      "v               ",
      "v               "
    ],
    [
      "vvvvvvvvvvvvvvvv",
      "vaaaaaav        ",
      "vaaaaaav        ",
      "vaaaaaav        ",
      "vvvvvvvvkkkkkkkk",
      "v  v    v    v  ",
      "v       p       ",
      "v       p       ",
      "v       p       ",
      "vrrvrrrrv    v  ",
      "v               ",
      "v               ",
      "v               ",
      "v  v         v  ",
      "v               ",
      "v               "
    ],
    [
      "vvvvvvvvvvvvvvvv",
      "vaaaaaavcEEEEcEE",
      "vaaaaaavcEEEEcEE",
      "vaaaaaavcEEEEcEE",
      "vvvvvvvvcvvvvcvv",
      "vEEcEEEEcEEEEcEE",
      "vEEcEEEEcEEEEcEE",
      "vEEcEEEEcEEEEcEE",
      "vEEcEEEEcEEEEcEE",
      "vccccccccccccccc",
      "vEEcEEEEcEEEEcEE",
      "vEEcEEEEcEEEEcEE",
      "vEEcEEEEcEEEEcEE",
      "vcccccccccccccEE",
      "vEEcEEEEcEEEEcEE",
      "vEEcEEEEcEEEEcEE"
    ]
  ]
}