{
  "name": "multi_hospital_1_ground",
  "refpalette": "c70cities:multi_hospital_1_ground_palette",
  "xsize": 16,
  "zsize": 16,
  "slices": [
    [
      "GGavvvvvvabbbbbb",
      "GGavvvvvvabbbbbb",
      "GGcvvvvvvcbbbbbb",
      "GGGHHHHHGadddddd",
      "GGGeeeeeGGGGdddG",
      "GGGeeeeeeeeeeeee",
      "GGGeeeeeeeeeeeee",
      "GGGeeeeeeeeeeeee",
      "GGGeeeeeeeeeeeee",
      "GGGeeeeeeGGGGGGG",
      "GGGeeeeeGcffffff",
      "GGGeeeeeGggggggg",
      "GGGeeeeeGghhhhhh",
      "GGGeeeeeGghhhhhh",
      "GGGeeeeeGggggggg",
      "GGGeeeeeGGGGGGGG"
    ],
    [
      "  ijklkm nop    ",
      "  i lll  n      ",
      "  c      cq     ",
      "         arst ts",
      "                ",
      "                ",
      "                ",
      " u              ",
      "                ",
      "                ",
      "         wxxxxxx",
      "                ",
      "                ",
      " u              ",
      "                ",
      "                "
    ],
    [
      "  i yAB  n      ",
      "  i CCC  n      ",
      "  c DED  cq     ",
      "         arst ts",
      "                ",
      "                ",
      "                ",
      " ~              ",
      "                ",
      "                ",
      "         w      ",
      "                ",
      "                ",
      " ~              ",
      "                ",
      "                "
    ],
    [
      "  F III  n      ",
      "  F      n      ",
      "  c      cq     ",
      "         arst ts",
      "                ",
      "                ",
      "                ",
      "                ",
      "                ",
      "                ",
      "         w      ",
      "                ",
      "                ",
      "                ",
      "                ",
      "                "
    ],
    [
      "  F JJJ  n      ",
      "  F      n      ",
      "  crrrrrrcq     ",
      "         arsssss",
      "                ",
      "                ",
      "                ",
      "                ",
      "                ",
      "                ",
      "         w      ",
      "                ",
      "                ",
      "                ",
      "                ",
      "                "
    ],
    [
      "  i      n      ",
      "  i      n      ",
      "  crrrrrrcq     ",
      "         arrrrrr",
      "                ",
      "                ",
      "                ",
      "                ",
      "                ",
      "                ",
      "         w      ",
      "                ",
      "                ",
      "                ",
      "                ",
      "                "
    ]
  ]
}