{
  "name": "multi_laboratory1_5_base5",
  "refpalette": "c70cities:multi_laboratory1_5_base5_palette",
  "xsize": 16,
  "zsize": 16,
  "slices": [
    [
      "vvvvvvvvvvvvvvvv",
      "aaaaaaaaaaaaaaaa",
      "bbbbbbbbbbbbbbbb",
      "                ",
      "            c   ",
      "dddddddddddddddd",
      "d    d    d    d",
      "de  ede  ede  ed",
      "dddddddddddddddd",
      "d    d    d    d",
      "d    d    d    d",
      "df  gd    d    d",
      "d    d    d    d",
      "d    d    d    d",
      "d hi d    d    d",
      "djjjjdjjjjdjjjjd"
    ],
    [
      "vvvvvvvvvvvvvvvv",
      "aaaaaaaaaaaaaaaa",
      "bbbbbbbbbbbbbbbb",
      "                ",
      "             c  ",
      "djjjjjjjjjjjjjjd",
      "j    j    j    j",
      "je  eje  eje  ej",
      "djjjjdjjjjdjjjjd",
      "j    j    j    j",
      "j    j    j    j",
      "j    j    j    j",
      "j    j    j    j",
      "j    j    j    j",
      "j    j    j    j",
      "djjjjdjjjjdjjjjd"
    ],
    [
      "vvvvvvvvvvvvvvvv",
      "aaaaaaaaaaaaaaaa",
      "bbbbbbbbbbbbbbbb",
      "                ",
      "              c ",
      "djjjjjjjjjjjjjjd",
      "j    j    j    j",
      "je  eje  eje  ej",
      "djjjjdjjjjdjjjjd",
      "j    j    j    j",
      "j    j    j    j",
      "j    j    j    j",
      "j    j    j    j",
      "j    j    j    j",
      "j    j    j    j",
      "djjjjdjjjjdjjjjd"
    ],
    [
      "vvvvvvvvvvvvvvvv",
      "aaaaaaaaaaaaaaaa",
      "bbbbbbbbbbbbbbbb",
      "                ",
      "               c",
      "djjjjjjjjjjjjjjd",
      "j    j    j    j",
      "je  eje  eje  ej",
      "djjjjdjjjjdjjjjd",
      "j    j    j    j",
      "j    j    j    j",
      "j    j    j    j",
      "j    j    j    j",
      "j    j    j    j",
      "j    j    j    j",
      "djjjjdjjjjdjjjjd"
    ],
    [
      "vvvvvvvvvvvvvvvv",
      "aaaaaaaaaaaaaaaa",
      "bbbbbbbbbbbbbbbb",
      "                ",
      "                ",
      "djjjjjjjjjjjjjjd",
      "j    j    j    j",
      "je  eje  eje  ej",
      "djjjjdjjjjdjjjjd",
      "j    j    j    j",
      "j    j    j    j",
      "j    j    j    j",
      "j    j    j    j",
      "j    j    j    j",
      "j    j    j    j",
      "djjjjdjjjjdjjjjd"
    ],
    [
      "vvvvvvvvvvvvvvvv",
      "aaaaaaaaaaaaaaaa",
      "bbbbbbbbbbbbbbbb",
      "                ",
      "                ",
      "djjjjjjjjjjjjjjd",
      "j    j    j    j",
      "je  eje  eje  ej",
      "djjjjdjjjjdjjjjd",
      "j    j    j    j",
      "j    j    j    j",
      "j    j    j    j",
      "j    j    j    j",
      "j    j    j    j",
      "j    j    j    j",
      "djjjjdjjjjdjjjjd"
    ]
  ]
}