{
  "name": "multi_megatower1_1_floor9",
  "refpalette": "c70cities:multi_megatower1_1_floor9_palette",
  "xsize": 16,
  "zsize": 16,
  "slices": [
    [
      "           abc  ",
      "           dbc  ",
      "           dbcef",
      "           dbcgg",
      "          hijkcc",
      "           abccc",
      "           abccc",
      "           abccc",
      "           dbccc",
      "           dbccc",
      "           dbccc",
      "          hijkcc",
      "           abccc",
      "           abccc",
      "           abccc",
      "           dbccc"
    ],
    [
      "           a l  ",
      "           d le ",
      "           d lm ",
      "           d l  ",
      "           h kdn",
      "           a o  ",
      "           a o  ",
      "           a o  ",
      "           d op ",
      "           d oqr",
      "           d os ",
      "           h kt ",
      "           a op ",
      "           a oqr",
      "           a os ",
      "           d op "
    ],
    [
      "           a lg ",
      "           d lm ",
      "           d l  ",
      "           d l  ",
      "           h kdu",
      "           a o  ",
      "           a o  ",
      "           a o  ",
      "           d o  ",
      "           d o  ",
      "           d o  ",
      "           h kw ",
      "           a o  ",
      "           a o  ",
      "           a o  ",
      "           d o  "
    ],
    [
      "           a lmx",
      "           d l  ",
      "           d l  ",
      "           d l y",
      "           h kdd",
      "           a o  ",
      "           a o  ",
      "           a o  ",
      "           d o  ",
      "           d o  ",
      "           d o  ",
      "           h kw ",
      "           a o  ",
      "           a o  ",
      "           a o  ",
      "           d o  "
    ],
    [
      "           a A f",
      "           d A x",
      "           d A  ",
      "           d A  ",
      "           h kdd",
      "           a B  ",
      "           a C  ",
      "           a B  ",
      "           d C  ",
      "           d B  ",
      "           d C  ",
      "           h k  ",
      "           a B  ",
      "           a C  ",
      "           a B  ",
      "           d C  "
    ],
    [
      "           a D  ",
      "           d D f",
      "           d D g",
      "           d Deg",
      "           hikEE",
      "           a DFF",
      "           a DFI",
      "           a DFF",
      "           d DFF",
      "           d DFI",
      "           d DFF",
      "           hikEE",
      "           a DFF",
      "           a DFI",
      "           a DFF",
      "           d DFF"
    ]
  ]
}