{
  "name": "multi_militarybase_0_floor1",
  "refpalette": "c70cities:multi_militarybase_0_floor1_palette",
  "xsize": 16,
  "zsize": 16,
  "slices": [
    [
      "                ",
      "                ",
      "                ",
      "                ",
      "        aaaaaaaa",
      "        a       ",
      "        a       ",
      "        a       ",
      "        a       ",
      "        a    aaa",
      "        a    a  ",
      "        ab   a  ",
      "        a    a  ",
      "        a    a  ",
      "        a    a  ",
      "        a    a  "
    ],
    [
      "                ",
      "                ",
      "                ",
      "                ",
      "                ",
      "                ",
      "                ",
      "                ",
      "                ",
      "                ",
      "                ",
      "                ",
      "                ",
      "                ",
      "                ",
      "                "
    ],
    [
      "                ",
      "                ",
      "                ",
      "                ",
      "                ",
      "                ",
      "                ",
      "                ",
      "                ",
      "                ",
      "                ",
      "                ",
      "                ",
      "                ",
      "                ",
      "                "
    ],
    [
      "                ",
      " ~~~~~~~~~~~~~~~",
      " ~~~~~~~~~~~~~~~",
      " ~~~~~~~~~~~~~~~",
      " ~~~~~~~~~~~~~~~",
      " ~~~~~~~~~~~~~~~",
      " ~~~~~~~~~~~~~~~",
      " ~~~~~~~~~~~~~~~",
      " ~~~~~~~~~~~~~~~",
      " ~~~~~~~~~~~~~~~",
      " ~~~~~~~~~~~~~~~",
      " ~~~~~~~~~~~~~~~",
      " ~~~~~~~~~~~~~~~",
      " ~~~~~~~~~~~~~~~",
      " ~~~~~~~~~~~~~~~",
      " ~~~~~~~~~~~~~~~"
    ],
    [
      "                ",
      " ~~~~~~~~~~~~~~~",
      " ~~~~~~~~~~~~~~~",
      " ~~~~~~~~~~~~~~~",
      " ~~~~~~~~~~~~~~~",
      " ~~~~~~~~~~~~~~~",
      " ~~~~~~~~~~~~~~~",
      " ~~~~~~~~~~~~~~~",
      " ~~~~~~~~~~~~~~~",
      " ~~~~~~~~~~~~~~~",
      " ~~~~~~~~~~~~~~~",
      " ~~~~~~~~~~~~~~~",
      " ~~~~~~~~~~~~~~~",
      " ~~~~~~~~~~~~~~~",
      " ~~~~~~~~~~~~~~~",
      " ~~~~~~~~~~~~~~~"
    ],
    [
      "                ",
      " ~~~~~~~~~~~~~~~",
      " ~~~~~~~~~~~~~~~",
      " ~~~~~~~~~~~~~~~",
      " ~~~~~~~~~~~~~~~",
      " ~~~~~~~~~~~~~~~",
      " ~~~~~~~~~~~~~~~",
      " ~~~~~~~~~~~~~~~",
      " ~~~~~~~~~~~~~~~",
      " ~~~~~~~~~~~~~~~",
      " ~~~~~~~~~~~~~~~",
      " ~~~~~~~~~~~~~~~",
      " ~~~~~~~~~~~~~~~",
      " ~~~~~~~~~~~~~~~",
      " ~~~~~~~~~~~~~~~",
      " ~~~~~~~~~~~~~~~"
    ]
  ]
}