{
  "name": "multi_megatower1_7_floor3",
  "refpalette": "c70cities:multi_megatower1_7_floor3_palette",
  "xsize": 16,
  "zsize": 16,
  "slices": [
    [
      "aaab            ",
      "aaac            ",
      "aaac            ",
      "aaac            ",
      "aadef           ",
      "aaab            ",
      "ggab            ",
      "ggab            ",
      "ggac            ",
      "ggac            ",
      "aaac            ",
      "aadef           ",
      "aaab            ",
      "aaab            ",
      "aaab            ",
      "aaac            "
    ],
    [
      "hijb            ",
      "  jc            ",
      "kkjc            ",
      "lmjc            ",
      "nedef           ",
      "nojb            ",
      "ppjb            ",
      "  jb            ",
      "  jc            ",
      "qqjc            ",
      "nojc            ",
      "nedef           ",
      "lmjb            ",
      "rrjb            ",
      " sjb            ",
      " ijc            "
    ],
    [
      "  jb            ",
      "  jc            ",
      "kkjc            ",
      "  jc            ",
      "ntdef           ",
      "nojb            ",
      "ppjb            ",
      "  ub            ",
      "  uc            ",
      "qqjc            ",
      "n!jc            ",
      "ntdef           ",
      "  jb            ",
      "rrjb            ",
      "  jb            ",
      "  jc            "
    ],
    [
      "  jb            ",
      "  jc            ",
      "kkjc            ",
      "  jc            ",
      " odef           ",
      " ojb            ",
      "ppjb            ",
      "  wb            ",
      "  wc            ",
      "qqjc            ",
      "xojc            ",
      " odef           ",
      "  jb            ",
      "rrjb            ",
      "  jb            ",
      "  jc            "
    ],
    [
      "  jb            ",
      " xjc            ",
      "kkjc            ",
      " xjc            ",
      " odef           ",
      "xojb            ",
      "ppjb            ",
      "  jb            ",
      "  jc            ",
      "qqjc            ",
      "xojc            ",
      "xodef           ",
      " xjb            ",
      "rrjb            ",
      "  jb            ",
      "  jc            "
    ],
    [
      "  yb            ",
      " xyc            ",
      "aayc            ",
      "aayc            ",
      "AAdef           ",
      "aayb            ",
      "BByb            ",
      "CCyb            ",
      "CCyc            ",
      "DDyc            ",
      "aayc            ",
      "AAdef           ",
      "aayb            ",
      "aayb            ",
      "  yb            ",
      "  yc            "
    ]
  ]
}