{
  "name": "multi_laboratory1_7_base2",
  "refpalette": "c70cities:multi_laboratory1_7_base2_palette",
  "xsize": 16,
  "zsize": 16,
  "slices": [
    [
      "                ",
      "                ",
      "                ",
      " a              ",
      "                ",
      "b    a         b",
      "b              b",
      "bc            cb",
      "dbbb        bbbd",
      "dddbbc    cbbddd",
      "dddddbbbbbbddddd",
      "dddddddddddddddd",
      "dddddddddddddddd",
      "dddddddddddddddd",
      "dddddddddddddddd",
      "dddddddddddddddd"
    ],
    [
      "                ",
      "                ",
      "                ",
      " a              ",
      "                ",
      "e    a         e",
      "e              e",
      "ec            ce",
      "feee        eeef",
      "  feec    cee   ",
      "gg hceeeeeecifgg",
      "gg   jjjjjj   gg",
      "      k  k    f ",
      " f              ",
      "                ",
      "                "
    ],
    [
      "                ",
      "                ",
      "                ",
      " a              ",
      "                ",
      "e    a         e",
      "e              e",
      "ec            ce",
      " eee        eee ",
      "   eec    cee   ",
      "    leeeeeel  mn",
      " o   pqr q      ",
      "                ",
      "                ",
      "                ",
      "                "
    ],
    [
      "                ",
      "                ",
      "                ",
      " a              ",
      "                ",
      "e    s         e",
      "e              e",
      "ec            ce",
      " eee        eee ",
      "   eec    cee   ",
      "    leeeeeel    ",
      "                ",
      "                ",
      "                ",
      "                ",
      "                "
    ],
    [
      "                ",
      "                ",
      "                ",
      " a              ",
      "                ",
      "e    a         e",
      "e              e",
      "ec            ce",
      " eee        eee ",
      "   eec    cee   ",
      "     eeeeee     ",
      "                ",
      "                ",
      "                ",
      "                ",
      "                "
    ],
    [
      "                ",
      "                ",
      "                ",
      " a              ",
      "                ",
      "e    a         e",
      "e              e",
      "ec            ce",
      "teee        eeet",
      "ttteec    ceettt",
      "ttttteeeeeettttt",
      "tttttttttttttttt",
      "tttttttttttttttt",
      "tutttuttttwtttut",
      "tutttuttttutttut",
      "tutttuttttutttut"
    ]
  ]
}