{
  "name": "multi_laboratory1_14_base5",
  "refpalette": "c70cities:multi_laboratory1_14_base5_palette",
  "xsize": 16,
  "zsize": 16,
  "slices": [
    [
      "   ab   cdc   ez",
      "    f   d d   gz",
      "    h  id dj  gz",
      "    h   d dkk gz",
      "    h   cdckk gz",
      "    h   l l   gz",
      "    h   mdm   gz",
      "   nb  opqpr  ez",
      "    s  o  tr  gz",
      "    s         gz",
      "    u         gz",
      "    u         gz",
      "    s         gz",
      "wwwws         gz",
      "xxxxwgggggggggwz",
      "zzzzzzzzzzzzzzzz"
    ],
    [
      "   yb    q    ez",
      "    h    q    gz",
      "    h   ABA   gz",
      "    h    qC   gz",
      "    h         gz",
      "    h         gz",
      "    h    D    gz",
      "    b   q q   ez",
      "    s   q q   gz",
      "    s         gz",
      "    u         gz",
      "    u         gz",
      "    s         gz",
      "wwwws         gz",
      "xxxxwgggggggggwz",
      "zzzzzzzzzzzzzzzz"
    ],
    [
      "    b         ez",
      "    h         gz",
      "    h         gz",
      "    h         gz",
      "    h         gz",
      "    h         gz",
      "    h         gz",
      "    b         ez",
      "    s         gz",
      "    s         gz",
      "    u         gz",
      "    u         gz",
      "    s         gz",
      "wwwws         gz",
      "xxxxwgggggggggwz",
      "zzzzzzzzzzzzzzzz"
    ],
    [
      "    b         ez",
      "    h         gz",
      "    h         gz",
      "    h         gz",
      "    h         gz",
      "    h         gz",
      "    h         gz",
      "    b         ez",
      "    s         gz",
      "    s         gz",
      "    u         gz",
      "    u         gz",
      "    s         gz",
      "wwwws         gz",
      "xxxxwgggggggggwz",
      "zzzzzzzzzzzzzzzz"
    ],
    [
      "    b         ez",
      "    s         gz",
      "    s         gz",
      "    s         gz",
      "    s         gz",
      "    s         gz",
      "    s         gz",
      "    b         ez",
      "    s         gz",
      "    s         gz",
      "    s         gz",
      "    s         gz",
      "    s         gz",
      "wwwws         gz",
      "xxxxwgggggggggwz",
      "zzzzzzzzzzzzzzzz"
    ],
    [
      "eeeeseeeeeeeeewz",
      "eeeeseeeeeeeeewz",
      "eeeeseeeeeeeeewz",
      "eeeeseeEFFFEeewz",
      "eeeeseeEFFFEeewz",
      "eeeeseeeeeeeeewz",
      "eeeeseeeeeeeeewz",
      "eeeeseeeeeeeeewz",
      "eeeeseeeeeeeeewz",
      "eeeeseeeeeeeeewz",
      "eeeeseeFEFFFeewz",
      "eeeeseeFEFFFeewz",
      "eeeeseeeeeeeeewz",
      "wwwwseeeeeeeeewz",
      "xxxxwwwwwwwwwwwz",
      "zzzzzzzzzzzzzzzz"
    ]
  ]
}