{
  "name": "multi_megatower1_5_floor11",
  "refpalette": "c70cities:multi_megatower1_5_floor11_palette",
  "xsize": 16,
  "zsize": 16,
  "slices": [
    [
      "    abbbbbbbbbbb",
      "    abbbbbbbbbbb",
      "ccccdbbbbbbdbbbb",
      "cccceccccccecccc",
      "fggghfffggghfffg",
      "    i      i    ",
      "                ",
      "                ",
      "                ",
      "                ",
      "                ",
      "                ",
      "                ",
      "                ",
      "                ",
      "                "
    ],
    [
      "    j k lk m    ",
      "    j kn knmopqq",
      "jjjjdjjjjjjdrrrr",
      "                ",
      "fggghfffggghfffg",
      "    i      i    ",
      "                ",
      "                ",
      "                ",
      "                ",
      "                ",
      "                ",
      "                ",
      "                ",
      "                ",
      "                "
    ],
    [
      "    j      m    ",
      "    j      ms   ",
      "jjjjdjjjjjjdrttt",
      "                ",
      "fggghfffggghfffg",
      "    i      i    ",
      "                ",
      "                ",
      "                ",
      "                ",
      "                ",
      "                ",
      "                ",
      "                ",
      "                ",
      "                "
    ],
    [
      "    j      m    ",
      "    j      mu   ",
      "jjjjdjjjjjjdrwww",
      "                ",
      "fggghfffggghfffg",
      "    i      i    ",
      "                ",
      "                ",
      "                ",
      "                ",
      "                ",
      "                ",
      "                ",
      "                ",
      "                ",
      "                "
    ],
    [
      "    mx xxyxAxBxx",
      "    mxxxxxxAxxxx",
      "CDCDdrrrrrrdrrrr",
      "                ",
      "fggghfffggghfffg",
      "    i      i    ",
      "                ",
      "                ",
      "                ",
      "                ",
      "                ",
      "                ",
      "                ",
      "                ",
      "                ",
      "                "
    ],
    [
      "    E FF IJE I F",
      "    EF  F JE    ",
      "KKKKdKKKKKKdKKKK",
      "    L      L    ",
      "fggghfffggghfffg",
      "    i      i    ",
      "                ",
      "                ",
      "                ",
      "                ",
      "                ",
      "                ",
      "                ",
      "                ",
      "                ",
      "                "
    ]
  ]
}