{
  "name": "multi_laboratory1_1_floor1",
  "refpalette": "c70cities:multi_laboratory1_1_floor1_palette",
  "xsize": 16,
  "zsize": 16,
  "slices": [
    [
      "        abbczzde",
      "        fbbczzde",
      "        fbbc!zde",
      "        fbbczzde",
      "        fbbczzde",
      "        fbbczzde",
      "        fghcddee",
      "        fbbceeee",
      "        fbbceeee",
      "        fbbceeee",
      "        abbceee ",
      "        fbbceee ",
      "        fbbceee ",
      "        fghcee  ",
      "        i bcee  ",
      "        j bcee  "
    ],
    [
      "        f  kllm ",
      "        f  knom ",
      "        f  kp m ",
      "        f  koqm ",
      "        f  k lm ",
      "        f  klop ",
      "        f  rmm  ",
      "        f  k    ",
      "        f  k    ",
      "        f  k   s",
      "        f  k  st",
      "        f  k  s ",
      "        a  k  s ",
      "        f  r st ",
      "        i  k s  ",
      "        i  k s  "
    ],
    [
      "        f       ",
      "        f       ",
      "        f       ",
      "        f       ",
      "        f       ",
      "        f       ",
      "        f       ",
      "        f       ",
      "        f       ",
      "        f       ",
      "        f       ",
      "        f       ",
      "        f       ",
      "        f       ",
      "        i       ",
      "        i       "
    ],
    [
      "        f       ",
      "        f       ",
      "        f       ",
      "        f       ",
      "        f       ",
      "        f       ",
      "        f       ",
      "        f       ",
      "        f       ",
      "        f       ",
      "        f       ",
      "        f       ",
      "        f       ",
      "        f       ",
      "        i       ",
      "        j       "
    ],
    [
      "        f       ",
      "        f       ",
      "        f       ",
      "        f       ",
      "        f       ",
      "        f       ",
      "        f       ",
      "        u       ",
      "        u       ",
      "        u       ",
      "                ",
      "                ",
      "                ",
      "                ",
      "                ",
      "                "
    ],
    [
      "        f    ~  ",
      "        u       ",
      "        u       ",
      "        u       ",
      "                ",
      "                ",
      "                ",
      "                ",
      "                ",
      "                ",
      "                ",
      "                ",
      "                ",
      "                ",
      "                ",
      "                "
    ]
  ]
}