{
  "name": "multi_megatower1_3_floor12",
  "refpalette": "c70cities:multi_megatower1_3_floor12_palette",
  "xsize": 16,
  "zsize": 16,
  "slices": [
    [
      "                ",
      "                ",
      "                ",
      "                ",
      "                ",
      "                ",
      "                ",
      "                ",
      "                ",
      "                ",
      "    a      a    ",
      "bcccdbbbcccdbbbc",
      "eeeefeeeeeefeeee",
      "gggghgggggghgggg",
      "ijjjgggggggggggg",
      "i   gggggggggggg"
    ],
    [
      "                ",
      "                ",
      "                ",
      "                ",
      "                ",
      "                ",
      "                ",
      "                ",
      "                ",
      "                ",
      "    a      a    ",
      "bcccdbbbcccdbbbc",
      "                ",
      "klmnhoooooohpppp",
      "ijjjqr    stu  w",
      "i   qx yyy t    "
    ],
    [
      "                ",
      "                ",
      "                ",
      "                ",
      "                ",
      "                ",
      "                ",
      "                ",
      "                ",
      "                ",
      "    a      a    ",
      "bcccdbbbcccdbbbc",
      "                ",
      "k   hoooooohpAAA",
      "ijjjq     Btu   ",
      "i   q      t    "
    ],
    [
      "                ",
      "                ",
      "                ",
      "                ",
      "                ",
      "                ",
      "                ",
      "                ",
      "                ",
      "                ",
      "    a      a    ",
      "bcccdbbbcccdbbbc",
      "                ",
      "k   hoooooohpCCC",
      "ijjjq     BtD   ",
      "i   q      t    "
    ],
    [
      "                ",
      "                ",
      "                ",
      "                ",
      "                ",
      "                ",
      "                ",
      "                ",
      "                ",
      "                ",
      "    a      a    ",
      "bcccdbbbcccdbbbc",
      "                ",
      "k   hpppppphpppp",
      "ijjjEFFFFFFIFFFF",
      "i   EFJFFKFIFKFF"
    ],
    [
      "                ",
      "                ",
      "                ",
      "                ",
      "                ",
      "                ",
      "                ",
      "                ",
      "                ",
      "                ",
      "    a      a    ",
      "bcccdbbbcccdbbbc",
      "    L      L    ",
      "MMMMhMMMMMMhMMMM",
      "NOOON     PN Q Q",
      "N   N R QRSN R Q"
    ]
  ]
}