{
  "name": "multi_laboratory1_0_base7",
  "refpalette": "c70cities:multi_laboratory1_0_base7_palette",
  "xsize": 16,
  "zsize": 16,
  "slices": [
    [
      "zzzzzzzzzzzzzzzz",
      "zaaaaaaaaaaaabac",
      "zaaaaaaaaaaaaaca",
      "zaaaaaaaaaaaacaa",
      "zaaaaaaaaaaaacac",
      "zaaaaaaaaaacacac",
      "zaaaaaaaaaaaaccd",
      "zaaaaaaaaaaabdad",
      "zaaaaaaaaaabbcba",
      "zaaaaaaaaabbbecf",
      "zaaaaaaaacbbccff",
      "zaaaaaaaacbccbaa",
      "zaaaaaaaabcbbcaa",
      "zaaaaaaaccbbacaa",
      "zaaaaaaaccbaacaa",
      "zaaaaaacbbbaacaa"
    ],
    [
      "zzzzzzzzzzzzzzzz",
      "zaaaaaaaaaaaaaaa",
      "zaaaaaaaaaaagggg",
      "zaaaaaaaaaaaahij",
      "zaaaaaaaaaaad   ",
      "zaaaaaaaaadkl m ",
      "zaaaaaaaaaad    ",
      "zaaaaaaaaadn    ",
      "zaaaaaaaaod     ",
      "zaaaaaaaaaffd p ",
      "zaaaaaaaaaaaadqr",
      "zaaaaaaaaaaaafff",
      "zaaaaaaaaaaaaaaa",
      "zaaaaaaaafaaaaaa",
      "zaaaaaaafaaaaaaa",
      "zaaaafddfbaacaaa"
    ],
    [
      "zzzzzzzzzzzzzzzz",
      "zaaaaaaaaaaaaaaa",
      "zaaaaaaaaaaagggg",
      "zaaaaaaaaaaa    ",
      "zaaaaaaaaaad    ",
      "zaaaaaaaaa ks   ",
      "zaaaaaaaaf      ",
      "zaaaaaaafd      ",
      "zaaaaaaat       ",
      "zaaaaaaaad q    ",
      "zaaaaaaaaadft  u",
      "zaaaaaaaaaafff r",
      "zaaaaatddfaaaaff",
      "zaaaaaw dtfaaaaa",
      "zaaaaf   fcabaaa",
      "zaaaft   faabaaa"
    ],
    [
      "zzzzzzzzzzzzzzzz",
      "zaaaaaaaaaaaaaaa",
      "zaaaaaaaaaaagggg",
      "zaaaaaaaaaa     ",
      "zaaaaaaaaa      ",
      "zaaaaaaaaa k    ",
      "zaaaaaaafq      ",
      "zaaaaaaa        ",
      "zaaaaaaat       ",
      "zaaaaaaan    x  ",
      "zaaaaaaa   rt  y",
      "zaaaaaan  aaf xq",
      "zaaaaat  raaafff",
      "zaaaaa   tfaaaaa",
      "zaaaf    qfaaaaa",
      "zaaaat   bbbaaaa"
    ],
    [
      "zzzzzzzzzzzzzzzz",
      "zaaaaaaaaaaaaaaa",
      "zaaaaaaaaaaagggg",
      "zaaaaaaaaaaa    ",
      "zaaaaaaaaaao    ",
      "zaaaaaaaaack    ",
      "zaaaaaaaaeo     ",
      "zaaaaaaaf       ",
      "zaaaaaaat      x",
      "zaaaaaaao   oA  ",
      "zaaaaaaa   qaoxA",
      "zaaaaaa   aaaaaf",
      "zaaaaat  qaaaaaa",
      "zaaaaao  tfaaaaa",
      "zaaaaa    aaaaaa",
      "zaaaat   eaaaaaa"
    ],
    [
      "zzzzzzzzzzzzzzzz",
      "zaaaaaaaaaaaaaaa",
      "zaaaaaaaaaaagggg",
      "zaaaaaaaaaaa    ",
      "zaaaaaaaaaaa    ",
      "zaaaaaaaaaakoo  ",
      "zaaaaaaaaaaaaBoo",
      "zaaaaaaaaaaacafo",
      "zaaaaaaaaooaafaf",
      "zaaaaaaaaoaaafff",
      "zaaaaaaaaoaaaaff",
      "zaaaaaaaaaaaaaaa",
      "zaaaaaaaofaaaaaa",
      "zaaaaaaaaaaaaaaa",
      "zaaaaaaaaaaaaaaa",
      "zaaaaaaoaaaaaaaa"
    ]
  ]
}