{
  "name": "multi_condo1_5_ground",
  "refpalette": "c70cities:multi_condo1_5_ground_palette",
  "xsize": 16,
  "zsize": 16,
  "slices": [
    [
      "      aHHHHHHHHH",
      "      abbaaaaGGG",
      "      abba  accc",
      "      a  a  aGaG",
      "      a  a  aGaG",
      "      a  a  aGaG",
      "      a  a  aGaG",
      "      a  a  aGaG",
      "      a  a  aGaG",
      "      a  a  aGaG",
      "      a  a  aGaG",
      "aaaaaaa     aGaG",
      "      a     aGaG",
      "aaaaaaaaaaaaaaaG",
      "GGGGGGGGGGGGGGGG",
      "GGGGGGGGGGGGGGGG"
    ],
    [
      "      a         ",
      "      a         ",
      "      a      ccc",
      "      a      de ",
      "      a      de ",
      "      a      de ",
      "      a      de ",
      "      a      de ",
      "      a      de ",
      "      a      de ",
      "      a      de ",
      "     aa      de ",
      "      a      de ",
      "       eeeeeeee ",
      "                ",
      "                "
    ],
    [
      "      a         ",
      "      a         ",
      "      a      ccc",
      "      a      d  ",
      "      a      d  ",
      "      a      d  ",
      "      a      d  ",
      "      a      d  ",
      "      a      d  ",
      "      a      d  ",
      "      a      d  ",
      "     aa      d  ",
      "      a      d  ",
      "                ",
      "                ",
      "                "
    ],
    [
      "      a         ",
      "      a         ",
      "      a      ccc",
      "      a         ",
      "      a         ",
      "      a         ",
      "      a         ",
      "      a         ",
      "      a         ",
      "      a         ",
      "      a         ",
      "     aa         ",
      "      a         ",
      "                ",
      "                ",
      "                "
    ],
    [
      "      a         ",
      "      a         ",
      "      a      ccc",
      "      a         ",
      "      a         ",
      "      a         ",
      "      a         ",
      "      a         ",
      "      a         ",
      "      a         ",
      "      a         ",
      "     aa         ",
      "      a         ",
      "                ",
      "                ",
      "                "
    ],
    [
      "      a     a   ",
      "      a     a   ",
      "      a     accc",
      "      a     af  ",
      "      a     af  ",
      "      a     af  ",
      "      a     af  ",
      "      a     af  ",
      "      a     af  ",
      "      a     af  ",
      "      a     af  ",
      "     aaaaaaaaf  ",
      "      afffffff  ",
      "                ",
      "                ",
      "                "
    ]
  ]
}