{
  "name": "multi_convenientstore_3_ground",
  "refpalette": "c70cities:multi_convenientstore_3_ground_palette",
  "xsize": 16,
  "zsize": 16,
  "slices": [
    [
      "aaaaaaaaaaaaHHHb",
      "cccccccccccaHHHb",
      "cccccccccccaHHHb",
      "cccccccccccaHHHb",
      "cccccccccccaHHHb",
      "cccccccccccaHHHb",
      "cccccccccccaHHHb",
      "cccccccccccaHHHb",
      "cccccccccccaHHHb",
      "cccccccccccaHHHb",
      "cccccccccccaHHHb",
      "cccccccccccaHHHb",
      "aaaaaaaaaaaaHHHb",
      "HHHHHHHHHHHHHHHb",
      "HHHHHHHHHHHHHHHb",
      "bbbbbbbbbbbbbbbb"
    ],
    [
      "aaaaaaaaaaaaddde",
      "cccccccccccaddde",
      "cccccccccccaddde",
      "cccccccccccaddde",
      "cccccccccccaHHHb",
      "cccccccccccaHHHb",
      "cccccccccccaHHHb",
      "cccccccccccaHHHb",
      "cccccccccccaHHHb",
      "cccccccccccaHHHb",
      "cccccccccccaHHHb",
      "cccccccc!ccaHHHb",
      "aaaaaaaaaaaaHHHb",
      "HHHHHHHHHHHHHHHb",
      "HHHHHHHHHHHHHHHb",
      "HHHHHHHHHHHHHHHb"
    ],
    [
      "fghhhhhiiiij    ",
      "       k  lj    ",
      "       k  mj    ",
      "       k  nj   e",
      "  oppp k qnj   e",
      "  r    s  nj   e",
      " t     uwxwj y e",
      "  AAAAAu       e",
      "  BCCDDA       e",
      "     EFk       e",
      "I    J k  Kj   e",
      " L!ILEMkNOOj   e",
      "jjjjjjjjjjjj   e",
      "  P   PN N     e",
      "               e",
      "               e"
    ],
    [
      "Qghhhhhiihij    ",
      "       k  Rj    ",
      "       k   j    ",
      "       k   h    ",
      "   ST  k   h    ",
      "  U    VW  h    ",
      " tX   YuwZwj    ",
      "  000 1u   2    ",
      "   B3DDA   2    ",
      "     E k   2    ",
      "     4 k   j    ",
      " 5667E k  8j    ",
      "jjjjjjjjjjjj    ",
      "  9  N9N        ",
      "                ",
      "                "
    ],
    [
      "gghhhhhiihij    ",
      "       k   j    ",
      "       k   j    ",
      "       k   h    ",
      "       k   h    ",
      "       k   h    ",
      " t56667uwwwj    ",
      "  000@@u   2    ",
      "    BDDA   2    ",
      "     E k   2    ",
      "     E#k   j    ",
      "  $I%E kN  j    ",
      "jjjjjjjjjjjj    ",
      "99^999^         ",
      "                ",
      "                "
    ],
    [
      "hhhhhhhiihij    ",
      "       k   j    ",
      "       k   j    ",
      "       k  &j    ",
      "       k  &j    ",
      "       k  &j    ",
      "*()))))uwwwj    ",
      "+ iiiiiuN  c    ",
      "+    -DA   c    ",
      "     DDA   c    ",
      "     DDAN Nj    ",
      "[99[99[9999j    ",
      "jjjjjjjjjjjj    ",
      "     N9         ",
      "                ",
      "                "
    ]
  ]
}