{
  "name": "multi_hospital_3_base1",
  "refpalette": "c70cities:multi_hospital_3_base1_palette",
  "xsize": 16,
  "zsize": 16,
  "slices": [
    [
      "aabbbbbbbbbbbbbv",
      "aabbbbbbbbbbbbbv",
      "aaaaaaaaaaaaaaav",
      "aacccccccccccccv",
      "aacccccccccccccv",
      "aacccccccccccccv",
      "aacccccccccccccv",
      "aacccccccccccccv",
      "aacccccccccccccv",
      "dacccccccccccccv",
      "aacccccccccccccv",
      "cccccccccccccccv",
      "cccccccccccccccv",
      "cccccccccccccccv",
      "cccccccccccccccv",
      "vvvvvvvvvvvvvvvv"
    ],
    [
      "efb b b b b b!bv",
      " fb b b b b b bv",
      "gavvvvvvvvvvvvvv",
      "efcccccccccccccv",
      " fcccccccccccccv",
      "gacccccccccccccv",
      "efcccccccccccccv",
      " fcccccccccccccv",
      "hacccccccccccccv",
      "ddcccccccccccccv",
      "dacccccccccccccv",
      "cccccccccccccccv",
      "cccccccccccccccv",
      "cccccccccccccccv",
      "cccccccccccccccv",
      "vvvvvvvvvvvvvvvv"
    ],
    [
      " fbibibibibibibv",
      " fbibibibibibibv",
      "javvvvvvvvvvvvvv",
      " fcccccccccccccv",
      " fcccccccccccccv",
      "jacccccccccccccv",
      " fcccccccccccccv",
      " fcccccccccccccv",
      "hacccccccccccccv",
      "ddcccccccccccccv",
      "dacccccccccccccv",
      "cccccccccccccccv",
      "cccccccccccccccv",
      "cccccccccccccccv",
      "cccccccccccccccv",
      "vvvvvvvvvvvvvvvv"
    ],
    [
      " fbkbkbkbkbkbkbv",
      " fbkbkbkbkbkbkbv",
      " avvvvvvvvvvvvvv",
      " fcccccccccccccv",
      " fcccccccccccccv",
      " acccccccccccccv",
      " fcccccccccccccv",
      " fcccccccccccccv",
      "hacccccccccccccv",
      "ddcccccccccccccv",
      "dacccccccccccccv",
      "cccccccccccccccv",
      "cccccccccccccccv",
      "cccccccccccccccv",
      "cccccccccccccccv",
      "vvvvvvvvvvvvvvvv"
    ],
    [
      " fb!b b b b b bv",
      " fb b b b b b bv",
      " avvvvvvvvvvvvvv",
      " fcccccccccccccv",
      " fcccccccccccccv",
      " acccccccccccccv",
      " fcccccccccccccv",
      " fcccccccccccccv",
      "hacccccccccccccv",
      "ddcccccccccccccv",
      "dacccccccccccccv",
      "cccccccccccccccv",
      "cccccccccccccccv",
      "cccccccccccccccv",
      "cccccccccccccccv",
      "vvvvvvvvvvvvvvvv"
    ],
    [
      "labbbbbbbbbbbbbv",
      "labbbbbbbbbbbbbv",
      "aavvvvvvvvvvvvvv",
      "lacccccccccccccv",
      "lacccccccccccccv",
      "lacccccccccccccv",
      "lacccccccccccccv",
      "lacccccccccccccv",
      "aacccccccccccccv",
      "dacccccccccccccv",
      "aacccccccccccccv",
      "cccccccccccccccv",
      "cccccccccccccccv",
      "cccccccccccccccv",
      "cccccccccccccccv",
      "vvvvvvvvvvvvvvvv"
    ]
  ]
}