{
  "name": "multi_condo1_2_base2",
  "refpalette": "c70cities:multi_condo1_2_base2_palette",
  "xsize": 16,
  "zsize": 16,
  "slices": [
    [
      "vaHHHHHHHHHHHHHH",
      "vaHHHHHHHHHHHHHH",
      "vaHHHHHHHHHHHHHH",
      "vaHHHHHHHHHHHHHH",
      "vaHHHHHHHHHHHHHH",
      "vaHHHHHHHHHHHHHH",
      "vaHHHHHHHHHHHHHH",
      "vaHHHHHHHHHHHHHH",
      "vaHHHHHHHHHHHHHH",
      "vaHHHHHHHHHHHHHH",
      "vaHHHHHHHHHHHHHH",
      "vaHHHHHHHHHHHHHH",
      "vaHHHHHHHHHHHHHH",
      "vaaaaaaaaaaaaaaa",
      "vbbbbbbbbbbbbbbb",
      "vvvvvvvvvvvvvvvv"
    ],
    [
      "va              ",
      "va  cdedededede ",
      "va  c           ",
      "va  cfgfgfgfgfgf",
      "va  chhhhhhhhhhh",
      "va  cdededededed",
      "va  c           ",
      "va  cfgfgfgfgfgf",
      "va              ",
      "va              ",
      "vacdedededededed",
      "vac             ",
      "vacfgfgfgfgfgfgf",
      "vaaaaaaaaaaaaaaa",
      "vbbbbbbbbbbbbbbb",
      "vvvvvvvvvvvvvvvv"
    ],
    [
      "va              ",
      "va              ",
      "va              ",
      "va              ",
      "va              ",
      "va              ",
      "va              ",
      "va              ",
      "va              ",
      "va              ",
      "va              ",
      "va              ",
      "va              ",
      "vaaaaaaaaaaaaaaa",
      "vbbbbbbbbbbbbbbb",
      "vvvvvvvvvvvvvvvv"
    ],
    [
      "va              ",
      "va              ",
      "va              ",
      "va              ",
      "va              ",
      "va              ",
      "va              ",
      "va              ",
      "va              ",
      "va              ",
      "va              ",
      "va              ",
      "va              ",
      "vaaaaaaaaaaaaaaa",
      "vbbbbbbbbbbbbbbb",
      "vvvvvvvvvvvvvvvv"
    ],
    [
      "vai       a     ",
      "vai       a     ",
      "va!iiiiiiiaiiiii",
      "vai       a     ",
      "vai       a     ",
      "vai       a     ",
      "vai       a     ",
      "vai       a     ",
      "vai       a     ",
      "vai       a     ",
      "vai       a     ",
      "vai       a     ",
      "vaiiiiiiiiaiiiii",
      "vaaaaaaaaaaaaaaa",
      "vbbbbbbbbbbbbbbb",
      "vvvvvvvvvvvvvvvv"
    ],
    [
      "vajjjjjjjjajjjjj",
      "vajjjjjjjjajjjjj",
      "vajjjjjjjjajjjjj",
      "vajjjjjjjjajjjjj",
      "vajjjjjjjjajjjjj",
      "vajjjjjjjjajjjjj",
      "vajjjjjjjjajjjjj",
      "vajjjjjjjjajjjjj",
      "vajjjjjjjjajjjjj",
      "vajjjjjjjjajjjjj",
      "vajjjjjjjjajjjjj",
      "vajjjjjjjjajjjjj",
      "vajjjjjjjjajjjjj",
      "vaaaaaaaaaaaaaaa",
      "vbbbbbbbbbbbbbbb",
      "vvvvvvvvvvvvvvvv"
    ]
  ]
}