{
  "name": "multi_clubhouse1_1_base1",
  "refpalette": "c70cities:multi_clubhouse1_1_base1_palette",
  "xsize": 16,
  "zsize": 16,
  "slices": [
    [
      "vaa   bccccccb  ",
      "vaad  beeeeeeb  ",
      "vaa   beeeeeeb  ",
      "vaa   beeeeeeb  ",
      "vaad  bbbbbbbb  ",
      "vaa   bccccccb  ",
      "vaa   bccccccb  ",
      "vaa   bccccccb  ",
      "vaa   beeeeeeb  ",
      "vaa   beeeeeeb  ",
      "vaa   beeeeeeb  ",
      "vaa   bbbbbbbb  ",
      "vaa   bccccccb  ",
      "vaa   bccccccb  ",
      "vaa   bccccccb  ",
      "vaa   beeeeeeb  "
    ],
    [
      "vaa             ",
      "vaa             ",
      "vaa             ",
      "vaa             ",
      "vaa             ",
      "vaa             ",
      "vaa             ",
      "vaa             ",
      "vaa             ",
      "vaa             ",
      "vaa             ",
      "vaa             ",
      "vaa             ",
      "vaa             ",
      "vaa             ",
      "vaa             "
    ],
    [
      "vaa             ",
      "vaa             ",
      "vaa             ",
      "vaa             ",
      "vaa             ",
      "vaa             ",
      "vaa             ",
      "vaa             ",
      "vaa             ",
      "vaa             ",
      "vaa             ",
      "vaa             ",
      "vaa             ",
      "vaa             ",
      "vaa             ",
      "vaa             "
    ],
    [
      "va              ",
      "va              ",
      "va              ",
      "va              ",
      "va              ",
      "va              ",
      "va              ",
      "vad             ",
      "vad             ",
      "va              ",
      "va              ",
      "va              ",
      "va              ",
      "vad             ",
      "va              ",
      "va              "
    ],
    [
      "va              ",
      "va              ",
      "va              ",
      "va              ",
      "va              ",
      "va              ",
      "va              ",
      "va              ",
      "va              ",
      "va              ",
      "va              ",
      "va              ",
      "va              ",
      "va              ",
      "va              ",
      "va              "
    ],
    [
      "va              ",
      "va              ",
      "va              ",
      "va              ",
      "va              ",
      "va              ",
      "va              ",
      "va              ",
      "va              ",
      "va              ",
      "va              ",
      "va              ",
      "va              ",
      "va              ",
      "va              ",
      "va              "
    ]
  ]
}