{
  "name": "multi_condo1_3_floor4",
  "refpalette": "c70cities:multi_condo1_3_floor4_palette",
  "xsize": 16,
  "zsize": 16,
  "slices": [
    [
      "                ",
      "      a         ",
      "bbbbbbacccccccc ",
      "deeeeeafffffffc ",
      "ddgggddddddddfc ",
      "hhhhhhhhhhhhdfc ",
      "hhhhhhhhhhhhdfc ",
      "hhhhhhhhhhhhdfc ",
      "hhhhhhhhhhhhdfc ",
      "hhhhhhhhhhhhdfc ",
      "hhhhhhhhhhhhdfc ",
      "hhhhhhhhhhhhdfc ",
      "hhhhhhhhhiiidfc ",
      "hhhhhhhhhiiidaaa",
      "jjjjjjjhhiiide  ",
      "kkkkkljhhiiide  "
    ],
    [
      "                ",
      "      a         ",
      "bbbbbba         ",
      "d     afffffff  ",
      "ddm mdddnnnddf  ",
      "o     op   qdf  ",
      "op r sotu wxdf  ",
      "op r yotu  Adf  ",
      "oB   !op   !df  ",
      "oC   Coooo Ddf  ",
      "oE       F Ddf  ",
      "oI    JK o Ddf  ",
      "oI    JK oLodf  ",
      "oMNOPQJ  o Rdaaa",
      "ddddddd  o Sd   ",
      "      T  F  U   "
    ],
    [
      "                ",
      "      a         ",
      "      a         ",
      "d     a         ",
      "ddm mdddmmmdd   ",
      "o     o    Vd   ",
      "o     o     d   ",
      "oW    o     d   ",
      "o     oX    d   ",
      "oY   Yoooo Dd   ",
      "o        Z Dd   ",
      "o0    1  o Dd   ",
      "o     2  o3od   ",
      "o  4567  o 8daaa",
      "ddddddd  o9 d   ",
      "      @  Z  b   "
    ],
    [
      "                ",
      "      a         ",
      "      a         ",
      "d     a         ",
      "ddmmmdddmmmdd   ",
      "o     o     d   ",
      "o     o     d   ",
      "o     o     d   ",
      "o     o     d   ",
      "o     oooo #d   ",
      "o        o  d   ",
      "o        o  d   ",
      "o        oood   ",
      "o        o $daaa",
      "ddddddd  o  d   ",
      "      %  o  b   "
    ],
    [
      "                ",
      "      a         ",
      "      a         ",
      "d     a^^^^^^^  ",
      "ddddddddddddd^  ",
      "o     o     d^  ",
      "o     o     d^  ",
      "o     o     d^  ",
      "o     o     d^  ",
      "o     oooo  d^  ",
      "o        o  d^  ",
      "o        o  d^  ",
      "o        oood^  ",
      "o        o  daaa",
      "ddddddd  o  d   ",
      "      d  o  d   "
    ],
    [
      "                ",
      "      a         ",
      "&&&&&&a         ",
      "d     a*******  ",
      "ddddddddddddd*  ",
      "((((((((((((d*  ",
      "((((((((((((d*  ",
      "((((((((((((d*  ",
      "((((((((((((d*  ",
      "((((((((((((d*  ",
      "((((((((((((d*  ",
      "((((((((((((d*  ",
      "((((((((((((d*  ",
      "((((((((((((daaa",
      "ddddddd(((((d   ",
      "      d(((((d   "
    ]
  ]
}