{
  "name": "multi_laboratory1_13_base2",
  "refpalette": "c70cities:multi_laboratory1_13_base2_palette",
  "xsize": 16,
  "zsize": 16,
  "slices": [
    [
      "aaaaaaaaaaaaabcv",
      "aaaaaaaaaaaaabcv",
      "aaaadaaaaaaaabcv",
      "aaaaaaaaaaaaabcv",
      "aaaaaaaaaaaaabcv",
      "aaaaaaaaaaaaabcv",
      "aaaaaaaaaaaaabcv",
      "aaaaaaaaaaaaabcv",
      "aaaaaeeeeeeeebcv",
      "aaaadaaaaaaaabcv",
      "aaaaaaaaaaaaabcv",
      "aaaaaaaaaaaaabcv",
      "aaaaaaaaaaaaabcv",
      "aaaaaaaaaaaaabcv",
      "aaaaaaaaaaaaabcv",
      "aaaaaaaaaaaaabcv"
    ],
    [
      " f  g  h  ijkbcv",
      "lf  mn   jo kbcv",
      " f  dpq hh jrbcv",
      " f  ms      rbcv",
      "tf  ms i ho kbcv",
      "    m h  j jkbcv",
      "    m      tkbcv",
      "    m       kbcv",
      "    m       ubcv",
      "mmmmdw  xx  wbcv",
      "   ymw AAAA wbcv",
      "    mwBACCADwbcv",
      "    mwBAEEADwbcv",
      "FF  mw AAAA wbcv",
      "I   mw  JJ  wbcv",
      "K   mwwwwwwwwbcv"
    ],
    [
      "    g        bcv",
      " L  mn      Mbcv",
      "    dpN      bcv",
      "    m        bcv",
      " L  O       Mbcv",
      "    O       Lbcv",
      "    O       Lbcv",
      "    O       Mbcv",
      "    m        bcv",
      "OOOmdw      wbcv",
      "    mw  PP  wbcv",
      "    Qw P  P wbcv",
      "    QRRPSEPRRbcv",
      "    Qw  PP  wbcv",
      "    Qw      wbcv",
      "    mw!wwwwwwbcv"
    ],
    [
      "    g        bcv",
      "    m        bcv",
      "    dT       bcv",
      "    m        bcv",
      "    O        bcv",
      "    O        bcv",
      "    O        bcv",
      "    O        bcv",
      "    mU      Ubcv",
      "OOOmdw      wbcv",
      "    mw  PP  wbcv",
      "    Vw P  P wbcv",
      "    Vw PW P wbcv",
      "    Vw  PPR wbcv",
      "    Vw  R X wbcv",
      "    mwwwRwwwwbcv"
    ],
    [
      "    m        bcv",
      "    m        bcv",
      "    dT       bcv",
      "    m       Ybcv",
      "    m        bcv",
      "    m        bcv",
      "    m        bcv",
      "    m        bcv",
      "    m        bcv",
      "mmmmdw      wbcv",
      "    mw  PP  wbcv",
      "    mw P  P wbcv",
      "    mw PWEP wbcv",
      "    mw  PP  wbcv",
      "    mw    ZRRbcv",
      "    mwwwwwwwwbcv"
    ],
    [
      "00 01T232242Tbcv",
      "00001T232242Tbcv",
      "0000dT222222Tbcv",
      "00001T222222Tbcv",
      "00301T242242Tbcv",
      "00301T232232Tbcv",
      "00301T232232Tbcv",
      "00301T232252Tbcv",
      "00001T222222Tbcv",
      "6666dw      wbcv",
      "22221w  PP  wbcv",
      "22221w P EP wbcv",
      "22221w PCCP wbcv",
      "33221w  PP  wbcv",
      "23221w      wbcv",
      "25221wwwwwwwwbcv"
    ]
  ]
}