{
  "name": "multi_carservice_0_floor1",
  "refpalette": "c70cities:multi_carservice_0_floor1_palette",
  "xsize": 16,
  "zsize": 16,
  "slices": [
    [
      "                ",
      "                ",
      "                ",
      "                ",
      "                ",
      "                ",
      "    aabaaabaaab ",
      "   cc deeeeeeda ",
      "  cc  defegheda ",
      " ac   defegheda ",
      " ai   deee!geda ",
      " adddddddddddda ",
      " adddddddddddda ",
      " adddddddddddda ",
      " adddddddddddda ",
      " adddddddddddda "
    ],
    [
      "                ",
      "                ",
      "                ",
      "                ",
      "                ",
      "                ",
      "    aabaaabaaab ",
      "   jjklmnm   oa ",
      "  jj k npn   qj ",
      " aj  k npn   qj ",
      " ai  krsnm   tj ",
      " a uuu       qj ",
      " aw    x     yj ",
      " aA          yj ",
      " aB          yj ",
      " aB C         j "
    ],
    [
      "                ",
      "                ",
      "                ",
      "                ",
      "                ",
      "                ",
      "    aabaaabaaab ",
      "   jj DEFE    a ",
      "  jj   I J    j ",
      " aj           j ",
      " ai    JEI    j ",
      " b      K     j ",
      " j            j ",
      " j            j ",
      " j            j ",
      " j            j "
    ],
    [
      "                ",
      "                ",
      "                ",
      "                ",
      "                ",
      "                ",
      "    aabaaabaaab ",
      "   jj  L L    a ",
      "  jj   M M    j ",
      " aj    M M    j ",
      " ai    MMM    j ",
      " a            j ",
      " a           Nj ",
      " a           Oj ",
      " a           Nj ",
      " a            j "
    ],
    [
      "                ",
      "                ",
      "                ",
      "                ",
      "                ",
      "                ",
      "    aabaaabaaab ",
      "   jj         a ",
      "  jj          P ",
      " aj           P ",
      " ai           P ",
      " a            P ",
      " a            P ",
      " a            P ",
      " a            P ",
      " a            P "
    ],
    [
      "                ",
      "                ",
      "                ",
      "                ",
      "                ",
      "                ",
      "    aabaaabaaab ",
      "   jj  QQQQQQQa ",
      "  jj   QQQQQQQa ",
      " aj    QQQQQQQa ",
      " ai    QQQQQQQa ",
      " a     QQQQQQQa ",
      " aQQQQQQQQQQQQa ",
      " aQQQQQQQQQQQQa ",
      " aQQQQQQQQQQQQa ",
      " aQQQQQQQQQQQQa "
    ]
  ]
}