{
  "name": "multi_militarybase_3_ground",
  "refpalette": "c70cities:multi_militarybase_3_ground_palette",
  "xsize": 16,
  "zsize": 16,
  "slices": [
    [
      "HHHHHHHHaHHHHbcd",
      "HHHa==HHH=HHHbcd",
      "bbbbbbbbbaHH=bcd",
      "bbb    bb=HH=bcd",
      "bbb   ebbHHHHbcd",
      "bbbbbbbbbHHHHbcd",
      "bbbbbbbbbH=H=bcd",
      "bbbbbbbbbbbbbbcd",
      "bbbbbbbbbbbbbbcd",
      "bbbbbbbbbbbbbbcd",
      "bbbbbb!bbbbbbbcd",
      "bbbbbbbbbbbbbbcd",
      "bbbbbbbbbbbbbbcd",
      "bbbbbbbbbbbbbbcd",
      "cccccccccccccccd",
      "dddddddddddddddd"
    ],
    [
      "              c ",
      "              c ",
      "  ffffff      c ",
      "  f    f      c ",
      "  f    f      c ",
      "  fggg f      c ",
      " ffh   f      c ",
      " hhh   f      c ",
      "              c ",
      "              c ",
      "ijkkhh f      c ",
      "ffffffff      c ",
      "              c ",
      "              c ",
      "ccccccccccccccc ",
      "                "
    ],
    [
      "              c ",
      "              c ",
      "  llmmll      c ",
      "  l    l      c ",
      "  m    m      c ",
      "  l    m      c ",
      " ll    l      c ",
      "       l      c ",
      "              c ",
      "              c ",
      "ijk    l      c ",
      "llllmmll      c ",
      "              c ",
      "              c ",
      "ccccccccccccccc ",
      "                "
    ],
    [
      "              c ",
      "              c ",
      "  llmmll      c ",
      "  l    ln     c ",
      "  m    ln     c ",
      "  l    ln     c ",
      "lll    ln     c ",
      "       l      c ",
      "       l      c ",
      "       l      c ",
      "o      l      c ",
      "llllllll      c ",
      "   nnnn       c ",
      "              c ",
      "ccccccccccccccc ",
      "                "
    ],
    [
      "              c ",
      "              c ",
      "  llllll      c ",
      "  l   gl      c ",
      "  l   gp      c ",
      "  l   gp      c ",
      "pll   gl      c ",
      "gg    gl      c ",
      "      gp      c ",
      "      gp      c ",
      " o ggggl      c ",
      "llllppll      c ",
      "              c ",
      "              c ",
      "ccccccccccccccc ",
      "                "
    ],
    [
      "  foooof      q ",
      "  foooof      q ",
      "  fddddf      q ",
      "  fddddf      q ",
      "  fddddf      q ",
      "  fddddf      q ",
      "fffddddf      q ",
      "dddddddf      q ",
      "dddddddf      q ",
      "dddddddf      q ",
      "  dddddf      q ",
      "ffffffff      q ",
      "              q ",
      "              q ",
      "rrrrrrrrrrrrrst ",
      "                "
    ]
  ]
}