{
  "name": "multi_laboratory1_12_floor1",
  "refpalette": "c70cities:multi_laboratory1_12_floor1_palette",
  "xsize": 16,
  "zsize": 16,
  "slices": [
    [
      "  aabc          ",
      "  aabc          ",
      "  aabc          ",
      "  aabc          ",
      "  aabdef        ",
      " aaabccf        ",
      " aaabccf        ",
      " aaabccf        ",
      "aaaabccf        ",
      "aaaabccf        ",
      "aaaabccf        ",
      "aaggbdef        ",
      "agzzbccf        ",
      "agzzbccf        ",
      "agzzbccf        ",
      "agzzbccf        "
    ],
    [
      "  h i  j        ",
      "  h i  j        ",
      "  h i  k        ",
      "  h i  k        ",
      " lh m  n        ",
      " h  i  n        ",
      " h  i  n        ",
      "lh  i  o        ",
      "h   i  n        ",
      "    i  n        ",
      "    i  n        ",
      "  pqm  n        ",
      " qrsi  n        ",
      " t ri  n        ",
      " qs i  n        ",
      " qsui  n        "
    ],
    [
      "       k        ",
      "       k        ",
      "       k        ",
      "       k        ",
      "       o        ",
      "       o        ",
      "       w        ",
      "       w        ",
      "       o        ",
      "       w        ",
      "       o        ",
      "       w        ",
      "       w        ",
      "       w        ",
      "       w        ",
      "       w        "
    ],
    [
      "       k        ",
      "       k        ",
      "       j        ",
      "       k        ",
      "       o        ",
      "       w        ",
      "       w        ",
      "       w        ",
      "       w        ",
      "       w        ",
      "       w        ",
      "       w        ",
      "       w        ",
      "       w        ",
      "       o        ",
      "       w        "
    ],
    [
      "                ",
      "                ",
      "                ",
      "                ",
      "       x        ",
      "       x        ",
      "       x        ",
      "       w        ",
      "       w        ",
      "       w        ",
      "       w        ",
      "       w        ",
      "       w        ",
      "       w        ",
      "       w        ",
      "       w        "
    ],
    [
      "                ",
      "                ",
      "                ",
      "                ",
      "                ",
      "                ",
      "                ",
      "                ",
      "                ",
      "                ",
      "       x        ",
      "       x        ",
      "       x        ",
      "       w        ",
      "       w        ",
      "       w        "
    ]
  ]
}