{
  "name": "multi_laboratory1_10_base4",
  "refpalette": "c70cities:multi_laboratory1_10_base4_palette",
  "xsize": 16,
  "zsize": 16,
  "slices": [
    [
      "zzzzzzzzzzzzzzzz",
      "aaaaaaaaaaaaaaaz",
      "bbbbccccccccccaz",
      "    d========caz",
      "  e d========caz",
      "ddddd========caz",
      "    d========caz",
      "    d========caz",
      "    d========caz",
      "    d========caz",
      "    d========caz",
      " f  d========caz",
      " fggd========caz",
      "hhhhd========caz",
      "hhhhd========caz",
      "dddddiiiiiiiicaz"
    ],
    [
      "zzzzzzzzzzzzzzzz",
      "aaaaaaaaaaaaaaaz",
      "bbbbbbbbbbbbbcaz",
      "  jklmnooo pqbaz",
      "   klr      sbaz",
      "lllldtu     wbaz",
      "    lx      qbaz",
      "    ly AAA  sbaz",
      "    ly BCB  xbaz",
      "    lw BCB pqbaz",
      "    lD BCB  Ebaz",
      "hh  lF CsC wxbaz",
      "ggI l   J    baz",
      "    l       Kbaz",
      "    L       Kbaz",
      "Mllldllllllllcaz"
    ],
    [
      "zzzzzzzzzzzzzzzz",
      "aaaaaaaaaaaaaaaz",
      "bbbbbbbbbbbbbcaz",
      " j  l!     pqbaz",
      "    l       Ebaz",
      "lllldt      xbaz",
      "    lx     pqbaz",
      "    lx AAA  sbaz",
      "    l  NNN  xbaz",
      "hh  l  NNO  qbaz",
      "ggI l  NNN  sbaz",
      "  I l  sss  xbaz",
      "    l   P    baz",
      "    l        baz",
      "    Q       Rbaz",
      "Sllldllllllllcaz"
    ],
    [
      "zzzzzzzzzzzzzzzz",
      "aaaaaaaaaaaaaaaz",
      "bbbbbbbbbbbbbcaz",
      "j   l       tbaz",
      "    l       sbaz",
      "lllldt      xbaz",
      "hhhhlx      tbaz",
      "hhhhl  AAA  sbaz",
      "ggI l   N   xbaz",
      "  I l  NNN  tbaz",
      "    l   N   sbaz",
      "    l       xbaz",
      "    l        baz",
      "    l        baz",
      "T   l       Ubaz",
      "Vllldllllllllcaz"
    ],
    [
      "zzzzzzzzzzzzzzzz",
      "aaaaaaaaaaaaaaaz",
      "bbbbbbbbbbbbbcaz",
      "    lt      Wbaz",
      "e   lt      tbaz",
      "lllldt      tbaz",
      "    lt      Wbaz",
      "    lXY     tbaz",
      " fgglXY     tbaz",
      "  hhlXY     Wbaz",
      "    lXY     tbaz",
      "    lt      tbaz",
      "    lttttttttbaz",
      "    l       tbaz",
      "    l       tbaz",
      "lllldllllllllcaz"
    ],
    [
      "zzzzzzzzzzzzzzzz",
      "aaaaaaaaaaaaaaaz",
      "bbbbbbbbbbbbbcaz",
      "    lZZZZZZZZbaz",
      " e  lZZZZZZZZbaz",
      "lllldZZZZZZZZbaz",
      "    lZZZZZZZZbaz",
      "    lZZZZZZZZbaz",
      "    lZZZZZZZZbaz",
      " f  lZZZZZZZZbaz",
      " fgglZZZZZZZZbaz",
      "  hhlZZZZZZZZbaz",
      "    lZZZZZZZZbaz",
      "    lZZZZZZZZbaz",
      "    lZZZZZZZZbaz",
      "lllldllllllllcaz"
    ]
  ]
}