{
  "name": "multi_militarybase_2_base4",
  "refpalette": "c70cities:multi_militarybase_2_base4_palette",
  "xsize": 16,
  "zsize": 16,
  "slices": [
    [
      "vvvvvvvvvvvvvvvv",
      "aaaaaaaaaaaaaaaa",
      "aaaaaaaaaaaaaaaa",
      "aaaaaaaaaaaaaaaa",
      "aaaaaaaaaaaaaaaa",
      "bbbbbbbbbbbbbbbb",
      "aaaaaaaaaaaaaaaa",
      "aaaaaaaaaaaaaaaa",
      "aaaaaaaaaaaaaaaa",
      "aaaaaaaaaaaaaaaa",
      "aaaaaaaaaaaaaaaa",
      "aaaaaaaaaaaaaaaa",
      "aaaaaaaaaaaaaaaa",
      "bbvbbbbvbbbbvbbb",
      "cccccccccccccccc",
      "cccccccccccccccc"
    ],
    [
      "vvvvvvvvvvvvvvvv",
      "dddddddddddddddd",
      "dddddddddddddddd",
      "dddddddddddddddd",
      "dddddddddddddddd",
      "dddddddddddddddd",
      "dddddddddddddddd",
      "dddddddddddddddd",
      "effggggg hhiii e",
      " ej jgg k h ii  ",
      "   l   l   m    ",
      "                ",
      "                ",
      "ddvddddvddddvddd",
      "no nnnn onnn non",
      "                "
    ],
    [
      "vvvvvvvvvvvvvvvv",
      "pp pppp pppp ppp",
      "q        q     r",
      "     q          ",
      "               s",
      "dddddddddddddddd",
      "dddddddddddddddd",
      "dddddddddddddddd",
      "e  g  g   kh    ",
      "     j      k   ",
      "                ",
      "                ",
      "                ",
      "ddvddddvddddvddd",
      " t      u     w ",
      "                "
    ],
    [
      "vvvvvvvvvvvvvvvv",
      " x x  x x x  x x",
      "                ",
      "                ",
      "                ",
      "ppp ppp ppp ppp ",
      " y   y  y     y ",
      "               s",
      "dddddddddddddddd",
      "dddddddddddddddd",
      "AAAAAAAAAAAAAAAA",
      "                ",
      "BBBBBBBBBBBBBBBB",
      "ddvddddvddddvddd",
      "                ",
      "                "
    ],
    [
      "vvvvvvvvvvvvvvvv",
      "CCCCCDCCCCCCDEC ",
      "                ",
      "                ",
      "                ",
      " FF IFJ FF  IFF ",
      "                ",
      "                ",
      "ppp ppp ppp ppp ",
      " y  y    y  y   ",
      "               s",
      "dddddddddddddddd",
      "dddddddddddddddd",
      "ddvddddvddddvddd",
      "                ",
      "                "
    ],
    [
      "vvvvvvvvvvvvvvvv",
      "CCCDCCCCDDCCCDD ",
      "                ",
      "                ",
      "                ",
      "                ",
      "                ",
      "                ",
      "KF  FFL  FJ F M ",
      "                ",
      "                ",
      "ppp ppp ppp ppp ",
      " y   y    y  y  ",
      "  v    v!   v  s",
      "AAAAAAAAAAAAAAAA",
      "NNNNNNNNNNNNNNNN"
    ]
  ]
}