{
  "name": "multi_condo1_5_floor2",
  "refpalette": "c70cities:multi_condo1_5_floor2_palette",
  "xsize": 16,
  "zsize": 16,
  "slices": [
    [
      "aaaaabcdddddef  ",
      "cccccccdddddef  ",
      "ggggggggggggehhh",
      "ggggggggggggeij ",
      "ggggggggggggeij ",
      "ggggggggggggeij ",
      "ggggggggggggeij ",
      "ggggggggggggeij ",
      "cccccccgggggeij ",
      "cccccccgggggeij ",
      "cccccccgggggeij ",
      "ccccccceeeeeeij ",
      "kkkkkkhiiiiiiij ",
      "llllllhjjjjjjjj ",
      "      h         ",
      "                "
    ],
    [
      "     men   op   ",
      "qeeeeeersrrre   ",
      "  ttttru wwwehhh",
      "      rx    ei  ",
      "y A   B     ei  ",
      "y C   r    Dei  ",
      "      rE  FIei  ",
      "JJK  LrM  FIei  ",
      "NNNNNee    Dei  ",
      "      O  P  ei  ",
      "  QR LeLSTULei  ",
      "     eeeVVVeei  ",
      "      hiiiiiii  ",
      "llllllh         ",
      "      h         ",
      "                "
    ],
    [
      "     ie   W l   ",
      "XeeeeeerYrrre   ",
      "  Z01 r2 wwwehhh",
      "      r     e   ",
      "      3     e   ",
      "      r     e   ",
      "      r4    e   ",
      "5 6  7r4    e   ",
      "NNNNNee     e   ",
      "      8     e   ",
      "     7e7   7e   ",
      "     eeeNNNee   ",
      "      h         ",
      "      h         ",
      "      h         ",
      "                "
    ],
    [
      "     ie     l   ",
      "9eeeeeerrrrre   ",
      "   !  r   @#ehhh",
      "      r     e   ",
      "      r     e   ",
      "      r    $e   ",
      "      r     e   ",
      "     7r     e   ",
      "NNNNNee    $e   ",
      "      %     e   ",
      "      e     e   ",
      "     eeeNNNee   ",
      "      h         ",
      "      h         ",
      "      h         ",
      "                "
    ],
    [
      "     ^e     e   ",
      "eeeeeeerrrrre   ",
      "      r     ehhh",
      "      r     e&  ",
      "      r     e&  ",
      "      r    *e&  ",
      "      r     e&  ",
      "      r     e&  ",
      "NNNNNee    *e&  ",
      "      e     e&  ",
      "      e     e&  ",
      "eeeeeeeeeeeee&  ",
      "      h&&&&&&&  ",
      "      h         ",
      "      h         ",
      "                "
    ],
    [
      "      e(((((e   ",
      "eeeeeee(((((e   ",
      "((((((((((((ehhh",
      "((((((((((((e)  ",
      "((((((((((((e)  ",
      "((((((((((((e)  ",
      "((((((((((((e)  ",
      "((((((((((((e)  ",
      "+++++ee(((((e)  ",
      "aaaaaae(((((e)  ",
      "aaaaaae(((((e)  ",
      "eeeeeeeeeeeee)  ",
      "      h)))))))  ",
      "------h         ",
      "      h         ",
      "                "
    ]
  ]
}