{
  "name": "multi_laboratory1_10_base1",
  "refpalette": "c70cities:multi_laboratory1_10_base1_palette",
  "xsize": 16,
  "zsize": 16,
  "slices": [
    [
      "vvvvvvvvvvvvvvvv",
      "aaaaaaaaaaaaaaav",
      "bbbbbbbbbbbbbcav",
      "    d========cav",
      "  e d========cav",
      "ddddd========cav",
      "    d========cav",
      "    d========cav",
      "    d========cav",
      "    d========cav",
      "    d========cav",
      " f  d========cav",
      " fggd========cav",
      "hhhhd========cav",
      "hhhhd========cav",
      "dddddiiiiiiiicav"
    ],
    [
      "vvvvvvvvvvvvvvvv",
      "aaaaaaaaaaaaaaav",
      "bbbbbbbbbbbbbcav",
      "    jkkkkl mnbav",
      "   opqlkk   rbav",
      "ssssdtk     rbav",
      "    sru    mnbav",
      "    s!u     rbav",
      "    su      rbav",
      "    sw     mnbav",
      "    sw      rbav",
      "hh  sx      rbav",
      "ggy s       Abav",
      "    s       Bbav",
      "    C    DE Bbav",
      "Fsssdsssssssscav"
    ],
    [
      "vvvvvvvvvvvvvvvv",
      "aaaaaaaaaaaaaaav",
      "bbbbbbbbbbbbbcav",
      "    jqkl   mnbav",
      "    pIJ     rbav",
      "ssssdt      rbav",
      "    srr    mnbav",
      "    s       rbav",
      "    s       rbav",
      "hh  s      mnbav",
      "ggy s       rbav",
      "  y s       rbav",
      "    s        bav",
      "    s        bav",
      "    K        bav",
      "Lsssdsssssssscav"
    ],
    [
      "vvvvvvvvvvvvvvvv",
      "aaaaaaaaaaaaaaav",
      "bbbbbbbbbbbbbcav",
      "    pI      tbav",
      "    j       rbav",
      "ssssdt      rbav",
      "hhhhsr      tbav",
      "hhhhs       rbav",
      "ggy s       rbav",
      "  y s       tbav",
      "    s       rbav",
      "    s       rbav",
      "    s        bav",
      "    s        bav",
      "M   s        bav",
      "Nsssdsssssssscav"
    ],
    [
      "vvvvvvvvvvvvvvvv",
      "aaaaaaaaaaaaaaav",
      "bbbbbbbbbbbbbcav",
      "    st      Obav",
      "    st      tbav",
      "ssssdt      tbav",
      "    st      Obav",
      "    sPQ     tbav",
      " fggsPQ     tbav",
      "  hhsPQ     Obav",
      "    sPQ     tbav",
      "    st      tbav",
      "    sttttttttbav",
      "    s       tbav",
      "    s       tbav",
      "ssssdsssssssscav"
    ],
    [
      "vvvvvvvvvvvvvvvv",
      "aaaaaaaaaaaaaaav",
      "bbbbbbbbbbbbbcav",
      "RRRRsRRRRRRRRbav",
      "RRRRsRRRRRRRRbav",
      "ssssdRRRRRRRRbav",
      "    sRRRRRRRRbav",
      "    sRRRRRRRRbav",
      "    sRRRRRRRRbav",
      " f  sRRRRRRRRbav",
      " fggsRRRRRRRRbav",
      "  hhsRRRRRRRRbav",
      "    sRRRRRRRRbav",
      "    sRRRRRRRRbav",
      "    sRRRRRRRRbav",
      "ssssdsssssssscav"
    ]
  ]
}