{
  "name": "multi_factory_1_ground",
  "refpalette": "c70cities:multi_factory_1_ground_palette",
  "xsize": 16,
  "zsize": 16,
  "slices": [
    [
      "aaabbbbbbbbbbbzz",
      "zaabbbbbbbbbbbzz",
      "azabbbbbbbbbbbzz",
      "aaabbbbbbbbbbbzz",
      "aaabbbbbbbbbbbzz",
      "aaabbbbbbbbbbbzz",
      "zaabbbbbbbbbbbzz",
      "aaabbbbbbbbbbbzz",
      "zaabbbbbbbbbbbzz",
      "zaabbbbbbbbbbbzz",
      "aaabbbbbbbbbbbzz",
      "aaabbbbbbbbbbbzz",
      "azabbbbbbbbbbbzz",
      "aaabbbbbbbbbbbzz",
      "zaazzzzzzzzzzzzz",
      "aazzzzzzzzzzzzzz"
    ],
    [
      "      ccdcc ef  ",
      "      cgggchif  ",
      "      jgggjhkf  ",
      "   f  ggggghlf  ",
      "   fm mgngg mf  ",
      "   f    o    f  ",
      "   p       qrf  ",
      "   p     sss f  ",
      "   p    qs!sqf  ",
      "   p   qrsss f  ",
      "   p     q   f  ",
      "   pr     tt f  ",
      "   fmuuwmxjymf  ",
      "   fffffffffff  ",
      "                ",
      "                "
    ],
    [
      "      dAAAd  f  ",
      "      dBBBd  f  ",
      "      jBBBj Cf  ",
      "   f         f  ",
      "   fm D     mf  ",
      "   f    E    f  ",
      "   p         f  ",
      "   p     sss f  ",
      "   p       s f  ",
      "   p     sss f  ",
      "   p         f  ",
      "   pr        f  ",
      "   fm   m ttmf  ",
      "   fffffffffff  ",
      "                ",
      "                "
    ],
    [
      "   p  cAAAc Ff  ",
      "   p   BBB   f  ",
      "   p  jBBBj If  ",
      "   f   BBB   f  ",
      "   fm  BBB  mf  ",
      "   f         f  ",
      "   pr        f  ",
      "   p     ss  f  ",
      "   p       s f  ",
      "   p     qss f  ",
      "   p         f  ",
      "   p         f  ",
      "   fmr  m  rmf  ",
      "   ffJKLfJKLff  ",
      "                ",
      "                "
    ],
    [
      "  MfN  mAm   f  ",
      "  MfN  BBB  Of  ",
      "  MfN  BBB PQf  ",
      "   f   BBB   f  ",
      "   fm       mf  ",
      "   fr        f  ",
      "  MfN        f  ",
      "  MfN    RRR f  ",
      "  MfN    R R f  ",
      "  MfN    RRR f  ",
      "  MfN        f  ",
      "  MfN   S   Sf  ",
      "   fmSSSmSSSmf  ",
      "   fffffffffff  ",
      "                ",
      "                "
    ],
    [
      "   f   mAm   f  ",
      "   f    A    f  ",
      "   f    A    f  ",
      "   f         f  ",
      "   fm       mf  ",
      "   f         f  ",
      "   f         f  ",
      "   fS   SRRRSf  ",
      "   fSSSSSR RSf  ",
      "   fS   SRRRSf  ",
      "   fT   T   Tf  ",
      "   fUUUUUUUUUf  ",
      "   fUUUUUUUUUf  ",
      "   VVVVVVVVVVV  ",
      "                ",
      "                "
    ]
  ]
}