{
  "name": "multi_communitycenter_4_ground",
  "refpalette": "c70cities:multi_communitycenter_4_ground_palette",
  "xsize": 16,
  "zsize": 16,
  "slices": [
    [
      "aabcddeffffedddg",
      "ahbcddeffffeddGg",
      "aabcddeffffeddGg",
      "ahbcddeffffeddGg",
      "aabcddeffffedddg",
      "ahbcddeffffeddGg",
      "aabcddeffffeddGg",
      "iiicddeffffeddGg",
      "jjjjjddeffeddddg",
      "kkkkjdddeeddddGg",
      "kkkkjjddddddddGg",
      "kkkkkjjjddddddGg",
      "kkkkkkjjjjjjjjjl",
      "kkkkkkljjjjjjjjl",
      "lkkkkkljjjjjjjjl",
      "jlkkkkljjjjjjjjl"
    ],
    [
      "   c  effffe  mn",
      "  oc  effffe  pn",
      "   c  effffe  pq",
      "   c  effffe  pn",
      "   c  effffe  mn",
      "  oc  effffe  pn",
      "   c  effffe  pq",
      "iiic  effffe  pn",
      "rrrrc seffes  mn",
      "t  tc  sees   pn",
      "u oucc        pq",
      "t  t ccc  ww  pn",
      "  o x icyABCAyci",
      " tu DDE   FF   E",
      "I o             ",
      " I  o           "
    ],
    [
      "JJJy          mn",
      "   y           n",
      "   c           q",
      "   c           n",
      "   y          mn",
      "   y           n",
      "   y           q",
      "iiic           n",
      "rrrrc         mn",
      "    y          n",
      "    yy         q",
      "     yyc       n",
      "      icyAKLAyci",
      "      E        E",
      "I       M       ",
      " I              "
    ],
    [
      "NNNc          mn",
      "OOOc           n",
      "JJJc           q",
      "JJJc           n",
      "JJJy          mn",
      "   y           n",
      "   y           q",
      "iiic           n",
      "rrrrc         mn",
      "    y          n",
      "    yy         q",
      "     yyc       n",
      "      icyAAAAyci",
      "      E        E",
      "I       P       ",
      " I              "
    ],
    [
      "Q Rc          mn",
      "NNNc           n",
      "NNNc           n",
      "NNNc           n",
      "NNNc          mn",
      "OOOc           n",
      "OOOc           n",
      "iiic           n",
      "ccccc         mn",
      "    c          n",
      "    cc         n",
      "     ccc       n",
      "      icyyyyyyci",
      "      E        E",
      "E     E P    M E",
      " E    E        E"
    ],
    [
      "  R           Sg",
      " QR           Sg",
      " TRU          Sg",
      "  RU          Sg",
      "VVRc          mg",
      "NNNc          Sg",
      "NNWc          Sg",
      "NNWc          Sg",
      "NNNcc         Sg",
      "OOOOc         Sg",
      "OOOOcc        Sg",
      "OOOOOccc      Sg",
      "OOOOOOiccccccccc",
      "iOOOOOiJJJJJJJJi",
      "iiOOOOiJPM M PJi",
      " iiOOOiJM M  MJi"
    ]
  ]
}