{
  "name": "multi_laboratory1_14_base2",
  "refpalette": "c70cities:multi_laboratory1_14_base2_palette",
  "xsize": 16,
  "zsize": 16,
  "slices": [
    [
      "aaaabaaaaaaaacdv",
      "aaaaaaaaaaaaacdv",
      "aaaaaaaaaaaaacdv",
      "aaaaaaaaaaaaacdv",
      "aaaaaaaaaaaaacdv",
      "aaaaaaaaaaaaacdv",
      "aaaaaaaaaaaaacdv",
      "aaaabaaaaaaaacdv",
      "aaaaaeeeeeeeecdv",
      "aaaaaeeeeeeeecdv",
      "aaaaaeeeeeeeecdv",
      "aaaaaeeeeeeeecdv",
      "aa!aa!eeeeeeecdv",
      "ccccccccccccccdv",
      "dddddddddddddddv",
      "vvvvvvvvvvvvvvvv"
    ],
    [
      "f   bggggggggcdv",
      "f   g h    h cdv",
      "i   g        cdv",
      "jj  g k ll m cdv",
      "    g   no pqcdv",
      "    r     st cdv",
      "    guuuuuuuucdv",
      "    bggggggggcdv",
      "    gwwxxxxwwcdv",
      "    y        cdv",
      "    gABCBABABcdv",
      "    g D D D Dcdv",
      " EEFgIDIDIDIDcdv",
      "ccccccccccccccdv",
      "dddddddddddddddv",
      "vvvvvvvvvvvvvvvv"
    ],
    [
      "    bggJJJJggcdv",
      "    g h    h cdv",
      "K   g        cdv",
      "    g        cdv",
      "    g        cdv",
      "    L        cdv",
      "    gMN   O Mcdv",
      "    bggggggggcdv",
      "    gMPPPPPPMcdv",
      "    Q        cdv",
      "    gRBSBRBRBcdv",
      "    g D D D Dcdv",
      "    g D D D Dcdv",
      "ccccccccccccccdv",
      "dddddddddddddddv",
      "vvvvvvvvvvvvvvvv"
    ],
    [
      "    bggTTTTggcdv",
      "    g        cdv",
      "   Ug        cdv",
      "   Ug        cdv",
      "    g        cdv",
      "    V        cdv",
      "    g        cdv",
      "    bggggggggcdv",
      "    g PPPPPP cdv",
      "    g        cdv",
      "    gBBBBBBBBcdv",
      "    g D D D Dcdv",
      "    g D D D Dcdv",
      "ccccccccccccccdv",
      "dddddddddddddddv",
      "vvvvvvvvvvvvvvvv"
    ],
    [
      "    bggggggggcdv",
      "    g        cdv",
      "    g        cdv",
      "    g        cdv",
      "    g        cdv",
      "    g        cdv",
      "    g        cdv",
      "    bggggggggcdv",
      "    gWWWWWWWWcdv",
      "    gWWWWWWWWcdv",
      "    gWWWWWWWWcdv",
      "    gWWWWWWWWcdv",
      "    gXWXWXWXWcdv",
      "ccccccccccccccdv",
      "dddddddddddddddv",
      "vvvvvvvvvvvvvvvv"
    ],
    [
      "Y YYbggggggggcdv",
      "YZYYV00000000cdv",
      "YZYYV01000010cdv",
      "22YYV00000000cdv",
      "YYYYV00000000cdv",
      "YYYYV030000Z0cdv",
      "YYYYV00000000cdv",
      "ggggbggggggggcdv",
      "4444g55555555cdv",
      "4424g5 5 5 5ccdv",
      "4424g5 5 5 5ccdv",
      "4424g5 5 5 5ccdv",
      "4444g5 5 5 5ccdv",
      "ccccccccccccccdv",
      "dddddddddddddddv",
      "vvvvvvvvvvvvvvvv"
    ]
  ]
}