{
  "name": "multi_laboratory1_5_base4",
  "refpalette": "c70cities:multi_laboratory1_5_base4_palette",
  "xsize": 16,
  "zsize": 16,
  "slices": [
    [
      "vvvvvvvvvvvvvvvv",
      "aaaaaaaaaaaaaaaa",
      "bbbbbbbbbbbbbbbb",
      "                ",
      "                ",
      "cccccccccccccccc",
      "c    c    c    c",
      "cd  dcd  dcd  dc",
      "cccccccccccccccc",
      "c    c    c    c",
      "c    c    c    c",
      "c    c    c    c",
      "c    c    c    c",
      "c    c    c    c",
      "c    c    c    c",
      "ccccefcccgcccceh"
    ],
    [
      "vvvvvvvvvvvvvvvv",
      "aaaaaaaaaaaaaaaa",
      "bbbbbbbbbbbbbbbb",
      "                ",
      "                ",
      "ciiiiiiiiiiiiiic",
      "i    i    i    i",
      "id  did  did  di",
      "ciiiiciiiiciiiic",
      "i    i    i    i",
      "i    i    i    i",
      "i    i    i    i",
      "i    i    i    i",
      "i    i    i    i",
      "i    i    i    i",
      "cijjicijjicijjic"
    ],
    [
      "vvvvvvvvvvvvvvvv",
      "aaaaaaaaaaaaaaaa",
      "bbbbbbbbbbbbbbbb",
      "                ",
      "                ",
      "ciiiiiiiiiiiiiic",
      "i    i    i    i",
      "id  did  did  di",
      "ciiiiciiiiciiiic",
      "i    i    i    i",
      "i    i    i    i",
      "i    i    i    i",
      "i    i    i    i",
      "i    i    i    i",
      "i    i    i    i",
      "ci  ici  ici  ic"
    ],
    [
      "vvvvvvvvvvvvvvvv",
      "aaaaaaaaaaaaaaaa",
      "bbbbbbbbbbbbbbbb",
      "                ",
      "                ",
      "ciiiiiiiiiiiiiic",
      "i    i    i    i",
      "id  did  did  di",
      "ciiiiciiiiciiiic",
      "i    i    i    i",
      "i    i    i    i",
      "i    i    i    i",
      "i    i    i    i",
      "i    i    i    i",
      "i    i    i    i",
      "cikkicikkicikkic"
    ],
    [
      "vvvvvvvvvvvvvvvv",
      "aaaaaaaaaaaaaaaa",
      "bbbbbbbbbbbbbbbb",
      "               l",
      "               l",
      "ciiiiiiiiiiiiiic",
      "i    i    i    i",
      "id  did  did  di",
      "ciiiiciiiiciiiic",
      "i    i    i    i",
      "i    i    i    i",
      "i    i    i    i",
      "i    i    i    i",
      "i    i    i    i",
      "i    i    i    i",
      "ciiiiciiiiciiiic"
    ],
    [
      "vvvvvvvvvvvvvvvv",
      "aaaaaaaaaaaaaaaa",
      "bbbbbbbbbbbbbbbb",
      "                ",
      "                ",
      "ciiiiiiiiiiiiiic",
      "i    i    i    i",
      "id  did  did  di",
      "ciiiiciiiiciiiic",
      "i    i    i    i",
      "i    i    i    i",
      "i    i    i    i",
      "i    i    i    i",
      "i    i    i    i",
      "i    i    i    i",
      "ciiiiciiiiciiiic"
    ]
  ]
}