{
  "name": "multi_hospital_1_top",
  "refpalette": "c70cities:multi_hospital_1_top_palette",
  "xsize": 16,
  "zsize": 16,
  "slices": [
    [
      "        abcccccc",
      "        abcccccc",
      "        abbbbbbb",
      "        abdddddd",
      "        abdddddd",
      "        abdddddd",
      "        abdddddd",
      "        abdddddd",
      "        abdddddd",
      "        abdddddd",
      "        abdddddd",
      "        abdddddd",
      "        abdddddd",
      "        abbbbbbb",
      "        abbbbbbb",
      "                "
    ],
    [
      "         eff    ",
      "         e      ",
      "         egggggg",
      "         h      ",
      "                ",
      "                ",
      "                ",
      "                ",
      "                ",
      "                ",
      "                ",
      "                ",
      "                ",
      "                ",
      "                ",
      "                "
    ],
    [
      "         ij     ",
      "         e      ",
      "         egggggg",
      "         h      ",
      "                ",
      "                ",
      "                ",
      "                ",
      "                ",
      "                ",
      "                ",
      "                ",
      "                ",
      "                ",
      "                ",
      "                "
    ],
    [
      "         e      ",
      "         e      ",
      "         egggggg",
      "         h      ",
      "                ",
      "                ",
      "                ",
      "                ",
      "                ",
      "                ",
      "                ",
      "                ",
      "                ",
      "                ",
      "                ",
      "                "
    ],
    [
      "        ke      ",
      "        ke      ",
      "        keeeeeee",
      "        kkkkkkkk",
      "                ",
      "                ",
      "                ",
      "                ",
      "                ",
      "                ",
      "                ",
      "                ",
      "                ",
      "                ",
      "                ",
      "                "
    ],
    [
      "        l llllll",
      "        l llllll",
      "        l       ",
      "        llllllll",
      "        llllllll",
      "                ",
      "                ",
      "                ",
      "                ",
      "                ",
      "                ",
      "                ",
      "                ",
      "                ",
      "                ",
      "                "
    ]
  ]
}