{
  "name": "multi_megatower1_4_top",
  "refpalette": "c70cities:multi_megatower1_4_top_palette",
  "xsize": 16,
  "zsize": 16,
  "slices": [
    [
      "a  a            ",
      "a  a bb         ",
      "a  a bb         ",
      "aaca            ",
      "  dde      e    ",
      "                ",
      "                ",
      "                ",
      "                ",
      "                ",
      "                ",
      "    e      e    ",
      "                ",
      "                ",
      "                ",
      "                "
    ],
    [
      "  f             ",
      "  g             ",
      "  f             ",
      " dc             ",
      "   de      e    ",
      "                ",
      "                ",
      "                ",
      "                ",
      "                ",
      "                ",
      "    e      e    ",
      "                ",
      "                ",
      "                ",
      "                "
    ],
    [
      "                ",
      "                ",
      "                ",
      "                ",
      "    e      e    ",
      "                ",
      "                ",
      "                ",
      "                ",
      "                ",
      "                ",
      "    e      e    ",
      "                ",
      "                ",
      "                ",
      "                "
    ],
    [
      "                ",
      "                ",
      "                ",
      "                ",
      "    e      e    ",
      "                ",
      "                ",
      "                ",
      "                ",
      "                ",
      "                ",
      "    e      e    ",
      "                ",
      "                ",
      "                ",
      "                "
    ],
    [
      "                ",
      "                ",
      "                ",
      "                ",
      "    e      e    ",
      "                ",
      "                ",
      "                ",
      "                ",
      "                ",
      "                ",
      "    e      e    ",
      "                ",
      "                ",
      "                ",
      "                "
    ],
    [
      "    hiiiiiihiiii",
      "    hiiiiiihiiii",
      "    hiiiiiihiiii",
      "    hiiiiiihiiii",
      "jjjjejjjjjjejjjj",
      "    hiiiiiihiiii",
      "    hiiiiiihiiii",
      "    hiiiiiihiiii",
      "    hiiiiiihiiii",
      "    hiiiiiihiiii",
      "    hiiiiiihiiii",
      "jjjjejjjjjjejjjj",
      "    hiiiiiihiiii",
      "    hiiiiiihiiii",
      "    hiiiiiihiiii",
      "    hiiiiiihiiii"
    ]
  ]
}