{
  "name": "multi_flatapartment_0_ground",
  "refpalette": "c70cities:multi_flatapartment_0_ground_palette",
  "xsize": 16,
  "zsize": 16,
  "slices": [
    [
      "GGGGGGGGGGGGGGGa",
      "HHHHHaaaaaaaaaaa",
      "HHHHHaaaaaaaaaaa",
      "HHHHHaaaaaaaaaaa",
      "HHHHHaaaaaaaaaaa",
      "HHHHHaaaaaaaaaaa",
      "HHHbHaaaaaaaaaaa",
      "HHHHHaaaaaaaaaaa",
      "HHHHHaaaaaaaaaaa",
      "HHHHHaaaaaaaaaaa",
      "HHHHHaaaaaaaaaaa",
      "HHHHHaaaaaaaaaaa",
      "HHHHHaaaaaaaaaaa",
      "HHHHHaaaaaaaaaaa",
      "HHHHHaaaaaaaaaaa",
      "GGGGGGGGGGGGGGGa"
    ],
    [
      "     cccccccccc ",
      "  d efggggfgggf ",
      "  h ide         ",
      "  d e           ",
      "  h ihi    d e  ",
      "  d ef    fh if ",
      "  h  de  d ejd e",
      "  d e    h ijh i",
      "  h i    d ejd e",
      "  d ehi  h ijh i",
      "  h if    fd ef ",
      "  d ede    h i  ",
      "  h i           ",
      "  d ehi         ",
      "  h ifkkkkfkkkf ",
      "l    cccccccccc "
    ],
    [
      "                ",
      "     m    m   m ",
      "                ",
      "                ",
      "                ",
      "     m    m   m ",
      "                ",
      "                ",
      "                ",
      "                ",
      "     m    m   m ",
      "                ",
      "                ",
      "                ",
      "     m    m   m ",
      "n               "
    ],
    [
      "                ",
      "     mo  omo omo",
      "     o          ",
      "                ",
      "     o          ",
      "     m    m   m ",
      "     o          ",
      "                ",
      "                ",
      "     o          ",
      "     m    m   m ",
      "     o          ",
      "                ",
      "     o          ",
      "     mo  omo omo",
      "p               "
    ],
    [
      "                ",
      "     m qq m q m ",
      "          r   r ",
      "     q          ",
      "                ",
      "     mr   m   m ",
      "                ",
      "     q          ",
      "     q          ",
      "                ",
      "     mr   m   m ",
      "                ",
      "     q          ",
      "          r   r ",
      "     m qq m q m ",
      "                "
    ],
    [
      "                ",
      "     qqqqqqqqqqq",
      "     qaaaaaaaaaa",
      "     qa   a   a ",
      "     qa   a   a ",
      "     qaaaaaaaaaa",
      "     qa   a   a ",
      "     qa   a   a ",
      "     qa   a   a ",
      "     qa   a   a ",
      "     qaaaaaaaaaa",
      "     qa   a   a ",
      "     qa   a   a ",
      "     qaaaaaaaaaa",
      "     qqqqqqqqqqq",
      "                "
    ]
  ]
}