{
  "name": "multi_megatower1_6_ground",
  "refpalette": "c70cities:multi_megatower1_6_ground_palette",
  "xsize": 16,
  "zsize": 16,
  "slices": [
    [
      "aGGGGGaGGGGaGGGG",
      "GaaGaaGaaGaGaaGG",
      "GGaGGGGGGaGGGGGG",
      "vvvvvvvvvvvvvvGG",
      "vvvvbbbbbccccGGG",
      "vvvvbbbbbccccGGG",
      "vvdvbbbbbccccGGG",
      "vvvvbbbbbccccGGG",
      "vvvvbbbbbccccGGG",
      "vvvvbbbbbccccGGG",
      "vvvvbbbbbccccGGG",
      "vvvvbbbbbccccGGG",
      "vvvvbbbbbccccGGG",
      "vvdvbbbbbccccGGG",
      "vvvvbbbbbccccGGG",
      "vvvvbbbbbccccGGG"
    ],
    [
      "                ",
      "                ",
      "ee eeef e eef   ",
      "gghgggggghggii  ",
      "ccdbbccccj      ",
      "ccdbbcccc       ",
      "ccdbbcccc       ",
      "ccdbbcccc       ",
      "ccdbbcccc       ",
      "ccdbbcccc       ",
      "ccdbbcccc       ",
      "ccdbbcccc       ",
      "ccdbbcccc       ",
      "ccdbbcccc       ",
      "ccdbbcccc       ",
      "ccdbbcccc       "
    ],
    [
      "                ",
      "                ",
      "                ",
      "gghgggggik      ",
      "ccccc           ",
      "ccccc           ",
      "ccccc           ",
      "ccccc           ",
      "ccccc           ",
      "ccccc           ",
      "ccccc           ",
      "ccccc           ",
      "ccccc           ",
      "ccdcc           ",
      "ccccc           ",
      "ccccc           "
    ],
    [
      "                ",
      "                ",
      "  l             ",
      "gghgii          ",
      "c j             ",
      "c               ",
      "c               ",
      "c               ",
      "c               ",
      "c               ",
      "c               ",
      "c               ",
      "c               ",
      "c d             ",
      "c m             ",
      "c               "
    ],
    [
      "                ",
      "                ",
      "                ",
      "ii              ",
      "                ",
      "                ",
      "                ",
      "                ",
      "                ",
      "                ",
      "                ",
      "                ",
      "                ",
      "  n             ",
      "                ",
      "                "
    ],
    [
      "                ",
      "                ",
      "                ",
      "                ",
      "                ",
      "                ",
      "                ",
      "                ",
      "                ",
      "                ",
      "                ",
      "                ",
      "                ",
      "  d             ",
      "                ",
      "                "
    ]
  ]
}