{
  "name": "multi_hospital_2_top",
  "refpalette": "c70cities:multi_hospital_2_top_palette",
  "xsize": 16,
  "zsize": 16,
  "slices": [
    [
      "                ",
      "                ",
      " a              ",
      "bc              ",
      "db              ",
      "dc              ",
      "db              ",
      "dc              ",
      "deeeeeeeeeeeeee ",
      "deffffffffffffe ",
      "deffffghhhifffe ",
      "dejffklmmmnoffe ",
      "dejffpmqqqmrffe ",
      "dejffpmmqmmrffe ",
      "dejffpmqqqmrffe ",
      "dejffstmmmuwffe "
    ],
    [
      "                ",
      "                ",
      " a              ",
      "xx              ",
      "yx              ",
      " x              ",
      " x              ",
      " x              ",
      " x              ",
      " x              ",
      " x              ",
      " x              ",
      " A              ",
      " B              ",
      " C              ",
      " A              "
    ],
    [
      "                ",
      "                ",
      " a              ",
      "xx              ",
      "Dx              ",
      " x              ",
      " x              ",
      " x              ",
      " x              ",
      " x              ",
      " x              ",
      " x              ",
      " A              ",
      " E              ",
      " F              ",
      " A              "
    ],
    [
      "                ",
      "                ",
      " a              ",
      "xx              ",
      " x              ",
      " x              ",
      " x              ",
      " x              ",
      " x              ",
      " x              ",
      " x              ",
      " x              ",
      " A              ",
      " A              ",
      " A              ",
      " A              "
    ],
    [
      "                ",
      "                ",
      "III             ",
      "mmJ             ",
      " m              ",
      " m              ",
      " m              ",
      " mK             ",
      " mK             ",
      " mK             ",
      " mK             ",
      " mK             ",
      " mK             ",
      " mK             ",
      " mK             ",
      " mK             "
    ],
    [
      "                ",
      "                ",
      "                ",
      "                ",
      "I I             ",
      "I I             ",
      "I I             ",
      "I I             ",
      "I I             ",
      "I I             ",
      "I I             ",
      "I I             ",
      "I I             ",
      "I I             ",
      "I I             ",
      "I I             "
    ]
  ]
}