{
  "name": "multi_residential1_1_floor1",
  "refpalette": "c70cities:multi_residential1_1_floor1_palette",
  "xsize": 16,
  "zsize": 16,
  "slices": [
    [
      "  aaaaaaaaaaaa  ",
      "  bc   d     b  ",
      "  a          a  ",
      " eae      f eae ",
      " ggg        ggg ",
      " hhh        hhh ",
      "   i        i   ",
      "                ",
      "   i        i   ",
      "                ",
      "   i  i  i  i   ",
      "                ",
      "                ",
      "                ",
      "                ",
      "                "
    ],
    [
      "  aabbbaabbbaa  ",
      " eae   jj   eae ",
      " ggg        ggg ",
      " hhh      f hhh ",
      "   i        i   ",
      "                ",
      "   i        i   ",
      "                ",
      "   i        i   ",
      "                ",
      "   i  i  i  i   ",
      "                ",
      "                ",
      "                ",
      "                ",
      "                "
    ],
    [
      " gggggggggggggg ",
      " hhhhhhhhhhhhhh ",
      "  hhkkkkkkkkhh  ",
      "  hhkkkkkkkkhh  ",
      "  hhkkkkkkkkhh  ",
      "  hhkkkkkkkkhh  ",
      "  hhkkkkkkkkhh  ",
      "  hhkkkkkkkkhh  ",
      "  hhkkkkkkkkhh  ",
      "  hhkkkkkkkkhh  ",
      "  hhhhhhhhhhhh  ",
      "  hhhhhhhhhhhh  ",
      "                ",
      "                ",
      "                ",
      "                "
    ],
    [
      "                ",
      "                ",
      "                ",
      "                ",
      "                ",
      "                ",
      "       ~        ",
      "                ",
      "                ",
      "                ",
      "                ",
      "                ",
      "                ",
      "                ",
      "                ",
      "                "
    ],
    [
      "                ",
      "                ",
      "                ",
      "                ",
      "                ",
      "                ",
      "       ~        ",
      "                ",
      "                ",
      "                ",
      "                ",
      "                ",
      "                ",
      "                ",
      "                ",
      "                "
    ],
    [
      "                ",
      "                ",
      "                ",
      "                ",
      "                ",
      "                ",
      "       ~        ",
      "                ",
      "                ",
      "                ",
      "                ",
      "                ",
      "                ",
      "                ",
      "                ",
      "                "
    ]
  ]
}