{
  "name": "multi_condo1_5_base2",
  "refpalette": "c70cities:multi_condo1_5_base2_palette",
  "xsize": 16,
  "zsize": 16,
  "slices": [
    [
      "HHHHHHHHHHHHabbv",
      "HHHHHHaaaaHHabbv",
      "HHHHHHaccaHHabbv",
      "HHHHHHaccaHHabbv",
      "HHHHHHdccaHHabbv",
      "HHHHHHaccaHHabbv",
      "HHHHHHaccaHHabbv",
      "HHHHHHaccaHHabbv",
      "HHHHHHaccaHHabbv",
      "HHHHHHaccaHHabbv",
      "HHHHHHaaaaHHabbv",
      "HHHHHHaHHHHHabbv",
      "HHHHHHaHHHHHabbv",
      "aaaaaaaaaaaaabbv",
      "bbbbbbbbbbbbbbbv",
      "vvvvvvvvvvvvvvvv"
    ],
    [
      "            abbv",
      "efeg  aaaahhabbv",
      "   g  aiiahhabbv",
      "jkjg  almaHHabbv",
      "nnng  o paHHabbv",
      "efeg  ampaHHabbv",
      "   g  ap aHHabbv",
      "jkjg  aqraHHabbv",
      "      a laHHabbv",
      "      a!qaHHabbv",
      "efefesaaaaHHabbv",
      "     saHHHHHabbv",
      "jkjkjsaHHHHHabbv",
      "aaaaaaaaaaaaabbv",
      "bbbbbbbbbbbbbbbv",
      "vvvvvvvvvvvvvvvv"
    ],
    [
      "            abbv",
      "     taaaa  abbv",
      "      a ia  abbv",
      "      a  a  abbv",
      "      u  a  abbv",
      "      a  ahhabbv",
      "      a  ahhabbv",
      "      a  aHHabbv",
      "      a  aHHabbv",
      "      al aHHabbv",
      "      aaaaHHabbv",
      "      aHHHHHabbv",
      "      aHHHHHabbv",
      "aaaaaaaaaaaaabbv",
      "bbbbbbbbbbbbbbbv",
      "vvvvvvvvvvvvvvvv"
    ],
    [
      "      w     abbv",
      "      aaaa  abbv",
      "      a  a  abbv",
      "      a  a  abbv",
      "      x  a  abbv",
      "      a  a  abbv",
      "      a  a  abbv",
      "      a  a  abbv",
      "      al a  abbv",
      "      allahhabbv",
      "      aaaahhabbv",
      "      aHHHHHabbv",
      "      aHHHHHabbv",
      "aaaaaaaaaaaaabbv",
      "bbbbbbbbbbbbbbbv",
      "vvvvvvvvvvvvvvvv"
    ],
    [
      "     ya     abbv",
      "     yaaaa  abbv",
      "yyyyyyaHHa  abbv",
      "     yaHHa  abbv",
      "     yaHHa  abbv",
      "     yaHHa  abbv",
      "     yaHHa  abbv",
      "     yaHHa  abbv",
      "     yaHHa  abbv",
      "     yahha  abbv",
      "     yahha  abbv",
      "     ya     abbv",
      "yyyyyya     abbv",
      "aaaaaaaaaaaaabbv",
      "bbbbbbbbbbbbbbbv",
      "vvvvvvvvvvvvvvvv"
    ],
    [
      "AAAAAAa     abbv",
      "AAAAAAaaaaaaabbv",
      "AAAAAAaHHa  abbv",
      "AAAAAAaHHa  abbv",
      "AAAAAAaHHa  abbv",
      "AAAAAAahha  abbv",
      "AAAAAAahha  abbv",
      "AAAAAAa  a  abbv",
      "AAAAAAa  a  abbv",
      "AAAAAAa  a  abbv",
      "AAAAAAa  a  abbv",
      "AAAAAAa     abbv",
      "AAAAAAa     abbv",
      "aaaaaaaaaaaaabbv",
      "bbbbbbbbbbbbbbbv",
      "vvvvvvvvvvvvvvvv"
    ]
  ]
}