{
  "name": "multi_laboratory1_0_base1",
  "refpalette": "c70cities:multi_laboratory1_0_base1_palette",
  "xsize": 16,
  "zsize": 16,
  "slices": [
    [
      "vvvvvvvvvvvvvvvv",
      "vaaaaaaaaaaaaaaa",
      "vabbbbbbbbbbcccc",
      "vabdddddddde    ",
      "vabdddddddde    ",
      "vabddddddddeeeee",
      "vabddddddddfffff",
      "vabddddddddfffff",
      "vabffffffffeffff",
      "vabd!ddddddfffff",
      "vabddddddddfffff",
      "vabddddddddfffff",
      "vabddddddddfffff",
      "vabddddddddfffff",
      "vabddddddddfffff",
      "vabffffffffeffff"
    ],
    [
      "vvvvvvvvvvvvvvvv",
      "vaaaaaaaaaaaaaaa",
      "vabbbbbbbbbbcccc",
      "vabghghghghi    ",
      "vabg g g g i    ",
      "vabjkjljljliiiii",
      "vab        m  n!",
      "vabooppppooi   q",
      "vabiiiiiiiie   r",
      "vabssttttssi   u",
      "vab        w   u",
      "vab        i   u",
      "vabxyAyAyAyi   u",
      "vab B B B Bi   r",
      "vabCBCBCBCBi    ",
      "vabiiiiiiiie    "
    ],
    [
      "vvvvvvvvvvvvvvvv",
      "vaaaaaaaaaaaaaaa",
      "vabbbbbbbbbbcccc",
      "vabg g g g i    ",
      "vabg g g g i    ",
      "vabjDjEjEjEiiiii",
      "vab        F    ",
      "vabIJJJJJJKi    ",
      "vabiiiiiiiie   L",
      "vabIMMMMMMKi   N",
      "vab        O    ",
      "vab        i   P",
      "vabQyRyRyRyi   S",
      "vab B B B Bi   L",
      "vab B B B Bi    ",
      "vabiiiiiiiie    "
    ],
    [
      "vvvvvvvvvvvvvvvv",
      "vaaaaaaaaaaaaaaa",
      "vabbbbbbbbbbcccc",
      "vabg g g g i    ",
      "vabg g g g i    ",
      "vabjjjjjjjjiiiii",
      "vab        i    ",
      "vab JJJJJJ i    ",
      "vabiiiiiiiie   K",
      "vab MMMMMM i    ",
      "vab        i    ",
      "vab        i   T",
      "vabyyyyyyyyi    ",
      "vab B B B Bi   K",
      "vab B B B Bi    ",
      "vabiiiiiiiie    "
    ],
    [
      "vvvvvvvvvvvvvvvv",
      "vaaaaaaaaaaaaaaa",
      "vabbbbbbbbbbcccc",
      "vabUVUVUVUVi    ",
      "vabUUUUUUUUi    ",
      "vabUUUUUUUUiiiii",
      "vabUUUUUUUUi    ",
      "vabUUUUUUUUi    ",
      "vabiiiiiiiie    ",
      "vabUUUUUUUUi    ",
      "vabUUUUUUUUi    ",
      "vabUUUUUUUUi    ",
      "vabUUUUUUUUi    ",
      "vabUUUUUUUUi    ",
      "vabVUVUVUVUi    ",
      "vabiiiiiiiie    "
    ],
    [
      "vvvvvvvvvvvvvvvv",
      "vaaaaaaaaaaaaaaa",
      "vabbbbbbbbbbcccc",
      "vab W W W WiXXXX",
      "vab W W W WiXXXX",
      "vab W W W Wiiiii",
      "vab W W W WiYYYY",
      "vab WWWWWWWiYYYY",
      "vabiiiiiiiieYYYY",
      "vabWWWWWWWWiYYYY",
      "vabW W W W iYYYY",
      "vabW W W W iYYYY",
      "vabW W W W iYYYY",
      "vabW W W W iYYYY",
      "vabW W W W iYYYY",
      "vabZZZZZZZZe0000"
    ]
  ]
}