{
  "name": "multi_condo1_5_base1",
  "refpalette": "c70cities:multi_condo1_5_base1_palette",
  "xsize": 16,
  "zsize": 16,
  "slices": [
    [
      "HHHHHHHHHHHHabbv",
      "HHHHHHaccaaaabbv",
      "HHHHHHaccaddabbv",
      "HHHHHHa  addabbv",
      "HHHHHHa  a  abbv",
      "HHHHHHa  a  abbv",
      "HHHHHHa  a  abbv",
      "HHHHHHa  a  abbv",
      "HHHHHHa  a  abbv",
      "HHHHHHa  a  abbv",
      "HHHHHHa  a  abbv",
      "HHHHHHa     abbv",
      "HHHHHHa     abbv",
      "aaaaaaaaaaaaabbv",
      "bbbbbbbbbbbbbbbv",
      "vvvvvvvvvvvvvvvv"
    ],
    [
      "            abbv",
      "efeg  a  accabbv",
      "   g  a  accabbv",
      "hihg  a  aHHabbv",
      "jjjg  a  aHHabbv",
      "efeg  a  aHHabbv",
      "   g  a  addabbv",
      "hihg  a  addabbv",
      "      a  a  abbv",
      "      a  a  abbv",
      "efefega  a  abbv",
      "     ga     abbv",
      "hihihga     abbv",
      "aaaaaaaaaaaaabbv",
      "bbbbbbbbbbbbbbbv",
      "vvvvvvvvvvvvvvvv"
    ],
    [
      "            abbv",
      "     ka  a  abbv",
      "      a  a  abbv",
      "      a  a  abbv",
      "      a  a  abbv",
      "      a  accabbv",
      "      a  accabbv",
      "      a  aHHabbv",
      "      a  aHHabbv",
      "      a  aHHabbv",
      "      a  addabbv",
      "      a   ddabbv",
      "      a     abbv",
      "aaaaaaaaaaaaabbv",
      "bbbbbbbbbbbbbbbv",
      "vvvvvvvvvvvvvvvv"
    ],
    [
      "      l     abbv",
      "      a  a  abbv",
      "      a  a  abbv",
      "      a  a  abbv",
      "      a  a  abbv",
      "      a  a  abbv",
      "      a  a  abbv",
      "      a  a  abbv",
      "      adda  abbv",
      "      addaccabbv",
      "      aHHaccabbv",
      "      aHHHHHabbv",
      "      aHHHHHabbv",
      "aaaaaaaaaaaaabbv",
      "bbbbbbbbbbbbbbbv",
      "vvvvvvvvvvvvvvvv"
    ],
    [
      "     ma     abbv",
      "     ma  a  abbv",
      "mmmmm!a  a  abbv",
      "     ma  a  abbv",
      "     madda  abbv",
      "     madda  abbv",
      "     maHHa  abbv",
      "     maHHa  abbv",
      "     maHHa  abbv",
      "     macca  abbv",
      "     macca  abbv",
      "     ma     abbv",
      "mmmmmma     abbv",
      "aaaaaaaaaaaaabbv",
      "bbbbbbbbbbbbbbbv",
      "vvvvvvvvvvvvvvvv"
    ],
    [
      "nnnnnna     abbv",
      "nnnnnnaaaaaaabbv",
      "nnnnnnaHHa  abbv",
      "nnnnnnaHHa  abbv",
      "nnnnnnaHHa  abbv",
      "nnnnnnacca  abbv",
      "nnnnnnacca  abbv",
      "nnnnnna  o  abbv",
      "nnnnnna  o  abbv",
      "nnnnnna     abbv",
      "nnnnnna     abbv",
      "nnnnnna     abbv",
      "nnnnnna     abbv",
      "aaaaaaaaaaaaabbv",
      "bbbbbbbbbbbbbbbv",
      "vvvvvvvvvvvvvvvv"
    ]
  ]
}