{
  "name": "multi_laboratory1_11_base6",
  "refpalette": "c70cities:multi_laboratory1_11_base6_palette",
  "xsize": 16,
  "zsize": 16,
  "slices": [
    [
      "aaaaaaaaaaaaabcv",
      "aaaaaaaaaaaaabcv",
      "aaaaaaaaaaaaabcv",
      "aaaaaaaaaaaaabcv",
      "aaaaaaaaaaaaabcv",
      "aaaaaaaaaaaaabcv",
      "aaaadaaaaaaaabcv",
      "aaaaaaaaaaaaabcv",
      "aaaaaaaaaaaaabcv",
      "aaaaaaaaaaaaabcv",
      "aaaaaaaaaaaaabcv",
      "aaaaaaaaaaaaabcv",
      "eaaaaaaaaaaaabcv",
      "eaaadaaaaaaaabcv",
      "feaaaaaaaaaaabcv",
      " eaaaaaaaaaaabcv"
    ],
    [
      "             gcv",
      "             bcv",
      "            hbcv",
      "            hbcv",
      " i           bcv",
      "jjj       kkkkcv",
      "    d     klmbcv",
      "   nh     kkkkcv",
      "    o        bcv",
      "    o p     hbcv",
      "    on      hbcv",
      "    o        bcv",
      "q   r     kkkkcv",
      "q   d     klmbcv",
      "fq  s     kkkkcv",
      " q  ot       bcv"
    ],
    [
      "             gcv",
      "            ubcv",
      "           wxbcv",
      "           wxbcv",
      "             bcv",
      "yA         qkkcv",
      "    d     qlmbcv",
      "    h      qkkcv",
      "    B       ubcv",
      "    C       xbcv",
      "    D      wEbcv",
      "    F       Ibcv",
      "q          qkkcv",
      "q   d     qlmbcv",
      "fq  F      qkkcv",
      " q  h       ubcv"
    ],
    [
      "             gcv",
      "             bcv",
      "             bcv",
      "             bcv",
      "             bcv",
      "           qkkcv",
      "    d     qlmbcv",
      "    J      qkkcv",
      "             bcv",
      "             bcv",
      "    K        bcv",
      "             bcv",
      "q          qkkcv",
      "q   d     qlmbcv",
      "fq         qkkcv",
      " q           bcv"
    ],
    [
      "     L       gcv",
      "             bcv",
      "            Mbcv",
      "            Mbcv",
      "             bcv",
      "           qkkcv",
      "    d     qlmbcv",
      "           qkkcv",
      "             bcv",
      "            Mbcv",
      "            Mbcv",
      "             bcv",
      "q          qkkcv",
      "q   d     qlmbcv",
      "fq         qkkcv",
      " q           bcv"
    ],
    [
      "             gcv",
      "             bcv",
      "             bcv",
      "            gbcv",
      "             bcv",
      "           qkkcv",
      "    d     qlmbcv",
      "           qkkcv",
      "             bcv",
      "            gbcv",
      "             bcv",
      "             bcv",
      "q          qkkcv",
      "q   d     qlmbcv",
      "fq         qkkcv",
      " q           bcv"
    ]
  ]
}