{
  "name": "multi_megatower1_3_ground",
  "refpalette": "c70cities:multi_megatower1_3_ground_palette",
  "xsize": 16,
  "zsize": 16,
  "slices": [
    [
      "GaGGGGGGaGaGGGGG",
      "GGaaaGaaGGaaaaGa",
      "GGGGaGGGGGGaGGGG",
      "vvvvvvvvvvvvvvvv",
      "vvvvvvvvvvvvvvvv",
      "vvvvvvvvvvvvvvvv",
      "vvvvbvvvvvvbvvvv",
      "vvvvvvvvvvvvvvvv",
      "vvvvvvvvvvvvvvvv",
      "vvvvvvvvvvvvvvvv",
      "vvvvvvvvvvvvvvvv",
      "vvvvvvvvvvvvvvvv",
      "vvvvvvvvvvvvvvvv",
      "vvvvbvvvvvvbvvvv",
      "cdddvvvvvvvvvvvv",
      "c   vvvvvvvvvvvv"
    ],
    [
      "                ",
      "                ",
      "e fe eef ee efe ",
      "gggghgggggghgggg",
      "ijklmnopio qcrrr",
      "so lt on inucrrr",
      "ccccb n o  bcrrr",
      "w x yk   nkAcrrr",
      "w   yBC  D Acrrr",
      "wE  yCFD  k crrr",
      "IIJIy      Acrrr",
      " kKLm      Acrrr",
      " MNMykO    Pcrrr",
      "QQQQbORO  kbcrrr",
      "cdddySO   k!crrr",
      "c   yTOkO kAcrrr"
    ],
    [
      "                ",
      "                ",
      "                ",
      "gggghgggggghgggg",
      "    U   V  Wcrrr",
      "X  kY      Wcrrr",
      "ccccb     Zbcrrr",
      "w 0 y       crrr",
      "w   y1      crrr",
      "w   yk     kcrrr",
      "II2Iy       crrr",
      "  kMU       crrr",
      " 3kLy      kcrrr",
      "QQQQb4Ok   bcrrr",
      "cdddyO5    kcrrr",
      "c   y6      crrr"
    ],
    [
      "                ",
      "                ",
      "    7      7    ",
      "gggghgggggghgggg",
      "   ky   V88brrrr",
      "    y    88brrrr",
      "ccccbbbbbbbbrrrr",
      "w   y    88brrrr",
      "w   y    88brrrr",
      "w   y    88brrrr",
      "IIIIy    88brrrr",
      "   9y    88brrrr",
      "   ky   k88brrrr",
      "QQQQbbbbbbbbrrrr",
      "cdddyk   88brrrr",
      "c   y    88brrrr"
    ],
    [
      "                ",
      "                ",
      "                ",
      "gggghgggggghgggg",
      "  kk@88ccrrrr   ",
      " k k@88ccrrrr   ",
      "ccccb88ccrrrr   ",
      "    @88ccrrrr   ",
      "    @88ccrrrr   ",
      "    @88ccrrrr   ",
      "####@88ccrrrr   ",
      "   k@88ccrrrr   ",
      "  kk@88ccrrrr   ",
      "QQQQb88ccrrbr   ",
      "cddd@88ccrrrr   ",
      "c   @88ccrrrr   "
    ],
    [
      "                ",
      "                ",
      "                ",
      "gggghggggggh$$  ",
      "8888brrrr  %    ",
      "8888brrrr       ",
      "bbbbbrrrr       ",
      "ccccbrrrr       ",
      "ccccbrrrr       ",
      "ccccbrrrr       ",
      "ccccbrrrr       ",
      "8888brrrr       ",
      "8888brrrr       ",
      "bbbbbrrrr  ^    ",
      "bdddbrrrr       ",
      "b   brrrr       "
    ]
  ]
}