{
  "name": "multi_militarybase_4_base3",
  "refpalette": "c70cities:multi_militarybase_4_base3_palette",
  "xsize": 16,
  "zsize": 16,
  "slices": [
    [
      "vvvvvvvvvvvvvvvv",
      " vaaaaaaavaaaavv",
      " baaaaaaabaaaavv",
      " baaaaaaabaaaavv",
      " baaaaaaabaaaavv",
      " vbbbbbbbvbbbvvv",
      " bcccaaaabaaaavv",
      " bcccaaaabaaaavv",
      " bcccaaaabaaaavv",
      " vdccaaaabaaaavv",
      " bcccaaaabaaaavv",
      " bcccaaaabaaaavv",
      " bcccaaaabaaaavv",
      " vbbbbbbbvbbbvvv",
      " bcccaaaaaaaaavv",
      " bcccaaaaaaaaavv"
    ],
    [
      "vvvvvvvvvvvvvvvv",
      " ve fgh eviiiivv",
      " j      klimnivv",
      " j  ooo plqmnivv",
      " j      rli sivv",
      " v       vltlvvv",
      " j       uw wwvv",
      " j       u    vv",
      " j           wvv",
      " vd           vv",
      " j           wvv",
      " j       u  wwvv",
      " j       u!wwwvv",
      " v       vlllvvv",
      " j   xyx AyA Bvv",
      " j           !vv"
    ],
    [
      "vvvvvvvvvvvvvvvv",
      " ve     evisssvv",
      "         lq  ivv",
      "         lq  qvv",
      "         li  ivv",
      " v       vlClvvv",
      "         u  wDvv",
      "         u    vv",
      "              vv",
      " vd           vv",
      "             wvv",
      "         u   Evv",
      "         u  wwvv",
      " v       vlllvvv",
      "              vv",
      "              vv"
    ],
    [
      "vvvvvvvvvvvvvvvv",
      " v       vi qivv",
      "         l   svv",
      "         lq   vv",
      "         l   svv",
      " v       vlllvvv",
      "         u    vv",
      "         u    vv",
      "         u    vv",
      " vd      u    vv",
      "         u    vv",
      "         u    vv",
      "         u    vv",
      " v       vlllvvv",
      "             Fvv",
      "              vv"
    ],
    [
      "vvvvvvvvvvvvvvvv",
      " v       vq  svv",
      " I       l    vv",
      " I       l    vv",
      " I       l    vv",
      " vjjjjjjjvlllvvv",
      " I       j    vv",
      " I       j    vv",
      " I       j    vv",
      " vd      j    vv",
      " I       j    vv",
      " I       j    vv",
      " I       j    vv",
      "Iv       vlllvvv",
      " I            vv",
      " I            vv"
    ],
    [
      "vvvvvvvvvvvvvvvv",
      "JvJJJJJJJvJJJJvv",
      "KbKKKKKKKbKKKJvv",
      "KbKKKKKKKbKKKJvv",
      "KbKKKKKKKbKKKJvv",
      "Kvbbbbbbbvbbbvvv",
      "KbKKKKKKKbKKKJvv",
      "KbKKKKKKKbKKKJvv",
      "KbKKKKKKKbKKKJvv",
      "KvdKKKKKKbKKKJvv",
      "KbKKKKKKKbKKKJvv",
      "KbKKKKKKKbKKKJvv",
      "KbKKKKKKKbKKKJvv",
      "Lvbbbbbbbvbbbvvv",
      " LKKKKKKKKKKKJvv",
      " LKKKKKKKKKKKJvv"
    ]
  ]
}