{
  "name": "multi_condo1_3_floor5",
  "refpalette": "c70cities:multi_condo1_3_floor5_palette",
  "xsize": 16,
  "zsize": 16,
  "slices": [
    [
      "                ",
      "      a         ",
      "bbbbbbacccccccc ",
      "deeeeeafffffffc ",
      "ddgggddddddddfc ",
      "hhhhhhhhhhhhdfc ",
      "hhhhhhhhhhhhdfc ",
      "hhhhhhhhhhhhdfc ",
      "hhhhhhhhhhhhdfc ",
      "hhhhhhhhhhhhdfc ",
      "hhhhhhhhhhhhdfc ",
      "hiiihhhhhhhhdfc ",
      "hiiihhhhhhhhdfc ",
      "hiiihhhhhhhhdaaa",
      "jjjjjjjhhiiide  ",
      "kkkkkljhhiiide  "
    ],
    [
      "                ",
      "      a         ",
      "bbbbbba         ",
      "d     afffffff  ",
      "ddm mdddnnnddf  ",
      "op  qro  !stdf  ",
      "ou  qro     df  ",
      "o ww xo qr  df  ",
      "oooo yo qrwwdf  ",
      "oA B Co xooodf  ",
      "oD o Eo  F Adf  ",
      "ooIo Jo yo Ddf  ",
      "oK B Lo Co Mdf  ",
      "oN o Lo Eo Odaaa",
      "ddddPdd JoQod   ",
      "      R  F  S   "
    ],
    [
      "                ",
      "      a         ",
      "      a         ",
      "d     a         ",
      "ddm mdddmmmdd   ",
      "o     o     d   ",
      "o    To     d   ",
      "o UV Wo  T  d   ",
      "oooo Xo   Y d   ",
      "oZ 0 1o Woood   ",
      "o2 o  o  3  d   ",
      "oo4o 5o Xo  d   ",
      "o  0  o 1o  d   ",
      "o 6o7 o  o 8daaa",
      "dddd9dd @o#od   ",
      "      $  3 %b   "
    ],
    [
      "                ",
      "      a         ",
      "      a         ",
      "d     a         ",
      "ddmmmdddmmmdd   ",
      "o     o     d   ",
      "o     o     d   ",
      "o     o     d   ",
      "oooo  o     d   ",
      "o! o  o  oood   ",
      "o^ o  o  o  d   ",
      "oooo  o  o  d   ",
      "o  o  o  o  d   ",
      "o &o  o  o  daaa",
      "dddd*dd  oood   ",
      "      (  o )b   "
    ],
    [
      "                ",
      "      a         ",
      "      a         ",
      "d     a+++++++  ",
      "ddddddddddddd+  ",
      "o     o     d+  ",
      "o     o     d+  ",
      "o     o     d+  ",
      "oooo  o     d+  ",
      "o  o  o  oood+  ",
      "o  o  o  o  d+  ",
      "oooo  o  o  d+  ",
      "o  o  o  o  d+  ",
      "o  o  o  o  daaa",
      "ddddddd  oood   ",
      "      d  o  d   "
    ],
    [
      "                ",
      "      a         ",
      "------a         ",
      "d     a[[[[[[[  ",
      "ddddddddddddd[  ",
      "]]]]]]]]]]]]d[  ",
      "]]]]]]]]]]]]d[  ",
      "]]]]]]]]]]]]d[  ",
      "]]]]]]]]]]]]d[  ",
      "]]]]]]]]]]]]d[  ",
      "]]]]]]]]]]]]d[  ",
      "]]]]]]]]]]]]d[  ",
      "]]]]]]]]]]]]d[  ",
      "]]]]]]]]]]]]daaa",
      "ddddddd]]]]]d   ",
      "      d]]]]]d   "
    ]
  ]
}