{
  "name": "multi_flatapartment_0_floor1",
  "refpalette": "c70cities:multi_flatapartment_0_floor1_palette",
  "xsize": 16,
  "zsize": 16,
  "slices": [
    [
      "                ",
      "     abbbbabbbab",
      "     bcccccccccc",
      "     bcddddddddd",
      "     bcddddddddd",
      "     acddddddddd",
      "     bcddddddddd",
      "     bcddddddddd",
      "     bcddddddddd",
      "     bcddddddddd",
      "     acddddddddd",
      "     bcddddddddd",
      "     bcddddddddd",
      "     bcccccccccc",
      "     abbbbabbbab",
      "                "
    ],
    [
      "                ",
      "     abeebabebab",
      "     b    f     ",
      "     e   gh iih ",
      "     b jk h   hl",
      "     ahhhmh   hh",
      "     bn   o pphq",
      "     e    hhhhhq",
      "     e rr hs  t ",
      "     b uuwhxy h ",
      "     ahhhhhxy h ",
      "     bA   B   h ",
      "     e   ghhhhh ",
      "     b    f     ",
      "     abeebabebab",
      "                "
    ],
    [
      "                ",
      "     abCCbabCbab",
      "     bD   E     ",
      "     C    h   h ",
      "     bF   h   h ",
      "     ahhhIh   hh",
      "     b    J KKh ",
      "     C    hhhhh ",
      "     C    h!  L ",
      "     b    h   h ",
      "     ahhhhh   h ",
      "     b  M N   h ",
      "     C    hhhhh ",
      "     bD   E     ",
      "     abCCbabCbab",
      "                "
    ],
    [
      "                ",
      "     abCCbabCbab",
      "     bO   h     ",
      "     C    h   h ",
      "     b    h   h ",
      "     ahhhhh   hh",
      "     b    h KKh ",
      "     C    hhhhh ",
      "     C    h   h ",
      "     b    h   h ",
      "     ahhhhh   h ",
      "     b    h   h ",
      "     C    hhhhh ",
      "     bO   h     ",
      "     abCCbabCbab",
      "                "
    ],
    [
      "                ",
      "     abbbbabbbab",
      "     bPPPPh   h ",
      "     bPPPPh   h ",
      "     bPPPPh Q h ",
      "     ahhhhh   hh",
      "     b    h   h ",
      "     b    hhhhh ",
      "     b    h   h ",
      "     b    h   h ",
      "     ahhhhh   hh",
      "     bPPPPh   h ",
      "     bPPPPhhhhh ",
      "     bPPPPh   h ",
      "     abbbbabbbab",
      "                "
    ],
    [
      "                ",
      "     RSSSSRSSSRS",
      "     Scccccccccc",
      "     Scddddddddd",
      "     Scddddddddd",
      "     Rcddddddddd",
      "     Scddddddddd",
      "     Scddddddddd",
      "     Scddddddddd",
      "     Scddddddddd",
      "     Rcddddddddd",
      "     Scddddddddd",
      "     Scddddddddd",
      "     Scccccccccc",
      "     RSSSSRSSSRS",
      "                "
    ]
  ]
}