{
  "name": "multi_megatower1_4_floor4",
  "refpalette": "c70cities:multi_megatower1_4_floor4_palette",
  "xsize": 16,
  "zsize": 16,
  "slices": [
    [
      "a   bbbbbbbbbbbb",
      "a   bbbbbbbbbbbb",
      "a   bbbbbbbbbbbb",
      "cdeebbbbbbbbbbbb",
      "bbbbfbbbbbbfbbbb",
      "bbbbbbbbbbbbbbbb",
      "gggggggggggggggg",
      "gggggggggggggggg",
      "gggggggggggggggg",
      "gggggggggggggggg",
      "bbbbbbbbbbbbbbbb",
      "bbbbfbbbbbbfbbbb",
      "bbbbbbbbbbbbbbbb",
      "bbbbbbbbbbbbbbbb",
      "bbbbbbbbbbbbbbbb",
      "bbbbbbbbbbbbbbbb"
    ],
    [
      "a   ah  ijklmn  ",
      "a   aoi  iplp   ",
      "a   aqq rqqlqqsi",
      "aettauw r xly s ",
      "ABCDfEF I rfs J ",
      "     KF rLrMsLs ",
      "     NNONNN NNNP",
      "                ",
      "                ",
      "QRQQ QQSQQQ QQQR",
      "s TUMKF rVrMsWs ",
      "J TEfEF X rfs Y ",
      "siwuluw r xlZ s ",
      "si00l00 r00l00si",
      "   1lo    plpi i",
      " ii2lh   jklmn  "
    ],
    [
      "a   a      l    ",
      "a   a     3l4   ",
      "a   aqq rqqlqqs ",
      "ae  a   r5 l 6s ",
      "A 78f9F @ rfs # ",
      "     KF r rMs s ",
      "     NN$NNN NNN%",
      "                ",
      "                ",
      "Q^QQ QQ&QQQ QQQ^",
      "s TUMKF r rMs s ",
      "# T9f9F * rfs ( ",
      "s  !l   r5 l) s ",
      "s 00l00 r00l00s ",
      "    l     +l-   ",
      "    l      l    "
    ],
    [
      "a   a      l    ",
      "a   a      l    ",
      "a   aqq rqqlqqs ",
      "aeeea   r[ l ]s ",
      "A{  fK  r rfs s ",
      "     K} r rMs s ",
      "     NN\\NNN NNN\\",
      "                ",
      "                ",
      "Q|QQ QQ|QQQ QQQ|",
      "s  UMK  r rMs s ",
      "s  UfK  r rfs s ",
      "s  }l}  r[ l  s ",
      "s 00l00 r00l00s ",
      "    l      l    ",
      "    l      l    "
    ],
    [
      "a   a      l    ",
      "a   a}     l}   ",
      "a   aqq rqqlqqs ",
      "aeeea   r }l `s ",
      "AAAAfK  r rfs s}",
      "     K} r r:s s ",
      "     NNNNNN;NNNN",
      "                ",
      "                ",
      "QQQQ'QQQQQQ'QQQQ",
      "s }U:K  r}r!s s ",
      "s  UfK  r rfs s ",
      "s }}l}  r }l} s ",
      "s 00l00 r00l00s ",
      "    l      l    ",
      "    l      l    "
    ],
    [
      ",   ,}     ,    ",
      ",   ,}     ,    ",
      ",   ,bbbbbb,bbbb",
      ",e./,bbbbbb,bbbb",
      "<<<<f<<<<<<f<<<<",
      ">>>>,bbbbbb,bbbb",
      ">>>>,??????,????",
      ">>>>,>>>>>>,>>>>",
      ">>>>,>>>>>>,>>>>",
      "\u00a3\u00a3\u00a3\u00a3,\u00a3\u00a3\u00a3\u00a3\u00a3\u00a3,\u00a3\u00a3\u00a3\u00a3",
      "bbbb,bbbbbb,bbbb",
      "<<<<f<<<<<<f<<<<",
      "bbbb,bbbbbb,bbbb",
      "bbbb,bbbbbb,bbbb",
      "   },      ,    ",
      "    ,      ,    "
    ]
  ]
}