{
  "name": "multi_clubhouse1_7_base2",
  "refpalette": "c70cities:multi_clubhouse1_7_base2_palette",
  "xsize": 16,
  "zsize": 16,
  "slices": [
    [
      "vvvvvvvvvvvvvvvv",
      "vvvvvvvvvvvvvvvv",
      "vvvvvvvvvvvvvvvv",
      "vvvvvvvvvvvvvvvv",
      "vvvvvvvvvvvvvvvv",
      "vvvvvvvvvvvvvvvv",
      "vvvvvvvvvvvvvvvv",
      "vvvvvvvvvvvvvvvv",
      "vvvvvvvvvvvvvvvv",
      "vvvvvvvvvvvvvvvv",
      "vvvvvvvvvvvvvvvv",
      "vvvvvvvvvvvvvvvv",
      "vvvvvvvvvvvvvvvv",
      "vvvvvvvvvvvvvvvv",
      "vvvvvvvvvvvvvvvv",
      "vvvvvvvvvvvvvvvv"
    ],
    [
      "aaaaaaaaaaaaaaav",
      "aaaaaaaaaaaaaaav",
      "aaaaaaaaaaaaaaav",
      "aaaaaaaaaaaaaaav",
      "aaaaaaaaaaaaaaav",
      "aaaaaaaaaaaaaabv",
      "aaaaaaaaaaaaaabv",
      "ccccccccccccccbv",
      "ccccccccccdccGbv",
      "cccccccccccdcGbv",
      "ccccccccccGccGbv",
      "cceccccccedGc!fv",
      "cccccccccccdcGbv",
      "GcccccccccddcGbv",
      "GcccccccccdGcGbv",
      "GcccccccccddcGbv"
    ],
    [
      "aaaaaaaaaaaaaaav",
      "aaaaaaaaaaaaaaav",
      "aaaaaaaaaaaaaaav",
      "aaaaaaaaaaaaaaav",
      "cceccccccecccgfv",
      "ccccccccccddcchv",
      "cccccccccccdcchv",
      "i  ii cccccccchv",
      "   ii      ijkhv",
      "i   ii i    lmhv",
      "  i         jnhv",
      "  e    i e  o fv",
      "pp i ii   i lkhv",
      "qp     i    jkhv",
      "np ii i     lnhv",
      "mp      i   jkhv"
    ],
    [
      "aaaaaaaaaaacdabv",
      "ccccccccccccadbv",
      "ccccccccccccdcbv",
      "cccccccccccdccbv",
      "ccecccccceccc fv",
      "   i  ii    okhv",
      "     i i    lnhv",
      "            jrhv",
      "             shv",
      "              tv",
      "             uhv",
      "  e      e    fv",
      "             shv",
      "w            stv",
      "u            uhv",
      "             shv"
    ],
    [
      "ccccccccccc   hv",
      "ccccccccc     hv",
      "ccccc         hv",
      "              hv",
      "  e      e    fv",
      "             shv",
      "             uhv",
      "              hv",
      "              hv",
      "              tv",
      "              hv",
      "  e      e    fv",
      "              hv",
      "              tv",
      "              hv",
      "              hv"
    ],
    [
      "cccccc        tv",
      "              hv",
      "              tv",
      "              hv",
      "  e      e    fv",
      "              tv",
      "              tv",
      "              hv",
      "               v",
      "              tv",
      "              tv",
      "  e      e    fv",
      "               v",
      "              tv",
      "              hv",
      "               v"
    ]
  ]
}