{
  "name": "multi_militarybase_2_base3",
  "refpalette": "c70cities:multi_militarybase_2_base3_palette",
  "xsize": 16,
  "zsize": 16,
  "slices": [
    [
      "vvvvvvvvvvvvvvvv",
      "abaaaaaaaaacaca ",
      "                ",
      "                ",
      "                ",
      "                ",
      "                ",
      "                ",
      "                ",
      "                ",
      "                ",
      "def  ee gee def ",
      "                ",
      "  v    v    v   ",
      "hhh hhh hhh hhh ",
      " i   i  i    i  "
    ],
    [
      "vvvvvvvvvvvvvvvv",
      "baaabaacbaaaaaa ",
      "                ",
      "                ",
      "                ",
      "                ",
      "                ",
      "                ",
      "                ",
      "                ",
      "                ",
      "                ",
      "                ",
      "  v    v    v   ",
      "fee jef eef eej ",
      "                "
    ],
    [
      "vvvvvvvvvvvvvvvv",
      "acbaaaaaaaaacac ",
      "                ",
      "                ",
      "                ",
      "                ",
      "                ",
      "                ",
      "                ",
      "                ",
      "                ",
      "                ",
      "                ",
      "  v    v    v   ",
      "                ",
      "                "
    ],
    [
      "vvvvvvvvvvvvvvvv",
      "aaaaabbaaaaaaaa ",
      "                ",
      "                ",
      "                ",
      "                ",
      "                ",
      "                ",
      "                ",
      "                ",
      "                ",
      "                ",
      "                ",
      "  v    v    v   ",
      "                ",
      "                "
    ],
    [
      "vvvvvvvvvvvvvvvv",
      "                ",
      "                ",
      "                ",
      "                ",
      "                ",
      "                ",
      "                ",
      "                ",
      "                ",
      "                ",
      "                ",
      "                ",
      "kkvkkkkvkkkkvkkk",
      "                ",
      "                "
    ],
    [
      "vvvvvvvvvvvvvvvv",
      "llllllllllllllll",
      "mmmmmmmmmmmmmmmm",
      "nnnnnnmmmnnnnnnn",
      "mmmmmmmmmmmmmmmm",
      "mmmmmmmmmmmmmmmm",
      "mmmmmmmmmmmmmmmm",
      "nnnnnnmmmnnnnnnn",
      "mmmmmmmmmmmmmmmm",
      "mmmmmmmmmmmmmmmm",
      "mmmmmmmmmmmmmmmm",
      "nnnnnnmmmnnnnnnn",
      "mmmmmmmmmmmmmmmm",
      "oovoooovoooovooo",
      "                ",
      "                "
    ]
  ]
}