{
  "name": "multi_militarybase_4_base4",
  "refpalette": "c70cities:multi_militarybase_4_base4_palette",
  "xsize": 16,
  "zsize": 16,
  "slices": [
    [
      "vvvvvvvvvvvvvvvv",
      "avaaaaaaavaaaavv",
      "abaaaaaaabaaaavv",
      "abaaaaaaabaaaavv",
      "abaaaaaaabaaaavv",
      "bvbbbbbbbvbbbvvv",
      "abaaaaaaabaaaavv",
      "abaaaaaaabaaaavv",
      "abaaaaaaabaaaavv",
      "avaaaaaaabaaaavv",
      "abaaaaaaabaaaavv",
      "abaaaaaaabaaaavv",
      "abaaaaaaabaaaavv",
      "bvbbbbbbbbbbbvvv",
      "cbddddddddddddvv",
      "cbddddddddddddvv"
    ],
    [
      "vvvvvvvvvvvvvvvv",
      "evfffffffvghghvv",
      "eijklmnlop   qvv",
      "ei       r   hvv",
      "ei       p   qvv",
      "ev       vsssvvv",
      "ei          tfvv",
      "ei          ufvv",
      "wi  xyx     nfvv",
      "wvA yBy     Cfvv",
      " i  xyx     nfvv",
      " D          Efvv",
      " i          Ffvv",
      "ev           vvv",
      "I             vv",
      "              vv"
    ],
    [
      "vvvvvvvvvvvvvvvv",
      "JvKnLnlMKv N !vv",
      " i       p    vv",
      " i       O   Pvv",
      "Qi       p    vv",
      "ev       vsssvvv",
      "ei           Evv",
      "ei           Rvv",
      "wi  SSS      Tvv",
      " vA SUS      nvv",
      " i  SSS      Tvv",
      " D           Vvv",
      " i           Evv",
      "ev           vvv",
      "n             vv",
      "             Wvv"
    ],
    [
      "vvvvvvvvvvvvvvvv",
      " v       v    vv",
      " i       p    vv",
      " i       p    vv",
      " i       p    vv",
      " v       vsssvvv",
      " i            vv",
      "Qi            vv",
      "ei            vv",
      "evA           vv",
      "Xi            vv",
      " i            vv",
      "Yi            vv",
      "ev           vvv",
      "              vv",
      "              vv"
    ],
    [
      "vvvvvvvvvvvvvvvv",
      " v       v    vv",
      " i       p    vv",
      " i       p    vv",
      " i       p    vv",
      " vZZZZZZZvsssvvv",
      " i       Z    vv",
      " i       Z    vv",
      " i       Z    vv",
      " vA      Z    vv",
      "Qi       Z    vv",
      "ei       Z    vv",
      "ei       Z    vv",
      "evZZZZZZZZZZZvvv",
      "              vv",
      "              vv"
    ],
    [
      "vvvvvvvvvvvvvvvv",
      " v0000000v0000vv",
      " 10000000b0000vv",
      " 10000000b0000vv",
      " 10000000b0000vv",
      " vbbbbbbbbbbbvvv",
      " 10000000b0000vv",
      " 10000000b0000vv",
      " 10000000b0000vv",
      " vA000000b0000vv",
      " 10000000b0000vv",
      " 10000000b0000vv",
      " 10000000b0000vv",
      "Qvbbbbbbbbbbbvvv",
      "X1000000000000vv",
      "21000000000000vv"
    ]
  ]
}