{
  "name": "multi_hospital_3_base2",
  "refpalette": "c70cities:multi_hospital_3_base2_palette",
  "xsize": 16,
  "zsize": 16,
  "slices": [
    [
      "vvvvvvvvvvvvvvvv",
      "vvvvvvvvvvvvvvvv",
      "vvvvvvvvvvvvvvvv",
      "vvvvvvvvvvvvvvvv",
      "vvvvvvvvvvvvvvvv",
      "vvvvvvvvvvvvvvvv",
      "vvvvvvvvvvvvvvvv",
      "vvvvvvvvvvvvvvvv",
      "vvvvvvvvvvvvvvvv",
      "vvvvvvvvvvvvvvvv",
      "vvvvvvvvvvvvvvvv",
      "vvvvvvvvvvvvvvvv",
      "vvvvvvvvvvvvvvvv",
      "vvvvvvvvvvvvvvvv",
      "vvvvvvvvvvvvvvvv",
      "vvvvvvvvvvvvvvvv"
    ],
    [
      "abv  cvdcccccccv",
      "abv  cvdcccccccv",
      "abvvvvvdcccccccv",
      "abve evdcccccccv",
      "abv  evdcccccccv",
      "abve  vdcccccccv",
      "abve  vdcccccccv",
      "abv   vdcccccccv",
      "abve evdcccccccv",
      "abvvvvvdcccccccv",
      "ddddddddcccccccv",
      "cccccccccccccccv",
      "cccccccccccccccv",
      "cccccccccccccccv",
      "cccccccccccccccv",
      "vvvvvvvvvvvvvvvv"
    ],
    [
      " f   ggdcccccccv",
      " f   g dcccccccv",
      " b  g  dcccccccv",
      " f   h dcccccccv",
      " f   h dcccccccv",
      " f     dcccccccv",
      " f h   dcccccccv",
      " f     dcccccccv",
      " f   h dcccccccv",
      "db     dcccccccv",
      "ddddddddcccccccv",
      "cccccccccccccccv",
      "cccccccccccccccv",
      "cccccccccccccccv",
      "cccccccccccccccv",
      "vvvvvvvvvvvvvvvv"
    ],
    [
      " f     dcccccccv",
      " f     dcccccccv",
      " b     dcccccccv",
      " f     dcccccccv",
      " f     dcccccccv",
      " f     dcccccccv",
      " f     dcccccccv",
      " f     dcccccccv",
      " f     dcccccccv",
      "db     dcccccccv",
      "ddddddddcccccccv",
      "cccccccccccccccv",
      "cccccccccccccccv",
      "cccccccccccccccv",
      "cccccccccccccccv",
      "vvvvvvvvvvvvvvvv"
    ],
    [
      " f     dcccccccv",
      " f     dcccccccv",
      " b     icccccccv",
      " f     dcccccccv",
      " f     dcccccccv",
      " f     dcccccccv",
      " f     dcccccccv",
      " f     dcccccccv",
      " f     dcccccccv",
      "db     dcccccccv",
      "ddddddddcccccccv",
      "cccccccccccccccv",
      "cccccccccccccccv",
      "cccccccccccccccv",
      "cccccccccccccccv",
      "vvvvvvvvvvvvvvvv"
    ],
    [
      "dbjjjjjdcccccccv",
      "dbjjjjjdcccccccv",
      "dbjjjjjdcccccccv",
      "dbjjjjjdcccccccv",
      "dbjjjjjdcccccccv",
      "dbjjjjjdcccccccv",
      "dbjjjjjdcccccccv",
      "dbjjjjjdcccccccv",
      "dbjjjjjdcccccccv",
      "dbjjjjjdcccccccv",
      "ddddddddcccccccv",
      "cccccccccccccccv",
      "cccccccccccccccv",
      "cccccccccccccccv",
      "cccccccccccccccv",
      "vvvvvvvvvvvvvvvv"
    ]
  ]
}