{
  "name": "multi_residential2_0_floor1",
  "refpalette": "c70cities:multi_residential2_0_floor1_palette",
  "xsize": 16,
  "zsize": 16,
  "slices": [
    [
      "                ",
      "                ",
      "                ",
      "                ",
      "                ",
      " aaaaaaaaaaaaaa ",
      " bc   de fge cb ",
      "  c   d      c  ",
      "  h          h  ",
      "  h          h  ",
      "  ci        ic  ",
      " jjkllmlddllkjj ",
      " nnnno    pnnnn ",
      "     q    r     ",
      "     q    r     ",
      "     q    r     "
    ],
    [
      "                ",
      "                ",
      "                ",
      "                ",
      "                ",
      "                ",
      " aaaaaaaaaaaaaa ",
      " bc   d      cb ",
      "  c          c  ",
      "  c          c  ",
      " jci        icj ",
      " nnnnnollpnnnnn ",
      "      q  r      ",
      "      q  r      ",
      "      q  r      ",
      "      q  r      "
    ],
    [
      "                ",
      "                ",
      "                ",
      "                ",
      "                ",
      "                ",
      "                ",
      " aaaaaaaaaaaaaa ",
      " bcs        tcb ",
      " jcs         cj ",
      " nnnnnnopnnnnnn ",
      "       qr       ",
      "       qr       ",
      "       qr       ",
      "       qr       ",
      "       qr       "
    ],
    [
      "                ",
      "                ",
      "                ",
      "                ",
      "                ",
      "                ",
      "                ",
      "                ",
      " aaaaaaaaaaaaaa ",
      " nnnnnnnnnnnnnn ",
      "                ",
      "                ",
      "                ",
      "                ",
      "                ",
      "                "
    ],
    [
      "                ",
      "                ",
      "                ",
      "                ",
      "                ",
      "                ",
      "                ",
      "                ",
      "       ~        ",
      "       ~        ",
      "                ",
      "                ",
      "                ",
      "                ",
      "                ",
      "                "
    ],
    [
      "                ",
      "                ",
      "                ",
      "                ",
      "                ",
      "                ",
      "                ",
      "                ",
      "                ",
      "       ~        ",
      "                ",
      "                ",
      "                ",
      "                ",
      "                ",
      "                "
    ]
  ]
}