{
  "name": "multi_laboratory1_13_base2",
  "refpalette": "c70cities:multi_laboratory1_13_base2_palette",
  "xsize": 16,
  "zsize": 16,
  "slices": [
    [
      "aaaaaaaaaaaaabcv",
      "aaaaaaaaaaaaabcv",
      "aaaadaaaaaaaabcv",
      "aaaaaaaaaaaaabcv",
      "aaaaaaaaaaaaabcv",
      "aaaaaaaaaaaaabcv",
      "aaaaaaaaaaaaabcv",
      "aaaaaaaaaaaaabcv",
      "aaaaaeeeeeeeebcv",
      "aaaadaaaaaaaabcv",
      "aaaaaaaaaaaaabcv",
      "aaaaaaaaaaaaabcv",
      "aaaaaaaaaaaaabcv",
      "aaaaaaaaaaaaabcv",
      "aaaaaaaaaaaaabcv",
      "aaaaaaaaaaaaabcv"
    ],
    [
      " f  g  h  ijfbcv",
      "kf  lm   jn fbcv",
      " f  dop hh jqbcv",
      " f  lr      qbcv",
      "sf  lr i hn fbcv",
      "    l h  j jfbcv",
      "    l      sfbcv",
      "    l       fbcv",
      "    l       tbcv",
      "lllldu  ww  ubcv",
      "   xlu yyyy ubcv",
      "    luAyBByCubcv",
      "    luAyDDyCubcv",
      "EE  lu yyyy ubcv",
      "F   lu  II  ubcv",
      "J   luuuuuuuubcv"
    ],
    [
      "    g        bcv",
      " K  lm      Lbcv",
      "    doM      bcv",
      "    l        bcv",
      " K  N       Lbcv",
      "    N       Kbcv",
      "    N       Kbcv",
      "    N       Lbcv",
      "    l        bcv",
      "NNNldu      ubcv",
      "    lu  OO  ubcv",
      "    Pu O  O ubcv",
      "    PQQORDOQQbcv",
      " S  Pu  OO  ubcv",
      "    Pu      ubcv",
      "    lu!uuuuuubcv"
    ],
    [
      "    g        bcv",
      "    l        bcv",
      "    dT       bcv",
      "    l        bcv",
      "    N        bcv",
      "    N        bcv",
      "    N        bcv",
      "    N        bcv",
      "    lU      Ubcv",
      "NNNldu      ubcv",
      "    lu  OO  ubcv",
      "    Vu O  O ubcv",
      "    Vu OW O ubcv",
      "    Vu  OOQ ubcv",
      "    Vu  Q X ubcv",
      "    luuuQuuuubcv"
    ],
    [
      "    l        bcv",
      "    l        bcv",
      "    dT       bcv",
      "    l       Ybcv",
      "    l        bcv",
      "    l        bcv",
      "    l        bcv",
      "    l        bcv",
      "    l        bcv",
      "lllldu      ubcv",
      "    lu  OO  ubcv",
      "    lu O  O ubcv",
      "    lu OWDO ubcv",
      "    lu  OO  ubcv",
      "    lu    ZQQbcv",
      "    luuuuuuuubcv"
    ],
    [
      "00 01T232242Tbcv",
      "00001T232242Tbcv",
      "0000dT222222Tbcv",
      "00001T222222Tbcv",
      "00301T242242Tbcv",
      "00301T232232Tbcv",
      "00301T232232Tbcv",
      "00301T232252Tbcv",
      "00001T222222Tbcv",
      "6666du      ubcv",
      "22221u  OO  ubcv",
      "22221u O DO ubcv",
      "22221u OBBO ubcv",
      "33221u  OO  ubcv",
      "23221u      ubcv",
      "25221uuuuuuuubcv"
    ]
  ]
}