{
  "name": "multi_megatower1_3_floor7",
  "refpalette": "c70cities:multi_megatower1_3_floor7_palette",
  "xsize": 16,
  "zsize": 16,
  "slices": [
    [
      "                ",
      "                ",
      "                ",
      "                ",
      "                ",
      "                ",
      "                ",
      "                ",
      "                ",
      "                ",
      "                ",
      "  a b c  a bcc  ",
      "ddddeddddddedddd",
      "ffffgffffffgffff",
      "hiiiffffffffjjjj",
      "h   ffffffffjjjj"
    ],
    [
      "                ",
      "                ",
      "                ",
      "                ",
      "                ",
      "                ",
      "                ",
      "                ",
      "                ",
      "                ",
      "                ",
      "  a b c  a b c  ",
      "    e      e    ",
      "klmngoooooogoooo",
      "hiiipqrs  t   u ",
      "h   pwxxx t     "
    ],
    [
      "                ",
      "                ",
      "                ",
      "                ",
      "                ",
      "                ",
      "                ",
      "                ",
      "                ",
      "                ",
      "                ",
      "  a b c  a b c  ",
      "    e      e    ",
      "k   g      g    ",
      "hiiipy   t      ",
      "h   p    t      "
    ],
    [
      "                ",
      "                ",
      "                ",
      "                ",
      "                ",
      "                ",
      "                ",
      "                ",
      "                ",
      "                ",
      "                ",
      "  a b c  a b c  ",
      "    e      e    ",
      "k   g      g    ",
      "hiiipy  t       ",
      "h   p   t       "
    ],
    [
      "                ",
      "                ",
      "                ",
      "                ",
      "                ",
      "                ",
      "                ",
      "                ",
      "                ",
      "                ",
      "                ",
      "  a b c  a b c  ",
      "    e      e    ",
      "k   goooooogoooo",
      "hiiipAAt        ",
      "h   pAAt        "
    ],
    [
      "                ",
      "                ",
      "                ",
      "                ",
      "                ",
      "                ",
      "                ",
      "                ",
      "                ",
      "                ",
      "                ",
      "  a b c  a b c  ",
      "    e      e    ",
      "BBBBgBBBBBBgBBBB",
      "CDDDC      C    ",
      "C   C      C    "
    ]
  ]
}