{
  "name": "multi_condo1_1_floor1",
  "refpalette": "c70cities:multi_condo1_1_floor1_palette",
  "xsize": 16,
  "zsize": 16,
  "slices": [
    [
      "   abccccccdeeee",
      "  ffgggggggdehii",
      "   ajkkkkkgdej  ",
      "   ajggggggdej  ",
      "   ajlllllgdej  ",
      "   ajlllllgdej  ",
      "   ajlllllgdej  ",
      "   ajlllllgdej  ",
      "   ajlllllgdej  ",
      "   ajlllllgdej  ",
      "   ajlllllgdej  ",
      "   ajlllllgdej  ",
      "   ajggggggdej  ",
      "   ajkkkkkgdej  ",
      "  ffgggggggdemnn",
      "   abccccccdeeee"
    ],
    [
      "    o           ",
      "  ffoooooop  qqq",
      "     rrrrro  q  ",
      "          o  q  ",
      "          o  q  ",
      "          o  q  ",
      "          o  q  ",
      "          o  q  ",
      "          o  q  ",
      "          o  q  ",
      "          o  q  ",
      "          o  q  ",
      "          o  q  ",
      "     ssssso  q  ",
      "  ffoooooop  qqq",
      "    o           "
    ],
    [
      "    o           ",
      "  ffoooooop     ",
      "          o     ",
      "          o     ",
      "          o     ",
      "          o     ",
      "          o     ",
      "          o     ",
      "          o     ",
      "          o     ",
      "          o     ",
      "          o     ",
      "          o     ",
      "          o     ",
      "  ffoooooop     ",
      "    o           "
    ],
    [
      "                ",
      "  ff      t     ",
      "                ",
      "                ",
      "                ",
      "                ",
      "                ",
      "                ",
      "                ",
      "                ",
      "                ",
      "                ",
      "                ",
      "                ",
      "  ff      t     ",
      "                "
    ],
    [
      "                ",
      "  ff      t     ",
      "                ",
      "                ",
      "                ",
      "                ",
      "                ",
      "                ",
      "                ",
      "                ",
      "                ",
      "                ",
      "                ",
      "                ",
      "  ff      t     ",
      "                "
    ],
    [
      "                ",
      "  ff      t     ",
      "                ",
      "                ",
      "                ",
      "                ",
      "                ",
      "                ",
      "                ",
      "                ",
      "                ",
      "                ",
      "                ",
      "                ",
      "  ff      t     ",
      "                "
    ]
  ]
}