{
  "name": "multi_communitycenter_7_ground",
  "refpalette": "c70cities:multi_communitycenter_7_ground_palette",
  "xsize": 16,
  "zsize": 16,
  "slices": [
    [
      "aaab    baaaaaGc",
      "aaab    baaaaaGc",
      "aaab    baaaaaGc",
      "aaabddddbaaaaaGc",
      "aaabbbbbbaaaaaGc",
      "aaaaaaaaaaaaaaGc",
      "aaaaaaaaaaaaaaGc",
      "aaaaaaaaaaaaaaGc",
      "aaaaaaaaaaaaaaGc",
      "aaaaaaaaaaaaaaGc",
      "aaaaaaaaaaaaaaGc",
      "aaaaaaaaaaaaaaGc",
      "eeeeeeaaaaaaaaGc",
      "ffffffaaaaaaaaGc",
      "ffffffaaaaaaaaGc",
      "ffffffaaaaaaaaGc"
    ],
    [
      " ghi    ih   jk ",
      " lmi    im  nop ",
      " qmi    im rrop ",
      " smiiiiiim t op ",
      "  hmmmmmmh  njk ",
      "   uuwwxy    op ",
      "        A  rrop ",
      "        y  t op ",
      "  wB C   hDDDjk ",
      "   E C  y n nop ",
      "   F  C A rrrop ",
      "   I!C  y t top ",
      "JKLLLL   hDDDjk ",
      "  y  L  y n nop ",
      "  M NL  A rrrop ",
      "  yOOL  y t top "
    ],
    [
      "  h      h   j  ",
      "  m      m   o  ",
      "  m      m  !o  ",
      "  m      m   o  ",
      "  hmmmmmmh   j  ",
      "       Py    o  ",
      "        Q  R o  ",
      "        y    o  ",
      "    S    hTTTj  ",
      "    S   y    o  ",
      "    S   Q    o  ",
      "    S   y    o  ",
      "UVLLLL   hTTTj  ",
      "  y  L  y    o  ",
      "  W  L  Q    o  ",
      "  yOOL  y    o  "
    ],
    [
      "  h      h   j  ",
      "  m      m   X  ",
      "  m      m   X  ",
      "  m      m   X  ",
      "  hmmmmmmh   j  ",
      "        y    X  ",
      "        y    X  ",
      "        y    X  ",
      "         hDDDj  ",
      "        y    X  ",
      "        y    X  ",
      "        y    X  ",
      "LLLLLL   hDDDj  ",
      "  yYYL  y    X  ",
      "  yYYL  y    X  ",
      "  yZZL  y    X  "
    ],
    [
      "  h      h   j  ",
      "  m      m   o  ",
      "  m      m   o  ",
      "  m      m   o  ",
      " 0hmmmmmmh0  j  ",
      "   11111y    o  ",
      "        y    o  ",
      "        y    o  ",
      "  2     0hDDDj  ",
      "        y    o  ",
      "        y    o  ",
      "        y    o  ",
      "LLLLLL   hDDDj  ",
      "   34L  y    o  ",
      "    4L  y    o  ",
      "   33L  y    o  "
    ],
    [
      "aaaaaaaaaaaaa5  ",
      "aaaaaaaaaaaaa5  ",
      "aaaaaaaaaaaaa5  ",
      "aaaaaaaaaaaaa5  ",
      "aaaaaaaaaaaaaj  ",
      "aaaaaaaaaaaaa5  ",
      "aaaaaaaaaaaaa5  ",
      "aaaaaaaaaaaaa5  ",
      "aaaaaaaaaaaaa5  ",
      "aaaaaaaaaaaaa5  ",
      "aaaaaaaaaaaaa5  ",
      "aaaaaaaaaaaaa5  ",
      "LLLLLLaaaaaaaj  ",
      "bbbbbLaaaaaaa5  ",
      "bbbbbLaaaaaaa5  ",
      "bbbbbLaaaaaaa5  "
    ]
  ]
}