{
  "name": "multi_factory_0_ground",
  "refpalette": "c70cities:multi_factory_0_ground_palette",
  "xsize": 16,
  "zsize": 16,
  "slices": [
    [
      "zaazzzzzzzzzzzzz",
      "aaazzzzzzzzzzzzz",
      "aazbbbbbbbbbbbzz",
      "aaabbbbbbbbbbbzz",
      "aaabbbbbbbbbbbzz",
      "zaabbbbbbbbbbbzz",
      "zaabbbbbbbbbbbzz",
      "aaabbbbbbbbbbbzz",
      "zaabbbbbbbbbbbzz",
      "aaabbbbbbbbbbbzz",
      "aaabbbbbbbbbbbzz",
      "aaabbbbbbbbbbbzz",
      "zaabbbbbbbbbbbzz",
      "aaabbbbbbbbbbbzz",
      "zaabbbbbbbbbbbzz",
      "aaabbbbbbbbbbbzz"
    ],
    [
      "                ",
      "                ",
      "   ccccccccccc  ",
      "   cdeffdgh dc  ",
      "   ij    k  lc  ",
      "   c     mnnnc  ",
      "   co    p  lc  ",
      "   coq   gr  c  ",
      "   co    ssssc  ",
      "   co t     uc  ",
      "   c wxxyA j c  ",
      "   cmmmmmmmBmc  ",
      "   cCCddD D dc  ",
      "            dc  ",
      "           EFc  ",
      "            dc  "
    ],
    [
      "                ",
      "                ",
      "   ccccccccccc  ",
      "   cd ffdg  dc  ",
      "   I     J  Kc  ",
      "   c     mnnnc  ",
      "   LM    N  Kc  ",
      "   LO    g   c  ",
      "   LO    ssssc  ",
      "   L        uc  ",
      "   c   P     c  ",
      "   cmLLLLmmQmc  ",
      "   cd       Rc  ",
      "            Sc  ",
      "           TUc  ",
      "            Sc  "
    ],
    [
      "                ",
      "                ",
      "   ccVWXcVWXcc  ",
      "   cd   dg  dc  ",
      "   L     g   c  ",
      "   c     mnnnc  ",
      "   L     g   c  ",
      "   L     g   c  ",
      "   L     ssssc  ",
      "   L        uc  ",
      "   c         c  ",
      "   cmLLLLmmmmc  ",
      "   c         c  ",
      "   Y         c  ",
      "   Y        Zc  ",
      "   Y         c  "
    ],
    [
      "                ",
      "                ",
      "   ccccccccccc  ",
      "   cd   dg  dc  ",
      "  0c     g   c  ",
      "  0c     mnnnc  ",
      "  0c     g   c  ",
      "  0c     g   c  ",
      "  0c     ssssc  ",
      "  0c        uc  ",
      "   c         c  ",
      "   cmmmmmmmmmc  ",
      "   c         c  ",
      "  0c1        c  ",
      "  0c1       2c  ",
      "  0c1        c  "
    ],
    [
      "                ",
      "                ",
      "   ccccccccccc  ",
      "   cd   dbbbdc  ",
      "   c    3bbbbc  ",
      "   c    3bbbbc  ",
      "   c    3bbbbc  ",
      "   c    3bbbbc  ",
      "   c    3bbbbc  ",
      "   c    3bbbuc  ",
      "   c    3bbbbc  ",
      "   cmmmmmmmmmc  ",
      "   c        Dc  ",
      "   c         c  ",
      "   c         c  ",
      "   c         c  "
    ]
  ]
}