{
  "name": "multi_condo1_1_floor7",
  "refpalette": "c70cities:multi_condo1_1_floor7_palette",
  "xsize": 16,
  "zsize": 16,
  "slices": [
    [
      "   abccccccccccc",
      "  ddbeeeeeeeeeee",
      "    b           ",
      "    b           ",
      "    f           ",
      "   gf           ",
      "    f           ",
      "    f           ",
      "    f           ",
      "    f           ",
      "   hf           ",
      "    f           ",
      "    b           ",
      "    b           ",
      "  ddbiiiiiiiiiii",
      "   abccccccccccc"
    ],
    [
      "    b           ",
      "  ddbjjjjjjjjjjj",
      "    b           ",
      "    b           ",
      "    f           ",
      "   gf           ",
      "    f           ",
      "    f           ",
      "    f           ",
      "    f           ",
      "   hf          k",
      "    f           ",
      "    b           ",
      "    b           ",
      "  ddbjjjjjjjjjjj",
      "    b           "
    ],
    [
      "    b           ",
      "  ddb           ",
      "    b           ",
      "    b           ",
      "    f           ",
      "   gf           ",
      "    f           ",
      "    f           ",
      "    f           ",
      "    f           ",
      "   hf          l",
      "    f           ",
      "    b           ",
      "    b           ",
      "  ddb           ",
      "    b           "
    ],
    [
      "    b           ",
      "  ddb           ",
      "    b           ",
      "    b           ",
      "    f           ",
      "   mf           ",
      "   nf          k",
      "   nf           ",
      "   nf           ",
      "   nf           ",
      "   of          l",
      "    f           ",
      "    b           ",
      "    b           ",
      "  ddb           ",
      "    b           "
    ],
    [
      "    b           ",
      "  ddb           ",
      "    b           ",
      "    b           ",
      "    f           ",
      "    f           ",
      "    f          l",
      "    f           ",
      "    f           ",
      "    f           ",
      "    f          p",
      "    f           ",
      "    b           ",
      "    b           ",
      "  ddb           ",
      "    b           "
    ],
    [
      "    b  qq       ",
      "  ddb           ",
      "    b           ",
      "    b           ",
      "    r           ",
      "    r  qq       ",
      "    r          p",
      "    r           ",
      "    r           ",
      "    r           ",
      "    r  qq      p",
      "    r           ",
      "    b           ",
      "    b           ",
      "  ddb           ",
      "    b  qq       "
    ]
  ]
}