{
  "name": "multi_laboratory1_14_base1",
  "refpalette": "c70cities:multi_laboratory1_14_base1_palette",
  "xsize": 16,
  "zsize": 16,
  "slices": [
    [
      "aaaabaaaaaaaacdz",
      "aaaaaaaaaaaaacdz",
      "aaaaaaaaaaaaacdz",
      "aaaaaaaaaaaaacdz",
      "aaaaaaaaaaaaacdz",
      "aaaaaaaaaaaaacdz",
      "aaaaaaaaaaaaacdz",
      "aaaabaaaaaaaacdz",
      "aaaaaeeeeeeeecdz",
      "aaaaaeeeeeeeecdz",
      "aaaaaeeeeeeeecdz",
      "aaaaaeeeeeeeecdz",
      "aaaaaee!eeeeecdz",
      "ccccccccccccccdz",
      "dddddddddddddddz",
      "zzzzzzzzzzzzzzzz"
    ],
    [
      "    b       fcdz",
      "    g   h   fcdz",
      "    g  iii  jcdz",
      "    k       lcdz",
      "    g  mmm  jcdz",
      "    g  h h  lcdz",
      "    g      nlcdz",
      "o   bppppppppcdz",
      "q   prrssssrrcdz",
      "q   t        cdz",
      "q   puwuwxwuwcdz",
      "q   p y y y ycdz",
      "!qqopAyAyAyAycdz",
      "ccccccccccccccdz",
      "dddddddddddddddz",
      "zzzzzzzzzzzzzzzz"
    ],
    [
      "    b        cdz",
      "    g        cdz",
      "    g  B C  Dcdz",
      "    E        cdz",
      "    g  F I   cdz",
      "    g       Jcdz",
      "    g K     Dcdz",
      "L   bppppppppcdz",
      "    pM NNNNNMcdz",
      "    O        cdz",
      "    pPwPwQwPwcdz",
      "R   p y y y ycdz",
      "LSTLp y y y ycdz",
      "ccccccccccccccdz",
      "dddddddddddddddz",
      "zzzzzzzzzzzzzzzz"
    ],
    [
      "    b        cdz",
      "    g        cdz",
      "    g       Ucdz",
      "    g       Vcdz",
      "    g        cdz",
      "    g       Ucdz",
      "    g       Vcdz",
      "M   bppppppppcdz",
      "    p N  NN  cdz",
      "    p        cdz",
      "    pwwwwwwwwcdz",
      "    p y y y ycdz",
      "MW Mp y y y ycdz",
      "ccccccccccccccdz",
      "dddddddddddddddz",
      "zzzzzzzzzzzzzzzz"
    ],
    [
      "    b        cdz",
      "    g        cdz",
      "    g        cdz",
      "    g       Xcdz",
      "    g        cdz",
      "    g       Ycdz",
      "    g       !cdz",
      "    bppppppppcdz",
      "    pZZZZZZZZcdz",
      "    pZZZZZZZZcdz",
      "    pZZZZZZZZcdz",
      "    pZZZZZZZZcdz",
      "    p0Z0Z0Z0Zcdz",
      "ccccccccccccccdz",
      "dddddddddddddddz",
      "zzzzzzzzzzzzzzzz"
    ],
    [
      "1111b11111111cdz",
      "1111211111111cdz",
      "1111213111311cdz",
      "1111213111311cdz",
      "1111213111311cdz",
      "1111213111311cdz",
      "1111211111111cdz",
      "1111bppppppppcdz",
      "1111p44444444cdz",
      "1111p4 4 4 4ccdz",
      "1111p4 4 4 4ccdz",
      "1111p4 4 4 4ccdz",
      "1111p4 4 4 4ccdz",
      "ccccccccccccccdz",
      "dddddddddddddddz",
      "zzzzzzzzzzzzzzzz"
    ]
  ]
}