{
  "name": "multi_megatower1_7_floor4",
  "refpalette": "c70cities:multi_megatower1_7_floor4_palette",
  "xsize": 16,
  "zsize": 16,
  "slices": [
    [
      "aaab            ",
      "aaac            ",
      "aaac            ",
      "aaac            ",
      "aadef           ",
      "aaab            ",
      "ggab            ",
      "ggab            ",
      "ggac            ",
      "ggac            ",
      "aaac            ",
      "aadef           ",
      "aaab            ",
      "aaab            ",
      "aaab            ",
      "aaac            "
    ],
    [
      "hijb            ",
      "  jc            ",
      "kkjc            ",
      "lmjc            ",
      "nedef           ",
      "nojb            ",
      "ppjb            ",
      "  jb            ",
      "  jc            ",
      "qqjc            ",
      "nojc            ",
      "nedef           ",
      "lmjb            ",
      "rrjb            ",
      " sjb            ",
      " ijc            "
    ],
    [
      "  jb            ",
      "  jc            ",
      "kkjc            ",
      "  jc            ",
      "ntdef           ",
      "n!jb            ",
      "ppjb            ",
      "  ub            ",
      "  uc            ",
      "qqjc            ",
      "nwjc            ",
      "ntdef           ",
      "  jb            ",
      "rrjb            ",
      "  jb            ",
      "  jc            "
    ],
    [
      "  jb            ",
      "  jc            ",
      "kkjc            ",
      " xjc            ",
      " odef           ",
      " ojb            ",
      "ppjb            ",
      "  yb            ",
      "  yc            ",
      "qqjc            ",
      " ojc            ",
      " odef           ",
      "  jb            ",
      "rrjb            ",
      "  jb            ",
      "  jc            "
    ],
    [
      "  jb            ",
      " xjc            ",
      "kkjc            ",
      "xxjc            ",
      " odef           ",
      "xojb            ",
      "ppjb            ",
      "  jb            ",
      "  jc            ",
      "qqjc            ",
      "xojc            ",
      " odef           ",
      "  jb            ",
      "rrjb            ",
      "  jb            ",
      "  jc            "
    ],
    [
      "  Ab            ",
      " xAc            ",
      "aaAc            ",
      "aaAc            ",
      "BBdef           ",
      "aaAb            ",
      "CCAb            ",
      "DDAb            ",
      "DDAc            ",
      "EEAc            ",
      "aaAc            ",
      "BBdef           ",
      "aaAb            ",
      "aaAb            ",
      "  Ab            ",
      "  Ac            "
    ]
  ]
}