{
  "name": "multi_hospital_1_base1",
  "refpalette": "c70cities:multi_hospital_1_base1_palette",
  "xsize": 16,
  "zsize": 16,
  "slices": [
    [
      "vabccccccddddddd",
      "vabccccccddddddd",
      "vaebbbbbbddddddd",
      "vaaaaaaaaddddddd",
      "vaaaaaaaaddddddd",
      "vaaaaaaaaddddddd",
      "vaaaaaaaaddddddd",
      "vaaaaaaaaddddddd",
      "vaaaaaaaaddddddd",
      "vaaaaaaaadf     ",
      "vaaaaaaaaddddddd",
      "vaaaaaaaaaaaaaaa",
      "vaaaaaaaaaaaaaaa",
      "vaaaaaaaaaaaaaaa",
      "vaaaaaaaaaaaaaaa",
      "vvvvvvvvvvvvvvvv"
    ],
    [
      "vab ghi bjk     ",
      "vab ghi bj      ",
      "vaebbbbbbdll   l",
      "vaaaaaaaajm     ",
      "vaaaaaaaaj      ",
      "vaaaaaaaadll   l",
      "vaaaaaaaajn     ",
      "vaaaaaaaajoo    ",
      "vaaaaaaaad ppdpp",
      "vaaaaaaaaq      ",
      "vaaaaaaaadrrrdrr",
      "vaaaaaaaaaaaaaaa",
      "vaaaaaaaaaaaaaaa",
      "vaaaaaaaaaaaaaaa",
      "vaaaaaaaaaaaaaaa",
      "vvvvvvvvvvvvvvvv"
    ],
    [
      "vab stu bj      ",
      "vab swu bj      ",
      "vaeb   bbdx     ",
      "vaaaaaaaaj      ",
      "vaaaaaaaaj      ",
      "vaaaaaaaadx     ",
      "vaaaaaaaaj      ",
      "vaaaaaaaajoo y  ",
      "vaaaaaaaad ppdpp",
      "vaaaaaaaaq      ",
      "vaaaaaaaadrrrdrr",
      "vaaaaaaaaaaaaaaa",
      "vaaaaaaaaaaaaaaa",
      "vaaaaaaaaaaaaaaa",
      "vaaaaaaaaaaaaaaa",
      "vvvvvvvvvvvvvvvv"
    ],
    [
      "vab iAg bj      ",
      "vab iAg bj      ",
      "vaeb   bbd      ",
      "vaaaaaaaaj      ",
      "vaaaaaaaaj      ",
      "vaaaaaaaad      ",
      "vaaaaaaaaj      ",
      "vaaaaaaaajB     ",
      "vaaaaaaaadpppdpp",
      "vaaaaaaaaq      ",
      "vaaaaaaaadrrrdrr",
      "vaaaaaaaaaaaaaaa",
      "vaaaaaaaaaaaaaaa",
      "vaaaaaaaaaaaaaaa",
      "vaaaaaaaaaaaaaaa",
      "vvvvvvvvvvvvvvvv"
    ],
    [
      "vab  C  bj      ",
      "vab  C  bj      ",
      "vaebbbbbbd      ",
      "vaaaaaaaaj      ",
      "vaaaaaaaaj      ",
      "vaaaaaaaad      ",
      "vaaaaaaaaj      ",
      "vaaaaaaaaj      ",
      "vaaaaaaaadpppdpp",
      "vaaaaaaaaq      ",
      "vaaaaaaaadrrrdrr",
      "vaaaaaaaaaaaaaaa",
      "vaaaaaaaaaaaaaaa",
      "vaaaaaaaaaaaaaaa",
      "vaaaaaaaaaaaaaaa",
      "vvvvvvvvvvvvvvvv"
    ],
    [
      "vabDDDDDbdffffff",
      "vabDDDDDbdffffff",
      "vaebbbbbbddddddd",
      "vaaaaaaaadffffff",
      "vaaaaaaaadffffff",
      "vaaaaaaaadffffff",
      "vaaaaaaaadffffff",
      "vaaaaaaaadffffff",
      "vaaaaaaaaddddddd",
      "vaaaaaaaadDDDDDD",
      "vaaaaaaaaddddddd",
      "vaaaaaaaaaaaaaaa",
      "vaaaaaaaaaaaaaaa",
      "vaaaaaaaaaaaaaaa",
      "vaaaaaaaaaaaaaaa",
      "vvvvvvvvvvvvvvvv"
    ]
  ]
}