{
  "name": "multi_militarybase_0_base2",
  "refpalette": "c70cities:multi_militarybase_0_base2_palette",
  "xsize": 16,
  "zsize": 16,
  "slices": [
    [
      "vvvvvvvvvvvvvvvv",
      "vaaaavaaaaaaavaa",
      "vaaaabaaaaaaabaa",
      "vaaaabaaaaaaabaa",
      "vaaaabaaaaaaabaa",
      "vvbbbvbbbbbbbvbb",
      "vaaaabaaaaaaabaa",
      "vaaaabaaaaaaabaa",
      "vaaaabaaaaaaabaa",
      "vaaaabaaaaaacvdd",
      "vaaaabaaaaaeebee",
      "vaaaabaaaaeeebee",
      "vaaaabaaaaeeebee",
      "vvbbbvbbbbbbbvbb",
      "vaaaaaaaaaeeeb  ",
      "vaaaaaaaaaeeeb  "
    ],
    [
      "vvvvvvvvvvvvvvvv",
      "vfgfgvh h h hv i",
      "vj   kl l l lk m",
      "vj   n  o o ok o",
      "vf   k       k  ",
      "vvkpkvqqqrqqqvqq",
      "vstu w          ",
      "v    w          ",
      "vstu w         x",
      "v    y  A   cvqB",
      "vstu w CCA      ",
      "v    wACC       ",
      "vstu w          ",
      "vvkkkv       vDD",
      "vEFEE   A    D  ",
      "v     ACC    D  "
    ],
    [
      "vvvvvvvvvvvvvvvv",
      "v!   vh h h hv i",
      "v    kl l l lk m",
      "v    I  J J Jk J",
      "vK   k       k  ",
      "vvkLkvqqqMqqqvqq",
      "vstN w          ",
      "v    w          ",
      "vstN w          ",
      "v    O      cvqB",
      "vstN w P        ",
      "v    w          ",
      "vstN w          ",
      "vvkkkv       v  ",
      "vE!FE           ",
      "v               "
    ],
    [
      "vvvvvvvvvvvvvvvv",
      "v    v       v  ",
      "v    k       k  ",
      "v    k       k  ",
      "v    k       k  ",
      "vvkkkvqqqqqqqvqq",
      "v    w          ",
      "v    w          ",
      "v    w          ",
      "v    w      cvqq",
      "v    w          ",
      "v    w          ",
      "v    w          ",
      "vvkkkv       v  ",
      "vQEEE           ",
      "v               "
    ],
    [
      "vvvvvvvvvvvvvvvv",
      "v    v       v  ",
      "v    k       k  ",
      "v    k       k  ",
      "v    k       k  ",
      "vvkkkvDDDDDDDvqq",
      "v    D       D  ",
      "v    D       D  ",
      "v    D       D  ",
      "v    D      cvDD",
      "v    D          ",
      "v    D          ",
      "v    D          ",
      "vvkkkv       vRR",
      "v            R  ",
      "v            R  "
    ],
    [
      "vvvvvvvvvvvvvvvv",
      "vSSSSvSSSSSSSvSS",
      "vSTTTbTTTTTTTbTT",
      "vSTTTbTTTTTTTbTT",
      "vSTTTbTTTTTTTbTT",
      "vvbbbvbbbbbbbvbb",
      "vSTTTbTTTTTTTbTT",
      "vSTTTbTTTTTTTbTT",
      "vSTTTbTTTTTTTbTT",
      "vSTTTbTTTTTTcvTT",
      "vSTTTbTTTTTTTbTT",
      "vSTTTbTTTTTTTbTT",
      "vSTTTbTTTTTTTbTT",
      "vvbbbvbbbbbbbvUU",
      "vSTTTTTTTTTTTU  ",
      "vSTTTTTTTTTTTU  "
    ]
  ]
}