{
  "name": "multi_megatower1_1_floor3",
  "refpalette": "c70cities:multi_megatower1_1_floor3_palette",
  "xsize": 16,
  "zsize": 16,
  "slices": [
    [
      "            ab  ",
      "            cb  ",
      "            cbde",
      "            cbff",
      "           ghibb",
      "            abbb",
      "            abjj",
      "            abjj",
      "            cbjj",
      "            cbjj",
      "            cbbb",
      "           ghibb",
      "            abbb",
      "            abbb",
      "            abbb",
      "            cbbb"
    ],
    [
      "            ak  ",
      "            ckd ",
      "            ckl ",
      "            ck  ",
      "           ghicm",
      "            an  ",
      "            an  ",
      "            an  ",
      "            cn  ",
      "            cnoo",
      "            cnpq",
      "           ghip ",
      "            anr ",
      "            anss",
      "            ant ",
      "            cnuw"
    ],
    [
      "            akf ",
      "            ckl ",
      "            ck  ",
      "            ck  ",
      "           ghicx",
      "            an  ",
      "            an  ",
      "            ay  ",
      "            cy  ",
      "            cnoo",
      "            cnp ",
      "           ghip ",
      "            anA ",
      "            anss",
      "            anB ",
      "            cn  "
    ],
    [
      "            aklC",
      "            ck  ",
      "            ck  ",
      "            ck D",
      "           ghicc",
      "            an  ",
      "            an  ",
      "            aE  ",
      "            cE  ",
      "            cnoo",
      "            cnp ",
      "           ghip ",
      "            an  ",
      "            anss",
      "            an  ",
      "            cn  "
    ],
    [
      "            aF e",
      "            cF C",
      "            cF  ",
      "            cF  ",
      "           ghicc",
      "            an  ",
      "            an  ",
      "            an  ",
      "            cn  ",
      "            cnoo",
      "            cnp ",
      "           ghip ",
      "            anI ",
      "            anss",
      "            anI ",
      "            cn  "
    ],
    [
      "            aJ  ",
      "            cJ e",
      "            cJ f",
      "            cJdf",
      "           ghiKK",
      "            aJLL",
      "            aJLL",
      "            aJLL",
      "            cJLL",
      "            cJMM",
      "            cJbb",
      "           ghiKK",
      "            aJbb",
      "            aJbb",
      "            aJII",
      "            cJ  "
    ]
  ]
}