{
  "name": "multi_condo1_1_base2",
  "refpalette": "c70cities:multi_condo1_1_base2_palette",
  "xsize": 16,
  "zsize": 16,
  "slices": [
    [
      "vaHHHHHHHHHHHHHH",
      "vaHHHHHHHHaHHHHH",
      "vaHHHHHHHHHHHHHH",
      "vaHHHHHHHHHHHHHH",
      "vaHHHHHHHHHHHHHH",
      "vaHHHHHHHHHHHHHH",
      "vaHHHHHHHHHHHHHH",
      "vaHHHHHHHHHHHHHH",
      "vaHHHHHHHHHHHHHH",
      "vaHHHHHHHHHHHHHH",
      "vaHHHHHHHHHHHHHH",
      "vaHHHHHHHHHHHHHH",
      "vaHHHHHHHHHHHHHH",
      "vaHHHHHHHHHHHHHH",
      "vaHHHHHHHHaHHHHH",
      "vaHHHHHHHHHHHHHH"
    ],
    [
      "vab c           ",
      "vad e  fffafff  ",
      "vab c  b cgb c  ",
      "vad e  d egd e  ",
      "vab c  b cgb c  ",
      "vad e  d egd e  ",
      "vab c  b cgb c  ",
      "vad e  d egdhe  ",
      "vab c  b cgb c  ",
      "vad e  d egd e  ",
      "vab c  b cgb c  ",
      "vad eh d egd e  ",
      "vab c  b cgb c  ",
      "vad e  d egd e  ",
      "vaiii  iiiaiii  ",
      "va              "
    ],
    [
      "va              ",
      "va        a     ",
      "va              ",
      "va              ",
      "va              ",
      "va              ",
      "va              ",
      "va              ",
      "va              ",
      "va              ",
      "va              ",
      "va              ",
      "va              ",
      "va              ",
      "va        a     ",
      "va              "
    ],
    [
      "va              ",
      "va        a     ",
      "va              ",
      "va              ",
      "va              ",
      "va              ",
      "va              ",
      "va              ",
      "va              ",
      "va              ",
      "va              ",
      "va              ",
      "va              ",
      "va              ",
      "va        a     ",
      "va              "
    ],
    [
      "vaj       a     ",
      "vaaaaaaaaaaaaaaa",
      "vaj       a     ",
      "vaj       a     ",
      "vaj       a     ",
      "vaj       a     ",
      "vaj       a     ",
      "vaj       a     ",
      "vaj       a     ",
      "vaj       a     ",
      "vaj       a     ",
      "vaj       a     ",
      "vaj       a     ",
      "vaj       a     ",
      "vaaaaaaaaaaaaaaa",
      "vaj       a     "
    ],
    [
      "vakkkkkkkkakkkkk",
      "vaaaaaaaaaaaaaaa",
      "vakkkkkkkkakkkkk",
      "vakkkkkkkkakkkkk",
      "vakkkkkkkkakkkkk",
      "vakkkkkkkkakkkkk",
      "vakkkkkkkkakkkkk",
      "vakkkkkkkkakkkkk",
      "vakkkkkkkkakkkkk",
      "vakkkkkkkkakkkkk",
      "vakkkkkkkkakkkkk",
      "vakkkkkkkkakkkkk",
      "vakkkkkkkkakkkkk",
      "vakkkkkkkkakkkkk",
      "vaaaaaaaaaaaaaaa",
      "vakkkkkkkkakkkkk"
    ]
  ]
}