{
  "name": "multi_laboratory1_3_base6",
  "refpalette": "c70cities:multi_laboratory1_3_base6_palette",
  "xsize": 16,
  "zsize": 16,
  "slices": [
    [
      "vabccccccccccccc",
      "vabccccccccccccc",
      "vbcccccccccdeeee",
      "vbfffffffffccccc",
      "vbffffbbbbfccccc",
      "vbffffbg bfccccc",
      "vbffffbg bfccccc",
      "vbffffbbbbfccccc",
      "vbfffffffffccccc",
      "vbhiiiiiiiidcccc",
      "vbjjjjcccccccc!c",
      "vbjjjjcccccccccc",
      "vbjjjjcccccccccc",
      "vbjjjjcccccccccc",
      "vbjjjjcccccccccc",
      "vbjjjjcccccccccc"
    ],
    [
      "vab             ",
      "vak             ",
      "vdllllllllldmmmm",
      "vb     nn  l    ",
      "vbo   pppp l    ",
      "vb   qpg prl    ",
      "vb   qpg prl    ",
      "vbo   pppp l    ",
      "vb st  uu  l wx ",
      "vdy  ydyyyyd  x ",
      "vb AB l    lC x ",
      "vbD   E    l    ",
      "vbF   l    l    ",
      "vbFI  l    l    ",
      "vb   Jl    l    ",
      "vbKLLKl    lM x "
    ],
    [
      "vab             ",
      "vak             ",
      "vdllllllllldNNNN",
      "vb         O    ",
      "vb         O    ",
      "vb     PP  O    ",
      "vb     QQ  O    ",
      "vb         O    ",
      "vb RS      O    ",
      "vdy  ydyyyyd  T ",
      "vb UV l    O  W ",
      "vb    X    O    ",
      "vb    lY   O    ",
      "vbZ  0l    O    ",
      "vb   Jl    O    ",
      "vb1   l2   O  3 "
    ],
    [
      "vab             ",
      "vak             ",
      "vdllllllllldNNNN",
      "vb         O    ",
      "vb         O    ",
      "vb         O    ",
      "vb         O    ",
      "vb         O    ",
      "vb         O    ",
      "vdyyyydyyyyd    ",
      "vb    l    O    ",
      "vb    4    O    ",
      "vb    l    O    ",
      "vb    l    O    ",
      "vb   Jl2   O    ",
      "vb    l    O    "
    ],
    [
      "vab             ",
      "vak             ",
      "vdllllllllldNNNN",
      "vb         O    ",
      "vb         O    ",
      "vb         O    ",
      "vb         O    ",
      "vb         O    ",
      "vb         O    ",
      "vdyyyydyyyyd    ",
      "vb    l    O    ",
      "vb    l    O    ",
      "vb    l    O    ",
      "vb    l2   O    ",
      "vb   Jl    O    ",
      "vb    l    O    "
    ],
    [
      "vab             ",
      "vak             ",
      "vdllllllllldNNNN",
      "vb         O    ",
      "vb         O    ",
      "vb         O    ",
      "vb         O    ",
      "vb         O    ",
      "vb         O    ",
      "vdyyyydyyyyd    ",
      "vb5555l    O    ",
      "vb5555l    O    ",
      "vb5555l2   O    ",
      "vb5555l    O    ",
      "vb555Jl    O    ",
      "vb5555l    O    "
    ]
  ]
}