{
  "name": "multi_laboratory1_8_floor1",
  "refpalette": "c70cities:multi_laboratory1_8_floor1_palette",
  "xsize": 16,
  "zsize": 16,
  "slices": [
    [
      "aaaabcd  bcdaaaa",
      "aaaa        aaaa",
      "aaaa        aaaa",
      "aaaa        aaaa",
      "aaaa        aaaa",
      "aaaa        aaaa",
      "aaaa        aaaa",
      "aaaa  !     aaaa",
      "aaaa        aaaa",
      "aaaa        aaaa",
      "aaaa        aaaa",
      "aaaa        aaaa",
      "aaaa        aaaa",
      "aaaa        aaaa",
      "aaaa        aaaa",
      "aaaa        aaaa"
    ],
    [
      "   b        d   ",
      "   b        d   ",
      "  eb        de  ",
      "   b        d   ",
      "ff b        d gg",
      "hh b        d hh",
      "ii b        d gg",
      "   b        d   ",
      "   b        d   ",
      "ffeb        degg",
      "hh b        d hh",
      "ii b        d gg",
      "   b        d   ",
      "   b        d   ",
      "ff b        d gg",
      "hh b        d hh"
    ],
    [
      "                ",
      "                ",
      "  e          e  ",
      "                ",
      "                ",
      " j            j ",
      "                ",
      "                ",
      "                ",
      "  e          e  ",
      "              kj",
      "                ",
      "                ",
      "                ",
      "                ",
      "l             j "
    ],
    [
      "                ",
      "                ",
      "  e          e  ",
      "                ",
      "                ",
      "                ",
      "                ",
      "                ",
      "                ",
      "  e          e  ",
      "                ",
      "                ",
      "                ",
      "                ",
      "                ",
      "                "
    ],
    [
      "                ",
      "                ",
      "  e          e  ",
      "                ",
      "                ",
      "                ",
      "                ",
      "                ",
      "                ",
      "  e          e  ",
      "                ",
      "                ",
      "                ",
      "                ",
      "                ",
      "                "
    ],
    [
      "    mmmmmmmm    ",
      "  mmm      mmm  ",
      "mmn          nmm",
      "m              m",
      "                ",
      "                ",
      "     mmmmmm     ",
      "   mmm    mmm   ",
      "  mm        mm  ",
      "  n          n  ",
      " mm          mm ",
      " m            m ",
      " m            m ",
      " m            m ",
      " m            m ",
      " mm          mm "
    ]
  ]
}