{
  "name": "multi_condo1_2_floor1",
  "refpalette": "c70cities:multi_condo1_2_floor1_palette",
  "xsize": 16,
  "zsize": 16,
  "slices": [
    [
      "   abccccccdeeee",
      "   abfffffffffff",
      " gggbhhhhhhhhhhh",
      "  ifbhhhhhhhhhhh",
      "  ifbhhhhhhhhhhh",
      "  ifbhhhhhhhhhhh",
      "  ifbhhhhhhhhhhh",
      "  ifbhhhhhhhhhhh",
      "  ifbhhhhhhhhhhh",
      "  ifbhhhhhhhhhhh",
      "  ifbhhhhhhhhhhh",
      "  ifjkkkkkkkkkkk",
      "  ifffffffglllll",
      "  iiiiiiiig     ",
      "          g     ",
      "                "
    ],
    [
      "    m           ",
      "    m           ",
      " ggnm           ",
      " ggom           ",
      " ggom           ",
      " ggom           ",
      " ggom     ~     ",
      " ggom           ",
      " ggom           ",
      " ggom           ",
      " ggom           ",
      " ggommmmmmmmmmmm",
      " ggooooooop     ",
      " gggggggggg     ",
      " gggggggggg     ",
      "                "
    ],
    [
      "    m           ",
      "    m           ",
      "    m           ",
      "    m           ",
      "    m           ",
      "    m           ",
      "    m    ~~     ",
      "    m           ",
      "    m           ",
      "    m           ",
      "    m           ",
      "    mmmmmmmmmmmm",
      "                ",
      "                ",
      "                ",
      "                "
    ],
    [
      "                ",
      "                ",
      "                ",
      "                ",
      "                ",
      "                ",
      "          ~     ",
      "                ",
      "                ",
      "                ",
      "                ",
      "    q           ",
      "                ",
      "                ",
      "                ",
      "                "
    ],
    [
      "                ",
      "                ",
      "                ",
      "                ",
      "                ",
      "                ",
      "          ~     ",
      "                ",
      "                ",
      "                ",
      "                ",
      "    r           ",
      "                ",
      "                ",
      "                ",
      "                "
    ],
    [
      "                ",
      "                ",
      "                ",
      "                ",
      "                ",
      "                ",
      "          ~     ",
      "                ",
      "                ",
      "                ",
      "                ",
      "                ",
      "                ",
      "                ",
      "                ",
      "                "
    ]
  ]
}