{
  "name": "multi_megatower1_5_ground",
  "refpalette": "c70cities:multi_megatower1_5_ground_palette",
  "xsize": 16,
  "zsize": 16,
  "slices": [
    [
      "vvvvvvvvvvvvvvvv",
      "HHHHHHHHHHHHHvvv",
      "HHHHaHHHHHHaHvvv",
      "HHHHHHHHHHHHHvvv",
      "HHHHHHHHHHHHHvvv",
      "HHHHHHHHHHHHHvvv",
      "HHHHHHHHHHHHHvvv",
      "HHHHHHHHHHHHHvvv",
      "HHHHHHHHHHHHHvvv",
      "HHHHaHHHHHHaHvvv",
      "HHHHHHHHHHHHHvvv",
      "vvvvvvvvvvvvvvvv",
      "vvvvvvvvvvvvvvvv",
      "GGGGbGGGGGGbGGGG",
      "bGbbbGbbGGbGbbGb",
      "GGGGGbGGbGGGGGbG"
    ],
    [
      "cccdddccccdddccc",
      "efef efefef     ",
      "    a      aaaaa",
      "ghghighghghj kl ",
      "             kml",
      "             kl ",
      "             kl ",
      "             kml",
      "efefnefefefn kl ",
      "    a      aaaaa",
      "ghgh ghghgh  kl ",
      "kkkkkkkkkkkkkkl ",
      "oooopoooooopoooo",
      "qqrq qqqqqr qrqq",
      "                ",
      "                "
    ],
    [
      "             sst",
      "             sst",
      "    a      a sst",
      "             sst",
      "             sst",
      "             sst",
      "             sst",
      "             sst",
      "             sst",
      "    a      a sst",
      "             sst",
      "             sst",
      "oooopoooooopoooo",
      "                ",
      "                ",
      "                "
    ],
    [
      "         ssatuuu",
      "         ssatuuu",
      "    aaaaaaaatuuu",
      "         ssatuuu",
      "         ssatuuu",
      "         ssatuuu",
      "         ssatuuu",
      "         ssatuuu",
      "         ssatuuu",
      "    aaaaaaaatuuu",
      "         ssatuuu",
      "         ssatuuu",
      "oooopoooooopoooo",
      "    w      w    ",
      "                ",
      "                "
    ],
    [
      "     ssttuuuu   ",
      "     ssttuuuu   ",
      "    assttuuau   ",
      "     ssttuuuu   ",
      "     ssttuuuu   ",
      "     ssttuuuu   ",
      "     ssttuuuu   ",
      "     ssttuuuu   ",
      "     ssttuuuu   ",
      "    assttuuuu   ",
      "     ssttuuuu   ",
      "     ssttuuuu   ",
      "oooopoooooopoooo",
      "                ",
      "                ",
      "                "
    ],
    [
      "ssssauuuu       ",
      "ssssauuuu       ",
      "aaaaauuuu  xy   ",
      "ssssauuuu       ",
      "ssssauuuu       ",
      "ssssauuuu       ",
      "ssssauuuu       ",
      "ssssauuuu       ",
      "ssssauuuu       ",
      "aaaaauuuu       ",
      "ssssauuuu       ",
      "ssssauuuu  A    ",
      "oooopoooooopBB  ",
      "                ",
      "                ",
      "                "
    ]
  ]
}