{
  "name": "multi_megatower1_0_base2",
  "refpalette": "c70cities:multi_megatower1_0_base2_palette",
  "xsize": 16,
  "zsize": 16,
  "slices": [
    [
      "vvvvvvvvvvvvvvvv",
      "vaaaaaaaaaaaaaaa",
      "vaaaaaaaaaaaaaaa",
      "vaavvvvvvvvvvvvv",
      "vaavvvvvvvvvvvvv",
      "vaavvHHHHHHHHHHH",
      "vaavvHbHHHHHHbHH",
      "vaavvHHHHHHHHHHH",
      "vaavvHHHHHHHHHHH",
      "vaavvHHHHHHHHHHH",
      "vaavvHHHHHHHHHHH",
      "vaavvHHHHHHHHHHH",
      "vaavvHHHHHHHHHHH",
      "vaavvHbHHHHHHbvv",
      "vaavvHHHHHHHHvvv",
      "vaavvHHHHHHHHvvv"
    ],
    [
      "vvvvvvvvvvvvvvvv",
      "vaaaaaaaaaaaaaaa",
      "vaaaaaaaaaaaaaaa",
      "vaavvvvvvvvvvvvv",
      "vaavcccccccccccc",
      "vaavc   defef ef",
      "vaavc b d    b  ",
      "vaavc   dghghigh",
      "vaavcjjj        ",
      "vaavce f        ",
      "vaavcg h        ",
      "vaavce f        ",
      "vaavcg h     k  ",
      "vaavc bl     bmm",
      "vaavce f     n  ",
      "vaavcg h     n  "
    ],
    [
      "vvvvvvvvvvvvvvvv",
      "vaaaaaaaaaaaaaaa",
      "vaaaaaaaaaaaaaaa",
      "vaavvvvvvvvvvvvv",
      "vaav            ",
      "vaav            ",
      "vaav  b      b  ",
      "vaav            ",
      "vaav            ",
      "vaav            ",
      "vaav            ",
      "vaav            ",
      "vaav            ",
      "vaav  b      bmm",
      "vaav         noo",
      "vaav         nop"
    ],
    [
      "vvvvvvvvvvvvvvvv",
      "vaaaaaaaaaaaaaaa",
      "vaaaaaaaaaaaaaaa",
      "vaavvvvvvvvvvvvv",
      "vaav            ",
      "vaav            ",
      "vaav  b      b  ",
      "vaav            ",
      "vaav            ",
      "vaav            ",
      "vaav            ",
      "vaav            ",
      "vaav            ",
      "vaav  b      bmm",
      "vaav         noo",
      "vaav         noo"
    ],
    [
      "vvvvvvvvvvvvvvvv",
      "vaaaaaaaaaaaaaaa",
      "vaaaaaaaaaaaaaaa",
      "vaavvvvvvvvvvvvv",
      "vaav            ",
      "vaav  q      q  ",
      "vaav rb      b  ",
      "vaav            ",
      "vaav            ",
      "vaav            ",
      "vaav            ",
      "vaav            ",
      "vaav            ",
      "vaav rb      bmm",
      "vaav         s  ",
      "vaav         s  "
    ],
    [
      "vvvvvvvvvvvvvvvv",
      "vaaaaaaaaaaaaaaa",
      "vaaaaaaaaaaaaaaa",
      "vaavvvvvvvvvvvvv",
      "vaavvvvvvvvvvvvv",
      "vaavvttttttttttt",
      "vaavvtbbbbbbbbbb",
      "vaavvtbttttttbtt",
      "vaavvtbttttttbtt",
      "vaavvtbttttttbtt",
      "vaavvtbttttttbtt",
      "vaavvtbttttttbtt",
      "vaavvtbttttttbtt",
      "vaavvtbbbbbbbbbb",
      "vaavvtbttttttb  ",
      "vaavvtbttttttb  "
    ]
  ]
}