{
  "name": "multi_megatower1_1_floor7",
  "refpalette": "c70cities:multi_megatower1_1_floor7_palette",
  "xsize": 16,
  "zsize": 16,
  "slices": [
    [
      "            ab  ",
      "            ab  ",
      "           cabde",
      "            abff",
      "           ghibb",
      "            ab  ",
      "           jab  ",
      "            ab  ",
      "            ab  ",
      "           cab  ",
      "            ab  ",
      "           ghi  ",
      "            ab  ",
      "           jab  ",
      "            ab  ",
      "            ab  "
    ],
    [
      "             k  ",
      "             kd ",
      "           c kl ",
      "             k  ",
      "           ghicc",
      "             m  ",
      "           j m  ",
      "             m  ",
      "             m  ",
      "           c m  ",
      "             m  ",
      "           ghi  ",
      "             m  ",
      "           j m  ",
      "             m  ",
      "             m  "
    ],
    [
      "             kf ",
      "             kl ",
      "           c k  ",
      "             k  ",
      "           ghicc",
      "                ",
      "           j    ",
      "                ",
      "                ",
      "           c    ",
      "                ",
      "           ghi  ",
      "                ",
      "           j    ",
      "                ",
      "                "
    ],
    [
      "             kln",
      "             k  ",
      "           c k  ",
      "             k  ",
      "           ghicc",
      "                ",
      "           j    ",
      "                ",
      "                ",
      "           c    ",
      "                ",
      "           ghi  ",
      "                ",
      "           j    ",
      "                ",
      "                "
    ],
    [
      "             m e",
      "             m n",
      "           c m  ",
      "             m  ",
      "           ghicc",
      "             m  ",
      "           j m  ",
      "             m  ",
      "             m  ",
      "           c m  ",
      "             m  ",
      "           ghi  ",
      "             m  ",
      "           j m  ",
      "             m  ",
      "             m  "
    ],
    [
      "             o  ",
      "             o e",
      "           c o f",
      "             odf",
      "           ghipp",
      "             oqq",
      "           j oqr",
      "             oqq",
      "             oqq",
      "           c oqs",
      "             oqq",
      "           ghipp",
      "             oqq",
      "           j oqs",
      "             oqq",
      "             oqq"
    ]
  ]
}