{
  "name": "multi_clubhouse1_8_base1",
  "refpalette": "c70cities:multi_clubhouse1_8_base1_palette",
  "xsize": 16,
  "zsize": 16,
  "slices": [
    [
      "  ab    ba    cv",
      "  abbbbbba     v",
      "aaaaaaaaaa    dv",
      "bbabbbbbba    ev",
      " bab    ba    cv",
      " bab    ba     v",
      " bab    ba    cv",
      " bab    ba    ev",
      "bbabbbbbba    cv",
      "aaaaaaaaaa    dv",
      "              ev",
      "              cv",
      "              ev",
      "               v",
      "eedeeee edce eev",
      "vvvvvvvvvvvvvvvv"
    ],
    [
      "fffffffffg    cv",
      "fffffffffg     v",
      "fffffffffg    dv",
      "fffffffffg     v",
      "fffffffffg    cv",
      "fffffffffg     v",
      "fffffffffg     v",
      "fffffffffg    ev",
      "fffffffffg    ev",
      "gggggggggg    dv",
      "              cv",
      "               v",
      "              ev",
      "               v",
      "e de e  cdce ecv",
      "vvvvvvvvvvvvvvvv"
    ],
    [
      "         h     v",
      "    i i ih     v",
      " jk !    d    dv",
      " jl   m  h     v",
      " jl  mnm h     v",
      " jk m m  h     v",
      " jomnm m h     v",
      "pjq m mnmh     v",
      "rjq    m h    ev",
      "hhdhhhhhhd    dv",
      "              cv",
      "               v",
      "               v",
      "               v",
      "  de e  cd e  cv",
      "vvvvvvvvvvvvvvvv"
    ],
    [
      "               v",
      "               v",
      " s  tttttd    dv",
      " s             v",
      " s             v",
      " su            v",
      " sw            v",
      " s             v",
      " s            ev",
      "  d      d    dv",
      "               v",
      "               v",
      "               v",
      "               v",
      "  de    cd    cv",
      "vvvvvvvvvvvvvvvv"
    ],
    [
      "               v",
      "               v",
      "         d    dv",
      "               v",
      "               v",
      "               v",
      "               v",
      "               v",
      "               v",
      "  d      d    dv",
      "               v",
      "               v",
      "               v",
      "               v",
      "  d      d    cv",
      "vvvvvvvvvvvvvvvv"
    ],
    [
      "bbbbbbbbb      v",
      "bbbbbbbbb      v",
      "bbbbxbbybd    dv",
      "bbbbbbbbb      v",
      "bbybbbbbb      v",
      "bbbbbbbbb      v",
      "bbbbbbbbb      v",
      "bbxbbbbyb      v",
      "bbbbbbbbb      v",
      "  d      d    dv",
      "               v",
      "               v",
      "               v",
      "               v",
      "  d      d     v",
      "vvvvvvvvvvvvvvvv"
    ]
  ]
}