{
  "name": "multi_laboratory1_4_base6",
  "refpalette": "c70cities:multi_laboratory1_4_base6_palette",
  "xsize": 16,
  "zsize": 16,
  "slices": [
    [
      "zabbbbcbbbbcbbbb",
      "zabbbbbbbbbbbbbb",
      "zabbbbbbbbbbbbbb",
      "zabbbbbbbbbbbbbb",
      "zabbbbbbbbbbbbbb",
      "zabbbbbbbbbbbbbb",
      "zabbbbbbbbbbbbbb",
      "zabbbbcbbbbcbbbb",
      "zabbbbbbbbbbbbbb",
      "zabbbbbbbbbbbbbb",
      "zabbbbbbbbbbbbbb",
      "zabbbbbbbbbbbbbb",
      "zabbbbbbbbbbbbbb",
      "zabbbbbbbbbbaaaa",
      "zaaaaaaaaaaadddd",
      "zzzzzzzzzzzzzzzz"
    ],
    [
      "zceeeecf   c  g ",
      "zahiihe    e jg ",
      "za  k e    e    ",
      "za    e    e    ",
      "za l  e    e    ",
      "zamn  e    e    ",
      "zaop ke    e  g ",
      "zcop  c    c qg ",
      "za!pk e    e rg ",
      "zahn  s    e    ",
      "za    t    t    ",
      "za    u    u    ",
      "zaw w s    e    ",
      "zamxxme    eaaaa",
      "zaaaaaaaaaaadddd",
      "zzzzzzzzzzzzzzzz"
    ],
    [
      "zceeeec    c  y ",
      "zaA  Be    C    ",
      "za    C    C    ",
      "za    C    C    ",
      "za    C    C    ",
      "zaDB  C    C    ",
      "zaE   e    C    ",
      "zcE   c    c  y ",
      "za    e    e  F ",
      "zaI   s    e    ",
      "za    J    J    ",
      "za    K    K    ",
      "za    s    e    ",
      "zaLLLLe    eaaaa",
      "zaaaaaaaaaaadddd",
      "zzzzzzzzzzzzzzzz"
    ],
    [
      "zceeeec    c    ",
      "za    e    C    ",
      "za    C    C    ",
      "za    C    C    ",
      "za    C    C    ",
      "za    C    C    ",
      "za    e    C    ",
      "zc    c    c    ",
      "za    e    e    ",
      "za    s    e    ",
      "za    s    s    ",
      "za    s    s    ",
      "za    s    e    ",
      "zaMMMMe    eaaaa",
      "zaaaaaaaaaaadddd",
      "zzzzzzzzzzzzzzzz"
    ],
    [
      "zceeeec    c    ",
      "za    e    C    ",
      "za    e    C    ",
      "za    e    C    ",
      "za    e    C    ",
      "za    e    C    ",
      "za    e    C    ",
      "zc    c    c    ",
      "za    e    e    ",
      "za    e    e    ",
      "za    e    s    ",
      "za    e    s    ",
      "za    e    e    ",
      "za    e    eaaaa",
      "zaaaaaaaaaaadddd",
      "zzzzzzzzzzzzzzzz"
    ],
    [
      "zceeeec    c    ",
      "zaNNNNe    C    ",
      "zaNOONe    C    ",
      "zaNNNNe    C    ",
      "zaNNNNe    C    ",
      "zaNOONe    C    ",
      "zaNNNNe    C    ",
      "zceeeec    c    ",
      "zaNNNNe    e    ",
      "zaNOONe    e    ",
      "zaNNNNe    s    ",
      "zaNNNNe    s    ",
      "zaNOONe    e    ",
      "zaNNNNe    eaaaa",
      "zaaaaaaaaaaadddd",
      "zzzzzzzzzzzzzzzz"
    ]
  ]
}