{
  "name": "multi_megatower1_5_base1",
  "refpalette": "c70cities:multi_megatower1_5_base1_palette",
  "xsize": 16,
  "zsize": 16,
  "slices": [
    [
      "vvvvvvvvvvvvvvvv",
      "HHHHHHHHHHHHHHHH",
      "HHHHaHHHHHHaHHHH",
      "HHHHHHHHHHHHHHHH",
      "HHHHHHHHHHHHHHHH",
      "HHHHHHHHHHHHHHHH",
      "HHHHHHHHHHHHHHHH",
      "HHHHHHHHHHHHHHHH",
      "HHHHHHHHHHHHHHHH",
      "HHHHaHHHHHHaHHHH",
      "HHHHHHHHHHHHHHHH",
      "vvvvvvvvvvvvvvvv",
      "vvvvvvvvvvvvvvvv",
      "bbbbbbbbbbbbbbbb",
      "bbbbbbbbbbbbbbbb",
      "vvvvvvvvvvvvvvvv"
    ],
    [
      "cccdddccccdddccc",
      "efef efefef efef",
      " g  a      a    ",
      "hihijhihihijhihi",
      "                ",
      "                ",
      "                ",
      "                ",
      "efefkefefefkefef",
      "    a   g  a    ",
      "hihi hihihi hihi",
      "llllllllllllllll",
      "vvvvvvvvvvvvvvvv",
      "bbbbbbbbbbbbbbbb",
      "bbbbbbbbbbbbbbbb",
      "vvvvvvvvvvvvvvvv"
    ],
    [
      "                ",
      "                ",
      "    a      a    ",
      "                ",
      "                ",
      "                ",
      "                ",
      "                ",
      "                ",
      "    a      a    ",
      "                ",
      "                ",
      "vvvvvvvvvvvvvvvv",
      "bbbbbbbbbbbbbbbb",
      "bbbbbbbbbbbbbbbb",
      "vvvvvvvvvvvvvvvv"
    ],
    [
      "                ",
      "                ",
      "    a      a    ",
      "                ",
      "                ",
      "                ",
      "                ",
      "                ",
      "                ",
      "    a      a    ",
      "                ",
      "                ",
      "vvvvvvvvvvvvvvvv",
      "bbbbbbbbbbbbbbbb",
      "bbbbbbbbbbbbbbbb",
      "vvvvvvvvvvvvvvvv"
    ],
    [
      "                ",
      "                ",
      "    a      a    ",
      "                ",
      "                ",
      "                ",
      "                ",
      "                ",
      "                ",
      "    a      a    ",
      "                ",
      "                ",
      "vvvvvvvvvvvvvvvv",
      "bbbbbbbbbbbbbbbb",
      "bbbbbbbbbbbbbbbb",
      "vvvvvvvvvvvvvvvv"
    ],
    [
      "    a      a    ",
      "mmmmammmmmmammmm",
      "aaaaaaaaaaaaaaaa",
      "mmmmammmmmmammmm",
      "mmmmammmmmmammmm",
      "mmmmammmmmmammmm",
      "mmmmammmmmmammmm",
      "mmmmammmmmmammmm",
      "mmmmammmmmmammmm",
      "aaaaaaaaaaaaaaaa",
      "mmmmmmmmmmmmmmmm",
      "vvvvvvvvvvvvvvvv",
      "vvvvvvvvvvvvvvvv",
      "bbbbbbbbbbbbbbbb",
      "bbbbbbbbbbbbbbbb",
      "vvvvvvvvvvvvvvvv"
    ]
  ]
}