{
  "name": "multi_megatower1_4_base1",
  "refpalette": "c70cities:multi_megatower1_4_base1_palette",
  "xsize": 16,
  "zsize": 16,
  "slices": [
    [
      "a   vHHHHHHHHHHH",
      "a   vHHHHHHHHHHH",
      "a   vHHHHHHHHHHH",
      "bcddvHHHHHHHHHHH",
      "vvvveHHHHHHeHHHH",
      "vvvvfvvvvvvvvvvv",
      "HHghi           ",
      "HHghi           ",
      "HHghi           ",
      "HHghi           ",
      "vvvvjvvvvvvvvvvv",
      "    e      e    ",
      "                ",
      "                ",
      "                ",
      "                "
    ],
    [
      "a   k           ",
      "a   k           ",
      "a   k           ",
      "adllkm nm n m nm",
      "opqres ts tes ts",
      "     vvvvvvvvvvv",
      "             uua",
      "             uua",
      "             uua",
      "             uua",
      "vvvvvvvvvvvvvvvv",
      "    e      e    ",
      "                ",
      "                ",
      "                ",
      "                "
    ],
    [
      "a   k           ",
      "a   k           ",
      "a   k           ",
      "ad  k           ",
      "o wxe      e    ",
      "     vvvvvvvvvvv",
      "          uuaHgh",
      "          uuaHgh",
      "          uuaHgh",
      "          uuaHgh",
      "vvvvvvvvvvvvvvvv",
      "    e      e    ",
      "                ",
      "                ",
      "                ",
      "                "
    ],
    [
      "a   k           ",
      "a   k           ",
      "a   k           ",
      "adddk           ",
      "oy  e      e    ",
      "     vvvvvvvvvvv",
      "       uuaHgh   ",
      "       uuaHgh   ",
      "       uuaHgh   ",
      "       uuaHgh   ",
      "vvvvvvvvvvvvvvvv",
      "    e      e    ",
      "                ",
      "                ",
      "                ",
      "                "
    ],
    [
      "a   k           ",
      "a   k           ",
      "a   k           ",
      "adddk           ",
      "ooooe      e    ",
      "     vvvvvvvvvvv",
      "     uaHgh      ",
      "     uaHgh      ",
      "     uaHgh      ",
      "     uaHgh      ",
      "vvvvvvvvvvvvvvvv",
      "    e      e    ",
      "                ",
      "                ",
      "                ",
      "                "
    ],
    [
      "e   euuuuuuuuuuu",
      "e   euuuuuuuuuuu",
      "e   euuuuuuuuuuu",
      "edABeuuuuuuuuuuu",
      "eeeeeeeeeeeeeeee",
      "uuuuevvvvvvvvvvv",
      "uuuuegh         ",
      "uuuuegh         ",
      "uuuuegh         ",
      "uuuuegh         ",
      "vvvvevvvvvvvvvvv",
      "eeeeeeeeeeeeeeee",
      "    e      e    ",
      "    e      e    ",
      "    e      e    ",
      "    e      e    "
    ]
  ]
}