{
  "name": "multi_communitycenter_1_ground",
  "refpalette": "c70cities:multi_communitycenter_1_ground_palette",
  "xsize": 16,
  "zsize": 16,
  "slices": [
    [
      "aabcdd  e dd f  ",
      "aabcgdhi  dd  je",
      "aabcdd ie dd hje",
      "aabcgdh   dd    ",
      "aabcdd  f dd   e",
      "aabcgdhi  ddh j ",
      "aabcddhie dd hje",
      "aabkkkkkkllllkkk",
      "aammmmmmnmmmmnmm",
      "aamooooonmmmmnpp",
      "aamoooooonmmmmnp",
      "aammooooonmmmmnp",
      "aaamooooonmmmmnp",
      "aaamoooooonmmmmn",
      "aaammooooonmmmmm",
      "aaaamoooooonmmmm"
    ],
    [
      "  b             ",
      "  bq            ",
      "  b             ",
      "  bq            ",
      "  b             ",
      "  b             ",
      "  b             ",
      "  bkkkkkk    kkk",
      "  bbrrrbk    kbs",
      "  b     t    t  ",
      "  b      u    wx",
      "  bbrrr  u    w ",
      "   b     u    w ",
      "   b      u    w",
      "   bbrrr  u     ",
      "    b           "
    ],
    [
      "  yAAAAAAAAAAAAA",
      "  y             ",
      "  b             ",
      "  b             ",
      "  y             ",
      "  y           B ",
      "  y             ",
      "  bkkkkkk    kkk",
      "  bbCCCbk    kbs",
      "  y     t    t  ",
      "  y      u    w ",
      "  yyD E  u    w ",
      "   y     u    w ",
      "   b      u    w",
      "   byFIJ  u     ",
      "    y           "
    ],
    [
      "  bKKKKKKKKKKKKK",
      "  bLLLLLLLLLLLLL",
      "  bAAAAAAAAAAAAA",
      "  bAAAAAAAAAAAAA",
      "  yAAAAAAAAAAAAA",
      "  y    M      M ",
      "  y             ",
      "  bkkkkkk    kkk",
      "  bbbbbbk    kbs",
      "  y     t    t  ",
      "  y      u    w ",
      "  yy     u    w ",
      "   y     u    w ",
      "   b      u    w",
      "   by     u     ",
      "    y           "
    ],
    [
      "  bN  O  PPPPPPP",
      "  bKKKKKKKKKKKKK",
      "  bKKKKKKKKKKKKK",
      "  bKKKKKKKKKKKKK",
      "  bKKKKKKKKKKKKK",
      "  bLLLLLLLLLLLLL",
      "  bLLLLLLLLLLLLL",
      "  bkkkkkk    kkk",
      "  bbbbbbk    kbb",
      "  b     t    t  ",
      "  b      t    Q ",
      "  bb     t    Q ",
      "   b     t    Q ",
      "   b      t    Q",
      "   bb     t     ",
      "    b      t    "
    ],
    [
      "   N            ",
      "   N            ",
      "  RN            ",
      "  RN            ",
      "  bNPPPPP   O PP",
      "  bKKKKKKKKKKKKK",
      "  brKKKKKKKKKKKK",
      "  brKKKKkkkkkkKK",
      "  bKKKKrk    krK",
      "  bLLLLLk    kkL",
      "  bLLLLLkk    kL",
      "  bbLLLLLk    kL",
      "   bLLLLLk    kk",
      "   bLLLLLkk    k",
      "   bbLLLLLk    S",
      "    bLLLLLkk  SS"
    ]
  ]
}