{
  "name": "multi_laboratory1_3_base3",
  "refpalette": "c70cities:multi_laboratory1_3_base3_palette",
  "xsize": 16,
  "zsize": 16,
  "slices": [
    [
      "vabccccccccccccc",
      "vabccccccccccccc",
      "vabccccccccdcccc",
      "vabccccccccccccc",
      "vabccccccccccccc",
      "vabccccccccccccc",
      "vabccccccccccccc",
      "vabccccccccccccc",
      "vabeeffffffccccc",
      "vabccccccccdcccc",
      "vabccccccccccccc",
      "vabccccccccccccc",
      "vabccccccccccccc",
      "vabccccccccccccc",
      "vabccccccccccccc",
      "vabccccccccccccc"
    ],
    [
      "vabg h     i  j ",
      "vabkkl     m no ",
      "vabp  q    d  o ",
      "vabrstsuwxym  j ",
      "vabkkA BsBBmxCj ",
      "vabDEDEx  Am C F",
      "vabDDIDJ x m  K ",
      "vabDDLDDMJJm    ",
      "vab  NNDDOJm    ",
      "vabP  JD JPdmmmm",
      "vabPQ RD SPmQ   ",
      "vabPj RRDTPm    ",
      "vabPj RRDUPm    ",
      "vabPj RDDDPm  VV",
      "vabPWXDDD Pm   Y",
      "vabPPPPPPPPm   Z"
    ],
    [
      "vab        i  A ",
      "vab0       m    ",
      "vab1       d    ",
      "vab        m  2 ",
      "vab0x      3  4 ",
      "vabJ J     n    ",
      "vabJJ J    3    ",
      "vabD 5JJJ  3    ",
      "vabDDNN J6 m    ",
      "vabP      Pdm333",
      "vabP  JJ5 Pm    ",
      "vabP7  D  P8    ",
      "vabP7     P8    ",
      "vabP     DP8    ",
      "vabP    DDP8    ",
      "vabPPPPPPPPm    "
    ],
    [
      "vab        i    ",
      "vab        m    ",
      "vab        d    ",
      "vab        m    ",
      "vab        3    ",
      "vab        3    ",
      "vab        3    ",
      "vabJ 9 5   3    ",
      "vabDNNNN N m    ",
      "vabP      Pdm333",
      "vabP @  9 Pm    ",
      "vabP  5   P#    ",
      "vabP   $  P#    ",
      "vabP      P#    ",
      "vabP    D%P#    ",
      "vabPPPPPPPPm    "
    ],
    [
      "vab        m    ",
      "vab        m    ",
      "vab        d    ",
      "vab        m    ",
      "vab        m    ",
      "vab        m    ",
      "vab   DD   m    ",
      "vab  %%DD  m    ",
      "vabDDDD%%D m    ",
      "vabPD%D%% Pdmmmm",
      "vabPD^%%D Pm    ",
      "vabPD%%%D Pm    ",
      "vabP  %^D Pm    ",
      "vabP &    Pm    ",
      "vabP * DDDPm    ",
      "vabPPPPPPPPm    "
    ],
    [
      "vab(()(()((+-)--",
      "vab(([(()((+----",
      "vab((((((((d----",
      "vab((((((((+----",
      "vab(()((]((+- --",
      "vab(([(()((+-[--",
      "vab((](([((+-)--",
      "vab(()(()((+-)--",
      "vab((((((((+----",
      "vabP]]]]]]Pd{{{{",
      "vabP]}\\|`]P+((((",
      "vabP]\\|`:]P+((((",
      "vabP]\\`};]P+((((",
      "vabP]}\\`']P+(())",
      "vabP]]]]]]P+(()(",
      "vabPPPPPPPP+(()("
    ]
  ]
}