{
  "name": "multi_communitycenter_6_floor1",
  "refpalette": "c70cities:multi_communitycenter_6_floor1_palette",
  "xsize": 16,
  "zsize": 16,
  "slices": [
    [
      "                ",
      "                ",
      "                ",
      "                ",
      "                ",
      "                ",
      "                ",
      "                ",
      "aaaaaaaaaaaaaa  ",
      "b    bb    bba  ",
      "cccccccccccc a  ",
      "c  dd  e   c a  ",
      "c  fggggf  c a  ",
      "c  fggggf  cba  ",
      "c  fggggf  cba  ",
      "c          c a  "
    ],
    [
      "                ",
      "                ",
      "                ",
      "                ",
      "                ",
      "                ",
      "                ",
      "                ",
      "                ",
      "b    bb    bb   ",
      "                ",
      "                ",
      "    dde         ",
      "    ed      b   ",
      "      e     b   ",
      "                "
    ],
    [
      "                ",
      "                ",
      "                ",
      "                ",
      "                ",
      "                ",
      "                ",
      "                ",
      "                ",
      "b    bb    bb   ",
      "                ",
      "                ",
      "                ",
      "            b   ",
      "            b   ",
      "                "
    ],
    [
      "                ",
      "                ",
      "                ",
      "                ",
      "                ",
      "                ",
      "                ",
      "                ",
      "                ",
      "h    hh    hh   ",
      "                ",
      "                ",
      "                ",
      "            h   ",
      "            h   ",
      "                "
    ],
    [
      "                ",
      "                ",
      "                ",
      "                ",
      "                ",
      "                ",
      "                ",
      "iiiiiiiiiiiiiii ",
      "iiiiiiiiiiiiiii ",
      "jjjjjjjjjjjjjii ",
      "kkkkkkkkkkkkjii ",
      "kkkkkkkkkkkkjii ",
      "kkkkkkkkkkkkjii ",
      "kkkkkkkkkkkkjii ",
      "kkkkkkkkkkkkjii ",
      "kkkkkkkkkkkkjii "
    ],
    [
      "                ",
      "                ",
      "                ",
      "                ",
      "                ",
      "                ",
      "                ",
      "                ",
      "                ",
      "                ",
      "                ",
      "      ~         ",
      "                ",
      "                ",
      "                ",
      "                "
    ]
  ]
}