{
  "name": "multi_factory_0_ground",
  "refpalette": "c70cities:multi_factory_0_ground_palette",
  "xsize": 16,
  "zsize": 16,
  "slices": [
    [
      "zaazzzzzzzzzzzzz",
      "aaazzzzzzzzzzzzz",
      "aazbbbbbbbbbbbzz",
      "aaabbbbbbbbbbbzz",
      "aaabbbbbbbbbbbzz",
      "zaabbbbbbbbbbbzz",
      "zaabbbbbbbbbbbzz",
      "aaabbbbbbbbbbbzz",
      "zaabbbbbbbbbbbzz",
      "aaabbbbbbbbbbbzz",
      "aaabbbbbbbbbbbzz",
      "aaabbbbbbbbbbbzz",
      "zaabbbbbbbbbbbzz",
      "aaabbbbbbbbbbbzz",
      "zaabbbbbbbbbbbzz",
      "aaabbbbbbbbbbbzz"
    ],
    [
      "                ",
      "                ",
      "   ccccccccccc  ",
      "   cdeffdgh dc  ",
      "   ij    k  lc  ",
      "   c     mnnnc  ",
      "   co    p  lc  ",
      "   coq   gr  c  ",
      "   co    ssssc  ",
      "   co t     uc  ",
      "   c wxxyA j c  ",
      "   cmmmmmmmBmc  ",
      "   cddCdd    c  ",
      "      D      c  ",
      "             c  ",
      "             c  "
    ],
    [
      "                ",
      "                ",
      "   ccccccccccc  ",
      "   cd ffdg  dc  ",
      "   E     F  Ic  ",
      "   c     mnnnc  ",
      "   JK    L  Ic  ",
      "   JM    g   c  ",
      "   JM    ssssc  ",
      "   J        uc  ",
      "   c   N     c  ",
      "   cmJJJJmmOmc  ",
      "   cPQRQS    c  ",
      "      T      c  ",
      "             c  ",
      "             c  "
    ],
    [
      "                ",
      "                ",
      "   ccUVWcUVWcc  ",
      "   cd   dg  dc  ",
      "   J     g   c  ",
      "   c     mnnnc  ",
      "   J     g   c  ",
      "   J     g   c  ",
      "   J     ssssc  ",
      "   J        uc  ",
      "   c         c  ",
      "   cmJJJJmmmmc  ",
      "   c  X    YZc  ",
      "   0         c  ",
      "   0         c  ",
      "   0         c  "
    ],
    [
      "                ",
      "                ",
      "   ccccccccccc  ",
      "   cd   dg  dc  ",
      "  1c     g   c  ",
      "  1c     mnnnc  ",
      "  1c     g   c  ",
      "  1c     g   c  ",
      "  1c     ssssc  ",
      "  1c        uc  ",
      "   c         c  ",
      "   cmmmmmmmmmc  ",
      "   c  2      c  ",
      "  1c3        c  ",
      "  1c3        c  ",
      "  1c3        c  "
    ],
    [
      "                ",
      "                ",
      "   ccccccccccc  ",
      "   cd   dbbbdc  ",
      "   c    4bbbbc  ",
      "   c    4bbbbc  ",
      "   c    4bbbbc  ",
      "   c    4bbbbc  ",
      "   c    4bbbbc  ",
      "   c    4bbbuc  ",
      "   c    4bbbbc  ",
      "   cmmmmmmmmmc  ",
      "   c        5c  ",
      "   c         c  ",
      "   c         c  ",
      "   c         c  "
    ]
  ]
}