{
  "name": "multi_gallery_2_ground",
  "refpalette": "c70cities:multi_gallery_2_ground_palette",
  "xsize": 16,
  "zsize": 16,
  "slices": [
    [
      "GGGGGGGGGGGGGGGG",
      "GGGaaGaaaaGaaaaa",
      "GGaaaaaaGaaaaGaa",
      "GGaaGGGGGGaaGGGG",
      "bbaabbbGGaaGGvcG",
      "ccccccbGGaGGGvcG",
      "ccccccbGGaaGGvcG",
      "ccccccbGGaaGGvcG",
      "ccccccbGGaaGGvcG",
      "ccccccbGGaGGGvcG",
      "ccccccbdGGaGGvcG",
      "ccccccbGGaaGGvcG",
      "ccccccbGGaaGGvcG",
      "ccccccbGGaGGGvcG",
      "ccccccbGGaGGGvcG",
      "ccccccbGGaaGGvcG"
    ],
    [
      " e  e   e     e ",
      "e               ",
      "                ",
      "     e       e  ",
      "ff  fffg    hvie",
      " i    fhj  khv  ",
      "  ll ifh    hv  ",
      "i     fhm  mhvi ",
      "  ll  fhk  ehv  ",
      "    i fhm  nhv  ",
      " ill  fo   jhvi ",
      "    i fhk  khvi ",
      "i ll  fhm  phv  ",
      "      fhn  jhvi ",
      "  ll ifh   mhv p",
      "i     fhj   hv  "
    ],
    [
      "                ",
      "                ",
      "                ",
      "                ",
      "                ",
      "             q  ",
      "             r  ",
      "             s  ",
      "             r  ",
      "             t  ",
      "       o     s  ",
      "             r  ",
      "             u  ",
      "             w  ",
      "             s  ",
      "             q  "
    ],
    [
      "                ",
      "                ",
      "                ",
      "                ",
      "             x  ",
      "             r  ",
      "             u  ",
      "      yyy    u  ",
      "     yyyyy   A  ",
      "     yyoyy      ",
      "     yyoyy   q  ",
      "      yyy    x  ",
      "             r  ",
      "             s  ",
      "             B  ",
      "             q  "
    ],
    [
      "                ",
      "                ",
      "                ",
      "                ",
      "                ",
      "                ",
      "                ",
      "                ",
      "      yyy       ",
      "      yyy       ",
      "      yoy       ",
      "                ",
      "                ",
      "                ",
      "                ",
      "                "
    ],
    [
      "                ",
      "                ",
      "                ",
      "                ",
      "                ",
      "                ",
      "                ",
      "                ",
      "                ",
      "                ",
      "                ",
      "       o        ",
      "                ",
      "                ",
      "                ",
      "                "
    ]
  ]
}