{
  "name": "multi_condo1_0_floor4",
  "refpalette": "c70cities:multi_condo1_0_floor4_palette",
  "xsize": 16,
  "zsize": 16,
  "slices": [
    [
      "                ",
      "          a     ",
      "  bbbbbbbbaccccc",
      "  bdddddddaeeeee",
      "  bdffffffffgggf",
      "  bdfhhhhhhhhhhh",
      "  bdfhhhhhhhhhhh",
      "  bdfhhhhhhhhhhh",
      "  bdfhhhhhhhhhhh",
      "  bdfhhhhhhhhhhh",
      "  bdfhhhhhhhhhhh",
      "  bdfhhhhhhhhhhh",
      "  bdfiiihhhhhhhh",
      " aaafiiihhhhhhhh",
      "   efiiihhjjjjjj",
      "   efiiihhjkllll"
    ],
    [
      "                ",
      "          a     ",
      "          accccc",
      "   ddddddda     ",
      "   dffmmmfffn nf",
      "   dfo   pq!    ",
      "   dfr  stqu w p",
      "   dfxy stqA w p",
      "   dfB   pq     ",
      "   dfC qqqqD   D",
      "   dfC E       F",
      "   dfC q IJ    K",
      "   dfqLq MJ    K",
      " aaafN q  JOPQRS",
      "    fT q  ffffff",
      "    U! E  V     "
    ],
    [
      "                ",
      "          a     ",
      "          a     ",
      "          a     ",
      "    ffnnnfffn nf",
      "    fW   Xq     ",
      "    f     q     ",
      "    fY    q    Z",
      "    f0    q     ",
      "    fC qqqq1   1",
      "    fC 2        ",
      "    fC q  3     ",
      "    fq4q       5",
      " aaaf6 q  789@  ",
      "    f  q  ffffff",
      "    c  2  #     "
    ],
    [
      "                ",
      "          a     ",
      "          a     ",
      "          a     ",
      "    ffnnnfffnnnf",
      "    f     q     ",
      "    f     q     ",
      "    f     q     ",
      "    f     q     ",
      "    f  qqqq     ",
      "    f  q        ",
      "    f$ q        ",
      "    fqqq        ",
      " aaaf% q        ",
      "    f  q  ffffff",
      "    c  q  ^     "
    ],
    [
      "                ",
      "          a     ",
      "          a     ",
      "   &&&&&&&a     ",
      "   &ffffffffffff",
      "   &f     q     ",
      "   &f     q     ",
      "   &f     q     ",
      "   &f     q     ",
      "   &f  qqqq     ",
      "   &f  q        ",
      "   &f  q        ",
      "   &fqqq        ",
      " aaaf  q        ",
      "    f  q  ffffff",
      "    f  q  f     "
    ],
    [
      "                ",
      "          a     ",
      "          a*****",
      "   (((((((a     ",
      "   (ffffffffffff",
      "   (f)))))))))))",
      "   (f)))))))))))",
      "   (f)))))))))))",
      "   (f)))))))))))",
      "   (f)))))))))))",
      "   (f)))))))))))",
      "   (f)))))))))))",
      "   (f)))))))))))",
      " aaaf)))))))))))",
      "    f)))))ffffff",
      "    f)))))f     "
    ]
  ]
}