{
  "name": "multi_laboratory1_14_base5",
  "refpalette": "c70cities:multi_laboratory1_14_base5_palette",
  "xsize": 16,
  "zsize": 16,
  "slices": [
    [
      "   ab   cdc   ev",
      "    f   d d   gv",
      "    h  id dj  gv",
      "    h   d dkk gv",
      "    h   cdckk gv",
      "    h   l l   gv",
      "    h   mdm   gv",
      "   nb  opqpr  ev",
      "    s  o  tr  gv",
      "    s         gv",
      "    u         gv",
      "    u         gv",
      "    s         gv",
      "wwwws         gv",
      "xxxxwgggggggggwv",
      "vvvvvvvvvvvvvvvv"
    ],
    [
      "    b    q    ev",
      "    h    q    gv",
      "    h   yAy   gv",
      "    h    qB   gv",
      "    h         gv",
      "    h         gv",
      "    h    C    gv",
      "    b   q q   ev",
      "    s   q q   gv",
      "    s         gv",
      "    u         gv",
      "    u         gv",
      "    s         gv",
      "wwwws         gv",
      "xxxxwgggggggggwv",
      "vvvvvvvvvvvvvvvv"
    ],
    [
      "    b         ev",
      "    h         gv",
      "    h         gv",
      "    h         gv",
      "    h         gv",
      "    h         gv",
      "    h         gv",
      "    b         ev",
      "    s         gv",
      "    s         gv",
      "    u         gv",
      "    u         gv",
      "    s         gv",
      "wwwws         gv",
      "xxxxwgggggggggwv",
      "vvvvvvvvvvvvvvvv"
    ],
    [
      "    b         ev",
      "    h         gv",
      "    h         gv",
      "    h         gv",
      "    h         gv",
      "    h         gv",
      "    h         gv",
      "    b         ev",
      "    s         gv",
      "    s         gv",
      "    u         gv",
      "    u         gv",
      "    s         gv",
      "wwwws         gv",
      "xxxxwgggggggggwv",
      "vvvvvvvvvvvvvvvv"
    ],
    [
      "    b         ev",
      "    s         gv",
      "    s         gv",
      "    s         gv",
      "    s         gv",
      "    s         gv",
      "    s         gv",
      "    b         ev",
      "    s         gv",
      "    s         gv",
      "    s         gv",
      "    s         gv",
      "    s         gv",
      "wwwws         gv",
      "xxxxwgggggggggwv",
      "vvvvvvvvvvvvvvvv"
    ],
    [
      "eeeeseeeeeeeeewv",
      "eeeeseeeeeeeeewv",
      "eeeeseeeeeeeeewv",
      "eeeeseeDEEEDeewv",
      "eeeeseeDEEEDeewv",
      "eeeeseeeeeeeeewv",
      "eeeeseeeeeeeeewv",
      "eeeeseeeeeeeeewv",
      "eeeeseeeeeeeeewv",
      "eeeeseeeeeeeeewv",
      "eeeeseeEDEEEeewv",
      "eeeeseeEDEEEeewv",
      "eeeeseeeeeeeeewv",
      "wwwwseeeeeeeeewv",
      "xxxxwwwwwwwwwwwv",
      "vvvvvvvvvvvvvvvv"
    ]
  ]
}