{
  "name": "multi_megatower1_0_ground",
  "refpalette": "c70cities:multi_megatower1_0_ground_palette",
  "xsize": 16,
  "zsize": 16,
  "slices": [
    [
      "HHHGaGGGGaGGGGaG",
      "HHHGGaaGaGaaGaaa",
      "HHHGGGaGGGGGGaGG",
      "HHHvvvvvvvvvvvvv",
      "HHHvvvvvvvvvvvvv",
      "HHHvvvvvvvvvvvvv",
      "HHHvvvbvvvvvvbvv",
      "HHHvvvvvvvvvvvvv",
      "HHHvvvvvvvvvvvvv",
      "HHHvvvvvvvvvvvvv",
      "HHHvvvvvvvvvvvvv",
      "HHHvvvvvvvvvvvvv",
      "HHHvvvvvvvvvvvvv",
      "HHHvvvbvvvvvvbvv",
      "HHHvvvvvvvvvvv  ",
      "HHHvvvvvvvvvvv  "
    ],
    [
      "                ",
      "                ",
      "   c d dddddc dd",
      "   eeefeeeeeefee",
      "   e!g       hij",
      "   eg       ig h",
      "  kfg bllllllbll",
      "   e  mnoooopm q",
      "   e  m    r m  ",
      "   e  ms     mt ",
      "   e  m      luw",
      "   e  m      x  ",
      "   e  m      lgy",
      "  kf  bABAAAAbAA",
      "   e  mC DDEEF  ",
      "   e  I      F  "
    ],
    [
      "                ",
      "                ",
      "                ",
      "   eeefeeeeeefee",
      "   eg           ",
      "   e            ",
      "   f  bllllllbll",
      "   e  mJKJLJJm M",
      "   e  m      m  ",
      "   e  m      m  ",
      "   e  m      luN",
      "   e  m      O  ",
      "   e  m      l  ",
      "   f  bAPAAAAbAA",
      "   e  m    QRFSS",
      "   e  T      FSU"
    ],
    [
      "                ",
      "                ",
      "      V      V  ",
      "   eeefeeeeeefee",
      "   eg g         ",
      "   e         g  ",
      "   f  bllllllbll",
      "   e  mLLKJLKm  ",
      "   e  m      m  ",
      "   e  m      m  ",
      "   e  m      luu",
      "   e  m     Wl  ",
      "   e  m      l  ",
      "   f  bAAAAAAbAA",
      "   e  m X   YFSS",
      "   e  m      FSS"
    ],
    [
      "                ",
      "                ",
      "                ",
      "   eeefeeeeeefee",
      "   e  g     gZ  ",
      "   e  g     ggg ",
      "   f  bllllllbll",
      "   e  mJJLJJJl  ",
      "   e  m      l  ",
      "   e  m      l  ",
      "   e  m      l00",
      "   e  m      l  ",
      "   e  m      lg ",
      "   f  b000000bAA",
      "   e  0      0  ",
      "   e  0      0  "
    ],
    [
      "                ",
      "                ",
      "                ",
      "   eeefeeeeeefee",
      "   e11b111111b11",
      "   e11b111111b11",
      "  1fbbbbbbbbbbbb",
      "  1011b111111bll",
      "  1011b111111bll",
      "  1011b111111bll",
      "  1011b111111bll",
      "  1011b111111b11",
      "  1011b111111b11",
      "  1fbbbbbbbbbbbb",
      "   e11b111111b  ",
      "   e11b111111b  "
    ]
  ]
}