{
  "name": "multi_laboratory1_4_base6",
  "refpalette": "c70cities:multi_laboratory1_4_base6_palette",
  "xsize": 16,
  "zsize": 16,
  "slices": [
    [
      "vabbbbcbbbbcbbbb",
      "vabbbbbbbbbbbbbb",
      "vabbbbbbbbbbbbbb",
      "vabbbbbbbbbbbbbb",
      "vabbbbbbbbbbbbbb",
      "vabbbbbbbbbbbbbb",
      "vabbbbbbbbbbbbbb",
      "vabbbbcbbbbcbbbb",
      "vabbbbbbbbbbbbbb",
      "vabbbbbbbbbbbbbb",
      "vabbbbbbbbbbbbbb",
      "vabbbbbbbbbbbbbb",
      "vabbbbbbbbbbbbbb",
      "vabbbbbbbbbbaaaa",
      "vaaaaaaaaaaadddd",
      "vvvvvvvvvvvvvvvv"
    ],
    [
      "vceeeecf   c  g ",
      "vahiihe    e jg ",
      "va  k e    e    ",
      "va    e    e    ",
      "va l  e    e    ",
      "vamn  e    e    ",
      "vaop ke    e  g ",
      "vcop  c    c qg ",
      "va!pk e    e rg ",
      "vahn  s    e    ",
      "va    t    t    ",
      "va    u    u    ",
      "vaw w s    e    ",
      "vamxxme    eaaaa",
      "vaaaaaaaaaaadddd",
      "vvvvvvvvvvvvvvvv"
    ],
    [
      "vceeeec    c  y ",
      "vaA  Be    C    ",
      "va    C    C    ",
      "va    C    C    ",
      "va    C    C    ",
      "vaDB  C    C    ",
      "vaE   e    C    ",
      "vcE   c    c  y ",
      "va    e    e  F ",
      "vaI   s    e    ",
      "va    J    J    ",
      "va    K    K    ",
      "va    s    e    ",
      "vaLLLLe    eaaaa",
      "vaaaaaaaaaaadddd",
      "vvvvvvvvvvvvvvvv"
    ],
    [
      "vceeeec    c    ",
      "va    e    C    ",
      "va    C    C    ",
      "va    C    C    ",
      "va    C    C    ",
      "va    C    C    ",
      "va    e    C    ",
      "vc    c    c    ",
      "va    e    e    ",
      "va    s    e    ",
      "va    s    s    ",
      "va    s    s    ",
      "va    s    e    ",
      "vaMMMMe    eaaaa",
      "vaaaaaaaaaaadddd",
      "vvvvvvvvvvvvvvvv"
    ],
    [
      "vceeeec    c    ",
      "va    e    C    ",
      "va    e    C    ",
      "va    e    C    ",
      "va    e    C    ",
      "va    e    C    ",
      "va    e    C    ",
      "vc    c    c    ",
      "va    e    e    ",
      "va    e    e    ",
      "va    e    s    ",
      "va    e    s    ",
      "va    e    e    ",
      "va    e    eaaaa",
      "vaaaaaaaaaaadddd",
      "vvvvvvvvvvvvvvvv"
    ],
    [
      "vceeeec    c    ",
      "vaNNNNe    C    ",
      "vaNOONe    C    ",
      "vaNNNNe    C    ",
      "vaNNNNe    C    ",
      "vaNOONe    C    ",
      "vaNNNNe    C    ",
      "vceeeec    c    ",
      "vaNNNNe    e    ",
      "vaNOONe    e    ",
      "vaNNNNe    s    ",
      "vaNNNNe    s    ",
      "vaNOONe    e    ",
      "vaNNNNe    eaaaa",
      "vaaaaaaaaaaadddd",
      "vvvvvvvvvvvvvvvv"
    ]
  ]
}