{
  "name": "multi_condo1_0_base1",
  "refpalette": "c70cities:multi_condo1_0_base1_palette",
  "xsize": 16,
  "zsize": 16,
  "slices": [
    [
      "vvvvvvvvvvvvvvvv",
      "vaaaaaaaaaaaaaaa",
      "vbbbbbbbbbbbbbbb",
      "vbHHHHHHHHHHHHHH",
      "vbHHHHHHHHHHHHHH",
      "vbHHHHHHHHHHHHHH",
      "vbHHHHHHHHHHHHHH",
      "vbHHHHHHHHHHHHHH",
      "vbHHHHHHHHHHHHHH",
      "vbHHHHHHHHHHHHHH",
      "vbHHHHHHHHHHHHHH",
      "vbHHHHHHHHHHHHHH",
      "vbHHHHHHHHHHHHHH",
      "vbHHHHHHHHHHHHHH",
      "vbHHHHHHHHHHHHHH",
      "vbHHHHHHHHHHHHHH"
    ],
    [
      "vvvvvvvvvvvvvvvv",
      "vaaaaaaaaaaaaaaa",
      "vbbbbbbbbbbbbbbb",
      "vbccc           ",
      "vbd e           ",
      "vbf g  hhhhhhh  ",
      "vbd e  d eid e  ",
      "vbf g  f gif g  ",
      "vbd e  d eid e  ",
      "vbf g  f gif g  ",
      "vbd e  djeid e  ",
      "vbf g  f gif g  ",
      "vbd e  d eid e  ",
      "vbf g  f gif g  ",
      "vbd e  ccccccc  ",
      "vbf g           "
    ],
    [
      "vvvvvvvvvvvvvvvv",
      "vaaaaaaaaaaaaaaa",
      "vbbbbbbbbbbbbbbb",
      "vb              ",
      "vb              ",
      "vb              ",
      "vb              ",
      "vb              ",
      "vb              ",
      "vb              ",
      "vb              ",
      "vb              ",
      "vb              ",
      "vb              ",
      "vb              ",
      "vb              "
    ],
    [
      "vvvvvvvvvvvvvvvv",
      "vaaaaaaaaaaaaaaa",
      "vbbbbbbbbbbbbbbb",
      "vb              ",
      "vb              ",
      "vb              ",
      "vb              ",
      "vb              ",
      "vb              ",
      "vb              ",
      "vb              ",
      "vb              ",
      "vb              ",
      "vb              ",
      "vb              ",
      "vb              "
    ],
    [
      "vvvvvvvvvvvvvvvv",
      "vaaaaaaaaaaaaaaa",
      "vbbbbbbbbbbbbbbb",
      "vbkkkkkkkkbkkkkk",
      "vbk       b     ",
      "vbk       b     ",
      "vbk       b     ",
      "vbk       b     ",
      "vbk       b     ",
      "vbk       b     ",
      "vbk       b     ",
      "vbk       b     ",
      "vbk       b     ",
      "vb!kkkkkkkbkkkkk",
      "vbk       b     ",
      "vbk       b     "
    ],
    [
      "vvvvvvvvvvvvvvvv",
      "vaaaaaaaaaaaaaaa",
      "vbbbbbbbbbbbbbbb",
      "vbllllllllblllll",
      "vbllllllllblllll",
      "vbllllllllblllll",
      "vbllllllllblllll",
      "vbllllllllblllll",
      "vbllllllllblllll",
      "vbllllllllblllll",
      "vbllllllllblllll",
      "vbllllllllblllll",
      "vbllllllllblllll",
      "vbllllllllblllll",
      "vbllllllllblllll",
      "vbllllllllblllll"
    ]
  ]
}