{
  "name": "multi_laboratory1_9_ground",
  "refpalette": "c70cities:multi_laboratory1_9_ground_palette",
  "xsize": 16,
  "zsize": 16,
  "slices": [
    [
      "aaaaabccccbaaaaa",
      "aaaaacbccbcaaaaa",
      "aaaaaacbbcaaaaaa",
      "dddaaaaaaaaaaddd",
      "dddaaaaaaaaaaddd",
      "dddaaaaaaaaaaddd",
      "dddaaaaaaaaaaddd",
      "aaaaaaaaaaaaaaaa",
      "aaaaaaaaaaaaaaaa",
      "aaaaaaaaaaaaaaaa",
      "eeeeeeeeeeeeeeee",
      "ffffffffffffffff",
      "fffffff ffffffff",
      "ffffffffffffffff",
      "ggggggggggggzggg",
      "gzzgzggzzzgzgzzz"
    ],
    [
      "   h ijkkki l   ",
      "  mn kikkok pm  ",
      "qqqr  ksik  tqqq",
      "uwun        pxuy",
      " w n AAAAAA p   ",
      "BCBn  D  D  pCCE",
      "   n FFFFFF p   ",
      "q  n  I  J  p  q",
      "q              q",
      "q    m KL m    q",
      "MNNNNeO  OeNNNNM",
      "                ",
      "                ",
      "              PQ",
      "            R   ",
      "  R           R "
    ],
    [
      "   h        l   ",
      "  Sn        pS  ",
      "qqq          qqq",
      " w n        p   ",
      " w n TTTTTT p   ",
      "UCUn        pCCV",
      "   n W      p   ",
      "q  n        p  q",
      "q              q",
      "q    S XY S    q",
      "MNNNZeO  OeZNNNM",
      "                ",
      "                ",
      "             PQQ",
      "                ",
      "                "
    ],
    [
      "   h        l   ",
      "  Sn        pS  ",
      "qqq          qqq",
      " w n        p   ",
      " w n TTTTTT p   ",
      "CCCn        pCCC",
      "   n        p   ",
      "q  n        p  q",
      "q              q",
      "q    S    S    q",
      "MNNNZeOOOOeZNNNM",
      "                ",
      "                ",
      "            PQ01",
      "                ",
      "                "
    ],
    [
      "   h        l   ",
      "   n        p   ",
      "qqq          qqq",
      " w n        p   ",
      " w n TTTTTT p   ",
      "CCCn        pCCC",
      "   n        p   ",
      "q  n        p  q",
      "q  n        p  q",
      "q  n        p  q",
      "MNNNZeOOOOeZNNNM",
      "                ",
      "                ",
      "           PQ110",
      "                ",
      "                "
    ],
    [
      "222n        p222",
      "222n22222222p222",
      "qqq3444444445qqq",
      "666n22222222p666",
      "676n2TTTTTT2p686",
      "666n22222222p666",
      "676n22922922p676",
      "q66n22222222p66q",
      "q76n22222222p68q",
      "q66n22222222p66q",
      "MNNNNeNNNNeNNNNM",
      "                ",
      "                ",
      "          PQ1100",
      "                ",
      "                "
    ]
  ]
}