{
  "name": "multi_convenientstore_2_ground",
  "refpalette": "c70cities:multi_convenientstore_2_ground_palette",
  "xsize": 16,
  "zsize": 16,
  "slices": [
    [
      "GGGGGGGGGGGaHHHG",
      "GGGGGGGGGGGaHHHG",
      "aaaaaaaaaaaaHHHG",
      "HHHHHHHHHHHHHHHG",
      "HHHHHHHHHHHHHHHG",
      "HHHHHHHHHHHHHHHG",
      "HHHHHHHHHHHHHHHG",
      "HHHHHHHHHHHHHHHG",
      "HHHHHHHHHHHHHHHG",
      "HHHHHHHHHHHHHHHG",
      "HHHHHHHHHHHHHHHG",
      "HHHHHHHHHHHHHHHG",
      "HHHHHHHHHHHHHHHG",
      "HHHHHHHHHHHHHHHb",
      "HHHHHHHHHHHHHHHb",
      "HHHHHHHHHHHHHHHb"
    ],
    [
      "           c    ",
      "           c    ",
      "ccccc ccc cc    ",
      "dededededed fg  ",
      "        h       ",
      "ijijijijiji k   ",
      "        g       ",
      "         ~      ",
      "    l           ",
      " k              ",
      "dededededed     ",
      "             m  ",
      "ijijijijiji     ",
      "cccccccccccc   n",
      "aaaaaaaaaaaaooon",
      "aaaaaaaaaaaaooon"
    ],
    [
      "                ",
      "                ",
      "                ",
      "                ",
      "                ",
      "                ",
      "                ",
      "         ~      ",
      "                ",
      "                ",
      "                ",
      "                ",
      "                ",
      "                ",
      "       p        ",
      " qr r rpstss    "
    ],
    [
      "                ",
      "                ",
      "                ",
      "                ",
      "                ",
      "                ",
      "                ",
      "         ~      ",
      "                ",
      "                ",
      "                ",
      "                ",
      "                ",
      "                ",
      "       p        ",
      " qr r rpsuss    "
    ],
    [
      "                ",
      "                ",
      "                ",
      "                ",
      "                ",
      "                ",
      "                ",
      "         ~      ",
      "                ",
      "                ",
      "                ",
      "                ",
      "                ",
      "                ",
      "       p        ",
      "wxr r rps ss    "
    ],
    [
      "                ",
      "                ",
      "                ",
      "                ",
      "                ",
      "                ",
      "                ",
      "         ~      ",
      "                ",
      "                ",
      "                ",
      "                ",
      "                ",
      "                ",
      "       p        ",
      "  r r rps ss    "
    ]
  ]
}