{
  "name": "multi_laboratory1_4_base4",
  "refpalette": "c70cities:multi_laboratory1_4_base4_palette",
  "xsize": 16,
  "zsize": 16,
  "slices": [
    [
      "zaabbbbbbbbcbbbb",
      "zaabbbbbbbbbbbbb",
      "zaabbbbbbbbbbbbb",
      "zaabbbbbbbbbbbbb",
      "zaabbbbbbbbbbbbb",
      "zaabbbbbbbbbbbbb",
      "zaabbbbbbbbbbbbb",
      "zaabbbbbbbbcbbbb",
      "zaaddddddddbbbbb",
      "zaaddddddddbbbbb",
      "zaaddddddddbbbbb",
      "zaaddddddddbbbbb",
      "zaaddddddddbbb!b",
      "zaaaaaaaaaaaaaaa",
      "zaaaaaaaaaaaeeee",
      "zzzzzzzzzzzzzzzz"
    ],
    [
      "zaaffffffffc   g",
      "zaah ij  klf   g",
      "zaam    knof   p",
      "zaaq rr  kof  ss",
      "zaaq rr t  f    ",
      "zaau       w    ",
      "zaah xy    f    ",
      "zaaffffffffc    ",
      "zaaAABBBBAAf    ",
      "zaa        C    ",
      "zaaDEDEFEDEf    ",
      "zaa I I I If    ",
      "zaaJIJIJIJIfKLL ",
      "zaaaaaaaaaaaaaaa",
      "zaaaaaaaaaaaeeee",
      "zzzzzzzzzzzzzzzz"
    ],
    [
      "zaaffffffffc    ",
      "zaaM       f    ",
      "zaa        f    ",
      "zaa        f   N",
      "zaa        f    ",
      "zaa        O    ",
      "zaaM       f    ",
      "zaaffffffffc    ",
      "zaaMPPPPPPMf    ",
      "zaa        Q    ",
      "zaaRERESEREf    ",
      "zaa I I I If    ",
      "zaa I I I If    ",
      "zaaaaaaaaaaaaaaa",
      "zaaaaaaaaaaaeeee",
      "zzzzzzzzzzzzzzzz"
    ],
    [
      "zaaffffffffc    ",
      "zaaM       f    ",
      "zaa        fT   ",
      "zaa        fT   ",
      "zaa        f    ",
      "zaa        U    ",
      "zaaM       f    ",
      "zaaffffffffc    ",
      "zaa PPPPPP f    ",
      "zaa        f    ",
      "zaaEEEEEEEEf    ",
      "zaa I I I If    ",
      "zaa I I I If    ",
      "zaaaaaaaaaaaaaaa",
      "zaaaaaaaaaaaeeee",
      "zzzzzzzzzzzzzzzz"
    ],
    [
      "zaaffffffffc    ",
      "zaa        f    ",
      "zaa        f    ",
      "zaa        f    ",
      "zaa        f    ",
      "zaa        f    ",
      "zaa        f    ",
      "zaaffffffffc    ",
      "zaaVVVVVVVVf    ",
      "zaaVVVVVVVVf    ",
      "zaaVVVVVVVVf    ",
      "zaaVVVVVVVVf    ",
      "zaaWV!VWVWVf    ",
      "zaaaaaaaaaaaaaaa",
      "zaaaaaaaaaaaeeee",
      "zzzzzzzzzzzzzzzz"
    ],
    [
      "zeaffffffffcXXYX",
      "zeaZZZZZZZZUXXYX",
      "zeaZ0ZZZZ1ZUXX2X",
      "zeaZZZZZZZZUXX22",
      "zeaZZZZZZZZUXXXX",
      "zeaZ3ZZZZ3ZUXXXX",
      "zeaZZZZZZZZUXXXX",
      "zeaffffffffcffff",
      "zea44444444f5555",
      "zea4 4 4 4 f5Y55",
      "zea4 4 4 4 f5Y55",
      "zea4 4 4 4 f5255",
      "zea4 4 4 4 f5555",
      "zeaaaaaaaaaaaaaa",
      "zeeeeeeeeeeeeeee",
      "zzzzzzzzzzzzzzzz"
    ]
  ]
}