{
  "name": "multi_megatower1_7_floor11",
  "refpalette": "c70cities:multi_megatower1_7_floor11_palette",
  "xsize": 16,
  "zsize": 16,
  "slices": [
    [
      "aaabc           ",
      "aaabd           ",
      "aaabd           ",
      "aaabd           ",
      "aaefgh          ",
      "aaabc           ",
      "aaabc           ",
      "aaabc           ",
      "aaabd           ",
      "aaabd           ",
      "aaabd           ",
      "aaefgh          ",
      "aaabc           ",
      "aaabc           ",
      "aaabc           ",
      "aaabd           "
    ],
    [
      "i j c           ",
      "  j d           ",
      "k j d           ",
      "l!j d           ",
      "mme gh          ",
      "  j c           ",
      " nj c           ",
      "ooj c           ",
      " nj d           ",
      "ooj d           ",
      " nj d           ",
      "mme gh          ",
      "  j c           ",
      "  j c           ",
      "p j c           ",
      "  j d           "
    ],
    [
      "  q c           ",
      "  q d           ",
      "  q d           ",
      " rj d           ",
      "mme gh          ",
      "  j c           ",
      " sj c           ",
      "ooj c           ",
      " sj d           ",
      "ooj d           ",
      " sj d           ",
      "mme gh          ",
      "  j c           ",
      "  q c           ",
      "  q c           ",
      "  q d           "
    ],
    [
      "  t c           ",
      "  t d           ",
      "  t d           ",
      " rj d           ",
      "mme gh          ",
      "  j c           ",
      "  j c           ",
      "ooj c           ",
      "  j d           ",
      "ooj d           ",
      "  j d           ",
      "mme gh          ",
      "  j c           ",
      "  t c           ",
      "  t c           ",
      "  t d           "
    ],
    [
      "uuj c           ",
      "uuj d           ",
      "uuj d           ",
      "uuj d           ",
      "mme gh          ",
      "wwj c           ",
      "wxj c           ",
      "wwj c           ",
      "wxj d           ",
      "wwj d           ",
      "wxj d           ",
      "mme gh          ",
      "uuj c           ",
      "uuj c           ",
      "uuj c           ",
      "uuj d           "
    ],
    [
      " yA c           ",
      "ByA d           ",
      " yA d           ",
      " yA d           ",
      "CCeDgh          ",
      "ByA c           ",
      "yyA c           ",
      "ByA c           ",
      "yyA d           ",
      " yA d           ",
      "yyA d           ",
      "CCeDgh          ",
      "ByA c           ",
      " yA c           ",
      " yA c           ",
      "ByA d           "
    ]
  ]
}