{
  "name": "multi_megatower1_3_base2",
  "refpalette": "c70cities:multi_megatower1_3_base2_palette",
  "xsize": 16,
  "zsize": 16,
  "slices": [
    [
      "vvvvvvvvvvvvvvvv",
      "aaaaaaaaaaaaaaaa",
      "aaaaaaaaaaaaaaaa",
      "vvvvvvvvvvvvvvvv",
      "vvvvvvvvvvvvvvvv",
      "HHHHHHHHHHHHHHHH",
      "HHHHbHHHHHHbHHHH",
      "HHHHHHHHHHHHHHHH",
      "HHHHHHHHHHHHHHHH",
      "HHHHHHHHHHHHHHHH",
      "HHHHHHHHHHHHHHHH",
      "HHHHHHHHHHHHHHHH",
      "HHHHHHHHHHHHHHHH",
      "vvvvbHHHHHHbHHHH",
      "vcccvHHHHHHHHHHH",
      "vdddvHHHHHHHHHHH"
    ],
    [
      "vvvvvvvvvvvvvvvv",
      "aaaaaaaaaaaaaaaa",
      "aaaaaaaaaaaaaaaa",
      "vvvvvvvvvvvvvvvv",
      "eeeeeeeeeeeeeeee",
      "fgfg fgfgfg fgfg",
      "    b      bh   ",
      "ijijkijijijkijij",
      "                ",
      "                ",
      "                ",
      "                ",
      "    lfgfgfglfgfg",
      "mmmmb   n  b    ",
      "occcpijijij ijij",
      "odqqp           "
    ],
    [
      "vvvvvvvvvvvvvvvv",
      "aaaaaaaaaaaaaaaa",
      "aaaaaaaaaaaaaaaa",
      "vvvvvvvvvvvvvvvv",
      "                ",
      "                ",
      "    b      b    ",
      "                ",
      "                ",
      "                ",
      "                ",
      "                ",
      "                ",
      "mmmmb      b    ",
      "occcp           ",
      "odqqp           "
    ],
    [
      "vvvvvvvvvvvvvvvv",
      "aaaaaaaaaaaaaaaa",
      "aaaaaaaaaaaaaaaa",
      "vvvvvvvvvvvvvvvv",
      "                ",
      "                ",
      "    b      b    ",
      "                ",
      "                ",
      "                ",
      "                ",
      "                ",
      "                ",
      "mmmmb      b    ",
      "occcp           ",
      "odqqp           "
    ],
    [
      "vvvvvvvvvvvvvvvv",
      "aaaaaaaaaaaaaaaa",
      "aaaaaaaaaaaaaaaa",
      "vvvvvvvvvvvvvvvv",
      "                ",
      "    r      r    ",
      "    b      b    ",
      "                ",
      "                ",
      "                ",
      "                ",
      "                ",
      "                ",
      "mmmmb      b    ",
      "occcp           ",
      "odddp           "
    ],
    [
      "vvvvvvvvvvvvvvvv",
      "aaaaaaaaaaaaaaaa",
      "aaaaaaaaaaaaaaaa",
      "vvvvvvvvvvvvvvvv",
      "vvvvvvvvvvvvvvvv",
      "ssssssssssssssss",
      "bbbbbbbbbbbbbbbb",
      "ssssbssssssbssss",
      "ssssbssssssbssss",
      "ssssbssssssbssss",
      "ssssbssssssbssss",
      "ssssbssssssbssss",
      "ssssbssssssbssss",
      "bbbbbbbbbbbbbbbb",
      "bcccbsssssssssss",
      "b   bsssssssssss"
    ]
  ]
}