{
  "name": "multi_laboratory1_0_base2",
  "refpalette": "c70cities:multi_laboratory1_0_base2_palette",
  "xsize": 16,
  "zsize": 16,
  "slices": [
    [
      "zzzzzzzzzzzzzzzz",
      "zaaaaaaaaaaaaaaa",
      "zabbbbbbbbbbcccc",
      "zabdddddddde    ",
      "zabdddddddde    ",
      "zabddddddddeeeee",
      "zabddddddddfffff",
      "zabd!ddddddfffff",
      "zabffffffffeffff",
      "zabddddddddfffff",
      "zabddddddddfffff",
      "zabddddddddfffff",
      "zabddddddddfffff",
      "zabddddddddfffff",
      "zabddddddddfffff",
      "zabffffffffeffff"
    ],
    [
      "zzzzzzzzzzzzzzzz",
      "zaaaaaaaaaaaaaaa",
      "zabbbbbbbbbbcccc",
      "zabghghghghi    ",
      "zabg g g g i    ",
      "zabjkjkjkjkiiiii",
      "zab        l   m",
      "zabnnoooonni   p",
      "zabiiiiiiiie   q",
      "zabrrssssrri   t",
      "zab        u   t",
      "zab        i   t",
      "zabwxwxwxwxi   t",
      "zab y y y yi   q",
      "zabAyAyAyAyi    ",
      "zabiiiiiiiie    "
    ],
    [
      "zzzzzzzzzzzzzzzz",
      "zaaaaaaaaaaaaaaa",
      "zabbbbbbbbbbcccc",
      "zabg g g g i    ",
      "zabg g g g i    ",
      "zabjBjBjBjBiiiii",
      "zab        C    ",
      "zabDEEEEEEDi    ",
      "zabiiiiiiiie   F",
      "zabDIIIIIIDi   J",
      "zab        K    ",
      "zab        i   L",
      "zabMxMxMxMxi   N",
      "zab y y y yi   F",
      "zab y y y yi    ",
      "zabiiiiiiiie    "
    ],
    [
      "zzzzzzzzzzzzzzzz",
      "zaaaaaaaaaaaaaaa",
      "zabbbbbbbbbbcccc",
      "zabg g g g i    ",
      "zabg g g g i    ",
      "zabjjjjjjjjiiiii",
      "zab        i    ",
      "zab EEEEEE i    ",
      "zabiiiiiiiie   D",
      "zab IIIIII i    ",
      "zab        i    ",
      "zab        i   O",
      "zabxxxxxxxxi    ",
      "zab y y y yi   D",
      "zab y y y yi    ",
      "zabiiiiiiiie    "
    ],
    [
      "zzzzzzzzzzzzzzzz",
      "zaaaaaaaaaaaaaaa",
      "zabbbbbbbbbbcccc",
      "zabPQPQPQPQi    ",
      "zabPPPPPPPPi    ",
      "zabPPPPPPPPiiiii",
      "zabPPPPPPPPi    ",
      "zabPPPPPPPPi    ",
      "zabiiiiiiiie    ",
      "zabPPPPPPPPi    ",
      "zabPPPPPPPPi    ",
      "zabPPPPPPPPi    ",
      "zabPPPPPPPPi    ",
      "zabPPPPPPPPi    ",
      "zabQP!PQPQPi    ",
      "zabiiiiiiiie    "
    ],
    [
      "zzzzzzzzzzzzzzzz",
      "zaaaaaaaaaaaaaaa",
      "zabbbbbbbbbbcccc",
      "zab R R R Ri    ",
      "zab R R R Ri    ",
      "zab R R R Riiiii",
      "zab R R R RiSSSS",
      "zab RRRRRRRiSSSS",
      "zabiiiiiiiieSSSS",
      "zabRRRRRRRRiSSSS",
      "zabR R R R iSSSS",
      "zabRTRTRTRTiSSSS",
      "zabRURTRTRTiSSSS",
      "zabRTRTRTRTiSSSS",
      "zabRTRTRTRTiSSSS",
      "zabiiiiiiiieVVVV"
    ]
  ]
}