{
  "name": "multi_militarybase_0_base4",
  "refpalette": "c70cities:multi_militarybase_0_base4_palette",
  "xsize": 16,
  "zsize": 16,
  "slices": [
    [
      "vvvvvvvvvvvvvvvv",
      "vaaaavaaaaaaavaa",
      "vaaaabaaaaaaabaa",
      "vaaaabaaaaaaabaa",
      "vaaaabaaaaaaabaa",
      "vvbbbvbbbbbbbvbb",
      "vaaaabaaaaaaabaa",
      "vaaaabaaaaaaabaa",
      "vaaaabaaaaaaabaa",
      "vaaaabaaaaaaavaa",
      "vaaaabaaaaaaabaa",
      "vaaaabaaaaaaabaa",
      "vaaaabaaaaaaabaa",
      "vvbbbbbbbbbbbvbb",
      "vccccccccccccbdd",
      "vccccccccccccbdd"
    ],
    [
      "vvvvvvvvvvvvvvvv",
      "veeffvgggggggvhh",
      "vi   jklmnlklohh",
      "ve   p       ohh",
      "vi   j       ohh",
      "vvqqqv       vhh",
      "v!r          ohh",
      "vgs          ohh",
      "vgt     uwu  oxx",
      "vgl     yAB Cv x",
      "vgD     uEu  o  ",
      "vgF          I  ",
      "vgt          o  ",
      "vv           vhh",
      "v             lJ",
      "v               "
    ],
    [
      "vvvvvvvvvvvvvvvv",
      "veK  vLMLlNnOvPP",
      "v    j       o  ",
      "vQ   R       o  ",
      "v    j       oSS",
      "vvqqqv       vhh",
      "vT           ohh",
      "vl           ohh",
      "vt      UUU  o  ",
      "vV      UWU Cv  ",
      "vt      UUU  o  ",
      "vX           I  ",
      "vl           o  ",
      "vv           vhh",
      "v               ",
      "vY              "
    ],
    [
      "vvvvvvvvvvvvvvvv",
      "v    v       v Z",
      "v    j       o  ",
      "v    j       o  ",
      "v    j       o  ",
      "vvqqqv       v  ",
      "v            o  ",
      "v            oSS",
      "v            ohh",
      "v           Cvhh",
      "v            o00",
      "v            o  ",
      "v            o11",
      "vv           vhh",
      "v               ",
      "v               "
    ],
    [
      "vvvvvvvvvvvvvvvv",
      "v    v       v  ",
      "v    j       o  ",
      "v    j       o  ",
      "v    j       o  ",
      "vvqqqv2222222v  ",
      "v    2       o  ",
      "v    2       o  ",
      "v    2       o  ",
      "v    2      Cv  ",
      "v    2       oSS",
      "v    2       ohh",
      "v    2       ohh",
      "vv22222222222vhh",
      "v               ",
      "v               "
    ],
    [
      "vvvvvvvvvvvvvvvv",
      "v3333v3333333v  ",
      "v3333b33333334  ",
      "v3333b33333334  ",
      "v3333b33333334  ",
      "vvbbbvbbbbbbbv  ",
      "v3333b33333334  ",
      "v3333b33333334  ",
      "v3333b33333334  ",
      "v3333b333333Cv  ",
      "v3333b33333334  ",
      "v3333b33333334  ",
      "v3333b33333334  ",
      "vvbbbbbbbbbbbvSS",
      "v333333333333400",
      "v333333333333455"
    ]
  ]
}