{
  "name": "multi_condo1_3_floor6",
  "refpalette": "c70cities:multi_condo1_3_floor6_palette",
  "xsize": 16,
  "zsize": 16,
  "slices": [
    [
      "                ",
      "aaaaaaa         ",
      "aaaaaaabbbbbbbb ",
      "aaaaaaacccccccb ",
      "dddddddeeeeeecb ",
      "ddddddddddddecb ",
      "ddddddddddddecb ",
      "ddddddddddddecb ",
      "ddddddddddddecb ",
      "ddddddddddddecb ",
      "ddddddddddddecb ",
      "ddddddddddddecb ",
      "ddddddddddddecb ",
      "ddddddddddddeaaa",
      "ddddddddddddef  ",
      "ggggghddddddef  "
    ],
    [
      "                ",
      "      a         ",
      "iiiiiia         ",
      "      accccccc  ",
      "     eeejjjeec  ",
      "  kl me    nec  ",
      "      o    pec  ",
      "     ee   qpec  ",
      "   r st    pec  ",
      "  rur t    nec  ",
      "   r  t    pec  ",
      "    r t   qpec  ",
      "  ru rt    pec  ",
      "   r  tw   neaaa",
      "     eeexeeee   ",
      "            y   "
    ],
    [
      "                ",
      "      a         ",
      "      a         ",
      "      a         ",
      "     eeeAAAee   ",
      "     Be    Ce   ",
      "      D     e   ",
      "     ee    Ee   ",
      "      t    Fe   ",
      "      t    Ce   ",
      "      t     e   ",
      "      t    Ee   ",
      "      t    Fe   ",
      "      t    Ceaaa",
      "     eeeIeeee   ",
      "            i   "
    ],
    [
      "                ",
      "      a         ",
      "      a         ",
      "      a         ",
      "     eeeAAAee   ",
      "      e    Ce   ",
      "      J    Ke   ",
      "     ee    Ke   ",
      "      L    Ke   ",
      "      L    Ce   ",
      "      L    Ke   ",
      "      L    Ke   ",
      "      L    Ke   ",
      "      L    Ceaaa",
      "     eeeMeeee   ",
      "            i   "
    ],
    [
      "                ",
      "      a         ",
      "      a         ",
      "NNNNNNaOOOOOOO  ",
      "eeeeeeeeeeeeeO  ",
      "      e    CeO  ",
      "      e    CeO  ",
      "AAAAAee    CeO  ",
      "           CeO  ",
      "           CeO  ",
      "           CeO  ",
      "           CeO  ",
      "           CeO  ",
      "           Ceaaa",
      "AAAAAeeeeeeee   ",
      "            e   "
    ],
    [
      "                ",
      "      a         ",
      "PPPPPPa         ",
      "e     aQQQQQQQ  ",
      "eeeeeeeeeeeeeQ  ",
      "      eggghReQ  ",
      "      eggghSeQ  ",
      "TTTTTeeggghUeQ  ",
      "gggggggggghVeQ  ",
      "gWgWgWWWgghXeQ  ",
      "ggWggWgWgghYeQ  ",
      "gWgWgWWWgghZeQ  ",
      "ggggggggggh0eQ  ",
      "gggggggggghReaaa",
      "MMMMMeeeeeeee   ",
      "      111111e   "
    ]
  ]
}