{
  "name": "multi_laboratory1_1_base5",
  "refpalette": "c70cities:multi_laboratory1_1_base5_palette",
  "xsize": 16,
  "zsize": 16,
  "slices": [
    [
      "zab             ",
      "zac             ",
      "zacb            ",
      "zac             ",
      "zac             ",
      "zadde           ",
      "zacfge     hi   ",
      "zadde           ",
      "zacj            ",
      "zacb            ",
      "zac             ",
      "zac             ",
      "zadde          e",
      "zacfge     hk  e",
      "zadde         el",
      "zac           e "
    ],
    [
      "zab             ",
      "zac             ",
      "zabb            ",
      "zab             ",
      "zab             ",
      "zadde           ",
      "zacfge     h    ",
      "zadde           ",
      "zacb            ",
      "zacb            ",
      "zac             ",
      "zac             ",
      "zadde          e",
      "zacfge     h   e",
      "zadde         el",
      "zac           e "
    ],
    [
      "zab             ",
      "zac             ",
      "zacb            ",
      "zac             ",
      "zac             ",
      "zadde           ",
      "zacfge     h    ",
      "zadde           ",
      "zac             ",
      "zabb            ",
      "zab             ",
      "zab             ",
      "zadde          e",
      "zacfge     h   e",
      "zadde         el",
      "zacb          e "
    ],
    [
      "zab             ",
      "zac             ",
      "zacb            ",
      "zacj            ",
      "zac             ",
      "zadde           ",
      "zacfge     h    ",
      "zadde           ",
      "zac             ",
      "zacb            ",
      "zacj            ",
      "zac             ",
      "zadde          e",
      "zacfge     h   e",
      "zadde         el",
      "zac           e "
    ],
    [
      "zab             ",
      "zac             ",
      "zacb            ",
      "zacj            ",
      "zacj            ",
      "zadde           ",
      "zacfge     h    ",
      "zadde           ",
      "zacj            ",
      "zacb            ",
      "zacj            ",
      "zac             ",
      "zadde          e",
      "zacfge     h   e",
      "zadde         el",
      "zac           e "
    ],
    [
      "zabbmmmmmmmmmmmm",
      "zacbmmmmmmmmmmmm",
      "zacnmmmmmmmmmmmm",
      "zacbmmmmmmmmmmmm",
      "zacbmmmmmmmmmmmm",
      "zaddddmmmmmmmmmm",
      "zacfodmmmmmhmmmm",
      "zaddddmmmmmmmmmm",
      "zacbmmmmmmmmmmmm",
      "zacnmmmmmmmmmmmm",
      "zacbmmmmmmmmmmmm",
      "zacbmmmmmmmmmmmm",
      "zaddddmmmmmmmmme",
      "zacfodmmmmmhmmme",
      "zaddddmmmmmmmmel",
      "zacbmmmmmmmmmme "
    ]
  ]
}