{
  "name": "multi_residential2_0_floor1",
  "refpalette": "c70cities:multi_residential2_0_floor1_palette",
  "xsize": 16,
  "zsize": 16,
  "slices": [
    [
      "                ",
      "                ",
      "                ",
      "                ",
      "                ",
      " aaaaaaaaaaaaaa ",
      " bcd  ef ghf cb ",
      "  c   e      c  ",
      "  i          i  ",
      "  i          i  ",
      "  cj        jc  ",
      " kklmmnmeemmlkk ",
      " oooop    qoooo ",
      "     r    s     ",
      "     r    s     ",
      "     r    s     "
    ],
    [
      "                ",
      "                ",
      "                ",
      "                ",
      "                ",
      "                ",
      " aaaaaaaaaaaaaa ",
      " bc   e      cb ",
      "  c          c  ",
      "  c          c  ",
      " kcj        jck ",
      " ooooopmmqooooo ",
      "      r  s      ",
      "      r  s      ",
      "      r  s      ",
      "      r  s      "
    ],
    [
      "                ",
      "                ",
      "                ",
      "                ",
      "                ",
      "                ",
      "                ",
      " aaaaaaaaaaaaaa ",
      " bct        ucb ",
      " kct         ck ",
      " oooooopqoooooo ",
      "       rs       ",
      "       rs       ",
      "       rs       ",
      "       rs       ",
      "       rs       "
    ],
    [
      "                ",
      "                ",
      "                ",
      "                ",
      "                ",
      "                ",
      "                ",
      "                ",
      " aaaaaaaaaaaaaa ",
      " oooooooooooooo ",
      "                ",
      "                ",
      "                ",
      "                ",
      "                ",
      "                "
    ],
    [
      "                ",
      "                ",
      "                ",
      "                ",
      "                ",
      "                ",
      "                ",
      "                ",
      " ~~~~~~~~~~~~~  ",
      " ~~~~~~~~~~~~~  ",
      " ~~~~~~~~~~~~~  ",
      " ~~~~~~~~~~~~~  ",
      " ~~~~~~~~~~~~~  ",
      " ~~~~~~~~~~~~~  ",
      " ~~~~~~~~~~~~~  ",
      " ~~~~~~~~~~~~~  "
    ],
    [
      "                ",
      "                ",
      "                ",
      "                ",
      "                ",
      "                ",
      "                ",
      "                ",
      " ~~~~~~~~~~~~~  ",
      " ~~~~~~~~~~~~~  ",
      " ~~~~~~~~~~~~~  ",
      " ~~~~~~~~~~~~~  ",
      " ~~~~~~~~~~~~~  ",
      " ~~~~~~~~~~~~~  ",
      " ~~~~~~~~~~~~~  ",
      " ~~~~~~~~~~~~~  "
    ]
  ]
}