{
  "name": "multi_militarybase_4_base4",
  "refpalette": "c70cities:multi_militarybase_4_base4_palette",
  "xsize": 16,
  "zsize": 16,
  "slices": [
    [
      "vvvvvvvvvvvvvvvv",
      "avaaaaaaavaaaavv",
      "abaaaaaaabaaaavv",
      "abaaaaaaabaaaavv",
      "abaaaaaaabaaaavv",
      "bvbbbbbbbvbbbvvv",
      "abaaaaaaabaaaavv",
      "abaaaaaaabaaaavv",
      "abaaaaaaabaaaavv",
      "avaaaaaaabaaaavv",
      "abaaaaaaabaaaavv",
      "abaaaaaaabaaaavv",
      "abaaaaaaabaaaavv",
      "bvbbbbbbbbbbbvvv",
      "cbddddddddddddvv",
      "cbddddddddddddvv"
    ],
    [
      "vvvvvvvvvvvvvvvv",
      "evfffffffvghghvv",
      "eijklmnlop   qvv",
      "ei       r   hvv",
      "ei       p   qvv",
      "ev       vsssvvv",
      "ei          tfvv",
      "ei          ufvv",
      "wi  xyx     nfvv",
      "wvA yBy     Cfvv",
      " i  xyx     nfvv",
      " D          Efvv",
      " i          Ffvv",
      "ev           vvv",
      "I             vv",
      "              vv"
    ],
    [
      "vvvvvvvvvvvvvvvv",
      "JvmnKnlLmv M !vv",
      " i       p    vv",
      " i       N   Ovv",
      "Pi       p    vv",
      "ev       vsssvvv",
      "ei           Evv",
      "ei           Qvv",
      "wi  RRR      Svv",
      " vA RTR      nvv",
      " i  RRR      Svv",
      " D           Uvv",
      " i           Evv",
      "ev           vvv",
      "n             vv",
      "             Vvv"
    ],
    [
      "vvvvvvvvvvvvvvvv",
      " v       v    vv",
      " i       p    vv",
      " i       p    vv",
      " i       p    vv",
      " v       vsssvvv",
      " i            vv",
      "Pi            vv",
      "ei            vv",
      "evA           vv",
      "Wi            vv",
      " i            vv",
      "Xi            vv",
      "ev           vvv",
      "              vv",
      "              vv"
    ],
    [
      "vvvvvvvvvvvvvvvv",
      " v       v    vv",
      " i       p    vv",
      " i       p    vv",
      " i       p    vv",
      " vYYYYYYYvsssvvv",
      " i       Y    vv",
      " i       Y    vv",
      " i       Y    vv",
      " vA      Y    vv",
      "Pi       Y    vv",
      "ei       Y    vv",
      "ei       Y    vv",
      "evYYYYYYYYYYYvvv",
      "              vv",
      "              vv"
    ],
    [
      "vvvvvvvvvvvvvvvv",
      " vZZZZZZZvZZZZvv",
      " 0ZZZZZZZbZZZZvv",
      " 0ZZZZZZZbZZZZvv",
      " 0ZZZZZZZbZZZZvv",
      " vbbbbbbbbbbbvvv",
      " 0ZZZZZZZbZZZZvv",
      " 0ZZZZZZZbZZZZvv",
      " 0ZZZZZZZbZZZZvv",
      " vAZZZZZZbZZZZvv",
      " 0ZZZZZZZbZZZZvv",
      " 0ZZZZZZZbZZZZvv",
      " 0ZZZZZZZbZZZZvv",
      "Pvbbbbbbbbbbbvvv",
      "W0ZZZZZZZZZZZZvv",
      "10ZZZZZZZZZZZZvv"
    ]
  ]
}