{
  "name": "multi_megatower1_7_ground",
  "refpalette": "c70cities:multi_megatower1_7_ground_palette",
  "xsize": 16,
  "zsize": 16,
  "slices": [
    [
      "vvvvaaaaabbbbGGG",
      "vvvvaaaaabbbbGGG",
      "vvvvaaaaabbbbGGG",
      "vvvvaaaaabbbbGGG",
      "vvcvaaaaabbbbGGG",
      "vvvaaaaaabbbbGGG",
      "   daaaaabbbbGGG",
      "   vaaaaabbbbGGG",
      "   vaaaaabbbbGGG",
      "   eaaaaabbbbGGG",
      "vvvaaaaaabbbbGGG",
      "vvcvaaaaabbbbGGG",
      "vvvvaaaaabbbbGGG",
      "vvvvaaaaabbbbGGG",
      "vvvvaaaaabbbbGGG",
      "vvvvaaaaabbbbGGG"
    ],
    [
      "bbcaabbbb       ",
      "bbcaabbbb       ",
      "bbcaabbbb       ",
      "bbcaabbbb       ",
      "bbcaabbbb       ",
      "vvcaabbbb       ",
      " fcaabbbbg      ",
      " fcaabbbbg      ",
      " fcaabbbbg      ",
      " fcaabbbbg      ",
      "vvcaabbbb       ",
      "cccaabbbb       ",
      "hfcaabbbb       ",
      "hfcaabbbb       ",
      "hfcaabbbb       ",
      "hfcaabbbb       "
    ],
    [
      "bbbbb           ",
      "bbbbb           ",
      "bbbbb           ",
      "bbbbb           ",
      "bbcbb           ",
      "vbbbb           ",
      "iibbbg          ",
      "iibbbg          ",
      "iibbbg          ",
      "iibbbg          ",
      "vbbbb           ",
      "ibcbb           ",
      "ibbbb           ",
      "ibbbb           ",
      "ibbbb           ",
      "ibbbb           "
    ],
    [
      "b               ",
      "b               ",
      "b               ",
      "b  j            ",
      "b k             ",
      "b               ",
      "bg              ",
      "bg              ",
      "bg              ",
      "bg              ",
      "b               ",
      "b c             ",
      "b               ",
      "b               ",
      "b               ",
      "b               "
    ],
    [
      "                ",
      "                ",
      "                ",
      "                ",
      "l k             ",
      "                ",
      "                ",
      "                ",
      "                ",
      "                ",
      "                ",
      "  k             ",
      "                ",
      "                ",
      "                ",
      "                "
    ],
    [
      "                ",
      "                ",
      "                ",
      "                ",
      "  c             ",
      "                ",
      "                ",
      "                ",
      "                ",
      "                ",
      "                ",
      "  k             ",
      "                ",
      "                ",
      "                ",
      "                "
    ]
  ]
}