{
  "name": "multi_laboratory1_9_floor1",
  "refpalette": "c70cities:multi_laboratory1_9_floor1_palette",
  "xsize": 16,
  "zsize": 16,
  "slices": [
    [
      "aaaaaaaaaaaaaaaa",
      "aaaaaaaaaaaaaaaa",
      "aaaaaaaaaaaaaaaa",
      "aaaaaaaaaaaaaaaa",
      "aaaaaaaaaaaaaaaa",
      "aaaaaaaaaaaaaaaa",
      "aaaaaaaaaaaaaaaa",
      "aaaaaaaaaaaaaaaa",
      "aaaaaaaaaaaaaaaa",
      "aaaaaaaaaaaaaaaa",
      "bbbbbbbbbbbbbbbb",
      "cccccdeffgdccccc",
      "ccccchijjkhccccc",
      "lllllllllmnopopo",
      "                ",
      "                "
    ],
    [
      "qqrsttttttttsrqq",
      "    quq  quq    ",
      "    quq  quq    ",
      "                ",
      "                ",
      "                ",
      " wwww      wwww ",
      "xyAAAA    AAAAyx",
      "                ",
      "                ",
      "BBBBBr    rBBBBB",
      "     C    D     ",
      "     C    D     ",
      "nonnnnnnnnpppppp",
      "                ",
      "                "
    ],
    [
      "  rE        Er  ",
      "     F          ",
      "     F          ",
      "                ",
      "                ",
      "                ",
      "                ",
      "  F I     JF  IK",
      "                ",
      "                ",
      "     r    r     ",
      "    C      D    ",
      "    C      D    ",
      "pppppppoppppoppp",
      "                ",
      "                "
    ],
    [
      "  rE        Er  ",
      "                ",
      "                ",
      "                ",
      "                ",
      "                ",
      "                ",
      "                ",
      "                ",
      "                ",
      "     r    r     ",
      "   C        D   ",
      "   C        D   ",
      "pLMMpoppMLMppMpp",
      "                ",
      "                "
    ],
    [
      "  r          r  ",
      "                ",
      "                ",
      "                ",
      "                ",
      "                ",
      "                ",
      "                ",
      "                ",
      "                ",
      "     r    r     ",
      "  C          D  ",
      "  C          D  ",
      "pMpppMLpLoMpppMp",
      "                ",
      "                "
    ],
    [
      "  b          b  ",
      "  hh        hh  ",
      "   hhh    hhh   ",
      "     hhhhhh     ",
      "                ",
      "                ",
      "                ",
      "                ",
      "                ",
      "                ",
      "hhhhhbhhhhbhhhhh",
      " C            D ",
      " C            D ",
      "ppLMppppMMppMLLp",
      "                ",
      "                "
    ]
  ]
}