{
  "name": "multi_laboratory1_5_base6",
  "refpalette": "c70cities:multi_laboratory1_5_base6_palette",
  "xsize": 16,
  "zsize": 16,
  "slices": [
    [
      "zzzzzzzzzzzzzzzz",
      "aaaaaaaaaaaaaaaa",
      "bbbbbbbbbbbbbbbb",
      "                ",
      "      c         ",
      "dddddddddddddddd",
      "d    d    d    d",
      "de  ede   d   ed",
      "dddddddddddddddd",
      "dffffd    dffffd",
      "dffffd    dffffd",
      "dfgffd    dffffd",
      "dffffd    dffffd",
      "dfhffd    dffffd",
      "dffffd    dffffd",
      "dddddddddddddddd"
    ],
    [
      "zzzzzzzzzzzzzzzz",
      "aaaaaaaaaaaaaaaa",
      "bbbbbbbbbbbbbbbb",
      "                ",
      "       c        ",
      "diiiiiiiiiiiiiid",
      "i    i    i    i",
      "ie  eie   i   ei",
      "diiiidiiiidiiiid",
      "ifjjfi    ifjjfi",
      "ikhlmi    in  mi",
      "in hmi    in  mi",
      "ighfoi    in  oi",
      "in pfi    in  mi",
      "ifqrfi    ifsrfi",
      "digtidittidittid"
    ],
    [
      "zzzzzzzzzzzzzzzz",
      "aaaaaaaaaaaaaaaa",
      "bbbbbbbbbbbbbbbb",
      "                ",
      "        c       ",
      "diiiiiiiiiiiiiid",
      "i    i    i    i",
      "ie  eie   iu  ei",
      "diiiidiiiidiiiid",
      "ifjhfi    ifjjfi",
      "iw   i    in  mi",
      "in  mi    in  mi",
      "i  hxi    in  mi",
      "in  mi    in  mi",
      "iy Afi    ifBAfi",
      "diC idi  idi  id"
    ],
    [
      "zzzzzzzzzzzzzzzz",
      "aaaaaaaaaaaaaaaa",
      "bbbbbbbbbbbbbbbb",
      "                ",
      "         c      ",
      "diiiiiiiiiiiiiid",
      "i    i    i    i",
      "ie  eie   iu  ei",
      "diiiidiiiidiiiid",
      "ifwDfi    ifjjfi",
      "i   mi    in  mi",
      "i    i    in  mi",
      "i   mi    in  mi",
      "ik  mi    in  mi",
      "i   fi    ifjjfi",
      "diffidiffidiffid"
    ],
    [
      "zzzzzzzzzzzzzzzz",
      "aaaaaaaaaaaaaaaa",
      "bbbbbbbbbbbbbbbb",
      "                ",
      "          c     ",
      "diiiiiiiiiiiiiid",
      "i    i    i    i",
      "ie  eie  eie  ei",
      "diiiidiiiidiiiid",
      "ifDjfi    ifjjfi",
      "in Emi    in Emi",
      "i   Fi    inE mi",
      "i    i    in Emi",
      "iI  mi    inEEmi",
      "i  Dfi    ifjjfi",
      "diiiidiiiidiiiid"
    ],
    [
      "zzzzzzzzzzzzzzzz",
      "aaaaaaaaaaaaaaaa",
      "bbbbbbbbbbbbbbbb",
      "                ",
      "           c    ",
      "diiiiiiiiiiiiiid",
      "i    i    i    i",
      "ie  eie  eie  ei",
      "diiiidiiiidiiiid",
      "iffffi    iffffi",
      "ifjjfi    ifjjfi",
      "iJ Dfi    ifjjfi",
      "iJ  fi    ifjjfi",
      "i  Dfi    ifjjfi",
      "i Jffi    iffffi",
      "diiiidiiiidiiiid"
    ]
  ]
}