{
  "name": "multi_laboratory1_3_base3",
  "refpalette": "c70cities:multi_laboratory1_3_base3_palette",
  "xsize": 16,
  "zsize": 16,
  "slices": [
    [
      "zabccccccccccccc",
      "zabccccccccccccc",
      "zabccccccccdcccc",
      "zabccccccccccccc",
      "zabccccccccccccc",
      "zabccccccccccccc",
      "zabccccccccccccc",
      "zabccccccccccccc",
      "zabeeffffffccccc",
      "zabccccccccdcccc",
      "zabccccccccccccc",
      "zabccccccccccccc",
      "zabccccccccccccc",
      "zabccccccccccccc",
      "zabccccccccccccc",
      "zabccccccccccccc"
    ],
    [
      "zabg h     i  j ",
      "zabkkl     m no ",
      "zabp  q    d  o ",
      "zabrstsuwxym  j ",
      "zabkkA BsBBmxCj ",
      "zabDEDEx  Am C F",
      "zabDDIDJ x m  K ",
      "zabDDLDDMJJm    ",
      "zab  NNDDOJm    ",
      "zabP  JD JPdmmmm",
      "zabPQ RD SPmQ   ",
      "zabPj RRDTPm    ",
      "zabPj RRDUPm    ",
      "zabPj RDDDPm  VV",
      "zabPWXDDD Pm   Y",
      "zabPPPPPPPPm   Z"
    ],
    [
      "zab        i  A ",
      "zab0       m    ",
      "zab1       d    ",
      "zab        m  2 ",
      "zab0x      3  4 ",
      "zabJ J     n    ",
      "zabJJ J    3    ",
      "zabD 5JJJ  3    ",
      "zabDDNN J6 m    ",
      "zabP      Pdm333",
      "zabP  JJ5 Pm    ",
      "zabP7  D  P8    ",
      "zabP7     P8    ",
      "zabP     DP8    ",
      "zabP    DDP8    ",
      "zabPPPPPPPPm    "
    ],
    [
      "zab        i    ",
      "zab        m    ",
      "zab        d    ",
      "zab        m    ",
      "zab        3    ",
      "zab        3    ",
      "zab        3    ",
      "zabJ 9 5   3    ",
      "zabDNNNN N m    ",
      "zabP      Pdm333",
      "zabP @  9 Pm    ",
      "zabP  5   P#    ",
      "zabP   $  P#    ",
      "zabP      P#    ",
      "zabP    D%P#    ",
      "zabPPPPPPPPm    "
    ],
    [
      "zab        m    ",
      "zab        m    ",
      "zab        d    ",
      "zab        m    ",
      "zab        m    ",
      "zab        m    ",
      "zab   DD   m    ",
      "zab  %%DD  m    ",
      "zabDDDD%%D m    ",
      "zabPD%D%% Pdmmmm",
      "zabPD^%%D Pm    ",
      "zabPD%%%D Pm    ",
      "zabP  %^D Pm    ",
      "zabP &    Pm    ",
      "zabP * DDDPm    ",
      "zabPPPPPPPPm    "
    ],
    [
      "zab(()(()((+-)--",
      "zab(([(()((+----",
      "zab((((((((d----",
      "zab((((((((+----",
      "zab(()((]((+- --",
      "zab(([(()((+-[--",
      "zab((](([((+-)--",
      "zab(()(()((+-)--",
      "zab((((((((+----",
      "zabP]]]]]]Pd{{{{",
      "zabP]}\\|`]P+((((",
      "zabP]\\|`:]P+((((",
      "zabP]\\`};]P+((((",
      "zabP]}\\`']P+(())",
      "zabP]]]]]]P+(()(",
      "zabPPPPPPPP+(()("
    ]
  ]
}