{
  "name": "multi_condo1_2_base1",
  "refpalette": "c70cities:multi_condo1_2_base1_palette",
  "xsize": 16,
  "zsize": 16,
  "slices": [
    [
      "vaHHHHHHHHHHHHHH",
      "vaHHHHHHHHHHHHHH",
      "vaHHHHHHHHHHHHHH",
      "vaHHHHHHHHHHHHHH",
      "vaHHHHHHHHHHHHHH",
      "vaHHHHHHHHHHHHHH",
      "vaHHHHHHHHHHHHHH",
      "vaHHHHHHHHHHHHHH",
      "vaHHHHHHHHHHHHHH",
      "vaHHHHHHHHHHHHHH",
      "vaHHHHHHHHHHHHHH",
      "vaHHHHHHHHHHHHHH",
      "vaHHHHHHHHHHHHHH",
      "vaaaaaaaaaaaaaaa",
      "vbbbbbbbbbbbbbbb",
      "vvvvvvvvvvvvvvvv"
    ],
    [
      "va              ",
      "va  cdededededed",
      "va  c     f     ",
      "va  cghghghghghg",
      "va  ciiiiiiiiiii",
      "va  cdededededed",
      "va  c           ",
      "va  cghghghghghg",
      "va              ",
      "va              ",
      "vajdedededededed",
      "vaj             ",
      "vajghghghghghghg",
      "vaaaaaaaaaaaaaaa",
      "vbbbbbbbbbbbbbbb",
      "vvvvvvvvvvvvvvvv"
    ],
    [
      "va              ",
      "va              ",
      "va              ",
      "va              ",
      "va              ",
      "va              ",
      "va              ",
      "va              ",
      "va              ",
      "va              ",
      "va              ",
      "va              ",
      "va              ",
      "vaaaaaaaaaaaaaaa",
      "vbbbbbbbbbbbbbbb",
      "vvvvvvvvvvvvvvvv"
    ],
    [
      "va              ",
      "va              ",
      "va              ",
      "va              ",
      "va              ",
      "va              ",
      "va              ",
      "va              ",
      "va              ",
      "va              ",
      "va              ",
      "va              ",
      "va              ",
      "vaaaaaaaaaaaaaaa",
      "vbbbbbbbbbbbbbbb",
      "vvvvvvvvvvvvvvvv"
    ],
    [
      "vak       a     ",
      "vak       a     ",
      "vakkkkkkkkakkkkk",
      "vak       a     ",
      "vak       a     ",
      "vak       a     ",
      "vak       a     ",
      "vak       a     ",
      "vak       a     ",
      "vak       a     ",
      "vak       a     ",
      "vak       a     ",
      "vakkkkkkkkakkkkk",
      "vaaaaaaaaaaaaaaa",
      "vbbbbbbbbbbbbbbb",
      "vvvvvvvvvvvvvvvv"
    ],
    [
      "vallllllllalllll",
      "vallllllllalllll",
      "vallllllllalllll",
      "vallllllllalllll",
      "vallllllllalllll",
      "vallllllllalllll",
      "vallllllllalllll",
      "vallllllllalllll",
      "vallllllllalllll",
      "vallllllllalllll",
      "vallllllllalllll",
      "vallllllllalllll",
      "vallllllllalllll",
      "vaaaaaaaaaaaaaaa",
      "vbbbbbbbbbbbbbbb",
      "vvvvvvvvvvvvvvvv"
    ]
  ]
}