{
  "name": "multi_flatapartment_1_floor2",
  "refpalette": "c70cities:multi_flatapartment_1_floor2_palette",
  "xsize": 16,
  "zsize": 16,
  "slices": [
    [
      "                ",
      "aaabaaabaaaabaaa",
      "cccccccccccccccc",
      "dddddddddddddddd",
      "dddddddddddddddd",
      "dddddddccccccddd",
      "dddddddc  edcddd",
      "dddddddc   dcddd",
      "dddddddc   dcddd",
      "dddddddcddddcddd",
      "dddddddccccccddd",
      "dddddddcddddcddd",
      "dddddddcddddcddd",
      "cccccccccccccccc",
      "aaabaaabaaaabaaa",
      "                "
    ],
    [
      "                ",
      "ffabafabaggabafa",
      "      hi!j jik  ",
      "l l   min   io  ",
      "ppp   qinj  ir  ",
      "iiii  sbtttubw  ",
      "  xi  sy    Aw  ",
      "  Bi   y   CA!  ",
      "   i   yDDE A   ",
      "l li   F    I   ",
      "pppiiiib    biii",
      "JJKLM  N    O  M",
      "       y    A   ",
      "       y    A   ",
      "ffabafabaPPabafa",
      "                "
    ],
    [
      "                ",
      "QQabaQabaQQabaQa",
      "      Ri    iS  ",
      "       in   i   ",
      "       in   i   ",
      "iiii   btttTb   ",
      "  Ui   y    A   ",
      "  Ui   y    A   ",
      "   i   ydE  A   ",
      "   i   V    W   ",
      "  Xiiiib    biii",
      "    Y  Z    0  Y",
      "       y    A   ",
      "       y    A   ",
      "QQabaQabaQQabaQa",
      "                "
    ],
    [
      "                ",
      "QQabaQabaQQabaQa",
      "       i    i   ",
      "       i    i   ",
      "       ij   i   ",
      "iiii   bttttb   ",
      "  Ui   y    A   ",
      "  Ui   yd   A   ",
      "   i   yE   A   ",
      "   i1  y    A  1",
      "   iiiib    biii",
      "       y    A   ",
      "       y    A   ",
      "       y    A   ",
      "QQabaQabaQQabaQa",
      "                "
    ],
    [
      "                ",
      "aaabaaabaaaabaaa",
      "   i   i2222i   ",
      "   i   i2222i   ",
      "   i   i2222i   ",
      "iiiiiiibttttb   ",
      "   i   yd3  A   ",
      "4  i   y5   A   ",
      "   i   y    A   ",
      "   i6  y 4  A  7",
      "iiiiiiib8888biii",
      "   i   y    A   ",
      "   i   y    A   ",
      "   i   y    A   ",
      "aaabaaabaaaabaaa",
      "                "
    ],
    [
      "                ",
      "999@999@9999@999",
      "cccccccccccccccc",
      "dddddddddddddddd",
      "dddddddddddddddd",
      "dddddddddddddddd",
      "dddddddd edddddd",
      "dddddddd   ddddd",
      "dddddddd   ddddd",
      "dddddddddddddddd",
      "dddddddddddddddd",
      "dddddddddddddddd",
      "dddddddddddddddd",
      "cccccccccccccccc",
      "999@999@9999@999",
      "                "
    ]
  ]
}