{
  "name": "multi_militarybase_0_ground",
  "refpalette": "c70cities:multi_militarybase_0_ground_palette",
  "xsize": 16,
  "zsize": 16,
  "slices": [
    [
      "aaaaaaaaaaaaaaaa",
      "abbbbbbbbbbbbbbb",
      "abcccccccccccccc",
      "abcccccccccccccc",
      "abcccccccccccccc",
      "abcccccccccccccc",
      "abcccccccccccccc",
      "abcccccccccccccc",
      "abcccccccccccccc",
      "abcccccccccccccc",
      "abcccccccccccccc",
      "abcccccccccccccc",
      "abcccccccccccccc",
      "abcccccc!ccccccc",
      "aHH=HHd=HHHHH==H",
      "aHHHHHHHHHHHHHHH"
    ],
    [
      "                ",
      " bbbbbbbbbbbbbbb",
      " b              ",
      " b              ",
      " b      eeeeeeee",
      " b      efghi jk",
      " b      el      ",
      " b      el      ",
      " b      emm   n ",
      " b      e!o meep",
      " b      eqr se  ",
      " b      eq t e  ",
      " b      eqqq e  ",
      " b      eeeeee  ",
      "  u             ",
      "                "
    ],
    [
      "                ",
      " bbbbbbbbbbbbbbb",
      " b              ",
      " b              ",
      " b      wwxxwwww",
      " b      w      j",
      " b      x       ",
      " b      x       ",
      " b      wmm   y ",
      " b      w o mwwA",
      " b      x   sw  ",
      " b      xB   x  ",
      " b      w C  w  ",
      " b      wwxxww  ",
      "                ",
      "                "
    ],
    [
      "                ",
      " bbbbbbbbbbbbbbb",
      " b              ",
      " b       DDDD   ",
      " b      wwwwwwww",
      " b     Dw       ",
      " b     Dw       ",
      " b     Dw       ",
      " b     Dwmm     ",
      " b     Dw ommwww",
      " b     Dw   sw  ",
      " b     Dw    x  ",
      " b     Dw    w  ",
      " b      wwxxww  ",
      "                ",
      "                "
    ],
    [
      "                ",
      " bbbbbbbbbbbbbbb",
      " b              ",
      " b              ",
      " b      wwEEwwww",
      " b      wnnnn   ",
      " b      En      ",
      " b      En      ",
      " b      wnn   nn",
      " b      wnnnnwwE",
      " b      En  sw  ",
      " b      En   w  ",
      " b      wn   w  ",
      " b      wwwwww  ",
      "                ",
      "                "
    ],
    [
      "                ",
      "  FFFFFFFFFFFFFF",
      " u              ",
      " u              ",
      " u      eeeeeeee",
      " u      eaaaaa  ",
      " u      eaaaaaaa",
      " u      eaaaaaaa",
      " u      eaaaaaaa",
      " u      eaaaaeee",
      " u      eaaase  ",
      " u      eaaaae  ",
      " u      eaaaae  ",
      " u      eaaaae  ",
      "        ejjjje  ",
      "        ejjjje  "
    ]
  ]
}