{
  "name": "multi_megatower1_3_floor9",
  "refpalette": "c70cities:multi_megatower1_3_floor9_palette",
  "xsize": 16,
  "zsize": 16,
  "slices": [
    [
      "                ",
      "                ",
      "                ",
      "                ",
      "                ",
      "                ",
      "                ",
      "                ",
      "                ",
      "                ",
      "    a      a    ",
      "bcccdbbbcccdbbbc",
      "eeeefeeeeeefeeee",
      "gggghgggggghgggg",
      "ijjjgggggggggggg",
      "i   gggggggggggg"
    ],
    [
      "                ",
      "                ",
      "                ",
      "                ",
      "                ",
      "                ",
      "                ",
      "                ",
      "                ",
      "                ",
      "                ",
      "bcccabbbcccabbbc",
      "                ",
      "klmnhoooooohoooo",
      "ijjjipqqrrsstttu",
      "i   ip         u"
    ],
    [
      "                ",
      "                ",
      "                ",
      "                ",
      "                ",
      "                ",
      "                ",
      "                ",
      "                ",
      "                ",
      "                ",
      "bcccabbbcccabbbc",
      "                ",
      "k   hoooooohoooo",
      "ijjji  w  xyAAAu",
      "i   iB         u"
    ],
    [
      "                ",
      "                ",
      "                ",
      "                ",
      "                ",
      "                ",
      "                ",
      "                ",
      "                ",
      "                ",
      "                ",
      "bcccabbbcccabbbc",
      "                ",
      "k   hoooooohoooo",
      "ijjji CCCC  D Eu",
      "i   i          u"
    ],
    [
      "                ",
      "                ",
      "                ",
      "                ",
      "                ",
      "                ",
      "                ",
      "                ",
      "                ",
      "                ",
      "                ",
      "bcccabbbcccabbbc",
      "                ",
      "k   hoooooohoooo",
      "ijjjiFIIIIFFFFFJ",
      "i   iFKFFLFFFLFJ"
    ],
    [
      "                ",
      "                ",
      "                ",
      "                ",
      "                ",
      "                ",
      "                ",
      "                ",
      "                ",
      "                ",
      "                ",
      "bcccabbbcccabbbc",
      "    d      d    ",
      "MMMMhMMMMMMhMMMM",
      "iNNNOIIIIIIOIIII",
      "i   O PE PEOEPEE"
    ]
  ]
}