{
  "name": "multi_laboratory1_6_base7",
  "refpalette": "c70cities:multi_laboratory1_6_base7_palette",
  "xsize": 16,
  "zsize": 16,
  "slices": [
    [
      "aaaaaaaaaaaaaabc",
      "aaaaaaaaaaaaaaca",
      "aaaaaaaaaaaaaaaa",
      "aaaaaaaaaaaaaaaa",
      "aaaaaaaaaaaaaaaa",
      "aaaaaaaaaaaaaaaa",
      "aaaaaaaaaaaaaaaa",
      "aaaaaddddddaaaaa",
      "aaadddaaaadddaaa",
      "adddaaaaaaaaddda",
      "ddaaaaacaaaaaadd",
      "daaaaaaaacaaaaad",
      "daaaaabaaaaaaaad",
      "aaaaeeeeeeeeaaaa",
      "aaaaeffffffeaaaa",
      "aaaaeffffffeaaaa"
    ],
    [
      "aaaaaaaaaaaaaagh",
      "aaaaaaaaaaaaaaic",
      "aaaaaaaaaaaaaajc",
      "aaaaaaaaaaaaaaka",
      "aaaaaaaaaaaaaala",
      "aaaaaaaaaaaaaaaa",
      "aaaaaaaaaaaaaaaa",
      "aaaaaaaaaaaaaaaa",
      "aaaaamnnnnmabaaa",
      "aaaaann   nbaaaa",
      "amaaa     o bcma",
      "aaaa    h  pbqaa",
      "aaa r    p s baa",
      "bht uwwwwwwu xby",
      "aa AB      Bo yb",
      "aaC B      B Dbb"
    ],
    [
      "aaaaaaaaaaaaaaa ",
      "aaaaaaaaaaaaaaah",
      "aaaaaaaaaaaaaaac",
      "aaaaaaaaaaaaaaaa",
      "aaaaaaaaaaaaaaaa",
      "aaaaaaaaaaaaaaaa",
      "aaaaaaaaaaaaaaaa",
      "aaaaaaaaaaaaaaaa",
      "aaaaamn  nmaaaaa",
      "aaaa        aaaa",
      "amaa         Dma",
      "a!yo          ba",
      "aa           Dba",
      "a         E   Fy",
      "IJI            y",
      "at             y"
    ],
    [
      "aaaaaaaaaaaaaaaK",
      "aaaaaaaaaaaaaaaK",
      "aaaaaaaaaaaaaaaa",
      "aaaaaaaaaaaaaaaa",
      "aaaaaaaaaaaaaaaa",
      "aaaaaaaaaaaaaaaa",
      "aaaaaaaaaaaaaaaa",
      "aaaaaaaaaaaaaaaa",
      "aaaaam    maaaaa",
      "aaaa        aaaa",
      "ama           ma",
      "L D           ba",
      "               a",
      "M             D ",
      " N             O",
      "                "
    ],
    [
      "aaaaaaaaaaaaaaaa",
      "aaaaaaaaaaaaaaaa",
      "aaaaaaaaaaaaaaaa",
      "aaaaaaaaaaaaaaaa",
      "aaaaaaaaaaaaaaaa",
      "aaaaaaaaaaaaaaaa",
      "aaaaaaaaaaaaaaaa",
      "aaaaabaaaaaaaaaa",
      "aaaaam    maaaaa",
      "aaaa        aaaa",
      "Lm            ma",
      "L              a",
      "               a",
      "                ",
      "               F",
      "                "
    ],
    [
      "aaaaaaaaaaaaaaaa",
      "aaaaaaaaaaaaaaaa",
      "aaaaaaaaaaaaaaaa",
      "aaaaaaaaaaaaaaaa",
      "aaaaaaaaaaaaaaaa",
      "aaaaaaaaaaaaaaaa",
      "aaaaaaaaaaaaaaaa",
      "aaaaaaaaaaaaaaaa",
      "aaaaam    maaaaa",
      "aaaa        aaaa",
      "Lm            ma",
      "L              a",
      "               a",
      "                ",
      "               D",
      "                "
    ]
  ]
}