{
  "name": "multi_laboratory1_9_base4",
  "refpalette": "c70cities:multi_laboratory1_9_base4_palette",
  "xsize": 16,
  "zsize": 16,
  "slices": [
    [
      "aaaaaaaaaaaaaaaa",
      "aaaaaaaaaaaaaaaa",
      "aaaaaaaaaaaaaaaa",
      "aaaaaaaaaaaaaaaa",
      "aaaaaaaaaaaaaaaa",
      "aaaaaaaaaaaaaaaa",
      "aaaaaaaaaaaaaaaa",
      "aaaaaaaaaaaaaaaa",
      "aaaaa!aaaaaaaaaa",
      "aaaaaaaaaaaaaaaa",
      "aaaaaaaaaaaaaaaa",
      "aaaaaaaaaaaaaaaa",
      "aaaaaaaaaaaaaaaa",
      "bbbbbbbbbbbbbbbb",
      "cccccccccccccccc",
      "zzzzzzzzzzzzzzzz"
    ],
    [
      "d     e  d    fe",
      "dg   fe  d g   e",
      "d     e  d     e",
      "hg    hhhhg   gh",
      "     f          ",
      "           i    ",
      "   jkllllllkj   ",
      "mmmmmmmmmmmmmmmm",
      "   jnnnoohhpj   ",
      "                ",
      " q   q    q     ",
      " rs qr s  rq srs",
      "sq   q   sq   s ",
      "bbbbbbbbbbbbbbbb",
      "cccccccccccccccc",
      "zzzzzzzzzzzzzzzz"
    ],
    [
      "      i         ",
      "                ",
      "t               ",
      "                ",
      "                ",
      "                ",
      "   uw xt yA u   ",
      "mmmmmmmmmmmmmmmm",
      "   u B     pu   ",
      "                ",
      "                ",
      "                ",
      "                ",
      "bbbbbbbbbbbbbbbb",
      "cccccccccccccccc",
      "zzzzzzzzzzzzzzzz"
    ],
    [
      "                ",
      "                ",
      "                ",
      "                ",
      "                ",
      "                ",
      "   u        u   ",
      "mmmmmCmCmCCmmmmm",
      "    DDDEEFFF    ",
      "                ",
      "                ",
      "                ",
      "                ",
      "bbbbbbbbbbbbbbbb",
      "cccccccccccccccc",
      "zzzzzzzzzzzzzzzz"
    ],
    [
      "                ",
      "                ",
      "                ",
      "                ",
      "                ",
      "                ",
      "                ",
      "mmmmmmCCCmCmmmmm",
      "    IIIIIIII    ",
      "                ",
      "                ",
      "                ",
      "                ",
      "bbbbbbbbbbbbbbbb",
      "cccccccccccccccc",
      "zzzzzzzzzzzzzzzz"
    ],
    [
      "JKKmKKJKKLKKmKKL",
      "JKKmKKJKKLKKmKKL",
      "LKKmKKLKKJKKmKKJ",
      "LKKmKKLLJJKKmKKJ",
      "KKKmKKKKKKKKmKKK",
      "KKKmKKKKKKKKmKKK",
      "KKKmKKKKKKKKmKKK",
      "mmmmmmmmmmmmmmmm",
      "MMMMMMMMMMMMMMMM",
      "MLMMMLMMMMJMMMLM",
      "MJMMMLMMMMLMMMLM",
      "MLMMMLMMMMLMMMLM",
      "MMMMMMMMMMMMMMMM",
      "bbbbbbbbbbbbbbbb",
      "cccccccccccccccc",
      "zzzzzzzzzzzzzzzz"
    ]
  ]
}