{
  "name": "multi_laboratory1_6_base6",
  "refpalette": "c70cities:multi_laboratory1_6_base6_palette",
  "xsize": 16,
  "zsize": 16,
  "slices": [
    [
      "aaaaaaaaaaaaaaaa",
      "aaaaaaaaaaaaaaaa",
      "aaaaaaaaaaaaaaaa",
      "aaaaaaaaaaaaaaaa",
      "aaaaaaaaaaaaaaaa",
      "aaaaaaaaaaaaaaaa",
      "aaaaaaaaaaaaaaaa",
      "aaaaabbbbbbaaaaa",
      "aaabbc    cbbaaa",
      "abbb        bbba",
      "bc            cb",
      "b              b",
      "b              b",
      "                ",
      "                ",
      "                "
    ],
    [
      "  d ef dg h dg f",
      "   e            ",
      "                ",
      "                ",
      "i              i",
      "jj           kjj",
      "                ",
      "     llllll     ",
      "   llc    cll   ",
      " lll        lll ",
      "lc            cl",
      "l              l",
      "l              l",
      "                ",
      "                ",
      "                "
    ],
    [
      " mn   mno  mno  ",
      "                ",
      "                ",
      "                ",
      "                ",
      "p            q p",
      "                ",
      "     llllll     ",
      "   llc    cll   ",
      " lll        lll ",
      "lc        r   cl",
      "l         s    l",
      "l         t    l",
      "          u     ",
      "          u     ",
      "          w     "
    ],
    [
      "                ",
      "                ",
      "                ",
      "                ",
      "                ",
      "                ",
      "                ",
      "     llllll     ",
      "   llc    cll   ",
      " lll        lll ",
      "lc            cl",
      "l              l",
      "l         x    l",
      "                ",
      "                ",
      "                "
    ],
    [
      "                ",
      "                ",
      "                ",
      "                ",
      "                ",
      "                ",
      "                ",
      "     llllll     ",
      "   llc    cll   ",
      " lll        lll ",
      "lc            cl",
      "l              l",
      "l         y    l",
      "                ",
      "                ",
      "                "
    ],
    [
      "                ",
      "                ",
      "                ",
      "                ",
      "                ",
      "                ",
      "                ",
      "     llllll     ",
      "   llc    cll   ",
      " lll        lll ",
      "lc            cl",
      "l              l",
      "l         y    l",
      "                ",
      "                ",
      "                "
    ]
  ]
}