{
  "name": "multi_megatower1_7_floor2",
  "refpalette": "c70cities:multi_megatower1_7_floor2_palette",
  "xsize": 16,
  "zsize": 16,
  "slices": [
    [
      "aaab            ",
      "aaac            ",
      "aaac            ",
      "aaac            ",
      "aadef           ",
      "aaab            ",
      "aaab            ",
      "aaab            ",
      "aaac            ",
      "aaac            ",
      "aaac            ",
      "aadef           ",
      "aaab            ",
      "aaab            ",
      "aaab            ",
      "aaac            "
    ],
    [
      "ghib            ",
      "jkic            ",
      "lkic            ",
      "lkic            ",
      "lkdef           ",
      "lkib            ",
      "mnib            ",
      "opib            ",
      "qric            ",
      "mnic            ",
      "lkic            ",
      "lkdef           ",
      "lkib            ",
      "lkib            ",
      " kib            ",
      "hhic            "
    ],
    [
      "stib            ",
      "uuic            ",
      "  ic            ",
      "  ic            ",
      "  def           ",
      "  ib            ",
      "  ib            ",
      "wxib            ",
      "yAic            ",
      "  ic            ",
      "  ic            ",
      "  def           ",
      "  ib            ",
      "  ib            ",
      "  ib            ",
      "  ic            "
    ],
    [
      "BCDb            ",
      " CDc            ",
      " CDc            ",
      " CDc            ",
      "ECdef           ",
      "ECDb            ",
      "ECDb            ",
      "ECDb            ",
      "ECDc            ",
      "ECDc            ",
      "ECDc            ",
      "ECdef           ",
      "ECDb            ",
      "ECDb            ",
      "ECDb            ",
      "ECDc            "
    ],
    [
      "hC b            ",
      " C c            ",
      " F c            ",
      " C c            ",
      "ICdef           ",
      "JC b            ",
      "JF b            ",
      "JC b            ",
      "JC c            ",
      "JF c            ",
      "JC c            ",
      "JCdef           ",
      "JC b            ",
      "JF b            ",
      "JC b            ",
      "JC c            "
    ],
    [
      "CC              ",
      "CC              ",
      "CC              ",
      "IC              ",
      "JCd             ",
      "JC              ",
      "JC              ",
      "JC              ",
      "JC              ",
      "JC              ",
      "JC              ",
      "JCd             ",
      "JC              ",
      "JC              ",
      "JC              ",
      "JC              "
    ]
  ]
}