{
  "name": "multi_militarybase_2_base1",
  "refpalette": "c70cities:multi_militarybase_2_base1_palette",
  "xsize": 16,
  "zsize": 16,
  "slices": [
    [
      "vvvvvvvvvvvvvvvv",
      "aaaaaaaabbbbbbbv",
      "aaaaaaaabbbbbbbv",
      "aaaaaaaabbbbbbbv",
      "aaaaaaaabbbbbbbv",
      "ccccccccbbbbbbbv",
      "dddaaaacbbbbbbbv",
      "dddaaaacbbbbbbbv",
      "dddaaaacbbbbbbbv",
      "cccaaaacbbbbbbbv",
      "  caaaaceeeeeeev",
      "  caaaaceeeeeeev",
      "  caaaaceeeeeeev",
      "  cccccceeeeeeev",
      "        veeeeeev",
      "        veeeeeev"
    ],
    [
      "vvvvvvvvvfffvvvv",
      "ghg ghg ijjjk lv",
      "m m m m i   n  v",
      "o p p p q   k !v",
      "rrrrrrrri   k  v",
      " sv g gvi   n  v",
      "  t m m i   k  v",
      "  t o p i   n  v",
      "  u     q   k  v",
      "wwv    vi   n  v",
      "  w x ytvvvvvvvv",
      "  w A Ateeeeeeev",
      "  w B Bteeeeeeev",
      "  vCCCCveeeeeeev",
      "        veeeeeev",
      "        veeeeeev"
    ],
    [
      "vvvvvvvvvjjjvvvv",
      "ghg ghg i   k Dv",
      "m m m m i   E  v",
      "F I I I J   k  v",
      "rrrrrrrri   k  v",
      " sv g gvi   E  v",
      "  t m m i   k  v",
      "  t F I i   E  v",
      "  K     J   k  v",
      "  v    vi   E  v",
      "  w L Mtvvvvvvvv",
      "  w A Ateeeeeeev",
      "  w B Bteeeeeeev",
      "  vCCCCveeeeeeev",
      "        veeeeeev",
      "        veeeeeev"
    ],
    [
      "vvvvvvvvvjjjvvvv",
      "        i   N  v",
      "        i   N  v",
      "        i   N  v",
      "rrrrrrrri   NOOv",
      " sv    vi   N  v",
      "  t     i   NOOv",
      "  t     i   N  v",
      "  t     i   NOOv",
      "  v    vi   N  v",
      "  w    tvvvvvvvv",
      "  w    teeeeeeev",
      "  w    teeeeeeev",
      "  vCCCCveeeeeeev",
      "        veeeeeev",
      "        veeeeeev"
    ],
    [
      "vvvvvvvvvvvvvvvv",
      "        i      v",
      "        i      v",
      "        i      v",
      "rrrrrrrri      v",
      " sv    vi      v",
      "  t     i      v",
      "  t     i      v",
      "  t     i      v",
      "  v    vi      v",
      "  P    tvvvvvvvv",
      "  Q    teeeeeeev",
      "  P    teeeeeeev",
      "  vCCCCveeeeeeev",
      "        veeeeeev",
      "        veeeeeev"
    ],
    [
      "vvvvvvvvvvvvvvvv",
      "RRcRRRRcSSSSSSSv",
      "RRcRRRRcSSSSSSSv",
      "RRcRRRRcSSSSSSSv",
      "vvcvvvvcSSSSSSSv",
      "RscRRRRcSSSSSSSv",
      "RRcRRRRcSSSSSSSv",
      "RRcRRRRcSSSSSSSv",
      "RRcRRRRcSSSSSSSv",
      "ccccccccSSSSSSSv",
      "RRcRRRRcvvvvvvvv",
      "RRcRRRRceeeeeeev",
      "RRcRRRRceeeeeeev",
      "RRcccccceeeeeeev",
      "RRcRRRRRveeeeeev",
      "RRcRRRRRveeeeeev"
    ]
  ]
}