{
  "name": "multi_militarybase_4_base4",
  "refpalette": "c70cities:multi_militarybase_4_base4_palette",
  "xsize": 16,
  "zsize": 16,
  "slices": [
    [
      "vvvvvvvvvvvvvvvv",
      "avaaaaaaavaaaavv",
      "abaaaaaaabaaaavv",
      "abaaaaaaabaaaavv",
      "abaaaaaaabaaaavv",
      "bvbbbbbbbvbbbvvv",
      "abaaaaaaabaaaavv",
      "abaaaaaaabaaaavv",
      "abaaaaaaabaaaavv",
      "avaaaaaaabaaaavv",
      "abaaaaaaabaaaavv",
      "abaaaaaaabaaaavv",
      "abaaaaaaabaaaavv",
      "bvbbbbbbbbbbbvvv",
      "cbddddddddddddvv",
      "cbddddddddddddvv"
    ],
    [
      "vvvvvvvvvvvvvvvv",
      "evfffffffvggghvv",
      "eijklmjlno   pvv",
      "ei       q   hvv",
      "ei       o   pvv",
      "ev       vrrrvvv",
      "ei          sfvv",
      "ei          tfvv",
      "ui  wxw     yfvv",
      "uvA xBx     Cfvv",
      " i  wxw     yfvv",
      " D          yfvv",
      " i          tfvv",
      "ev           vvv",
      "g             vv",
      "              vv"
    ],
    [
      "vvvvvvvvvvvvvvvv",
      "EvmlmjlFmv   !vv",
      " i       o    vv",
      " i       I   Jvv",
      "Ki       o    vv",
      "ev       vrrrvvv",
      "ei           Cvv",
      "ei           Lvv",
      "ui  MMM      yvv",
      " vA MNM      tvv",
      " i  MMM      yvv",
      " D           Ovv",
      " i           Cvv",
      "ev           vvv",
      "              vv",
      "             Pvv"
    ],
    [
      "vvvvvvvvvvvvvvvv",
      " v       v    vv",
      " i       o    vv",
      " i       o    vv",
      " i       o    vv",
      " v       vrrrvvv",
      " i            vv",
      "Ki            vv",
      "ei            vv",
      "evA           vv",
      "Qi            vv",
      " i            vv",
      "Ri            vv",
      "ev           vvv",
      "              vv",
      "              vv"
    ],
    [
      "vvvvvvvvvvvvvvvv",
      " v       v    vv",
      " i       o    vv",
      " i       o    vv",
      " i       o    vv",
      " vSSSSSSSvrrrvvv",
      " i       S    vv",
      " i       S    vv",
      " i       S    vv",
      " vA      S    vv",
      "Ki       S    vv",
      "ei       S    vv",
      "ei       S    vv",
      "evSSSSSSSSSSSvvv",
      "              vv",
      "              vv"
    ],
    [
      "vvvvvvvvvvvvvvvv",
      " vTTTTTTTvTTTTvv",
      " UTTTTTTTbTTTTvv",
      " UTTTTTTTbTTTTvv",
      " UTTTTTTTbTTTTvv",
      " vbbbbbbbbbbbvvv",
      " UTTTTTTTbTTTTvv",
      " UTTTTTTTbTTTTvv",
      " UTTTTTTTbTTTTvv",
      " vATTTTTTbTTTTvv",
      " UTTTTTTTbTTTTvv",
      " UTTTTTTTbTTTTvv",
      " UTTTTTTTbTTTTvv",
      "Kvbbbbbbbbbbbvvv",
      "QUTTTTTTTTTTTTvv",
      "VUTTTTTTTTTTTTvv"
    ]
  ]
}