{
  "name": "multi_militarybase_5_ground",
  "refpalette": "c70cities:multi_militarybase_5_ground_palette",
  "xsize": 16,
  "zsize": 16,
  "slices": [
    [
      "aaaaabbbabbaazcd",
      "aaaaaaaaaaaazzcd",
      "aaaaaaaaaaaazacd",
      "aaaababbbbbaazcd",
      "aaaaaaaaaaaazzcd",
      "aaaaaaaaaaaaaacd",
      "aaaaaaaaaaaazacd",
      "aaaaaaaaaaaazzcd",
      "eaaaaaaaaaaaazcd",
      "aaaaaaaaaaaazzcd",
      "aaaaaaaaaaaaazcd",
      "aaaaaaaaaaaazacd",
      "azzzaazzazazzzcd",
      "aazzzzazaazzaacd",
      "cccccccccccccccd",
      "dddddddddddddddd"
    ],
    [
      "             fc ",
      "              c ",
      "              c ",
      "g             c ",
      "gg           fc ",
      "hgg    iii    c ",
      "  g   jkkkj  lc ",
      " mg  nkokokp fc ",
      "e g  nkoookp fc ",
      "  g  nkokokp  c ",
      " mg   jkkkj  fc ",
      "ggg    qqq    c ",
      "             fc ",
      " r ff l   f  lc ",
      "ccccccccccccccc ",
      "                "
    ],
    [
      "              c ",
      "              c ",
      "              c ",
      "g             c ",
      "gg            c ",
      " gg           c ",
      "  g          lc ",
      "  g           c ",
      "e g     s     c ",
      "  g           c ",
      "  g     ~     c ",
      "ggg           c ",
      "              c ",
      "  r   l      lc ",
      "ccccccccccccccc ",
      "                "
    ],
    [
      "              c ",
      "              c ",
      "              c ",
      "g             c ",
      "gg            c ",
      " gg           c ",
      "  g          lc ",
      "  g           c ",
      "  g           c ",
      "  g           c ",
      "  g    ~~     c ",
      "ggg           c ",
      "              c ",
      "   r  l      lc ",
      "ccccccccccccccc ",
      "                "
    ],
    [
      "              c ",
      "              c ",
      "              c ",
      "t             c ",
      "tt            c ",
      " tt           c ",
      "  t          lc ",
      "  t           c ",
      "  t           c ",
      "  t           c ",
      "  t     ~     c ",
      "ttt           c ",
      "              c ",
      "    r l      lc ",
      "ccccccccccccccc ",
      "                "
    ],
    [
      "             uw ",
      "             uw ",
      "             uw ",
      "             uw ",
      "             uw ",
      "             uw ",
      "             ux ",
      "             uy ",
      "             uw ",
      "             uw ",
      "        ~    uw ",
      "             uw ",
      "             uw ",
      "     uuuuuuuuuA ",
      "BBBBBB!BBBBBBAA ",
      "                "
    ]
  ]
}