{
  "name": "multi_laboratory1_1_base4",
  "refpalette": "c70cities:multi_laboratory1_1_base4_palette",
  "xsize": 16,
  "zsize": 16,
  "slices": [
    [
      "zabccccccccccccc",
      "zabccccccccccccc",
      "zabccccccccccccc",
      "zabccccccccccccc",
      "zabccccccccccccc",
      "zabccccccccccccc",
      "zabccccccccdcccc",
      "zabccccccccccccc",
      "zabccccccccccccc",
      "zabccccccccccccc",
      "zabcc!cccccccccc",
      "zabccccccccccccc",
      "zabcccccccccccce",
      "zabccccccccdccce",
      "zabcccccccccccef",
      "zabccccccccccce "
    ],
    [
      "zabghhhhhhgi    ",
      "zabjk l mn i    ",
      "zabhl    omi    ",
      "zabhkp     i    ",
      "zabh       q    ",
      "zabgrstrurwi    ",
      "zabiiiiiiiidf   ",
      "zabxyAAAA xi    ",
      "zabB  C    i    ",
      "zabD nt    i    ",
      "zab tE FI  i    ",
      "zabJoKKKKt i    ",
      "zabJ AAAA  i  LM",
      "zab    C   d  fM",
      "zab o o    i  Mf",
      "zabD nN I  O  M "
    ],
    [
      "zabghhhhhhgi    ",
      "zabh       P    ",
      "zabQ       P    ",
      "zabQ       i    ",
      "zabh       R    ",
      "zabg       i    ",
      "zabiiiiiiiidS   ",
      "zab   TUV  i    ",
      "zab        P    ",
      "zab        P    ",
      "zab        P    ",
      "zab  tWXn  P    ",
      "zab  V T   i   M",
      "zab        d  SM",
      "zab        i  Mf",
      "zab        O  M "
    ],
    [
      "zabgYYYYYYgi    ",
      "zab        Z    ",
      "zab0       Z    ",
      "zab1       i    ",
      "zab        Z    ",
      "zabg       i    ",
      "zabiiiiiiiidS   ",
      "zab        i    ",
      "zab        P    ",
      "zab        P    ",
      "zab        P    ",
      "zab        P    ",
      "zab        i   M",
      "zab        d  SM",
      "zab        i  Mf",
      "zab        O  M "
    ],
    [
      "zabg      gi    ",
      "zab        i    ",
      "zab        i    ",
      "zab2       i    ",
      "zab        i    ",
      "zabg       i    ",
      "zabiiiiiiiid    ",
      "zab        i    ",
      "zab        i    ",
      "zab        i    ",
      "zab        i    ",
      "zab        i    ",
      "zab        i   M",
      "zab        d   M",
      "zab        i  Mf",
      "zab        i  M "
    ],
    [
      "zabg333333gZ4444",
      "zab35333363Z4744",
      "zab33333333Z4744",
      "zab33333333Z4744",
      "zab35333353Z4744",
      "zabg3333333Z4444",
      "zabiiiiiiiid4444",
      "zab88888888Z4444",
      "zab88888888Z4444",
      "zab88688788Z4444",
      "zab88688788Z4444",
      "zab88788688Z4444",
      "zab88788788Z444M",
      "zab88888888d444M",
      "zab88888888Z44Mf",
      "zab88688788Z44M "
    ]
  ]
}