{
  "name": "multi_megatower1_4_floor6",
  "refpalette": "c70cities:multi_megatower1_4_floor6_palette",
  "xsize": 16,
  "zsize": 16,
  "slices": [
    [
      "a   b           ",
      "a   bcc         ",
      "a   bdd         ",
      "efggbdd         ",
      "bbbbhbbb   h    ",
      "bbbbbbbb        ",
      "bbbbbbbb        ",
      "bbbbbbbb        ",
      "bbbbbbbb        ",
      "bbbbbbbb        ",
      "bbbbbbbb   i    ",
      "bbbbhbbb  jhi j ",
      "bbbbbbbb   j    ",
      "bbbbbbbb  kk    ",
      "bbbbbbbb        ",
      "bbbbbbbb        "
    ],
    [
      "a   l           ",
      "a   l           ",
      "a   l           ",
      "agmml           ",
      "nopqh      h    ",
      "       r        ",
      "       s        ",
      " t ut  s        ",
      " wx t  s        ",
      "xt  t  s        ",
      " u x   r        ",
      "    h      h    ",
      "  x x  r        ",
      " t uy  s        ",
      " !  t  s        ",
      " wx t  s        "
    ],
    [
      "a   l           ",
      "a   l           ",
      "a   l           ",
      "ag  l           ",
      "n ABh  !   h    ",
      "       C        ",
      "                ",
      " t  t           ",
      " t  D           ",
      "    E           ",
      "       C        ",
      "    h  F   h    ",
      "       C        ",
      " E              ",
      " t  t           ",
      "    E           "
    ],
    [
      "a   l           ",
      "a   l           ",
      "a   l           ",
      "agggl           ",
      "nI  h  J   h    ",
      "       C        ",
      "                ",
      "                ",
      "                ",
      "                ",
      "       C        ",
      "    h  J   h    ",
      "       C        ",
      "                ",
      " D              ",
      "                "
    ],
    [
      "a   l           ",
      "a   l           ",
      "a   l           ",
      "agggl           ",
      "nnnnh  J   h    ",
      "                ",
      "                ",
      "                ",
      "                ",
      "                ",
      "                ",
      "    h  J   h    ",
      "                ",
      "                ",
      "                ",
      "                "
    ],
    [
      "K   KLLL   K    ",
      "K   KLLL   K    ",
      "K   KLML   K    ",
      "KgNNKLLL   K    ",
      "OOOOhOOOOOOhOOOO",
      "LLLLKLLL   K    ",
      "LLMLKLML   K    ",
      "LLLLKLLL   K    ",
      "LLLLKLLL   K    ",
      "LLMLKLML   K    ",
      "LLLLKLLL   K    ",
      "OOOOhOOOOOOhOOOO",
      "    KLLL   K    ",
      "    KLML   K    ",
      "    KLLL   K    ",
      "    KLLL   K    "
    ]
  ]
}