{
  "name": "multi_derrick_1_ground",
  "refpalette": "c70cities:multi_derrick_1_ground_palette",
  "xsize": 16,
  "zsize": 16,
  "slices": [
    [
      "zzzzzzzzzzzzzzzz",
      "zzzzzzzzzzzzzzzz",
      "aHHHHHHHHHzzzzzz",
      "aHHHHHHHHHzzzzzz",
      "aHHHHHHHHHzzzzzz",
      "aHHHHHHHHHzzzzzz",
      "aHHHHHHHHHHHHHHz",
      "aHHHHHHHHHHHHHHz",
      "aHHHHHHHHHHHHHHz",
      "aHHHHHHHHHHHHHHz",
      "azzzzzbbzzzzzzzz",
      "azbbbbbbczzzzzzz",
      "azbbbbbcczzzzzzz",
      "azbbbbbbczzzzzzz",
      "zzzzzzzzzzzzzzzz",
      "zzzzzzzzzzzzzzzz"
    ],
    [
      "        d       ",
      "efgggfgggfeeefh ",
      "  i j i j    e  ",
      "             eh ",
      "             e d",
      " kl mkl mk   f  ",
      "             n  ",
      "o            n  ",
      "o       ~       ",
      "             n  ",
      " fggggpggfq rf  ",
      " gst   gugrrqkh ",
      " gw    x gyr ehd",
      " gs  ABgCg   eh ",
      "efgggggggfeeefd ",
      "                "
    ],
    [
      "                ",
      "DfgggfgggfDDDf  ",
      "             D  ",
      "             D  ",
      "             D  ",
      " k   k   k   f  ",
      "             n  ",
      "                ",
      "        ~       ",
      "     E F     n  ",
      " fgIIgJggf   f  ",
      " IK    gLgr  D  ",
      " IM    NOgy  D  ",
      " IP  Q gRg   D  ",
      "DfgIIggggfDDDf  ",
      "                "
    ],
    [
      "                ",
      " fSSSfSSSf   T  ",
      "                ",
      "                ",
      "                ",
      " k   k   k   f  ",
      "             n  ",
      "                ",
      "        ~    n  ",
      "             n  ",
      " fgggggggf   f  ",
      " gUUUUUVUg      ",
      " gUUUUUVUgy     ",
      " gUUUUUVUg      ",
      " fgggggggf   T  ",
      "                "
    ],
    [
      "                ",
      " k   k   k      ",
      " WUUUUUUUW      ",
      " WUUUUUUUW      ",
      " XSSSSSSSX      ",
      " XXXXXXXXX   T  ",
      "                ",
      "                ",
      "        ~       ",
      "                ",
      " fTTTTTTTf   T  ",
      " T       T      ",
      " T     yyyy     ",
      " TYk   yyT      ",
      " fTTTTTTTf      ",
      "                "
    ],
    [
      " XXXXXXXXX      ",
      " XSSSSSSSX      ",
      "                ",
      "                ",
      "                ",
      "                ",
      "                ",
      "                ",
      "        ~       ",
      "                ",
      "                ",
      "                ",
      "                ",
      "  kk   Z0       ",
      "                ",
      "                "
    ]
  ]
}