{
  "name": "multi_laboratory1_8_ground",
  "refpalette": "c70cities:multi_laboratory1_8_ground_palette",
  "xsize": 16,
  "zsize": 16,
  "slices": [
    [
      "aaaaa      aaaaa",
      "aaaaa      aaaaa",
      "aaaaa      aaaaa",
      "aaaaa      aaaaa",
      "aaaaa      aaaaa",
      "aaaaabcdecbaaaaa",
      "aaaaaff  ffaaaaa",
      "aaaaaaaaaaaaaaaa",
      "aaaaaaaaaaaaaaaa",
      "aaaaaaaaaaaaaaaa",
      "aaaaaaghhgaaaaaa",
      "aaaaaghgghgaaaaa",
      "aaaaahgggghaaaaa",
      "aaaaaggggggaaaaa",
      "aaaaaggggggaaaaa",
      "aaaaaggggggaaaaa"
    ],
    [
      "  ije      dk  l",
      "  ije      dk  m",
      "n ije      dk  m",
      "  oje      dko p",
      "qrqs b    b tquq",
      "w xjeyd  eydkA  ",
      "  Bje ddee dkC  ",
      "qDqE   FF   IqJq",
      "  oj        ko  ",
      "   d        e   ",
      "K  d  LMNL  e  O",
      "KP d LNLLNL e QO",
      "K R  NMLLSN  T O",
      "K U  LLVLLL  W O",
      "KP d LLLLLL e QO",
      "K  d LLLXLL e  O"
    ],
    [
      "  Yj        k   ",
      "  Zj        k   ",
      "  0j        k   ",
      "  1j b    b k1  ",
      "q2q eyd  eyd q3q",
      "   j        k   ",
      "   j        k   ",
      "q4q          q5q",
      "  1j        k1  ",
      "   d        e   ",
      "   d        e   ",
      "   d        e  6",
      "  7          8  ",
      "9 @          #  ",
      "$  d        e   ",
      "   d        e   "
    ],
    [
      "  %j        k   ",
      "  9j        k   ",
      "  ^j b    b k   ",
      "  1jeyd  eydk1  ",
      "q&q          q&q",
      "  Yj        k*  ",
      "  Zj        k(  ",
      "q)q          q)q",
      "  1j        k1  ",
      "   d        e   ",
      "   d        e   ",
      "   d        e   ",
      "   d        e   ",
      "   d        e   ",
      "   d        e   ",
      "   d        e   "
    ],
    [
      "   j        k   ",
      "   j b    b k   ",
      "   jeyd  eydk   ",
      "   j        k   ",
      "qqq          qqq",
      "  +j        k   ",
      "  -j        k[  ",
      "qqq          qqq",
      "   j        k   ",
      "   d        e   ",
      "   d        e   ",
      "   d        e   ",
      "   d        e   ",
      "   d        e   ",
      "   d        e   ",
      "   d        e   "
    ],
    [
      "]]{j b    b k{}]",
      "]]{jeyd  eydk{}]",
      "{{{j        k{{{",
      "{{{j        k{{{",
      "qqqj        kqqq",
      "  -j        k{]}",
      "   j        k{]}",
      "qqq\\||||||||`qqq",
      "{{{j        k{{{",
      "{{{j        k{{{",
      "]]{j        k{}}",
      "]]{j        k{}}",
      "{{{j        k{{{",
      "{{{j        k{{{",
      "}]{j        k{]]",
      "}]{j        k{]]"
    ]
  ]
}