{
  "name": "multi_condo1_4_floor7",
  "refpalette": "c70cities:multi_condo1_4_floor7_palette",
  "xsize": 16,
  "zsize": 16,
  "slices": [
    [
      "aaaaabccccccde  ",
      "fffgabhddddddii ",
      "   jabhkkkkkde  ",
      "   jabhkkkkkde  ",
      "   jabhkkkkkde  ",
      "   jabhkkkkkdii ",
      "   jabhdddddde  ",
      "   jabh     he  ",
      "   jabh     he  ",
      "   jabh     de  ",
      "   jabl     dii ",
      "   jabmdddddde  ",
      "   jabhhj   de  ",
      "   jabhhn   de  ",
      "ooopabhddddddii ",
      "aaaaabccccccde  "
    ],
    [
      "      dqrdstd   ",
      "uuuu  dddddddii ",
      "   u  w     d   ",
      "   u  d     x   ",
      "   u  d  yA d   ",
      "   u  d BCC dii ",
      "   u  ddddddd   ",
      "   u  d     D   ",
      "   u  E     D   ",
      "   u  F     d   ",
      "   u  d     dii ",
      "   u  ddddddd   ",
      "   u  d     x   ",
      "   u  I Jn  d   ",
      "uuuu  dddddddii ",
      "      dKrdLMd   "
    ],
    [
      "      dNOd  d   ",
      "      dddddddii ",
      "      P     d   ",
      "      dQ    R   ",
      "      d  ST d   ",
      "      dUUCC dii ",
      "      ddddddd   ",
      "      d     D   ",
      "      V     D   ",
      "      W     d   ",
      "      d     dii ",
      "      ddddddd   ",
      "      d     R   ",
      "      X  Jn d   ",
      "      dddddddii ",
      "      dYOd  d   "
    ],
    [
      "      dN d  d   ",
      "      dddddddii ",
      "      Z     d   ",
      "      d     R   ",
      "      d     d   ",
      "      dU 00 dii ",
      "      ddddddd   ",
      "      d     D   ",
      "      Z     D   ",
      "      Z     d   ",
      "      d     dii ",
      "      ddddddd   ",
      "      d   ZnR   ",
      "      Z   Jhd   ",
      "      dddddddii ",
      "      dY d  d   "
    ],
    [
      "      d  d  d   ",
      "      dddddddii ",
      "      d     d   ",
      "      d     d   ",
      "      d     d   ",
      "      dU    dii ",
      "      ddddddd   ",
      "      d     D   ",
      "      d     D   ",
      "      d     d   ",
      "      d     dii ",
      "      ddddddd   ",
      "      d  Zj d   ",
      "      d     d   ",
      "      dddddddii ",
      "      d  d  d   "
    ],
    [
      "      dkkkkkd   ",
      "      dddddddii ",
      "      dU    d   ",
      "      dU    d   ",
      "      dU    d   ",
      "      dUUUUUdii ",
      "      ddddddd   ",
      "      d     D   ",
      "      d     D   ",
      "      d     d   ",
      "      d     dii ",
      "      ddddddd   ",
      "      d Zj  d   ",
      "      d     d   ",
      "      dddddddii ",
      "      dkkkkkd   "
    ]
  ]
}