{
  "name": "multi_megatower1_1_floor3",
  "refpalette": "c70cities:multi_megatower1_1_floor3_palette",
  "xsize": 16,
  "zsize": 16,
  "slices": [
    [
      "            ab  ",
      "            cb  ",
      "            cbde",
      "            cbff",
      "           ghibb",
      "            abbb",
      "            abjj",
      "            abjj",
      "            cbjj",
      "            cbjj",
      "            cbbb",
      "           ghibb",
      "            abbb",
      "            abbb",
      "            abbb",
      "            cbbb"
    ],
    [
      "            ak  ",
      "            ckd ",
      "            ckl ",
      "            ck  ",
      "           ghicm",
      "            an  ",
      "            an  ",
      "            an  ",
      "            cn  ",
      "            cnoo",
      "            cnpq",
      "           ghip ",
      "            anr ",
      "            anss",
      "            ant ",
      "            cnuw"
    ],
    [
      "            akf ",
      "            ckl ",
      "            ck  ",
      "            ck  ",
      "           ghicx",
      "            an  ",
      "            an  ",
      "            ay  ",
      "            cy  ",
      "            cnoo",
      "            cnp ",
      "           ghip ",
      "            an  ",
      "            anss",
      "            anA ",
      "            cn  "
    ],
    [
      "            aklB",
      "            ck  ",
      "            ck  ",
      "            ck C",
      "           ghicc",
      "            an  ",
      "            an  ",
      "            aD  ",
      "            cD  ",
      "            cnoo",
      "            cnp ",
      "           ghip ",
      "            an  ",
      "            anss",
      "            an  ",
      "            cn  "
    ],
    [
      "            aE e",
      "            cE B",
      "            cE  ",
      "            cE  ",
      "           ghicc",
      "            an  ",
      "            an  ",
      "            an  ",
      "            cn  ",
      "            cnoo",
      "            cnp ",
      "           ghip ",
      "            anF ",
      "            anss",
      "            anF ",
      "            cn  "
    ],
    [
      "            aI  ",
      "            cI e",
      "            cI f",
      "            cIdf",
      "           ghiJJ",
      "            aIKK",
      "            aIKK",
      "            aIKK",
      "            cIKK",
      "            cILL",
      "            cIbb",
      "           ghiJJ",
      "            aIbb",
      "            aIbb",
      "            aIFF",
      "            cI  "
    ]
  ]
}