{
  "name": "multi_megatower1_3_base2",
  "refpalette": "c70cities:multi_megatower1_3_base2_palette",
  "xsize": 16,
  "zsize": 16,
  "slices": [
    [
      "vvvvvvvvvvvvvvvv",
      "aaaaaaaaaaaaaaaa",
      "aaaaaaaaaaaaaaaa",
      "vvvvvvvvvvvvvvvv",
      "vvvvvvvvvvvvvvvv",
      "HHHHHHHHHHHHHHHH",
      "HHHHbHHHHHHbHHHH",
      "HHHHHHHHHHHHHHHH",
      "HHHHHHHHHHHHHHHH",
      "HHHHHHHHHHHHHHHH",
      "HHHHHHHHHHHHHHHH",
      "HHHHHHHHHHHHHHHH",
      "HHHHHHHHHHHHHHHH",
      "vvvvbHHHHHHbHHHH",
      "vcccvHHHHHHHHHHH",
      "vdddvHHHHHHHHHHH"
    ],
    [
      "vvvvvvvvvvvvvvvv",
      "aaaaaaaaaaaaaaaa",
      "aaaaaaaaaaaaaaaa",
      "vvvvvvvvvvvvvvvv",
      "eeeeeeeeeeeeeeee",
      "fgfg fgfgfg fgfg",
      "    b      b    ",
      "hihijhihihijhihi",
      "                ",
      "                ",
      "                ",
      "                ",
      "    kfgfgfgkfgfg",
      "llllb      b    ",
      "mcccnhihihi hihi",
      "mdoon           "
    ],
    [
      "vvvvvvvvvvvvvvvv",
      "aaaaaaaaaaaaaaaa",
      "aaaaaaaaaaaaaaaa",
      "vvvvvvvvvvvvvvvv",
      "                ",
      "                ",
      "    b      b    ",
      "                ",
      "                ",
      "                ",
      "                ",
      "                ",
      "                ",
      "llllb      b    ",
      "mcccn           ",
      "mdoon           "
    ],
    [
      "vvvvvvvvvvvvvvvv",
      "aaaaaaaaaaaaaaaa",
      "aaaaaaaaaaaaaaaa",
      "vvvvvvvvvvvvvvvv",
      "                ",
      "                ",
      "    b      b    ",
      "                ",
      "                ",
      "                ",
      "                ",
      "                ",
      "                ",
      "llllb      b    ",
      "mcccn           ",
      "mdoon           "
    ],
    [
      "vvvvvvvvvvvvvvvv",
      "aaaaaaaaaaaaaaaa",
      "aaaaaaaaaaaaaaaa",
      "vvvvvvvvvvvvvvvv",
      "                ",
      "    p      p    ",
      "    b      b    ",
      "                ",
      "                ",
      "                ",
      "                ",
      "                ",
      "                ",
      "llllb      b    ",
      "mcccn           ",
      "mdddn           "
    ],
    [
      "vvvvvvvvvvvvvvvv",
      "aaaaaaaaaaaaaaaa",
      "aaaaaaaaaaaaaaaa",
      "vvvvvvvvvvvvvvvv",
      "vvvvvvvvvvvvvvvv",
      "qqqqqqqqqqqqqqqq",
      "bbbbbbbbbbbbbbbb",
      "qqqqbqqqqqqbqqqq",
      "qqqqbqqqqqqbqqqq",
      "qqqqbqqqqqqbqqqq",
      "qqqqbqqqqqqbqqqq",
      "qqqqbqqqqqqbqqqq",
      "qqqqbqqqqqqbqqqq",
      "bbbbbbbbbbbbbbbb",
      "bcccbqqqqqqqqqqq",
      "b   bqqqqqqqqqqq"
    ]
  ]
}