{
  "name": "multi_megatower1_7_base1",
  "refpalette": "c70cities:multi_megatower1_7_base1_palette",
  "xsize": 16,
  "zsize": 16,
  "slices": [
    [
      "HHHHHHHHHHHvvaav",
      "HHHHHHHHHHHvvaav",
      "HHHHHHHHHHHvvaav",
      "HHHHHHHHHHHvvaav",
      "HHbHHHHHHbHvvaav",
      "vvHHHHHHHHHvvaav",
      "ccdHHHHHHHHvvaav",
      "cceHHHHHHHHvvaav",
      "cceHHHHHHHHvvaav",
      "ccfHHHHHHHHvvaav",
      "vvHHHHHHHHHvvaav",
      "vHbHHHHHHbHvvaav",
      "vHHHHHHHHHHvvaav",
      "vHHHHHHHHHHvvaav",
      "vHHHHHHHHHHvvaav",
      "vHHHHHHHHHHvvaav"
    ],
    [
      "        g hivaav",
      "        j kivaav",
      "        g hivaav",
      " h      j kivaav",
      " kbl    mb ivaav",
      "vvn     g hivaav",
      "Hon     j kivaav",
      "Hon     g hivaav",
      "Hon     j kivaav",
      "Hon     g hivaav",
      "vvn     j kivaav",
      "p bl    mb ivaav",
      "p       g hivaav",
      "pg h    j kivaav",
      "pj k    g hivaav",
      "pg h    j kivaav"
    ],
    [
      "            vaav",
      "            vaav",
      "            vaav",
      "            vaav",
      "  b      b  vaav",
      "vv          vaav",
      "            vaav",
      "            vaav",
      "            vaav",
      "            vaav",
      "vv          vaav",
      "  b      b  vaav",
      "            vaav",
      "            vaav",
      "            vaav",
      "            vaav"
    ],
    [
      "            vaav",
      "            vaav",
      "            vaav",
      "            vaav",
      "  b      b  vaav",
      "vv          vaav",
      "            vaav",
      "            vaav",
      "            vaav",
      "            vaav",
      "vv          vaav",
      "  b      b  vaav",
      "            vaav",
      "            vaav",
      "            vaav",
      "            vaav"
    ],
    [
      "            vaav",
      "            vaav",
      "            vaav",
      "            vaav",
      "  b      b  vaav",
      "vv          vaav",
      "            vaav",
      "            vaav",
      "            vaav",
      "            vaav",
      "vv          vaav",
      "  b      b  vaav",
      "            vaav",
      "            vaav",
      "            vaav",
      "            vaav"
    ],
    [
      "ccbccccccbcvvaav",
      "ccbccccccbcvvaav",
      "ccbccccccbcvvaav",
      "ccbccccccbcvvaav",
      "bbbbbbbbbbcvvaav",
      "vvbccccccbcvvaav",
      "  bccccccbcvvaav",
      "  bccccccbcvvaav",
      "  bccccccbcvvaav",
      "  bccccccbcvvaav",
      "vvbccccccbcvvaav",
      "bbbbbbbbbbcvvaav",
      " cbccccccbcvvaav",
      " cbccccccbcvvaav",
      " cbccccccbcvvaav",
      " cbccccccbcvvaav"
    ]
  ]
}