{
  "name": "multi_megatower1_5_base1",
  "refpalette": "c70cities:multi_megatower1_5_base1_palette",
  "xsize": 16,
  "zsize": 16,
  "slices": [
    [
      "vvvvvvvvvvvvvvvv",
      "HHHHHHHHHHHHHHHH",
      "HHHHaHHHHHHaHHHH",
      "HHHHHHHHHHHHHHHH",
      "HHHHHHHHHHHHHHHH",
      "HHHHHHHHHHHHHHHH",
      "HHHHHHHHHHHHHHHH",
      "HHHHHHHHHHHHHHHH",
      "HHHHHHHHHHHHHHHH",
      "HHHHaHHHHHHaHHHH",
      "HHHHHHHHHHHHHHHH",
      "vvvvvvvvvvvvvvvv",
      "vvvvvvvvvvvvvvvv",
      "bbbbbbbbbbbbbbbb",
      "bbbbbbbbbbbbbbbb",
      "vvvvvvvvvvvvvvvv"
    ],
    [
      "cccdddccccdddccc",
      "efef efefef efef",
      "    a      a    ",
      "ghghighghghighgh",
      "                ",
      "                ",
      "                ",
      "                ",
      "efefjefefefjefef",
      "    a      a    ",
      "ghgh ghghgh ghgh",
      "kkkkkkkkkkkkkkkk",
      "vvvvvvvvvvvvvvvv",
      "bbbbbbbbbbbbbbbb",
      "bbbbbbbbbbbbbbbb",
      "vvvvvvvvvvvvvvvv"
    ],
    [
      "                ",
      "                ",
      "    a      a    ",
      "                ",
      "                ",
      "                ",
      "                ",
      "                ",
      "                ",
      "    a      a    ",
      "                ",
      "                ",
      "vvvvvvvvvvvvvvvv",
      "bbbbbbbbbbbbbbbb",
      "bbbbbbbbbbbbbbbb",
      "vvvvvvvvvvvvvvvv"
    ],
    [
      "                ",
      "                ",
      "    a      a    ",
      "                ",
      "                ",
      "                ",
      "                ",
      "                ",
      "                ",
      "    a      a    ",
      "                ",
      "                ",
      "vvvvvvvvvvvvvvvv",
      "bbbbbbbbbbbbbbbb",
      "bbbbbbbbbbbbbbbb",
      "vvvvvvvvvvvvvvvv"
    ],
    [
      "                ",
      "                ",
      "    a      a    ",
      "                ",
      "                ",
      "                ",
      "                ",
      "                ",
      "                ",
      "    a      a    ",
      "                ",
      "                ",
      "vvvvvvvvvvvvvvvv",
      "bbbbbbbbbbbbbbbb",
      "bbbbbbbbbbbbbbbb",
      "vvvvvvvvvvvvvvvv"
    ],
    [
      "    a      a    ",
      "llllallllllallll",
      "aaaaaaaaaaaaaaaa",
      "llllallllllallll",
      "llllallllllallll",
      "llllallllllallll",
      "llllallllllallll",
      "llllallllllallll",
      "llllallllllallll",
      "aaaaaaaaaaaaaaaa",
      "llllllllllllllll",
      "vvvvvvvvvvvvvvvv",
      "vvvvvvvvvvvvvvvv",
      "bbbbbbbbbbbbbbbb",
      "bbbbbbbbbbbbbbbb",
      "vvvvvvvvvvvvvvvv"
    ]
  ]
}