{
  "name": "multi_laboratory1_11_base3",
  "refpalette": "c70cities:multi_laboratory1_11_base3_palette",
  "xsize": 16,
  "zsize": 16,
  "slices": [
    [
      "aaaaaaaaaaaaabcz",
      "aaaaaaaaaaaaabcz",
      "aaaaaaaaaaaaabcz",
      "aaaaaaaaaaaaabcz",
      "aaaaaaaaaaaaabcz",
      "aaaaaaaaaaaaabcz",
      "aaaadaaaaaaaabcz",
      "aaaaaaaaaaaaabcz",
      "aaaaaaaaaaaaabcz",
      "aaaaaaaaaaaaabcz",
      "aaaaaaaaaaaaabcz",
      "aaaaaaaaaaaaabcz",
      "eaaaaaaaaaaaabcz",
      "eaaadaaaaaaaabcz",
      "feaaaaaaaaaaabcz",
      " eaaaaaaaaaaabcz"
    ],
    [
      "    ghiiiiiihbcz",
      "    gj k  l ibcz",
      "    gmk    nibcz",
      "    g       ibcz",
      "    o       ibcz",
      "    gpqpqpqqhbcz",
      "r  fdggggggggbcz",
      "    gsss tt ubcz",
      "    gssw     bcz",
      "    gs xy   AAcz",
      "    g BBB CADEcz",
      "    g BFF xADEcz",
      "IJ  g KBB   AAcz",
      "If  d CL  y ubcz",
      "fI  g        bcz",
      " I  M       AAcz"
    ],
    [
      "    ghiNiiOihbcz",
      "    PQ      ibcz",
      "    P       Rbcz",
      "    g       ibcz",
      "    S       Rbcz",
      "    gT    UVhbcz",
      "   Wdggggggggbcz",
      "    g!s     ubcz",
      "    P       Xbcz",
      "    P       IAcz",
      "    P YY   IDEcz",
      "    P YY   IDEcz",
      "I   g K Z   IAcz",
      "IW  d  0    ubcz",
      "fI  g       Xbcz",
      " I  M       IAcz"
    ],
    [
      "    gh111111hbcz",
      "    2       nbcz",
      "    2       3bcz",
      "    g       4bcz",
      "    2        bcz",
      "    g       hbcz",
      "   Wdggggggggbcz",
      "    gs   55 ubcz",
      "    P        bcz",
      "    P       IAcz",
      "    P 66   IDEcz",
      "    P 66   IDEcz",
      "I   g       IAcz",
      "IW  d       ubcz",
      "fI  g        bcz",
      " I  M       IAcz"
    ],
    [
      "    gh      hbcz",
      "    g        bcz",
      "    g       7bcz",
      "    g        bcz",
      "    g        bcz",
      "    g       hbcz",
      "    dggggggggbcz",
      "    g  8  8 9bcz",
      "    g       Xbcz",
      "    g       IAcz",
      "    g      I@Ecz",
      "    g      I@Ecz",
      "I   g       IAcz",
      "I   d       9bcz",
      "fI  g       Xbcz",
      " I  g       IAcz"
    ],
    [
      "####2$$$$$$$$bcz",
      "##%#2$^$$$$^$bcz",
      "##%#2$$$$$$$$bcz",
      "##%#2$$$$$$$$bcz",
      "##%#2$^$$$$&$bcz",
      "####2$$$$$$$$bcz",
      "####dggggggggbcz",
      "####2********bcz",
      "####2((((((((bcz",
      "####2(()((%(AAcz",
      "####2((%((%A+Ecz",
      "####2(()((%A+Ecz",
      "I###2((%((%(AAcz",
      "I###d((((((((bcz",
      "fI##2((((((((bcz",
      " I##2((%((%(AAcz"
    ]
  ]
}