{
  "name": "multi_pumpjack_1_ground",
  "refpalette": "c70cities:multi_pumpjack_1_ground_palette",
  "xsize": 16,
  "zsize": 16,
  "slices": [
    [
      "zzzzzzzzzzzzzzzz",
      "zzzzzzzzzzzzzzzz",
      "zzzzHHHHHHHHHHHz",
      "zzzzHHHHHHHHHHHz",
      "zzzzHHaaaaaaaHHz",
      "zzzzHHHHHHHHHHHz",
      "zzzzHHHHHHHHHHHz",
      "zzzzHHHHHHHHHHHz",
      "zzzzHHHHHHHHHHHz",
      "zzzzHHHHHHHHHHHz",
      "zzzzzHHHHzHHHHzz",
      "zbzzzbbbbzbbbbzz",
      "zzbzbbbzbbzbzbzb",
      "zbbbzbbbbbbbbzbb",
      "zzzzzbbzzbzbzbzz",
      "zzzzzzzbzzzzzzzz"
    ],
    [
      "  cdeeeeeefffffd",
      "  cddddddddddddd",
      "   dfffffffffffd",
      "   dggfffffffggd",
      "   dh          d",
      "   d  i j i j  d",
      "   d          kd",
      "   d          hd",
      "   d  l m l m nd",
      "   d!h        nd",
      "   coppppo    oc",
      "                ",
      "                ",
      "                ",
      "                ",
      "                "
    ],
    [
      "  cd     dq   rd",
      "  cdoddddodstdoo",
      "   d  uwxkk   ud",
      "   d           d",
      "   y           y",
      "   y           y",
      "   y           y",
      "   y           y",
      "   y           d",
      "   dh          d",
      "   coppppo    oc",
      "                ",
      "                ",
      "                ",
      "                ",
      "                "
    ],
    [
      "  cd     dq   rd",
      "  cdodAAdodBCdoo",
      "   d     k     d",
      "   d           d",
      "   y           y",
      "   y           y",
      "   y           y",
      "   y           y",
      "   y           d",
      "   d           d",
      "   coppppoppppoc",
      "                ",
      "                ",
      "                ",
      "                ",
      "                "
    ],
    [
      "  cd  D  dq   rd",
      "  cdodEEdoddddoo",
      "   du          d",
      "   d           d",
      "   E           E",
      "   E           E",
      "   E           E",
      "   E           E",
      "   E           d",
      "   d          ud",
      "   coooooooooooc",
      "     FFFF FFFF  ",
      "                ",
      "                ",
      "                ",
      "                "
    ],
    [
      "  cdIIIIIdqu  rd",
      "  cdoddddoddddoo",
      "   duu        ud",
      "   du          d",
      "   d          ud",
      "   d           d",
      "   d           d",
      "   d           d",
      "   d          ud",
      "   d     u    ud",
      "   cdJJJJdJJJJdc",
      "                ",
      "                ",
      "                ",
      "                ",
      "                "
    ]
  ]
}