{
  "name": "multi_gasstation_0_ground",
  "refpalette": "c70cities:multi_gasstation_0_ground_palette",
  "xsize": 16,
  "zsize": 16,
  "slices": [
    [
      "GGGGGGGGGGGGGGGG",
      "HHHHHHHHHHHHHaGG",
      "HHHHHHHHHHHHHaGG",
      "HHHHHHHHHHHHHaGG",
      "bHHHHHHHHHHHHaGG",
      "bHHHHHHHHHHHHaGG",
      "HHHHHHHHHHHHHaGG",
      "HHHHbHHbbbbbbbGG",
      "HHHHbHHbbbbbbbGG",
      "HHHHbHHbbbbbbbGG",
      "HHHHbHHbbbbbbbGG",
      "HHHHbHHbbbbbbbGG",
      "HHHHbHHbbbbbbbGG",
      "HHHHbHHbbbbbbbGG",
      "HHHHbHHbbbbbbbGG",
      "HHHHbHHbbbbbbbGG"
    ],
    [
      "                ",
      "             c  ",
      "             c  ",
      "             c  ",
      "d      efefefc  ",
      "g            c  ",
      " g     hihihic  ",
      "    j  kkkkkkk  ",
      "  lmn  k okp k  ",
      "       k  k  k  ",
      "  qrj  kskkktk  ",
      "  lmc  k uuu k  ",
      "       k     k  ",
      "  qrj  k     k  ",
      "  lmc  kkwkkkk  ",
      "       xy AyAk  "
    ],
    [
      "                ",
      "                ",
      "                ",
      "                ",
      "g               ",
      "d               ",
      "                ",
      "    j  kkkkkkk  ",
      "    B  k CkD k  ",
      "       k  k  k  ",
      "    j  kEkkkFk  ",
      "       k     k  ",
      "       k     k  ",
      "    j  k     k  ",
      "       kkIkkkk  ",
      "       x  J Jk  "
    ],
    [
      "                ",
      "                ",
      "                ",
      "                ",
      "g               ",
      "                ",
      "                ",
      "    j  KKKKKKK  ",
      "       L  K  L  ",
      "       L  K  L  ",
      "    j  KKKKKKK  ",
      "       K     K  ",
      "       L     L  ",
      "    j  L     L  ",
      "       KKKKKKK  ",
      "       K  MNOL  "
    ],
    [
      "                ",
      "                ",
      "                ",
      "                ",
      "                ",
      "                ",
      "                ",
      "    kP kkkkkkk  ",
      "       kQQkQQk  ",
      "       kQQkQQk  ",
      "    kR kkkkkkk  ",
      "       kQQQQQk  ",
      "       kQQQQQk  ",
      "    kP kQQRQQk  ",
      "       kkkkkkk  ",
      "       k  S Tk  "
    ],
    [
      "                ",
      "                ",
      "                ",
      "                ",
      "                ",
      "                ",
      " UUUUUUUUUUUUUU ",
      " UccbbbbbbbbbbU ",
      " UccbccccccccbU ",
      " UccbccccccccbU ",
      " UccbccccccccbU ",
      " UccbccccccccbU ",
      " UccbccccccccbU ",
      " UccbccccccccbU ",
      " UccbbbbbbbbbbU ",
      " UccbccccccccbU "
    ]
  ]
}