{
  "name": "multi_communitycenter_7_base1",
  "refpalette": "c70cities:multi_communitycenter_7_base1_palette",
  "xsize": 16,
  "zsize": 16,
  "slices": [
    [
      "HHHHHHHHHHHHHHHv",
      "HHHHHHHHHHHHHHHv",
      "HHHHHHHHHHHHHHHv",
      "HHHHHHHHHHHHHHHv",
      "HHHHHHHHHHHHHHHv",
      "HHHHHHHHHHHHHHHv",
      "HHHHHHHHHHHHHHHv",
      "HHHHHHHHHHHHHHHv",
      "HHHHHHHHHHHHHHHv",
      "HHHHHHHHHHHHHHHv",
      "HHHHHHHHHHHHHHHv",
      "HHHHHHHHHHHHHHHv",
      "HHHHHHHHHHHHHHHv",
      "HHHHHHHHHHHHHHHv",
      "HHHHHHHHHHHHHHHv",
      "HHHHHHHHHHabHHHv"
    ],
    [
      "   cH  Hd    efv",
      "ghgcHijHd     fv",
      "klkcHHHHd     fv",
      "   cHHHHd     fv",
      "ghgmHHHHm    mfv",
      "   cHHHHd     fv",
      "   cnnnnd     fv",
      "   cooood     fv",
      "              fv",
      "              fv",
      "              fv",
      "klkm    mlklkmfv",
      "   d    c     fv",
      "ghgd    chghg fv",
      "klkd    clklk fv",
      "   d    c     fv"
    ],
    [
      "    H  H      fv",
      "    HppH      fv",
      "    HHHH      fv",
      "    nnnn      fv",
      "   moooom    mfv",
      "              fv",
      "              fv",
      "              fv",
      "              fv",
      "              fv",
      "              fv",
      "   m    m    mfv",
      "              fv",
      "              fv",
      "              fv",
      "              fv"
    ],
    [
      "    nnnne    efv",
      "    oooo      fv",
      "              fv",
      "              fv",
      "   m    m    mfv",
      "              fv",
      "              fv",
      "              fv",
      "              fv",
      "              fv",
      "              fv",
      "   m    m    mfv",
      "              fv",
      "              fv",
      "              fv",
      "              fv"
    ],
    [
      "   m    me  emfv",
      "   m    m   emfv",
      "   m    m    mfv",
      "   m    m   emfv",
      "qqqm    mqqqqmfv",
      "   m    m    mfv",
      "   m    m    mfv",
      "   m    m    mfv",
      "   m    m    mfv",
      "   m    m    mfv",
      "   m    m    mfv",
      "qqqmqqqqmqqqqmfv",
      "   m    m    mfv",
      "   m    m    mfv",
      "   m    m    mfv",
      "   m    m    mfv"
    ],
    [
      "fffr    rffffffv",
      "fffr    rffffffv",
      "fffr    rffffffv",
      "fffr    rffffffv",
      "fffm    mffffffv",
      "ffffssssfffffffv",
      "fffffffffffffffv",
      "fffffffffffffffv",
      "fffffffffffffffv",
      "fffffffffffffffv",
      "fffffffffffffffv",
      "fffffffffffffffv",
      "fffffffffffffffv",
      "fffffffffffffffv",
      "fffffffffffffffv",
      "fffffffffffffffv"
    ]
  ]
}