{
  "name": "multi_condo1_5_floor3",
  "refpalette": "c70cities:multi_condo1_5_floor3_palette",
  "xsize": 16,
  "zsize": 16,
  "slices": [
    [
      "aaaaabcddeeefg  ",
      "cccccccddeeefg  ",
      "deeeddddddddfhhh",
      "deeeddddddddfij ",
      "deeeddddddddfij ",
      "ddddddddddddfij ",
      "ddddddddddddfij ",
      "ddddddddddddfij ",
      "ddddddddddddfij ",
      "ddddddddddddfij ",
      "ddddddddddddfij ",
      "ffkkkffffffffij ",
      "fggggghiiiiiiij ",
      "llllllhjjjjjjjj ",
      "      h         ",
      "                "
    ],
    [
      "      m  n  o   ",
      "ffffpff qrsrf   ",
      "rt r ur wr xfhhh",
      "ry A ur Br Cfi  ",
      "rrDr qr Er Ffi  ",
      "rF r wr  n Ifi  ",
      "rI A Br Jrrrfi  ",
      "rrrr Er KLMMfi  ",
      "rNMM Jr  L  fi  ",
      "rO K LrK    fi  ",
      "rP  QLr!  RSfi  ",
      "ffT TfffUUUffi  ",
      "f     hiiiiiii  ",
      "llllllh         ",
      "      h         ",
      "                "
    ],
    [
      "      V  W Xl   ",
      "ffffYff  rZrf   ",
      "r 0r  r  r 1fhhh",
      "r  2  r 3r  f   ",
      "rr4r 5r 6r  f   ",
      "r7 r  r  W  f   ",
      "r8 2 3r 9rrrf   ",
      "rrrr 6r  @# f   ",
      "r  $ 9r  %  f   ",
      "r     r     f   ",
      "r     r     f   ",
      "ffT TfffTTTff   ",
      "f     h         ",
      "      h         ",
      "      h         ",
      "                "
    ],
    [
      "      ^  r &l   ",
      "ffff*ff  rrrf   ",
      "r (r  r  r  fhhh",
      "r  r  r  r  f   ",
      "rrrr  r  r  f   ",
      "r  r  r  r  f   ",
      "r! r  r  rrrf   ",
      "rrrr  r     f   ",
      "r     r     f   ",
      "r     r     f   ",
      "r     r     f   ",
      "ffTTTfffTTTff   ",
      "f     h         ",
      "      h         ",
      "      h         ",
      "                "
    ],
    [
      "      f  r  f   ",
      "fffffff  rrrf   ",
      "r  r  r  r  fhhh",
      "r  r  r  r  f)  ",
      "rrrr  r  r  f)  ",
      "r  r  r  r  f)  ",
      "r  r  r  rrrf)  ",
      "rrrr  r     f)  ",
      "r     r     f)  ",
      "r     r     f)  ",
      "r     r     f)  ",
      "fffffffffffff)  ",
      "f     h)))))))  ",
      "      h         ",
      "      h         ",
      "                "
    ],
    [
      "      f+++++f   ",
      "fffffff+++++f   ",
      "++++++++++++fhhh",
      "++++++++++++f-  ",
      "++++++++++++f-  ",
      "++++++++++++f-  ",
      "++++++++++++f-  ",
      "++++++++++++f-  ",
      "++++++++++++f-  ",
      "++++++++++++f-  ",
      "++++++++++++f-  ",
      "fffffffffffff-  ",
      "f     h-------  ",
      "[[[[[[h         ",
      "      h         ",
      "                "
    ]
  ]
}