{
  "name": "multi_condo1_1_base1",
  "refpalette": "c70cities:multi_condo1_1_base1_palette",
  "xsize": 16,
  "zsize": 16,
  "slices": [
    [
      "vaHHHHHHHHHHHHHH",
      "vaHHHHHHHHaHHHHH",
      "vaHHHHHHHHHHHHHH",
      "vaHHHHHHHHHHHHHH",
      "vaHHHHHHHHHHHHHH",
      "vaHHHHHHHHHHHHHH",
      "vaHHHHHHHHHHHHHH",
      "vaHHHHHHHHHHHHHH",
      "vaHHHHHHHHHHHHHH",
      "vaHHHHHHHHHHHHHH",
      "vaHHHHHHHHHHHHHH",
      "vaHHHHHHHHHHHHHH",
      "vaHHHHHHHHHHHHHH",
      "vaHHHHHHHHHHHHHH",
      "vaHHHHHHHHaHHHHH",
      "vaHHHHHHHHHHHHHH"
    ],
    [
      "vab c           ",
      "vad e  fffafff  ",
      "vab c  b cgb c  ",
      "vad e  d egd e  ",
      "vab c  b cgb c  ",
      "vad e  d egd e  ",
      "vab c  b cgb c  ",
      "vad e  d egd e  ",
      "vab c  b cgb c  ",
      "vad e  d egd e  ",
      "vab c  b cgb c  ",
      "vad e  d egd e  ",
      "vab c  b cgb c  ",
      "vad e  d egd e  ",
      "vahhh  hhhafff  ",
      "va              "
    ],
    [
      "va              ",
      "va        a     ",
      "va              ",
      "va              ",
      "va              ",
      "va              ",
      "va              ",
      "va              ",
      "va              ",
      "va              ",
      "va              ",
      "va              ",
      "va              ",
      "va              ",
      "va        a     ",
      "va              "
    ],
    [
      "va              ",
      "va        a     ",
      "va              ",
      "va              ",
      "va              ",
      "va              ",
      "va              ",
      "va              ",
      "va              ",
      "va              ",
      "va              ",
      "va              ",
      "va              ",
      "va              ",
      "va        a     ",
      "va              "
    ],
    [
      "vai       a     ",
      "vaaaaaaaaaaaaaaa",
      "vai       a     ",
      "vai       a     ",
      "vai       a     ",
      "vai       a     ",
      "vai       a     ",
      "vai       a     ",
      "vai       a     ",
      "vai       a     ",
      "vai       a     ",
      "vai       a     ",
      "vai       a     ",
      "vai       a     ",
      "vaaaaaaaaaaaaaaa",
      "vai       a     "
    ],
    [
      "vajjjjjjjjajjjjj",
      "vaaaaaaaaaaaaaaa",
      "vajjjjjjjjajjjjj",
      "vajjjjjjjjajjjjj",
      "vajjjjjjjjajjjjj",
      "vajjjjjjjjajjjjj",
      "vajjjjjjjjajjjjj",
      "vajjjjjjjjajjjjj",
      "vajjjjjjjjajjjjj",
      "vajjjjjjjjajjjjj",
      "vajjjjjjjjajjjjj",
      "vajjjjjjjjajjjjj",
      "vajjjjjjjjajjjjj",
      "vajjjjjjjjajjjjj",
      "vaaaaaaaaaaaaaaa",
      "vajjjjjjjjajjjjj"
    ]
  ]
}