{
  "name": "multi_megatower1_4_floor5",
  "refpalette": "c70cities:multi_megatower1_4_floor5_palette",
  "xsize": 16,
  "zsize": 16,
  "slices": [
    [
      "a   bbbbbbbbbbbb",
      "a   bbbbbbbbbbbb",
      "a   bbbbbbbbbbbb",
      "cdeebbbbbbbbbbbb",
      "bbbbfbbbbbbfgggg",
      "bbbbbbbbbbbbgggg",
      "bbbbbbbbbbbbgggg",
      "bbbbbbbbbbbbgggg",
      "bbbbbbbbbbbbgggg",
      "bbbbbbbbbbbbgggg",
      "bbbbbbbbbbbbgggg",
      "hhhhfbbbbbbfgggg",
      "    ibbbbbbbbbbb",
      "    ibbbbbbbbbbb",
      "    ibbbbbbbbbbb",
      "    ibbbbbbbbbbb"
    ],
    [
      "a   jk ll mno  p",
      "a   jq ll rn    ",
      "a   j      s   t",
      "aeuuj      n   w",
      "xyABf      fCDCC",
      "        eeEn   C",
      "        e FnI  J",
      "K       e  nL  C",
      "E       e  nL  J",
      "        e FnI  C",
      "E       eeEn   J",
      "MMMMf      fCNCC",
      "    M      n    ",
      "    M      O   P",
      "    Mk ll mn  QR",
      "    Mq ll rn   S"
    ],
    [
      "a   j      no   ",
      "a   j      n    ",
      "a   j      T    ",
      "ae  j      n    ",
      "x UVf      fCWCC",
      "        X Yn   C",
      "        Z  01  2",
      "           0   C",
      "Y       3  01  2",
      "        Z  01  C",
      "Y         Yn   2",
      "    f      fC4CC",
      "    M      n    ",
      "    M      5    ",
      "    M      n    ",
      "    M      n    "
    ],
    [
      "a   j      n    ",
      "a   j      n    ",
      "a   j      6    ",
      "aeeej      n    ",
      "x7  f      fCCCC",
      "          Yn   C",
      "           01  C",
      "           01  C",
      "Y          01  C",
      "           0   C",
      "Y         Yn   C",
      "    f      fCCCC",
      "    M      n    ",
      "    M      6    ",
      "    M      n    ",
      "    M      n    "
    ],
    [
      "a   j      n8888",
      "a   j      n8888",
      "a   j      n8988",
      "aeeej      n8888",
      "xxxxf      fCCCC",
      "           n@@@@",
      "           n@@@@",
      "           n@@@@",
      "           n@@@@",
      "           n@@@@",
      "           n@@@@",
      "    f      fCCCC",
      "    n      n8888",
      "    n      n8#88",
      "    n      n8888",
      "    n      n8888"
    ],
    [
      "$   $888888$    ",
      "$   $888888$%% %",
      "$   $898898$ ^% ",
      "$e&*$888888$%% %",
      "((((f((((((f((((",
      "8888$888888$ %  ",
      "8898$8988#8$))))",
      "8888$888888$% )%",
      "8888$888888$  ))",
      "8898$8988#8$  )%",
      "8888$888888$%%))",
      "((((f((((((f((((",
      "    $888888$ % %",
      "    $898898$ ^  ",
      "    $888888$ %  ",
      "    $888888$    "
    ]
  ]
}