{
  "name": "multi_carservice_0_top",
  "refpalette": "c70cities:multi_carservice_0_top_palette",
  "xsize": 16,
  "zsize": 16,
  "slices": [
    [
      "                ",
      "                ",
      "                ",
      "                ",
      "                ",
      "                ",
      "    aabaaabaaab ",
      "   cc dddddddda ",
      "  cc  dddddddda ",
      " ac   dddddddda ",
      " ae   dddddddda ",
      " adddddddddddda ",
      " adddddddddddda ",
      " adddddddddddda ",
      " adddddddddddda ",
      " adddddddddddda "
    ],
    [
      "                ",
      "                ",
      "                ",
      "                ",
      "                ",
      "                ",
      "    aabaaabaaab ",
      "   ffg        a ",
      "  ff g hijjikkf ",
      " af  g kkkljkkf ",
      " ae  g hijjikkf ",
      " a mmm  n  n  f ",
      " a        o o f ",
      " a        p q f ",
      " a    r   s t f ",
      " a    ru      f "
    ],
    [
      "                ",
      "                ",
      "                ",
      "                ",
      "                ",
      "                ",
      "    aabaaabaaab ",
      "   ff         a ",
      "  ff         wf ",
      " af      wxwjkf ",
      " a           wf ",
      " b            f ",
      " f            f ",
      " f            f ",
      " f    y       f ",
      " f            f "
    ],
    [
      "                ",
      "                ",
      "                ",
      "                ",
      "                ",
      "                ",
      "    aabaaabaaab ",
      "   ff A   A   b ",
      "  ff  A   A   b ",
      " af   A   A   b ",
      " a    A   A   b ",
      " a    A   A   b ",
      " a    A   A   b ",
      " a    A   A   b ",
      " a    A   A   b ",
      " a    A   A   b "
    ],
    [
      "                ",
      "                ",
      "                ",
      "                ",
      "                ",
      "                ",
      "    aaaaaaaaaaa ",
      "   BBBBBBBBBBBa ",
      "  BBBBBBBBBBBBa ",
      " aBBBBBBBBBBBBa ",
      " aBBBBBBBBBBBBa ",
      " aBBBBBBBBBBBBa ",
      " aBBBBBBBBBBBBa ",
      " aBBBBBBBBBBBBa ",
      " aBBBBBBBBBBBBa ",
      " aBBBBBBBBBBBBa "
    ],
    [
      "                ",
      "                ",
      "                ",
      "                ",
      "                ",
      "                ",
      "    aaaaaaaaaaa ",
      "              a ",
      "              a ",
      " a            a ",
      " a            a ",
      " a            a ",
      " a            a ",
      " a            a ",
      " a            a ",
      " a            a "
    ]
  ]
}