{
  "name": "multi_convenientstore_3_floor1",
  "refpalette": "c70cities:multi_convenientstore_3_floor1_palette",
  "xsize": 16,
  "zsize": 16,
  "slices": [
    [
      "aaaaaaaaabac    ",
      "      de   c    ",
      "       e   c    ",
      "       efffc    ",
      "       efffc    ",
      "ggggggghfffc    ",
      "fffffffffffc    ",
      "fffffffffffc    ",
      "ff    iffffc    ",
      "fffffffffffc    ",
      "fffffffffffc    ",
      "fffffffffffc    ",
      "cccccccccccc    ",
      "      j         ",
      "                ",
      "                "
    ],
    [
      "aaaaaaaaabac    ",
      "       k   c    ",
      "       k   c    ",
      "       kkkkc    ",
      "       k  lc    ",
      "kkkkkkkk m c    ",
      "nm lnm l o c    ",
      "           c    ",
      " k       p c    ",
      " kkkkkk  m c    ",
      "           c    ",
      "qrqqqr   orc    ",
      "cccccccccccc    ",
      "      s         ",
      "                ",
      "                "
    ],
    [
      "aaaaaaaaaaac    ",
      "           c    ",
      "           c    ",
      "           b    ",
      "           b    ",
      "           b    ",
      "           c    ",
      "           b    ",
      "           b    ",
      "           b    ",
      "           c    ",
      "trut r    rc    ",
      "bccbbccbbccc    ",
      "                ",
      "                ",
      "                "
    ],
    [
      "aaaaaaaaaaac    ",
      "           c    ",
      "           c    ",
      "           c    ",
      "           c    ",
      "           c    ",
      "           c    ",
      "           c    ",
      "           c    ",
      "           c    ",
      "           c    ",
      "           c    ",
      "cccccccccccc    ",
      "      j         ",
      "                ",
      "                "
    ],
    [
      "wwwwwwwwwwwc    ",
      "wwwwwwwwwwwc    ",
      "wwwwwwwwwwwc    ",
      "wwwwwwwwwwwc    ",
      "wwwwwwwwwwwc    ",
      "wwwwwwwwwwwc    ",
      "wwwwwwwwwwwc    ",
      "wwwwwwwwwwwc    ",
      "wwwwwwwwwwwc    ",
      "wwwwwwwwwwwc    ",
      "wwwwwwwwwwwc    ",
      "wwwwwwwwwwwc    ",
      "cccccccccccc    ",
      "                ",
      "                ",
      "                "
    ],
    [
      "                ",
      "                ",
      "                ",
      "                ",
      "                ",
      "     ~          ",
      "                ",
      "                ",
      "                ",
      "                ",
      "                ",
      "                ",
      "                ",
      "                ",
      "                ",
      "                "
    ]
  ]
}