{
  "name": "multi_laboratory1_13_base4",
  "refpalette": "c70cities:multi_laboratory1_13_base4_palette",
  "xsize": 16,
  "zsize": 16,
  "slices": [
    [
      "aaaaaaaaaaaaabcv",
      "aaaaaaaaaaaaabcv",
      "aaaadaaaaaaaabbv",
      "aaaaaaaaaaaaabbv",
      "aaaaaaaaaaaaabbv",
      "aaaaaaaaaaaaabbv",
      "aaaaaaaaaaaaabbv",
      "aaaaaaaaaaaaabbv",
      "aaaaaeeeeeeeebbv",
      "aaaadffffffffbbv",
      "aaaaafghhhhifbbv",
      "aaaaafhhhghgfbbv",
      "aaaaafghhhggfbbv",
      "aaaaafhghgggfbbv",
      "aaaaafhhhghgfbbv",
      "aaaaaffffffffbbv"
    ],
    [
      " j  k  l    mbcv",
      "  n op      qbcv",
      "r   dst    uqbbv",
      " j  ow l    qbbv",
      " mxyoA B lxCDbbv",
      "  x oAll u lDbbv",
      "B   oE     CDbbv",
      "    oA     uDbbv",
      "    o       Fbbv",
      "oooodIIIIIIIIbbv",
      "   Joh KLKMNgbbv",
      "    ogKOKPKPhbbv",
      "    ohPKOOPKgbbv",
      "QQ  ogK KPK gbbv",
      "R   oggSgK ggbbv",
      "T   ofgghhggfbbv"
    ],
    [
      "    k       Ubcv",
      "    op      qbcv",
      "    d!V     Wbbv",
      " B  o       pbbv",
      " X  Y      CZbbv",
      "    Y      CZbbv",
      "    Y      C!bbv",
      "    Y      CZbbv",
      "    o       Fbbv",
      "YYYodIIIIIIIIbbv",
      "    oh   0  hbbv",
      "    1h0     gbbv",
      "    1g     Lgbbv",
      "    1g  0 L hbbv",
      "2   1hg     gbbv",
      "    ofhihghgfbbv"
    ],
    [
      "    k        bcv",
      "    o       qbcv",
      "    dq       bbv",
      "    o        bbv",
      "    Y        bbv",
      "    Y        bbv",
      "    Y        bbv",
      "    Y        bbv",
      "    o3      3bbv",
      "YYYodIIIIIIIIbbv",
      "    oh      ibbv",
      "    4i      hbbv",
      "    4h      hbbv",
      "    4h      gbbv",
      "    4g      hbbv",
      "    ofhhhhggfbbv"
    ],
    [
      "    o        bcv",
      "    o       qbcv",
      "    dq       bbv",
      "    o5       bbv",
      "    o6       bbv",
      "    o7       bbv",
      "    o8       bbv",
      "    o9       bbv",
      "    o@       bbv",
      "oooodIIIIIIIIbbv",
      "    og      hbbv",
      "    oh      gbbv",
      "    og      hbbv",
      "    oh      hbbv",
      "    oh      gbbv",
      "    ofhhihhhfbbv"
    ],
    [
      "## #$q%^%%^%qbcv",
      "####$q%^%%^%qbcv",
      "####dq%%%%%%qbcv",
      "####$q%%%%%%qbcv",
      "##&#$q%&%%&%*bcv",
      "##&#$q%^%%^%*bcv",
      "##^#$q%^%%^%*bcv",
      "##^#$q%^%%^%*bcv",
      "####$q%%%%%%qbcv",
      "((((dqIIIIIIqbcv",
      "%%%%$hhihhihhbcv",
      "%%%%$hhhhihhhbcv",
      "%%%%$hhhhhhhhbcv",
      "^)%%$hhhihhhhbcv",
      "%^%%$hiihhhhhbcv",
      "%^%%$fhhhhhhfbcv"
    ]
  ]
}