{
  "name": "multi_residential2_0_ground",
  "refpalette": "c70cities:multi_residential2_0_ground_palette",
  "xsize": 16,
  "zsize": 16,
  "slices": [
    [
      "GGGGGGGGGGGGGGGG",
      "GGGGGGGGGGGGGGGG",
      "GGGGGGGGGGGGGGGG",
      "GGGGGGGGGGGGGGGG",
      "GGaaaaaaaaaaaaGG",
      "GGabbbbbbbbbbaGG",
      "GGabbbbbbbbbbaGG",
      "GGabbbbbbbbbbaGG",
      "GGabbbbbbbbbbaGG",
      "GGabbbbbbbbbbaGG",
      "GGabbbbbbbbbbaGG",
      "GGGcddddddddcGGG",
      "GGGcddddddddcGGG",
      "GGGcddddddddcGGG",
      "GGGcddddddddcGGG",
      "GGGcddddddddcGGG"
    ],
    [
      "effffgffffgffffe",
      "f              f",
      "e              f",
      "               f",
      "  hijkllllkjim g",
      "  no   pq   rs f",
      "  nt  u      s f",
      "  j       wxwj f",
      "  y    AA B  s f",
      "  C   kkkkBD s g",
      "  j    E !FFFj f",
      "  Ic  JKKLLMcI f",
      "  IcN  OO  PcI f",
      "  IcQ N    McI g",
      "  IcRQ     ScI f",
      "  IcTTTUVTTTcI f"
    ],
    [
      "effffgffffgffffe",
      "f              f",
      "e              f",
      "               f",
      "  lljkllllkjll g",
      "  lW        Xl f",
      "  l          l f",
      "  j       wYwj f",
      "  Z    00 B  1 f",
      "  2   3333B4 1 g",
      "  j     E FFFj f",
      "   c        c  f",
      "   5        5  f",
      "   c        c  g",
      "   c6N     7c  f",
      "   cTTT89TTTc  f"
    ],
    [
      "                ",
      "                ",
      "                ",
      "                ",
      "  lljkllllkjll  ",
      "  l          l  ",
      "  l          l  ",
      "  j       wwwj  ",
      "  n       B  1  ",
      "  n   3333B  1  ",
      "  j      EFFFj  ",
      "   c        c   ",
      "   5        5   ",
      "   c        c   ",
      " iic        cii ",
      " @#cTTTTTTTTc$@ "
    ],
    [
      "                ",
      "                ",
      "                ",
      " %%%%%%%%%%%%%% ",
      " ^jjjjjjjjjjjj^ ",
      "  jbbbbbbbbbbj  ",
      "  jbbbbbbbbbbj  ",
      "  jbbbbbbbbbbj  ",
      "  jbbbbbbbbbbj  ",
      "  jbbbbbbbbbbj  ",
      "  jbbbb   Ebbj  ",
      "   cbbbbbbbbc   ",
      "   cbbbbbbbbc   ",
      " iicbbbbbbbbcii ",
      " @@#bbbbbbbb$@@ ",
      "   &bbbbbbbb*   "
    ],
    [
      "                ",
      "                ",
      "                ",
      "                ",
      " %%%%%%%%%%%%%% ",
      " ^jkkkkkkkkkkj^ ",
      "  j())+r-[]r j  ",
      "  j {{+  }   j  ",
      "  n \\\\       s  ",
      "  n    ||||  s  ",
      "  j|   `    |j  ",
      "   ckk:k++kkc   ",
      " iickk   ;'kcii ",
      " @@@#',   '$@@@ ",
      "    &'., !'*    ",
      "    &'/  <'*    "
    ]
  ]
}