{
  "name": "multi_laboratory1_2_base4",
  "refpalette": "c70cities:multi_laboratory1_2_base4_palette",
  "xsize": 16,
  "zsize": 16,
  "slices": [
    [
      "zabcccccccccccd ",
      "zabcccccccccccd ",
      "zabcccccccccccd ",
      "zabcccccccccccde",
      "zabccccccccfcccd",
      "zabccccccccccccd",
      "zabccccccccccccc",
      "zabccccccccccccc",
      "zabcccc!cccccccc",
      "zabccccccccccccc",
      "zabccccccccccccc",
      "zabccccccccfcccc",
      "zabccccccccccccc",
      "zabccccccccccccc",
      "zabccccccccccccc",
      "zabccccccccccccc"
    ],
    [
      "zabghiiii  j  k ",
      "zablmnnnno p  k ",
      "zablqrstru u  k ",
      "zab  wwww  x  ke",
      "zab  nnnn  f  ek",
      "zab qrysru x  Ak",
      "zab  wwww  x    ",
      "zab  nnnn  x    ",
      "zab qr Bru x    ",
      "zab  wwww  x    ",
      "zab    C  Dx  E ",
      "zabxxxFIxxxfe   ",
      "zab     J  x    ",
      "zabKL  M   u    ",
      "zabNN      j    ",
      "zabLOM     p    "
    ],
    [
      "zab  P QD  R  k ",
      "zab  nnnn  S  k ",
      "zab qT  Tu u  k ",
      "zab  wwww  x  ke",
      "zab  nnnn  f  Uk",
      "zab qV  Vu x   k",
      "zab  wwww  W    ",
      "zab  nnnn  W    ",
      "zab qV  Vu W    ",
      "zab  wwww  W    ",
      "zab        x    ",
      "zabxxxXYxxxfU   ",
      "zab        x    ",
      "zab        u    ",
      "zabZ       R    ",
      "zab0       S    "
    ],
    [
      "zab        u  k ",
      "zab  nnnn  u  k ",
      "zab q1  1u u  k ",
      "zab  wwww  x  ke",
      "zab  nnnn  f  Uk",
      "zab q2  2u x   k",
      "zab  wwww  W    ",
      "zab  nnnn  W    ",
      "zab q2  2u W    ",
      "zab  wwww  W    ",
      "zab        x    ",
      "zabxxxxxxxxfU   ",
      "zab        x    ",
      "zab        u    ",
      "zab        u    ",
      "zab        u    "
    ],
    [
      "zab        x  k ",
      "zab        x  k ",
      "zab33333333x  k ",
      "zab     3  x  ke",
      "zab     3  f   k",
      "zab  3  3  x   k",
      "zab  3  3  x    ",
      "zab  3  3  x    ",
      "zab33333333x    ",
      "zab        x    ",
      "zab        x    ",
      "zabxxxxxxxxf    ",
      "zab        x    ",
      "zab        x    ",
      "zab        x    ",
      "zab        x    "
    ],
    [
      "zab44544644788k ",
      "zab44644544788k ",
      "zab44544544788k ",
      "zab44444444788ke",
      "zab44444444f888k",
      "zab445445447888k",
      "zab4454454478888",
      "zab4454454478888",
      "zab4454454478888",
      "zab4444444478888",
      "zab4444444478888",
      "zabxxxxxxxxf8888",
      "zab4444444478888",
      "zab4444444478588",
      "zab4454454478588",
      "zab4454454478588"
    ]
  ]
}