{
  "name": "multi_communitycenter_2_ground",
  "refpalette": "c70cities:multi_communitycenter_2_ground_palette",
  "xsize": 16,
  "zsize": 16,
  "slices": [
    [
      "aaaabbccccccdbbb",
      "aaaaabccccccdbbb",
      "aaaaabbcccccbdbb",
      "aaaaaabcccccbbdd",
      "aaaaaabbcccbeeee",
      "aaGaaaabbcbeeeee",
      "aaGfaaaabbeeeeee",
      "aaGffaaaabbeeeee",
      "aaGGffaaaabbeeee",
      "aaGGGGGaaaabbbee",
      "aaaaaaGGaaaaabbb",
      "aagggaGffaaaaaab",
      "aagggaGfGfaaaaaa",
      "aagggaGGGGGaaaaa",
      "aaaaaaaaaaaaaaaa",
      "aaaaaaaaaaaaaaaa"
    ],
    [
      "    hhi         ",
      "     hjjj   k   ",
      "     hh l   mm  ",
      "      h     mmk ",
      " n    hhjjjmo   ",
      " np    hh!mqr   ",
      " np     hhs r t ",
      " uw      hh   t ",
      " uxp      hh  m ",
      " uyABpp    hhh  ",
      " uuuuu p     hhh",
      " uGGGuw        h",
      " uGgGux p       ",
      " uGGGuyABpp     ",
      " uuuuuuuunnn    ",
      "                "
    ],
    [
      "    CC          ",
      "     C D    k   ",
      "     hh     mm  ",
      "      C     mmk ",
      "      CCE Fm    ",
      "       CCImI    ",
      "        hh  J r ",
      "         hC   o ",
      "          CC  r ",
      "  K        CCh  ",
      " nnnnn       hCC",
      " npppn         C",
      " n Lpn          ",
      " np pnK         ",
      " nnnnn          ",
      "                "
    ],
    [
      "    CC          ",
      "     C      k   ",
      "     hh     mm  ",
      "      C     mmk ",
      "      CC   m    ",
      "       CC m     ",
      "        hh    J ",
      "         hC   J ",
      "          CC  J ",
      "           CCh  ",
      "             hCC",
      "               C",
      "   L            ",
      "                ",
      "                ",
      "                "
    ],
    [
      "    hh      M   ",
      "     h      k   ",
      "     hh     mm  ",
      "      h     mmkk",
      "      hh   m    ",
      "       hhIm     ",
      "        hh      ",
      "         hh     ",
      "          hh    ",
      "           hhh  ",
      "  NNN        hhh",
      " NNNNN         h",
      " NNLNN          ",
      " NNNNN          ",
      "  NNN           ",
      "                "
    ],
    [
      "    hhOOOOOmmPP ",
      "     hOOOOOOmP  ",
      "     hhOOOOOmm  ",
      "      hOOOOOmmmm",
      "      hhOOOmOOOm",
      "       hhOmOOOOO",
      "        hhOOOOOO",
      "         hhOOOOO",
      "          hhOOOO",
      "           hhhOO",
      "             hhh",
      "   N           h",
      "  NLN           ",
      "   N            ",
      "                ",
      "                "
    ]
  ]
}