{
  "name": "multi_clubhouse1_6_ground",
  "refpalette": "c70cities:multi_clubhouse1_6_ground_palette",
  "xsize": 16,
  "zsize": 16,
  "slices": [
    [
      "GGGGGGGGGGGGGGGG",
      "aabaacaaabbbbbbG",
      "aabacaaaabddddbG",
      " ebaaaacabddddbG",
      "  baacaaabddddbG",
      "  baaacaabddddbG",
      "  baaccaGbffffbG",
      "  baccaaabddddbG",
      "  baacaaabddddbG",
      "  bacacaabddddbG",
      "  baccaaabddddbG",
      "  baaccaabddddbG",
      "  baaacaabddddbG",
      "  baacaaGbffffbG",
      "  baaccaabddddbG",
      "  baaacaabddddbG"
    ],
    [
      "~~~~~~~~~~~~~~~~",
      "ghi~~~~~~iiiiii~",
      "~hi~~~~~~ihhhhi~",
      "~hi~~~~~~ih~~hi~",
      "~hi~~~~~~ih~~hi~",
      "~hi~~~~~~ih~~hi~",
      "~hj~~~~~kjh~~hj~",
      "~hi~~~~~~ih~~hi~",
      "~hi~~~~~~ih~~hi~",
      "~hil~~~~~ih~~hi~",
      "~him~~~~~ih~~hi~",
      "~hi~~~~~~ih~~hi~",
      "~hi~~~~~~ih~~hi~",
      "~hj~~~~~kjh~~hj~",
      "~hi~~~~~~ih~~hi~",
      "~hi~~~~~~ih~~hi~"
    ],
    [
      "~~~~~~~~~~~~~~~~",
      "~~~~~~~~~~~~~~~~",
      "~~~~~~~~~~~~~~~~",
      "~~~~~~~~~~~~~~~~",
      "~~~~~~~~~~~~~~~~",
      "~~~~~~~~~~~~~~~~",
      "~~n~~~~~~~~~~~n~",
      "~~~~~~~~~~~~~~~~",
      "~~~~~~~~~~~~~~~~",
      "~~~~~~~~~~~~~~~~",
      "~~~~~~~~~~~~~~~~",
      "~~~~~~~~~~~~~~~~",
      "~~~~~~~~~~~~~~~~",
      "~~~~~~~~~n~~~~~~",
      "~~~~~~~~~~~~~~~~",
      "~~~~~~~~~~~~~~~~"
    ],
    [
      "~~~~~~~~~~~~~~~~",
      "~~~~~~~~~~~~~~~~",
      "~~~~~~~~~~~~~~~~",
      "~~~~~~~~~~~~~~~~",
      "~~~~~~~~~~~~~~~~",
      "~~~~~~~~~~~~~~~~",
      "~~~~~~~~~~~~~~~~",
      "~~~~~~~~~~~~~~~~",
      "~~~~~~~~~~~~~~~~",
      "~~~~~~~~~~~~~~~~",
      "~~~~~~~~~~~~~~~~",
      "~~~~~~~~~~~~~~~~",
      "~~~~~~~~~~~~~~~~",
      "~~~~~~~~~~~~~~~~",
      "~~~~~~~~~~~~~~~~",
      "~~~~~~~~~~~~~~~~"
    ],
    [
      "~~~~~~~~~~~~~~~~",
      "~~~~~~~~~~~~~~~~",
      "~~~~~~~~~~~~~~~~",
      "~~~~~~~~~~~~~~~~",
      "~~~~~~~~~~~~~~~~",
      "~~~~~~~~~~~~~~~~",
      "~~~~~~~~~~~~~~~~",
      "~~~~~~~~~~~~~~~~",
      "~~~~~~~~~~~~~~~~",
      "~~~~~~~~~~~~~~~~",
      "~~~~~~~~~~~~~~~~",
      "~~~~~~~~~~~~~~~~",
      "~~~~~~~~~~~~~~~~",
      "~~~~~~~~~~~~~~~~",
      "~~~~~~~~~~~~~~~~",
      "~~~~~~~~~~~~~~~~"
    ],
    [
      "~~~~~~~~~~~~~~~~",
      "~~~~~~~~~~~~~~~~",
      "~~~~~~~~~~~~~~~~",
      "~~~~~~~~~~~~~~~~",
      "~~~~~~~~~~~~~~~~",
      "~~~~~~~~~~~~~~~~",
      "~~~~~~~~~~~~~~~~",
      "~~~~~~~~~~~~~~~~",
      "~~~~~~~~~~~~~~~~",
      "~~~~~~~~~~~~~~~~",
      "~~~~~~~~~~~~~~~~",
      "~~~~~~~~~~~~~~~~",
      "~~~~~~~~~~~~~~~~",
      "~~~~~~~~~~~~~~~~",
      "~~~~~~~~~~~~~~~~",
      "~~~~~~~~~~~~~~~~"
    ]
  ]
}