{
  "name": "multi_megatower1_4_floor7",
  "refpalette": "c70cities:multi_megatower1_4_floor7_palette",
  "xsize": 16,
  "zsize": 16,
  "slices": [
    [
      "a   bbbbbbbbcccc",
      "a   bbbbbbbbcccc",
      "a   bbbbbbbbcccc",
      "adddbbbbbbbbcccc",
      "bbbbebbbbbbecccc",
      "             ccc",
      "             ccc",
      "             fcc",
      "             gcc",
      "             hcc",
      "             gcc",
      "    e      e  ic",
      "           j h c",
      "               c",
      "               c",
      "              hc"
    ],
    [
      "a   klmmm       ",
      "a   klmmm      n",
      "a   kommm    g  ",
      "adddkpqr     f  ",
      "ssssetttttte   g",
      "               h",
      "              f ",
      "                ",
      "              n ",
      "                ",
      "              ii",
      "    e      e  i ",
      "               h",
      "                ",
      "               n",
      "                "
    ],
    [
      "a   k           ",
      "a   k          ~",
      "a   k           ",
      "adddku          ",
      "sssse      e    ",
      "                ",
      "                ",
      "                ",
      "              ~ ",
      "                ",
      "    j           ",
      "    e      e    ",
      "                ",
      "                ",
      "               ~",
      "                "
    ],
    [
      "a   k           ",
      "a   k           ",
      "a   k           ",
      "adddku          ",
      "sssse      e    ",
      "                ",
      "                ",
      "                ",
      "                ",
      "                ",
      "    j     j     ",
      "    e      e j  ",
      "     i          ",
      "                ",
      "                ",
      "                "
    ],
    [
      "a   k           ",
      "a   k           ",
      "a   k           ",
      "adddk           ",
      "sssse      e    ",
      "                ",
      "                ",
      "                ",
      "                ",
      "                ",
      "    jj    ji    ",
      "    eii    ejj  ",
      "     i          ",
      "          j     ",
      "                ",
      "                "
    ],
    [
      "w   wxx    w    ",
      "w   w      w    ",
      "w   w      w    ",
      "wdyAw      w    ",
      "BBBBeBBBBBBeBBBB",
      "CCCCw      w    ",
      "CCDCw      w    ",
      "CCCCw      w    ",
      "CCCCw      w    ",
      "CCDCw      w    ",
      "CCCCw     jwi   ",
      "BBBBeBBBBBBeBBBB",
      "CCCCw      w    ",
      "CCDCw     jw    ",
      "CCCCw      w    ",
      "CCCCw      w    "
    ]
  ]
}