{
  "name": "multi_communitycenter_7_ground",
  "refpalette": "c70cities:multi_communitycenter_7_ground_palette",
  "xsize": 16,
  "zsize": 16,
  "slices": [
    [
      "aaab    baaaaaGc",
      "aaab    baaaaaGc",
      "aaab    baaaaaGc",
      "aaabddddbaaaaaGc",
      "aaabbbbbbaaaaaGc",
      "aaaaaaaaaaaaaaGc",
      "aaaaaaaaaaaaaaGc",
      "aaaaaaaaaaaaaaGc",
      "aaaaaaaaaaaaaaGc",
      "aaaaaaaaaaaaaaGc",
      "aaaaaaaaaaaaaaGc",
      "aaaaaaaaaaaaaaGc",
      "eeeeeeaaaaaaaaGc",
      "ffffffaaaaaaaaGc",
      "ffffffaaaaaaaaGc",
      "ffffffaaaaaaaaGc"
    ],
    [
      " ghi    ih   jk ",
      " lmi    im  nop ",
      " qmi    im rrop ",
      " smiiiiiim t op ",
      "  hmmmmmmh  njk ",
      "   uuwwxy    op ",
      "        A  rrop ",
      "        y  t op ",
      "  wB C   hDDDjk ",
      "   E C  y n nop ",
      "   F  C A rrrop ",
      "   I!C  y t top ",
      "JKLLLL   hDDDjk ",
      "  y  L  y n nop ",
      "  M NL  A rrrop ",
      "  yOOL  y t top "
    ],
    [
      "  h      h   j  ",
      "  m      m   o  ",
      "  m      m  !o  ",
      "  m      m   o  ",
      "  hmmmmmmh   j  ",
      "       Py    o  ",
      "        Q  R o  ",
      "        y    o  ",
      "    S    hTTTj  ",
      "    S   y    o  ",
      "    S   Q    o  ",
      "    S   y    o  ",
      "UVLLLL   hTTTj  ",
      "  y  L  y    o  ",
      "  W XL  Q    o  ",
      "  yOOL  y    o  "
    ],
    [
      "  h      h   j  ",
      "  m      m   Y  ",
      "  m      m   Y  ",
      "  m      m   Y  ",
      "  hmmmmmmh   j  ",
      "        y    Y  ",
      "        y    Y  ",
      "        y    Y  ",
      "         hDDDj  ",
      "        y    Y  ",
      "        y    Y  ",
      "        y    Y  ",
      "LLLLLL   hDDDj  ",
      "  yZZL  y    Y  ",
      "  yZZL  y    Y  ",
      "  y00L  y    Y  "
    ],
    [
      "  h      h   j  ",
      "  m      m   o  ",
      "  m      m   o  ",
      "  m      m   o  ",
      " 1hmmmmmmh1  j  ",
      "   22222y    o  ",
      "        y    o  ",
      "        y    o  ",
      "  3     1hDDDj  ",
      "        y    o  ",
      "        y    o  ",
      "        y    o  ",
      "LLLLLL   hDDDj  ",
      "   45L  y    o  ",
      "    5L  y    o  ",
      "   44L  y    o  "
    ],
    [
      "aaaaaaaaaaaaa6  ",
      "aaaaaaaaaaaaa6  ",
      "aaaaaaaaaaaaa6  ",
      "aaaaaaaaaaaaa6  ",
      "aaaaaaaaaaaaaj  ",
      "aaaaaaaaaaaaa6  ",
      "aaaaaaaaaaaaa6  ",
      "aaaaaaaaaaaaa6  ",
      "aaaaaaaaaaaaa6  ",
      "aaaaaaaaaaaaa6  ",
      "aaaaaaaaaaaaa6  ",
      "aaaaaaaaaaaaa6  ",
      "LLLLLLaaaaaaaj  ",
      "bbbbbLaaaaaaa6  ",
      "bbbbbLaaaaaaa6  ",
      "bbbbbLaaaaaaa6  "
    ]
  ]
}