{
  "name": "multi_laboratory1_7_base7",
  "refpalette": "c70cities:multi_laboratory1_7_base7_palette",
  "xsize": 16,
  "zsize": 16,
  "slices": [
    [
      "aaaabccccccbaaaa",
      "aaaabccccccbaaaa",
      "aaaabccccccbaaaa",
      "aaaabccccccbaaaa",
      "aaaabbbbbbbbaaaa",
      "daaaaaaaaaaaaaad",
      "daaaaaaaaaaaaead",
      "ddaaaaaaaaaaaedd",
      "adddaaaaaaaaddda",
      "aaadddaaaadddaaa",
      "aaaaaddddddaaaaa",
      "aaaaaaaaaaaaaaaa",
      "aaaaaaaaaaaaaaaa",
      "aaaaaaaaaaaaaaaa",
      "aaaaaaaaaaaaaaaa",
      "aaaaaaaaaaaaaaaa"
    ],
    [
      "aaf g      g  eh",
      "aaa g      g  ih",
      "aaa g      g  ah",
      "aaa g      g jhe",
      "aa  kllllllk  hh",
      "aaaa   m    n oa",
      "aaahn        aaa",
      "apaah    q   apa",
      "aaaaoa     jaaaa",
      "aaaaapaa  paaaaa",
      "aaaaaaaaaaaaaaaa",
      "aaaaaaaaaaaaaaaa",
      "aaaaaaaaaaaaaaaa",
      "aaaaaaaaaaaaaaaa",
      "aaaaaaaaaaaaaaaa",
      "aaaaaaaaaaaaaaaa"
    ],
    [
      "a               ",
      "a r            e",
      "as            ii",
      "af              ",
      "on    t       ih",
      "ah             a",
      "ahhi           a",
      "aphh         !pa",
      "aaaa t   q  aaaa",
      "aaaaap    paaaaa",
      "aaaaaauuuuaaaaaa",
      "aaaaawxyyAwaaaaa",
      "aaaaawBCCDwaaaaa",
      "aaaaawBCCDwaaaaa",
      "aaaaaEBCCDEaaaaa",
      "aaaaawBCCDwaaaaa"
    ],
    [
      "a               ",
      "                ",
      "               i",
      "j               ",
      "                ",
      "ai             a",
      "ah i           a",
      "apij          pa",
      "aaaa        aaaa",
      "aaaaapFFFFpaaaaa",
      "aaaaaauIJuaaaaaa",
      "aaaaaw    waaaaa",
      "aaaaaw    waaaaa",
      "aaaaaw    waaaaa",
      "aaaaaK    Laaaaa",
      "aaaaaw    waaaaa"
    ],
    [
      " ~~~~~~~~~~~~~~ ",
      " ~~~~~~~~~~~~~~ ",
      " ~~~~~~~~~~~~~~ ",
      " ~~~~~~~~~~~~~~ ",
      " ~~~~~~~~~~~~~~ ",
      "ai~~~~~~~~~~~~~a",
      "a~~~~~~~~~~~~~~a",
      "api~~~~~~~~~~~pa",
      "aaaa        aaaa",
      "aaaaap    paaaaa",
      "aaaaaauMNuaaaaaa",
      "aaaaawO  Owaaaaa",
      "aaaaaw    waaaaa",
      "aaaaaw    waaaaa",
      "aaaaaK    Laaaaa",
      "aaaaaw    waaaaa"
    ],
    [
      " ~~~~~~~~~~~~~~ ",
      " ~~~~~~~~~~~~~~ ",
      " ~~~~~~~~~~~~~~ ",
      " ~~~~~~~~~~~~~~ ",
      " ~~~~~~~~~~~~~~ ",
      "a~~~~~~~~~~~~~~a",
      "a~~~~~~~~~~~~~~a",
      "api~~~~~~~~~~~pa",
      "aaaa        aaaa",
      "aaaaap    paaaaa",
      "aaaaaauuuuaaaaaa",
      "aaaaawPQQRwaaaaa",
      "aaaaawP  Rwaaaaa",
      "aaaaawPQQRwaaaaa",
      "aaaaawP  Rwaaaaa",
      "aaaaawPQQRwaaaaa"
    ]
  ]
}