{
  "name": "multi_factory_1_ground",
  "refpalette": "c70cities:multi_factory_1_ground_palette",
  "xsize": 16,
  "zsize": 16,
  "slices": [
    [
      "aaabbbbbbbbbbbzz",
      "zaabbbbbbbbbbbzz",
      "azabbbbbbbbbbbzz",
      "aaabbbbbbbbbbbzz",
      "aaabbbbbbbbbbbzz",
      "aaabbbbbbbbbbbzz",
      "zaabbbbbbbbbbbzz",
      "aaabbbbbbbbbbbzz",
      "zaabbbbbbbbbbbzz",
      "zaabbbbbbbbbbbzz",
      "aaabbbbbbbbbbbzz",
      "aaabbbbbbbbbbbzz",
      "azabbbbbbbbbbbzz",
      "aaabbbbbbbbbbbzz",
      "zaazzzzzzzzzzzzz",
      "aazzzzzzzzzzzzzz"
    ],
    [
      "     ccccd  ce  ",
      "     ccdcd fge  ",
      "     ccdcd fhe  ",
      "   e   i   fje  ",
      "   ec  kc   ce  ",
      "   e         e  ",
      "   l       mne  ",
      "   l     ooo e  ",
      "   l    mo!ome  ",
      "   l   mnooo e  ",
      "   l     m   e  ",
      "   ln     pp e  ",
      "   ecqqrcstuce  ",
      "   eeeeeeeeeee  ",
      "                ",
      "                "
    ],
    [
      "      kkkd  we  ",
      "     dkdkd   e  ",
      "     xkkkd  ye  ",
      "   e   A     e  ",
      "   ec  kc   ce  ",
      "   e         e  ",
      "   l         e  ",
      "   l     ooo e  ",
      "   l       o e  ",
      "   l     ooo e  ",
      "   l         e  ",
      "   ln        e  ",
      "   ec   c ppce  ",
      "   eeeeeeeeeee  ",
      "                ",
      "                "
    ],
    [
      "   l  BBBy   e  ",
      "   l  BBBy   e  ",
      "   l  BBBy  Ce  ",
      "   e         e  ",
      "   ec   c   ce  ",
      "   e         e  ",
      "   ln        e  ",
      "   l     oo  e  ",
      "   l       o e  ",
      "   l     moo e  ",
      "   l         e  ",
      "   l         e  ",
      "   ecn  c  nce  ",
      "   eeDEFeDEFee  ",
      "                ",
      "                "
    ],
    [
      "  IeJ        e  ",
      "  IeJ       Ke  ",
      "  IeJ      LMe  ",
      "   e         e  ",
      "   ec   c   ce  ",
      "   en        e  ",
      "  IeJ        e  ",
      "  IeJ    NNN e  ",
      "  IeJ    N N e  ",
      "  IeJ    NNN e  ",
      "  IeJ        e  ",
      "  IeJ   O   Oe  ",
      "   ecOOOcOOOce  ",
      "   eeeeeeeeeee  ",
      "                ",
      "                "
    ],
    [
      "   e         e  ",
      "   e         e  ",
      "   e         e  ",
      "   e         e  ",
      "   ec   c   ce  ",
      "   e         e  ",
      "   e         e  ",
      "   eO   ONNNOe  ",
      "   eOOOOON NOe  ",
      "   eO   ONNNOe  ",
      "   eP   P   Pe  ",
      "   eQQQQQQQQQe  ",
      "   eQQQQQQQQQe  ",
      "   RRRRRRRRRRR  ",
      "                ",
      "                "
    ]
  ]
}