{
  "name": "multi_gallery_0_base1",
  "refpalette": "c70cities:multi_gallery_0_base1_palette",
  "xsize": 16,
  "zsize": 16,
  "slices": [
    [
      "vvvvvvvvvvvvvvvv",
      "vaaaaaaaaaaaaaaa",
      "vabccccccccccccb",
      "vabddddddddddddb",
      "vabddddddddddddb",
      "vabddeeeeedddddb",
      "vabddeeeeedddddb",
      "vabddeeeeedddddb",
      "vabddeeeeedddddb",
      "vabddeeeeedddddb",
      "vabddeeeeedddddb",
      "vabddddddddddddb",
      "vabddddddddddddb",
      "vabddeeeeedddddb",
      "vabddeeeeedddddb",
      "vabddeeeeedddddb"
    ],
    [
      "vvvvvvvvvvvvvvvv",
      "vaaaaaaaaaaaaaaa",
      "vabccccccccccccb",
      "vab            b",
      "vab            b",
      "vab  eeeee    fb",
      "vab  egghe     b",
      "vab  eggge     b",
      "vab  ehgge    fb",
      "vab  egg!e     b",
      "vab  eeeee     b",
      "vab           fb",
      "vab            b",
      "vab  eeeee     b",
      "vab  eaije    fb",
      "vab  ejiie     b"
    ],
    [
      "vvvvvvvvvvvvvvvv",
      "vaaaaaaaaaaaaaaa",
      "vabccccccccccccb",
      "vab            b",
      "vab            b",
      "vab  klllk    mb",
      "vab  lhhhl     b",
      "vab  lhghl     b",
      "vab  lhhhl    nb",
      "vab  lhhhl     b",
      "vab  klllk     b",
      "vab           ob",
      "vab            b",
      "vab  klllk     b",
      "vab  l   l    pb",
      "vab  l G l     b"
    ],
    [
      "vvvvvvvvvvvvvvvv",
      "vaaaaaaaaaaaaaaa",
      "vabccccccccccccb",
      "vab            b",
      "vab            b",
      "vab  klllk     b",
      "vab  l   l     b",
      "vab  l q l     b",
      "vab  l   l     b",
      "vab  l   l     b",
      "vab  klllk     b",
      "vab            b",
      "vab            b",
      "vab  klllk     b",
      "vab  l   l     b",
      "vab  l r l     b"
    ],
    [
      "vvvvvvvvvvvvvvvv",
      "vaaaaaaaaaaaaaaa",
      "vabccccccccccccb",
      "vab            b",
      "vab            b",
      "vab  klllk     b",
      "vab  l   l     b",
      "vab  l   l     b",
      "vab  l   l     b",
      "vab  l   l     b",
      "vab  klllk     b",
      "vab            b",
      "vab            b",
      "vab  klllk     b",
      "vab  l   l     b",
      "vab  l   l     b"
    ],
    [
      "vvvvvvvvvvvvvvvv",
      "vaaaaaaaaaaaaaaa",
      "vabccccccccccccb",
      "vabs       ssssb",
      "vabs       ssssb",
      "vabs klllk ssstb",
      "vabs l   l ssssb",
      "vabs l   l ssssb",
      "vabs l   l ssstb",
      "vabs l   l ssssb",
      "vabs klllk ssssb",
      "vabs       sssub",
      "vabs       ssssb",
      "vabs klllk ssssb",
      "vabs l   l ssstb",
      "vabs l   l ssssb"
    ]
  ]
}