{
  "name": "multi_militarybase_1_base2",
  "refpalette": "c70cities:multi_militarybase_1_base2_palette",
  "xsize": 16,
  "zsize": 16,
  "slices": [
    [
      "vaaaaaaaaabbbc  ",
      "vaaaaaaaaabbbc  ",
      "vvcccvcccccccvcc",
      "vaaaacaaaabbbcbb",
      "vaaaacaaaabbbcbb",
      "vaaaacaaaaabbcbb",
      "vaaaacaaaaaadvee",
      "vaaaacaaaaaaacaa",
      "vaaaacaaaaaaacaa",
      "vaaaacaaaaaaacaa",
      "vvcccvcccccccvcc",
      "vaaaacaaaaaaacff",
      "vaaaacaaaaaaacff",
      "vaaaacaaaaaaacff",
      "vaaaavaaaaaaavff",
      "vvvvvvvvvvvvvvvv"
    ],
    [
      "v      ggh   i  ",
      "vjkkk   h    i  ",
      "vvlllv       vii",
      "vk mn  h        ",
      "vk     gg       ",
      "vk oo  ggh      ",
      "vp     h    dvqr",
      "vk oo          s",
      "vk              ",
      "vk tu           ",
      "vvqqqvqqqwqqqvqq",
      "vxyxABCCC DEFIJ ",
      "vK   L    M NIqq",
      "vO   B PP D  IJ ",
      "v!OQQvRSSRDTUvqq",
      "vvvvvvvvvvvvvvvv"
    ],
    [
      "v               ",
      "vkkjk           ",
      "vvlllv       v  ",
      "vk              ",
      "vV              ",
      "vk              ",
      "vk          dvqr",
      "vk             s",
      "vp              ",
      "vk              ",
      "vvqqqvqqqWqqqvqq",
      "v    B!X  DY I  ",
      "v    Z    0  Iqq",
      "v    B    D 1I  ",
      "vO2  v    D 3vqq",
      "vvvvvvvvvvvvvvvv"
    ],
    [
      "v               ",
      "vk4kk           ",
      "vvlllv       v  ",
      "vk              ",
      "vk              ",
      "vk              ",
      "vk          dvqq",
      "vV              ",
      "vk              ",
      "vk              ",
      "vvqqqvqqqqqqqvqq",
      "v    B    DY I  ",
      "v    B    D  Iqq",
      "v    B    D  I  ",
      "v    v    D 5vqq",
      "vvvvvvvvvvvvvvvv"
    ],
    [
      "v            6  ",
      "v7           6  ",
      "vvlllv       v66",
      "v    i          ",
      "v    i          ",
      "v    i          ",
      "v    i      dvii",
      "v    i       i  ",
      "v    i       i  ",
      "v8   i       i  ",
      "vvqqqviiiiiiivqq",
      "v    B    D  I99",
      "v    B    D  I99",
      "v    B    D  I99",
      "v    v    D  v99",
      "vvvvvvvvvvvvvvvv"
    ],
    [
      "v@###########$  ",
      "v@###########$  ",
      "vvcccvcccccccv$$",
      "v@###c#######c##",
      "v@###c#######c##",
      "v@###c#######c##",
      "v@###c######dv##",
      "v@###c#######c##",
      "v@###c#######c##",
      "v@###c#######c##",
      "vvcccvcccccccvcc",
      "v@###c#######c77",
      "v@###c#######c  ",
      "v@###c#######c7 ",
      "v@@@@v@@@@@@@v@@",
      "vvvvvvvvvvvvvvvv"
    ]
  ]
}