{
  "name": "multi_laboratory1_0_base5",
  "refpalette": "c70cities:multi_laboratory1_0_base5_palette",
  "xsize": 16,
  "zsize": 16,
  "slices": [
    [
      "zzzzzzzzzzzzzzzz",
      "zaaaaaaaaaaaaaaa",
      "zabbbbbbbbbbcccc",
      "zab===!====d    ",
      "zab========d    ",
      "zab========ddddd",
      "zab========de   ",
      "zabfg======d    ",
      "zab========d    ",
      "zabfg==hh==d    ",
      "zabg=======d    ",
      "zab========d    ",
      "zab========d    ",
      "zab====i===d    ",
      "zabf=======d    ",
      "zadjjjjjjjjdjjjj"
    ],
    [
      "zzzzzzzzzzzzzzzz",
      "zaaaaaaaaaaaaaaa",
      "zabbbbbbbbbbcccc",
      "zabklmnnnnmj    ",
      "zabk mmmmmmj    ",
      "zabo  pppp jjjjj",
      "zab        q    ",
      "zabfg      q    ",
      "zabk  pppp d    ",
      "zabfg p  p q    ",
      "zabr  pppp q    ",
      "zabst  u  wq    ",
      "zabxy mmmm q    ",
      "zab  Amhhm q    ",
      "zabfg mmmm q    ",
      "zadjjjjjjjjdjjjj"
    ],
    [
      "zzzzzzzzzzzzzzzz",
      "zaaaaaaaaaaaaaaa",
      "zabbbbbbbbbbcccc",
      "zabB   CnC j    ",
      "zabB       j    ",
      "zab        jjjjj",
      "zab             ",
      "zabfg           ",
      "zabB       d    ",
      "zabfg           ",
      "zab             ",
      "zabDE           ",
      "zabFI   A       ",
      "zab J K         ",
      "zabfr  w        ",
      "zadjjjjjjjjdjjjj"
    ],
    [
      "zzzzzzzzzzzzzzzz",
      "zaaaaaaaaaaaaaaa",
      "zabbbbbbbbbbcccc",
      "zab     g  j    ",
      "zab        j    ",
      "zab        jjjjj",
      "zablL           ",
      "zabfr           ",
      "zab        d    ",
      "zabfg           ",
      "zab             ",
      "zab g           ",
      "zab             ",
      "zab             ",
      "zabf            ",
      "zadjjjjjjjjdjjjj"
    ],
    [
      "zzzzzzzzzzzzzzzz",
      "zaaaaaaaaaaaaaaa",
      "zabbbbbbbbbbcccc",
      "zabl    g  j    ",
      "zab        j    ",
      "zabl       jjjjj",
      "zablg           ",
      "zabf            ",
      "zab        d    ",
      "zabfg           ",
      "zab             ",
      "zab g           ",
      "zab             ",
      "zab             ",
      "zabf            ",
      "zadjjjjjjjjdjjjj"
    ],
    [
      "zzzzzzzzzzzzzzzz",
      "zaaaaaaaaaaaaaaa",
      "zabbbbbbbbbbcccc",
      "zabfMMMMgMMj    ",
      "zabfMMMMMMMj    ",
      "zabfMMMMMMMjjjjj",
      "zabfMMMMMMMMMMMM",
      "zabfMMMMMMMMMMMM",
      "zabNMMMMMMMdMMMM",
      "zabfMMMMMMMMMMMM",
      "zabfMMMMMMMMMMMM",
      "zabfMMMMMMMMMMMM",
      "zabfMMMMMMMMMMMM",
      "zabfMMMMMMMMMMMM",
      "zabfMMMMMMMMMMMM",
      "zadjjjjjjjjdjjjj"
    ]
  ]
}