{
  "name": "multi_hospital_2_ground",
  "refpalette": "c70cities:multi_hospital_2_ground_palette",
  "xsize": 16,
  "zsize": 16,
  "slices": [
    [
      "GGGGGGGGGGGGGGGG",
      "aaaaaaaaaaaaaaaG",
      "aaaabbbbbbbbbbaG",
      "caaabbbbbbbbbbaG",
      "daaadGGdGGdGGdaG",
      "caaaaaaaaaaaaaaG",
      "caaaaaaaaaaaaaaG",
      "caaaaaaaaaaaaaaG",
      "caaaaaaaaaaaaaaG",
      "cceeeeeeeeeeeeaG",
      "cceeee!eeeeeeeaG",
      "cceeeeeeeeeeeeaG",
      "cceeeeeeeeeeeeaG",
      "cceeeeeeeeeeeeaG",
      "ccccccccccccccaG",
      "ccccccccccccccaG"
    ],
    [
      "                ",
      "                ",
      " f              ",
      "gh   ij ij ij   ",
      "kh  llllllllll  ",
      " h              ",
      " m              ",
      " h              ",
      "ngggggggggggggo ",
      " p   p   p   qo ",
      " q r q r q r qo ",
      "sqtthqtthqtt qo ",
      "squu quu q u qo ",
      "sqw  qw  qx  qo ",
      "yqAABAAACAAABAo ",
      "            DGE "
    ],
    [
      "                ",
      "                ",
      " f              ",
      "gh              ",
      "kh              ",
      " h              ",
      " F              ",
      " h              ",
      "nggIIggIIggIIgo ",
      " J   J   J   qo ",
      " q   q   q   qo ",
      " qKL qML qN  qo ",
      " q   q   q   qo ",
      " qN  qN  q   qo ",
      " qAAOAAAPAAAOAo ",
      "             QR "
    ],
    [
      "                ",
      "                ",
      " f              ",
      "gh              ",
      "kh              ",
      " h              ",
      " h              ",
      " h              ",
      "nggIIggIIggIIgo ",
      " S   S   S   qo ",
      " q   q   q   qo ",
      " q   q   q   qo ",
      " q   q   q   qo ",
      " qTU qTU qTU qo ",
      " qAAVAAAVAAAVAo ",
      "             WR "
    ],
    [
      "                ",
      "                ",
      " f              ",
      "gh              ",
      " h              ",
      " h              ",
      " h              ",
      " h              ",
      "ngggggggggggggo ",
      " q   q   q   qo ",
      " q   q   q   qo ",
      " q   q   q   qo ",
      " q   q   q   qo ",
      " q X qYX qZ0 qo ",
      " qAAAAAAAAAAAAo ",
      "              R "
    ],
    [
      "                ",
      "                ",
      " f              ",
      "gh              ",
      " h              ",
      " h              ",
      " h              ",
      " h              ",
      "n1222222222222o ",
      " q           qo ",
      " q           qo ",
      " q           qo ",
      " q           qo ",
      " q           qo ",
      " qAAAAAAAAAAAAo ",
      "              R "
    ]
  ]
}