{
  "name": "multi_communitycenter_3_ground",
  "refpalette": "c70cities:multi_communitycenter_3_ground_palette",
  "xsize": 16,
  "zsize": 16,
  "slices": [
    [
      "aaaaaaaaaaaaaaaa",
      "aaaaaaaaaaaaaaaa",
      "bbbcaaaaaaaaaaaa",
      "bbbcaaaaaaaaaaaG",
      "bbbcaaaaaaaaaaGG",
      "dddcaaaaaaaaaaGG",
      "dddcaaaaaaaaaaGG",
      "dddcaaaaeeaaaaGG",
      "dddcaaaeffeaaaag",
      "dddcaaeffffeaaGg",
      "dddcaaeffffeaaGg",
      "dddcaaeffffeaaGg",
      "hhhcaaeffffeaaag",
      "iihjaaeffffeaaGg",
      "kkljaaeffffeaaGg",
      "kmljaaeffffeaaGg"
    ],
    [
      "                ",
      "                ",
      " nop            ",
      "nqop           r",
      "ssoj          rr",
      "bbbj          rt",
      "bbbj          r ",
      "bbbj   ueeu   rw",
      "bbbj  ueffeu  xy",
      "dddj  effffe  rA",
      "dddj  effffe  ry",
      "dddj  effffe  rA",
      "BBhj  effffe  xA",
      "  hj  effffe  rA",
      "   j  effffe  ry",
      "  Cj  effffe  rA"
    ],
    [
      "                ",
      "                ",
      "                ",
      "                ",
      "  o             ",
      "  o            D",
      " Eop            ",
      "  op           F",
      " Eoj      ~   xy",
      "bbbj           A",
      "bbIj           y",
      "bbIj           A",
      "bbbj          xA",
      "hhhj           A",
      "JJJj           y",
      "JJJK           A"
    ],
    [
      "                ",
      "                ",
      "                ",
      "                ",
      "                ",
      "                ",
      "                ",
      "                ",
      "  o       ~   xy",
      " no            A",
      "n op           y",
      " Eop           A",
      " qoj          xA",
      "bbbj           A",
      "bbbj           y",
      "bbbj           A"
    ],
    [
      "                ",
      "                ",
      "                ",
      "                ",
      "                ",
      "                ",
      "                ",
      "                ",
      "         ~~   xL",
      "               A",
      "               A",
      "               A",
      "  o           xA",
      "  o            A",
      "qnop           A",
      " nop           A"
    ],
    [
      "                ",
      "                ",
      "                ",
      "                ",
      "                ",
      "                ",
      "                ",
      "                ",
      "          ~   MM",
      "              Mg",
      "              Mg",
      "              Mg",
      "              xg",
      "              Mg",
      "              Mg",
      "              Mg"
    ]
  ]
}