{
  "name": "multi_megatower1_1_floor14",
  "refpalette": "c70cities:multi_megatower1_1_floor14_palette",
  "xsize": 16,
  "zsize": 16,
  "slices": [
    [
      "   abGcdceeeff  ",
      "   abGcceeeeff  ",
      "   abGccdcdeffgh",
      "   abGccedeeffii",
      "   jbGccdeeefkff",
      "   abGcceeeeffff",
      "   abGccdceeffff",
      "   abGcccedeffff",
      "   abGccdeeeffff",
      "   abGcccdeeffff",
      "   abGccddeeffff",
      "   jbGcdeeeefkff",
      "   abGccedeeffff",
      "   abGcdeeeeffff",
      "   abGccdcdeffff",
      "   abGcceeeeffff"
    ],
    [
      "   almn      o  ",
      "   alpq      og ",
      "   alrn    s ot ",
      "   almq    u o  ",
      "   jlmq    w kxy",
      "   alrn    A    ",
      "   alpn         ",
      "   alrn         ",
      "   almq         ",
      "   alpn         ",
      "   alrq    u    ",
      "   jlmn    w kB ",
      "   alrn    A oCC",
      "   alpq    s oD ",
      "   almq      o  ",
      "   alrn      oE "
    ],
    [
      "   alF       oi ",
      "   al        ot ",
      "   aIJ     s o  ",
      "   alF       o  ",
      "   jlF       kxK",
      "   aIJ          ",
      "   al           ",
      "   alJ          ",
      "   alF          ",
      "   a            ",
      "   alJ          ",
      "   jlF       k  ",
      "   aIJ       oLM",
      "   al      s o  ",
      "   alF       o  ",
      "   alJ       o  "
    ],
    [
      "   al        otN",
      "   a         o  ",
      "   al        o  ",
      "   al        o O",
      "   jI        kxx",
      "   aI           ",
      "   al           ",
      "   al           ",
      "   al           ",
      "   a            ",
      "   aI           ",
      "   jl        k  ",
      "   al        o  ",
      "   al        o  ",
      "   aI        o  ",
      "   al        oPP"
    ],
    [
      "   aI        Q h",
      "   a         Q N",
      "   a         Q  ",
      "   a         Q  ",
      "   j         kxx",
      "   al        Q  ",
      "   al        Q  ",
      "   a         Q  ",
      "   aI        Q  ",
      "   a         Q  ",
      "   a         Q  ",
      "   j         k  ",
      "   a         Q  ",
      "   aI        Q  ",
      "   aI        QPP",
      "   a         Q  "
    ],
    [
      "   R       S k  ",
      "   R       x k h",
      "   R       x k i",
      "   R       x kgi",
      "   T      UVWkkk",
      "   R       S k  ",
      "   R       S k  ",
      "   R       S k  ",
      "   R       x k  ",
      "   R       x k  ",
      "   R       x k  ",
      "   T      UVWkkk",
      "   R       S k  ",
      "   R       S kPP",
      "   R       S k  ",
      "   R       x k  "
    ]
  ]
}