{
  "name": "multi_laboratory1_2_base5",
  "refpalette": "c70cities:multi_laboratory1_2_base5_palette",
  "xsize": 16,
  "zsize": 16,
  "slices": [
    [
      "zab           c ",
      "zadd          c ",
      "zad           c ",
      "zaeec         cf",
      "zabg c     hi  c",
      "zaeec          c",
      "zabd            ",
      "zabd            ",
      "zabd            ",
      "zab             ",
      "zaeec           ",
      "zabgjc     hk   ",
      "zaeec           ",
      "zab             ",
      "zabd            ",
      "zab             "
    ],
    [
      "zab           c ",
      "zabd          c ",
      "zab           c ",
      "zaeec         cf",
      "zabg c     h   c",
      "zaeec          c",
      "zab             ",
      "zab             ",
      "zabd            ",
      "zab             ",
      "zaeec           ",
      "zabgjc     h    ",
      "zaeec           ",
      "zabd            ",
      "zabd            ",
      "zab             "
    ],
    [
      "zabd          c ",
      "zabd          c ",
      "zab           c ",
      "zaeec         cf",
      "zabg c     h   c",
      "zaeec          c",
      "zab             ",
      "zab             ",
      "zabd            ",
      "zab             ",
      "zaeec           ",
      "zabgjc     h    ",
      "zaeec           ",
      "zab             ",
      "zabd            ",
      "zab             "
    ],
    [
      "zab           c ",
      "zabd          c ",
      "zab           c ",
      "zaeec         cf",
      "zabg c     h   c",
      "zaeec          c",
      "zab             ",
      "zab             ",
      "zadd            ",
      "zad             ",
      "zaeec           ",
      "zabgjc     h    ",
      "zaeec           ",
      "zab             ",
      "zabd            ",
      "zab             "
    ],
    [
      "zab           c ",
      "zabd          c ",
      "zab           c ",
      "zaeec         cf",
      "zabg c     h   c",
      "zaeec          c",
      "zab             ",
      "zab             ",
      "zabd            ",
      "zab             ",
      "zaeec           ",
      "zabgjc     h    ",
      "zaeec           ",
      "zab             ",
      "zabd            ",
      "zab             "
    ],
    [
      "zabdllllllllllc ",
      "zabmllllllllllc ",
      "zabdllllllllllc ",
      "zaeeeellllllllcf",
      "zabgnelllllhlllc",
      "zaeeeelllllllllc",
      "zabdllllllllllll",
      "zabdllllllllllll",
      "zabmllllllllllll",
      "zabdllllllllllll",
      "zaeeeellllllllll",
      "zabgoelllllhllll",
      "zaeeeellllllllll",
      "zabdllllllllllll",
      "zabmllllllllllll",
      "zabdllllllllllll"
    ]
  ]
}