{
  "name": "multi_megatower1_4_floor3",
  "refpalette": "c70cities:multi_megatower1_4_floor3_palette",
  "xsize": 16,
  "zsize": 16,
  "slices": [
    [
      "a   bbbbbbbbbbbb",
      "a   bbbbbbbbbbbb",
      "a   bbbbbbbbbbbb",
      "cdeebbbbbbbbbbbb",
      "bbbbfbbbbbbfbbbb",
      "bbbbbbbbbbbbbbbb",
      "gggggggggggggggg",
      "gggggggggggggggg",
      "gggggggggggggggg",
      "gggggggggggggggg",
      "bbbbbbbbbbbbbbbb",
      "bbbbfbbbbbbfbbbb",
      "bbbbbbbbbbbbbbbb",
      "bbbbbbbbbbbbbbbb",
      "bbbbbbbbbbbbbbbb",
      "bbbbbbbbbbbbbbbb"
    ],
    [
      "a   ah  ijklmn  ",
      "a   aoi  iplpq  ",
      "a   arr srrlrrt ",
      "aeuuawx s ylA t ",
      "BCDEfFI J sft K ",
      "     LI sMsNtOt ",
      "     PPQPPP PPPR",
      "                ",
      "                ",
      "STSS SSUSSS SSSV",
      "t WXNLI sYsNtYt ",
      "Z WFfFI 0 sft Z ",
      "tixwlwx s 1lA t ",
      "t 22l22 s22l22ti",
      "   3lo    plpi i",
      " ii4lh   jklmn  "
    ],
    [
      "a   a      l    ",
      "a   a     5l6   ",
      "a   arr srrlrrt ",
      "ae  a   s 7l  t ",
      "B 89f@I # sft $ ",
      "     LI s sNt t ",
      "     PP%PPP PPP^",
      "                ",
      "                ",
      "S&SS SS*SSS SSS(",
      "t WXNLI s sNt t ",
      ") W@f@I + sft ) ",
      "t  !l   s  l  t ",
      "t 22l22 s22l22t ",
      "    l     -l[   ",
      "    l      l    "
    ],
    [
      "a   a      l    ",
      "a   a      l    ",
      "a   arr srrlrrt ",
      "aeeea   s  l  t ",
      "B]  fL  s sft t ",
      "     L{ s sNt t ",
      "     PP}PPP PPP}",
      "                ",
      "                ",
      "S\\SS SS\\SSS SSS\\",
      "t  XNL  s sNt t ",
      "t  XfL  s sft t ",
      "t  {l{  s  l  t ",
      "t 22l22 s22l22t ",
      "    l      l    ",
      "    l      l    "
    ],
    [
      "a   a      l    ",
      "a   a{     l{   ",
      "a   arr srrlrrt ",
      "aeeea   s {l  t ",
      "BBBBfL  s sft t ",
      "     L{ s s|t t ",
      "     PPPPPP`PPPP",
      "                ",
      "                ",
      "SSSS:SSSSSS:SSSS",
      "t {X|L  s{s|t t{",
      "t  XfL  s sft t ",
      "t {{l{  s {l{ t ",
      "t 22l22 s22l22t ",
      "    l      l    ",
      "    l      l    "
    ],
    [
      ";   ;{     ;    ",
      ";   ;{     ;    ",
      ";   ;bbbbbb;bbbb",
      ";e'';bbbbbb;bbbb",
      ",,,,f,,,,,,f,,,,",
      "....;bbbbbb;bbbb",
      "....;//////;////",
      "....;......;....",
      "....;......;....",
      "<<<<;<<<<<<;<<<<",
      "bbbb;bbbbbb;bbbb",
      ",,,,f,,,,,,f,,,,",
      "bbbb;bbbbbb;bbbb",
      "bbbb;bbbbbb;bbbb",
      "   {;      ;{   ",
      "    ;      ;    "
    ]
  ]
}