{
  "name": "multi_clubhouse1_7_ground",
  "refpalette": "c70cities:multi_clubhouse1_7_ground_palette",
  "xsize": 16,
  "zsize": 16,
  "slices": [
    [
      "  abbbccbaddddaG",
      "  abbccbbaddddaG",
      "  abcbbbbaddddaG",
      "  abccbbbaddddaG",
      "  abbbcbGaeeeeaG",
      "  abbcbbba    aG",
      "  abbcbcbaffffaG",
      "  abcbcbca    aG",
      "  abbbccca    aG",
      "  abbcbcbaffffaG",
      "  abbccbba    aG",
      "  abcbcbgaeeeeaG",
      " aabbccbbaddddaG",
      " abbbcbbbaddddaG",
      "aabbbbcbbaddddaG",
      "abbcbcbbbaddddaG"
    ],
    [
      "~hi~~~~~jih~~hi~",
      "~hi~~~~~kih~~hi~",
      "~hi~~~~~~ih~~hi~",
      "~hi~~~~~~ih~~hi~",
      "~hl~~~~~mlh~~hl~",
      "~hi~~~~~~ihhhhi~",
      "~hi~~~~~~iiiiii~",
      "~hin~~~~~oppppq~",
      "~hir~~~~~oppppq~",
      "~hi~~~~~~iiiiii~",
      "~hi~~~~~~ihhhhi~",
      "~hl~~~~~slh~~hl~",
      "hhi~~~~~~ih~~hi~",
      "hi~~~~~~~ih~~hi~",
      "hi~~~~~~jih~~hi~",
      "i~~~~~~~kih~~hi~"
    ],
    [
      "~~~~~~~~~~~~~~~~",
      "~~~~~~~~~~~~~~~~",
      "~~~~~~~~~~~~~~~~",
      "~~~~~~~~~~~~~~~~",
      "~~t~~~~~~t~~~~~~",
      "~~~~~~~~~~~~~~~~",
      "~~~~~~~~~uiiiii~",
      "~~~~~~~~~~~~~~~~",
      "~~~~~~~~~~~~~~~~",
      "~~~~~~~~~iiiiii~",
      "~~~~~~~~~~~~~~~~",
      "~~~~~~~~st~~~~t~",
      "~~~~~~~~~~~~~~~~",
      "~~~~~~~~~~~~~~~~",
      "~~~~~~~~~~~~~~~~",
      "~~~~~~~~~~~~~~~~"
    ],
    [
      "~~~~~~~~~~~~~~~~",
      "~~~~~~~~~~~~~~~~",
      "~~~~~~~~~~~~~~~~",
      "~~~~~~~~~~~~~~~~",
      "~~~~~~~~~~~~~~~~",
      "~~~~~~~~~~~~~~~~",
      "~~~~~~~~~~~~~~~~",
      "~~~~~~~~~~~~~~~~",
      "~~~~~~~~~~~~~~~~",
      "~~~~~~~~~~~~~~~~",
      "~~~~~~~~u~~~~~~~",
      "~~~~~~~usu~~~~~~",
      "~~~~~~~~u~~~~~~~",
      "~~~~~~~~~~~~~~~~",
      "~~~~~~~~~~~~~~~~",
      "~~~~~~~~~~~~~~~~"
    ],
    [
      "~~~~~~~~~~~~~~~~",
      "~~~~~~~~~~~~~~~~",
      "~~~~~~~~~~~~~~~~",
      "~~~~~~~~~~~~~~~~",
      "~~~~~~~~~~~~~~~~",
      "~~~~~~~~~~~~~~~~",
      "~~~~~~~~~~~~~~~~",
      "~~~~~~~~~~~~~~~~",
      "~~~~~~~~~~~~~~~~",
      "~~~~~~~uuu~~~~~~",
      "~~~~~~uuuuu~~~~~",
      "~~~~~~uusuu~~~~~",
      "~~~~~~uuuuu~~~~~",
      "~~~~~~~uuu~~~~~~",
      "~~~~~~~~~~~~~~~~",
      "~~~~~~~~~~~~~~~~"
    ],
    [
      "~~~~~~~~~~~~~~~~",
      "~~~~~~~~~~~~~~~~",
      "~~~~~~~~~~~~~~~~",
      "~~~~~~~~~~~~~~~~",
      "~~~~~~~~~~~~~~~~",
      "~~~~~~~~~~~~~~~~",
      "~~~~~~~~~~~~~~~~",
      "~~~~~~~~~~~~~~~~",
      "~~~~~~~~~~~~~~~~",
      "~~~~~~~~~~~~~~~~",
      "~~~~~~~~u~~~~~~~",
      "~~~~~~~usu~~~~~~",
      "~~~~~~~~u~~~~~~~",
      "~~~~~~~~~~~~~~~~",
      "~~~~~~~~~~~~~~~~",
      "~~~~~~~~~~~~~~~~"
    ]
  ]
}