{
  "name": "multi_laboratory1_13_base5",
  "refpalette": "c70cities:multi_laboratory1_13_base5_palette",
  "xsize": 16,
  "zsize": 16,
  "slices": [
    [
      "             abz",
      "             cbz",
      "ddddefffffffffez",
      "    g         hz",
      "    g         hz",
      "    g         hz",
      "    g         hz",
      "    g         hz",
      "    g         hz",
      "   ie         jz",
      "    g    k    hz",
      "    g   klk   hz",
      "    g     l   hz",
      "    g     m   hz",
      "    g   mnm   hz",
      "    g   mom   hz"
    ],
    [
      "             abz",
      "             cbz",
      "ddddefffffffffez",
      "    g         hz",
      "    g         hz",
      "    g         hz",
      "    g         hz",
      "    g         hz",
      "    g         hz",
      "    e         jz",
      "    g         hz",
      "    g    p    hz",
      "    g         hz",
      "    g         hz",
      "    g         hz",
      "    g         hz"
    ],
    [
      "             abz",
      "             cbz",
      "ddddefffffffffez",
      "    g         hz",
      "    g         hz",
      "    g         hz",
      "    g         hz",
      "    g         hz",
      "    g         hz",
      "    e         jz",
      "    g         hz",
      "    g         hz",
      "    g         hz",
      "    g         hz",
      "    g         hz",
      "    g         hz"
    ],
    [
      "            qabz",
      "             cbz",
      "ddddefffffffffez",
      "    g         hz",
      "    g         hz",
      "    g         hz",
      "    g         hz",
      "    g         hz",
      "    g         hz",
      "    e         jz",
      "    g         hz",
      "    g         hz",
      "    g         hz",
      "    g         hz",
      "    g         hz",
      "    g         hz"
    ],
    [
      "            rabz",
      "             cbz",
      "ssssesssssssssez",
      "    t         hz",
      "    t         hz",
      "    t         hz",
      "    t         hz",
      "    t         hz",
      "    t         hz",
      "    e         jz",
      "    t         hz",
      "    t         hz",
      "    t         hz",
      "    t         hz",
      "    t         hz",
      "    t         hz"
    ],
    [
      "uuuuuuuuuuuuwabz",
      "uuuuuuuuuuuuwcbz",
      "xxxxexxxxxxxxxaz",
      "jjjjtjjjjjjjjjaz",
      "jjjjtjjjjjjjjjaz",
      "jjjjtjjyAyAAjjaz",
      "jjjjtjjyAyAAjjaz",
      "jjjjtjjjjjjjjjaz",
      "jjjjtjjjjjjjjjaz",
      "jjjjtjjjjjjjjjaz",
      "jjjjtjjjjjjjjjaz",
      "jjjjtjjjjjjjjjaz",
      "jjjjtjjyyyAyjjaz",
      "jjjjtjjyyyAyjjaz",
      "jjjjtjjjjjjjjjaz",
      "jjjjtjjjjjjjjjaz"
    ]
  ]
}