{
  "name": "multi_communitycenter_0_base1",
  "refpalette": "c70cities:multi_communitycenter_0_base1_palette",
  "xsize": 16,
  "zsize": 16,
  "slices": [
    [
      "vvvvvvvvvvvvvvvv",
      "vHHHHHHHHHHHHHHH",
      "vHHHHHHHHHHHHHHH",
      "vHHHHHHHHHHHHHHH",
      "vHHHHHHHHHHHHHHH",
      "vHHHHHHHHHHHHHHH",
      "vHHHHHHHHHHHHHHH",
      "vHHHHHHHHHHHHHaH",
      "vHHHHHHHHHHHHHHH",
      "vHHHHHHHHHHHHHHH",
      "vHHHHHHHHHHHHHHH",
      "vHHHHHHHHHHHHHHH",
      "vHHHHHHHHHHHHHHH",
      "vHHHHHHHHHHHHHHH",
      "vHHHHHHHHHHHHHHH",
      "vHHHHHHHHHHHHHHH"
    ],
    [
      "vvvvvvvvvvvvvvvv",
      "vbbbbbbbbbbbbbbb",
      "vbbbbbbbbbbbbbbb",
      "vbbbbbbbbbbbbbbb",
      "vbbbbbbbbbbbbbbb",
      "vbbbbbbbbbbbbbbb",
      "vbbbb cdcd cdcd ",
      "vbbbb           ",
      "vbbbbefgfgefgfge",
      "vbbbb           ",
      "vbbbb           ",
      "vbbbb           ",
      "vbbbb           ",
      "vbbbb           ",
      "vbbbb           ",
      "vbbbbecdcde    e"
    ],
    [
      "vvvvvvvvvvvvvvvv",
      "vbbbbbbbbbbbbbbb",
      "vbbbbbbbbbbbbbbb",
      "vbbbbbbbbbbbbbbb",
      "vbbbbbbbbbbbbbbb",
      "vbbbbbbbbbbbbbbb",
      "vbbbb           ",
      "vbbbb           ",
      "vbbbbe    e    e",
      "vbbbb           ",
      "vbbbb           ",
      "vbbbb           ",
      "vbbbb           ",
      "vbbbb           ",
      "vbbbb           ",
      "vbbbbe    e    e"
    ],
    [
      "vvvvvvvvvvvvvvvv",
      "vbbbbbbbbbbbbbbb",
      "vbbbbbbbbbbbbbbb",
      "vbbbbbbbbbbbbbbb",
      "vbbbbbbbbbbbbbbb",
      "vbbbbbbbbbbbbbbb",
      "vbbbb!          ",
      "vbbbb           ",
      "vbbbbe    e    e",
      "vbbbb           ",
      "vbbbb           ",
      "vbbbb           ",
      "vbbbb           ",
      "vbbbb           ",
      "vbbbb           ",
      "vbbbbe    e    e"
    ],
    [
      "vvvvvvvvvvvvvvvv",
      "vbbbbbbbbbbbbbbb",
      "vbbbbbbbbbbbbbbb",
      "vbbbbbbbbbbbbbbb",
      "vbbbbbbbbbbbbbbb",
      "vbbbbbbbbbbbbbbb",
      "vbbbbe    e    e",
      "vbbbbe    e    e",
      "vbbbbehhhhehhhhe",
      "vbbbbe    e    e",
      "vbbbbe    e    e",
      "vbbbbe    e    e",
      "vbbbbe    e    e",
      "vbbbbe    e    e",
      "vbbbbe    e    e",
      "vbbbbehhhhehhhhe"
    ],
    [
      "vvvvvvvvvvvvvvvv",
      "vbbbbbbbbbbbbbbb",
      "vbbbbbbbbbbbbbbb",
      "vbbbbbbbbbbbbbbb",
      "vbbbbbbbbbbbbbbb",
      "vbbbbbbbbbbbbbbb",
      "vbbbbbbbbbbbbbbb",
      "vbbbbbbbbbbbbbbb",
      "vbbbbbbbbbbbbbbb",
      "vbbbbbbbbbbbbbbb",
      "vbbbbbbbbbbbbbbb",
      "vbbbbbbbbbbbbbbb",
      "vbbbbbbbbbbbbbbb",
      "vbbbbbbbbbbbbbbb",
      "vbbbbbbbbbbbbbbb",
      "vbbbbbbbbbbbbbbb"
    ]
  ]
}