{
  "name": "multi_laboratory1_10_base4",
  "refpalette": "c70cities:multi_laboratory1_10_base4_palette",
  "xsize": 16,
  "zsize": 16,
  "slices": [
    [
      "vvvvvvvvvvvvvvvv",
      "aaaaaaaaaaaaaaav",
      "bbbbccccccccccav",
      "    d========cav",
      "  e d========cav",
      "ddddd========cav",
      "    d========cav",
      "    d========cav",
      "    d========cav",
      "    d========cav",
      "    d========cav",
      " f  d========cav",
      " fggd========cav",
      "hhhhd========cav",
      "hhhhd========cav",
      "dddddiiiiiiiicav"
    ],
    [
      "vvvvvvvvvvvvvvvv",
      "aaaaaaaaaaaaaaav",
      "bbbbbbbbbbbbbcav",
      "  jklmnooo pqbav",
      "   klr      sbav",
      "lllldtu     wbav",
      "    lx      qbav",
      "    ly AAA  sbav",
      "    ly BCB  xbav",
      "    lw BCB pqbav",
      "    lD BCB  Ebav",
      "hh  lF CsC wxbav",
      "ggI l   J    bav",
      "    l       Kbav",
      "    L       Kbav",
      "Mllldllllllllcav"
    ],
    [
      "vvvvvvvvvvvvvvvv",
      "aaaaaaaaaaaaaaav",
      "bbbbbbbbbbbbbcav",
      " j  l!     pqbav",
      "    l       Ebav",
      "lllldt      xbav",
      "    lx     pqbav",
      "    lx AAA  sbav",
      "    l  NNN  xbav",
      "hh  l  NNO  qbav",
      "ggI l  NNN  sbav",
      "  I l  sss  xbav",
      "    l   P    bav",
      "    l        bav",
      "    Q       Rbav",
      "Sllldllllllllcav"
    ],
    [
      "vvvvvvvvvvvvvvvv",
      "aaaaaaaaaaaaaaav",
      "bbbbbbbbbbbbbcav",
      "j   l       tbav",
      "    l       sbav",
      "lllldt      xbav",
      "hhhhlx      tbav",
      "hhhhl  AAA  sbav",
      "ggI l   N   xbav",
      "  I l  NNN  tbav",
      "    l   N   sbav",
      "    l       xbav",
      "    l        bav",
      "    l        bav",
      "T   l       Ubav",
      "Vllldllllllllcav"
    ],
    [
      "vvvvvvvvvvvvvvvv",
      "aaaaaaaaaaaaaaav",
      "bbbbbbbbbbbbbcav",
      "    lt      Wbav",
      "e   lt      tbav",
      "lllldt      tbav",
      "    lt      Wbav",
      "    lXY     tbav",
      " fgglXY     tbav",
      "  hhlXY     Wbav",
      "    lXY     tbav",
      "    lt      tbav",
      "    lttttttttbav",
      "    l       tbav",
      "    l       tbav",
      "lllldllllllllcav"
    ],
    [
      "vvvvvvvvvvvvvvvv",
      "aaaaaaaaaaaaaaav",
      "bbbbbbbbbbbbbcav",
      "    lZZZZZZZZbav",
      " e  lZZZZZZZZbav",
      "lllldZZZZZZZZbav",
      "    lZZZZZZZZbav",
      "    lZZZZZZZZbav",
      "    lZZZZZZZZbav",
      " f  lZZZZZZZZbav",
      " fgglZZZZZZZZbav",
      "  hhlZZZZZZZZbav",
      "    lZZZZZZZZbav",
      "    lZZZZZZZZbav",
      "    lZZZZZZZZbav",
      "lllldllllllllcav"
    ]
  ]
}