{
  "name": "multi_megatower1_2_ground",
  "refpalette": "c70cities:multi_megatower1_2_ground_palette",
  "xsize": 16,
  "zsize": 16,
  "slices": [
    [
      "HHHvvHHHHHHHHHHv",
      "HHHvvHHHHHHHHHHH",
      "HHHvvHaHHHHHHaHH",
      "HHHvvHHHHHHHHHHH",
      "HHHvvHHHHHHHHHHH",
      "HHHvvHHHHHHHHHHH",
      "HHHvvHHHHHHHHHHH",
      "HHHvvHHHHHHHHHHH",
      "HHHvvHHHHHHHHHHH",
      "HHHvvHaHHHHHHaHH",
      "HHHvvHHHHHHHHHHH",
      "HHHvvvvvvvvvvvvv",
      "HHHvvvvvvvvvvvvv",
      "HHHGGGbGGGGGGbGG",
      "HHHGbGbbGGbbbGbG",
      "HHHGGGGGbGGGbbGG"
    ],
    [
      "   cde f    g hi",
      "   cdg h      ef",
      "  jkd al    ja  ",
      "   cde f     mgh",
      "   cdg h        ",
      "   cde f        ",
      "   cdg h        ",
      "   cdnnn        ",
      "   cd   oefefpef",
      "  jkd a o q  a  ",
      "   cd   oghgh gh",
      "   cdddddddddddd",
      "   ccckcccccckcc",
      "   rrs rsrrsr sr",
      "                ",
      "                "
    ],
    [
      "   c            ",
      "   c            ",
      "   k  a      a  ",
      "   c            ",
      "   c            ",
      "   c            ",
      "   c            ",
      "   c            ",
      "   c            ",
      "   k  a      a  ",
      "   c            ",
      "   c            ",
      "   ccckcccccckcc",
      "                ",
      "                ",
      "                "
    ],
    [
      "   c            ",
      "   c            ",
      "   k  a      a  ",
      "   c            ",
      "   c            ",
      "   c            ",
      "   c            ",
      "   c            ",
      "   c            ",
      "   k  a      a  ",
      "   c            ",
      "   c            ",
      "   ccckcccccckcc",
      "      t      t  ",
      "                ",
      "                "
    ],
    [
      "   c            ",
      "   c            ",
      "   k  a      a  ",
      "   c            ",
      "   c            ",
      "   c            ",
      "   c            ",
      "   c            ",
      "   c            ",
      "   k  a      a  ",
      "   c            ",
      "   c            ",
      "   ccckcccccckcc",
      "                ",
      "                ",
      "                "
    ],
    [
      "   cuuauuuuuuauu",
      "   cuuauuuuuuauu",
      "  ukaaaaaaaaaaaa",
      "  uiuuauuuuuuauu",
      "  uiuuauuuuuuauu",
      "  uiuuauuuuuuauu",
      "  uiuuauuuuuuauu",
      "  uiuuauuuuuuauu",
      "  uiuuauuuuuuauu",
      "  ukaaaaaaaaaaaa",
      "   cuuauuuuuuauu",
      "   cuuauuuuuuauu",
      "   ccckcccccckcc",
      "                ",
      "                ",
      "                "
    ]
  ]
}