{
  "name": "multi_condo1_2_floor6",
  "refpalette": "c70cities:multi_condo1_2_floor6_palette",
  "xsize": 16,
  "zsize": 16,
  "slices": [
    [
      "   abcccdddeffff",
      "   abcccdddddddd",
      " gggbcccdddddddd",
      "  hibcccdddddddd",
      "  hibcccdddddddd",
      "  hibcccdddddddd",
      "  hibcccdddddddd",
      "  hibcccdddddddd",
      "  hibcccdddddddd",
      "  hibddddddddddd",
      "  hibddddddddddd",
      "  hibbbbbbbbdddd",
      "  hiiiiiiigggggg",
      "  hhhhhhhhgggggg",
      "          gggggg",
      "                "
    ],
    [
      "    j  k        ",
      "    bbbblbbbmmmm",
      " gggbnob pbqr ss",
      "   ib  k tb uw  ",
      "   ibbbb tbqr   ",
      "   ib! k tbq    ",
      "   ibbbb tbx  y ",
      "   ib  k pbx  s ",
      "   ibbbb bbb  A ",
      "   ib           ",
      "   ibBC BCD     ",
      "   ibbEEEbbb    ",
      "   iiiiiiig     ",
      "          gFFFFF",
      "          g     ",
      "                "
    ],
    [
      "    F  I        ",
      "    bbbbJbbbmmmm",
      " gggb  b  b K   ",
      "    bL I  bMN   ",
      "    bbbb  b K   ",
      "    bL I  bM    ",
      "    bbbb  bx    ",
      "    bL I Obx    ",
      "    bbbb bbbM P ",
      "    b           ",
      "    b     Q     ",
      "    bbmmmbbb    ",
      "          g     ",
      "          g     ",
      "          g     ",
      "                "
    ],
    [
      "    F  b        ",
      "    bbbbRbbbmmmm",
      " gggb  b  b     ",
      "    bS b  b     ",
      "    bbbb !b     ",
      "    bS b  b     ",
      "    bbbb  bx    ",
      "    bS b  bx    ",
      "    bbbbTbbb    ",
      "    b           ",
      "    b           ",
      "    bbmmmbbb    ",
      "          g     ",
      "          g     ",
      "          g     ",
      "                "
    ],
    [
      "    b  b        ",
      "    bbbbbbbbmmmm",
      " gggb  b  b     ",
      "   Ub  b  b     ",
      "   Ubbbb  b     ",
      "   Ub  b  b     ",
      "   Ubbbb  b     ",
      "   Ub  b  b     ",
      "   Ubbbbbbbbmmmm",
      "   Ub           ",
      "   Ub           ",
      "   Ubbbbbbbbbbbb",
      "   UUUUUUUg     ",
      "          g     ",
      "          g     ",
      "                "
    ],
    [
      "    bVVbWWW     ",
      "    bbbbbbbbRRRR",
      " gggbVVbVVbfffff",
      "   XbVVbVVbfffff",
      "   XbbbbVVbfffff",
      "   XbVVbVVbfffff",
      "   XbbbbVVbfffff",
      "   XbVVbVVbfffff",
      "   XbbbbbbbbTTTT",
      "   Xbfffffffffff",
      "   Xbfffffffffff",
      "   Xbbbbbbbbbbbb",
      "   XXXXXXXg     ",
      "          gYYYYY",
      "          g     ",
      "                "
    ]
  ]
}