{
  "name": "multi_laboratory1_2_base1",
  "refpalette": "c70cities:multi_laboratory1_2_base1_palette",
  "xsize": 16,
  "zsize": 16,
  "slices": [
    [
      "zabcccccccccccd ",
      "zabcccccccccccd ",
      "zabcccccccccccd ",
      "zabcccccccccccde",
      "zabccccccccfcc!d",
      "zabccccccccccccd",
      "zabccccccccccccc",
      "zabccccccccccccc",
      "zabccccccccccccc",
      "zabccccccccccccc",
      "zabccccccccccccc",
      "zabccccccccfcccc",
      "zabccccccccccccc",
      "zabccccccccccccc",
      "zabccccccccccccc",
      "zabccccccccccccc"
    ],
    [
      "zabg      hi  j ",
      "zabk      hi  j ",
      "zabk    lmhi  j ",
      "zabnopo qrhi  js",
      "zabiiiitiiif  sj",
      "zabuuu l wwx   j",
      "zabuu      x  y ",
      "zabAABC C  x    ",
      "zabA  qDq  x    ",
      "zabEB FIF  x    ",
      "zabk  C C  x    ",
      "zabkJ      fs   ",
      "zabg  C C  K    ",
      "zabg  qrq  K    ",
      "zabL  FMF  N    ",
      "zabOC C C  K    "
    ],
    [
      "zabP       x  j ",
      "zab       Qx  j ",
      "zab        x  j ",
      "zab! p  RS x  js",
      "zabiiiiTiiif  Uj",
      "zab!uQ     x   j",
      "zabEl      x    ",
      "zabA       x    ",
      "zab   B    x    ",
      "zab     J  x    ",
      "zab        x    ",
      "zab        fU   ",
      "zabV       K    ",
      "zabW   Q   K    ",
      "zabX  l    Y    ",
      "zabZ       K    "
    ],
    [
      "zabA       x  j ",
      "zab        x  j ",
      "zab        x  j ",
      "zab0122    x  js",
      "zabiiiiiiiif  Uj",
      "zabE     32x   j",
      "zab        x    ",
      "zab4       x    ",
      "zab        x    ",
      "zab        x    ",
      "zab        x    ",
      "zab        fU   ",
      "zab        K    ",
      "zab        K    ",
      "zab5       K    ",
      "zab6       K    "
    ],
    [
      "zab        x  j ",
      "zab        x  j ",
      "zab        x  j ",
      "zabn       x  js",
      "zabiiiiiiiif   j",
      "zab        x   j",
      "zab        x    ",
      "zab        x    ",
      "zab        x    ",
      "zab        x    ",
      "zab        x    ",
      "zab        f    ",
      "zab        K    ",
      "zab        K    ",
      "zab        K    ",
      "zab        K    "
    ],
    [
      "zab77877787977@ ",
      "zab77877787977@ ",
      "zab77877787977@ ",
      "zabn7777777977@#",
      "zabiiii$iiif777@",
      "zab777777779777@",
      "zab7787778797777",
      "zab7787778797777",
      "zab7787778797777",
      "zab7787778797777",
      "zab7777777797777",
      "zab77777777f7777",
      "zab7777777797777",
      "zab7787778797777",
      "zab7787778797777",
      "zab7787778797777"
    ]
  ]
}