{
  "name": "multi_clubhouse1_7_base1",
  "refpalette": "c70cities:multi_clubhouse1_7_base1_palette",
  "xsize": 16,
  "zsize": 16,
  "slices": [
    [
      "  ab    ba    cv",
      "  ab    ba     v",
      "  ab    ba    cv",
      "  abbbbbba    dv",
      "  aaaaaaaa    ev",
      "  abbbbbba    cv",
      "  ab    ba     v",
      "  ab    ba    dv",
      "  ab    ba     v",
      "  ab    ba    cv",
      "  abbbbbba     v",
      "  aaaaaaaa    ev",
      "  abbbbbba     v",
      "  ab    ba     v",
      "  ab    ba    dv",
      "  ab    ba     v"
    ],
    [
      " fghhhhhhg    cv",
      " fghhhhhhg     v",
      " fghhhhhhg     v",
      " fghhhhhhg    dv",
      " fghhhhhhg    ev",
      " fghhhhhhg    cv",
      " fghhhhhhg     v",
      " fghhhhhhg     v",
      " fghhhhhhg     v",
      " fghhhhhhg    cv",
      " fghhhhhhg     v",
      " fghhhhhhg    ev",
      "fgghhhhhhg     v",
      "fghhhhhhhg     v",
      "gghhhhhhhg     v",
      "ghhhhhhhhg     v"
    ],
    [
      "  i      j    cv",
      "  i  kkk j     v",
      "  i lmmmnj     v",
      "  i lmmmnj    cv",
      "  o  ppp e    ev",
      "  i      j    cv",
      "  i  kkk j     v",
      "  i lmmmnj     v",
      "  i lmmmnj     v",
      "  i  ppp j     v",
      "  i      j     v",
      "  o  kkk e    ev",
      " ii lmmmnj     v",
      " i  lmmmnj     v",
      "ii   ppp j     v",
      "i        j     v"
    ],
    [
      "  i            v",
      "  i            v",
      "  i            v",
      "  i           cv",
      "  o      e    ev",
      "  i            v",
      "  i            v",
      "  i            v",
      "  i            v",
      "  i            v",
      "  i            v",
      "  o      e    ev",
      " ii            v",
      " i             v",
      "ii             v",
      "i              v"
    ],
    [
      "  i            v",
      "  i            v",
      "  i            v",
      "  i            v",
      "  o      e    ev",
      "  i            v",
      "  i            v",
      "  i            v",
      "  i            v",
      "  i            v",
      "  i            v",
      "  o      e    ev",
      " ii            v",
      " i             v",
      "ii             v",
      "i              v"
    ],
    [
      "  ibbbbbb      v",
      "  ibbbbbb      v",
      "  ibbbbbb      v",
      "  ibbbbbb      v",
      "  obqbbqbe    ev",
      "  ibbbbbb      v",
      "  ibbbbbb      v",
      "  ibbbbbb      v",
      "  ibbbbbb      v",
      "  ibbbbbb      v",
      "  ibbbbbb      v",
      "  obqbbqbe    ev",
      " iibbbbbb      v",
      " ibbbbbbb      v",
      "iibbbbbbb      v",
      "ibbbbbbbb      v"
    ]
  ]
}