{
  "name": "multi_flatapartment_2_floor2",
  "refpalette": "c70cities:multi_flatapartment_2_floor2_palette",
  "xsize": 16,
  "zsize": 16,
  "slices": [
    [
      "                ",
      "abbbbabbbabbbba ",
      "ccccccccccccccb ",
      "dddddddddddddcb ",
      "dddddddddddddcb ",
      "dddddddddddddca ",
      "dddddddddddddcb ",
      "dddddddddddddcb ",
      "dddddddddddddcb ",
      "dddddddddddddcb ",
      "dddddddddddddca ",
      "dddddddddddddcb ",
      "dddddddddddddcb ",
      "ccccccccccccccb ",
      "abbbbabbbabbbba ",
      "                "
    ],
    [
      "                ",
      "abeebabebabeeba ",
      "         f    b ",
      " g g hii h    e ",
      " jjj h   h kl b ",
      "hhhhhh   hhhhha ",
      "hm  nhoo p    b ",
      "hm  nhhhhh    e ",
      "h    q  rh ss e ",
      "hg g h tuhwxxyb ",
      "hjjj h tuhhhhha ",
      "ABCC h   f DE b ",
      "     hhhhh    e ",
      "         F    b ",
      "abeebabebabeeba ",
      "                "
    ],
    [
      "                ",
      "abIIbabIbabIIba ",
      "         J    b ",
      "     h   h    I ",
      "     h   h  K b ",
      "hhhhhh   hhhhha ",
      "hL   hLL M    b ",
      "hL   hhhhh    I ",
      "h    N   h    I ",
      "h    h   h    b ",
      "h    h   hhhhha ",
      "     h   J  O b ",
      "     hhhhh    I ",
      "         P    b ",
      "abIIbabIbabIIba ",
      "                "
    ],
    [
      "                ",
      "abIIbabIbabIIba ",
      "         h    b ",
      "     h   h    I ",
      "     h   h    b ",
      "hhhhhh   hhhhha ",
      "hL   hLL h    b ",
      "hL   hhhhh    I ",
      "h    h   h    I ",
      "h    h   h    b ",
      "h    h   hhhhha ",
      "     h   h    b ",
      "     hhhhh    I ",
      "         h    b ",
      "abIIbabIbabIIba ",
      "                "
    ],
    [
      "                ",
      "abbbbabbbabbbba ",
      "h    h   hQQQQb ",
      "h    h   hQQQQb ",
      "h    h R hQQQQb ",
      "hhhhhh   hhhhha ",
      "h    h   h    b ",
      "h  S hhhhh    b ",
      "h    h   h    b ",
      "h    h   h    b ",
      "h    h   hhhhha ",
      "h    h   hQQQQb ",
      "h    hhhhhQQQQb ",
      "h    h   hQQQQb ",
      "abbbbabbbabbbba ",
      "                "
    ],
    [
      "                ",
      "TUUUUTUUUTUUUUT ",
      "ccccccccccccccU ",
      "dddddddddddddcU ",
      "dddddddddddddcU ",
      "dddddddddddddcT ",
      "dddddddddddddcU ",
      "dddddddddddddcU ",
      "dddddddddddddcU ",
      "dddddddddddddcU ",
      "dddddddddddddcT ",
      "dddddddddddddcU ",
      "dddddddddddddcU ",
      "ccccccccccccccU ",
      "TUUUUTUUUTUUUUT ",
      "                "
    ]
  ]
}