{
  "name": "multi_clubhouse1_8_ground",
  "refpalette": "c70cities:multi_clubhouse1_8_ground_palette",
  "xsize": 16,
  "zsize": 16,
  "slices": [
    [
      "aaaabbabacddddcG",
      "abaabaaaacddddcG",
      "aabaabaaGceeeecG",
      "babbbaaaacddddcG",
      "ababaabaacddddcG",
      "baaaaaaafcddddcG",
      "aaabaaaagcddddcG",
      "aaaaaaahhcddddcG",
      "aaGaaghghcddddcG",
      "cccccccccceeeecG",
      "ddeddddddeddddcG",
      "ddeddddddeddddcG",
      "ddeddddddeddddcG",
      "ddeddddddeddddcG",
      "cccccccccccccccG",
      "GGGGGGGGGGGGGGGG"
    ],
    [
      "~~~~~~~~~ij~~ji~",
      "~~~~~~~~~ij~~ji~",
      "~~~~~~~~klj~~jl~",
      "~~~~~~~~~ij~~ji~",
      "~~~~~~~~~ij~~ji~",
      "~~~~~~~~~ij~~ji~",
      "~~~~~~~~~ij~~ji~",
      "~~~~~~~~~ij~~ji~",
      "~~k~~~~~~ij~~ji~",
      "iiliiiiiilj~~jl~",
      "jjjjjjjjjjj~~ji~",
      "~~~~~~~~~~~~~ji~",
      "~~~~~~~~~~~~~ji~",
      "jjjjjjjjjjjjjji~",
      "iiliiiiiiliiiii~",
      "~~~~~~~~~~~~~~~~"
    ],
    [
      "~~~~~~~~~~~~~~~~",
      "~~~~~~~~~~~~~~~~",
      "~~~~~~~~~~~~~~m~",
      "~~~~~~~~~~~~~~~~",
      "~~~~~~~~~~~~~~~~",
      "~~~~~~~~~~~~~~~~",
      "~~~~~~~~~~~~~~~~",
      "~~~~~~~~~~~~~~~~",
      "~~~~~~~~~~~~~~~~",
      "~~m~~~~~~m~~~~~~",
      "~~~~~~~~~~~~~~~~",
      "~~~~~~~~~~~~~~~~",
      "~~~~~~~~~~~~~~~~",
      "~~~~~~~~~~~~~~~~",
      "~~~~~~~~~~~~~~~~",
      "~~~~~~~~~~~~~~~~"
    ],
    [
      "~~~~~~~~~~~~~~~~",
      "~~~~~~~~~~~~~~~~",
      "~~~~~~~~~~~~~~~~",
      "~~~~~~~~~~~~~~~~",
      "~~~~~~~~~~~~~~~~",
      "~~~~~~~~~~~~~~~~",
      "~~~~~~~~~~~~~~~~",
      "~~~~~~~~~~~~~~~~",
      "~~~~~~~~~~~~~~~~",
      "~~~~~~~~~~~~~~~~",
      "~~~~~~~~~~~~~~~~",
      "~~~~~~~~~~~~~~~~",
      "~~~~~~~~~~~~~~~~",
      "~~~~~~~~~~~~~~~~",
      "~~~~~~~~~~~~~~~~",
      "~~~~~~~~~~~~~~~~"
    ],
    [
      "~~~~~~~~~~~~~~~~",
      "~~~~~~~~~~~~~~~~",
      "~~~~~~~~~~~~~~~~",
      "~~~~~~~~~~~~~~~~",
      "~~~~~~~~~~~~~~~~",
      "~~~~~~~~~~~~~~~~",
      "~~~~~~~~~~~~~~~~",
      "~~~~~~~~~~~~~~~~",
      "~~~~~~~~~~~~~~~~",
      "~~~~~~~~~~~~~~~~",
      "~~~~~~~~~~~~~~~~",
      "~~~~~~~~~~~~~~~~",
      "~~~~~~~~~~~~~~~~",
      "~~~~~~~~~~~~~~~~",
      "~~~~~~~~~~~~~~~~",
      "~~~~~~~~~~~~~~~~"
    ],
    [
      "~~~~~~~~~~~~~~~~",
      "~~~~~~~~~~~~~~~~",
      "~~~~~~~~~~~~~~~~",
      "~~~~~~~~~~~~~~~~",
      "~~~~~~~~~~~~~~~~",
      "~~~~~~~~~~~~~~~~",
      "~~~~~~~~~~~~~~~~",
      "~~~~~~~~~~~~~~~~",
      "~~~~~~~~~~~~~~~~",
      "~~~~~~~~~~~~~~~~",
      "~~~~~~~~~~~~~~~~",
      "~~~~~~~~~~~~~~~~",
      "~~~~~~~~~~~~~~~~",
      "~~~~~~~~~~~~~~~~",
      "~~~~~~~~~~~~~~~~",
      "~~~~~~~~~~~~~~~~"
    ]
  ]
}