{
  "name": "multi_condo1_0_ground",
  "refpalette": "c70cities:multi_condo1_0_ground_palette",
  "xsize": 16,
  "zsize": 16,
  "slices": [
    [
      "GGGGGGGGGGGGGGGG",
      "GGGGGGGGGGGGGGGG",
      "GGGGaaaaaaaaaaaa",
      "GGGGabbbbbabbbbb",
      "GGGGaaaaaaabbbbb",
      "GGGGabbbbbbbbbbb",
      "GGGGabbbbbbbbbbb",
      "GGGGabbbbbbbbbbb",
      "GGGGabbbbbbbbbbb",
      "GGGGabbbbbbbbbbb",
      "GGccabbbbbbbbbbb",
      "GGGbabbbbbbbbbbb",
      "GGGbabbbbbbbbbbb",
      "Gdddabbbbbbbbbbb",
      "GGGbabbbbbbbbbbb",
      "GGGbabbbbbbbbbbb"
    ],
    [
      "                ",
      "                ",
      "  e aaaaaaaaaaaa",
      "    afffffafffff",
      "  e aaaaaaaaaaaa",
      "    aghijkhljghi",
      "  e amhijkhnjmhi",
      "    a   j   j   ",
      "  e a           ",
      "    a   oho  o  ",
      "  ccapq  o  oho ",
      "    ar          ",
      "    arq   s s q ",
      " dddap    tuuut ",
      "    abw  wbwwwww",
      "    xy    ABCCD "
    ],
    [
      "                ",
      "                ",
      "  E             ",
      "          a     ",
      "  E FFFFFFaFFFFF",
      "    F   j   j I ",
      "  E F   j I j   ",
      "    F   j   j   ",
      "  E F           ",
      "    F           ",
      "  cca        J  ",
      "    a           ",
      "    aJ          ",
      " ddda          K",
      "    abL  LbLLLLL",
      "    M     E     "
    ],
    [
      "                ",
      "                ",
      "  L             ",
      "          a     ",
      "  L FFFFFFaFFFFF",
      "    F           ",
      "  L F           ",
      "    F           ",
      "  L F           ",
      "    F           ",
      "  cca           ",
      "    a           ",
      "    a           ",
      " ddda         K ",
      "    ab    b     ",
      "    M           "
    ],
    [
      "                ",
      "                ",
      "  L             ",
      "          a     ",
      "  L FFFFFFaFFFFF",
      "    F           ",
      "  L F     N     ",
      "    F           ",
      "  L F           ",
      "    F           ",
      "  cca           ",
      "    a           ",
      "    aO    N     ",
      " ddda        K  ",
      "    ab    b     ",
      "    a           "
    ],
    [
      "                ",
      "                ",
      "  P             ",
      "          a     ",
      "  P FFFFFFaFFFFF",
      "    F           ",
      "  P F     Q     ",
      "    F           ",
      "  P F           ",
      "    F           ",
      "  cca           ",
      "    a           ",
      "    aR    Q     ",
      " ddda       K   ",
      "    ab    b     ",
      "    a           "
    ]
  ]
}