{
  "name": "multi_condo1_0_floor6",
  "refpalette": "c70cities:multi_condo1_0_floor6_palette",
  "xsize": 16,
  "zsize": 16,
  "slices": [
    [
      "                ",
      "          a     ",
      "  bbbbbbbbaccccc",
      "  bdddddddaeeeee",
      "  bdffffffgggggg",
      "  bdfggggggggggg",
      "  bdfggggggggggg",
      "  bdfggggggggggg",
      "  bdfggggggggggg",
      "  bdfggggggggggg",
      "  bdfggggggggggg",
      "  bdfggggggggggg",
      "  bdfggggggggggg",
      " aaafggggggggggg",
      "   hfggggggggggg",
      "   hfggggggijjjj"
    ],
    [
      "                ",
      "          a     ",
      "          accccc",
      "   ddddddda     ",
      "   dffkkkfff    ",
      "   dfl    fm no ",
      "   dfp    q     ",
      "   dfp r  ff    ",
      "   dfp    s  tt ",
      "   dfl    suwxxy",
      "   dfp    s wxxy",
      "   dfp r  s wxxy",
      "   dfp    suwxxy",
      " aaafl   As  BB ",
      "    ffffCfff    ",
      "    D           "
    ],
    [
      "                ",
      "          a     ",
      "          a     ",
      "          a     ",
      "    ffEEEfff    ",
      "    fF    fI    ",
      "    fJ    K     ",
      "    fL    ff    ",
      "    f     s     ",
      "    fF    s     ",
      "    fJ    s     ",
      "    fL    s     ",
      "    f     s     ",
      " aaafF    s     ",
      "    ffffMfff    ",
      "    c           "
    ],
    [
      "                ",
      "          a     ",
      "          a     ",
      "          a     ",
      "    ffEEEfff    ",
      "    fF    f     ",
      "    fN    O     ",
      "    fN    ff    ",
      "    fN    P     ",
      "    fF    P     ",
      "    fN    P     ",
      "    fN    P     ",
      "    fN    P     ",
      " aaafF    P     ",
      "    ffffQfff    ",
      "    c           "
    ],
    [
      "                ",
      "          a     ",
      "          a     ",
      "   RRRRRRRa     ",
      "   Rffffffffffff",
      "   RfF    f     ",
      "   RfF    f     ",
      "   RfF    ffEEEE",
      "   RfF          ",
      "   RfF          ",
      "   RfF          ",
      "   RfF          ",
      "   RfF          ",
      " aaafF          ",
      "    ffffffffEEEE",
      "    f           "
    ],
    [
      "                ",
      "          a     ",
      "          aSSSSS",
      "   TTTTTTTa     ",
      "   Tffffffffffff",
      "   TfUijjjf     ",
      "   TfVijjjf     ",
      "   TfWijjjffXXXX",
      "   TfYijjjjjjjjj",
      "   TfZijj000jj0j",
      "   Tf1ijj0j0j0j0",
      "   Tf2ijjj0jjj0j",
      "   Tf3ijjjjjjjjj",
      " aaafUijjjjjjjjj",
      "    ffffffffQQQQ",
      "    f444444     "
    ]
  ]
}