{
  "name": "multi_gallery_3_top",
  "refpalette": "c70cities:multi_gallery_3_top_palette",
  "xsize": 16,
  "zsize": 16,
  "slices": [
    [
      "                ",
      "                ",
      "                ",
      "a               ",
      "b           v   ",
      "b               ",
      "b               ",
      "b               ",
      "b               ",
      "b               ",
      "b               ",
      "b               ",
      "b               ",
      "b           v   ",
      "a               ",
      "                "
    ],
    [
      "                ",
      "                ",
      "                ",
      "ccaaaaaaaaaaaaa ",
      "cdbbbbbbbbbbvaa ",
      "cdbbbbbbbbbbeaa ",
      "cdbbbbbbbbbbbaa ",
      "cdbbbbbbbbbbbaa ",
      "cdbbbbbbbbbbbaa ",
      "cdbbbbbbbbbbbaa ",
      "cdbbbbbbbbbbbaa ",
      "cdbbbbbbbbbbbaa ",
      "cdbbbbbbbbbbeaa ",
      "cdbbbbbbbbbbvaa ",
      "ccaaaaaaaaaaaaa ",
      "                "
    ],
    [
      "                ",
      "                ",
      "                ",
      " ffffffffffffff ",
      " ffffffffffffff ",
      " ffffffffffffff ",
      " ffffffffffffff ",
      " ffffffffffffff ",
      " ffffffffffffff ",
      " ffffffffffffff ",
      " ffffffffffffff ",
      " ffffffffffffff ",
      " ffffffffffffff ",
      " ffffffffffffff ",
      " ffffffffffffff ",
      "                "
    ],
    [
      "                ",
      "                ",
      "                ",
      "                ",
      "                ",
      "                ",
      "                ",
      "                ",
      "                ",
      "                ",
      "                ",
      "                ",
      "                ",
      "                ",
      "                ",
      "                "
    ],
    [
      "                ",
      "                ",
      "                ",
      "                ",
      "                ",
      "                ",
      "                ",
      "                ",
      "                ",
      "                ",
      "                ",
      "                ",
      "                ",
      "                ",
      "                ",
      "                "
    ],
    [
      "                ",
      "                ",
      "                ",
      "                ",
      "                ",
      "                ",
      "                ",
      "                ",
      "                ",
      "                ",
      "                ",
      "                ",
      "                ",
      "                ",
      "                ",
      "                "
    ]
  ]
}