{
  "name": "multi_laboratory1_10_base3",
  "refpalette": "c70cities:multi_laboratory1_10_base3_palette",
  "xsize": 16,
  "zsize": 16,
  "slices": [
    [
      "zzzzzzzzzzzzzzzz",
      "aaaaaaaaaaaaaaaz",
      "bbbbbbbbbbbbbcaz",
      "    d========caz",
      "  e d========caz",
      "ddddd========caz",
      "    d========caz",
      "    d========caz",
      "    d========caz",
      "    d========caz",
      "    d========caz",
      " f  d========caz",
      " fggd========caz",
      "hhhhd========caz",
      "hhhhd========caz",
      "dddddiiiiiiiicaz"
    ],
    [
      "zzzzzzzzzzzzzzzz",
      "aaaaaaaaaaaaaaaz",
      "bbbbbbbbbbbbbcaz",
      "  jklmn    opbaz",
      "   klq      rbaz",
      "lllldst     ubaz",
      "    lw      pbaz",
      "    lx      rbaz",
      "    lx      wbaz",
      "    lu     opbaz",
      "    ly      rbaz",
      "hh  lA     uwbaz",
      "ggB l       !baz",
      "    l       Cbaz",
      "    D       Cbaz",
      "Ellldllllllllcaz"
    ],
    [
      "zzzzzzzzzzzzzzzz",
      "aaaaaaaaaaaaaaaz",
      "bbbbbbbbbbbbbcaz",
      " j  l      opbaz",
      "    l        baz",
      "llllds      wbaz",
      "    lw     opbaz",
      "    lw       baz",
      "    l       wbaz",
      "hh  l       pbaz",
      "ggB l        baz",
      "  B l       wbaz",
      "    l        baz",
      "    l        baz",
      "    F       Ibaz",
      "Jllldllllllllcaz"
    ],
    [
      "zzzzzzzzzzzzzzzz",
      "aaaaaaaaaaaaaaaz",
      "bbbbbbbbbbbbbcaz",
      "j   l       sbaz",
      "    l        baz",
      "llllds      wbaz",
      "hhhhlw      sbaz",
      "hhhhl        baz",
      "ggB l       wbaz",
      "  B l       sbaz",
      "    l        baz",
      "    l       wbaz",
      "    l        baz",
      "    l        baz",
      "K   l       Lbaz",
      "Mllldllllllllcaz"
    ],
    [
      "zzzzzzzzzzzzzzzz",
      "aaaaaaaaaaaaaaaz",
      "bbbbbbbbbbbbbcaz",
      "    ls      Nbaz",
      "e   ls      sbaz",
      "llllds      sbaz",
      "    ls      Nbaz",
      "    lOP     sbaz",
      " fgglOP     sbaz",
      "  hhlOP     Nbaz",
      "    lOP     sbaz",
      "    ls      sbaz",
      "    lssssssssbaz",
      "    l       sbaz",
      "    l       sbaz",
      "lllldllllllllcaz"
    ],
    [
      "zzzzzzzzzzzzzzzz",
      "aaaaaaaaaaaaaaaz",
      "bbbbbbbbbbbbbcaz",
      "    lQQQQQQQQbaz",
      " e  lQQQQQQQQbaz",
      "lllldQQQQQQQQbaz",
      "    lQQQQQQQQbaz",
      "    lQQQQQQQQbaz",
      "    lQQQQQQQQbaz",
      " f  lQQQQQQQQbaz",
      " fgglQQQQQQQQbaz",
      "  hhlQQQQQQQQbaz",
      "    lQQQQQQQQbaz",
      "    lQQQQQQQQbaz",
      "    lQQQQQQQQbaz",
      "lllldllllllllcaz"
    ]
  ]
}