{
  "name": "multi_laboratory1_3_base4",
  "refpalette": "c70cities:multi_laboratory1_3_base4_palette",
  "xsize": 16,
  "zsize": 16,
  "slices": [
    [
      "vabccccccccccccc",
      "vabccccccccccccc",
      "vbbccccccccdcccc",
      "vbbccccccccccccc",
      "vbbccccccccccccc",
      "vbbccccccccccccc",
      "vbbccccccccccccc",
      "vbbccccccccccccc",
      "vbbccccccccccccc",
      "vbbccccccccdcccc",
      "vbbccccccccccccc",
      "vbbccccccccccccc",
      "vbbccccccccccccc",
      "vbbccccccccccccc",
      "vbbccccccccccccc",
      "vbbccccccccccccc"
    ],
    [
      "vabe fg    h  i ",
      "vabjjk     l mno",
      "vbb k p   qd  n ",
      "vbbr    g sl t  ",
      "vbbiug  fwql fn ",
      "vbbskx g  sly  x",
      "vbbr k   wAl    ",
      "vbbiuf k  Al    ",
      "vbbB  gC DAl    ",
      "vbbEF    IEdllll",
      "vbbEi    JElB   ",
      "vbbEK    LEl    ",
      "vbbEK    LEl    ",
      "vbbEr    MEl  NN",
      "vbbEiOPP AEl   A",
      "vbbEEEEEEEEl   Q"
    ],
    [
      "vab        h    ",
      "vabR       l    ",
      "vbb        d    ",
      "vbb       sl    ",
      "vbbS       T    ",
      "vbbs       T    ",
      "vbbU      VT    ",
      "vbbS      mT    ",
      "vbb        l    ",
      "vbbE     WEdlTTT",
      "vbbE     XEl    ",
      "vbbE      EY    ",
      "vbbE      EY    ",
      "vbbE     ZEY   0",
      "vbbE     1EY    ",
      "vbbEEEEEEEEl    "
    ],
    [
      "vab        h    ",
      "vab        l    ",
      "vbb        d    ",
      "vbb        l    ",
      "vbb        T    ",
      "vbb        T    ",
      "vbb        T    ",
      "vbb        T    ",
      "vbb        l    ",
      "vbbE      EdlTTT",
      "vbbY      El    ",
      "vbbY     2E3    ",
      "vbbY     2E3    ",
      "vbbY      E3    ",
      "vbbE  44  E3    ",
      "vbbEEEEEEEEl    "
    ],
    [
      "vab        l    ",
      "vab        l    ",
      "vbb        d    ",
      "vbb        l    ",
      "vbb        l    ",
      "vbb        l    ",
      "vbb        l    ",
      "vbb        l    ",
      "vbb        l    ",
      "vbbE      Edllll",
      "vbb3      El    ",
      "vbb3      El    ",
      "vbb3      El    ",
      "vbb3      El    ",
      "vbbE      El    ",
      "vbbEEEEEEEEl    "
    ],
    [
      "vab5565575589799",
      "vab5565575589999",
      "vab55555555d9999",
      "vab5555555589999",
      "vab5575565589699",
      "vab5565575589799",
      "vab5575565589799",
      "vab5565575589@99",
      "vab5555555589999",
      "vabE@@@@@@Ed####",
      "vabE@    @E85555",
      "vabE@$  $@E85555",
      "vabE@    @E85555",
      "vabE@    @E85577",
      "vabE@@@@@@E85575",
      "vabEEEEEEEE855@5"
    ]
  ]
}