{
  "name": "multi_condo1_1_floor5",
  "refpalette": "c70cities:multi_condo1_1_floor5_palette",
  "xsize": 16,
  "zsize": 16,
  "slices": [
    [
      "   abcccddefgggg",
      "  hhbbbbbbefgijj",
      "   ab     efgk  ",
      "   ab    lefgk  ",
      "   akeeeeeefgk  ",
      "   akeeeeeefgk  ",
      "   akeeeeeefgk  ",
      "   akeeeeeefgk  ",
      "   akeeeeeefgk  ",
      "   akeeeeeefgk  ",
      "   akeeeeeefgk  ",
      "   akeeeeeefgk  ",
      "   abeeeeeefgk  ",
      "   abeeeeeefgk  ",
      "  hhbbbbbbefgmnn",
      "   abcccddefgggg"
    ],
    [
      "    bopqrrb     ",
      "  hhbbbbbbb  sss",
      "    b    t   s  ",
      "    buuuuu   s  ",
      "    w xyAx   s  ",
      "    w        s  ",
      "    w  BC    s  ",
      "    w        s  ",
      "    w        s  ",
      "    w  yA    s  ",
      "    w        s  ",
      "    w xBCx   s  ",
      "    b        s  ",
      "    bDDDDDE  s  ",
      "  hhbbbbbbb  sss",
      "    bFIqJJb     "
    ],
    [
      "    b  qKLb     ",
      "  hhbbbbbbb     ",
      "    b   t       ",
      "    b           ",
      "    w           ",
      "    w           ",
      "    w           ",
      "    w           ",
      "    w           ",
      "    w           ",
      "    w           ",
      "    w           ",
      "    b           ",
      "    bDDDDDM     ",
      "  hhbbbbbbb     ",
      "    b  qNOb     "
    ],
    [
      "    b  q  b     ",
      "  hhbbbbbbb     ",
      "    bPPt        ",
      "    bPP         ",
      "    w           ",
      "    w           ",
      "    w           ",
      "    w           ",
      "    w           ",
      "    w           ",
      "    w           ",
      "    w           ",
      "    b           ",
      "    b   Q       ",
      "  hhbbbbbbb     ",
      "    b  q! b     "
    ],
    [
      "    b  q  b     ",
      "  hhbbbbbbb     ",
      "    b           ",
      "    buul        ",
      "    w           ",
      "    w           ",
      "    w           ",
      "    w           ",
      "    w           ",
      "    w           ",
      "    w           ",
      "    w           ",
      "    b           ",
      "    b           ",
      "  hhbbbbbbb     ",
      "    b  q  b     "
    ],
    [
      "    bRRRRRb     ",
      "  hhbbbbbbb     ",
      "    b           ",
      "    b   l       ",
      "    S           ",
      "    S           ",
      "    S           ",
      "    S           ",
      "    S           ",
      "    S           ",
      "    S           ",
      "    S           ",
      "    b           ",
      "    b           ",
      "  hhbbbbbbb     ",
      "    bRRRRRb     "
    ]
  ]
}