{
  "name": "multi_laboratory1_9_base2",
  "refpalette": "c70cities:multi_laboratory1_9_base2_palette",
  "xsize": 16,
  "zsize": 16,
  "slices": [
    [
      "aaaaaaaaaaaaaaaa",
      "aaaaaaaaaaaaaaaa",
      "aaaaaaaaaaaaaaaa",
      "aaaaaaaaaaaaaaaa",
      "aaaaaaaaaaaaaaaa",
      "aaaaaaaaaaaaaaaa",
      "aaaaaaaaaaaaaaaa",
      "aaaaaaaaaaaaaaaa",
      "aaaaaaaaaaaaaaaa",
      "aaaaaaaaaaaaaaaa",
      "aaaaaaaaaaaaaaaa",
      "aaaaaaaaaaaaaaaa",
      "aaaaaaaaaaaaaaaa",
      "bbbbbbbbbbbbbbbb",
      "cccccccccccccccc",
      "zzzzzzzzzzzzzzzz"
    ],
    [
      "de   fg  d    hg",
      "d    hg  de    g",
      "de    g  d    hg",
      "i    hiiiie    i",
      "                ",
      "                ",
      "   jkllllllkj   ",
      "mmmmmmmmmmmmmmmm",
      "   jnnnooiipj   ",
      "                ",
      " q        q   r ",
      "qsq qsq  qsq rs ",
      " q   q    q   r ",
      "bbbbbbbbbbbbbbbb",
      "cccccccccccccccc",
      "zzzzzzzzzzzzzzzz"
    ],
    [
      "t     u        w",
      "                ",
      "      w         ",
      "       w        ",
      "                ",
      "                ",
      "   x yw AwB x   ",
      "mmmmmmmmmmmmmmmm",
      "   x C     pD   ",
      "                ",
      "                ",
      "                ",
      "                ",
      "bbbbbbbbbbbbbbbb",
      "cccccccccccccccc",
      "zzzzzzzzzzzzzzzz"
    ],
    [
      "                ",
      "                ",
      "                ",
      "                ",
      "                ",
      "                ",
      "   x        x   ",
      "mmmmmEmEmEEmmmmm",
      "    FFFIIJJJ    ",
      "                ",
      "                ",
      "                ",
      "                ",
      "bbbbbbbbbbbbbbbb",
      "cccccccccccccccc",
      "zzzzzzzzzzzzzzzz"
    ],
    [
      "                ",
      "                ",
      "         !      ",
      "                ",
      "                ",
      "                ",
      "                ",
      "mmmmmEEmEEEmmmmm",
      "    KKKKKKKK    ",
      "                ",
      "                ",
      "                ",
      "                ",
      "bbbbbbbbbbbbbbbb",
      "cccccccccccccccc",
      "zzzzzzzzzzzzzzzz"
    ],
    [
      "LMMmMMNMMLMMmMML",
      "LMMmMMLMMLMMmMML",
      "LMMmMMLMMNMMmMML",
      "LMMmMMLLLLMMmMML",
      "MMMmMMMMMMMMmMMM",
      "MMMmMMMMMMMMmMMM",
      "MMMmMMMMMMMMmMMM",
      "mmmmmmmmmmmmmmmm",
      "OOOOOOOOOOOOOOOO",
      "OLOOOLOOOOLOOOLO",
      "OLOOOLOOOOLOOOLO",
      "O!OOOLOOOOPOOOLO",
      "OOOOOOOOOOOOOOOO",
      "bbbbbbbbbbbbbbbb",
      "cccccccccccccccc",
      "zzzzzzzzzzzzzzzz"
    ]
  ]
}