{
  "name": "multi_clubhouse1_5_ground",
  "refpalette": "c70cities:multi_clubhouse1_5_ground_palette",
  "xsize": 16,
  "zsize": 16,
  "slices": [
    [
      "              aa",
      "            aaab",
      "aaaaaaaaaaaaabbb",
      "bbbbbbbbbbbbbbbb",
      "bbbbbbbbbcbbbbbc",
      "cbbccbcccbcbcbcc",
      "cbbbccbcbcccbccc",
      "bbcbbbccccbbbbbb",
      "bbbbGbcbcbbGbbbb",
      "aaaaaaaaaaaaaaaa",
      "dddde f  f edddd",
      "dddde f  f edddd",
      "dddde f  f edddd",
      "dddde f  f edddd",
      "aaaaaaaaaaaaaaaa",
      "GGGGGGGGGGGGGGGG"
    ],
    [
      "~~~~~~~~~~~~gggh",
      "ggggggggggggghh~",
      "hhhhihhhhhhih~~~",
      "~~~~~~~jk~~~~~~~",
      "~~~~~~~~~~~~~~~~",
      "~~~~~~~~~~~~~~~~",
      "~~~~~~~~~~~~~~~~",
      "~~~~~~~~~~~~~~~~",
      "lm~~n~~~~~~n~~lm",
      "hhhhihhoohhihhhh",
      "gggggghpphgggggg",
      "~~~~~ghpphg~~~~~",
      "~~~~~ghpphg~~~~~",
      "gggggghpphgggggg",
      "hhhhihhqqhhihhhh",
      "~~~~~~~~~~~~~~~~"
    ],
    [
      "~~~~~~~~~~~~~~~~",
      "~~~~~~~~~~~~~~~~",
      "~~~~r~~~~~~r~~~~",
      "~~~~~~~~~~~~~~~~",
      "~~~~~~~~~~~~~~~~",
      "~~~~~~~~~~~~~~~~",
      "~~~~~~~~~~~~~~~~",
      "~~~~~~~~~~~~~~~~",
      "~~~~~~~~~~~~~~~~",
      "~~~~~~h~~h~r~~~~",
      "~~~~~~h~~h~~~~~~",
      "~~~~~~h~~h~~~~~~",
      "~~~~~~h~~h~~~~~~",
      "~~~~~~h~~h~~~~~~",
      "~~~~r~h~~h~r~~~~",
      "~~~~~~~~~~~~~~~~"
    ],
    [
      "~~~~~~~~~~~~~~~~",
      "~~~~~~~~~~~~~~~~",
      "~~~~~~~~~~~~~~~~",
      "~~~~~~~~~~~~~~~~",
      "~~~~~~~~~~~~~~~~",
      "~~~~~~~~~~~~~~~~",
      "~~~~~~~~~~~~~~~~",
      "~~~~~~~~~~~~~~~~",
      "~~~~~~~~~~~~~~~~",
      "~~~~~~~~~~~~~~~~",
      "~~~~~~~~~~~~~~~~",
      "~~~~~~~~~~~~~~~~",
      "~~~~~~~~~~~~~~~~",
      "~~~~~~~~~~~~~~~~",
      "~~~~~~~~~~~~~~~~",
      "~~~~~~~~~~~~~~~~"
    ],
    [
      "~~~~~~~~~~~~~~~~",
      "~~~~~~~~~~~~~~~~",
      "~~~~~~~~~~~~~~~~",
      "~~~~~~~~~~~~~~~~",
      "~~~~~~~~~~~~~~~~",
      "~~~~~~~~~~~~~~~~",
      "~~~~~~~~~~~~~~~~",
      "~~~~~~~~~~~~~~~~",
      "~~~~~~~~~~~~~~~~",
      "~~~~~~~~~~~~~~~~",
      "~~~~~~~~~~~~~~~~",
      "~~~~~~~~~~~~~~~~",
      "~~~~~~~~~~~~~~~~",
      "~~~~~~~~~~~~~~~~",
      "~~~~~~~~~~~~~~~~",
      "~~~~~~~~~~~~~~~~"
    ],
    [
      "~~~~~~~~~~~~~~~~",
      "~~~~~~~~~~~~~~~~",
      "~~~~~~~~~~~~~~~~",
      "~~~~~~~~~~~~~~~~",
      "~~~~~~~~~~~~~~~~",
      "~~~~~~~~~~~~~~~~",
      "~~~~~~~~~~~~~~~~",
      "~~~~~~~~~~~~~~~~",
      "~~~~~~~~~~~~~~~~",
      "~~~~~~~~~~~~~~~~",
      "~~~~~~~~~~~~~~~~",
      "~~~~~~~~~~~~~~~~",
      "~~~~~~~~~~~~~~~~",
      "~~~~~~~~~~~~~~~~",
      "~~~~~~~~~~~~~~~~",
      "~~~~~~~~~~~~~~~~"
    ]
  ]
}