{
  "name": "multi_communitycenter_3_ground",
  "refpalette": "c70cities:multi_communitycenter_3_ground_palette",
  "xsize": 16,
  "zsize": 16,
  "slices": [
    [
      "aaaaaaaaaaaaaaaa",
      "aaaaaaaaaaaaaaaa",
      "bbbcaaaaaaaaaaaa",
      "bbbcaaaaaaaaaaaG",
      "bbbcaaaaaaaaaaGG",
      "dddcaaaaaaaaaaGG",
      "dddcaaaaaaaaaaGG",
      "dddcaaaaeeaaaaGG",
      "dddcaaaeffeaaaag",
      "dddcaaeffffeaaGg",
      "dddcaaeffffeaaGg",
      "dddcaaeffffeaaGg",
      "hhhcaaeffffeaaag",
      "iihjaaeffffeaaGg",
      "kkljaaeffffeaaGg",
      "kmljaaeffffeaaGg"
    ],
    [
      "                ",
      "                ",
      "  no            ",
      " pno           q",
      "rrnj          qq",
      "bbbj          qs",
      "bbbj          q ",
      "bbbj   teet   qu",
      "bbbj  tewwet  xy",
      "dddj  ewwwwe  qA",
      "dddj  ewwwwe  qy",
      "dddj  ewwwwe  qA",
      "BBhj  ewwwwe  xA",
      "  hj  ewwwwe  qA",
      "   j  ewwwwe  qy",
      "  Cj  ewwwwe  qA"
    ],
    [
      "                ",
      "                ",
      "                ",
      "                ",
      "  n             ",
      "  n            D",
      "  no            ",
      "  no    ~      E",
      "  nj          xy",
      "bbbj           A",
      "bbFj           y",
      "bbFj           A",
      "bbbj          xA",
      "hhhj           A",
      "IIIj           y",
      "IIIJ           A"
    ],
    [
      "                ",
      "                ",
      "                ",
      "                ",
      "                ",
      "                ",
      "                ",
      "        ~       ",
      "  n           xy",
      "  n            A",
      "  no           y",
      "  no           A",
      " pnj          xA",
      "bbbj           A",
      "bbbj           y",
      "bbbj           A"
    ],
    [
      "                ",
      "                ",
      "                ",
      "                ",
      "                ",
      "                ",
      "                ",
      "        ~       ",
      "              xK",
      "               A",
      "               A",
      "               A",
      "  n           xA",
      "  n            A",
      "p no           A",
      "  no           A"
    ],
    [
      "                ",
      "                ",
      "                ",
      "                ",
      "                ",
      "                ",
      "                ",
      "        ~       ",
      "              LL",
      "              Lg",
      "              Lg",
      "              Lg",
      "              xg",
      "              Lg",
      "              Lg",
      "              Lg"
    ]
  ]
}