{
  "name": "multi_laboratory1_7_base6",
  "refpalette": "c70cities:multi_laboratory1_7_base6_palette",
  "xsize": 16,
  "zsize": 16,
  "slices": [
    [
      " ~~~~~~~~~~~~~~ ",
      " ~~~~~~~~~~~~~~ ",
      " ~~~~~~~~~~~~~~ ",
      " ~~~~~~~~~~~~~~ ",
      " ~~~~~~~~~~~~~~ ",
      "a~~~~~~~~~~~~~~a",
      "a~~~~~~~~~~~~~~a",
      "ab~~~~~~~~~~~~ba",
      "caaa        aaac",
      "cccaab    baaccc",
      "cccccaaaaaaccccc",
      "cccccccccccccccc",
      "cccccccddccccccc",
      "cccccccccccccccc",
      "cccccccddccccccc",
      "cccccccccccccccc"
    ],
    [
      " ~~~~~~~~~~~~~~ ",
      " ~~~~~~~~~~~~~~ ",
      " ~~~~~~~~~~~~~~ ",
      " ~~~~~~~~~~~~~~ ",
      " ~~~~~~~~~~~~~~ ",
      "e~~~~~~~~~~~~~~e",
      "e~~~~~~~~~~~~~~e",
      "eb~~~~~~~~~~~~be",
      " eee        eee ",
      "   eeb    beefg ",
      "     eeeeee  h  ",
      "                ",
      "iij           ii",
      "k           l m ",
      "             n  ",
      "              o "
    ],
    [
      " ~~~~~~~~~~~~~~ ",
      " ~~~~~~~~~~~~~~ ",
      " ~~~~~~~~~~~~~~ ",
      " ~~~~~~~~~~~~~~ ",
      " ~~~~~~~~~~~~~~ ",
      "e~~~~~~~~~~~~~~e",
      "e~~~~~~~~~~~~~~e",
      "eb~~~~~~~~~~~~be",
      " eee        eee ",
      "   eeb    bee   ",
      "     eeeeee     ",
      "                ",
      "pqr            p",
      "                ",
      "                ",
      "                "
    ],
    [
      " ~~~~~~~~~~~~~~ ",
      " ~~~~~~~~~~~~~~ ",
      " ~~~~~~~~~~~~~~ ",
      "!sttu~~~~~~~~~~ ",
      " ~~~~~~~~~~~~~~ ",
      "e~~~~~~~~~~~~~~e",
      "e~~~~~~~~~~~~~~e",
      "eb~~~~~~~~~~~~be",
      " eee        eee ",
      "   eeb    bee   ",
      "     eeeeee     ",
      "                ",
      "                ",
      "                ",
      "                ",
      "                "
    ],
    [
      " ~~~~~~~~~~~~~~ ",
      " ~~~~~~~~~~~~~~ ",
      " ~~~~~~~~~~~~~~ ",
      " w~~~~~~~~~~~~~ ",
      " ~~~~~~~~~~~~~~ ",
      "e~~~~~~~~~~~~~~e",
      "e~~~~~~~~~~~~~~e",
      "eb~~~~~~~~~~~~be",
      " eee        eee ",
      "   eeb    bee   ",
      "     eeeeee     ",
      "                ",
      "                ",
      "                ",
      "                ",
      "                "
    ],
    [
      " ~~~~~~~~~~~~~~ ",
      " ~~~~~~~~~~~~~~ ",
      " ~~~~~~~~~~~~~~ ",
      " x~~~~~~~~~~~~~ ",
      " ~~~~~~~~~~~~~~ ",
      "e~~~~~~~~~~~~~~e",
      "e~~~~~~~~~~~~~~e",
      "eb~~~~~~~~~~~~be",
      " eee        eee ",
      "   eeb    bee   ",
      "     eeeeee     ",
      "                ",
      "                ",
      "                ",
      "                ",
      "                "
    ]
  ]
}