{
  "name": "multi_militarybase_4_base1",
  "refpalette": "c70cities:multi_militarybase_4_base1_palette",
  "xsize": 16,
  "zsize": 16,
  "slices": [
    [
      "vvvvvvvvvvvvvvvv",
      "avaaaaaaavaaaavv",
      "abaaaaaaabaaaavv",
      "abaaaaaaabaaaavv",
      "abaaaaaaabaaaavv",
      "bvbbbbbbbvbbbvvv",
      "abaaaaaaabaaaavv",
      "abaaaaaaabaaaavv",
      "abaaaaaaabaaaavv",
      "cvdaaaaaabaaaavv",
      "ebeeaaaaabaaaavv",
      "ebeeeaaaabaaaavv",
      "ebeeeaaaabaaaavv",
      "bvbbbbbbbvbbbvvv",
      " beeeaaaaaaaaavv",
      " beeeaaaaaaaaavv"
    ],
    [
      "vvvvvvvvvvvvvvvv",
      "fv ghhh!ivjjjjvv",
      " k l   min  jjvv",
      " op q r  s  jjvv",
      " k       nj  jvv",
      "tv       vuuuvvv",
      " k       nwwqxvv",
      " op      nwq yvv",
      " k       nl ABCv",
      "tvd      D   BCv",
      "      EE nF  BCv",
      "     IEEInJp Kvv",
      "       I nJp Lvv",
      "Mv       vuuuvvv",
      " M    I   NONOvv",
      " M   IEE      vv"
    ],
    [
      "vvvvvvvvvvvvvvvv",
      "fv  lr riv jjjvv",
      "        Pn   jvv",
      " Q       R    vv",
      "         n    vv",
      "tv       vuuuvvv",
      "         nww  vv",
      " Q       n   Svv",
      "         n    Cv",
      "tv       T    Cv",
      "         n    Cv",
      "       U n   Svv",
      "         nV   vv",
      " v       vuuuvvv",
      "          NNNNvv",
      "              vv"
    ],
    [
      "vvvvvvvvvvvvvvvv",
      "fv       v  jjvv",
      "         n   Wvv",
      "         n    vv",
      "         n    vv",
      "tv       vuuuvvv",
      "         nq   vv",
      "         n    vv",
      "         n    Cv",
      "tvX      n    Cv",
      "         n    Cv",
      "         n    vv",
      "         n    vv",
      " v       vuuuvvv",
      "          NYYNvv",
      "              vv"
    ],
    [
      "vvvvvvvvvvvvvvvv",
      "fv       v   Wvv",
      " M       n   Wvv",
      " M       n    vv",
      " M       n    vv",
      "tvMMMMMMMvuuuvvv",
      " M       M    vv",
      " M       M    vv",
      " M       M   ZCv",
      "tv       M   ZCv",
      "         M   ZCv",
      "         M    vv",
      "         M    vv",
      "0v       vuuuvvv",
      " 0            vv",
      " 0            vv"
    ],
    [
      "vvvvvvvvvvvvvvvv",
      "1v1111111v1111vv",
      "2b2222222b2221vv",
      "2b2222222b2221vv",
      "2b2222222b2221vv",
      "bvbbbbbbbvbbbvvv",
      "2b2222222b2221vv",
      "2b2222222b2221vv",
      "2b2222222b222!vv",
      "2v2222222b2221vv",
      "2b2222222b2221vv",
      "2b2222222b2221vv",
      "2b2222222b2221vv",
      "bvbbbbbbbvbbbvvv",
      "3b222222222221vv",
      "3b222222222221vv"
    ]
  ]
}