{
  "name": "multi_gasstation_0_ground",
  "refpalette": "c70cities:multi_gasstation_0_ground_palette",
  "xsize": 16,
  "zsize": 16,
  "slices": [
    [
      "GGGGGGGGGGGGGGGG",
      "HHHHHHHHHHHHHaGG",
      "HHHHHHHHHHHHHaGG",
      "HHHHHHHHHHHHHaGG",
      "bHHHHHHHHHHHHaGG",
      "bHHHHHHHHHHHHaGG",
      "HHHHHHHHHHHHHaGG",
      "HHHHbHHbbbbbbbGG",
      "HHHHbHHbbbbbbbGG",
      "HHHHbHHbbbbbbbGG",
      "HHHHbHHbbbbbbbGG",
      "HHHHbHHbbbbbbbGG",
      "HHHHbHHbbbbbbbGG",
      "HHHHbHHbbbbbbbGG",
      "HHHHbHHbbbbbbbGG",
      "HHHHbHHbbbbbbbGG"
    ],
    [
      "                ",
      "             c  ",
      "             c  ",
      "             c  ",
      "d      efefefc  ",
      "g            c  ",
      " g     hihihic  ",
      "    j  kkkkkkk  ",
      "  lmn  k okp k  ",
      "       k  k  k  ",
      "  qrj  kskkktk  ",
      "  lmc  k uuu k  ",
      "       k     k  ",
      "  qrj  k     k  ",
      "  lmc  kkwkkkk  ",
      "       x  yyyk  "
    ],
    [
      "                ",
      "                ",
      "                ",
      "                ",
      "g               ",
      "d               ",
      "                ",
      "    j  kkkkkkk  ",
      "    A  k BkC k  ",
      "       k  k  k  ",
      "    j  kDkkkEk  ",
      "       k     k  ",
      "       k     k  ",
      "    j  k     k  ",
      "       kkFkkkk  ",
      "       x  IIIk  "
    ],
    [
      "                ",
      "                ",
      "                ",
      "                ",
      "g               ",
      "                ",
      "                ",
      "    j  JJJJJJJ  ",
      "       K  J  K  ",
      "       K  J  K  ",
      "    j  JJJJJJJ  ",
      "       J     J  ",
      "       K     K  ",
      "    j  K     K  ",
      "       JJJJJJJ  ",
      "       J     K  "
    ],
    [
      "                ",
      "                ",
      "                ",
      "                ",
      "                ",
      "                ",
      "                ",
      "    kL kkkkkkk  ",
      "       kMMkMMk  ",
      "       kMMkMMk  ",
      "    kN kkkkkkk  ",
      "       kMMMMMk  ",
      "       kMMMMMk  ",
      "    kL kMMNMMk  ",
      "       kkkkkkk  ",
      "       k     k  "
    ],
    [
      "                ",
      "                ",
      "                ",
      "                ",
      "                ",
      "                ",
      " OOOOOOOOOOOOOO ",
      " OccbbbbbbbbbbO ",
      " OccbccccccccbO ",
      " OccbccccccccbO ",
      " OccbccccccccbO ",
      " OccbccccccccbO ",
      " OccbccccccccbO ",
      " OccbccccccccbO ",
      " OccbbbbbbbbbbO ",
      " OccbccccccccbO "
    ]
  ]
}