{
  "name": "multi_condo1_4_top",
  "refpalette": "c70cities:multi_condo1_4_top_palette",
  "xsize": 16,
  "zsize": 16,
  "slices": [
    [
      "                ",
      "     abbbbbbbcc ",
      "     def    b   ",
      "     def    b   ",
      "     def    b   ",
      "     defghhhbcc ",
      "     defhhhhb   ",
      "     defhhhhb   ",
      "     def hhhb   ",
      "     defhhhhb   ",
      "     defhhhhbcc ",
      "     def    b   ",
      "     deii iib   ",
      "     deiifiib   ",
      "     jbbbbbbbcc ",
      "                "
    ],
    [
      "                ",
      "ccccccccccccccc ",
      "kkkkk c         ",
      "kkkkk c         ",
      "kkkkk c  l      ",
      "kkkkk ccmcccccc ",
      "kkkkk c jn      ",
      "kkkkk c o       ",
      "kkkkk c p       ",
      "kkkkk c ol      ",
      "kkkkk ccqcccccc ",
      "kkkkk c jn      ",
      "kkkkk cii ii    ",
      "kkkkk cii ii    ",
      "ccccccccccccccc ",
      "                "
    ],
    [
      "                ",
      "ccccccccccccccc ",
      "      c         ",
      "      c         ",
      "      c  l      ",
      "      ccccccccc ",
      "      c  n      ",
      "      c         ",
      "      c         ",
      "      c  l      ",
      "      ccccccccc ",
      "      c  n      ",
      "      crr rr    ",
      "      css ss    ",
      "ccccccccccccccc ",
      "                "
    ],
    [
      "                ",
      "                ",
      "                ",
      "                ",
      "                ",
      "                ",
      "                ",
      "                ",
      "                ",
      "                ",
      "                ",
      "                ",
      "                ",
      "                ",
      "                ",
      "                "
    ],
    [
      "                ",
      "                ",
      "                ",
      "                ",
      "                ",
      "                ",
      "                ",
      "                ",
      "                ",
      "                ",
      "                ",
      "                ",
      "                ",
      "                ",
      "                ",
      "                "
    ],
    [
      "                ",
      "                ",
      "                ",
      "                ",
      "                ",
      "                ",
      "                ",
      "                ",
      "                ",
      "                ",
      "                ",
      "                ",
      "                ",
      "                ",
      "                ",
      "                "
    ]
  ]
}