{
  "name": "multi_convenientstore_2_ground",
  "refpalette": "c70cities:multi_convenientstore_2_ground_palette",
  "xsize": 16,
  "zsize": 16,
  "slices": [
    [
      "GGGGGGGGGGGaHHHG",
      "GGGGGGGGGGGaHHHG",
      "aaaaaaaaaaaaHHHG",
      "HHHHHHHHHHHHHHHG",
      "HHHHHHHHbcHHHHHG",
      "HHHHHHHHHHHHHHHG",
      "HHHHHHHHHHHHHHHG",
      "HHHHHHHHHHHHHHHG",
      "HHHHHHHHHHHHHHHG",
      "HHHHHHHHHHHHHHHG",
      "HHHHHHHHHHHHHHHG",
      "HHHHHHHHHHHHHHHG",
      "HHHHHHHHHHHHHHHG",
      "HHHHHHHHHHHHHHHd",
      "HHHHHHHHHHHHHHHd",
      "HHHHHHHHHHHHHHHd"
    ],
    [
      " e     e  ef    ",
      "           f    ",
      "fffff fff ff    ",
      "ghghghghghg     ",
      "                ",
      "ijijijijiji     ",
      "               e",
      "                ",
      "                ",
      "                ",
      "ghghghghghg     ",
      "                ",
      "ijijijijiji     ",
      "ffffffffffff   k",
      "aaaaaaaaaaaalllk",
      "aaaaaaaaaaaalllk"
    ],
    [
      "                ",
      "                ",
      "                ",
      "                ",
      "                ",
      "                ",
      "                ",
      "                ",
      "                ",
      "                ",
      "                ",
      "                ",
      "                ",
      "                ",
      "       m        ",
      " no o ompqpp    "
    ],
    [
      "                ",
      "                ",
      "                ",
      "                ",
      "                ",
      "                ",
      "                ",
      "                ",
      "                ",
      "                ",
      "                ",
      "                ",
      "                ",
      "                ",
      "       m        ",
      " no o omprpp    "
    ],
    [
      "                ",
      "                ",
      "                ",
      "                ",
      "                ",
      "                ",
      "                ",
      "                ",
      "                ",
      "                ",
      "                ",
      "                ",
      "                ",
      "                ",
      "       m        ",
      "sto o omp pp    "
    ],
    [
      "                ",
      "                ",
      "                ",
      "                ",
      "                ",
      "                ",
      "                ",
      "                ",
      "                ",
      "                ",
      "                ",
      "                ",
      "                ",
      "                ",
      "       m        ",
      "  o o omp pp    "
    ]
  ]
}