{
  "name": "multi_laboratory1_3_base2",
  "refpalette": "c70cities:multi_laboratory1_3_base2_palette",
  "xsize": 16,
  "zsize": 16,
  "slices": [
    [
      "zabccccccccccccc",
      "zab!cccccccccccc",
      "zabccccccccdcccc",
      "zabccccccccccccc",
      "zabccccccccccccc",
      "zabccccccccccccc",
      "zabccccccccccccc",
      "zabccccccccccccc",
      "zabeeffffffccccc",
      "zabccccccccdcccc",
      "zabccccccccccccc",
      "zabccccccccccccc",
      "zabccccccccccccc",
      "zabccccccccccccc",
      "zabccccccccccccc",
      "zabccccccccccccc"
    ],
    [
      "zabg h     i  j ",
      "zabkklm    n  jo",
      "zabp qp   rd  j ",
      "zabst     rn  j ",
      "zabkkp   uwn  jx",
      "zabyhA q  Bn    ",
      "zab  qC lD n    ",
      "zab  EFF   n    ",
      "zab IJJJJK n    ",
      "zabL      Ldnnnn",
      "zabLM NN OLnM   ",
      "zabLj NN PLn    ",
      "zabLj NN QLn    ",
      "zabLj NNR Ln  FF",
      "zabLS     Ln   T",
      "zabLLLLLLLLn   U"
    ],
    [
      "zab        i    ",
      "zabV       n  W ",
      "zabX       d    ",
      "zab        n  W ",
      "zabV       Y    ",
      "zabX       Y    ",
      "zab        Y    ",
      "zab   Z0   Y    ",
      "zab 1JJJJ2 n    ",
      "zabL      LdnYYY",
      "zabL      Ln    ",
      "zabL3     L4    ",
      "zabL3     L4    ",
      "zabL      L4  5 ",
      "zabL      L4   6",
      "zabLLLLLLLLn    "
    ],
    [
      "zab        i    ",
      "zab        n    ",
      "zab        d    ",
      "zab        n    ",
      "zab        Y    ",
      "zab        Y    ",
      "zab        Y    ",
      "zab        Y    ",
      "zab JJJJJJ n    ",
      "zabL      LdnYYY",
      "zabL 7    Ln    ",
      "zabL      L8    ",
      "zabL   9  L8    ",
      "zabL      L8    ",
      "zabL      L8    ",
      "zabLLLLLLLLn    "
    ],
    [
      "zab        n    ",
      "zab        n    ",
      "zab        d    ",
      "zab        n    ",
      "zab        n    ",
      "zab        n    ",
      "zab        n    ",
      "zab        n    ",
      "zab JJJJJJ n    ",
      "zabL      Ldnnnn",
      "zabL @    Ln    ",
      "zabL      Ln    ",
      "zabL   @  Ln    ",
      "zabL #    Ln    ",
      "zabL $  $ Ln    ",
      "zabLLLLLLLLn    "
    ],
    [
      "zab%%^%%^%%&*^**",
      "zab%%(%%^%%&****",
      "zab%%%%%%%%d****",
      "zab%%%%%%%%&****",
      "zab%%^%%^%%&*^**",
      "zab%%(%%^%%&*^**",
      "zab%%^%%(%%&*^**",
      "zab%%^%%^%%&*)**",
      "zab%%%%%%%%&****",
      "zabL))))))Ld++++",
      "zabL)-[]{)L&%%%%",
      "zabL)[]{})L&%%%%",
      "zabL)[{-\\)L&%%%%",
      "zabL)-[{|)L&%%^^",
      "zabL))))))L&%%^%",
      "zabLLLLLLLL&%%^%"
    ]
  ]
}