{
  "name": "multi_megatower1_5_floor5",
  "refpalette": "c70cities:multi_megatower1_5_floor5_palette",
  "xsize": 16,
  "zsize": 16,
  "slices": [
    [
      "    abbbbbbbbbbb",
      "    abbbbbbbbbbb",
      "ccccdbbbbbbdbbbb",
      "ef fge ef fge ef",
      "  f h e  f h e  ",
      "                ",
      "                ",
      "                ",
      "                ",
      "                ",
      "                ",
      "                ",
      "                ",
      "                ",
      "                ",
      "                "
    ],
    [
      "    i      j    ",
      "    iklmmnkjopqq",
      "iiiidiiiiiidrrrr",
      "ef fge ef fge ef",
      "    h      h    ",
      "                ",
      "                ",
      "                ",
      "                ",
      "                ",
      "                ",
      "                ",
      "                ",
      "                ",
      "                ",
      "                "
    ],
    [
      "    i      j    ",
      "    is    sjtu  ",
      "iiiidiiiiiidrwww",
      "ef fge ef fge ef",
      "    h      h    ",
      "                ",
      "                ",
      "                ",
      "                ",
      "                ",
      "                ",
      "                ",
      "                ",
      "                ",
      "                ",
      "                "
    ],
    [
      "    i      j    ",
      "    is    sj    ",
      "iiiidiiiiiidrxxx",
      "ef fge ef fge ef",
      "    h      h    ",
      "                ",
      "                ",
      "                ",
      "                ",
      "                ",
      "                ",
      "                ",
      "                ",
      "                ",
      "                ",
      "                "
    ],
    [
      "    j      jyAyy",
      "    j      jyyyy",
      "BCBCdBCBCBCdrrrr",
      "ef fge ef fge ef",
      "    h      h    ",
      "                ",
      "                ",
      "                ",
      "                ",
      "                ",
      "                ",
      "                ",
      "                ",
      "                ",
      "                ",
      "                "
    ],
    [
      "    DyAyyAyD E F",
      "    DyyyyyyD    ",
      "IIIIdIIIIIIdIIII",
      "efffgeeefffgeeef",
      "    h      h    ",
      "                ",
      "                ",
      "                ",
      "                ",
      "                ",
      "                ",
      "                ",
      "                ",
      "                ",
      "                ",
      "                "
    ]
  ]
}