{
  "name": "multi_clubhouse1_6_base1",
  "refpalette": "c70cities:multi_clubhouse1_6_base1_palette",
  "xsize": 16,
  "zsize": 16,
  "slices": [
    [
      "vvvvvvvvvvvvvvvv",
      "aaaaaaaaaaaaaaav",
      "aaaaaaaaaaaaaaav",
      "aaaaaaaaaaaaaaav",
      "aaaaaaaaaaaaaaav",
      "aaaaaaaaaaaaaaav",
      "aaaaaaaaaaaaaaav",
      "aaaaaaaaabvvvvvv",
      "aaaaaaaaacdddddv",
      "aaaaaaaaaeffggdv",
      "aaaaaaaaaeffggdv",
      "aaaaaaaaae    dv",
      "hhhhhhhhhe    dv",
      "hheeeeeeee    iv",
      "hhejjjjjje    dv",
      "  ej    je     v"
    ],
    [
      "vvvvvvvvvvvvvvvv",
      "aaaaaaaaaa!kkkkv",
      "aaaaaaaaaakkkkkv",
      "aaaaaaaaaakkkkkv",
      "aaaaaaaaaaaaaaav",
      "aaaaaaaaaaaaaaav",
      "aalllllllllllllv",
      "aalmmmmmmlvvvvvv",
      "aalmmmmmmlddnddv",
      "aalmmmmmmlg   dv",
      "aalmmmmmmlg   dv",
      "hhlmmmmmml     v",
      "hhlmmmmmml    dv",
      " olmmmmmml    iv",
      " olmmmmmml    dv",
      " olmmmmmml     v"
    ],
    [
      "vvvvvvvvvvvvvvvv",
      "aapqr qpqrsssskv",
      "aap r  p rsssskv",
      "aaktkkuktkwwwwkv",
      "aap           kv",
      "aap           kv",
      "aaixxxxyxiABBAiv",
      "aafC     fvvvvvv",
      "aaf DE   fd nndv",
      "hhf           dv",
      "hhf           nv",
      " Ff IJ   f     v",
      "  fC     f    nv",
      "  i      i    iv",
      "  K      L     v",
      "  K      L     v"
    ],
    [
      "vvvvvvvvvvvvvvvv",
      "aap r  p r  MMkv",
      "aap r  p r M Mkv",
      "aakNkkOkNk    kv",
      "aap           kv",
      "aap           kv",
      "aaixxxxPxi    iv",
      "hhfQ     fvvvvvv",
      "hhf      fn  ndv",
      "  f            v",
      "  f           nv",
      "  f      f     v",
      "  fQ     f     v",
      "  i      i    iv",
      "  K            v",
      "  K            v"
    ],
    [
      "vvvvvvvvvvvvvvvv",
      "aap r  p r    kv",
      "aap r  p r    kv",
      "aakkkkkkkk    kv",
      "aap           kv",
      "hhp           kv",
      "hhixxxxxxi    iv",
      "RFfQ     fvvvvvv",
      "  f      fn   dv",
      "  f      S     v",
      "  f      S     v",
      "  f      f     v",
      "  fQ     f     v",
      "  i      i    iv",
      "  K            v",
      "  K            v"
    ],
    [
      "vvvvvvvvvvvvvvvv",
      "aakTkkUkTk    kv",
      "aakkkkkkkk    kv",
      "hhkkkkkkkk    kv",
      "hhkjjjjjjk    kv",
      "  kjjjjjjk    kv",
      "  iiiiiiii    iv",
      "  fjjjjjjfvvvvvv",
      "  fjjjjjjf     v",
      "  fjjjjjjf     v",
      "  fjjjjjjf     v",
      "  fjjjjjjf     v",
      "  fjjjjjjf     v",
      "  ijVjjWji    iv",
      "  Kjjjjjj      v",
      "  Kjjjjjj      v"
    ]
  ]
}