{
  "name": "multi_condo1_0_floor2",
  "refpalette": "c70cities:multi_condo1_0_floor2_palette",
  "xsize": 16,
  "zsize": 16,
  "slices": [
    [
      "                ",
      "          a     ",
      "  bbbbbbbbaccccc",
      "  bdddddddaeeeee",
      "  bdffffffgggggg",
      "  bdfhhhhhgggggg",
      "  bdfhhhhhgggggg",
      "  bdfhhhhhgggggg",
      "  bdfhhhhhhhhhhh",
      "  bdfhhhhhhhhhhh",
      "  bdfhhhhhhhhhhh",
      "  bdfhhhhhhhhhhh",
      "  bdfhhhhhhhhhhh",
      " aaafhhhhhhhhhhh",
      "   ifjjjjjgggggg",
      "   ifjjjjjgkllll"
    ],
    [
      "                ",
      "          a     ",
      "          accccc",
      "   ddddddda     ",
      "   dffmmmfff    ",
      "   df!noppfq rs ",
      "   dft    u     ",
      "   dfw  xxffyyyy",
      "   dfA  BB q  CD",
      "   dfE          ",
      "   dfFFFF     I ",
      "   dfJ  K     L ",
      "   dfMN F OPQ   ",
      " aaafR  F OPQ S ",
      "    fFF FTffffff",
      "    U     f!    "
    ],
    [
      "                ",
      "          a     ",
      "          a     ",
      "          a     ",
      "    ffyyyfff    ",
      "    f    VfW    ",
      "    f     X     ",
      "    fY    ffyyyy",
      "    fZ     W  0 ",
      "    f1          ",
      "    fFFFF       ",
      "    f!  2       ",
      "    f   F       ",
      " aaafR  F       ",
      "    fFF F3ffffff",
      "    c 4   fd    "
    ],
    [
      "                ",
      "          a     ",
      "          a     ",
      "          a     ",
      "    ffyyyfff    ",
      "    f5    f     ",
      "    f5    6     ",
      "    f7    ffyyyy",
      "    f5     W    ",
      "    f8          ",
      "    fFFFF       ",
      "    f   F       ",
      "    f   F       ",
      " aaaf   F       ",
      "    fFFFFFffffff",
      "    c     fd    "
    ],
    [
      "                ",
      "          a     ",
      "          a     ",
      "   9999999a     ",
      "   9ffffffffffff",
      "   9f     f     ",
      "   9f     f     ",
      "   9f@    ffyyyy",
      "   9f           ",
      "   9f           ",
      "   9fFFFF       ",
      "   9f   F       ",
      "   9f   F       ",
      " aaaf   F       ",
      "    fFFFFFffffff",
      "    f     f#    "
    ],
    [
      "                ",
      "          a     ",
      "          a$$$$$",
      "   %%%%%%%a     ",
      "   %ffffffffffff",
      "   %f^^^^^flllll",
      "   %f^^^^^flllll",
      "   %f^^^^^ff&&&&",
      "   %f^^^^^^^^^^^",
      "   %f^^^^^^^^^^^",
      "   %f^^^^^^^^^^^",
      "   %f^^^^^^^^^^^",
      "   %f^^^^^^^^^^^",
      " aaaf^^^^^^^^^^^",
      "    f^^^^^ffffff",
      "    f^^^^^f     "
    ]
  ]
}