{
  "name": "multi_carservice_0_floor2",
  "refpalette": "c70cities:multi_carservice_0_floor2_palette",
  "xsize": 16,
  "zsize": 16,
  "slices": [
    [
      "                ",
      "                ",
      "                ",
      "                ",
      "                ",
      "                ",
      "    aabaaabaaab ",
      "   cc defegggda ",
      "  cc  d   ghgda ",
      " ac   d   ghgda ",
      " ai   de egggda ",
      " adddddddddddda ",
      " adddddddddddda ",
      " adddddddddddda ",
      " adddddddddddda ",
      " adddddddddddda "
    ],
    [
      "                ",
      "                ",
      "                ",
      "                ",
      "                ",
      "                ",
      "    aabaaabaaab ",
      "   jjk l lmnm a ",
      "  jj k     o  j ",
      " aj  k     o  j ",
      " ai  k l lmnm j ",
      " a ppp q   q  j ",
      " ar      s   qj ",
      " at           j ",
      " au          wj ",
      " au           j "
    ],
    [
      "                ",
      "                ",
      "                ",
      "                ",
      "                ",
      "                ",
      "    aabaaabaaab ",
      "   jj xyyy A xa ",
      "  jj   yByC C j ",
      " aj    yByC C j ",
      " ai    yyy C  j ",
      " b            j ",
      " j            j ",
      " j            j ",
      " j            j ",
      " j            j "
    ],
    [
      "                ",
      "                ",
      "                ",
      "                ",
      "                ",
      "                ",
      "    aabaaabaaab ",
      "   jj         a ",
      "  jj          j ",
      " aj           j ",
      " ai           j ",
      " a            j ",
      " a            j ",
      " a            j ",
      " a            j ",
      " a            j "
    ],
    [
      "                ",
      "                ",
      "                ",
      "                ",
      "                ",
      "                ",
      "    aabaaabaaab ",
      "   jj         a ",
      "  jj          D ",
      " aj           D ",
      " ai           D ",
      " a            D ",
      " a            D ",
      " a            D ",
      " a            D ",
      " a            D "
    ],
    [
      "                ",
      "                ",
      "                ",
      "                ",
      "                ",
      "                ",
      "    aabaaabaaab ",
      "   jj  EEEEEEEa ",
      "  jj   EEEEEEEa ",
      " aj    EEEEEEEa ",
      " ai    EEEEEEEa ",
      " a     EEEEEEEa ",
      " aEEEEEEEEEEEEa ",
      " aEEEEEEEEEEEEa ",
      " aEEEEEEEEEEEEa ",
      " aEEEEEEEEEEEEa "
    ]
  ]
}