{
  "name": "multi_condo1_5_floor7",
  "refpalette": "c70cities:multi_condo1_5_floor7_palette",
  "xsize": 16,
  "zsize": 16,
  "slices": [
    [
      "aaaaabccccccde  ",
      "ffffffddddddde  ",
      "      d     dggg",
      "      d     d   ",
      "      d     d   ",
      "      d     dhh ",
      "      d     i   ",
      "      d     i   ",
      "      d     i   ",
      "      d     i   ",
      "      d     i   ",
      "iiiiiidiiiiii   ",
      "      d         ",
      "                ",
      "                ",
      "                "
    ],
    [
      "      j  k  l   ",
      "mmmmmmddddddd   ",
      "      d     dggg",
      "      d     d   ",
      "      d     d   ",
      "      d     dhh ",
      "      d     dn  ",
      "      d     dn  ",
      "      d     dn  ",
      "      d     dn  ",
      "      d     dn  ",
      "dddddddddddddn  ",
      "nnnnnndnnnnnnn  ",
      "                ",
      "                ",
      "                "
    ],
    [
      "      o  p  i   ",
      "      ddddddd   ",
      "      d     dggg",
      "      d     d   ",
      "      d     d   ",
      "      d     dhh ",
      "      d     d   ",
      "      d     d   ",
      "      d     d   ",
      "      d     d   ",
      "      d     d   ",
      "ddddddddddddd   ",
      "      d         ",
      "                ",
      "                ",
      "                "
    ],
    [
      "      d  q  i   ",
      "      ddddddd   ",
      "      d     dggg",
      "      d     d   ",
      "      d     d   ",
      "      d     dhh ",
      "      d     dhh ",
      "      d     dhh ",
      "      d     dhh ",
      "      d     dhh ",
      "      d     dhh ",
      "dddddddddddddhh ",
      "hhhhhhhhhhhhhhh ",
      "hhhhhhhhhhhhhhh ",
      "                ",
      "                "
    ],
    [
      "      d  d  d   ",
      "      ddddddd   ",
      "      d     dggg",
      "      d     d   ",
      "      d     d   ",
      "      d     d   ",
      "      d     d   ",
      "      d     d   ",
      "      d     d   ",
      "      d     d   ",
      "rsrrrrd     d   ",
      "ddddddddddddd   ",
      "                ",
      "                ",
      "                ",
      "                "
    ],
    [
      "      dtttttd   ",
      "mmmmmmddddddd   ",
      "uuuuuudtttttdggg",
      "uuuuuudtttttdm  ",
      "uuuuuudtwwwtdm  ",
      "uuuuuudtttttdm  ",
      "uuuuuudtttttdm  ",
      "uuuuuudtttttdm  ",
      "uuuuuudtwwwtdm  ",
      "uuuuuudtttttdm  ",
      "uuuuuudtttttdm  ",
      "dddddddddddddm  ",
      "mmmmmmmmmmmmmm  ",
      "                ",
      "                ",
      "                "
    ]
  ]
}