{
  "name": "multi_communitycenter_4_ground",
  "refpalette": "c70cities:multi_communitycenter_4_ground_palette",
  "xsize": 16,
  "zsize": 16,
  "slices": [
    [
      "aabcddeffffedddg",
      "ahbcddeffffeddGg",
      "aabcddeffffeddGg",
      "ahbcddeffffeddGg",
      "aabcddeffffedddg",
      "ahbcddeffffeddGg",
      "aabcddeffffeddGg",
      "iiicddeffffeddGg",
      "jjjjjddeffeddddg",
      "kkkkjdddeeddddGg",
      "kkkkjjddddddddGg",
      "kkkkkjjjddddddGg",
      "kkkkkkjjjjjjjjjl",
      "kkkkkkljjjjjjjjl",
      "lkkkkkljjjjjjjjl",
      "jlkkkkljjjjjjjjl"
    ],
    [
      "   c  emmmme  no",
      "  pc  emmmme  qo",
      "   c  emmmme  qr",
      "   c  emmmme  qo",
      "   c  emmmme  no",
      "  pc  emmmme  qo",
      "   c  emmmme  qr",
      "iiic  emmmme  qo",
      "ssssc temmet  no",
      "u  uc  teet   qo",
      "w pwcc        qr",
      "u  u ccc  xx  qo",
      "  p y icABCDBAci",
      " uw EEF   II   F",
      "J p             ",
      " J  p           "
    ],
    [
      "KKKA          no",
      "   A           o",
      "   c           r",
      "   c           o",
      "   A          no",
      "   A    ~      o",
      "   A           r",
      "iiic           o",
      "ssssc         no",
      "    A          o",
      "    AA         r",
      "     AAc       o",
      "      icABLMBAci",
      "      F        F",
      "J       N       ",
      " J              "
    ],
    [
      "OOOc          no",
      "PPPc           o",
      "KKKc           r",
      "KKKc           o",
      "KKKA          no",
      "   A    ~      o",
      "   A           r",
      "iiic           o",
      "ssssc         no",
      "    A          o",
      "    AA         r",
      "     AAc       o",
      "      icABBBBAci",
      "      F        F",
      "J       Q       ",
      " J              "
    ],
    [
      "  Rc          no",
      "OOOc           o",
      "OOOc           o",
      "OOOc           o",
      "OOOc          no",
      "PPPc    ~      o",
      "PPPc           o",
      "iiic           o",
      "ccccc         no",
      "    c          o",
      "    cc         o",
      "     ccc       o",
      "      icAAAAAAci",
      "      F        F",
      "F     F Q    N F",
      " F    F        F"
    ],
    [
      "  R           Sg",
      "  R           Sg",
      " TRU          Sg",
      "  RU          Sg",
      "VVRc          ng",
      "OOOc    ~     Sg",
      "OOWc          Sg",
      "OOWc          Sg",
      "OOOcc         Sg",
      "PPPPc         Sg",
      "PPPPcc        Sg",
      "PPPPPccc      Sg",
      "PPPPPPiccccccccc",
      "iPPPPPiKKKKKKKKi",
      "iiPPPPiKQN N QKi",
      " iiPPPiKN N  NKi"
    ]
  ]
}