{
  "name": "multi_laboratory1_11_base6",
  "refpalette": "c70cities:multi_laboratory1_11_base6_palette",
  "xsize": 16,
  "zsize": 16,
  "slices": [
    [
      "aaaaaaaaaaaaabcz",
      "aaaaaaaaaaaaabcz",
      "aaaaaaaaaaaaabcz",
      "aaaaaaaaaaaaabcz",
      "aaaaaaaaaaaaabcz",
      "aaaaaaaaaaaaabcz",
      "aaaadaaaaaaaabcz",
      "aaaaaaaaaaaaabcz",
      "aaaaaaaaaaaaabcz",
      "aaaaaaaaaaaaabcz",
      "aaaaaaaaaaaaabcz",
      "aaaaaaaaaaaaabcz",
      "eaaaaaaaaaaaabcz",
      "eaaadaaaaaaaabcz",
      "feaaaaaaaaaaabcz",
      " eaaaaaaaaaaabcz"
    ],
    [
      "             gcz",
      "             bcz",
      "            hbcz",
      "            hbcz",
      " i           bcz",
      "jjj       kkkkcz",
      "    d     klmbcz",
      "   nh     kkkkcz",
      "    o        bcz",
      "    o p     hbcz",
      "    on      hbcz",
      "    o        bcz",
      "q   r     kkkkcz",
      "q   d     klmbcz",
      "fq  s     kkkkcz",
      " q  ot       bcz"
    ],
    [
      "             gcz",
      "            ubcz",
      "           wxbcz",
      "           wxbcz",
      "             bcz",
      "yA         qkkcz",
      "    d     qlmbcz",
      "    h      qkkcz",
      "    B       ubcz",
      "    C       xbcz",
      "    D      wEbcz",
      "    F       Ibcz",
      "q          qkkcz",
      "q   d     qlmbcz",
      "fq  F      qkkcz",
      " q  h       ubcz"
    ],
    [
      "             gcz",
      "             bcz",
      "             bcz",
      "             bcz",
      "             bcz",
      "           qkkcz",
      "    d     qlmbcz",
      "    J      qkkcz",
      "             bcz",
      "             bcz",
      "    K        bcz",
      "             bcz",
      "q          qkkcz",
      "q   d     qlmbcz",
      "fq         qkkcz",
      " q           bcz"
    ],
    [
      "     L       gcz",
      "             bcz",
      "            Mbcz",
      "            Mbcz",
      "             bcz",
      "           qkkcz",
      "    d     qlmbcz",
      "           qkkcz",
      "             bcz",
      "            Mbcz",
      "            Mbcz",
      "             bcz",
      "q          qkkcz",
      "q   d     qlmbcz",
      "fq         qkkcz",
      " q           bcz"
    ],
    [
      "             gcz",
      "             bcz",
      "             bcz",
      "            gbcz",
      "             bcz",
      "           qkkcz",
      "    d     qlmbcz",
      "           qkkcz",
      "             bcz",
      "            gbcz",
      "             bcz",
      "             bcz",
      "q          qkkcz",
      "q   d     qlmbcz",
      "fq         qkkcz",
      " q           bcz"
    ]
  ]
}