{
  "name": "multi_laboratory1_0_base7",
  "refpalette": "c70cities:multi_laboratory1_0_base7_palette",
  "xsize": 16,
  "zsize": 16,
  "slices": [
    [
      "zzzzzzzzzzzzzzzz",
      "zaaaaaaaaaaaabac",
      "zaaaaaaaaaaaaaca",
      "zaaaaaaaaaaaacaa",
      "zaaaaaaaaaaaacac",
      "zaaaaaaaaaacacac",
      "zaaaaaaaaaaaaccd",
      "zaaaaaaaaaaabdad",
      "zaaaaaaaaaabbcba",
      "zaaaaaaaaabbbecf",
      "zaaaaaaaacbbccff",
      "zaaaaaaaacbccbaa",
      "zaaaaaaaabcbbcaa",
      "zaaaaaaaccbbacaa",
      "zaaaaaaaccbaacaa",
      "zaaaaaacbbbaacaa"
    ],
    [
      "zzzzzzzzzzzzzzzz",
      "zaaaaaaaaaaaaaaa",
      "zaaaaaaaaaaagggg",
      "zaaaaaaaaaaaahij",
      "zaaaaaaaaaaad   ",
      "zaaaaaaaaadkl m ",
      "zaaaaaaaaaad    ",
      "zaaaaaaaaadn    ",
      "zaaaaaaaaod     ",
      "zaaaaaaaaaffd p ",
      "zaaaaaaaaaaaadqq",
      "zaaaaaaaaaaaafff",
      "zaaaaaaaaaaaaaaa",
      "zaaaaaaaafaaaaaa",
      "zaaaaaaafaaaaaaa",
      "zaaaafddfbaacaaa"
    ],
    [
      "zzzzzzzzzzzzzzzz",
      "zaaaaaaaaaaaaaaa",
      "zaaaaaaaaaaagggg",
      "zaaaaaaaaaaa    ",
      "zaaaaaaaaaad    ",
      "zaaaaaaaaa kr   ",
      "zaaaaaaaaf      ",
      "zaaaaaaafd      ",
      "zaaaaaaas       ",
      "zaaaaaaaad q    ",
      "zaaaaaaaaadfs  q",
      "zaaaaaaaaaafff q",
      "zaaaaasddfaaaaff",
      "zaaaaat dsfaaaaa",
      "zaaaaf   fcabaaa",
      "zaaafs   faabaaa"
    ],
    [
      "zzzzzzzzzzzzzzzz",
      "zaaaaaaaaaaaaaaa",
      "zaaaaaaaaaaagggg",
      "zaaaaaaaaaa     ",
      "zaaaaaaaaa      ",
      "zaaaaaaaaa k    ",
      "zaaaaaaafq      ",
      "zaaaaaaa        ",
      "zaaaaaaas       ",
      "zaaaaaaan    q  ",
      "zaaaaaaa   qs  q",
      "zaaaaaan  aaf qq",
      "zaaaaas  qaaafff",
      "zaaaaa   sfaaaaa",
      "zaaaf    qfaaaaa",
      "zaaaas   bbbaaaa"
    ],
    [
      "zzzzzzzzzzzzzzzz",
      "zaaaaaaaaaaaaaaa",
      "zaaaaaaaaaaagggg",
      "zaaaaaaaaaaa    ",
      "zaaaaaaaaaao    ",
      "zaaaaaaaaack    ",
      "zaaaaaaaaeo     ",
      "zaaaaaaaf       ",
      "zaaaaaaas      q",
      "zaaaaaaao   oq  ",
      "zaaaaaaa   qaoqq",
      "zaaaaaa   aaaaaf",
      "zaaaaas  qaaaaaa",
      "zaaaaao  sfaaaaa",
      "zaaaaa    aaaaaa",
      "zaaaas   eaaaaaa"
    ],
    [
      "zzzzzzzzzzzzzzzz",
      "zaaaaaaaaaaaaaaa",
      "zaaaaaaaaaaagggg",
      "zaaaaaaaaaaa    ",
      "zaaaaaaaaaaa    ",
      "zaaaaaaaaaakoo  ",
      "zaaaaaaaaaaaauoo",
      "zaaaaaaaaaaacafo",
      "zaaaaaaaaooaafaf",
      "zaaaaaaaaoaaafff",
      "zaaaaaaaaoaaaaff",
      "zaaaaaaaaaaaaaaa",
      "zaaaaaaaofaaaaaa",
      "zaaaaaaaaaaaaaaa",
      "zaaaaaaaaaaaaaaa",
      "zaaaaaaoaaaaaaaa"
    ]
  ]
}