{
  "name": "multi_laboratory1_14_base6",
  "refpalette": "c70cities:multi_laboratory1_14_base6_palette",
  "xsize": 16,
  "zsize": 16,
  "slices": [
    [
      "aaaabacdddddcaez",
      "faaaaacdddddcaez",
      "aaaaaacdddddcaez",
      "aaaaaacdddddcaez",
      "aaaaaacdddddcaez",
      "aaaaaacdddddcaez",
      "aaaaaacdddddcaez",
      "aaaabacdddddcaez",
      "aaaaaacccccccaez",
      "aaaaaaaaaaaaaaez",
      "aaaaaaaaaaaaaaez",
      "aaaaaaaaaaaaaaez",
      "aaaaaaaaaaaaaaez",
      "eeeeeaaaaaaaaaez",
      "ggggeeeeeeeeeeez",
      "zzzzzzzzzzzzzzzz"
    ],
    [
      "hijkb     l   dz",
      " mnop q rs    tz",
      "h   p    us   tz",
      "w  np   s   q tz",
      " n  p  x  rx  tz",
      "y ABp         tz",
      "C yhp   l  s  tz",
      " nhhb         dz",
      " m  p         tz",
      "    p       D tz",
      "    E  F      tz",
      "    I         tz",
      "    p        Jtz",
      "eeeepKKLLMNOL!tz",
      "ggggetttttttttez",
      "zzzzzzzzzzzzzzzz"
    ],
    [
      "    b         dz",
      "    P q       tz",
      "    P         tz",
      "    P       q tz",
      "    P  xQ Rx  tz",
      "    P         tz",
      "    P         tz",
      "  STb         dz",
      "    p       D tz",
      "    p         tz",
      "    U         tz",
      "    V         tz",
      "    p         tz",
      "eeeep         tz",
      "ggggetttttttttez",
      "zzzzzzzzzzzzzzzz"
    ],
    [
      "    b    W    dz",
      "    P q  W    tz",
      "    P   XYX   tz",
      "    P    W  q tz",
      "    P  RxxxQ  tz",
      "    P         tz",
      "    P    Y    tz",
      "   Zb   W W D dz",
      "    p   W W   tz",
      "    p         tz",
      "    0         tz",
      "    0         tz",
      "    p         tz",
      "eeeep         tz",
      "ggggetttttttttez",
      "zzzzzzzzzzzzzzzz"
    ],
    [
      "   1b 22343   dz",
      "      224 4   tz",
      "    P  54 46  tz",
      "    P   474 q tz",
      "    P   343   tz",
      "    P   8 8   tz",
      "    P   949 D tz",
      "    b  @#W#$  dz",
      "    p  @%  $  tz",
      "    p         tz",
      "    0         tz",
      "    0         tz",
      "    p         tz",
      "eeeep         tz",
      "ggggetttttttttez",
      "zzzzzzzzzzzzzzzz"
    ],
    [
      "   ^b  @494$  dz",
      "    P  &*9*(  tz",
      "    o  5*8*6  tz",
      "    P  &*9*(q tz",
      "    P  @434$  tz",
      "    P  @ ) $D tz",
      "    P  @4#4$  tz",
      "    b   @%$   dz",
      "    p         tz",
      "    p         tz",
      "    0         tz",
      "    0         tz",
      "    p         tz",
      "eeeep         tz",
      "ggggetttttttttez",
      "zzzzzzzzzzzzzzzz"
    ]
  ]
}