{
  "name": "multi_carservice_1_top",
  "refpalette": "c70cities:multi_carservice_1_top_palette",
  "xsize": 16,
  "zsize": 16,
  "slices": [
    [
      " abbbbbbbbbbbba ",
      " abbbbbbbbbbbba ",
      " abbbbbbbbbbbba ",
      " acdeecdeecbbbc ",
      "           fffe ",
      "           fffe ",
      "           fffe ",
      "            ffe ",
      "            ffe ",
      "            ffe ",
      "  c   c   ceeec ",
      "                ",
      "                ",
      "                ",
      "                ",
      "                "
    ],
    [
      " a   gh       i ",
      " a    hj      i ",
      " akll!lmn     a ",
      " acaaacaaacoooc ",
      "      p       p ",
      "      q       q ",
      "      q       q ",
      "      q       q ",
      "      q       q ",
      "      q       q ",
      "  cqqqcqqqcqqqc ",
      "                ",
      "                ",
      "                ",
      "                ",
      "                "
    ],
    [
      " i            i ",
      " i            i ",
      " c llllr      a ",
      " acaaacaaacoooc ",
      "                ",
      "                ",
      "                ",
      "                ",
      "                ",
      "                ",
      "  c   c   c   c ",
      "                ",
      "                ",
      "                ",
      "                ",
      "                "
    ],
    [
      " a    s   s   c ",
      " a    s   s   c ",
      " a tu s   s   c ",
      " acaaacaaacoooc ",
      "  s   s   s   s ",
      "  s   s   s   s ",
      "  s   s   s   s ",
      "  s   s   s   s ",
      "  s   s   s   s ",
      "  s   s   s   s ",
      "  c   c   c   c ",
      "                ",
      "                ",
      "                ",
      "                ",
      "                "
    ],
    [
      " awwwwwwwwwwwwa ",
      " awwwwwwwwwwwwa ",
      " awwwwwwwwwwwwa ",
      " aaaaaaaaaaxxxa ",
      "                ",
      "                ",
      "                ",
      "                ",
      "                ",
      "                ",
      "                ",
      "                ",
      "                ",
      "                ",
      "                ",
      "                "
    ],
    [
      " a            a ",
      " a            a ",
      " a            a ",
      " aaaaaaaaaaaaaa ",
      "                ",
      "                ",
      "                ",
      "                ",
      "                ",
      "                ",
      "                ",
      "                ",
      "                ",
      "                ",
      "                ",
      "                "
    ]
  ]
}