{
  "name": "multi_laboratory1_13_base6",
  "refpalette": "c70cities:multi_laboratory1_13_base6_palette",
  "xsize": 16,
  "zsize": 16,
  "slices": [
    [
      "aaabcababaaaadez",
      "aaaaaabaaaaaadez",
      "ffbfgffffffffhdz",
      "aaaaaaaaaaaaaadz",
      "abbiaaaaaaaaaadz",
      "abaaaaaaaaaaaadz",
      "abaaaaaaaaaaaadz",
      "aaabaaaaaaaaaadz",
      "aaaaaafffffffadz",
      "a!aagafjjjjjfadz",
      "aaaaaafjjjjjfadz",
      "aaaaaafjjjjjfadz",
      "aaaaaafjjjjjfadz",
      "aaaaaafjjjjjfadz",
      "aaaaaafjjjjjfadz",
      "a!aaaafjjjjjfadz"
    ],
    [
      "  kl mbb    ndez",
      " o bbb    k  pez",
      "  qbgqqqqqqqqqgz",
      " rbms        tuz",
      "w nxs   y y  tuz",
      " lbcs  ABBBA Cuz",
      "  bbs         uz",
      "  m s  D   D  uz",
      "xcmrs         uz",
      "mEF g        Ijz",
      "bJ  s         uz",
      "bb  s         uz",
      " b  s  K   K  uz",
      "b  ys L       uz",
      "b Mrs   N     uz",
      "bEOMs         uz"
    ],
    [
      "     nn      dez",
      "  Pnl        pez",
      "  PmgQQQQQQQQQgz",
      "  bbR         uz",
      "   nR         uz",
      "   nR  STUT   uz",
      "   VR         uz",
      "    R         uz",
      "nn  R         uz",
      "n   g         jz",
      "n   R         uz",
      "    R         uz",
      " n  R  KW XK  uz",
      "l   R         uz",
      "    R L       uz",
      "nY  Z         uz"
    ],
    [
      "             dez",
      "             pez",
      "   bgQQQQQQQQQgz",
      "   bR        0uz",
      "    R         uz",
      "    R         uz",
      "    R         uz",
      "    R         uz",
      "    R         uz",
      "    g         jz",
      "    R         uz",
      "    R    1    uz",
      "    R  XKKKW  uz",
      "    R         uz",
      "    R         uz",
      "    R L       uz"
    ],
    [
      "             dez",
      "             pez",
      "   bgQQQQQQQQQgz",
      "   xR         uz",
      "    R         uz",
      "    R         uz",
      "    R         uz",
      "    R         uz",
      "    R         uz",
      "    g         jz",
      "    R    2    uz",
      "    R   232   uz",
      "    R   343   uz",
      "    R   555   uz",
      "    R   545   uz",
      "    R   565   uz"
    ],
    [
      "             dez",
      "   P         pez",
      " PbbgQQQQQQQQQgz",
      "   nR         uz",
      "    R         uz",
      "    R         uz",
      "    R         uz",
      "    R         uz",
      "    R    2    uz",
      "    g    3    jz",
      "    R   272   uz",
      "    R  8393@  uz",
      "    R   434   uz",
      "    R   #5#   uz",
      "    R    4    uz",
      "    R  $ 9 %  uz"
    ]
  ]
}