{
  "name": "multi_pumpjack_2_ground",
  "refpalette": "c70cities:multi_pumpjack_2_ground_palette",
  "xsize": 16,
  "zsize": 16,
  "slices": [
    [
      "zzzzzzzzzzzzzzzz",
      "zzzzzzzzzzzzzzzz",
      "zzzzzzzzzzzzzzzz",
      "zzzzzzzzzzzzzzzz",
      "zzzzzzzzzzzzzzzz",
      "zzzzzzzzzzzzzzzz",
      "zzzzzzzzzzzzzzzz",
      "zzzzzzzzzzzzzzzz",
      "zzzzzzzzzzzzzzzz",
      "zzzzzzzzzzzzzzzz",
      "zzzzzzzzzzzzzzzz",
      "zzzzzzzzzzzzzzzz",
      "zzzzzzzzzzzzzzzz",
      "zzzzzzzzzzzzzzzz",
      "zzzzzzzzzzzzzzzz",
      "zzzzzzzzzzzzzzzz"
    ],
    [
      "                ",
      "a               ",
      "abbbabbbabbba   ",
      "cd          b   ",
      "c   e  fgggfb   ",
      "c      gggggh   ",
      "c     iggggga   ",
      "c     igggggh   ",
      "c      fgggfb   ",
      "c   j    k  b   ",
      "c     ~    ia   ",
      "c          ih   ",
      "c          db   ",
      "c        e lh   ",
      "c         lla   ",
      "c         mmhe  "
    ],
    [
      "                ",
      "a               ",
      "annnannnannna   ",
      "          o n   ",
      "       gggggn   ",
      "       g   gn   ",
      "      ig   ga   ",
      "       g   gn   ",
      "       gggggn   ",
      "         p  n   ",
      "      ~     a   ",
      "            n   ",
      "            n   ",
      "            n   ",
      "           la   ",
      "            n   "
    ],
    [
      "                ",
      "a               ",
      "annnan nannna   ",
      "         qoqn   ",
      "       gggggn   ",
      "       gggggn   ",
      "       ggggga   ",
      "       gggggn   ",
      "       gggggn   ",
      "            n   ",
      "      ~     a   ",
      "            n   ",
      "            n   ",
      "            n   ",
      "            a   ",
      "                "
    ],
    [
      "                ",
      "a               ",
      "a   r   r   r   ",
      "                ",
      "       ff  f    ",
      "       f   f    ",
      "       f   fr   ",
      "       f   f    ",
      "       fffff    ",
      "                ",
      "      ~     r   ",
      "                ",
      "                ",
      "                ",
      "            r   ",
      "                "
    ],
    [
      "                ",
      "a               ",
      "a               ",
      "                ",
      "                ",
      "                ",
      "                ",
      "                ",
      "                ",
      "                ",
      "      ~         ",
      "                ",
      "                ",
      "                ",
      "                ",
      "                "
    ]
  ]
}