{
  "name": "multi_laboratory1_11_base4",
  "refpalette": "c70cities:multi_laboratory1_11_base4_palette",
  "xsize": 16,
  "zsize": 16,
  "slices": [
    [
      "aaaaaaaaaaaaabcz",
      "aaaaaaaaaaaaabcz",
      "aaaaaaaaaaaaabcz",
      "aaaaaaaaaaaaabcz",
      "aaaaaaaaaaaaabcz",
      "aaaaaaaaaaaaabcz",
      "aaaadaaaaaaaabcz",
      "aaaaaaaaaaaaabcz",
      "aaaaaaaaaaaaabcz",
      "aaaaaaaaaaaaabcz",
      "aaaaaaaaaaaaabcz",
      "aaaaaaaaaaaaabcz",
      "eaaaaaaaaaaaabcz",
      "eaaadaaaaaaaabcz",
      "feaaaaaaaaaaabcz",
      " eaaaaaaaaaaabcz"
    ],
    [
      "    ghiiiiiihbcz",
      "    gj      ibcz",
      "    gk      ibcz",
      "    g       ibcz",
      "    l       ibcz",
      "    gmnnnnnnhbcz",
      "   fdggggggggbcz",
      "o   gpp p p qbcz",
      "    g        bcz",
      "    g  r s  ttcz",
      "    guwwwxytABcz",
      "    gCwwwDEFABcz",
      "IJ  g KLDMNOttcz",
      "If  dPysxDMQqbcz",
      "fI  g   sxDxsbcz",
      " I  R    sxsttcz"
    ],
    [
      "    ghiiiiiihbcz",
      "    S       ibcz",
      "    ST      ibcz",
      "    g       ibcz",
      "    U       ibcz",
      "    gV     Whbcz",
      "   Xdggggggggbcz",
      "    g       qbcz",
      "    S       Ybcz",
      "    S       Itcz",
      "    S ZZ0  IABcz",
      "    S1ZyZ   ABcz",
      "I   g       Qtcz",
      "IX  d       qbcz",
      "fI  g       Ybcz",
      " I  R       Itcz"
    ],
    [
      "    gh222222hbcz",
      "    3       4bcz",
      "    3       5bcz",
      "    g       6bcz",
      "    3       7bcz",
      "    g       hbcz",
      "   Xdggggggggbcz",
      "    g       qbcz",
      "    S        bcz",
      "    S       Itcz",
      "    S      IABcz",
      "    S      8ABcz",
      "I   g       Itcz",
      "IX  d       qbcz",
      "fI  g        bcz",
      " I  R       Itcz"
    ],
    [
      "    gh      hbcz",
      "    g        bcz",
      "    g        bcz",
      "    g        bcz",
      "    g        bcz",
      "    g       hbcz",
      "    dggggggggbcz",
      "    g  9  9 @bcz",
      "    g       Ybcz",
      "    g       Itcz",
      "    g      I#Bcz",
      "    g      I#Bcz",
      "I   g       Itcz",
      "I   d       @bcz",
      "fI  g       Ybcz",
      " I  g       Itcz"
    ],
    [
      "$$$$3%%%%%%%%bcz",
      "$$^$3%&%%%%!%bcz",
      "$$^$3%%%%%%%%bcz",
      "$$^$3%%%%%%%%bcz",
      "$$^$3%&%%%%&%bcz",
      "$$$$3%%%%%%%%bcz",
      "$$$$dggggggggbcz",
      "$$$$3********bcz",
      "$$$$3((((((((bcz",
      "$$$$3((^((^(ttcz",
      "$$$$3((^(()t+Bcz",
      "$$$$3((^((^t+Bcz",
      "I$$$3(()(()(ttcz",
      "I$$$d((((((((bcz",
      "fI$$3((((((((bcz",
      " I$$3((^((^(ttcz"
    ]
  ]
}