{
  "name": "multi_megatower1_7_floor9",
  "refpalette": "c70cities:multi_megatower1_7_floor9_palette",
  "xsize": 16,
  "zsize": 16,
  "slices": [
    [
      "aaabc           ",
      "aaabd           ",
      "aaabd           ",
      "aaabd           ",
      "eefghi          ",
      "eeabc           ",
      "eeabc           ",
      "eeabc           ",
      "eeabd           ",
      "eeabd           ",
      "eeabd           ",
      "eefghi          ",
      "aaabc           ",
      "aaabc           ",
      "aaabc           ",
      "aaabd           "
    ],
    [
      "jkl c           ",
      " kl d           ",
      " ml d           ",
      "nnl d           ",
      "oof i           ",
      "ppl c           ",
      " ql c           ",
      "ppl c           ",
      " ql d           ",
      "ppl d           ",
      " ql d           ",
      "oof i           ",
      "rsl c           ",
      "  l c           ",
      "  l c           ",
      "t l d           "
    ],
    [
      " kl c           ",
      " ml d           ",
      "  l d           ",
      "nnl d           ",
      "oof i           ",
      "ppl c           ",
      "  l c           ",
      "ppl c           ",
      "  l d           ",
      "ppl d           ",
      "  l d           ",
      "oof i           ",
      " ul c           ",
      "  w c           ",
      "  w c           ",
      "  w d           "
    ],
    [
      " jl c           ",
      " ml d           ",
      "  l d           ",
      " nl d           ",
      "oof i           ",
      "ppl c           ",
      "  l c           ",
      "ppl c           ",
      "  l d           ",
      "ppl d           ",
      "  l d           ",
      "oof i           ",
      " ul c           ",
      "  x c           ",
      "  x c           ",
      "  x d           "
    ],
    [
      "yyl c           ",
      "yyl d           ",
      "Ayl d           ",
      "yyl d           ",
      "oof i           ",
      "BBl c           ",
      "BCl c           ",
      "BBl c           ",
      "BCl d           ",
      "BBl d           ",
      "BCl d           ",
      "oof i           ",
      "  l c           ",
      "  l c           ",
      "  l c           ",
      "  l d           "
    ],
    [
      " DE c           ",
      "jDE d           ",
      "FDE d           ",
      "jDE d           ",
      "IIfhi           ",
      "jDE c           ",
      "DDE c           ",
      "jDE c           ",
      "DDE d           ",
      " DE d           ",
      "DDE d           ",
      "IIfhi           ",
      "yyE c           ",
      "AyE c           ",
      "yyE c           ",
      "yyE d           "
    ]
  ]
}