{
  "name": "multi_militarybase_1_base2",
  "refpalette": "c70cities:multi_militarybase_1_base2_palette",
  "xsize": 16,
  "zsize": 16,
  "slices": [
    [
      "vaaaaaaaaabbbc  ",
      "vaaaaaaaaabbbc  ",
      "vvcccvcccccccvcc",
      "vaaaacaaaabbbcbb",
      "vaaaacaaaabbbcbb",
      "vaaaacaaaaabbcbb",
      "vaaaacaaaaaadvee",
      "vaaaacaaaaaaacaa",
      "vaaaacaaaaaaacaa",
      "vaaaacaaaaaaacaa",
      "vvcccvcccccccvcc",
      "vaaaacaaaaaaacff",
      "vaaaacaaaaaaacff",
      "vaaaacaaaaaaacff",
      "vaaaavaaaaaaavff",
      "vvvvvvvvvvvvvvvv"
    ],
    [
      "v      ggh   i  ",
      "vjkkk   h    i  ",
      "vvlllv       vii",
      "vm no  h        ",
      "vm     gg       ",
      "vm pp  ggh      ",
      "vm     h    dvqr",
      "vm pp          s",
      "vm              ",
      "vm tu           ",
      "vvqqqvqqqwqqqvqq",
      "vxyxABCCC DEFIJ ",
      "vK   L    M NIqq",
      "vO   B PP D  IJ ",
      "v!OQQvRSSRDTUvqq",
      "vvvvvvvvvvvvvvvv"
    ],
    [
      "v               ",
      "vkkjk           ",
      "vvlllv       v  ",
      "vm              ",
      "vm              ",
      "vm              ",
      "vm          dvqr",
      "vm             s",
      "vm              ",
      "vm              ",
      "vvqqqvqqqVqqqvqq",
      "v    B!W  DX I  ",
      "v    Y    Z  Iqq",
      "v    B    D 0I  ",
      "vO1  v    D 2vqq",
      "vvvvvvvvvvvvvvvv"
    ],
    [
      "v               ",
      "vk3kk           ",
      "vvlllv       v  ",
      "vm              ",
      "vm              ",
      "vm              ",
      "vm          dvqq",
      "vm              ",
      "vm              ",
      "vm              ",
      "vvqqqvqqqqqqqvqq",
      "v    B    DX I  ",
      "v    B    D  Iqq",
      "v    B    D  I  ",
      "v    v    D 4vqq",
      "vvvvvvvvvvvvvvvv"
    ],
    [
      "v            5  ",
      "v6           5  ",
      "vvlllv       v55",
      "v    i          ",
      "v    i          ",
      "v    i          ",
      "v    i      dvii",
      "v    i       i  ",
      "v    i       i  ",
      "v7   i       i  ",
      "vvqqqviiiiiiivqq",
      "v    B    D  I88",
      "v    B    D  I88",
      "v    B    D  I88",
      "v    v    D  v88",
      "vvvvvvvvvvvvvvvv"
    ],
    [
      "v9@@@@@@@@@@@#  ",
      "v9@@@@@@@@@@@#  ",
      "vvcccvcccccccv##",
      "v9@@@c@@@@@@@c@@",
      "v9@@@c@@@@@@@c@@",
      "v9@@@c@@@@@@@c@@",
      "v9@@@c@@@@@@dv@@",
      "v9@@@c@@@@@@@c@@",
      "v9@@@c@@@@@@@c@@",
      "v9@@@c@@@@@@@c@@",
      "vvcccvcccccccvcc",
      "v9@@@c@@@@@@@c66",
      "v9@@@c@@@@@@@c  ",
      "v9@@@c@@@@@@@c6 ",
      "v9999v9999999v99",
      "vvvvvvvvvvvvvvvv"
    ]
  ]
}