{
  "name": "multi_clubhouse1_4_base2",
  "refpalette": "c70cities:multi_clubhouse1_4_base2_palette",
  "xsize": 16,
  "zsize": 16,
  "slices": [
    [
      "vvvvvvvvvvvvvvvv",
      "vvvvvvvvvvvvvvvv",
      "vvvvvvvvvvvvvvvv",
      "vvvvvvvvvvvvvvvv",
      "vvvvvvvvvvvvvvvv",
      "vvvvvvvvvvvvvvvv",
      "vvvvvvvvvvvvvvvv",
      "vvvvvvvvvvvvvvvv",
      "vvvvvvvvvvvvvvvv",
      "vvvvvvvvvvvvvvvv",
      "vvvvvvvvvvvvvvvv",
      "vvvvvvvvvvvvvvvv",
      "vvvvvvvvvvvvvvvv",
      "vvvvvvvvvvvvvvvv",
      "vvvvvvvvvvvvvvvv",
      "vvvvvvvvvvvvvvvv"
    ],
    [
      "aaaaaaaaaaaaaaaa",
      "aaaaaaaaaaaaaaaa",
      "aaaaaaaaaaaaaaaa",
      "aaaaaaaaaaaaaaaa",
      "aaaaaaaaaaaaaaaa",
      "aaaaaaaaaaaaaaaa",
      "baaaaaaaaaaaaaaa",
      "bbbbbbbccbbbbbbb",
      "bbbbbbbccbdbbbbb",
      "bbbbbbdccbbbbbbb",
      "bbbbbbbccdbbbbbb",
      "bbbbbbbccbbbbbbb",
      "bbbbbbdccdbbbbbb",
      "bbbbbdbccddbbGGG",
      "bbbbbbdccbdbbGGG",
      "bbbbbbdccdbbbGGG"
    ],
    [
      "aaaaaaaaaaaaaaaa",
      "aaaaaaaaaaaaaaaa",
      "aaaaaaaaaaaaaaaa",
      "aaaaaaaaaaaaaaaa",
      "bbbbbbbbbbbbbbbb",
      "bbbbbbbbbbbbbbbb",
      " bbbbbbbbbbbbbbb",
      "e   bbbbbbbb    ",
      "      ffff    e ",
      "  e e  g        ",
      "e     g         ",
      "     h    g     ",
      "iiii    h   iiii",
      "jjki   g    iljj",
      "mjmin    h oijjm",
      " jjip      qijjj"
    ],
    [
      "aaaaaaaaaaaaaaaa",
      "bbbbbbbbbbbbbbbb",
      "bbbbbbbbbbbbbbbb",
      "bbbbbbbbbbbbbbbb",
      "  bbbbbbbbbbbbbb",
      "      ffff  ee  ",
      "                ",
      "     e     e    ",
      "                ",
      "                ",
      "                ",
      "                ",
      "                ",
      "rr           srr",
      " r           rr ",
      " rr          rrr"
    ],
    [
      "bbbbbbbbbbbbbbbb",
      "bbbbbbbbbbbbbbbb",
      "  ebbbbbbbbbbbbb",
      "    e ffff   eee",
      "            e ee",
      "                ",
      "                ",
      "                ",
      "                ",
      "                ",
      "                ",
      "                ",
      "                ",
      "                ",
      "                ",
      "                "
    ],
    [
      "    bbbbbbbbbbbb",
      "ee    ffff     e",
      "               e",
      "                ",
      "                ",
      "                ",
      "                ",
      "                ",
      "                ",
      "                ",
      "                ",
      "                ",
      "                ",
      "                ",
      "                ",
      "                "
    ]
  ]
}