{
  "name": "multi_laboratory1_3_ground",
  "refpalette": "c70cities:multi_laboratory1_3_ground_palette",
  "xsize": 16,
  "zsize": 16,
  "slices": [
    [
      "zaazzavvbbbcdddd",
      "zzzaaaevbbbcdddd",
      "zazzzaevbbbcdddd",
      "zzzzaaaebbbcdddd",
      "azzazzavbbbcdddd",
      "zzaaaaevbbbcdddd",
      "zazfaaevbbbcdddd",
      "zzaazaavbbbcdddd",
      "azzaaaevbbbcdddd",
      "zzzazeeebbbcdddd",
      "zazzaaevbbbcdddd",
      "zzzazaevbbbcdddd",
      "zzaaaaeebbbcdddd",
      "zzzazaavbbbcdddd",
      "azazazvvbbbcdddd",
      "zzzazzevbbbcdddd"
    ],
    [
      "g   h   i  j klm",
      " g      i  j    ",
      "g  g    i  cn o ",
      "g g     i  j    ",
      " h      i  pqqqq",
      "gr hs   t  juwww",
      "g xy r     pAwBC",
      " g x D     pqqqq",
      " DgE       j    ",
      "    g      c   F",
      "           j  IJ",
      "g          j KI!",
      "g          j  IL",
      "  M g      j  IL",
      "           j KIL",
      "     g     j  IN"
    ],
    [
      "        i  j    ",
      "        i  j    ",
      "        i  c    ",
      "        O  P    ",
      "        i  pqQQQ",
      "        i  j www",
      "        t  j R  ",
      "           pqqqq",
      "           P    ",
      "           c    ",
      "           j    ",
      "           j  S ",
      "           j  T ",
      "  ~        j    ",
      "           j    ",
      "           j    "
    ],
    [
      "        O  j    ",
      "        O  j    ",
      "        U  c    ",
      "        O  P    ",
      "        O  pqVVV",
      "        O  jRw w",
      "        i  j    ",
      "        t  pqqqq",
      "           P    ",
      "           c    ",
      "           j    ",
      "           j    ",
      "           j    ",
      "           j    ",
      "           j    ",
      "           j    "
    ],
    [
      "        U  j    ",
      "        U  j    ",
      "        O  c    ",
      "        U  P    ",
      "        U  pqqqq",
      "        O  jR   ",
      "        U  j    ",
      "        i  pqqqq",
      "        t  P    ",
      "           c    ",
      "           j    ",
      "           j    ",
      "           j    ",
      "           j    ",
      "           j    ",
      "           j    "
    ],
    [
      "        U  jWXXX",
      "        U  jWXXX",
      "        U  cWWWW",
      "        U  jWWWW",
      "        O  pqqqq",
      "        O  j R  ",
      "        O  jR   ",
      "        O  pqqqq",
      "        i  jWWWW",
      "        t  cWWWW",
      "           jWXXX",
      "           jWXXX",
      "           jWWWW",
      "           jWWWW",
      "           jWXXX",
      "           jWXXX"
    ]
  ]
}