{
  "name": "multi_hospital_2_ground",
  "refpalette": "c70cities:multi_hospital_2_ground_palette",
  "xsize": 16,
  "zsize": 16,
  "slices": [
    [
      "GGGGGGGGGGGGGGGG",
      "aaaaaaaaaaaaaaaG",
      "aaaabbbbbbbbbbaG",
      "caaabbbbbbbbbbaG",
      "daaadGGdGGdGGdaG",
      "caaaaaaaaaaaaaaG",
      "caaaaaaaaaaaaaaG",
      "caaaaaaaaaaaaaaG",
      "caaaaaaaaaaaaaaG",
      "cceeeeeeeeeeeeaG",
      "cceeee!eeeeeeeaG",
      "cceeeeeeeeeeeeaG",
      "cceeeeeeeeeeeeaG",
      "cceeeeeeeeeeeeaG",
      "ccccccccccccccaG",
      "ccccccccccccccaG"
    ],
    [
      "  f    f  f  f  ",
      "                ",
      " g              ",
      "hi   jk jk jk   ",
      "li  mmmmmmmmmm f",
      " i              ",
      " n             f",
      " i              ",
      "ohhhhhhhhhhhhhp ",
      " q   q   q   rp ",
      " r s r s r s rpf",
      "truuiruuiruu rp ",
      "trww rww r w rp ",
      "trx  rx  ry  rpf",
      "ArBBCBBBDBBBCBp ",
      "            EGF "
    ],
    [
      "                ",
      "                ",
      " g              ",
      "hi              ",
      "li              ",
      " i              ",
      " I              ",
      " i              ",
      "ohhJJhhJJhhJJhp ",
      " K   K   K   rp ",
      " r   r   r   rp ",
      " rLM rNM r   rp ",
      " r   r   rO  rp ",
      " rO  rO  r   rp ",
      " rBBPBBBQBBBPBp ",
      "             RS "
    ],
    [
      "                ",
      "                ",
      " g              ",
      "hi              ",
      "li              ",
      " i              ",
      " i              ",
      " i              ",
      "ohhJJhhJJhhJJhp ",
      " T   T   T   rp ",
      " r   r   r   rp ",
      " r   r   r   rp ",
      " r   r   r   rp ",
      " r   r   r   rp ",
      " rBBUBBBUBBBUBp ",
      "             VS "
    ],
    [
      "                ",
      "                ",
      " g              ",
      "hi              ",
      " i              ",
      " i              ",
      " i              ",
      " i              ",
      "ohhhhhhhhhhhhhp ",
      " r   r   r   rp ",
      " r   r   r   rp ",
      " r   r   r   rp ",
      " r   r   r   rp ",
      " r   r   r   rp ",
      " rBBBBBBBBBBBBp ",
      "              S "
    ],
    [
      "                ",
      "                ",
      " g              ",
      "hi              ",
      " i              ",
      " i              ",
      " i              ",
      " i              ",
      "oWXXXXXXXXXXXXp ",
      " r           rp ",
      " r           rp ",
      " r           rp ",
      " r           rp ",
      " r           rp ",
      " rBBBBBBBBBBBBp ",
      "              S "
    ]
  ]
}