{
  "name": "multi_hospital_0_base2",
  "refpalette": "c70cities:multi_hospital_0_base2_palette",
  "xsize": 16,
  "zsize": 16,
  "slices": [
    [
      "vvvvvvvvvvvvvvvv",
      "vvvvvvvvvvvvvvvv",
      "vvvvvvvvvvvvvvvv",
      "vvvvvvvvvvvvvvvv",
      "vvvvvvvvvvvvvvvv",
      "vvvvvvvvvvvvvvvv",
      "vvvvvvvvvvvvvvvv",
      "vvvvvvvvvvvvvvvv",
      "vvvvvvvvvaaaavvv",
      "vvvvvvvvvabbavvv",
      "vvvvvvvvvabbavvv",
      "vvvvvvvvvaacavvv",
      "vvvvvvvvvvvvvvvv",
      "vvvvvvvvvvvvvvvv",
      "vvvvvvvvvvvvvvvv",
      "vvvvvvvvvvvvvvvv"
    ],
    [
      "vvvvvvvvvvvvvvvv",
      "vddddddddddddddd",
      "vddddddddddddddd",
      "vddddddddeeeeeee",
      "vddddddddeffffff",
      "vddddddddeffffff",
      "vddddddddeffffff",
      "vddddddddeffffff",
      "vddddddddfaaafff",
      "vddddddddabbgfff",
      "vddddddddabbgfff",
      "vddddddddabaafff",
      "vddddddddevvefff",
      "vddddddddeffffff",
      "vddddddddeffffff",
      "vddddddddeffffff"
    ],
    [
      "vvvvvvvvvvvvvvvv",
      "vddddddddddddddd",
      "vddddddddddddddd",
      "vddddddddeeeeeee",
      "vdddddddde  h h ",
      "vddddddddeijjjj ",
      "vdddddddde jjjjk",
      "vdddddddde l l  ",
      "vddddddddfaaa   ",
      "vddddddddam n   ",
      "vdddddddda  o   ",
      "vdddddddda aa   ",
      "vddddddddevvp   ",
      "vddddddddeppp   ",
      "vdddddddde      ",
      "vddddddddejk  j "
    ],
    [
      "vvvvvvvvvvvvvvvv",
      "vddddddddddddddd",
      "vddddddddddddddd",
      "vddddddddeeeeeee",
      "vdddddddde      ",
      "vdddddddde q  r ",
      "vdddddddde s q  ",
      "vdddddddde      ",
      "vddddddddfaaa   ",
      "vdddddddda  t   ",
      "vdddddddda  u   ",
      "vdddddddda aaw  ",
      "vddddddddevvp   ",
      "vddddddddeppp   ",
      "vdddddddde      ",
      "vdddddddde    x "
    ],
    [
      "vvvvvvvvvvvvvvvv",
      "vddddddddddddddd",
      "vddddddddddddddd",
      "vddddddddeeeeeee",
      "vdddddddde      ",
      "vdddddddde      ",
      "vdddddddde      ",
      "vdddddddde      ",
      "vddddddddfaaa   ",
      "vdddddddda  y   ",
      "vdddddddda  y   ",
      "vdddddddda aa   ",
      "vddddddddevvp   ",
      "vddddddddeppp   ",
      "vdddddddde      ",
      "vdddddddde      "
    ],
    [
      "vvvvvvvvvvvvvvvv",
      "vddddddddddddddd",
      "vddddddddddddddd",
      "vddddddddeeeeeee",
      "vddddddddeAAAAAA",
      "vddddddddeAAAAAA",
      "vddddddddeAAAAAA",
      "vddddddddeAAAAAA",
      "vddddddddfaaaAAA",
      "vdddddddda  aAAA",
      "vdddddddda  aAAA",
      "vdddddddda caAAA",
      "vddddddddevvpAAA",
      "vddddddddepppAAA",
      "vddddddddeAAAAAA",
      "vddddddddeAAAAAA"
    ]
  ]
}