{
  "name": "multi_megatower1_3_base2",
  "refpalette": "c70cities:multi_megatower1_3_base2_palette",
  "xsize": 16,
  "zsize": 16,
  "slices": [
    [
      "vvvvvvvvvvvvvvvv",
      "aaaaaaaaaaaaaaaa",
      "aaaaaaaaaaaaaaaa",
      "vvvvvvvvvvvvvvvv",
      "vvvvvvvvvvvvvvvv",
      "HHHHHHHHHHHHHHHH",
      "HHHHbHHHHHHbHHHH",
      "HHHHHHHHHHHHHHHH",
      "HHHHHHHHHHHHHHHH",
      "HHHHHHHHHHHHHHHH",
      "HHHHHHHHHHHHHHHH",
      "HHHHHHHHHHHHHHHH",
      "HHHHHHHHHHHHHHHH",
      "vvvvbHHHHHHbHHHH",
      "vcccvHHHHHHHHHHH",
      "vdddvHHHHHHHHHHH"
    ],
    [
      "vvvvvvvvvvvvvvvv",
      "aaaaaaaaaaaaaaaa",
      "aaaaaaaaaaaaaaaa",
      "vvvvvvvvvvvvvvvv",
      "eeeeeeeeeeeeeeee",
      "fgfg fgfgfg fgfg",
      "    b      b    ",
      "hihijhihihijhihi",
      "                ",
      "                ",
      "                ",
      "                ",
      "    kfgfgfgkfgfg",
      "llllb   m  b    ",
      "ncccohihihi hihi",
      "ndppo           "
    ],
    [
      "vvvvvvvvvvvvvvvv",
      "aaaaaaaaaaaaaaaa",
      "aaaaaaaaaaaaaaaa",
      "vvvvvvvvvvvvvvvv",
      "                ",
      "                ",
      "    b      b    ",
      "                ",
      "                ",
      "                ",
      "                ",
      "                ",
      "                ",
      "llllb      b    ",
      "nccco           ",
      "ndppo           "
    ],
    [
      "vvvvvvvvvvvvvvvv",
      "aaaaaaaaaaaaaaaa",
      "aaaaaaaaaaaaaaaa",
      "vvvvvvvvvvvvvvvv",
      "                ",
      "                ",
      "    b      b    ",
      "                ",
      "                ",
      "                ",
      "                ",
      "                ",
      "                ",
      "llllb      b    ",
      "nccco           ",
      "ndppo           "
    ],
    [
      "vvvvvvvvvvvvvvvv",
      "aaaaaaaaaaaaaaaa",
      "aaaaaaaaaaaaaaaa",
      "vvvvvvvvvvvvvvvv",
      "                ",
      "    q      q    ",
      "    b      b    ",
      "                ",
      "                ",
      "                ",
      "                ",
      "                ",
      "                ",
      "llllb      b    ",
      "nccco           ",
      "ndddo           "
    ],
    [
      "vvvvvvvvvvvvvvvv",
      "aaaaaaaaaaaaaaaa",
      "aaaaaaaaaaaaaaaa",
      "vvvvvvvvvvvvvvvv",
      "vvvvvvvvvvvvvvvv",
      "rrrrrrrrrrrrrrrr",
      "bbbbbbbbbbbbbbbb",
      "rrrrbrrrrrrbrrrr",
      "rrrrbrrrrrrbrrrr",
      "rrrrbrrrrrrbrrrr",
      "rrrrbrrrrrrbrrrr",
      "rrrrbrrrrrrbrrrr",
      "rrrrbrrrrrrbrrrr",
      "bbbbbbbbbbbbbbbb",
      "bcccbrrrrrrrrrrr",
      "b   brrrrrrrrrrr"
    ]
  ]
}