{
  "name": "multi_convenientstore_0_ground",
  "refpalette": "c70cities:multi_convenientstore_0_ground_palette",
  "xsize": 16,
  "zsize": 16,
  "slices": [
    [
      "GGGHHHaGGGGGGGGG",
      "GGGHHHaGGGGGGGGG",
      "GGHHHHaaaaaaaaaa",
      "GGHHHHHHHHHHHHHH",
      "GGHHHHHHHHHHHHHH",
      "GGHHHHHHHHHHHHHH",
      "GGHHHHHHHHHHHHHH",
      "GGHHHHHHHHHHHHHH",
      "GGHHHHHHHHHHHHHH",
      "GGHHHHHHHHHHHHHH",
      "GGHHHHHHHHHHHHHH",
      "GGHHHHHHHHHHHHHH",
      "GGHHHHHHHHHHHHHH",
      "GGHHHHHHHHHHHHHH",
      "GGHHHHHHHHHHHHHH",
      "GGHHHHHHHHHHHHHH"
    ],
    [
      "b     c  b      ",
      "bdb   c         ",
      "      ccccc cccc",
      "b      efefefefe",
      "                ",
      "       ghghghghg",
      "d               ",
      "b               ",
      "                ",
      "                ",
      "       efefefefe",
      " d      i       ",
      " b     ghghghghg",
      "     ccccccccccc",
      "b    caaaaaaaaaa",
      "     caaaaaaaaaa"
    ],
    [
      "                ",
      " ~              ",
      "                ",
      "                ",
      "                ",
      "                ",
      "~               ",
      "                ",
      "                ",
      "                ",
      "                ",
      " ~              ",
      "                ",
      "                ",
      "                ",
      "         j  j k "
    ],
    [
      "                ",
      "                ",
      "                ",
      "                ",
      "                ",
      "                ",
      "                ",
      "                ",
      "                ",
      "                ",
      "                ",
      "                ",
      "                ",
      "                ",
      "                ",
      "              k "
    ],
    [
      "                ",
      "                ",
      "                ",
      "                ",
      "                ",
      "                ",
      "                ",
      "                ",
      "                ",
      "                ",
      "                ",
      "                ",
      "                ",
      "                ",
      "                ",
      "              lm"
    ],
    [
      "                ",
      "                ",
      "                ",
      "                ",
      "                ",
      "                ",
      "                ",
      "                ",
      "                ",
      "                ",
      "                ",
      "                ",
      "                ",
      "                ",
      "                ",
      "                "
    ]
  ]
}