{
  "name": "multi_megatower1_3_floor10",
  "refpalette": "c70cities:multi_megatower1_3_floor10_palette",
  "xsize": 16,
  "zsize": 16,
  "slices": [
    [
      "                ",
      "                ",
      "                ",
      "                ",
      "                ",
      "                ",
      "                ",
      "                ",
      "                ",
      "                ",
      "    a      a    ",
      "bcccdbbbcccdbbbc",
      "eeeefeeeeeefeeee",
      "gggghgggggghgggg",
      "ijjjgggggggggggg",
      "i   gggggggggggg"
    ],
    [
      "                ",
      "                ",
      "                ",
      "                ",
      "                ",
      "                ",
      "                ",
      "                ",
      "                ",
      "                ",
      "    a      a    ",
      "bcccdbbbcccdbbbc",
      "                ",
      "klmnhoooooohpppp",
      "ijjjqr  s tuw  x",
      "i   qy ssA uB   "
    ],
    [
      "                ",
      "                ",
      "                ",
      "                ",
      "                ",
      "                ",
      "                ",
      "                ",
      "                ",
      "                ",
      "    a      a    ",
      "bcccdbbbcccdbbbc",
      "                ",
      "k   hoooooohpCCC",
      "ijjjq     Duw   ",
      "i   q      u    "
    ],
    [
      "                ",
      "                ",
      "                ",
      "                ",
      "                ",
      "                ",
      "                ",
      "                ",
      "                ",
      "                ",
      "    a      a    ",
      "bcccdbbbcccdbbbc",
      "                ",
      "k   hoooooohpEEE",
      "ijjjq     Du    ",
      "i   q      u    "
    ],
    [
      "                ",
      "                ",
      "                ",
      "                ",
      "                ",
      "                ",
      "                ",
      "                ",
      "                ",
      "                ",
      "    a      a    ",
      "bcccdbbbcccdbbbc",
      "                ",
      "k   hpppppphpppp",
      "ijjjFIIIIIIJIIII",
      "i   FIKII IJILII"
    ],
    [
      "                ",
      "                ",
      "                ",
      "                ",
      "                ",
      "                ",
      "                ",
      "                ",
      "                ",
      "                ",
      "    a      a    ",
      "bcccdbbbcccdbbbc",
      "    M      M    ",
      "NNNNhNNNNNNhNNNN",
      "OPPPO    QRO Q Q",
      "O   O S QSRO S Q"
    ]
  ]
}