{
  "name": "multi_condo1_5_floor7",
  "refpalette": "c70cities:multi_condo1_5_floor7_palette",
  "xsize": 16,
  "zsize": 16,
  "slices": [
    [
      "aaaaabccccccde  ",
      "ffffffffffffde  ",
      "      d     dggg",
      "      d     d   ",
      "      d     d   ",
      "      d     d   ",
      "      d     d   ",
      "      d     d   ",
      "      d     d   ",
      "      d     d   ",
      "      d     d   ",
      "     dddddddd   ",
      "      d         ",
      "                ",
      "                ",
      "                "
    ],
    [
      "      h  i  j   ",
      "      ddddddd   ",
      "      d     dggg",
      "      d     d   ",
      "      d     d   ",
      "      d     d   ",
      "      d     d   ",
      "      d     d   ",
      "      d     d   ",
      "      d     d   ",
      "      d     d   ",
      "     dddkkkdd   ",
      "      d         ",
      "                ",
      "                ",
      "                "
    ],
    [
      "      l  m  n   ",
      "      ddddddd   ",
      "      d     dggg",
      "      d     d   ",
      "      d     d   ",
      "      d     doo ",
      "      d     d   ",
      "      d     d   ",
      "      d     d   ",
      "      d     d   ",
      "      d     d   ",
      "     dddpppdd   ",
      "      d         ",
      "                ",
      "                ",
      "                "
    ],
    [
      "      d  q  n   ",
      "      ddddddd   ",
      "      d     dggg",
      "      d     d   ",
      "      d     d   ",
      "      d     doo ",
      "      d     doo ",
      "      d     doo ",
      "      d     doo ",
      "      d     doo ",
      "      d     doo ",
      "ddddddddpppddoo ",
      "ooooooooooooooo ",
      "ooooooooooooooo ",
      "                ",
      "                "
    ],
    [
      "      d  d  d   ",
      "      ddddddd   ",
      "      d     dggg",
      "      d     d   ",
      "      d     d   ",
      "      d     d   ",
      "      d     d   ",
      "      d     d   ",
      "      d     d   ",
      "      d     d   ",
      "      d     d   ",
      "ddddddddddddd   ",
      "                ",
      "                ",
      "                ",
      "                "
    ],
    [
      "      drrrrrd   ",
      "      ddddddd   ",
      "      d     dggg",
      "      d     ds  ",
      "      d     ds  ",
      "      d     ds  ",
      "      d     ds  ",
      "      d     ds  ",
      "      d     ds  ",
      "      d     ds  ",
      "      d     ds  ",
      "ddddddddddddds  ",
      "ssssssssssssss  ",
      "                ",
      "                ",
      "                "
    ]
  ]
}