{
  "name": "multi_megatower1_1_floor1",
  "refpalette": "c70cities:multi_megatower1_1_floor1_palette",
  "xsize": 16,
  "zsize": 16,
  "slices": [
    [
      "            ab  ",
      "            cb  ",
      "            cbde",
      "            cbff",
      "           ghibb",
      "            abbb",
      "            abbb",
      "            abbb",
      "            cbbb",
      "            cbbb",
      "            cbbb",
      "           ghibb",
      "            abbb",
      "            abbb",
      "            abbb",
      "            cbbb"
    ],
    [
      "            aj  ",
      "            cj  ",
      "            cj  ",
      "            cj  ",
      "           ghick",
      "            alm ",
      "            aln ",
      "            alop",
      "            clqp",
      "            cln ",
      "            clm ",
      "           ghir ",
      "            als ",
      "            als ",
      "            alt ",
      "            clt "
    ],
    [
      "            aj  ",
      "            cj  ",
      "            cj  ",
      "            cj  ",
      "           ghicu",
      "            alw ",
      "            al  ",
      "            al  ",
      "            cl  ",
      "            cl  ",
      "            clw ",
      "           ghi  ",
      "            al  ",
      "            al  ",
      "            al  ",
      "            cl  "
    ],
    [
      "            aj  ",
      "            cj  ",
      "            cj  ",
      "            cj x",
      "           ghicc",
      "            alw ",
      "            al  ",
      "            al  ",
      "            cl  ",
      "            cl  ",
      "            clw ",
      "           ghiy ",
      "            al  ",
      "            al  ",
      "            al  ",
      "            cl  "
    ],
    [
      "             A  ",
      "             A  ",
      "             A  ",
      "             A  ",
      "             icc",
      "             B  ",
      "             C  ",
      "             B  ",
      "             C  ",
      "             B  ",
      "             C  ",
      "             iCB",
      "             B  ",
      "             C  ",
      "             B  ",
      "             C  "
    ],
    [
      "             DEE",
      "             DEE",
      "             DEE",
      "             DEE",
      "             iFF",
      "             DII",
      "             DII",
      "             DII",
      "             DII",
      "             DII",
      "             DII",
      "             iFF",
      "             DII",
      "             DII",
      "             DII",
      "             DII"
    ]
  ]
}