{
  "name": "multi_hospital_0_floor1",
  "refpalette": "c70cities:multi_hospital_0_floor1_palette",
  "xsize": 16,
  "zsize": 16,
  "slices": [
    [
      "                ",
      "         a      ",
      "         b c c c",
      "         deeeeee",
      "         f  ghhh",
      "         d  ghhh",
      "         fi ghhh",
      "         dijghhh",
      "  kllllllkeeehhh",
      "  l      e  mhhh",
      "  l      e  mhhh",
      "  l      e eehhh",
      "  l      khhhhhh",
      "  l      khhhhhh",
      "  l      khhhhhh",
      "  l      khhhhhh"
    ],
    [
      "                ",
      "         a      ",
      "         b c c c",
      "         neeeeee",
      "         n  l o ",
      "         ni l   ",
      "         np l q ",
      "         n      ",
      "  krrrrrrkeeel  ",
      "  shhhhhhe  t   ",
      "  shhuwhhe  x   ",
      "  shhhhhhe ee   ",
      "  shhhhhhbyA B  ",
      "  shhwChhb   D  ",
      "  shhhhhhb   B  ",
      "  shhhhhhb EEB  "
    ],
    [
      "                ",
      "         a      ",
      "         b c c c",
      "         neennne",
      "         ni     ",
      "         np     ",
      "         n      ",
      "         n      ",
      "  kkkkkkkkeeel  ",
      "    FFhhhe  I   ",
      "    FFhhhe  J   ",
      "    FFhhhe eeK  ",
      "    FFhhhby  B  ",
      "    FFhhhb   L  ",
      "    FFhhhb   B  ",
      "    FFhhhb  MB  "
    ],
    [
      "                ",
      "         a      ",
      "         b c c c",
      "         neennne",
      "         nji    ",
      "         n i    ",
      "         n      ",
      "         n      ",
      "         keeel  ",
      "        Ne  O   ",
      "        Ne  O   ",
      "        Ne ee   ",
      "        Nby  B  ",
      "         f   O  ",
      "         f   B  ",
      "         f   B  "
    ],
    [
      "                ",
      "         a      ",
      "         b c c c",
      "         neeeeee",
      "         n      ",
      "         n P    ",
      "         n i  Q ",
      "         n      ",
      "         keeel  ",
      "        Ne  e   ",
      "        Ne  e   ",
      "        Ne ee   ",
      "        Nby  B  ",
      "        NR   B  ",
      "        NR   B  ",
      "        NR  SB  "
    ],
    [
      "                ",
      "         a      ",
      "         b c c c",
      "         neeeeee",
      "         n      ",
      "         n      ",
      "         n P  C ",
      "         n i    ",
      "         keeelll",
      "        Ne  e   ",
      "        Ne  e   ",
      "        Ne Te   ",
      "        NbvUUB  ",
      "        NbvUUB  ",
      "        NbvUUB  ",
      "        NbvUUB  "
    ]
  ]
}