{
  "name": "multi_laboratory1_11_base3",
  "refpalette": "c70cities:multi_laboratory1_11_base3_palette",
  "xsize": 16,
  "zsize": 16,
  "slices": [
    [
      "aaaaaaaaaaaaabcv",
      "aaaaaaaaaaaaabcv",
      "aaaaaaaaaaaaabcv",
      "aaaaaaaaaaaaabcv",
      "aaaaaaaaaaaaabcv",
      "aaaaaaaaaaaaabcv",
      "aaaadaaaaaaaabcv",
      "aaaaaaaaaaaaabcv",
      "aaaaaaaaaaaaabcv",
      "aaaaaaaaaaaaabcv",
      "aaaaaaaaaaaaabcv",
      "aaaaaaaaaaaaabcv",
      "eaaaaaaaaaaaabcv",
      "eaaadaaaaaaaabcv",
      "feaaaaaaaaaaabcv",
      " eaaaaaaaaaaabcv"
    ],
    [
      "    ghiiiiiihbcv",
      "    gj k  l ibcv",
      "    gmk    nibcv",
      "    g       ibcv",
      "    o       ibcv",
      "    gpqpqpqqhbcv",
      "r  fdggggggggbcv",
      "    gsss tt ubcv",
      "    gssw     bcv",
      "    gs xy   AAcv",
      "    g BBB CADEcv",
      "    g BFF xADEcv",
      "IJ  g KBB   AAcv",
      "If  d CL  y ubcv",
      "fI  g        bcv",
      " I  M       AAcv"
    ],
    [
      "    ghiNiiOihbcv",
      "    PQ      ibcv",
      "    P       Rbcv",
      "    g       ibcv",
      "    S       Rbcv",
      "    gT    UVhbcv",
      "   Wdggggggggbcv",
      "    g!s     ubcv",
      "    P       Xbcv",
      "    P       IAcv",
      "    P YY   IDEcv",
      "    P YY   IDEcv",
      "I   g K Z   IAcv",
      "IW  d  0    ubcv",
      "fI  g       Xbcv",
      " I  M       IAcv"
    ],
    [
      "    gh111111hbcv",
      "    2       nbcv",
      "    2       3bcv",
      "    g       4bcv",
      "    2        bcv",
      "    g       hbcv",
      "   Wdggggggggbcv",
      "    gs   55 ubcv",
      "    P        bcv",
      "    P       IAcv",
      "    P 66   IDEcv",
      "    P 66   IDEcv",
      "I   g       IAcv",
      "IW  d       ubcv",
      "fI  g        bcv",
      " I  M       IAcv"
    ],
    [
      "    gh      hbcv",
      "    g        bcv",
      "    g       7bcv",
      "    g        bcv",
      "    g        bcv",
      "    g       hbcv",
      "    dggggggggbcv",
      "    g  8  8 9bcv",
      "    g       Xbcv",
      "    g       IAcv",
      "    g      I@Ecv",
      "    g      I@Ecv",
      "I   g       IAcv",
      "I   d       9bcv",
      "fI  g       Xbcv",
      " I  g       IAcv"
    ],
    [
      "####2$$$$$$$$bcv",
      "##%#2$^$$$$^$bcv",
      "##%#2$$$$$$$$bcv",
      "##%#2$$$$$$$$bcv",
      "##%#2$^$$$$&$bcv",
      "####2$$$$$$$$bcv",
      "####dggggggggbcv",
      "####2********bcv",
      "####2((((((((bcv",
      "####2(()((%(AAcv",
      "####2((%((%A+Ecv",
      "####2(()((%A+Ecv",
      "I###2((%((%(AAcv",
      "I###d((((((((bcv",
      "fI##2((((((((bcv",
      " I##2((%((%(AAcv"
    ]
  ]
}