{
  "name": "multi_megatower1_1_floor8",
  "refpalette": "c70cities:multi_megatower1_1_floor8_palette",
  "xsize": 16,
  "zsize": 16,
  "slices": [
    [
      "           abc  ",
      "           dbc  ",
      "           dbcef",
      "           dbcgg",
      "           hijcc",
      "           abccc",
      "           abccc",
      "           abckk",
      "           dbcll",
      "           dbcll",
      "           dbcll",
      "           hijll",
      "           abcll",
      "           abcll",
      "           abcll",
      "           dbcll"
    ],
    [
      "             m  ",
      "             me ",
      "           d mn ",
      "           d m  ",
      "           hijdo",
      "             p  ",
      "           a p  ",
      "           a p  ",
      "           d p  ",
      "           d p q",
      "             p  ",
      "           hij q",
      "           a p  ",
      "           a p  ",
      "             p  ",
      "             pr "
    ],
    [
      "             mg ",
      "             mn ",
      "           d m  ",
      "           d m  ",
      "           hijds",
      "                ",
      "           a    ",
      "           a    ",
      "           d    ",
      "           d    ",
      "                ",
      "           hij  ",
      "           a    ",
      "           a    ",
      "                ",
      "                "
    ],
    [
      "             mnt",
      "             m  ",
      "           d m  ",
      "             m u",
      "           hijdd",
      "                ",
      "           a    ",
      "                ",
      "                ",
      "           d    ",
      "                ",
      "           hij  ",
      "                ",
      "           a    ",
      "                ",
      "                "
    ],
    [
      "             p f",
      "             p t",
      "           d p  ",
      "             p  ",
      "           hijdd",
      "             p  ",
      "           a p  ",
      "             p  ",
      "             p  ",
      "           d p  ",
      "             p  ",
      "           hij  ",
      "             p  ",
      "           a p  ",
      "             p  ",
      "             p  "
    ],
    [
      "             w  ",
      "             w f",
      "           d w g",
      "             weg",
      "           hijxx",
      "             w  ",
      "           a w  ",
      "             w  ",
      "             w  ",
      "           d w  ",
      "             w  ",
      "           hij  ",
      "             w  ",
      "           a w  ",
      "             w  ",
      "             w  "
    ]
  ]
}