{
  "name": "multi_convenientstore_3_floor1",
  "refpalette": "c70cities:multi_convenientstore_3_floor1_palette",
  "xsize": 16,
  "zsize": 16,
  "slices": [
    [
      "aaaaaaaaabac    ",
      "       d   c    ",
      "       d   c    ",
      "       deeec    ",
      "       deeec    ",
      "fffffffgeeec    ",
      "eeeeeeeeeeec    ",
      "eeeeeeeeeeec    ",
      "ee    heeeec    ",
      "eeeeeeeeeeec    ",
      "eeeeeeeeeeec    ",
      "eeeeeeeeeeec    ",
      "cccccccccccc    ",
      "      i         ",
      "                ",
      "                "
    ],
    [
      "aaaaaaaaabac    ",
      "       j   c    ",
      "       j   c    ",
      "       jjjjc    ",
      "       j  kc    ",
      "jjjjjjjj l c    ",
      "ml kml k n c    ",
      "           c    ",
      " j       o c    ",
      " jjjjjj  l c    ",
      "           c    ",
      "pqpppq   nqc    ",
      "cccccccccccc    ",
      "      r         ",
      "                ",
      "                "
    ],
    [
      "aaaaaaaaaaac    ",
      "           c    ",
      "           c    ",
      "           b    ",
      "           b    ",
      "           b    ",
      "           c    ",
      "           b    ",
      "           b    ",
      "           b    ",
      "           c    ",
      "sqts q    qc    ",
      "bccbbccbbccc    ",
      "                ",
      "                ",
      "                "
    ],
    [
      "aaaaaaaaaaac    ",
      "           c    ",
      "           c    ",
      "           c    ",
      "           c    ",
      "           c    ",
      "           c    ",
      "           c    ",
      "           c    ",
      "           c    ",
      "           c    ",
      "           c    ",
      "cccccccccccc    ",
      "      i         ",
      "                ",
      "                "
    ],
    [
      "uuuuuuuuuuuc    ",
      "uuuuuuuuuuuc    ",
      "uuuuuuuuuuuc    ",
      "uuuuuuuuuuuc    ",
      "uuuuuuuuuuuc    ",
      "uuuuuuuuuuuc    ",
      "uuuuuuuuuuuc    ",
      "uuuuuuuuuuuc    ",
      "uuuuuuuuuuuc    ",
      "uuuuuuuuuuuc    ",
      "uuuuuuuuuuuc    ",
      "uuuuuuuuuuuc    ",
      "cccccccccccc    ",
      "                ",
      "                ",
      "                "
    ],
    [
      "                ",
      "                ",
      "                ",
      "                ",
      "                ",
      "                ",
      "                ",
      "                ",
      "                ",
      "                ",
      "                ",
      "                ",
      "                ",
      "                ",
      "                ",
      "                "
    ]
  ]
}