{
  "name": "multi_laboratory1_1_base3",
  "refpalette": "c70cities:multi_laboratory1_1_base3_palette",
  "xsize": 16,
  "zsize": 16,
  "slices": [
    [
      "zabccccccccccccc",
      "zabccccccccccccc",
      "zabccccccccccccc",
      "zabccccccccccccc",
      "zabccccccccccccc",
      "zabccccccccccccc",
      "zabccccccccdcccc",
      "zabccccccccccccc",
      "zabccccccccccccc",
      "zabccccccccccccc",
      "zabccccccccccccc",
      "zabccccccccccccc",
      "zabcccccccccccce",
      "zabccccccccdccce",
      "zabcccccccccccef",
      "zabccccccccccce "
    ],
    [
      "zabghhh!higj    ",
      "zabh kl kmnj    ",
      "zabok  m   j    ",
      "zaboml     j    ",
      "zabh       p    ",
      "zabg       j    ",
      "zabjjjjjjjjdf  q",
      "zabrs tuwsxj    ",
      "zab   y A  j    ",
      "zabB CCCC  j    ",
      "zabD E AFI j    ",
      "zabDJE  F  j    ",
      "zabK LLLL  j  MN",
      "zabO   P   d  fN",
      "zab        j  Nf",
      "zabB  t    Q  N "
    ],
    [
      "zabghhihRhgj    ",
      "zabS       T    ",
      "zabh       T    ",
      "zabh       j    ",
      "zabh       U    ",
      "zabg VWWWX j    ",
      "zabjjjjjjjjdY   ",
      "zab        j    ",
      "zab        T    ",
      "zab   Z0   T    ",
      "zab  1  2  T    ",
      "zab  3     T    ",
      "zab   45   j   N",
      "zab        d  YN",
      "zab        j  Nf",
      "zab        Q  N "
    ],
    [
      "zabg666666gj    ",
      "zab        7    ",
      "zab8       7    ",
      "zab9       j    ",
      "zabl       7    ",
      "zabg @#$%  j    ",
      "zabjjjjjjjjdY   ",
      "zab        j    ",
      "zab        T    ",
      "zab        T    ",
      "zab        T    ",
      "zab        T    ",
      "zab        j   N",
      "zab        d  YN",
      "zab        j  Nf",
      "zab        Q  N "
    ],
    [
      "zabg      gj    ",
      "zab        j    ",
      "zab        j    ",
      "zab        j    ",
      "zab        j    ",
      "zabg       j    ",
      "zabjjjjjjjjd    ",
      "zab        j    ",
      "zab        j    ",
      "zab        j    ",
      "zab        j    ",
      "zab        j    ",
      "zab        j   N",
      "zab        d   N",
      "zab        j  Nf",
      "zab        j  N "
    ],
    [
      "zabg^^^^^^g7&&&&",
      "zab^*^^^^*^7&(&&",
      "zab^^^^^^^^7&(&&",
      "zab^^^^^^^^7&(&&",
      "zab^*^^^^*^7&(&&",
      "zabg^^^^^^^7&&&&",
      "zabjjjjjjjjd&&&&",
      "zab))))))))7&&&&",
      "zab))))))))7&&&&",
      "zab))++-())7&&&&",
      "zab))+))+))7&&&&",
      "zab))())())7&&&&",
      "zab))+(++))7&&&N",
      "zab))))))))d&&&N",
      "zab))))))))7&&Nf",
      "zab))())())7&&N "
    ]
  ]
}