{
  "name": "multi_laboratory1_8_base4",
  "refpalette": "c70cities:multi_laboratory1_8_base4_palette",
  "xsize": 16,
  "zsize": 16,
  "slices": [
    [
      "aaaaaaaaaaaaaaaa",
      "aaaaaaaaaaaaaaaa",
      "aaabaaaaaaaabaaa",
      "aaaaaaaaaaaaaaaa",
      "aaaaaaaaaaaaaaaa",
      "aaaaaaaaaaaaaaaa",
      "aaaaaaaaaaaaaaaa",
      "aaaaaaaaaaaaaaaa",
      "aaaaaaaaaaaaaaaa",
      "aaabaaaaaaaabaaa",
      "aaaaaaaaaaaaaaaa",
      "aaaaaaaaaaaaaaaa",
      "aaaaaaaaaaaaaaaa",
      "aaaaaaaaaaaaaaaa",
      "aaaaaaaaaaaaaaaa",
      "aaaaaaaaaaaaaaaa"
    ],
    [
      " cd e    fgh ij ",
      "  gkil    ch m  ",
      "  hb!no    hbe  ",
      " ch ig    ph e n",
      "  h ep     d e  ",
      "                ",
      "              g ",
      "              f ",
      "   q        q   ",
      "rrrbrsstussrbrrr",
      "   q        q   ",
      "                ",
      "                ",
      "wx   ywwwwx  A w",
      "e     h  e     h",
      "e   y h  e x   h"
    ],
    [
      "    m      B    ",
      "                ",
      "   b       Bb   ",
      "    m        m  ",
      "  B          l  ",
      "                ",
      "                ",
      "                ",
      "   C        D   ",
      "EErbrssFIssrbrEE",
      "   D        D   ",
      "                ",
      "                ",
      "        J       ",
      "K               ",
      "      J  K      "
    ],
    [
      "                ",
      "                ",
      "   b        b   ",
      "                ",
      "                ",
      "                ",
      "                ",
      "                ",
      "            D   ",
      "EErbrssssssrbrEE",
      "   D        D   ",
      "                ",
      "                ",
      "                ",
      "                ",
      "                "
    ],
    [
      "                ",
      "                ",
      "   b        b   ",
      "                ",
      "                ",
      "                ",
      "              ! ",
      "                ",
      "                ",
      "rrrbrrrrrrrrbrrr",
      "                ",
      "                ",
      "                ",
      "                ",
      "                ",
      "                "
    ],
    [
      "LMLLLMLLLLNLLLML",
      "LLLLLLLLLLLLLLLL",
      "LLLbLLLLLLLLbLLL",
      "LLLLLLLLLLLLLLLL",
      "LMLLLNLLLLMLLLML",
      "LMLLL LLLLMLLLML",
      "LMLLLMLLLLMLLLNL",
      "LMLLLMLLLLMLLLML",
      "LLLLLLLLLLLLLLLL",
      "OOObOOOOOOOObOOO",
      "PPPrPPPPPPPPraPP",
      "PPPrPPPPPPPPrPPP",
      "PPPrPPPPPPPPrPPP",
      "QPPrPPQQMMPPrPPM",
      "MPPrPPQPPMPPrPPM",
      "MPPrPPMPPQPPrPPQ"
    ]
  ]
}