{
  "name": "multi_laboratory1_5_floor1",
  "refpalette": "c70cities:multi_laboratory1_5_floor1_palette",
  "xsize": 16,
  "zsize": 16,
  "slices": [
    [
      "                ",
      "                ",
      "aababaaaababaaba",
      "cccccdccccdccccc",
      "cccccecccceccccc",
      "ffffffffffffffff",
      "g  h g  h g ii g",
      "gjjjjgjjjjgjjjjg",
      "gggggggggggggggg",
      "g    g    g    g",
      "g    g    g    g",
      "g    g    g    g",
      "g    g    g    g",
      "g    g    g    g",
      "g    g    g    g",
      "gggggggggggggggg"
    ],
    [
      "                ",
      "                ",
      "aaaaaabaaaaaabaa",
      "                ",
      "                ",
      "kllllfllllfllllk",
      "mii  mii  m  iim",
      "mjjjjmjjjjmjjjjm",
      "gmmmmgmmmmgmmmmg",
      "m    m    m    m",
      "m    m    m    m",
      "m    m    m    m",
      "m    m    m    m",
      "m    m    m    m",
      "m    m    m    m",
      "gmnnmgmnnmgmnnmg"
    ],
    [
      "                ",
      "                ",
      "aabaaaabaaaaaaab",
      "                ",
      "                ",
      "kllllfllllfllllk",
      "mi iim  h m h im",
      "mjjjjmjjjjmjjjjm",
      "gmmmmgmmmmgmmmmg",
      "m    m    m    m",
      "m    m    m    m",
      "m    m    m    m",
      "m    m    m    m",
      "m    m    m    m",
      "m    m    m    m",
      "gm  mgm  mgm  mg"
    ],
    [
      "                ",
      "                ",
      "baaaaaaaaaaaaaaa",
      "                ",
      "                ",
      "kllllfllllfllllk",
      "m h  m i  m  i m",
      "mjjjjmjjjjmjjjjm",
      "gmmmmgmmmmgmmmmg",
      "m    m    m    m",
      "m    m    m    m",
      "m    m    m    m",
      "m    m    m    m",
      "m    m    m    m",
      "m    m    m    m",
      "gmoomgmoomgmoomg"
    ],
    [
      "                ",
      "                ",
      "aaaaaaaaaaabaaaa",
      "                ",
      "                ",
      "kllllfllllfllllk",
      "m    m    m    m",
      "mp  pmp  pmp  pm",
      "gmmmmgmmmmgmmmmg",
      "m    m    m    m",
      "m    m    m    m",
      "m    m    m    m",
      "m    m    m    m",
      "m    m    m    m",
      "m    m    m    m",
      "gmmmmgmmmmgmmmmg"
    ],
    [
      "                ",
      "                ",
      "aaaaaaaaaaaaaaaa",
      "                ",
      "                ",
      "ffffffffffffffff",
      "qqqqqqqqqqqqqqqq",
      "qqqqqqqqqqqqqqqq",
      "qqqqqqqqqqqqqqqq",
      "qrrrrqrrrrqrrrrq",
      "sr  rsr  rsr  rs",
      "qrrrrqrrrrqrrrrq",
      "qrrrrqrrrrqrrrrq",
      "qrrrrqrrrrqrrrrq",
      "qrrrrqrrrrqrrrrq",
      "ffffffffffffffff"
    ]
  ]
}