{
  "name": "multi_laboratory1_12_base6",
  "refpalette": "c70cities:multi_laboratory1_12_base6_palette",
  "xsize": 16,
  "zsize": 16,
  "slices": [
    [
      " abbbbbbbbbbbcdz",
      " abbbbbbbbbbbcdz",
      " abbbbbbbbbbbcdz",
      "eabbbbbbbbbbbcdz",
      "abbbfbbbbbbbbcdz",
      "abbbbbbbbbbbbcdz",
      "bbbbbbbbbbbbbcdz",
      "bbbbbbbbbbbbbcdz",
      "bbbbbbbbbgbbbcdz",
      "bbbbbbbbbbhbbcdz",
      "bbbbbgbbbbbbbcdz",
      "bbbbfigbbgbbbcdz",
      "bbbbbbbbigbbbcdz",
      "bbbbbbbbgggbbcdz",
      "bbbbbbbbibggbcdz",
      "bbbbgbgiggbbbcdz"
    ],
    [
      " j  k       lcdz",
      " j  km      lcdz",
      " j  k        cdz",
      "ej n      oooodz",
      "j   f     opqcdz",
      "j   r     oooodz",
      "    ks  t    cdz",
      "    k       lcdz",
      "    k    uu lcdz",
      "   wk   x uggcdz",
      " s yl     oooodz",
      "A mBfC DtioEFcdz",
      "IJ tKm   Lgooodz",
      "        u Miicdz",
      "t Nt     D ulcdz",
      "N      u Ltuicdz"
    ],
    [
      " j  O      PQcdz",
      " j         PQcdz",
      " j  R       Scdz",
      "ej         joodz",
      "j   f     jpqcdz",
      "j          joodz",
      "    n       Tcdz",
      "    O      PQcdz",
      "    U       Vcdz",
      "           ugcdz",
      "    W     igoodz",
      "    f     gEFcdz",
      "           hoodz",
      "          uuicdz",
      "             cdz",
      "            Lcdz"
    ],
    [
      " j           cdz",
      " j           cdz",
      " j           cdz",
      "ej         joodz",
      "j   f     jpqcdz",
      "j          joodz",
      "             cdz",
      "             cdz",
      "             cdz",
      "            Lcdz",
      "          ijoodz",
      "    f     jEFcdz",
      "           Xoodz",
      "             cdz",
      "             cdz",
      "             cdz"
    ],
    [
      " j          Ycdz",
      " j          Ycdz",
      " j           cdz",
      "ej         joodz",
      "j   f     jpqcdz",
      "j          joodz",
      "             cdz",
      "            Ycdz",
      "            Ycdz",
      "             cdz",
      "          ujoodz",
      "    f     jEFcdz",
      "           joodz",
      "             cdz",
      "            Ycdz",
      "            Ycdz"
    ],
    [
      " j          Zcdz",
      " j           cdz",
      " j           cdz",
      "ej         joodz",
      "j   f     jpqcdz",
      "j          joodz",
      "             cdz",
      "             cdz",
      "            Zcdz",
      "             cdz",
      "           joodz",
      "    f     jEFcdz",
      "           joodz",
      "             cdz",
      "            Zcdz",
      "            tcdz"
    ]
  ]
}