{
  "name": "multi_militarybase_0_base1",
  "refpalette": "c70cities:multi_militarybase_0_base1_palette",
  "xsize": 16,
  "zsize": 16,
  "slices": [
    [
      "vvvvvvvvvvvvvvvv",
      "vaaaaaavbbbbbbbb",
      "vaaaaaavbbbbbbbb",
      "vaaaaaavbbbbbbbb",
      "vvvvvvvvbbbbbbbb",
      "vccccccccccccccc",
      "vcbbbbbbdddddddd",
      "vcbbbbbbdddddddd",
      "vcbbbbbbdddddddd",
      "vcbbbbbbbbbddccc",
      "vcbbbbbbbbbddc  ",
      "vcbbbeebeebddc  ",
      "vcbbbebbbebddc  ",
      "vcbbbbbbbbbddc  ",
      "vcbbbbeeebbddc  ",
      "vcbbbbbbbbbddc  "
    ],
    [
      "vvvvvvvvvvvvvvvv",
      "vaaaaaav fg gfg ",
      "vaaaaaav  h h h ",
      "vaaaaaav  i j j ",
      "vvvvvvvvkkkkkkkl",
      "vmmvnnnnvoooov  ",
      "v       p       ",
      "v       p       ",
      "v       q       ",
      "vrrvrrrrv    vss",
      "vt           s  ",
      "v            s  ",
      "vt           s  ",
      "v  v         v  ",
      "vt           s  ",
      "v            s  "
    ],
    [
      "vvvvvvvvvvvvvvvv",
      "vaaaaaav fg gfg ",
      "vaaaaaav  h h h ",
      "vaaaaaav  u w w ",
      "vvvvvvvvkkkkkkkx",
      "vy vnABnvoooov  ",
      "v       p       ",
      "v       p       ",
      "v       C       ",
      "vrrvrrrrv    v  ",
      "vD              ",
      "v               ",
      "vt              ",
      "v  v         v  ",
      "vD              ",
      "v               "
    ],
    [
      "vvvvvvvvvvvvvvvv",
      "vaaaaaav        ",
      "vaaaaaav        ",
      "vaaaaaav        ",
      "vvvvvvvvkkkkkkkk",
      "v  vE  FvIoJov  ",
      "v       p       ",
      "v       p       ",
      "v       p       ",
      "vrrvrrrrv    v  ",
      "v               ",
      "v               ",
      "vD              ",
      "v  v         v  ",
      "v               ",
      "v               "
    ],
    [
      "vvvvvvvvvvvvvvvv",
      "vaaaaaav        ",
      "vaaaaaav        ",
      "vaaaaaav        ",
      "vvvvvvvvkkkkkkkk",
      "v  v    v    v  ",
      "v       p       ",
      "v       p       ",
      "v       p       ",
      "vrrvrrrrv    v  ",
      "v               ",
      "v               ",
      "v               ",
      "v  v         v  ",
      "v               ",
      "v               "
    ],
    [
      "vvvvvvvvvvvvvvvv",
      "vaaaaaavcKKKKcKK",
      "vaaaaaavcKKKKcKK",
      "vaaaaaavcKKKKcKK",
      "vvvvvvvvcvvvvcvv",
      "vKKcKKKKcKKKKcKK",
      "vKKcKKKKcKKKKcKK",
      "vKKcKKKKcKKKKcKK",
      "vKKcKKKKcKKKKcKK",
      "vccccccccccccccc",
      "vKKcKKKKcKKKKcKK",
      "vKKcKKKKcKKKKcKK",
      "vKKcKKKKcKKKKcKK",
      "vcccccccccccccKK",
      "vKKcKKKKcKKKKcKK",
      "vKKcKKKKcKKKKcKK"
    ]
  ]
}