{
  "name": "multi_laboratory1_13_base1",
  "refpalette": "c70cities:multi_laboratory1_13_base1_palette",
  "xsize": 16,
  "zsize": 16,
  "slices": [
    [
      "aaaaaaaaaaaaabcz",
      "aaaaaaaaaaaaabcz",
      "aaaadaaaaaaaabcz",
      "eeeaaaaaaaaaabcz",
      "eeeaaaaaaaaaabcz",
      "eeeaaaaaaaaaabcz",
      "eeeaaaaaaaaaabcz",
      "eeeaaaaaaaaaabcz",
      "aaa!aaaaaaaaabcz",
      "aaaadaaaaaaaabcz",
      "aaaaaaaaaaaaabcz",
      "aaaaaaaaaaaaabcz",
      "aaaaaaaaaaaaabcz",
      "aaaaaaaaaaaaabcz",
      "aaaaaaaaaaaaabcz",
      "aaaaaaaaaaaaabcz"
    ],
    [
      "    fghi  ghjbcz",
      "    fgggk gggbcz",
      "lllmdnnnnnnnnbcz",
      "   ln       obcz",
      "   pn  q q  rbcz",
      "  sln  ttt  obcz",
      " ggln  ttt  ubcz",
      " s ln  w w  ubcz",
      "lllmn   x   !bcz",
      "nnnndnnn nnnnbcz",
      "s  yA   B   obcz",
      "    A  C C  obcz",
      "    A  ttt  rbcz",
      "    A       obcz",
      "    A  DDD  rbcz",
      "    A  C    obcz"
    ],
    [
      "    f        bcz",
      "    fEF    FIbcz",
      "   Jdnnnnnnnnbcz",
      "    A       Kbcz",
      "    A        bcz",
      "    A    L   bcz",
      "    A   L    bcz",
      "    A        bcz",
      "   JA E M   Nbcz",
      "OOOndnnn nnnnbcz",
      "    A   P   Qbcz",
      "    A        bcz",
      "    A    R   bcz",
      "    A        bcz",
      "    A   S   Tbcz",
      "    A       Ubcz"
    ],
    [
      "    f        bcz",
      "    f        bcz",
      "   Jdnnnnnnnnbcz",
      "    A        bcz",
      "    A        bcz",
      "    A        bcz",
      "    A        bcz",
      "    A        bcz",
      "   JA        bcz",
      "VVVndnnnnnnnnbcz",
      "    A        bcz",
      "    A       Wbcz",
      "    A       Xbcz",
      "    A        bcz",
      "    A        bcz",
      "    A        bcz"
    ],
    [
      "    f        bcz",
      "    f        bcz",
      "    dnnnnnnnnbcz",
      "    A        bcz",
      "    A        bcz",
      "    A        bcz",
      "    A        bcz",
      "    A        bcz",
      "    A        bcz",
      "YYYndnnnnnnnnbcz",
      "    A        bcz",
      "    A        bcz",
      "    A       Zbcz",
      "    A        bcz",
      "             bcz",
      "    A        bcz"
    ],
    [
      "0000102000300bcz",
      "0000100000000bcz",
      "4444dnnnnnnnnbcz",
      "0000100000000bcz",
      "0000102000200bcz",
      "0000102000200bcz",
      "0000102000200bcz",
      "0000102000200bcz",
      "0000100000000bcz",
      "nnnndnnnnnnnnbcz",
      "0000100000000bcz",
      "0000103000200bcz",
      "0000102000200bcz",
      "0000102000200bcz",
      "0000102000200bcz",
      "0000100000000bcz"
    ]
  ]
}