{
  "name": "multi_condo1_2_ground",
  "refpalette": "c70cities:multi_condo1_2_ground_palette",
  "xsize": 16,
  "zsize": 16,
  "slices": [
    [
      "GGGabaaaaaaaaaaa",
      "GGGabaaaaaaaaaaa",
      "Gcccbaaaaaaaaaaa",
      "GGGabaaaaaaaaaaa",
      "GGGabaaaaaaaaaaa",
      "GGddbaaaaaaaaaaa",
      "GGGGbaaaaaaaaaaa",
      "GGGGbaaaaaaaaaaa",
      "GGGGbaaaaaaaaaaa",
      "GGGGbaaaaaaaaaaa",
      "GGGGbaaaaaaaaaaa",
      "GGGGbbbbbbbaaaaa",
      "GGGGbaaaaabaaaaa",
      "GGGGbbbbbbbbbbbb",
      "GGGGGGGGGGGGGGGG",
      "GGGGGGGGGGGGGGGG"
    ],
    [
      "    ef    ghiij ",
      "    baklmkannnnn",
      " cccbo    pqqqqq",
      "    bor   p     ",
      "    bo    p     ",
      "  ddbor   p  sts",
      "    bou   g     ",
      "  w bor      sts",
      "    bo          ",
      "  w bor   x  yAy",
      "    bo   BC     ",
      "  w bbbbbbbbbbbb",
      "    bDDDDDbDDDDD",
      "  w bbbbbbbbbbbb",
      "                ",
      "                "
    ],
    [
      "    E     F     ",
      "    bakIJkannnnn",
      " cccb       KLMN",
      "    bM    O     ",
      "    bP          ",
      "  ddb     Q  RST",
      "    n     F     ",
      "  F nU       VRW",
      "    nX          ",
      "  F n        RRY",
      "    n           ",
      "  F nnnnnnbnnnnn",
      "          b     ",
      "  F             ",
      "                ",
      "                "
    ],
    [
      "    E           ",
      "    bakkkkannnnn",
      " cccb         N ",
      "    b           ",
      "    b           ",
      "  ddb           ",
      "    n           ",
      "  Z n           ",
      "    n           ",
      "  Z n         0 ",
      "    n           ",
      "  Z nnnnnnbnnnnn",
      "          b     ",
      "  Z             ",
      "                ",
      "                "
    ],
    [
      "    b           ",
      "    bakkkkannnnn",
      " cccb        N  ",
      "    b           ",
      "    b           ",
      "  ddb           ",
      "    n           ",
      "  Z n           ",
      "    n           ",
      "  Z n           ",
      "    n           ",
      "  Z nnnnnnbnnnnn",
      "          b     ",
      "  Z             ",
      "                ",
      "                "
    ],
    [
      "    b           ",
      "    bakkkkannnnn",
      " cccb       N   ",
      "    b     1     ",
      "    b           ",
      "  ddb           ",
      "    n     1     ",
      "  2 n           ",
      "    n           ",
      "  2 n     1     ",
      "    n           ",
      "  2 nnnnnnbnnnnn",
      "          b     ",
      "  2             ",
      "                ",
      "                "
    ]
  ]
}