{
  "name": "multi_laboratory1_11_base7",
  "refpalette": "c70cities:multi_laboratory1_11_base7_palette",
  "xsize": 16,
  "zsize": 16,
  "slices": [
    [
      "aaaaaaaaaaaaaaav",
      "aaabaaaaaaaaaaav",
      "aaaaaacdaaaaaaav",
      "aaaaaaccaaaaaaav",
      "aaaaaaaaaaaaaaav",
      "aaaaaaaaaaaaaaav",
      "aaaaaaaaaaaaaaav",
      "aaaaaaaaaaaaaaav",
      "aaaaaaaaaaaaaaav",
      "aaaaaaaaaaaaaaav",
      "aaaaaaaaaaaaaaav",
      "aaaaaaaaaaaaaaav",
      "eaaaaaaaaaaaaaav",
      "eaaaaaaaaaaaaaav",
      "eeaaaaaaaaaaaaav",
      "aeaaaaaaaaaaaaav"
    ],
    [
      "f ggaaaaaaaaaaav",
      "aggbaaaaaaaaaaav",
      "aaahaaaiaaaaaaav",
      "aaaaaaiiaaaaaaav",
      "aaaaaaaaaaaaaaav",
      "aaaaaaaaaaaaaaav",
      "aaaaaaaaaaaaaaav",
      "aaaaaaaaaaaaaaav",
      "aaaaaaaaaaaaaaav",
      "aaaaaaaaaaaaaaav",
      "aaaaaaaaaaaaaaav",
      "aaaaaaaaaaaaaaav",
      "aaaaaaaaaaaaaaav",
      "aaaaaaaaaaaaaaav",
      "jaaaaaaaaaaaaaav",
      "aaaaaaaaaaaaaaav"
    ],
    [
      "    kgaaaaaaaaav",
      "    gaaaaaaaaaav",
      "aal gahiaaaaaaav",
      "aaagagmhaaaaaaav",
      "aaaaaaggaaaaaaav",
      "aaaahaiaaaaaaaav",
      "aaaaaaaaaaaaaaav",
      "aaaaaaaaaaaaaaav",
      "aaaaaaaaaaaaaaav",
      "aaaaaaaaaaaaaaav",
      "aaaaaaaaaaaaaaav",
      "aaaaaaaaaaaaaaav",
      "aaaaaaaaaaaaaaav",
      "aaaaaaaaaaaaaaav",
      "jaaaaaaaaaaaaaav",
      "baaaaaaaaaaaaaav"
    ],
    [
      "       aaaaaaaav",
      "      gibaaaaaav",
      "aa     maaaaaaav",
      "aaa     kgaaaaav",
      "aaa  f  aaaaaaav",
      "aaaa  m aaaaaaav",
      "aaaaaahaaaaaaaav",
      "aaaaaaaaaaaaaaav",
      "aaaaaaaaaaaaaaav",
      "aaaaaaaaaaaaaaav",
      "aaaaaaaaaaaaaaav",
      "aaaaaaaaaaaaaaav",
      "aaaaaaaaaaaaaaav",
      "aaaaaaaaaaaaaaav",
      "jaaaaaaaaaaaaaav",
      "baaaaaaaaaaaaaav"
    ],
    [
      "aa      aaaaaaav",
      "aa     nmhaaaaav",
      "aa       aaaaaav",
      "aaa       aaaaav",
      "aaao     aaaaaav",
      "aaaa   oaaaaaaav",
      "aaaaaaaaaaaaaaav",
      "aaaaaaaaaaaaaaav",
      "aaaaaaaaaaaaaaav",
      "aaaaaaaaaaaaaaav",
      "aaaaaaaaaaaaaaav",
      "aaaaaaaaaaaaaaav",
      "aaaaaaaaaaaaaaav",
      "aaaaaaaaaaaaaaav",
      "jaaaaaaaaaaaaaav",
      "gaaaaaaaaaaaaaav"
    ],
    [
      "aaaaaaaaaaaaaaav",
      "aaaaaaoaaaaaaaav",
      "aaoaaooooaaaaaav",
      "aaaaaooooaaaaaav",
      "aaaaaoooaaaaaaav",
      "aaaaaaaaaaaaaaav",
      "aaaaaaaaaaaaaaav",
      "aaaaaaaaaaaaaaav",
      "aaaaaaaaaaaaaaav",
      "aaaaaaaaaaaaaaav",
      "aaaaaaaaaaaaaaav",
      "aaaaaaaaaaaaaaav",
      "aaaaaaaaaaaaaaav",
      "aaaaaaaaaaaaaaav",
      "jaaaaaaaaaaaaaav",
      " aaaaaaaaaaaaaav"
    ]
  ]
}