{
  "name": "multi_hospital_3_ground",
  "refpalette": "c70cities:multi_hospital_3_ground_palette",
  "xsize": 16,
  "zsize": 16,
  "slices": [
    [
      "aaaaaaaaaaaaaabG",
      "aaaaaaaaaaaaaabG",
      "acaaaaaaaaaaaabG",
      "dbGGGGGGGGGGGGGG",
      "GGGGGGGGGGGGGGGG",
      "eeeeeeeeeeeeGGGG",
      "eeeeeeeeeeeeeGGG",
      "eeeeeeeeeeeeeeGG",
      "eeeeeeeeeeeeeeGG",
      "GGGGGGGGGeeeeeGG",
      "fcGGGGGGGGeeeeGG",
      "ggGGGGGGGGeeeeGG",
      "hgGGGGGGGGeeeeGG",
      "hgGGGGGGGGeeeeGG",
      "ggGGGGGGGGeeeeGG",
      "GGGGGGGGGGeeeeGG"
    ],
    [
      "            iGj ",
      "    k  k  k iGj ",
      "lcmmnmmnmmnmmnj ",
      "obooooooooooooo ",
      "                ",
      "                ",
      "                ",
      "                ",
      "                ",
      "                ",
      "pq      ~       ",
      "   rrrrrr       ",
      "   rstuwr       ",
      "   rtwsur       ",
      "   rrrrrr       ",
      "                "
    ],
    [
      "             xy ",
      "             Ay ",
      "lcBBBBBBBBBBBBy ",
      "ob              ",
      "                ",
      "                ",
      "                ",
      "                ",
      "                ",
      "                ",
      " q      ~       ",
      "                ",
      "    CD E        ",
      "    DEC         ",
      "                ",
      "                "
    ],
    [
      "              y ",
      "             Fy ",
      "lcBBBBBBBBBBBBy ",
      "ob              ",
      "                ",
      "                ",
      "                ",
      "                ",
      "                ",
      "                ",
      " q      ~       ",
      "                ",
      "                ",
      "                ",
      "                ",
      "                "
    ],
    [
      "              y ",
      "              y ",
      "lcBBBBBBBBBBBBy ",
      "ob              ",
      "                ",
      "                ",
      "                ",
      "                ",
      "                ",
      "                ",
      " q      ~       ",
      "                ",
      "                ",
      "                ",
      "                ",
      "                "
    ],
    [
      "              y ",
      "              y ",
      "lcBBBBBBBBBBBBy ",
      "ob              ",
      "                ",
      "                ",
      "                ",
      "                ",
      "                ",
      "                ",
      " q      ~       ",
      "                ",
      "                ",
      "                ",
      "                ",
      "                "
    ]
  ]
}