{
  "name": "multi_megatower1_1_floor5",
  "refpalette": "c70cities:multi_megatower1_1_floor5_palette",
  "xsize": 16,
  "zsize": 16,
  "slices": [
    [
      "            ab  ",
      "            cb  ",
      "           c bde",
      "            cbff",
      "           ghibb",
      "            abbb",
      "           a bbb",
      "            abbb",
      "            cbbb",
      "           c bbb",
      "            cbbb",
      "           ghijj",
      "            aj  ",
      "           a j  ",
      "            aj  ",
      "            cj  "
    ],
    [
      "            ak  ",
      "            ckd ",
      "             kl ",
      "            ck  ",
      "           ghicm",
      "            an  ",
      "             n  ",
      "            anaa",
      "            cnop",
      "             n  ",
      "            cnqr",
      "           ghinn",
      "            an  ",
      "             n  ",
      "            an  ",
      "            cn  "
    ],
    [
      "            akf ",
      "            ckl ",
      "             k  ",
      "            ck  ",
      "           ghics",
      "            an  ",
      "             n  ",
      "            an  ",
      "            cn  ",
      "             n  ",
      "            cn  ",
      "           ghi  ",
      "            an  ",
      "             n  ",
      "            an  ",
      "            cn  "
    ],
    [
      "            aklt",
      "            ck  ",
      "             k  ",
      "            ck u",
      "           ghicc",
      "            an  ",
      "             n  ",
      "            an  ",
      "            cn  ",
      "             n  ",
      "            cn  ",
      "           ghi  ",
      "            an  ",
      "             n  ",
      "            an  ",
      "            cn  "
    ],
    [
      "            aw e",
      "            cw t",
      "             w  ",
      "            cw  ",
      "           ghicc",
      "            ax  ",
      "             y  ",
      "            ax  ",
      "            cy  ",
      "             x  ",
      "            cy  ",
      "           ghi  ",
      "            ax  ",
      "             y  ",
      "            ax  ",
      "            cy  "
    ],
    [
      "            aA  ",
      "            cA e",
      "            cA f",
      "            cAdf",
      "           ghiBB",
      "            aACC",
      "            aACD",
      "            aACC",
      "            cACC",
      "            cACE",
      "            cACC",
      "           ghiBB",
      "            aA  ",
      "            aA  ",
      "            aA  ",
      "            cA  "
    ]
  ]
}