{
  "name": "multi_megatower1_4_ground",
  "refpalette": "c70cities:multi_megatower1_4_ground_palette",
  "xsize": 16,
  "zsize": 16,
  "slices": [
    [
      "a   vvvvvvvvvvvv",
      "a   vvvvvvvvvvvv",
      "a   vvvvvvvvvvvv",
      "bcddvvvvvvvvvvvv",
      "vvvvevvvvvvevvvv",
      "vvvvfvvvvvvvvvvv",
      "HHghi           ",
      "HHghi           ",
      "HHghi           ",
      "HHghi           ",
      "vvvvjvvvvvvvvvvv",
      "    e      e    ",
      "                ",
      "                ",
      "                ",
      "                "
    ],
    [
      "a   kl     mannn",
      "a   ko     pannn",
      "a   kqor   sannn",
      "adttkqr    mannn",
      "uwxyeABqrsoeannn",
      "    Cvvvvvvvvvvv",
      "                ",
      "                ",
      "                ",
      "                ",
      "DDDECvvvvvvvvvvv",
      "    e      eeeee",
      "                ",
      "                ",
      "                ",
      "                "
    ],
    [
      "a   k       annn",
      "a   k       annn",
      "a   k       annn",
      "ad  ko      annn",
      "u FIeJq o oeannn",
      "     vvvvvvvvvvv",
      "             KKa",
      "             KKa",
      "             KKa",
      "             KKa",
      "     vvvvvvvvvvv",
      "    e      e KKa",
      "             KKa",
      "             KKa",
      "             KKa",
      "             KKa"
    ],
    [
      "a   k    KKennnn",
      "a   k    KKennnn",
      "a   k    KKennnn",
      "adddk    KKennnn",
      "uL  eeeeeeeennnn",
      "     vvvvvvevnnn",
      "         KKeaann",
      "         KKeaann",
      "         KKeaann",
      "         KKeaann",
      "     vvvvvvevnnn",
      "    eeeeeeeeannn",
      "         KKeannn",
      "         KKeannn",
      "         KKeannn",
      "         KKeannn"
    ],
    [
      "a   MKKaannnn   ",
      "a   MKKaannnn   ",
      "a   MKKaannnn   ",
      "adddMKKaannnn   ",
      "uuuueKKaannenN  ",
      "     vvvvnnnn   ",
      "     KKaannnnO  ",
      "     KKaannnnO  ",
      "     KKaannnnO  ",
      "     KKaannnnO  ",
      "     vvvvnnnn   ",
      "    eKKaannen   ",
      "     KKaannnn   ",
      "     KKaannnn   ",
      "     KKaannnn   ",
      "     KKaannnn   "
    ],
    [
      "e   ennnn       ",
      "e   ennnn       ",
      "e   ennnn       ",
      "edPQennnnR N    ",
      "eeeeennnn  e    ",
      "KKKKennnn N R   ",
      "KKKKennnnO      ",
      "KKKKennnnO      ",
      "KKKKennnnO      ",
      "KKKKennnnO      ",
      "KKKKennnn       ",
      "eeeeennnn  e    ",
      "KKKKennnn R     ",
      "KKKKennnn       ",
      "KKKKennnn       ",
      "KKKKennnn       "
    ]
  ]
}