{
  "name": "multi_laboratory1_14_base2",
  "refpalette": "c70cities:multi_laboratory1_14_base2_palette",
  "xsize": 16,
  "zsize": 16,
  "slices": [
    [
      "aaaabaaaaaaaacdv",
      "aaaaaaaaaaaaacdv",
      "aaaaaaaaaaaaacdv",
      "aaaaaaaaaaaaacdv",
      "aaaaaaaaaaaaacdv",
      "aaaaaaaaaaaaacdv",
      "aaaaaaaaaaaaacdv",
      "aaaabaaaaaaaacdv",
      "aaaaaeeeeeeeecdv",
      "aaaaaeeeeeeeecdv",
      "aaaaaeeeeeeeecdv",
      "aaaaaeeeeeeeecdv",
      "aa!aa!eeeeeeecdv",
      "ccccccccccccccdv",
      "dddddddddddddddv",
      "vvvvvvvvvvvvvvvv"
    ],
    [
      "f   bggggggggcdv",
      "f   g h    h cdv",
      "i   g        cdv",
      "jj  g k ll m cdv",
      "    g   no pqcdv",
      "    r     st cdv",
      "    guuuuuuuucdv",
      "    bggggggggcdv",
      "    gwwxxxxwwcdv",
      "    y        cdv",
      "    gABCBABABcdv",
      "    g D D D Dcdv",
      " EEFgIDIDIDIDcdv",
      "ccccccccccccccdv",
      "dddddddddddddddv",
      "vvvvvvvvvvvvvvvv"
    ],
    [
      "    bggJJJJggcdv",
      "    g h    h cdv",
      "    g        cdv",
      "    g        cdv",
      "    g        cdv",
      "    K        cdv",
      "    gLM   N Lcdv",
      "    bggggggggcdv",
      "    gLOOOOOOLcdv",
      "    P        cdv",
      "    gQBRBQBQBcdv",
      "    g D D D Dcdv",
      "    g D D D Dcdv",
      "ccccccccccccccdv",
      "dddddddddddddddv",
      "vvvvvvvvvvvvvvvv"
    ],
    [
      "    bggSSSSggcdv",
      "    g        cdv",
      "   Tg        cdv",
      "   Tg        cdv",
      "    g        cdv",
      "    U        cdv",
      "    g        cdv",
      "    bggggggggcdv",
      "    g OOOOOO cdv",
      "    g        cdv",
      "    gBBBBBBBBcdv",
      "    g D D D Dcdv",
      "    g D D D Dcdv",
      "ccccccccccccccdv",
      "dddddddddddddddv",
      "vvvvvvvvvvvvvvvv"
    ],
    [
      "    bggggggggcdv",
      "    g        cdv",
      "    g        cdv",
      "    g        cdv",
      "    g        cdv",
      "    g        cdv",
      "    g        cdv",
      "    bggggggggcdv",
      "    gVVVVVVVVcdv",
      "    gVVVVVVVVcdv",
      "    gVVVVVVVVcdv",
      "    gVVVVVVVVcdv",
      "    gWVWVWVWVcdv",
      "ccccccccccccccdv",
      "dddddddddddddddv",
      "vvvvvvvvvvvvvvvv"
    ],
    [
      "X XXbggggggggcdv",
      "XYXXUZZZZZZZZcdv",
      "XYXXUZ0ZZZZ0Zcdv",
      "11XXUZZZZZZZZcdv",
      "XXXXUZZZZZZZZcdv",
      "XXXXUZ2ZZZZYZcdv",
      "XXXXUZZZZZZZZcdv",
      "ggggbggggggggcdv",
      "3333g44444444cdv",
      "3313g4 4 4 4ccdv",
      "3313g4 4 4 4ccdv",
      "3313g4 4 4 4ccdv",
      "3333g4 4 4 4ccdv",
      "ccccccccccccccdv",
      "dddddddddddddddv",
      "vvvvvvvvvvvvvvvv"
    ]
  ]
}