{
  "name": "multi_militarycamp1_0_ground",
  "refpalette": "c70cities:multi_militarycamp1_0_ground_palette",
  "xsize": 16,
  "zsize": 16,
  "slices": [
    [
      "zzaazaazzaazzaaz",
      "zbbbbzabbbbbbbbz",
      "zb!cccczHHHH!=dz",
      "abccccczHHHHHHH=",
      "abccccczHHHHHHHH",
      "aaccccczHHHHHHHH",
      "zzcccccHHHHHHHHH",
      "zbeeeeecHHdzHHHH",
      "zbcccccz=zzz=HHH",
      "abzzfzzzzzzzdHHH",
      "zbzzzzzzdzzzzHHH",
      "zbzzzzzzzzzzzzHH",
      "abzzzzzzzzzz=HH=",
      "abzzzzzzzzzzzd=z",
      "zbbbbbazbbbbzbbb",
      "zaazzaazazzazzaa"
    ],
    [
      "                ",
      " ghhhhhgiiiiigii",
      " hjkhlmh    mnn ",
      " ho hpqhr  s  tt",
      " hhuh whx   x  y",
      " hA    hx   xB  ",
      " hCDE  F   s    ",
      " hI JKLh        ",
      " hgMNOghP       ",
      " ghh hhgQ       ",
      " iRSgSRi        ",
      " iTSSSUV        ",
      " iRSSSRiW       ",
      " i XXX iYZ012Z W",
      " giiiiigiiiiigii",
      "                "
    ],
    [
      "                ",
      " ghhhhhgiiiiigii",
      " h  h  h     n  ",
      " h3 h  4   s  5 ",
      " hh6h  4    7   ",
      " h8 9  h        ",
      " h@    #   s    ",
      " h     h        ",
      " hgM$%gh        ",
      " ghh hhg        ",
      " iR%f%Ri        ",
      " i Nf  V        ",
      " iR   Ri        ",
      " i     i        ",
      " giiiiigiiiiigii",
      "                "
    ],
    [
      "                ",
      " ghhhhhg^^^^^&^^",
      " h  h  h        ",
      " h  h  4   *((((",
      " hh)h  4   *((((",
      " h     h   *((((",
      " h     +   *((((",
      " h-   -h        ",
      " hg XXgh        ",
      " gh[[[hg        ",
      " ]{%f%{}        ",
      " ] $f\\ }        ",
      " ]{ | {}        ",
      " ]     }        ",
      " &`````&`````&``",
      "                "
    ],
    [
      "                ",
      " g:::::g        ",
      " ; 'S'',        ",
      " ;''S'',        ",
      " ;SSS'',        ",
      " ;''''',        ",
      " ;''''',        ",
      " ;ff'ff,        ",
      " ;ff'ff,        ",
      " g.[[[.g        ",
      "  {XXX{         ",
      "    {           ",
      "  {   {         ",
      "                ",
      "                ",
      "                "
    ],
    [
      "                ",
      " /&&&&&/        ",
      " &<    &        ",
      " &     &        ",
      " &     &        ",
      " &     &        ",
      " &:: ::&        ",
      " &ff ff&        ",
      " &ff ff&        ",
      " /&&&&&/        ",
      "  >RRR>         ",
      "  >?M?>         ",
      "  >RRR>         ",
      "   \u00a3 \u00a3          ",
      "                ",
      "                "
    ]
  ]
}