{
  "name": "multi_laboratory1_12_base5",
  "refpalette": "c70cities:multi_laboratory1_12_base5_palette",
  "xsize": 16,
  "zsize": 16,
  "slices": [
    [
      " a          bcdv",
      " a           cdv",
      " a           cdv",
      "ea         affdv",
      "a  gh     aijcdv",
      "a          affdv",
      "             cdv",
      "             cdv",
      "            bcdv",
      "             cdv",
      "           affdv",
      "   kh     almcdv",
      "           affdv",
      "             cdv",
      "            ncdv",
      "            ocdv"
    ],
    [
      " a          bbdv",
      " a           cdv",
      " a           cdv",
      "ea         affdv",
      "a   h     aijcdv",
      "a          affdv",
      "             cdv",
      "             cdv",
      "            bcdv",
      "            bcdv",
      "           affdv",
      "    h     almcdv",
      "           affdv",
      "             ndv",
      "            pndv",
      "            ncdv"
    ],
    [
      " a          bcdv",
      " a           cdv",
      " a           cdv",
      "ea         affdv",
      "a   h     aijcdv",
      "a          affdv",
      "             cdv",
      "             cdv",
      "            bcdv",
      "             cdv",
      "           affdv",
      "    h     almcdv",
      "           affdv",
      "             cdv",
      "            qcdv",
      "            ncdv"
    ],
    [
      " a          bcdv",
      " a          bcdv",
      " a          bcdv",
      "ea         affdv",
      "a   h     aijcdv",
      "a          affdv",
      "             bdv",
      "             bdv",
      "            bbdv",
      "             cdv",
      "           affdv",
      "    h     almcdv",
      "           affdv",
      "             cdv",
      "             cdv",
      "            ncdv"
    ],
    [
      " a          bcdv",
      " a           cdv",
      " a           cdv",
      "ea         affdv",
      "a   h     aijcdv",
      "a          affdv",
      "             cdv",
      "             cdv",
      "            bcdv",
      "             cdv",
      "           affdv",
      "    h     almcdv",
      "           affdv",
      "             cdv",
      "             cdv",
      "            pcdv"
    ],
    [
      " arrrrrrrrrrscdv",
      " arrrrrrrrrrbcdv",
      " arrrrrrrrrrbcdv",
      "earrrrrrrrffffdv",
      "arrrhrrrrrftjcdv",
      "arrrrrrrrrffffdv",
      "rrrrrrrrrrrrbcdv",
      "rrrrrrrrrrrrbcdv",
      "rrrrrrrrrrrrscdv",
      "rrrrrrrrrrrrbcdv",
      "rrrrrrrrrrffffdv",
      "rrrrhrrrrrfumcdv",
      "rrrrrrrrrrffffdv",
      "rrrrrrrrrrrrbcdv",
      "rrrrrrrrrrrrncdv",
      "rrrrrrrrrrrrpcdv"
    ]
  ]
}