{
  "name": "multi_laboratory1_10_base5",
  "refpalette": "c70cities:multi_laboratory1_10_base5_palette",
  "xsize": 16,
  "zsize": 16,
  "slices": [
    [
      "zzzzzzzzzzzzzzzz",
      "aaaaaaaaaaaaaaaz",
      "bbbbccccccccccaz",
      "    deeeeeeeecaz",
      "    deeeeeeeecaz",
      "fffffeeeeeeeecaz",
      "    feeeeeeeecaz",
      "    fggggggggcaz",
      "    f   h    caz",
      "    f        caz",
      "    f        caz",
      " i  f        caz",
      " ijjf        caz",
      "kkkkf        caz",
      "kkkkf        caz",
      "ddddfddddddddcaz"
    ],
    [
      "zzzzzzzzzzzzzzzz",
      "aaaaaaaaaaaaaaaz",
      "bbbbccccccccccaz",
      "    dglm lm ncaz",
      "    dg      ocaz",
      "ddddfg      ncaz",
      "    dglm lm ncaz",
      "    dggggggpgcaz",
      "    d    qqqqcaz",
      "    d        caz",
      "    d        caz",
      "kk  d        caz",
      "jjr d        caz",
      "    d        caz",
      "    d        caz",
      "ddddfddddddddcaz"
    ],
    [
      "zzzzzzzzzzzzzzzz",
      "aaaaaaaaaaaaaaaz",
      "bbbbccccccccccaz",
      "    dglm lm  caz",
      "    dg      scaz",
      "ddddfg       caz",
      "    dglm lm  caz",
      "    dggggggtgcaz",
      "    d        caz",
      "kk  d        caz",
      "jjr d        caz",
      "  r d        caz",
      "    d        caz",
      "    d        caz",
      "    d        caz",
      "ddddfddddddddcaz"
    ],
    [
      "zzzzzzzzzzzzzzzz",
      "aaaaaaaaaaaaaaaz",
      "bbbbccccccccccaz",
      "    dg      ucaz",
      "    dg       caz",
      "ddddfg      wcaz",
      "kkkkdg      xcaz",
      "kkkkdggggggggcaz",
      "jjr d        caz",
      "  r d        caz",
      "    d        caz",
      "    d        caz",
      "    d        caz",
      "    d        caz",
      "    d        caz",
      "ddddfddddddddcaz"
    ],
    [
      "zzzzzzzzzzzzzzzz",
      "aaaaaaaaaaaaaaaz",
      "bbbbccccccccccaz",
      "    dg       caz",
      "h   dg       caz",
      "ddddfg      wcaz",
      "    dg     wwcaz",
      "    dggggggggcaz",
      " ijjd        caz",
      "  kkd        caz",
      "    d        caz",
      "    d        caz",
      "    d        caz",
      "    d        caz",
      "    d        caz",
      "ddddfddddddddcaz"
    ],
    [
      "zzzzzzzzzzzzzzzz",
      "aaaaaaaaaaaaaaaz",
      "bbbbccccccccccaz",
      "    dyyyyyyyycaz",
      " h  dyyyyyyyycaz",
      "ddddfyyyyyyyycaz",
      "    dyyyyyyyycaz",
      "    dddddddddcaz",
      "    dyyyyyyyycaz",
      " i  dyyyyyyyycaz",
      " ijjdyyyyyyyycaz",
      "  kkdyyyyyyyycaz",
      "    dyyyyyyyycaz",
      "    dyyyyyyyycaz",
      "    dyyyyyyyycaz",
      "ddddfddddddddcaz"
    ]
  ]
}