{
  "name": "multi_megatower1_1_floor4",
  "refpalette": "c70cities:multi_megatower1_1_floor4_palette",
  "xsize": 16,
  "zsize": 16,
  "slices": [
    [
      "            ab  ",
      "            cb  ",
      "            cbde",
      "            cbff",
      "           ghibb",
      "            abbb",
      "            abjj",
      "            abjj",
      "            cbjj",
      "            cbjj",
      "            cbbb",
      "           ghibb",
      "            abbb",
      "            abbb",
      "            abbb",
      "            cbbb"
    ],
    [
      "            ak  ",
      "            ckd ",
      "            ckl ",
      "            ck  ",
      "           ghicm",
      "            an  ",
      "            an  ",
      "            an  ",
      "            cn  ",
      "            cnoo",
      "            cnpq",
      "           ghip ",
      "            anr ",
      "            anss",
      "            ant ",
      "            cnuw"
    ],
    [
      "            akf ",
      "            ckl ",
      "            ck  ",
      "            ck  ",
      "           ghicx",
      "            an  ",
      "            an  ",
      "            ay  ",
      "            cy  ",
      "            cnoo",
      "            cnp ",
      "           ghip ",
      "            an A",
      "            anss",
      "            anB ",
      "            cn  "
    ],
    [
      "            aklC",
      "            ck  ",
      "            ck  ",
      "            ck D",
      "           ghicc",
      "            an  ",
      "            an  ",
      "            aE  ",
      "            cE  ",
      "            cnoo",
      "            cnpF",
      "           ghip ",
      "            an I",
      "            anss",
      "            an  ",
      "            cn  "
    ],
    [
      "            aJ e",
      "            cJ C",
      "            cJ  ",
      "            cJ  ",
      "           ghicc",
      "            an  ",
      "            an  ",
      "            an  ",
      "            cn  ",
      "            cnoo",
      "            cnpK",
      "           ghip ",
      "            anL ",
      "            anss",
      "            anL ",
      "            cn  "
    ],
    [
      "            aM  ",
      "            cM e",
      "            cM f",
      "            cMdf",
      "           ghiNN",
      "            aMOO",
      "            aMOO",
      "            aMOO",
      "            cMOO",
      "            cMPP",
      "            cMbb",
      "           ghiNN",
      "            aMbb",
      "            aMbb",
      "            aMLL",
      "            cM  "
    ]
  ]
}