{
  "name": "multi_laboratory1_13_ground",
  "refpalette": "c70cities:multi_laboratory1_13_ground_palette",
  "xsize": 16,
  "zsize": 16,
  "slices": [
    [
      "aaaabcccvvzddddz",
      "aaaabcccvedddzzz",
      "aaaabcccvedddddz",
      "aaaabcccvdddddzd",
      "aaaabcccveedddzz",
      "aaaabcccvedddddz",
      "aaaabcccveddzzdz",
      "aaaabcccveedddzd",
      "aaaabcccveeddddz",
      "aaaabcccvededdzd",
      "aaaabcccvvddddzd",
      "aaaabccceeddddzz",
      "aaaabcccvddddddz",
      "aaaabcccveddzdzz",
      "aaaabcccvedddddz",
      "aaaabcccveedddzz"
    ],
    [
      " f  g           ",
      "hh  g     ijk l ",
      "hh mb           ",
      " n  g           ",
      "oooop     ijqr l",
      "sss!p           ",
      "  stg       l   ",
      "oooop     ijk   ",
      "    g           ",
      "u   b         l ",
      "wx  g     ikqr  ",
      "bxy g           ",
      "bx  g           ",
      "bx  g  A  ir k l",
      "bxy g  B        ",
      "Cx  g  B      l "
    ],
    [
      "    g           ",
      "    g           ",
      "    b           ",
      "    D           ",
      "oooop           ",
      "E s g           ",
      "  t g           ",
      "oooop           ",
      "    D           ",
      "    b           ",
      "    g           ",
      "    g           ",
      "    g  A        ",
      "    g  B        ",
      " F  g  B        ",
      "IJ  g  B        "
    ],
    [
      "    g           ",
      "    g           ",
      "    b           ",
      "    D           ",
      "oooop           ",
      "  E g           ",
      "    g           ",
      "oooop           ",
      "    D           ",
      "    b           ",
      "    g           ",
      "    g  A        ",
      "    g  B        ",
      "    g  K        ",
      "    g  K        ",
      "    g  L        "
    ],
    [
      "    g           ",
      "    g           ",
      "    b           ",
      "    D           ",
      "oooop           ",
      "    g           ",
      "    g           ",
      "oooop           ",
      "    D           ",
      "    b           ",
      "    g  A        ",
      "    g  B        ",
      "    g  L        ",
      "    g  L        ",
      "    g  L        ",
      "    g  K        "
    ],
    [
      "MNMOg           ",
      "MNMOg           ",
      "OOOOb           ",
      "OOOOg           ",
      "oooop           ",
      "MMMOg           ",
      "MMMOg           ",
      "oooop           ",
      "OOOOg           ",
      "OOOOb  A        ",
      "NMMOg  B        ",
      "NMMOg  K        ",
      "OOOOg  L        ",
      "OOOOg  K        ",
      "NMNOg  K        ",
      "NMNOg  L        "
    ]
  ]
}