{
  "name": "multi_flatapartment_2_floor2",
  "refpalette": "c70cities:multi_flatapartment_2_floor2_palette",
  "xsize": 16,
  "zsize": 16,
  "slices": [
    [
      "                ",
      "abbbbabbbabbbba ",
      "ccccccccccccccb ",
      "dddddddddddddcb ",
      "dddddddddddddcb ",
      "dddddddddddddca ",
      "dddddddddddddcb ",
      "dddddddddddddcb ",
      "dddddddddddddcb ",
      "dddddddddddddcb ",
      "dddddddddddddca ",
      "dddddddddddddcb ",
      "dddddddddddddcb ",
      "ccccccccccccccb ",
      "abbbbabbbabbbba ",
      "                "
    ],
    [
      "                ",
      "abeebabebabeeba ",
      "         f    b ",
      " g g hii hj   e ",
      " kkk h   h  lmb ",
      "hhhhhh   hhhhha ",
      "hn  ohpp q    b ",
      "hn  ohhhhh    e ",
      "h    r  sh tt e ",
      "hg g h uwhxyyAb ",
      "hkkk h uwhhhhha ",
      "BCDD h   f   Eb ",
      "     hhhhhj  Fe ",
      "         I  lJb ",
      "abeebabebabeeba ",
      "                "
    ],
    [
      "                ",
      "abKKbabKbabKKba ",
      "         L    b ",
      "     h   h    K ",
      "     h   h M Nb ",
      "hhhhhh   hhhhha ",
      "hO   hOO P    b ",
      "hO   hhhhh    K ",
      "h    Q   h    K ",
      "h    h   h    b ",
      "h    h   hhhhha ",
      "     h   L R Sb ",
      "     hhhhh    K ",
      "         T    b ",
      "abKKbabKbabKKba ",
      "                "
    ],
    [
      "                ",
      "abKKbabKbabKKba ",
      "         h    b ",
      "     h   h    K ",
      "     h   h U  b ",
      "hhhhhh   hhhhha ",
      "hO   hOO h    b ",
      "hO   hhhhh    K ",
      "h    h   h    K ",
      "h    h   h    b ",
      "h    h   hhhhha ",
      "     h   h   Vb ",
      "     hhhhh    K ",
      "         h    b ",
      "abKKbabKbabKKba ",
      "                "
    ],
    [
      "                ",
      "abbbbabbbabbbba ",
      "h    h   hWWWWb ",
      "h    h   hWWWWb ",
      "h    h X hWWWWb ",
      "hhhhhh   hhhhha ",
      "hY   h   h    b ",
      "h  Z hhhhh    b ",
      "h    h   h    b ",
      "h    h   h    b ",
      "h    h   hhhhha ",
      "h    h   hWWWWb ",
      "h    hhhhhWWWWb ",
      "h    h   hWWWWb ",
      "abbbbabbbabbbba ",
      "                "
    ],
    [
      "                ",
      "011110111011110 ",
      "cccccccccccccc1 ",
      "dddddddddddddc1 ",
      "dddddddddddddc1 ",
      "dddddddddddddc0 ",
      "dddddddddddddc1 ",
      "dddddddddddddc1 ",
      "dddddddddddddc1 ",
      "dddddddddddddc1 ",
      "dddddddddddddc0 ",
      "dddddddddddddc1 ",
      "dddddddddddddc1 ",
      "cccccccccccccc1 ",
      "011110111011110 ",
      "                "
    ]
  ]
}