{
  "name": "multi_communitycenter_5_base1",
  "refpalette": "c70cities:multi_communitycenter_5_base1_palette",
  "xsize": 16,
  "zsize": 16,
  "slices": [
    [
      "HHHHHHHHHHHHHHHH",
      "HHHHHHHHHHHHHHHH",
      "HHHHHHHHHHHHHHHH",
      "HHHHHHHHHHHHHHHH",
      "HHHHHHHHHHHHHHHH",
      "HHHHHHHHHHHHHHHH",
      "HHHHHHHHHHHHHHHH",
      "HHHHHHHHHHHHHHaa",
      "HHHHHHHHHHHHHHab",
      "HHHHHHHHHHHHHHab",
      "HHHHHHHHHHHHHHaa",
      "HHHHHHHHHHHHHHHH",
      "HHHHHHHHHHHHHHHH",
      "HHHHHHHHHHHHHHHH",
      "HHHHHHHHHHHHHHHH",
      "vvvvvvvvvvvvvvvv"
    ],
    [
      "cdcdecdcdecdcdec",
      "                ",
      "                ",
      "                ",
      "                ",
      "                ",
      "                ",
      "fgfgefgfgefgfgeh",
      "              ij",
      "cdcd cdcd cdcdij",
      "iiiiiiiiiiiiiiik",
      "iiiiiiiiiiiiiiii",
      "iiiiiiiiiiiiiiii",
      "iiiiiiiiiiiiiiii",
      "iiiiiiiiiiiiiiii",
      "vvvvvvvvvvvvvvvv"
    ],
    [
      "    e    e    e ",
      "                ",
      "                ",
      "                ",
      "                ",
      "                ",
      "                ",
      "    e    e    eh",
      "              ij",
      "              ij",
      "iiiiiiiiiiiiiiik",
      "iiiiiiiiiiiiiiii",
      "iiiiiiiiiiiiiiii",
      "iiiiiiiiiiiiiiii",
      "iiiiiiiiiiiiiiii",
      "vvvvvvvvvvvvvvvv"
    ],
    [
      "    e    e    e ",
      "                ",
      "                ",
      "                ",
      "                ",
      "                ",
      "                ",
      "    e    e    eh",
      "              ij",
      "              ij",
      "iiiiiiiiiiiiiiik",
      "iiiiiiiiiiiiiiii",
      "iiiiiiiiiiiiiiii",
      "iiiiiiiiiiiiiiii",
      "iiiiiiiiiiiiiiii",
      "vvvvvvvvvvvvvvvv"
    ],
    [
      "llllellllellllel",
      "    e    e    e ",
      "    e    e    e ",
      "    e    e    e ",
      "    e    e    e ",
      "    e    e    e ",
      "    e    e    e ",
      "llllellllellllee",
      "    e    e    ej",
      "    e    e    ej",
      "iiiiiiiiiiiiiiak",
      "iiiiiiiiiiiiiiii",
      "iiiiiiiiiiiiiiii",
      "iiiiiiiiiiiiiiii",
      "iiiiiiiiiiiiiiii",
      "vvvvvvvvvvvvvvvv"
    ],
    [
      "iiiiiiiiiiiiiiii",
      "iiiiiiiiiiiiiiii",
      "iiiiiiiiiiiiiiii",
      "iiiiiiiiiiiiiiii",
      "iiiiiiiiiiiiiiii",
      "iiiiiiiiiiiiiiii",
      "iiiiiiiiiiiiiiii",
      "iiiiiiiiiiiiiiii",
      "iiiiiiiiiiiiiiij",
      "iiiiiiiiiiiiiiij",
      "iiiiiiiiiiiiiiik",
      "iiiiiiiiiiiiiiii",
      "iiiiiiiiiiiiiiii",
      "iiiiiiiiiiiiiiii",
      "iiiiiiiiiiiiiiii",
      "vvvvvvvvvvvvvvvv"
    ]
  ]
}