{
  "name": "multi_megatower1_3_floor4",
  "refpalette": "c70cities:multi_megatower1_3_floor4_palette",
  "xsize": 16,
  "zsize": 16,
  "slices": [
    [
      "                ",
      "                ",
      "                ",
      "                ",
      "                ",
      "                ",
      "                ",
      "                ",
      "                ",
      "                ",
      "                ",
      "    a      a    ",
      "bcccdbbbcccdbbbc",
      "eeeefeeeeeefeeee",
      "ghhheeeeeeeeeeee",
      "g   eeeeeeeeeeee"
    ],
    [
      "                ",
      "                ",
      "                ",
      "                ",
      "                ",
      "                ",
      "                ",
      "                ",
      "                ",
      "                ",
      "                ",
      "    a      a    ",
      "bcccdbbbcccdbbbc",
      "ijklfmmmmmmfmmmm",
      "ghhhgnop  qrq  p",
      "g   gs   turwx  "
    ],
    [
      "                ",
      "                ",
      "                ",
      "                ",
      "                ",
      "                ",
      "                ",
      "                ",
      "                ",
      "                ",
      "                ",
      "    a      a    ",
      "bcccdbbbcccdbbbc",
      "i   fmyyyymfmyyy",
      "ghhhg A   BrC   ",
      "g   g      r    "
    ],
    [
      "                ",
      "                ",
      "                ",
      "                ",
      "                ",
      "                ",
      "                ",
      "                ",
      "                ",
      "                ",
      "                ",
      "    a      a    ",
      "bcccdbbbcccdbbbc",
      "i   fmDDDDmfmDDD",
      "ghhhg EFEF r EFI",
      "g   g      r    "
    ],
    [
      "                ",
      "                ",
      "                ",
      "                ",
      "                ",
      "                ",
      "                ",
      "                ",
      "                ",
      "                ",
      "                ",
      "    a      a    ",
      "bcccdbbbcccdbbbc",
      "i   fmmmmmmfmmmm",
      "ghhhg      r    ",
      "g   g      r    "
    ],
    [
      "                ",
      "                ",
      "                ",
      "                ",
      "                ",
      "                ",
      "                ",
      "                ",
      "                ",
      "                ",
      "                ",
      "    a      a    ",
      "bcccdbbbcccdbbbc",
      "JJJJfJJJJJJfJJJJ",
      "KLLLK      K    ",
      "K   K      K    "
    ]
  ]
}