{
  "name": "multi_militarybase_1_base1",
  "refpalette": "c70cities:multi_militarybase_1_base1_palette",
  "xsize": 16,
  "zsize": 16,
  "slices": [
    [
      "vabbbbcccbbdda  ",
      "vabbbbcccbbdda  ",
      "vabbbbbbbbbdda  ",
      "vabbbcbbbcbdda  ",
      "vabbbccbccbdda  ",
      "vabbbbbbbbbdda  ",
      "vabbbbbbbbbddaaa",
      "vabbbbbbbbbddddd",
      "vabbbbbbbbbddddd",
      "vabbbbbbbbbbbaaa",
      "vabbbbbbbbbbbbbb",
      "vabbbbbbbbbbbbbb",
      "vabbbbbbbbbbbbbb",
      "vabbbbbbbbbbbbbb",
      "vaaaaaaaaaaaaaaa",
      "vvvvvvvvvvvvvvvv"
    ],
    [
      "v            e  ",
      "vf           e  ",
      "v  v         v  ",
      "vf           e  ",
      "v            e  ",
      "vf           e  ",
      "v  v    v    vee",
      "v               ",
      "v               ",
      "v            ggg",
      "v  v    v    vhh",
      "v               ",
      "vi              ",
      "vii            j",
      "viivkkkkvllllv j",
      "vvvvvvvvvvvvvvvv"
    ],
    [
      "v               ",
      "vf              ",
      "v  v         v  ",
      "vf              ",
      "v               ",
      "vm              ",
      "v  v    v    v  ",
      "v               ",
      "v               ",
      "v            ggg",
      "v  v    v    v  ",
      "v               ",
      "v               ",
      "vi              ",
      "viiv    v    v n",
      "vvvvvvvvvvvvvvvv"
    ],
    [
      "v               ",
      "v!              ",
      "v  v         v  ",
      "vm              ",
      "v               ",
      "v               ",
      "v  v    v    v  ",
      "v               ",
      "v               ",
      "v            ggg",
      "v  v    v    v  ",
      "v               ",
      "v               ",
      "v               ",
      "vi v    v    v  ",
      "vvvvvvvvvvvvvvvv"
    ],
    [
      "v               ",
      "v               ",
      "v  v         v  ",
      "v               ",
      "v               ",
      "v               ",
      "v  v    v    v  ",
      "v               ",
      "v               ",
      "v            ggg",
      "v  v    v    v  ",
      "v               ",
      "v               ",
      "v               ",
      "v  v    v    v  ",
      "vvvvvvvvvvvvvvvv"
    ],
    [
      "vooaooooaooooaoo",
      "vooaooooaooooaoo",
      "vaaaaaaaaaaaaaoo",
      "vooaooooaooooaoo",
      "vooaooooaooooaoo",
      "vooaooooaooooaoo",
      "vaaaaaaaaaaaaaaa",
      "vooaooooaooooaoo",
      "vooaooooaooooaoo",
      "vooaooooaooooaoo",
      "vooaooooaooooaoo",
      "vooaooooaooooaoo",
      "vooaooooaooooaoo",
      "vooaooooaooooaoo",
      "vaaaaaaaaaaaaaaa",
      "vvvvvvvvvvvvvvvv"
    ]
  ]
}