{
  "name": "multi_communitycenter_8_base1",
  "refpalette": "c70cities:multi_communitycenter_8_base1_palette",
  "xsize": 16,
  "zsize": 16,
  "slices": [
    [
      "HHHHHHHHHHHHHHHv",
      "HHHHHHHHHHHHHHHv",
      "HHHHHHHHHHHHHHHv",
      "HHHHHHHHHHHHHHHv",
      "HHHHHHHHHHHHHHHv",
      "HHHHHHHHHHHHHHHv",
      "HHHHHHHHHHHHHHHv",
      "aaaaHHHHHHHHHHHv",
      "bbbaccccHHHHHHHv",
      "bbbaccccHHHHHHHv",
      "aaaaccccHHHHHHHv",
      "HHHHHHccHHHHHHHv",
      "HHHHHHccHHHHHHHv",
      "HHHHHHHHHHHHHHHv",
      "HHHHHHHHHHHHHHHv",
      "vvvvvvvvvvvvvvvv"
    ],
    [
      "dedf    fededfgv",
      "              gv",
      "              gv",
      "              gv",
      "              gv",
      "              gv",
      "              gv",
      "hijfkklkfmnmnfgv",
      "oopgqr  g     gv",
      "sspgqt  geded!gv",
      "aauggg  gggggggv",
      "aaaaagwxgggggggv",
      "aaaaagyAgggggggv",
      "gggggggggggggggv",
      "gggggggggggggggv",
      "vvvvvvvvvvvvvvvv"
    ],
    [
      "   f    f    fgv",
      "              gv",
      "              gv",
      "              gv",
      "              gv",
      "              gv",
      "              gv",
      "BCjfkkDkf    fgv",
      "  pgqE  g     gv",
      "  pgqF  g     gv",
      "ssuggg  gggggggv",
      "aaaaagIJgggggggv",
      "aaaaag!Agggggggv",
      "gggggggggggggggv",
      "gggggggggggggggv",
      "vvvvvvvvvvvvvvvv"
    ],
    [
      "   f    f    fgv",
      "              gv",
      "              gv",
      "              gv",
      "              gv",
      "              gv",
      "              gv",
      "jjjfkkkkf    fgv",
      "  pg    g     gv",
      "  pg    g     gv",
      "  uggg  gggggggv",
      "  Kaag  gggggggv",
      "  Kaag Lgggggggv",
      "gggggggggggggggv",
      "gggggggggggggggv",
      "vvvvvvvvvvvvvvvv"
    ],
    [
      "MMMfMMMMfMMMMfgv",
      "   f    f    fgv",
      "   f    f    fgv",
      "   f    f    fgv",
      "   f    f    fgv",
      "   f    f    fgv",
      "   f    f    fgv",
      "fffffffffMMMMfgv",
      "  pfL  Lf    fgv",
      "  pfN  Nf    fgv",
      "  uOOg Lgggggggv",
      "     g Lgggggggv",
      "     gLLgggggggv",
      "gggggggggggggggv",
      "gggggggggggggggv",
      "vvvvvvvvvvvvvvvv"
    ],
    [
      "gggggggggggggggv",
      "gggggggggggggggv",
      "gggggggggggggggv",
      "gggggggggggggggv",
      "gggggggggggggggv",
      "gggggggggggggggv",
      "gggggggggggggggv",
      "gggggggggggggggv",
      "  paaggggggggggv",
      "  pOOggggggggggv",
      "  u  ggggggggggv",
      "     ggggggggggv",
      "     ggggggggggv",
      "gggggggggggggggv",
      "gggggggggggggggv",
      "vvvvvvvvvvvvvvvv"
    ]
  ]
}