{
  "name": "multi_laboratory1_4_base1",
  "refpalette": "c70cities:multi_laboratory1_4_base1_palette",
  "xsize": 16,
  "zsize": 16,
  "slices": [
    [
      "vabccccccccdcccc",
      "vabccccccccccccc",
      "vabccccccccccccc",
      "vabccccccccccccc",
      "vabccccccccccccc",
      "vabccccccccccccc",
      "vabccccccccccccc",
      "vabccccccccdcccc",
      "vabeeeeeeeeccccc",
      "vabeeeeeeeeccccc",
      "vabeeeeeeeeccccc",
      "vabeeeeeeeeccccc",
      "vabeeeeeeeeccccc",
      "vabbbbbbbbbbbbbb",
      "vaaaaaaaaaaaaaaa",
      "vvvvvvvvvvvvvvvv"
    ],
    [
      "vabfg      d    ",
      "vabf  h h  i    ",
      "vabj  klk  i    ",
      "vabm  non  p    ",
      "vabj  h h  i    ",
      "vabfg      i    ",
      "vabf  qqrssi    ",
      "vabttttttttd   u",
      "vabwwxxxxwwt   y",
      "vab        A   y",
      "vabBCDCBCBCt   y",
      "vab E E E Et   y",
      "vabFEFEFEFEtuyy!",
      "vabbbbbbbbbbbbbb",
      "vaaaaaaaaaaaaaaa",
      "vvvvvvvvvvvvvvvv"
    ],
    [
      "vabI       d    ",
      "vabJ       i    ",
      "vabK  L    i    ",
      "vab     M  N    ",
      "vabO       i    ",
      "vabP       i    ",
      "vabI       i    ",
      "vabttttttttd   Q",
      "vabR S SSSRt   T",
      "vab        U    ",
      "vabVCWCVCVCt    ",
      "vab E E E Et    ",
      "vab E E E EtQXYQ",
      "vabbbbbbbbbbbbbb",
      "vaaaaaaaaaaaaaaa",
      "vvvvvvvvvvvvvvvv"
    ],
    [
      "vab        d    ",
      "vab        Z    ",
      "vab        i    ",
      "vab        i    ",
      "vab        i    ",
      "vab0       i    ",
      "vab0       i    ",
      "vabttttttttd   R",
      "vab S SSSS t    ",
      "vab        t    ",
      "vabCCCCCCCCt    ",
      "vab E E E Et    ",
      "vab E E E EtR 1R",
      "vabbbbbbbbbbbbbb",
      "vaaaaaaaaaaaaaaa",
      "vvvvvvvvvvvvvvvv"
    ],
    [
      "vab        d    ",
      "vab        i    ",
      "vab        i    ",
      "vab        Z    ",
      "vab        Z    ",
      "vab        Z    ",
      "vab        Z    ",
      "vabttttttttd    ",
      "vab222 2222t    ",
      "vab2 222222t    ",
      "vab32222222t    ",
      "vab22222222t    ",
      "vab42424242t    ",
      "vabbbbbbbbbbbbbb",
      "vaaaaaaaaaaaaaaa",
      "vvvvvvvvvvvvvvvv"
    ],
    [
      "vab55555555d5555",
      "vab5555555565555",
      "vab5575558565555",
      "vab5575557565555",
      "vab5575557565555",
      "vab5575557565555",
      "vab5555555565555",
      "vab99999999d5555",
      "vab@@@@@@@@95555",
      "vab@ @ @ @ 95555",
      "vab@ @ @ @ 95555",
      "vab@!@ @ @ 95555",
      "vab@ @ @ @ 95555",
      "vabbbbbbbbbbbbbb",
      "vaaaaaaaaaaaaaaa",
      "vvvvvvvvvvvvvvvv"
    ]
  ]
}