{
  "name": "multi_megatower1_4_ground",
  "refpalette": "c70cities:multi_megatower1_4_ground_palette",
  "xsize": 16,
  "zsize": 16,
  "slices": [
    [
      "a   vvvvvvvvvvvv",
      "a   vvvvvvvvvvvv",
      "a   vvvvvvvvvvvv",
      "bcddvvvvvvvvvvvv",
      "vvvvevvvvvvevvvv",
      "vvvvfvvvvvvvvvvv",
      "HHghi           ",
      "HHghi           ",
      "HHghi           ",
      "HHghi           ",
      "vvvvjvvvvvvvvvvv",
      "    e      e    ",
      "                ",
      "                ",
      "                ",
      "                "
    ],
    [
      "a   kl     mannn",
      "a   ko     mannn",
      "a   kpoq   rannn",
      "adsskpq    mannn",
      "tuwxeyApqroeannn",
      "    Bvvvvvvvvvvv",
      "                ",
      "                ",
      "                ",
      "                ",
      "CCCDBvvvvvvvvvvv",
      "    e      eeeee",
      "                ",
      "                ",
      "                ",
      "                "
    ],
    [
      "a   k       annn",
      "a   k       annn",
      "a   k       annn",
      "ad  ko      annn",
      "t EFeIp o oeannn",
      "     vvvvvvvvvvv",
      "             JJa",
      "             JJa",
      "             JJa",
      "             JJa",
      "     vvvvvvvvvvv",
      "    e      e JJa",
      "             JJa",
      "             JJa",
      "             JJa",
      "             JJa"
    ],
    [
      "a   k    JJennnn",
      "a   k    JJennnn",
      "a   k    JJennnn",
      "adddk    JJennnn",
      "tK  eeeeeeeennnn",
      "     vvvvvvevnnn",
      "         JJeaann",
      "         JJeaann",
      "         JJeaann",
      "         JJeaann",
      "     vvvvvvevnnn",
      "    eeeeeeeeannn",
      "         JJeannn",
      "         JJeannn",
      "         JJeannn",
      "         JJeannn"
    ],
    [
      "a   LJJaannnn   ",
      "a   LJJaannnn   ",
      "a   LJJaannnn   ",
      "adddLJJaannnn   ",
      "tttteJJaannenM  ",
      "     vvvvnnnn   ",
      "     JJaannnnN  ",
      "     JJaannnnN  ",
      "     JJaannnnN  ",
      "     JJaannnnN  ",
      "     vvvvnnnn   ",
      "    eJJaannen   ",
      "     JJaannnn   ",
      "     JJaannnn   ",
      "     JJaannnn   ",
      "     JJaannnn   "
    ],
    [
      "e   ennnn       ",
      "e   ennnn       ",
      "e   ennnn       ",
      "edOPennnnQ M    ",
      "eeeeennnn  e    ",
      "JJJJennnn M Q   ",
      "JJJJennnnN      ",
      "JJJJennnnN      ",
      "JJJJennnnN      ",
      "JJJJennnnN      ",
      "JJJJennnn       ",
      "eeeeennnn  e    ",
      "JJJJennnn Q     ",
      "JJJJennnn       ",
      "JJJJennnn       ",
      "JJJJennnn       "
    ]
  ]
}