{
  "name": "multi_laboratory1_2_base2",
  "refpalette": "c70cities:multi_laboratory1_2_base2_palette",
  "xsize": 16,
  "zsize": 16,
  "slices": [
    [
      "zabcccccccccccd ",
      "zabcccccccccccd ",
      "zabcccccccccccd ",
      "zabcccccccccccde",
      "zabccccccccfcccd",
      "zabccccccccccccd",
      "zabccccccccccccc",
      "zabccccccccccccc",
      "zabccccccccccccc",
      "zabccccccccccccc",
      "zabccccccccccccc",
      "zabccccccccfcccc",
      "zabccccccccccccc",
      "zabccccccccccccc",
      "zabccccccccccccc",
      "zabccccccccccccc"
    ],
    [
      "zabghiiii  j  k ",
      "zabl mmmm  n  k ",
      "zabo  h p  q  k ",
      "zab        r  ke",
      "zab  sssst f  ek",
      "zab uw  wqxr  yk",
      "zab u   At r    ",
      "zab u  x q r    ",
      "zab uw  wq r    ",
      "zab  BBBB  r    ",
      "zab    A   r  C ",
      "zabrrrDErrrfe   ",
      "zab     x  r    ",
      "zabFI      q    ",
      "zabJJ    K j    ",
      "zabIL  MN  n    "
    ],
    [
      "zab  OPQ   R  k ",
      "zab   ST   U  k ",
      "zab        q  k ",
      "zab        r  ke",
      "zab  ssss  f  Vk",
      "zab uW  X  r   k",
      "zab u      Y    ",
      "zab u    q Y    ",
      "zab uX  Xq Y    ",
      "zab  BBBB  Y    ",
      "zab        r    ",
      "zabrrrZ0rrrfV   ",
      "zab        r    ",
      "zab        q    ",
      "zab1       R    ",
      "zab2       U    "
    ],
    [
      "zab        q  k ",
      "zab        q  k ",
      "zab        q  k ",
      "zab        r  ke",
      "zab  ssss  f  Vk",
      "zab u3  4q r   k",
      "zab u    q Y    ",
      "zab u    q Y    ",
      "zab u4  4q Y    ",
      "zab  BBBB  Y    ",
      "zab        r    ",
      "zabrrrrrrrrfV   ",
      "zab        r    ",
      "zab        q    ",
      "zab        q    ",
      "zab        q    "
    ],
    [
      "zab        r  k ",
      "zab        r  k ",
      "zab55555555r  k ",
      "zab     5  r  ke",
      "zab     5  f   k",
      "zab  5  5  r   k",
      "zab  5  5  r    ",
      "zab  5  5  r    ",
      "zab55555555r    ",
      "zab        r    ",
      "zab        r    ",
      "zabrrrrrrrrf    ",
      "zab        r    ",
      "zab        r    ",
      "zab        r    ",
      "zab        r    "
    ],
    [
      "zab667668669@@k ",
      "zab66#668669@@k ",
      "zab668668669@@k ",
      "zab666666669@@ke",
      "zab66666666f@@@k",
      "zab66#668669@@@k",
      "zab66766#669@@@@",
      "zab66866#669@@@@",
      "zab66#66#669@@@@",
      "zab666666669@@@@",
      "zab666666669@@@@",
      "zabrrrrrrrrf@@@@",
      "zab666666669@@@@",
      "zab666666669@#@@",
      "zab66#66#669@#@@",
      "zab66#667669@#@@"
    ]
  ]
}