{
  "name": "multi_laboratory1_1_base7",
  "refpalette": "c70cities:multi_laboratory1_1_base7_palette",
  "xsize": 16,
  "zsize": 16,
  "slices": [
    [
      "vaaaaabbbcaaacaa",
      "vaaaaabbbaaaacaa",
      "vaaaaabaaaaaacaa",
      "vaaaaaaaaaaaacaa",
      "vaaaaabaabaaacaa",
      "vaaaaabaaaaaacaa",
      "vaaaaaaaaaaaacaa",
      "vaaaaaaaaaaaacaa",
      "vaaaaaaaaaaaacaa",
      "vaaaaaaaabaaacaa",
      "vaaaaaaaaaaaacaa",
      "vaaaaaaaaaaaacaa",
      "vaaaaaaaaaaaacad",
      "vaaaaaaaaaaaccad",
      "vaaaaaaaaaaaaadd",
      "vaaaaaaaaaaaaada"
    ],
    [
      "vaaaabe fggaaaaa",
      "vaaaabh igaaaaaa",
      "vaaaaj  caaaaaaa",
      "vaaaai  baaaaaaa",
      "vaaaaa  kiaaaaaa",
      "vaaaaae  jaaaaaa",
      "vaaaaaj   caaaaa",
      "vaaaaaai   jacaa",
      "vaaaaaaaeh jgbaa",
      "vaaaaaaab jaggaa",
      "vaaaaaaaaaagggaa",
      "vaaaaaaaaaaaggaa",
      "vaaaaaaaaaaaa aa",
      "vaaaaaaaaaaaaaaa",
      "vaaaaaaaaaaaaaal",
      "vaaaaaaaaaaaaaaa"
    ],
    [
      "vaaaaf  egggaaaa",
      "vaaaaa  igaaaaaa",
      "vaaaa   aaaaaaaa",
      "vaaaai  baaaaaaa",
      "vaaaa    iaaaaaa",
      "vaaaaj    maaaaa",
      "vaaaam     aaaaa",
      "vaaaaaai    iaaa",
      "vaaaaaaa     fba",
      "vaaaaaaab    jji",
      "vaaaaaaaaaijjggj",
      "vaaaaaaaaaagmcaa",
      "vaaaaaaaaaaagbba",
      "vaaaaaaaaaaaaaba",
      "vaaaaaaaaaaaaaal",
      "vaaaaaaaaaaaaaaa"
    ],
    [
      "vaaaae  naggaaaa",
      "vaaaaa  aaaaaaaa",
      "vaaaac  baaaaaaa",
      "vaaaai  baaaaaaa",
      "vaaaa   niaaaaaa",
      "vaaaa    gaaaaaa",
      "vaaaaa   naaaaaa",
      "vaaaaaai    iaaa",
      "vaaaaaaaa    eba",
      "vaaaaaaaaa     i",
      "vaaaaaaaaai     ",
      "vaaaaaaaaaaa    ",
      "vaaaaaaaaaaaae  ",
      "vaaaaaaaaaaaabbo",
      "vaaaaaaaaaaaaaal",
      "vaaaaaaaaaaaaaag"
    ],
    [
      "vaaaaa naaaaaaaa",
      "vaaaaaaaaaaaaaaa",
      "vaaaaaanaaaaaaaa",
      "vaaaaannaaaaaaaa",
      "vaaaama aaaaaaaa",
      "vaaaaaaaaaaaaaaa",
      "vaaaaaaaaaaaaaaa",
      "vaaaaaaanaa iaaa",
      "vaaaaaaaaan   ca",
      "vaaaaaaaaa     i",
      "vaaaaaaaaaaa    ",
      "vaaaaaaaaaaaa   ",
      "vaaaaaaaaaaaag  ",
      "vaaaaaaaaaaaaabo",
      "vaaaaaaaaaaaaaal",
      "vaaaaaaaaaaaaaa "
    ],
    [
      "vaaaaaaaaaaaaaaa",
      "vaaaaaaaaaaaaaaa",
      "vaaaaaaaaaaaaaaa",
      "vaaaaaaaaaaaaaaa",
      "vaaaaaaaaaaaaaaa",
      "vaaaaaaaaaaaaaaa",
      "vaaaaaaaaaaaaaaa",
      "vaaaaaaaaaaaagaa",
      "vaaaaaaaaaaaacca",
      "vaaaaaaaaaaannna",
      "vaaaaaaaaaaaannn",
      "vaaaaaaaaaaaannn",
      "vaaaaaaaaaaaagpn",
      "vaaaaaaaaaaaagao",
      "vaaaaaaaaaaaaaal",
      "vaaaaaaaaaaaaaa "
    ]
  ]
}