{
  "name": "multi_megatower1_4_floor13",
  "refpalette": "c70cities:multi_megatower1_4_floor13_palette",
  "xsize": 16,
  "zsize": 16,
  "slices": [
    [
      "a   b           ",
      "a   b           ",
      "a   b           ",
      "cdeeb           ",
      "ffffg      h!   ",
      "ffffb           ",
      "ffffb           ",
      "ffffb           ",
      "ffffb           ",
      "ffffb           ",
      "ffffb           ",
      "ffffg      g    ",
      "ffffb           ",
      "ffffb           ",
      "ffffb           ",
      "ffffb           "
    ],
    [
      "a   i           ",
      "a   i           ",
      "a   i           ",
      "aejji           ",
      "klmng      h    ",
      "    o           ",
      "    o           ",
      "    o           ",
      "    o           ",
      "  p o           ",
      "  q o           ",
      "r srg      g    ",
      "o p o           ",
      "o q o           ",
      "o   o           ",
      "o p o           "
    ],
    [
      "a   i           ",
      "a   i           ",
      "a   i           ",
      "ae  i           ",
      "k tug      g    ",
      "                ",
      "                ",
      "                ",
      "                ",
      "                ",
      "                ",
      "!  wg      g    ",
      "                ",
      "                ",
      "                ",
      "                "
    ],
    [
      "a   i           ",
      "a   i           ",
      "a   i           ",
      "aeeei           ",
      "kx  g      g    ",
      "                ",
      "                ",
      "                ",
      "                ",
      "                ",
      "                ",
      "   wg      g    ",
      "                ",
      "                ",
      "                ",
      "                "
    ],
    [
      "a   i           ",
      "a   i           ",
      "a   i           ",
      "aeeei           ",
      "kkkkg      g    ",
      "                ",
      "                ",
      "                ",
      "                ",
      "                ",
      "                ",
      "    g      g    ",
      "                ",
      "                ",
      "                ",
      "                "
    ],
    [
      "g   g      g    ",
      "g   g      g    ",
      "g   g      g    ",
      "geyAg      g    ",
      "gggggggggggggggg",
      "    g      g    ",
      "    g      g    ",
      "    g      g    ",
      "    g      g    ",
      "    g      g    ",
      "    g      g    ",
      "gggggggggggggggg",
      "    g      g    ",
      "    g      g    ",
      "    g      g    ",
      "    g      g    "
    ]
  ]
}