{
  "name": "multi_laboratory1_13_base3",
  "refpalette": "c70cities:multi_laboratory1_13_base3_palette",
  "xsize": 16,
  "zsize": 16,
  "slices": [
    [
      "aaaaaaaaaaaaabcz",
      "aaaaaaaaaaaaabcz",
      "aaaadaaaaaaaabcz",
      "aaaaaaaaaaaaabcz",
      "aaaaaaaaaaaaabcz",
      "aaaaaaaaaaaaabcz",
      "aaaaaaaaaaaaabcz",
      "aaaaaaaaaaaaabcz",
      "aaaaaaaaaaaaabcz",
      "aaaadaaaaaaaabcz",
      "aaaaaaaaaaaaabcz",
      "aaaaaaaaaaaaabcz",
      "aaaaaaaaaaaaabcz",
      "aaaaaaaaaaaaabcz",
      "aaaaaaaaaaaaabcz",
      "aaaaaaaaaaaaabcz"
    ],
    [
      "ef  g  h  i fbcz",
      " f  jk   hl fbcz",
      " f  dmn    opbcz",
      "qr  jsh     pbcz",
      " f  js i hi fbcz",
      "    j h  o ofbcz",
      "    j     ltfbcz",
      "    j  l    fbcz",
      "    jk  uuu  bcz",
      "jjjjdmn uuu  bcz",
      "   wjx  uuu  bcz",
      "    jxxouyy  bcz",
      "    jxxl A   bcz",
      "BB  jxo      bcz",
      "C   j!xD  D  bcz",
      "E   jxx     Fbcz"
    ],
    [
      "    g        bcz",
      " I  jk      Ibcz",
      " I  dmJ      bcz",
      "    j        bcz",
      "    K       Lbcz",
      "    K       Ibcz",
      "    K       Ibcz",
      "    K       Lbcz",
      "    jk  MMM  bcz",
      "KKKjdmJ MMM  bcz",
      "    jx  MMM  bcz",
      "    Nx  OyP  bcz",
      "    Nx   Q   bcz",
      "    Nx       bcz",
      "    N        bcz",
      "    jx       bcz"
    ],
    [
      "    g        bcz",
      "    j        bcz",
      "    dR       bcz",
      "    j        bcz",
      "    K        bcz",
      "    K        bcz",
      "    K        bcz",
      "    K        bcz",
      "    j    MM  bcz",
      "KKKjdR   MM  bcz",
      "    j    MM  bcz",
      "    Sx   yP  bcz",
      "    Sx       bcz",
      "    S        bcz",
      "    S        bcz",
      "    jx       bcz"
    ],
    [
      "    j        bcz",
      "    j        bcz",
      "    dR       bcz",
      "    j       Tbcz",
      "    j        bcz",
      "    j        bcz",
      "    j        bcz",
      "    j        bcz",
      "    j        bcz",
      "jjjjdR       bcz",
      "    j        bcz",
      "    j        bcz",
      "    j        bcz",
      "    j        bcz",
      "    j        bcz",
      "    j        bcz"
    ],
    [
      "UUVUWRXVXXYXRbcz",
      "UUUUWRXVXXYXRbcz",
      "UUUUdRXXXXXXRbcz",
      "UUUUWRXXXXXXRbcz",
      "UUVUWRXYXXYXRbcz",
      "UUVUWRXVXXVXRbcz",
      "UUVUWRXYXXYXRbcz",
      "UUVUWRXYXXVXRbcz",
      "UUUUWRXXXXXXRbcz",
      "ZZZZdRXXXXXXRbcz",
      "XXXXWRXVXXVXRbcz",
      "XXXXWRXVXXVXRbcz",
      "XXXXWRXYXXVXRbcz",
      "VVXXWRXVXXVXRbcz",
      "XVXXWRXXXXXXRbcz",
      "XVXXWRXXXXXXRbcz"
    ]
  ]
}