{
  "name": "multi_militarybase_2_ground",
  "refpalette": "c70cities:multi_militarybase_2_ground_palette",
  "xsize": 16,
  "zsize": 16,
  "slices": [
    [
      "aaaaaaaaaaaaaaaa",
      "bbbbbbbbbbbbbbba",
      "ccccccccccccccba",
      "ccccccccccccccba",
      "ccccccccccHdccba",
      "ceafcccccdHH=cba",
      "ccccccccc=HHHcba",
      "cccccccccHHHHcba",
      "ccccc!cccHHHHcba",
      "cccccccccHHHdcba",
      "cccccccccHHHHcba",
      "cccccccccHHHHcba",
      "cccccccccHHHdcba",
      "cccccccccdHHHcba",
      "HHd=HHHHH=HHHcba",
      "HHHHHHHHHHHH=cba"
    ],
    [
      "                ",
      "bbbbbbbbbbbbbbb ",
      "              b ",
      "              b ",
      "gggggggg      b ",
      "    hiii  jjj b ",
      "         kljlmb ",
      "          jjj b ",
      " no   o   jjj b ",
      "pggqrqqg  jjj b ",
      "  gs   g kljlmb ",
      "  gt  ug  jjj b ",
      "  gw xyg      b ",
      "  gggggg      b ",
      "              b ",
      "              b "
    ],
    [
      "                ",
      "bbbbbbbbbbbbbbb ",
      "              b ",
      "              b ",
      "AAAABBAA  C C b ",
      "D   E i   F F b ",
      "          I J b ",
      "         KF FLb ",
      " M        FoF b ",
      "NAAqOqq  KFFFLb ",
      "  A    B  I J b ",
      "  B    B  PQR b ",
      "  A   wA  STS b ",
      "  AABBAA      b ",
      "              b ",
      "              b "
    ],
    [
      "                ",
      "bbbbbbbbbbbbbbb ",
      "              b ",
      "   UUUU       b ",
      "AAAAAAAA  C C b ",
      "VD        F F b ",
      "          F F b ",
      "              b ",
      "          F F b ",
      "AAAqqqqAU     b ",
      "  A    AU WWW b ",
      "  B    AU  W  b ",
      "  A    AU     b ",
      "  AABBAA      b ",
      "              b ",
      "              b "
    ],
    [
      "                ",
      "bbbbbbbbbbbbbbb ",
      "              b ",
      "              b ",
      "AAAAXXAA      b ",
      " VDnnnn    W  b ",
      "      n    W  b ",
      "      n   WWW b ",
      "nn    n   WWW b ",
      "XAAnnnnA  WWW b ",
      "  A   nX      b ",
      "  A   nX      b ",
      "  A   nA      b ",
      "  AAAAAA      b ",
      "              b ",
      "              b "
    ],
    [
      "                ",
      "YYYYYYYYYYYYYYM ",
      "              Z ",
      "              Z ",
      "gggggggg      Z ",
      "  aaaaag      Z ",
      "aaaaaaag      Z ",
      "aaaaaaag      Z ",
      "aaaaaaag      Z ",
      "gggaaaag      Z ",
      "  gaaaag      Z ",
      "  gaaaag      Z ",
      "  gaaaag      Z ",
      "  gaaaag      Z ",
      "  gVVVVg      Z ",
      "  gVVVVg      Z "
    ]
  ]
}