{
  "name": "multi_laboratory1_9_base2",
  "refpalette": "c70cities:multi_laboratory1_9_base2_palette",
  "xsize": 16,
  "zsize": 16,
  "slices": [
    [
      "aaaaaaaaaaaaaaaa",
      "aaaaaaaaaaaaaaaa",
      "aaaaaaaaaaaaaaaa",
      "aaaaaaaaaaaaaaaa",
      "aaaaaaaaaaaaaaaa",
      "aaaaaaaaaaaaaaaa",
      "aaaaaaaaaaaaaaaa",
      "aaaaaaaaaaaaaaaa",
      "aaaaaaaaaaaaaaaa",
      "aaaaaaaaaaaaaaaa",
      "aaaaaaaaaaaaaaaa",
      "aaaaaaaaaaaaaaaa",
      "aaaaaaaaaaaaaaaa",
      "bbbbbbbbbbbbbbbb",
      "cccccccccccccccc",
      "vvvvvvvvvvvvvvvv"
    ],
    [
      "de   fg  d    hg",
      "d    hg  de    g",
      "de    g  d    hg",
      "i    hiiiie    i",
      "                ",
      "                ",
      "   jkllllllkj   ",
      "mmmmmmmmmmmmmmmm",
      "   jnnnooiipj   ",
      "                ",
      " q        q   r ",
      "qsq qsq  qsq rs ",
      " q   q    q   r ",
      "bbbbbbbbbbbbbbbb",
      "cccccccccccccccc",
      "vvvvvvvvvvvvvvvv"
    ],
    [
      "t     u        w",
      "w     w         ",
      "                ",
      "       w        ",
      "                ",
      "                ",
      "   x y  A B x   ",
      "mmmmmmmmmmmmmmmm",
      "   xCD     pE   ",
      "                ",
      "                ",
      "                ",
      "                ",
      "bbbbbbbbbbbbbbbb",
      "cccccccccccccccc",
      "vvvvvvvvvvvvvvvv"
    ],
    [
      "                ",
      "                ",
      "                ",
      "                ",
      "                ",
      "                ",
      "   x        x   ",
      "mmmmmFmFmFFmmmmm",
      "    IIIJJKKK    ",
      "                ",
      "                ",
      "                ",
      "                ",
      "bbbbbbbbbbbbbbbb",
      "cccccccccccccccc",
      "vvvvvvvvvvvvvvvv"
    ],
    [
      "                ",
      "                ",
      "         !      ",
      "                ",
      "                ",
      "                ",
      "                ",
      "mmmmmFFmFFFmmmmm",
      "    LLLLLLLL    ",
      "                ",
      "                ",
      "                ",
      "                ",
      "bbbbbbbbbbbbbbbb",
      "cccccccccccccccc",
      "vvvvvvvvvvvvvvvv"
    ],
    [
      "MNNmNNONNMNNmNNM",
      "MNNmNNMNNMNNmNNM",
      "MNNmNNMNNONNmNNM",
      "MNNmNNMMMMNNmNNM",
      "NNNmNNNNNNNNmNNN",
      "NNNmNNNNNNNNmNNN",
      "NNNmNNNNNNNNmNNN",
      "mmmmmmmmmmmmmmmm",
      "PPPPPPPPPPPPPPPP",
      "PMPPPMPPPPMPPPMP",
      "PMPPPMPPPPMPPPMP",
      "P!PPPMPPPPQPPPMP",
      "PPPPPPPPPPPPPPPP",
      "bbbbbbbbbbbbbbbb",
      "cccccccccccccccc",
      "vvvvvvvvvvvvvvvv"
    ]
  ]
}