{
  "name": "multi_megatower1_4_floor11",
  "refpalette": "c70cities:multi_megatower1_4_floor11_palette",
  "xsize": 16,
  "zsize": 16,
  "slices": [
    [
      "a   bbbbbbbbbbbb",
      "a   bbbbbbbbbbbb",
      "a   bbbbbbbbbbbb",
      "cdeebbbbbbbbbbbb",
      "bbbbfbbbbbbfbbbb",
      "bbbbbbbbbbbbbbbb",
      "bbbbbbbbbbbbbbbb",
      "bbbbbbbbbbbbbbbb",
      "bbbbbbbbbbbbbbbb",
      "bbbbbbbbbbbbbbbb",
      "bbbbbbbbbbbbbbbb",
      "ggggfbbbbbbfbbbb",
      "    hbbbbbbbbbbb",
      "    hbbbbbbbbbbb",
      "    hbbbbbbbbbbb",
      "    hbbbbbbbbbbb"
    ],
    [
      "a   ij klk m   n",
      "a   ij kkk o    ",
      "a   ip kkk qr  s",
      "aettiu    wqx yA",
      "BCDEfw  xxxfFIFF",
      "    J   KL q   F",
      "    M    LNqO  P",
      "Q   R      qS  F",
      "w   T      qS  P",
      "    M    LNqO  F",
      "w   J   nL q   P",
      "JJJJfwl xxxfFUFF",
      "    J    LNq    ",
      "    J   nL q   V",
      "    J      W  XY",
      "    JK   l Z   0"
    ],
    [
      "a   i      1    ",
      "a   i      2    ",
      "a   i      q    ",
      "ae  i     3qx   ",
      "B 45f3  xxxfF6FF",
      "    J      q   F",
      "    M      7   8",
      "    9      7   F",
      "3   @      7   8",
      "    M      7   F",
      "3   J      q   8",
      "    f3   xxfF#FF",
      "    J      q    ",
      "    J      q    ",
      "    J      $    ",
      "    J      %    "
    ],
    [
      "a   i      ^    ",
      "a   i      ^    ",
      "a   i      q    ",
      "aeeei     3q    ",
      "B&  f3   l fFFFF",
      "    J      q   F",
      "    M      7   F",
      "    M      7   F",
      "3   M      7   F",
      "    M      7   F",
      "3   J      q   F",
      "    f3     fFFFF",
      "    J      q    ",
      "    J      q    ",
      "    J      ^    ",
      "    J      ^    "
    ],
    [
      "a   *((( ( )((((",
      "a   *(((((()((((",
      "a   *(+ (+()(+((",
      "aeee*(((((()((((",
      "BBBBf(((( (fFFFF",
      "    q(((((()----",
      "    q(+(([()----",
      "    q(((((()----",
      "    q(((((()----",
      "    q( ((+()----",
      "    q(((((()----",
      "    f  ((((fFFFF",
      "    q(((((()((((",
      "    q(+ (+()(+((",
      "    q(((((()((((",
      "    q(((( ()(((("
    ],
    [
      "]   ]     {]    ",
      "]   ]    }{]}} }",
      "]   ]}\\  \\{] \\} ",
      "]e|`] : } ;]}} }",
      "''''f''''''f''''",
      "((((] }   ;] }  ",
      "((+(] \\ }\\{]{{{{",
      "((((]},   {]} {}",
      "((((]  } }{]  {{",
      "((+(] \\  \\{]  {}",
      "((((]   } ;]}}{{",
      "''''f''''''f''''",
      "    ] }   ;] } }",
      "    ] \\ }\\{] \\  ",
      "    ]}!}  {] }  ",
      "    ]}  }}{]    "
    ]
  ]
}