{
  "name": "multi_megatower1_2_ground",
  "refpalette": "c70cities:multi_megatower1_2_ground_palette",
  "xsize": 16,
  "zsize": 16,
  "slices": [
    [
      "HHHvvHHHHHHHHHHv",
      "HHHvvHHHHHHHHHHH",
      "HHHvvHaHHHHHHaHH",
      "HHHvvHHHHHHHHHHH",
      "HHHvvHHHHHHHHHHH",
      "HHHvvHHHHHHHHHHH",
      "HHHvvHHHHHHHHHHH",
      "HHHvvHHHHHHHHHHH",
      "HHHvvHHHHHHHHHHH",
      "HHHvvHaHHHHHHaHH",
      "HHHvvHHHHHHHHHHH",
      "HHHvvvvvvvvvvvvv",
      "HHHvvvvvvvvvvvvv",
      "HHHGGGbGGGGGGbGG",
      "HHHGbGbbGGbbbGbG",
      "HHHGGGGGbGGGbbGG"
    ],
    [
      "   cde f    g hi",
      "   cdg h      ef",
      "  jkd al    ja  ",
      "   cde f     mgh",
      "   cdg h        ",
      "   cde f        ",
      "   cdg h        ",
      "   cdnnn        ",
      "   cd   oefefpef",
      "  jkd a o    a  ",
      "   cd   oghgh gh",
      "   cdddddddddddd",
      "   ccckcccccckcc",
      "   qqr qrqqrq rq",
      "                ",
      "                "
    ],
    [
      "   c            ",
      "   c            ",
      "   k  a      a  ",
      "   c            ",
      "   c            ",
      "   c            ",
      "   c            ",
      "   c            ",
      "   c            ",
      "   k  a      a  ",
      "   c            ",
      "   c            ",
      "   ccckcccccckcc",
      "                ",
      "                ",
      "                "
    ],
    [
      "   c            ",
      "   c            ",
      "   k  a      a  ",
      "   c            ",
      "   c            ",
      "   c            ",
      "   c            ",
      "   c            ",
      "   c            ",
      "   k  a      a  ",
      "   c            ",
      "   c            ",
      "   ccckcccccckcc",
      "      s      s  ",
      "                ",
      "                "
    ],
    [
      "   c            ",
      "   c            ",
      "   k  a      a  ",
      "   c            ",
      "   c            ",
      "   c            ",
      "   c            ",
      "   c            ",
      "   c            ",
      "   k  a      a  ",
      "   c            ",
      "   c            ",
      "   ccckcccccckcc",
      "                ",
      "                ",
      "                "
    ],
    [
      "   cttattttttatt",
      "   cttattttttatt",
      "  tkaaaaaaaaaaaa",
      "  tittattttttatt",
      "  tittattttttatt",
      "  tittattttttatt",
      "  tittattttttatt",
      "  tittattttttatt",
      "  tittattttttatt",
      "  tkaaaaaaaaaaaa",
      "   cttattttttatt",
      "   cttattttttatt",
      "   ccckcccccckcc",
      "                ",
      "                ",
      "                "
    ]
  ]
}