{
  "name": "multi_megatower1_5_floor5",
  "refpalette": "c70cities:multi_megatower1_5_floor5_palette",
  "xsize": 16,
  "zsize": 16,
  "slices": [
    [
      "    abbbbbbbbbbb",
      "    abbbbbbbbbbb",
      "ccccdbbbbbbdbbbb",
      "ef fge ef fge ef",
      "  f h e  f h e  ",
      "                ",
      "                ",
      "                ",
      "                ",
      "                ",
      "                ",
      "                ",
      "                ",
      "                ",
      "                ",
      "                "
    ],
    [
      "    i      j    ",
      "    iklmmnkjoopq",
      "iiiidiiiiiidrrrr",
      "ef fge ef fge ef",
      "    h      h    ",
      "                ",
      "                ",
      "                ",
      "                ",
      "                ",
      "                ",
      "                ",
      "                ",
      "                ",
      "                ",
      "                "
    ],
    [
      "    i      j    ",
      "    is    sjtt  ",
      "iiiidiiiiiidruuu",
      "ef fge ef fge ef",
      "    h      h    ",
      "                ",
      "                ",
      "                ",
      "                ",
      "                ",
      "                ",
      "                ",
      "                ",
      "                ",
      "                ",
      "                "
    ],
    [
      "    i      j    ",
      "    is    sj    ",
      "iiiidiiiiiidrwww",
      "ef fge ef fge ef",
      "    h      h    ",
      "                ",
      "                ",
      "                ",
      "                ",
      "                ",
      "                ",
      "                ",
      "                ",
      "                ",
      "                ",
      "                "
    ],
    [
      "    j      jxyxx",
      "    j      jxxxx",
      "ABABdABABABdrrrr",
      "ef fge ef fge ef",
      "    h      h    ",
      "                ",
      "                ",
      "                ",
      "                ",
      "                ",
      "                ",
      "                ",
      "                ",
      "                ",
      "                ",
      "                "
    ],
    [
      "    CxyxxyxC D E",
      "    CxxxxxxC    ",
      "FFFFdFFFFFFdFFFF",
      "efffgeeefffgeeef",
      "    h      h    ",
      "                ",
      "                ",
      "                ",
      "                ",
      "                ",
      "                ",
      "                ",
      "                ",
      "                ",
      "                ",
      "                "
    ]
  ]
}