{
  "name": "multi_hospital_2_floor1",
  "refpalette": "c70cities:multi_hospital_2_floor1_palette",
  "xsize": 16,
  "zsize": 16,
  "slices": [
    [
      "                ",
      "                ",
      " a              ",
      "bc              ",
      "db              ",
      "dc              ",
      "db              ",
      "dc              ",
      "deeeeeeeeeeeeee ",
      "dddddddddddddde ",
      "dddddddddddddde ",
      "dddddddddddddde ",
      "dddddddddddddde ",
      "dddddddddddddde ",
      "dddddddddddddde ",
      "dddddddddddddde "
    ],
    [
      "                ",
      "                ",
      " a              ",
      "ff              ",
      " f              ",
      "gf              ",
      "hf              ",
      "if              ",
      "jeeeeeeeeeeeeee ",
      "klmn opqrs tuwx ",
      "kly   p  s ABw  ",
      " lmn  pC D  ywx ",
      " EEEEFEEEs ABwx ",
      "         I  yw  ",
      " JJJJKJJJs ABwx ",
      " lmn  pmn   ywx "
    ],
    [
      "                ",
      "                ",
      " a              ",
      "ff              ",
      " f              ",
      " f              ",
      " f              ",
      " f              ",
      "jeeeeeeeeeeeeee ",
      "LM    N  O   wx ",
      " M    N  O   j  ",
      " M    N  P   wx ",
      " QQQQRQQQO   wx ",
      "         S   j  ",
      " TTTTUTTTO   wx ",
      " M    N      wx "
    ],
    [
      "                ",
      "                ",
      " a              ",
      "ff              ",
      " f              ",
      " f              ",
      " f              ",
      " f              ",
      "jeecceecceeccee ",
      " M    N  O   wx ",
      " M    N  O   j  ",
      " M    N  O   wx ",
      " QQQQQQQQO   wx ",
      "         O   j  ",
      " TTTTTTTTO   wx ",
      " M    N      wx "
    ],
    [
      "                ",
      "                ",
      " a              ",
      "ff              ",
      " f              ",
      " f              ",
      " f              ",
      " f              ",
      "jeeeeeeeeeeeeee ",
      " M    N  O   wx ",
      " M    N  O   j  ",
      " M    N  O   wx ",
      " QQQQQQQQO   wx ",
      " V   V   O   j  ",
      " TTTTTTTTO   wx ",
      " M    N      wx "
    ],
    [
      "                ",
      "                ",
      " a              ",
      "ff              ",
      " f              ",
      " f              ",
      " f              ",
      " f              ",
      "jeeeeeeeeeeeeee ",
      " wWWWwWWWwWWWwx ",
      " wWWWwWWWwWWWw  ",
      " wWWWwWWWwWWWwx ",
      " wWWWwWWWwWWWwx ",
      " wWWWwWWWwWWWw  ",
      " wWWWwWWWwWWWwx ",
      " wWWWwWWWwWWWwx "
    ]
  ]
}