{
  "name": "multi_megatower1_8_base2",
  "refpalette": "c70cities:multi_megatower1_8_base2_palette",
  "xsize": 16,
  "zsize": 16,
  "slices": [
    [
      "HHHHHHHHHHHvvaav",
      "HHHHHHHHHHHvvaav",
      "HHbHHHHHHbHvvaav",
      "HHHHHHHHHHHvvaav",
      "HHHHHHHHHHHvvaav",
      "HHHHHHHHHHHvvaav",
      "HHHHHHHHHHHvvaav",
      "HHHHHHHHHHHvvaav",
      "HHHHHHHHHHHvvaav",
      "HHbHHHHHHHHvvaav",
      "HHHHHHHHHHHvvaav",
      "vvvvvvvvvvvvvaav",
      "vvvvvvvvvvvvvaav",
      "            aaav",
      "aaaaaaaaaaaaaaav",
      "vvvvvvvvvvvvvvvv"
    ],
    [
      " c d    e fgvaav",
      "ef      c dgvaav",
      "  bh    ib gvaav",
      "cdj     e fgvaav",
      "        c dgvaav",
      "        e fgvaav",
      "        c dgvaav",
      "        kkkgvaav",
      "eflefefm   gvaav",
      "  b    m b gvaav",
      "cd cdcdm   gvaav",
      "ggggggggggggvaav",
      "vvvvvvvvvvvvvaav",
      "aaaaaaaaaaaaaaav",
      "aaaaaaaaaaaaaaav",
      "vvvvvvvvvvvvvvvv"
    ],
    [
      "            vaav",
      "            vaav",
      "  b      b  vaav",
      "            vaav",
      "            vaav",
      "            vaav",
      "            vaav",
      "            vaav",
      "            vaav",
      "  b      b  vaav",
      "            vaav",
      "            vaav",
      "vvvvvvvvvvvvvaav",
      "aaaaaaaaaaaaaaav",
      "aaaaaaaaaaaaaaav",
      "vvvvvvvvvvvvvvvv"
    ],
    [
      "            vaav",
      "            vaav",
      "  b      b  vaav",
      "            vaav",
      "            vaav",
      "            vaav",
      "            vaav",
      "            vaav",
      "            vaav",
      "  b      b  vaav",
      "            vaav",
      "            vaav",
      "vvvvvvvvvvvvvaav",
      "aaaaaaaaaaaaaaav",
      "aaaaaaaaaaaaaaav",
      "vvvvvvvvvvvvvvvv"
    ],
    [
      "            vaav",
      "            vaav",
      "  b      bn vaav",
      "            vaav",
      "            vaav",
      "            vaav",
      "            vaav",
      "            vaav",
      "            vaav",
      "  b      bn vaav",
      "  o      o  vaav",
      "            vaav",
      "vvvvvvvvvvvvvaav",
      "aaaaaaaaaaaaaaav",
      "aaaaaaaaaaaaaaav",
      "vvvvvvvvvvvvvvvv"
    ],
    [
      " pbppppppbpvvaav",
      "ppbppppppbpvvaav",
      "bbbbbbbbbbpvvaav",
      "ppbppppppbpvvaav",
      "ppbppppppbpvvaav",
      "ppbppppppbpvvaav",
      "ppbppppppbpvvaav",
      "ppbppppppbpvvaav",
      "ppbppppppbpvvaav",
      "bbbbbbbbbbpvvaav",
      "pppppppppppvvaav",
      "vvvvvvvvvvvvvaav",
      "vvvvvvvvvvvvvaav",
      "aaaaaaaaaaaaaaav",
      "aaaaaaaaaaaaaaav",
      "vvvvvvvvvvvvvvvv"
    ]
  ]
}