{
  "name": "multi_laboratory1_1_base6",
  "refpalette": "c70cities:multi_laboratory1_1_base6_palette",
  "xsize": 16,
  "zsize": 16,
  "slices": [
    [
      "vabccccccccccccc",
      "vabccccccccccccc",
      "vabccccccccccccc",
      "vabccccccccccccc",
      "vabccccccccccccc",
      "vabccccccccccccc",
      "vabccccccccdcccc",
      "vabccccccccccccc",
      "vabccccccccccccc",
      "vabccccccccccccc",
      "vabccccccccccccc",
      "vabccccccccccccc",
      "vabcccccccccccce",
      "vabccccccccdccce",
      "vabcccccccccccef",
      "vabccccccccccce "
    ],
    [
      "vag             ",
      "vab             ",
      "vabh            ",
      "vabh          i ",
      "vab             ",
      "vajjjj       kkk",
      "vablmj     d    ",
      "vajjjj     !    ",
      "vab        n    ",
      "vabh     o np   ",
      "vabh       n    ",
      "vab        n    ",
      "vajjjj         q",
      "vablmj     d   q",
      "vajjjj     r  qf",
      "vab        n  q "
    ],
    [
      "vag             ",
      "vab             ",
      "vabst           ",
      "vabut           ",
      "vabw            ",
      "vajjq        xy ",
      "vablmq     d    ",
      "vajjq           ",
      "vabA       B    ",
      "vabut      C    ",
      "vabst      r    ",
      "vabw       D    ",
      "vajjq          q",
      "vablmq     d   q",
      "vajjq      x  qf",
      "vabA       B  q "
    ],
    [
      "vag             ",
      "vab             ",
      "vab             ",
      "vab             ",
      "vab             ",
      "vajjq        E  ",
      "vablmq     d    ",
      "vajjq           ",
      "vab             ",
      "vab             ",
      "vab             ",
      "vab             ",
      "vajjq          q",
      "vablmq     d   q",
      "vajjq      F  qf",
      "vab           q "
    ],
    [
      "vag             ",
      "vab             ",
      "vabI            ",
      "vabI            ",
      "vab             ",
      "vajjq           ",
      "vablmq     d    ",
      "vajjq           ",
      "vab             ",
      "vabI            ",
      "vabI            ",
      "vab             ",
      "vajjq          q",
      "vablmq     d   q",
      "vajjq         qf",
      "vab           q "
    ],
    [
      "vag             ",
      "vab             ",
      "vabg            ",
      "vab             ",
      "vab             ",
      "vajjq           ",
      "vablmq     d    ",
      "vajjq           ",
      "vab             ",
      "vabg            ",
      "vab             ",
      "vab             ",
      "vajjq          q",
      "vablmq     d   q",
      "vajjq         qf",
      "vab           q "
    ]
  ]
}