{
  "name": "multi_clubhouse1_2_base2",
  "refpalette": "c70cities:multi_clubhouse1_2_base2_palette",
  "xsize": 16,
  "zsize": 16,
  "slices": [
    [
      "vvvvvvvvvvvvvvvv",
      "vvvvvvvvvvvvvvvv",
      "vvvvvvvvvvvvvvvv",
      "vvvvvvvaaaaaaaaa",
      "vvvvvvvaaaaaaaaa",
      "vvvvvvvaaaaaaaaa",
      "vvvvvvvaaaaaaaaa",
      "vvvvvvvaaaaaaaaa",
      "vvvvvvvaaaaaaaaa",
      "vvvvvvvvvvvvvvvv",
      "vvvvvvvvvvvvvvvv",
      "vvvvvvvvvvvvvvvv",
      "vvvvvvvvvvvvvvvv",
      "vvvvvvvvvvvvvvvv",
      "vvvvvvvvvvvvvvvv",
      "vvvvvvvvvvvvvvvv"
    ],
    [
      "vbbbbbbccccccbbb",
      "vbbbbbbccccccbbb",
      "vbbbbbdaaaaaadaa",
      "vbbbbbaefefeffef",
      "vbbbbbafeffffeff",
      "vbbbbbaeffefffff",
      "vbbbbbafeffffffe",
      "vbbbbbaegffeffff",
      "vbbbbbafffeffefe",
      "vbbbbbdaaaaaadaa",
      "vbbbbhibijhiGkkk",
      "vbbbbbihijikiGkk",
      "vbbbbbbbbbbbbbbb",
      "vbbbGGlGGGGGGmGG",
      "vbbbnnonnnnnnonn",
      "vvvvvvvvvvvvvvvv"
    ],
    [
      "vbbb pqrstuuuwpx",
      "vbbb  quuuuuuwpp",
      "vbbb  dyyyyyyd  ",
      "vbbb            ",
      "vbbb   A  A     ",
      "vbbb    A       ",
      "vbbbB  A     A  ",
      "vbbb    AAA     ",
      "vbbb B A A A    ",
      "vbbb  d      d  ",
      "vbbb    CD      ",
      "vbbb    CD      ",
      "vbbbEFIIIEIFIIIE",
      "vbbbJK LJLLKJ JL",
      "vbbbMNoNNNNNNoNN",
      "vvvvvvvvvvvvvvvv"
    ],
    [
      "vbbb  q      w O",
      "vbbb  q      w  ",
      "vbbb  dPQQQQRd  ",
      "vbbb            ",
      "vbbb            ",
      "vbbb            ",
      "vbbb            ",
      "vbbb            ",
      "vbbb            ",
      "vbbb  d      d  ",
      "vbbb   CD       ",
      "vbbb   CD       ",
      "vbbb            ",
      "vbbbS  TSTT S ST",
      "vbbbUNoNNUNNNoNN",
      "vvvvvvvvvvvvvvvv"
    ],
    [
      "vbbb  q      w  ",
      "vbbb  q      w  ",
      "vbbb  d      d  ",
      "vbbb            ",
      "vbbb            ",
      "vbbb            ",
      "vbbb            ",
      "vbbb            ",
      "vbbb            ",
      "vbbb  d      d  ",
      "vbbb  CD        ",
      "vbbb  CD        ",
      "vbbb            ",
      "vbbb            ",
      "vbbbNNoNNUNNNoNN",
      "vvvvvvvvvvvvvvvv"
    ],
    [
      "vbbb  V      V  ",
      "vbbb  V      V  ",
      "vbbb  dVVVVVVd  ",
      "vbbb            ",
      "vbbb            ",
      "vbbb            ",
      "vbbb            ",
      "vbbb            ",
      "vbbb            ",
      "vbbb  d      d  ",
      "vbbb CD         ",
      "vbbb CD         ",
      "vbbb            ",
      "vbbb            ",
      "vbbb NoN UN NoUN",
      "vvvvvvvvvvvvvvvv"
    ]
  ]
}