{
  "name": "multi_hospital_2_floor1",
  "refpalette": "c70cities:multi_hospital_2_floor1_palette",
  "xsize": 16,
  "zsize": 16,
  "slices": [
    [
      "                ",
      "                ",
      " a              ",
      "bc              ",
      "db              ",
      "dc              ",
      "db              ",
      "dc              ",
      "deeeeeeeeeeeeee ",
      "dddddddddddddde ",
      "dddddddddddddde ",
      "dddddddddddddde ",
      "dddddddddddddde ",
      "dddddddddddddde ",
      "dddddddddddddde ",
      "dddddddddddddde "
    ],
    [
      "                ",
      "                ",
      " a              ",
      "ff              ",
      " f              ",
      "gf              ",
      "hf              ",
      "if              ",
      "jeeeeeeeeeeeeee ",
      "klmn op  q rstu ",
      "klw   p  q xyt  ",
      " lmn  pAB   wtu ",
      " CCCCDCCCq xytu ",
      "         E  wt  ",
      " FFFFIFFFq xytu ",
      " lmn  pmn   wtu "
    ],
    [
      "                ",
      "                ",
      " a              ",
      "ff              ",
      " f              ",
      " f              ",
      " f              ",
      " f              ",
      "jeeeeeeeeeeeeee ",
      "JK    LMNO   tu ",
      " K    L  O   j  ",
      " K    L P    tu ",
      " QQQQRQQQO   tu ",
      "         S   j  ",
      " TTTTUTTTO   tu ",
      " K    L      tu "
    ],
    [
      "                ",
      "                ",
      " a              ",
      "ff              ",
      " f              ",
      " f              ",
      " f              ",
      " f              ",
      "jeecceecceeccee ",
      " K    L  O   tu ",
      " K    L  O   j  ",
      " K    L  O   tu ",
      " QQQQQQQQO   tu ",
      "         O   j  ",
      " TTTTTTTTO   tu ",
      " K    L      tu "
    ],
    [
      "                ",
      "                ",
      " a              ",
      "ff              ",
      " f              ",
      " f              ",
      " f              ",
      " f              ",
      "jeeeeeeeeeeeeee ",
      " K    L  O   tu ",
      " K    L  O   j  ",
      " K    L  O   tu ",
      " QQQQQQQQO   tu ",
      " V   V   O   j  ",
      " TTTTTTTTO   tu ",
      " K    L      tu "
    ],
    [
      "                ",
      "                ",
      " a              ",
      "ff              ",
      " f              ",
      " f              ",
      " f              ",
      " f              ",
      "jeeeeeeeeeeeeee ",
      " tWWWtWWWtWWWtu ",
      " tWWWtWWWtWWWt  ",
      " tWWWtWWWtWWWtu ",
      " tWWWtWWWtWWWtu ",
      " tWWWtWWWtWWWt  ",
      " tWWWtWWWtWWWtu ",
      " tWWWtWWWtWWWtu "
    ]
  ]
}