{
  "name": "multi_megatower1_5_floor8",
  "refpalette": "c70cities:multi_megatower1_5_floor8_palette",
  "xsize": 16,
  "zsize": 16,
  "slices": [
    [
      "aaaaa========bbb",
      "aaaaa===========",
      "ccccdccccccdcccc",
      "eeeefeeeeeefeeee",
      "ghhhiggghhhigggh",
      "                ",
      "                ",
      "                ",
      "                ",
      "                ",
      "                ",
      "                ",
      "                ",
      "                ",
      "                ",
      "                "
    ],
    [
      "   jaaaaaaakl   ",
      "m jjaaaaaaaafllf",
      "nnnndoooooodoooo",
      "    f      f    ",
      "ghhhiggghhhigggh",
      "                ",
      "                ",
      "                ",
      "                ",
      "                ",
      "                ",
      "                ",
      "                ",
      "                ",
      "                ",
      "                "
    ],
    [
      "    mjaaaapq    ",
      "   jjjaaaaaarstf",
      "    doooooodoooo",
      "    f      f    ",
      "ghhhiggghhhigggh",
      "                ",
      "                ",
      "                ",
      "                ",
      "                ",
      "                ",
      "                ",
      "                ",
      "                ",
      "                ",
      "                "
    ],
    [
      "     j  aaaa    ",
      "    ujjjaaaatawr",
      "    doooooodoooo",
      "    f      f    ",
      "  hhiggghhhigggh",
      "                ",
      "                ",
      "                ",
      "                ",
      "                ",
      "                ",
      "                ",
      "                ",
      "                ",
      "                ",
      "                "
    ],
    [
      "          jaaa t",
      " u uujj xmjaaawa",
      "nnnndnnnnnndoooo",
      "    f      f    ",
      "  hhi gghh igggh",
      "                ",
      "                ",
      "                ",
      "                ",
      "                ",
      "                ",
      "                ",
      "                ",
      "                ",
      "                ",
      "                "
    ],
    [
      "            xaaa",
      "uuuujj   ujjuaaa",
      "yyyydyyyyyydyyyy",
      "    f      f    ",
      "  h i gghh igg  ",
      "                ",
      "                ",
      "                ",
      "                ",
      "                ",
      "                ",
      "                ",
      "                ",
      "                ",
      "                ",
      "                "
    ]
  ]
}