{
  "name": "multi_megatower1_4_floor10",
  "refpalette": "c70cities:multi_megatower1_4_floor10_palette",
  "xsize": 16,
  "zsize": 16,
  "slices": [
    [
      "a   bbbbbbbbbbbb",
      "a   bbbbbbbbbbbb",
      "a   bbbbbbbbbbbb",
      "cdeebbbbbbbbbbbb",
      "bbbbfbbbbbbfbbbb",
      "bbbbbbbbbbbbbbbb",
      "bbbbbbbbbbbbbbbb",
      "bbbbbbbbbbbbbbbb",
      "bbbbbbbbbbbbbbbb",
      "bbbbbbbbbbbbbbbb",
      "bbbbbbbbbbbbbbbb",
      "ggggfbbbbbbfbbbb",
      "    hbbbbbbbbbbb",
      "    hbbbbbbbbbbb",
      "    hbbbbbbbbbbb",
      "    hbbbbbbbbbbb"
    ],
    [
      "a   ij klk m   n",
      "a   ij kkk o    ",
      "a   ip kkk q   r",
      "aessit    uq  wx",
      "yABCfu  DDDfEFEE",
      "    I   JK q   E",
      "    L    KMqN  O",
      "P   Q      qR  E",
      "u   S      qR  O",
      "    L    KMqN  E",
      "u   I   nK q   O",
      "IIIIful DDDfETEE",
      "    I    KMq    ",
      "    I   nK q   U",
      "    I      V  WX",
      "    IJ   l Y   Z"
    ],
    [
      "a   i      0    ",
      "a   i      1    ",
      "a   i      q    ",
      "ae  i     2q    ",
      "y 34f2  DDDfE5EE",
      "    I      q   E",
      "    L      6   7",
      "    8      6   E",
      "2   9      6   7",
      "    L      6   E",
      "2   I      q   7",
      "    f2   DDfE@EE",
      "    I      q    ",
      "    I      q    ",
      "    I      #    ",
      "    I      $    "
    ],
    [
      "a   i      %    ",
      "a   i      %    ",
      "a   i      q    ",
      "aeeei     2q    ",
      "y^  f2   l fEEEE",
      "    I      q   E",
      "    L      6   E",
      "    L      6   E",
      "2   L      6   E",
      "    L      6   E",
      "2   I      q   E",
      "    f2     fEEEE",
      "    I      q    ",
      "    I      q    ",
      "    I      %    ",
      "    I      %    "
    ],
    [
      "a   &*** * (****",
      "a   &******(****",
      "a   &*) *)*(*!**",
      "aeee&******(****",
      "yyyyf**** *fEEEE",
      "    q******(++++",
      "    q*)**-*(++++",
      "    q******(++++",
      "    q******(++++",
      "    q* **)*(++++",
      "    q******(++++",
      "    f  ****fEEEE",
      "    q******(****",
      "    q*) *-*(*)**",
      "    q******(****",
      "    q**** *(****"
    ],
    [
      "[   [     ][    ",
      "[   [    {][{{ {",
      "[   [{}  }][ }{ ",
      "[e\\\\[ | { `[{{ {",
      "::::f::::::f::::",
      "****[ {   `[ {  ",
      "**)*[ } {}][]]]]",
      "****[{;   ][{ ]{",
      "****[  { {][  ]]",
      "**-*[ }  }][  ]{",
      "****[   { `[{{]]",
      "::::f::::::f::::",
      "    [ {   `[ { {",
      "    [ } {}][ }  ",
      "    [{!{  ][ {  ",
      "    [{  {{][    "
    ]
  ]
}