{
  "name": "multi_laboratory1_12_base6",
  "refpalette": "c70cities:multi_laboratory1_12_base6_palette",
  "xsize": 16,
  "zsize": 16,
  "slices": [
    [
      " abbbbbbbbbbbcdz",
      " abbbbbbbbbbbcdz",
      " abbbbbbbbbbbcdz",
      "eabbbbbbbbbbbcdz",
      "abbbfbbbbbbbbcdz",
      "abbbbbbbbbbbbcdz",
      "bbbbbbbbbbbbbcdz",
      "bbbbbbbbbbbbbcdz",
      "bbbbbbbbbgbbbcdz",
      "bbbbbbbbbbhbbcdz",
      "bbbbbgbbbbbbbcdz",
      "bbbbfigbbgbbbcdz",
      "bbbbbbbbigbbbcdz",
      "bbbbbbbbgggbbcdz",
      "bbbbbbbbibggbcdz",
      "bbbbgbgiggbbbcdz"
    ],
    [
      " j  k       lcdz",
      " j  km      lcdz",
      " j  k        cdz",
      "ej n      oooodz",
      "j   f     opqcdz",
      "j   r     oooodz",
      "    ks  t    cdz",
      "    k       lcdz",
      "    k    uu lcdz",
      "   wk   x uggcdz",
      " s yl     oooodz",
      "A mBfC DtioEFcdz",
      "IJ tKm   Lgooodz",
      "        u Miicdz",
      "t Nt     D ulcdz",
      "N     Ou Ltuicdz"
    ],
    [
      " j  P      QRcdz",
      " j         QRcdz",
      " j  S       Tcdz",
      "ej         joodz",
      "j   f     jpqcdz",
      "j          joodz",
      "    n       Ucdz",
      "    P      QRcdz",
      "    V       Wcdz",
      "           ugcdz",
      "    X     igoodz",
      "    f     gEFcdz",
      "          Ohoodz",
      "          uuicdz",
      "             cdz",
      "            Lcdz"
    ],
    [
      " j           cdz",
      " j           cdz",
      " j           cdz",
      "ej         joodz",
      "j   f     jpqcdz",
      "j          joodz",
      "             cdz",
      "             cdz",
      "             cdz",
      "            Lcdz",
      "          ijoodz",
      "    f     jEFcdz",
      "           Yoodz",
      "             cdz",
      "             cdz",
      "             cdz"
    ],
    [
      " j          Zcdz",
      " j          Zcdz",
      " j           cdz",
      "ej         joodz",
      "j   f     jpqcdz",
      "j          joodz",
      "             cdz",
      "            Zcdz",
      "            Zcdz",
      "             cdz",
      "          ujoodz",
      "    f     jEFcdz",
      "           joodz",
      "             cdz",
      "            Zcdz",
      "            Zcdz"
    ],
    [
      " j          0cdz",
      " j           cdz",
      " j           cdz",
      "ej         joodz",
      "j   f     jpqcdz",
      "j          joodz",
      "             cdz",
      "             cdz",
      "            0cdz",
      "             cdz",
      "           joodz",
      "    f     jEFcdz",
      "           joodz",
      "             cdz",
      "            0cdz",
      "            tcdz"
    ]
  ]
}