{
  "name": "multi_militarybase_2_base4",
  "refpalette": "c70cities:multi_militarybase_2_base4_palette",
  "xsize": 16,
  "zsize": 16,
  "slices": [
    [
      "vvvvvvvvvvvvvvvv",
      "aaaaaaaaaaaaaaaa",
      "aaaaaaaaaaaaaaaa",
      "aaaaaaaaaaaaaaaa",
      "aaaaaaaaaaaaaaaa",
      "bbbbbbbbbbbbbbbb",
      "aaaaaaaaaaaaaaaa",
      "aaaaaaaaaaaaaaaa",
      "aaaaaaaaaaaaaaaa",
      "aaaaaaaaaaaaaaaa",
      "aaaaaaaaaaaaaaaa",
      "aaaaaaaaaaaaaaaa",
      "aaaaaaaaaaaaaaaa",
      "bbvbbbbvbbbbvbbb",
      "cccccccccccccccc",
      "cccccccccccccccc"
    ],
    [
      "vvvvvvvvvvvvvvvv",
      "dddddddddddddddd",
      "dddddddddddddddd",
      "dddddddddddddddd",
      "dddddddddddddddd",
      "dddddddddddddddd",
      "dddddddddddddddd",
      "dddddddddddddddd",
      "effggggg hhiii e",
      " ej jgg k h ii  ",
      "   l   l   m    ",
      "                ",
      "                ",
      "ddvddddvddddvddd",
      "no nnon onnn non",
      "                "
    ],
    [
      "vvvvvvvvvvvvvvvv",
      "pp pppp pppp ppp",
      "q        q     r",
      "     q          ",
      "               s",
      "dddddddddddddddd",
      "dddddddddddddddd",
      "dddddddddddddddd",
      "e  g  g   kh    ",
      "     j      k   ",
      "                ",
      "                ",
      "                ",
      "ddvddddvddddvddd",
      " t   u  w     x ",
      "                "
    ],
    [
      "vvvvvvvvvvvvvvvv",
      " y y  y y y  y y",
      "                ",
      "                ",
      "                ",
      "ppp ppp ppp ppp ",
      " A   A  A     A ",
      "               s",
      "dddddddddddddddd",
      "dddddddddddddddd",
      "BBBBBBBBBBBBBBBB",
      "                ",
      "CCCCCCCCCCCCCCCC",
      "ddvddddvddddvddd",
      "                ",
      "                "
    ],
    [
      "vvvvvvvvvvvvvvvv",
      "DDDDDEDDDDDDEFD ",
      "                ",
      "                ",
      "                ",
      " II JIK II  JII ",
      "                ",
      "                ",
      "ppp ppp ppp ppp ",
      " A  A    A  A   ",
      "               s",
      "dddddddddddddddd",
      "dddddddddddddddd",
      "ddvddddvddddvddd",
      "                ",
      "                "
    ],
    [
      "vvvvvvvvvvvvvvvv",
      "DDDEDDDDEEDDDEE ",
      "                ",
      "                ",
      "                ",
      "                ",
      "                ",
      "                ",
      "LI  IIM  IK I N ",
      "                ",
      "                ",
      "ppp ppp ppp ppp ",
      " A   A    A  A  ",
      "  v    v!   v  s",
      "BBBBBBBBBBBBBBBB",
      "OOOOOOOOOOOOOOOO"
    ]
  ]
}