{
  "name": "multi_flatapartment_1_floor2",
  "refpalette": "c70cities:multi_flatapartment_1_floor2_palette",
  "xsize": 16,
  "zsize": 16,
  "slices": [
    [
      "                ",
      "aaabaaabaaaabaaa",
      "cccccccccccccccc",
      "dddddddddddddddd",
      "dddddddddddddddd",
      "dddddddccccccddd",
      "dddddddc  edcddd",
      "dddddddc   dcddd",
      "dddddddc   dcddd",
      "dddddddcddddcddd",
      "dddddddccccccddd",
      "dddddddcddddcddd",
      "dddddddcddddcddd",
      "cccccccccccccccc",
      "aaabaaabaaaabaaa",
      "                "
    ],
    [
      "                ",
      "ffabafabaggabafa",
      "      hi!j jik  ",
      "l l   min   io  ",
      "ppp   qinj  ir  ",
      "iiii  sbtttubw  ",
      "  xi  sy    Aw  ",
      "  Bi   y   CA!  ",
      "   i   yDDE A   ",
      "l li   F    I   ",
      "pppiiiib    biii",
      "JJKLM  N    O  M",
      "       y    A   ",
      "       y    A   ",
      "ffabafabaPPabafa",
      "                "
    ],
    [
      "                ",
      "QQabaQabaQQabaQa",
      "      Ri    iS  ",
      "       in   i   ",
      "       in   i   ",
      "iiii   btttTb   ",
      "  Ui   y    A   ",
      "  Ui   y    A   ",
      "   i   ydE  A   ",
      "   i   V    W   ",
      "   iiiib    biii",
      "    X  Y    Z  X",
      "       y    A   ",
      "       y    A   ",
      "QQabaQabaQQabaQa",
      "                "
    ],
    [
      "                ",
      "QQabaQabaQQabaQa",
      "       i    i   ",
      "       i    i   ",
      "       ij   i   ",
      "iiii   bttttb   ",
      "  Ui   y    A   ",
      "  Ui   yd   A   ",
      "   i   yE   A   ",
      "   i   y    A   ",
      "   iiiib    biii",
      "       y    A   ",
      "       y    A   ",
      "       y    A   ",
      "QQabaQabaQQabaQa",
      "                "
    ],
    [
      "                ",
      "aaabaaabaaaabaaa",
      "   i   i0000i   ",
      "   i   i0000i   ",
      "   i   i0000i   ",
      "iiiiiiibttttb   ",
      "   i   yd1  A   ",
      "2  i   y3   A   ",
      "   i   y    A   ",
      "   i   y 2  A   ",
      "iiiiiiib4444biii",
      "   i   y    A   ",
      "   i   y    A   ",
      "   i   y    A   ",
      "aaabaaabaaaabaaa",
      "                "
    ],
    [
      "                ",
      "5556555655556555",
      "cccccccccccccccc",
      "dddddddddddddddd",
      "dddddddddddddddd",
      "dddddddddddddddd",
      "dddddddd edddddd",
      "dddddddd   ddddd",
      "dddddddd   ddddd",
      "dddddddddddddddd",
      "dddddddddddddddd",
      "dddddddddddddddd",
      "dddddddddddddddd",
      "cccccccccccccccc",
      "5556555655556555",
      "                "
    ]
  ]
}