{
  "name": "multi_militarybase_0_base2",
  "refpalette": "c70cities:multi_militarybase_0_base2_palette",
  "xsize": 16,
  "zsize": 16,
  "slices": [
    [
      "vvvvvvvvvvvvvvvv",
      "vaaaavaaaaaaavaa",
      "vaaaabaaaaaaabaa",
      "vaaaabaaaaaaabaa",
      "vaaaabaaaaaaabaa",
      "vvbbbvbbbbbbbvbb",
      "vaaaabaaaaaaabaa",
      "vaaaabaaaaaaabaa",
      "vaaaabaaaaaaabaa",
      "vaaaabaaaaaacvdd",
      "vaaaabaaaaaeebee",
      "vaaaabaaaaeeebee",
      "vaaaabaaaaeeebee",
      "vvbbbvbbbbbbbvbb",
      "vaaaaaaaaaeeeb  ",
      "vaaaaaaaaaeeeb  "
    ],
    [
      "vvvvvvvvvvvvvvvv",
      "vfgfgvh h h hv i",
      "vj   kl l l lk m",
      "vj   n       k  ",
      "vf   k       k  ",
      "vvkokvpppqpppvpp",
      "vrs  t          ",
      "v    t          ",
      "vrs  t         u",
      "v    w  x   cvpy",
      "vrs  t AAx      ",
      "v    txAA       ",
      "vrs  t          ",
      "vvkkkv       vBB",
      "vCDCC   x    B  ",
      "v     xAA    B  "
    ],
    [
      "vvvvvvvvvvvvvvvv",
      "v!   vh h h hv i",
      "v    kl l l lk m",
      "v    E       k  ",
      "vF   k       k  ",
      "vvkIkvpppJpppvpp",
      "vrs  t          ",
      "v    t          ",
      "vrs  t          ",
      "v    K      cvpL",
      "vrs  t M        ",
      "v    t          ",
      "vrs  t          ",
      "vvkkkv       v  ",
      "vC!DC           ",
      "v               "
    ],
    [
      "vvvvvvvvvvvvvvvv",
      "v    v       v  ",
      "v    k       k  ",
      "v    k       k  ",
      "v    k       k  ",
      "vvkkkvpppppppvpp",
      "v    t          ",
      "v    t          ",
      "v    t          ",
      "v    t      cvpp",
      "v    t          ",
      "v    t          ",
      "v    t          ",
      "vvkkkv       v  ",
      "vNCCC           ",
      "v               "
    ],
    [
      "vvvvvvvvvvvvvvvv",
      "v    v       v  ",
      "v    k       k  ",
      "v    k       k  ",
      "v    k       k  ",
      "vvkkkvBBBBBBBvpp",
      "v    B       B  ",
      "v    B       B  ",
      "v    B       B  ",
      "v    B      cvBB",
      "v    B          ",
      "v    B          ",
      "v    B          ",
      "vvkkkv       vOO",
      "v            O  ",
      "v            O  "
    ],
    [
      "vvvvvvvvvvvvvvvv",
      "vPPPPvPPPPPPPvPP",
      "vPQQQbQQQQQQQbQQ",
      "vPQQQbQQQQQQQbQQ",
      "vPQQQbQQQQQQQbQQ",
      "vvbbbvbbbbbbbvbb",
      "vPQQQbQQQQQQQbQQ",
      "vPQQQbQQQQQQQbQQ",
      "vPQQQbQQQQQQQbQQ",
      "vPQQQbQQQQQQcvQQ",
      "vPQQQbQQQQQQQbQQ",
      "vPQQQbQQQQQQQbQQ",
      "vPQQQbQQQQQQQbQQ",
      "vvbbbvbbbbbbbvRR",
      "vPQQQQQQQQQQQR  ",
      "vPQQQQQQQQQQQR  "
    ]
  ]
}