{
  "name": "multi_laboratory1_14_base3",
  "refpalette": "c70cities:multi_laboratory1_14_base3_palette",
  "xsize": 16,
  "zsize": 16,
  "slices": [
    [
      "aaaabaaaaaaaacdz",
      "aaaaaaaaaaaaacdz",
      "aaeaaaaaaaaaacdz",
      "aaaaaaaaaaaaacdz",
      "aaafaaaaaaaaacdz",
      "aghaaaaaaaaaacdz",
      "aagaaaaaaaaaacdz",
      "aaaabaaaaaaaacdz",
      "aafaai!iiiiiicdz",
      "aajgafiiiiiffcdz",
      "aagaaiiiiifficdz",
      "aaaaaiiiiiiiicdz",
      "aaaaaiiii!iiicdz",
      "ccccccccccccccdz",
      "dddddddddddddddz",
      "zzzzzzzzzzzzzzzz"
    ],
    [
      "k   bllllllllcdz",
      "kmnolpqr stupcdz",
      "w xylA     BCcdz",
      "DE FlI JK  LMcdz",
      "  n lNOPQ  RScdz",
      "   nTUmVWXYZ0cdz",
      "   1l23445546cdz",
      "7 89bllllllllcdz",
      "   @l##$$$$##cdz",
      " %  f ^  E  &cdz",
      "   *lf()(+()(cdz",
      "    l^- -8-e-cdz",
      "  8 l[-[-[-e-cdz",
      "ccccccccccccccdz",
      "dddddddddddddddz",
      "zzzzzzzzzzzzzzzz"
    ],
    [
      "    bllllllllcdz",
      "    l]      ]cdz",
      "    l        cdz",
      "    l        cdz",
      "    l{       cdz",
      "    }\\ |     cdz",
      "    l234`4446cdz",
      "    bllllllllcdz",
      "   fl]:::::8]cdz",
      "             cdz",
      "    l (;('(;(cdz",
      "    l - - -@-cdz",
      "    l - - -e-cdz",
      "ccccccccccccccdz",
      "dddddddddddddddz",
      "zzzzzzzzzzzzzzzz"
    ],
    [
      "    bllllllllcdz",
      "    l]      ]cdz",
      "    l        cdz",
      "    l{       cdz",
      "    l        cdz",
      "    ,        cdz",
      "    l .  Y/ 6cdz",
      " @  bllllllllcdz",
      "   fl  :: :: cdz",
      "    l        cdz",
      "    l((((((((cdz",
      "    l - - -<-cdz",
      "    l - -@-efcdz",
      "ccccccccccccccdz",
      "dddddddddddddddz",
      "zzzzzzzzzzzzzzzz"
    ],
    [
      "    bllllllllcdz",
      "    l        cdz",
      "    l        cdz",
      "  @ l        cdz",
      "    l        cdz",
      "    l        cdz",
      "    l       6cdz",
      " < fbllllllllcdz",
      "    l>>>>>>>>cdz",
      "    l>>>>>>>>cdz",
      "    l>>>>>>>>cdz",
      "    l>>>>>>e@cdz",
      "    l?>?>f>eecdz",
      "ccccccccccccccdz",
      "dddddddddddddddz",
      "zzzzzzzzzzzzzzzz"
    ],
    [
      "\u00a3\u00a4\u00a3\u00a3bllllllllcdz",
      "\u00a3\u00a5\u00a3\u00a3,\u00a7\u00a7\u00a7\u00a7\u00a7\u00a7\u00a7\u00a7cdz",
      "\u00a3\u00a5\u00a3\u00a3,\u00a7\u00c0\u00a7\u00a7\u00a7\u00a7\u00c1\u00a7cdz",
      "\u00c2\u00a4f\u00a3,\u00a7\u00a7\u00a7\u00a7\u00a7\u00a7\u00a7\u00a7cdz",
      "\u00a3\u00a3f\u00a3,\u00a7\u00a7\u00a7\u00a7\u00a7\u00a7\u00a7\u00a7cdz",
      "\u00a3f\u00a3\u00a3,\u00a7\u00a5\u00a7\u00a7\u00a7\u00a7\u00c0\u00a7cdz",
      "\u00a3\u00a3ff,\u00a7\u00a7\u00a7\u00a7\u00a7\u00a7\u00a7\u00a7cdz",
      "lffebllllllllcdz",
      "\u00c3\u00c3\u00c3\u00c3l\u00c4\u00c4\u00c4eeff\u00c4cdz",
      "\u00c3\u00c3\u00a4\u00c3l\u00c4 \u00c4 e f cdz",
      "\u00c3\u00c3\u00a4\u00c3l\u00c4 \u00c4 f f cdz",
      "\u00c3\u00c3\u00a4\u00c3l\u00c4 \u00c4 f efcdz",
      "\u00c3\u00c3\u00c3\u00c3l\u00c4 \u00c4 f e\u00c5cdz",
      "ccccccccccccccdz",
      "dddddddddddddddz",
      "zzzzzzzzzzzzzzzz"
    ]
  ]
}