{
  "name": "multi_laboratory1_14_floor1",
  "refpalette": "c70cities:multi_laboratory1_14_floor1_palette",
  "xsize": 16,
  "zsize": 16,
  "slices": [
    [
      "aaaabcde        ",
      "aaaabffe        ",
      "aaaabffe        ",
      "aaaabffe        ",
      "aaaabffe        ",
      "aaaabffg        ",
      "aaaabffe        ",
      "aaaabcdg        ",
      "aaaab!fe        ",
      "aaaabffe        ",
      "bbbbbffg        ",
      "hihhhhg         ",
      "hdhhhee         ",
      "eeeee           ",
      "                ",
      "                "
    ],
    [
      "    j  e        ",
      "   kl  g        ",
      "   ml  e        ",
      "   nl  e        ",
      "    l  e        ",
      "    l  e        ",
      "    l  e        ",
      "oo pj  e        ",
      " q rl  e        ",
      " q  l  e        ",
      "ljlll  e        ",
      "      e         ",
      "     eg         ",
      "egeee           ",
      "                ",
      "                "
    ],
    [
      "    j  g        ",
      "       e        ",
      "       e        ",
      "       g        ",
      "       e        ",
      "       e        ",
      "       e        ",
      "st uj  e        ",
      "       e        ",
      "       g        ",
      " j     e        ",
      "      e         ",
      "     ee         ",
      "geeeg           ",
      "                ",
      "                "
    ],
    [
      "    j  e        ",
      "       e        ",
      "       e        ",
      "       e        ",
      "       e        ",
      "       e        ",
      "       g        ",
      "   uj  e        ",
      "       e        ",
      "       e        ",
      " j     e        ",
      "      e         ",
      "     eg         ",
      "eeeee           ",
      "                ",
      "                "
    ],
    [
      "    j  e        ",
      "       e        ",
      "       e        ",
      "       e        ",
      "       e        ",
      "       e        ",
      "       e        ",
      "    j  e        ",
      "       e        ",
      "       e        ",
      " j     e        ",
      "      e         ",
      "     ee         ",
      "eeeee           ",
      "                ",
      "                "
    ],
    [
      "    b  e        ",
      "    d  e        ",
      "    d  e        ",
      "    d  e        ",
      "    d  e        ",
      "    d  e        ",
      "    d  e        ",
      "    b  e        ",
      "    d  e        ",
      "    d  e        ",
      "dbddd  e        ",
      "      e         ",
      "     ee         ",
      "eeeeg           ",
      "                ",
      "                "
    ]
  ]
}