{
  "name": "multi_militarybase_1_ground",
  "refpalette": "c70cities:multi_militarybase_1_ground_palette",
  "xsize": 16,
  "zsize": 16,
  "slices": [
    [
      "abcccccccccccccc",
      "abcccccccccccccc",
      "deczczzcffffffff",
      "gezzzzccfhhhhfff",
      "gezzzzzzfhhhhfff",
      "gezczzzcfhhhhfff",
      "geczzzzcf hhhfff",
      "gezzczzcf hhhhhh",
      "gezzzzzcf hhhhhh",
      "gezzzzczfihhhhhh",
      "gezzzzzcfhhhhhhh",
      "gezzczzcffffffff",
      "geczzzczcccczzcc",
      "gecczzzcczzzzczz",
      "geeeeeeeeeeeeeee",
      "gggggggggggggggg"
    ],
    [
      "j k  k   k   k  ",
      "j  k            ",
      " e      llllll  ",
      " emm m  lnnnnl  ",
      " em   mmlo p l  ",
      " e    m lq   l  ",
      " er m   l s  llt",
      " e m  m l s  uw ",
      " e m    l s     ",
      " em     l s     ",
      " e    m lx   y A",
      " em  m  llllllll",
      " e              ",
      " erBmm  r m m  m",
      " eeeeeeeeeeeeeee",
      "                "
    ],
    [
      "                ",
      "                ",
      " e      CCDDCC  ",
      " e      CEF IC  ",
      " e      D    D  ",
      " e      D    C  ",
      " er     C    CCJ",
      " e      C    uI ",
      " e      D       ",
      " e      D       ",
      " e      C     y ",
      " e      CDDDDCCC",
      " e              ",
      " er     r       ",
      " eeeeeeeeeeeeeee",
      "                "
    ],
    [
      "                ",
      "                ",
      " e      CCDDCC  ",
      " e     KC    C  ",
      " e     KC    D  ",
      " e     KC    C  ",
      " er    KC    CCC",
      " e     KC    u  ",
      " e     KC       ",
      " e     KC       ",
      " e     KC      y",
      " e      CCCCCCCC",
      " e       KKKK   ",
      " er     r       ",
      " eeeeeeeeeeeeeee",
      "                "
    ],
    [
      "                ",
      "                ",
      " e      CCCCCC  ",
      " e      CL   C  ",
      " e      ML   C  ",
      " e      ML   C  ",
      " er     CL   CCM",
      " e      CL   uLL",
      " e      ML      ",
      " e      ML      ",
      " e      CLLLLL  ",
      " e      CMMMMCCC",
      " e              ",
      " er     r       ",
      " eeeeeeeeeeeeeee",
      "                "
    ],
    [
      "        lNNNNl  ",
      "        lNNNNl  ",
      " j      lggggl  ",
      " j      lggggl  ",
      " j      lggggl  ",
      " jO     lggggl  ",
      "PQO     lgggglll",
      " RO     lggggugg",
      " jO     lggggggg",
      " jO     lggggggg",
      " jO     lggggg  ",
      " jO     llllllll",
      " jO      S      ",
      " TUVVVVVVUVVVVVV",
      " TTWWWWWXWWWWWWW",
      "                "
    ]
  ]
}