{
  "name": "multi_gallery_3_ground",
  "refpalette": "c70cities:multi_gallery_3_ground_palette",
  "xsize": 16,
  "zsize": 16,
  "slices": [
    [
      "aabbaaaGGGbGGGGG",
      "GGbGGGGGGbbbGGGG",
      "GGGbGGGGGGbbGGGG",
      "GGbbGGGGGGGbbGGG",
      "GGbbGGGGcvGbbbGG",
      "dddddddddcGGbbGG",
      "dddddddddcGGbGGG",
      "dddddddddcGGbbGG",
      "dddddddddcGGGbGG",
      "dddddddddcGGGbGG",
      "dddddddddcGGbbGG",
      "dddddddddcGGbGGG",
      "dddddddddcGGbbGG",
      "GGbbGGGGcvGbbbGG",
      "GGbbbbbGGbbbbGGG",
      "GGGbbGbbbbGbGGGG"
    ],
    [
      "ee  eeef       g",
      "               g",
      "               g",
      "h      h       h",
      "     g hcvh     ",
      "ijkljjjjcmno    ",
      "       ncmn    h",
      "     pq cmno  h ",
      "     r  cmno    ",
      "n    r scmn     ",
      "n    r  cmno  h ",
      "n      ncmnh    ",
      "ijtujjjjcmno   h",
      "    h   cv      ",
      "        h      h",
      "                "
    ],
    [
      "       w        ",
      "                ",
      "                ",
      "                ",
      "       cmxy     ",
      "ijABjjjjm       ",
      "       nm       ",
      "     C  m       ",
      "        m       ",
      "        m       ",
      "        m       ",
      "       nm       ",
      "ijDEjjjjm       ",
      "       cmxy     ",
      "                ",
      "                "
    ],
    [
      "                ",
      "                ",
      "                ",
      "                ",
      "      cm xy     ",
      "ijFFjjjm        ",
      "       m        ",
      "       m        ",
      "       m        ",
      "       m        ",
      "       m        ",
      "       m        ",
      "ijFFjjjm        ",
      "      cm xy     ",
      "                ",
      "                "
    ],
    [
      "                ",
      "                ",
      "                ",
      "                ",
      "    Icm   v     ",
      "ijFFjjm         ",
      "      m         ",
      "      m         ",
      "      m         ",
      "      m         ",
      "      m         ",
      "      m         ",
      "ijFFjjm         ",
      "     cm   v     ",
      "                ",
      "                "
    ],
    [
      "                ",
      "                ",
      "                ",
      "                ",
      "cccccJ    v     ",
      "cccccJ          ",
      "cccccJ          ",
      "cccccJ          ",
      "cccccJ          ",
      "cccccJ          ",
      "cccccJ          ",
      "cccccJ          ",
      "cccccJ          ",
      "cccccJ    v     ",
      "                ",
      "                "
    ]
  ]
}