{
  "name": "multi_gallery_1_base1",
  "refpalette": "c70cities:multi_gallery_1_base1_palette",
  "xsize": 16,
  "zsize": 16,
  "slices": [
    [
      "vabccdddddcccccb",
      "vabccdddddcccccb",
      "vabccdddddcccccb",
      "vabccccccccccccb",
      "vabccccccccccccb",
      "vaeccccccccceeeb",
      "vaeccccccc!caaaa",
      "vaecccccccccaaaa",
      "vaecccccccccaaaa",
      "vaecccccccccaaaa",
      "vaecccccccccaaaa",
      "vaecccccccccaaaa",
      "vaecccccccccaaaa",
      "vaecccccccccaaaa",
      "vaecccccccccaaaa",
      "vvvvvvvvvvvvvvvv"
    ],
    [
      "vab  dfgad     b",
      "vab  daafd    hb",
      "vab  ddddd     b",
      "vab            b",
      "vab         dddb",
      "vaeiijjjjjiieeeb",
      "vaek  lml  naaaa",
      "vaeop qqq rsaaaa",
      "vaekp qqq rnaaaa",
      "vaeot lml tsaaaa",
      "vaeku      naaaa",
      "vaeou      saaaa",
      "vaeiiiiiiiiiaaaa",
      "vaeaaaaaaaaaaaaa",
      "vaeaaaaaaaaaaaaa",
      "vvvvvvvvvvvvvvvv"
    ],
    [
      "vab  w   w     b",
      "vab  w   w     b",
      "vab  xwwwx     b",
      "vab            b",
      "vab         y Ab",
      "vaeiijjjjjiieeeb",
      "vaen       kaaaa",
      "vaes       oaaaa",
      "vaen       kaaaa",
      "vaesu      oaaaa",
      "vaenu      kaaaa",
      "vaes       oaaaa",
      "vaeiiiiiiiiiaaaa",
      "vaeaaaaaaaaaaaaa",
      "vaeaaaaaaaaaaaaa",
      "vvvvvvvvvvvvvvvv"
    ],
    [
      "vab  w   w     b",
      "vab  w   w     b",
      "vab  xwwwx     b",
      "vab            b",
      "vab            b",
      "vaeiijjjjjiieeeb",
      "vaek       naaaa",
      "vaeo       saaaa",
      "vaeku      naaaa",
      "vaeou      saaaa",
      "vaek       naaaa",
      "vaeo       saaaa",
      "vaeiiiiiiiiiaaaa",
      "vaeaaaaaaaaaaaaa",
      "vaeaaaaaaaaaaaaa",
      "vvvvvvvvvvvvvvvv"
    ],
    [
      "vab  w   w     b",
      "vab  w   w     b",
      "vab  xwwwx     b",
      "vab            b",
      "vab            b",
      "vaeiijjjjjiieeeb",
      "vaen       kaaaa",
      "vaesu      oaaaa",
      "vaenu      kaaaa",
      "vaes       oaaaa",
      "vaen       kaaaa",
      "vaes       oaaaa",
      "vaeiiiiiiiiiaaaa",
      "vaeaaaaaaaaaaaaa",
      "vaeaaaaaaaaaaaaa",
      "vvvvvvvvvvvvvvvv"
    ],
    [
      "vabu w   w uuuub",
      "vabu w   w uuuBb",
      "vabu xwwwx uuuub",
      "vabu       uuuub",
      "vabu       uuuub",
      "vaeiiiiiiiiieeeb",
      "vaeku      naaaa",
      "vaeou      saaaa",
      "vaek       naaaa",
      "vaeo       saaaa",
      "vaek       naaaa",
      "vaeo       saaaa",
      "vaeiiiiiiiiiaaaa",
      "vaeaaaaaaaaaaaaa",
      "vaeaaaaaaaaaaaaa",
      "vvvvvvvvvvvvvvvv"
    ]
  ]
}