{
  "name": "multi_laboratory1_4_ground",
  "refpalette": "c70cities:multi_laboratory1_4_ground_palette",
  "xsize": 16,
  "zsize": 16,
  "slices": [
    [
      "zazzaabvcccdeeee",
      "zzazzabvcccdeeee",
      "azaaaabbcccdeeee",
      "zzzazbbvcccdffff",
      "zazzaaavcccdffff",
      "zzazzabvcccdffff",
      "zazzazbvcccdffff",
      "zzazzabvcccdffff",
      "azzaaabvcccdffff",
      "zzaazabbcccdffff",
      "zazaazbvcccddddd",
      "zzzazaavvccccccc",
      "zzzzaabbvccccccc",
      "zazzzaababbccccc",
      "zzzazzzaazaaaaaz",
      "zzzzzzzzzzzzazzz"
    ],
    [
      "  g        d   h",
      "   ij      k    ",
      " i         lmmmm",
      "           knopq",
      "i  r       k   q",
      " i         kssts",
      "   i       k    ",
      "           d   u",
      "           k   w",
      " i  x      ly  u",
      "i A        llkdk",
      "ii              ",
      " Bi             ",
      "  iii           ",
      " i   ij        A",
      " i  i i  i    i "
    ],
    [
      "           d    ",
      "           C    ",
      "           lmmmm",
      "           k   q",
      "   ~       k   q",
      "           kssDs",
      "           E    ",
      "           d    ",
      "           k   F",
      "           kI   ",
      "           lkkdE",
      "                ",
      "                ",
      "                ",
      "                ",
      "                "
    ],
    [
      "           d    ",
      "           C    ",
      "           lmmmm",
      "           k   q",
      "           k   q",
      "           kssss",
      "           E    ",
      "           d    ",
      "           k   F",
      "           kI   ",
      "           lkkdE",
      "                ",
      "                ",
      "                ",
      "                ",
      "                "
    ],
    [
      "           d    ",
      "           C    ",
      "           lmmmm",
      "           k   q",
      "           k   q",
      "           kssss",
      "           E    ",
      "           d    ",
      "           k    ",
      "           k    ",
      "           lkkdE",
      "                ",
      "                ",
      "                ",
      "                ",
      "                "
    ],
    [
      "           dJJJJ",
      "           kJJJJ",
      "           lmmmm",
      "           kKKKK",
      "           kKLKL",
      "           kKKKK",
      "           kKLKK",
      "           dKKKK",
      "           kKLKM",
      "           kKKKK",
      "           lkkdk",
      "                ",
      "                ",
      "                ",
      "                ",
      "                "
    ]
  ]
}