{
  "name": "multi_hospital_0_floor1",
  "refpalette": "c70cities:multi_hospital_0_floor1_palette",
  "xsize": 16,
  "zsize": 16,
  "slices": [
    [
      "                ",
      "         a      ",
      "         b c c c",
      "         deeeeee",
      "         f  ghhh",
      "         d  ghhh",
      "         fi ghhh",
      "         dijghhh",
      "  kllllllkeeehhh",
      "  l      e  mhhh",
      "  l      e  mhhh",
      "  l      e eehhh",
      "  l      khhhhhh",
      "  l      khhhhhh",
      "  l      khhhhhh",
      "  l      khhhhhh"
    ],
    [
      "                ",
      "         a      ",
      "         b c c c",
      "         neeeeee",
      "         n  l o ",
      "         ni l   ",
      "         np l q ",
      "         n      ",
      "  krrrrrrkeeel  ",
      "  shhhhhhe  t   ",
      "  shhuwhhe  x   ",
      "  shhhhhhe ee   ",
      "  shhhhhhby  A  ",
      "  shhwBhhb   C  ",
      "  shhhhhhb   A  ",
      "  shhhhhhb DDA  "
    ],
    [
      "                ",
      "         a      ",
      "         b c c c",
      "         neennne",
      "         ni     ",
      "         np     ",
      "         n      ",
      "         n      ",
      "  kkkkkkkkeeel  ",
      "         e  E   ",
      "         e  F   ",
      "         e eeI  ",
      "         by  A  ",
      "         b   J  ",
      "         b   A  ",
      "         b  KA  "
    ],
    [
      "                ",
      "         a      ",
      "         b c c c",
      "         neennne",
      "         nji    ",
      "         n i    ",
      "         n      ",
      "         n      ",
      "         keeel  ",
      "        Le  M   ",
      "        Le  M   ",
      "        Le ee   ",
      "        Lby  A  ",
      "         f   M  ",
      "         f   A  ",
      "         f   A  "
    ],
    [
      "                ",
      "         a      ",
      "         b c c c",
      "         neeeeee",
      "         n      ",
      "         n N    ",
      "         n i  O ",
      "         n      ",
      "         keeel  ",
      "        Le  e   ",
      "        Le  e   ",
      "        Le ee   ",
      "        Lby  A  ",
      "        LP   A  ",
      "        LP   A  ",
      "        LP  QA  "
    ],
    [
      "                ",
      "         a      ",
      "         b c c c",
      "         neeeeee",
      "         n      ",
      "         n      ",
      "         n N  B ",
      "         n i    ",
      "         keeelll",
      "        Le  e   ",
      "        Le  e   ",
      "        Le ee   ",
      "        LbvRRA  ",
      "        LbvRRA  ",
      "        LbvRRA  ",
      "        LbvRRA  "
    ]
  ]
}