{
  "name": "multi_laboratory1_0_base3",
  "refpalette": "c70cities:multi_laboratory1_0_base3_palette",
  "xsize": 16,
  "zsize": 16,
  "slices": [
    [
      "zzzzzzzzzzzzzzzz",
      "zaaaaaaaaaaaaaaa",
      "zabbbbbbbbbbcccc",
      "zabddeeedddf    ",
      "zabddeegeddf    ",
      "zabddddehidfffff",
      "zabdddg!eedjjjjj",
      "zabddddhdedjjjjj",
      "zabjjjeejjjfjjjj",
      "zabddeeddddjjjjj",
      "zabddkeddehejjjj",
      "zabdde!hehdjeejj",
      "zabddddehedjjejj",
      "zabddhdddddjjjjj",
      "zabddddddddjjjjj",
      "zabjjjjjjjjfjjjj"
    ],
    [
      "zzzzzzzzzzzzzzzz",
      "zaaaaaaaaaaaaaaa",
      "zabbbbbbbbbbcccc",
      "zablml!lhlmn    ",
      "zabl lelolpn    ",
      "zabqrqsp   nnnnn",
      "zab tp  su w  x ",
      "zabyyhpAByyn   C",
      "zabnne ennnf   D",
      "zabhh  EEFFnn  I",
      "zabeJ Apuu ee KI",
      "zab eu  J eLuAMI",
      "zabNONOeePOKp  I",
      "zab QAQ Q QnKt D",
      "zabRQhQRQRQn  p ",
      "zabnnnnnnnnf    "
    ],
    [
      "zzzzzzzzzzzzzzzz",
      "zaaaaaaaaaaaaaaa",
      "zabbbbbbbbbbcccc",
      "zabl lSlAl n    ",
      "zabl lul   n    ",
      "zabqT      nnnnn",
      "zab        U    ",
      "zabVW    W n    ",
      "zabnnS Jhnnf   X",
      "zabeY    YZL   0",
      "zabeu      t    ",
      "zab A   u 1    2",
      "zab3O3OAh4O    5",
      "zab Q Q Q Qn   X",
      "zab QSQ Q Qn    ",
      "zabnnnnnnnnf    "
    ],
    [
      "zzzzzzzzzzzzzzzz",
      "zaaaaaaaaaaaaaaa",
      "zabbbbbbbbbbcccc",
      "zabl lelSl n    ",
      "zabl l   l n    ",
      "zabqq  S  qnnnnn",
      "zab        n    ",
      "zab W   WW n    ",
      "zabnnh Jnnnf   Z",
      "zabuY6  YY 7    ",
      "zab             ",
      "zab S    S 7   8",
      "zabOOOOOOOOn   9",
      "zab Q Q Q Qn   Z",
      "zab Q@Q Q Qn    ",
      "zabnnnnnnnnf    "
    ],
    [
      "zzzzzzzzzzzzzzzz",
      "zaaaaaaaaaaaaaaa",
      "zabbbbbbbbbbcccc",
      "zab#$#e#h#$n    ",
      "zab####  ##n    ",
      "zab####@ ##nnnnn",
      "zab#####S##n    ",
      "zab########n    ",
      "zabnneennnnf    ",
      "zab##J#####n    ",
      "zab#S #####n    ",
      "zab#@####@#n    ",
      "zab######S#n    ",
      "zab########n    ",
      "zab$#h#$#$#n    ",
      "zabnnnnnnnnf    "
    ],
    [
      "zzzzzzzzzzzzzzzz",
      "zaaaaaaaaaaaaaaa",
      "zabbbbbbbbbbcccc",
      "zab % e e %n    ",
      "zab % eee %n    ",
      "zab % hhe %nnnnn",
      "zab % h e %n7777",
      "zab %%%%e%%n7777",
      "zabnnnnnnnnf7777",
      "zab%%h%%%%%n7777",
      "zab%he % % n7777",
      "zab%eh^%^e^n7777",
      "zab%&e^%^e^n7777",
      "zab%^%^%^%^n7777",
      "zab%^%^%^%^n7777",
      "zabnnnnnnnnf****"
    ]
  ]
}