{
  "name": "multi_laboratory1_3_base2",
  "refpalette": "c70cities:multi_laboratory1_3_base2_palette",
  "xsize": 16,
  "zsize": 16,
  "slices": [
    [
      "vabccccccccccccc",
      "vab!cccccccccccc",
      "vabccccccccdcccc",
      "vabccccccccccccc",
      "vabccccccccccccc",
      "vabccccccccccccc",
      "vabccccccccccccc",
      "vabccccccccccccc",
      "vabeeffffffccccc",
      "vabccccccccdcccc",
      "vabccccccccccccc",
      "vabccccccccccccc",
      "vabccccccccccccc",
      "vabccccccccccccc",
      "vabccccccccccccc",
      "vabccccccccccccc"
    ],
    [
      "vabg h     i  j ",
      "vabkklm    n  jo",
      "vabp qp   rd  j ",
      "vabst     rn  j ",
      "vabkkp   uwn  jx",
      "vabyhA q  Bn    ",
      "vab  qC lD n    ",
      "vab  EFF   n    ",
      "vab IJJJJK n    ",
      "vabL      Ldnnnn",
      "vabLM NN OLnM   ",
      "vabLj NN PLn    ",
      "vabLj NN QLn    ",
      "vabLj NNR Ln  FF",
      "vabLS     Ln   T",
      "vabLLLLLLLLn   U"
    ],
    [
      "vab        i    ",
      "vabV       n  W ",
      "vabX       d    ",
      "vab        n  W ",
      "vabV       Y    ",
      "vabX       Y    ",
      "vab        Y    ",
      "vab   Z0   Y    ",
      "vab 1JJJJ2 n    ",
      "vabL      LdnYYY",
      "vabL      Ln    ",
      "vabL3     L4    ",
      "vabL3     L4    ",
      "vabL      L4    ",
      "vabL      L4   5",
      "vabLLLLLLLLn    "
    ],
    [
      "vab        i    ",
      "vab        n    ",
      "vab        d    ",
      "vab        n    ",
      "vab        Y    ",
      "vab        Y    ",
      "vab        Y    ",
      "vab        Y    ",
      "vab JJJJJJ n    ",
      "vabL      LdnYYY",
      "vabL 6    Ln    ",
      "vabL      L7    ",
      "vabL   8  L7    ",
      "vabL      L7    ",
      "vabL      L7    ",
      "vabLLLLLLLLn    "
    ],
    [
      "vab        n    ",
      "vab        n    ",
      "vab        d    ",
      "vab        n    ",
      "vab        n    ",
      "vab        n    ",
      "vab        n    ",
      "vab        n    ",
      "vab JJJJJJ n    ",
      "vabL      Ldnnnn",
      "vabL 9    Ln    ",
      "vabL      Ln    ",
      "vabL   9  Ln    ",
      "vabL @    Ln    ",
      "vabL #  # Ln    ",
      "vabLLLLLLLLn    "
    ],
    [
      "vab$$%$$%$$^&%&&",
      "vab$$*$$%$$^&&&&",
      "vab$$$$$$$$d&&&&",
      "vab$$$$$$$$^&&&&",
      "vab$$%$$%$$^&%&&",
      "vab$$*$$%$$^&%&&",
      "vab$$%$$*$$^&%&&",
      "vab$$%$$%$$^&(&&",
      "vab$$$$$$$$^&&&&",
      "vabL((((((Ld))))",
      "vabL(+-[](L^$$$$",
      "vabL(-[]{(L^$$$$",
      "vabL(-]+}(L^$$$$",
      "vabL(+-]\\(L^$$%%",
      "vabL((((((L^$$%$",
      "vabLLLLLLLL^$$%$"
    ]
  ]
}