{
  "name": "multi_convenientstore_1_ground",
  "refpalette": "c70cities:multi_convenientstore_1_ground_palette",
  "xsize": 16,
  "zsize": 16,
  "slices": [
    [
      "GGHHHHHHaaaaaaaa",
      "GGHHHHHHabbbbbbb",
      "GGHHHHHHabbbbbbb",
      "GGHHHHHHabbbbbbb",
      "GGHHHHHHabbbbbbb",
      "GGHHHHHHabbbbbbb",
      "GGHHHHHHabbbbbbb",
      "GGHHHHHHabbbbbbb",
      "GGHHHHHHabbbbbbb",
      "GGHHHHHHabbbbbbb",
      "GGHHHHHHabbbbbbb",
      "GGHHHHHHabbbbbbb",
      "GGHHHHHHaaaaaaaa",
      "GGHHHHHHHHHHHHHH",
      "GGHHHHHHHHHHHHHH",
      "GGHHHHHccccccccc"
    ],
    [
      " d   eaaaaaaaaaa",
      " f   eaaabbbbbbb",
      " f   eaaabbbbbbb",
      " f   eaaabbbbbbb",
      "     eaaabbbbbbb",
      "d    eaaabbbbbbb",
      "     eaaabbbbbbb",
      "f    eaaabbbbbbb",
      "     eaaabbbbbbb",
      "     eaaabbbbbbb",
      "d    eaaabbbbbbb",
      "f    eaaabbbbbbb",
      "     eaaaaaaaaaa",
      " f   vvvvHHHHHHH",
      "f     gggHHHHHHH",
      " d    gggHHHHHHH"
    ],
    [
      " ~     hhh  hhij",
      "        k     l ",
      "        h  m    ",
      "        n  opoq ",
      "        n mr    ",
      "~       n   r s ",
      "       ti  oqoq ",
      "        u       ",
      "        w       ",
      "       xi       ",
      "~       n       ",
      "        nyAAyBBB",
      "        nCCCCCCC",
      "     vvvvD EEEFD",
      "                ",
      " ~              "
    ],
    [
      "        hh  hhiI",
      "        h       ",
      "        h       ",
      "        n  J K  ",
      "        h       ",
      "        n       ",
      "       ti  pKLM ",
      "        N       ",
      "        O       ",
      "       xi       ",
      "        n       ",
      "        hPPPPQQQ",
      "        nCCCCCCC",
      "     vvvv     E ",
      "                ",
      "                "
    ],
    [
      "        hh hhhii",
      "        h       ",
      "        h       ",
      "        n       ",
      "        h       ",
      "        n       ",
      "       Ri       ",
      "       Si       ",
      "       Si       ",
      "       Ti       ",
      "        n       ",
      "        h       ",
      "        nCCCCCCC",
      "     vvvv     EE",
      "                ",
      "                "
    ],
    [
      "        hhhhhhhh",
      "        h       ",
      "        h       ",
      "        n       ",
      "        n       ",
      "        n       ",
      "        nUUUUUUU",
      "        n V  W  ",
      "        n W  V  ",
      "        n       ",
      "        n       ",
      "        nEXEEXEE",
      "        nCCCCCCC",
      "     vvvv       ",
      "                ",
      "                "
    ]
  ]
}