{
  "name": "multi_laboratory1_9_base6",
  "refpalette": "c70cities:multi_laboratory1_9_base6_palette",
  "xsize": 16,
  "zsize": 16,
  "slices": [
    [
      "aaaaaaaaaaaaaaaa",
      "aaaaaaaaaaaaaaaa",
      "aaaaaaaaaaaaaaaa",
      "aaaaaaaaaaaaaaaa",
      "aaaaaaaaaaaaaaaa",
      "aaaaaaaaaaaaaaaa",
      "aaaa!aaaaaaaaaaa",
      "aaaaaaaaaaaaaaaa",
      "aaaaaaaaaaaaaaaa",
      "aaaaaaaaaaaaaaaa",
      "aaaaaaaaaaaaaaaa",
      "aaaaaaaaaaaaaaaa",
      "aaaaaaaaaaaaaaaa",
      "bbbbbbbbbbbbbbbb",
      "cccccccccccccccc",
      "zzzzzzzzzzzzzzzz"
    ],
    [
      "  deefeeggeeed f",
      "  deeeeeegeeedhf",
      "iideefefeefgedjj",
      "iideeeffkgggkdjj",
      "iid!eeefggekedjj",
      "iideeeeekegffdjj",
      "  degeeeeekfedhl",
      "  meeeeeeegfednh",
      "  ddddddddddddo ",
      "      pppp qlr  ",
      "     ippppj s   ",
      "     ippppj  s  ",
      "      pppp      ",
      "bbbbbbbbbbbbbbbb",
      "cccccccccccccccc",
      "zzzzzzzzzzzzzzzz"
    ],
    [
      "  t          t u",
      "  t  r     l t  ",
      "  t    u wf  tff",
      "  t    xn   ukky",
      "  t nl l  wurt  ",
      "  t     ul  xh  ",
      "  t    w sulfl  ",
      "  t  n   ! kft  ",
      "  ttttABCAtlrt  ",
      "      A  A      ",
      "      D  E      ",
      "      F  I      ",
      "      A  A      ",
      "bbbbbbbJJbbbbbbb",
      "cccccccccccccccc",
      "zzzzzzzzzzzzzzzz"
    ],
    [
      "  t          t  ",
      "  t          t  ",
      "  t       u  tk ",
      "  t          t  ",
      "  t          l  ",
      "  t             ",
      "  t             ",
      "  t        fkK  ",
      "  ttttALMAtNtt  ",
      "     OAPOA      ",
      "      Q  R      ",
      "      S  T      ",
      "     OAPOAP     ",
      "bbbbbbbJJbbbbbbb",
      "cccccccccccccccc",
      "zzzzzzzzzzzzzzzz"
    ],
    [
      "  t     U    t  ",
      "  t          t  ",
      "  t          t  ",
      "  t          K  ",
      "  t          t  ",
      "  t             ",
      "  t          V  ",
      "  t        uft  ",
      "  ttttAAAAtttt  ",
      "      AAAA      ",
      "      AAAA      ",
      "      AAAA      ",
      "      AAAA      ",
      "bbbbbbbbbbbbbbbb",
      "cccccccccccccccc",
      "zzzzzzzzzzzzzzzz"
    ],
    [
      "  t     W    t  ",
      "  t          t  ",
      "  t          t  ",
      "  t      XYZ0t  ",
      "  t          t  ",
      "  t             ",
      "  t    1     f  ",
      "  t         ft  ",
      "  tttttttttttt  ",
      "      2  2      ",
      "      2  2      ",
      "      2  2      ",
      "      2  2      ",
      "bbbbbbbbbbbbbbbb",
      "cccccccccccccccc",
      "zzzzzzzzzzzzzzzz"
    ]
  ]
}