{
  "name": "multi_megatower1_4_floor9",
  "refpalette": "c70cities:multi_megatower1_4_floor9_palette",
  "xsize": 16,
  "zsize": 16,
  "slices": [
    [
      "a   bbbbbbbbbbbb",
      "a   bbbbbbbbbbbb",
      "a   bbbbbbbbbbbb",
      "cdeebbbbbbbbbbbb",
      "bbbbfbbbbbbfgggg",
      "bbbbbbbbbbbbgggg",
      "bbbbbbbbbbbbgggg",
      "bbbbbbbbbbbbgggg",
      "bbbbbbbbbbbbgggg",
      "bbbbbbbbbbbbgggg",
      "bbbbbbbbbbbbgggg",
      "bbbbfbbbbbbfgggg",
      "bbbbbbbbbbbbbbbb",
      "bbbbbbbbbbbbbbbb",
      "bbbbbbbbbbbbbbbb",
      "bbbbbbbbbbbbbbbb"
    ],
    [
      "a   ah         i",
      "a   ah  jkkl   m",
      "a   ah         n",
      "aeooah         n",
      "pqrsfttuwttfxyxx",
      "         A BC  x",
      "        DE BF  I",
      "        DE BJ  x",
      " K      DE BJ  I",
      " LMNO   DE BF  x",
      " LMNOP   A B   I",
      "   QfQ    QfxRxx",
      " LMSOTMU    Q VW",
      " LMSOTMU        ",
      "       X        ",
      "     X    YY  ZY"
    ],
    [
      "a   a0         1",
      "a   a2   34    5",
      "a   a6         n",
      "ae  a7         n",
      "p 89ftt@#ttfx$xx",
      "           B   x",
      "         % ^&  *",
      "         % ^   x",
      "           ^&  *",
      "  K (    % ^&  x",
      "  ) +      B   *",
      "   -f-    -fx[xx",
      "  Z (       -   ",
      "    + Z         ",
      "                ",
      "                "
    ],
    [
      "a   a          n",
      "a   a]         n",
      "a   a{         n",
      "aeeea}         n",
      "p\\  ftt||ttfxxxx",
      "         ` B   x",
      "         ` ^&  x",
      "         ` ^&  x",
      "         ` ^   x",
      "         ` ^&  x",
      "         ` B   x",
      "   -f-    -fxxxx",
      "            -   ",
      "                ",
      "                ",
      "                "
    ],
    [
      "a   a::::::::::;",
      "a   a::::::::::;",
      "a   a:'::':::':;",
      "aeeea::::::::::;",
      "ppppfttttttfxxxx",
      "           ,....",
      "         / ,....",
      "           ,....",
      "           ,....",
      "         / ,....",
      "           ,....",
      "    f      fxxxx",
      "                ",
      "                ",
      "                ",
      "                "
    ],
    [
      "a   <> >  ><>   ",
      "a   <  > > <  > ",
      "a   < /  / < / >",
      "ae??<>     <>   ",
      "\u00a3\u00a3\u00a3\u00a3f\u00a3\u00a3\u00a3\u00a3\u00a3\u00a3f\u00a3\u00a3\u00a3\u00a3",
      "::::<::::::< >  ",
      "::':<:'::\u00a4:<\u00a5\u00a5\u00a5\u00a5",
      "::::<::::::<> \u00a5>",
      "::::<::::::<  \u00a5\u00a5",
      "::':<:'::\u00a7:<  \u00a5>",
      "::::<::::::<>>\u00a5\u00a5",
      "\u00a3\u00a3\u00a3\u00a3f\u00a3\u00a3\u00a3\u00a3\u00a3\u00a3f\u00a3\u00a3\u00a3\u00a3",
      "::::<::::::<::::",
      "::':<:'::':<:'::",
      "::::<::::::<::::",
      "::::<::::::<::::"
    ]
  ]
}