{
  "name": "multi_militarybase_2_ground",
  "refpalette": "c70cities:multi_militarybase_2_ground_palette",
  "xsize": 16,
  "zsize": 16,
  "slices": [
    [
      "aaaaaaaaaaaaaaaa",
      "bbbbbbbbbbbbbbbb",
      "cczzzzcczczzzccz",
      "zcczccccczczcczc",
      "ddddddddcccccccc",
      "eeeeeeedcccccccc",
      "eeeeeeedcccccccc",
      "eeeeeeedcccccccc",
      "eeeeeeedcccccccc",
      "dddeeeedcccccccc",
      "dddeeeedcccccccc",
      "dddeeeedcccccccc",
      "dddfeeedcccccccc",
      "ddddddddcccccccc",
      "cccccccccccccccc",
      "cccccccccccccccc"
    ],
    [
      "                ",
      "bbbbbbbbbbbbbbbb",
      "  gg g hg g i   ",
      "                ",
      "jjjjjjjj        ",
      "kkl    m        ",
      "       m        ",
      "       m        ",
      " n     m        ",
      "ojjpqrpj st t   ",
      "  ju  wjstxst s ",
      "  jw  yjssssst  ",
      "  jfyy!jsstss   ",
      "  jjjjjj tt     ",
      "  A             ",
      "                "
    ],
    [
      "                ",
      "bbbbbbbbbbbbbbbb",
      "       h   i    ",
      "                ",
      "BBBCCCCB        ",
      "  D    m        ",
      "       m        ",
      "       m        ",
      " E     m        ",
      "FBBpIJpB        ",
      "  B    C  ss    ",
      "  C    C tsst   ",
      "  Bf uKBt   L   ",
      "  BBBBBB        ",
      "                ",
      "                "
    ],
    [
      "                ",
      "bbbbbbbbbbbbbbbb",
      "       h  i     ",
      "   MMMM         ",
      "BBBBBBBB        ",
      "       m        ",
      "       m        ",
      "       m        ",
      "       m        ",
      "BBBppppBM       ",
      "  B    BM       ",
      "  C    BM       ",
      "  Bf  KBM       ",
      "  BBBBBB        ",
      "                ",
      "                "
    ],
    [
      "                ",
      "bbbbbbbbbbbbbbbb",
      "       h i      ",
      "                ",
      "BBBNNNNB        ",
      "O PPPPPQ        ",
      "      PQ        ",
      "      PQ        ",
      "PP    PQ        ",
      "NBBPPPPB        ",
      "  B   PN        ",
      "  BK  PN        ",
      "  BfK PB        ",
      "  BBBBBB        ",
      "                ",
      "                "
    ],
    [
      "                ",
      "RRRRRRRSTRRRRRRR",
      "UUUUUUUUU       ",
      "      V         ",
      "jjjjjjjj        ",
      " Oaaaaaj        ",
      "aaaaaaaj        ",
      "aaaaaaaj        ",
      "aaaaaaaj        ",
      "jjjaaaaj        ",
      "  jaaaaj        ",
      "  jaaaaj        ",
      "  jfaaaj        ",
      "  jaaaaj        ",
      "  jWWWWj        ",
      "  jWWWWj        "
    ]
  ]
}