{
  "name": "multi_cafe_2_floor1",
  "refpalette": "c70cities:multi_cafe_2_floor1_palette",
  "xsize": 16,
  "zsize": 16,
  "slices": [
    [
      "                ",
      "                ",
      "              a ",
      "             ba ",
      " ccccccccccccba ",
      " cdddddddddd==a ",
      " cd          ef ",
      " cd          ea ",
      " cd g   h   iif ",
      " cd         jea ",
      " cd       jjjea ",
      " cd       k kea ",
      " cd       j jea ",
      " cd g l h   iif ",
      " cd          ea ",
      " cd          ea "
    ],
    [
      "                ",
      "                ",
      "              a ",
      "             ba ",
      "             ba ",
      "  ============a ",
      "  =     cccccef ",
      "  =     cccccea ",
      "  =mmmmmhhhhiif ",
      " n=     cccccea ",
      " o=     cccccea ",
      " n=     cccccea ",
      " n=     cccccea ",
      " p=mmmmmhhhhiif ",
      "  =     cccccea ",
      " p=     cccccea "
    ],
    [
      "                ",
      "                ",
      "              a ",
      "           qqra ",
      "           qqra ",
      "  ============a ",
      "  =     i sjjjf ",
      "  =     i  ssja ",
      "  =    !hs  iif ",
      " n=     i   sja ",
      " t=     i s uja ",
      " w=     i   xja ",
      " n=     i  sija ",
      " w=     h  siif ",
      " y=     is   ja ",
      " A=     i ssxja "
    ],
    [
      "                ",
      "                ",
      "          BBBBa ",
      "   qqqqqqrCDDDa ",
      "   qqqqqqrCBBBE ",
      "  ========BBBBE ",
      "  =FFFFFis    f ",
      "  =FFFFFi BBBBE ",
      "  =     hs  iif ",
      "  =FFFFFi BBBBE ",
      "  =FFFFFisBBBBE ",
      "  =FFFFFi BBBBE ",
      "  =FFFFFisBBBBE ",
      "  =     hs  iif ",
      "  =FFFFFi BBBBE ",
      "  =FFFFFi BBBBE "
    ],
    [
      "                ",
      "                ",
      "  BBBBIIII      ",
      "qrCDDDDIIII     ",
      "qrCBBBDIIII     ",
      "qrBBBBIIII      ",
      "qrffffffffJJJJJ ",
      "qrfBBBIIII      ",
      "qrfKKKKKffJJJJJ ",
      "qrfBBBIIII      ",
      "qrfBBBDIIII     ",
      "qrfBBBDIIII     ",
      "qrfBBBIIII      ",
      "qrfKKKKKffJJJJJ ",
      "qrfBBBIIII      ",
      "qrfBBBDIIII     "
    ],
    [
      "                ",
      "                ",
      "II              ",
      "III             ",
      "III             ",
      "II              ",
      "IIJJJJ          ",
      "IIJ             ",
      "IIJ     ~       ",
      "IIJ             ",
      "IIJ             ",
      "IIJ             ",
      "IIJ             ",
      "IIJ             ",
      "IIJ             ",
      "IIJ             "
    ]
  ]
}