{
  "name": "multi_condo1_3_base1",
  "refpalette": "c70cities:multi_condo1_3_base1_palette",
  "xsize": 16,
  "zsize": 16,
  "slices": [
    [
      "vvvvvvvvvvvvvvvv",
      "aaaaaaaaaaaaaaav",
      "bbbbbbbbbbbbbaav",
      "bcccccb     baav",
      "Hcccccb     baav",
      "Hcccccb  b  baav",
      "Hcccccb  b  baav",
      "bcccccb  b  baav",
      "bcccccb  b  baav",
      "bcccccb  b  baav",
      "bcccccb  b  baav",
      "bcccccb  b  baav",
      "bcccccb  bddbaav",
      "bcccccbeebddbaav",
      "bbbbbbbeebbbbaav",
      "HHHHHHHHHHHHbaav"
    ],
    [
      "vvvvvvvvvvvvvvvv",
      "aaaaaaaaaaaaaaav",
      "bbbbbbbbbbbbbaav",
      "b ffffb     baav",
      "g  hffb     baav",
      "g  i fb  b  baav",
      "g j  kb  b  baav",
      "b   f b  b  baav",
      "bl   kb  bddbaav",
      "bl    b  bddbaav",
      "b   f b  bHHbaav",
      "bl  mnb  bHHbaav",
      "bl   nb  bHHbaav",
      "bokpqnb  beebaav",
      "bbbbbbb  beebaav",
      "            baav"
    ],
    [
      "vvvvvvvvvvvvvvvv",
      "aaaaaaaaaaaaaaav",
      "bbbbbbbbbbbbbaav",
      "b  f!fb     baav",
      "g   rjb   ddbaav",
      "g     b  bddbaav",
      "g     b  bHHbaav",
      "b   msb  bHHbaav",
      "blt   b  bHHbaav",
      "blt   b  beebaav",
      "bu  msb  beebaav",
      "blt f b  b  baav",
      "blt   b  b  baav",
      "buuu kb  b  baav",
      "bbbbbbb  b  baav",
      "            baav"
    ],
    [
      "vvvvvvvvvvvvvvvv",
      "aaaaaaaaaaaaaaav",
      "bbbbbbbbbbbbbaav",
      "b  i  bHHHHHbaav",
      "g     bHHHHHbaav",
      "g     bHHbeebaav",
      "g    nbddbeebaav",
      "b     bddb  baav",
      "bw   nb  b  baav",
      "bw   nb  b  baav",
      "b     b  b  baav",
      "bw   kb  b  baav",
      "bw    b  b  baav",
      "bk u  b  b  baav",
      "bbbbbbb  b  baav",
      "      x     baav"
    ],
    [
      "vvvvvvvvvvvvvvvv",
      "aaaaaaaaaaaaaaav",
      "bbbbbbbbbbbbbaav",
      "buuuuub     baav",
      "y    ub     baav",
      "y    ubeeb  baav",
      "y    ubeeb  baav",
      "b    ubHHb  baav",
      "b    ubHHb  baav",
      "b    ubHHb  baav",
      "b    ubddb  baav",
      "b    ubddb  baav",
      "bk   ub  b  baav",
      "buuuuub  b  baav",
      "bbbbbub  b  baav",
      "     ub     baav"
    ],
    [
      "vvvvvvvvvvvvvvvv",
      "aaaaaaaaaaaaaaav",
      "bbbbbbbbbbbbbaav",
      "AAAAAAb     baav",
      "AAAAAAb     baav",
      "AAAAAAb     baav",
      "AAAAAAb     baav",
      "AAAAAAb  B  baav",
      "AAAAAAb  B  baav",
      "AAAAAAbeeb  baav",
      "AAAAAAbeeb  baav",
      "AAAAAAbHHb  baav",
      "AAAAAAbHHb  baav",
      "AAAAAAbHHb  baav",
      "AAAAAAbbbbbbbaav",
      "AAAAAAb     baav"
    ]
  ]
}