{
  "name": "multi_condo1_0_floor1",
  "refpalette": "c70cities:multi_condo1_0_floor1_palette",
  "xsize": 16,
  "zsize": 16,
  "slices": [
    [
      "                ",
      "          a     ",
      "  bbbbbbbba     ",
      "  bcccccccaddddd",
      "  bcefffffffffff",
      "  bcghhhhhhhhhhh",
      "  bcghhhhhhhhhhh",
      "  bcghhhhhhhhhhh",
      "  bcghhhhhhhhhhh",
      "  bcghhhhhhhhhhh",
      "  bcghhhhhhhhhhh",
      "  bcghhhhhhhhhhh",
      "  bcghhhhhhhhhhh",
      " aaaghhhhhhhhhhh",
      "   igccccccccccc",
      "   igjjjjjjkllll"
    ],
    [
      "                ",
      " aaaaaaaaaa     ",
      " aaaaaaaaaa     ",
      " aammmmmmmn     ",
      " aamoooooooooooo",
      " aamo           ",
      " aamo           ",
      " aamo  p   p   p",
      " aamo  q   q   q",
      " aamo  q   q   q",
      " aamo  q   q   q",
      " aamo  rqqq!qqqr",
      " aamo           ",
      " aaso           ",
      "    o           ",
      "    o           "
    ],
    [
      "                ",
      "                ",
      "                ",
      "                ",
      "    oooooooooooo",
      "    o           ",
      "    o           ",
      "    o  ~        ",
      "    o           ",
      "    o           ",
      "    o           ",
      "    o  t   u   u",
      "    o           ",
      "    o           ",
      "    o           ",
      "    o           "
    ],
    [
      "                ",
      "                ",
      "                ",
      "                ",
      "    w           ",
      "                ",
      "                ",
      "       ~        ",
      "                ",
      "                ",
      "                ",
      "                ",
      "                ",
      "                ",
      "                ",
      "                "
    ],
    [
      "                ",
      "                ",
      "                ",
      "                ",
      "    x           ",
      "                ",
      "                ",
      "       ~        ",
      "                ",
      "                ",
      "                ",
      "                ",
      "                ",
      "                ",
      "                ",
      "                "
    ],
    [
      "                ",
      "                ",
      "                ",
      "                ",
      "                ",
      "                ",
      "                ",
      "       ~        ",
      "                ",
      "                ",
      "                ",
      "                ",
      "                ",
      "                ",
      "                ",
      "                "
    ]
  ]
}