{
  "name": "multi_militarybase_2_base2",
  "refpalette": "c70cities:multi_militarybase_2_base2_palette",
  "xsize": 16,
  "zsize": 16,
  "slices": [
    [
      "vvvvvvvvvvvvvvvv",
      "aaaaaaavaaaaaaaa",
      "aaaaaaabaaaaaaaa",
      "aaaaaaabaaaaaaaa",
      "aaaaaaabaaaaaaaa",
      "bbbbbbbvbbbbbbbb",
      "aaaaaaabaaaaaaaa",
      "aaaaaaabaaaaaaaa",
      "aaaaaaabaaaaaaaa",
      "cccccccvcccccccd",
      "eeeeeeebeeeeeeee",
      "eeeeeeebeeeeeeee",
      "eeeeeeebeeeeeeee",
      "bbvbbbbvbbbbvbbb",
      "  f    f    f   ",
      "                "
    ],
    [
      "vvvvvvvvvvvvvvvv",
      " g g g v g g g g",
      " h h h   h h h h",
      " i i i   i i i i",
      "                ",
      "jjkjjjjvjjjljjjj",
      "                ",
      "                ",
      "mmnmom   moonmmm",
      "ppppppjvjppppppp",
      "                ",
      "                ",
      "                ",
      "qqvqqqqvqqqqvqqq",
      "                ",
      "                "
    ],
    [
      "vvvvvvvvvvvvvvvv",
      " g g g v g g g g",
      " h h h   h h h h",
      " r r r   r r r r",
      "                ",
      "jjsjjjjvjjjtjjjj",
      "                ",
      "                ",
      "  u w     xyu   ",
      "ppApppjvjBpp!ppp",
      "                ",
      "                ",
      "                ",
      "  v    v    v   ",
      "                ",
      "                "
    ],
    [
      "vvvvvvvvvvvvvvvv",
      "       v        ",
      "                ",
      "                ",
      "                ",
      "jjjjjjjvjjjjjjjj",
      "                ",
      "                ",
      "                ",
      "jjjjjjjvjjjjjjjj",
      "                ",
      "                ",
      "                ",
      "  v    v    v   ",
      "                ",
      "                "
    ],
    [
      "vvvvvvvvvvvvvvvv",
      "       v        ",
      "                ",
      "                ",
      "                ",
      "jjjjjjjvjjjjjjjj",
      "       q        ",
      "       q        ",
      "       q        ",
      "qqqqqqqvqqqqqqqq",
      "                ",
      "                ",
      "                ",
      "CCvCCCCvCCCCvCCC",
      "                ",
      "                "
    ],
    [
      "vvvvvvvvvvvvvvvv",
      "DD!DDDDvDDDDDDDD",
      "EEEEEEEbEEEEEEEE",
      "EEEEEEEbEEEEEEEE",
      "EEEEEEEbEEEEEEEE",
      "bbbbbbbvbbbbbbbb",
      "EEEEEEEbEEEEEEEE",
      "EEEEEEEbEEEEEEEE",
      "EEEEEEEbEEEEEEEE",
      "EEEEEEEvEEEEEEEE",
      "EEEEEEEbEEEEEEEE",
      "EEEEEEEbEEEEEEEE",
      "EEEEEEEbEEEEEEEE",
      "FFvFFFFvFFFFvFFF",
      "                ",
      "                "
    ]
  ]
}