{
  "name": "multi_communitycenter_7_base1",
  "refpalette": "c70cities:multi_communitycenter_7_base1_palette",
  "xsize": 16,
  "zsize": 16,
  "slices": [
    [
      "HHHHHHHHHHHHHHHv",
      "HHHHHHHHHHHHHHHv",
      "HHHHHHHHHHHHHHHv",
      "HHHHHHHHHHHHHHHv",
      "HHHHHHHHHHHHHHHv",
      "HHHHHHHHHHHHHHHv",
      "HHHHHHHHHHHHHHHv",
      "HHHHHHHHHHHHHHHv",
      "HHHHHHHHHHHHHHHv",
      "HHHHHHHHHHHHHHHv",
      "HHHHHHHHHHHHHHHv",
      "HHHHHHHHHHHHHHHv",
      "HHHHHHHHHHHHHHHv",
      "HHHHHHHHHHHHHHHv",
      "HHHHHHHHHHHHHHHv",
      "HHHHHHHHHHHHHHHv"
    ],
    [
      "   aH  Hb    cdv",
      "efeaHghHb     dv",
      "ijiaHHHHb     dv",
      "   aHHHHb     dv",
      "efekHHHHk    kdv",
      "   aHHHHb     dv",
      "   allllb     dv",
      "   ammmmb     dv",
      "              dv",
      "              dv",
      "              dv",
      "ijik    kjijikdv",
      "   b    a     dv",
      "efeb    afefe dv",
      "ijib    ajiji dv",
      "   b    a n   dv"
    ],
    [
      "    H  H      dv",
      "    HooH      dv",
      "    HHHH      dv",
      "    llll      dv",
      "   kmmmmk    kdv",
      "              dv",
      "              dv",
      "              dv",
      "              dv",
      "              dv",
      "              dv",
      "   k    k    kdv",
      "              dv",
      "              dv",
      "              dv",
      "              dv"
    ],
    [
      "    llllc    cdv",
      "    mmmm      dv",
      "              dv",
      "              dv",
      "   k    k    kdv",
      "              dv",
      "              dv",
      "              dv",
      "              dv",
      "              dv",
      "              dv",
      "   k    k    kdv",
      "              dv",
      "              dv",
      "              dv",
      "              dv"
    ],
    [
      "   k    kc  ckdv",
      "   k    k   ckdv",
      "   k    k    kdv",
      "   k    k   ckdv",
      "pppk    kppppkdv",
      "   k    k    kdv",
      "   k    k    kdv",
      "   k    k    kdv",
      "   k    k    kdv",
      "   k    k    kdv",
      "   k    k    kdv",
      "pppkppppkppppkdv",
      "   k    k    kdv",
      "   k    k    kdv",
      "   k    k    kdv",
      "   k    k    kdv"
    ],
    [
      "dddq    qddddddv",
      "dddq    qddddddv",
      "dddq    qddddddv",
      "dddq    qddddddv",
      "dddk    kddddddv",
      "ddddrrrrdddddddv",
      "dddddddddddddddv",
      "dddddddddddddddv",
      "dddddddddddddddv",
      "dddddddddddddddv",
      "dddddddddddddddv",
      "dddddddddddddddv",
      "dddddddddddddddv",
      "dddddddddddddddv",
      "dddddddddddddddv",
      "dddddddddddddddv"
    ]
  ]
}