{
  "name": "multi_residential2_0_ground",
  "refpalette": "c70cities:multi_residential2_0_ground_palette",
  "xsize": 16,
  "zsize": 16,
  "slices": [
    [
      "GGGGGGGGGGGGGGGG",
      "GGGGGGGGGGGGGGGG",
      "GGGGGGGGGGGGGGGG",
      "GGGGGGGGGGGGGGGG",
      "GGaaaaaaaaaaaaGG",
      "GGabbbbbbbbbbaGG",
      "GGabbbbbbbbbbaGG",
      "GGabbbbbbbbbbaGG",
      "GGabbbbbbbbbbaGG",
      "GGabbbbbbbbbbaGG",
      "GGabbbbbbbbbbaGG",
      "GGGcddddddddcGGG",
      "GGGcddddddddcGGG",
      "GGGcddddddddcGGG",
      "GGGcddddddddcGGG",
      "GGGcddddddddcGGG"
    ],
    [
      "effffgffffgffffe",
      "f              f",
      "e              f",
      "               f",
      "  hijkllllkjim g",
      "  no   pq   rs f",
      "  nt  u      s f",
      "w j       xyxj f",
      "  A    BB C  s f",
      "  D   kkkkCEFs g",
      "  j    I !JJJj f",
      "  Kc  LMMNNOcK f",
      "  KcP  QQ  RcK f",
      "  KcS P    OcK g",
      "  KcTS     UcK f",
      "  KcVVVWXVVVcK f"
    ],
    [
      "effffgffffgffffe",
      "f              f",
      "e              f",
      "               f",
      "  lljkllllkjll g",
      "  lY        Zl f",
      "  l          l f",
      "  j       x0xj f",
      "  1    22 C  3 f",
      "  4   5555C  3 g",
      "  j     I6JJJj f",
      "   c        c  f",
      "   7        7  f",
      "   c        c  g",
      "   c8P     9c  f",
      "   cVVV@#VVVc  f"
    ],
    [
      "                ",
      "                ",
      "                ",
      "                ",
      "  lljkllllkjll  ",
      "  l          l  ",
      "  l          l  ",
      "  j       xxxj  ",
      "  n       C  3  ",
      "  n   5555C  3  ",
      "  j      IJJJj  ",
      "   c        c   ",
      "   7        7   ",
      "   c        c   ",
      " iic        cii ",
      " $%cVVVVVVVVc^$ "
    ],
    [
      "                ",
      "                ",
      "                ",
      " &&&&&&&&&&&&&& ",
      " *jjjjjjjjjjjj* ",
      "  jbbbbbbbbbbj  ",
      "  jbbbbbbbbbbj  ",
      "  jbbbbbbbbbbj  ",
      "  jbbbbbbbbbbj  ",
      "  jbbbbbbbbbbj  ",
      "  jbbbb   Ibbj  ",
      "   cbbbbbbbbc   ",
      "   cbbbbbbbbc   ",
      " iicbbbbbbbbcii ",
      " $$%bbbbbbbb^$$ ",
      "   (bbbbbbbb)   "
    ],
    [
      "                ",
      "                ",
      "                ",
      "                ",
      " &&&&&&&&&&&&&& ",
      " *jkkkkkkkkkkj* ",
      "  j+--[r]{}r\\j  ",
      "  j ||[  `   j  ",
      "  n ::       s  ",
      "  n    ;;;;  s  ",
      "  j;   '    ;j  ",
      "   ckk,k[[kkc   ",
      " iickk   ./kcii ",
      " $$$%/<   /^$$$ ",
      "    (/>< !/)    ",
      "    (/?  \u00a3/)    "
    ]
  ]
}