{
  "name": "multi_communitycenter_5_ground",
  "refpalette": "c70cities:multi_communitycenter_5_ground_palette",
  "xsize": 16,
  "zsize": 16,
  "slices": [
    [
      "aabcccbaaaaaaaab",
      "aaabbbbaaaGGaaab",
      "aaaaaaaaaGGGGaab",
      "aaaaaaaaaGGGGaad",
      "baaaaaaaaaGGaaad",
      "ebbaaaaaaaaaaaaa",
      "eeebbbaaaaaaaaaa",
      "eeeeebbbbbbbbbbf",
      "eeeeeagggggggggf",
      "eeeeeagggggggggf",
      "eeeeeagggggggggf",
      "aaeeeagggggggggf",
      "haaaaagggggggggf",
      "hhhhaaaaaaaaaaaf",
      "hhhhhhhhhhhhhhhh",
      "hhhhhhhhhhhhhhhh"
    ],
    [
      "  ijkjl        l",
      "   imnn   oo   n",
      "         oppo  n",
      "         oppo   ",
      "          oo    ",
      "               q",
      "   lnn          ",
      " r   nls sttssln",
      " r  rnuw  xx xxn",
      " r  rnyA       n",
      "    rnBB  xx xxn",
      "CC  Dn E       n",
      " CCCCn F  xx xxn",
      "    CCCCCCCCCCCC",
      "                ",
      "                "
    ],
    [
      "  i   l        l",
      "   imnn        n",
      "          II   n",
      "          II    ",
      "                ",
      "                ",
      "   lnn          ",
      " J   nls sttssln",
      " J  KnLL   L MNn",
      " J  Kn L       n",
      "    JnBB  O  PQn",
      "ss   nRS       n",
      " CCssnRF  TN QUn",
      "    sssCCsssCCss",
      "                ",
      "                "
    ],
    [
      "  i   l V    V l",
      "   imnn        n",
      "               n",
      "                ",
      "                ",
      "                ",
      "   lnn          ",
      " W  Dnls sttssln",
      " W  Wn         n",
      " W  Wn         n",
      "    WnBB       n",
      "ss   n F       n",
      " CCssn F       n",
      "    sssCCsssCCss",
      "                ",
      "                "
    ],
    [
      "  l   l XV  VX l",
      "   lmnn        n",
      "               n",
      "                ",
      "l               ",
      " ll             ",
      "   lnn          ",
      "    Dnllllllllln",
      "    Dn         n",
      "     n         n",
      "     n         n",
      "CC   n         n",
      " CCCCn         n",
      "    CCCCCCCCCCCC",
      "                ",
      "                "
    ],
    [
      "  nnYYnZXX VXXZn",
      "   nnnnZZZZZZZZn",
      "      nnnnnnnnnn",
      "      0        0",
      "n     0        0",
      "nnn   0        0",
      "YYnnnn0        0",
      "YYYYYnnnnnnnnnnn",
      "YYYYYnYYYYYYYYYn",
      "YYYYYnYYYYYYYYYn",
      "YYYYYnYYYYYYYYYn",
      "CCYYYnYYYYYYYYYn",
      " CCCCnYYYYYYYYYn",
      "    CCCCCCCCCCCC",
      "                ",
      "                "
    ]
  ]
}