{
  "name": "multi_laboratory1_11_ground",
  "refpalette": "c70cities:multi_laboratory1_11_ground_palette",
  "xsize": 16,
  "zsize": 16,
  "slices": [
    [
      "aaaabcccvdeeeezz",
      "aaaabcccveeeeeez",
      "aaaabcccvdezezze",
      "aaaabcccvddeezez",
      "aaaabcccvdedeeez",
      "aaaabcccddeeeezz",
      "aaaabcccvdeeeeee",
      "aaaabcccvddeeeez",
      "aaaabcccvdeeezez",
      "aaaabcccvveeeezz",
      "aaaabcccvvdezeez",
      "aaaabcccvdeeeeee",
      "baaabcccvveeeezz",
      "baaabcccvdeeeezz",
      "bbaabcccvddeeeze",
      "fbaabcccvedeeeez"
    ],
    [
      "  g h     ij kl ",
      "    h           ",
      " mmgh           ",
      "gmm h     ijk   ",
      " g  h          l",
      "    h           ",
      "  g b     iknk  ",
      "gmm h           ",
      " mmgh          l",
      "  g h     ijn   ",
      "    h       l  l",
      "    h           ",
      "o   h     ijpk  ",
      "o  qb         l ",
      "oo  h           ",
      " o  h     i nk  "
    ],
    [
      "    h           ",
      "    h           ",
      "  r h           ",
      "  s h           ",
      "    h           ",
      "    h           ",
      "    b           ",
      "    t           ",
      " u  h           ",
      "    h           ",
      "    h           ",
      "    h           ",
      "    t           ",
      "   wb           ",
      "    t           ",
      "    t           "
    ],
    [
      "    h           ",
      "    h           ",
      "    h           ",
      "    h           ",
      "    h           ",
      "    h           ",
      "    b           ",
      "    t           ",
      "    h           ",
      "    h           ",
      "    h           ",
      "    h           ",
      "    t           ",
      "   wb           ",
      "    t           ",
      "    t           "
    ],
    [
      "    h           ",
      "    h           ",
      "    h           ",
      "    h           ",
      "    h           ",
      "    h           ",
      "    b           ",
      "    t           ",
      "    h           ",
      "    h           ",
      "    h           ",
      "    h           ",
      "    t           ",
      "    b           ",
      "    t           ",
      "    t           "
    ],
    [
      "xxxxh           ",
      "xxxxh           ",
      "xxxxh           ",
      "xxxxh           ",
      "xxxxh           ",
      "xxxxh           ",
      "xxxxb           ",
      "xxxxh           ",
      " xxxh           ",
      "  xxh           ",
      "  xxh           ",
      "  xxh           ",
      "   xh           ",
      "   xb           ",
      "   xh           ",
      "   xh           "
    ]
  ]
}