{
  "name": "multi_derrick_0_base1",
  "refpalette": "c70cities:multi_derrick_0_base1_palette",
  "xsize": 16,
  "zsize": 16,
  "slices": [
    [
      "vvvvvvvvvvvvvvvv",
      "vzzzzzzzzzzzzzzz",
      "vzzzzzzzzzzzzzzz",
      "vzzzzzzzzzzzzzzz",
      "vzzzzzzzzzzzzzzz",
      "vzzzzzzzzzzzzzzz",
      "vzzzzzzzzzzzzzzz",
      "vzzzzzzzzzzzzzzz",
      "vzzzzzzzzzzzzzzz",
      "vzzzzzzzzzzzzzzz",
      "vzzzzzzzzzzzzzzz",
      "vzzzzzzzzzzzzzzz",
      "vzzzzzzzzzzzzzzz",
      "vzzzzzzzzzzzzzzz",
      "vzzzzzzzzzzzzzzz",
      "vvvvvvvvvvvvvvvv"
    ],
    [
      "vvvvvvvvvvvvvvvv",
      "vzzzzzzzzzzzzzzz",
      "vzzzzzzzzzzzzzzz",
      "vzzzzzzzzzzzzzzz",
      "vzzzzzzzzzzzzzzz",
      "vzzzzzzzzzzzzzzz",
      "vzzzzzzzzzzzzzzz",
      "vzzzzzzzzzzzzzzz",
      "vzzzzzzzzzzzzzzz",
      "vzzzzzzzzzzzzzzz",
      "vzzzzzzzzzzzzzzz",
      "vzzzzzzzzzzzzzzz",
      "vzzzzzzzzzzzzzzz",
      "vzzzzzzzzzzzzzzz",
      "vzzzzzzzzzzzzzzz",
      "vvvvvvvvvvvvvvvv"
    ],
    [
      "vvvvvvvvvvvvvvvv",
      "vzzzzzzzzzzzzzzz",
      "vzzzzzzzzzzzzzzz",
      "vzzzzzzzzzzzzzzz",
      "vzzzzzzzzzzzzzzz",
      "vzzzzzzzzzzzzzzz",
      "vzzzzzzzzzzzzzzz",
      "vzzzzzzzzzzzzzzz",
      "vzzzzzzzzzzzzzzz",
      "vzzzzzzzzzzzzzzz",
      "vzzzzzzzzzzzzzzz",
      "vzzzzzzzzzzzzzzz",
      "vzzzzzzzzzzzzzzz",
      "vzzzzzzzzzzzzzzz",
      "vzzzzzzzzzzzzzzz",
      "vvvvvvvvvvvvvvvv"
    ],
    [
      "vvvvvvvvvvvvvvvv",
      "vzzzzzzzzzzzzzzz",
      "vzzzzzzzzzzzzzzz",
      "vzzzzzzzzzzzzzzz",
      "vzzzzzzzzzzzzzzz",
      "vzzzzzzzzzzzzzzz",
      "vzzzzzzzzzzzzzzz",
      "vzzzzzzzzzzzzzzz",
      "vzzzzzzzzzzzzzzz",
      "vzzzzzzzzzzzzzzz",
      "vzzzzzzzzzzzzzzz",
      "vzzzzzzzzzzzzzzz",
      "vzzzzzzzzzzzzzzz",
      "vzzzzzzzzzzzzzzz",
      "vzzzzzzzzzzzzzzz",
      "vvvvvvvvvvvvvvvv"
    ],
    [
      "vvvvvvvvvvvvvvvv",
      "vzzzzzzzzzzzzzzz",
      "vzzzzzzzzzzzzzzz",
      "vzzzzzzzzzzzzzzz",
      "vzzzzzzzzzzzzzzz",
      "vzzzzzzzzzzzzzzz",
      "vzzzzzzzzzzzzzzz",
      "vzzzzzzzzzzzzzzz",
      "vzzzzzzzzzzzzzzz",
      "vzzzzzzzzzzzzzzz",
      "vzzzzzzzzzzzzzzz",
      "vzzzzzzzzzzzzzzz",
      "vzzzzzzzzzzzzzzz",
      "vzzzzzzzzzzzzzzz",
      "vzzzzzzzzzzzzzzz",
      "vvvvvvvvvvvvvvvv"
    ],
    [
      "vvvvvvvvvvvvvvvv",
      "vzzzzzzzzzzzzzzz",
      "vzzzzzzzzzzzzzzz",
      "vzzzzzzzzzzzzzzz",
      "vzzzzzzzzzzzzzzz",
      "vzzzzzzzzzzzzzzz",
      "vzzzz!zzzzzzzzzz",
      "vzzzzzzzzzzzazzz",
      "vzzzzzzzzzzzzzzz",
      "vzzzzzzzzzz!zzzz",
      "vzzzzzzzzzzzzzzz",
      "vzzzzzzzzzzzzzzz",
      "vzzzzzzzzzzzzzzz",
      "vzzzzzzzzzzzzzzz",
      "vzzzzzzzzzzzzzzz",
      "vvvvvvvvvvvvvvvv"
    ]
  ]
}