{
  "name": "multi_militarybase_1_ground",
  "refpalette": "c70cities:multi_militarybase_1_ground_palette",
  "xsize": 16,
  "zsize": 16,
  "slices": [
    [
      "abcccccccccccccc",
      "abcccccccccccccc",
      "deczczzcffffffff",
      "zezzzzccfggggfff",
      "zezzzzzzfggggfff",
      "zezczzzcfggggfff",
      "zeczzzzcf gggfff",
      "zezzczzcf gggggg",
      "zezzzzzcf gggggg",
      "zezzzzczfhgggggg",
      "zezzzzzcfggggggg",
      "zezzczzcffffffff",
      "zeczzzczcccczzcc",
      "zecczzzcczzzzczz",
      "zeeeeeeeeeeeeeee",
      "zzzzzzzzzzzzzzzz"
    ],
    [
      "i j  j   j   j  ",
      "i  j            ",
      " e      kkkkkk  ",
      " ell l  kmmmmk  ",
      " el   llkn o k  ",
      " e    l kp   k  ",
      " eq l   k r  kks",
      " e l  l k r  tu ",
      " e l    k r     ",
      " el     k r     ",
      " e    l kw   x y",
      " el  l  kkkkkkkk",
      " e              ",
      " eqAll  q l l  l",
      " eeeeeeeeeeeeeee",
      "                "
    ],
    [
      "                ",
      "                ",
      " e      BBCCBB  ",
      " e      BDE FB  ",
      " e      C    C  ",
      " e      C    B  ",
      " eq     B    BBI",
      " e      B    tF ",
      " e      C       ",
      " e      C       ",
      " e      B     x ",
      " e      BCCCCBBB",
      " e              ",
      " eq     q       ",
      " eeeeeeeeeeeeeee",
      "                "
    ],
    [
      "                ",
      "                ",
      " e      BBCCBB  ",
      " e     JB    B  ",
      " e     JB    C  ",
      " e     JB    B  ",
      " eq    JB    BBB",
      " e     JB    t  ",
      " e     JB       ",
      " e     JB       ",
      " e     JB      x",
      " e      BBBBBBBB",
      " e       JJJJ   ",
      " eq     q       ",
      " eeeeeeeeeeeeeee",
      "                "
    ],
    [
      "                ",
      "                ",
      " e      BBBBBB  ",
      " e      BK   B  ",
      " e      LK   B  ",
      " e      LK   B  ",
      " eq     BK   BBL",
      " e      BK   tKK",
      " e      LK      ",
      " e      LK      ",
      " e      BKKKKK  ",
      " e      BLLLLBBB",
      " e              ",
      " eq     q       ",
      " eeeeeeeeeeeeeee",
      "                "
    ],
    [
      "        kMMMMk  ",
      "        kMMMMk  ",
      " i      kNNNNk  ",
      " i      kNNNNk  ",
      " i      kNNNNk  ",
      " iO     kNNNNk  ",
      "PQO     kNNNNkkk",
      " RO     kNNNNtNN",
      " iO     kNNNNNNN",
      " iO     kNNNNNNN",
      " iO     kNNNNN  ",
      " iO     kkkkkkkk",
      " iO      S      ",
      " TUVVVVVVUVVVVVV",
      " TTWWWWWXWWWWWWW",
      "                "
    ]
  ]
}