{
  "name": "multi_laboratory1_13_base6",
  "refpalette": "c70cities:multi_laboratory1_13_base6_palette",
  "xsize": 16,
  "zsize": 16,
  "slices": [
    [
      "aaabcababaaaadev",
      "aaaaaabaaaaaadev",
      "ffbfgffffffffhdv",
      "aaaaaaaaaaaaaadv",
      "abbiaaaaaaaaaadv",
      "abaaaaaaaaaaaadv",
      "abaaaaaaaaaaaadv",
      "aaabaaaaaaaaaadv",
      "aaaaaafffffffadv",
      "a!aagafjjjjjfadv",
      "aaaaaafjjjjjfadv",
      "aaaaaafjjjjjfadv",
      "aaaaaafjjjjjfadv",
      "aaaaaafjjjjjfadv",
      "aaaaaafjjjjjfadv",
      "a!aaaafjjjjjfadv"
    ],
    [
      "  kl mbb    ndev",
      " o bbb    k  pev",
      "  qbgqqqqqqqqqgv",
      " rbms        tuv",
      "w nxs   y y  tuv",
      " lbcs  ABBBA Cuv",
      "  bbs         uv",
      "  m s  D   D  uv",
      "xcmrs         uv",
      "mEF g        Ijv",
      "bJ  s         uv",
      "bb  s         uv",
      " b  s  K   K  uv",
      "b  ys L       uv",
      "b Mrs   N     uv",
      "bEOMs         uv"
    ],
    [
      "     nn      dev",
      "  Pnl        pev",
      "  PmgQQQQQQQQQgv",
      "  bbR         uv",
      "   nR         uv",
      "   nR  STUT   uv",
      "    R         uv",
      "    R         uv",
      "nn  R         uv",
      "n   g         jv",
      "n   R         uv",
      "    R         uv",
      " n  R  KV WK  uv",
      "l   R         uv",
      "    R L       uv",
      "nX  Y         uv"
    ],
    [
      "             dev",
      "             pev",
      "   bgQQQQQQQQQgv",
      "   bR        Zuv",
      "    R         uv",
      "    R         uv",
      "    R         uv",
      "    R         uv",
      "    R         uv",
      "    g         jv",
      "    R         uv",
      "    R    0    uv",
      "    R  WKKKV  uv",
      "    R         uv",
      "    R         uv",
      "    R L       uv"
    ],
    [
      "             dev",
      "             pev",
      "   bgQQQQQQQQQgv",
      "   xR         uv",
      "    R         uv",
      "    R         uv",
      "    R         uv",
      "    R         uv",
      "    R         uv",
      "    g         jv",
      "    R    1    uv",
      "    R   121   uv",
      "    R   232   uv",
      "    R   444   uv",
      "    R   434   uv",
      "    R   454   uv"
    ],
    [
      "             dev",
      "   P         pev",
      " PbbgQQQQQQQQQgv",
      "   nR         uv",
      "    R         uv",
      "    R         uv",
      "    R         uv",
      "    R         uv",
      "    R    1    uv",
      "    g    2    jv",
      "    R   161   uv",
      "    R  72829  uv",
      "    R   323   uv",
      "    R   @4@   uv",
      "    R    3    uv",
      "    R  # 8 $  uv"
    ]
  ]
}