{
  "name": "multi_laboratory1_1_base6",
  "refpalette": "c70cities:multi_laboratory1_1_base6_palette",
  "xsize": 16,
  "zsize": 16,
  "slices": [
    [
      "zabccccccccccccc",
      "zabccccccccccccc",
      "zabccccccccccccc",
      "zabccccccccccccc",
      "zabccccccccccccc",
      "zabccccccccccccc",
      "zabccccccccdcccc",
      "zabccccccccccccc",
      "zabccccccccccccc",
      "zabccccccccccccc",
      "zabccccccccccccc",
      "zabccccccccccccc",
      "zabcccccccccccce",
      "zabccccccccdccce",
      "zabcccccccccccef",
      "zabccccccccccce "
    ],
    [
      "zag             ",
      "zab             ",
      "zabh            ",
      "zabh          i ",
      "zab             ",
      "zajjjj       kkk",
      "zablmj     d    ",
      "zajjjj     n    ",
      "zab        o    ",
      "zabh     p oq   ",
      "zabh       o    ",
      "zab        o    ",
      "zajjjj         r",
      "zablmj     d   r",
      "zajjjj     s  rf",
      "zab        o  r "
    ],
    [
      "zag             ",
      "zab             ",
      "zabtu           ",
      "zabwu           ",
      "zabx            ",
      "zajjr        yA ",
      "zablmr     d    ",
      "zajjr           ",
      "zabB       C    ",
      "zabwu      D    ",
      "zabtu      s    ",
      "zabx       E    ",
      "zajjr          r",
      "zablmr     d   r",
      "zajjr      y  rf",
      "zabB       C  r "
    ],
    [
      "zag             ",
      "zab             ",
      "zab             ",
      "zab             ",
      "zab             ",
      "zajjr        F  ",
      "zablmr     d    ",
      "zajjr           ",
      "zab             ",
      "zab             ",
      "zab             ",
      "zab             ",
      "zajjr          r",
      "zablmr     d   r",
      "zajjr      I  rf",
      "zab           r "
    ],
    [
      "zag             ",
      "zab             ",
      "zabJ            ",
      "zabJ            ",
      "zab             ",
      "zajjr           ",
      "zablmr     d    ",
      "zajjr           ",
      "zab             ",
      "zabJ            ",
      "zabJ            ",
      "zab             ",
      "zajjr          r",
      "zablmr     d   r",
      "zajjr         rf",
      "zab           r "
    ],
    [
      "zag             ",
      "zab             ",
      "zabg            ",
      "zab             ",
      "zab             ",
      "zajjr           ",
      "zablmr     d    ",
      "zajjr           ",
      "zab             ",
      "zabg            ",
      "zab             ",
      "zab             ",
      "zajjr          r",
      "zablmr     d   r",
      "zajjr         rf",
      "zab           r "
    ]
  ]
}