{
  "name": "multi_megatower1_4_floor8",
  "refpalette": "c70cities:multi_megatower1_4_floor8_palette",
  "xsize": 16,
  "zsize": 16,
  "slices": [
    [
      "a   b===========",
      "a   b===========",
      "a   b===========",
      "cdeeb===========",
      "bbbbf======f====",
      "bbbbg===========",
      "bbbbg===========",
      "hhhhi===========",
      "jjjjj===========",
      "jjjjj===========",
      "jjjjj===========",
      "jjjjf======f====",
      "jjjjj===========",
      "jjjjj===========",
      "jjjjj========kkk",
      "jjjjj========kkk"
    ],
    [
      "a   alzmnzlzzzln",
      "a   aooooooooooo",
      "a   ap          ",
      "aeqqap          ",
      "rstufwwrrwwf   x",
      "     p  pjj     ",
      "        jjy     ",
      "      pjjjAB    ",
      "     jjjjjA     ",
      "     jjjjjyA    ",
      "  C CjjjjjyB    ",
      "C   fjjjjjjf    ",
      "    jjjjjjD B   ",
      "    jjjjjjjEE  F",
      "I   jjjjjjJKL   ",
      "  M jjjjjjjJB N "
    ],
    [
      "a   aO   PpP Pp ",
      "a   aQ Q Q Q Q Q",
      "a   ap          ",
      "ae  a           ",
      "r RSfwwrrwwf x x",
      "         pjj    ",
      "        pjj     ",
      "       jjj      ",
      "      CjjjA     ",
      "     C jjjy     ",
      "      Cjjjj     ",
      "    f  jjjjf    ",
      "     C jjjjT   T",
      "      MjjjjL    ",
      "~   MCjjjjJ T   ",
      "    CUjjjjjE    "
    ],
    [
      "a   ap          ",
      "a   a           ",
      "a   a           ",
      "aeeea           ",
      "rV  fwwwwwwfxx x",
      "          pj    ",
      "         jj     ",
      "       C jj     ",
      "         jj     ",
      "         jj     ",
      "       C jj     ",
      "    f  C jjf    ",
      "         jjjT  W",
      "         jjT  T ",
      "         jj W   ",
      "        Ijj  T T"
    ],
    [
      "a   a           ",
      "a   a           ",
      "a   ap          ",
      "aeeeap          ",
      "rrrrfwwwwwwfxxxx",
      "           j    ",
      "         Cpj    ",
      "         X j    ",
      "           jj   ",
      "         CMjj   ",
      "          Cjj   ",
      "    f     Yfj   ",
      "          YjjjTW",
      "         CMjj W ",
      "           jjT T",
      "        ~ XjjWZW"
    ],
    [
      "0   011111101111",
      "0   011111101111",
      "0   011111101111",
      "0eee011111101111",
      "2222f222222f2222",
      "            j  j",
      "            j  j",
      "            jj j",
      "             jjj",
      "            Cjjj",
      "           M jjj",
      "    f      fUjjj",
      "           Y jjj",
      "            Mjjj",
      "            Xjjj",
      "           M jJj"
    ]
  ]
}