{
  "name": "multi_carservice_0_base1",
  "refpalette": "c70cities:multi_carservice_0_base1_palette",
  "xsize": 16,
  "zsize": 16,
  "slices": [
    [
      "vvvvvvvvvvvvvvvv",
      "vaaaaaaaaaaaaaav",
      "vaaaaaaaaaaaaaav",
      "vaaaaaaaaaaaaaav",
      "vaaaaaaaaaaaaaav",
      "vaaaaaaaaaaaaaav",
      "vvvvvvvvvvvvvvvv",
      "vbbbbbbbbbbbbbbv",
      "vbbbbbbbbbbbbbbv",
      "vbbbbbbbbbbbbbbv",
      "vbbbbbbbbbbbbbbv",
      "vbbbbbbbbbbb===v",
      "vbbbbbbbbbbb===v",
      "vbbbbbbbbbbb===v",
      "vbbbbbbbbbbb===v",
      "vbbbbbbbbbbb===v"
    ],
    [
      "vvvvvvvvvvvvvvvv",
      "vaaaaaaaaaaaaaav",
      "vaaaaaaaaaaaaaav",
      "vaaaaaaaaaaaaaav",
      "vaaaaaaaaaaaaaav",
      "vaaaaaaaaaaaaaav",
      "vccccccccccccccv",
      "v             dv",
      "v             dv",
      "v!efggh       iv",
      "vcccccccjjjccccv",
      "vc     k   cl lv",
      "vc mno k   p  qv",
      "vc mnrsk   p   v",
      "vc t t k   p   v",
      "vc tnt k   c   v"
    ],
    [
      "vvvvvvvvvvvvvvvv",
      "vaaaaaaaaaaaaaav",
      "vaaaaaaaaaaaaaav",
      "vaaaaaaaaaaaaaav",
      "vaaaaaaaaaaaaaav",
      "vaaaaaaaaaaaaaav",
      "vccccccccccccccv",
      "v             uv",
      "v             wv",
      "v x    y   y  Av",
      "vcccccccjjjccccv",
      "vc     k   c   v",
      "vc BCD k   p   v",
      "vc EFE k   p   v",
      "vc E E k   p   v",
      "vc IJI k   c   v"
    ],
    [
      "vvvvvvvvvvvvvvvv",
      "vaaaaaaaaaaaaaav",
      "vaaaaaaaaaaaaaav",
      "vaaaaaaaaaaaaaav",
      "vaaaaaaaaaaaaaav",
      "vaaaaaaaaaaaaaav",
      "vccccccccccccccv",
      "v              v",
      "v              v",
      "v   K L        v",
      "vcccccccjjjccccv",
      "vc     k   c   v",
      "vc     k   p   v",
      "vc     k   p   v",
      "vc     k   p   v",
      "vc     k   c   v"
    ],
    [
      "vvvvvvvvvvvvvvvv",
      "vaaaaaaaaaaaaaav",
      "vaaaaaaaaaaaaaav",
      "vaaaaaaaaaaaaaav",
      "vaaaaaaaaaaaaaav",
      "vaaaaaaaaaaaaaav",
      "vccccccccccccccv",
      "v             Mv",
      "v             Mv",
      "v  NNNN       Mv",
      "vcccccccOOOccccv",
      "vc     =c=cc   v",
      "vc     =c=cc   v",
      "vc     =c=cc   v",
      "vc     =c=cc   v",
      "vc     =c=cc   v"
    ],
    [
      "vvvvvvvvvvvvvvvv",
      "vaaaaaaaaaaaaaav",
      "vaaaaaaaaaaaaaav",
      "vaaaaaaaaaaaaaav",
      "vaaaaaaaaaaaaaav",
      "vaaaaaaaaaaaaaav",
      "vccccccccccccccv",
      "vPPPPPPQPPPQPPPv",
      "vPPPPPPRPPPRPPPv",
      "vRRRRRRRRRRRRRRv",
      "vccccccccccccccv",
      "vcSSSSSSSSScPPPv",
      "vcSTTTSSSSScPPPv",
      "vcSTTTSSSSScPPPv",
      "vcSSSSSSSSScPPPv",
      "vcSSSSSSSSScPPPv"
    ]
  ]
}