{
  "name": "multi_megatower1_1_floor6",
  "refpalette": "c70cities:multi_megatower1_1_floor6_palette",
  "xsize": 16,
  "zsize": 16,
  "slices": [
    [
      "            ab  ",
      "            ab  ",
      "           cabde",
      "            abff",
      "           ghibb",
      "            abbb",
      "           jabbb",
      "            abbb",
      "            abbb",
      "           cabbb",
      "            abbb",
      "           ghibb",
      "            abbb",
      "           jabbb",
      "            abbb",
      "            abbb"
    ],
    [
      "             k  ",
      "             kd ",
      "           c kl ",
      "             k  ",
      "           ghicm",
      "             n  ",
      "           j n  ",
      "             n  ",
      "             no ",
      "           c np ",
      "             no ",
      "           ghiq ",
      "             no ",
      "           j np ",
      "             no ",
      "             n  "
    ],
    [
      "             kf ",
      "             kl ",
      "           c k  ",
      "             k  ",
      "           ghicr",
      "             n  ",
      "           j n  ",
      "             n  ",
      "             n  ",
      "           c n  ",
      "             n  ",
      "           ghis ",
      "             n  ",
      "           j n  ",
      "             n  ",
      "             n  "
    ],
    [
      "             klt",
      "             k  ",
      "           c k  ",
      "            ck u",
      "           ghicc",
      "             n  ",
      "           j n  ",
      "            jn  ",
      "            cn  ",
      "           c n  ",
      "             n  ",
      "           ghis ",
      "            jn  ",
      "           j n  ",
      "             n  ",
      "             n  "
    ],
    [
      "             w e",
      "             w t",
      "           c w  ",
      "            cw  ",
      "           ghicc",
      "             x  ",
      "           j y  ",
      "            jx  ",
      "            cy  ",
      "           c x  ",
      "             y  ",
      "           ghi  ",
      "            jx  ",
      "           j y  ",
      "             x  ",
      "             y  "
    ],
    [
      "            jA  ",
      "            cA e",
      "           c A f",
      "            cAdf",
      "           ghiBB",
      "            jACC",
      "           j ACD",
      "            jACC",
      "            cACC",
      "           c ACD",
      "            cACC",
      "           ghiBB",
      "            jA  ",
      "           j A  ",
      "            jA  ",
      "            cA  "
    ]
  ]
}