{
  "name": "multi_carservice_1_base1",
  "refpalette": "c70cities:multi_carservice_1_base1_palette",
  "xsize": 16,
  "zsize": 16,
  "slices": [
    [
      "vaaaaaaaaaaaaaav",
      "vaaaaaaaaaaaaaav",
      "vaaaaaaaaaaaaaav",
      "vaaaaaaaaaaaaaav",
      "vaaaaaaaaaaaaaav",
      "vaaaaaaaaaaaaaav",
      "vaaaaaaaaaaaaaav",
      "vaaaaaaaaaaaaaav",
      "vaaaaaaaaaaaaaav",
      "vaaaaaaaaaaaaaav",
      "vaaaaaaaaaaaaaav",
      "vaaaaaaaaaaaaaav",
      "vaaaaaaaaaaaaaav",
      "vaaaaaaaaaaaaaav",
      "vaaaaaaaaaaaaaav",
      "vvvvvvvvvvvvvvvv"
    ],
    [
      "vbcdedfg  hbiiiv",
      "vb jej g  hb===v",
      "vb     g  hb===v",
      "vbgggggg   b===v",
      "vbk       hb===v",
      "vbgggggg  hb===v",
      "vb lml g  hb===v",
      "vb n=n g   bbbbv",
      "vbodndpg   qrrqv",
      "vb nnn g       v",
      "vb nsn g    tt v",
      "vbodndpg    tt v",
      "vb unw g       v",
      "vb     g   qxxqv",
      "vbbbbbbbb=bbbbbv",
      "vvvvvvvvvvvvvvvv"
    ],
    [
      "vb     g  hb   v",
      "vb     g  yb   v",
      "vb     g  hbiiiv",
      "vbgggggg   b===v",
      "vbA       hb===v",
      "vbgggggg  yb===v",
      "vb     g  hb===v",
      "vb BCB g   bbbbv",
      "vb BDB g   E  !v",
      "vb FFF g       v",
      "vb F F g       v",
      "vb IFI g       v",
      "vb JKJ g       v",
      "vb     g   E  Ev",
      "vbbbbbbbb=bbbbbv",
      "vvvvvvvvvvvvvvvv"
    ],
    [
      "vb     g  hb   v",
      "vb     g  hb   v",
      "vb     g  hb   v",
      "vbgggggg   b   v",
      "vb        h=iiiv",
      "vbgggggg  h=iiiv",
      "vb     g  h=iiiv",
      "vb     g   bbbbv",
      "vb     g       v",
      "vb BCB g       v",
      "vb BDB g       v",
      "vb  C  g       v",
      "vb DDD g       v",
      "vb     g       v",
      "vbbbbbbbb=bbbbbv",
      "vvvvvvvvvvvvvvvv"
    ],
    [
      "vb     =b=bb   v",
      "vb     =b=bb   v",
      "vb     =b=bb   v",
      "vb======b=bb   v",
      "vb      b=i    v",
      "vb======b=i    v",
      "vb     =b=i    v",
      "vb     =b=bbbbbv",
      "vb     =b=bbbbbv",
      "vb     =b=bbbbbv",
      "vb     =b=bbbbbv",
      "vb     =b=bbbbbv",
      "vb     =b=bbbbbv",
      "vb     =b=bbbbbv",
      "vbbbbbbbb=bbbbbv",
      "vvvvvvvvvvvvvvvv"
    ],
    [
      "vbLMMMLLLLLbNNNv",
      "vbLMMMLLLLLbNNNv",
      "vbLLLLLLLLLbNNNv",
      "vbLLLLLLbbbb   v",
      "vbLLLLL=i      v",
      "vbLLLLL=i      v",
      "vbLLLLL=i      v",
      "vbLOOOLLbbbbbbbv",
      "vbLOOOLLLLLLLLLv",
      "vbLLLLLLLLLLLLLv",
      "vbLLLLLLLLLLLLLv",
      "vbLOOOLLLLLLLLLv",
      "vbLOOOLLLLLLLLLv",
      "vbLLLLLLLLLLLLLv",
      "vbbbbbbbbbbbbbbv",
      "vvvvvvvvvvvvvvvv"
    ]
  ]
}