{
  "name": "multi_megatower1_4_floor2",
  "refpalette": "c70cities:multi_megatower1_4_floor2_palette",
  "xsize": 16,
  "zsize": 16,
  "slices": [
    [
      "a   bbbbbbbbbbbb",
      "a   bbbbbbbbbbbb",
      "a   bbbbbbbbbbbb",
      "cdeebbbbbbbbbbbb",
      "bbbbfbbbbbbfbbbb",
      "bbbbbbbbbbbbbbbb",
      "bbbbbbbbbbbbbbbb",
      "bbbbbbbbbbbbbbbb",
      "bbbbbbbbbbbbbbbb",
      "bbbbbbbbbbbbbbbb",
      "bbbbbbbbbbbbbbbb",
      "bbbbfbbbbbbfbbbb",
      "bbbbbbbbbbbbbbbb",
      "bbbbbbbbbbbbbbbb",
      "bbbbbbbbbbbbbbbb",
      "bbbbbbbbbbbbbbbb"
    ],
    [
      "a   ag hih jkkl ",
      "a   am hih jk ll",
      "a   am hih j    ",
      "aenna  ooopj    ",
      "qrstf    ppf    ",
      "    u   pppj    ",
      "    ww xywwA    ",
      "           B    ",
      "           C    ",
      "    DDDEFDDA    ",
      "    uI    Jj    ",
      "EKDDfI    Jf    ",
      "   Lu      j    ",
      "   Lu M  N j    ",
      "   LuO OO Oj   P",
      "   Qu R  R j SSS"
    ],
    [
      "a   am mmm j  TU",
      "a   am gmm j  TT",
      "a   a  mmm j    ",
      "ae  a  ooo j    ",
      "q VWf     pf    ",
      "    uX   ppj    ",
      "    ww YZwwA    ",
      "           0    ",
      "           1    ",
      "    DDD23DDA    ",
      "    uI    Jj    ",
      "24DDf      f    ",
      "    u      j    ",
      "   iu 5  5 j    ",
      "    uRRRRRRj    ",
      "    uRRRR Rj    "
    ],
    [
      "a   am  m  6   U",
      "a   a  mmm 6    ",
      "a   a   m  6    ",
      "aeeea  ooo 6    ",
      "q7  f      f8888",
      "    u     p9@888",
      "    wwwwwwwA8888",
      "           A8888",
      "           A8888",
      "    DDDDDDDA8888",
      "    u      9@888",
      "DDDDf      f8888",
      "   #u      68888",
      "    u      68888",
      "    uRRRRRR68888",
      "    uRRRR R68888"
    ],
    [
      "a   a      j   S",
      "a   a      j    ",
      "a   a      j    ",
      "aeeea      j    ",
      "qqqqf$@$$@$f%%%%",
      "    ^$$$$$$&%***",
      "    wwwwwwwA(***",
      "           A%***",
      "           A%***",
      "    DDDDDDDA(***",
      "    ^$$$$$$&%***",
      "DDDDf$@$$@$f%***",
      "    u      j%***",
      "    u      j(***",
      "    uRRRRRRj%***",
      "    uRRRR Rj%***"
    ],
    [
      ")   )      )%%%%",
      ")   )      )%%%%",
      ")   )      )%%%%",
      ")e++)------)%%%%",
      "[[[[f[[[[[[f%%%%",
      "    )]]]]]])%***",
      "    ) ]  ] )%***",
      "    ) ]  ] )%***",
      "    ) ]  ] )%***",
      "    ) ]  ] )%***",
      "]]{])]]]]]])%***",
      "[[[[f[[[[[[f%***",
      "}}}})}}}}}})%***",
      "    )      )%***",
      "    )RRRRRR)%***",
      "    )RRRRRR)%***"
    ]
  ]
}