{
  "name": "multi_militarybase_0_base1",
  "refpalette": "c70cities:multi_militarybase_0_base1_palette",
  "xsize": 16,
  "zsize": 16,
  "slices": [
    [
      "vvvvvvvvvvvvvvvv",
      "vaaaavaaaaaaavaa",
      "vaaaabaaaaaaabaa",
      "vaaaabaaaaaaabaa",
      "vaaaabaaaaaaabaa",
      "vvbbbvbbbbbbbvbb",
      "vaaaabaaaaaaabaa",
      "vaaaabaaaaaaabaa",
      "vaaaabaaaaaaabaa",
      "vaaaabaaaaaacvdd",
      "vaaaabaaaaaeebee",
      "vaaaabaaaaeeebee",
      "vaaaabaaaaeeebee",
      "vvbbbvbbbbbbbvbb",
      "vaaaaaaaaaeeeb  ",
      "vaaaaaaaaaeeeb  "
    ],
    [
      "vvvvvvvvvvvvvvvv",
      "vffggvh h h hvii",
      "vfggjkl l l lkmn",
      "vfg  o       km ",
      "vgpqgk       kmn",
      "vvkkkvrrrsrrrvtt",
      "v! u w       kmn",
      "vxxy w       kmA",
      "vB  Cw   D   kmn",
      "vxx  w   E  cvtt",
      "vF   w          ",
      "vxx  w   I      ",
      "vJ K w          ",
      "vvk  v       vLL",
      "vM           L  ",
      "vM           L  "
    ],
    [
      "vvvvvvvvvvvvvvvv",
      "vggppv       vii",
      "vppq k       kNA",
      "vO   P       kQ ",
      "vpj  k       km!",
      "vvkkkvrrrRrrrvtt",
      "v    w       kQn",
      "vS   w       kmT",
      "v    w   D   kmn",
      "vS   w   E   vtt",
      "vU   w   I      ",
      "vSC  w          ",
      "v    w          ",
      "vvk  v       v  ",
      "vM              ",
      "vM              "
    ],
    [
      "vvvvvvvvvvvvvvvv",
      "vppjjv       vii",
      "vpj  k       k  ",
      "v    k       k  ",
      "vj   k       kQ ",
      "vvkkkvrrrrrrrvtt",
      "v    w       k  ",
      "v    w       kN ",
      "v    w   D   kQA",
      "v    w   I  Vvtt",
      "v    w          ",
      "v    w          ",
      "v    w          ",
      "vvk  v       v  ",
      "vM              ",
      "vM              "
    ],
    [
      "vvvvvvvvvvvvvvvv",
      "vj  jv       vii",
      "v    k       k  ",
      "v    k       k  ",
      "vj   k       k  ",
      "vvkkkvLLLLLLLvtt",
      "v    L       k  ",
      "v    L       k  ",
      "v    L   I   k  ",
      "v    L       vtt",
      "v    L          ",
      "v    L          ",
      "v    L          ",
      "vvkkkv       vww",
      "v            w  ",
      "v            w  "
    ],
    [
      "vvvvvvvvvvvvvvvv",
      "vWWWWvWWWWWWWvWW",
      "vWXXXbXXXXXXXbXX",
      "vWXXXbXXXXXXXbXX",
      "vWXXXbXXXXXXXbXX",
      "vvbbbvbbbbbbbvbb",
      "vWXXXbXXX XXXbXX",
      "vWXXXbXXXIXXXbXX",
      "vWXXXbXXX XXXbXX",
      "vWXXXbXXX XXXvXX",
      "vWXXXbXXX XXXbXX",
      "vWXXXbXXXXXXXbXX",
      "vWXXXbXXXXXXXbXX",
      "vvbbbvbbbbbbbvbb",
      "vWXXXXXXXXXXXbYY",
      "vWXXXXXXXXXXXbYY"
    ]
  ]
}