{
  "name": "multi_megatower1_1_floor4",
  "refpalette": "c70cities:multi_megatower1_1_floor4_palette",
  "xsize": 16,
  "zsize": 16,
  "slices": [
    [
      "            ab  ",
      "            cb  ",
      "            cbde",
      "            cbff",
      "           ghibb",
      "            abbb",
      "            abjj",
      "            abjj",
      "            cbjj",
      "            cbjj",
      "            cbbb",
      "           ghibb",
      "            abbb",
      "            abbb",
      "            abbb",
      "            cbbb"
    ],
    [
      "            ak  ",
      "            ckd ",
      "            ckl ",
      "            ck  ",
      "           ghicm",
      "            an  ",
      "            an  ",
      "            an  ",
      "            cn  ",
      "            cnoo",
      "            cnpq",
      "           ghip ",
      "            anr ",
      "            anss",
      "            ant ",
      "            cnuw"
    ],
    [
      "            akf ",
      "            ckl ",
      "            ck  ",
      "            ck  ",
      "           ghicx",
      "            an  ",
      "            an  ",
      "            ay  ",
      "            cy  ",
      "            cnoo",
      "            cnp ",
      "           ghip ",
      "            an  ",
      "            anss",
      "            anA ",
      "            cn  "
    ],
    [
      "            aklB",
      "            ck  ",
      "            ck  ",
      "            ck C",
      "           ghicc",
      "            an  ",
      "            an  ",
      "            aD  ",
      "            cD  ",
      "            cnoo",
      "            cnpE",
      "           ghip ",
      "            an  ",
      "            anss",
      "            an  ",
      "            cn  "
    ],
    [
      "            aF e",
      "            cF B",
      "            cF  ",
      "            cF  ",
      "           ghicc",
      "            an  ",
      "            an  ",
      "            an  ",
      "            cn  ",
      "            cnoo",
      "            cnpI",
      "           ghip ",
      "            anJ ",
      "            anss",
      "            anJ ",
      "            cn  "
    ],
    [
      "            aK  ",
      "            cK e",
      "            cK f",
      "            cKdf",
      "           ghiLL",
      "            aKMM",
      "            aKMM",
      "            aKMM",
      "            cKMM",
      "            cKNN",
      "            cKbb",
      "           ghiLL",
      "            aKbb",
      "            aKbb",
      "            aKJJ",
      "            cK  "
    ]
  ]
}