{
  "name": "multi_megatower1_5_floor2",
  "refpalette": "c70cities:multi_megatower1_5_floor2_palette",
  "xsize": 16,
  "zsize": 16,
  "slices": [
    [
      "aaaaaaaaaaaaaaaa",
      "aaaaaaaaaaaaaaaa",
      "aaaabaaaaaabaaaa",
      "cdddecccdddecccd",
      "    f      f    ",
      "                ",
      "                ",
      "                ",
      "                ",
      "                ",
      "                ",
      "                ",
      "                ",
      "                ",
      "                ",
      "                "
    ],
    [
      "gghhijkjjkjl k k",
      "mhhhi kkkkkkkn n",
      "oooobooooooboooo",
      "cdddecccdddecccd",
      "    f      f    ",
      "                ",
      "                ",
      "                ",
      "                ",
      "                ",
      "                ",
      "                ",
      "                ",
      "                ",
      "                ",
      "                "
    ],
    [
      "   hippppppl    ",
      "g hhi      l q q",
      "oooobooooooboooo",
      "cdddecccdddecccd",
      "    f      f    ",
      "                ",
      "                ",
      "                ",
      "                ",
      "                ",
      "                ",
      "                ",
      "                ",
      "                ",
      "                ",
      "                "
    ],
    [
      "    ipppppprssss",
      "   hi      rtttt",
      "oooobooooooboooo",
      "cdddecccdddecccd",
      "    f      f    ",
      "                ",
      "                ",
      "                ",
      "                ",
      "                ",
      "                ",
      "                ",
      "                ",
      "                ",
      "                ",
      "                "
    ],
    [
      "    ippppppluwww",
      "    i      ltttt",
      "rrrrbrrrrrrbxxxx",
      "cdddecccdddecccd",
      "    f      f    ",
      "                ",
      "                ",
      "                ",
      "                ",
      "                ",
      "                ",
      "                ",
      "                ",
      "                ",
      "                ",
      "                "
    ],
    [
      "    yppppppytwww",
      "AABAyABAAAAytttt",
      "CCCCbCCCCCCb    ",
      "cdddecccdddecccd",
      "    f      f    ",
      "                ",
      "                ",
      "                ",
      "                ",
      "                ",
      "                ",
      "                ",
      "                ",
      "                ",
      "                ",
      "                "
    ]
  ]
}