{
  "name": "multi_laboratory1_2_base3",
  "refpalette": "c70cities:multi_laboratory1_2_base3_palette",
  "xsize": 16,
  "zsize": 16,
  "slices": [
    [
      "zabcccccccccccd ",
      "zabcccccccccccd ",
      "zabcccccccccccd ",
      "zabcccccccccccde",
      "zabccccccccfcccd",
      "zabccccccccccccd",
      "zabccccccccccccc",
      "zabccccccccccccc",
      "zabccccccccccccc",
      "zabccccccccccccc",
      "zabccccccccccccc",
      "zabccccccccfcccc",
      "zabccccccccccccc",
      "zabccccccccccccc",
      "zab!cccccccccccc",
      "zabccccccccccccc"
    ],
    [
      "zab ghhhhi j  k ",
      "zab  lg m no  k ",
      "zabpiq     r  k ",
      "zabs       t  ke",
      "zab uwwwwx f  ek",
      "zab uyAABx t  Ck",
      "zab uyAABx t    ",
      "zab uyAABx t    ",
      "zab uyDABx t    ",
      "zab !yAEBx t   F",
      "zab uIIIIx t  J ",
      "zabttttttttfe   ",
      "zab     K  t    ",
      "zabLMi i   r    ",
      "zabNNO  n  P    ",
      "zabMQ   l  R    "
    ],
    [
      "zab  STTU  V  k ",
      "zab        W  k ",
      "zab        r  k ",
      "zab        t  ke",
      "zab XwwwwY f  Zk",
      "zab X0  1Y t   k",
      "zab X2  3Y 4    ",
      "zab X0  1Y 4    ",
      "zab X2  3Y 4    ",
      "zab X0E51Y 4    ",
      "zab XIIIIY t    ",
      "zabttttttttfZ   ",
      "zab        t    ",
      "zab        r    ",
      "zab6       7    ",
      "zab8       9    "
    ],
    [
      "zab        r  k ",
      "zab        r  k ",
      "zab        r  k ",
      "zab        t  ke",
      "zab XwwwwY f  Zk",
      "zab X0  1Y t   k",
      "zab X0  1Y 4    ",
      "zab X0 @1Y 4    ",
      "zab X05 1Y 4    ",
      "zab X0  1Y 4    ",
      "zab XIIIIY t    ",
      "zabttttttttfZ   ",
      "zab        t    ",
      "zab        r    ",
      "zab        r    ",
      "zab        r    "
    ],
    [
      "zab        t  k ",
      "zab        t  k ",
      "zab        t  k ",
      "zab        t  ke",
      "zab  #$$%  f   k",
      "zab  #$$%  t   k",
      "zab  #$$%  t    ",
      "zab  #$$%  t    ",
      "zab  #$$%  t    ",
      "zab  #$$%  t    ",
      "zab  #$$%  t    ",
      "zabttttttttf    ",
      "zab        t    ",
      "zab        t    ",
      "zab        t    ",
      "zab        t    "
    ],
    [
      "zab^^&^^*^^())k ",
      "zab^^*^^&^^())k ",
      "zab^^&^^&^^())k ",
      "zab^^^^^^^^())ke",
      "zab^^^^^^^^f)))k",
      "zab^^&^^&^^()))k",
      "zab^^&^^&^^())))",
      "zab^^&^^&^^())))",
      "zab^^&^^&^^())))",
      "zab^^^^^^^^())))",
      "zab^^^^^^^^())))",
      "zabttttttttf))))",
      "zab^^^^^^^^())))",
      "zab^^^^^^^^()&))",
      "zab^^*^^&^^()&))",
      "zab^^&^^*^^()&))"
    ]
  ]
}