{
  "name": "multi_megatower1_3_floor5",
  "refpalette": "c70cities:multi_megatower1_3_floor5_palette",
  "xsize": 16,
  "zsize": 16,
  "slices": [
    [
      "                ",
      "                ",
      "                ",
      "                ",
      "                ",
      "                ",
      "                ",
      "                ",
      "                ",
      "                ",
      "                ",
      "  a b c  a b c  ",
      "ca adc ca adc ca",
      "eeeefeeeeeefeeee",
      "ghhheeeeeeeeeeee",
      "g   eeeeeeeeeeee"
    ],
    [
      "                ",
      "                ",
      "                ",
      "                ",
      "                ",
      "                ",
      "                ",
      "                ",
      "                ",
      "                ",
      "                ",
      "    b      b    ",
      "ca adc ca adc ca",
      "ijklfmmmmmmfnnnn",
      "ghhhopqrrsptu  w",
      "g   o      tu   "
    ],
    [
      "                ",
      "                ",
      "                ",
      "                ",
      "                ",
      "                ",
      "                ",
      "                ",
      "                ",
      "                ",
      "                ",
      "    b      b    ",
      "ca adc ca adc ca",
      "i   fmmmmmmfnxxx",
      "ghhhoy    ytu   ",
      "g   o      t!   "
    ],
    [
      "                ",
      "                ",
      "                ",
      "                ",
      "                ",
      "                ",
      "                ",
      "                ",
      "                ",
      "                ",
      "                ",
      "    b      b    ",
      "ca adc ca adc ca",
      "i   fmmmmmmfnAAA",
      "ghhhoy    yt    ",
      "g   o      t    "
    ],
    [
      "                ",
      "                ",
      "                ",
      "                ",
      "                ",
      "                ",
      "                ",
      "                ",
      "                ",
      "                ",
      "                ",
      "    b      b    ",
      "ca adc ca adc ca",
      "i   fBCBCBCfnnnn",
      "ghhho      tDDDD",
      "g   o      tDEDD"
    ],
    [
      "                ",
      "                ",
      "                ",
      "                ",
      "                ",
      "                ",
      "                ",
      "                ",
      "                ",
      "                ",
      "                ",
      "    b      b    ",
      "caaadcccaaadccca",
      "FFFFfFFFFFFfFFFF",
      "IJJJIDDDDDDI K K",
      "I   IDEDDEDI L K"
    ]
  ]
}