{
  "name": "multi_flatapartment_1_floor1",
  "refpalette": "c70cities:multi_flatapartment_1_floor1_palette",
  "xsize": 16,
  "zsize": 16,
  "slices": [
    [
      "                ",
      "aaabaaabaaaabaaa",
      "cccccccccccccccc",
      "dddddddddddddddd",
      "dddddddddddddddd",
      "dddddddccccccddd",
      "dddddddc  edcddd",
      "dddddddc   dcddd",
      "dddddddc   dcddd",
      "dddddddcddddcddd",
      "dddddddccccccddd",
      "dddddddcddddcddd",
      "dddddddcddddcddd",
      "cccccccccccccccc",
      "aaabaaabaaaabaaa",
      "                "
    ],
    [
      "                ",
      "ffabafabaggabafa",
      "      hijk kil  ",
      "m m   nio   ip  ",
      "qqq   riok  is  ",
      "iiii  tbuuuwbx  ",
      "  yi  tA    Bx  ",
      "  yi   A   CB!  ",
      "   i   ADDE B   ",
      "m mi   F    I   ",
      "qqqiiiib    biii",
      "JJKLMN O    P  Q",
      "       A    B   ",
      "       A    B   ",
      "ffabafabaRRabafa",
      "                "
    ],
    [
      "                ",
      "SSabaSabaSSabaSa",
      "      Ti    iU  ",
      "       iV   i   ",
      "       iV   i   ",
      "iiii   buuuWb   ",
      "  Xi   A    B   ",
      "  Xi   A    B   ",
      "   i   AdE  B   ",
      "   i   Y    Z   ",
      "   iiiib    biii",
      "       0    1  2",
      "       A    B   ",
      "       A    B   ",
      "SSabaSabaSSabaSa",
      "                "
    ],
    [
      "                ",
      "SSabaSabaSSabaSa",
      "       i    i   ",
      "       i    i   ",
      "       ik   i   ",
      "iiii   buuuub   ",
      "  Xi   A    B   ",
      "  Xi   Ad   B   ",
      "   i   AE   B   ",
      "   i   A    B   ",
      "   iiiib    biii",
      "       A    B   ",
      "       A    B   ",
      "       A    B   ",
      "SSabaSabaSSabaSa",
      "                "
    ],
    [
      "                ",
      "aaabaaabaaaabaaa",
      "   i   i3333i   ",
      "   i   i3333i   ",
      "   i   i3333i   ",
      "iiiiiiibuuuub   ",
      "   i   Ad4  B   ",
      "5  i   A6   B   ",
      "   i   A    B   ",
      "   i   A 5  B   ",
      "iiiiiiib7777biii",
      "   i   A    B   ",
      "   i   A    B   ",
      "   i   A    B   ",
      "aaabaaabaaaabaaa",
      "                "
    ],
    [
      "                ",
      "8889888988889888",
      "cccccccccccccccc",
      "dddddddddddddddd",
      "dddddddddddddddd",
      "dddddddddddddddd",
      "dddddddd edddddd",
      "dddddddd   ddddd",
      "dddddddd   ddddd",
      "dddddddddddddddd",
      "dddddddddddddddd",
      "dddddddddddddddd",
      "dddddddddddddddd",
      "cccccccccccccccc",
      "8889888988889888",
      "                "
    ]
  ]
}