{
  "name": "multi_condo1_4_base2",
  "refpalette": "c70cities:multi_condo1_4_base2_palette",
  "xsize": 16,
  "zsize": 16,
  "slices": [
    [
      "HHHHHHHHHHHHabbv",
      "HHHaaaaaaaaaabbv",
      "HHHaccdeeeeeabbv",
      "HHHaccdeeeeeabbv",
      "HHHaccdeeeeeabbv",
      "HHHaccdeeeeeabbv",
      "HHHcccdaaaaaabbv",
      "HHHcccd     abbv",
      "HHHcccd     abbv",
      "HHHcccd     abbv",
      "HHHaccf     abbv",
      "HHHaccgaaaaaabbv",
      "HHHaccddddddabbv",
      "HHHaccddddddabbv",
      "HHHaaaaaaaaaabbv",
      "HHHHHHHHHHHHabbv"
    ],
    [
      "            abbv",
      " hhaaaaaaaaaabbv",
      " ija  k     abbv",
      "   a  a     abbv",
      " lma  a  no abbv",
      "  pa  aqrss abbv",
      "   t uaaaaaaabbv",
      "   w  a     abbv",
      "   x  y     abbv",
      "   t  A     abbv",
      "  Ba  a     abbv",
      " ija  aaaaaaabbv",
      "   a  a   ddabbv",
      " lma  C Ddddabbv",
      " hhaaaaaaaaaabbv",
      "            abbv"
    ],
    [
      "            abbv",
      "   aaaaaaaaaabbv",
      "   a  E     abbv",
      "   a  aF    abbv",
      "   a  a  IJ abbv",
      "  pa  aqqss abbv",
      "   t  aaaaaaabbv",
      "   K  a     abbv",
      "   L  M     abbv",
      "   t  N     abbv",
      "  Ba  a     abbv",
      "   a  aaaaaaabbv",
      "   a  a   ddabbv",
      "   a  O  Dddabbv",
      "   aaaaaaaaaabbv",
      "            abbv"
    ],
    [
      "      P     abbv",
      "   aaaaaaaaaabbv",
      "   a  Q     abbv",
      "   a  a     abbv",
      "   a  a     abbv",
      "  pa  aq RR abbv",
      "  St  aaaaaaabbv",
      "  St  a     abbv",
      "  St  Q     abbv",
      "  St  Q     abbv",
      "  Ba  a     abbv",
      "   a  aaaaaaabbv",
      "   a  a   ddabbv",
      "   a  Q   Ddabbv",
      "   aaaaaaaaaabbv",
      "      P     abbv"
    ],
    [
      "     qa     abbv",
      "aaaaaaaaaaaaabbv",
      "   a  a     abbv",
      "   a  a     abbv",
      "   a  a     abbv",
      "   a  aq    abbv",
      "   a  aaaaaaabbv",
      "   a  a     abbv",
      "   a  a     abbv",
      "   a  a     abbv",
      "   a  a     abbv",
      "   a  aaaaaaabbv",
      "   a  a  QT abbv",
      "   a  a     abbv",
      "aaaaaaaaaaaaabbv",
      "     qa     abbv"
    ],
    [
      "eeeeeea     abbv",
      "aaaaaaaaaaaaabbv",
      "eeeaeeaq    abbv",
      "eeeaeeaq    abbv",
      "eeeaeeaq    abbv",
      "eeeaeeaqqqqqabbv",
      "eeeaeeaaaaaaabbv",
      "eeeaeea     abbv",
      "eeeaeea     abbv",
      "eeeaeea     abbv",
      "eeeaeea     abbv",
      "eeeaeeaaaaaaabbv",
      "eeeaeea QT  abbv",
      "eeeaeea     abbv",
      "aaaaaaaaaaaaabbv",
      "eeeeeea     abbv"
    ]
  ]
}