{
  "name": "multi_laboratory1_3_floor1",
  "refpalette": "c70cities:multi_laboratory1_3_floor1_palette",
  "xsize": 16,
  "zsize": 16,
  "slices": [
    [
      "        abbczzde",
      "        abbczzde",
      "        afgcddee",
      "        abbceeee",
      "        abbceeee",
      "        hbbceeee",
      "        abbceeee",
      "        abbceeee",
      "        hbbceeee",
      "        ifgceeee",
      "        jbbceeee",
      "        kbbceeee",
      "        kbbceeee",
      "        kbbceeee",
      "        kbbceeee",
      "        kbbceeee"
    ],
    [
      "        a  lmno ",
      "        a  l mo ",
      "        h  pqo  ",
      "        a  l    ",
      "        a  l    ",
      "        a  l    ",
      "        a  l    ",
      "        h  lr   ",
      "        a  ls   ",
      "        a  tu   ",
      "        i  l    ",
      "        i  l    ",
      "        h  lr   ",
      "        i  ls   ",
      "        i  lu   ",
      "        i  l    "
    ],
    [
      "        a       ",
      "        a       ",
      "        a       ",
      "        a       ",
      "        a       ",
      "        a       ",
      "        a       ",
      "        a       ",
      "        a       ",
      "        h  t    ",
      "        a       ",
      "        h       ",
      "        a       ",
      "        a   w   ",
      "        a       ",
      "        h       "
    ],
    [
      "        h       ",
      "        a       ",
      "        a       ",
      "        a       ",
      "        a       ",
      "        h       ",
      "        a       ",
      "        a       ",
      "        a       ",
      "        a  t    ",
      "        h       ",
      "        a       ",
      "        a       ",
      "        a       ",
      "        h       ",
      "        a       "
    ],
    [
      "        a       ",
      "        a       ",
      "        a       ",
      "        a       ",
      "        a       ",
      "        a       ",
      "        a       ",
      "        a       ",
      "        a       ",
      "        a  t    ",
      "        a       ",
      "        a       ",
      "        a       ",
      "        a       ",
      "        a       ",
      "        a       "
    ],
    [
      "        a       ",
      "        a       ",
      "        a       ",
      "        a      f",
      "        a     ff",
      "        a    ff ",
      "        a    f  ",
      "        a   ff  ",
      "        a   f   ",
      "        a  cf   ",
      "        a  f    ",
      "        a  f    ",
      "        a  f    ",
      "        a  f    ",
      "        a  f    ",
      "        a  f    "
    ]
  ]
}