{
  "name": "multi_megatower1_5_base2",
  "refpalette": "c70cities:multi_megatower1_5_base2_palette",
  "xsize": 16,
  "zsize": 16,
  "slices": [
    [
      "HHHHHHHHHHHHHHHH",
      "HHHHHHHHHHHHHHHH",
      "HHHHaHHHHHHaHHHH",
      "HHHHHHHHHHHHHHHH",
      "HHHHHHHHHHHHHHHH",
      "HHHHHHHHHHHHHHHH",
      "HHHHHHHHHHHHHHHH",
      "HHHHHHHHHHHHHHHH",
      "HHHHHHHHHHHHHHHH",
      "HHHHaHHHHHHaHHHH",
      "HHHHHHHHHHHHHHHH",
      "vvvvvvvvvvvvvvvv",
      "vvvvvvvvvvvvvvvv",
      "bb              ",
      "bbbbbbbbbbbbbbbb",
      "vvvvvvvvvvvvvvvv"
    ],
    [
      "                ",
      "cdcd cdcdcd cdcd",
      "    a      a    ",
      "efefgefefefgefef",
      "                ",
      "                ",
      "                ",
      "                ",
      "cdcdhcdcdcdicdcd",
      "    a      a    ",
      "efef efefef efef",
      "jjjjjjjjjjjjjjjj",
      "vvvvvvvvvvvvvvvv",
      "bbbbbbbbbbbbbbbb",
      "bbbbbbbbbbbbbbbb",
      "vvvvvvvvvvvvvvvv"
    ],
    [
      "                ",
      "                ",
      "    a      a    ",
      "                ",
      "                ",
      "                ",
      "                ",
      "                ",
      "                ",
      "    a      a    ",
      "                ",
      "                ",
      "vvvvvvvvvvvvvvvv",
      "bbbbbbbbbbbbbbbb",
      "bbbbbbbbbbbbbbbb",
      "vvvvvvvvvvvvvvvv"
    ],
    [
      "                ",
      "                ",
      "    a      a    ",
      "                ",
      "                ",
      "                ",
      "                ",
      "                ",
      "                ",
      "    a      a    ",
      "                ",
      "                ",
      "vvvvvvvvvvvvvvvv",
      "bbbbbbbbbbbbbbbb",
      "bbbbbbbbbbbbbbbb",
      "vvvvvvvvvvvvvvvv"
    ],
    [
      "                ",
      "                ",
      "    a      a    ",
      "                ",
      "                ",
      "                ",
      "                ",
      "                ",
      "                ",
      "    a      a    ",
      "    k      k    ",
      "                ",
      "vvvvvvvvvvvvvvvv",
      "bbbbbbbbbbbbbbbb",
      "bbbbbbbbbbbbbbbb",
      "vvvvvvvvvvvvvvvv"
    ],
    [
      "    a      a    ",
      "llllallllllallll",
      "aaaaaaaaaaaaaaaa",
      "llllallllllallll",
      "llllallllllallll",
      "llllallllllallll",
      "llllallllllallll",
      "llllallllllallll",
      "llllallllllallll",
      "aaaaaaaaaaaaaaaa",
      "llllllllllllllll",
      "vvvvvvvvvvvvvvvv",
      "vvvvvvvvvvvvvvvv",
      "bbbbbbbbbbbbbbbb",
      "bbbbbbbbbbbbbbbb",
      "vvvvvvvvvvvvvvvv"
    ]
  ]
}