{
  "name": "multi_megatower1_4_base2",
  "refpalette": "c70cities:multi_megatower1_4_base2_palette",
  "xsize": 16,
  "zsize": 16,
  "slices": [
    [
      "vaaavHHHHHHHHHHH",
      "vaaavHHHHHHHHHHH",
      "vbaavHHHHHHHHHHH",
      "cdeevHHHHHHHHHHH",
      "vvvvfHHHHHHfHHHH",
      "vvvvvvvvvvvvvvvv",
      "vvvvvvaaaavvvvvv",
      "vvvvvvaaaavvvvvv",
      "vvvvvvaaaavvvvvv",
      "vvvvvvaaaavvvvvv",
      "vvvvvvvvvvvvvvvv",
      "HHHHfHHHHHHfHHHH",
      "HHHHHHHHHHHHHHHH",
      "HHHggggggHgggHHH",
      "HHHgHHHHgHgHgHHH",
      "HHHgggHHgHgggHHH"
    ],
    [
      "hi  j           ",
      "hk  j           ",
      "halmj           ",
      "hennjo po p o po",
      "qrstfu wu wfu wu",
      "     vvvvvvvvvvv",
      "     vxxxyHHHHHH",
      "     vxAAxHHHHHH",
      "    Bv    HHHHHH",
      "    !v   CHHHHHH",
      "vvvvvvvvDvvvvvvv",
      "    f EF E f    ",
      "                ",
      "                ",
      "                ",
      "                "
    ],
    [
      "hi  j           ",
      "hi  j           ",
      "haIJj           ",
      "he  j           ",
      "q KLf      f    ",
      "    Bvvvvvvvvvvv",
      "     vM   HHHHNO",
      "     v    HHHHNO",
      "     v    HHHHNO",
      "    Bv    HHHHNO",
      "vvvvvvvDvvvvvvvv",
      "    f FPE Bf    ",
      "                ",
      "                ",
      "                ",
      "                "
    ],
    [
      "hi  j           ",
      "hi  j           ",
      "haQQj           ",
      "heeej           ",
      "qR  f      f    ",
      "    Bvvvvvvvvvvv",
      "     vSSSSHNO   ",
      "    BvSSSSHNO   ",
      "     vSSSSHNO   ",
      "     vSSSSHNO   ",
      "vvvvvvvvvvvvvvvv",
      "    fB E  Bf    ",
      "                ",
      "                ",
      "                ",
      "                "
    ],
    [
      "hTUUj           ",
      "hTUUj           ",
      "haaaj           ",
      "heeej           ",
      "qqqqf      f    ",
      "    Bvvvvvvvvvvv",
      "    BvHHNO      ",
      "    BvHHNO      ",
      "     vHHNO      ",
      "    BvHHNO      ",
      "vvvvvvvvvvvvvvvv",
      "B  BfB   BBfB  B",
      "    B           ",
      "                ",
      "                ",
      "                "
    ],
    [
      "f   fVVVVVVVVVVV",
      "f   fVVVVVVVVVVV",
      "f   fVVVVVVVVVVV",
      "feWXfVVVVVVVVVVV",
      "ffffffffffffffff",
      "VVVVfvvvvvvvvvvv",
      "VVVVfNO         ",
      "VVVVfNO         ",
      "VVVVfNO         ",
      "VVVVfNO         ",
      "vvvvfvvvvvvvvvvv",
      "ffffffffffffffff",
      "    f      f    ",
      "    f      f    ",
      "    f      f    ",
      "    f      f    "
    ]
  ]
}