{
  "name": "multi_laboratory1_6_base3",
  "refpalette": "c70cities:multi_laboratory1_6_base3_palette",
  "xsize": 16,
  "zsize": 16,
  "slices": [
    [
      "aaaaaaaaaaaaaaaa",
      "aaaaaaaaaaaaaaaa",
      "aaaaaaaaaaaaaaaa",
      "aaaaaaaaaaaaaaaa",
      "aaaaaaaaaaaaaaaa",
      "aaaaaaaaaaaaaaaa",
      "aaaaaaaaaaaaaaaa",
      "aaaaabbbbbbaaaaa",
      "aaabbc    cbbaaa",
      "abbb        bbba",
      "bc            cb",
      "b              b",
      "b         d    b",
      "                ",
      " d              ",
      "                "
    ],
    [
      "e fg e fg e fg e",
      "                ",
      "                ",
      "        h ij    ",
      "     kkllkmh    ",
      "n    o   pqn   n",
      "rrn           rr",
      "rr scttttttcu rr",
      " n ttc    ctt n ",
      " ttt        ttt ",
      "tc            ct",
      "t              t",
      "t         d    t",
      "                ",
      " d              ",
      "                "
    ],
    [
      "  wx   wx   wx  ",
      "                ",
      "                ",
      "                ",
      "       y  j     ",
      "                ",
      "              AB",
      "    CttttttC    ",
      "   ttc    ctt   ",
      " ttt        ttt ",
      "tc            ct",
      "t              t",
      "t         d    t",
      "                ",
      " d              ",
      "                "
    ],
    [
      "                ",
      "                ",
      "                ",
      "                ",
      "                ",
      "                ",
      "                ",
      "    CttttttC    ",
      "   ttc    ctt   ",
      " ttt        ttt ",
      "tc            ct",
      "t              t",
      "t         d    t",
      "                ",
      " d              ",
      "                "
    ],
    [
      "                ",
      "                ",
      "                ",
      "                ",
      "                ",
      "                ",
      "                ",
      "     tttttt     ",
      "   ttc    ctt   ",
      " ttt        ttt ",
      "tc            ct",
      "t              t",
      "t         D    t",
      "                ",
      " d              ",
      "                "
    ],
    [
      "EEEEEEEEEEEEEEEE",
      "EFEEEFEEEEFEEEFE",
      "EFEEEFEEEEFEEEFE",
      "EFEEEFEEEE EEEFE",
      "EFEEEFEEEEIEEEFE",
      "EEEEEEEEEEEEEEEE",
      "EEEEEEEEEEEEEEEE",
      "EEEEEttttttEEEEE",
      "EEEttc    cttEEE",
      "Ettt        tttE",
      "tc            ct",
      "t              t",
      "t         d    t",
      "                ",
      " d              ",
      "                "
    ]
  ]
}