{
  "name": "multi_hospital_0_base1",
  "refpalette": "c70cities:multi_hospital_0_base1_palette",
  "xsize": 16,
  "zsize": 16,
  "slices": [
    [
      "vvvvvvvvvvvvvvvv",
      "vaaaaaaaaaaaaaaa",
      "vaaaaaaaaaaaaaaa",
      "vaaaaaaaabbbbbbb",
      "vaaaaaaaabbbbbbb",
      "vaaaaaaaabbbbbbb",
      "vaaaaaaaabbbbbbb",
      "vaaaaaaaabbbbbbb",
      "vacddddddceeebbb",
      "vadffffff   gbbb",
      "vadffffff   gbbb",
      "vadffffffeheebbb",
      "vadffffffbbbbbbb",
      "vadffffffbbbbbbb",
      "vadffffffbbbbbbb",
      "vadffffffbbbbbbb"
    ],
    [
      "vvvvvvvvvvvvvvvv",
      "vaaaaaaaaaaaaaaa",
      "vaaaaaaaaaaaaaaa",
      "vaaaaaaaaiiiiiii",
      "vaaaaaaaai  j   ",
      "vaaaaaaaaik j   ",
      "vaaaaaaaail jj  ",
      "vaaaaaaaai      ",
      "vacddddddceee   ",
      "vad      m  n   ",
      "vadoo    p  q   ",
      "vadr     e ee   ",
      "vads   tdbuuuuwx",
      "vads k  dy      ",
      "vad  A  dy      ",
      "vad BCD dboo   o"
    ],
    [
      "vvvvvvvvvvvvvvvv",
      "vaaaaaaaaaaaaaaa",
      "vaaaaaaaaaaaaaaa",
      "vaaaaaaaaiiiiiii",
      "vaaaaaaaaik j   ",
      "vaaaaaaaail j   ",
      "vaaaaaaaai  jj  ",
      "vaaaaaaaai      ",
      "vacddddddceee   ",
      "vad      E  F   ",
      "vadI     J  K   ",
      "vad     Le eeM  ",
      "vadN   jdbuuuuOP",
      "vad  Q  dy      ",
      "vad  Q  dy      ",
      "vad RQS dbI     "
    ],
    [
      "vvvvvvvvvvvvvvvv",
      "vaaaaaaaaaaaaaaa",
      "vaaaaaaaaaaaaaaa",
      "vaaaaaaaaiiiiiii",
      "vaaaaaaaaiTkj   ",
      "vaaaaaaaai kj   ",
      "vaaaaaaaai  j   ",
      "vaaaaaaaai  j   ",
      "vacddddddceee   ",
      "vad      U  V   ",
      "vad      U  V   ",
      "vad      e ee   ",
      "vad    jdbuuuuWW",
      "vad     dy      ",
      "vad     dy      ",
      "vad D B db      "
    ],
    [
      "vvvvvvvvvvvvvvvv",
      "vaaaaaaaaaaaaaaa",
      "vaaaaaaaaaaaaaaa",
      "vaaaaaaaaiiiiiii",
      "vaaaaaaaai  j   ",
      "vaaaaaaaai Xj   ",
      "vaaaaaaaai kj   ",
      "vaaaaaaaai  j   ",
      "vacddddddceee   ",
      "vad      e  e   ",
      "vad      e  e   ",
      "vad      e ee   ",
      "vad     dbuuuuuu",
      "vad     dy      ",
      "vad     dy      ",
      "vad  T  db      "
    ],
    [
      "vvvvvvvvvvvvvvvv",
      "vaaaaaaaaaaaaaaa",
      "vaaaaaaaaaaaaaaa",
      "vaaaaaaaaiiiiiii",
      "vaaaaaaaai  jYYY",
      "vaaaaaaaai  jYYY",
      "vaaaaaaaai XjYYY",
      "vaaaaaaaai kjYYY",
      "vacddddddceeebbb",
      "vadkkkkkke  eYYY",
      "vadkkkkkke  eYYY",
      "vadkkkkkke eebbb",
      "vadkkkkkdbZZZZZZ",
      "vadkkkkkdbssssss",
      "vadkkkkkdbssssss",
      "vadkkkkkdbssssss"
    ]
  ]
}