{
  "name": "multi_condo1_3_base2",
  "refpalette": "c70cities:multi_condo1_3_base2_palette",
  "xsize": 16,
  "zsize": 16,
  "slices": [
    [
      "vvvvvvvvvvvvvvvv",
      "aaaaaaaaaaaaaaav",
      "bbbbbbbbbbbbbaav",
      "bcccccbHHHHHbaav",
      "HcccccbHHHHHbaav",
      "HcccccbbbbHHbaav",
      "HcccccbccbHHbaav",
      "bcccccbccbHHbaav",
      "bcccccbccbHHbaav",
      "bcccccbccbHHbaav",
      "bcccccbccbHHbaav",
      "bcccccbccbHHbaav",
      "bcccccbccbHHbaav",
      "bcccccbccbHHbaav",
      "bbbbbbbbbbHHbaav",
      "HHHHHHHHHHHHbaav"
    ],
    [
      "vvvvvvvvvvvvvvvv",
      "aaaaaaaaaaaaaaav",
      "bbbbbbbbbbbbbaav",
      "bdddedbHHHHHbaav",
      "      bHHHHHbaav",
      "     ebbbbHHbaav",
      "    dfg hbHHbaav",
      "b    ibjhbHHbaav",
      "bk    b  bHHbaav",
      "bk  libmnbHHbaav",
      "b   lib hbHHbaav",
      "bk   ibhobHHbaav",
      "bk    bohbHHbaav",
      "b!epqiboobrrbaav",
      "bbbbbbbbbbrrbaav",
      "            baav"
    ],
    [
      "vvvvvvvvvvvvvvvv",
      "aaaaaaaaaaaaaaav",
      "bbbbbbbbbbbbbaav",
      "b  d sbHHHHHbaav",
      "t     bHHHHHbaav",
      "t     bbbbHHbaav",
      "t   luw hbHHbaav",
      "b     b  bHHbaav",
      "bkx  ub  bHHbaav",
      "bkx d b  brrbaav",
      "by  d b nbrrbaav",
      "bkx  ebA b  baav",
      "bkx  ub hb  baav",
      "byyy  bhob  baav",
      "bbbbbbbbbb  baav",
      "            baav"
    ],
    [
      "vvvvvvvvvvvvvvvv",
      "aaaaaaaaaaaaaaav",
      "bbbbbbbbbbbbbaav",
      "be    bHHHHHbaav",
      "t     bHHHHHbaav",
      "t     bbbbrrbaav",
      "t     b nbrrbaav",
      "b    eb  b  baav",
      "bB    b  b  baav",
      "bB    b  b  baav",
      "b     b  b  baav",
      "bB    b  b  baav",
      "bB    b  b  baav",
      "b  y eb Cb  baav",
      "bbbbbbbbbb  baav",
      "      D     baav"
    ],
    [
      "vvvvvvvvvvvvvvvv",
      "aaaaaaaaaaaaaaav",
      "bbbbbbbbbbbbbaav",
      "byyyyyb     baav",
      "E    yb     baav",
      "E    ybrrb  baav",
      "E    ybrrb  baav",
      "b    ybHHb  baav",
      "b    ybHHb  baav",
      "b    ybHHb  baav",
      "b    ybHHb  baav",
      "b    ybHHb  baav",
      "b    ybHHb  baav",
      "byyyyybHHb  baav",
      "bbbbbybbbb  baav",
      "     yb     baav"
    ],
    [
      "vvvvvvvvvvvvvvvv",
      "aaaaaaaaaaaaaaav",
      "bbbbbbbbbbbbbaav",
      "FFFFFFb     baav",
      "FFFFFFb     baav",
      "FFFFFFb  b  baav",
      "FFFFFFb  b  baav",
      "FFFFFFb  b  baav",
      "FFFFFFb  b  baav",
      "FFFFFFbrrb  baav",
      "FFFFFFbrrb  baav",
      "FFFFFFbHHb  baav",
      "FFFFFFbHHb  baav",
      "FFFFFFbHHb  baav",
      "FFFFFFbbbbbbbaav",
      "FFFFFFb     baav"
    ]
  ]
}