{
  "name": "multi_laboratory1_5_base2",
  "refpalette": "c70cities:multi_laboratory1_5_base2_palette",
  "xsize": 16,
  "zsize": 16,
  "slices": [
    [
      "vvvvvvvvvvvvvvvv",
      "aaaaaaaaaaaaaaaa",
      "bbbbbbbbbbbbbbbb",
      "                ",
      "                ",
      "cccccccccccccccc",
      "c    c    c    c",
      "cd  dcd  dcd  dc",
      "cccccccccccccccc",
      "c    c    c    c",
      "c    c    c    c",
      "c    c    c    c",
      "c    c    c    c",
      "c    c    c    c",
      "c    c    c    c",
      "cccceccccefcccgc"
    ],
    [
      "vvvvvvvvvvvvvvvv",
      "aaaaaaaaaaaaaaaa",
      "bbbbbbbbbbbbbbbb",
      "                ",
      "                ",
      "chhhhhhhhhhhhhhc",
      "h    h    h    h",
      "hd  dhd  dhd  dh",
      "chhhhchhhhchhhhc",
      "h    h    h    h",
      "h    h    h    h",
      "h    h    h    h",
      "h    h    h    h",
      "h    h    h    h",
      "h    h    h    h",
      "chiihchiihchiihc"
    ],
    [
      "vvvvvvvvvvvvvvvv",
      "aaaaaaaaaaaaaaaa",
      "bbbbbbbbbbbbbbbb",
      "                ",
      "                ",
      "chhhhhhhhhhhhhhc",
      "h    h    h    h",
      "hd  dhd  dhd  dh",
      "chhhhchhhhchhhhc",
      "h    h    h    h",
      "h    h    h    h",
      "h    h    h    h",
      "h    h    h    h",
      "h    h    h    h",
      "h    h    h    h",
      "ch  hch  hch  hc"
    ],
    [
      "vvvvvvvvvvvvvvvv",
      "aaaaaaaaaaaaaaaa",
      "bbbbbbbbbbbbbbbb",
      "                ",
      "                ",
      "chhhhhhhhhhhhhhc",
      "h    h    h    h",
      "hd  dhd  dhd  dh",
      "chhhhchhhhchhhhc",
      "h    h    h    h",
      "h    h    h    h",
      "h    h    h    h",
      "h    h    h    h",
      "h    h    h    h",
      "h    h    h    h",
      "chjjhchjjhchjjhc"
    ],
    [
      "vvvvvvvvvvvvvvvv",
      "aaaaaaaaaaaaaaaa",
      "bbbbbbbbbbbbbbbb",
      "               k",
      "               k",
      "chhhhhhhhhhhhhhc",
      "h    h    h    h",
      "hd  dhd  dhd  dh",
      "chhhhchhhhchhhhc",
      "h    h    h    h",
      "h    h    h    h",
      "h    h    h    h",
      "h    h    h    h",
      "h    h    h    h",
      "h    h    h    h",
      "chhhhchhhhchhhhc"
    ],
    [
      "vvvvvvvvvvvvvvvv",
      "aaaaaaaaaaaaaaaa",
      "bbbbbbbbbbbbbbbb",
      "                ",
      "                ",
      "chhhhhhhhhhhhhhc",
      "h    h    h    h",
      "hd  dhd  dhd  dh",
      "chhhhchhhhchhhhc",
      "h    h    h    h",
      "h    h    h    h",
      "h    h    h    h",
      "h    h    h    h",
      "h    h    h    h",
      "h    h    h    h",
      "chhhhchhhhchhhhc"
    ]
  ]
}