{
  "name": "multi_factory_1_ground",
  "refpalette": "c70cities:multi_factory_1_ground_palette",
  "xsize": 16,
  "zsize": 16,
  "slices": [
    [
      "aaabbbbbbbbbbbzz",
      "zaabbbbbbbbbbbzz",
      "azabbbbbbbbbbbzz",
      "aaabbbbbbbbbbbzz",
      "aaabbbbbbbbbbbzz",
      "aaabbbbbbbbbbbzz",
      "zaabbbbbbbbbbbzz",
      "aaabbbbbbbbbbbzz",
      "zaabbbbbbbbbbbzz",
      "zaabbbbbbbbbbbzz",
      "aaabbbbbbbbbbbzz",
      "aaabbbbbbbbbbbzz",
      "azabbbbbbbbbbbzz",
      "aaabbbbbbbbbbbzz",
      "zaazzzzzzzzzzzzz",
      "aazzzzzzzzzzzzzz"
    ],
    [
      "     ccccc  de  ",
      "     ccccc  de  ",
      "             e  ",
      "   e        fe  ",
      "   eg   g   ge  ",
      "   e         e  ",
      "   h       ife  ",
      "   h     jjj e  ",
      "   h    ij!jie  ",
      "   h   ifjjj e  ",
      "   h     i   e  ",
      "   hf     kk e  ",
      "   egllmgnopge  ",
      "   eeeeeeeeeee  ",
      "                ",
      "                "
    ],
    [
      "     ccccc   e  ",
      "     ccccc  de  ",
      "             e  ",
      "   e         e  ",
      "   eg   g   ge  ",
      "   e         e  ",
      "   h         e  ",
      "   h     jjj e  ",
      "   h       j e  ",
      "   h     jjj e  ",
      "   h         e  ",
      "   hf        e  ",
      "   eg   g kkge  ",
      "   eeeeeeeeeee  ",
      "                ",
      "                "
    ],
    [
      "   h  ccc   de  ",
      "   h  ccc    e  ",
      "   h         e  ",
      "   e         e  ",
      "   eg   g   ge  ",
      "   e         e  ",
      "   hf        e  ",
      "   h     jj  e  ",
      "   h       j e  ",
      "   h     ijj e  ",
      "   h         e  ",
      "   h         e  ",
      "   egf  g  fge  ",
      "   eeqrseqrsee  ",
      "                ",
      "                "
    ],
    [
      "  teu        e  ",
      "  teu        e  ",
      "  teu        e  ",
      "   e         e  ",
      "   eg   g   ge  ",
      "   ef        e  ",
      "  teu        e  ",
      "  teu    www e  ",
      "  teu    w w e  ",
      "  teu    www e  ",
      "  teu        e  ",
      "  teu   x   xe  ",
      "   egxxxgxxxge  ",
      "   eeeeeeeeeee  ",
      "                ",
      "                "
    ],
    [
      "   e         e  ",
      "   e         e  ",
      "   e         e  ",
      "   e         e  ",
      "   eg   g   ge  ",
      "   e         e  ",
      "   e         e  ",
      "   ex   xwwwxe  ",
      "   exxxxxw wxe  ",
      "   ex   xwwwxe  ",
      "   ey   y   ye  ",
      "   eAAAAAAAAAe  ",
      "   eAAAAAAAAAe  ",
      "   BBBBBBBBBBB  ",
      "                ",
      "                "
    ]
  ]
}