{
  "name": "multi_laboratory1_1_base7",
  "refpalette": "c70cities:multi_laboratory1_1_base7_palette",
  "xsize": 16,
  "zsize": 16,
  "slices": [
    [
      "zaaaaabbbcaaacaa",
      "zaaaaabbbaaaacaa",
      "zaaaaabaaaaaacaa",
      "zaaaaaaaaaaaacaa",
      "zaaaaabaabaaacaa",
      "zaaaaabaaaaaacaa",
      "zaaaaaaaaaaaacaa",
      "zaaaaaaaaaaaacaa",
      "zaaaaaaaaaaaacaa",
      "zaaaaaaaabaaacaa",
      "zaaaaaaaaaaaacaa",
      "zaaaaaaaaaaaacaa",
      "zaaaaaaaaaaaacad",
      "zaaaaaaaaaaaccad",
      "zaaaaaaaaaaaaadd",
      "zaaaaaaaaaaaaada"
    ],
    [
      "zaaaabe fggaaaaa",
      "zaaaabh igaaaaaa",
      "zaaaaj  caaaaaaa",
      "zaaaai  baaaaaaa",
      "zaaaaa  kiaaaaaa",
      "zaaaaae  jaaaaaa",
      "zaaaaaj   caaaaa",
      "zaaaaaai   jacaa",
      "zaaaaaaaeh jgbaa",
      "zaaaaaaab jaggaa",
      "zaaaaaaaaaagggaa",
      "zaaaaaaaaaaaggaa",
      "zaaaaaaaaaaaa aa",
      "zaaaaaaaaaaaaaaa",
      "zaaaaaaaaaaaaaal",
      "zaaaaaaaaaaaaaaa"
    ],
    [
      "zaaaaf  egggaaaa",
      "zaaaaa  igaaaaaa",
      "zaaaa   aaaaaaaa",
      "zaaaai  baaaaaaa",
      "zaaaa    iaaaaaa",
      "zaaaaj    maaaaa",
      "zaaaam     aaaaa",
      "zaaaaaai    iaaa",
      "zaaaaaaa     fba",
      "zaaaaaaab    jji",
      "zaaaaaaaaaijjggj",
      "zaaaaaaaaaagmcaa",
      "zaaaaaaaaaaagbba",
      "zaaaaaaaaaaaaaba",
      "zaaaaaaaaaaaaaal",
      "zaaaaaaaaaaaaaaa"
    ],
    [
      "zaaaae  naggaaaa",
      "zaaaaa  aaaaaaaa",
      "zaaaac  baaaaaaa",
      "zaaaai  baaaaaaa",
      "zaaaa   niaaaaaa",
      "zaaaa    gaaaaaa",
      "zaaaaa   naaaaaa",
      "zaaaaaai    iaaa",
      "zaaaaaaaa    eba",
      "zaaaaaaaaa     i",
      "zaaaaaaaaai     ",
      "zaaaaaaaaaaa    ",
      "zaaaaaaaaaaaae  ",
      "zaaaaaaaaaaaabbo",
      "zaaaaaaaaaaaaaal",
      "zaaaaaaaaaaaaaag"
    ],
    [
      "zaaaaa naaaaaaaa",
      "zaaaaaaaaaaaaaaa",
      "zaaaaaanaaaaaaaa",
      "zaaaaannaaaaaaaa",
      "zaaaama aaaaaaaa",
      "zaaaaaaaaaaaaaaa",
      "zaaaaaaaaaaaaaaa",
      "zaaaaaaanaa iaaa",
      "zaaaaaaaaan   ca",
      "zaaaaaaaaa     i",
      "zaaaaaaaaaaa    ",
      "zaaaaaaaaaaaa   ",
      "zaaaaaaaaaaaag  ",
      "zaaaaaaaaaaaaabo",
      "zaaaaaaaaaaaaaal",
      "zaaaaaaaaaaaaaa "
    ],
    [
      "zaaaaaaaaaaaaaaa",
      "zaaaaaaaaaaaaaaa",
      "zaaaaaaaaaaaaaaa",
      "zaaaaaaaaaaaaaaa",
      "zaaaaaaaaaaaaaaa",
      "zaaaaaaaaaaaaaaa",
      "zaaaaaaaaaaaaaaa",
      "zaaaaaaaaaaaagaa",
      "zaaaaaaaaaaaacca",
      "zaaaaaaaaaaannna",
      "zaaaaaaaaaaaannn",
      "zaaaaaaaaaaaannn",
      "zaaaaaaaaaaaagpn",
      "zaaaaaaaaaaaagao",
      "zaaaaaaaaaaaaaal",
      "zaaaaaaaaaaaaaa "
    ]
  ]
}