{
  "name": "multi_megatower1_5_floor9",
  "refpalette": "c70cities:multi_megatower1_5_floor9_palette",
  "xsize": 16,
  "zsize": 16,
  "slices": [
    [
      "aaaaaaaaaaaaaaaa",
      "aaaaaaaaaaaaaaaa",
      "aaaabaaaaaabaaaa",
      "ccccdccccccdcccc",
      "efffgeeefffgeeef",
      "    h      h    ",
      "                ",
      "                ",
      "                ",
      "                ",
      "                ",
      "                ",
      "                ",
      "                ",
      "                ",
      "                "
    ],
    [
      " ijklmjn ioon io",
      " ijklmjn  pp   p",
      "qqqqbqqqqqqbqqqq",
      "                ",
      "efffheeefffheeef",
      "                ",
      "                ",
      "                ",
      "                ",
      "                ",
      "                ",
      "                ",
      "                ",
      "                ",
      "                ",
      "                "
    ],
    [
      "    r           ",
      "    s           ",
      "qqqqbqqqqqqbqqqq",
      "                ",
      "efffheeefffheeef",
      "                ",
      "                ",
      "                ",
      "                ",
      "                ",
      "                ",
      "                ",
      "                ",
      "                ",
      "                ",
      "                "
    ],
    [
      "                ",
      "                ",
      "qqqqbqqqqqqbqqqq",
      "                ",
      "efffheeefffheeef",
      "                ",
      "                ",
      "                ",
      "                ",
      "                ",
      "                ",
      "                ",
      "                ",
      "                ",
      "                ",
      "                "
    ],
    [
      "                ",
      "                ",
      "tutubtututubtutu",
      "                ",
      "efffheeefffheeef",
      "                ",
      "                ",
      "                ",
      "                ",
      "                ",
      "                ",
      "                ",
      "                ",
      "                ",
      "                ",
      "                "
    ],
    [
      "wwxwywxwwAwywAww",
      "wwwwywwwwwwywwww",
      "BBBBbBBBBBBbBBBB",
      "    g      g    ",
      "efffheeefffheeef",
      "                ",
      "                ",
      "                ",
      "                ",
      "                ",
      "                ",
      "                ",
      "                ",
      "                ",
      "                ",
      "                "
    ]
  ]
}