{
  "name": "multi_communitycenter_8_ground",
  "refpalette": "c70cities:multi_communitycenter_8_ground_palette",
  "xsize": 16,
  "zsize": 16,
  "slices": [
    [
      "aaaaaabbbbbbbbGc",
      "aaaaaabbbbbbbbGc",
      "dddddabbbbbbbbGc",
      "eaaaaabbbbbbbbGc",
      "eaaaaabbbbbbbbGc",
      "aaaaaabbbbbbbbGc",
      "aaaaaabbbbbbbbGc",
      "bbbbbbbbbbbbbbGc",
      "  fggbcccGGGGGGc",
      "  f  bcccGGGGGGc",
      "  h  bcccGGGGGGc",
      "     bcccGGGGGGc",
      "     bcccGGGGGGc",
      "bbbbbbcccccccccc",
      "cccccccccccccccc",
      "cccccccccccccccc"
    ],
    [
      "  i jk   lmmmnh ",
      "oopqqk  p    rs ",
      "tttuuk  w xyArs ",
      "BC   k  p  y rs ",
      "BC   k   lxyAnh ",
      "D    E  p  y ns ",
      "     F  pIxyAns ",
      "ttt  knJnnnnnns ",
      "  f  k   hK LKh ",
      "  f  k   sKKK s ",
      "  h  k   sL LKs ",
      "     k   sKLKKs ",
      "     k   hssssh ",
      "kkkkkk          ",
      "                ",
      "                "
    ],
    [
      "  M  k   lNNNn  ",
      "  pqqk  p    r  ",
      "tOO  k  P  Q r  ",
      " BC  k  p    r  ",
      " BC  k   l Q n  ",
      "RD   S  pT   n  ",
      "     U  pV   n  ",
      "tOO  knWnnnnnn  ",
      "  f  k    X YX  ",
      "  f  k    XXX   ",
      "  h  k    Y YX  ",
      "     k    XYXX  ",
      "     Z          ",
      "ZkkZZZ          ",
      "                ",
      "                "
    ],
    [
      "  p00k   lmmmn  ",
      "  p11k  p    2  ",
      "tOO  k  p    2  ",
      "  BC k  p    2  ",
      "  BC k   l   n  ",
      " RD  k  pT   n  ",
      "     k  pV   n  ",
      "tOO  knnnnnnnn  ",
      "  f  k          ",
      "  f  k          ",
      "  h  k          ",
      "     k          ",
      "     Z          ",
      "ZkkZZZ          ",
      "                ",
      "                "
    ],
    [
      "    Ik  3lmmmn  ",
      "     k  p    r  ",
      "tOOOOk  p    r  ",
      "   BCk  p    r  ",
      "   BCk   l   n  ",
      "  RD k  p4   n  ",
      "     k  p    n  ",
      "tOOOOknnnnnnnn  ",
      "  f  k          ",
      "  f  k          ",
      "  h  k          ",
      "     k          ",
      "     k          ",
      "kkkkkk          ",
      "                ",
      "                "
    ],
    [
      "55555kbbbbbbb6  ",
      "55555kbbbbbbb6  ",
      "tttttkbbbbbbb6  ",
      "    Bebbbbbbb6  ",
      "    Bebbbbbbbn  ",
      "   RDkbbbbbbb6  ",
      "     kbbbbbbb6  ",
      "tttttk666n6666  ",
      "55555k          ",
      "55555k          ",
      "55555k          ",
      "55555k          ",
      "55555k          ",
      "kkkkkk          ",
      "                ",
      "                "
    ]
  ]
}