{
  "name": "multi_laboratory1_4_base3",
  "refpalette": "c70cities:multi_laboratory1_4_base3_palette",
  "xsize": 16,
  "zsize": 16,
  "slices": [
    [
      "vabccccccccdcccc",
      "vabccccccccccccc",
      "vabccccccccccccc",
      "vabccccccefcfccc",
      "vabccccccccfgccc",
      "vabccccccchccccc",
      "vabccccccccccccc",
      "vabccccccccdcccc",
      "vabiiiiiiiiccccc",
      "vabiiiiiiiiccccc",
      "vabiiiiiiiiccccc",
      "vabjiiiiiiiccccc",
      "vab!kiiiiiiccccc",
      "vabbbbbbbbbbbbbb",
      "vaaaaaaaaaaaaaaa",
      "vvvvvvvvvvvvvvvv"
    ],
    [
      "vablllllllld   m",
      "vab! nnopnql r m",
      "vabstuuu wql   x",
      "vabyABBBo  r  Cx",
      "vabyDBBBBEF     ",
      "vabs IIII  Jr   ",
      "vabK   LM ol   r",
      "vablllllllld   N",
      "vabOOPPPPOOlQ   ",
      "vabQ       R    ",
      "vabSTUTUTUTl    ",
      "vab V V V Vl   W",
      "vabXVYVYVYVlZ00 ",
      "vabbbbbbbbbbbbbb",
      "vaaaaaaaaaaaaaaa",
      "vvvvvvvvvvvvvvvv"
    ],
    [
      "vablllllllld    ",
      "vab       1l    ",
      "vab w     1    W",
      "vab2 ooo        ",
      "vab3 oooo       ",
      "vab        4    ",
      "vab   55   l    ",
      "vablllllllld   6",
      "vab7 888896l    ",
      "vab        @    ",
      "vab#T$T$T$Tl    ",
      "vab V V V Vl    ",
      "vab%V V V Vl    ",
      "vabbbbbbbbbbbbbb",
      "vaaaaaaaaaaaaaaa",
      "vvvvvvvvvvvvvvvv"
    ],
    [
      "vablllllllld    ",
      "vab       1l    ",
      "vab       1^    ",
      "vab             ",
      "vab             ",
      "vab        &    ",
      "vab        l    ",
      "vablllllllld    ",
      "vab 8 8 88 l    ",
      "vab        l    ",
      "vabTTTTTTTTl    ",
      "vab V V V Vl    ",
      "vabjV V%V Vl    ",
      "vabbbbbbbbbbbbbb",
      "vaaaaaaaaaaaaaaa",
      "vvvvvvvvvvvvvvvv"
    ],
    [
      "vablllllllld    ",
      "vab        l    ",
      "vab        l    ",
      "vab        l    ",
      "vab        l    ",
      "vab        l    ",
      "vab        l    ",
      "vablllllllld    ",
      "vab********l    ",
      "vab********l    ",
      "vab********l    ",
      "vab********l    ",
      "vabX*(*X*(*l    ",
      "vabbbbbbbbbbbbbb",
      "vaaaaaaaaaaaaaaa",
      "vvvvvvvvvvvvvvvv"
    ],
    [
      "vablllllllld))+)",
      "vab--------&))+)",
      "vab-[----t-&))+)",
      "vab--------&))++",
      "vab--------&))))",
      "vab-t----[-&))))",
      "vab--------&))))",
      "vablllllllldllll",
      "vab]]]]]]]]l^^^^",
      "vab] ] ] ] l^+^^",
      "vab] ] ] ] l^+^^",
      "vabX ] ] ] l^+^^",
      "vabX ] ] ] l^^^^",
      "vabbbbbbbbbbbbbb",
      "vaaaaaaaaaaaaaaa",
      "vvvvvvvvvvvvvvvv"
    ]
  ]
}