{
  "name": "multi_laboratory1_11_base1",
  "refpalette": "c70cities:multi_laboratory1_11_base1_palette",
  "xsize": 16,
  "zsize": 16,
  "slices": [
    [
      "aaaaaaaaaaaaabcv",
      "aaaaaaaaaaaaabcv",
      "aaaaaaaaaaaaabcv",
      "aaaaaaaaaaaaabcv",
      "aaaaaaaaaaaaabcv",
      "aaaaaaaaaaaaabcv",
      "aaaadaaaaaaaabcv",
      "aaaaaaaaaaaaabcv",
      "aaaaaaaaaaaaabcv",
      "aaaaaaaaaaaaabcv",
      "aaaaaaaaaaaaabcv",
      "aaaaaaaaaaaaabcv",
      "eaaaaaaaaaaaabcv",
      "eaaadaaaaaaaabcv",
      "feaaaaaaaaaaabcv",
      " eaaaaaaaaaaabcv"
    ],
    [
      "    ghiijkiihbcv",
      "    g       ibcv",
      "    g       ibcv",
      "    l  iii  mbcv",
      "    g       nbcv",
      "    g       ibcv",
      "   od  iii  ibcv",
      "p   q       hbcv",
      "    q       ibcv",
      "    q  iii  mbcv",
      "    q       nbcv",
      "    qr      !bcv",
      "st  quw    xhbcv",
      "so  dyy    yybcv",
      "os  yA      Bbcv",
      " s  yAC  D  Bbcv"
    ],
    [
      "    ghiiEFiihbcv",
      "    g       ibcv",
      "    g       ibcv",
      "    I  iii  Jbcv",
      "    g       Kbcv",
      "    g       ibcv",
      "   Ld  iii  ibcv",
      "    q       hbcv",
      "    q       ibcv",
      "    q  iii  Jbcv",
      "    q       Kbcv",
      "    q       ibcv",
      "s   q M     hbcv",
      "sL  dyy    yybcv",
      "os  qNO     Pbcv",
      " s  q       Pbcv"
    ],
    [
      "    ghQQR QQhbcv",
      "    g       Qbcv",
      "    g       Qbcv",
      "    g  QQQ  Rbcv",
      "    g       Sbcv",
      "    g       Qbcv",
      "   Ld  QQQ  Qbcv",
      "    q       hbcv",
      "    q       Qbcv",
      "    q  QQQ  Tbcv",
      "    q        bcv",
      "    q       Qbcv",
      "s   q       hbcv",
      "sL  dyy    yybcv",
      "os  q       Ubcv",
      " s  q       Ubcv"
    ],
    [
      "    gV      Vbcv",
      "    g        bcv",
      "    g        bcv",
      "    g        bcv",
      "    g        bcv",
      "    g        bcv",
      "    d        bcv",
      "    q       Vbcv",
      "    q        bcv",
      "    q        bcv",
      "    q        bcv",
      "    q        bcv",
      "s   q       Vbcv",
      "s   dyy    yybcv",
      "os  q        bcv",
      " s  q        bcv"
    ],
    [
      "WWWWXWWWWWWWWbcv",
      "WWWWXWYWWWYWWbcv",
      "WWWWXWYWWWYWWbcv",
      "WWWWXWYWWWZWWbcv",
      "WWWWXWYWWWYWWbcv",
      "WWWWXWWWWWWWWbcv",
      "WWWWdWWWWWWWWbcv",
      "WWWWXWWWWWWWWbcv",
      "WWWWXWYWWWYWWbcv",
      "WWWWXWYWWWYWWbcv",
      "WWWWXWYWWWYWWbcv",
      "WWWWXWYWWWYWWbcv",
      "0WWWXWWWWWWWWbcv",
      "0WWWdyyyyyyyybcv",
      "10WWXWWWWWWWWbcv",
      " 0WWXWYWWWYWWbcv"
    ]
  ]
}