{
  "name": "multi_flatapartment_2_top",
  "refpalette": "c70cities:multi_flatapartment_2_top_palette",
  "xsize": 16,
  "zsize": 16,
  "slices": [
    [
      "                ",
      "                ",
      "abbbbabbbabbbb  ",
      "cccccccccccccb  ",
      "cccccccccccccb  ",
      "ccccccccccccca  ",
      "cccccccccccccb  ",
      "cccccccccccccb  ",
      "cccccccccccccb  ",
      "cccccccccccccb  ",
      "ccccccccccccca  ",
      "cccccccccccccb  ",
      "cccccccccccccb  ",
      "abbbbabbbabbbb  ",
      "                ",
      "                "
    ],
    [
      "                ",
      "                ",
      "deeeedeeedeeef  ",
      "d    d   d   e  ",
      "             e  ",
      "           gdd  ",
      "         h h e  ",
      "          i  e  ",
      "         h hge  ",
      "             e  ",
      "            dd  ",
      "            ge  ",
      "d    d   d   e  ",
      "deeeedeeedeeef  ",
      "                ",
      "                "
    ],
    [
      "                ",
      "                ",
      "                ",
      "                ",
      "                ",
      "                ",
      "         iii    ",
      "           i    ",
      "         iii    ",
      "                ",
      "                ",
      "                ",
      "                ",
      "                ",
      "                ",
      "                "
    ],
    [
      "                ",
      "                ",
      "                ",
      "                ",
      "                ",
      "                ",
      "                ",
      "                ",
      "                ",
      "                ",
      "                ",
      "                ",
      "                ",
      "                ",
      "                ",
      "                "
    ],
    [
      "                ",
      "                ",
      "                ",
      "                ",
      "                ",
      "                ",
      "                ",
      "                ",
      "                ",
      "                ",
      "                ",
      "                ",
      "                ",
      "                ",
      "                ",
      "                "
    ],
    [
      "                ",
      "                ",
      "                ",
      "                ",
      "                ",
      "                ",
      "                ",
      "                ",
      "                ",
      "                ",
      "                ",
      "                ",
      "                ",
      "                ",
      "                ",
      "                "
    ]
  ]
}