{
  "name": "multi_megatower1_0_base2",
  "refpalette": "c70cities:multi_megatower1_0_base2_palette",
  "xsize": 16,
  "zsize": 16,
  "slices": [
    [
      "vvvvvvvvvvvvvvvv",
      "vaaaaaaaaaaaaaaa",
      "vaaaaaaaaaaaaaaa",
      "vaavvvvvvvvvvvvv",
      "vaavvvvvvvvvvvvv",
      "vaavvHHHHHHHHHHH",
      "vaavvHbHHHHHHbHH",
      "vaavvHHHHHHHHHHH",
      "vaavvHHHHHHHHHHH",
      "vaavvHHHHHHHHHHH",
      "vaavvHHHHHHHHHHH",
      "vaavvHHHHHHHHHHH",
      "vaavvHHHHHHHHHHH",
      "vaavvHbHHHHHHbvv",
      "vaavvHHHHHHHHvvv",
      "vaavvHHHHHHHHvvv"
    ],
    [
      "vvvvvvvvvvvvvvvv",
      "vaaaaaaaaaaaaaaa",
      "vaaaaaaaaaaaaaaa",
      "vaavvvvvvvvvvvvv",
      "vaavcccccccccccc",
      "vaavc   defef ef",
      "vaavc b dg   b  ",
      "vaavc   dhihijhi",
      "vaavckkk        ",
      "vaavce f        ",
      "vaavch i        ",
      "vaavce f        ",
      "vaavch i     l  ",
      "vaavc bm     bnn",
      "vaavce f     o  ",
      "vaavch i     o  "
    ],
    [
      "vvvvvvvvvvvvvvvv",
      "vaaaaaaaaaaaaaaa",
      "vaaaaaaaaaaaaaaa",
      "vaavvvvvvvvvvvvv",
      "vaav            ",
      "vaav            ",
      "vaav  b      b  ",
      "vaav            ",
      "vaav            ",
      "vaav            ",
      "vaav            ",
      "vaav            ",
      "vaav            ",
      "vaav  b      bnn",
      "vaav         opp",
      "vaav         opq"
    ],
    [
      "vvvvvvvvvvvvvvvv",
      "vaaaaaaaaaaaaaaa",
      "vaaaaaaaaaaaaaaa",
      "vaavvvvvvvvvvvvv",
      "vaav            ",
      "vaav            ",
      "vaav  b      b  ",
      "vaav            ",
      "vaav            ",
      "vaav            ",
      "vaav            ",
      "vaav            ",
      "vaav            ",
      "vaav  b      bnn",
      "vaav         opp",
      "vaav         opp"
    ],
    [
      "vvvvvvvvvvvvvvvv",
      "vaaaaaaaaaaaaaaa",
      "vaaaaaaaaaaaaaaa",
      "vaavvvvvvvvvvvvv",
      "vaav            ",
      "vaav  r      r  ",
      "vaav sb      b  ",
      "vaav            ",
      "vaav            ",
      "vaav            ",
      "vaav            ",
      "vaav            ",
      "vaav            ",
      "vaav sb      bnn",
      "vaav         t  ",
      "vaav         t  "
    ],
    [
      "vvvvvvvvvvvvvvvv",
      "vaaaaaaaaaaaaaaa",
      "vaaaaaaaaaaaaaaa",
      "vaavvvvvvvvvvvvv",
      "vaavvvvvvvvvvvvv",
      "vaavvuuuuuuuuuuu",
      "vaavvubbbbbbbbbb",
      "vaavvubuuuuuubuu",
      "vaavvubuuuuuubuu",
      "vaavvubuuuuuubuu",
      "vaavvubuuuuuubuu",
      "vaavvubuuuuuubuu",
      "vaavvubuuuuuubuu",
      "vaavvubbbbbbbbbb",
      "vaavvubuuuuuub  ",
      "vaavvubuuuuuub  "
    ]
  ]
}