{
  "name": "multi_militarybase_5_base1",
  "refpalette": "c70cities:multi_militarybase_5_base1_palette",
  "xsize": 16,
  "zsize": 16,
  "slices": [
    [
      " abbbcccccccccvv",
      " abbbcccccccccvv",
      "avaaaaaaavaaavvv",
      "babbbccccaccccvv",
      "babbbccccaccccvv",
      "babbcccccaccccvv",
      "dveccccccaccccvv",
      "cacccccccaccccvv",
      "cacccccccaccccvv",
      "cacccccccaccccvv",
      "avaaaaaaavaaavvv",
      "cacccccccaccccvv",
      "cacccccccaccccvv",
      "cacccccccaccccvv",
      "cvcccccccvccccvv",
      "vvvvvvvvvvvvvvvv"
    ],
    [
      " f    gg      vv",
      " f     h  ijjivv",
      "fv       vkkkvvv",
      "       h lm  nvv",
      "     hgghl  opvv",
      "      gg l   pvv",
      "qve   h  r   pvv",
      " k       l  spvv",
      "tk       l   pvv",
      " k       l   nvv",
      " vqqquqqqvkwkvvv",
      " k       k   xvv",
      " y       k   xvv",
      " k       k   xvv",
      "AvBCBCBCBvxxxxvv",
      "vvvvvvvvvvvvvvvv"
    ],
    [
      "              vv",
      "          iiiivv",
      " v       vkkkvvv",
      "         l    vv",
      "         l   DEv",
      "         l   FIv",
      "qv       J    Iv",
      " k       l   DIv",
      "tk       l    Ev",
      " k       l   Kvv",
      " vqqqLqqqvkMkvvv",
      " k       k   Nvv",
      " O       k   Cvv",
      " k       k   Nvv",
      "AvB B B BvNCN!vv",
      "vvvvvvvvvvvvvvvv"
    ],
    [
      "              vv",
      "          iPiPvv",
      " v       vkkkvvv",
      "         l    vv",
      "         l    Iv",
      "         l    Iv",
      "qvQ      l    Iv",
      " k       l    Ev",
      "tk       l    Iv",
      " k       l    vv",
      " vqqqqqqqvkkkvvv",
      " k       k   tvv",
      " k       k    vv",
      " k       k    vv",
      " vR R R Rvt   vv",
      "vvvvvvvvvvvvvvvv"
    ],
    [
      " S            vv",
      " S           Tvv",
      "Sv       vkkkvvv",
      "         f    vv",
      "         f    vv",
      "         f    vv",
      "qv       f    vv",
      " k       f    vv",
      "tk       f    vv",
      " k       f    vv",
      " vfffffffvkkkvvv",
      " k       k   tvv",
      " k       k    vv",
      " k       k    vv",
      " vU U U Uvt   vv",
      "vvvvvvvvvvvvvvvv"
    ],
    [
      "VaWWWWWWWWWWWtvv",
      "VaWWWWWWWWWWWtvv",
      "avaaaaaaavaaavvv",
      "WaWWWWWWWaWWWtvv",
      "WaWWWWWWWaWWWtvv",
      "WaWWWWWWWaWWWtvv",
      "XvWWWWWWWaWWWtvv",
      "WaWWWWWWWaWWWtvv",
      "taWWWWWWWaWWWtvv",
      "WaWWWWWWWaWWWtvv",
      "avaaaaaaavaaavvv",
      "WaWWWWWWWaWWWtvv",
      "WaWWWWWWWaWWWtvv",
      "WaWWWWWWWaWWWtvv",
      "tvtttttttvttttvv",
      "vvvvvvvvvvvvvvvv"
    ]
  ]
}