{
  "name": "multi_laboratory1_0_base7",
  "refpalette": "c70cities:multi_laboratory1_0_base7_palette",
  "xsize": 16,
  "zsize": 16,
  "slices": [
    [
      "vvvvvvvvvvvvvvvv",
      "vaaaaaaaaaaaabac",
      "vaaaaaaaaaaaaaca",
      "vaaaaaaaaaaaacaa",
      "vaaaaaaaaaaaacac",
      "vaaaaaaaaaacacac",
      "vaaaaaaaaaaaaccd",
      "vaaaaaaaaaaabdad",
      "vaaaaaaaaaabbcba",
      "vaaaaaaaaabbbecf",
      "vaaaaaaaacbbccff",
      "vaaaaaaaacbccbaa",
      "vaaaaaaaabcbbcaa",
      "vaaaaaaaccbbacaa",
      "vaaaaaaaccbaacaa",
      "vaaaaaacbbbaacaa"
    ],
    [
      "vvvvvvvvvvvvvvvv",
      "vaaaaaaaaaaaaaaa",
      "vaaaaaaaaaaagggg",
      "vaaaaaaaaaaaahij",
      "vaaaaaaaaaaad   ",
      "vaaaaaaaaadkl m ",
      "vaaaaaaaaaad    ",
      "vaaaaaaaaadn    ",
      "vaaaaaaaaod     ",
      "vaaaaaaaaaffd p ",
      "vaaaaaaaaaaaadqr",
      "vaaaaaaaaaaaafff",
      "vaaaaaaaaaaaaaaa",
      "vaaaaaaaafaaaaaa",
      "vaaaaaaafaaaaaaa",
      "vaaaafddfbaacaaa"
    ],
    [
      "vvvvvvvvvvvvvvvv",
      "vaaaaaaaaaaaaaaa",
      "vaaaaaaaaaaagggg",
      "vaaaaaaaaaaa    ",
      "vaaaaaaaaaad    ",
      "vaaaaaaaaa ks   ",
      "vaaaaaaaaf      ",
      "vaaaaaaafd      ",
      "vaaaaaaat       ",
      "vaaaaaaaad q    ",
      "vaaaaaaaaadft  u",
      "vaaaaaaaaaafff r",
      "vaaaaatddfaaaaff",
      "vaaaaaw dtfaaaaa",
      "vaaaaf   fcabaaa",
      "vaaaft   faabaaa"
    ],
    [
      "vvvvvvvvvvvvvvvv",
      "vaaaaaaaaaaaaaaa",
      "vaaaaaaaaaaagggg",
      "vaaaaaaaaaa     ",
      "vaaaaaaaaa      ",
      "vaaaaaaaaa k    ",
      "vaaaaaaafq      ",
      "vaaaaaaa        ",
      "vaaaaaaat       ",
      "vaaaaaaan    x  ",
      "vaaaaaaa   rt  y",
      "vaaaaaan  aaf xq",
      "vaaaaat  raaafff",
      "vaaaaa   tfaaaaa",
      "vaaaf    qfaaaaa",
      "vaaaat   bbbaaaa"
    ],
    [
      "vvvvvvvvvvvvvvvv",
      "vaaaaaaaaaaaaaaa",
      "vaaaaaaaaaaagggg",
      "vaaaaaaaaaaa    ",
      "vaaaaaaaaaao    ",
      "vaaaaaaaaack    ",
      "vaaaaaaaaeo     ",
      "vaaaaaaaf       ",
      "vaaaaaaat      x",
      "vaaaaaaao   oA  ",
      "vaaaaaaa   qaoxA",
      "vaaaaaa   aaaaaf",
      "vaaaaat  qaaaaaa",
      "vaaaaao  tfaaaaa",
      "vaaaaa    aaaaaa",
      "vaaaat   eaaaaaa"
    ],
    [
      "vvvvvvvvvvvvvvvv",
      "vaaaaaaaaaaaaaaa",
      "vaaaaaaaaaaagggg",
      "vaaaaaaaaaaa    ",
      "vaaaaaaaaaaa    ",
      "vaaaaaaaaaakoo  ",
      "vaaaaaaaaaaaaBoo",
      "vaaaaaaaaaaacafo",
      "vaaaaaaaaooaafaf",
      "vaaaaaaaaoaaafff",
      "vaaaaaaaaoaaaaff",
      "vaaaaaaaaaaaaaaa",
      "vaaaaaaaofaaaaaa",
      "vaaaaaaaaaaaaaaa",
      "vaaaaaaaaaaaaaaa",
      "vaaaaaaoaaaaaaaa"
    ]
  ]
}