{
  "name": "multi_pumpjack_3_ground",
  "refpalette": "c70cities:multi_pumpjack_3_ground_palette",
  "xsize": 16,
  "zsize": 16,
  "slices": [
    [
      "zzzzzzzzzzzzzzzz",
      "zzzzzzzzzzzzzzzz",
      "zzzzzzzzaazzzzzz",
      "zzzzzbzzazzzzzzz",
      "zbzzzzzbzzzzzzzz",
      "zzzzzzzzzzzzzzzz",
      "zazzzzzbzzzzzzzz",
      "zazzzzzzzzzzzzzz",
      "zbzzzbzzzzzzzzzz",
      "zzzzaaz!zzzzzzzz",
      "zzzzzzzzzzzzzzzz",
      "zzzzzzzzzzzzzzzz",
      "zccczczczcczcczz",
      "czccczccczcczzcz",
      "ccccccczzzzzcczz",
      "zzzzzzzzzzzzzzzz"
    ],
    [
      "de         fg   ",
      "dee        fg   ",
      "e          fd   ",
      " h i     ihhg   ",
      "  ifih  ififg   ",
      " hffffhfffffg   ",
      "h iiij  iiihd   ",
      "  iii hjiiihg   ",
      "j iik jjiik g   ",
      "jh l  h  lh g   ",
      "dggmdgggdmggd   ",
      "                ",
      "                ",
      "                ",
      "                ",
      "                "
    ],
    [
      "d           n   ",
      "d           n   ",
      "            d   ",
      "            n   ",
      "            n   ",
      "  o o   o o n   ",
      "            d   ",
      "   p     p  n   ",
      "  q k   q k n   ",
      "j  r     r  n   ",
      "dnnndnnndnnnd   ",
      "                ",
      "                ",
      "                ",
      "                ",
      "                "
    ],
    [
      "d           n   ",
      "d           n   ",
      "            d   ",
      "   s     s  n   ",
      "            n   ",
      "  o o   o o n   ",
      "            d   ",
      "   p     p  n   ",
      "    t       n   ",
      "            n   ",
      "dnnndnnndnnnd   ",
      "                ",
      "                ",
      "                ",
      "                ",
      "                "
    ],
    [
      "d               ",
      "d               ",
      "            u   ",
      "   s     s      ",
      "   w     w      ",
      "  owo   owo     ",
      "   w     w  u   ",
      "   w     w      ",
      "                ",
      "                ",
      "u   u   u   u   ",
      "                ",
      "                ",
      "                ",
      "                ",
      "                "
    ],
    [
      "d               ",
      "d               ",
      "                ",
      "                ",
      "                ",
      "                ",
      "                ",
      "                ",
      "                ",
      "                ",
      "                ",
      "                ",
      "                ",
      "                ",
      "                ",
      "                "
    ]
  ]
}