{
  "name": "multi_flatapartment_0_floor2",
  "refpalette": "c70cities:multi_flatapartment_0_floor2_palette",
  "xsize": 16,
  "zsize": 16,
  "slices": [
    [
      "                ",
      "     abbbbabbbab",
      "     bcccccccccc",
      "     bcddddddddd",
      "     bcddddddddd",
      "     acddddddddd",
      "     bcddddddddd",
      "     bcddddddddd",
      "     bcddddddddd",
      "     bcddddddddd",
      "     acddddddddd",
      "     bcddddddddd",
      "     bcddddddddd",
      "     bcccccccccc",
      "     abbbbabbbab",
      "                "
    ],
    [
      "                ",
      "     abeebabebab",
      "     b    f     ",
      "     e   gh iih ",
      "     b jk h   hl",
      "     ahhhmh   hh",
      "     b    n oohp",
      "     e    hhhhhp",
      "     e qq hr  s ",
      "     b ttuhwx h ",
      "     ahhhhhwx h ",
      "     byA  B   h ",
      "     eC  ghhhhh ",
      "     bD   E     ",
      "     abeebabebab",
      "                "
    ],
    [
      "                ",
      "     abFFbabFbab",
      "     b    I     ",
      "     F    h   h ",
      "     bJ   h   h ",
      "     ahhhKh   hh",
      "     b    L MMh ",
      "     F    hhhhh ",
      "     F    h!  N ",
      "     b    h   h ",
      "     ahhhhh   h ",
      "     b  O P   h ",
      "     F    hhhhh ",
      "     bJ   Q     ",
      "     abFFbabFbab",
      "                "
    ],
    [
      "                ",
      "     abFFbabFbab",
      "     b    h     ",
      "     F    h   h ",
      "     bR   h   h ",
      "     ahhhhh   hh",
      "     b    h MMh ",
      "     F    hhhhh ",
      "     F    h   h ",
      "     b    h   h ",
      "     ahhhhh   h ",
      "     b    h   h ",
      "     F    hhhhh ",
      "     bR   h     ",
      "     abFFbabFbab",
      "                "
    ],
    [
      "                ",
      "     abbbbabbbab",
      "     bSSSSh   h ",
      "     bSSSSh   h ",
      "     bSSSSh T h ",
      "     ahhhhh   hh",
      "     b    h   h ",
      "     b    hhhhh ",
      "     b    h   h ",
      "     b    h   h ",
      "     ahhhhh   hh",
      "     bSSSSh   h ",
      "     bSSSShhhhh ",
      "     bSSSSh   h ",
      "     abbbbabbbab",
      "                "
    ],
    [
      "                ",
      "     UVVVVUVVVUV",
      "     Vcccccccccc",
      "     Vcddddddddd",
      "     Vcddddddddd",
      "     Ucddddddddd",
      "     Vcddddddddd",
      "     Vcddddddddd",
      "     Vcddddddddd",
      "     Vcddddddddd",
      "     Ucddddddddd",
      "     Vcddddddddd",
      "     Vcddddddddd",
      "     Vcccccccccc",
      "     UVVVVUVVVUV",
      "                "
    ]
  ]
}