{
  "name": "multi_condo1_5_base1",
  "refpalette": "c70cities:multi_condo1_5_base1_palette",
  "xsize": 16,
  "zsize": 16,
  "slices": [
    [
      "HHHHHHHHHHHHabbv",
      "HHHHHHaccaaaabbv",
      "HHHHHHaccaddabbv",
      "HHHHHHa  addabbv",
      "HHHHHHa  a  abbv",
      "HHHHHHa  a  abbv",
      "HHHHHHa  a  abbv",
      "HHHHHHa  a  abbv",
      "HHHHHHa  a  abbv",
      "HHHHHHa  a  abbv",
      "HHHHHHa  a  abbv",
      "HHHHHHa     abbv",
      "HHHHHHa     abbv",
      "aaaaaaaaaaaaabbv",
      "bbbbbbbbbbbbbbbv",
      "vvvvvvvvvvvvvvvv"
    ],
    [
      "            abbv",
      "efeg  a  accabbv",
      "   g  a  accabbv",
      "hihg  a  aHHabbv",
      "jjjg  a  aHHabbv",
      "efeg  a  aHHabbv",
      "   g  a  addabbv",
      "hihg  a  addabbv",
      "      a  a  abbv",
      "      a  a  abbv",
      "efefega  a  abbv",
      "     ga     abbv",
      "hihihga     abbv",
      "aaaaaaaaaaaaabbv",
      "bbbbbbbbbbbbbbbv",
      "vvvvvvvvvvvvvvvv"
    ],
    [
      "            abbv",
      "      a  a  abbv",
      "      a  a  abbv",
      "      a  a  abbv",
      "      a  a  abbv",
      "      a  accabbv",
      "      a  accabbv",
      "      a  aHHabbv",
      "      a  aHHabbv",
      "      a  aHHabbv",
      "      a  addabbv",
      "      a   ddabbv",
      "      a     abbv",
      "aaaaaaaaaaaaabbv",
      "bbbbbbbbbbbbbbbv",
      "vvvvvvvvvvvvvvvv"
    ],
    [
      "      k     abbv",
      "      a  a  abbv",
      "      a  a  abbv",
      "      a  a  abbv",
      "      a  a  abbv",
      "      a  a  abbv",
      "      a  a  abbv",
      "      a  a  abbv",
      "      adda  abbv",
      "      addaccabbv",
      "      aHHaccabbv",
      "      aHHHHHabbv",
      "      aHHHHHabbv",
      "aaaaaaaaaaaaabbv",
      "bbbbbbbbbbbbbbbv",
      "vvvvvvvvvvvvvvvv"
    ],
    [
      "     la     abbv",
      "     la  a  abbv",
      "lllll!a  a  abbv",
      "     la  a  abbv",
      "     ladda  abbv",
      "     ladda  abbv",
      "     laHHa  abbv",
      "     laHHa  abbv",
      "     laHHa  abbv",
      "     lacca  abbv",
      "     lacca  abbv",
      "     la     abbv",
      "lllllla     abbv",
      "aaaaaaaaaaaaabbv",
      "bbbbbbbbbbbbbbbv",
      "vvvvvvvvvvvvvvvv"
    ],
    [
      "mmmmmma     abbv",
      "mmmmmmaaaaaaabbv",
      "mmmmmmaHHa  abbv",
      "mmmmmmaHHa  abbv",
      "mmmmmmaHHa  abbv",
      "mmmmmmacca  abbv",
      "mmmmmmacca  abbv",
      "mmmmmma  a  abbv",
      "mmmmmma  a  abbv",
      "mmmmmma  a  abbv",
      "mmmmmma  a  abbv",
      "mmmmmma     abbv",
      "mmmmmma     abbv",
      "aaaaaaaaaaaaabbv",
      "bbbbbbbbbbbbbbbv",
      "vvvvvvvvvvvvvvvv"
    ]
  ]
}