{
  "name": "multi_megatower1_3_floor8",
  "refpalette": "c70cities:multi_megatower1_3_floor8_palette",
  "xsize": 16,
  "zsize": 16,
  "slices": [
    [
      "                ",
      "                ",
      "                ",
      "                ",
      "                ",
      "                ",
      "                ",
      "                ",
      "                ",
      "                ",
      "                ",
      "abbbcaaabbbcaaab",
      "ddddeddddddedddd",
      "ffffgffffffgffff",
      "hiiif===========",
      "h   f==========="
    ],
    [
      "                ",
      "                ",
      "                ",
      "                ",
      "                ",
      "                ",
      "                ",
      "                ",
      "                ",
      "                ",
      "                ",
      "abbbcaaabbbcaaab",
      "    e      e    ",
      "jklmgnnnnnngnnnn",
      "hiiihzzzzozzpzoo",
      "h   hzzozqzoz!zz"
    ],
    [
      "                ",
      "                ",
      "                ",
      "                ",
      "                ",
      "                ",
      "                ",
      "                ",
      "                ",
      "                ",
      "                ",
      "abbbcaaabbbcaaab",
      "    e      e    ",
      "j   gnnnnnngnnnn",
      "hiiihrsrt qq ruq",
      "h   h rurtqurtsr"
    ],
    [
      "                ",
      "                ",
      "                ",
      "                ",
      "                ",
      "                ",
      "                ",
      "                ",
      "                ",
      "                ",
      "                ",
      "  bbcaaabbbcaaab",
      "    e      e    ",
      "j   gnnnnnngnnnn",
      "hiiiht    tqt   ",
      "h   h         ~ "
    ],
    [
      "                ",
      "                ",
      "                ",
      "                ",
      "                ",
      "                ",
      "                ",
      "                ",
      "                ",
      "                ",
      "                ",
      "  bbc aabb caaab",
      "    e      e    ",
      "j   gnnnnnngnnnn",
      "hiiihtt    tt   ",
      "h   h           "
    ],
    [
      "                ",
      "                ",
      "                ",
      "                ",
      "                ",
      "                ",
      "                ",
      "                ",
      "                ",
      "                ",
      "                ",
      "  b c aabb caa  ",
      "    e      e    ",
      "wwwwgwwwwwwgwwww",
      "xyyyxAAAAAAxAAAA",
      "x   xAAAAAAxAAAA"
    ]
  ]
}