{
  "name": "multi_megatower1_0_ground",
  "refpalette": "c70cities:multi_megatower1_0_ground_palette",
  "xsize": 16,
  "zsize": 16,
  "slices": [
    [
      "HHHGaGGGGaGGGGaG",
      "HHHGGaaGaGaaGaaa",
      "HHHGGGaGGGGGGaGG",
      "HHHvvvvvvvvvvvvv",
      "HHHvvvvvvvvvvvvv",
      "HHHvvvvvvvvvvvvv",
      "HHHvvvbvvvvvvbvv",
      "HHHvvvvvvvvvvvvv",
      "HHHvvvvvvvvvvvvv",
      "HHHvvvvvvvvvvvvv",
      "HHHvvvvvvvvvvvvv",
      "HHHvvvvvvvvvvvvv",
      "HHHvvvvvvvvvvvvv",
      "HHHvvvbvvvvvvbvv",
      "HHHvvvvvvvvvvv  ",
      "HHHvvvvvvvvvvv  "
    ],
    [
      "                ",
      "                ",
      "   c d dddddc dd",
      "   eeefeeeeeefee",
      "   e!g       hij",
      "   eg       ig h",
      "  kfg bllllllbll",
      "   e  mnoooopm q",
      "   e  m    r m  ",
      "   e  ms     mt ",
      "   e  m      luw",
      "   e  m      x  ",
      "   e  m     ylgA",
      "  kf  bBCBBBBbBB",
      "   e  mD EEFFI  ",
      "   e  J      I  "
    ],
    [
      "                ",
      "                ",
      "                ",
      "   eeefeeeeeefee",
      "   eg           ",
      "   e            ",
      "   f  bllllllbll",
      "   e  mKLKMKKm N",
      "   e  m      m  ",
      "   e  m      m  ",
      "   e  m      luO",
      "   e  m      P  ",
      "   e  m      l  ",
      "   f  bBQBBBBbBB",
      "   e  m    RSITT",
      "   e  U      ITV"
    ],
    [
      "                ",
      "                ",
      "      W      W  ",
      "   eeefeeeeeefee",
      "   eg g         ",
      "   e         g  ",
      "   f  bllllllbll",
      "   e  mMMLKMLm  ",
      "   e  m      m  ",
      "   e  m      m  ",
      "   e  m      luu",
      "   e  m     Xl  ",
      "   e  m      l  ",
      "   f  bBBBBBBbBB",
      "   e  m Y   ZITT",
      "   e  m      ITT"
    ],
    [
      "                ",
      "                ",
      "                ",
      "   eeefeeeeeefee",
      "   e  g     g0  ",
      "   e  g     ggg ",
      "   f  bllllllbll",
      "   e  mKKMKKKl  ",
      "   e  m      l  ",
      "   e  m      l  ",
      "   e  m      l11",
      "   e  m      l  ",
      "   e  m      lg ",
      "   f  b111111bBB",
      "   e  1      1  ",
      "   e  1      1  "
    ],
    [
      "                ",
      "                ",
      "                ",
      "   eeefeeeeeefee",
      "   e22b222222b22",
      "   e22b222222b22",
      "  2fbbbbbbbbbbbb",
      "  2122b222222bll",
      "  2122b222222bll",
      "  2122b222222bll",
      "  2122b222222bll",
      "  2122b222222b22",
      "  2122b222222b22",
      "  2fbbbbbbbbbbbb",
      "   e22b222222b  ",
      "   e22b222222b  "
    ]
  ]
}