{
  "name": "multi_megatower1_4_floor4",
  "refpalette": "c70cities:multi_megatower1_4_floor4_palette",
  "xsize": 16,
  "zsize": 16,
  "slices": [
    [
      "a   bbbbbbbbbbbb",
      "a   bbbbbbbbbbbb",
      "a   bbbbbbbbbbbb",
      "cdeebbbbbbbbbbbb",
      "bbbbfbbbbbbfbbbb",
      "bbbbbbbbbbbbbbbb",
      "gggggggggggggggg",
      "gggggggggggggggg",
      "gggggggggggggggg",
      "gggggggggggggggg",
      "bbbbbbbbbbbbbbbb",
      "bbbbfbbbbbbfbbbb",
      "bbbbbbbbbbbbbbbb",
      "bbbbbbbbbbbbbbbb",
      "bbbbbbbbbbbbbbbb",
      "bbbbbbbbbbbbbbbb"
    ],
    [
      "a   ah  ijklmn  ",
      "a   aoi  iplp   ",
      "a   aqq rqqlqqsi",
      "aettauw r xly s ",
      "ABCDfEF I rfs J ",
      "     KF rLrMsLs ",
      "     NNONNN NNNP",
      "                ",
      "                ",
      "QRQQ QQSQQQ QQQR",
      "s TUMKF rVrMsVs ",
      "W TEfEF X rfs W ",
      "siwuluw r xly s ",
      "siYYlYY rYYlYYsi",
      "   Zlo    plpi i",
      " ii0lh   jklmn  "
    ],
    [
      "a   a      l    ",
      "a   a     1l2   ",
      "a   aqq rqqlqqs ",
      "ae  a   r 3l4 s ",
      "A 56f7F 8 rfs 9 ",
      "     KF r rMs s ",
      "     NN@NNN NNN#",
      "                ",
      "                ",
      "Q$QQ QQ%QQQ QQQ$",
      "s TUMKF r rMs s ",
      "^ T7f7F & rfs ^ ",
      "s  !l   r 3l4 s ",
      "s YYlYY rYYlYYs ",
      "    l     *l(   ",
      "    l      l    "
    ],
    [
      "a   a      l    ",
      "a   a      l    ",
      "a   aqq rqqlqqs ",
      "aeeea   r  l )s ",
      "A+  fK  r rfs s ",
      "     K- r rMs s ",
      "     NN[NNN NNN[",
      "                ",
      "                ",
      "Q]QQ QQ]QQQ QQQ]",
      "s  UMK  r rMs s ",
      "s  UfK  r rfs s ",
      "s  -l-  r  l  s ",
      "s YYlYY rYYlYYs ",
      "    l      l    ",
      "    l      l    "
    ],
    [
      "a   a      l    ",
      "a   a-     l-   ",
      "a   aqq rqqlqqs ",
      "aeeea   r -l {s ",
      "AAAAfK  r rfs s-",
      "     K- r r}s s ",
      "     NNNNNN\\NNNN",
      "                ",
      "                ",
      "QQQQ|QQQQQQ|QQQQ",
      "s -U}K  r-r!s s ",
      "s  UfK  r rfs s ",
      "s --l-  r -l- s ",
      "s YYlYY rYYlYYs ",
      "    l      l    ",
      "    l      l    "
    ],
    [
      "`   `-     `    ",
      "`   `-     `    ",
      "`   `bbbbbb`bbbb",
      "`e:;`bbbbbb`bbbb",
      "''''f''''''f''''",
      ",,,,`bbbbbb`bbbb",
      ",,,,`......`....",
      ",,,,`,,,,,,`,,,,",
      ",,,,`,,,,,,`,,,,",
      "////`//////`////",
      "bbbb`bbbbbb`bbbb",
      "''''f''''''f''''",
      "bbbb`bbbbbb`bbbb",
      "bbbb`bbbbbb`bbbb",
      "   -`      `    ",
      "    `      `    "
    ]
  ]
}