{
  "name": "multi_condo1_4_floor6",
  "refpalette": "c70cities:multi_condo1_4_floor6_palette",
  "xsize": 16,
  "zsize": 16,
  "slices": [
    [
      "aaaaabccccccde  ",
      "fffgabcddddddhh ",
      "iiijabckkkkkde  ",
      "iiijabckkkkkde  ",
      "iiijabckkkkkde  ",
      "iiijabckkkkkdhh ",
      "iiijabcdddddde  ",
      "iiijabc     ce  ",
      "iiijabc     ce  ",
      "iiijabc     de  ",
      "iiijabl     dhh ",
      "iiijabmdddddde  ",
      "iiijabccj   de  ",
      "iiijabccn   de  ",
      "ooopabcddddddhh ",
      "aaaaabcccqqqde  "
    ],
    [
      "      r  stud   ",
      "wwww  dddddddhh ",
      "   w  x     d   ",
      "   w  d     y   ",
      "   w  d  AB d   ",
      "   w  dCDEE dhh ",
      "   w  ddddddd   ",
      "   w  d     F   ",
      "   w  I     F   ",
      "   w  J     d   ",
      "   w Kd     dhh ",
      "   w  ddddddd   ",
      "   w  d     y   ",
      "   w  L Mn  d   ",
      "wwww  dddddddhh ",
      "      r NdOPd   "
    ],
    [
      "      Q RS  d   ",
      "      dddddddhh ",
      "      T     d   ",
      "      dU    V   ",
      "      d  WX d   ",
      "      dYYEE dhh ",
      "      ddddddd   ",
      "      d     F   ",
      "      Z     F   ",
      "      0     d   ",
      "      d     dhh ",
      "      ddddddd   ",
      "      d     V   ",
      "      1  Mn d   ",
      "      dddddddhh ",
      "      Q  d  d   "
    ],
    [
      "            d   ",
      "      dddddddhh ",
      "      2     d   ",
      "      d     V   ",
      "      d     d   ",
      "      dY 33 dhh ",
      "      ddddddd   ",
      "     4d     F   ",
      "      2     F   ",
      "      2     d   ",
      "     5d     dhh ",
      "      ddddddd   ",
      "      d   2nV   ",
      "      2   Mcd   ",
      "      dddddddhh ",
      "         d  d   "
    ],
    [
      "            d   ",
      "      dddddddhh ",
      "      d     d   ",
      "      d     d   ",
      "      dC    d   ",
      "      dY    dhh ",
      "      ddddddd   ",
      "     6d     F   ",
      "      d     F   ",
      "      d     d   ",
      "     6d     dhh ",
      "      ddddddd   ",
      "      d  2j d   ",
      "      d     d   ",
      "      dddddddhh ",
      "         d  d   "
    ],
    [
      "      777777d   ",
      "      dddddddhh ",
      "      dY    d   ",
      "      dY    d   ",
      "      dY    d   ",
      "      dYYYYYdhh ",
      "      ddddddd   ",
      "      d     F   ",
      "      d     F   ",
      "      d     d   ",
      "      d     dhh ",
      "      ddddddd   ",
      "      d 2j  d   ",
      "      d     d   ",
      "      dddddddhh ",
      "      777dkkd   "
    ]
  ]
}