{
  "name": "multi_communitycenter_2_floor1",
  "refpalette": "c70cities:multi_communitycenter_2_floor1_palette",
  "xsize": 16,
  "zsize": 16,
  "slices": [
    [
      "    aabbbbbcdeee",
      "     abbbbbbceee",
      "     aabbbbbccee",
      "      abbbbbbccd",
      "      aabbbbbbbc",
      "       aafbbbbbb",
      "        aafbbbbb",
      "         aabbbbb",
      "          aabbbb",
      "           aaabb",
      "  ggg        aaa",
      " ggggg         a",
      " gghgg          ",
      " ggggg          ",
      "  ggg           ",
      "                "
    ],
    [
      "    iijk  klm   ",
      "     ijj   kl   ",
      "     iijn   ll  ",
      "      ijjk  kllm",
      "      iijjn   kl",
      "       iijjo n o",
      "        iijj    ",
      "         iijjn k",
      "          iijjj ",
      "           iiijj",
      "             iii",
      "   g           i",
      "  ghg           ",
      "   g            ",
      "                ",
      "                "
    ],
    [
      "                ",
      "                ",
      "                ",
      "                ",
      "                ",
      "                ",
      "                ",
      "                ",
      "                ",
      "                ",
      "  ggg           ",
      " ggggg          ",
      " gghgg          ",
      " ggggg          ",
      "  ggg           ",
      "                "
    ],
    [
      "                ",
      "                ",
      "                ",
      "                ",
      "                ",
      "                ",
      "                ",
      "                ",
      "                ",
      "                ",
      "                ",
      "   g            ",
      "  ggg           ",
      "   g            ",
      "                ",
      "                "
    ],
    [
      "                ",
      "                ",
      "                ",
      "                ",
      "                ",
      "                ",
      "                ",
      "                ",
      "                ",
      "                ",
      "                ",
      "                ",
      "   g            ",
      "                ",
      "                ",
      "                "
    ],
    [
      "                ",
      "                ",
      "                ",
      "                ",
      "                ",
      "                ",
      "                ",
      "                ",
      "                ",
      "                ",
      "                ",
      "   g            ",
      "  ggg           ",
      "   g            ",
      "                ",
      "                "
    ]
  ]
}