{
  "name": "multi_gasstation_0_ground",
  "refpalette": "c70cities:multi_gasstation_0_ground_palette",
  "xsize": 16,
  "zsize": 16,
  "slices": [
    [
      "GGGGGGGGGGGGGGGG",
      "HHHHHHHHHHHHHaGG",
      "HHHHHHHHHHHHHaGG",
      "HHHHHHHHHHHHHaGG",
      "bHHHHHHHHHHHHaGG",
      "bHHHHHHHHHHHHaGG",
      "HHHHHHHHHHHHHaGG",
      "HHHHbHHbbbbbbbGG",
      "HHHHbHHbbbbbbbGG",
      "HHHHbHHbbbbbbbGG",
      "HHHHbHHbbbbbbbGG",
      "HHHHbHHbbbbbbbGG",
      "HHHHbHHbbbbbbbGG",
      "HHHHbHHbbbbbbbGG",
      "HHHHbHHbbbbbbbGG",
      "HHHHbHHbbbbbbbGG"
    ],
    [
      "                ",
      "             c  ",
      "             c  ",
      "             c  ",
      "d      efefefc  ",
      "g            c  ",
      " g     hihihic  ",
      "    j  kkkkkkk  ",
      "  lmn  k okp k  ",
      "       k  k  k  ",
      "  qrj  kskkktk  ",
      "  lmc  k uuu k  ",
      "       k     k  ",
      "  qrj  k     k  ",
      "  lmc  kkwkkkk  ",
      "       x  yyyk  "
    ],
    [
      "                ",
      "                ",
      "                ",
      "                ",
      "g               ",
      "d               ",
      "                ",
      "    j  kkkkkkk  ",
      "    A  k BkC k  ",
      "       k  k  k  ",
      "    j  kDkkkEk  ",
      "       k     k  ",
      "       k     k  ",
      "    j  k     k  ",
      "       kkFkkkk  ",
      "       x  IIIk  "
    ],
    [
      "                ",
      "                ",
      "                ",
      "                ",
      "g               ",
      "                ",
      "                ",
      "    j  JJJJJJJ  ",
      "       K  J  K  ",
      "       K  J  K  ",
      "    j  JJJJJJJ  ",
      "       J     J  ",
      "       K     K  ",
      "    j  K     K  ",
      "       JJJJJJJ  ",
      "       J  LMNK  "
    ],
    [
      "                ",
      "                ",
      "                ",
      "                ",
      "                ",
      "                ",
      "                ",
      "    kO kkkkkkk  ",
      "       kPPkPPk  ",
      "       kPPkPPk  ",
      "    kQ kkkkkkk  ",
      "       kPPPPPk  ",
      "       kPPPPPk  ",
      "    kO kPPQPPk  ",
      "       kkkkkkk  ",
      "       k   R k  "
    ],
    [
      "                ",
      "                ",
      "                ",
      "                ",
      "                ",
      "                ",
      " SSSSSSSSSSSSSS ",
      " SccbbbbbbbbbbS ",
      " SccbccccccccbS ",
      " SccbccccccccbS ",
      " SccbccccccccbS ",
      " SccbccccccccbS ",
      " SccbccccccccbS ",
      " SccbccccccccbS ",
      " SccbbbbbbbbbbS ",
      " SccbccccccccbS "
    ]
  ]
}