{
  "name": "multi_laboratory1_14_base1",
  "refpalette": "c70cities:multi_laboratory1_14_base1_palette",
  "xsize": 16,
  "zsize": 16,
  "slices": [
    [
      "aaaabaaaaaaaacdz",
      "aaaaaaaaaaaaacdz",
      "aaaaaaaaaaaaacdz",
      "aaaaaaaaaaaaacdz",
      "aaaaaaaaaaaaacdz",
      "aaaaaaaaaaaaacdz",
      "aaaaaaaaaaaaacdz",
      "aaaabaaaaaaaacdz",
      "aaaaaeeeeeeeecdz",
      "aaaaaeeeeeeeecdz",
      "aaaaaeeeeeeeecdz",
      "aaaaaeeeeeeeecdz",
      "aaaaaee!eeeeecdz",
      "ccccccccccccccdz",
      "dddddddddddddddz",
      "zzzzzzzzzzzzzzzz"
    ],
    [
      "    b       fcdz",
      "    g   h   fcdz",
      "    g  iii  jcdz",
      "    k       lcdz",
      "    g  mmm  jcdz",
      "    g  h h  lcdz",
      "    g      nlcdz",
      "o   bppppppppcdz",
      "q   prrssssrrcdz",
      "q   t        cdz",
      "q   puwuwxwuwcdz",
      "q   p y y y ycdz",
      "!qqopAyAyAyAycdz",
      "ccccccccccccccdz",
      "dddddddddddddddz",
      "zzzzzzzzzzzzzzzz"
    ],
    [
      "    b        cdz",
      "    g        cdz",
      "    g  B C  Dcdz",
      "    E        cdz",
      "    g  F I   cdz",
      "    g       Jcdz",
      "    g K     Dcdz",
      "L   bppppppppcdz",
      "    pM NNNNNMcdz",
      "    O        cdz",
      "P   pQwQwRwQwcdz",
      "S   p y y y ycdz",
      "LTULp y y y ycdz",
      "ccccccccccccccdz",
      "dddddddddddddddz",
      "zzzzzzzzzzzzzzzz"
    ],
    [
      "    b        cdz",
      "    g        cdz",
      "    g       Vcdz",
      "    g       Wcdz",
      "    g        cdz",
      "    g       Vcdz",
      "    g       Wcdz",
      "M   bppppppppcdz",
      "    p N  NN  cdz",
      "    p        cdz",
      "    pwwwwwwwwcdz",
      "    p y y y ycdz",
      "MX Mp y y y ycdz",
      "ccccccccccccccdz",
      "dddddddddddddddz",
      "zzzzzzzzzzzzzzzz"
    ],
    [
      "    b        cdz",
      "    g        cdz",
      "    g        cdz",
      "    g       Ycdz",
      "    g        cdz",
      "    g       Zcdz",
      "    g       !cdz",
      "    bppppppppcdz",
      "    p00000000cdz",
      "    p00000000cdz",
      "    p00000000cdz",
      "    p00000000cdz",
      "    p10101010cdz",
      "ccccccccccccccdz",
      "dddddddddddddddz",
      "zzzzzzzzzzzzzzzz"
    ],
    [
      "2222b22222222cdz",
      "2222322222222cdz",
      "2222324222422cdz",
      "2222324222422cdz",
      "2222324222422cdz",
      "2222324222422cdz",
      "2222322222222cdz",
      "2222bppppppppcdz",
      "2222p55555555cdz",
      "2222p5 5 5 5ccdz",
      "2222p5 5 5 5ccdz",
      "2222p5 5 5 5ccdz",
      "2222p5 5 5 5ccdz",
      "ccccccccccccccdz",
      "dddddddddddddddz",
      "zzzzzzzzzzzzzzzz"
    ]
  ]
}