{
  "name": "multi_pumpjack_1_floor1",
  "refpalette": "c70cities:multi_pumpjack_1_floor1_palette",
  "xsize": 16,
  "zsize": 16,
  "slices": [
    [
      "  abcdefgbhhhhib",
      "  abjjjjjjjjjjjj",
      "   jkl   k    kj",
      "   jm    m    mj",
      "   jn    o    oj",
      "   jo    o    oj",
      "   jm    m    mj",
      "   jk    k    kj",
      "   jk    k    kj",
      "   jpppppppppppj",
      "   jbbbbbbbbbbbj",
      "   qrrrrrrrrrrrq",
      "   qqqqqqqqqqqqq",
      "                ",
      "                ",
      "                "
    ],
    [
      "  absltuwbl   ib",
      "  abjjjjjjjjjjjj",
      "   jxxyxxxxxyxxj",
      "   jx         xj",
      "   jx         xj",
      "   jxpppppppppxA",
      "   jxpppppppppxA",
      "   qrrrrrrrrrrrq",
      "   qrrrrrrrrrrrq",
      "                ",
      "                ",
      "                ",
      "                ",
      "                ",
      "                ",
      "                "
    ],
    [
      "  absBBBBbxxxxib",
      "  abbbbbbbbbbbjb",
      "   jjjjjjjjjjjjj",
      "   qrrrrrrrrrrrq",
      "   qrrrrrrrrrrrq",
      "    x         x ",
      "    y         y ",
      "                ",
      "         ~      ",
      "                ",
      "                ",
      "                ",
      "                ",
      "                ",
      "                ",
      "                "
    ],
    [
      "  aaCCCCCabbbbDb",
      "  aaaaaaaaaaaaaa",
      "                ",
      "                ",
      "                ",
      "    E         E ",
      "                ",
      "                ",
      "         ~      ",
      "                ",
      "                ",
      "                ",
      "                ",
      "                ",
      "                ",
      "                "
    ],
    [
      " qqaaaaaaa      ",
      " qqqqqqqqqqqqqqq",
      " qqqqqqqqqqqqqqq",
      "                ",
      "                ",
      "                ",
      "                ",
      "                ",
      "         ~      ",
      "                ",
      "                ",
      "                ",
      "                ",
      "                ",
      "                ",
      "                "
    ],
    [
      "                ",
      "                ",
      "                ",
      "                ",
      "                ",
      "                ",
      "                ",
      "                ",
      "         ~      ",
      "                ",
      "                ",
      "                ",
      "                ",
      "                ",
      "                ",
      "                "
    ]
  ]
}