{
  "name": "multi_condo1_5_floor6",
  "refpalette": "c70cities:multi_condo1_5_floor6_palette",
  "xsize": 16,
  "zsize": 16,
  "slices": [
    [
      "aaaaabcccdddef  ",
      "cccccccccdddef  ",
      "cccccccccdddeggg",
      "cccccccccdddehi ",
      "cccccccccdddehi ",
      "cccccccccdddehi ",
      "cccccccccdddehi ",
      "cccccccccdddehi ",
      "cccccccccdddehi ",
      "ccccccccccccehi ",
      "ccccccccccccehi ",
      "ccccceeeeeeeehi ",
      "ggggggghhhhhhhi ",
      "gggggggiiiiiiii ",
      "ggggggg         ",
      "                "
    ],
    [
      "         j  k   ",
      "llllleeemeeee   ",
      " n oopeq erseggg",
      "n     et j !eh  ",
      "   oopet eeeeh  ",
      "      et j  eh  ",
      "u  oopet eeeeh  ",
      "w    xeq j  eh  ",
      "y    eee eeeeh  ",
      "            eh  ",
      "      ABC BCeh  ",
      "     eeeDDDeeh  ",
      "      ghhhhhhh  ",
      "EEEEEEg         ",
      "      g         ",
      "                "
    ],
    [
      "         F  E   ",
      "llllleeeIeeee   ",
      "      eJ e  eggg",
      "     Ke  F Le   ",
      "      e  eeee   ",
      "     Ke  F Le   ",
      "      e  eeee   ",
      "      eM F Le   ",
      "N   Keee eeee   ",
      "            e   ",
      "      O     e   ",
      "     eeelllee   ",
      "      g         ",
      "      g         ",
      "      g         ",
      "                "
    ],
    [
      "         e  E   ",
      "llllleeePeeee   ",
      "      e  e  eggg",
      "      e  e Qe   ",
      "      eR eeee   ",
      "      e  e Qe   ",
      "      e  eeee   ",
      "      e  e Qe   ",
      "     eeeSeeee   ",
      "            e   ",
      "            e   ",
      "     eeelllee   ",
      "      g         ",
      "      g         ",
      "      g         ",
      "                "
    ],
    [
      "         e  e   ",
      "llllleeeeeeee   ",
      "      e  e  eggg",
      "      e  e  eT  ",
      "      e  eeeeT  ",
      "      e  e  eT  ",
      "      e  eeeeT  ",
      "      e  e  eT  ",
      "llllleeeeeeeeT  ",
      "            eT  ",
      "            eT  ",
      "eeeeeeeeeeeeeT  ",
      "UUUUUUgTTTTTTT  ",
      "      g         ",
      "      g         ",
      "                "
    ],
    [
      "      VVVeWWe   ",
      "PPPPPeeeeeeee   ",
      "aaaaaaeWWeWWeggg",
      "aaaaaaeWWeWWeX  ",
      "aaaaaaeWWeeeeX  ",
      "aaaaaaeWWeWWeX  ",
      "aaaaaaeWWeeeeX  ",
      "aaaaaaeWWeWWeX  ",
      "SSSSSeeeeeeeeX  ",
      "aaaaaaaaaaaaeX  ",
      "aaaaaaaaaaaaeX  ",
      "eeeeeeeeeeeeeX  ",
      "e     gXXXXXXX  ",
      "YYYYYYg         ",
      "      g         ",
      "                "
    ]
  ]
}