{
  "name": "multi_laboratory1_7_base3",
  "refpalette": "c70cities:multi_laboratory1_7_base3_palette",
  "xsize": 16,
  "zsize": 16,
  "slices": [
    [
      "                ",
      "                ",
      "                ",
      " a              ",
      "                ",
      "b    a         b",
      "b              b",
      "bc            cb",
      "dbbb        bbbd",
      "dddbbc    cbbddd",
      "dddddbbbbbbddddd",
      "dddddddddddddddd",
      "dddddddddddddddd",
      "dddddddddddddddd",
      "dddddddddddddddd",
      "dddddddddddddddd"
    ],
    [
      "                ",
      "                ",
      "                ",
      " a              ",
      "                ",
      "e    a         e",
      "e              e",
      "ec            ce",
      " eee        eee ",
      "f  eec    cee f ",
      "ggfhceeeeeecifgg",
      "ggj kl! mmm   gg",
      "  nf  ojp q    f",
      "     jn         ",
      "     r          ",
      "                "
    ],
    [
      "                ",
      "                ",
      "                ",
      " a              ",
      "                ",
      "e    a         e",
      "e              e",
      "ec            ce",
      " eee        eee ",
      "   eec    cee   ",
      "j   seeeeeet  u ",
      "        wx      ",
      "                ",
      "                ",
      "                ",
      "                "
    ],
    [
      "                ",
      "                ",
      "                ",
      " a              ",
      "                ",
      "e    a         e",
      "e              e",
      "ec            ce",
      " eee        eee ",
      "   eec    cee   ",
      "     eeeeeet    ",
      "                ",
      "                ",
      "                ",
      "                ",
      "                "
    ],
    [
      "                ",
      "                ",
      "                ",
      " a              ",
      "                ",
      "e    a         e",
      "e              e",
      "ec            ce",
      " eee        eee ",
      "   eec    cee   ",
      "     eeeeee     ",
      "                ",
      "                ",
      "                ",
      "                ",
      "                "
    ],
    [
      "                ",
      "                ",
      "                ",
      " a              ",
      "                ",
      "e    a         e",
      "e              e",
      "ec            ce",
      "yeee        eeey",
      "yyyeec    ceeyyy",
      "yyyyyeeeeeeyyyyy",
      "yyyyyyyyyyyyyyyy",
      "yyyyyyyyyyyyyyyy",
      "yAyyy yyyyAyyyAy",
      "yAyyy yyyyAyyyAy",
      "yAyyyAyyyyAyyyAy"
    ]
  ]
}