{
  "name": "multi_residential2_1_ground",
  "refpalette": "c70cities:multi_residential2_1_ground_palette",
  "xsize": 16,
  "zsize": 16,
  "slices": [
    [
      "GGGGabaccGcbGGGG",
      "GGGGcGGccabGGGGG",
      "GGGGGGcbcbcbGGGG",
      "GGGGcbGcabbcGGGG",
      "GGddddddddddddGG",
      "ddddddddddddddGG",
      "dddddHHHeeedddGG",
      "dddddHHHfghdddGG",
      "dddddHHHijkdddGG",
      "dddddHHHlmndddGG",
      "ddddddddddddddGG",
      "GGddddddddddddGG",
      "GGGGGGGGGGGGGGGG",
      "GGGGGGGGGGGGGGGG",
      "GGGGGGGGGGGGGGGG",
      "GGGGGGGGGGGGGGGG"
    ],
    [
      "  op     qr po s",
      "  opr q    qpo s",
      "  op  r     po t",
      "  op q   q rpo s",
      " uvvvvv  vvvvv s",
      "u v        wxv s",
      "            yv t",
      "      A     Bv s",
      "            Bv s",
      " u          Cv s",
      "D v       EFIv s",
      "  vvvvvvvvvvvv t",
      "               s",
      "J              s",
      "s              s",
      "JsssstsssstssssJ"
    ],
    [
      "   p        p  s",
      "   p        p  s",
      "   p        p  t",
      "   p        p  s",
      "  vvvvv  vvvvv s",
      "  v         xv s",
      "  K         Lv t",
      "  K         Mv s",
      "  K         Nv s",
      "  K          v s",
      "  v         Ov s",
      "  vvvvvvvvvvvv t",
      "               s",
      "J              s",
      "s              s",
      "JsssstsssstssssJ"
    ],
    [
      "  Pp        pQ  ",
      "  Pp        pQ  ",
      "  Pp        pQ  ",
      "  Pp        pQ  ",
      "  vvvvvvvvvvvv  ",
      "  v          v  ",
      "  K          v  ",
      "  K          v  ",
      "  K          v  ",
      "  K        R v  ",
      "  v        SOv  ",
      "  vvTTTvvTTTvv  ",
      "                ",
      "                ",
      "                ",
      "                "
    ],
    [
      "   PUUUUUUUUQ   ",
      "   PUUUUUUUUQ   ",
      "   PUUUUUUUUQ   ",
      "   PUUUUUUUUQ   ",
      "  vvvvvvvvvvvv  ",
      "  v          v  ",
      "  vV         v  ",
      "  vV         v  ",
      "  vV         v  ",
      "  vV         v  ",
      "  v         Ov  ",
      "  vvvvvvvvvvvv  ",
      "                ",
      "                ",
      "                ",
      "                "
    ],
    [
      "    PWX  YWQ    ",
      "    PWZ012WQ    ",
      "    PWZ  3WQ    ",
      "    P444444Q    ",
      "  vvvvvvvvvvvv  ",
      "  v5555555555v  ",
      "  v5555555555v  ",
      "  v5555555555v  ",
      "  v5555555555v  ",
      "  v5555555555v  ",
      "  v5555555555v  ",
      "  vvvvvvvvvvvv  ",
      "                ",
      "                ",
      "                ",
      "                "
    ]
  ]
}