{
  "name": "multi_laboratory1_6_base4",
  "refpalette": "c70cities:multi_laboratory1_6_base4_palette",
  "xsize": 16,
  "zsize": 16,
  "slices": [
    [
      "aaaaaaaaaaaaaaaa",
      "aaaaaaaaaaaaaaaa",
      "aaaaaaaaaaaaaaaa",
      "aaaaaaaaaaaaaaaa",
      "aaaaaaaaaaaaaaaa",
      "aaaaaaaa!aaaaaaa",
      "aaaaaaaaaaaaaaaa",
      "aaaaabbbbbbaaaaa",
      "aaabbc    cbbaaa",
      "abbb        bbba",
      "bc            cb",
      "b              b",
      "b         d    b",
      "                ",
      " d              ",
      "                "
    ],
    [
      "e fg e fg e fg h",
      "                ",
      "                ",
      "ij              ",
      " j   kkllkk     ",
      "m   mn o  p   m ",
      "qq            qq",
      "qq rcssssssct qq",
      " m ssc    css   ",
      " sss        sss ",
      "sc            cs",
      "s              s",
      "s         d    s",
      "                ",
      " u              ",
      "                "
    ],
    [
      "  wx   wx   wx  ",
      "                ",
      "                ",
      "                ",
      "      y  A      ",
      "          B     ",
      " C            D ",
      "    EssssssE   F",
      "   ssc    css   ",
      " sss        sss ",
      "sc            cs",
      "s              s",
      "s         d    s",
      "                ",
      " d              ",
      "                "
    ],
    [
      "                ",
      "                ",
      "                ",
      "                ",
      "                ",
      "                ",
      "                ",
      "    EssssssE    ",
      "   ssc    css   ",
      " sss        sss ",
      "sc            cs",
      "s              s",
      "s         d    s",
      "                ",
      " d              ",
      "                "
    ],
    [
      "                ",
      "                ",
      "                ",
      "                ",
      "                ",
      "                ",
      "                ",
      "     ssssss     ",
      "   ssc    css   ",
      " sss        sss ",
      "sc            cs",
      "s              s",
      "s         d    s",
      "                ",
      " d              ",
      "                "
    ],
    [
      "IIIIIIIIIIIIIIII",
      "IJIIIJIIIIJIIIJI",
      "IJIIIJIIIIJIIIJI",
      "IKIIIJIIIIJIIIJI",
      "IKIIIJIIIIJIIIJI",
      "IIIIIIIIIIIIIIII",
      "IIIIIIIIIIIIIIII",
      "IIIIIssssssIIIII",
      "IIIssc    cssIII",
      "Isss        sssI",
      "sc            cs",
      "s              s",
      "s         d    s",
      "                ",
      " d              ",
      "                "
    ]
  ]
}