{
  "name": "multi_gasstation_1_ground",
  "refpalette": "c70cities:multi_gasstation_1_ground_palette",
  "xsize": 16,
  "zsize": 16,
  "slices": [
    [
      "HHHHaHHaaaaaaaGG",
      "HHHHHHHaaaaaaaGG",
      "HHHHHHHaaaaaaaGG",
      "HHHHaHHaaaaaaaGG",
      "HHHHaHHaaaaaaaGG",
      "HHHHaHHaaaaaaaGG",
      "HHHHaHHaaaaaaaGG",
      "HHHHaHHaaaaaaaGG",
      "HHHHaHHaaaaaaaGG",
      "HHHHaHHaaaaaaaGG",
      "HHHHaHHaaaaaaaGG",
      "HHHHaHHaaaaaaaGG",
      "HHHHaHHaaaaaaaGG",
      "HHHHHHHHHHbGGGGG",
      "HHHHHHHHHHbGGGGG",
      "GGGGGGGGGGGGGGGG"
    ],
    [
      "  cde  f    gh  ",
      "       i  j jh  ",
      "       k  j lh  ",
      "    e  f  j jh  ",
      "  mno  f     h  ",
      "  p    h  jjlh  ",
      "  cde  f    qh  ",
      "  mno  f    qh  ",
      "       i    rh  ",
      "  cde  hst hhh  ",
      "  mnu  wx  ygh  ",
      "       w   hAh  ",
      "  cde  hhhhhhh  ",
      "       B Cu     ",
      "       D Eu     ",
      "                "
    ],
    [
      "    e  f     h  ",
      "       F  l gh  ",
      "       I  j jh  ",
      "    e  f    lh  ",
      "    J  f     h  ",
      "       h  jgjh  ",
      "    e  f     h  ",
      "    J  f     h  ",
      "       F     h  ",
      "    e  hK  hhh  ",
      "       L   M h  ",
      "       L NOhgh  ",
      "    e  hhhhhhh  ",
      "                ",
      "                ",
      "                "
    ],
    [
      "    e  P     Q  ",
      "       P     P  ",
      "       P     P  ",
      "    e  P     Q  ",
      "       P     Q  ",
      "       P    gP  ",
      "    e  P     Q  ",
      "       P     Q  ",
      "       P     P  ",
      "    e  P   hhP  ",
      "       P   h Q  ",
      "       P  !h Q  ",
      "    e  PPPPPPP  ",
      "                ",
      "                ",
      "                "
    ],
    [
      "    hR h  S  h  ",
      "       h     h  ",
      "       h     h  ",
      "    hR h  R  h  ",
      "       h     h  ",
      "       hhhhhhh  ",
      "    hS h  S  h  ",
      "       h     h  ",
      "       h    gh  ",
      "    hS h  Shhh  ",
      "       h   h h  ",
      "       h  ghgh  ",
      "    hR hhhhhhh  ",
      "                ",
      "                ",
      "                "
    ],
    [
      " TuuauuuuuuuuaT ",
      " TuuauuuuuuuuaT ",
      " TuuauuuuuuuuaT ",
      " TuuauuuuuuuuaT ",
      " TuuauuuuuuuuaT ",
      " TuuaaaaaaaaaaT ",
      " TuuauuuuuuuuaT ",
      " TuuauuuuuuuuaT ",
      " TuuauuuuuuuuaT ",
      " TuuauuuuuuuuaT ",
      " TuuauuuuuuuuaT ",
      " TuuauuuuuuuuaT ",
      " TuuaaaaaaaaaaT ",
      " TTTTTTTTTTTTTT ",
      "                ",
      "                "
    ]
  ]
}