{
  "name": "multi_militarybase_1_base1",
  "refpalette": "c70cities:multi_militarybase_1_base1_palette",
  "xsize": 16,
  "zsize": 16,
  "slices": [
    [
      "vaaaaaaaaabbbc  ",
      "vaaaaaaaaabbbc  ",
      "vvcccvcccccccvcc",
      "vaaaacaaaabbbcbb",
      "vaaaacaaaabbbcbb",
      "vaaaacaaaaabbcbb",
      "vaaaacaaaaaadvee",
      "vaaaacaaaaaaacaa",
      "vaaaacaaaaaaacaa",
      "vaaaacaaaaaaacaa",
      "vvcccvcccccccvcc",
      "vaaaacaaaaaaacff",
      "vaaaacaaaaaaacff",
      "vaaaacaaaaaaacff",
      "vaaaavaaaaaaavff",
      "vvvvvvvvvvvvvvvv"
    ],
    [
      "vgh          i  ",
      "vgh          i  ",
      "vvj  v       vii",
      "vkl  m          ",
      "vnn  m   o      ",
      "v p  m          ",
      "vnn qm   r  dv  ",
      "v sq m   t      ",
      "vnn  m          ",
      "vu   m        wx",
      "vvj  vmmmmmmmvyy",
      "vA           jB ",
      "vA     nC Dn jyy",
      "vEF Ij nk Jn jB ",
      "vKLLKv M   M vyy",
      "vvvvvvvvvvvvvvvv"
    ],
    [
      "v!              ",
      "vg              ",
      "vvj  v       v  ",
      "v    m          ",
      "vN   m          ",
      "vO   m   o      ",
      "vN   m   r   v  ",
      "vO   m   t      ",
      "vN   m          ",
      "v    m          ",
      "vvj  vmmmmmmmvyy",
      "vP           j  ",
      "vP     Q   R jyy",
      "v    j S   T j  ",
      "v    v U   U vyy",
      "vvvvvvvvvvvvvvvv"
    ],
    [
      "vg              ",
      "vg              ",
      "vvj  v       v  ",
      "v    m          ",
      "v    m          ",
      "v    m          ",
      "v    m   o  Vv  ",
      "v    m   t      ",
      "v    m          ",
      "v    m          ",
      "vvj  vmmmmmmmvyy",
      "v            j  ",
      "v            jyy",
      "v    j       j  ",
      "vWWWWv       vyy",
      "vvvvvvvvvvvvvvvv"
    ],
    [
      "v            m  ",
      "vh           m  ",
      "vvjjjv       vmm",
      "v    i          ",
      "v    i          ",
      "v    i          ",
      "v    i       v  ",
      "v    i   o      ",
      "v    i          ",
      "v    i          ",
      "vvjjjviiiiiiivyy",
      "v    j       jXX",
      "v    j       jXX",
      "v    j       jXX",
      "v    v       vXX",
      "vvvvvvvvvvvvvvvv"
    ],
    [
      "vYZZZZZZZZZZZc00",
      "vYZZZZZZZZZZZc00",
      "vvcccvcccccccvcc",
      "vYZZZcZZZZZZZcZZ",
      "vYZZZcZZZZZZZcZZ",
      "vYZZZcZZZ ZZZcZZ",
      "vYZZZcZZZ ZZZvZZ",
      "vYZZZcZZZ ZZZcZZ",
      "vYZZZcZZZoZZZcZZ",
      "vYZZZcZZZ ZZZcZZ",
      "vvcccvcccccccvcc",
      "v!ZZZcZZZZZZZc h",
      "vYZZZcZ1ZZZ1Zc  ",
      "vYZZZcZZZZZZZch ",
      "vYYYYvYYYYYYYvYY",
      "vvvvvvvvvvvvvvvv"
    ]
  ]
}