{
  "name": "multi_condo1_4_floor1",
  "refpalette": "c70cities:multi_condo1_4_floor1_palette",
  "xsize": 16,
  "zsize": 16,
  "slices": [
    [
      "aaaaabccccccde  ",
      "fffgabhiiiiiijj ",
      "   kabhlllllie  ",
      "   kabhlllllie  ",
      "   kabhlllllie  ",
      "   kabhmllllijj ",
      "   kabhiiiiiie  ",
      "   kabhnnnnnhe  ",
      "   kabhnnnnnhe  ",
      "   kabhnnnnnie  ",
      "   kabonnnnnijj ",
      "   kabpiiiiiie  ",
      "   kabhhk   ie  ",
      "   kabhh    ie  ",
      "qqqrabhiiiiiijj ",
      "aaaaabccccccde  "
    ],
    [
      "          m s   ",
      "tttt  iiiiiiijj ",
      "   t  u    wi   ",
      "   t  i     x   ",
      "   t  i yy  i   ",
      "   t  imAy  ijj ",
      "   t  iiiiiii   ",
      "   t  iBBB  C   ",
      "   t  D     C   ",
      "   t  E    hi   ",
      "   t FiIJIKhijj ",
      "   t  iiiiiii   ",
      "   t  i     x   ",
      "   t  L     i   ",
      "tttt  iiiiiiijj ",
      "       MMMMMs   "
    ],
    [
      "            s   ",
      "      iiiiiiijj ",
      "      N    wi   ",
      "      iO    P   ",
      "      i   Q i   ",
      "      imR S ijj ",
      "      iiiiiii   ",
      "      iBBB  C   ",
      "      T     C   ",
      "      U    hi   ",
      "      iIIIKhijj ",
      "      iiiiiii   ",
      "      i     P   ",
      "      V     i   ",
      "      iiiiiiijj ",
      "         M Ms   "
    ],
    [
      "                ",
      "      iiiiiiijj ",
      "      W    wi   ",
      "      i     P   ",
      "      i     i   ",
      "      imRy  ijj ",
      "      iiiiiii   ",
      "     XiBBB  C   ",
      "      W     C   ",
      "      W    hi   ",
      "     YiIIIKhijj ",
      "      iiiiiii   ",
      "      i     P   ",
      "      W     i   ",
      "      iiiiiiijj ",
      "                "
    ],
    [
      "                ",
      "      iiiiiiijj ",
      "      i    wi   ",
      "      i     i   ",
      "      i     i   ",
      "      imR   ijj ",
      "      iiiiiii   ",
      "     ZiBBB  C   ",
      "      i     C   ",
      "      i    hi   ",
      "     ZiIIIKhijj ",
      "      iiiiiii   ",
      "      i     i   ",
      "      i     i   ",
      "      iiiiiiijj ",
      "                "
    ],
    [
      "                ",
      "      iiiiiiijj ",
      "      illll0i   ",
      "      illllli   ",
      "      illllli   ",
      "      imRlllijj ",
      "      illllli   ",
      "      i11111i   ",
      "      i11111i   ",
      "      i11111i   ",
      "      i11111ijj ",
      "      illllli   ",
      "      illllli   ",
      "      illllli   ",
      "      iiiiiiijj ",
      "                "
    ]
  ]
}