{
  "name": "multi_laboratory1_9_base5",
  "refpalette": "c70cities:multi_laboratory1_9_base5_palette",
  "xsize": 16,
  "zsize": 16,
  "slices": [
    [
      "  a     bc   a  ",
      "  a          a  ",
      "  a          a  ",
      "  a        d a  ",
      "  a          a  ",
      "  a          e  ",
      "  a    d     a  ",
      "  a         fa  ",
      "  aaaaaaaaaaaa  ",
      "                ",
      "                ",
      "                ",
      "                ",
      "gggggggggggggggg",
      "hhhhhhhhhhhhhhhh",
      "vvvvvvvvvvvvvvvv"
    ],
    [
      "  a    ij    a  ",
      "  a i   k    a  ",
      "  a          a  ",
      "  a        l a  ",
      "  a    i     a  ",
      "  a          a  ",
      "  a    d     a  ",
      "  a         ma  ",
      "  aaaaaaaaaaaa  ",
      "                ",
      "                ",
      "                ",
      "                ",
      "ggggnngnnnnngggg",
      "hhhhhhhhhhhhhhhh",
      "vvvvvvvvvvvvvvvv"
    ],
    [
      "  a    o     a  ",
      "  a f   b    a  ",
      "  a          a  ",
      "  a        l a  ",
      "  a    o     a  ",
      "  a          a  ",
      "  a    d     a  ",
      "  a        fpa  ",
      "  aaaaaaaaaaaa  ",
      "                ",
      "                ",
      "                ",
      "                ",
      "gggggnnngngngggg",
      "hhhhhhhhhhhhhhhh",
      "vvvvvvvvvvvvvvvv"
    ],
    [
      "  a    f     a  ",
      "  a ff  b    a  ",
      "  a  q       a  ",
      "  a        l a  ",
      "  a    o     a  ",
      "  a         ia  ",
      "  a    d    fa  ",
      "  a       m!fa  ",
      "  aaaaaaaaaaaa  ",
      "                ",
      "                ",
      "                ",
      "                ",
      "ggggngnnnngngggg",
      "hhhhhhhhhhhhhhhh",
      "vvvvvvvvvvvvvvvv"
    ],
    [
      "  a   fffm   a  ",
      "  affmffj    a  ",
      "  a  d       a  ",
      "  a        l a  ",
      "  a    f     a  ",
      "  a         ma  ",
      "  a    d rfmfa  ",
      "  a       p fa  ",
      "  aaaaaaaaaaaa  ",
      "                ",
      "                ",
      "                ",
      "                ",
      "gggggggggggggggg",
      "hhhhhhhhhhhhhhhh",
      "vvvvvvvvvvvvvvvv"
    ],
    [
      "sstuwuuuuuuwxtss",
      "sstuwuuuuuuwxtss",
      "sstuwyAAAABwutss",
      "sstuwuuuuuuwutss",
      "sstuwuumfuuwutss",
      "sstuwuuuffuwutss",
      "sstuCyAAAABCutss",
      "sstuuxuxxuuuutss",
      "ssttttttttttttss",
      "ssssssssssssssss",
      "ssssssssssssssss",
      "ssssssssssssssss",
      "ssssssssssssssss",
      "gggggggggggggggg",
      "hhhhhhhhhhhhhhhh",
      "vvvvvvvvvvvvvvvv"
    ]
  ]
}