{
  "name": "multi_convenientstore_2_ground",
  "refpalette": "c70cities:multi_convenientstore_2_ground_palette",
  "xsize": 16,
  "zsize": 16,
  "slices": [
    [
      "GGGGGGGGGGGaHHHG",
      "GGGGGGGGGGGaHHHG",
      "aaaaaaaaaaaaHHHG",
      "HHHHHHHHHHHHHHHG",
      "HHHHHHHHbHHHHHHG",
      "HHHHHHHHHHHHHHHG",
      "HHHHHHHHHHHHHHHG",
      "HHHHHHHHHHHHHHHG",
      "HHHHHHHHHHHHHHHG",
      "HHHHHHHHHHHHHHHG",
      "HHHHHHHHHHHHHHHG",
      "HHHHHHHHHHHHHHHG",
      "HHHHHHHHHHHHHHHG",
      "HHHHHHHHHHHHHHHc",
      "HHHHHHHHHHHHHHHc",
      "HHHHHHHHHHHHHHHc"
    ],
    [
      " d     d  de    ",
      "           e    ",
      "eeeee eee ee    ",
      "fgfgfgfgfgf     ",
      "                ",
      "hihihihihih     ",
      "               d",
      "                ",
      "                ",
      "                ",
      "fgfgfgfgfgf     ",
      "                ",
      "hihihihihih     ",
      "eeeeeeeeeeee   j",
      "aaaaaaaaaaaakkkj",
      "aaaaaaaaaaaakkkj"
    ],
    [
      "                ",
      "                ",
      "                ",
      "                ",
      "                ",
      "                ",
      "                ",
      "                ",
      "                ",
      "                ",
      "                ",
      "                ",
      "                ",
      "                ",
      "       l        ",
      " mn n nlopoo    "
    ],
    [
      "                ",
      "                ",
      "                ",
      "                ",
      "                ",
      "                ",
      "                ",
      "                ",
      "                ",
      "                ",
      "                ",
      "                ",
      "                ",
      "                ",
      "       l        ",
      " mn n nloqoo    "
    ],
    [
      "                ",
      "                ",
      "                ",
      "                ",
      "                ",
      "                ",
      "                ",
      "                ",
      "                ",
      "                ",
      "                ",
      "                ",
      "                ",
      "                ",
      "       l        ",
      "rsn n nlo oo    "
    ],
    [
      "                ",
      "                ",
      "                ",
      "                ",
      "                ",
      "                ",
      "                ",
      "                ",
      "                ",
      "                ",
      "                ",
      "                ",
      "                ",
      "                ",
      "       l        ",
      "  n n nlo oo    "
    ]
  ]
}