{
  "name": "multi_laboratory1_11_base5",
  "refpalette": "c70cities:multi_laboratory1_11_base5_palette",
  "xsize": 16,
  "zsize": 16,
  "slices": [
    [
      "             abz",
      "             cbz",
      "             cbz",
      "            acbz",
      "             cbz",
      "           deebz",
      "   fg     dhicbz",
      "           deebz",
      "             cbz",
      "            acbz",
      "             cbz",
      "             cbz",
      "d          deebz",
      "d  fg     dhicbz",
      "jd         deebz",
      " d           cbz"
    ],
    [
      "             abz",
      "             cbz",
      "             cbz",
      "            aabz",
      "             abz",
      "           deebz",
      "    g     dhicbz",
      "           deebz",
      "             cbz",
      "            aabz",
      "             abz",
      "             abz",
      "d          deebz",
      "d   g     dhicbz",
      "jd         deebz",
      " d           abz"
    ],
    [
      "             abz",
      "             cbz",
      "             cbz",
      "            acbz",
      "             cbz",
      "           deebz",
      "    g     dhicbz",
      "           deebz",
      "             cbz",
      "            acbz",
      "             cbz",
      "             cbz",
      "d          deebz",
      "d   g     dhicbz",
      "jd         deebz",
      " d           cbz"
    ],
    [
      "             abz",
      "             cbz",
      "             cbz",
      "            acbz",
      "             cbz",
      "           deebz",
      "    g     dhicbz",
      "           deebz",
      "            acbz",
      "            acbz",
      "            acbz",
      "             cbz",
      "d          deebz",
      "d   g     dhicbz",
      "jd         deebz",
      " d           cbz"
    ],
    [
      "            kabz",
      "             cbz",
      "             cbz",
      "            acbz",
      "             cbz",
      "           deebz",
      "    g     dhicbz",
      "           deebz",
      "             cbz",
      "             cbz",
      "            acbz",
      "             cbz",
      "d          deebz",
      "d   g     dhicbz",
      "jd         deebz",
      " d          kcbz"
    ],
    [
      "llllllllllllaabz",
      "llllllllllllacbz",
      "llllllllllllacbz",
      "llllllllllllmcbz",
      "llllllllllllacbz",
      "lllllllllleeeebz",
      "llllglllllenicbz",
      "lllllllllleeeebz",
      "llllllllllllacbz",
      "llllllllllllacbz",
      "llllllllllllmcbz",
      "llllllllllllacbz",
      "dllllllllleeeebz",
      "dlllglllllenicbz",
      "jdlllllllleeeebz",
      " dllllllllllacbz"
    ]
  ]
}