{
  "name": "multi_flatapartment_2_floor1",
  "refpalette": "c70cities:multi_flatapartment_2_floor1_palette",
  "xsize": 16,
  "zsize": 16,
  "slices": [
    [
      "                ",
      "abbbbabbbabbbba ",
      "ccccccccccccccb ",
      "dddddddddddddcb ",
      "dddddddddddddcb ",
      "dddddddddddddca ",
      "dddddddddddddcb ",
      "dddddddddddddcb ",
      "dddddddddddddcb ",
      "dddddddddddddcb ",
      "dddddddddddddca ",
      "dddddddddddddcb ",
      "dddddddddddddcb ",
      "ccccccccccccccb ",
      "abbbbabbbabbbba ",
      "                "
    ],
    [
      "                ",
      "abeebabebabeeba ",
      "         f    b ",
      " g g hii hj  ke ",
      " lll h   h m nb ",
      "hhhhhh   hhhhha ",
      "ho  phqq r    b ",
      "ho  phhhhh    e ",
      "h    s  th uu e ",
      "hg g h wxhyAABb ",
      "hlll h wxhhhhha ",
      "CDEE h   f FI b ",
      "     hhhhhj   e ",
      "         J  KLb ",
      "abeebabebabeeba ",
      "                "
    ],
    [
      "                ",
      "abMMbabMbabMMba ",
      "         N    b ",
      "     h   h    M ",
      "O    h   hP Q b ",
      "hhhhhh   hhhhha ",
      "hR   hRR S    b ",
      "hR   hhhhh    M ",
      "h    T   h    M ",
      "h    h   h    b ",
      "h    h   hhhhha ",
      "     h   N   Ub ",
      "     hhhhh    M ",
      "         V    b ",
      "abMMbabMbabMMba ",
      "                "
    ],
    [
      "                ",
      "abMMbabMbabMMba ",
      "         h    b ",
      "     h   h    M ",
      "     h   h  W b ",
      "hhhhhh   hhhhha ",
      "hR   hRR h    b ",
      "hR   hhhhh    M ",
      "h    h   h    M ",
      "h    h   h    b ",
      "h    h   hhhhha ",
      "     h   h   Xb ",
      "     hhhhh    M ",
      "         h    b ",
      "abMMbabMbabMMba ",
      "                "
    ],
    [
      "                ",
      "abbbbabbbabbbba ",
      "h    h   hYYYYb ",
      "h    h   hYYYYb ",
      "h    h Z hYYYYb ",
      "hhhhhh   hhhhha ",
      "h    h   h    b ",
      "h  Z hhhhh    b ",
      "h    h   h    b ",
      "h    h   h    b ",
      "h    h   hhhhha ",
      "h    h   hYYYYb ",
      "h    hhhhhYYYYb ",
      "h    h   hYYYYb ",
      "abbbbabbbabbbba ",
      "                "
    ],
    [
      "                ",
      "011110111011110 ",
      "cccccccccccccc1 ",
      "dddddddddddddc1 ",
      "dddddddddddddc1 ",
      "dddddddddddddc0 ",
      "dddddddddddddc1 ",
      "dddddddddddddc1 ",
      "dddddddddddddc1 ",
      "dddddddddddddc1 ",
      "dddddddddddddc0 ",
      "dddddddddddddc1 ",
      "dddddddddddddc1 ",
      "cccccccccccccc1 ",
      "011110111011110 ",
      "                "
    ]
  ]
}