{
  "name": "multi_residential1_1_ground",
  "refpalette": "c70cities:multi_residential1_1_ground_palette",
  "xsize": 16,
  "zsize": 16,
  "slices": [
    [
      "GGabbbbbbbbbbaGG",
      "GGabbbbbbbbbbaGG",
      "GGabbbbbbbbbbaGG",
      "GGabbbbbbbbbbaGG",
      "GGabbbbbbbbbbaGG",
      "GGabbbbbbbbbbaGG",
      "GGabbbbbbbbbbaGG",
      "GGaaaaaaaaaaaaGG",
      "GGcGGGGGGdGGGcGG",
      "GGcGGGddGGGGGcGG",
      "GGcGGdGGGdGddcGG",
      "GGccccccccccccGG",
      "GGGGGGGGGGGGGGGG",
      "GGGGGGGGGGGGGGGG",
      "GGGGGGGGGGGGGGGG",
      "GGGGGGGGGGGGGGGG"
    ],
    [
      "  eeeee  f !ee g",
      "  c hh    ii c g",
      "  e          e j",
      "  c kl     mnc g",
      "  e        ooe g",
      "  p        q c g",
      "  r        stc j",
      "  eccuuwxuucce g",
      "  yABCBD  ADBy g",
      "  yCAA  CACACy g",
      "  yDA DAB B  y g",
      "  eEEEEEEEEEEe j",
      "               g",
      "F              g",
      "g              g",
      "FggggjggggjggggF"
    ],
    [
      "  eeeee  IIIee g",
      "  J KKL     MJ g",
      "  e         Ne j",
      "  J          J g",
      "  e        ooe g",
      "  O        P c g",
      "  Q        sRc j",
      "  eccuuSTuucce g",
      "               g",
      "               g",
      "               g",
      " UeeeeeeeeeeeeUj",
      " ccccccccccccccg",
      "F              g",
      "g              g",
      "FggggjggggjggggF"
    ],
    [
      "  eeeee     ee  ",
      "  J        V J  ",
      "  e          e  ",
      "  J          J  ",
      "  e        ooe  ",
      "  J        s W  ",
      "  J        s W  ",
      "  eccuuuuuucce  ",
      "                ",
      " UUU        UUU ",
      " cccccccccccccc ",
      " XXXXXXXXXXXXXX ",
      "                ",
      "Y               ",
      "                ",
      "                "
    ],
    [
      "  eeeeeeeeeeee  ",
      "  JbbbbbbbV  J  ",
      "  ebbbbbbb   e  ",
      "  Jbbbbbbb   J  ",
      "  ebbbbbbbbbbe  ",
      "  ebbbbbbbbbbe  ",
      "  ebbbbbbbbbbe  ",
      " UeeeeeeeeeeeeU ",
      " ccc        ccc ",
      " XXX        XXX ",
      "   E  E  E  E   ",
      "                ",
      "                ",
      "                ",
      "                ",
      "                "
    ],
    [
      "  eeeeeeeeeeee  ",
      "  JZ00Z1     J  ",
      "  e 22 345   e  ",
      "  J    6 57  J  ",
      "  e       888e  ",
      " UeU  59  @ UeU ",
      " cccJ 59  @Jccc ",
      " XXXJJJJJJJJXXX ",
      "   E        E   ",
      "                ",
      "   E  E  E  E   ",
      "                ",
      "                ",
      "                ",
      "                ",
      "                "
    ]
  ]
}