{
  "name": "multi_megatower1_4_floor9",
  "refpalette": "c70cities:multi_megatower1_4_floor9_palette",
  "xsize": 16,
  "zsize": 16,
  "slices": [
    [
      "a   bbbbbbbbbbbb",
      "a   bbbbbbbbbbbb",
      "a   bbbbbbbbbbbb",
      "cdeebbbbbbbbbbbb",
      "bbbbfbbbbbbfbbbb",
      "bbbbbbbbbbbbbbbb",
      "bbbbbbbbbbbbbbbb",
      "bbbbbbbbbbbbbbbb",
      "bbbbbbbbbbbbbbbb",
      "bbbbbbbbbbbbbbbb",
      "bbbbbbbbbbbbbbbb",
      "bbbbfbbbbbbfbbbb",
      "bbbbbbbbbbbbbbbb",
      "bbbbbbbbbbbbbbbb",
      "bbbbbbbbbbbbbbbb",
      "bbbbbbbbbbbbbbbb"
    ],
    [
      "a   ag         h",
      "a   ag  ijjk   l",
      "a   ag         m",
      "aennag         m",
      "opqrfsstussfwxww",
      "         y A   w",
      "        BC Ay  D",
      "        BC AE  w",
      "        BC AE  D",
      " FIJK   BC Ay  w",
      " FIJK    y A   D",
      "   LfL    LfwMww",
      " FINKOIP    L  Q",
      " FINKOIP        ",
      "                ",
      "          RR   R"
    ],
    [
      "a   aS         T",
      "a   aU   VW    X",
      "a   aY         m",
      "ae  aZ         m",
      "o 01fss23ssfw4ww",
      "           A   w",
      "         5 6   7",
      "         5 6   w",
      "           6   7",
      "    8    5 6   w",
      "    9      A   7",
      "   @f@    @fw#ww",
      "    8       @  $",
      "    9           ",
      "                ",
      "                "
    ],
    [
      "a   a          m",
      "a   a%         m",
      "a   a^         m",
      "aeeea&         m",
      "o*  fss((ssfwwww",
      "         ) A   w",
      "         ) 6   w",
      "         ) 6   w",
      "         ) 6   w",
      "         ) 6   w",
      "         ) A   w",
      "   @f@    @fwwww",
      "            @   ",
      "                ",
      "                ",
      "                "
    ],
    [
      "a   a++++++++++-",
      "a   a++++++++++-",
      "a   a+[++[+++[+-",
      "aeeea++++++++++-",
      "oooofssssssfwwww",
      "           ]{{{{",
      "         } ]{{{{",
      "           ]{{{{",
      "           ]{{{{",
      "         } ]{{{{",
      "           ]{{{{",
      "    f      fwwww",
      "                ",
      "                ",
      "                ",
      "                "
    ],
    [
      "a   \\| |  |\\|   ",
      "a   \\  | | \\  | ",
      "a   \\ }  } \\ } |",
      "ae``\\|     \\|   ",
      "::::f::::::f::::",
      "++++\\++++++\\ |  ",
      "++[+\\+[++;+\\''''",
      "++++\\++++++\\| '|",
      "++++\\++++++\\  ''",
      "++[+\\+[++,+\\  '|",
      "++++\\++++++\\||''",
      "::::f::::::f::::",
      "++++\\++++++\\++++",
      "++[+\\+[++[+\\+[++",
      "++++\\++++++\\++++",
      "++++\\++++++\\++++"
    ]
  ]
}