{
  "name": "multi_factory_0_ground",
  "refpalette": "c70cities:multi_factory_0_ground_palette",
  "xsize": 16,
  "zsize": 16,
  "slices": [
    [
      "zaazzzzzzzzzzzzz",
      "aaazzzzzzzzzzzzz",
      "aazbbbbbbbbbbbzz",
      "aaabbbbbbbbbbbzz",
      "aaabbbbbbbbbbbzz",
      "zaabbbbbbbbbbbzz",
      "zaabbbbbbbbbbbzz",
      "aaabbbbbbbbbbbzz",
      "zaabbbbbbbbbbbzz",
      "aaabbbbbbbbbbbzz",
      "aaabbbbbbbbbbbzz",
      "aaabbbbbbbbbbbzz",
      "zaabbbbbbbbbbbzz",
      "aaabbbbbbbbbbbzz",
      "zaabbbbbbbbbbbzz",
      "aaabbbbbbbbbbbzz"
    ],
    [
      "                ",
      "                ",
      "   ccccccccccc  ",
      "   cdeffdgh dc  ",
      "   ij    k  lc  ",
      "   c     mnnnc  ",
      "   co    p  lc  ",
      "   coq   gr  c  ",
      "   co    ssssc  ",
      "   co t     uc  ",
      "   c wxxye j c  ",
      "   cmmmmmmmAmc  ",
      "   cBBddC C Cc  ",
      "             c  ",
      "             c  ",
      "     DDDDD  Ec  "
    ],
    [
      "                ",
      "                ",
      "   ccccccccccc  ",
      "   cd ffdg  dc  ",
      "   F     I  Jc  ",
      "   c     mnnnc  ",
      "   KL    M  Jc  ",
      "   KN    g   c  ",
      "   KN    ssssc  ",
      "   K        uc  ",
      "   c   O     c  ",
      "   cmKKKKmmPmc  ",
      "   cd        c  ",
      "             c  ",
      "             c  ",
      "     QDDDD  Ec  "
    ],
    [
      "                ",
      "                ",
      "   ccRSTcRSTcc  ",
      "   cd   dg  dc  ",
      "   K     g   c  ",
      "   c     mnnnc  ",
      "   K     g   c  ",
      "   K     g   c  ",
      "   K     ssssc  ",
      "   K        uc  ",
      "   c         c  ",
      "   cmKKKKmmmmc  ",
      "   c         c  ",
      "   U         c  ",
      "   U         c  ",
      "   U  DDD   Ec  "
    ],
    [
      "                ",
      "                ",
      "   ccccccccccc  ",
      "   cd   dg  dc  ",
      "  Vc     g   c  ",
      "  Vc     mnnnc  ",
      "  Vc     g   c  ",
      "  Vc     g   c  ",
      "  Vc     ssssc  ",
      "  Vc        uc  ",
      "   c         c  ",
      "   cmmmmmmmmmc  ",
      "   c         c  ",
      "  VcW        c  ",
      "  VcW        c  ",
      "  VcW        c  "
    ],
    [
      "                ",
      "                ",
      "   ccccccccccc  ",
      "   cd   dbbbdc  ",
      "   c    Xbbbbc  ",
      "   c    Xbbbbc  ",
      "   c    Xbbbbc  ",
      "   c    Xbbbbc  ",
      "   c    Xbbbbc  ",
      "   c    Xbbbuc  ",
      "   c    Xbbbbc  ",
      "   cmmmmmmmmmc  ",
      "   c        Cc  ",
      "   c         c  ",
      "   c         c  ",
      "   c         c  "
    ]
  ]
}