{
  "name": "multi_laboratory1_11_base2",
  "refpalette": "c70cities:multi_laboratory1_11_base2_palette",
  "xsize": 16,
  "zsize": 16,
  "slices": [
    [
      "aaaaaaaaaaaaabcv",
      "aaaaaaaaaaaaabcv",
      "aaaaaaaaaaaaabcv",
      "aaaaaaaaaaaaabcv",
      "aaaaaaaaaaaaabcv",
      "aaaaaaaaaaaaabcv",
      "aaaadaaaaaaaabcv",
      "aaaaaaaaaaaaabcv",
      "aaaaaaaaaaaaabcv",
      "aaaaaaaaaaaaabcv",
      "aaaaaaaaaaaaabcv",
      "aaaaaaaaaaaaabcv",
      "eaaaaaaaaaaaabcv",
      "eaaadaaaaaaaabcv",
      "feaaaaaaaaaaabcv",
      " eaaaaaaaaaaabcv"
    ],
    [
      "    ghijkiiihbcv",
      "    gl  m   ibcv",
      "    gn o  p ibcv",
      "    g      qibcv",
      "    r     psibcv",
      "    gtuuuuuuhbcv",
      " w fdggggggggbcv",
      "    gx  xx  ybcv",
      "    g        bcv",
      "    g  A    BBcv",
      "    gCDDD EBFIcv",
      "    gJDDD sBFIcv",
      "KL  gMNN    BBcv",
      "Kf  d E     ybcv",
      "fK  g        bcv",
      " K  O       BBcv"
    ],
    [
      "    ghiiii!ihbcv",
      "    P       ibcv",
      "    P       ibcv",
      "    g       ibcv",
      "    Q       ibcv",
      "    gR    SThbcv",
      "   Udggggggggbcv",
      "    g       ybcv",
      "    P       Vbcv",
      "    P       KBcv",
      "    P  W   KFIcv",
      "    PWXYX  KFIcv",
      "K   g       KBcv",
      "KU  d       ybcv",
      "fK  g       Vbcv",
      " K  O       KBcv"
    ],
    [
      "    ghZZZZZZhbcv",
      "    0       1bcv",
      "    0       2bcv",
      "    g       3bcv",
      "    0        bcv",
      "    g       hbcv",
      "   Udggggggggbcv",
      "    g       ybcv",
      "    P        bcv",
      "    P       KBcv",
      "    P      KFIcv",
      "    P      KFIcv",
      "K   g       KBcv",
      "KU  d       ybcv",
      "fK  g        bcv",
      " K  O       KBcv"
    ],
    [
      "    gh      hbcv",
      "    g        bcv",
      "    g        bcv",
      "    g       4bcv",
      "    g        bcv",
      "    g       hbcv",
      "    dggggggggbcv",
      "    g  5  5 6bcv",
      "    g       Vbcv",
      "    g       KBcv",
      "    g      K7Icv",
      "    g      K7Icv",
      "K   g       KBcv",
      "K   d       6bcv",
      "fK  g       Vbcv",
      " K  g       KBcv"
    ],
    [
      "8888099999999bcv",
      "88@809#9999#9bcv",
      "88@8099999999bcv",
      "88@8099999999bcv",
      "88@809#9999$9bcv",
      "8888099999999bcv",
      "8888dggggggggbcv",
      "88880%%%%%%%%bcv",
      "88880^^^^^^^^bcv",
      "88880^^ ^^@^BBcv",
      "88880^^@^^@B&Icv",
      "88880^^$^^$B&Icv",
      "K8880^^*^^@^BBcv",
      "K888d^^^^^^^^bcv",
      "fK880^^^^^^^^bcv",
      " K880^^@^^@^BBcv"
    ]
  ]
}