{
  "name": "multi_megatower1_1_floor2",
  "refpalette": "c70cities:multi_megatower1_1_floor2_palette",
  "xsize": 16,
  "zsize": 16,
  "slices": [
    [
      "            ab  ",
      "            cb  ",
      "            cbde",
      "            cbff",
      "           ghibb",
      "            abbb",
      "            abbb",
      "            abbb",
      "            cbbb",
      "            cbbb",
      "            cbbb",
      "           ghibb",
      "            abbb",
      "            abbb",
      "            abbb",
      "            cbbb"
    ],
    [
      "            aj  ",
      "            cjd ",
      "            cjk ",
      "            cj  ",
      "           ghicl",
      "            am  ",
      "            am  ",
      "            am  ",
      "            cm  ",
      "            cm  ",
      "            cm  ",
      "           ghinn",
      "            amo ",
      "            amp ",
      "            amq ",
      "            cmq "
    ],
    [
      "            ajf ",
      "            cjk ",
      "            cj  ",
      "            cj  ",
      "           ghicr",
      "            am  ",
      "            am  ",
      "            am  ",
      "            cm  ",
      "            cm  ",
      "            cm  ",
      "           ghinn",
      "            am  ",
      "            am  ",
      "            am  ",
      "            cmp "
    ],
    [
      "            ajks",
      "            cj  ",
      "            cj  ",
      "            cj t",
      "           ghicc",
      "            am  ",
      "            am  ",
      "            am  ",
      "            cm  ",
      "            cm  ",
      "            cm  ",
      "           ghinn",
      "            am  ",
      "            am  ",
      "            am  ",
      "            cm  "
    ],
    [
      "            au e",
      "            cu s",
      "            cu  ",
      "            cu  ",
      "           ghicc",
      "            au  ",
      "            au  ",
      "            au  ",
      "            cu  ",
      "            cu  ",
      "            cu  ",
      "           ghinn",
      "            au  ",
      "            au  ",
      "            au  ",
      "            cu  "
    ],
    [
      "            aw  ",
      "            cw e",
      "            cw f",
      "            cwdf",
      "           ghixx",
      "            aw  ",
      "            aw  ",
      "            aw  ",
      "            cw  ",
      "            cw  ",
      "            cwyy",
      "           ghixx",
      "            awAA",
      "            aw  ",
      "            aw  ",
      "            cw  "
    ]
  ]
}