{
  "name": "multi_laboratory1_5_base7",
  "refpalette": "c70cities:multi_laboratory1_5_base7_palette",
  "xsize": 16,
  "zsize": 16,
  "slices": [
    [
      "zzzzzzzzzzzzzzzz",
      "abaaaaaaaaaaaaaa",
      "abcaaaaaaaaaaaaa",
      "baacaabaaaaaaaaa",
      "aaaaaaaaaaaaaaaa",
      "baacacaaaaaaaaab",
      "daeaeeaaaaaaaaaa",
      "aeeeeeaaaaaaaaaa",
      "eeeeaeeaaaaaaaaa",
      "aeaaaaaaaaaaaaaa",
      "aaaaaaaaaaaaaaaa",
      "aaaaaaaaaaaaaaaa",
      "aaaaaaaaaaaaaaaa",
      "aaaaaaaaaaaaaaaa",
      "aaaaaaaaaaaaaaaa",
      "aaaaaaaaaaaaaaaa"
    ],
    [
      "zzzzzzzzzzzzzzzz",
      "aaaaaaaaaaaaaaaa",
      "ffffffffffffffff",
      "   agghiddj  dda",
      " k   l       gmd",
      "n   hno   nd   n",
      "   o p a dba ggd",
      "  qq peaaaaaa ga",
      "p  peeeaaaaaaaaa",
      "epeeeeeaaaaaaaaa",
      "eeeeeeeaaaaaaaaa",
      "eeeaaaaaaaaaaaaa",
      "eaaaaaaaaaaaaaaa",
      "aaaaaaaaaaaaadad",
      "aaaaaaaaaaaaaaad",
      "aaaaaaaaaaaaaaaa"
    ],
    [
      "zzzzzzzzzzzzzzzz",
      "aaaaaaaaaaaaaaaa",
      "ffffffffffffffff",
      "     g         r",
      "  k             ",
      "n    n    n    n",
      "           d  g ",
      " g   ps  daat  d",
      "    upedcaaaaaaa",
      "ppppeeeaaaaawdaa",
      "ppeeeeeaaaaacwwa",
      "eeeeaaaaaaaadxxx",
      "eeaaaaaaaaaaat d",
      "eaaaaaaaaaaaa   ",
      "aaaaaaaaaaaaaa  ",
      "aaaaaaaaaaaaaaa "
    ],
    [
      "zzzzzzzzzzzzzzzz",
      "aaaaaaaaaaaaaaaa",
      "ffffffffffffffff",
      "                ",
      "   k            ",
      "n    n    n    n",
      "                ",
      " s    s         ",
      "     p   aaaadaa",
      "  pppeeaaaaayyaa",
      "ppeeeeeaaaaawwwa",
      "eeaaaaaaaaaaxx x",
      "eaaaaaaaaaaaa   ",
      "aaaaaaaaaaaaa   ",
      "aaaaaaaaaaaaaa  ",
      "aaaaaaaaaaaaaaa "
    ],
    [
      "zzzzzzzzzzzzzzzz",
      "aaaaaaaaaaaaaaaa",
      "ffffffffffffffff",
      "                ",
      "    k           ",
      "n    n    n    n",
      "                ",
      " s    s       sr",
      "     peA  dd Aaa",
      "   eeeeaaaawAyaa",
      "peeeeeeaaaaawAwa",
      "eaaaaaaaaaaaxxca",
      "aaaaaaaaaaaaaAAa",
      "aaaaaaaaaaaaa Aa",
      "aaaaaaaaaaaaaaaa",
      "aaaaaaaaaaaaaaaa"
    ],
    [
      "zzzzzzzzzzzzzzzz",
      "aaaaaaaaaaaaaaaa",
      "ffffffffffffffff",
      "                ",
      "     k          ",
      "n    n    n    n",
      "               A",
      "As  s s       sa",
      "cA  eeeaaAAccaaa",
      "effffeffffaffffa",
      "effffeffffaffffa",
      "affffaffffaffffa",
      "affffaffffaffffa",
      "affffaffffaffffa",
      "affffaffffaffffa",
      "aaaaaaaaaaaaaaaa"
    ]
  ]
}