{
  "name": "multi_militarybase_3_ground",
  "refpalette": "c70cities:multi_militarybase_3_ground_palette",
  "xsize": 16,
  "zsize": 16,
  "slices": [
    [
      "aaaaaaaaaaaaaaaa",
      "aaaaaaaaaaaaaaaa",
      "bbbbbbbbaaaaaaaa",
      "bbbcdbbbaaaaaaaa",
      "bbbbbbbbaaaaaaaa",
      "bbbbbbbbaaaaaaaa",
      "bbbeeeebaaaaaaaa",
      "eeeeeeebaaffaffa",
      "eeeeeeebaaffaffa",
      "eeeeeeebaaffaffa",
      "eeeeeeebaaaaaaaa",
      "bbbbbbbbzaaaaaaa",
      "aaaazaaaaazzzzaz",
      "zzazzzzaazazzaaz",
      "gggggggggggggggg",
      "zzzzzzzzzzzzzzzz"
    ],
    [
      "     h          ",
      "                ",
      "  iiiiiijjjjj jj",
      "  ickllim   n  j",
      "  i   oi        ",
      "  i   pi n      ",
      "qiirstri  uw uw ",
      " x    yi  f! ff ",
      "      Ai  ff ff ",
      "      Ai mff ffB",
      "CD    !i    n   ",
      "iiiiiiiijjjjjjjj",
      "                ",
      "   E E F E EI   ",
      "gggggggggggggggg",
      "                "
    ],
    [
      "                ",
      "                ",
      "  JJJJJJjjjjj jj",
      "  Jc KKJ       j",
      "  L    L        ",
      "  J    L        ",
      "MJJrNOrJ  PQ PQ ",
      " R     J  ff ff ",
      "       L  ffcffc",
      "       L  SS SS ",
      " T    UJ        ",
      "JJJLLLLJjjjjjjjj",
      "                ",
      "       F   I    ",
      "gggggggggggggggg",
      "                "
    ],
    [
      "                ",
      "                ",
      "  JJJJJJjjjjj jj",
      "  Jc kkJV      j",
      "  L    JV       ",
      "  J    JV       ",
      "JJJrrrrJV       ",
      "       JV ff ff ",
      "       JV ff ff ",
      "       JV       ",
      "      UJV       ",
      "JJJJJJJJjjjjjjjj",
      "   VVVV         ",
      "       F  I     ",
      "gggggggggggggggg",
      "                "
    ],
    [
      "                ",
      "                ",
      "  JJJJJJWWWWWWWW",
      "  Jc oXJ       W",
      "  Jo  XY        ",
      "  J   XY        ",
      "YJJXXXXJ        ",
      "XX    XJ  ZZ ZZ ",
      "      XY  ZZ ZZ ",
      "      XY        ",
      "0 XXXXXJ        ",
      "JJJYYYYJWWWWWWWW",
      "                ",
      "       F I      ",
      "gggggggggggggggg",
      "                "
    ],
    [
      "  i1111i        ",
      "  i1111i        ",
      "  i2222i        ",
      "  ic222i        ",
      "  i2222i        ",
      "  i2222i        ",
      "iii2222i        ",
      "2222222i        ",
      "2222222i        ",
      "2222222i        ",
      " 022222i        ",
      "iiiiiiii        ",
      "      3         ",
      "444444544       ",
      "6666666786666966",
      "                "
    ]
  ]
}