{
  "name": "multi_pumpjack_2_ground",
  "refpalette": "c70cities:multi_pumpjack_2_ground_palette",
  "xsize": 16,
  "zsize": 16,
  "slices": [
    [
      "zzzzzzzzzzzzzzzz",
      "zzzzzzzzzzzzzzzz",
      "zzzzzzzzzzzzzzzz",
      "zzzzzzzzzzzzzzzz",
      "zzzzzzzzzzzzzzzz",
      "zzzzzzzzzzzzzzzz",
      "zzzzzzzzzzzzzzzz",
      "zzzzzzzzzzzzzzzz",
      "zzzzzzzzzzzzzzzz",
      "zzzzzzzzzzzzzzzz",
      "zzzzzzzzzzzzzzzz",
      "zzzzzzzzzzzzzzzz",
      "zzzzzzzzzzzzzzzz",
      "zzzzzzzzzzzzzzzz",
      "zzzzzzzzzzzzzzzz",
      "zzzzzzzzzzzzzzzz"
    ],
    [
      "                ",
      "a               ",
      "abbbabbbabbba   ",
      "c           b   ",
      "c      deeedb   ",
      "c      eeeeef   ",
      "c     geeeeea   ",
      "c     geeeeef   ",
      "c      deeedb   ",
      "c        h  b   ",
      "c          ga   ",
      "c          gf   ",
      "c           b   ",
      "c          if   ",
      "c         iia   ",
      "c           b   "
    ],
    [
      "                ",
      "a               ",
      "ajjjajjjajjja   ",
      "          k j   ",
      "       eeeeej   ",
      "       e   ej   ",
      "      ge   ea   ",
      "       e   ej   ",
      "       eeeeej   ",
      "         l  j   ",
      "            a   ",
      "            j   ",
      "            j   ",
      "            j   ",
      "           ia   ",
      "            j   "
    ],
    [
      "                ",
      "a               ",
      "ajjjajjjajjja   ",
      "         mkmj   ",
      "       eeeeej   ",
      "       eeeeej   ",
      "       eeeeea   ",
      "       eeeeej   ",
      "       eeeeej   ",
      "            j   ",
      "            a   ",
      "            j   ",
      "            j   ",
      "            j   ",
      "            a   ",
      "            j   "
    ],
    [
      "                ",
      "a               ",
      "a   n   n   n   ",
      "                ",
      "       dd  d    ",
      "       d   d    ",
      "       d   dn   ",
      "       d   d    ",
      "       ddddd    ",
      "                ",
      "            n   ",
      "                ",
      "                ",
      "                ",
      "            n   ",
      "                "
    ],
    [
      "                ",
      "a               ",
      "a               ",
      "                ",
      "                ",
      "                ",
      "                ",
      "                ",
      "                ",
      "                ",
      "                ",
      "                ",
      "                ",
      "                ",
      "                ",
      "                "
    ]
  ]
}