{
  "name": "multi_hospital_2_base2",
  "refpalette": "c70cities:multi_hospital_2_base2_palette",
  "xsize": 16,
  "zsize": 16,
  "slices": [
    [
      "vvvvvvvvvvvvvvvv",
      "vvvvvvvvvvvvvvvv",
      "vvvvvvvvvvvvvvvv",
      "vvvvvvvvvvvvvvvv",
      "vvvvvvvvvvvvvvvv",
      "vvvvvvvvvvvvvvvv",
      "vvvvvvvvvvvvvvvv",
      "vvvvvvvvvvvvvvvv",
      "vvvvvvvvvvvvvvvv",
      "vvvvvvvvvvvvvvvv",
      "vvvvvvvvvvvvvvvv",
      "vvvvvvvvvvvvvvvv",
      "vvvvvvvvvvvvvvvv",
      "vvvvvvvvvvvvvvvv",
      "vvvvvvvvvvvvvvvv",
      "vvvvvvvvvvvvvvvv"
    ],
    [
      "vvvvvvvvvvvvvvvv",
      "aaaaaaaaaaaaaaav",
      "aaaaaaaaaaaaaaav",
      "bbbbbbbbaaaaaaav",
      "cdvvvvvbaaaaaaav",
      "cdve evbaaaaaaav",
      "cdv  evbaaaaaaav",
      "cdve  vbaaaaaaav",
      "cdv   vbaaaaaaav",
      "cdve  vbaaaaaaav",
      "cdve evbaaaaaaav",
      "cdvvvvvbaaaaaaav",
      "cdvf fvbaaaaaaav",
      "cdv   vbaaaaaaav",
      "cdvf fvbaaaaaaav",
      "cdvf  vbaaaaaaav"
    ],
    [
      "vvvvvvvvvvvvvvvv",
      "aaaaaaaaaaaaaaav",
      "aaaaaaaaaaaaaaav",
      "bbbbbbbbaaaaaaav",
      "bd     baaaaaaav",
      " g     baaaaaaav",
      " g   h baaaaaaav",
      " g     baaaaaaav",
      " g     baaaaaaav",
      " g h   baaaaaaav",
      " g     baaaaaaav",
      " d     baaaaaaav",
      " g     baaaaaaav",
      " g     baaaaaaav",
      " g     baaaaaaav",
      " g     baaaaaaav"
    ],
    [
      "vvvvvvvvvvvvvvvv",
      "aaaaaaaaaaaaaaav",
      "aaaaaaaaaaaaaaav",
      "bbbbbbbbaaaaaaav",
      "bd     baaaaaaav",
      " g     baaaaaaav",
      " g   h baaaaaaav",
      " g     baaaaaaav",
      " g     baaaaaaav",
      " g h   baaaaaaav",
      " g     baaaaaaav",
      " d     baaaaaaav",
      " g     baaaaaaav",
      " g     baaaaaaav",
      " g     baaaaaaav",
      " g     baaaaaaav"
    ],
    [
      "vvvvvvvvvvvvvvvv",
      "aaaaaaaaaaaaaaav",
      "aaaaaaaaaaaaaaav",
      "bbbbbbbbaaaaaaav",
      "bd     baaaaaaav",
      " g     baaaaaaav",
      " g   h baaaaaaav",
      " g     baaaaaaav",
      " g     baaaaaaav",
      " g h   baaaaaaav",
      " g     baaaaaaav",
      " d     iaaaaaaav",
      " g     baaaaaaav",
      " g     baaaaaaav",
      " g     baaaaaaav",
      " g     baaaaaaav"
    ],
    [
      "vvvvvvvvvvvvvvvv",
      "aaaaaaaaaaaaaaav",
      "aaaaaaaaaaaaaaav",
      "bbbbbbbbaaaaaaav",
      "bdjjjjjbaaaaaaav",
      "bdjjjjjbaaaaaaav",
      "bdjjjjjbaaaaaaav",
      "bdjjjjjbaaaaaaav",
      "bdjjjjjbaaaaaaav",
      "bdjjjjjbaaaaaaav",
      "bdjjjjjbaaaaaaav",
      "bdjjjjjbaaaaaaav",
      "bdjjjjjbaaaaaaav",
      "bdjjjjjbaaaaaaav",
      "bdjjjjjbaaaaaaav",
      "bdjjjjjbaaaaaaav"
    ]
  ]
}