{
  "name": "multi_condo1_4_ground",
  "refpalette": "c70cities:multi_condo1_4_ground_palette",
  "xsize": 16,
  "zsize": 16,
  "slices": [
    [
      "aaaaaabHHHHHHHHH",
      "aaaaaaabbbbbbccG",
      "aaaaaaadddddbaGG",
      "aaaaaaadddddbaGG",
      "aaaaaaadddddbaGG",
      "aaaaaaadddddbccG",
      "aaaaaaabbbbbbaGG",
      "aaaaaaa     aaGG",
      "aaaaaaa     aaGG",
      "aaaaaaa     baGG",
      "aaaaaae     bccG",
      "aaaaaafbbbbbbaGG",
      "aaaaaaaag   baGG",
      "aaaaaaaah   baGG",
      "aaaaaabbbbbbbccG",
      "aaaaaabHHHHHHHHH"
    ],
    [
      "      b         ",
      "      bbbbbbbcc ",
      "      i  jklb   ",
      "   m  b     n   ",
      "   m  b o o b   ",
      "p  m  bqrrrsbcc ",
      "pt m  bbbbbbb   ",
      "p  m  b     u   ",
      "p  m  w     u   ",
      "pt m  x     b   ",
      "p  m yb     bcc ",
      "   m  bbbbbbb   ",
      "   m  b     n   ",
      "      A Bh  b   ",
      "      bbbbbbbcc ",
      "      b         "
    ],
    [
      "      b         ",
      "     Cbbbbbbbcc ",
      "      D     b   ",
      "   E  bF    I   ",
      "   E  b     b   ",
      "   E  bJKKL bcc ",
      "   E  bbbbbbb   ",
      "M  E  b     u   ",
      "   E  N     u   ",
      "   E  O     b   ",
      "M  E  b     bcc ",
      "   E  bbbbbbb   ",
      "   E  b     I   ",
      "      P  Bh b   ",
      "      bbbbbbbcc ",
      "      b         "
    ],
    [
      "      b         ",
      "      bbbbbbbcc ",
      "      Q     b   ",
      "   E  b     I   ",
      "   E  b     b   ",
      "   E  b KLK bcc ",
      "   E  bbbbbbb   ",
      "   E Rb     u   ",
      "   E  Q     u   ",
      "   E  Q     b   ",
      "   E Sb     bcc ",
      "   E  bbbbbbb   ",
      "   E  b   QhI   ",
      "      Q   Bab   ",
      "      bbbbbbbcc ",
      "      b         "
    ],
    [
      "      b     b   ",
      "      bbbbbbbcc ",
      "      b     b   ",
      "   E  b     b   ",
      "   E  b     b   ",
      "   E  b     bcc ",
      "   E  bbbbbbb   ",
      "   E Tb     u   ",
      "   E  b     u   ",
      "   E  b     b   ",
      "   E Tb     bcc ",
      "   E  bbbbbbb   ",
      "   E  b  Qg b   ",
      "      b     b   ",
      "      bbbbbbbcc ",
      "      b     b   "
    ],
    [
      "      bdddddb   ",
      "      bbbbbbbcc ",
      "      bU    b   ",
      "   E  bU    b   ",
      "   E  bU    b   ",
      "   E  bUUUUUbcc ",
      "   E  bbbbbbb   ",
      "   E  b     u   ",
      "   E  b     u   ",
      "   E  b     b   ",
      "   E  b     bcc ",
      "   E  bbbbbbb   ",
      "   E  b Qg  b   ",
      "      b     b   ",
      "      bbbbbbbcc ",
      "      bdddddb   "
    ]
  ]
}