{
  "name": "multi_condo1_4_floor1",
  "refpalette": "c70cities:multi_condo1_4_floor1_palette",
  "xsize": 16,
  "zsize": 16,
  "slices": [
    [
      "aaaaabccccccde  ",
      "fffgabhiiiiiijj ",
      "   kabhlllllie  ",
      "   kabhlllllie  ",
      "   kabhlllllie  ",
      "   kabhmllllijj ",
      "   kabhiiiiiie  ",
      "   kabhnnnnnhe  ",
      "   kabhnnnnnhe  ",
      "   kabhnnnnnie  ",
      "   kabopnnnnijj ",
      "   kabqiiiiiie  ",
      "   kabhhk   ie  ",
      "   kabhh    ie  ",
      "rrrsabhiiiiiijj ",
      "aaaaabccccccde  "
    ],
    [
      "          m t   ",
      "uuuu  iiiiiiijj ",
      "   u  w    xi   ",
      "   u  i     y   ",
      "   u  i AA  i   ",
      "   u  imBA  ijj ",
      "   u  iiiiiii   ",
      "   u  iCCC  D   ",
      "   u  E     D   ",
      "   u  F    hi   ",
      "   u IiJKJLhijj ",
      "   u  iiiiiii   ",
      "   u  i     y   ",
      "   u  M     i   ",
      "uuuu  iiiiiiijj ",
      "       NNNNNt   "
    ],
    [
      "            t   ",
      "      iiiiiiijj ",
      "      O    xi   ",
      "      iP    Q   ",
      "      i   R i   ",
      "      imS T ijj ",
      "      iiiiiii   ",
      "      iCCC  D   ",
      "      U     D   ",
      "      V    hi   ",
      "      iJJJLhijj ",
      "      iiiiiii   ",
      "      i     Q   ",
      "      W     i   ",
      "      iiiiiiijj ",
      "         N Nt   "
    ],
    [
      "                ",
      "      iiiiiiijj ",
      "      X    xi   ",
      "      i     Q   ",
      "      i     i   ",
      "      imSA  ijj ",
      "      iiiiiii   ",
      "     YiCCC  D   ",
      "      X     D   ",
      "      X    hi   ",
      "     ZiJJJLhijj ",
      "      iiiiiii   ",
      "      i     Q   ",
      "      X     i   ",
      "      iiiiiiijj ",
      "                "
    ],
    [
      "                ",
      "      iiiiiiijj ",
      "      i    xi   ",
      "      i     i   ",
      "      i     i   ",
      "      imS   ijj ",
      "      iiiiiii   ",
      "     0iCCC  D   ",
      "      i     D   ",
      "      i    hi   ",
      "     0iJJJLhijj ",
      "      iiiiiii   ",
      "      i     i   ",
      "      i     i   ",
      "      iiiiiiijj ",
      "                "
    ],
    [
      "                ",
      "      iiiiiiijj ",
      "      illll1i   ",
      "      illllli   ",
      "      illllli   ",
      "      imSlllijj ",
      "      illllli   ",
      "      i22222i   ",
      "      i22222i   ",
      "      i22222i   ",
      "      i22222ijj ",
      "      illllli   ",
      "      illllli   ",
      "      illllli   ",
      "      iiiiiiijj ",
      "                "
    ]
  ]
}