{
  "name": "multi_militarybase_3_floor1",
  "refpalette": "c70cities:multi_militarybase_3_floor1_palette",
  "xsize": 16,
  "zsize": 16,
  "slices": [
    [
      "  a    a        ",
      "  a    a        ",
      "  a    a        ",
      "  a    a        ",
      "  a    a        ",
      "  a    a        ",
      "aaa    a        ",
      "       a        ",
      "       a        ",
      "       a        ",
      "       a        ",
      "aaaaaaaa        ",
      "                ",
      "                ",
      "                ",
      "                "
    ],
    [
      "                ",
      "                ",
      "                ",
      "                ",
      "                ",
      "                ",
      "                ",
      "                ",
      "                ",
      "                ",
      "                ",
      "                ",
      "                ",
      "                ",
      "                ",
      "                "
    ],
    [
      "                ",
      "                ",
      "                ",
      "                ",
      "                ",
      "                ",
      "                ",
      "                ",
      "                ",
      "                ",
      "                ",
      "                ",
      "                ",
      "                ",
      "                ",
      "                "
    ],
    [
      "~~~~~~~~~~~~~~~ ",
      "~~~~~~~~~~~~~~~ ",
      "~~~~~~~~~~~~~~~ ",
      "~~~~~~~~~~~~~~~ ",
      "~~~~~~~~~~~~~~~ ",
      "~~~~~~~~~~~~~~~ ",
      "~~~~~~~~~~~~~~~ ",
      "~~~~~~~~~~~~~~~ ",
      "~~~~~~~~~~~~~~~ ",
      "~~~~~~~~~~~~~~~ ",
      "~~~~~~~~~~~~~~~ ",
      "~~~~~~~~~~~~~~~ ",
      "~~~~~~~~~~~~~~~ ",
      "~~~~~~~~~~~~~~~ ",
      "~~~~~~~~~~~~~~~ ",
      "                "
    ],
    [
      "~~~~~~~~~~~~~~~ ",
      "~~~~~~~~~~~~~~~ ",
      "~~~~~~~~~~~~~~~ ",
      "~~~~~~~~~~~~~~~ ",
      "~~~~~~~~~~~~~~~ ",
      "~~~~~~~~~~~~~~~ ",
      "~~~~~~~~~~~~~~~ ",
      "~~~~~~~~~~~~~~~ ",
      "~~~~~~~~~~~~~~~ ",
      "~~~~~~~~~~~~~~~ ",
      "~~~~~~~~~~~~~~~ ",
      "~~~~~~~~~~~~~~~ ",
      "~~~~~~~~~~~~~~~ ",
      "~~~~~~~~~~~~~~~ ",
      "~~~~~~~~~~~~~~~ ",
      "                "
    ],
    [
      "~~~~~~~~~~~~~~~ ",
      "~~~~~~~~~~~~~~~ ",
      "~~~~~~~~~~~~~~~ ",
      "~~~~~~~~~~~~~~~ ",
      "~~~~~~~~~~~~~~~ ",
      "~~~~~~~~~~~~~~~ ",
      "~~~~~~~~~~~~~~~ ",
      "~~~~~~~~~~~~~~~ ",
      "~~~~~~~~~~~~~~~ ",
      "~~~~~~~~~~~~~~~ ",
      "~~~~~~~~~~~~~~~ ",
      "~~~~~~~~~~~~~~~ ",
      "~~~~~~~~~~~~~~~ ",
      "~~~~~~~~~~~~~~~ ",
      "~~~~~~~~~~~~~~~ ",
      "                "
    ]
  ]
}