{
  "name": "multi_megatower1_1_floor13",
  "refpalette": "c70cities:multi_megatower1_1_floor13_palette",
  "xsize": 16,
  "zsize": 16,
  "slices": [
    [
      "           a b  ",
      "           c b  ",
      "           c bde",
      "           c bff",
      "          gh ihh",
      "           a bhh",
      "           a bhh",
      "           a bhh",
      "           c bhh",
      "           c bhh",
      "           c bhh",
      "          gh ihh",
      "           a bjj",
      "           a b  ",
      "           a b  ",
      "           c b  "
    ],
    [
      "           a k  ",
      "           c kd ",
      "           c kl ",
      "           c k  ",
      "          gh icm",
      "           a n  ",
      "           a n  ",
      "           a n  ",
      "           c n  ",
      "           c n  ",
      "           c n  ",
      "          gh i  ",
      "           a n  ",
      "           a n  ",
      "           a n  ",
      "           c n  "
    ],
    [
      "           a kf ",
      "           c kl ",
      "           c k  ",
      "           c k  ",
      "          gh ico",
      "           a    ",
      "           a    ",
      "           a    ",
      "           c    ",
      "           c    ",
      "           c    ",
      "          gh i  ",
      "           a    ",
      "           a    ",
      "           a    ",
      "           c    "
    ],
    [
      "           a klp",
      "           c k  ",
      "           c k  ",
      "           c k q",
      "          gh icc",
      "           a    ",
      "           a    ",
      "           a    ",
      "           c    ",
      "           c    ",
      "           c    ",
      "          gh i  ",
      "           a    ",
      "           a    ",
      "           a    ",
      "           c    "
    ],
    [
      "           a r e",
      "           c r p",
      "           c r  ",
      "           c r  ",
      "          gh icc",
      "           a r  ",
      "           a r  ",
      "           a r  ",
      "           c r  ",
      "           c r  ",
      "           c r  ",
      "          gh i  ",
      "           a r  ",
      "           a r  ",
      "           a r  ",
      "           c r  "
    ],
    [
      "           a i  ",
      "           c i e",
      "           c i f",
      "           c idf",
      "          ghsiii",
      "           a i  ",
      "           a i  ",
      "           a i  ",
      "           c i  ",
      "           c i  ",
      "           c i  ",
      "          ghsiii",
      "           a i  ",
      "           a i  ",
      "           a i  ",
      "           c i  "
    ]
  ]
}