{
  "name": "multi_laboratory1_11_base2",
  "refpalette": "c70cities:multi_laboratory1_11_base2_palette",
  "xsize": 16,
  "zsize": 16,
  "slices": [
    [
      "aaaaaaaaaaaaabcz",
      "aaaaaaaaaaaaabcz",
      "aaaaaaaaaaaaabcz",
      "aaaaaaaaaaaaabcz",
      "aaaaaaaaaaaaabcz",
      "aaaaaaaaaaaaabcz",
      "aaaadaaaaaaaabcz",
      "aaaaaaaaaaaaabcz",
      "aaaaaaaaaaaaabcz",
      "aaaaaaaaaaaaabcz",
      "aaaaaaaaaaaaabcz",
      "aaaaaaaaaaaaabcz",
      "eaaaaaaaaaaaabcz",
      "eaaadaaaaaaaabcz",
      "feaaaaaaaaaaabcz",
      " eaaaaaaaaaaabcz"
    ],
    [
      "    ghijkiiihbcz",
      "    gl  m   ibcz",
      "    gn o  p ibcz",
      "    g      qibcz",
      "    r     psibcz",
      "    gtuuuuuuhbcz",
      " w fdggggggggbcz",
      "    gx  xx  ybcz",
      "    g        bcz",
      "    g  A    BBcz",
      "    gCDDD EBFIcz",
      "    gJDDD sBFIcz",
      "KL  gMNN    BBcz",
      "Kf  d E     ybcz",
      "fK  g        bcz",
      " K  O       BBcz"
    ],
    [
      "    ghiiii!ihbcz",
      "    P       ibcz",
      "    P       ibcz",
      "    g       ibcz",
      "    Q       ibcz",
      "    gR    SThbcz",
      "   Udggggggggbcz",
      "    g       ybcz",
      "    P       Vbcz",
      "    P       KBcz",
      "    P  W   KFIcz",
      "    PWXYX  KFIcz",
      "K   g       KBcz",
      "KU  d       ybcz",
      "fK  g       Vbcz",
      " K  O       KBcz"
    ],
    [
      "    ghZZZZZZhbcz",
      "    0       1bcz",
      "    0       2bcz",
      "    g       3bcz",
      "    0        bcz",
      "    g       hbcz",
      "   Udggggggggbcz",
      "    g       ybcz",
      "    P        bcz",
      "    P       KBcz",
      "    P      KFIcz",
      "    P      KFIcz",
      "K   g       KBcz",
      "KU  d       ybcz",
      "fK  g        bcz",
      " K  O       KBcz"
    ],
    [
      "    gh      hbcz",
      "    g        bcz",
      "    g        bcz",
      "    g       4bcz",
      "    g        bcz",
      "    g       hbcz",
      "    dggggggggbcz",
      "    g  5  5 6bcz",
      "    g       Vbcz",
      "    g       KBcz",
      "    g      K7Icz",
      "    g      K7Icz",
      "K   g       KBcz",
      "K   d       6bcz",
      "fK  g       Vbcz",
      " K  g       KBcz"
    ],
    [
      "8888099999999bcz",
      "88@809#9999#9bcz",
      "88@8099999999bcz",
      "88@8099999999bcz",
      "88@809#9999$9bcz",
      "8888099999999bcz",
      "8888dggggggggbcz",
      "88880%%%%%%%%bcz",
      "88880^^^^^^^^bcz",
      "88880^^ ^^@^BBcz",
      "88880^^@^^@B&Icz",
      "88880^^$^^$B&Icz",
      "K8880^^*^^@^BBcz",
      "K888d^^^^^^^^bcz",
      "fK880^^^^^^^^bcz",
      " K880^^@^^@^BBcz"
    ]
  ]
}