{
  "name": "multi_hospital_3_base1",
  "refpalette": "c70cities:multi_hospital_3_base1_palette",
  "xsize": 16,
  "zsize": 16,
  "slices": [
    [
      "aabbbbbbbbbbbbbv",
      "aabbbbbbbbbbbbbv",
      "aaaaaaaaaaaaaaav",
      "aacccccccccccccv",
      "aacccccccccccccv",
      "aacccccccccccccv",
      "aacccccccccccccv",
      "aacccccccccccccv",
      "aacccccccccccccv",
      "dacccccccccccccv",
      "aacccccccccccccv",
      "cccccccccccccccv",
      "cccccccccccccccv",
      "cccccccccccccccv",
      "cccccccccccccccv",
      "vvvvvvvvvvvvvvvv"
    ],
    [
      "efbgbgb b bhb!bv",
      " fb b b b b b bv",
      "iavvvvvvvvvvvvvv",
      "efcccccccccccccv",
      " fcccccccccccccv",
      "iacccccccccccccv",
      "jfcccccccccccccv",
      " fcccccccccccccv",
      "kacccccccccccccv",
      "ddcccccccccccccv",
      "dacccccccccccccv",
      "cccccccccccccccv",
      "cccccccccccccccv",
      "cccccccccccccccv",
      "cccccccccccccccv",
      "vvvvvvvvvvvvvvvv"
    ],
    [
      " fblblblblblblbv",
      " fblblblblblblbv",
      "mavvvvvvvvvvvvvv",
      " fcccccccccccccv",
      " fcccccccccccccv",
      "macccccccccccccv",
      " fcccccccccccccv",
      " fcccccccccccccv",
      "kacccccccccccccv",
      "ddcccccccccccccv",
      "dacccccccccccccv",
      "cccccccccccccccv",
      "cccccccccccccccv",
      "cccccccccccccccv",
      "cccccccccccccccv",
      "vvvvvvvvvvvvvvvv"
    ],
    [
      " fbnbnbnbnbnbnbv",
      " fbnbnbnbnbnbnbv",
      " avvvvvvvvvvvvvv",
      " fcccccccccccccv",
      " fcccccccccccccv",
      " acccccccccccccv",
      " fcccccccccccccv",
      " fcccccccccccccv",
      "kacccccccccccccv",
      "ddcccccccccccccv",
      "dacccccccccccccv",
      "cccccccccccccccv",
      "cccccccccccccccv",
      "cccccccccccccccv",
      "cccccccccccccccv",
      "vvvvvvvvvvvvvvvv"
    ],
    [
      " fb!bhb b b bhbv",
      " fb b b b b b bv",
      " avvvvvvvvvvvvvv",
      " fcccccccccccccv",
      " fcccccccccccccv",
      " acccccccccccccv",
      " fcccccccccccccv",
      " fcccccccccccccv",
      "kacccccccccccccv",
      "ddcccccccccccccv",
      "dacccccccccccccv",
      "cccccccccccccccv",
      "cccccccccccccccv",
      "cccccccccccccccv",
      "cccccccccccccccv",
      "vvvvvvvvvvvvvvvv"
    ],
    [
      "oabbbbbbbbbbbbbv",
      "oabbbbbbbbbbbbbv",
      "aavvvvvvvvvvvvvv",
      "oacccccccccccccv",
      "oacccccccccccccv",
      "oacccccccccccccv",
      "oacccccccccccccv",
      "oacccccccccccccv",
      "aacccccccccccccv",
      "dacccccccccccccv",
      "aacccccccccccccv",
      "cccccccccccccccv",
      "cccccccccccccccv",
      "cccccccccccccccv",
      "cccccccccccccccv",
      "vvvvvvvvvvvvvvvv"
    ]
  ]
}