{
  "name": "multi_megatower1_3_base1",
  "refpalette": "c70cities:multi_megatower1_3_base1_palette",
  "xsize": 16,
  "zsize": 16,
  "slices": [
    [
      "vvvvvvvvvvvvvvvv",
      "aaaaaaaaaaaaaaaa",
      "aaaaaaaaaaaaaaaa",
      "vvvvvvvvvvvvvvvv",
      "vvvvvvvvvvvvvvvv",
      "HHHHHHHHHHHHHHHH",
      "HHHHbHHHHHHbHHHH",
      "HHHHHHHHHHHHHHHH",
      "HHHHHHHHHHHHHHHH",
      "HHHHHHHHHHHHHHHH",
      "HHHHHHHHHHHHHHHH",
      "HHHHHHHHHHHHHHHH",
      "HHHHHHHHHHHHHHHH",
      "vvvvbHHHHHHbHHHH",
      "cdddvHHHHHHHHHHH",
      "c   vHHHHHHHHHHH"
    ],
    [
      "vvvvvvvvvvvvvvvv",
      "aaaaaaaaaaaaaaaa",
      "aaaaaaaaaaaaaaaa",
      "vvvvvvvvvvvvvvvv",
      "eeeeeeeeeeeeeeee",
      "fgfg fgfgfg fgfg",
      "    b   h  b    ",
      "ijijkijijijkijij",
      "                ",
      "                ",
      "                ",
      "                ",
      "    lfgfgfglfgfg",
      "mmmmb      b    ",
      "cdddnijijij ijij",
      "c   n           "
    ],
    [
      "vvvvvvvvvvvvvvvv",
      "aaaaaaaaaaaaaaaa",
      "aaaaaaaaaaaaaaaa",
      "vvvvvvvvvvvvvvvv",
      "                ",
      "                ",
      "    b      b    ",
      "                ",
      "                ",
      "                ",
      "                ",
      "                ",
      "                ",
      "mmmmb      b    ",
      "cdddn           ",
      "c   n           "
    ],
    [
      "vvvvvvvvvvvvvvvv",
      "aaaaaaaaaaaaaaaa",
      "aaaaaaaaaaaaaaaa",
      "vvvvvvvvvvvvvvvv",
      "                ",
      "                ",
      "    b      b    ",
      "                ",
      "                ",
      "                ",
      "                ",
      "                ",
      "                ",
      "mmmmb      b    ",
      "cdddn           ",
      "c   n           "
    ],
    [
      "vvvvvvvvvvvvvvvv",
      "aaaaaaaaaaaaaaaa",
      "aaaaaaaaaaaaaaaa",
      "vvvvvvvvvvvvvvvv",
      "                ",
      "                ",
      "    b      b    ",
      "                ",
      "                ",
      "                ",
      "                ",
      "                ",
      "                ",
      "mmmmb      b    ",
      "cdddn           ",
      "c   n           "
    ],
    [
      "vvvvvvvvvvvvvvvv",
      "aaaaaaaaaaaaaaaa",
      "aaaaaaaaaaaaaaaa",
      "vvvvvvvvvvvvvvvv",
      "vvvvvvvvvvvvvvvv",
      "oooooooooooooooo",
      "bbbbbbbbbbbbbbbb",
      "oooobooooooboooo",
      "oooobooooooboooo",
      "oooobooooooboooo",
      "oooobooooooboooo",
      "oooobooooooboooo",
      "oooobooooooboooo",
      "bbbbbbbbbbbbbbbb",
      "bdddbooooooooooo",
      "b   booooooooooo"
    ]
  ]
}