{
  "name": "multi_laboratory1_13_floor1",
  "refpalette": "c70cities:multi_laboratory1_13_floor1_palette",
  "xsize": 16,
  "zsize": 16,
  "slices": [
    [
      "abzzcdde        ",
      "abzzcdde        ",
      "aabbcfge        ",
      "aaaacdde        ",
      "aaaacdde        ",
      "aaaacdde        ",
      "aaaacdde        ",
      "aaaacdde        ",
      "aaaacddh        ",
      "aaaacfgi        ",
      "aaaacddj        ",
      "aaaacddj        ",
      "aaaacddj        ",
      "aaaacddj        ",
      "aaaacddj        ",
      "aaaacddj        "
    ],
    [
      " kl m  n        ",
      " oppm  i        ",
      "  ooq  i        ",
      "    m  i        ",
      "    m  i        ",
      "    m  i        ",
      "    m  n        ",
      "   rm  i        ",
      "   sm  i        ",
      "   tu  j        ",
      "    m  j        ",
      "    m  j        ",
      "   rm  j        ",
      "   sm  j        ",
      "   tm  n        ",
      "    m  j        "
    ],
    [
      "       j        ",
      "       j        ",
      "       j        ",
      "       j        ",
      "       n        ",
      "       j        ",
      "       j        ",
      "       j        ",
      "   w   j        ",
      "    u  j        ",
      "       j        ",
      "       n        ",
      "       j        ",
      "       j        ",
      "       j        ",
      "       j        "
    ],
    [
      "       j        ",
      "       j        ",
      "       j        ",
      "       j        ",
      "       j        ",
      "       j        ",
      "       j        ",
      "       n        ",
      "       j        ",
      "    u  j        ",
      "       j        ",
      "       j        ",
      "       j        ",
      "       j        ",
      "       j        ",
      "       j        "
    ],
    [
      "       j        ",
      "       j        ",
      "       j        ",
      "       j        ",
      "       j        ",
      "       j        ",
      "       j        ",
      "       j        ",
      "       j        ",
      "    u  n        ",
      "       j        ",
      "       j        ",
      "       j        ",
      "       j        ",
      "       j        ",
      "       j        "
    ],
    [
      "       j        ",
      "       j        ",
      "       j        ",
      "g      j        ",
      "gg     j        ",
      " gg    j        ",
      "  g    j        ",
      "  gg   j        ",
      "   g   j        ",
      "   gc  j        ",
      "    g  j        ",
      "    g  j        ",
      "    g  j        ",
      "    g  j        ",
      "    g  j        ",
      "    g  j        "
    ]
  ]
}