{
  "name": "multi_communitycenter_1_ground",
  "refpalette": "c70cities:multi_communitycenter_1_ground_palette",
  "xsize": 16,
  "zsize": 16,
  "slices": [
    [
      "aabcdd  e dd f  ",
      "aabcgdhi  dd  je",
      "aabcdd ie dd hje",
      "aabcgdh   dd    ",
      "aabcdd  f dd   e",
      "aabcgdhi  ddh j ",
      "aabcddhie dd hje",
      "aabkkkkkkllllkkk",
      "aammmmmmnmmmmnmm",
      "aamooooonmmmmnpp",
      "aamoooooonmmmmnp",
      "aammooooonmmmmnp",
      "aaamooooonmmmmnp",
      "aaamoooooonmmmmn",
      "aaammooooonmmmmm",
      "aaaamoooooonmmmm"
    ],
    [
      "  b             ",
      "  bq            ",
      "  b             ",
      "  bq            ",
      "  b             ",
      "  b             ",
      "  b             ",
      "  bkkkkkk    kkk",
      "  bbrrrbk    kbs",
      "  b     t    t  ",
      "  b      u    wx",
      "  bbrrr  u    w ",
      "   b     u    w ",
      "   b      u    w",
      "   bbrrr  u     ",
      "    b           "
    ],
    [
      "  yAAAAAAAAAAAAA",
      "  y    B      B ",
      "  b             ",
      "  b             ",
      "  y             ",
      "  y    B      C ",
      "  y             ",
      "  bkkkkkk    kkk",
      "  bbDDDbk    kbs",
      "  y     t    t  ",
      "  y      u    w ",
      "  yyEFI  u    w ",
      "   y     u    w ",
      "   b      u    w",
      "   byJKL  u     ",
      "    y           "
    ],
    [
      "  bMMMMMMMMMMMMM",
      "  bNNNNNNNNNNNNN",
      "  bAAAAAAAAAAAAA",
      "  bAAAAAAAAAAAAA",
      "  yAAAAAAAAAAAAA",
      "  y    O      O ",
      "  y             ",
      "  bkkkkkk    kkk",
      "  bbbbbbk    kbs",
      "  y     t    t  ",
      "  y      u    w ",
      "  yy     u    w ",
      "   y     u    w ",
      "   b      u    w",
      "   by     u     ",
      "    y           "
    ],
    [
      "  bP  Q  RRRRRRR",
      "  bMMMMMMMMMMMMM",
      "  bMMMMMMMMMMMMM",
      "  bMMMMMMMMMMMMM",
      "  bMMMMMMMMMMMMM",
      "  bNNNNNNNNNNNNN",
      "  bNNNNNNNNNNNNN",
      "  bkkkkkk    kkk",
      "  bbbbbbk    kbb",
      "  b     t    t  ",
      "  b      t    S ",
      "  bb     t    S ",
      "   b     t    S ",
      "   b      t    S",
      "   bb     t     ",
      "    b      t    "
    ],
    [
      "   P            ",
      "   P            ",
      "  TP            ",
      "  TP            ",
      "  bPRRRRR   Q RR",
      "  bMMMMMMMMMMMMM",
      "  brMMMMMMMMMMMM",
      "  brMMMMkkkkkkMM",
      "  bMMMMrk    krM",
      "  bNNNNNk    kkN",
      "  bNNNNNkk    kN",
      "  bbNNNNNk    kN",
      "   bNNNNNk    kk",
      "   bNNNNNkk    k",
      "   bbNNNNNk    U",
      "    bNNNNNkk  UU"
    ]
  ]
}