{
  "name": "multi_militarybase_0_ground",
  "refpalette": "c70cities:multi_militarybase_0_ground_palette",
  "xsize": 16,
  "zsize": 16,
  "slices": [
    [
      "aaaaaaaaaaaaaaaa",
      "abbbbbbbbbbbbbbb",
      "abczzczcczczzzzz",
      "abzzzzcccczccccc",
      "abzczzzcdddddddd",
      "abzzzzccdeeeeeee",
      "abzzzzczdfeeeeee",
      "abzzzzzcd eeeeee",
      "abzzczzcd eeeeee",
      "abcczzccd eeeddd",
      "abzzzzzcdeeeeddd",
      "abzczzczdeeeeddd",
      "abzzzzzcdeeeeddd",
      "gbczzcccdddddddd",
      "hicccczccccccccc",
      "hicccccccccccccc"
    ],
    [
      "                ",
      " bbbbbbbbbbbbbbb",
      " bj k k jk k k k",
      " b  k           ",
      " bk  k  llllllll",
      " b   k  lm   n o",
      " b kk   l p     ",
      " b k k  l p     ",
      " b    k l p  qr ",
      " bj  k  l p  lls",
      " bk k k lt   l  ",
      " bk  k  l  uwl  ",
      " b  k   lxxxxl  ",
      "yb      llllll  ",
      "y A             ",
      "      A        A"
    ],
    [
      "                ",
      " bbbbbbbbbbbbbbb",
      " bj     j       ",
      " b              ",
      " b      BCCCCBBB",
      " b      B     n ",
      " b      C       ",
      " b      C       ",
      " b      B    qD ",
      " bj     B    BBE",
      " b      C    B  ",
      " b      C    C  ",
      " b      BFIJ B  ",
      " b      BBCCBB  ",
      "                ",
      "                "
    ],
    [
      "                ",
      " bbbbbbbbbbbbbbb",
      " bj     j       ",
      " b       KKKK   ",
      " b      BBBBBBBB",
      " b     KB      n",
      " b     KB       ",
      " b     KB       ",
      " b     KB    q  ",
      " bj    KB    BBB",
      " b     KB    B  ",
      " b     KB    C  ",
      " b     KB    B  ",
      " b      BBCCBB  ",
      "                ",
      "                "
    ],
    [
      "                ",
      " bbbbbbbbbbbbbbb",
      " bj     j       ",
      " b              ",
      " b      BLLLLBBB",
      " b      BMMMMM  ",
      " b      LM      ",
      " b      LM      ",
      " b      BM   qMM",
      " bj     BM   BBL",
      " b      LM   B  ",
      " b      LM   B  ",
      " b      BM   B  ",
      " b      BBBBBB  ",
      "                ",
      "                "
    ],
    [
      "                ",
      " NNOOOOOPOOOOOOO",
      " Nmmmmmmmmmmmmmm",
      " ym      Q      ",
      " ym     llllllll",
      " ym     laaaaa  ",
      " ym     laaaaaaa",
      " ym     laaaaaaa",
      " Rm     laaaaqaa",
      "STm     laaaalll",
      " ym     laaaal  ",
      " y      laaaal  ",
      " y      laaaal  ",
      " y      laaaal  ",
      "        lUUUUl  ",
      "        lUUUUl  "
    ]
  ]
}