{
  "name": "multi_communitycenter_5_floor1",
  "refpalette": "c70cities:multi_communitycenter_5_floor1_palette",
  "xsize": 16,
  "zsize": 16,
  "slices": [
    [
      "aabbcccccccccccc",
      "aaadbbbccccccccc",
      "aaaaaabdbbbdbbbb",
      "aaaaaaaaaaaaaaab",
      "baaaaaaaaaaaaaab",
      "bbbaaaaaaaaaaaab",
      "ccbdbbaaaaaaaaab",
      "cccccbbdbbbdbbbb",
      "cccccccccccccccc",
      "cccccccccccccccc",
      "cccccccccccccccc",
      "eecccccccccccccc",
      " eeeecccffcccccc",
      "    eeeeeeeeeeee",
      "                ",
      "                "
    ],
    [
      "  gghijk    k   ",
      "   lgggmnijmmijo",
      "      glggglgggp",
      "               p",
      "g              p",
      "ggg            p",
      " qglgg         p",
      "  k mgglggglggg!",
      "k    rsmhrshnrsh",
      "tm    k   k    k",
      "tttuk    m   k  ",
      "wwtttt  k  u km ",
      " wwwwttttttttttt",
      "    wwwwwwwwwwww",
      "                ",
      "                "
    ],
    [
      "                ",
      "               o",
      "               o",
      "                ",
      "                ",
      "                ",
      " ~             o",
      "                ",
      "                ",
      "                ",
      "                ",
      "                ",
      "                ",
      "                ",
      "                ",
      "                "
    ],
    [
      "                ",
      "               x",
      "               x",
      "                ",
      "                ",
      "                ",
      "               x",
      "                ",
      "                ",
      "                ",
      "                ",
      "                ",
      "                ",
      "                ",
      "                ",
      "                "
    ],
    [
      "             yyb",
      "             yyb",
      "             yyb",
      "             yyb",
      "             yyb",
      "             yyb",
      "             yyb",
      "             yyy",
      "             yyy",
      "                ",
      "                ",
      "                ",
      "                ",
      "                ",
      "                ",
      "                "
    ],
    [
      "                ",
      "                ",
      "                ",
      "                ",
      "                ",
      "                ",
      "                ",
      "                ",
      "                ",
      "                ",
      "                ",
      "                ",
      "                ",
      "                ",
      "                ",
      "                "
    ]
  ]
}