{
  "name": "multi_flatapartment_2_floor1",
  "refpalette": "c70cities:multi_flatapartment_2_floor1_palette",
  "xsize": 16,
  "zsize": 16,
  "slices": [
    [
      "                ",
      "abbbbabbbabbbba ",
      "ccccccccccccccb ",
      "dddddddddddddcb ",
      "dddddddddddddcb ",
      "dddddddddddddca ",
      "dddddddddddddcb ",
      "dddddddddddddcb ",
      "dddddddddddddcb ",
      "dddddddddddddcb ",
      "dddddddddddddca ",
      "dddddddddddddcb ",
      "dddddddddddddcb ",
      "ccccccccccccccb ",
      "abbbbabbbabbbba ",
      "                "
    ],
    [
      "                ",
      "abeebabebabeeba ",
      "         f    b ",
      " g g hii h    e ",
      " jjj h   h kl b ",
      "hhhhhh   hhhhha ",
      "hm  nhoo p    b ",
      "hm  nhhhhh    e ",
      "h    q  rh ss e ",
      "hg g h tuhwxxyb ",
      "hjjj h tuhhhhha ",
      "ABCC h   f DE b ",
      "     hhhhh    e ",
      "         F    b ",
      "abeebabebabeeba ",
      "                "
    ],
    [
      "                ",
      "abIIbabIbabIIba ",
      "         J    b ",
      "     h   h    I ",
      "K    h   h  L b ",
      "hhhhhh   hhhhha ",
      "hM   hMM N    b ",
      "hM   hhhhh    I ",
      "h    O   h    I ",
      "h    h   h    b ",
      "h    h   hhhhha ",
      "     h   J  P b ",
      "     hhhhh    I ",
      "         Q    b ",
      "abIIbabIbabIIba ",
      "                "
    ],
    [
      "                ",
      "abIIbabIbabIIba ",
      "         h    b ",
      "     h   h    I ",
      "     h   h    b ",
      "hhhhhh   hhhhha ",
      "hM   hMM h    b ",
      "hM   hhhhh    I ",
      "h    h   h    I ",
      "h    h   h    b ",
      "h    h   hhhhha ",
      "     h   h    b ",
      "     hhhhh    I ",
      "         h    b ",
      "abIIbabIbabIIba ",
      "                "
    ],
    [
      "                ",
      "abbbbabbbabbbba ",
      "h    h   hRRRRb ",
      "h    h   hRRRRb ",
      "h    h S hRRRRb ",
      "hhhhhh   hhhhha ",
      "h    h   h    b ",
      "h  S hhhhh    b ",
      "h    h   h    b ",
      "h    h   h    b ",
      "h    h   hhhhha ",
      "h    h   hRRRRb ",
      "h    hhhhhRRRRb ",
      "h    h   hRRRRb ",
      "abbbbabbbabbbba ",
      "                "
    ],
    [
      "                ",
      "TUUUUTUUUTUUUUT ",
      "ccccccccccccccU ",
      "dddddddddddddcU ",
      "dddddddddddddcU ",
      "dddddddddddddcT ",
      "dddddddddddddcU ",
      "dddddddddddddcU ",
      "dddddddddddddcU ",
      "dddddddddddddcU ",
      "dddddddddddddcT ",
      "dddddddddddddcU ",
      "dddddddddddddcU ",
      "ccccccccccccccU ",
      "TUUUUTUUUTUUUUT ",
      "                "
    ]
  ]
}