{
  "name": "multi_hospital_1_base2",
  "refpalette": "c70cities:multi_hospital_1_base2_palette",
  "xsize": 16,
  "zsize": 16,
  "slices": [
    [
      "vvvvvvvvvvvvvvvv",
      "vvvvvvvvvvvvvvvv",
      "vvvvvvvvvvvvvvvv",
      "vvvvvvvvvvvvvvvv",
      "vvvvvvvvvvvvvvvv",
      "vvvvvvvvvvvvvvvv",
      "vvvvvvvvvvvvvvvv",
      "vvvvvvvvvvvvvvvv",
      "vvvvvvvvvvvvvvvv",
      "vvvvvvvvvvvvvvvv",
      "vvvvvvvvvvvvvvvv",
      "vvvvvvvvvvvvvvvv",
      "vvvvvvvvvvvvvvvv",
      "vvvvvvvvvvvvvvvv",
      "vvvvvvvvvvvvvvvv",
      "vvvvvvvvvvvvvvvv"
    ],
    [
      "vaaaaaaaabcccccc",
      "vaaaaaaaabcccccc",
      "vaaaaaaaabcccccc",
      "vaaaaaaaabcccccc",
      "vaaaaaaaabcccccc",
      "vaaaaaaaabcccccc",
      "vaaaaaaaabcccccc",
      "vaaaaaaaabcccccc",
      "vaaaaaaaabcccccc",
      "vaaaaaaaabcccccc",
      "vaaaaaaaabbbbbbb",
      "vaaaaaaaaaaaaaaa",
      "vaaaaaaaaaaaaaaa",
      "vaaaaaaaaaaaaaaa",
      "vaaaaaaaaaaaaaaa",
      "vvvvvvvvvvvvvvvv"
    ],
    [
      "vaaaaaaaabd  ed ",
      "vaaaaaaaabf     ",
      "vaaaaaaaabdg  d ",
      "vaaaaaaaabd  ed ",
      "vaaaaaaaabh     ",
      "vaaaaaaaabdg  d ",
      "vaaaaaaaabd  ed ",
      "vaaaaaaaab      ",
      "vaaaaaaaabijiji ",
      "vaaaaaaaabk   l ",
      "vaaaaaaaabbbbbbb",
      "vaaaaaaaaaaaaaaa",
      "vaaaaaaaaaaaaaaa",
      "vaaaaaaaaaaaaaaa",
      "vaaaaaaaaaaaaaaa",
      "vvvvvvvvvvvvvvvv"
    ],
    [
      "vaaaaaaaabm   n ",
      "vaaaaaaaabo     ",
      "vaaaaaaaab    p ",
      "vaaaaaaaabq   q ",
      "vaaaaaaaabo     ",
      "vaaaaaaaab      ",
      "vaaaaaaaabq   n ",
      "vaaaaaaaabo     ",
      "vaaaaaaaabijiji ",
      "vaaaaaaaab   l  ",
      "vaaaaaaaabbbbbbb",
      "vaaaaaaaaaaaaaaa",
      "vaaaaaaaaaaaaaaa",
      "vaaaaaaaaaaaaaaa",
      "vaaaaaaaaaaaaaaa",
      "vvvvvvvvvvvvvvvv"
    ],
    [
      "vaaaaaaaab      ",
      "vaaaaaaaab      ",
      "vaaaaaaaab      ",
      "vaaaaaaaab      ",
      "vaaaaaaaab      ",
      "vaaaaaaaab      ",
      "vaaaaaaaab      ",
      "vaaaaaaaab      ",
      "vaaaaaaaabijiji ",
      "vaaaaaaaab  l   ",
      "vaaaaaaaabbbbbbb",
      "vaaaaaaaaaaaaaaa",
      "vaaaaaaaaaaaaaaa",
      "vaaaaaaaaaaaaaaa",
      "vaaaaaaaaaaaaaaa",
      "vvvvvvvvvvvvvvvv"
    ],
    [
      "vaaaaaaaabrrrrrr",
      "vaaaaaaaabrrrrrr",
      "vaaaaaaaabrrrrrr",
      "vaaaaaaaabrrrrrr",
      "vaaaaaaaabrrrrrr",
      "vaaaaaaaabrrrrrr",
      "vaaaaaaaabrrrrrr",
      "vaaaaaaaabrrrrrr",
      "vaaaaaaaabijiji ",
      "vaaaaaaaab l    ",
      "vaaaaaaaabbbbbbb",
      "vaaaaaaaaaaaaaaa",
      "vaaaaaaaaaaaaaaa",
      "vaaaaaaaaaaaaaaa",
      "vaaaaaaaaaaaaaaa",
      "vvvvvvvvvvvvvvvv"
    ]
  ]
}