{
  "name": "multi_laboratory1_12_base6",
  "refpalette": "c70cities:multi_laboratory1_12_base6_palette",
  "xsize": 16,
  "zsize": 16,
  "slices": [
    [
      " abbbbbbbbbbbcdv",
      " abbbbbbbbbbbcdv",
      " abbbbbbbbbbbcdv",
      "eabbbbbbbbbbbcdv",
      "abbbfbbbbbbbbcdv",
      "abbbbbbbbbbbbcdv",
      "bbbbbbbbbbbbbcdv",
      "bbbbbbbbbbbbbcdv",
      "bbbbbbbbbgbbbcdv",
      "bbbbbbbbbbhbbcdv",
      "bbbbbgbbbbbbbcdv",
      "bbbbfigbbgbbbcdv",
      "bbbbbbbbigbbbcdv",
      "bbbbbbbbgggbbcdv",
      "bbbbbbbbibggbcdv",
      "bbbbgbgiggbbbcdv"
    ],
    [
      " j  k       lcdv",
      " j  km      lcdv",
      " j  k        cdv",
      "ej n      oooodv",
      "j   f     opqcdv",
      "j   r     oooodv",
      "    ks  t    cdv",
      "    k       lcdv",
      "    k    uu lcdv",
      "   wk   x uggcdv",
      " s yl     oooodv",
      "A mBfC DtioEFcdv",
      "IJ tKm   Lgooodv",
      "        u Miicdv",
      "t Nt     D ulcdv",
      "N      u Ltuicdv"
    ],
    [
      " j  O      PQcdv",
      " j         PQcdv",
      " j  R       Scdv",
      "ej         joodv",
      "j   f     jpqcdv",
      "j          joodv",
      "    n       Tcdv",
      "    O      PQcdv",
      "    U       Vcdv",
      "           ugcdv",
      "    W     igoodv",
      "    f     gEFcdv",
      "           hoodv",
      "          uuicdv",
      "             cdv",
      "            Lcdv"
    ],
    [
      " j           cdv",
      " j           cdv",
      " j           cdv",
      "ej         joodv",
      "j   f     jpqcdv",
      "j          joodv",
      "             cdv",
      "             cdv",
      "             cdv",
      "            Lcdv",
      "          ijoodv",
      "    f     jEFcdv",
      "           Xoodv",
      "             cdv",
      "             cdv",
      "             cdv"
    ],
    [
      " j          Ycdv",
      " j          Ycdv",
      " j           cdv",
      "ej         joodv",
      "j   f     jpqcdv",
      "j          joodv",
      "             cdv",
      "            Ycdv",
      "            Ycdv",
      "             cdv",
      "          ujoodv",
      "    f     jEFcdv",
      "           joodv",
      "             cdv",
      "            Ycdv",
      "            Ycdv"
    ],
    [
      " j          Zcdv",
      " j           cdv",
      " j           cdv",
      "ej         joodv",
      "j   f     jpqcdv",
      "j          joodv",
      "             cdv",
      "             cdv",
      "            Zcdv",
      "             cdv",
      "           joodv",
      "    f     jEFcdv",
      "           joodv",
      "             cdv",
      "            Zcdv",
      "            tcdv"
    ]
  ]
}