{
  "name": "multi_laboratory1_2_base5",
  "refpalette": "c70cities:multi_laboratory1_2_base5_palette",
  "xsize": 16,
  "zsize": 16,
  "slices": [
    [
      "zab           c ",
      "zadd          c ",
      "zad           c ",
      "zaeec         cf",
      "zabg c     hi  c",
      "zaeec          c",
      "zabd            ",
      "zabd            ",
      "zabd            ",
      "zab             ",
      "zaeec           ",
      "zabjkc     hl   ",
      "zaeec           ",
      "zab             ",
      "zabd            ",
      "zab             "
    ],
    [
      "zab           c ",
      "zabd          c ",
      "zab           c ",
      "zaeec         cf",
      "zabg c     h   c",
      "zaeec          c",
      "zab             ",
      "zab             ",
      "zabd            ",
      "zab             ",
      "zaeec           ",
      "zabjkc     h    ",
      "zaeec           ",
      "zabd            ",
      "zabd            ",
      "zab             "
    ],
    [
      "zabd          c ",
      "zabd          c ",
      "zab           c ",
      "zaeec         cf",
      "zabg c     h   c",
      "zaeec          c",
      "zab             ",
      "zab             ",
      "zabd            ",
      "zab             ",
      "zaeec           ",
      "zabgkc     h    ",
      "zaeec           ",
      "zab             ",
      "zabd            ",
      "zab             "
    ],
    [
      "zab           c ",
      "zabd          c ",
      "zab           c ",
      "zaeec         cf",
      "zabg c     h   c",
      "zaeec          c",
      "zab             ",
      "zab             ",
      "zadd            ",
      "zad             ",
      "zaeec           ",
      "zabgkc     h    ",
      "zaeec           ",
      "zab             ",
      "zabd            ",
      "zab             "
    ],
    [
      "zab           c ",
      "zabd          c ",
      "zab           c ",
      "zaeec         cf",
      "zabg c     h   c",
      "zaeec          c",
      "zab             ",
      "zab             ",
      "zabd            ",
      "zab             ",
      "zaeec           ",
      "zabgkc     h    ",
      "zaeec           ",
      "zab             ",
      "zabd            ",
      "zab             "
    ],
    [
      "zabdmmmmmmmmmmc ",
      "zabnmmmmmmmmmmc ",
      "zabdmmmmmmmmmmc ",
      "zaeeeemmmmmmmmcf",
      "zabgoemmmmmhmmmc",
      "zaeeeemmmmmmmmmc",
      "zabdmmmmmmmmmmmm",
      "zabdmmmmmmmmmmmm",
      "zabnmmmmmmmmmmmm",
      "zabdmmmmmmmmmmmm",
      "zaeeeemmmmmmmmmm",
      "zabgpemmmmmhmmmm",
      "zaeeeemmmmmmmmmm",
      "zabdmmmmmmmmmmmm",
      "zabnmmmmmmmmmmmm",
      "zabdmmmmmmmmmmmm"
    ]
  ]
}