{
  "name": "multi_laboratory1_1_base2",
  "refpalette": "c70cities:multi_laboratory1_1_base2_palette",
  "xsize": 16,
  "zsize": 16,
  "slices": [
    [
      "vabccccccccccccc",
      "vabccccccccccccc",
      "vabccccccccccccc",
      "vabccccccccccccc",
      "vabccccccccccccc",
      "vabccccccccccccc",
      "vabccccccccdcccc",
      "vabccccccccccccc",
      "vabccccccccccccc",
      "vabccccccccccccc",
      "vabccccccccccccc",
      "vabccccccccccccc",
      "vabcccccccccccce",
      "vabccccccccdccce",
      "vabcccccccccccef",
      "vabccccccccccce "
    ],
    [
      "vabghhhhhhgi    ",
      "vabh j    ki    ",
      "vabh      li    ",
      "vabh      mi    ",
      "vabh    no p    ",
      "vabgqrsrqqqi    ",
      "vabiiiiiiiidf t ",
      "vabl uuuulli    ",
      "vab  w     i    ",
      "vabx    j  i    ",
      "vabx  yno  i    ",
      "vabA BBBBn i    ",
      "vabCmuuuu  i  DE",
      "vab  FI    d  fE",
      "vab        i  Ef",
      "vabA my    J  E "
    ],
    [
      "vabghhhhhhgi    ",
      "vabh       K    ",
      "vabh       K    ",
      "vabh       i    ",
      "vabh       L    ",
      "vabgq   Ms i    ",
      "vabiiiiiiiidN   ",
      "vab   OPQ  i    ",
      "vab        K    ",
      "vab        K    ",
      "vab        K    ",
      "vab   RST  K    ",
      "vab  U O   i   E",
      "vab        d  NE",
      "vab        i  Ef",
      "vab        J  E "
    ],
    [
      "vabgVVVVVVgi    ",
      "vab        W    ",
      "vabX       W    ",
      "vabY       i    ",
      "vabZ       W    ",
      "vabg       i    ",
      "vabiiiiiiiidN   ",
      "vab        i    ",
      "vab        K    ",
      "vab        K    ",
      "vab        K    ",
      "vab        K    ",
      "vab        i   E",
      "vab        d  NE",
      "vab        i  Ef",
      "vab        J  E "
    ],
    [
      "vabg      gi    ",
      "vab !      i    ",
      "vab        i    ",
      "vab0       i    ",
      "vab        i    ",
      "vabg       i    ",
      "vabiiiiiiiid    ",
      "vab        i    ",
      "vab        i    ",
      "vab        i    ",
      "vab        i    ",
      "vab        i    ",
      "vab        i   E",
      "vab        d   E",
      "vab        i  Ef",
      "vab        i  E "
    ],
    [
      "vabg111111gW2222",
      "vab13111141W2522",
      "vab11111111W2522",
      "vab11111111W2522",
      "vab14111131W2522",
      "vabg1111111W2222",
      "vabiiiiiiiid2222",
      "vab66666666W2222",
      "vab66666666W2222",
      "vab66766566W2222",
      "vab66766366W2222",
      "vab66566566W2222",
      "vab66366766W222E",
      "vab66666666d222E",
      "vab66666666W22Ef",
      "vab66566766W22E "
    ]
  ]
}