{
  "name": "multi_convenientstore_3_ground",
  "refpalette": "c70cities:multi_convenientstore_3_ground_palette",
  "xsize": 16,
  "zsize": 16,
  "slices": [
    [
      "aaaaaaaaaaaaHHHb",
      "cccccccccccaHHHb",
      "cccccccccccaHHHb",
      "cccccccccccaHHHb",
      "cccccccccccaHHHb",
      "cccccccccccaHHHb",
      "cccccccccccaHHHb",
      "cccccccccccaHHHb",
      "cccccccccccaHHHb",
      "cccccccccccaHHHb",
      "cccccccccccaHHHb",
      "cccccccccccaHHHb",
      "aaaaaaaaaaaaHHHb",
      "HHHHHHHHHHHHHHHb",
      "HHHHHHHHHHHHHHHb",
      "bbbbbbbbbbbbbbbb"
    ],
    [
      "aaaaaaaaaaaaddde",
      "cccccccccccaddde",
      "cccccccccccaddde",
      "cccccccccccaddde",
      "cccccccccccaHHHb",
      "cccccccccccaHHHb",
      "cccccccccccaHHHb",
      "cccccccccccaHHHb",
      "cccccccccccaHHHb",
      "cccccccccccaHHHb",
      "cccccccccccaHHHb",
      "cccccccc!ccaHHHb",
      "aaaaaaaaaaaaHHHb",
      "HHHHHHHHHHHHHHHb",
      "HHHHHHHHHHHHHHHb",
      "HHHHHHHHHHHHHHHb"
    ],
    [
      "fghhhhhiiiij    ",
      "       k  lj    ",
      "       k  mj    ",
      "       k  nj   e",
      "  oppp k qnj   e",
      "  r    s  nj   e",
      " t     uwxwj   e",
      "  yyyyyu       e",
      "  ABCDEy       e",
      "     FIk       e",
      "J    K k  Lj   e",
      " M!JMFNkOPPj   e",
      "jjjjjjjjjjjj   e",
      "  Q   QO O     e",
      "               e",
      "               e"
    ],
    [
      "Rghhhhhiihij    ",
      "       k  Ej    ",
      "       k   j    ",
      "       k   h    ",
      "   ST  k   h    ",
      "  U    VW  h    ",
      " tX   YuwZwj    ",
      "  000 1u   2    ",
      "   A3DDy   2    ",
      "     F4k   2    ",
      "     5 k   j    ",
      " 6778F k  9j    ",
      "jjjjjjjjjjjj    ",
      "  @  O@O        ",
      "                ",
      "                "
    ],
    [
      "gghhhhhiihij    ",
      "       k   j    ",
      "       k   j    ",
      "       k   h    ",
      "       k   h    ",
      "       k   h    ",
      " t67778uwwwj    ",
      "  000##u   2    ",
      "    ADDy   2    ",
      "     F k   2    ",
      "     F$k   j    ",
      "   J F kO  j    ",
      "jjjjjjjjjjjj    ",
      "@@%@@@%         ",
      "                ",
      "                "
    ],
    [
      "hhhhhhhiihij    ",
      "       k   j    ",
      "       k   j    ",
      "       k  ^j    ",
      "       k  ^j    ",
      "       k  ^j    ",
      "&*(((((uwwwj    ",
      ") iiiiiuO  c    ",
      ")    +Dy   c    ",
      "     DDy   c    ",
      "     DDyO Oj    ",
      "-@@-@@-@@@@j    ",
      "jjjjjjjjjjjj    ",
      "     O@         ",
      "                ",
      "                "
    ]
  ]
}