{
  "name": "multi_condo1_2_ground",
  "refpalette": "c70cities:multi_condo1_2_ground_palette",
  "xsize": 16,
  "zsize": 16,
  "slices": [
    [
      "GGGab           ",
      "GGGab           ",
      "Gcccb           ",
      "GGGab           ",
      "GGGab           ",
      "GGddb           ",
      "GGbeb           ",
      "GGbeb           ",
      "GGbeb           ",
      "GGbeb           ",
      "GGbeb           ",
      "GGbebbbbbbbbbbbb",
      "GGbeeeeeeeb     ",
      "GGbbbbbbbbbbbbbb",
      "GGGGGGGGGGGGGGGG",
      "GGGGGGGGGGGGGGGG"
    ],
    [
      "    f           ",
      "    b           ",
      " cccb           ",
      "    b           ",
      "    b           ",
      "  ddb           ",
      "   eb           ",
      "   ef           ",
      "   ef           ",
      "   ef           ",
      "   ef           ",
      "   eghhhhbbb    ",
      "   eeeeeeeb     ",
      "                ",
      "                ",
      "                "
    ],
    [
      "    i           ",
      "    b           ",
      " cccb           ",
      "    b           ",
      "    b           ",
      "  ddb           ",
      "    b           ",
      "    j           ",
      "    j           ",
      "    j           ",
      "    j           ",
      "    jjjjjbbb    ",
      "          b     ",
      "                ",
      "                ",
      "                "
    ],
    [
      "    i           ",
      "    b           ",
      " cccb           ",
      "    b           ",
      "    b           ",
      "  ddb           ",
      "    b           ",
      "    j           ",
      "    j           ",
      "    j           ",
      "    j           ",
      "    jjjjjbbb    ",
      "          b     ",
      "                ",
      "                ",
      "                "
    ],
    [
      "    b           ",
      "    b           ",
      " cccb           ",
      "    b           ",
      "    b           ",
      "  ddb           ",
      "    b           ",
      "    j           ",
      "    j           ",
      "    j           ",
      "    j           ",
      "    jjjjjbbb    ",
      "          b     ",
      "                ",
      "                ",
      "                "
    ],
    [
      "    b           ",
      "    b           ",
      " cccb           ",
      "    b           ",
      "    b           ",
      "  ddb           ",
      "    b           ",
      "    j           ",
      "    j           ",
      "    j           ",
      "    j           ",
      "    jjjjjbbb    ",
      "          b     ",
      "                ",
      "                ",
      "                "
    ]
  ]
}