{
  "name": "multi_laboratory1_1_base1",
  "refpalette": "c70cities:multi_laboratory1_1_base1_palette",
  "xsize": 16,
  "zsize": 16,
  "slices": [
    [
      "zabccccccccccccc",
      "zabccccccccccccc",
      "zabccccccccccccc",
      "zabccccccccccccc",
      "zabccccccccccccc",
      "zabccccccccccccc",
      "zabccccccccdcccc",
      "zabccccccccccccc",
      "zabccccccccccccc",
      "zabccccccccccccc",
      "zabccccccccccccc",
      "zabccccccccccccc",
      "zabcccccccccccce",
      "zabccccccccdccce",
      "zabcccccccccccef",
      "zabccccccccccce "
    ],
    [
      "zabghhiiii j    ",
      "zabgk   l  j    ",
      "zabm       j    ",
      "zabgn      o    ",
      "zabg       j    ",
      "zabp  qqq  j    ",
      "zabp rstuw dx   ",
      "zabp rstuw y    ",
      "zabg rtttw y    ",
      "zabg rAtBw y    ",
      "zabm rAtBw y    ",
      "zabg  CCC  y    ",
      "zabgD    EFy  IJ",
      "zabKKKKLKKKd  xJ",
      "zabg    iMiK  Jx",
      "zabm     ENK  J "
    ],
    [
      "zabk  OPQR j    ",
      "zabS       j    ",
      "zabT       j    ",
      "zabR       U    ",
      "zab        j    ",
      "zabS       j    ",
      "zabV  W X  dY   ",
      "zabT  W    y    ",
      "zabZ       y    ",
      "zab0  1 2  y    ",
      "zabS       y    ",
      "zabV       y    ",
      "zabT       y   J",
      "zabKKKK3KKKd  YJ",
      "zabS    4Q y  Jx",
      "zabV       y  J "
    ],
    [
      "zab566     j    ",
      "zab7       j    ",
      "zab        j    ",
      "zab        j    ",
      "zab        j    ",
      "zab8       j    ",
      "zab5       dY   ",
      "zab        y    ",
      "zab        y    ",
      "zab        y    ",
      "zab9       y    ",
      "zab5       y    ",
      "zab!       y   J",
      "zabKKKKKKKKd  YJ",
      "zab        y  Jx",
      "zab5       y  J "
    ],
    [
      "zab        j    ",
      "zab        j    ",
      "zab        j    ",
      "zab        j    ",
      "zab        j    ",
      "zab        j    ",
      "zab   @ @  d    ",
      "zab        y    ",
      "zab        y    ",
      "zab        y    ",
      "zab   # #  y    ",
      "zab        y    ",
      "zab        y   J",
      "zabKKKKKKKKd   J",
      "zab        y  Jx",
      "zab        y  J "
    ],
    [
      "zab$$$$$$$$%$$$$",
      "zab$$^$$$^$%$$$$",
      "zab$$&$$$^$%$$$$",
      "zab$$^$$$^$%$$$$",
      "zab$$^$$$^$%$$$$",
      "zab$$$$$$$$%$$$$",
      "zab$$$***$$d$$$$",
      "zab$$$(*($$%$$$$",
      "zab$$^$$$^$%$$$$",
      "zab$$^(*(^$%$$$$",
      "zab$$^***^$%$$$$",
      "zab$$^$$$^$%$$$$",
      "zab$$$$$$$$%$$$)",
      "zab++++++++d$$$)",
      "zab$$$$$$$$%$$)-",
      "zab$$^$$$^$%$$) "
    ]
  ]
}