{
  "name": "multi_factory_1_floor1",
  "refpalette": "c70cities:multi_factory_1_floor1_palette",
  "xsize": 16,
  "zsize": 16,
  "slices": [
    [
      "   a         a  ",
      "   a         a  ",
      "   a         a  ",
      "   ab   b   ba  ",
      "   acbbbcbbbca  ",
      "   ab   b   ba  ",
      "   ad   d e da  ",
      "   afffffgggfa  ",
      "   afffffg gfa  ",
      "   hiiiiigggih  ",
      "   hiiiiiiiiih  ",
      "                ",
      "                ",
      "                ",
      "                ",
      "                "
    ],
    [
      "   abbbbbbbbba  ",
      "   ab   b   ba  ",
      "   ad   d   da  ",
      "   afffffffffa  ",
      "   afffffffffa  ",
      "   hiiiiiiiiih  ",
      "   hiiiiiiiiih  ",
      "         ggg    ",
      "         g g    ",
      "         ggg    ",
      "                ",
      "                ",
      "                ",
      "                ",
      "                ",
      "                "
    ],
    [
      "   afffffffffa  ",
      "   hiiiiiiiiih  ",
      "   hiiiiiiiiih  ",
      "                ",
      "                ",
      "                ",
      "                ",
      "         ggg    ",
      "         gjg    ",
      "         ggg    ",
      "                ",
      "                ",
      "                ",
      "                ",
      "                ",
      "                "
    ],
    [
      "                ",
      "                ",
      "                ",
      "                ",
      "                ",
      "                ",
      "                ",
      "         kgk    ",
      "         g g    ",
      "         kgk    ",
      "                ",
      "                ",
      "                ",
      "                ",
      "                ",
      "                "
    ],
    [
      "                ",
      "                ",
      "                ",
      "                ",
      "                ",
      "                ",
      "                ",
      "         kgk    ",
      "         gjg    ",
      "         kgk    ",
      "                ",
      "                ",
      "                ",
      "                ",
      "                ",
      "                "
    ],
    [
      "                ",
      "                ",
      "                ",
      "                ",
      "                ",
      "                ",
      "                ",
      "         kgk    ",
      "         glg    ",
      "         kgk    ",
      "                ",
      "                ",
      "                ",
      "                ",
      "                ",
      "                "
    ]
  ]
}