{
  "name": "multi_condo1_5_base2",
  "refpalette": "c70cities:multi_condo1_5_base2_palette",
  "xsize": 16,
  "zsize": 16,
  "slices": [
    [
      "HHHHHHHHHHHHabbv",
      "HHHHHHaaaaHHabbv",
      "HHHHHHaccaHHabbv",
      "HHHHHHaccaHHabbv",
      "HHHHHHdccaHHabbv",
      "HHHHHHaccaHHabbv",
      "HHHHHHaccaHHabbv",
      "HHHHHHaccaHHabbv",
      "HHHHHHaccaHHabbv",
      "HHHHHHaccaHHabbv",
      "HHHHHHaaaaHHabbv",
      "HHHHHHaHHHHHabbv",
      "HHHHHHaHHHHHabbv",
      "aaaaaaaaaaaaabbv",
      "bbbbbbbbbbbbbbbv",
      "vvvvvvvvvvvvvvvv"
    ],
    [
      "            abbv",
      "efeg  aaaahhabbv",
      "   g  aijahhabbv",
      "klkg  amnaHHabbv",
      "ooog  p qaHHabbv",
      "efeg  anqaHHabbv",
      "   g  aq aHHabbv",
      "klkg  arsaHHabbv",
      "      a maHHabbv",
      "      a!raHHabbv",
      "efefetaaaaHHabbv",
      "     taHHHHHabbv",
      "klklktaHHHHHabbv",
      "aaaaaaaaaaaaabbv",
      "bbbbbbbbbbbbbbbv",
      "vvvvvvvvvvvvvvvv"
    ],
    [
      "            abbv",
      "      aaaa  abbv",
      "      auia  abbv",
      "      a  a  abbv",
      "      w  a  abbv",
      "      a  ahhabbv",
      "      a  ahhabbv",
      "      a  aHHabbv",
      "      a  aHHabbv",
      "      am aHHabbv",
      "      aaaaHHabbv",
      "      aHHHHHabbv",
      "      aHHHHHabbv",
      "aaaaaaaaaaaaabbv",
      "bbbbbbbbbbbbbbbv",
      "vvvvvvvvvvvvvvvv"
    ],
    [
      "      x     abbv",
      "      aaaa  abbv",
      "      a  a  abbv",
      "      a  a  abbv",
      "      y  a  abbv",
      "      a  a  abbv",
      "      a  a  abbv",
      "      a  a  abbv",
      "      am a  abbv",
      "      ammahhabbv",
      "      aaaahhabbv",
      "      aHHHHHabbv",
      "      aHHHHHabbv",
      "aaaaaaaaaaaaabbv",
      "bbbbbbbbbbbbbbbv",
      "vvvvvvvvvvvvvvvv"
    ],
    [
      "     Aa     abbv",
      "     Aaaaa  abbv",
      "AAAAAAaHHa  abbv",
      "     AaHHa  abbv",
      "     AaHHa  abbv",
      "     AaHHa  abbv",
      "     AaHHa  abbv",
      "     AaHHa  abbv",
      "     AaHHa  abbv",
      "     Aahha  abbv",
      "     Aahha  abbv",
      "     Aa     abbv",
      "AAAAAAa     abbv",
      "aaaaaaaaaaaaabbv",
      "bbbbbbbbbbbbbbbv",
      "vvvvvvvvvvvvvvvv"
    ],
    [
      "BBBBBBa     abbv",
      "BBBBBBaaaaaaabbv",
      "BBBBBBaHHa  abbv",
      "BBBBBBaHHa  abbv",
      "BBBBBBaHHa  abbv",
      "BBBBBBahha  abbv",
      "BBBBBBahha  abbv",
      "BBBBBBa  a  abbv",
      "BBBBBBa  a  abbv",
      "BBBBBBa  a  abbv",
      "BBBBBBa  a  abbv",
      "BBBBBBa     abbv",
      "BBBBBBa     abbv",
      "aaaaaaaaaaaaabbv",
      "bbbbbbbbbbbbbbbv",
      "vvvvvvvvvvvvvvvv"
    ]
  ]
}