{
  "name": "multi_condo1_1_floor6",
  "refpalette": "c70cities:multi_condo1_1_floor6_palette",
  "xsize": 16,
  "zsize": 16,
  "slices": [
    [
      "   abccccccdeeee",
      "  ffbccccccdeghh",
      "   abccccccdeijj",
      "   abccccccdeijj",
      "   aiccccccdeijj",
      "   aiccccccdeijj",
      "   aiccccccdeijj",
      "   aiccccccdeijj",
      "   aiccccccdeijj",
      "   aiccccccdeijj",
      "   aiccccccdeijj",
      "   aiccccccdeijj",
      "   abccccccdeijj",
      "   abccccccdeijj",
      "  ffbccccccdekll",
      "   abccccccdeeee"
    ],
    [
      "    bmno  p     ",
      "  ffbbbbbbb  qqq",
      "    bp   r   q  ",
      "    b        q  ",
      "    s        q  ",
      "    s tu     q  ",
      "    s    w   q  ",
      "    s xx y   q  ",
      "    s xx y   q  ",
      "    s    A   q  ",
      "    s BC     q  ",
      "    s        q  ",
      "    b        q  ",
      "    bDDDDDp  q  ",
      "  ffbbbbbbb  qqq",
      "    bEFbI p     "
    ],
    [
      "    b  JK L     ",
      "  ffbbbbbbb     ",
      "    bL  r       ",
      "    b           ",
      "    s           ",
      "    s           ",
      "    s           ",
      "    s           ",
      "    s           ",
      "    s           ",
      "    s           ",
      "    s           ",
      "    b           ",
      "    bDDDDDL     ",
      "  ffbbbbbbb     ",
      "    b  b  L     "
    ],
    [
      "    b           ",
      "  ffbbbbbbb     ",
      "    bMMr        ",
      "    bMM         ",
      "    s           ",
      "    s           ",
      "    s           ",
      "    s           ",
      "    s           ",
      "    s           ",
      "    s           ",
      "    s           ",
      "    b           ",
      "    b N         ",
      "  ffbbbbbbb     ",
      "    b  b        "
    ],
    [
      "    b           ",
      "  ffbbbbbbb     ",
      "    b           ",
      "    bOOP        ",
      "    s           ",
      "    s           ",
      "    s           ",
      "    s           ",
      "    s           ",
      "    s           ",
      "    s           ",
      "    s           ",
      "    b           ",
      "    b           ",
      "  ffbbbbbbb     ",
      "    b  b        "
    ],
    [
      "    bQQQQQQ     ",
      "  ffbbbbbbb     ",
      "    b           ",
      "    b   P       ",
      "    R           ",
      "    R           ",
      "    R           ",
      "    R           ",
      "    R           ",
      "    R           ",
      "    R   S       ",
      "    R           ",
      "    b           ",
      "    b           ",
      "  ffbbbbbbb     ",
      "    bTTbQQQ     "
    ]
  ]
}