{
  "name": "multi_laboratory1_0_base4",
  "refpalette": "c70cities:multi_laboratory1_0_base4_palette",
  "xsize": 16,
  "zsize": 16,
  "slices": [
    [
      "vvvvvvvvvvvvvvvv",
      "vaaaaaaaaaaaaaaa",
      "vabbbbbbbbbbcccc",
      "vabddd!dddde    ",
      "vabdddddddde    ",
      "vabddddddddeeeee",
      "vabddddddddfffff",
      "vabddddddddfffff",
      "vabffffffffeffff",
      "vabddddddddfffff",
      "vabddddddddfffff",
      "vabddddddddfffff",
      "vabddddddddfffff",
      "vabddddddddfffff",
      "vabddddddddfffff",
      "vabffffffffeffff"
    ],
    [
      "vvvvvvvvvvvvvvvv",
      "vaaaaaaaaaaaaaaa",
      "vabbbbbbbbbbcccc",
      "vabghghghghi    ",
      "vabg g g g i    ",
      "vabjkjljkjkiiiii",
      "vab        m   n",
      "vabooppppooi   q",
      "vabiiiiiiiie   r",
      "vabssttttssi   u",
      "vab        m   u",
      "vab        i   u",
      "vabwxwxyxwxi   u",
      "vab A A A Ai   r",
      "vabBABABABAi    ",
      "vabiiiiiiiie    "
    ],
    [
      "vvvvvvvvvvvvvvvv",
      "vaaaaaaaaaaaaaaa",
      "vabbbbbbbbbbcccc",
      "vabg g g g i    ",
      "vabg g g g i    ",
      "vabjCjDjCjCiiiii",
      "vab        E   F",
      "vabFIIII IFi    ",
      "vabiiiiiiiie   n",
      "vabFJJ J JKi   L",
      "vab        E    ",
      "vab        i   M",
      "vabNxNxOxNxi   P",
      "vab A A A Ai   n",
      "vab A A A Ai    ",
      "vabiiiiiiiie    "
    ],
    [
      "vvvvvvvvvvvvvvvv",
      "vaaaaaaaaaaaaaaa",
      "vabbbbbbbbbbcccc",
      "vabg g g g i    ",
      "vabg g g g i    ",
      "vabjjjjjjjjiiiii",
      "vab        i   F",
      "vab III II i    ",
      "vabiii!iiiie   F",
      "vab JJJJJ  i    ",
      "vab        i    ",
      "vab        i   Q",
      "vabxxxxxxxxi   !",
      "vab A A A Ai   F",
      "vab A A A Ai    ",
      "vabiiiiiiiie    "
    ],
    [
      "vvvvvvvvvvvvvvvv",
      "vaaaaaaaaaaaaaaa",
      "vabbbbbbbbbbcccc",
      "vabRSRSRSRSi    ",
      "vabRRRRRRRRi    ",
      "vabRRRRRRRRiiiii",
      "vabRRRRRRRRi    ",
      "vabRRRRRRRRi    ",
      "vabiiiiiiiie    ",
      "vabRRRRRRRRi    ",
      "vabRRRRRRRRi    ",
      "vabRRRRRRRRi    ",
      "vabRRRRRRRRi    ",
      "vabRRRRRRRRi    ",
      "vabSRSRSRSRi    ",
      "vabiiiiiiiie    "
    ],
    [
      "vvvvvvvvvvvvvvvv",
      "vaaaaaaaaaaaaaaa",
      "vabbbbbbbbbbcccc",
      "vab T T T Ti    ",
      "vab T T T Ti    ",
      "vab T T T Tiiiii",
      "vab T T T TiUUUU",
      "vab TTTTTTTiUUUU",
      "vabiiiiiiiieUUUU",
      "vabTTTTTTTTiUUUU",
      "vabT T T T iUUUU",
      "vabTVTVTVTViUUUU",
      "vabTWTVTVTViUUUU",
      "vabTVTVTVTViUUUU",
      "vabTVTVTVTViUUUU",
      "vabiiiiiiiieXXXX"
    ]
  ]
}