{
  "name": "multi_laboratory1_0_base6",
  "refpalette": "c70cities:multi_laboratory1_0_base6_palette",
  "xsize": 16,
  "zsize": 16,
  "slices": [
    [
      "zzzzzzzzzzzzzzzz",
      "zaaaaaaaaaaaaaaa",
      "zabbbbbbbbbbcccc",
      "zabdddddddde    ",
      "zabdddddddde    ",
      "zabddddddddeeeee",
      "zabddddddddffff!",
      "zabddddddddfffff",
      "zabffffffffeffff",
      "zabddddddddfffff",
      "zabddddddddfffff",
      "zabddddddddfffff",
      "zabddddddddfffff",
      "zabddddddddfffff",
      "zabddddddddfffff",
      "zabffffffffeffff"
    ],
    [
      "zzzzzzzzzzzzzzzz",
      "zaaaaaaaaaaaaaaa",
      "zabbbbbbbbbbcccc",
      "zabghghghghi    ",
      "zabg g g g i    ",
      "zabjkjkjkjkeiiii",
      "zab        l   m",
      "zabnnoooonni    ",
      "zabiiiiiiiiep   ",
      "zabqqrrrrqqi   s",
      "zab        t    ",
      "zab        i    ",
      "zabuwuwuwuwix   ",
      "zab y y y yix   ",
      "zabAyAyAyAyi!B  ",
      "zaeiiiiiiiieiiiC"
    ],
    [
      "zzzzzzzzzzzzzzzz",
      "zaaaaaaaaaaaaaaa",
      "zabbbbbbbbbbcccc",
      "zabg g g g i    ",
      "zabg g g g i    ",
      "zabjDjDjDjDeiiii",
      "zab        E FIm",
      "zabJKKKKKKJi    ",
      "zabiiiiiiiie   s",
      "zabJLLLLLLMi    ",
      "zab        N    ",
      "zab        i    ",
      "zabOwOwOwOwi    ",
      "zab y y y yi    ",
      "zab y y y yi    ",
      "zaeiiiiiiiieiiiP"
    ],
    [
      "zzzzzzzzzzzzzzzz",
      "zaaaaaaaaaaaaaaa",
      "zabbbbbbbbbbcccc",
      "zabg g g g i    ",
      "zabg g g g i    ",
      "zabjjjjjjjjiiiii",
      "zab        i QRm",
      "zab KKKKKK i   s",
      "zabiiiiiiiie    ",
      "zab LLLLLL i    ",
      "zab        i    ",
      "zab        i    ",
      "zabwwwwwwwwi    ",
      "zab y y y yi    ",
      "zab y y y yi    ",
      "zaeiiiiiiiieiiiS"
    ],
    [
      "zzzzzzzzzzzzzzzz",
      "zaaaaaaaaaaaaaaa",
      "zabbbbbbbbbbcccc",
      "zabTUTUTUTUi    ",
      "zabTTTTTTTTi    ",
      "zabTTTTTTTTiiiii",
      "zabTTTTTTTTi  VW",
      "zabTTTTTTTTi    ",
      "zabiiiiiiiie    ",
      "zabTTTTTTTTi    ",
      "zabTTTTTTTTi    ",
      "zabTTTTTTTTi    ",
      "zabTTTTTTTTi    ",
      "zabTTTTTTTTi    ",
      "zabUTUTUTUTi    ",
      "zaeiiiiiiiieiiii"
    ],
    [
      "zzzzzzzzzzzzzzzz",
      "zaaaaaaaaaaaaaaa",
      "zabbbbbbbbbbcccc",
      "zab X X X Xi    ",
      "zab X X X Xi    ",
      "zab X X X Xiiiii",
      "zab X X X Xi V  ",
      "zabXXXXXXXXi    ",
      "zabiiiiiiiie    ",
      "zabXXXXXXXXi    ",
      "zabX X X X i    ",
      "zabX X X X i    ",
      "zabX X X X i    ",
      "zabX X X X i    ",
      "zabX X X X i    ",
      "zaeiiiiiiiieiiii"
    ]
  ]
}