{
  "name": "multi_megatower1_2_base2",
  "refpalette": "c70cities:multi_megatower1_2_base2_palette",
  "xsize": 16,
  "zsize": 16,
  "slices": [
    [
      "vaavvHHHHHHHHHHH",
      "vaavvHHHHHHHHHHH",
      "vaavvHbHHHHHHbHH",
      "vaavvHHHHHHHHHHH",
      "vaavvHHHHHHHHHHH",
      "vaavvHHHHHHHHHHH",
      "vaavvHHHHHHHHHHH",
      "vaavvHHHHHHHHHHH",
      "vaavvHHHHHHHHHHH",
      "vaavvHbHHHHHHbHH",
      "vaavvHHHHHHHHHHH",
      "vaavvvvvvvvvvvvv",
      "vaavvvvvvvvvvvvv",
      "vaaaaaaaaaaaaaaa",
      "vaaaaaaaaaaaaaaa",
      "vvvvvvvvvvvvvvvv"
    ],
    [
      "vaavcd e    f g ",
      "vaavcf g      de",
      "vaavc bh    ib  ",
      "vaavcd e     jfg",
      "vaavcf g        ",
      "vaavcd e        ",
      "vaavcf g        ",
      "vaavckkk        ",
      "vaavc   ldedemde",
      "vaavc b l    b  ",
      "vaavc   lfgfg fg",
      "vaavcccccccccccc",
      "vaavvvvvvvvvvvvv",
      "vaaaaaaaaaaaaaaa",
      "vaaaaaaaaaaaaaaa",
      "vvvvvvvvvvvvvvvv"
    ],
    [
      "vaav            ",
      "vaav            ",
      "vaav  b      b  ",
      "vaav            ",
      "vaav            ",
      "vaav            ",
      "vaav            ",
      "vaav            ",
      "vaav            ",
      "vaav  b      b  ",
      "vaav            ",
      "vaav            ",
      "vaavvvvvvvvvvvvv",
      "vaaaaaaaaaaaaaaa",
      "vaaaaaaaaaaaaaaa",
      "vvvvvvvvvvvvvvvv"
    ],
    [
      "vaav            ",
      "vaav            ",
      "vaav  b      b  ",
      "vaav            ",
      "vaav            ",
      "vaav            ",
      "vaav            ",
      "vaav            ",
      "vaav            ",
      "vaav  b      b  ",
      "vaav            ",
      "vaav            ",
      "vaavvvvvvvvvvvvv",
      "vaaaaaaaaaaaaaaa",
      "vaaaaaaaaaaaaaaa",
      "vvvvvvvvvvvvvvvv"
    ],
    [
      "vaav            ",
      "vaav            ",
      "vaav nb      b  ",
      "vaav            ",
      "vaav            ",
      "vaav            ",
      "vaav            ",
      "vaav            ",
      "vaav            ",
      "vaav nb      b  ",
      "vaav  o      o  ",
      "vaav            ",
      "vaavvvvvvvvvvvvv",
      "vaaaaaaaaaaaaaaa",
      "vaaaaaaaaaaaaaaa",
      "vvvvvvvvvvvvvvvv"
    ],
    [
      "vaavvpbppppppbp ",
      "vaavvpbppppppbpp",
      "vaavvpbbbbbbbbbb",
      "vaavvpbppppppbpp",
      "vaavvpbppppppbpp",
      "vaavvpbppppppbpp",
      "vaavvpbppppppbpp",
      "vaavvpbppppppbpp",
      "vaavvpbppppppbpp",
      "vaavvpbbbbbbbbbb",
      "vaavvppppppppppp",
      "vaavvvvvvvvvvvvv",
      "vaavvvvvvvvvvvvv",
      "vaaaaaaaaaaaaaaa",
      "vaaaaaaaaaaaaaaa",
      "vvvvvvvvvvvvvvvv"
    ]
  ]
}