{
  "name": "multi_laboratory1_7_base7",
  "refpalette": "c70cities:multi_laboratory1_7_base7_palette",
  "xsize": 16,
  "zsize": 16,
  "slices": [
    [
      "aaaabccccccbaaaa",
      "aaaabccccccbaaaa",
      "aaaabccccccbaaaa",
      "aaaabccccccbaaaa",
      "aaaabbbbbbbbaaaa",
      "daaaaaaaaaaaaaad",
      "daaaaaaaaaaaaead",
      "ddaaaaaaaaaaaedd",
      "adddaaaaaaaaddda",
      "aaadddaaaadddaaa",
      "aaaaaddddddaaaaa",
      "aaaaaaaaaaaaaaaa",
      "aaaaaaaaaaaaaaaa",
      "aaaaaaaaaaaaaaaa",
      "aaaaaaaaaaaaaaaa",
      "aaaaaaaaaaaaaaaa"
    ],
    [
      "aaf g      g  eh",
      "aaa g      g  ih",
      "aaa g      g  ah",
      "aaa g      g jhe",
      "ka  lmmmmmml  hh",
      "aaaa   n    o  a",
      "aaaho        aaa",
      "apaah    q   apa",
      "aaaaka     jaaaa",
      "aaaaapaa  paaaaa",
      "aaaaaaaaaaaaaaaa",
      "aaaaaaaaaaaaaaaa",
      "aaaaaaaaaaaaaaaa",
      "aaaaaaaaaaaaaaaa",
      "aaaaaaaaaaaaaaaa",
      "aaaaaaaaaaaaaaaa"
    ],
    [
      "a               ",
      "a r            e",
      "a             is",
      "af              ",
      " o    t       ih",
      "ah             a",
      "ahhs           a",
      "aphh         !pa",
      "aaaa t   q  aaaa",
      "aaaaap    paaaaa",
      "aaaaaauuuuaaaaaa",
      "aaaaawxyyAwaaaaa",
      "aaaaawBCCDwaaaaa",
      "aaaaawBCCDwaaaaa",
      "aaaaaEBCCDEaaaaa",
      "aaaaawBCCDwaaaaa"
    ],
    [
      "a               ",
      "                ",
      "               i",
      "j               ",
      "                ",
      "as             a",
      "ah i           a",
      "apFj          pa",
      "aaaa        aaaa",
      "aaaaapIIIIpaaaaa",
      "aaaaaauJKuaaaaaa",
      "aaaaaw    waaaaa",
      "aaaaaw    waaaaa",
      "aaaaaw    waaaaa",
      "aaaaaL    Maaaaa",
      "aaaaaw    waaaaa"
    ],
    [
      "                ",
      "                ",
      "                ",
      "                ",
      "                ",
      "ai             a",
      "a              a",
      "aps           pa",
      "aaaa        aaaa",
      "aaaaap    paaaaa",
      "aaaaaauNOuaaaaaa",
      "aaaaawP  Pwaaaaa",
      "aaaaaw    waaaaa",
      "aaaaaw    waaaaa",
      "aaaaaL    Maaaaa",
      "aaaaaw    waaaaa"
    ],
    [
      "                ",
      "                ",
      "                ",
      "                ",
      "                ",
      "a              a",
      "a              a",
      "api           pa",
      "aaaa        aaaa",
      "aaaaap    paaaaa",
      "aaaaaauuuuaaaaaa",
      "aaaaawQRRSwaaaaa",
      "aaaaawQ  Swaaaaa",
      "aaaaawQRRSwaaaaa",
      "aaaaawQ  Swaaaaa",
      "aaaaawQRRSwaaaaa"
    ]
  ]
}