{
  "name": "multi_condo1_4_base1",
  "refpalette": "c70cities:multi_condo1_4_base1_palette",
  "xsize": 16,
  "zsize": 16,
  "slices": [
    [
      "HHHHHHHHHHHHabbv",
      "HHHaaaaaaaaaabbv",
      "HHHaccdeeeeeabbv",
      "HHHaccdeeeeeabbv",
      "HHHaccdeeeeeabbv",
      "HHHaccdeeeeeabbv",
      "HHHcccdaaaaaabbv",
      "HHHcccd     abbv",
      "HHHcccd     abbv",
      "HHHcccd     abbv",
      "HHHaccf     abbv",
      "HHHaccgaaaaaabbv",
      "HHHaccddh   abbv",
      "HHHaccddi   abbv",
      "HHHaaaaaaaaaabbv",
      "HHHHHHHHHHHHabbv"
    ],
    [
      "            abbv",
      " jjaaaaaaaaaabbv",
      " kla  m     abbv",
      "   a  a     abbv",
      " noa  a  pq abbv",
      "  ra  astuu abbv",
      "   w xaaaaaaabbv",
      "   y  a     abbv",
      "   A  B     abbv",
      "   w  C     abbv",
      "  Da Ea     abbv",
      " kla  aaaaaaabbv",
      "   a  a     abbv",
      " noa  F Ii  abbv",
      " jjaaaaaaaaaabbv",
      "            abbv"
    ],
    [
      "            abbv",
      "  Jaaaaaaaaaabbv",
      "   a  K     abbv",
      "   a  aL    abbv",
      "   a  a  MN abbv",
      "  ra  assuu abbv",
      "   w  aaaaaaabbv",
      "   O  a     abbv",
      "   P  Q     abbv",
      "   w  R     abbv",
      "  Da  a     abbv",
      "   a  aaaaaaabbv",
      "   a  a     abbv",
      "   a  S  Ii abbv",
      "   aaaaaaaaaabbv",
      "            abbv"
    ],
    [
      "      T     abbv",
      "   aaaaaaaaaabbv",
      "   a  U     abbv",
      "   a  a     abbv",
      "   a  a     abbv",
      "  ra  as VV abbv",
      "  Ww  aaaaaaabbv",
      "  Ww Xa     abbv",
      "  Ww  U     abbv",
      "  Ww  U     abbv",
      "  Da Ya     abbv",
      "   a  aaaaaaabbv",
      "   a  a   Udabbv",
      "   a  U   Idabbv",
      "   aaaaaaaaaabbv",
      "      T     abbv"
    ],
    [
      "     sa     abbv",
      "aaaaaaaaaaaaabbv",
      "   a  a     abbv",
      "   a  a     abbv",
      "   a  a     abbv",
      "   a  as    abbv",
      "   a  aaaaaaabbv",
      "   a Za     abbv",
      "   a  a     abbv",
      "   a  a     abbv",
      "   a Za     abbv",
      "   a  aaaaaaabbv",
      "   a  a  Uh abbv",
      "   a  a     abbv",
      "aaaaaaaaaaaaabbv",
      "     sa     abbv"
    ],
    [
      "eeeeeea     abbv",
      "aaaaaaaaaaaaabbv",
      "eeeaeeas    abbv",
      "eeeaeeas    abbv",
      "eeeaeeas    abbv",
      "eeeaeeasssssabbv",
      "eeeaeeaaaaaaabbv",
      "eeeaeea     abbv",
      "eeeaeea     abbv",
      "eeeaeea     abbv",
      "eeeaeea     abbv",
      "eeeaeeaaaaaaabbv",
      "eeeaeea Uh  abbv",
      "eeeaeea     abbv",
      "aaaaaaaaaaaaabbv",
      "eeeeeea     abbv"
    ]
  ]
}