{
  "name": "multi_militarybase_1_base1",
  "refpalette": "c70cities:multi_militarybase_1_base1_palette",
  "xsize": 16,
  "zsize": 16,
  "slices": [
    [
      "vaaaaaaaaabbbc  ",
      "vaaaaaaaaabbbc  ",
      "vvcccvcccccccvcc",
      "vaaaacaaaabbbcbb",
      "vaaaacaaaabbbcbb",
      "vaaaacaaaaabbcbb",
      "vaaaacaaaaaadvee",
      "vaaaacaaaaaaacaa",
      "vaaaacaaaaaaacaa",
      "vaaaacaaaaaaacaa",
      "vvcccvcccccccvcc",
      "vaaaacaaaaaaacff",
      "vaaaacaaaaaaacff",
      "vaaaacaaaaaaacff",
      "vaaaavaaaaaaavff",
      "vvvvvvvvvvvvvvvv"
    ],
    [
      "vgh          i  ",
      "vgh          i  ",
      "vvj  v       vii",
      "vkl  m          ",
      "vnn  m   o      ",
      "v p  m          ",
      "vnn qm   r  dv  ",
      "v sq m   t      ",
      "vnn  m          ",
      "vu   m        wx",
      "vvj  vmmmmmmmvyy",
      "vA           jB ",
      "vA     nC Dn jyy",
      "vEF Ij nk Jn jB ",
      "vKLLKv MN OM vyy",
      "vvvvvvvvvvvvvvvv"
    ],
    [
      "v!              ",
      "vg              ",
      "vvj  v       v  ",
      "v    m          ",
      "vP   m          ",
      "vQ   m   o      ",
      "vP   m   r   v  ",
      "vQ   m   t      ",
      "vP   m          ",
      "v    m          ",
      "vvj  vmmmmmmmvyy",
      "vR           j  ",
      "v      S   T jyy",
      "v    j U   V j  ",
      "v    v W   W vyy",
      "vvvvvvvvvvvvvvvv"
    ],
    [
      "vg              ",
      "vg              ",
      "vvj  v       v  ",
      "v    m          ",
      "v    m          ",
      "v    m          ",
      "v    m   o  Xv  ",
      "v    m   t      ",
      "v    m          ",
      "v    m          ",
      "vvj  vmmmmmmmvyy",
      "v            j  ",
      "v            jyy",
      "v    j       j  ",
      "vYZZYv       vyy",
      "vvvvvvvvvvvvvvvv"
    ],
    [
      "v            m  ",
      "vh           m  ",
      "vvjjjv       vmm",
      "v    i          ",
      "v    i          ",
      "v    i          ",
      "v    i       v  ",
      "v    i   o      ",
      "v    i          ",
      "v    i          ",
      "vvjjjviiiiiiivyy",
      "v    j       j00",
      "v    j       j00",
      "v    j       j00",
      "vY  Yv       v00",
      "vvvvvvvvvvvvvvvv"
    ],
    [
      "v122222222222c33",
      "v122222222222c33",
      "vvcccvcccccccvcc",
      "v1222c2222222c22",
      "v1222c2222222c22",
      "v1222c222 222c22",
      "v1222c222 222v22",
      "v1222c222 222c22",
      "v1222c222o222c22",
      "v1222c222 222c22",
      "vvcccvcccccccvcc",
      "v!222c2222222c h",
      "v1222c2422242c  ",
      "v1222c2222222ch ",
      "v1111v1111111v11",
      "vvvvvvvvvvvvvvvv"
    ]
  ]
}