{
  "name": "multi_militarybase_3_base2",
  "refpalette": "c70cities:multi_militarybase_3_base2_palette",
  "xsize": 16,
  "zsize": 16,
  "slices": [
    [
      "                ",
      "  a    a    a   ",
      "bbvbbbbvbbbbvbbb",
      "cccccccbcccccccc",
      "cccccccbcccccccc",
      "cccccccbcccccccc",
      "dddddddvdddddddd",
      "eeeeeeebeeeeeeee",
      "eeeeeeebeeeeeeee",
      "eeeeeeebeeeeeeee",
      "bbbbbbbvbbbbbbbb",
      "fffffffbffffffff",
      "fffffffbffffffff",
      "fffffffbffffffff",
      "fffffffvffffffff",
      "vvvvvvvvvvvvvvvv"
    ],
    [
      "                ",
      "                ",
      "ggvggggvggggvggg",
      "                ",
      "                ",
      "                ",
      "hhhhhhivihjhhhhh",
      "klmlll   llkmkll",
      "                ",
      "                ",
      "iiniiiiviiiioiii",
      "p  qrsst        ",
      "u   w xt        ",
      "p   rsst y y y y",
      "u A w xv y y y!y",
      "vvvvvvvvvvvvvvvv"
    ],
    [
      "                ",
      "                ",
      "  v    v    v   ",
      "                ",
      "                ",
      "                ",
      "hB!hChiviDhhEhhh",
      "F I        JIK  ",
      "                ",
      "                ",
      "iiLiiiiviiiiMiii",
      "N   rsstO O   O ",
      "u   P  t        ",
      "N   rsst y y y y",
      "u Q P  vRyRyRyRy",
      "vvvvvvvvvvvvvvvv"
    ],
    [
      "                ",
      "                ",
      "  v    v    v   ",
      "                ",
      "                ",
      "                ",
      "iiiiiiiviiiiiiii",
      "                ",
      "                ",
      "                ",
      "iiiiiiiviiiiiiii",
      "u   rsst        ",
      "u   r  t        ",
      "u   rsst        ",
      "u Q r  vS S S S ",
      "vvvvvvvvvvvvvvvv"
    ],
    [
      "                ",
      "                ",
      "TTvTTTTvTTTTvTTT",
      "                ",
      "                ",
      "                ",
      "gggggggvgggggggg",
      "       g        ",
      "       g        ",
      "       g        ",
      "iiiiiiiviiiiiiii",
      "UUUUUUUtUUUUUUUU",
      "UUUUUUUtUUUUUUUU",
      "UUUUUUUtUUUUUUUU",
      "UUUUUUUvUUUUUUUU",
      "vvvvvvvvvvvvvvvv"
    ],
    [
      "                ",
      "                ",
      "VVvVVVVvVVVVvVVV",
      "WWWWWWWbWWWWWWWW",
      "WWWWWWWbWWWWWWWW",
      "WWWWWWWbWWWWWWWW",
      "WWWWWWWvWWWWWWWW",
      "WWWWWWWbWWWWWWWW",
      "WWWWWWWbWWWWWWWW",
      "WWWWWWWbWWWWWWWW",
      "bbbbbbbvbbbbbbbb",
      "XY  X YbY X  YX ",
      "X   X  b  X   XY",
      "X   X Yb  X  YXY",
      "XXXXXXXvXXXXXXXX",
      "vvvvvvvvvvvvvvvv"
    ]
  ]
}