{
  "name": "multi_communitycenter_7_floor1",
  "refpalette": "c70cities:multi_communitycenter_7_floor1_palette",
  "xsize": 16,
  "zsize": 16,
  "slices": [
    [
      "a  b       a c  ",
      "a d eeebe  a c  ",
      "ab   b   b afc  ",
      "a  ee eeg  afc  ",
      "a b  e   b a c  ",
      "a e eee d  a c  ",
      "a  b   e b a c  ",
      "a          afc  ",
      "a          afc  ",
      "a          a c  ",
      "a          a c  ",
      "ahhh       a c  ",
      "iiiiii   jjafc  ",
      "kkkkki   llafc  ",
      "kkkkkih    a c  ",
      "kkkkkih  mma c  "
    ],
    [
      "                ",
      "                ",
      "            f   ",
      "            f   ",
      "                ",
      "                ",
      "                ",
      "            f   ",
      "            f   ",
      "                ",
      "                ",
      "                ",
      "            f   ",
      "            f   ",
      "                ",
      "                "
    ],
    [
      "                ",
      "                ",
      "            f   ",
      "            f   ",
      "                ",
      "                ",
      "                ",
      "            f   ",
      "            f   ",
      "                ",
      "                ",
      "                ",
      "            f   ",
      "            f   ",
      "                ",
      "                "
    ],
    [
      "                ",
      "                ",
      "            n   ",
      "            n   ",
      "                ",
      "                ",
      "                ",
      "            n   ",
      "            n   ",
      "                ",
      "                ",
      "                ",
      "            n   ",
      "            n   ",
      "                ",
      "                "
    ],
    [
      "oooooooooooopqq ",
      "oooooooooooopqq ",
      "oooooooooooopqq ",
      "oooooooooooopqq ",
      "oooooooooooopqq ",
      "oooooooooooopqq ",
      "oooooooooooopqq ",
      "oooooooooooopqq ",
      "oooooooooooopqq ",
      "oooooooooooopqq ",
      "oooooooooooopqq ",
      "oooooooooooopqq ",
      "oooooooooooopqq ",
      "oooooooooooopqq ",
      "oooooooooooopqq ",
      "oooooooooooopqq "
    ],
    [
      "                ",
      "                ",
      "                ",
      "                ",
      "                ",
      "                ",
      "                ",
      "                ",
      "      ~         ",
      "                ",
      "                ",
      "                ",
      "                ",
      "                ",
      "                ",
      "                "
    ]
  ]
}