{
  "name": "multi_militarybase_3_base3",
  "refpalette": "c70cities:multi_militarybase_3_base3_palette",
  "xsize": 16,
  "zsize": 16,
  "slices": [
    [
      "                ",
      "aaaaaaaaaaaaaaaa",
      "bbvbbbbvbbbbvbbb",
      "cccccccbcccccccc",
      "cccccccbcccccccc",
      "cccccccbcccccccc",
      "dddddddvdddddddd",
      "eeeeeeebeeeeeeee",
      "eeeeeeebeeeeeeee",
      "eeeeeeebeeeeeeee",
      "bbbbbbbvbbbbbbbb",
      "fffffffbeeeeeeee",
      "fffffffbeeeeeeee",
      "fffffffbeeeeeeee",
      "fffffffveeeeeeee",
      "vvvvvvvvvvvvvvvv"
    ],
    [
      "                ",
      "                ",
      " gvggggvggggvg  ",
      "                ",
      "                ",
      "                ",
      "       v        ",
      "                ",
      "         hih hih",
      "j   klj  hih hih",
      "mmnmmmmv        ",
      "o  pqrrs hih tit",
      "u   w xs hih hih",
      "o   qrrs        ",
      "u y w xv hih hih",
      "vvvvvvvvvvvvvvvv"
    ],
    [
      "                ",
      "                ",
      "  v    v    v   ",
      "                ",
      "                ",
      "                ",
      "       v        ",
      "                ",
      "                ",
      "                ",
      "mmAmmmmv        ",
      "B   qrrs  C     ",
      "u   D  s        ",
      "B   qrrs        ",
      "u E D  v        ",
      "vvvvvvvvvvvvvvvv"
    ],
    [
      "                ",
      "                ",
      "  v    v    v   ",
      "                ",
      "                ",
      "                ",
      "       v        ",
      "                ",
      "                ",
      "                ",
      "mmmmmmmv        ",
      "u   qrrs        ",
      "u   q  s        ",
      "u   qrrs        ",
      "u E q  v        ",
      "vvvvvvvvvvvvvvvv"
    ],
    [
      "                ",
      "                ",
      "FFvFFFFvFFFFvFFF",
      "                ",
      "                ",
      "                ",
      "       v        ",
      "                ",
      "                ",
      "                ",
      "mmmmmmmvgggggggg",
      "IIIIIIIs        ",
      "IIIIIIIs        ",
      "IIIIIIIs        ",
      "IIIIIIIv        ",
      "vvvvvvvvvvvvvvvv"
    ],
    [
      "                ",
      "                ",
      "JJvJJJJvJJJJvJJJ",
      "KKKKKKKbKKKKKKKK",
      "KKKKKKKbKKKKKKKK",
      "KKKKKKKbKKKKKKKK",
      "KKKKKKKvKKKKKKKK",
      "KKKKKKKbKKKKKKKK",
      "KKKKKKKbKKKKKKKK",
      "KKKKKKKbKKKKKKKK",
      "bbbbbbbvbbbbbbbb",
      "L  M!  bKKKKKKKK",
      "L   L  bKKKKKKKK",
      "L  ML MbKKKKKKKK",
      "LLLLLLLvLLLLLLLL",
      "vvvvvvvvvvvvvvvv"
    ]
  ]
}