{
  "name": "multi_militarybase_5_base2",
  "refpalette": "c70cities:multi_militarybase_5_base2_palette",
  "xsize": 16,
  "zsize": 16,
  "slices": [
    [
      " abbbcccccccccvv",
      " abbbcccccccccvv",
      "avaaaaaaavaaavvv",
      "babbbccccaccccvv",
      "babbbccccaccccvv",
      "babbcccccaccccvv",
      "dveccccccaccccvv",
      "cacccccccaccccvv",
      "cacccccccaccccvv",
      "cacccccccaccccvv",
      "avaaaaaaavaaavvv",
      "facccccccaccccvv",
      "facccccccaccccvv",
      "facccccccaccccvv",
      "fvcccccccvccccvv",
      "vvvvvvvvvvvvvvvv"
    ],
    [
      " g           hvv",
      " g        ijk vv",
      "gv       vlllvvv",
      "         m    vv",
      "         mno  vv",
      "         m    vv",
      "pve      mno  vv",
      "         m    vv",
      "         mno  vv",
      "         m    vv",
      "pvpp   ppvq  vvv",
      " lr          !vv",
      " lrs   s     tvv",
      " luwu uwu    tvv",
      " vx  x   v    vv",
      "vvvvvvvvvvvvvvvv"
    ],
    [
      "              vv",
      "              vv",
      " v       vlllvvv",
      "         m    vv",
      "         m    vv",
      "         m    vv",
      "pve      m    vv",
      "         m    vv",
      "         m    vv",
      "         m    vv",
      "pvpp   ppv   vvv",
      "yl            vv",
      " l           tvv",
      " lABA CBC    tvv",
      "Dvx      vEEEEvv",
      "vvvvvvvvvvvvvvvv"
    ],
    [
      "              vv",
      "              vv",
      " v       vlllvvv",
      "         m    vv",
      "         m    vv",
      "         m    vv",
      "pve      m    vv",
      "         m    vv",
      "         m    vv",
      "         m    vv",
      "pvpppppppv   vvv",
      " l            vv",
      " l           tvv",
      " l           tvv",
      "Fv       v    vv",
      "vvvvvvvvvvvvvvvv"
    ],
    [
      " m            vv",
      " m            vv",
      "mv       vlllvvv",
      "         g    vv",
      "         g    vv",
      "         g    vv",
      "gve      g    vv",
      " g       g    vv",
      " g       g    vv",
      " g       g    vv",
      "pvgggggggv   vvv",
      "Il            vv",
      "Il            vv",
      "Il            vv",
      "Iv       v    vv",
      "vvvvvvvvvvvvvvvv"
    ],
    [
      " JKKKKKKKKKKKLvv",
      " JKKKKKKKKKKKLvv",
      "Jvaaaaaaavaaavvv",
      "KaKKKKKKKaKKKLvv",
      "KaKKKKKKKaKKKLvv",
      "KaKKKKKKKaKKKLvv",
      "KveKKKKKKaKKKLvv",
      "KaKKKKKKKaKKKLvv",
      "KaKKKKKKKaKKKLvv",
      "KaKKKKKKKaKKKLvv",
      "avaaaaaaavaaavvv",
      "MaKKKKKKKaKKKLvv",
      " aKKKKKKKaKKKLvv",
      "MaKKKKKKKaKKKLvv",
      "LvLLLLLLLvLLLLvv",
      "vvvvvvvvvvvvvvvv"
    ]
  ]
}