{
  "name": "multi_hospital_1_ground",
  "refpalette": "c70cities:multi_hospital_1_ground_palette",
  "xsize": 16,
  "zsize": 16,
  "slices": [
    [
      "GGavvvvvvabbbbbb",
      "GGavvvvvvabbbbbb",
      "GGcvvvvvvcbbbbbb",
      "GGGHHHHHGadddddd",
      "GGGeeeeeGGGGdddG",
      "GGGeeeeeeeeeeeee",
      "GGGeeeeeeeeeeeee",
      "GGGeeeeeeeeeeeee",
      "GGGeeeeeeeeeeeee",
      "GGGeeeeeeGGGGGGG",
      "GGGeeeeeGcffffff",
      "GGGeeeeeGggggggg",
      "GGGeeeeeGghhhhhh",
      "GGGeeeeeGghhhhhh",
      "GGGeeeeeGggggggg",
      "GGGeeeeeGGGGGGGG"
    ],
    [
      " ijklmln opq    ",
      "  j mmm  o      ",
      "  c      cr     ",
      " i       astu ut",
      " i              ",
      "  i             ",
      "i               ",
      " w              ",
      " i              ",
      "          i ii i",
      "i i     ixyyyyyy",
      " ii             ",
      "ii      i       ",
      " wi     i       ",
      " i              ",
      " i       i i  i "
    ],
    [
      "  j ABC  o      ",
      "  j DDD  o      ",
      "  c EFE  cr     ",
      "         astu ut",
      "                ",
      "                ",
      "                ",
      " ~              ",
      "                ",
      "                ",
      "         x      ",
      "                ",
      "                ",
      " ~              ",
      "                ",
      "                "
    ],
    [
      "  I JJJ  o      ",
      "  I      o      ",
      "  c      cr     ",
      "         astu ut",
      "                ",
      "                ",
      "                ",
      "                ",
      "                ",
      "                ",
      "         x      ",
      "                ",
      "                ",
      "                ",
      "                ",
      "                "
    ],
    [
      "  I KKK  o      ",
      "  I      o      ",
      "  csssssscr     ",
      "         asttttt",
      "                ",
      "                ",
      "                ",
      "                ",
      "                ",
      "                ",
      "         x      ",
      "                ",
      "                ",
      "                ",
      "                ",
      "                "
    ],
    [
      "  j      o      ",
      "  j      o      ",
      "  csssssscr     ",
      "         assssss",
      "                ",
      "                ",
      "                ",
      "                ",
      "                ",
      "                ",
      "         x      ",
      "                ",
      "                ",
      "                ",
      "                ",
      "                "
    ]
  ]
}