{
  "name": "multi_condo1_4_floor7",
  "refpalette": "c70cities:multi_condo1_4_floor7_palette",
  "xsize": 16,
  "zsize": 16,
  "slices": [
    [
      "aaaaabccccccde  ",
      "fffgabhddddddii ",
      "   jabhkkkkkde  ",
      "   jabhkkkkkde  ",
      "   jabhkkkkkde  ",
      "   jabhkkkkkdii ",
      "   jabhdddddde  ",
      " l jabh     he  ",
      "   jabh     he  ",
      "   jabh     de  ",
      "   jabm     dii ",
      "   jabndddddde  ",
      "   jabhhj   de  ",
      "   jabhho   de  ",
      "pppqabhddddddii ",
      "aaaaabccccccde  "
    ],
    [
      "      drsdtud   ",
      "wwww  dddddddii ",
      "   w  x     d   ",
      "   w  d     y   ",
      "   w  d  AB d   ",
      "   w  d C!D dii ",
      "   w  ddddddd   ",
      " E w  d     F   ",
      "   w  I     F   ",
      "   w  J     d   ",
      "   w Kd     dii ",
      "   w  ddddddd   ",
      "   w  d     y   ",
      "   w  L Mo  d   ",
      "wwww  dddddddii ",
      "      dNsdOPd   "
    ],
    [
      "      dQRd  d   ",
      "      dddddddii ",
      "      S     d   ",
      "      dT    U   ",
      "      d  VW d   ",
      " l    dXXDD dii ",
      "      ddddddd   ",
      " E    d     F   ",
      "!     Y     F   ",
      "      Z     d   ",
      "      d     dii ",
      "      ddddddd   ",
      "      d     U   ",
      "      0  Mo d   ",
      "      dddddddii ",
      "      d1Rd  d   "
    ],
    [
      "      dQ d  d   ",
      "      dddddddii ",
      "      2     d   ",
      "3     d     U   ",
      "      d     d   ",
      " E    dX 44 dii ",
      "      ddddddd   ",
      " E   5d     F   ",
      "E     2     F   ",
      "      2     d   ",
      "     6d     dii ",
      "      ddddddd   ",
      " l    d   2oU   ",
      "      2   Mhd   ",
      "      dddddddii ",
      "      d1 d  d   "
    ],
    [
      "      d  d  d   ",
      "      dddddddii ",
      "      d     d   ",
      "E     d     d   ",
      "      d     d   ",
      " E    dX    dii ",
      "      ddddddd   ",
      " 7   8d     F   ",
      "E     d     F   ",
      "      d     d   ",
      "     8d     dii ",
      "      ddddddd   ",
      " E    d  2j d   ",
      "      d     d   ",
      "      dddddddii ",
      "      d  d  d   "
    ],
    [
      "      dkkkkkd   ",
      "      dddddddii ",
      "      dX    d   ",
      "7     dX    d   ",
      "      dX    d   ",
      " 7    dXXXXXdii ",
      "      ddddddd   ",
      " 7    d     F   ",
      "7     d     F   ",
      "      d     d   ",
      " 7    d     dii ",
      "      ddddddd   ",
      " 7    d 2j  d   ",
      "      d     d   ",
      "      dddddddii ",
      "      dkkkkkd   "
    ]
  ]
}