{
  "name": "multi_laboratory1_0_floor1",
  "refpalette": "c70cities:multi_laboratory1_0_floor1_palette",
  "xsize": 16,
  "zsize": 16,
  "slices": [
    [
      "                ",
      "                ",
      "           aaaaa",
      "         bbcccdc",
      "         accccec",
      "        affggggg",
      "        affghhhh",
      "        affghhhh",
      "        bdighhhh",
      "        affghhhh",
      "        affghhhh",
      "        affghhhh",
      "        affghhhh",
      "        affghhhh",
      "        affghhhh",
      "        adigjjjj"
    ],
    [
      "                ",
      "                ",
      "           abaaa",
      "         aa     ",
      "         a      ",
      "        b  kllgl",
      "        a  l mno",
      "        a  lpq n",
      "        a  gn  r",
      "        a  l    ",
      "        a  l s  ",
      "        a  l    ",
      "        a  kt  u",
      "        a  ktt  ",
      "        a  ktt  ",
      "        a  gwwwx"
    ],
    [
      "                ",
      "                ",
      "           aaaaa",
      "         ba     ",
      "         a      ",
      "        a  kllgy",
      "        a  l  A ",
      "        a  l   n",
      "        a  gu  r",
      "        a  y    ",
      "        a  l    ",
      "        b  l    ",
      "        a  l    ",
      "        a  kt   ",
      "        a  yB   ",
      "        a  gwwwC"
    ],
    [
      "                ",
      "                ",
      "           aaaaa",
      "         aa     ",
      "         a      ",
      "        a  kllgy",
      "        a  l    ",
      "        a  l    ",
      "        a  g   r",
      "        a  y    ",
      "        a  l    ",
      "        a  lD   ",
      "        a  lDEF ",
      "        a  kI   ",
      "        a  y    ",
      "        a  gwwwJ"
    ],
    [
      "                ",
      "                ",
      "           aaaaa",
      "         aa     ",
      "         a    K ",
      "        a  kllgy",
      "        b  l    ",
      "        a  l    ",
      "        a  g   r",
      "        a  y    ",
      "        a  lLM  ",
      "        a  l    ",
      "        a  l    ",
      "        a  kI   ",
      "        a  y    ",
      "        a  gwwww"
    ],
    [
      "                ",
      "                ",
      "           aaaaa",
      "         aa     ",
      "         a    N ",
      "        a  ggggg",
      "        a  gOOOO",
      "        a  gOOOO",
      "        a  gOOOr",
      "        a  g OOO",
      "        a  g OOO",
      "        a  gDOOO",
      "        a  gOOOO",
      "        a  gIOOO",
      "        a  gOOOO",
      "        a  ggggg"
    ]
  ]
}