{
  "name": "multi_hospital_1_base1",
  "refpalette": "c70cities:multi_hospital_1_base1_palette",
  "xsize": 16,
  "zsize": 16,
  "slices": [
    [
      "vabccccccddddddd",
      "vabccccccddddddd",
      "vaebbbbbbddddddd",
      "vaaaaaaaaddddddd",
      "vaaaaaaaaddddddd",
      "vaaaaaaaaddddddd",
      "vaaaaaaaaddddddd",
      "vaaaaaaaaddddddd",
      "vaaaaaaaaddddddd",
      "vaaaaaaaadf     ",
      "vaaaaaaaaddddddd",
      "vaaaaaaaaaaaaaaa",
      "vaaaaaaaaaaaaaaa",
      "vaaaaaaaaaaaaaaa",
      "vaaaaaaaaaaaaaaa",
      "vvvvvvvvvvvvvvvv"
    ],
    [
      "vab ghi bjk     ",
      "vab ghi bj      ",
      "vaebbbbbbdll   l",
      "vaaaaaaaajk     ",
      "vaaaaaaaaj      ",
      "vaaaaaaaadll   l",
      "vaaaaaaaajk     ",
      "vaaaaaaaajmm n  ",
      "vaaaaaaaad oodoo",
      "vaaaaaaaap      ",
      "vaaaaaaaadqqqdqq",
      "vaaaaaaaaaaaaaaa",
      "vaaaaaaaaaaaaaaa",
      "vaaaaaaaaaaaaaaa",
      "vaaaaaaaaaaaaaaa",
      "vvvvvvvvvvvvvvvv"
    ],
    [
      "vab rst bj      ",
      "vab rut bj      ",
      "vaeb   bbdw     ",
      "vaaaaaaaaj      ",
      "vaaaaaaaaj      ",
      "vaaaaaaaadw     ",
      "vaaaaaaaaj      ",
      "vaaaaaaaajmm x  ",
      "vaaaaaaaad oodoo",
      "vaaaaaaaap      ",
      "vaaaaaaaadqqqdqq",
      "vaaaaaaaaaaaaaaa",
      "vaaaaaaaaaaaaaaa",
      "vaaaaaaaaaaaaaaa",
      "vaaaaaaaaaaaaaaa",
      "vvvvvvvvvvvvvvvv"
    ],
    [
      "vab iyg bj      ",
      "vab iyg bj      ",
      "vaeb   bbd      ",
      "vaaaaaaaaj      ",
      "vaaaaaaaaj      ",
      "vaaaaaaaad      ",
      "vaaaaaaaaj      ",
      "vaaaaaaaajA     ",
      "vaaaaaaaadooodoo",
      "vaaaaaaaap      ",
      "vaaaaaaaadqqqdqq",
      "vaaaaaaaaaaaaaaa",
      "vaaaaaaaaaaaaaaa",
      "vaaaaaaaaaaaaaaa",
      "vaaaaaaaaaaaaaaa",
      "vvvvvvvvvvvvvvvv"
    ],
    [
      "vab  B  bj      ",
      "vab  B  bj      ",
      "vaebbbbbbd      ",
      "vaaaaaaaaj      ",
      "vaaaaaaaaj      ",
      "vaaaaaaaad      ",
      "vaaaaaaaaj      ",
      "vaaaaaaaaj      ",
      "vaaaaaaaadooodoo",
      "vaaaaaaaap      ",
      "vaaaaaaaadqqqdqq",
      "vaaaaaaaaaaaaaaa",
      "vaaaaaaaaaaaaaaa",
      "vaaaaaaaaaaaaaaa",
      "vaaaaaaaaaaaaaaa",
      "vvvvvvvvvvvvvvvv"
    ],
    [
      "vabCCCCCbdffffff",
      "vabCCCCCbdffffff",
      "vaebbbbbbddddddd",
      "vaaaaaaaadffffff",
      "vaaaaaaaadffffff",
      "vaaaaaaaadffffff",
      "vaaaaaaaadffffff",
      "vaaaaaaaadffffff",
      "vaaaaaaaaddddddd",
      "vaaaaaaaadCCCCCC",
      "vaaaaaaaaddddddd",
      "vaaaaaaaaaaaaaaa",
      "vaaaaaaaaaaaaaaa",
      "vaaaaaaaaaaaaaaa",
      "vaaaaaaaaaaaaaaa",
      "vvvvvvvvvvvvvvvv"
    ]
  ]
}