{
  "name": "multi_laboratory1_2_base1",
  "refpalette": "c70cities:multi_laboratory1_2_base1_palette",
  "xsize": 16,
  "zsize": 16,
  "slices": [
    [
      "vabcccccccccccd ",
      "vabcccccccccccd ",
      "vabcccccccccccd ",
      "vabcccccccccccde",
      "vabccccccccfcc!d",
      "vabccccccccccccd",
      "vabccccccccccccc",
      "vabccccccccccccc",
      "vabccccccccccccc",
      "vabccccccccccccc",
      "vabccccccccccccc",
      "vabccccccccfcccc",
      "vabccccccccccccc",
      "vabccccccccccccc",
      "vabccccccccccccc",
      "vabccccccccccccc"
    ],
    [
      "vabg      hi  j ",
      "vabk      hi  j ",
      "vabk    lmhi  j ",
      "vabnopo qrhi  js",
      "vabiiiitiiif  sj",
      "vabuuu l wwx   j",
      "vabuu      x  y ",
      "vabAABC C  x    ",
      "vabA  qDq  x    ",
      "vabEB FIF  x    ",
      "vabk  C C  x    ",
      "vabkJ      fs   ",
      "vabg  C C  K    ",
      "vabg  qrq  K    ",
      "vabL  FMF  N    ",
      "vabOC C C  K    "
    ],
    [
      "vabP       x  j ",
      "vab       Qx  j ",
      "vab        x  j ",
      "vab! p  RS x  js",
      "vabiiiiTiiif  Uj",
      "vab!uQ     x   j",
      "vabEl      x    ",
      "vabA       x    ",
      "vab   B    x    ",
      "vab     J  x    ",
      "vab        x    ",
      "vab        fU   ",
      "vabV       K    ",
      "vabW   Q   K    ",
      "vabX  l    Y    ",
      "vabZ       K    "
    ],
    [
      "vabA       x  j ",
      "vab        x  j ",
      "vab        x  j ",
      "vab0122    x  js",
      "vabiiiiiiiif  Uj",
      "vabE     32x   j",
      "vab        x    ",
      "vab4       x    ",
      "vab        x    ",
      "vab        x    ",
      "vab        x    ",
      "vab        fU   ",
      "vab        K    ",
      "vab        K    ",
      "vab5       K    ",
      "vab6       K    "
    ],
    [
      "vab        x  j ",
      "vab        x  j ",
      "vab        x  j ",
      "vabn       x  js",
      "vabiiiiiiiif   j",
      "vab        x   j",
      "vab        x    ",
      "vab        x    ",
      "vab        x    ",
      "vab        x    ",
      "vab        x    ",
      "vab        f    ",
      "vab        K    ",
      "vab        K    ",
      "vab        K    ",
      "vab        K    "
    ],
    [
      "vab77877787977@ ",
      "vab77877787977@ ",
      "vab77877787977@ ",
      "vabn7777777977@#",
      "vabiiii$iiif777@",
      "vab777777779777@",
      "vab7787778797777",
      "vab7787778797777",
      "vab7787778797777",
      "vab7787778797777",
      "vab7777777797777",
      "vab77777777f7777",
      "vab7777777797777",
      "vab7787778797777",
      "vab7787778797777",
      "vab7787778797777"
    ]
  ]
}