{
  "name": "multi_laboratory1_12_base1",
  "refpalette": "c70cities:multi_laboratory1_12_base1_palette",
  "xsize": 16,
  "zsize": 16,
  "slices": [
    [
      " abbbbbbbbbbbcdv",
      " abbbbbbbbbbbcdv",
      " abbbbbbbbbbbcdv",
      "eabbbbbbbbbbbcdv",
      "abbbfbbbbbbbbcdv",
      "abbbbbbbbbbbbcdv",
      "bbbbbbbbbbbbbcdv",
      "bbbbbbbbbbbbbcdv",
      "bbbbbbbbbbbbbcdv",
      "bbbbbbbbbbbbbcdv",
      "bbbbbbbbbbbbbcdv",
      "bbbbfbbbbbbbbcdv",
      "bbbbbbbbbbbbbcdv",
      "bbbbbbbbbbbbbcdv",
      "bbbbbbbbbbbbbcdv",
      "bbbbbbbbbbbbbcdv"
    ],
    [
      " g  hi  ii jicdv",
      " g  hik ii  icdv",
      " g  hi  ii jicdv",
      "lg  hik m   icdv",
      "gl  fhh    h!cdv",
      "gn  o l    lpcdv",
      "    oqr      cdv",
      "    oqk   qstcdv",
      "    oqq   qqqcdv",
      "    o        cdv",
      "    oqu   qstcdv",
      "   lfqk   qqqcdv",
      "    wqq      cdv",
      "    w     qstcdv",
      "    x     qqqcdv",
      "    w        cdv"
    ],
    [
      " g  o       ycdv",
      " g  o        cdv",
      " g  o        cdv",
      "lg  oA      Bcdv",
      "gC  fhh    hhcdv",
      "g   o C    C cdv",
      "    oD       cdv",
      "    o        cdv",
      "    o E    F cdv",
      "    o        cdv",
      "    o        cdv",
      "   CfI     F cdv",
      "    wDE      cdv",
      "    w     E  cdv",
      "    J      F cdv",
      "    w        cdv"
    ],
    [
      " g  o       Kcdv",
      " g  o       Kcdv",
      " g  o       Kcdv",
      "lg  o       Kcdv",
      "gC  fhh    hhcdv",
      "g   o C    C cdv",
      "    o        cdv",
      "    o        cdv",
      "    o        cdv",
      "    o        cdv",
      "    o        cdv",
      "   Cf        cdv",
      "    w        cdv",
      "    w        cdv",
      "    w        cdv",
      "    w        cdv"
    ],
    [
      " g  o        cdv",
      " g  o        cdv",
      " g  o        cdv",
      "lg  o        cdv",
      "g   fhh    hhcdv",
      "g   o        cdv",
      "    o        cdv",
      "    o        cdv",
      "    o        cdv",
      "    o        cdv",
      "    o        cdv",
      "    f        cdv",
      "    w        cdv",
      "    w        cdv",
      "    w        cdv",
      "    w        cdv"
    ],
    [
      " LMMNMOMMMOMMcdv",
      " LMMNMOMMMOMMcdv",
      " LMMNMOMMMOMMcdv",
      "PLMMNMMMMMMMMcdv",
      "LMMMfhhhhhhhhcdv",
      "LMMMNMMMMMMMMcdv",
      "MMMMNMOMMMOMMcdv",
      "MMMMNMOMMMOMMcdv",
      "MMMMNMOMMMOMMcdv",
      "MMMMNMOMMMOMMcdv",
      "MMMMNMMMMMMMMcdv",
      "MMMMfMMMMMMMMcdv",
      "MMMMNMMMMMMMMcdv",
      "MMMMNMOMMMOMMcdv",
      "MMMMNMOMMMOMMcdv",
      "MMMMNMOMMMQMMcdv"
    ]
  ]
}