{
  "name": "multi_megatower1_7_floor3",
  "refpalette": "c70cities:multi_megatower1_7_floor3_palette",
  "xsize": 16,
  "zsize": 16,
  "slices": [
    [
      "aaab            ",
      "aaac            ",
      "aaac            ",
      "aaac            ",
      "aadef           ",
      "aaab            ",
      "ggab            ",
      "ggab            ",
      "ggac            ",
      "ggac            ",
      "aaac            ",
      "aadef           ",
      "aaab            ",
      "aaab            ",
      "aaab            ",
      "aaac            "
    ],
    [
      "hijb            ",
      "  jc            ",
      "kkjc            ",
      "lmjc            ",
      "nedef           ",
      "nojb            ",
      "ppjb            ",
      "  jb            ",
      "  jc            ",
      "qqjc            ",
      "nojc            ",
      "nedef           ",
      "lmjb            ",
      "rrjb            ",
      " sjb            ",
      " ijc            "
    ],
    [
      "  jb            ",
      "  jc            ",
      "kkjc            ",
      " tjc            ",
      " udef           ",
      "nojb            ",
      "ppjb            ",
      "  wb            ",
      "  wc            ",
      "qqjc            ",
      "n!jc            ",
      "nudef           ",
      "  jb            ",
      "rrjb            ",
      "  jb            ",
      "  jc            "
    ],
    [
      "  jb            ",
      "  jc            ",
      "kkjc            ",
      "  jc            ",
      " odef           ",
      " ojb            ",
      "ppjb            ",
      "  xb            ",
      "  xc            ",
      "qqjc            ",
      "yojc            ",
      " odef           ",
      "  jb            ",
      "rrjb            ",
      "  jb            ",
      "  jc            "
    ],
    [
      "  jb            ",
      " yjc            ",
      "kkjc            ",
      " yjc            ",
      " odef           ",
      "yojb            ",
      "ppjb            ",
      "  jb            ",
      "  jc            ",
      "qqjc            ",
      "yojc            ",
      "yodef           ",
      " yjb            ",
      "rrjb            ",
      "  jb            ",
      "  jc            "
    ],
    [
      "  Ab            ",
      " yAc            ",
      "aaAc            ",
      "aaAc            ",
      "BBdef           ",
      "aaAb            ",
      "CCAb            ",
      "DDAb            ",
      "DDAc            ",
      "EEAc            ",
      "aaAc            ",
      "BBdef           ",
      "aaAb            ",
      "aaAb            ",
      "  Ab            ",
      "  Ac            "
    ]
  ]
}