{
  "name": "multi_communitycenter_8_floor1",
  "refpalette": "c70cities:multi_communitycenter_8_floor1_palette",
  "xsize": 16,
  "zsize": 16,
  "slices": [
    [
      "aaaaabc    d e  ",
      "aaaaab   ffdge  ",
      "hhhhhb   iidge  ",
      "j          d e  ",
      "j          d e  ",
      "j   kbdddddd e  ",
      "j    bg    gge  ",
      "hhhhhbeeeeeeee  ",
      "aaaaab          ",
      "aaaaab          ",
      "aaaaab          ",
      "aaaaab          ",
      "aaaalb          ",
      "bbbbbb          ",
      "                ",
      "                "
    ],
    [
      " m              ",
      "mn m        g   ",
      "ooooo       g   ",
      "                ",
      "                ",
      "                ",
      "g    gg    gg   ",
      "ooooop          ",
      "mqrmsp          ",
      " n  np          ",
      "  n tp          ",
      "n  tmp          ",
      "uuuuup          ",
      "pppppp          ",
      "                ",
      "                "
    ],
    [
      "                ",
      "            g   ",
      "            g   ",
      "                ",
      "                ",
      "                ",
      "g    gg    gg   ",
      "                ",
      "                ",
      "                ",
      "                ",
      "                ",
      "                ",
      "                ",
      "                ",
      "                "
    ],
    [
      "                ",
      "            w   ",
      "            w   ",
      "                ",
      "                ",
      "                ",
      "w    ww    ww   ",
      "                ",
      "                ",
      "                ",
      "                ",
      "                ",
      "                ",
      "                ",
      "                ",
      "                "
    ],
    [
      "xxxxxxxxxxxxhyy ",
      "xxxxxxxxxxxxhyy ",
      "xxxxxxxxxxxxhyy ",
      "xxxxxxxxxxxxhyy ",
      "xxxxxxxxxxxxhyy ",
      "xxxxxxxxxxxxhyy ",
      "hhhhhhhhhhhhhyy ",
      "yyyyyyyyyyyyyyy ",
      "yyyyyyyyyyyyyyy ",
      "                ",
      "                ",
      "                ",
      "                ",
      "                ",
      "                ",
      "                "
    ],
    [
      "                ",
      "                ",
      "                ",
      "                ",
      "                ",
      "                ",
      "                ",
      "                ",
      "                ",
      "                ",
      "                ",
      "                ",
      "                ",
      "                ",
      "                ",
      "                "
    ]
  ]
}