{
  "name": "multi_clubhouse1_5_base2",
  "refpalette": "c70cities:multi_clubhouse1_5_base2_palette",
  "xsize": 16,
  "zsize": 16,
  "slices": [
    [
      "vvvvvvvvvvvvvvvv",
      "vvvvvvvvvvvvvvvv",
      "vvvvvvvvvvvvvvvv",
      "aaaaaaaaaaaaaaaa",
      "aaaaaaaaaaaaaaaa",
      "aaaaaaaaaaaaaaaa",
      "aaaaaaaaaaaaaaaa",
      "aaaaaaaaaaaaaaaa",
      "aaaaaaaaaaaaaaaa",
      "vvvvvvvvvvvvvvvv",
      "vvvvvvvvvvvvvvvv",
      "vvvvvvvvvvvvvvvv",
      "vvvvvvvvvvvvvvvv",
      "vvvvvvvvvvvvvvvv",
      "vvvvvvvvvvvvvvvv",
      "vvvvvvvvvvvvvvvv"
    ],
    [
      "bbbbbcbaacbbbGGG",
      "bbbbcccaaccbbbbb",
      "aaaadaaaaaadaaaa",
      "effefffggfffefff",
      "fffffeffffffffff",
      "fffffffggffffefe",
      "fffffffggfffffff",
      "ffffffffffffffff",
      "fefefffggeffffee",
      "aaaadaaaaaadaaaa",
      "bcccccbcccGccccb",
      "cccbGccccbcccGcc",
      "bbbbbbbbbbbbbbbb",
      "GGGGhGGGGGG!GGGG",
      "iiiijiiiiiijiiii",
      "vvvvvvvvvvvvvvvv"
    ],
    [
      "klmn  o p   nmqm",
      "nnnn   o    nnnn",
      "    d      d    ",
      "     r ss       ",
      "  r       r   r ",
      "r      ss  r    ",
      "    r  ss       ",
      "r               ",
      "  r    ss r r   ",
      "    d      d    ",
      "               t",
      "   t     t      ",
      "ququuuquwwuuququ",
      "mkxm yxmmym xmxk",
      "AAAAjAAAAAAjAAAA",
      "vvvvvvvvvvvvvvvv"
    ],
    [
      " BC          C C",
      "                ",
      "    d      d    ",
      "                ",
      "                ",
      "                ",
      "                ",
      "                ",
      "                ",
      "    d      d    ",
      "                ",
      "                ",
      "                ",
      "C DC  DCC C DCD ",
      "AAAAjAAAAAAjAAAA",
      "vvvvvvvvvvvvvvvv"
    ],
    [
      "                ",
      "                ",
      "    d      d    ",
      "                ",
      "                ",
      "                ",
      "                ",
      "                ",
      "                ",
      "    d      d    ",
      "                ",
      "                ",
      "                ",
      "                ",
      "A EAjEAAAAAjEAAA",
      "vvvvvvvvvvvvvvvv"
    ],
    [
      "                ",
      "                ",
      "    d      d    ",
      "                ",
      "                ",
      "                ",
      "                ",
      "                ",
      "                ",
      "    d      d    ",
      "                ",
      "                ",
      "                ",
      "                ",
      "A EEjEAAAAEjEAAA",
      "vvvvvvvvvvvvvvvv"
    ]
  ]
}