{
  "name": "multi_condo1_0_floor7",
  "refpalette": "c70cities:multi_condo1_0_floor7_palette",
  "xsize": 16,
  "zsize": 16,
  "slices": [
    [
      "                ",
      "                ",
      "                ",
      "          a     ",
      "    bbbbbbabbbbb",
      "    bcccccd     ",
      "    bcccccd     ",
      "    bcccccd     ",
      "    bcccccd     ",
      "    bcccccd     ",
      "  eeacccccd     ",
      "    acccccd     ",
      "    acccccd     ",
      " fffacccccdg    ",
      "   haiiiiiiiiiii",
      "   hajjjjjjjjjjj"
    ],
    [
      "                ",
      "                ",
      "                ",
      "   kkkkkkkakkkkk",
      "   kaaaaaaaaaaaa",
      "   kal mnop     ",
      "   kaq   rp     ",
      "   kas t up     ",
      "   kaw t sp     ",
      "   kax    p     ",
      "  eeayAB  p     ",
      "    aCDDDDp     ",
      "    aE    p     ",
      " fffaE          ",
      "    al    lFFFFF",
      "    I           "
    ],
    [
      "                ",
      "                ",
      "                ",
      "          a     ",
      "    aaaaaaaaaaaa",
      "    aJ          ",
      "    a           ",
      "    aK          ",
      "    a    K      ",
      "    a           ",
      "  eea           ",
      "    aCDDDD      ",
      "    aE          ",
      " fffaE          ",
      "    aJ    J     ",
      "    b           "
    ],
    [
      "                ",
      "                ",
      "  eeeeeeeeeeeeee",
      "  eeeeeeeeeeeeee",
      "  eeaaaaaaaaaaaa",
      "  eea           ",
      "  eea           ",
      "  eea           ",
      "  eea           ",
      "  eea           ",
      "  eea           ",
      "    aL          ",
      "    a           ",
      " fffa           ",
      "    a           ",
      "    b           "
    ],
    [
      "                ",
      "                ",
      "                ",
      "                ",
      "    aaaaaaaaaaaa",
      "    a        MNN",
      "    a           ",
      "    a           ",
      "    a           ",
      "    a           ",
      "    a           ",
      "    a           ",
      "    a           ",
      " fffa           ",
      "    a           ",
      "    a           "
    ],
    [
      "                ",
      "                ",
      "                ",
      "   FFFFFFFFFFFFF",
      "   Faaaaaaaaaaaa",
      "   FaOOOOOOOOOOO",
      "   FaOOOOOOOOOOO",
      "   FaOOOOOOOOOOO",
      "   FaOOOOOOOOOOO",
      "   FaOOOOOOOOOOO",
      "   FaOOOOOOOOOOO",
      "   FaOOOOOOOOOOO",
      "   FaOOOOOOOOOOO",
      " fffaOOOOOOOOOOO",
      "    aFFFFFFFFFFF",
      "    a           "
    ]
  ]
}