{
  "name": "multi_condo1_2_floor6",
  "refpalette": "c70cities:multi_condo1_2_floor6_palette",
  "xsize": 16,
  "zsize": 16,
  "slices": [
    [
      "   abccccccdeeee",
      "   abccccccccccc",
      " fffbgggcccccccc",
      "  hibgggcccccccc",
      "  hibgggcccccccc",
      "  hibgggcccccccc",
      "  hibgggcccccccc",
      "  hibgggcccccccc",
      "  hibgggcccccccc",
      "  hibccccccccccc",
      "  hibccccccccccc",
      "  hibbbbbbbbcccc",
      "  hiiiiiiiffffff",
      "  hhhhhhhhffffff",
      "          ffffff",
      "                "
    ],
    [
      "    j  k        ",
      "    bbbblbbbmmmm",
      " fffbnob pbqr ss",
      "   ib  k tb uw  ",
      "   ibbbb tbqr   ",
      "   ib! k tbq    ",
      "   ibbbb tbx  y ",
      "   ib  k pbx  s ",
      "   ibbbb bbb  A ",
      "   ib           ",
      "   ibBC BCD     ",
      "   ibbEEEbbb    ",
      "   iiiiiiif     ",
      "          fFFFFF",
      "          f     ",
      "                "
    ],
    [
      "    F  I        ",
      "    bbbbJbbbmmmm",
      " fffb  b  b K   ",
      "    bL I  bMN   ",
      "    bbbb  b K   ",
      "    bL I  bM    ",
      "    bbbb  bx    ",
      "    bL I Obx    ",
      "    bbbb bbbM P ",
      "    b           ",
      "    b     Q     ",
      "    bbmmmbbb    ",
      "          f     ",
      "          f     ",
      "          f     ",
      "                "
    ],
    [
      "    F  b        ",
      "    bbbbRbbbmmmm",
      " fffb  b  b     ",
      "    bS b  b     ",
      "    bbbb !b     ",
      "    bS b  b     ",
      "    bbbb  bx    ",
      "    bS b  bx    ",
      "    bbbbTbbb    ",
      "    b           ",
      "    b           ",
      "    bbmmmbbb    ",
      "          f     ",
      "          f     ",
      "          f     ",
      "                "
    ],
    [
      "    b  b        ",
      "    bbbbbbbbmmmm",
      " fffb  b  b     ",
      "   Ub  b  b     ",
      "   Ubbbb  b     ",
      "   Ub  b  b     ",
      "   Ubbbb  b     ",
      "   Ub  b  b     ",
      "   Ubbbbbbbbmmmm",
      "   Ub           ",
      "   Ub           ",
      "   Ubbbbbbbbbbbb",
      "   UUUUUUUfVVVVV",
      "          f     ",
      "          f     ",
      "                "
    ],
    [
      "    bWWbXXX     ",
      "    bbbbbbbbRRRR",
      " fffbWWbWWbeeeee",
      "   YbWWbWWbeeeee",
      "   YbbbbWWbeeeee",
      "   YbWWbWWbeeeee",
      "   YbbbbWWbeeeee",
      "   YbWWbWWbeeeee",
      "   YbbbbbbbbTTTT",
      "   Ybeeeeeeeeeee",
      "   Ybeeeeeeeeeee",
      "   Ybbbbbbbbbbbb",
      "   YYYYYYYf     ",
      "          fZZZZZ",
      "          f     ",
      "                "
    ]
  ]
}