{
  "name": "multi_clubhouse1_1_base2",
  "refpalette": "c70cities:multi_clubhouse1_1_base2_palette",
  "xsize": 16,
  "zsize": 16,
  "slices": [
    [
      "vvvvvvvvvvvvvvvv",
      "vvvvvvvvvvvvvvvv",
      "vvvvvvvvvvvvvvvv",
      "vvvvvvvvvvvvvvvv",
      "vvvvvvvvvvvvvvvv",
      "vvvvvvvvvvvvvvvv",
      "vvvvvvvvvvvvvvvv",
      "vvvvvvvvvvvvvvvv",
      "vvvvvvvvvvvvvvvv",
      "vvvvvvvvvvvvvvvv",
      "vvvvvvvvvvvvvvvv",
      "vvvvvvvvvvvvvvvv",
      "vvvvvvvvvvvvvvvv",
      "vvvvvvvvvvvvvvvv",
      "vvvvvvvvvvvvvvvv",
      "vvvvvvvvvvvvvvvv"
    ],
    [
      "vaaaaaaaaaaaaaaa",
      "vaaaaaaaaaaaaaaa",
      "vaaaaaaaaaaaaaaa",
      "vaaaaaaaaaaaaaaa",
      "vaaaaabaaaaaabaa",
      "vaaaaacaaaaaacca",
      "vaaaaccaaaaaaccc",
      "vccccccaaaaaaccc",
      "vccccccaaaaaaccc",
      "vccccccaaaaaaccc",
      "vccccccaaaaaaccc",
      "vcccccbaaaaaabcc",
      "vccccccaaaaaaccc",
      "vccccccaaaaaaccc",
      "vccccccaaaaaaccc",
      "vccccccaaaaaaccc"
    ],
    [
      "vaaaaad e  f daa",
      "vaaaaadgg  ggdaa",
      "vaaaaad!    hdaa",
      "vaaaaadii  iidaa",
      "vcccccbjjjjjjbcc",
      "vccccckjjjjjjl c",
      "vcccc kmnojjj   ",
      "vccccp jjjjjjl  ",
      "vcccp kjjjjjj   ",
      "vccc  kmnojjj   ",
      "vccc pkjjjjjjl  ",
      "vccc  bjjjjjjb  ",
      "vccc   jjjjjjlqq",
      "vccc qkmnojjj qr",
      "vccc qkjjjjjjlqs",
      "vccc qkjjjjjjlqr"
    ],
    [
      "vaaaaad t  u daa",
      "vcccccdgg  ggdcc",
      "vcccccdw    xdcc",
      "vcccccdii  iidcc",
      "vcccc b      b  ",
      "vccc  k      l  ",
      "vccc  k         ",
      "vccc         l  ",
      "vccc  k      l  ",
      "vccc  k         ",
      "vccc  k      l  ",
      "vccc  b      b  ",
      "vccc  k      l  ",
      "vccc  k        y",
      "vccc  k      l A",
      "vccc  k      l y"
    ],
    [
      "vcccccd B  C dcc",
      "vcccccdDDEEDDdcc",
      "vccc  d      d  ",
      "vccc  dFFEEFFd  ",
      "vccc  b  IJ  b  ",
      "vccc  k      l  ",
      "vccc  k      l  ",
      "vccc  k      l  ",
      "vccc  k      l  ",
      "vccc  k         ",
      "vccc  k      l  ",
      "vccc  b      b  ",
      "vccc  k      l  ",
      "vccc  k      l  ",
      "vccc  k      l  ",
      "vccc  k      l  "
    ],
    [
      "vcccp K      K  ",
      "vcccp K      K  ",
      "vccc  K      K  ",
      "vccc  K      K  ",
      "vccc  bKKKKKKb  ",
      "vccc  K      K  ",
      "vccc  K      K  ",
      "vccc  K      K  ",
      "vccc  K      K  ",
      "vccc  K      K  ",
      "vccc  K      K  ",
      "vccc  b      b  ",
      "vccc  K      K  ",
      "vccc  K      K  ",
      "vccc  K      K  ",
      "vccc  K      K  "
    ]
  ]
}