{
  "name": "multi_communitycenter_0_base1",
  "refpalette": "c70cities:multi_communitycenter_0_base1_palette",
  "xsize": 16,
  "zsize": 16,
  "slices": [
    [
      "vvvvvvvvvvvvvvvv",
      "vHHHHHHHHHHHHHHH",
      "vHHHHHHHHHHHHHHH",
      "vHHHHHHHHHHHHHHH",
      "vHHHHHHHHHHHHHHH",
      "vHHHHHHHHHHHHHHH",
      "vHHHHHHHHHHHHHHH",
      "vHHHHHHHHHHHHHHH",
      "vHHHHHHHHHHHHHHH",
      "vHHHHHHHHHHHHHHH",
      "vHHHHHHHHHHHHHHH",
      "vHHHHHHHHHHHHHHH",
      "vHHHHHHHHHHHHHHH",
      "vHHHHHHHHHHHHHHH",
      "vHHHHHHHHHHHHHHH",
      "vHHHHHHHHHHHHHHH"
    ],
    [
      "vvvvvvvvvvvvvvvv",
      "vaaaaaaaaaaaaaaa",
      "vaaaaaaaaaaaaaaa",
      "vaaaaaaaaaaaaaaa",
      "vaaaaaaaaaaaaaaa",
      "vaaaaaaaaaaaaaaa",
      "vaaaa bcbc bcbc ",
      "vaaaa         d ",
      "vaaaaefgfgefgfge",
      "vaaaa           ",
      "vaaaa           ",
      "vaaaa           ",
      "vaaaa           ",
      "vaaaa           ",
      "vaaaa           ",
      "vaaaaebcbce    e"
    ],
    [
      "vvvvvvvvvvvvvvvv",
      "vaaaaaaaaaaaaaaa",
      "vaaaaaaaaaaaaaaa",
      "vaaaaaaaaaaaaaaa",
      "vaaaaaaaaaaaaaaa",
      "vaaaaaaaaaaaaaaa",
      "vaaaa           ",
      "vaaaa           ",
      "vaaaae    e    e",
      "vaaaa           ",
      "vaaaa           ",
      "vaaaa           ",
      "vaaaa           ",
      "vaaaa           ",
      "vaaaa           ",
      "vaaaae    e    e"
    ],
    [
      "vvvvvvvvvvvvvvvv",
      "vaaaaaaaaaaaaaaa",
      "vaaaaaaaaaaaaaaa",
      "vaaaaaaaaaaaaaaa",
      "vaaaaaaaaaaaaaaa",
      "vaaaaaaaaaaaaaaa",
      "vaaaa!          ",
      "vaaaa           ",
      "vaaaae    e    e",
      "vaaaa           ",
      "vaaaa           ",
      "vaaaa           ",
      "vaaaa           ",
      "vaaaa           ",
      "vaaaa           ",
      "vaaaae    e    e"
    ],
    [
      "vvvvvvvvvvvvvvvv",
      "vaaaaaaaaaaaaaaa",
      "vaaaaaaaaaaaaaaa",
      "vaaaaaaaaaaaaaaa",
      "vaaaaaaaaaaaaaaa",
      "vaaaaaaaaaaaaaaa",
      "vaaaae    e    e",
      "vaaaae    e    e",
      "vaaaaehhhhehhhhe",
      "vaaaae    e    e",
      "vaaaae    e    e",
      "vaaaae    e    e",
      "vaaaae    e    e",
      "vaaaae    e    e",
      "vaaaae    e    e",
      "vaaaaehhhhehhhhe"
    ],
    [
      "vvvvvvvvvvvvvvvv",
      "vaaaaaaaaaaaaaaa",
      "vaaaaaaaaaaaaaaa",
      "vaaaaaaaaaaaaaaa",
      "vaaaaaaaaaaaaaaa",
      "vaaaaaaaaaaaaaaa",
      "vaaaaaaaaaaaaaaa",
      "vaaaaaaaaaaaaaaa",
      "vaaaaaaaaaaaaaaa",
      "vaaaaaaaaaaaaaaa",
      "vaaaaaaaaaaaaaaa",
      "vaaaaaaaaaaaaaaa",
      "vaaaaaaaaaaaaaaa",
      "vaaaaaaaaaaaaaaa",
      "vaaaaaaaaaaaaaaa",
      "vaaaaaaaaaaaaaaa"
    ]
  ]
}