{
  "name": "multi_laboratory1_11_base3",
  "refpalette": "c70cities:multi_laboratory1_11_base3_palette",
  "xsize": 16,
  "zsize": 16,
  "slices": [
    [
      "aaaaaaaaaaaaabcz",
      "aaaaaaaaaaaaabcz",
      "aaaaaaaaaaaaabcz",
      "aaaaaaaaaaaaabcz",
      "aaaaaaaaaaaaabcz",
      "aaaaaaaaaaaaabcz",
      "aaaadaaaaaaaabcz",
      "aaaaaaaaaaaaabcz",
      "aaaaaaaaaaaaabcz",
      "aaaaaaaaaaaaabcz",
      "aaaaaaaaaaaaabcz",
      "aaaaaaaaaaaaabcz",
      "eaaaaaaaaaaaabcz",
      "eaaadaaaaaaaabcz",
      "feaaaaaaaaaaabcz",
      " eaaaaaaaaaaabcz"
    ],
    [
      "    ghiiiiiihbcz",
      "    gj k  l ibcz",
      "    gmk    nibcz",
      "    g       ibcz",
      "    o       ibcz",
      "    gpqpqpqqhbcz",
      "r  fdggggggggbcz",
      "    gsss tt ubcz",
      "    gssw     bcz",
      "    gs xy   AAcz",
      "    g BBB CADEcz",
      "    g BFF xADEcz",
      "IJ  g KBB   AAcz",
      "If  dLCM  y ubcz",
      "fI  gL       bcz",
      " I  N       AAcz"
    ],
    [
      "    ghiOiiPihbcz",
      "    QR      ibcz",
      "    Q       Sbcz",
      "    g       ibcz",
      "    T       Sbcz",
      "    gU    V hbcz",
      "   Wdggggggggbcz",
      "    g!s     ubcz",
      "    Q       Xbcz",
      "    Q       IAcz",
      "    Q YY   IDEcz",
      "    Q YY   IDEcz",
      "I   g K Z   IAcz",
      "IW  d  0    ubcz",
      "fI  g       Xbcz",
      " I  N       IAcz"
    ],
    [
      "    gh111111hbcz",
      "    2       nbcz",
      "    2       3bcz",
      "    g       4bcz",
      "    2        bcz",
      "    g       hbcz",
      "   Wdggggggggbcz",
      "    gs   55 ubcz",
      "    Q        bcz",
      "    Q       IAcz",
      "    Q 66   IDEcz",
      "    Q 66   IDEcz",
      "I   g       IAcz",
      "IW  d       ubcz",
      "fI  g        bcz",
      " I  N       IAcz"
    ],
    [
      "    gh      hbcz",
      "    g        bcz",
      "    g       7bcz",
      "    g        bcz",
      "    g        bcz",
      "    g       hbcz",
      "    dggggggggbcz",
      "    g  8  8 9bcz",
      "    g       Xbcz",
      "    g       IAcz",
      "    g      I@Ecz",
      "    g      I@Ecz",
      "I   g       IAcz",
      "I   d       9bcz",
      "fI  g       Xbcz",
      " I  g       IAcz"
    ],
    [
      "####2$$$$$$$$bcz",
      "##%#2$^$$$$^$bcz",
      "##%#2$$$$$$$$bcz",
      "##%#2$$$$$$$$bcz",
      "##%#2$^$$$$&$bcz",
      "####2$$$$$$$$bcz",
      "####dggggggggbcz",
      "####2********bcz",
      "####2((((((((bcz",
      "####2(()((%(AAcz",
      "####2((%((%A+Ecz",
      "####2(()((%A+Ecz",
      "I###2((%((%(AAcz",
      "I###d((((((((bcz",
      "fI##2((((((((bcz",
      " I##2((%((%(AAcz"
    ]
  ]
}