{
  "name": "multi_militarybase_3_base1",
  "refpalette": "c70cities:multi_militarybase_3_base1_palette",
  "xsize": 16,
  "zsize": 16,
  "slices": [
    [
      "        vaaaaaav",
      "        vaaaaaav",
      "  bbbbbbvaaaaaav",
      "  bccccbvaaaaaav",
      "  bccccbvaaaaaav",
      "  bccccbvaaaaaav",
      "bbbccccbvaaaaaav",
      "cccccccbvaaaaaav",
      "cccccccbvaaaaaav",
      "bbbbbbbbvaaaaaav",
      "dddddddbvaaaaaav",
      "dddddddbvaaaaaav",
      "dddddddbvaaaaaav",
      "dddddddbvaaaaaav",
      "bbbbbbbbvaaaaaav",
      "vvvvvvvvvvvvvvvv"
    ],
    [
      "        vaaaaaav",
      "        vaaaaaav",
      "  veeeevvaaaaaav",
      "  fgggg vaaaaaav",
      "  fh  g vaaaaaav",
      "  f     vaaaaaav",
      "ffv    vvaaaaaav",
      "        vaaaaaav",
      "        vaaaaaav",
      "eeeeijeevaaaaaav",
      "kkv    vvaaaaaav",
      "        vaaaaaav",
      "        vaaaaaav",
      " l  l l vaaaaaav",
      " lv l lvvaaaaaav",
      "vvvvvvvvvvvvvvvv"
    ],
    [
      "        vaaaaaav",
      "        vaaaaaav",
      "  veeeevvaaaaaav",
      "  fhggg vaaaaaav",
      "  f   g vaaaaaav",
      "  f     vaaaaaav",
      "  v    vvaaaaaav",
      "        vaaaaaav",
      "        vaaaaaav",
      "eeeemneevaaaaaav",
      " ov    vvaaaaaav",
      "        vaaaaaav",
      "        vaaaaaav",
      "        vaaaaaav",
      "pqv qpqvvaaaaaav",
      "vvvvvvvvvvvvvvvv"
    ],
    [
      "        vaaaaaav",
      "        vaaaaaav",
      "  veeeevvaaaaaav",
      "  f hgg vaaaaaav",
      "  f   g vaaaaaav",
      "  f     vaaaaaav",
      "  v    vvaaaaaav",
      "        vaaaaaav",
      "        vaaaaaav",
      "eeeeeeeevaaaaaav",
      "  v    vvaaaaaav",
      "        vaaaaaav",
      "        vaaaaaav",
      "        vaaaaaav",
      "  v    vvaaaaaav",
      "vvvvvvvvvvvvvvvv"
    ],
    [
      "        vaaaaaav",
      "        vaaaaaav",
      "  veeeevvaaaaaav",
      "  r  hg vaaaaaav",
      "  s   g vaaaaaav",
      "  r     vaaaaaav",
      "  v    vvaaaaaav",
      "        vaaaaaav",
      "        vaaaaaav",
      "eeeeeeeevaaaaaav",
      "  v    vvaaaaaav",
      "        vaaaaaav",
      "        vaaaaaav",
      "        vaaaaaav",
      "  v    vvaaaaaav",
      "vvvvvvvvvvvvvvvv"
    ],
    [
      "ttbtttttvaaaaaav",
      "ttbtttttvaaaaaav",
      "ttbbbbbbvaaaaaav",
      "ttb   hbvaaaaaav",
      "ttb   gbvaaaaaav",
      "ttbttttbvaaaaaav",
      "bbbbbbbbvaaaaaav",
      "ttbttttbvaaaaaav",
      "ttbttttbvaaaaaav",
      "ttbttttbvaaaaaav",
      "ttbttttbvaaaaaav",
      "ttbttttbvaaaaaav",
      "ttbttttbvaaaaaav",
      "ttbttttbvaaaaaav",
      "bbbbbbbbvaaaaaav",
      "vvvvvvvvvvvvvvvv"
    ]
  ]
}