{
  "name": "multi_hospital_0_floor1",
  "refpalette": "c70cities:multi_hospital_0_floor1_palette",
  "xsize": 16,
  "zsize": 16,
  "slices": [
    [
      "                ",
      "         a      ",
      "         b c c c",
      "         deeeeee",
      "         f  ghhh",
      "         d  ghhh",
      "         fi ghhh",
      "         dijghhh",
      "  kllllllkeeehhh",
      "  l      e  mhhh",
      "  l      e  mhhh",
      "  l      e eehhh",
      "  l      khhhhhh",
      "  l      khhhhhh",
      "  l      khhhhhh",
      "  l      khhhhhh"
    ],
    [
      "                ",
      "         a      ",
      "         b c c c",
      "         neeeeee",
      "         n  l o ",
      "         ni l   ",
      "         np l q ",
      "         n      ",
      "  krrrrrrkeeel  ",
      "  shhhhhhe  t   ",
      "  shhuwhhe  x   ",
      "  shhhhhhe ee   ",
      "  shhhhhhby  A  ",
      "  shhwBhhb   C  ",
      "  shhhhhhb   A  ",
      "  shhhhhhb DDA  "
    ],
    [
      "                ",
      "         a      ",
      "         b c c c",
      "         neennne",
      "         ni     ",
      "         np     ",
      "         n      ",
      "         n      ",
      "  kkkkkkkkeeel  ",
      "    EEhhhe  F   ",
      "    EEhhhe  I   ",
      "    EEhhhe eeJ  ",
      "    EEhhhby  A  ",
      "    EEhhhb   K  ",
      "    EEhhhb   A  ",
      "    EEhhhb  LA  "
    ],
    [
      "                ",
      "         a      ",
      "         b c c c",
      "         neennne",
      "         nji    ",
      "         n i    ",
      "         n      ",
      "         n      ",
      "         keeel  ",
      "        Me  N   ",
      "        Me  N   ",
      "        Me ee   ",
      "        Mby  A  ",
      "         f   N  ",
      "         f   A  ",
      "         f   A  "
    ],
    [
      "                ",
      "         a      ",
      "         b c c c",
      "         neeeeee",
      "         n      ",
      "         n O    ",
      "         n i  P ",
      "         n      ",
      "         keeel  ",
      "        Me  e   ",
      "        Me  e   ",
      "        Me ee   ",
      "        Mby  A  ",
      "        MQ   A  ",
      "        MQ   A  ",
      "        MQ  RA  "
    ],
    [
      "                ",
      "         a      ",
      "         b c c c",
      "         neeeeee",
      "         n      ",
      "         n      ",
      "         n O  B ",
      "         n i    ",
      "         keeelll",
      "        Me  e   ",
      "        Me  e   ",
      "        Me Se   ",
      "        MbvTTA  ",
      "        MbvTTA  ",
      "        MbvTTA  ",
      "        MbvTTA  "
    ]
  ]
}