{
  "name": "multi_laboratory1_7_ground",
  "refpalette": "c70cities:multi_laboratory1_7_ground_palette",
  "xsize": 16,
  "zsize": 16,
  "slices": [
    [
      "aaaaaaaaaaaaaaaa",
      "aaaaaaaaaaaaaaaa",
      "aaaaaaaaaaaaaaaa",
      "aaaaaaaaaaaaaaaa",
      "aaaaaaaaaaaaaaaa",
      "baaaaaaaaaaaaaab",
      "baaaaaaaaaaaaaab",
      "bbaaaaaaaaaaaabb",
      "cbbbaaaaaaaabbbc",
      "cccbbbaaaabbbccc",
      "cccccbbbbbbccccc",
      "cccccccccccccccc",
      "cccccccccccccccc",
      "cccccccccccccccc",
      "cccccccccccccccc",
      "ccccc      ccccc"
    ],
    [
      "                ",
      "                ",
      "                ",
      "                ",
      "                ",
      "d              d",
      "d              d",
      "dd            dd",
      " ddd        ddd ",
      "   ddd    ddd   ",
      "     dddddd     ",
      "e              e",
      "fe            eg",
      "hhe  ij  ij  ehk",
      "  lm nnnnnn oph ",
      "  qmr      sot  "
    ],
    [
      "                ",
      "                ",
      "                ",
      "                ",
      "                ",
      "                ",
      "                ",
      "                ",
      "                ",
      "                ",
      "                ",
      "e              e",
      "!e            eg",
      "hhe          eh ",
      "  um        o h ",
      "   m        o   "
    ],
    [
      "                ",
      "                ",
      "                ",
      "                ",
      "                ",
      "                ",
      "                ",
      "                ",
      "                ",
      "                ",
      "                ",
      "e              e",
      "we            eg",
      "hhe          eh ",
      "  um        o h ",
      "  xm        o   "
    ],
    [
      "                ",
      "                ",
      "                ",
      "                ",
      "                ",
      "                ",
      "                ",
      "                ",
      "                ",
      "                ",
      "                ",
      "e              e",
      " e            eg",
      "yAe          eBg",
      "   m        o  g",
      "   m        o C "
    ],
    [
      "                ",
      "                ",
      "                ",
      "                ",
      "                ",
      "                ",
      "                ",
      "                ",
      "                ",
      "                ",
      "                ",
      "e              e",
      "De            eD",
      "DDe          eDD",
      "DDDm        oDDD",
      "DDDm E    E oDDD"
    ]
  ]
}