{
  "name": "multi_megatower1_4_floor1",
  "refpalette": "c70cities:multi_megatower1_4_floor1_palette",
  "xsize": 16,
  "zsize": 16,
  "slices": [
    [
      "a   bccccdcefghh",
      "a   bccccdcefghh",
      "a   bccccdcefghh",
      "ijkkbccccdcefghh",
      "bbbblcccccclfhhh",
      "bbbbbbbbbbbefhhh",
      "bbbbbbbbbbbefhhh",
      "bbbbbbbbbbbefhhh",
      "bbbbbbbbbbbefhhh",
      "bbbbbbbbbbbefhhh",
      "bbbbbbbbbbbefhhh",
      "bbbblbbbbbblfhhh",
      "bbbbbbbbbbbefhhh",
      "bbbbbbbbbbbefhhh",
      "bbbbbbbbbbbefhhh",
      "bbbmbbbbbbbefhhh"
    ],
    [
      "a   a n n       ",
      "a   aopop       ",
      "a   a   n       ",
      "akqqarr n       ",
      "stuwlxxyx  l    ",
      "    A           ",
      "    B  CD       ",
      "E   F  I        ",
      "E   J  CD       ",
      "    B           ",
      "   KA  CD       ",
      "  LLl  I   l    ",
      "   KA  CD       ",
      "   MA           ",
      "    A  CD       ",
      " NNOA  I    PQ  "
    ],
    [
      "a   a n nR      ",
      "a   aSpSpR      ",
      "a   a   nR      ",
      "ak  a   n       ",
      "s TUlxxVx  l    ",
      "    A           ",
      "    B           ",
      "    W  I        ",
      "    X           ",
      "    B           ",
      "   YA           ",
      "   Zl  I   l    ",
      "   YA           ",
      "    A           ",
      "    A           ",
      "    A  I        "
    ],
    [
      "a   a n n       ",
      "a   apppp0      ",
      "a   a   n       ",
      "akkka   n       ",
      "s1  lxx2x  l    ",
      "    A           ",
      "    B           ",
      "    B  3        ",
      "    B           ",
      "    B           ",
      "    A           ",
      "    l  3   l    ",
      "    A           ",
      "    A           ",
      "    A           ",
      "    A  3        "
    ],
    [
      "a   a4p4p       ",
      "a   apppp       ",
      "a   a444p       ",
      "akkka444p       ",
      "sssslxxxx  l    ",
      "    5           ",
      "    6 787       ",
      "    5 898       ",
      "    6 787       ",
      "    5           ",
      "   @6 787       ",
      "5656l 898  l    ",
      "   @5 787       ",
      "    6           ",
      "    5 787       ",
      "    6 898       "
    ],
    [
      "#  #$   %       ",
      "#  #$^! %       ",
      "#  #$^^ %       ",
      "####$   %       ",
      "&&&&l%%%%  l    ",
      "****$           ",
      "****$           ",
      "****$           ",
      "****$           ",
      "****$           ",
      "****$           ",
      "&&&&l      l    ",
      "****$           ",
      "****$           ",
      "****$           ",
      "****$           "
    ]
  ]
}