{
  "name": "multi_clubhouse1_0_base1",
  "refpalette": "c70cities:multi_clubhouse1_0_base1_palette",
  "xsize": 16,
  "zsize": 16,
  "slices": [
    [
      "vvvvvvvvvvvvvvvv",
      "vaaaaaaaaaaaaaaa",
      "vaaaaaaaaaaaaaaa",
      "vaaaaaaaaaaaaaaa",
      "vaaaaaaaaaaaaaaa",
      "vaaaaaaaaaaaaaaa",
      "vaaaaaaaaaaaaaaa",
      "vaaaaaaaaaaaaaaa",
      "vaaaaaaaaaaaaaaa",
      "vaaaaaaaaaaaaaaa",
      "vaaaaaaaaaaaaaaa",
      "vaaaaaaaaaaaaaaa",
      "vbbbbbbbbbbbbbbb",
      "vbbbbbccccccccbb",
      "vbbd dceeeeeec  ",
      "vbbd dceeeeeecd "
    ],
    [
      "vvvvvvvvvvvvvvvv",
      "vaaaaaaaaaaaaaaa",
      "vaaaaaaaaaaaaaaa",
      "vaaaaaaaaaaaaaaa",
      "vaaaaaaaaaaaaaaa",
      "vaaaaaaaaaaaaaaa",
      "vaaaaaaaaaaaaaaa",
      "vaaaaaaaaaaaaaaa",
      "vaaaaaaaaaaaaaaa",
      "vaaaaaaaaaaaaaaa",
      "vaaaaaaaaaaaaaaa",
      "vbbbbbbbbbbbbbbb",
      "vbbbbbbbbbbbbbbb",
      "vbb d          d",
      "vbb             ",
      "vbb             "
    ],
    [
      "vvvvvvvvvvvvvvvv",
      "vaaaaaaaaaaaaaaa",
      "vaaaaaaaaaaaaaaa",
      "vaaaaaaaaaaaaaaa",
      "vaaaaaaaaaaaaaaa",
      "vaaaaaaaaaaaaaaa",
      "vaaaaaaaaaaaaaaa",
      "vaaaaaaaaaaaaaaa",
      "vaaaaaaaaaaaaaaa",
      "vaaaaaaaaaaaaaaa",
      "vbbbbbbbbbbbbbbb",
      "vbbbbbbbbbbbbbbb",
      "vbbd    d       ",
      "vbb             ",
      "vbb             ",
      "vbb             "
    ],
    [
      "vvvvvvvvvvvvvvvv",
      "vaaaaaaaaaaaaaaa",
      "vaaaaaaaaaaaaaaa",
      "vaaaaaaaaaaaaaaa",
      "vaaaaaaaaaaaaaaa",
      "vaaaaaaaaaaaaaaa",
      "vaaaaaaaaaaaaaaa",
      "vaaaaaaaaaaaaaaa",
      "vbbbbbbbbbbbbbbb",
      "vbbbbbbbbbbbbbbb",
      "vbbbbbbbbbbbbb  ",
      "vb    d ddd   d ",
      "vb              ",
      "vb              ",
      "vb              ",
      "vb              "
    ],
    [
      "vvvvvvvvvvvvvvvv",
      "vaaaaaaaaaaaaaaa",
      "vaaaaaaaaaaaaaaa",
      "vaaaaaaaaaaaaaaa",
      "vaaaaaaaaaaaaaaa",
      "vaaaaaaaaaaaaaaa",
      "vbbbbbbbbbbbbbbb",
      "vbbbbbbbbbbbbbbb",
      "vbbbbbbbbbbbbbbb",
      "vb              ",
      "vbd      d  d   ",
      "vb              ",
      "vb              ",
      "vb              ",
      "vb              ",
      "vb              "
    ],
    [
      "vvvvvvvvvvvvvvvv",
      "vaaaaaaaaaaaaaaa",
      "vaaaaaaaaaaaaaaa",
      "vbbbbbbbbbbbbbbb",
      "vbbbbbbbbbbbbbbb",
      "vbbbbbbbbbbbbbbb",
      "vbbbbbbbbbbbbbbb",
      "vb  d        d  ",
      "vb    d         ",
      "vb              ",
      "vb              ",
      "vb              ",
      "vb              ",
      "vb              ",
      "vb              ",
      "vb              "
    ]
  ]
}