{
  "name": "multi_laboratory1_0_base1",
  "refpalette": "c70cities:multi_laboratory1_0_base1_palette",
  "xsize": 16,
  "zsize": 16,
  "slices": [
    [
      "zzzzzzzzzzzzzzzz",
      "zaaaaaaaaaaaaaaa",
      "zabbbbbbbbbbcccc",
      "zabdddddddde    ",
      "zabdddddddde    ",
      "zabddddddddeeeee",
      "zabddddddddfffff",
      "zabddddddddfffff",
      "zabffffffffeffff",
      "zabd!ddddddfffff",
      "zabddddddddfffff",
      "zabddddddddfffff",
      "zabddddddddfffff",
      "zabddddddddfffff",
      "zabddddddddfffff",
      "zabffffffffeffff"
    ],
    [
      "zzzzzzzzzzzzzzzz",
      "zaaaaaaaaaaaaaaa",
      "zabbbbbbbbbbcccc",
      "zabghghghghi    ",
      "zabg g g g i    ",
      "zabjkjljljliiiii",
      "zab        m  n!",
      "zabooppppooi   q",
      "zabiiiiiiiie   r",
      "zabssttttssi   u",
      "zab        w   u",
      "zab        i   u",
      "zabxyAyAyAyi   u",
      "zab B B B Bi   r",
      "zabCBCBCBCBi    ",
      "zabiiiiiiiie    "
    ],
    [
      "zzzzzzzzzzzzzzzz",
      "zaaaaaaaaaaaaaaa",
      "zabbbbbbbbbbcccc",
      "zabg g g g i    ",
      "zabg g g g i    ",
      "zabjDjEjEjEiiiii",
      "zab        F    ",
      "zabIJJJJJJKi    ",
      "zabiiiiiiiie   L",
      "zabIMMMMMMKi   N",
      "zab        O    ",
      "zab        i   P",
      "zabQyRyRyRyi   S",
      "zab B B B Bi   L",
      "zab B B B Bi    ",
      "zabiiiiiiiie    "
    ],
    [
      "zzzzzzzzzzzzzzzz",
      "zaaaaaaaaaaaaaaa",
      "zabbbbbbbbbbcccc",
      "zabg g g g i    ",
      "zabg g g g i    ",
      "zabjjjjjjjjiiiii",
      "zab        i    ",
      "zab JJJJJJ i    ",
      "zabiiiiiiiie   K",
      "zab MMMMMM i    ",
      "zab        i    ",
      "zab        i   T",
      "zabyyyyyyyyi    ",
      "zab B B B Bi   K",
      "zab B B B Bi    ",
      "zabiiiiiiiie    "
    ],
    [
      "zzzzzzzzzzzzzzzz",
      "zaaaaaaaaaaaaaaa",
      "zabbbbbbbbbbcccc",
      "zabUVUVUVUVi    ",
      "zabUUUUUUUUi    ",
      "zabUUUUUUUUiiiii",
      "zabUUUUUUUUi    ",
      "zabUUUUUUUUi    ",
      "zabiiiiiiiie    ",
      "zabUUUUUUUUi    ",
      "zabUUUUUUUUi    ",
      "zabUUUUUUUUi    ",
      "zabUUUUUUUUi    ",
      "zabUUUUUUUUi    ",
      "zabVUVUVUVUi    ",
      "zabiiiiiiiie    "
    ],
    [
      "zzzzzzzzzzzzzzzz",
      "zaaaaaaaaaaaaaaa",
      "zabbbbbbbbbbcccc",
      "zab W W W WiXXXX",
      "zab W W W WiXXXX",
      "zab W W W Wiiiii",
      "zab W W W WiYYYY",
      "zab WWWWWWWiYYYY",
      "zabiiiiiiiieYYYY",
      "zabWWWWWWWWiYYYY",
      "zabW W W W iYYYY",
      "zabW W W W iYYYY",
      "zabW W W W iYYYY",
      "zabW W W W iYYYY",
      "zabW W W W iYYYY",
      "zabZZZZZZZZe0000"
    ]
  ]
}