{
  "name": "multi_residential1_1_ground",
  "refpalette": "c70cities:multi_residential1_1_ground_palette",
  "xsize": 16,
  "zsize": 16,
  "slices": [
    [
      "GGabbbbbbbbbbaGG",
      "GGabbbbbbbbbbaGG",
      "GGabbbbbbbbbbaGG",
      "GGabbbbbbbbbbaGG",
      "GGabbbbbbbbbbaGG",
      "GGabbbbbbbbbbaGG",
      "GGabbbbbbbbbbaGG",
      "GGaaaaaaaaaaaaGG",
      "GGcGGGGGGdGGGcGG",
      "GGcGGGddGGGGGcGG",
      "GGcGGdGGGdGddcGG",
      "GGccccccccccccGG",
      "GGGGGGGGGGGGGGGG",
      "GGGGGGGGGGGGGGGG",
      "GGGGGGGGGGGGGGGG",
      "GGGGGGGGGGGGGGGG"
    ],
    [
      "  eeeee  f !ee g",
      "  c hh    ii c g",
      "  e          e j",
      "  c kl     mnc g",
      "  e        ooe g",
      "  p        q c g",
      "  r        stc j",
      "u eccwwxywwcce g",
      "  ABCDCE  BECA g",
      "  ADBB  DBDBDA g",
      "  AEB EBC C  A g",
      "  eFFFFFFFFFFe j",
      "               g",
      "I              g",
      "g              g",
      "IggggjggggjggggI"
    ],
    [
      "  eeeee  JJJee g",
      "  K LLM     NK g",
      "  e         Oe j",
      "  K          K g",
      "  e        ooe g",
      "  P        Q c g",
      "  R        s c j",
      "  eccwwSTwwcce g",
      "               g",
      "               g",
      "               g",
      " UeeeeeeeeeeeeUj",
      " ccccccccccccccg",
      "I              g",
      "g              g",
      "IggggjggggjggggI"
    ],
    [
      "  eeeee     ee  ",
      "  K        V K  ",
      "  e          e  ",
      "  K          K  ",
      "  e        ooe  ",
      "  K        s W  ",
      "  K        s W  ",
      "  eccwwwwwwcce  ",
      "                ",
      " UUU        UUU ",
      " cccccccccccccc ",
      " XXXXXXXXXXXXXX ",
      "                ",
      "Y               ",
      "                ",
      "                "
    ],
    [
      "  eeeeeeeeeeee  ",
      "  KbbbbbbbV  K  ",
      "  ebbbbbbb   e  ",
      "  Kbbbbbbb   K  ",
      "  ebbbbbbbbbbe  ",
      "  ebbbbbbbbbbe  ",
      "  ebbbbbbbbbbe  ",
      " UeeeeeeeeeeeeU ",
      " ccc        ccc ",
      " XXX        XXX ",
      "   F  F  F  F   ",
      "                ",
      "                ",
      "                ",
      "                ",
      "                "
    ],
    [
      "  eeeeeeeeeeee  ",
      "  KZ00Z1     K  ",
      "  e 22 345   e  ",
      "  K    6 57  K  ",
      "  e       888e  ",
      " UeU  59  @ UeU ",
      " cccK 59  @Kccc ",
      " XXXKKKKKKKKXXX ",
      "   F        F   ",
      "                ",
      "   F  F  F  F   ",
      "                ",
      "                ",
      "                ",
      "                ",
      "                "
    ]
  ]
}