{
  "name": "multi_megatower1_5_floor12",
  "refpalette": "c70cities:multi_megatower1_5_floor12_palette",
  "xsize": 16,
  "zsize": 16,
  "slices": [
    [
      "aaaaaaaaaaaaaaaa",
      "aaaaaaaaaaaaaaaa",
      "aaaabaaaaaabaaaa",
      "ccccdccccccdcccc",
      "efffgeeefffgeeef",
      "    h      h    ",
      "                ",
      "                ",
      "                ",
      "                ",
      "                ",
      "                ",
      "                ",
      "                ",
      "                ",
      "                "
    ],
    [
      "i ji kj kj l    ",
      "  j m ji jilnopp",
      "qqqqbqqqqqqbrrrr",
      "                ",
      "efffgeeefffgeeef",
      "    h      h    ",
      "                ",
      "                ",
      "                ",
      "                ",
      "                ",
      "                ",
      "                ",
      "                ",
      "                ",
      "                "
    ],
    [
      "           l    ",
      "    s      lt   ",
      "qqqqbqqqqqqbruuu",
      "                ",
      "efffgeeefffgeeef",
      "    h      h    ",
      "                ",
      "                ",
      "                ",
      "                ",
      "                ",
      "                ",
      "                ",
      "                ",
      "                ",
      "                "
    ],
    [
      "           l    ",
      "    s      l    ",
      "qqqqbqqqqqqbrwww",
      "                ",
      "efffgeeefffgeeef",
      "    h      h    ",
      "                ",
      "                ",
      "                ",
      "                ",
      "                ",
      "                ",
      "                ",
      "                ",
      "                ",
      "                "
    ],
    [
      "           xyAyy",
      "           xyyyy",
      "BCBCbBCBCBCbrrrr",
      "                ",
      "efffgeeefffgeeef",
      "    h      h    ",
      "                ",
      "                ",
      "                ",
      "                ",
      "                ",
      "                ",
      "                ",
      "                ",
      "                ",
      "                "
    ],
    [
      "    DyEyyEyD F I",
      "    DyyyyyyD    ",
      "JJJJbJJJJJJbJJJJ",
      "    K      K    ",
      "efffgeeefffgeeef",
      "    h      h    ",
      "                ",
      "                ",
      "                ",
      "                ",
      "                ",
      "                ",
      "                ",
      "                ",
      "                ",
      "                "
    ]
  ]
}