{
  "name": "multi_condo1_3_floor6",
  "refpalette": "c70cities:multi_condo1_3_floor6_palette",
  "xsize": 16,
  "zsize": 16,
  "slices": [
    [
      "                ",
      "      a         ",
      "bbbbbbacccccccc ",
      "ddddddaeeeeeeec ",
      "fffffffggggggec ",
      "ffffffffffffgec ",
      "ffffffffffffgec ",
      "ffffffffffffgec ",
      "ffffffffffffgec ",
      "ffffffffffffgec ",
      "ffffffffffffgec ",
      "ffffffffffffgec ",
      "ffffffffffffgec ",
      "ffffffffffffgaaa",
      "ffffffffffffgh  ",
      "iiiiijffffffgh  "
    ],
    [
      "                ",
      "      a         ",
      "bbbbbba         ",
      "      aeeeeeee  ",
      "     gggkkkgge  ",
      "  lm ng    oge  ",
      "      p    qge  ",
      "     gg   rqge  ",
      "   s tu    qge  ",
      "  sws u    oge  ",
      "   s  u    qge  ",
      "    s u   rqge  ",
      "  sw su    qge  ",
      "   s  ux   ogaaa",
      "     gggygggg   ",
      "            A   "
    ],
    [
      "                ",
      "      a         ",
      "      a         ",
      "      a         ",
      "     gggBBBgg   ",
      "     Cg    Dg   ",
      "      E     g   ",
      "     gg    Fg   ",
      "      u    Ig   ",
      "      u    Dg   ",
      "      u     g   ",
      "      u    Fg   ",
      "      u    Ig   ",
      "      u    Dgaaa",
      "     gggJgggg   ",
      "            b   "
    ],
    [
      "                ",
      "      a         ",
      "      a         ",
      "      a         ",
      "     gggBBBgg   ",
      "      g    Dg   ",
      "      K    Lg   ",
      "     gg    Lg   ",
      "      M    Lg   ",
      "      M    Dg   ",
      "      M    Lg   ",
      "      M    Lg   ",
      "      M    Lg   ",
      "      M    Dgaaa",
      "     gggNgggg   ",
      "            b   "
    ],
    [
      "                ",
      "      a         ",
      "      a         ",
      "      aOOOOOOO  ",
      "gggggggggggggO  ",
      "      g    DgO  ",
      "      g    DgO  ",
      "BBBBBgg    DgO  ",
      "           DgO  ",
      "           DgO  ",
      "           DgO  ",
      "           DgO  ",
      "           DgO  ",
      "           Dgaaa",
      "BBBBBgggggggg   ",
      "            g   "
    ],
    [
      "                ",
      "      a         ",
      "PPPPPPa         ",
      "      aQQQQQQQ  ",
      "gggggggggggggQ  ",
      "      giiijRgQ  ",
      "      giiijSgQ  ",
      "TTTTTggiiijUgQ  ",
      "iiiiiiiiiijVgQ  ",
      "iWiWiWWWiijXgQ  ",
      "iiWiiWiWiijYgQ  ",
      "iWiWiWWWiijZgQ  ",
      "iiiiiiiiiij0gQ  ",
      "iiiiiiiiiijRgaaa",
      "NNNNNgggggggg   ",
      "      111111g   "
    ]
  ]
}