{
  "name": "multi_condo1_1_ground",
  "refpalette": "c70cities:multi_condo1_1_ground_palette",
  "xsize": 16,
  "zsize": 16,
  "slices": [
    [
      "GGGabaaaaaaaaaaa",
      "GGccbaaaaaaaaaaa",
      "GGGabaaaaaaaaaaa",
      "GGGabaaaaaaaaaaa",
      "GdGaaaaaaaaaaaaa",
      "GGGaaaaaaaaaaaaa",
      "dGdaaaaaaaaaaaaa",
      "dddaaaaaaaaaaaaa",
      "Gddaaaaaaaaaaaaa",
      "dddaaaaaaaaaaaaa",
      "dGGaaaaaaaaaaaaa",
      "GGGaaaaaaaaaaaaa",
      "GGdabaaaaaaaaaaa",
      "GGGabaaaaaaaaaaa",
      "GGccbaaaaaaaaaaa",
      "GGGabaaaaaaaaaaa"
    ],
    [
      "    be        f ",
      "  ccbg     hh   ",
      "   ibj          ",
      "    b           ",
      "    k     llll  ",
      "   mk     llll  ",
      "    k     llll n",
      "    opo   llll  ",
      "    oqo   llll  ",
      "    k     llll r",
      "   sk     llll  ",
      "    k     llll  ",
      "    b           ",
      "   ibj          ",
      "  ccbe     hh   ",
      "    bg        t "
    ],
    [
      "    b           ",
      "  ccb           ",
      "   ubw          ",
      "    b           ",
      "    k           ",
      "   mk           ",
      "    k           ",
      "     x          ",
      "     y          ",
      "    k           ",
      "   sk           ",
      "    k           ",
      "    b           ",
      "   ubw          ",
      "  ccb           ",
      "    b           "
    ],
    [
      "    b           ",
      "  ccb           ",
      "   ubw          ",
      "    b           ",
      "    k           ",
      "   mk           ",
      "    k           ",
      "    k           ",
      "    k           ",
      "    k           ",
      "   sk           ",
      "    k           ",
      "    b           ",
      "   ubw          ",
      "  ccb           ",
      "    b           "
    ],
    [
      "    b           ",
      "  ccb           ",
      "    bA          ",
      "    b           ",
      "    k           ",
      "   mk           ",
      "    k           ",
      "    k           ",
      "    k           ",
      "    k           ",
      "   sk           ",
      "    k           ",
      "    b           ",
      "    bA          ",
      "  ccb           ",
      "    b           "
    ],
    [
      "    b           ",
      "  ccb           ",
      "    b           ",
      "    b           ",
      "    k           ",
      "   mk           ",
      "    k           ",
      "    k           ",
      "    k           ",
      "    k           ",
      "   sk           ",
      "    k           ",
      "    b           ",
      "    b           ",
      "  ccb           ",
      "    b           "
    ]
  ]
}