{
  "name": "multi_laboratory1_12_base3",
  "refpalette": "c70cities:multi_laboratory1_12_base3_palette",
  "xsize": 16,
  "zsize": 16,
  "slices": [
    [
      " abbbbbbbbbbbcdz",
      " abbbbbbbbbbbcdz",
      " abbbbbbbbbbbcdz",
      "eabbbbbbbbbbbcdz",
      "abbbfbbbbbbbbcdz",
      "abbbbbbbbbbbbcdz",
      "bbbbbbbbbbbbbcdz",
      "bbbbbbbbbbbbbcdz",
      "bbbbbbbbbbbbbcdz",
      "bbbbbbbbbbbbbcdz",
      "bbbbbbbbbbbbbcdz",
      "bbbbfbbbbbbbbcdz",
      "bbbbbbbbbbbbbcdz",
      "bbbbbbbbbbbbbcdz",
      "bbbbbbbbbbbbbcdz",
      "bbbbbbbbbbbbbcdz"
    ],
    [
      " g  h    i jkldz",
      " g  m     njkldz",
      " g  o      pjjdz",
      "eg  qr       cdz",
      "ge  fr      scdz",
      "gt  q      u cdz",
      "    q     p wcdz",
      "    q xxyxx wcdz",
      "    q AAAAA  cdz",
      "    q xxBxx  cdz",
      "C   q   D    cdz",
      "   efqqqqqqqqcdz",
      "    qEE E  FFcdz",
      "    o       Icdz",
      "    h      JKcdz",
      "    m       Kcdz"
    ],
    [
      " g  L      gkldz",
      " g  M      gkldz",
      " g  o       gjdz",
      "eg  q       Ncdz",
      "gO  f       scdz",
      "g   q        cdz",
      "    P        cdz",
      "    P QQyQQ  cdz",
      "    P QQ QQ  cdz",
      "    P   B R  cdz",
      "    q   S    cdz",
      "   Ofqqqqqqqqcdz",
      "    q        cdz",
      "    o        cdz",
      "    L       Tcdz",
      "    M       Ucdz"
    ],
    [
      " g  o      gkldz",
      " g  o      gkldz",
      " g  o       gjdz",
      "eg  q        cdz",
      "gO  f       scdz",
      "g   q        cdz",
      "    P       Vcdz",
      "    P QQ QQ Vcdz",
      "    P QQ QQ  cdz",
      "    P        cdz",
      "    q        cdz",
      "   Ofqqqqqqqqcdz",
      "    q        cdz",
      "    o        cdz",
      "    o        cdz",
      "    o        cdz"
    ],
    [
      " g  q      gWldz",
      " g  q      gWldz",
      " g  q       gjdz",
      "eg  q       Ncdz",
      "g   f       Xcdz",
      "g   q       Ncdz",
      "    q       Xcdz",
      "    q       Xcdz",
      "    q        cdz",
      "    q        cdz",
      "    q  Y  Z  cdz",
      "    fqqqqqqqqcdz",
      "    q        cdz",
      "    q       0cdz",
      "    q        cdz",
      "    q        cdz"
    ],
    [
      " g112334334j5ldz",
      " g112334336j5ldz",
      " g1123343343jjdz",
      "eg11233333333cdz",
      "g111f33333333cdz",
      "g111233433433cdz",
      "1111233433633cdz",
      "1111233433433cdz",
      "1111233433433cdz",
      "1111233333333cdz",
      "111127777777!cdz",
      "1111fqqqqqqqqcdz",
      "1111273333337cdz",
      "1141273333337cdz",
      "1141273433437cdz",
      "1141273833437cdz"
    ]
  ]
}