{
  "name": "multi_megatower1_7_floor2",
  "refpalette": "c70cities:multi_megatower1_7_floor2_palette",
  "xsize": 16,
  "zsize": 16,
  "slices": [
    [
      "aaab            ",
      "aaac            ",
      "aaac            ",
      "aaac            ",
      "aadef           ",
      "aaab            ",
      "aaab            ",
      "aaab            ",
      "aaac            ",
      "aaac            ",
      "aaac            ",
      "aadef           ",
      "aaab            ",
      "aaab            ",
      "aaab            ",
      "aaac            "
    ],
    [
      "ghib            ",
      "jkic            ",
      "lkic            ",
      "lkic            ",
      "lkdef           ",
      "lkib            ",
      "mnib            ",
      "opib            ",
      "qric            ",
      "mnic            ",
      "lkic            ",
      "lkdef           ",
      "lkib            ",
      "lkib            ",
      " kib            ",
      "hhic            "
    ],
    [
      "stib            ",
      "uuic            ",
      "  ic            ",
      "  ic            ",
      "  def           ",
      "  ib            ",
      "  ib            ",
      "wxib            ",
      "yAic            ",
      "  ic            ",
      "  ic            ",
      "  def           ",
      "  ib            ",
      "  ib            ",
      "  ib            ",
      "  ic            "
    ],
    [
      "BCDb            ",
      " CDc            ",
      " CDc            ",
      " CDc            ",
      "ECdef           ",
      "ECDb            ",
      "ECDb            ",
      "ECDb            ",
      "ECDc            ",
      "ECDc            ",
      "ECDc            ",
      "ECdef           ",
      "ECDb            ",
      "ECDb            ",
      "ECDb            ",
      "ECDc            "
    ],
    [
      "FC b            ",
      " C c            ",
      " I c            ",
      " C c            ",
      "JCdef           ",
      "KC b            ",
      "KI b            ",
      "KC b            ",
      "KC c            ",
      "KI c            ",
      "KC c            ",
      "KCdef           ",
      "KC b            ",
      "KI b            ",
      "KC b            ",
      "KC c            "
    ],
    [
      "CC              ",
      "CC              ",
      "CC              ",
      "JC              ",
      "KCd             ",
      "KC              ",
      "KC              ",
      "KC              ",
      "KC              ",
      "KC              ",
      "KC              ",
      "KCd             ",
      "KC              ",
      "KC              ",
      "KC              ",
      "KC              "
    ]
  ]
}