{
  "name": "multi_condo1_5_floor5",
  "refpalette": "c70cities:multi_condo1_5_floor5_palette",
  "xsize": 16,
  "zsize": 16,
  "slices": [
    [
      "aaaaabcddeeefg  ",
      "cccccccddeeefg  ",
      "deeeddddddddfhhh",
      "deeeddddddddfij ",
      "deeeddddddddfij ",
      "ddddddddddddfij ",
      "ddddddddddddfij ",
      "ddddddddddddfij ",
      "ddddddddddddfij ",
      "ddddddddddddfij ",
      "ddddddddddddfij ",
      "ffkkkffffffffij ",
      "fggggghiiiiiiij ",
      "llllllhjjjjjjjj ",
      "      h         ",
      "                "
    ],
    [
      "      m  n  o   ",
      "ffffpff qrsrf   ",
      "rt r ur wr xfhhh",
      "ry A ur Br Cfi  ",
      "rrDr qr Er Ffi  ",
      "rF r wr  n Ifi  ",
      "rI A Br Jrrrfi  ",
      "rrrr Er KLMMfi  ",
      "r!MM Jr KL  fi  ",
      "rN  KLr     fi  ",
      "rO  KLr   PQfi  ",
      "ffR RfffSSSffi  ",
      "f     hiiiiiii  ",
      "llllllh         ",
      "      h         ",
      "                "
    ],
    [
      "      T  U Vl   ",
      "ffffWffXYrZrf   ",
      "r 0r  r  r !fhhh",
      "r  1  r 2r  f   ",
      "rr3r 4r 5r  f   ",
      "r6 r  r  U  f   ",
      "r7 1 2r 8rrrf   ",
      "rrrr 5r   9@f   ",
      "r  # 8r  $  f   ",
      "r    $r     f   ",
      "r    %r     f   ",
      "ffR RfffRRRff   ",
      "f     h         ",
      "      h         ",
      "      h         ",
      "                "
    ],
    [
      "      ^  r &l   ",
      "ffff*ff  rrrf   ",
      "r (r  r  r  fhhh",
      "r  r  r  r  f   ",
      "rrrr  r  r  f   ",
      "r  r  r  r  f   ",
      "r) r  r  rrrf   ",
      "rrrr  r     f   ",
      "r     r     f   ",
      "r     r     f   ",
      "r     r     f   ",
      "ffRRRfffRRRff   ",
      "f     h         ",
      "      h         ",
      "      h         ",
      "                "
    ],
    [
      "      f  r  f   ",
      "fffffff  rrrf   ",
      "r  r  r  r  fhhh",
      "r  r  r  r  f+  ",
      "rrrr  r  r  f+  ",
      "r  r  r  r  f+  ",
      "r  r  r  rrrf+  ",
      "rrrr  r     f+  ",
      "r     r     f+  ",
      "r     r     f+  ",
      "r     r     f+  ",
      "fffffffffffff+  ",
      "f     h+++++++  ",
      "      h         ",
      "      h         ",
      "                "
    ],
    [
      "      f-----f   ",
      "fffffff-----f   ",
      "------------fhhh",
      "------------f[  ",
      "------------f[  ",
      "------------f[  ",
      "------------f[  ",
      "------------f[  ",
      "------------f[  ",
      "------------f[  ",
      "------------f[  ",
      "fffffffffffff[  ",
      "f     h[[[[[[[  ",
      "]]]]]]h         ",
      "      h         ",
      "                "
    ]
  ]
}