{
  "name": "multi_warehouse_0_ground",
  "refpalette": "c70cities:multi_warehouse_0_ground_palette",
  "xsize": 16,
  "zsize": 16,
  "slices": [
    [
      "zzzzzzzzzzzzzzzz",
      "azaabbbbbbbbbbbz",
      "aaaabbccccccccbz",
      "aaaabbccccccccbz",
      "zazadbccccccccbz",
      "zaaadbccccccccbz",
      "zzaabbccccccccbz",
      "zaaabbccccccccbz",
      "zaaabbccccccccbz",
      "zzaabbccccccccbz",
      "zzaadbccccccccbz",
      "zaaabbccccccccbz",
      "zaaadbccccccccbz",
      "zaaabbccccccccbz",
      "zaaabbccccccccbz",
      "zaaabbccccccccbz"
    ],
    [
      " e e   ff f f ff",
      "     ghggghgggg ",
      "     ijklkkkkkg ",
      "     i jjmknkogf",
      "     ij jnmkong ",
      "     h    okovg ",
      "f    i  v vovvh ",
      "f    i  mvlvvvg ",
      "f    i   v ovog ",
      "     g    v vvgf",
      "     i      pqg ",
      "f    i      r!gf",
      "     i       rgf",
      "     g   s    g ",
      "              gf",
      "f         tuwug "
    ],
    [
      "                ",
      "     ggggxxghgg ",
      "     i   jlkokh ",
      "     i   j  oog ",
      "     i       kg ",
      "     g      lkg ",
      "     i      kvg ",
      "     i      jvg ",
      "     i       kg ",
      "     g       lg ",
      "     i        g ",
      "     i       rg ",
      "     i        g ",
      "     g        h ",
      "              g ",
      "             lg "
    ],
    [
      "                ",
      "     ggghgggggg ",
      "     i     jokg ",
      "     i      lkg ",
      "     i       jg ",
      "     g       kg ",
      "     i      j g ",
      "     i       og ",
      "     i        g ",
      "     g        g ",
      "     i        g ",
      "     i        g ",
      "     i        g ",
      "     g        g ",
      "     i        g ",
      "     i        g "
    ],
    [
      "                ",
      "     gggggggggg ",
      "    ygAl    jog ",
      "    ygA      kg ",
      "    ygA      lg ",
      "    yg  B    jg ",
      "    ygA       g ",
      "    ygA       g ",
      "    ygA       g ",
      "    yCl D     g ",
      "    ygA       g ",
      "    ygA       g ",
      "    ygA       g ",
      "    yg  D     g ",
      "    yhA       g ",
      "    ygA       g "
    ],
    [
      "                ",
      "     gggggggggg ",
      "     gEEEEEEEEg ",
      "     gEEEEEEEEg ",
      "     hEEEEEEEEg ",
      "     gEEbEEEEEg ",
      "     gEEEEEEEEg ",
      "     gEEEEEEEEg ",
      "     gEEEEEEEEg ",
      "     hEEbEEEEEg ",
      "     gEEEEEEEEg ",
      "     gEEEEEEEEg ",
      "     gEEEEEEEEg ",
      "     gEEbEEEEEg ",
      "     gEEEEEEEEg ",
      "     gEEEEEEEEg "
    ]
  ]
}