{
  "name": "multi_factory_0_ground",
  "refpalette": "c70cities:multi_factory_0_ground_palette",
  "xsize": 16,
  "zsize": 16,
  "slices": [
    [
      "zaazzzzzzzzzzzzz",
      "aaazzzzzzzzzzzzz",
      "aazbbbbbbbbbbbzz",
      "aaabbbbbbbbbbbzz",
      "aaabbbbbbbbbbbzz",
      "zaabbbbbbbbbbbzz",
      "zaabbbbbbbbbbbzz",
      "aaabbbbbbbbbbbzz",
      "zaabbbbbbbbbbbzz",
      "aaabbbbbbbbbbbzz",
      "aaabbbbbbbbbbbzz",
      "aaabbbbbbbbbbbzz",
      "zaabbbbbbbbbbbzz",
      "aaabbbbbbbbbbbzz",
      "zaabbbbbbbbbbbzz",
      "aaabbbbbbbbbbbzz"
    ],
    [
      "                ",
      "                ",
      "   ccccccccccc  ",
      "   cdeffdgh dc  ",
      "   ij    k  lc  ",
      "   c     mnnnc  ",
      "   co    p  lc  ",
      "   coq   gr  c  ",
      "   co    ssssc  ",
      "   co t     uc  ",
      "   c wxxye j c  ",
      "   cmmmmmmmAmc  ",
      "   cBBddC C dc  ",
      "            dc  ",
      "           DEc  ",
      "     ddddB  dc  "
    ],
    [
      "                ",
      "                ",
      "   ccccccccccc  ",
      "   cd ffdg  dc  ",
      "   F     I  Jc  ",
      "   c     mnnnc  ",
      "   KL    M  Jc  ",
      "   KN    g   c  ",
      "   KN    ssssc  ",
      "   K        uc  ",
      "   c   O     c  ",
      "   cmKKKKmmPmc  ",
      "   cd       ec  ",
      "            Qc  ",
      "           RSc  ",
      "     ETTTB  Qc  "
    ],
    [
      "                ",
      "                ",
      "   ccUVWcUVWcc  ",
      "   cd   dg  dc  ",
      "   K     g   c  ",
      "   c     mnnnc  ",
      "   K     g   c  ",
      "   K     g   c  ",
      "   K     ssssc  ",
      "   K        uc  ",
      "   c         c  ",
      "   cmKKKKmmmmc  ",
      "   c         c  ",
      "   X         c  ",
      "   X        Yc  ",
      "   X  ZZZ    c  "
    ],
    [
      "                ",
      "                ",
      "   ccccccccccc  ",
      "   cd   dg  dc  ",
      "  0c     g   c  ",
      "  0c     mnnnc  ",
      "  0c     g   c  ",
      "  0c     g   c  ",
      "  0c     ssssc  ",
      "  0c        uc  ",
      "   c         c  ",
      "   cmmmmmmmmmc  ",
      "   c         c  ",
      "  0c1        c  ",
      "  0c1       2c  ",
      "  0c1        c  "
    ],
    [
      "                ",
      "                ",
      "   ccccccccccc  ",
      "   cd   dbbbdc  ",
      "   c    3bbbbc  ",
      "   c    3bbbbc  ",
      "   c    3bbbbc  ",
      "   c    3bbbbc  ",
      "   c    3bbbbc  ",
      "   c    3bbbuc  ",
      "   c    3bbbbc  ",
      "   cmmmmmmmmmc  ",
      "   c        Cc  ",
      "   c         c  ",
      "   c         c  ",
      "   c         c  "
    ]
  ]
}