{
  "name": "multi_condo1_4_floor1",
  "refpalette": "c70cities:multi_condo1_4_floor1_palette",
  "xsize": 16,
  "zsize": 16,
  "slices": [
    [
      "aaaaabccccccde  ",
      "fffgabhiiiiiijj ",
      "   kabhlllllie  ",
      "   kabhlllllie  ",
      "   kabhlllllie  ",
      "   kabhmllllijj ",
      "   kabhiiiiiie  ",
      "   kabh     he  ",
      "   kabh     he  ",
      "   kabh     ie  ",
      "   kabn     ijj ",
      "   kaboiiiiiie  ",
      "   kabhhk   ie  ",
      "   kabhh    ie  ",
      "pppqabhiiiiiijj ",
      "aaaaabccccccde  "
    ],
    [
      "            r   ",
      "ssss  iiiiiiijj ",
      "   s  t    ui   ",
      "   s  i     w   ",
      "   s  i xx  i   ",
      "   s  imyx  ijj ",
      "   s  iiiiiii   ",
      "   s  i     A   ",
      "   s  B     A   ",
      "   s  C     i   ",
      "   s  i     ijj ",
      "   s  iiiiiii   ",
      "   s  i     w   ",
      "   s  D     i   ",
      "ssss  iiiiiiijj ",
      "            r   "
    ],
    [
      "            r   ",
      "      iiiiiiijj ",
      "      E    ui   ",
      "      iF    I   ",
      "      i   J i   ",
      "      imK L ijj ",
      "      iiiiiii   ",
      "      i     A   ",
      "      M     A   ",
      "      N     i   ",
      "      i     ijj ",
      "      iiiiiii   ",
      "      i     I   ",
      "      O     i   ",
      "      iiiiiiijj ",
      "            r   "
    ],
    [
      "                ",
      "      iiiiiiijj ",
      "      P    ui   ",
      "      i     I   ",
      "      i     i   ",
      "      imKx  ijj ",
      "      iiiiiii   ",
      "      i     A   ",
      "      P     A   ",
      "      P     i   ",
      "      i     ijj ",
      "      iiiiiii   ",
      "      i     I   ",
      "      P     i   ",
      "      iiiiiiijj ",
      "                "
    ],
    [
      "                ",
      "      iiiiiiijj ",
      "      i    ui   ",
      "      i     i   ",
      "      i     i   ",
      "      imK   ijj ",
      "      iiiiiii   ",
      "      i     A   ",
      "      i     A   ",
      "      i     i   ",
      "      i     ijj ",
      "      iiiiiii   ",
      "      i     i   ",
      "      i     i   ",
      "      iiiiiiijj ",
      "                "
    ],
    [
      "                ",
      "     Jiiiiiiijj ",
      "     QillllRi   ",
      "     Qillllli   ",
      "     Qillllli   ",
      "     QimSlllijj ",
      "     Qillllli   ",
      "     Qillllli   ",
      "     Qil llli   ",
      "     Qillllli   ",
      "     Qilllllijj ",
      "     Qillllli   ",
      "     Qillllli   ",
      "     Qillllli   ",
      "     xiiiiiiijj ",
      "                "
    ]
  ]
}