{
  "name": "multi_megatower1_8_base1",
  "refpalette": "c70cities:multi_megatower1_8_base1_palette",
  "xsize": 16,
  "zsize": 16,
  "slices": [
    [
      "vHHHHHHHHHHvvaav",
      "HHHHHHHHHHHvvaav",
      "HHbHHHHHHbHvvaav",
      "HHHHHHHHHHHvvaav",
      "HHHHHHHHHHHvvaav",
      "HHHHHHHHHHHvvaav",
      "HHHHHHHHHHHvvaav",
      "HHHHHHHHHHHvvaav",
      "HHHHHHHHHHHvvaav",
      "HHbHHHHHHHHvvaav",
      "HHHHHHHHHHHvvaav",
      "vvvvvvvvvvvvvaav",
      "vvvvvvvvvvvvvaav",
      "aaaaaaaaaaaaaaav",
      "aaaaaaaaaaaaaaav",
      "vvvvvvvvvvvvvvvv"
    ],
    [
      "cd e    f ghvaav",
      "fg      d ehvaav",
      "  bi    jb hvaav",
      "dek     f ghvaav",
      "        d ehvaav",
      "        f ghvaav",
      "        d ehvaav",
      "        lllhvaav",
      "fgmfgfgn   hvaav",
      "  b    n b hvaav",
      "de deden   hvaav",
      "hhhhhhhhhhhhvaav",
      "vvvvvvvvvvvvvaav",
      "aaaaaaaaaaaaaaav",
      "aaaaaaaaaaaaaaav",
      "vvvvvvvvvvvvvvvv"
    ],
    [
      "            vaav",
      "            vaav",
      "  b      b  vaav",
      "            vaav",
      "            vaav",
      "            vaav",
      "            vaav",
      "            vaav",
      "            vaav",
      "  b      b  vaav",
      "            vaav",
      "            vaav",
      "vvvvvvvvvvvvvaav",
      "aaaaaaaaaaaaaaav",
      "aaaaaaaaaaaaaaav",
      "vvvvvvvvvvvvvvvv"
    ],
    [
      "            vaav",
      "            vaav",
      "  b      b  vaav",
      "            vaav",
      "            vaav",
      "            vaav",
      "            vaav",
      "            vaav",
      "            vaav",
      "  b      b  vaav",
      "            vaav",
      "            vaav",
      "vvvvvvvvvvvvvaav",
      "aaaaaaaaaaaaaaav",
      "aaaaaaaaaaaaaaav",
      "vvvvvvvvvvvvvvvv"
    ],
    [
      "            vaav",
      "            vaav",
      "  b      b  vaav",
      "            vaav",
      "            vaav",
      "            vaav",
      "            vaav",
      "            vaav",
      "            vaav",
      "  b      b  vaav",
      "            vaav",
      "            vaav",
      "vvvvvvvvvvvvvaav",
      "aaaaaaaaaaaaaaav",
      "aaaaaaaaaaaaaaav",
      "vvvvvvvvvvvvvvvv"
    ],
    [
      " oboooooobovvaav",
      "ooboooooobovvaav",
      "bbbbbbbbbbovvaav",
      "ooboooooobovvaav",
      "ooboooooobovvaav",
      "ooboooooobovvaav",
      "ooboooooobovvaav",
      "ooboooooobovvaav",
      "ooboooooobovvaav",
      "bbbbbbbbbbovvaav",
      "ooooooooooovvaav",
      "vvvvvvvvvvvvvaav",
      "vvvvvvvvvvvvvaav",
      "aaaaaaaaaaaaaaav",
      "aaaaaaaaaaaaaaav",
      "vvvvvvvvvvvvvvvv"
    ]
  ]
}