{
  "name": "multi_condo1_0_floor6",
  "refpalette": "c70cities:multi_condo1_0_floor6_palette",
  "xsize": 16,
  "zsize": 16,
  "slices": [
    [
      "                ",
      "          aaaaaa",
      "  bbbbbbbbaaaaaa",
      "  bcccccccaaaaaa",
      "  bcddddddeeeeee",
      "  bcdeeeeeeeeeee",
      "  bcdeeeeeeeeeee",
      "  bcdeeeeeeeeeee",
      "  bcdeeeeeeeeeee",
      "  bcdeeeeeeeeeee",
      "  bcdeeeeeeeeeee",
      "  bcdeeeeeeeeeee",
      "  bcdeeeeeeeeeee",
      " aaadeeeeeeeeeee",
      "   fdeeeeeeeeeee",
      "   fdeeeeeeghhhh"
    ],
    [
      "                ",
      "          a     ",
      "          aiiiii",
      "   ccccccca     ",
      "   cddjjjddd    ",
      "   cdk   ldm no ",
      "   cdp    q     ",
      "   cdp r  dd    ",
      "   cdp    st uu ",
      "   cdk    swxyyA",
      "   cdp    s xyyA",
      "   cdp r  s xyyA",
      "   cdp    swxyyA",
      " aaadk    s  BB ",
      "    ddddCddd    ",
      "    D           "
    ],
    [
      "                ",
      "          a     ",
      "          a     ",
      "          a     ",
      "    ddEEEddd    ",
      "    dF    dI    ",
      "    dJ    K     ",
      "    dL    dd    ",
      "    d     s     ",
      "    dF    s     ",
      "    dJ    s     ",
      "    dL    s     ",
      "    d     s     ",
      " aaadF    s     ",
      "    ddddMddd    ",
      "    i           "
    ],
    [
      "                ",
      "          a     ",
      "          a     ",
      "          a     ",
      "    ddEEEddd    ",
      "    dF    d     ",
      "    dN    O     ",
      "    dN    dd    ",
      "    dN    P     ",
      "    dF    P     ",
      "    dN    P     ",
      "    dN    P     ",
      "    dN    P     ",
      " aaadF    P     ",
      "    ddddQddd    ",
      "    i           "
    ],
    [
      "                ",
      "          a     ",
      "          a     ",
      "   RRRRRRRaSSSSS",
      "   Rdddddddddddd",
      "   RdF    d     ",
      "   RdF    d     ",
      "   RdF    ddEEEE",
      "   RdF          ",
      "   RdF          ",
      "   RdF          ",
      "   RdF          ",
      "   RdF          ",
      " aaadF          ",
      "    ddddddddEEEE",
      "    d           "
    ],
    [
      "                ",
      "          a     ",
      "          aTTTTT",
      "   UUUUUUUa     ",
      "   Udddddddddddd",
      "   UdVghhhd     ",
      "   UdWghhhd     ",
      "   UdXghhhddYYYY",
      "   UdZghhhhhhhhh",
      "   Ud0ghh111hh1h",
      "   Ud2ghh1h1h1h1",
      "   Ud3ghhh1hhh1h",
      "   Ud4ghhhhhhhhh",
      " aaadVghhhhhhhhh",
      "    ddddddddQQQQ",
      "    d555555     "
    ]
  ]
}