{
  "name": "multi_condo1_4_floor2",
  "refpalette": "c70cities:multi_condo1_4_floor2_palette",
  "xsize": 16,
  "zsize": 16,
  "slices": [
    [
      "aaaaabcdddddef  ",
      "ggghabceeeeeeii ",
      "   jabckkkkkef  ",
      "   jabckkkkkef  ",
      "   jabckkkkkef  ",
      "   jabckkkkkeii ",
      "   jabceeeeeef  ",
      "   jabc     cf  ",
      "   jabc     cf  ",
      "   jabc     ef  ",
      "   jabl     eii ",
      "   jabmeeeeeef  ",
      "   jabccj   ef  ",
      "   jabccn   ef  ",
      "ooopabceeeeeeii ",
      "aaaaabcdddddef  "
    ],
    [
      "      eqrs te   ",
      "uuuu  eeeeeeeii ",
      "   u  w     e   ",
      "   u  e     x   ",
      "   u  e  yA e   ",
      "   u  e BCC eii ",
      "   u  eeeeeee   ",
      "   u  e     D   ",
      "   u  E     D   ",
      "   u  F     e   ",
      "   u  e     eii ",
      "   u  eeeeeee   ",
      "   u  e     x   ",
      "   u  I Jn  e   ",
      "uuuu  eeeeeeeii ",
      "      eKLM Ne   "
    ],
    [
      "      e   O e   ",
      "      eeeeeeeii ",
      "      P     e   ",
      "      eQ    R   ",
      "      e  ST e   ",
      "      eUUCC eii ",
      "      eeeeeee   ",
      "      e     D   ",
      "      V     D   ",
      "      W     e   ",
      "      e     eii ",
      "      eeeeeee   ",
      "      e     R   ",
      "      X  Jn e   ",
      "      eeeeeeeii ",
      "      e   Y e   "
    ],
    [
      "      e   Z e   ",
      "      eeeeeeeii ",
      "      0     e   ",
      "      e     R   ",
      "      e     e   ",
      "      eU 11 eii ",
      "      eeeeeee   ",
      "      e     D   ",
      "      0     D   ",
      "      0     e   ",
      "      e     eii ",
      "      eeeeeee   ",
      "      e   0nR   ",
      "      0   Jce   ",
      "      eeeeeeeii ",
      "      e   2 e   "
    ],
    [
      "      e     e   ",
      "      eeeeeeeii ",
      "      e     e   ",
      "      e     e   ",
      "      e     e   ",
      "      eU    eii ",
      "      eeeeeee   ",
      "      e     D   ",
      "      e     D   ",
      "      e     e   ",
      "      e     eii ",
      "      eeeeeee   ",
      "      e  0j e   ",
      "      e     e   ",
      "      eeeeeeeii ",
      "      e     e   "
    ],
    [
      "      ekkkkke   ",
      "      eeeeeeeii ",
      "      eU    e   ",
      "      eU    e   ",
      "      eU    e   ",
      "      eUUUUUeii ",
      "      eeeeeee   ",
      "      e     D   ",
      "      e     D   ",
      "      e     e   ",
      "      e     eii ",
      "      eeeeeee   ",
      "      e 0j  e   ",
      "      e     e   ",
      "      eeeeeeeii ",
      "      ekkkkke   "
    ]
  ]
}