{
  "name": "multi_militarybase_0_base3",
  "refpalette": "c70cities:multi_militarybase_0_base3_palette",
  "xsize": 16,
  "zsize": 16,
  "slices": [
    [
      "vvvvvvvvvvvvvvvv",
      "vaaaavaaavaaav  ",
      "vaaaabaaabaaab  ",
      "vaaaabaaabaaab  ",
      "vaaaabaaabaaab  ",
      "vvbbbvbbbvbbbv  ",
      "vaaaaaaaabcccb  ",
      "vaaaaaaaabcccb  ",
      "vaaaaaaaabcccb  ",
      "vaaaaaaaabccdv  ",
      "vaaaaaaaabcccb  ",
      "vaaaaaaaabcccb  ",
      "vaaaaaaaabcccb  ",
      "vvaaaaaaabbbbv  ",
      "vaaaaaaaabcccb  ",
      "vaaaaaaaabcccb  "
    ],
    [
      "vvvvvvvvvvvvvvvv",
      "ve efvgggvhiiv  ",
      "vjk  l m l   n  ",
      "vjk      o   n  ",
      "vjk      l   n  ",
      "vvpppvpppv   v  ",
      "v            n  ",
      "v            n  ",
      "v            n  ",
      "vq  r r     dv  ",
      "vq  sss      n  ",
      "vq tuwqx     n  ",
      "vq  uwq      n  ",
      "vv tuwqx     v  ",
      "vy  uwq      n  ",
      "vy tuwqx     n  "
    ],
    [
      "vvvvvvvvvvvvvvvv",
      "vA  evBC!viiiv  ",
      "vD   l   l      ",
      "vE       F      ",
      "vD       l      ",
      "vvpppvpppv   v  ",
      "v               ",
      "v               ",
      "v               ",
      "v           dv  ",
      "vI              ",
      "vJ  KLM         ",
      "v    L          ",
      "vv   LK      v  ",
      "v    L          ",
      "vN  ML          "
    ],
    [
      "vvvvvvvvvvvvvvvv",
      "v    v   viOiv  ",
      "v    l   l      ",
      "v        l      ",
      "v        l      ",
      "vvpppvpppv   v  ",
      "v               ",
      "v               ",
      "v               ",
      "v           dv  ",
      "v               ",
      "v               ",
      "v               ",
      "vv           v  ",
      "v               ",
      "v               "
    ],
    [
      "vvvvvvvvvvvvvvvv",
      "v    v   v   v  ",
      "v    l   l   p  ",
      "v    l   l   p  ",
      "v    l   l   p  ",
      "vvpppvpppvnnnv  ",
      "v        n   p  ",
      "v        n   p  ",
      "v        n   p  ",
      "v        n  dv  ",
      "v        n   p  ",
      "v        n   p  ",
      "v        n   p  ",
      "vv       n   vpp",
      "v        n   p  ",
      "v        n   p  "
    ],
    [
      "vvvvvvvvvvvvvvvv",
      "vPPPPvPPPvPPPvPP",
      "vPQQQbQQQbQQQbQQ",
      "vPQQQbQQQbQQQbQR",
      "vPQQQbQQQbQQQbQQ",
      "vvbbbvbbbvbbbvQQ",
      "vPQQQQQQQbQQQbQQ",
      "vPQQQQQQQbQQQbQR",
      "vPQQQQQQQbQQQbQQ",
      "vPQQQQQQQbQQdvQQ",
      "vPQQQQQQQbQQQbQQ",
      "vPQQQQQQQbQQQbQR",
      "vPQQQQQQQbQQQbQQ",
      "vvQQQQQQQbQQQvSS",
      "vPQQQQQQQbQQQS  ",
      "vPQQQQQQQbQQQS  "
    ]
  ]
}