{
  "name": "multi_laboratory1_0_base4",
  "refpalette": "c70cities:multi_laboratory1_0_base4_palette",
  "xsize": 16,
  "zsize": 16,
  "slices": [
    [
      "zzzzzzzzzzzzzzzz",
      "zaaaaaaaaaaaaaaa",
      "zabbbbbbbbbbcccc",
      "zabddd!dddde    ",
      "zabdddddddde    ",
      "zabddddddddeeeee",
      "zabddddddddfffff",
      "zabddddddddfffff",
      "zabffffffffeffff",
      "zabddddddddfffff",
      "zabddddddddfffff",
      "zabddddddddfffff",
      "zabddddddddfffff",
      "zabddddddddfffff",
      "zabddddddddfffff",
      "zabffffffffeffff"
    ],
    [
      "zzzzzzzzzzzzzzzz",
      "zaaaaaaaaaaaaaaa",
      "zabbbbbbbbbbcccc",
      "zabghghghghi    ",
      "zabg g g g i    ",
      "zabjkjljkjkiiiii",
      "zab        m   n",
      "zabooppppooi   q",
      "zabiiiiiiiie   r",
      "zabssttttssi   u",
      "zab        m   u",
      "zab        i   u",
      "zabwxwxyxwxi   u",
      "zab A A A Ai   r",
      "zabBABABABAi    ",
      "zabiiiiiiiie    "
    ],
    [
      "zzzzzzzzzzzzzzzz",
      "zaaaaaaaaaaaaaaa",
      "zabbbbbbbbbbcccc",
      "zabg g g g i    ",
      "zabg g g g i    ",
      "zabjCjDjCjCiiiii",
      "zab        E   F",
      "zabFIIII IFi    ",
      "zabiiiiiiiie   n",
      "zabFJJ J JKi   L",
      "zab        E    ",
      "zab        i   M",
      "zabNxNxOxNxi   P",
      "zab A A A Ai   n",
      "zab A A A Ai    ",
      "zabiiiiiiiie    "
    ],
    [
      "zzzzzzzzzzzzzzzz",
      "zaaaaaaaaaaaaaaa",
      "zabbbbbbbbbbcccc",
      "zabg g g g i    ",
      "zabg g g g i    ",
      "zabjjjjjjjjiiiii",
      "zab        i   F",
      "zab III II i    ",
      "zabiii!iiiie   F",
      "zab JJJJJ  i    ",
      "zab        i    ",
      "zab        i   Q",
      "zabxxxxxxxxi   !",
      "zab A A A Ai   F",
      "zab A A A Ai    ",
      "zabiiiiiiiie    "
    ],
    [
      "zzzzzzzzzzzzzzzz",
      "zaaaaaaaaaaaaaaa",
      "zabbbbbbbbbbcccc",
      "zabRSRSRSRSi    ",
      "zabRRRRRRRRi    ",
      "zabRRRRRRRRiiiii",
      "zabRRRRRRRRi    ",
      "zabRRRRRRRRi    ",
      "zabiiiiiiiie    ",
      "zabRRRRRRRRi    ",
      "zabRRRRRRRRi    ",
      "zabRRRRRRRRi    ",
      "zabRRRRRRRRi    ",
      "zabRRRRRRRRi    ",
      "zabSRSRSRSRi    ",
      "zabiiiiiiiie    "
    ],
    [
      "zzzzzzzzzzzzzzzz",
      "zaaaaaaaaaaaaaaa",
      "zabbbbbbbbbbcccc",
      "zab T T T Ti    ",
      "zab T T T Ti    ",
      "zab T T T Tiiiii",
      "zab T T T TiUUUU",
      "zab TTTTTTTiUUUU",
      "zabiiiiiiiieUUUU",
      "zabTTTTTTTTiUUUU",
      "zabT T T T iUUUU",
      "zabTVTVTVTViUUUU",
      "zabTWTVTVTViUUUU",
      "zabTVTVTVTViUUUU",
      "zabTVTVTVTViUUUU",
      "zabiiiiiiiieXXXX"
    ]
  ]
}