{
  "name": "multi_megatower1_4_floor6",
  "refpalette": "c70cities:multi_megatower1_4_floor6_palette",
  "xsize": 16,
  "zsize": 16,
  "slices": [
    [
      "a   b           ",
      "a   bcc         ",
      "a   bdd         ",
      "efggbdd         ",
      "bbbbhbbb   h    ",
      "bbbbbbbb        ",
      "bbbbbbbb        ",
      "bbbbbbbb        ",
      "bbbbbbbb        ",
      "bbbbbbbb        ",
      "bbbbbbbb   i    ",
      "bbbbhbbb  jhi j ",
      "bbbbbbbb   j    ",
      "bbbbbbbb  kk    ",
      "bbbbbbbb        ",
      "bbbbbbbb        "
    ],
    [
      "a   l           ",
      "a   l           ",
      "a   l           ",
      "agmml           ",
      "nopqh      h    ",
      "       r        ",
      "       s        ",
      " t ut  s        ",
      " wx t  s        ",
      "xt  t  s        ",
      " u x   r        ",
      "    h      h    ",
      "  x x  r        ",
      " t uy  s        ",
      " !  t  s        ",
      " wx t  s        "
    ],
    [
      "a   l           ",
      "a   l           ",
      "a   l           ",
      "ag  l           ",
      "n ABh  !   h    ",
      "       C        ",
      "                ",
      " t  t           ",
      " t              ",
      "    D           ",
      "       C        ",
      "    h  E   h    ",
      "       C        ",
      " D              ",
      " t  t           ",
      "    D           "
    ],
    [
      "a   l           ",
      "a   l           ",
      "a   l           ",
      "agggl           ",
      "nF  h  I   h    ",
      "       C        ",
      "                ",
      "                ",
      "                ",
      "                ",
      "       C        ",
      "    h  I   h    ",
      "       C        ",
      "                ",
      "                ",
      "                "
    ],
    [
      "a   l           ",
      "a   l           ",
      "a   l           ",
      "agggl           ",
      "nnnnh  I   h    ",
      "                ",
      "                ",
      "                ",
      "                ",
      "                ",
      "                ",
      "    h  I   h    ",
      "                ",
      "                ",
      "                ",
      "                "
    ],
    [
      "J   JKKK   J    ",
      "J   JKKK   J    ",
      "J   JKLK   J    ",
      "JgMMJKKK   J    ",
      "NNNNhNNNNNNhNNNN",
      "KKKKJKKK   J    ",
      "KKLKJKLK   J    ",
      "KKKKJKKK   J    ",
      "KKKKJKKK   J    ",
      "KKLKJKLK   J    ",
      "KKKKJKKK   J    ",
      "NNNNhNNNNNNhNNNN",
      "    JKKK   J    ",
      "    JKLK   J    ",
      "    JKKK   J    ",
      "    JKKK   J    "
    ]
  ]
}