{
  "name": "multi_laboratory1_2_base6",
  "refpalette": "c70cities:multi_laboratory1_2_base6_palette",
  "xsize": 16,
  "zsize": 16,
  "slices": [
    [
      "zabcccccccccccd ",
      "zabcccccccccccd ",
      "zabcccccccccccde",
      "zabcccccccccccdf",
      "zabccccccccgcccd",
      "zabccccccccccccd",
      "zabccccccccccccc",
      "zabccccccccccccc",
      "zabccccccccccccc",
      "zabccccccccccccc",
      "zabccccccccccccc",
      "zabccccccccgcccc",
      "zabccccccccccccc",
      "zabccccccccccccc",
      "zabccccccccccccc",
      "zabccccccccccccc"
    ],
    [
      "zabh      ij  k ",
      "zabh       j  k ",
      "zab   l    jm k ",
      "zannnn o   h  kf",
      "zabpqn   r g   k",
      "zannnnso   t   k",
      "zab   u   wj    ",
      "zabh       j    ",
      "zabh      ij    ",
      "zab        j    ",
      "zannnn     xw   ",
      "zabpyn     g    ",
      "zannnn       AAA",
      "zab             ",
      "zabh         B  ",
      "zabh            "
    ],
    [
      "zabCD      E  k ",
      "zabCD      F  k ",
      "zabI       J  k ",
      "zannks     w  kf",
      "zabp       g   k",
      "zannk      K   k",
      "zabL            ",
      "zabM       E    ",
      "zabMD      m    ",
      "zabI       h    ",
      "zannk           ",
      "zabpyk     g    ",
      "zannk        NO ",
      "zabL            ",
      "zabCD           ",
      "zabMD           "
    ],
    [
      "zab           k ",
      "zab           k ",
      "zab           k ",
      "zannk         kf",
      "zabp       g   k",
      "zannP          k",
      "zab             ",
      "zab             ",
      "zab             ",
      "zab             ",
      "zannk           ",
      "zabpyk     g    ",
      "zannk           ",
      "zab             ",
      "zab             ",
      "zab             "
    ],
    [
      "zabQ          k ",
      "zabQ          k ",
      "zab           k ",
      "zannk         kf",
      "zabp R     g   k",
      "zannk          k",
      "zab             ",
      "zabQ            ",
      "zabQ            ",
      "zab             ",
      "zannk           ",
      "zabpyk     g    ",
      "zannk           ",
      "zab             ",
      "zabQ            ",
      "zabQ            "
    ],
    [
      "zab           k ",
      "zabS          k ",
      "zab           k ",
      "zannk         kf",
      "zabp k     g   k",
      "zannk          k",
      "zab             ",
      "zabS            ",
      "zab             ",
      "zab             ",
      "zannk           ",
      "zabpyk     g    ",
      "zannk           ",
      "zab             ",
      "zabS            ",
      "zab             "
    ]
  ]
}