{
  "name": "multi_gasstation_1_ground",
  "refpalette": "c70cities:multi_gasstation_1_ground_palette",
  "xsize": 16,
  "zsize": 16,
  "slices": [
    [
      "HHHHaHHaaaaaaaGG",
      "HHHHHHHaaaaaaaGG",
      "HHHHHHHaaaaaaaGG",
      "HHHHaHHaaaaaaaGG",
      "HHHHaHHaaaaaaaGG",
      "HHbHaHHaaaaaaaGG",
      "HHHHaHHaaaaaaaGG",
      "HHHHaHHaaaaaaaGG",
      "HHHHaHHaaaaaaaGG",
      "HHHHaHHaaaaaaaGG",
      "HHHHaHHaaaaaaaGG",
      "HHHHaHHaaaaaaaGG",
      "HHHHaHHaaaaaaaGG",
      "HHHHHHHHHHcGGGGG",
      "HHHHHHHHHHcGGGGG",
      "GGGGGGGGGGGGGGGG"
    ],
    [
      "  def  g    hi  ",
      "       j  k ki  ",
      "       l  k mi  ",
      "    f  g  k ki  ",
      "  nop  g     i  ",
      "       i  kkmi  ",
      "  def  g    qi  ",
      "  nop  g    qi  ",
      "       j    qi  ",
      "  def  irs iii  ",
      "  not  uw  xhi  ",
      "       u   iyi  ",
      "  def  iiiiiii  ",
      "       A Bt     ",
      "       C Dt     ",
      "                "
    ],
    [
      "    f  g     i  ",
      "       E  m hi  ",
      "       F  k ki  ",
      "    f  g    mi  ",
      "    I  g     i  ",
      "       i  khki  ",
      "    f  g     i  ",
      "    I  g     i  ",
      "       E     i  ",
      "    f  iJ  iii  ",
      "       K   L i  ",
      "       K MNihi  ",
      "    f  iiiiiii  ",
      "                ",
      "                ",
      "                "
    ],
    [
      "    f  O     P  ",
      "       O     O  ",
      "       O     O  ",
      "    f  O     P  ",
      "       O     P  ",
      "       O    hO  ",
      "    f  O     P  ",
      "       O     P  ",
      "       O     O  ",
      "    f  O   iiO  ",
      "       O   i P  ",
      "       O  !i P  ",
      "    f  OOOOOOO  ",
      "                ",
      "                ",
      "                "
    ],
    [
      "    iQ i  R  i  ",
      "       i     i  ",
      "       i     i  ",
      "    iQ i  Q  i  ",
      "       i     i  ",
      "       iiiiiii  ",
      "    iR i  R  i  ",
      "       i     i  ",
      "       i    hi  ",
      "    iR i  Riii  ",
      "       i   i i  ",
      "       i  hihi  ",
      "    iQ iiiiiii  ",
      "                ",
      "                ",
      "                "
    ],
    [
      " SttattttttttaS ",
      " SttattttttttaS ",
      " SttattttttttaS ",
      " SttattttttttaS ",
      " SttattttttttaS ",
      " SttaaaaaaaaaaS ",
      " SttattttttttaS ",
      " SttattttttttaS ",
      " SttattttttttaS ",
      " SttattttttttaS ",
      " SttattttttttaS ",
      " SttattttttttaS ",
      " SttaaaaaaaaaaS ",
      " SSSSSSSSSSSSSS ",
      "                ",
      "                "
    ]
  ]
}