{
  "name": "multi_militarybase_2_ground",
  "refpalette": "c70cities:multi_militarybase_2_ground_palette",
  "xsize": 16,
  "zsize": 16,
  "slices": [
    [
      "zzzzzzzzzzzzzzzz",
      "aaaaaaaaaaaaaaaa",
      "bbzzzzbbzbzzzbbz",
      "zbbzbbbbbzbzbbzb",
      "ccccccccbbbbbbbb",
      "dddddddcbbbbbbbb",
      "dddddddcbbbbbbbb",
      "dddddddcbbbbbbbb",
      "dddddddcbbbbbbbb",
      "cccddddcbbbbbbbb",
      "cccddddcbbbbbbbb",
      "cccddddcbbbbbbbb",
      "cccedddcbbbbbbbb",
      "ccccccccbbbbbbbb",
      "bbbbbbbbbbbbbbbb",
      "bbbbbbbbbbbbbbbb"
    ],
    [
      "                ",
      "aaaaaaaaaaaaaaaa",
      "  ff f gf f h   ",
      "                ",
      "iiiiiiii        ",
      "jjk    l        ",
      "       l        ",
      "       l        ",
      " m     l        ",
      "niiopqoi rs s   ",
      "  it  uirswrs r ",
      "  iu  xirrrrrs  ",
      "  iexx!irrsrr   ",
      "  iiiiii ss     ",
      "  y             ",
      "                "
    ],
    [
      "                ",
      "aaaaaaaaaaaaaaaa",
      "       g   h    ",
      "                ",
      "AAABBBBA        ",
      "  C    l        ",
      "       l        ",
      "       l        ",
      " D     l        ",
      "EAAoFIoA        ",
      "  A    B  rr    ",
      "  B    B srrs   ",
      "  Ae tJAs   K   ",
      "  AAAAAA        ",
      "                ",
      "                "
    ],
    [
      "                ",
      "aaaaaaaaaaaaaaaa",
      "       g  h     ",
      "   LLLL         ",
      "AAAAAAAA        ",
      "       l        ",
      "       l        ",
      "       l        ",
      "       l        ",
      "AAAooooAL       ",
      "  A    AL       ",
      "  B    AL       ",
      "  Ae  JAL       ",
      "  AAAAAA        ",
      "                ",
      "                "
    ],
    [
      "                ",
      "aaaaaaaaaaaaaaaa",
      "       g h      ",
      "                ",
      "AAAMMMMA        ",
      "N OOOOOP        ",
      "      OP        ",
      "      OP        ",
      "OO    OP        ",
      "MAAOOOOA        ",
      "  A   OM        ",
      "  AJ  OM        ",
      "  AeJ OA        ",
      "  AAAAAA        ",
      "                ",
      "                "
    ],
    [
      "                ",
      "QQQQQQQRSQQQQQQQ",
      "TTTTTTUTT       ",
      "      V         ",
      "iiiiiiii        ",
      " NWWWWWi        ",
      "WWWWWWWi        ",
      "WWWWWWWi        ",
      "WWWWWWWi        ",
      "iiiWWWWi        ",
      "  iWWWWi        ",
      "  iWWWWi        ",
      "  ieWWWi        ",
      "  iWWWWi        ",
      "  iXXXXi        ",
      "  iXXXXi        "
    ]
  ]
}