{
  "name": "multi_laboratory1_1_base6",
  "refpalette": "c70cities:multi_laboratory1_1_base6_palette",
  "xsize": 16,
  "zsize": 16,
  "slices": [
    [
      "zabccccccccccccc",
      "zabccccccccccccc",
      "zabccccccccccccc",
      "zabccccccccccccc",
      "zabccccccccccccc",
      "zabccccccccccccc",
      "zabccccccccdcccc",
      "zabccccccccccccc",
      "zabccccccccccccc",
      "zabccccccccccccc",
      "zabccccccccccccc",
      "zabccccccccccccc",
      "zabcccccccccccce",
      "zabccccccccdccce",
      "zabcccccccccccef",
      "zabccccccccccce "
    ],
    [
      "zag             ",
      "zab             ",
      "zabh            ",
      "zabh          i ",
      "zab             ",
      "zajjjj       kkk",
      "zablmj     d    ",
      "zajjjj     !    ",
      "zab        n    ",
      "zabh     o np   ",
      "zabh       n    ",
      "zab        n    ",
      "zajjjj         q",
      "zablmj     d   q",
      "zajjjj     r  qf",
      "zab        n  q "
    ],
    [
      "zag             ",
      "zab             ",
      "zabst           ",
      "zabut           ",
      "zabw            ",
      "zajjq        xy ",
      "zablmq     d    ",
      "zajjq           ",
      "zabA       B    ",
      "zabut      C    ",
      "zabst      r    ",
      "zabw       D    ",
      "zajjq          q",
      "zablmq     d   q",
      "zajjq      x  qf",
      "zabA       B  q "
    ],
    [
      "zag             ",
      "zab             ",
      "zab             ",
      "zab             ",
      "zab             ",
      "zajjq        E  ",
      "zablmq     d    ",
      "zajjq           ",
      "zab             ",
      "zab             ",
      "zab             ",
      "zab             ",
      "zajjq          q",
      "zablmq     d   q",
      "zajjq      F  qf",
      "zab           q "
    ],
    [
      "zag             ",
      "zab             ",
      "zabI            ",
      "zabI            ",
      "zab             ",
      "zajjq           ",
      "zablmq     d    ",
      "zajjq           ",
      "zab             ",
      "zabI            ",
      "zabI            ",
      "zab             ",
      "zajjq          q",
      "zablmq     d   q",
      "zajjq         qf",
      "zab           q "
    ],
    [
      "zag             ",
      "zab             ",
      "zabg            ",
      "zab             ",
      "zab             ",
      "zajjq           ",
      "zablmq     d    ",
      "zajjq           ",
      "zab             ",
      "zabg            ",
      "zab             ",
      "zab             ",
      "zajjq          q",
      "zablmq     d   q",
      "zajjq         qf",
      "zab           q "
    ]
  ]
}