{
  "name": "multi_laboratory1_1_base1",
  "refpalette": "c70cities:multi_laboratory1_1_base1_palette",
  "xsize": 16,
  "zsize": 16,
  "slices": [
    [
      "zabccccccccccccc",
      "zabccccccccccccc",
      "zabccccccccccccc",
      "zabccccccccccccc",
      "zabccccccccccccc",
      "zabccccccccccccc",
      "zabccccccccdcccc",
      "zabccccccccccccc",
      "zabccccccccccccc",
      "zabccccccccccccc",
      "zabccccccccccccc",
      "zabccccccccccccc",
      "zabcccccccccccce",
      "zabccccccccdccce",
      "zabcccccccccccef",
      "zabccccccccccce "
    ],
    [
      "zabghhiiii j    ",
      "zabgkl  m  j    ",
      "zabn ll    j    ",
      "zabgo   l  p    ",
      "zabgl      j    ",
      "zabq  rrr  j    ",
      "zabq stuwx dy   ",
      "zabq stuwx A    ",
      "zabg suuux A    ",
      "zabgBsCuDx A    ",
      "zabn sCuDx A    ",
      "zabg BEEE  A    ",
      "zabgFIBBBJKA  LM",
      "zabNNNNONNNd  yM",
      "zabg    iPiN  My",
      "zabn     JQN  M "
    ],
    [
      "zabk  RSTU j    ",
      "zabV       j    ",
      "zabW       j    ",
      "zabU       X    ",
      "zabl       j    ",
      "zabV       j    ",
      "zabY  Z 0  d1   ",
      "zabW  Z    A    ",
      "zab2       A    ",
      "zab3  4 5  A    ",
      "zabV       A    ",
      "zabY       A    ",
      "zabW       A   M",
      "zabNNNN6NNNd  1M",
      "zabV    7T A  My",
      "zabY       A  M "
    ],
    [
      "zab899     j    ",
      "zab@       j    ",
      "zab        j    ",
      "zab        j    ",
      "zab        j    ",
      "zab#       j    ",
      "zab8       d1   ",
      "zab        A    ",
      "zab        A    ",
      "zab        A    ",
      "zab$       A    ",
      "zab8       A    ",
      "zab!       A   M",
      "zabNNNNNNNNd  1M",
      "zab%       A  My",
      "zab8       A  M "
    ],
    [
      "zab        j    ",
      "zab        j    ",
      "zab        j    ",
      "zab        j    ",
      "zab        j    ",
      "zab        j    ",
      "zab   ^ ^  d    ",
      "zab        A    ",
      "zab        A    ",
      "zab        A    ",
      "zab   & &  A    ",
      "zab        A    ",
      "zab        A   M",
      "zabNNNNNNNNd   M",
      "zab        A  My",
      "zab        A  M "
    ],
    [
      "zab********(****",
      "zab**)***)*(****",
      "zab**+***)*(****",
      "zab**)***)*(****",
      "zab**)***)*(****",
      "zab********(****",
      "zab***---**d****",
      "zab***[-[**(****",
      "zab**)***)*(****",
      "zab**)[-[)*(****",
      "zab**)---)*(****",
      "zab**)***)*(****",
      "zab********(***]",
      "zab{{{{{{{{d***]",
      "zab********(**]}",
      "zab**)***)*(**] "
    ]
  ]
}