{
  "name": "multi_laboratory1_5_base3",
  "refpalette": "c70cities:multi_laboratory1_5_base3_palette",
  "xsize": 16,
  "zsize": 16,
  "slices": [
    [
      "zzzzzzzzzzzzzzzz",
      "aaaaaaaaaaaaaaaa",
      "bbbbbbbbbbbbbbbb",
      "                ",
      "                ",
      "cccccccccccccccc",
      "c    c    c    c",
      "cd  dcd  dcd  dc",
      "cccccccccccccccc",
      "c    c    c    c",
      "c    c    c    c",
      "c    c    c    c",
      "c    c    c    c",
      "c    c    c    c",
      "c    c    c    c",
      "cccccccccccccccc"
    ],
    [
      "zzzzzzzzzzzzzzzz",
      "aaaaaaaaaaaaaaaa",
      "bbbbbbbbbbbbbbbb",
      "                ",
      "                ",
      "ceeeeeeeeeeeeeec",
      "e    e    e    e",
      "ed  ded  ded  de",
      "ceeeeceeeeceeeec",
      "e    e    e    e",
      "e    e    e    e",
      "e    e    e    e",
      "e    e    e    e",
      "e    e    e    e",
      "e    e    e    e",
      "ceffeceffeceffec"
    ],
    [
      "zzzzzzzzzzzzzzzz",
      "aaaaaaaaaaaaaaaa",
      "bbbbbbbbbbbbbbbb",
      "                ",
      "                ",
      "ceeeeeeeeeeeeeec",
      "e    e    e    e",
      "ed  ded  ded  de",
      "ceeeeceeeeceeeec",
      "e    e    e    e",
      "e    e    e    e",
      "e    e    e    e",
      "e    e    e    e",
      "e    e    e    e",
      "e    e    e    e",
      "ce  ece  ece  ec"
    ],
    [
      "zzzzzzzzzzzzzzzz",
      "aaaaaaaaaaaaaaaa",
      "bbbbbbbbbbbbbbbb",
      "                ",
      "                ",
      "ceeeeeeeeeeeeeec",
      "e    e    e    e",
      "ed  ded  ded  de",
      "ceeeeceeeeceeeec",
      "e    e    e    e",
      "e    e    e    e",
      "e    e    e    e",
      "e    e    e    e",
      "e    e    e    e",
      "e    e    e    e",
      "ceggeceggeceggec"
    ],
    [
      "zzzzzzzzzzzzzzzz",
      "aaaaaaaaaaaaaaaa",
      "bbbbbbbbbbbbbbbb",
      "               h",
      "               h",
      "ceeeeeeeeeeeeeec",
      "e    e    e    e",
      "ed  ded  ded  de",
      "ceeeeceeeeceeeec",
      "e    e    e    e",
      "e    e    e    e",
      "e    e    e    e",
      "e    e    e    e",
      "e    e    e    e",
      "e    e    e    e",
      "ceeeeceeeeceeeec"
    ],
    [
      "zzzzzzzzzzzzzzzz",
      "aaaaaaaaaaaaaaaa",
      "bbbbbbbbbbbbbbbb",
      "                ",
      "                ",
      "ceeeeeeeeeeeeeec",
      "e    e    e    e",
      "ed  ded  ded  de",
      "ceeeeceeeeceeeec",
      "e    e    e    e",
      "e    e    e    e",
      "e    e    e    e",
      "e    e    e    e",
      "e    e    e    e",
      "e    e    e    e",
      "ceeeeceeeeceeeec"
    ]
  ]
}