{
  "name": "multi_megatower1_7_floor7",
  "refpalette": "c70cities:multi_megatower1_7_floor7_palette",
  "xsize": 16,
  "zsize": 16,
  "slices": [
    [
      "aabcd           ",
      "aabce           ",
      "aabce           ",
      "aabce           ",
      "aafgh           ",
      "aabcd           ",
      "aabcd           ",
      "aabcd           ",
      "aabce           ",
      "aabce           ",
      "aabce           ",
      "aafgh           ",
      "aabcd           ",
      "aabcd           ",
      "aabcd           ",
      "aabce           "
    ],
    [
      " ij             ",
      "  j             ",
      "  j e           ",
      "i j e           ",
      " kfgh           ",
      "ikj             ",
      " ij d           ",
      "  j d           ",
      "  j e           ",
      " ij e           ",
      "klj             ",
      "kkfgh           ",
      " mj d           ",
      "imj d           ",
      "  j             ",
      " ij             "
    ],
    [
      "                ",
      "                ",
      "    e           ",
      "    e           ",
      " mfgh           ",
      " m              ",
      "    d           ",
      "    d           ",
      "    e           ",
      "    e           ",
      "                ",
      " mfgh           ",
      " m  d           ",
      "    d           ",
      "                ",
      "                "
    ],
    [
      "                ",
      "                ",
      "    e           ",
      "                ",
      " mfgh           ",
      "                ",
      "    d           ",
      "                ",
      "                ",
      "    e           ",
      " m              ",
      "  fgh           ",
      "                ",
      "    d           ",
      "                ",
      " m              "
    ],
    [
      "  j             ",
      "  j             ",
      "  j e           ",
      "  j             ",
      "  fgh           ",
      "  j             ",
      "  j d           ",
      "  j             ",
      "  j             ",
      "  j e           ",
      " mj             ",
      " mfgh           ",
      "  j             ",
      " mj d           ",
      "  j             ",
      " mj             "
    ],
    [
      "  n             ",
      "  n             ",
      "  n e           ",
      "  n             ",
      "oofgh           ",
      "  n             ",
      "  n d           ",
      "  n             ",
      "  n             ",
      "  n e           ",
      " kn             ",
      "oofgh           ",
      " kn             ",
      " mn d           ",
      " kn             ",
      " mn             "
    ]
  ]
}