{
  "name": "multi_convenientstore_1_ground",
  "refpalette": "c70cities:multi_convenientstore_1_ground_palette",
  "xsize": 16,
  "zsize": 16,
  "slices": [
    [
      "GGHHHHHHaaaaaaaa",
      "GGHHHHHHabbbbbbb",
      "GGHHHHHHabbbbbbb",
      "GGHHHHHHabbbbbbb",
      "GGHHHHHHabbbbbbb",
      "GGHHHHHHabbbbbbb",
      "GGHHHHHHabbbbbbb",
      "GGHHHHHHabbbbbbb",
      "GGHHHHHHabbbbbbb",
      "GGHHHHHHabbbbbbb",
      "GGHHHHHHabbbbbbb",
      "GGHHHHHHabbbbbbb",
      "GGHHHHHHaaaaaaaa",
      "GGHHHHHHHHHHHHHH",
      "GGHHHHHHHHHHHHHH",
      "GGHHHHHccccccccc"
    ],
    [
      " d   eaaaaaaaaaa",
      " f   eaaabbbbbbb",
      " f g eaaabbbbbbb",
      " f h eaaabbbbbbb",
      "     eaaabbbbbbb",
      "d    eaaabbbbbbb",
      "     eaaabbbbbbb",
      "f    eaaabbbbbbb",
      "     eaaabbbbbbb",
      "     eaaabbbbbbb",
      "d  i eaaabbbbbbb",
      "f    eaaabbbbbbb",
      "     eaaaaaaaaaa",
      " f   vvvvHHHHHHH",
      "f     jjjHHHHHHH",
      " d    jjjHHHHHHH"
    ],
    [
      " ~     kkk  kklm",
      "        n     o ",
      "        k  p    ",
      "        q  rsrt ",
      "        q pu    ",
      "~       q   u w ",
      "       xl  rtrt ",
      "        y       ",
      "        A       ",
      "       Bl       ",
      "~       q       ",
      "        qCDDCDDD",
      "        qEEEEEEE",
      "     vvvvF IIIJF",
      "                ",
      " ~              "
    ],
    [
      "        kk  kklK",
      "        k       ",
      "        k       ",
      "        q  L M  ",
      "        k       ",
      "        q       ",
      "       xl  sMNO ",
      "        P       ",
      "        Q       ",
      "       Bl       ",
      "        q       ",
      "        kRRRRSSS",
      "        qEEEEEEE",
      "     vvvv     I ",
      "                ",
      "                "
    ],
    [
      "        kk kkkll",
      "        k       ",
      "        k       ",
      "        q       ",
      "        k       ",
      "        q       ",
      "       Tl       ",
      "       Ul       ",
      "       Ul       ",
      "       Vl       ",
      "        q       ",
      "        k       ",
      "        qEEEEEEE",
      "     vvvv     II",
      "                ",
      "                "
    ],
    [
      "        kkkkkkkk",
      "        k       ",
      "        k       ",
      "        q       ",
      "        q       ",
      "        q       ",
      "        qWWWWWWW",
      "        q X  Y  ",
      "        q Y  X  ",
      "        q       ",
      "        q       ",
      "        qIZIIZII",
      "        qEEEEEEE",
      "     vvvv       ",
      "                ",
      "                "
    ]
  ]
}