{
  "name": "multi_laboratory1_14_base3",
  "refpalette": "c70cities:multi_laboratory1_14_base3_palette",
  "xsize": 16,
  "zsize": 16,
  "slices": [
    [
      "aaaabaaaaaaaacdv",
      "aaaaaaaaaaaaacdv",
      "aaeaaaaaaaaaacdv",
      "aaaaaaaaaaaaacdv",
      "aaafaaaaaaaaacdv",
      "aghaaaaaaaaaacdv",
      "aagaaaaaaaaaacdv",
      "aaaabaaaaaaaacdv",
      "aafaai!iiiiiicdv",
      "aajgafiiiiiffcdv",
      "aagaaiiiiifficdv",
      "aaaaaiiiiiiiicdv",
      "aaaaaiiii!iiicdv",
      "ccccccccccccccdv",
      "dddddddddddddddv",
      "vvvvvvvvvvvvvvvv"
    ],
    [
      "k   bllllllllcdv",
      "kmnolpqr stupcdv",
      "w xylA     BCcdv",
      "DE FlI JK  LMcdv",
      "  n lNOPQ  RScdv",
      "   nTUmVWXYZ0cdv",
      "   1l23445546cdv",
      "7 89bllllllllcdv",
      "   @l##$$$$##cdv",
      " %  f ^  E  &cdv",
      "   *lf()(+()(cdv",
      "    l^- -8-e-cdv",
      "  8 l[-[-[-e-cdv",
      "ccccccccccccccdv",
      "dddddddddddddddv",
      "vvvvvvvvvvvvvvvv"
    ],
    [
      "    bllllllllcdv",
      "    l]      ]cdv",
      "    l        cdv",
      "    l        cdv",
      "    l{       cdv",
      "    }\\ |     cdv",
      "    l234`4446cdv",
      "    bllllllllcdv",
      "   fl]:::::8]cdv",
      "             cdv",
      "    l (;('(;(cdv",
      "    l - - -@-cdv",
      "    l - - -e-cdv",
      "ccccccccccccccdv",
      "dddddddddddddddv",
      "vvvvvvvvvvvvvvvv"
    ],
    [
      "    bllllllllcdv",
      "    l]      ]cdv",
      "    l        cdv",
      "    l{       cdv",
      "    l        cdv",
      "    ,        cdv",
      "    l .  Y/ 6cdv",
      " @  bllllllllcdv",
      "   fl  :: :: cdv",
      "    l        cdv",
      "    l((((((((cdv",
      "    l - - -<-cdv",
      "    l - -@-efcdv",
      "ccccccccccccccdv",
      "dddddddddddddddv",
      "vvvvvvvvvvvvvvvv"
    ],
    [
      "    bllllllllcdv",
      "    l        cdv",
      "    l        cdv",
      "  @ l        cdv",
      "    l        cdv",
      "    l        cdv",
      "    l       6cdv",
      " < fbllllllllcdv",
      "    l>>>>>>>>cdv",
      "    l>>>>>>>>cdv",
      "    l>>>>>>>>cdv",
      "    l>>>>>>e@cdv",
      "    l?>?>f>eecdv",
      "ccccccccccccccdv",
      "dddddddddddddddv",
      "vvvvvvvvvvvvvvvv"
    ],
    [
      "\u00a3\u00a4\u00a3\u00a3bllllllllcdv",
      "\u00a3\u00a5\u00a3\u00a3,\u00a7\u00a7\u00a7\u00a7\u00a7\u00a7\u00a7\u00a7cdv",
      "\u00a3\u00a5\u00a3\u00a3,\u00a7\u00c0\u00a7\u00a7\u00a7\u00a7\u00c1\u00a7cdv",
      "\u00c2\u00a4f\u00a3,\u00a7\u00a7\u00a7\u00a7\u00a7\u00a7\u00a7\u00a7cdv",
      "\u00a3\u00a3f\u00a3,\u00a7\u00a7\u00a7\u00a7\u00a7\u00a7\u00a7\u00a7cdv",
      "\u00a3f\u00a3\u00a3,\u00a7\u00a5\u00a7\u00a7\u00a7\u00a7\u00c0\u00a7cdv",
      "\u00a3\u00a3ff,\u00a7\u00a7\u00a7\u00a7\u00a7\u00a7\u00a7\u00a7cdv",
      "lffebllllllllcdv",
      "\u00c3\u00c3\u00c3\u00c3l\u00c4\u00c4\u00c4eeff\u00c4cdv",
      "\u00c3\u00c3\u00a4\u00c3l\u00c4 \u00c4 e f cdv",
      "\u00c3\u00c3\u00a4\u00c3l\u00c4 \u00c4 f f cdv",
      "\u00c3\u00c3\u00a4\u00c3l\u00c4 \u00c4 f efcdv",
      "\u00c3\u00c3\u00c3\u00c3l\u00c4 \u00c4 f e\u00c5cdv",
      "ccccccccccccccdv",
      "dddddddddddddddv",
      "vvvvvvvvvvvvvvvv"
    ]
  ]
}