{
  "name": "multi_laboratory1_3_base5",
  "refpalette": "c70cities:multi_laboratory1_3_base5_palette",
  "xsize": 16,
  "zsize": 16,
  "slices": [
    [
      "zab             ",
      "zac             ",
      "zdeeeeeeeeedffff",
      "zb         g    ",
      "zb         g    ",
      "zb         g    ",
      "zb         g    ",
      "zb         g    ",
      "zb         g    ",
      "zdddddddddddh   ",
      "zbiiiid    g    ",
      "zbiiiidj   g    ",
      "zbiiiid    g    ",
      "zbiiiid    g    ",
      "zbiiikd    g    ",
      "zbiiiid    g    "
    ],
    [
      "zab             ",
      "zac             ",
      "zdeeeeeeeeedffff",
      "zb         g    ",
      "zb         g    ",
      "zb         g    ",
      "zb         g    ",
      "zb         g    ",
      "zb         g    ",
      "zdlllleeeeed    ",
      "zb    emm  g    ",
      "zbn  oe m  g    ",
      "zbp   e m  g    ",
      "zbn   e m  g    ",
      "zb    e m  g    ",
      "zbqqq e m  g    "
    ],
    [
      "zab             ",
      "zac             ",
      "zdeeeeeeeeedffff",
      "zb         g    ",
      "zb         g    ",
      "zb         g    ",
      "zb         g    ",
      "zb         g    ",
      "zb         g    ",
      "zdlllleeeeed    ",
      "zb    e    g    ",
      "zb    e    g    ",
      "zbr   e    g    ",
      "zb   se    g    ",
      "zb    e    g    ",
      "zb    e    g    "
    ],
    [
      "zab             ",
      "zac             ",
      "zdeeeeeeeeedffff",
      "zb         g    ",
      "zb         g    ",
      "zb         g    ",
      "zb         g    ",
      "zb         g    ",
      "zb         g    ",
      "zdlllleeeeed    ",
      "zb    e    g    ",
      "zb    e    g    ",
      "zb    e    g    ",
      "zb    e    g    ",
      "zb    e    g    ",
      "zbt   e    g    "
    ],
    [
      "zab             ",
      "zac             ",
      "zdeeeeeeeeeduuuu",
      "zb         e    ",
      "zb         e    ",
      "zb         e    ",
      "zb         e    ",
      "zb         e    ",
      "zb         e    ",
      "zdlllleeeeed    ",
      "zb    e    e    ",
      "zb    e    e    ",
      "zb    e    e    ",
      "zb    e    e    ",
      "zb    e    e    ",
      "zb    e    e    "
    ],
    [
      "zabcwwwwwwwwwwww",
      "zaccwwwwwwwwwwww",
      "zdeeeeeeeeedxxxx",
      "zbyyyyyyyyyeyyyy",
      "zbyyyyyyyyyeyyyy",
      "zbyyAAAAAyyeyyyy",
      "zbyyAAAAAyyeyyyy",
      "zbyyyyyyyyyeyyyy",
      "zbyyyyyyyyyeyyyy",
      "zdBBBBeeeeeeyyyy",
      "zbwwwweyyyyeyyyy",
      "zbwwwweyyyyeyyyy",
      "zbwwwweyACyeyyyy",
      "zbwwwweyACyeyyyy",
      "zbwwwweyyyyeyyyy",
      "zbwwwweyyyyeyyyy"
    ]
  ]
}