{
  "name": "multi_militarybase_1_ground",
  "refpalette": "c70cities:multi_militarybase_1_ground_palette",
  "xsize": 16,
  "zsize": 16,
  "slices": [
    [
      "aHHHHHHHHHHHHHH=",
      "ab=HH=H==HHbHHHH",
      "acdddddddddddddd",
      "acdddddddddd!ddd",
      "acdddddddddddddd",
      "acdddddddddddddd",
      "acdddddddddddddd",
      "acdddddddddddddd",
      "acdddddddddddddd",
      "acdddddddddddddd",
      "acdddddddddddddd",
      "acdddddddddddddd",
      "acdddddddddddddd",
      "acdddddddddddddd",
      "accccccccccccccc",
      "aaaaaaaaaaaaaaaa"
    ],
    [
      "  e             ",
      "                ",
      " c      ffffff  ",
      " c      fghihf  ",
      " c      fj   f  ",
      " c      fj k f  ",
      " c      fl   ff ",
      " c      fm      ",
      " c      fn      ",
      " c      fo      ",
      " c      foo   pq",
      " c      ffffffff",
      " c              ",
      " c              ",
      " ccccccccccccccc",
      "                "
    ],
    [
      "                ",
      "                ",
      " c      rrssrr  ",
      " c      r   tr  ",
      " c      s    s  ",
      " c      s    r  ",
      " c      r    rr ",
      " c      r       ",
      " c      s       ",
      " c      s       ",
      " c      ro     p",
      " c      rrssrrrr",
      " c              ",
      " c              ",
      " ccccccccccccccc",
      "                "
    ],
    [
      "                ",
      "                ",
      " c      rrssrr  ",
      " c     ur   tr  ",
      " c     ur    s  ",
      " c     ur    r  ",
      " c     ur    rrr",
      " c     ur       ",
      " c     ur       ",
      " c     ur       ",
      " c     ur       ",
      " c      rrrrrrrr",
      " c       uuuu   ",
      " c              ",
      " ccccccccccccccc",
      "                "
    ],
    [
      "                ",
      "                ",
      " c      rrrrrr  ",
      " c      rw  xr  ",
      " c      yw   r  ",
      " c      yw   r  ",
      " c      rw   rry",
      " c      rw    ww",
      " c      yw      ",
      " c      yw      ",
      " c      rwwww   ",
      " c      rryyrrrr",
      " c              ",
      " c              ",
      " ccccccccccccccc",
      "                "
    ],
    [
      "        fppppf  ",
      "        fppppf  ",
      " e      faaaaf  ",
      " e      faaaaf  ",
      " e      faaaaf  ",
      " e      faaaaf  ",
      " e      faaaafff",
      " e      faaaaaaa",
      " e      faaaaaaa",
      " e      faaaaaaa",
      " e      faaaaa  ",
      " e      ffffffff",
      " e              ",
      " e              ",
      " ABBBBBBBBBBBBBB",
      "                "
    ]
  ]
}