{
  "name": "multi_hospital_2_ground",
  "refpalette": "c70cities:multi_hospital_2_ground_palette",
  "xsize": 16,
  "zsize": 16,
  "slices": [
    [
      "GGGGGGGGGGGGGGGG",
      "aaaaaaaaaaaaaaaG",
      "aaaabbbbbbbbbbaG",
      "caaabbbbbbbbbbaG",
      "daaadGGdGGdGGdaG",
      "caaaaaaaaaaaaaaG",
      "caaaaaaaaaaaaaaG",
      "caaaaaaaaaaaaaaG",
      "caaaaaaaaaaaaaaG",
      "cceeeeeeeeeeeeaG",
      "cceeee!eeeeeeeaG",
      "cceeeeeeeeeeeeaG",
      "cceeeeeeeeeeeeaG",
      "cceeeeeeeeeeeeaG",
      "ccccccccccccccaG",
      "ccccccccccccccaG"
    ],
    [
      "                ",
      "                ",
      " f              ",
      "gh   ij ij ij   ",
      "kh  llllllllll  ",
      " h              ",
      " m              ",
      " h              ",
      "ngggggggggggggo ",
      " p   p   p   qo ",
      " q r q r q r qo ",
      "sqtthqtthqtt qo ",
      "squu quu q u qo ",
      "sqw  qw  qx  qo ",
      "yqAABAAABAAABAo ",
      "            CGD "
    ],
    [
      "                ",
      "                ",
      " f              ",
      "gh              ",
      "kh              ",
      " h              ",
      " E              ",
      " h              ",
      "nggFFggFFggFFgo ",
      " I   I   I   qo ",
      " q   q   q   qo ",
      " qJK qLK qM  qo ",
      " q   q   q   qo ",
      " qM  qM  q   qo ",
      " qAANAAANAAANAo ",
      "             OP "
    ],
    [
      "                ",
      "                ",
      " f              ",
      "gh              ",
      "kh              ",
      " h              ",
      " h              ",
      " h              ",
      "nggFFggFFggFFgo ",
      " Q   Q   Q   qo ",
      " q   q   q   qo ",
      " q   q   q   qo ",
      " q   q   q   qo ",
      " qRS qRS qRS qo ",
      " qAATAAATAAATAo ",
      "             UP "
    ],
    [
      "                ",
      "                ",
      " f              ",
      "gh              ",
      " h              ",
      " h              ",
      " h              ",
      " h              ",
      "ngggggggggggggo ",
      " q   q   q   qo ",
      " q   q   q   qo ",
      " q   q   q   qo ",
      " q   q   q   qo ",
      " q V qWV qXY qo ",
      " qAAAAAAAAAAAAo ",
      "              P "
    ],
    [
      "                ",
      "                ",
      " f              ",
      "gh              ",
      " h              ",
      " h              ",
      " h              ",
      " h              ",
      "nZ000000000000o ",
      " q           qo ",
      " q           qo ",
      " q           qo ",
      " q           qo ",
      " q           qo ",
      " qAAAAAAAAAAAAo ",
      "              P "
    ]
  ]
}