{
  "name": "multi_condo1_1_floor6",
  "refpalette": "c70cities:multi_condo1_1_floor6_palette",
  "xsize": 16,
  "zsize": 16,
  "slices": [
    [
      "   abccccccdeeee",
      "  ffbbbbbbcdeghh",
      "   abccccccdeijj",
      "   abccccccdeijj",
      "   aiccccccdeijj",
      "   aiccccccdeijj",
      "   aiccccccdeijj",
      "   aiccccccdeijj",
      "   aiccccccdeijj",
      "   aiccccccdeijj",
      "   aiccccccdeijj",
      "   aiccccccdeijj",
      "   abccccccdeijj",
      "   abccccccdeijj",
      "  ffbbbbbbcdekll",
      "   abmmmcccdeeee"
    ],
    [
      "    bnop  q     ",
      "  ffbbbbbbb  rrr",
      "    bq   s   r  ",
      "    b        r  ",
      "    t        r  ",
      "    t uw     r  ",
      "    t    x   r  ",
      "    t yy A   r  ",
      "    t yy A   r  ",
      "    t    B   r  ",
      "    t CD     r  ",
      "    t        r  ",
      "    b        r  ",
      "    bEEEEEq  r  ",
      "  ffbbbbbbb  rrr",
      "    bFIbJ q     "
    ],
    [
      "    b  KL M     ",
      "  ffbbbbbbb     ",
      "    bM  s       ",
      "    b           ",
      "    t           ",
      "    t           ",
      "    t           ",
      "    t           ",
      "    t           ",
      "    t           ",
      "    t           ",
      "    t           ",
      "    b           ",
      "    bEEEEEM     ",
      "  ffbbbbbbb     ",
      "    b  b  M     "
    ],
    [
      "    b           ",
      "  ffbbbbbbb     ",
      "    bNNs        ",
      "    bNN         ",
      "    t           ",
      "    t           ",
      "    t           ",
      "    t           ",
      "    t           ",
      "    t           ",
      "    t           ",
      "    t           ",
      "    b           ",
      "    b O         ",
      "  ffbbbbbbb     ",
      "    b  b        "
    ],
    [
      "    b           ",
      "  ffbbbbbbb     ",
      "    b           ",
      "    bPPQ        ",
      "    t           ",
      "    t           ",
      "    t           ",
      "    t           ",
      "    t           ",
      "    t           ",
      "    t           ",
      "    t           ",
      "    b           ",
      "    b           ",
      "  ffbbbbbbb     ",
      "    b  b        "
    ],
    [
      "    bRRRRRR     ",
      "  ffbbbbbbb     ",
      "    b           ",
      "    b   Q       ",
      "    S           ",
      "    S           ",
      "    S           ",
      "    S           ",
      "    S           ",
      "    S           ",
      "    S           ",
      "    S           ",
      "    b           ",
      "    b           ",
      "  ffbbbbbbb     ",
      "    bTTbRRR     "
    ]
  ]
}