{
  "name": "multi_laboratory1_0_base2",
  "refpalette": "c70cities:multi_laboratory1_0_base2_palette",
  "xsize": 16,
  "zsize": 16,
  "slices": [
    [
      "vvvvvvvvvvvvvvvv",
      "vaaaaaaaaaaaaaaa",
      "vabbbbbbbbbbcccc",
      "vabdddddddde    ",
      "vabdddddddde    ",
      "vabddddddddeeeee",
      "vabddddddddfffff",
      "vabd!ddddddfffff",
      "vabffffffffeffff",
      "vabddddddddfffff",
      "vabddddddddfffff",
      "vabddddddddfffff",
      "vabddddddddfffff",
      "vabddddddddfffff",
      "vabddddddddfffff",
      "vabffffffffeffff"
    ],
    [
      "vvvvvvvvvvvvvvvv",
      "vaaaaaaaaaaaaaaa",
      "vabbbbbbbbbbcccc",
      "vabghghghghi    ",
      "vabg g g g i    ",
      "vabjkjkjkjkiiiii",
      "vab        l   m",
      "vabnnoooonni   p",
      "vabiiiiiiiie   q",
      "vabrrssssrri   t",
      "vab        u   t",
      "vab        i   t",
      "vabwxwxwxwxi   t",
      "vab y y y yi   q",
      "vabAyAyAyAyi    ",
      "vabiiiiiiiie    "
    ],
    [
      "vvvvvvvvvvvvvvvv",
      "vaaaaaaaaaaaaaaa",
      "vabbbbbbbbbbcccc",
      "vabg g g g i    ",
      "vabg g g g i    ",
      "vabjBjBjBjBiiiii",
      "vab        C    ",
      "vabDEEEEEEDi    ",
      "vabiiiiiiiie   F",
      "vabDIIIIIIDi   J",
      "vab        K    ",
      "vab        i   L",
      "vabMxMxMxMxi   N",
      "vab y y y yi   F",
      "vab y y y yi    ",
      "vabiiiiiiiie    "
    ],
    [
      "vvvvvvvvvvvvvvvv",
      "vaaaaaaaaaaaaaaa",
      "vabbbbbbbbbbcccc",
      "vabg g g g i    ",
      "vabg g g g i    ",
      "vabjjjjjjjjiiiii",
      "vab        i    ",
      "vab EEEEEE i    ",
      "vabiiiiiiiie   D",
      "vab IIIIII i    ",
      "vab        i    ",
      "vab        i   O",
      "vabxxxxxxxxi    ",
      "vab y y y yi   D",
      "vab y y y yi    ",
      "vabiiiiiiiie    "
    ],
    [
      "vvvvvvvvvvvvvvvv",
      "vaaaaaaaaaaaaaaa",
      "vabbbbbbbbbbcccc",
      "vabPQPQPQPQi    ",
      "vabPPPPPPPPi    ",
      "vabPPPPPPPPiiiii",
      "vabPPPPPPPPi    ",
      "vabPPPPPPPPi    ",
      "vabiiiiiiiie    ",
      "vabPPPPPPPPi    ",
      "vabPPPPPPPPi    ",
      "vabPPPPPPPPi    ",
      "vabPPPPPPPPi    ",
      "vabPPPPPPPPi    ",
      "vabQP!PQPQPi    ",
      "vabiiiiiiiie    "
    ],
    [
      "vvvvvvvvvvvvvvvv",
      "vaaaaaaaaaaaaaaa",
      "vabbbbbbbbbbcccc",
      "vab R R R Ri    ",
      "vab R R R Ri    ",
      "vab R R R Riiiii",
      "vab R R R RiSSSS",
      "vab RRRRRRRiSSSS",
      "vabiiiiiiiieSSSS",
      "vabRRRRRRRRiSSSS",
      "vabR R R R iSSSS",
      "vabRTRTRTRTiSSSS",
      "vabRURTRTRTiSSSS",
      "vabRTRTRTRTiSSSS",
      "vabRTRTRTRTiSSSS",
      "vabiiiiiiiieVVVV"
    ]
  ]
}