{
  "name": "multi_laboratory1_12_base1",
  "refpalette": "c70cities:multi_laboratory1_12_base1_palette",
  "xsize": 16,
  "zsize": 16,
  "slices": [
    [
      " abbbbbbbbbbbcdz",
      " abbbbbbbbbbbcdz",
      " abbbbbbbbbbbcdz",
      "eabbbbbbbbbbbcdz",
      "abbbfbbbbbbbbcdz",
      "abbbbbbbbbbbbcdz",
      "bbbbbbbbbbbbbcdz",
      "bbbbbbbbbbbbbcdz",
      "bbbbbbbbbbbbbcdz",
      "bbbbbbbbbbbbbcdz",
      "bbbbbbbbbbbbbcdz",
      "bbbbfbbbbbbbbcdz",
      "bbbbbbbbbbbbbcdz",
      "bbbbbbbbbbbbbcdz",
      "bbbbbbbbbbbbbcdz",
      "bbbbbbbbbbbbbcdz"
    ],
    [
      " g  hi  ii jicdz",
      " g  hik ii  icdz",
      " g  hi  ii jicdz",
      "lg  hik m   icdz",
      "gl  fhh    h!cdz",
      "gn  o l    lpcdz",
      "    oqr      cdz",
      "    oqk   qstcdz",
      "    oqq   qqqcdz",
      "    o        cdz",
      "    oqu   qstcdz",
      "   lfqk   qqqcdz",
      "    wqq      cdz",
      "    w     qstcdz",
      "    x     qqqcdz",
      "    w        cdz"
    ],
    [
      " g  o       ycdz",
      " g  o        cdz",
      " g  o        cdz",
      "lg  oA      Bcdz",
      "gC  fhh    hhcdz",
      "g   o C    C cdz",
      "    oD       cdz",
      "    o        cdz",
      "    o E    F cdz",
      "    o        cdz",
      "    o        cdz",
      "   CfI     F cdz",
      "    wDE      cdz",
      "    w     E  cdz",
      "    J      F cdz",
      "    w        cdz"
    ],
    [
      " g  o       Kcdz",
      " g  o       Kcdz",
      " g  o       Kcdz",
      "lg  o       Kcdz",
      "gC  fhh    hhcdz",
      "g   o C    C cdz",
      "    o        cdz",
      "    o        cdz",
      "    o        cdz",
      "    o        cdz",
      "    o        cdz",
      "   Cf        cdz",
      "    w        cdz",
      "    w        cdz",
      "    w        cdz",
      "    w        cdz"
    ],
    [
      " g  o        cdz",
      " g  o        cdz",
      " g  o        cdz",
      "lg  o        cdz",
      "g   fhh    hhcdz",
      "g   o        cdz",
      "    o        cdz",
      "    o        cdz",
      "    o        cdz",
      "    o        cdz",
      "    o        cdz",
      "    f        cdz",
      "    w        cdz",
      "    w        cdz",
      "    w        cdz",
      "    w        cdz"
    ],
    [
      " LMMNMOMMMOMMcdz",
      " LMMNMOMMMOMMcdz",
      " LMMNMOMMMOMMcdz",
      "PLMMNMMMMMMMMcdz",
      "LMMMfhhhhhhhhcdz",
      "LMMMNMMMMMMMMcdz",
      "MMMMNMOMMMOMMcdz",
      "MMMMNMOMMMOMMcdz",
      "MMMMNMOMMMOMMcdz",
      "MMMMNMOMMMOMMcdz",
      "MMMMNMMMMMMMMcdz",
      "MMMMfMMMMMMMMcdz",
      "MMMMNMMMMMMMMcdz",
      "MMMMNMOMMMOMMcdz",
      "MMMMNMOMMMOMMcdz",
      "MMMMNMOMMMQMMcdz"
    ]
  ]
}