{
  "name": "multi_clubhouse1_2_base2",
  "refpalette": "c70cities:multi_clubhouse1_2_base2_palette",
  "xsize": 16,
  "zsize": 16,
  "slices": [
    [
      "vvvvvvvvvvvvvvvv",
      "vvvvvvvvvvvvvvvv",
      "vvvvvvvvvvvvvvvv",
      "vvvvvvvaaaaaaaaa",
      "vvvvvvvaaaaaaaaa",
      "vvvvvvvaaaaaaaaa",
      "vvvvvvvaaaaaaaaa",
      "vvvvvvvaaaaaaaaa",
      "vvvvvvvaaaaaaaaa",
      "vvvvvvvvvvvvvvvv",
      "vvvvvvvvvvvvvvvv",
      "vvvvvvvvvvvvvvvv",
      "vvvvvvvvvvvvvvvv",
      "vvvvvvvvvvvvvvvv",
      "vvvvvvvvvvvvvvvv",
      "vvvvvvvvvvvvvvvv"
    ],
    [
      "vbbbbbbccccccbbb",
      "vbbbbbbccccccbbb",
      "vbbbbbdaaaaaadaa",
      "vbbbbbaefefeffef",
      "vbbbbbafeffffeff",
      "vbbbbbaeffefffff",
      "vbbbbbafeffffffe",
      "vbbbbbaegffeffff",
      "vbbbbbafffeffefe",
      "vbbbbbdaaaaaadaa",
      "vbbbbhibijhiGkkk",
      "vbbbbbihijikiGkk",
      "vbbbbbbbbbbbbbbb",
      "vbbbGGlGGGGGGmGG",
      "vbbbnnonnnnnnonn",
      "vvvvvvvvvvvvvvvv"
    ],
    [
      "vbbb pqrstuuuwpx",
      "vbbb  quuuuuuwpp",
      "vbbb  dyyyyyyd  ",
      "vbbb            ",
      "vbbb   A  A     ",
      "vbbb    A       ",
      "vbbbB  A     A  ",
      "vbbb     AA     ",
      "vbbb B A A A    ",
      "vbbb  d      d  ",
      "vbbb    CD      ",
      "vbbb    CD      ",
      "vbbbEFIIIEIFIIIE",
      "vbbbJJ  JJJJJ JJ",
      "vbbbKLoLLLLLLoLL",
      "vvvvvvvvvvvvvvvv"
    ],
    [
      "vbbb  q      w M",
      "vbbb  q      w  ",
      "vbbb  dNOOOOPd  ",
      "vbbb            ",
      "vbbb            ",
      "vbbb            ",
      "vbbb            ",
      "vbbb            ",
      "vbbb            ",
      "vbbb  d      d  ",
      "vbbb   CD       ",
      "vbbb   CD       ",
      "vbbb            ",
      "vbbbQQ  QQQQQ QQ",
      "vbbbRLoLLRLLLoLL",
      "vvvvvvvvvvvvvvvv"
    ],
    [
      "vbbb  q      w  ",
      "vbbb  q      w  ",
      "vbbb  d      d  ",
      "vbbb            ",
      "vbbb            ",
      "vbbb            ",
      "vbbb            ",
      "vbbb            ",
      "vbbb            ",
      "vbbb  d      d  ",
      "vbbb  CD        ",
      "vbbb  CD        ",
      "vbbb            ",
      "vbbb            ",
      "vbbbLLoLLRLLLoLL",
      "vvvvvvvvvvvvvvvv"
    ],
    [
      "vbbb  S      S  ",
      "vbbb  S      S  ",
      "vbbb  dSSSSSSd  ",
      "vbbb            ",
      "vbbb            ",
      "vbbb            ",
      "vbbb            ",
      "vbbb            ",
      "vbbb            ",
      "vbbb  d      d  ",
      "vbbb CD         ",
      "vbbb CD         ",
      "vbbb            ",
      "vbbb            ",
      "vbbb LoL RL LoRL",
      "vvvvvvvvvvvvvvvv"
    ]
  ]
}