{
  "name": "multi_laboratory1_8_base5",
  "refpalette": "c70cities:multi_laboratory1_8_base5_palette",
  "xsize": 16,
  "zsize": 16,
  "slices": [
    [
      "                ",
      "                ",
      "aaabaaaaaaaabaaa",
      "   c        d   ",
      "                ",
      "                ",
      "                ",
      "                ",
      "  eeeeeeeeeeee  ",
      "  ef         e  ",
      "  eg         e  ",
      "  e          e  ",
      "  e          e  ",
      "  e          e  ",
      "  e      h   e  ",
      "  e      ij  e  "
    ],
    [
      "                ",
      "                ",
      "aaabaaaaaaaabaaa",
      "                ",
      "                ",
      "                ",
      "                ",
      "                ",
      "  eeeeeeeeeeee  ",
      "  ef         e  ",
      "  e k        e  ",
      "  e l        e  ",
      "  e m        e  ",
      "  e n        e  ",
      "  e      o   e  ",
      "  e      ii  e  "
    ],
    [
      "                ",
      "                ",
      "aaabaaaaaaaabaaa",
      "                ",
      "                ",
      "                ",
      "                ",
      "                ",
      "  eeeeeeeeeeee  ",
      "  epq        e  ",
      "  e          e  ",
      "  e o        e  ",
      "  e          e  ",
      "  e          e  ",
      "  e    q o   e  ",
      "  e      igj e  "
    ],
    [
      "                ",
      "                ",
      "aaabaaaaaaaabaaa",
      "                ",
      "                ",
      "                ",
      "                ",
      "                ",
      "  eeeeeeeeeeee  ",
      "  efr        e  ",
      "  eqs     h  e  ",
      "  e tq       e  ",
      "  e          e  ",
      "  e          e  ",
      "  e    r o   e  ",
      "  e      i i e  "
    ],
    [
      "                ",
      "                ",
      "uuubuuuuuuuubuuu",
      "                ",
      "                ",
      "                ",
      "                ",
      "                ",
      "  eeeeeeeeeeee  ",
      "  eff        e  ",
      "  effps   o  e  ",
      "  e trj      e  ",
      "  e   s      e  ",
      "  e    q     e  ",
      "  e    p o   e  ",
      "  e    !fgpi e  "
    ],
    [
      "wwwwwwwwwwwwwwww",
      "wwwwwwwwwwwwwwww",
      "xxxbxxxxxxxxbxxx",
      "yyyyyyyyyyyyyyyy",
      "yyyyyyyyyyyyyyyy",
      "yyyyyyyyyyyyyyyy",
      "yyyyyyyyyyyyyyyy",
      "yyyyyyyyyyyyyyyy",
      "yyAAAAAAAAAAAAyy",
      "yyABBBCBBCCCCAyy",
      "yyACDEFFFFIDCAyy",
      "yyABJpfBBBBJBAyy",
      "yyACJfKBBBBJCAyy",
      "yyABJBffBBBJBAyy",
      "yyABJEFFFFIJBAyy",
      "yyABJBBBBBBJBAyy"
    ]
  ]
}