{
  "name": "multi_gallery_0_ground",
  "refpalette": "c70cities:multi_gallery_0_ground_palette",
  "xsize": 16,
  "zsize": 16,
  "slices": [
    [
      "GGGGGGGGGGGGGGGG",
      "GGGGGGGGGGGGGGGG",
      "GGGaaaaaaaaaaaGG",
      "GGGGbbbbbbbccGGG",
      "GGGGbbbbbbbccGGd",
      "GGGGbbbbbbbccGGd",
      "GGGGbbbbbbbccGGd",
      "GGGGbbbebbbccGGd",
      "GGGGbbbbbbbccGGd",
      "GGGGbbbbbbbccGGd",
      "GGGGbbbbbbbccGGd",
      "GGGGbbbbbbbccGGd",
      "GGGGbbbbbbbccGGd",
      "GGGGbbbbbbbccGGd",
      "GGGGbbbbbbbccGGd",
      "GGGGbbbebbbccGGd"
    ],
    [
      "     f     f f f",
      "f  ff           ",
      "  gaaaaaaaaaaa  ",
      " fhiji k  l  f f",
      "  miji    n   op",
      " fqijr    ns tip",
      "   iji    nu tip",
      "  miji k  n   ip",
      "f hiji    n  tip",
      "  qijr    n   ip",
      " f iji    ns t p",
      "f hiji k  nu tip",
      "   iji    n   ip",
      "  hijr    n  tip",
      "  giji    n   ip",
      " fmiji k  ns tip"
    ],
    [
      "                ",
      "                ",
      "   aaaaaaaaaaa  ",
      "    j  !  l     ",
      "    w     n   x ",
      "    w     n     ",
      "    j     n     ",
      "    j  y  n     ",
      "    j     n     ",
      "    w     n     ",
      "    j     n     ",
      "    j  A  n     ",
      "    B     n     ",
      "    j     n     ",
      "    j     n     ",
      "    w  y  n     "
    ],
    [
      "                ",
      "                ",
      "   aaaaaaaaaaa  ",
      "    j  C  l     ",
      "    j     n     ",
      "    j     n     ",
      "    B     n     ",
      "    B  C  n     ",
      "    j     n     ",
      "    j     n     ",
      "    B     n     ",
      "    B  C  n     ",
      "    j     n     ",
      "    j     n     ",
      "    B     n     ",
      "    B  C  n     "
    ],
    [
      "                ",
      "                ",
      "   aaaaaaaaaaa  ",
      "    j  D  l     ",
      "    w     n     ",
      "    j     n     ",
      "    j     n     ",
      "    j  D  n     ",
      "    B     n     ",
      "    j     n     ",
      "    j     n     ",
      "    j  D  n     ",
      "    B     n     ",
      "    B     n     ",
      "    j     n     ",
      "    j  D  n     "
    ],
    [
      "                ",
      "                ",
      "   aaaaaaaaaaa  ",
      "    jEEEEEF     ",
      "    jEEEEEF     ",
      "    jEIEEIF     ",
      "    jEIEEIF     ",
      "    jEEEEEF     ",
      "    jEEEEEF     ",
      "    jEIEEIF     ",
      "    jEIEEIF     ",
      "    jEEEEEF     ",
      "    jEEEEEF     ",
      "    jEIEEIF     ",
      "    jEIEEIF     ",
      "    jEEEEEF     "
    ]
  ]
}