{
  "name": "multi_condo1_4_ground",
  "refpalette": "c70cities:multi_condo1_4_ground_palette",
  "xsize": 16,
  "zsize": 16,
  "slices": [
    [
      "      aHHHHHHHHH",
      "aaaaaabaaaaaaccG",
      "ddddddbeeeeeabGG",
      "ddddddbeeeeeabGG",
      "ddddddbeeeeeabGG",
      "ddddddbeeeeeaccG",
      "ddddddbaaaaaabGG",
      "ddddddb     bbGG",
      "ddddddb     bbGG",
      "ddddddb     abGG",
      "ddddddf     accG",
      "ddddddgaaaaaabGG",
      "ddddddbbh   abGG",
      "ddddddbbi   abGG",
      "aaaaaaaaaaaaaccG",
      "      aHHHHHHHHH"
    ],
    [
      "      a         ",
      "      aaaaaaacc ",
      "            a   ",
      "      a     j   ",
      "      a     a   ",
      "      a     acc ",
      "      aaaaaaa   ",
      "      a     k   ",
      "      l     k   ",
      "      m     a   ",
      "      a     acc ",
      "      aaaaaaa   ",
      "      a     j   ",
      "      n oi  a   ",
      "      aaaaaaacc ",
      "      a         "
    ],
    [
      "      a         ",
      "      aaaaaaacc ",
      "            a   ",
      "      a     p   ",
      "      a     a   ",
      "      a     acc ",
      "      aaaaaaa   ",
      "      a     k   ",
      "      q     k   ",
      "      r     a   ",
      "      a     acc ",
      "      aaaaaaa   ",
      "      a     p   ",
      "      s  oi a   ",
      "      aaaaaaacc ",
      "      a         "
    ],
    [
      "      a         ",
      "      aaaaaaacc ",
      "      t     a   ",
      "      a     p   ",
      "      a     a   ",
      "      a     acc ",
      "      aaaaaaa   ",
      "      a     k   ",
      "      t     k   ",
      "      t     a   ",
      "      a     acc ",
      "      aaaaaaa   ",
      "      a   tip   ",
      "      t   oba   ",
      "      aaaaaaacc ",
      "      a         "
    ],
    [
      "      a         ",
      "      aaaaaaacc ",
      "      a     a   ",
      "      a     a   ",
      "      a     a   ",
      "      a     acc ",
      "      aaaaaaa   ",
      "      a     k   ",
      "      a     k   ",
      "      a     a   ",
      "      a     acc ",
      "      aaaaaaa   ",
      "      a  th a   ",
      "      a     a   ",
      "      aaaaaaacc ",
      "      a         "
    ],
    [
      "      a         ",
      "      aaaaaaacc ",
      "      a     a   ",
      "      a     a   ",
      "      a     a   ",
      "      a     acc ",
      "      aaaaaaa   ",
      "      a     k   ",
      "      a     k   ",
      "      a     a   ",
      "      a     acc ",
      "      aaaaaaa   ",
      "      a th  a   ",
      "      a     a   ",
      "      aaaaaaacc ",
      "      a     a   "
    ]
  ]
}