{
  "name": "multi_laboratory1_3_base2",
  "refpalette": "c70cities:multi_laboratory1_3_base2_palette",
  "xsize": 16,
  "zsize": 16,
  "slices": [
    [
      "zabccccccccccccc",
      "zab!cccccccccccc",
      "zabccccccccdcccc",
      "zabccccccccccccc",
      "zabccccccccccccc",
      "zabccccccccccccc",
      "zabccccccccccccc",
      "zabccccccccccccc",
      "zabeeffffffccccc",
      "zabccccccccdcccc",
      "zabccccccccccccc",
      "zabccccccccccccc",
      "zabccccccccccccc",
      "zabccccccccccccc",
      "zabccccccccccccc",
      "zabccccccccccccc"
    ],
    [
      "zabg h     i  j ",
      "zabkklm    n  jo",
      "zabp qp   rd  j ",
      "zabst     rn  j ",
      "zabkkp   uwn  jx",
      "zab hy q  An    ",
      "zab  qB lC n    ",
      "zab  DEE   n    ",
      "zab FIIIIJ n    ",
      "zabK      Kdnnnn",
      "zabKL MM NKnL   ",
      "zabKj MM OKn    ",
      "zabKj MM PKn    ",
      "zabKj MMQ Kn  EE",
      "zabKR     Kn   S",
      "zabKKKKKKKKn   T"
    ],
    [
      "zab        i    ",
      "zabU       n  V ",
      "zabW       d    ",
      "zab        n  V ",
      "zabU       X    ",
      "zab        X    ",
      "zab        X    ",
      "zab   YZ   X    ",
      "zab 0IIII1 n    ",
      "zabK      KdnXXX",
      "zabK      Kn    ",
      "zabK2     K3    ",
      "zabK2     K3    ",
      "zabK      K3  4 ",
      "zabK      K3   5",
      "zabKKKKKKKKn    "
    ],
    [
      "zab        i    ",
      "zab        n    ",
      "zab        d    ",
      "zab        n    ",
      "zab        X    ",
      "zab        X    ",
      "zab        X    ",
      "zab        X    ",
      "zab IIIIII n    ",
      "zabK      KdnXXX",
      "zabK 6    Kn    ",
      "zabK      K7    ",
      "zabK   8  K7    ",
      "zabK      K7    ",
      "zabK      K7    ",
      "zabKKKKKKKKn    "
    ],
    [
      "zab        n    ",
      "zab        n    ",
      "zab        d    ",
      "zab        n    ",
      "zab        n    ",
      "zab        n    ",
      "zab        n    ",
      "zab        n    ",
      "zab IIIIII n    ",
      "zabK      Kdnnnn",
      "zabK 9    Kn    ",
      "zabK      Kn    ",
      "zabK   9  Kn    ",
      "zabK @    Kn    ",
      "zabK #  # Kn    ",
      "zabKKKKKKKKn    "
    ],
    [
      "zab$$%$$%$$^&%&&",
      "zab$$*$$%$$^&&&&",
      "zab$$$$$$$$d&&&&",
      "zab$$$$$$$$^&&&&",
      "zab$$%$$%$$^&%&&",
      "zab$$*$$%$$^&%&&",
      "zab$$%$$*$$^&%&&",
      "zab$$%$$%$$^&(&&",
      "zab$$$$$$$$^&&&&",
      "zabK((((((Kd))))",
      "zabK(+-[](K^$$$$",
      "zabK(-[]{(K^$$$$",
      "zabK(-]+}(K^$$$$",
      "zabK(+-]\\(K^$$%%",
      "zabK((((((K^$$%$",
      "zabKKKKKKKK^$$%$"
    ]
  ]
}