{
  "name": "multi_communitycenter_5_ground",
  "refpalette": "c70cities:multi_communitycenter_5_ground_palette",
  "xsize": 16,
  "zsize": 16,
  "slices": [
    [
      "aabcccbaaaaaaaab",
      "aaabbbbaaaGGaaab",
      "aaaaaaaaaGGGGaab",
      "aaaaaaaaaGGGGaad",
      "baaaaaaaaaGGaaad",
      "ebbaaaaaaaaaaaaa",
      "eeebbbaaaaaaaaaa",
      "eeeeebbbbbbbbbbf",
      "eeeeeagggggggggf",
      "eeeeeagggggggggf",
      "eeeeeagggggggggf",
      "aaeeeagggggggggf",
      "haaaaagggggggggf",
      "hhhhaaaaaaaaaaaf",
      "hhhhhhhhhhhhhhhh",
      "hhhhhhhhhhhhhhhh"
    ],
    [
      "  ijkjl        l",
      "   imnn   oo   n",
      "         oppo  n",
      "         oppo   ",
      "          oo    ",
      "               q",
      "   lnn          ",
      " r   nls sttssln",
      " r  rnuw  xx xxn",
      " r  rnyA       n",
      "    nnBB  xx xxn",
      "CC  Dn E       n",
      " CCCCn F  xx xxn",
      "    CCCCCCCCCCCC",
      "                ",
      "                "
    ],
    [
      "  i   l        l",
      "   imnn        n",
      "          II   n",
      "          II    ",
      "                ",
      "                ",
      "   lnn          ",
      " J   nls sttssln",
      " J  KnLL   L MNn",
      " J  Kn L       n",
      "    JnBB  O  PQn",
      "ss   n R       n",
      " CCssn F  SN QTn",
      "    sssCCsssCCss",
      "                ",
      "                "
    ],
    [
      "  i   l U    U l",
      "   imnn        n",
      "               n",
      "                ",
      "                ",
      "                ",
      "   lnn          ",
      " V  Wnls sttssln",
      " V  Xn         n",
      " V  Vn         n",
      "    YnBB       n",
      "ss   n F       n",
      " CCssn F       n",
      "    sssCCsssCCss",
      "                ",
      "                "
    ],
    [
      "  l   l ZU  UZ l",
      "   lmnn        n",
      "               n",
      "                ",
      "l               ",
      " ll             ",
      "   lnn          ",
      "    Wnllllllllln",
      "    Wn         n",
      "     n         n",
      "     n         n",
      "CC   n         n",
      " CCCCn         n",
      "    CCCCCCCCCCCC",
      "                ",
      "                "
    ],
    [
      "  nn00n1ZZ UZZ1n",
      "   nnnn11111111n",
      "      nnnnnnnnnn",
      "      2        2",
      "n     2        2",
      "nnn   2        2",
      "00nnnn2        2",
      "00000nnnnnnnnnnn",
      "00000n000000000n",
      "00000n000000000n",
      "00000n000000000n",
      "CC000n000000000n",
      " CCCCn000000000n",
      "    CCCCCCCCCCCC",
      "                ",
      "                "
    ]
  ]
}