{
  "name": "multi_laboratory1_12_base5",
  "refpalette": "c70cities:multi_laboratory1_12_base5_palette",
  "xsize": 16,
  "zsize": 16,
  "slices": [
    [
      " a          bcdz",
      " a           cdz",
      " a           cdz",
      "ea         affdz",
      "a  gh     aijcdz",
      "a          affdz",
      "             cdz",
      "             cdz",
      "            bcdz",
      "             cdz",
      "           affdz",
      "   kh     almcdz",
      "           affdz",
      "             cdz",
      "            ncdz",
      "            ocdz"
    ],
    [
      " a          bbdz",
      " a           cdz",
      " a           cdz",
      "ea         affdz",
      "a   h     aijcdz",
      "a          affdz",
      "             cdz",
      "             cdz",
      "            bcdz",
      "            bcdz",
      "           affdz",
      "    h     almcdz",
      "           affdz",
      "             ndz",
      "            pndz",
      "            ncdz"
    ],
    [
      " a          bcdz",
      " a           cdz",
      " a           cdz",
      "ea         affdz",
      "a   h     aijcdz",
      "a          affdz",
      "             cdz",
      "             cdz",
      "            bcdz",
      "             cdz",
      "           affdz",
      "    h     almcdz",
      "           affdz",
      "             cdz",
      "            qcdz",
      "            ncdz"
    ],
    [
      " a          bcdz",
      " a          bcdz",
      " a          bcdz",
      "ea         affdz",
      "a   h     aijcdz",
      "a          affdz",
      "             bdz",
      "             bdz",
      "            bbdz",
      "             cdz",
      "           affdz",
      "    h     almcdz",
      "           affdz",
      "             cdz",
      "             cdz",
      "            ncdz"
    ],
    [
      " a          bcdz",
      " a           cdz",
      " a           cdz",
      "ea         affdz",
      "a   h     aijcdz",
      "a          affdz",
      "             cdz",
      "             cdz",
      "            bcdz",
      "             cdz",
      "           affdz",
      "    h     almcdz",
      "           affdz",
      "             cdz",
      "             cdz",
      "            pcdz"
    ],
    [
      " arrrrrrrrrrscdz",
      " arrrrrrrrrrbcdz",
      " arrrrrrrrrrbcdz",
      "earrrrrrrrffffdz",
      "arrrhrrrrrftjcdz",
      "arrrrrrrrrffffdz",
      "rrrrrrrrrrrrbcdz",
      "rrrrrrrrrrrrbcdz",
      "rrrrrrrrrrrrscdz",
      "rrrrrrrrrrrrbcdz",
      "rrrrrrrrrrffffdz",
      "rrrrhrrrrrfumcdz",
      "rrrrrrrrrrffffdz",
      "rrrrrrrrrrrrbcdz",
      "rrrrrrrrrrrrncdz",
      "rrrrrrrrrrrrpcdz"
    ]
  ]
}