{
  "name": "multi_laboratory1_14_ground",
  "refpalette": "c70cities:multi_laboratory1_14_ground_palette",
  "xsize": 16,
  "zsize": 16,
  "slices": [
    [
      "aaaabcccvvddddzd",
      "aaaabcccvvdddzdz",
      "aaaabcccvedzdddd",
      "ffffbcccvedddddz",
      "ffffbcccveedddzz",
      "ffffbcccveeddddz",
      "ffffbcccveddzdzz",
      "ffffbcccevdddzdz",
      "ffffbcccvededdzz",
      "ffffbcccveddddzz",
      "bbbbbcccvdzdddzz",
      "cccccccvvedddzzd",
      "cccccccevedzzzzz",
      "ccccceeeeddzzdzz",
      "ddzddddddzdzzzzz",
      "dzzzzzdzzzzzzzzz"
    ],
    [
      "g   b  h   ij   ",
      "    k  h        ",
      "llllm  h   n    ",
      "opopk  h       n",
      "o o k  h      n ",
      "qrqrk  h        ",
      "    k  h       n",
      "s   b  h     n  ",
      "t   k  h        ",
      "s  um  h      n ",
      "kbkmm  h        ",
      "      h      n  ",
      "     hh    n n  ",
      "hhhhh       n n ",
      "         n w    ",
      "  n        n n  "
    ],
    [
      "    b  x        ",
      "    y  h        ",
      "llllm  h        ",
      "o o k  h        ",
      "o o k  x        ",
      "qAqAk  h        ",
      "    B  h        ",
      "    b  x        ",
      "C   k  x        ",
      "   Dk  h        ",
      "Bbkkm  h        ",
      "      h         ",
      "     hh         ",
      "hxhhh           ",
      "                ",
      "                "
    ],
    [
      "    b  x        ",
      "    y  E        ",
      "llllm  E        ",
      "o o k  x        ",
      "o o k  x        ",
      "qqqqk  x        ",
      "    B  E        ",
      "    b  x        ",
      "C   k  x        ",
      "   Dk  x        ",
      "Bbkkm  E        ",
      "      E         ",
      "     xx         ",
      "xxxEx           ",
      "                ",
      "                "
    ],
    [
      "    b  E        ",
      "    y  x        ",
      "llllm  x        ",
      "o o k  E        ",
      "o o k  x        ",
      "qqqqk  x        ",
      "    B  x        ",
      "    b  E        ",
      "    k  x        ",
      "    k  E        ",
      "Bbkkm  x        ",
      "      E         ",
      "     Ex         ",
      "ExxxE           ",
      "                ",
      "                "
    ],
    [
      "FFFFb  E        ",
      "FFFFk  E        ",
      "llllm  x        ",
      "IIIIk  E        ",
      "JIJIk  E        ",
      "IIIIk  E        ",
      "IIJIk  E        ",
      "IIIIb  x        ",
      "JIJIk  x        ",
      "IIIIk  E        ",
      "kbkkm  E        ",
      "      E         ",
      "     xE         ",
      "xxxEx           ",
      "                ",
      "                "
    ]
  ]
}