{
  "name": "multi_laboratory1_13_base2",
  "refpalette": "c70cities:multi_laboratory1_13_base2_palette",
  "xsize": 16,
  "zsize": 16,
  "slices": [
    [
      "aaaaaaaaaaaaabcz",
      "aaaaaaaaaaaaabcz",
      "aaaadaaaaaaaabcz",
      "aaaaaaaaaaaaabcz",
      "aaaaaaaaaaaaabcz",
      "aaaaaaaaaaaaabcz",
      "aaaaaaaaaaaaabcz",
      "aaaaaaaaaaaaabcz",
      "aaaaaeeeeeeeebcz",
      "aaaadaaaaaaaabcz",
      "aaaaaaaaaaaaabcz",
      "aaaaaaaaaaaaabcz",
      "aaaaaaaaaaaaabcz",
      "aaaaaaaaaaaaabcz",
      "aaaaaaaaaaaaabcz",
      "aaaaaaaaaaaaabcz"
    ],
    [
      " f  g  h  ijfbcz",
      "kf  lm   jn fbcz",
      " f  dop hh jqbcz",
      " f  lr      qbcz",
      "sf  lr i hn fbcz",
      "    l h  j jfbcz",
      "    l      sfbcz",
      "    l       fbcz",
      "    l       tbcz",
      "lllldu  ww  ubcz",
      "   xlu yyyy ubcz",
      "    luAyBByCubcz",
      "    luAyDDyCubcz",
      "EE  lu yyyy ubcz",
      "F   lu  II  ubcz",
      "J   luuuuuuuubcz"
    ],
    [
      "    g        bcz",
      " K  lm      Lbcz",
      "    doM      bcz",
      "    l        bcz",
      " K  N       Lbcz",
      "    N       Kbcz",
      "    N       Kbcz",
      "    N       Lbcz",
      "    l        bcz",
      "NNNldu      ubcz",
      "    lu  OO  ubcz",
      "    Pu O  O ubcz",
      "    PQQORDOQQbcz",
      " S  Pu  OO  ubcz",
      "    Pu      ubcz",
      "    lu!uuuuuubcz"
    ],
    [
      "    g        bcz",
      "    l        bcz",
      "    dT       bcz",
      "    l        bcz",
      "    N        bcz",
      "    N        bcz",
      "    N        bcz",
      "    N        bcz",
      "    lU      Ubcz",
      "NNNldu      ubcz",
      "    lu  OO  ubcz",
      "    Vu O  O ubcz",
      "    Vu OW O ubcz",
      "    Vu  OOQ ubcz",
      "    Vu  Q X ubcz",
      "    luuuQuuuubcz"
    ],
    [
      "    l        bcz",
      "    l        bcz",
      "    dT       bcz",
      "    l       Ybcz",
      "    l        bcz",
      "    l        bcz",
      "    l        bcz",
      "    l        bcz",
      "    l        bcz",
      "lllldu      ubcz",
      "    lu  OO  ubcz",
      "    lu O  O ubcz",
      "    lu OWDO ubcz",
      "    lu  OO  ubcz",
      "    lu    ZQQbcz",
      "    luuuuuuuubcz"
    ],
    [
      "00 01T232242Tbcz",
      "00001T232242Tbcz",
      "0000dT222222Tbcz",
      "00001T222222Tbcz",
      "00301T242242Tbcz",
      "00301T232232Tbcz",
      "00301T232232Tbcz",
      "00301T232252Tbcz",
      "00001T222222Tbcz",
      "6666du      ubcz",
      "22221u  OO  ubcz",
      "22221u O DO ubcz",
      "22221u OBBO ubcz",
      "33221u  OO  ubcz",
      "23221u      ubcz",
      "25221uuuuuuuubcz"
    ]
  ]
}