{
  "name": "multi_laboratory1_6_base1",
  "refpalette": "c70cities:multi_laboratory1_6_base1_palette",
  "xsize": 16,
  "zsize": 16,
  "slices": [
    [
      "aaaaaaaaaaaaaaaa",
      "aaaaaaaaaaaaaaaa",
      "aaaaaaaaaaaaaaaa",
      "aaaaaaaaaaaaaaaa",
      "aaaaaaaaaaaaaaaa",
      "aaaaaaaaaaaaaaaa",
      "aaaaaaaaaaaaaaaa",
      "aaaaabbbbbbaaaaa",
      "aaabbc    dbbaaa",
      "abbb e    e bbba",
      "bf   e    e   fb",
      "b    e    e    b",
      "b    e    g    b",
      "     e    e     ",
      "egeeeeeeeeeeeeee",
      "     e    e     "
    ],
    [
      "h ij k ij h ij h",
      "                ",
      "                ",
      "                ",
      "                ",
      "l               ",
      "mm           lmm",
      "mm nfoooooofp mm",
      " l oof    foo   ",
      " ooo        ooo ",
      "of            fo",
      "o              o",
      "o         q    o",
      "                ",
      "                ",
      "                "
    ],
    [
      "  rs   rs   rs  ",
      "                ",
      "                ",
      "                ",
      "                ",
      "                ",
      "                ",
      "tu  woooooow   x",
      "   oof    foo   ",
      " ooo        ooo ",
      "of            fo",
      "o              o",
      "o              o",
      "                ",
      "                ",
      "                "
    ],
    [
      "                ",
      "                ",
      "                ",
      "                ",
      "                ",
      "                ",
      "                ",
      "    woooooow    ",
      "   oof    foo   ",
      " ooo        ooo ",
      "of            fo",
      "o              o",
      "o              o",
      "                ",
      "                ",
      "                "
    ],
    [
      "                ",
      "                ",
      "                ",
      "                ",
      "                ",
      "                ",
      "                ",
      "     oooooo     ",
      "   oof    foo   ",
      " ooo        ooo ",
      "of            fo",
      "o              o",
      "o              o",
      "                ",
      "                ",
      "                "
    ],
    [
      "yyyyyyyyyyyyyyyy",
      "yyyyyyyyyyyyyyyy",
      "yyyyyyyyyyyyyyyy",
      "yyyyyyyyyyyyyyyy",
      "yyyyyyyyyyyyyyyy",
      "yyyyyyyyyyyyyyyy",
      "yyyyyyyyyyyyyyyy",
      "yyyyyAAAAAAyyyyy",
      "yyyAAB    BAAyyy",
      "yAAA        AAAy",
      "AB            BA",
      "A              A",
      "A              A",
      "                ",
      "                ",
      "                "
    ]
  ]
}