{
  "name": "multi_communitycenter_5_floor1",
  "refpalette": "c70cities:multi_communitycenter_5_floor1_palette",
  "xsize": 16,
  "zsize": 16,
  "slices": [
    [
      "aabbcccccccccccc",
      "aaadbbbccccccccc",
      "aaaaaabdbbbdbbbb",
      "aaaaaaaaaaaaaaab",
      "baaaaaaaaaaaaaab",
      "bbbaaaaaaaaaaaab",
      "ccbdbbaaaaaaaaab",
      "cccccbbdbbbdbbbb",
      "cccccccccccccccc",
      "cccccccccccccccc",
      "cccccccccccccccc",
      "eecccccccccccccc",
      " eeeecccffcccccc",
      "    eeeeeeeeeeee",
      "                ",
      "                "
    ],
    [
      "  gghij         ",
      "   kggglmijllijn",
      "      gkgggkgggo",
      "               o",
      "g              o",
      "ggg            o",
      " pgkgg         o",
      "    lggkgggkggg!",
      "     qrlhqrhmqrh",
      "sl       ~      ",
      "sss      l      ",
      "ttssss        l ",
      " ttttsssssssssss",
      "    tttttttttttt",
      "                ",
      "                "
    ],
    [
      "                ",
      "               n",
      "               n",
      "                ",
      "                ",
      "                ",
      " ~             n",
      "                ",
      "                ",
      "         ~      ",
      "                ",
      "                ",
      "                ",
      "                ",
      "                ",
      "                "
    ],
    [
      "                ",
      "               u",
      "               u",
      "                ",
      "                ",
      "                ",
      "               u",
      "                ",
      "                ",
      "         ~      ",
      "                ",
      "                ",
      "                ",
      "                ",
      "                ",
      "                "
    ],
    [
      "             wwb",
      "             wwb",
      "             wwb",
      "             wwb",
      "             wwb",
      "             wwb",
      "             wwb",
      "             www",
      "             www",
      "         ~      ",
      "                ",
      "                ",
      "                ",
      "                ",
      "                ",
      "                "
    ],
    [
      "                ",
      "                ",
      "                ",
      "                ",
      "                ",
      "                ",
      "                ",
      "                ",
      "                ",
      "         ~      ",
      "                ",
      "                ",
      "                ",
      "                ",
      "                ",
      "                "
    ]
  ]
}