{
  "name": "multi_megatower1_5_floor6",
  "refpalette": "c70cities:multi_megatower1_5_floor6_palette",
  "xsize": 16,
  "zsize": 16,
  "slices": [
    [
      "aaaaaaaa   b    ",
      "aaaaaaaa   c   d",
      "aaaaeaaaaaaeaaaa",
      "ffffgffffffgffff",
      "  h i j  h i j  ",
      "                ",
      "                ",
      "                ",
      "                ",
      "                ",
      "                ",
      "                ",
      "                ",
      "                ",
      "                ",
      "                "
    ],
    [
      " k  l  m        ",
      "       n        ",
      "mmmmemmmmmmeoooo",
      "    g      g    ",
      "  h i j  h i j  ",
      "                ",
      "                ",
      "                ",
      "                ",
      "                ",
      "                ",
      "                ",
      "                ",
      "                ",
      "                ",
      "                "
    ],
    [
      " k  k           ",
      "       p        ",
      "mmmmemmmmmme    ",
      "    g      g    ",
      "  h i j  h i j  ",
      "                ",
      "                ",
      "                ",
      "                ",
      "                ",
      "                ",
      "                ",
      "                ",
      "                ",
      "                ",
      "                "
    ],
    [
      "                ",
      "       p        ",
      "mmmmemmmmmme    ",
      "   hg  jh  gj   ",
      "  h i j  h i j  ",
      "                ",
      "                ",
      "                ",
      "                ",
      "                ",
      "                ",
      "                ",
      "                ",
      "                ",
      "                ",
      "                "
    ],
    [
      "                ",
      "                ",
      "qrqreqrqrqreoooo",
      "   hg  jh  gj   ",
      "  h i j  h i j  ",
      "                ",
      "                ",
      "                ",
      "                ",
      "                ",
      "                ",
      "                ",
      "                ",
      "                ",
      "                ",
      "                "
    ],
    [
      "    stut   s    ",
      "    sttt   s    ",
      "wwwwewwwwwwewwww",
      "jh hgj jh hgj jh",
      "  h i j  h i j  ",
      "                ",
      "                ",
      "                ",
      "                ",
      "                ",
      "                ",
      "                ",
      "                ",
      "                ",
      "                ",
      "                "
    ]
  ]
}