{
  "name": "multi_hospital_1_floor1",
  "refpalette": "c70cities:multi_hospital_1_floor1_palette",
  "xsize": 16,
  "zsize": 16,
  "slices": [
    [
      "  a      bcccccc",
      "  a      bcccccc",
      "  bddddddbeccccc",
      "        fghhhhhh",
      "        fghhhhhh",
      "        fghhhhhh",
      "        fghhhhhh",
      "        fghhhhhh",
      "        fghhhhhh",
      "        fghhhhhh",
      "        fghhhhhh",
      "        fghhhhhh",
      "        fghhhhhh",
      "        fggggggg",
      "        fggggggg",
      "                "
    ],
    [
      "  iccjkccg  lm  ",
      "  iccccccgn !m  ",
      "  boooooobpqpp  ",
      "        fgr  s  ",
      "        fgr  s  ",
      "        fgt  u  ",
      "        fgw  s  ",
      "        fgxxxs  ",
      "        fg  ys  ",
      "        fg AAs  ",
      "        fg   B  ",
      "        fg CCs  ",
      "        fg D s  ",
      "        fgCEEbFF",
      "        fggggg  ",
      "                "
    ],
    [
      "    IIcccg   m  ",
      "    IIcccg   m  ",
      "  bbbbbbbbpJpp  ",
      "        fgK  s  ",
      "        fgK  s  ",
      "        fg   L  ",
      "        fg   s  ",
      "        fgMMMs  ",
      "        fg   s  ",
      "        fg  Ns  ",
      "        fg   O  ",
      "        fg P s  ",
      "        fg   s  ",
      "        fgQEEbFF",
      "        fggggg  ",
      "                "
    ],
    [
      "         M   m  ",
      "        fg   m  ",
      "        fbpppp  ",
      "        fg   s  ",
      "         M   s  ",
      "         M   s  ",
      "         M   s  ",
      "        fg   s  ",
      "        fg   s  ",
      "         M   s  ",
      "         M   s  ",
      "         M   s  ",
      "        fg   s  ",
      "        fg  RbFF",
      "        fggSgg  ",
      "                "
    ],
    [
      "        fT   m  ",
      "        fg   m  ",
      "        fbpppppp",
      "        fg   s  ",
      "        fT   s  ",
      "        fT   s  ",
      "        fT   s  ",
      "        fg   s  ",
      "        fg   s  ",
      "        fT   s  ",
      "        fT   s  ",
      "        fT   s  ",
      "        fg   s  ",
      "        fg   bFF",
      "        fgSSSg  ",
      "                "
    ],
    [
      "        fgvUUm  ",
      "        fgvUUm  ",
      "        fbpppppp",
      "        fg   s  ",
      "        fg   s  ",
      "        fg   s  ",
      "        fg   s  ",
      "        fg   s  ",
      "        fg   s  ",
      "        fg   s  ",
      "        fg   s  ",
      "        fg   s  ",
      "        fg   s  ",
      "        fg   bFF",
      "        fggSgg  ",
      "                "
    ]
  ]
}