{
  "name": "multi_megatower1_0_floor14",
  "refpalette": "c70cities:multi_megatower1_0_floor14_palette",
  "xsize": 16,
  "zsize": 16,
  "slices": [
    [
      "                ",
      "                ",
      "                ",
      "   aaabaaaaaabaa",
      "   acGdddddddddd",
      "   acGddddddddde",
      "   bcGddeddddedd",
      "   acGddddedddfe",
      "   acGdddefeffdd",
      "   acGdeddfffded",
      "   acGddfdeedfdd",
      "   acGdefefeefde",
      "   acGddffffgggg",
      "   bcGddeeffghgg",
      "   acGdddfffgg  ",
      "   acGdddeffgg  "
    ],
    [
      "                ",
      "                ",
      "                ",
      "   aaabaaaaaabaa",
      "   aijk      k  ",
      "   ailm         ",
      "   bino         ",
      "   ailo         ",
      "   ailm         ",
      "   ailo         ",
      "   aijo         ",
      "   ailm         ",
      "   ailo    p    ",
      "   bijm    q hrr",
      "   ailm    s t  ",
      "   aijo    u t  "
    ],
    [
      "                ",
      "                ",
      "                ",
      "   aaabaaaaaabaa",
      "   awx          ",
      "   aiy          ",
      "   bi           ",
      "   awy          ",
      "   aiy          ",
      "   aiy          ",
      "   aix          ",
      "   aiy          ",
      "   awy          ",
      "   bwx       hrr",
      "   aiy       tAA",
      "   aix     u tAB"
    ],
    [
      "                ",
      "                ",
      "                ",
      "   aaabaaaaaCD  ",
      "   aw           ",
      "   ai           ",
      "   bi           ",
      "   a            ",
      "   ai           ",
      "   ai           ",
      "   ai           ",
      "   ai           ",
      "   ai           ",
      "   bw        hrr",
      "   ai        tAA",
      "   ai        tAA"
    ],
    [
      "                ",
      "                ",
      "                ",
      "   aaabaCC      ",
      "   ai           ",
      "   ai           ",
      "   b            ",
      "   a            ",
      "   aw           ",
      "   ai           ",
      "   a            ",
      "   a            ",
      "   a            ",
      "   bw        hrr",
      "   a         E  ",
      "   a         E  "
    ],
    [
      "                ",
      "                ",
      "                ",
      "   CCC          ",
      "   C            ",
      "   C            ",
      "   D            ",
      "   C            ",
      "   C            ",
      "   C            ",
      "   C         F  ",
      "   C        IJKK",
      "   C       L M  ",
      "   D      FJMhhh",
      "   C       N h  ",
      "   C       N h  "
    ]
  ]
}