{
  "name": "multi_laboratory1_1_base3",
  "refpalette": "c70cities:multi_laboratory1_1_base3_palette",
  "xsize": 16,
  "zsize": 16,
  "slices": [
    [
      "vabccccccccccccc",
      "vabccccccccccccc",
      "vabccccccccccccc",
      "vabccccccccccccc",
      "vabccccccccccccc",
      "vabccccccccccccc",
      "vabccccccccdcccc",
      "vabccccccccccccc",
      "vabccccccccccccc",
      "vabccccccccccccc",
      "vabccccccccccccc",
      "vabccccccccccccc",
      "vabcccccccccccce",
      "vabccccccccdccce",
      "vabcccccccccccef",
      "vabccccccccccce "
    ],
    [
      "vabghhh!higj    ",
      "vabh kl kmnj    ",
      "vabok  m   j    ",
      "vaboml     j    ",
      "vabh       p    ",
      "vabg       j    ",
      "vabjjjjjjjjdf  q",
      "vabrs tuwsxj    ",
      "vab   y A  j    ",
      "vabB CCCC  j    ",
      "vabD E AFI j    ",
      "vabDJE  F  j    ",
      "vabK LLLL  j  MN",
      "vabO   P   d  fN",
      "vab        j  Nf",
      "vabB  t    Q  N "
    ],
    [
      "vabghhihRhgj    ",
      "vabS       T    ",
      "vabh       T    ",
      "vabh       j    ",
      "vabh       U    ",
      "vabg VWWWX j    ",
      "vabjjjjjjjjdY   ",
      "vab        j    ",
      "vab        T    ",
      "vab   Z0   T    ",
      "vab  1  2  T    ",
      "vab  3     T    ",
      "vab   45   j   N",
      "vab        d  YN",
      "vab        j  Nf",
      "vab        Q  N "
    ],
    [
      "vabg666666gj    ",
      "vab        7    ",
      "vab8       7    ",
      "vab9       j    ",
      "vabl       7    ",
      "vabg @#$%  j    ",
      "vabjjjjjjjjdY   ",
      "vab        j    ",
      "vab        T    ",
      "vab        T    ",
      "vab        T    ",
      "vab        T    ",
      "vab        j   N",
      "vab        d  YN",
      "vab        j  Nf",
      "vab        Q  N "
    ],
    [
      "vabg      gj    ",
      "vab        j    ",
      "vab        j    ",
      "vab        j    ",
      "vab        j    ",
      "vabg       j    ",
      "vabjjjjjjjjd    ",
      "vab        j    ",
      "vab        j    ",
      "vab        j    ",
      "vab        j    ",
      "vab        j    ",
      "vab        j   N",
      "vab        d   N",
      "vab        j  Nf",
      "vab        j  N "
    ],
    [
      "vabg^^^^^^g7&&&&",
      "vab^*^^^^*^7&(&&",
      "vab^^^^^^^^7&(&&",
      "vab^^^^^^^^7&(&&",
      "vab^*^^^^*^7&(&&",
      "vabg^^^^^^^7&&&&",
      "vabjjjjjjjjd&&&&",
      "vab))))))))7&&&&",
      "vab))))))))7&&&&",
      "vab))++-())7&&&&",
      "vab))+))+))7&&&&",
      "vab))())())7&&&&",
      "vab))+(++))7&&&N",
      "vab))))))))d&&&N",
      "vab))))))))7&&Nf",
      "vab))())())7&&N "
    ]
  ]
}