{
  "name": "multi_laboratory1_10_base3",
  "refpalette": "c70cities:multi_laboratory1_10_base3_palette",
  "xsize": 16,
  "zsize": 16,
  "slices": [
    [
      "vvvvvvvvvvvvvvvv",
      "aaaaaaaaaaaaaaav",
      "bbbbbbbbbbbbbcav",
      "    d========cav",
      "  e d========cav",
      "ddddd========cav",
      "    d========cav",
      "    d========cav",
      "    d========cav",
      "    d========cav",
      "    d========cav",
      " f  d========cav",
      " fggd========cav",
      "hhhhd========cav",
      "hhhhd========cav",
      "dddddiiiiiiiicav"
    ],
    [
      "vvvvvvvvvvvvvvvv",
      "aaaaaaaaaaaaaaav",
      "bbbbbbbbbbbbbcav",
      "  jklmn    opbav",
      "   klq      rbav",
      "lllldst     ubav",
      "    lw      pbav",
      "    lx      rbav",
      "    lx      wbav",
      "    lu     opbav",
      "    ly      rbav",
      "hh  lA     uwbav",
      "ggB l       !bav",
      "    l       Cbav",
      "    D       Cbav",
      "Ellldllllllllcav"
    ],
    [
      "vvvvvvvvvvvvvvvv",
      "aaaaaaaaaaaaaaav",
      "bbbbbbbbbbbbbcav",
      " j  l      opbav",
      "    l        bav",
      "llllds      wbav",
      "    lw     opbav",
      "    lw       bav",
      "    l       wbav",
      "hh  l       pbav",
      "ggB l        bav",
      "  B l       wbav",
      "    l        bav",
      "    l        bav",
      "    F       Ibav",
      "Jllldllllllllcav"
    ],
    [
      "vvvvvvvvvvvvvvvv",
      "aaaaaaaaaaaaaaav",
      "bbbbbbbbbbbbbcav",
      "j   l       sbav",
      "    l        bav",
      "llllds      wbav",
      "hhhhlw      sbav",
      "hhhhl        bav",
      "ggB l       wbav",
      "  B l       sbav",
      "    l        bav",
      "    l       wbav",
      "    l        bav",
      "    l        bav",
      "K   l       Lbav",
      "Mllldllllllllcav"
    ],
    [
      "vvvvvvvvvvvvvvvv",
      "aaaaaaaaaaaaaaav",
      "bbbbbbbbbbbbbcav",
      "    ls      Nbav",
      "e   ls      sbav",
      "llllds      sbav",
      "    ls      Nbav",
      "    lOP     sbav",
      " fgglOP     sbav",
      "  hhlOP     Nbav",
      "    lOP     sbav",
      "    ls      sbav",
      "    lssssssssbav",
      "    l       sbav",
      "    l       sbav",
      "lllldllllllllcav"
    ],
    [
      "vvvvvvvvvvvvvvvv",
      "aaaaaaaaaaaaaaav",
      "bbbbbbbbbbbbbcav",
      "    lQQQQQQQQbav",
      " e  lQQQQQQQQbav",
      "lllldQQQQQQQQbav",
      "    lQQQQQQQQbav",
      "    lQQQQQQQQbav",
      "    lQQQQQQQQbav",
      " f  lQQQQQQQQbav",
      " fgglQQQQQQQQbav",
      "  hhlQQQQQQQQbav",
      "    lQQQQQQQQbav",
      "    lQQQQQQQQbav",
      "    lQQQQQQQQbav",
      "lllldllllllllcav"
    ]
  ]
}