{
  "name": "multi_convenientstore_3_ground",
  "refpalette": "c70cities:multi_convenientstore_3_ground_palette",
  "xsize": 16,
  "zsize": 16,
  "slices": [
    [
      "aaaaaaaaaaaaHHHb",
      "cccccccccccaHHHb",
      "cccccccccccaHHHb",
      "cccccccccccaHHHb",
      "cccccccccccaHHHb",
      "cccccccccccaHHHb",
      "cccccccccccaHHHb",
      "cccccccccccaHHHb",
      "cccccccccccaHHHb",
      "cccccccccccaHHHb",
      "cccccccccccaHHHb",
      "cccccccccccaHHHb",
      "aaaaaaaaaaaaHHHb",
      "HHHHHHHHHHHHHHHb",
      "HHHHHHHHHHHHHHHb",
      "bbbbbbbbbbbbbbbb"
    ],
    [
      "aaaaaaaaaaaaddde",
      "cccccccccccaddde",
      "cccccccccccaddde",
      "cccccccccccaddde",
      "cccccccccccaHHHb",
      "cccccccccccaHHHb",
      "cccccccccccaHHHb",
      "cccccccccccaHHHb",
      "cccccccccccaHHHb",
      "cccccccccccaHHHb",
      "cccccccccccaHHHb",
      "cccccccc!ccaHHHb",
      "aaaaaaaaaaaaHHHb",
      "HHHHHHHHHHHHHHHb",
      "HHHHHHHHHHHHHHHb",
      "HHHHHHHHHHHHHHHb"
    ],
    [
      "fghhhhhiiiij    ",
      "       k  lj    ",
      "       k  mj    ",
      "       k  nj   e",
      "  oppp k qnj   e",
      "  r    s  nj   e",
      " t     uwxwj   e",
      "  yyyyyu       e",
      "  ABCDEy       e",
      "     FIk       e",
      "J    K k  Lj   e",
      " M!JMFNkOPPj   e",
      "jjjjjjjjjjjj   e",
      "  Q   QO O     e",
      "               e",
      "               e"
    ],
    [
      "Rghhhhhiihij    ",
      "       k  Ej    ",
      "       k   j    ",
      "       k   h    ",
      "   ST  k   h    ",
      "  U    VW  h    ",
      " t    XuwYwj    ",
      "  ZZZ 0u   1    ",
      "   ACDDy   1    ",
      "     F2k   1    ",
      "     3 k   j    ",
      " 4556F k  7j    ",
      "jjjjjjjjjjjj    ",
      "  8  O8O        ",
      "                ",
      "                "
    ],
    [
      "gghhhhhiihij    ",
      "       k   j    ",
      "       k   j    ",
      "       k   h    ",
      "       k   h    ",
      "       k   h    ",
      " t45556uwwwj    ",
      "  ZZZ99u   1    ",
      "    ADDy   1    ",
      "     F k   1    ",
      "     F@k   j    ",
      "   J F kO  j    ",
      "jjjjjjjjjjjj    ",
      "88#888#         ",
      "                ",
      "                "
    ],
    [
      "hhhhhhhiihij    ",
      "       k   j    ",
      "       k   j    ",
      "       k  $j    ",
      "       k  $j    ",
      "       k  $j    ",
      "%^&&&&&uwwwj    ",
      "* iiiiiuO  c    ",
      "*    (Dy   c    ",
      "     DDy   c    ",
      "     DDyO Oj    ",
      ")88)88)8888j    ",
      "jjjjjjjjjjjj    ",
      "     O8         ",
      "                ",
      "                "
    ]
  ]
}