{
  "name": "multi_megatower1_4_floor10",
  "refpalette": "c70cities:multi_megatower1_4_floor10_palette",
  "xsize": 16,
  "zsize": 16,
  "slices": [
    [
      "a   bbbbbbbbbbbb",
      "a   bbbbbbbbbbbb",
      "a   bbbbbbbbbbbb",
      "cdeebbbbbbbbbbbb",
      "bbbbfbbbbbbfgggg",
      "bbbbbbbbbbbbgggg",
      "bbbbbbbbbbbbgggg",
      "bbbbbbbbbbbbgggg",
      "bbbbbbbbbbbbgggg",
      "bbbbbbbbbbbbgggg",
      "bbbbbbbbbbbbgggg",
      "hhhhfbbbbbbfgggg",
      "    ibbbbbbbbbbb",
      "    ibbbbbbbbbbb",
      "    ibbbbbbbbbbb",
      "    ibbbbbbbbbbb"
    ],
    [
      "a   jk lml n   o",
      "a   jk lll p    ",
      "a   jq lll r   s",
      "aettju    wr  xy",
      "ABCDfw  EEEfFIFF",
      "    J   oKLr   F",
      "    M    K rN  O",
      "P   Q      rR  F",
      "w   S      rR  O",
      "    M    KTrN  F",
      "w   J   oK rU  O",
      "JJJJfwm EEEfFVFF",
      "    J    KLr    ",
      "    J   oK r   W",
      "    J      X  YZ",
      "    Jo   m 0   1"
    ],
    [
      "a   j      2    ",
      "a   j      3    ",
      "a   j      r    ",
      "ae  j     4r    ",
      "A 56f4  EEEfF7FF",
      "    J      r   F",
      "    M      89  @",
      "    #      89  F",
      "4   $      8   @",
      "    M      89  F",
      "4   J      r   @",
      "    f4   EEfF%FF",
      "    J      r    ",
      "    J      r    ",
      "    J      ^    ",
      "    J      &    "
    ],
    [
      "a   j      *    ",
      "a   j      *    ",
      "a   j      r    ",
      "aeeej     4r    ",
      "A(  f4   m fFFFF",
      "    J      r   F",
      "    M      8   F",
      "    M      89  F",
      "4   M      89  F",
      "    M      8   F",
      "4   J      r   F",
      "    f4     fFFFF",
      "    J      r    ",
      "    J      r    ",
      "    J      *    ",
      "    J      *    "
    ],
    [
      "a   )+++ + -++++",
      "a   )++++++-++++",
      "a   )+[ +[+-+!++",
      "aeee)++++++-++++",
      "AAAAf++++ +fFFFF",
      "    r++++++-]]]]",
      "    r+[++{+-]]]]",
      "    r++++++-]]]]",
      "    r++++++-]]]]",
      "    r+ ++[+-]]]]",
      "    r++++++-]]]]",
      "    f  ++++fFFFF",
      "    r++++++-++++",
      "    r+[ +{+-+[++",
      "    r++++++-++++",
      "    r++++ +-++++"
    ],
    [
      "}   }     \\}    ",
      "}   }    |\\}|| |",
      "}   }|`  `\\} `| ",
      "}e::} ; | '}|| |",
      ",,,,f,,,,,,f,,,,",
      "++++} |   '} |  ",
      "++[+} ` |`\\}\\\\\\\\",
      "++++}|.   \\}| \\|",
      "++++}  | |\\}  \\\\",
      "++{+} `  `\\}  \\|",
      "++++}   | '}||\\\\",
      ",,,,f,,,,,,f,,,,",
      "    } |   '} | |",
      "    } ` |`\\} `  ",
      "    }|!|  \\} |  ",
      "    }|  ||\\}    "
    ]
  ]
}