{
  "name": "multi_condo1_3_floor7",
  "refpalette": "c70cities:multi_condo1_3_floor7_palette",
  "xsize": 16,
  "zsize": 16,
  "slices": [
    [
      "                ",
      "      a         ",
      "bbbbbbacccccccc ",
      "ddddddaeeeeeeec ",
      "fffffffggggggec ",
      "ghhhhhghhhhhgec ",
      "ghhhhhghhhhhgec ",
      "ghhhhhghhhhhgec ",
      "ghhhhhghhhhhgec ",
      "ghhhhhghhhhhgec ",
      "ghhhhhghhhhhgec ",
      "ghhhhhghhhhhgec ",
      "ghhhhhghhhhhgec ",
      "ghhhhhghhhhhgaaa",
      "ffffffffffffgi  ",
      "jjjjjkllllllgi  "
    ],
    [
      "                ",
      "      a         ",
      "bbbbbba         ",
      "      aeeeeeee  ",
      "     gggmmmgge  ",
      "            ge  ",
      "            ge  ",
      "            ge  ",
      "            ge  ",
      "            ge  ",
      "            ge  ",
      "            ge  ",
      "            ge  ",
      "            gaaa",
      "      ggggggg   ",
      "      n  o pq   "
    ],
    [
      "                ",
      "      a         ",
      "      a         ",
      "      a         ",
      "     gggrrrgg   ",
      "            g   ",
      "            g   ",
      "            g   ",
      "            g   ",
      "            g   ",
      "            g   ",
      "            g   ",
      "            g   ",
      "            gaaa",
      "      ggggggg   ",
      "      s  t  b   "
    ],
    [
      "                ",
      "      a         ",
      "      a         ",
      "      a         ",
      "     gggrrrgg   ",
      "            g   ",
      "            g   ",
      "            g   ",
      "            g   ",
      "            g   ",
      "            g   ",
      "            g   ",
      "            g   ",
      "            gaaa",
      "      ggggggg   ",
      "      g  u  b   "
    ],
    [
      "                ",
      "      a         ",
      "      a         ",
      "      awwwwwww  ",
      "gggggggggggggw  ",
      "            gw  ",
      "            gw  ",
      "            gw  ",
      "            gw  ",
      "            gw  ",
      "            gw  ",
      "            gw  ",
      "            gw  ",
      "            gaaa",
      "      ggggggg   ",
      "      g  g  g   "
    ],
    [
      "                ",
      "      a         ",
      "xxxxxxa         ",
      "      ayyyyyyy  ",
      "gggggggggggggy  ",
      "            gy  ",
      "            gy  ",
      "            gy  ",
      "            gy  ",
      "            gy  ",
      "            gy  ",
      "            gy  ",
      "            gy  ",
      "            gaaa",
      "      ggggggg   ",
      "      gAAAAAg   "
    ]
  ]
}