{
  "name": "multi_laboratory1_1_base1",
  "refpalette": "c70cities:multi_laboratory1_1_base1_palette",
  "xsize": 16,
  "zsize": 16,
  "slices": [
    [
      "vabccccccccccccc",
      "vabccccccccccccc",
      "vabccccccccccccc",
      "vabccccccccccccc",
      "vabccccccccccccc",
      "vabccccccccccccc",
      "vabccccccccdcccc",
      "vabccccccccccccc",
      "vabccccccccccccc",
      "vabccccccccccccc",
      "vabccccccccccccc",
      "vabccccccccccccc",
      "vabcccccccccccce",
      "vabccccccccdccce",
      "vabcccccccccccef",
      "vabccccccccccce "
    ],
    [
      "vabghhiiii j    ",
      "vabgk   l  j    ",
      "vabm       j    ",
      "vabgn      o    ",
      "vabg       j    ",
      "vabp  qqq  j    ",
      "vabp rstuw dx   ",
      "vabp rstuw y    ",
      "vabg rtttw y    ",
      "vabg rAtBw y    ",
      "vabm rAtBw y    ",
      "vabg  CCC  y    ",
      "vabgD    EFy  IJ",
      "vabKKKKLKKKd  xJ",
      "vabg    iMiK  Jx",
      "vabm     ENK  J "
    ],
    [
      "vabk  OPQR j    ",
      "vabS       j    ",
      "vabT       j    ",
      "vabR       U    ",
      "vab        j    ",
      "vabS       j    ",
      "vabV  W X  dY   ",
      "vabT  W    y    ",
      "vabZ       y    ",
      "vab0  1 2  y    ",
      "vabS       y    ",
      "vabV       y    ",
      "vabT       y   J",
      "vabKKKK3KKKd  YJ",
      "vabS    4Q y  Jx",
      "vabV       y  J "
    ],
    [
      "vab566     j    ",
      "vab7       j    ",
      "vab        j    ",
      "vab        j    ",
      "vab        j    ",
      "vab8       j    ",
      "vab5       dY   ",
      "vab        y    ",
      "vab        y    ",
      "vab        y    ",
      "vab9       y    ",
      "vab5       y    ",
      "vab!       y   J",
      "vabKKKKKKKKd  YJ",
      "vab        y  Jx",
      "vab5       y  J "
    ],
    [
      "vab        j    ",
      "vab        j    ",
      "vab        j    ",
      "vab        j    ",
      "vab        j    ",
      "vab        j    ",
      "vab   @ @  d    ",
      "vab        y    ",
      "vab        y    ",
      "vab        y    ",
      "vab   # #  y    ",
      "vab        y    ",
      "vab        y   J",
      "vabKKKKKKKKd   J",
      "vab        y  Jx",
      "vab        y  J "
    ],
    [
      "vab$$$$$$$$%$$$$",
      "vab$$^$$$^$%$$$$",
      "vab$$&$$$^$%$$$$",
      "vab$$^$$$^$%$$$$",
      "vab$$^$$$^$%$$$$",
      "vab$$$$$$$$%$$$$",
      "vab$$$***$$d$$$$",
      "vab$$$(*($$%$$$$",
      "vab$$^$$$^$%$$$$",
      "vab$$^(*(^$%$$$$",
      "vab$$^***^$%$$$$",
      "vab$$^$$$^$%$$$$",
      "vab$$$$$$$$%$$$)",
      "vab++++++++d$$$)",
      "vab$$$$$$$$%$$)-",
      "vab$$^$$$^$%$$) "
    ]
  ]
}