{
  "name": "multi_militarybase_0_base1",
  "refpalette": "c70cities:multi_militarybase_0_base1_palette",
  "xsize": 16,
  "zsize": 16,
  "slices": [
    [
      "vvvvvvvvvvvvvvvv",
      "vaaaavaaaaaaavaa",
      "vaaaabaaaaaaabaa",
      "vaaaabaaaaaaabaa",
      "vaaaabaaaaaaabaa",
      "vvbbbvbbbbbbbvbb",
      "vaaaabaaaaaaabaa",
      "vaaaabaaaaaaabaa",
      "vaaaabaaaaaaabaa",
      "vaaaabaaaaaacvdd",
      "vaaaabaaaaaeebee",
      "vaaaabaaaaeeebee",
      "vaaaabaaaaeeebee",
      "vvbbbvbbbbbbbvbb",
      "vaaaaaaaaaeeeb  ",
      "vaaaaaaaaaeeeb  "
    ],
    [
      "vvvvvvvvvvvvvvvv",
      "vffggvh h h hvii",
      "vfggjkl l l lkmn",
      "vfg  o       km ",
      "vgpqgk       kmn",
      "vvkkkvrrrsrrrvtt",
      "v! u w       kmn",
      "vxxy w       kmA",
      "v   Bw   C   kmn",
      "vxx  w   D  cvtt",
      "vE   w          ",
      "vxx  w   F      ",
      "vI J w          ",
      "vvk  v       vKK",
      "vL           K  ",
      "vL           K  "
    ],
    [
      "vvvvvvvvvvvvvvvv",
      "vggppv       vii",
      "vppq k       kMA",
      "vN   O       kP ",
      "vpj  k       km!",
      "vvkkkvrrrQrrrvtt",
      "v    w       kPn",
      "vR   w       kmS",
      "vT   w   C   kmn",
      "vR   w   D   vtt",
      "vT   w   F      ",
      "vRB  w          ",
      "v    w          ",
      "vvk  v       v  ",
      "vL              ",
      "vL              "
    ],
    [
      "vvvvvvvvvvvvvvvv",
      "vppjjv       vii",
      "vpj  k       k  ",
      "v    k       k  ",
      "vj   k       kP ",
      "vvkkkvrrrrrrrvtt",
      "v    w       k  ",
      "v    w       kM ",
      "v    w   C   kPA",
      "v    w   F  Uvtt",
      "v    w          ",
      "v    w          ",
      "v    w          ",
      "vvk  v       v  ",
      "vL              ",
      "vL              "
    ],
    [
      "vvvvvvvvvvvvvvvv",
      "vj  jv       vii",
      "v    k       k  ",
      "v    k       k  ",
      "vj   k       k  ",
      "vvkkkvKKKKKKKvtt",
      "v    K       k  ",
      "v    K       k  ",
      "v    K   F   k  ",
      "v    K       vtt",
      "v    K          ",
      "v    K          ",
      "v    K          ",
      "vvkkkv       vww",
      "v            w  ",
      "v            w  "
    ],
    [
      "vvvvvvvvvvvvvvvv",
      "vVVVVvVVVVVVVvVV",
      "vVWWWbWWWWWWWbWW",
      "vVWWWbWWWWWWWbWW",
      "vVWWWbWWWWWWWbWW",
      "vvbbbvbbbbbbbvbb",
      "vVWWWbWWW WWWbWW",
      "vVWWWbWWWFWWWbWW",
      "vVWWWbWWW WWWbWW",
      "vVWWWbWWW WWWvWW",
      "vVWWWbWWW WWWbWW",
      "vVWWWbWWWWWWWbWW",
      "vVWWWbWWWWWWWbWW",
      "vvbbbvbbbbbbbvbb",
      "vVWWWWWWWWWWWbXX",
      "vVWWWWWWWWWWWbXX"
    ]
  ]
}