{
  "name": "multi_laboratory1_13_base7",
  "refpalette": "c70cities:multi_laboratory1_13_base7_palette",
  "xsize": 16,
  "zsize": 16,
  "slices": [
    [
      "aaaaaaaaaaaaaaaz",
      "aaaaaaaaaaaaaaaz",
      "aaaaaaaaaaaaaaaz",
      "aaaaaaaaaaaaaaaz",
      "aaaaaaaaaaaaaaaz",
      "aaaaaaaaaaaaaaaz",
      "aaaaaaaaaaaaaaaz",
      "aaaaaaaaaaaaaaaz",
      "aaaaaaaaaaaaaaaz",
      "aaaaaaaaaaaaaaaz",
      "aaaaaaaaaaaaaaaz",
      "aaaaaaaaaaaaaaaz",
      "aaaaaaaaaaaaaaaz",
      "aaaaaaaaaaaaaaaz",
      "aaaaaaaaaaaaaaaz",
      "aaaaaaaaaaaaaaaz"
    ],
    [
      "aaaaaaaaaaaaaaaz",
      "aaaaaaaaaaaaaaaz",
      "aaaaaaaaaaaaaaaz",
      "aaaaaaaaaaaaaaaz",
      "aaaaaaaaaaaaaaaz",
      "aaaaaaaaaaaaaaaz",
      "aaaaaaaaaaaaaaaz",
      "aaaaaaaaaaaaaaaz",
      "aaaaaaaaaaaaaaaz",
      "aaaaaaaaaaaaaaaz",
      "aaaaaaaaaaaaaaaz",
      "aaaaaaaaaaaaaaaz",
      "aaaaaaaaaaaaaaaz",
      "aaaaaaaaaaaaaaaz",
      "aaaaaaaaaaaaaaaz",
      "aaaaaaaaaaaaaaaz"
    ],
    [
      "aaaaaaaaaaaaaaaz",
      "aaaaaaaaaaaaaaaz",
      "aaaaaaaaaaaaaaaz",
      "aaaaaaaaaaaaaaaz",
      "aaaaaaaaaaaaaaaz",
      "aaaaaaaaaaaaaaaz",
      "aaaaaaaaaaaaaaaz",
      "aaaaaaaaaaaaaaaz",
      "aaaaaaaaaaaaaaaz",
      "aaaaaaaaaaaaaaaz",
      "aaaaaaaaaaaaaaaz",
      "aaaaaaaaaaaaaaaz",
      "aaaaaaaaaaaaaaaz",
      "aaaaaaaaaaaaaaaz",
      "aaaaaaaaaaaaaaaz",
      "aaaaaaaaaaaaaaaz"
    ],
    [
      "aaaaaaaaaaaaaaaz",
      "aaaaaaaaaaaaaaaz",
      "aaaaaaaaaaaaaaaz",
      "aaaaaaaaaaaaaaaz",
      "aaaaaaaaaaaaaaaz",
      "aaaaaaaaaaaaaaaz",
      "aaaaaaaaaaaaaaaz",
      "aaaaaaaaaaaaaaaz",
      "aaaaaaaaaaaaaaaz",
      "aaaaaaaaaaaaaaaz",
      "aaaaaaaaaaaaaaaz",
      "aaaaaaaaaaaaaaaz",
      "aaaaaaaaaaaaaaaz",
      "aaaaaaaaaaaaaaaz",
      "aaaaaaaaaaaaaaaz",
      "aaaaaaaaaaaaaaaz"
    ],
    [
      "aaaaaaaaaaaaaaaz",
      "aaaaaaaaaaaaaaaz",
      "aaaaaaaaaaaaaaaz",
      "aaaaaaaaaaaaaaaz",
      "aaaaaaaaaaaaaaaz",
      "aaaaaaaaaaaaaaaz",
      "aaaaaaaaaaaaaaaz",
      "aaaaaaaaaaaaaaaz",
      "aaaaaaaaaaaaaaaz",
      "aaaaaaaaaaaaaaaz",
      "aaaaaaaaaaaaaaaz",
      "aaaaaaaaaaaaaaaz",
      "aaaaaaaaaaaaaaaz",
      "aaaaaaaaaaaaaaaz",
      "aaaaaaaaaaaaaaaz",
      "aaaaaaaaaaaaaaaz"
    ],
    [
      "aaaaaaaaaaaaaaaz",
      "aaaaaaaaaaaaaaaz",
      "aaaaaaaaaaaaaaaz",
      "aaaaaaaaaaaaaaaz",
      "aaaaaaaaaaaaaaaz",
      "aaaaaaaaaaaaaaaz",
      "aaaaaaaaaaaaaaaz",
      "aaaaaaaaaaaaaaaz",
      "aaaaaaaaaaaaaaaz",
      "aaaaaaaaaaaaaaaz",
      "aaaaaaaaaaaaaaaz",
      "aaaaaaaaaaaaaaaz",
      "aaaaaaaaaaaaaaaz",
      "aaaaaaaaaaaaaaaz",
      "aaaaaaaaaaaaaaaz",
      "aaaaaaaaaaaaaaaz"
    ]
  ]
}