{
  "name": "multi_laboratory1_0_ground",
  "refpalette": "c70cities:multi_laboratory1_0_ground_palette",
  "xsize": 16,
  "zsize": 16,
  "slices": [
    [
      "zzzzzzzzzzzzzzzz",
      "zzzzazzaazaaabza",
      "zzzzzaavbbbccccc",
      "zazzaabvvccccccc",
      "zzzzaaavbccccccc",
      "azzazabvcccddddd",
      "zzazzzbbcccdeeee",
      "zaazaabvcccdeeee",
      "zazaaabvcccdeeee",
      "zzaazbbvcccdeeee",
      "zazzaavbcccdeee!",
      "zzzaaabbcccdeeee",
      "azazzbbvcccdeeee",
      "zzazaaabcccdeeee",
      "zazazabvcccdeeee",
      "zzzzzabvcccdeeee"
    ],
    [
      "  f  f  f   f   ",
      " ff   g       f ",
      "   f       hhhhh",
      "         hh     ",
      "f i      h      ",
      "    j   h  klmdn",
      " f o    h  n  ~p",
      "   f    h  n   ~",
      "f f     h  d   q",
      "f       h  nr   ",
      "  s     h  nr  q",
      " f      h  nr   ",
      "   f    h  n   q",
      "        h  nr   ",
      "        h  nr   ",
      "f f     h  dtttu"
    ],
    [
      "                ",
      "                ",
      "           hhhhh",
      "         hh     ",
      "  ~      w      ",
      "        h  kxydA",
      "        h  n   q",
      "        h  n    ",
      "        h  d   B",
      "        h  A    ",
      "        h  n   B",
      "        w  n   C",
      "        w  n   B",
      "        h  n    ",
      "        h  A    ",
      "        h  dtttD"
    ],
    [
      "                ",
      "                ",
      "           wwwww",
      "         wE     ",
      "         E      ",
      "        w  knndA",
      "        w  n   F",
      "        w  n   C",
      "        w  d   I",
      "        E  A    ",
      "        w  n   I",
      "        w  n    ",
      "        E  n   I",
      "        w  n    ",
      "        w  A    ",
      "        w  dtttJ"
    ],
    [
      "                ",
      "                ",
      "           EEwEw",
      "         EE     ",
      "         E      ",
      "        E  knndA",
      "        w  n    ",
      "        E  n    ",
      "        w  d   q",
      "        w  A   C",
      "        E  n   q",
      "        E  n    ",
      "        E  n   q",
      "        w  n    ",
      "        E  A    ",
      "        E  dtttt"
    ],
    [
      "                ",
      "                ",
      "           wEEwE",
      "         wE     ",
      "         E      ",
      "        w  knndn",
      "        E  nKKKK",
      "        E  nKKKK",
      "        E  dKKKq",
      "        w  nKKKK",
      "        E  nKKKq",
      "        E  nKKKK",
      "        w  nKKKq",
      "        E  nKKKK",
      "        E  nKKKK",
      "        E  dtttt"
    ]
  ]
}