{
  "name": "multi_laboratory1_1_ground",
  "refpalette": "c70cities:multi_laboratory1_1_ground_palette",
  "xsize": 16,
  "zsize": 16,
  "slices": [
    [
      "azazaabvcccdeeee",
      "zazazabbcccdeeee",
      "zazaazbvcccdeeee",
      "zzzzaabvcccdeeee",
      "zzzazaavcccdeeee",
      "azazaabvcccdeeee",
      "zzzaaavvcccdeeee",
      "zzazzabvcccdeeee",
      "zazzabbbcccdeeee",
      "azazzabvcccdeeee",
      "zzzzaaavcccdeeee",
      "zzzaaaavcccdeeee",
      "azzazzbbcccdeeed",
      "zzazazbvcccdeeed",
      "zzzazabvcccdeedd",
      "zaaazabvcccdeedf"
    ],
    [
      "        g  h    ",
      "i i     g  h j  ",
      "     i  g  hjkk ",
      "i l     g  h kkj",
      " m      g  h    ",
      "        g  h    ",
      "ii      g  d j  ",
      "   i    g  h kk ",
      "i  n    g  hjkkj",
      "   i    g  h    ",
      "        g  h j  ",
      " l      g  h    ",
      "    i   g  h   o",
      "        g  dp  o",
      "i m     q  h  oo",
      "    i   q  h  o "
    ],
    [
      "        g  h    ",
      "        g  h    ",
      "        g  h r  ",
      "  ~     g  h s  ",
      "        g  h    ",
      "        g  h    ",
      "        g  d    ",
      "        g  t  u ",
      "        g  h  w ",
      "        x  h    ",
      "        g  h    ",
      " ~      g  h    ",
      "        g  t    ",
      "        x  dy   ",
      "        A  t    ",
      "        A  t    "
    ],
    [
      "        x  h    ",
      "        B  h    ",
      "        B  h    ",
      "        B  h    ",
      "        B  h    ",
      "        B  h    ",
      "        x  d    ",
      "        B  t    ",
      "        x  h    ",
      "        x  h    ",
      "        x  h    ",
      "        B  h    ",
      "        B  t    ",
      "        B  dy   ",
      "        A  t    ",
      "        A  t    "
    ],
    [
      "        B  h    ",
      "        B  h    ",
      "        B  h    ",
      "        B  h    ",
      "        x  h    ",
      "        B  h    ",
      "        B  d    ",
      "        B  t    ",
      "        B  h    ",
      "        x  h    ",
      "        B  h    ",
      "        x  h    ",
      "        B  t    ",
      "        x  d    ",
      "        A  t    ",
      "        A  t    "
    ],
    [
      "        B  hCCCC",
      "        x  hCCCC",
      "        x  hCCCC",
      "        B  hCCCC",
      "        B  hCCCC",
      "        x  hCCCC",
      "        B  dCCCC",
      "        B  hCCCC",
      "        B  hCCC ",
      "        B  hCC  ",
      "        B  hCC  ",
      "        B  hCC  ",
      "        x  hC   ",
      "        x  dC   ",
      "        A  hC   ",
      "        A  hC   "
    ]
  ]
}