{
  "name": "multi_laboratory1_12_base4",
  "refpalette": "c70cities:multi_laboratory1_12_base4_palette",
  "xsize": 16,
  "zsize": 16,
  "slices": [
    [
      " abbbbbbbbbbbcdz",
      " abbbbbbbbbbbcdz",
      " abbbbbbbbbbbcdz",
      "eabbbbbbbbbbbcdz",
      "abbbfbbbbbbbbcdz",
      "abbbbbbbbbbbbcdz",
      "bbbbbbbbbbbbbcdz",
      "bbbbbbbbbbbbbcdz",
      "bbbbbbbbbbbbbcdz",
      "bbbbbbbbbbbbbcdz",
      "bbbbbbbbbbbbbcdz",
      "bbbbfbbbbbbbbcdz",
      "bbbbbbbbbbbbbcdz",
      "bbbbbbbbbbbbbcdz",
      "bbbbbbbbbbbbbcdz",
      "bbbbbbbbbbbbbcdz"
    ],
    [
      " g  h    ijklmdz",
      " g  n     jklmdz",
      " g  o    pqklmdz",
      "eg  r     jklmdz",
      "ge  f ps p klmdz",
      "gt  r  u  wklmdz",
      "    rxyyy jklmdz",
      "    rAyyyjqklmdz",
      "    r B i wjkkdz",
      "    rCD   j  cdz",
      "    rEFIJIF Kcdz",
      "   efrrrrrrrrcdz",
      "    rLLL LLM!cdz",
      "    o        cdz",
      "    h    i BNcdz",
      "    n     wjNcdz"
    ],
    [
      " g  O      glmdz",
      " g  P      glmdz",
      " g  o      glmdz",
      "eg  r      glmdz",
      "gQ  f      glmdz",
      "g   r      glmdz",
      "    RS T   glmdz",
      "    R S U  glmdz",
      "    R       gkdz",
      "    R       Vcdz",
      "    r       Kcdz",
      "   Qfrrrrrrrrcdz",
      "    r        cdz",
      "    o        cdz",
      "    O        cdz",
      "    P       Wcdz"
    ],
    [
      " g  o      glmdz",
      " g  o      glmdz",
      " g  o      glmdz",
      "eg  r      glmdz",
      "gQ  f      glmdz",
      "g   r      glmdz",
      "    R      glmdz",
      "    R      glmdz",
      "    R       gkdz",
      "    R        cdz",
      "    r       Kcdz",
      "   Qfrrrrrrrrcdz",
      "    r        cdz",
      "    o        cdz",
      "    o        cdz",
      "    o        cdz"
    ],
    [
      " g  r      gXmdz",
      " g  r      gXmdz",
      " g  r      gXmdz",
      "eg  r      gXmdz",
      "g   f      gXmdz",
      "g   r      gXmdz",
      "    r      gXmdz",
      "    r      gXmdz",
      "    r       gkdz",
      "    r       Vcdz",
      "    r  Y  Z 0cdz",
      "    frrrrrrrrcdz",
      "    r        cdz",
      "    r       1cdz",
      "    r        cdz",
      "    r        cdz"
    ],
    [
      " g223445445k6mdz",
      " g223445445k!mdz",
      " g223445447k6mdz",
      "eg223444444k6mdz",
      "g222f444444k6mdz",
      "g2223445445k6mdz",
      "22223445445k6mdz",
      "22223448445k6mdz",
      "222234484454kkdz",
      "2222344444444cdz",
      "2222399999999cdz",
      "2222frrrrrrrrcdz",
      "2222394444449cdz",
      "2252394444449cdz",
      "2252394544549cdz",
      "2252394744749cdz"
    ]
  ]
}