{
  "name": "multi_laboratory1_10_base5",
  "refpalette": "c70cities:multi_laboratory1_10_base5_palette",
  "xsize": 16,
  "zsize": 16,
  "slices": [
    [
      "zzzzzzzzzzzzzzzz",
      "aaaaaaaaaaaaaaaz",
      "bbbbccccccccccaz",
      "    deeeeeeeecaz",
      "    deeeeeeeecaz",
      "fffffeeeeeeeecaz",
      "    feeeeeeeecaz",
      "    fggggggggcaz",
      "    f   h    caz",
      "    f        caz",
      "    f        caz",
      " i  f        caz",
      " ijjf        caz",
      "kkkkf        caz",
      "kkkkf        caz",
      "ddddfddddddddcaz"
    ],
    [
      "zzzzzzzzzzzzzzzz",
      "aaaaaaaaaaaaaaaz",
      "bbbbccccccccccaz",
      "    dglm lm ncaz",
      "    dgo   o ncaz",
      "ddddfg p p  ncaz",
      "    dglm lm ncaz",
      "    dggggggqgcaz",
      "    d    rrrrcaz",
      "    d        caz",
      "    d        caz",
      "kk  d        caz",
      "jjs d        caz",
      "    d        caz",
      "    d        caz",
      "ddddfddddddddcaz"
    ],
    [
      "zzzzzzzzzzzzzzzz",
      "aaaaaaaaaaaaaaaz",
      "bbbbccccccccccaz",
      "    dglm lm  caz",
      "    dgt   t  caz",
      "ddddfg u u   caz",
      "    dglm lm  caz",
      "    dggggggwgcaz",
      "    d        caz",
      "kk  d        caz",
      "jjs d        caz",
      "  s d        caz",
      "    d        caz",
      "    d        caz",
      "    d        caz",
      "ddddfddddddddcaz"
    ],
    [
      "zzzzzzzzzzzzzzzz",
      "aaaaaaaaaaaaaaaz",
      "bbbbccccccccccaz",
      "    dg      xcaz",
      "    dg      ycaz",
      "ddddfg       caz",
      "kkkkdg      ycaz",
      "kkkkdggggggggcaz",
      "jjs d        caz",
      "  s d        caz",
      "    d        caz",
      "    d        caz",
      "    d        caz",
      "    d        caz",
      "    d        caz",
      "ddddfddddddddcaz"
    ],
    [
      "zzzzzzzzzzzzzzzz",
      "aaaaaaaaaaaaaaaz",
      "bbbbccccccccccaz",
      "    dg       caz",
      "h   dg       caz",
      "ddddfg      ycaz",
      "    dg     yycaz",
      "    dggggggggcaz",
      " ijjd        caz",
      "  kkd        caz",
      "    d        caz",
      "    d        caz",
      "    d        caz",
      "    d        caz",
      "    d        caz",
      "ddddfddddddddcaz"
    ],
    [
      "zzzzzzzzzzzzzzzz",
      "aaaaaaaaaaaaaaaz",
      "bbbbccccccccccaz",
      "    dAAAAAAAAcaz",
      " h  dAAAAAAAAcaz",
      "ddddfAAAAAAAAcaz",
      "    dAAAAAAAAcaz",
      "    dddddddddcaz",
      "    dAAAAAAAAcaz",
      " i  dAAAAAAAAcaz",
      " ijjdAAAAAAAAcaz",
      "  kkdAAAAAAAAcaz",
      "    dAAAAAAAAcaz",
      "    dAAAAAAAAcaz",
      "    dAAAAAAAAcaz",
      "ddddfddddddddcaz"
    ]
  ]
}