{
  "name": "multi_condo1_4_base1",
  "refpalette": "c70cities:multi_condo1_4_base1_palette",
  "xsize": 16,
  "zsize": 16,
  "slices": [
    [
      "HHHHHHHHHHHHabbv",
      "HHHaaaaaaaaaabbv",
      "HHHaccdeeeeeabbv",
      "HHHaccdeeeeeabbv",
      "HHHaccdeeeeeabbv",
      "HHHaccdeeeeeabbv",
      "HHHcccdaaaaaabbv",
      "HHHcccd     abbv",
      "HHHcccd     abbv",
      "HHHcccd     abbv",
      "HHHaccf     abbv",
      "HHHaccgaaaaaabbv",
      "HHHaccddh   abbv",
      "HHHaccddi   abbv",
      "HHHaaaaaaaaaabbv",
      "HHHHHHHHHHHHabbv"
    ],
    [
      "            abbv",
      " jjaaaaaaaaaabbv",
      " kla  m     abbv",
      "   a  a     abbv",
      " noa  a  pq abbv",
      "  ra  astuu abbv",
      "   w xaaaaaaabbv",
      "   y  a     abbv",
      "   A  B     abbv",
      "   w  C     abbv",
      "  Da  a     abbv",
      " kla  aaaaaaabbv",
      "   a  a     abbv",
      " noa  E Fi  abbv",
      " jjaaaaaaaaaabbv",
      "            abbv"
    ],
    [
      "            abbv",
      "   aaaaaaaaaabbv",
      "   a  I     abbv",
      "   a  aJ    abbv",
      "   a  a  KL abbv",
      "  ra  assuu abbv",
      "   w  aaaaaaabbv",
      "   M  a     abbv",
      "   N  O     abbv",
      "   w  P     abbv",
      "  Da  a     abbv",
      "   a  aaaaaaabbv",
      "   a  a     abbv",
      "   a  Q  Fi abbv",
      "   aaaaaaaaaabbv",
      "            abbv"
    ],
    [
      "      R     abbv",
      "   aaaaaaaaaabbv",
      "   a  S     abbv",
      "   a  a     abbv",
      "   a  a     abbv",
      "  ra  as TT abbv",
      "  Uw  aaaaaaabbv",
      "  Uw  a     abbv",
      "  Uw  S     abbv",
      "  Uw  S     abbv",
      "  Da  a     abbv",
      "   a  aaaaaaabbv",
      "   a  a   Sdabbv",
      "   a  S   Fdabbv",
      "   aaaaaaaaaabbv",
      "      R     abbv"
    ],
    [
      "     sa     abbv",
      "aaaaaaaaaaaaabbv",
      "   a  a     abbv",
      "   a  a     abbv",
      "   a  a     abbv",
      "   a  as    abbv",
      "   a  aaaaaaabbv",
      "   a  a     abbv",
      "   a  a     abbv",
      "   a  a     abbv",
      "   a  a     abbv",
      "   a  aaaaaaabbv",
      "   a  a  Sh abbv",
      "   a  a     abbv",
      "aaaaaaaaaaaaabbv",
      "     sa     abbv"
    ],
    [
      "eeeeeea     abbv",
      "aaaaaaaaaaaaabbv",
      "eeeaeeas    abbv",
      "eeeaeeas    abbv",
      "eeeaeeas    abbv",
      "eeeaeeasssssabbv",
      "eeeaeeaaaaaaabbv",
      "eeeaeea     abbv",
      "eeeaeea     abbv",
      "eeeaeea     abbv",
      "eeeaeea     abbv",
      "eeeaeeaaaaaaabbv",
      "eeeaeea Sh  abbv",
      "eeeaeea     abbv",
      "aaaaaaaaaaaaabbv",
      "eeeeeea     abbv"
    ]
  ]
}