{
  "name": "multi_condo1_1_floor4",
  "refpalette": "c70cities:multi_condo1_1_floor4_palette",
  "xsize": 16,
  "zsize": 16,
  "slices": [
    [
      "   abcccddefgggg",
      "  hhbbbbbbefgijj",
      "   ab     efgk  ",
      "   ab    lefgk  ",
      "   ak     efgk  ",
      "   ak     efgk  ",
      "   ak     efgk  ",
      "   ak     efgk  ",
      "   ak     efgk  ",
      "   ak     efgk  ",
      "   ak     efgk  ",
      "   ak     efgk  ",
      "   ab     efgk  ",
      "   ab     efgk  ",
      "  hhbbbbbbefgmnn",
      "   abcccddefgggg"
    ],
    [
      "    bopqrrb     ",
      "  hhbbbbbbb  sss",
      "    b    t   s  ",
      "    b        s  ",
      "    u    w   s  ",
      "    u    wx  s  ",
      "    u    wy  s  ",
      "    u    w   s  ",
      "    u    w   s  ",
      "    u    wx  s  ",
      "    u    wy  s  ",
      "    u    w   s  ",
      "    b    w   s  ",
      "    b    wA  s  ",
      "  hhbbbbbbb  sss",
      "    bBCqDDb     "
    ],
    [
      "    b  qEFb     ",
      "  hhbbbbbbb     ",
      "    b   t       ",
      "    b           ",
      "    u           ",
      "    u           ",
      "    u           ",
      "    u           ",
      "    u           ",
      "    u           ",
      "    u           ",
      "    u           ",
      "    b           ",
      "    b     I     ",
      "  hhbbbbbbb     ",
      "    b  qJKb     "
    ],
    [
      "    b  qL b     ",
      "  hhbbbbbbb     ",
      "    bMMt        ",
      "    bMM         ",
      "    u           ",
      "    u           ",
      "    u           ",
      "    u           ",
      "    u           ",
      "    u           ",
      "    u           ",
      "    u           ",
      "    b           ",
      "    b           ",
      "  hhbbbbbbb     ",
      "    b NqOPb     "
    ],
    [
      "    b  q  b     ",
      "  hhbbbbbbb     ",
      "    b           ",
      "    bQQl        ",
      "    u           ",
      "    u           ",
      "    u           ",
      "    u           ",
      "    u           ",
      "    u           ",
      "    u           ",
      "    u           ",
      "    b           ",
      "    b           ",
      "  hhbbbbbbb     ",
      "    b  q  b     "
    ],
    [
      "    bRRRRRb     ",
      "  hhbbbbbbb     ",
      "    b           ",
      "    b   l       ",
      "    S           ",
      "    S  T        ",
      "    S           ",
      "    S           ",
      "    S           ",
      "    S           ",
      "    S  TT       ",
      "    S           ",
      "    b           ",
      "    b           ",
      "  hhbbbbbbb     ",
      "    bRRRRRb     "
    ]
  ]
}