{
  "name": "multi_residential2_0_ground",
  "refpalette": "c70cities:multi_residential2_0_ground_palette",
  "xsize": 16,
  "zsize": 16,
  "slices": [
    [
      "GGGGGGGGGGGGGGGG",
      "GGGGGGGGGGGGGGGG",
      "GGGGGGGGGGGGGGGG",
      "GGGGGGGGGGGGGGGG",
      "GGaaaaaaaaaaaaGG",
      "GGabbbbbbbbbbaGG",
      "GGabbbbbbbbbbaGG",
      "GGabbbbbbbbbbaGG",
      "GGabbbbbbbbbbaGG",
      "GGabbbbbbbbbbaGG",
      "GGabbbbbbbbbbaGG",
      "GGGcddddddddcGGG",
      "GGGcddddddddcGGG",
      "GGGcddddddddcGGG",
      "GGGcddddddddcGGG",
      "GGGcddddddddcGGG"
    ],
    [
      "effffgffffgffffe",
      "f              f",
      "e              f",
      "               f",
      "  hijkllllkjim g",
      "  no   pq   rs f",
      "  nt  u      s f",
      "  j       wxwj f",
      "  y    AA B  s f",
      "  C   kkkkBDEs g",
      "  j    F !IIIj f",
      "  Jc  KLLMMNcJ f",
      "  JcO  PP  QcJ f",
      "  JcR O    NcJ g",
      "  JcSR     TcJ f",
      "  JcUUUVWUUUcJ f"
    ],
    [
      "effffgffffgffffe",
      "f              f",
      "e              f",
      "               f",
      "  lljkllllkjll g",
      "  lX        Yl f",
      "  l          l f",
      "  j       wZwj f",
      "  0    11 B  2 f",
      "  3   4444B  2 g",
      "  j     F5IIIj f",
      "   c        c  f",
      "   6        6  f",
      "   c        c  g",
      "   c7O     8c  f",
      "   cUUU9@UUUc  f"
    ],
    [
      "                ",
      "                ",
      "                ",
      "                ",
      "  lljkllllkjll  ",
      "  l          l  ",
      "  l          l  ",
      "  j       wwwj  ",
      "  n       B  2  ",
      "  n   4444B  2  ",
      "  j      FIIIj  ",
      "   c        c   ",
      "   6        6   ",
      "   c        c   ",
      " iic        cii ",
      " #$cUUUUUUUUc%# "
    ],
    [
      "                ",
      "                ",
      "                ",
      " ^^^^^^^^^^^^^^ ",
      " &jjjjjjjjjjjj& ",
      "  jbbbbbbbbbbj  ",
      "  jbbbbbbbbbbj  ",
      "  jbbbbbbbbbbj  ",
      "  jbbbbbbbbbbj  ",
      "  jbbbbbbbbbbj  ",
      "  jbbbb   Fbbj  ",
      "   cbbbbbbbbc   ",
      "   cbbbbbbbbc   ",
      " iicbbbbbbbbcii ",
      " ##$bbbbbbbb%## ",
      "   *bbbbbbbb(   "
    ],
    [
      "                ",
      "                ",
      "                ",
      "                ",
      " ^^^^^^^^^^^^^^ ",
      " &jkkkkkkkkkkj& ",
      "  j)++-r[]{r}j  ",
      "  j \\\\-  |   j  ",
      "  n ``       s  ",
      "  n    ::::  s  ",
      "  j:   ;    :j  ",
      "   ckk'k--kkc   ",
      " iickk   ,.kcii ",
      " ###$./   .%### ",
      "    *.</ !.(    ",
      "    *.>  ?.(    "
    ]
  ]
}