{
  "name": "multi_megatower1_1_ground",
  "refpalette": "c70cities:multi_megatower1_1_ground_palette",
  "xsize": 16,
  "zsize": 16,
  "slices": [
    [
      "HHHvvvvvvvvvvv  ",
      "HHHvvvvvvvvvvv  ",
      "HHHvvvvvvvvvvvab",
      "HHHvvvvvvvvvvvcc",
      "HHHvvvdvvvvvvdvv",
      "HHHvvvvvvvvvvvvv",
      "HHHeHHHHHHHHHHHH",
      "HHHeHHHHHHHHHHHH",
      "HHHeHHHHHHHHHHHH",
      "HHHeHHHHHHHHHHHH",
      "HHHvvHHHHHHHHHHv",
      "HHHvvHdHHHHHHdHv",
      "HHHvvHHHHHHHHHHv",
      "HHHvvHHHHHHHHHHv",
      "HHHvvHHHHHHHHHHv",
      "HHHvvHHHHHHHHHHv"
    ],
    [
      "   f  g      h  ",
      "   f  g      ha ",
      "   f  g i  i hj ",
      "   f  gkkkkkkh  ",
      "  lmnodppppppdnq",
      "                ",
      "   r            ",
      "   r            ",
      "   r            ",
      "   r            ",
      "               s",
      "  lmt du    ld w",
      "   ftx y       w",
      "   ftA B    x yw",
      "   ftx y    A Bw",
      "   ftA B    x yw"
    ],
    [
      "   f  g      hc ",
      "   f  g      hj ",
      "   f  g      h  ",
      "   f  gCDEF Eh  ",
      "   mIJdKKKKKKdIL",
      "                ",
      "                ",
      "                ",
      "                ",
      "                ",
      "                ",
      "   m  d      d  ",
      "   f            ",
      "   f            ",
      "   f            ",
      "   f            "
    ],
    [
      "   f  g      hjM",
      "   f  g      h  ",
      "   f  g      h  ",
      "   f  g      hNN",
      "   mppdKKKKKKdpp",
      "                ",
      "                ",
      "                ",
      "                ",
      "                ",
      "                ",
      "   m  d      d  ",
      "   f            ",
      "   f            ",
      "   f            ",
      "   f            "
    ],
    [
      "   fm s      s b",
      "   f  s      s M",
      "   f  s      s  ",
      "   f  s      s  ",
      "   mssdssssssdpp",
      "                ",
      "                ",
      "                ",
      "                ",
      "                ",
      "                ",
      "   m  d      d  ",
      "   f            ",
      "   f            ",
      "   f            ",
      "   f            "
    ],
    [
      "   fOOdOOOOOOd  ",
      "   fOOdOOOOOOd b",
      "   fOOdOOOOOOd c",
      "   fOOdOOOOOOdac",
      "  Omdddddddddddd",
      "  OsOOdOOOOOOdOO",
      "  OsOOdOOOOOOdOO",
      "  OsOOdOOOOOOdOO",
      "  OsOOdOOOOOOdOO",
      "  OsOOdOOOOOOdOO",
      "  OsOOdOOOOOOdOO",
      "  Omdddddddddddd",
      "   fOOdOOOOOOdOO",
      "   fOOdOOOOOOdOO",
      "   fOOdOOOOOOdOO",
      "   fOOdOOOOOOdOO"
    ]
  ]
}