{
  "name": "multi_militarybase_4_ground",
  "refpalette": "c70cities:multi_militarybase_4_ground_palette",
  "xsize": 16,
  "zsize": 16,
  "slices": [
    [
      "aaaaaaaaaaaaaaaa",
      "bbbbbbbbbbbbbbba",
      "czzzzzczzzzcccba",
      "cczcczzczczzccba",
      "ccccdddcdddzzzba",
      "ccccccccccczzcba",
      "cccccccccccczzba",
      "cccdddddcddczzba",
      "ccccccccccccczba",
      "ccccccccccccccba",
      "ccdcdddddddczzba",
      "ccccccccccccczba",
      "cccccccccccczzba",
      "ccccdddddcdczcba",
      "ccccccccccccczba",
      "ccccccccccccczba"
    ],
    [
      "                ",
      "bbbbbbbbbbbbbbb ",
      " ef f g f f  gb ",
      "      h   h   b ",
      "     ijiiiji fb ",
      "     ikkkkkif b ",
      "     ikkkkki  b ",
      "     ijiiiji fb ",
      "      l   l   b ",
      "      h   h  gb ",
      "     ijiiijif b ",
      "     ikkkkki fb ",
      "     ikkkkki fb ",
      "     ijiiiji  b ",
      "      l   l  fb ",
      "              b "
    ],
    [
      "                ",
      "bbbbbbbbbbbbbbb ",
      "  e   g      gb ",
      "        m     b ",
      "    nopqrqpst b ",
      "     uwxyABCD b ",
      "     EFxyABCD b ",
      "    nqIqJoIKt b ",
      "        L     b ",
      "        M    gb ",
      "    nNONrPQRt b ",
      "     S xyABCD b ",
      "     TFxyABCD b ",
      "    nPUNJNVWt b ",
      "        X     b ",
      "              b "
    ],
    [
      "                ",
      "bbbbbbbbbbbbbbb ",
      "   e  g      gb ",
      "     Y        b ",
      "    nqZZ012   b ",
      "     3   145  b ",
      "     6   147  b ",
      "    noZZ819   b ",
      "     @        b ",
      "             gb ",
      "    nNZZ01#   b ",
      "     $   1%^  b ",
      "     &   1%*  b ",
      "    nNZZ81(   b ",
      "              b ",
      "              b "
    ],
    [
      "                ",
      "bbbbbbbbbbbbbbb ",
      "    e g      gb ",
      "              b ",
      "       747    b ",
      "     75qx7    b ",
      "     77qx5    b ",
      "       547    b ",
      "              b ",
      "             gb ",
      "       *%*    b ",
      "     **P)*    b ",
      "     ^*N)*    b ",
      "       *%^    b ",
      "              b ",
      "              b "
    ],
    [
      "                ",
      "+++++-[++++++]] ",
      "     {{{{{{{{{] ",
      "             {} ",
      "             {} ",
      "       \\     {} ",
      "       \\     {} ",
      "             {} ",
      "             {} ",
      "             {[ ",
      "       ~     {} ",
      "       \\     {} ",
      "       \\     {} ",
      "             {} ",
      "             {} ",
      "             {} "
    ]
  ]
}