{
  "name": "multi_laboratory1_11_base4",
  "refpalette": "c70cities:multi_laboratory1_11_base4_palette",
  "xsize": 16,
  "zsize": 16,
  "slices": [
    [
      "aaaaaaaaaaaaabcv",
      "aaaaaaaaaaaaabcv",
      "aaaaaaaaaaaaabcv",
      "aaaaaaaaaaaaabcv",
      "aaaaaaaaaaaaabcv",
      "aaaaaaaaaaaaabcv",
      "aaaadaaaaaaaabcv",
      "aaaaaaaaaaaaabcv",
      "aaaaaaaaaaaaabcv",
      "aaaaaaaaaaaaabcv",
      "aaaaaaaaaaaaabcv",
      "aaaaaaaaaaaaabcv",
      "eaaaaaaaaaaaabcv",
      "eaaadaaaaaaaabcv",
      "feaaaaaaaaaaabcv",
      " eaaaaaaaaaaabcv"
    ],
    [
      "    ghiiiiiihbcv",
      "    gj      ibcv",
      "    gk      ibcv",
      "    g       ibcv",
      "    l       ibcv",
      "    gmnnnnnnhbcv",
      "   fdggggggggbcv",
      "o   gpp p p qbcv",
      "    g        bcv",
      "    g  r s  ttcv",
      "    guwwwxytABcv",
      "    gCwwwDEFABcv",
      "IJ  g KLDMNOttcv",
      "If  dPysxDMQqbcv",
      "fI  g   sxDxsbcv",
      " I  R    sxsttcv"
    ],
    [
      "    ghiiiiiihbcv",
      "    S       ibcv",
      "    ST      ibcv",
      "    g       ibcv",
      "    U       ibcv",
      "    gV     Whbcv",
      "   Xdggggggggbcv",
      "    g       qbcv",
      "    S       Ybcv",
      "    S       Itcv",
      "    S ZZ0  IABcv",
      "    S1ZyZ   ABcv",
      "I   g       Qtcv",
      "IX  d       qbcv",
      "fI  g       Ybcv",
      " I  R       Itcv"
    ],
    [
      "    gh222222hbcv",
      "    3       4bcv",
      "    3       5bcv",
      "    g       6bcv",
      "    3       7bcv",
      "    g       hbcv",
      "   Xdggggggggbcv",
      "    g       qbcv",
      "    S        bcv",
      "    S       Itcv",
      "    S      IABcv",
      "    S      8ABcv",
      "I   g       Itcv",
      "IX  d       qbcv",
      "fI  g        bcv",
      " I  R       Itcv"
    ],
    [
      "    gh      hbcv",
      "    g        bcv",
      "    g        bcv",
      "    g        bcv",
      "    g        bcv",
      "    g       hbcv",
      "    dggggggggbcv",
      "    g  9  9 @bcv",
      "    g       Ybcv",
      "    g       Itcv",
      "    g      I#Bcv",
      "    g      I#Bcv",
      "I   g       Itcv",
      "I   d       @bcv",
      "fI  g       Ybcv",
      " I  g       Itcv"
    ],
    [
      "$$$$3%%%%%%%%bcv",
      "$$^$3%&%%%%!%bcv",
      "$$^$3%%%%%%%%bcv",
      "$$^$3%%%%%%%%bcv",
      "$$^$3%&%%%%&%bcv",
      "$$$$3%%%%%%%%bcv",
      "$$$$dggggggggbcv",
      "$$$$3********bcv",
      "$$$$3((((((((bcv",
      "$$$$3((^((^(ttcv",
      "$$$$3((^(()t+Bcv",
      "$$$$3((^((^t+Bcv",
      "I$$$3(()(()(ttcv",
      "I$$$d((((((((bcv",
      "fI$$3((((((((bcv",
      " I$$3((^((^(ttcv"
    ]
  ]
}