{
  "name": "multi_megatower1_7_floor5",
  "refpalette": "c70cities:multi_megatower1_7_floor5_palette",
  "xsize": 16,
  "zsize": 16,
  "slices": [
    [
      "aaab            ",
      "aaac            ",
      "aaa c           ",
      "aaac            ",
      "ddefg           ",
      "ddab            ",
      "dda b           ",
      "ddab            ",
      "ddac            ",
      "dda c           ",
      "ddac            ",
      "ddefg           ",
      "aaab            ",
      "aaa b           ",
      "aaab            ",
      "aaac            "
    ],
    [
      "h ib            ",
      "  ic            ",
      "j i             ",
      "klic            ",
      "mme g           ",
      "nnib            ",
      " oi             ",
      "nnib            ",
      " oic            ",
      "nni             ",
      " oic            ",
      "mmefg           ",
      "pqib            ",
      "  i             ",
      " rib            ",
      "  ic            "
    ],
    [
      "  sb            ",
      "  sc            ",
      "  s             ",
      " tic            ",
      "mme g           ",
      "nnib            ",
      "  i             ",
      "nnib            ",
      "  ic            ",
      "nni             ",
      "  ic            ",
      "mmefg           ",
      "  ib            ",
      "  s             ",
      "  sb            ",
      "  sc            "
    ],
    [
      "  ub            ",
      "  uc            ",
      "  u             ",
      " tic            ",
      "mme g           ",
      "nnib            ",
      "  i             ",
      "nnib            ",
      "  ic            ",
      "nni             ",
      "  ic            ",
      "mmefg           ",
      "  ib            ",
      "  u             ",
      "  ub            ",
      "  uc            "
    ],
    [
      "wwib            ",
      "wwic            ",
      "xwi             ",
      "wwic            ",
      "mme g           ",
      "yyib            ",
      "y!i             ",
      "yyib            ",
      "yAic            ",
      "yyi             ",
      "yAic            ",
      "mmefg           ",
      "wwib            ",
      "xwi             ",
      "wwib            ",
      "wwic            "
    ],
    [
      "BCDb            ",
      "ECDc            ",
      "FCDc            ",
      " CDc            ",
      "IIefg           ",
      "ECDb            ",
      "CCDb            ",
      "ECDb            ",
      "CCDc            ",
      " CDc            ",
      "CCDc            ",
      "IIefg           ",
      "ECDb            ",
      "FCDb            ",
      " CDb            ",
      "ECDc            "
    ]
  ]
}