{
  "name": "multi_condo1_0_floor3",
  "refpalette": "c70cities:multi_condo1_0_floor3_palette",
  "xsize": 16,
  "zsize": 16,
  "slices": [
    [
      "                ",
      "          a     ",
      "  bbbbbbbbaccccc",
      "  bdddddddaeeeee",
      "  bdffffffffgggf",
      "  bdfhhhhhhhhhhh",
      "  bdfhhhhhhhhhhh",
      "  bdfhhhhhhhhhhh",
      "  bdfhhhhhhhhhhh",
      "  bdfhhhhhhhhhhh",
      "  bdfhhhhhhhhhhh",
      "  bdfhhhhhhhhiii",
      "  bdfhhhhhhhhiii",
      " aaafhhhhhhhhiii",
      "   efiiihhjjjjjj",
      "   efiiihhjkllll"
    ],
    [
      "                ",
      "          a     ",
      "          accccc",
      "   ddddddda     ",
      "   dffmmmfffn nf",
      "   dfop  !qr s t",
      "   df     qrs  u",
      "   df  rw qx yyA",
      "   dfyyrs qB qqq",
      "   dfqqqx qC D E",
      "   dfE F  qI q J",
      "   dfJ qB qK qLq",
      "   df MqC qN D O",
      " aaafP qI qN q Q",
      "    fqRqK ffSfff",
      "    T  F  U     "
    ],
    [
      "                ",
      "          a     ",
      "          a     ",
      "          a     ",
      "    ffnnnfffn nf",
      "    f     q     ",
      "    f     qV    ",
      "    f     qW  X ",
      "    f Y   qZ qqq",
      "    fqqq0 q1 2 3",
      "    f  4  q  q56",
      "    f  qZ q7 q8q",
      "    f  q1 q  2  ",
      " aaaf9 q  q  q@ ",
      "    fq#q$ ff%fff",
      "    c^ 4  &     "
    ],
    [
      "                ",
      "          a     ",
      "          a     ",
      "          a     ",
      "    ffnnnfffnnnf",
      "    f     q     ",
      "    f     q     ",
      "    f     q     ",
      "    f     q  qqq",
      "    fqqq  q  q  ",
      "    f  q  q  q !",
      "    f  q  q  qqq",
      "    f  q  q  q  ",
      " aaaf  q  q  q* ",
      "    fqqq  ff(fff",
      "    c) q  +     "
    ],
    [
      "                ",
      "          a     ",
      "          a     ",
      "   -------a     ",
      "   -ffffffffffff",
      "   -f     q     ",
      "   -f     q     ",
      "   -f     q     ",
      "   -f     q  qqq",
      "   -fqqq  q  q  ",
      "   -f  q  q  q  ",
      "   -f  q  q  qqq",
      "   -f  q  q  q  ",
      " aaaf  q  q  q  ",
      "    fqqq  ffffff",
      "    f  q  f     "
    ],
    [
      "                ",
      "          a     ",
      "          a[[[[[",
      "   ]]]]]]]a     ",
      "   ]ffffffffffff",
      "   ]f{{{{{{{{{{{",
      "   ]f{{{{{{{{{{{",
      "   ]f{{{{{{{{{{{",
      "   ]f{{{{{{{{{{{",
      "   ]f{{{{{{{{{{{",
      "   ]f{{{{{{{{{{{",
      "   ]f{{{{{{{{{{{",
      "   ]f{{{{{{{{{{{",
      " aaaf{{{{{{{{{{{",
      "    f{{{{{ffffff",
      "    f{{{{{f     "
    ]
  ]
}