{
  "name": "multi_laboratory1_11_base7",
  "refpalette": "c70cities:multi_laboratory1_11_base7_palette",
  "xsize": 16,
  "zsize": 16,
  "slices": [
    [
      "aaaaaaaaaaaaaaaz",
      "aaabaaaaaaaaaaaz",
      "aaaaaacdaaaaaaaz",
      "aaaaaaccaaaaaaaz",
      "aaaaaaaaaaaaaaaz",
      "aaaaaaaaaaaaaaaz",
      "aaaaaaaaaaaaaaaz",
      "aaaaaaaaaaaaaaaz",
      "aaaaaaaaaaaaaaaz",
      "aaaaaaaaaaaaaaaz",
      "aaaaaaaaaaaaaaaz",
      "aaaaaaaaaaaaaaaz",
      "eaaaaaaaaaaaaaaz",
      "eaaaaaaaaaaaaaaz",
      "eeaaaaaaaaaaaaaz",
      "aeaaaaaaaaaaaaaz"
    ],
    [
      "f ggaaaaaaaaaaaz",
      "aggbaaaaaaaaaaaz",
      "aaahaaaiaaaaaaaz",
      "aaaaaaiiaaaaaaaz",
      "aaaaaaaaaaaaaaaz",
      "aaaaaaaaaaaaaaaz",
      "aaaaaaaaaaaaaaaz",
      "aaaaaaaaaaaaaaaz",
      "aaaaaaaaaaaaaaaz",
      "aaaaaaaaaaaaaaaz",
      "aaaaaaaaaaaaaaaz",
      "aaaaaaaaaaaaaaaz",
      "aaaaaaaaaaaaaaaz",
      "aaaaaaaaaaaaaaaz",
      "jaaaaaaaaaaaaaaz",
      "aaaaaaaaaaaaaaaz"
    ],
    [
      "    kgaaaaaaaaaz",
      "    gaaaaaaaaaaz",
      "aal gahiaaaaaaaz",
      "aaagagmhaaaaaaaz",
      "aaaaaaggaaaaaaaz",
      "aaaahaiaaaaaaaaz",
      "aaaaaaaaaaaaaaaz",
      "aaaaaaaaaaaaaaaz",
      "aaaaaaaaaaaaaaaz",
      "aaaaaaaaaaaaaaaz",
      "aaaaaaaaaaaaaaaz",
      "aaaaaaaaaaaaaaaz",
      "aaaaaaaaaaaaaaaz",
      "aaaaaaaaaaaaaaaz",
      "jaaaaaaaaaaaaaaz",
      "baaaaaaaaaaaaaaz"
    ],
    [
      "       aaaaaaaaz",
      "      gibaaaaaaz",
      "aa     maaaaaaaz",
      "aaa     kgaaaaaz",
      "aaa  f  aaaaaaaz",
      "aaaa  m aaaaaaaz",
      "aaaaaahaaaaaaaaz",
      "aaaaaaaaaaaaaaaz",
      "aaaaaaaaaaaaaaaz",
      "aaaaaaaaaaaaaaaz",
      "aaaaaaaaaaaaaaaz",
      "aaaaaaaaaaaaaaaz",
      "aaaaaaaaaaaaaaaz",
      "aaaaaaaaaaaaaaaz",
      "jaaaaaaaaaaaaaaz",
      "baaaaaaaaaaaaaaz"
    ],
    [
      "aa      aaaaaaaz",
      "aa     nmhaaaaaz",
      "aa       aaaaaaz",
      "aaa       aaaaaz",
      "aaao     aaaaaaz",
      "aaaa   oaaaaaaaz",
      "aaaaaaaaaaaaaaaz",
      "aaaaaaaaaaaaaaaz",
      "aaaaaaaaaaaaaaaz",
      "aaaaaaaaaaaaaaaz",
      "aaaaaaaaaaaaaaaz",
      "aaaaaaaaaaaaaaaz",
      "aaaaaaaaaaaaaaaz",
      "aaaaaaaaaaaaaaaz",
      "jaaaaaaaaaaaaaaz",
      "gaaaaaaaaaaaaaaz"
    ],
    [
      "aaaaaaaaaaaaaaaz",
      "aaaaaaoaaaaaaaaz",
      "aaoaaooooaaaaaaz",
      "aaaaaooooaaaaaaz",
      "aaaaaoooaaaaaaaz",
      "aaaaaaaaaaaaaaaz",
      "aaaaaaaaaaaaaaaz",
      "aaaaaaaaaaaaaaaz",
      "aaaaaaaaaaaaaaaz",
      "aaaaaaaaaaaaaaaz",
      "aaaaaaaaaaaaaaaz",
      "aaaaaaaaaaaaaaaz",
      "aaaaaaaaaaaaaaaz",
      "aaaaaaaaaaaaaaaz",
      "jaaaaaaaaaaaaaaz",
      " aaaaaaaaaaaaaaz"
    ]
  ]
}