{
  "name": "multi_megatower1_4_floor14",
  "refpalette": "c70cities:multi_megatower1_4_floor14_palette",
  "xsize": 16,
  "zsize": 16,
  "slices": [
    [
      "a   bb          ",
      "a   bb          ",
      "a   bb          ",
      "cdeebb          ",
      "bbbbfb  g  h    ",
      "bbbbbb          ",
      "bbbbbbi         ",
      "bbbbbbi         ",
      "bbbbbbi         ",
      "bbbbbbi         ",
      "bbbbbb          ",
      "bbbbfb     h    ",
      "bbbbbb          ",
      "bbbbbb          ",
      "bbbbbb          ",
      "bbbbbb          "
    ],
    [
      "a   j           ",
      "a   j           ",
      "a   j           ",
      "aekkj           ",
      "lmnof      f    ",
      "                ",
      "                ",
      "                ",
      "                ",
      "                ",
      "                ",
      "p   f      h    ",
      "ee  j           ",
      "q   j           ",
      "    j           ",
      "    j           "
    ],
    [
      "a   j           ",
      "a   j           ",
      "a   j           ",
      "ae  j           ",
      "l rsf      h    ",
      "                ",
      "                ",
      "                ",
      "                ",
      "                ",
      "                ",
      "    f      f    ",
      " t  j           ",
      "    j           ",
      "    j           ",
      "    j           "
    ],
    [
      "a   j           ",
      "a   j           ",
      "a   j           ",
      "aeeej           ",
      "lu  f      h    ",
      "                ",
      "                ",
      "                ",
      "                ",
      "                ",
      "                ",
      "    f      f    ",
      "    j           ",
      "    j           ",
      "    j           ",
      "    j           "
    ],
    [
      "a   j           ",
      "a   j           ",
      "a   j           ",
      "aeeej           ",
      "llllf      h    ",
      "                ",
      "                ",
      "                ",
      "                ",
      "                ",
      "                ",
      "    f      h    ",
      "    j           ",
      "    j           ",
      "    j           ",
      "    j           "
    ],
    [
      "f   f           ",
      "f   f           ",
      "f   f           ",
      "fewwf           ",
      "ffffffffhfhhhhhf",
      "    f           ",
      "    f           ",
      "    f           ",
      "    f           ",
      "    f           ",
      "    f           ",
      "fffffffffhfhhfff",
      "    f           ",
      "    f           ",
      "    f           ",
      "    f           "
    ]
  ]
}