{
  "name": "multi_condo1_2_base1",
  "refpalette": "c70cities:multi_condo1_2_base1_palette",
  "xsize": 16,
  "zsize": 16,
  "slices": [
    [
      "vaHHHHHHHHHHHHHH",
      "vaHHHHHHHHHHHHHH",
      "vaHHHHHHHHHHHHHH",
      "vaHHHHHHHHHHHHHH",
      "vaHHHHHHHHHHHHHH",
      "vaHHHHHHHHHHHHHH",
      "vaHHHHHHHHHHHHHH",
      "vaHHHHHHHHHHHHHH",
      "vaHHHHHHHHHHHHHH",
      "vaHHHHHHHHHHHHHH",
      "vaHHHHHHHHHHHHHH",
      "vaHHHHHHHHHHHHHH",
      "vaHHHHHHHHHHHHHH",
      "vaaaaaaaaaaaaaaa",
      "vbbbbbbbbbbbbbbb",
      "vvvvvvvvvvvvvvvv"
    ],
    [
      "va              ",
      "va  cdededededed",
      "va  c           ",
      "va  cfgfgfgfgfgf",
      "va  chhhhhhhhhhh",
      "va  cdededededed",
      "va  c           ",
      "va  cfgfgfgfgfgf",
      "va              ",
      "va              ",
      "vaidedededededed",
      "vai             ",
      "vaifgfgfgfgfgfgf",
      "vaaaaaaaaaaaaaaa",
      "vbbbbbbbbbbbbbbb",
      "vvvvvvvvvvvvvvvv"
    ],
    [
      "va              ",
      "va              ",
      "va              ",
      "va              ",
      "va              ",
      "va              ",
      "va              ",
      "va              ",
      "va              ",
      "va              ",
      "va              ",
      "va              ",
      "va              ",
      "vaaaaaaaaaaaaaaa",
      "vbbbbbbbbbbbbbbb",
      "vvvvvvvvvvvvvvvv"
    ],
    [
      "va              ",
      "va              ",
      "va              ",
      "va              ",
      "va              ",
      "va              ",
      "va              ",
      "va              ",
      "va              ",
      "va              ",
      "va              ",
      "va              ",
      "va              ",
      "vaaaaaaaaaaaaaaa",
      "vbbbbbbbbbbbbbbb",
      "vvvvvvvvvvvvvvvv"
    ],
    [
      "vaj       a     ",
      "vaj       a     ",
      "vajjjjjjjjajjjjj",
      "vaj       a     ",
      "vaj       a     ",
      "vaj       a     ",
      "vaj       a     ",
      "vaj       a     ",
      "vaj       a     ",
      "vaj       a     ",
      "vaj       a     ",
      "vaj       a     ",
      "vajjjjjjjjajjjjj",
      "vaaaaaaaaaaaaaaa",
      "vbbbbbbbbbbbbbbb",
      "vvvvvvvvvvvvvvvv"
    ],
    [
      "vakkkkkkkkakkkkk",
      "vakkkkkkkkakkkkk",
      "vakkkkkkkkakkkkk",
      "vakkkkkkkkakkkkk",
      "vakkkkkkkkakkkkk",
      "vakkkkkkkkakkkkk",
      "vakkkkkkkkakkkkk",
      "vakkkkkkkkakkkkk",
      "vakkkkkkkkakkkkk",
      "vakkkkkkkkakkkkk",
      "vakkkkkkkkakkkkk",
      "vakkkkkkkkakkkkk",
      "vakkkkkkkkakkkkk",
      "vaaaaaaaaaaaaaaa",
      "vbbbbbbbbbbbbbbb",
      "vvvvvvvvvvvvvvvv"
    ]
  ]
}