{
  "name": "multi_factory_0_floor1",
  "refpalette": "c70cities:multi_factory_0_floor1_palette",
  "xsize": 16,
  "zsize": 16,
  "slices": [
    [
      "                ",
      "                ",
      "   aaaaaaaaaaa  ",
      "   abcccbcccba  ",
      "   ac   cdd ca  ",
      "   a     deeda  ",
      "   a      d da  ",
      "   a      !d a  ",
      "   a        da  ",
      "   a  f  d d a  ",
      "   a         a  ",
      "   a         a  ",
      "   a         a  ",
      "   a         a  ",
      "   a      f  a  ",
      "   a         a  "
    ],
    [
      "                ",
      "                ",
      "   ggggggggggg  ",
      "   ahhhhhhhhha  ",
      "   ahhhhhhhhha  ",
      "   ai   i d ia  ",
      "   ac   cd  ca  ",
      "   accccccccca  ",
      "   ac   c   ca  ",
      "   a  j      a  ",
      "   a         a  ",
      "   a         a  ",
      "   a         a  ",
      "   a         a  ",
      "   a  j   j  a  ",
      "   ac   c   ca  "
    ],
    [
      "                ",
      "                ",
      "                ",
      "                ",
      "                ",
      "   gkkkkkkkkkg  ",
      "   gkkkkkkkkkg  ",
      "   ahhhhhhhhha  ",
      "   ahlhlhlhlha  ",
      "   ailjliljlia  ",
      "   ac   c   ca  ",
      "   ac   c   ca  ",
      "   ac   c   ca  ",
      "   ac   c   ca  ",
      "   amljlmljlma  ",
      "   ahlhlhlhlha  "
    ],
    [
      "                ",
      "                ",
      "                ",
      "                ",
      "                ",
      "                ",
      "                ",
      "                ",
      "                ",
      "   gk k k k kg  ",
      "   gklklklklkg  ",
      "   ahlhlhlhlha  ",
      "   ahlhlhlhlha  ",
      "   gklklklklkg  ",
      "   gk k k k kg  ",
      "                "
    ],
    [
      "                ",
      "                ",
      "                ",
      "                ",
      "                ",
      "                ",
      "                ",
      "                ",
      "                ",
      "                ",
      "                ",
      "                ",
      "        ~       ",
      "                ",
      "                ",
      "                "
    ],
    [
      "                ",
      "                ",
      "                ",
      "                ",
      "                ",
      "                ",
      "                ",
      "                ",
      "                ",
      "                ",
      "                ",
      "                ",
      "        ~       ",
      "                ",
      "                ",
      "                "
    ]
  ]
}