{
  "name": "multi_laboratory1_6_base6",
  "refpalette": "c70cities:multi_laboratory1_6_base6_palette",
  "xsize": 16,
  "zsize": 16,
  "slices": [
    [
      "aaaaaaaaaaaaaaaa",
      "aaaaaaaaaaaaaaaa",
      "aaaaaaaaaaaaaaaa",
      "aaaaaaaaaaaaaaaa",
      "aaaaaaaaaaaaaaaa",
      "aaaaaaaaaaaaaaaa",
      "aaaaaaaaaaaaaaaa",
      "aaaaabbbbbbaaaaa",
      "aaabbc    cbbaaa",
      "abbb        bbba",
      "bc~~~~~~~~~~~~cb",
      "b~~~~~~~~~~~~~~b",
      "b~~~~~~~~~~~~~~b",
      " ~~~~~~~~~~~~~~ ",
      " ~~~~~~~~~~~~~~ ",
      " ~~~~~~~~~~~~~~ "
    ],
    [
      "d e fd eg h eg d",
      "   f            ",
      "                ",
      "                ",
      "i              i",
      "jj           kjj",
      "                ",
      "     llllll     ",
      "   llc    cll   ",
      " lll        lll ",
      "lc~~~~~~~~~~~~cl",
      "l~~~~~~~~~~~~~~l",
      "l~~~~~~~~~~~~~~l",
      " ~~~~~~~~~~~~~~ ",
      " ~~~~~~~~~~~~~~ ",
      " ~~~~~~~~~~~~~~ "
    ],
    [
      "  m    mn   mn  ",
      "                ",
      "                ",
      "                ",
      "                ",
      "o            p o",
      "                ",
      "     llllll     ",
      "   llc    cll   ",
      " lll        lll ",
      "lc~~~~~~~~~~~~cl",
      "l~~~~~~~~~q~~~~l",
      "l~~~~~~~~~r~~~~l",
      " ~~~~~~~~~s~~~~ ",
      " ~~~~~~~~~s~~~~ ",
      " ~~~~~~~~~t~~~~ "
    ],
    [
      "                ",
      "                ",
      "                ",
      "                ",
      "                ",
      "                ",
      "                ",
      "     llllll     ",
      "   llc    cll   ",
      " lll        lll ",
      "lc~~~~~~~~~~~~cl",
      "l~~~~~~~~~~~~~~l",
      "l~~~~~~~~~u~~~~l",
      " ~~~~~~~~~~~~~~ ",
      " ~~~~~~~~~~~~~~ ",
      " ~~~~~~~~~~~~~~ "
    ],
    [
      "                ",
      "                ",
      "                ",
      "                ",
      "                ",
      "                ",
      "                ",
      "     llllll     ",
      "   llc    cll   ",
      " lll        lll ",
      "lc~~~~~~~~~~~~cl",
      "l~~~~~~~~~~~~~~l",
      "l~~~~~~~~~w~~~~l",
      " ~~~~~~~~~~~~~~ ",
      " ~~~~~~~~~~~~~~ ",
      " ~~~~~~~~~~~~~~ "
    ],
    [
      "                ",
      "                ",
      "                ",
      "                ",
      "                ",
      "                ",
      "                ",
      "     llllll     ",
      "   llc    cll   ",
      " lll        lll ",
      "lc~~~~~~~~~~~~cl",
      "l~~~~~~~~~~~~~~l",
      "l~~~~~~~~~w~~~~l",
      " ~~~~~~~~~~~~~~ ",
      " ~~~~~~~~~~~~~~ ",
      " ~~~~~~~~~~~~~~ "
    ]
  ]
}