{
  "name": "multi_laboratory1_5_base6",
  "refpalette": "c70cities:multi_laboratory1_5_base6_palette",
  "xsize": 16,
  "zsize": 16,
  "slices": [
    [
      "vvvvvvvvvvvvvvvv",
      "aaaaaaaaaaaaaaaa",
      "bbbbbbbbbbbbbbbb",
      "                ",
      "      c         ",
      "dddddddddddddddd",
      "d    d    d    d",
      "de  ede   d   ed",
      "dddddddddddddddd",
      "dffffd    dffffd",
      "dffffd    dffffd",
      "dfgffd    dffffd",
      "dffffd    dffffd",
      "dfhffd    dffffd",
      "dffffi    dfffjd",
      "ddddjkdddlddddmk"
    ],
    [
      "vvvvvvvvvvvvvvvv",
      "aaaaaaaaaaaaaaaa",
      "bbbbbbbbbbbbbbbb",
      "                ",
      "       c        ",
      "diiiiiiiiiiiiiid",
      "i    i    i    i",
      "ie  eie   i   ei",
      "diiiidiiiidiiiid",
      "ifnnfi    ifnnfi",
      "iohpqi    ir  qi",
      "ir hqi    ir  qi",
      "ighfsi    ir  si",
      "ir tfi    ir  qi",
      "ifuwfi    ifxwfi",
      "digyidiyyidiyyid"
    ],
    [
      "vvvvvvvvvvvvvvvv",
      "aaaaaaaaaaaaaaaa",
      "bbbbbbbbbbbbbbbb",
      "                ",
      "        c       ",
      "diiiiiiiiiiiiiid",
      "i    i    i    i",
      "ie  eie   iA  ei",
      "diiiidiiiidiiiid",
      "ifnhfi    ifnnfi",
      "iB   i    ir  qi",
      "ir  qi    ir  qi",
      "i  hCi    ir  qi",
      "ir  qi    ir  qi",
      "iD Efi    ifFEfi",
      "diI idi  idi  id"
    ],
    [
      "vvvvvvvvvvvvvvvv",
      "aaaaaaaaaaaaaaaa",
      "bbbbbbbbbbbbbbbb",
      "                ",
      "         c      ",
      "diiiiiiiiiiiiiid",
      "i    i    i    i",
      "ie  eie   iA  ei",
      "diiiidiiiidiiiid",
      "ifBJfi    ifnnfi",
      "i   qi    ir  qi",
      "i    i    ir  qi",
      "i   qi    ir  qi",
      "io  qi    ir  qi",
      "i   fi    ifnnfi",
      "diffidiffidiffid"
    ],
    [
      "vvvvvvvvvvvvvvvv",
      "aaaaaaaaaaaaaaaa",
      "bbbbbbbbbbbbbbbb",
      "                ",
      "          c     ",
      "diiiiiiiiiiiiiid",
      "i    i    i    i",
      "ie  eie  eie  ei",
      "diiiidiiiidiiiid",
      "ifJnfi    ifnnfi",
      "ir Kqi    ir Kqi",
      "i   Li    irK qi",
      "i    i    ir Kqi",
      "iM  qi    irKKqi",
      "i  Jfi    ifnnfi",
      "diiiidiiiidiiiid"
    ],
    [
      "vvvvvvvvvvvvvvvv",
      "aaaaaaaaaaaaaaaa",
      "bbbbbbbbbbbbbbbb",
      "                ",
      "           c    ",
      "diiiiiiiiiiiiiid",
      "i    i    i    i",
      "ie  eie  eie  ei",
      "diiiidiiiidiiiid",
      "iffffi    iffffi",
      "ifnnfi    ifnnfi",
      "iN Jfi    ifnnfi",
      "iN  fi    ifnnfi",
      "i  Jfi    ifnnfi",
      "i Nffi    iffffi",
      "diiiidiiiidiiiid"
    ]
  ]
}