{
  "name": "multi_megatower1_3_floor6",
  "refpalette": "c70cities:multi_megatower1_3_floor6_palette",
  "xsize": 16,
  "zsize": 16,
  "slices": [
    [
      "                ",
      "                ",
      "                ",
      "                ",
      "                ",
      "                ",
      "                ",
      "                ",
      "                ",
      "                ",
      "                ",
      "  a b c  a b c  ",
      "ddddeddddddedddd",
      "ffffgffffffgffff",
      "hiiif           ",
      "h   f           "
    ],
    [
      "                ",
      "                ",
      "                ",
      "                ",
      "                ",
      "                ",
      "                ",
      "                ",
      "                ",
      "                ",
      "                ",
      "  a b c  a b c  ",
      "    e      e    ",
      "jklmgnnnnnngnnnn",
      "hiiio           ",
      "h   o           "
    ],
    [
      "                ",
      "                ",
      "                ",
      "                ",
      "                ",
      "                ",
      "                ",
      "                ",
      "                ",
      "                ",
      "                ",
      "  a b c  a b c  ",
      "    e      e    ",
      "j   g      g    ",
      "hiiio           ",
      "h   o           "
    ],
    [
      "                ",
      "                ",
      "                ",
      "                ",
      "                ",
      "                ",
      "                ",
      "                ",
      "                ",
      "                ",
      "                ",
      "  a b c  a b c  ",
      "   ae  ca  ec   ",
      "j   g      g    ",
      "hiiio           ",
      "h   o           "
    ],
    [
      "                ",
      "                ",
      "                ",
      "                ",
      "                ",
      "                ",
      "                ",
      "                ",
      "                ",
      "                ",
      "                ",
      "  a b c  a b c  ",
      "   ae  ca  ec   ",
      "j   gnnnnnngnnnn",
      "hiiio           ",
      "h   o           "
    ],
    [
      "                ",
      "                ",
      "                ",
      "                ",
      "                ",
      "                ",
      "                ",
      "                ",
      "                ",
      "                ",
      "                ",
      "  a b c  a b c  ",
      "ca aec ca aec ca",
      "ppppgppppppgpppp",
      "qrrrqsss   q    ",
      "q   qsts   q    "
    ]
  ]
}