{
  "name": "multi_condo1_3_base2",
  "refpalette": "c70cities:multi_condo1_3_base2_palette",
  "xsize": 16,
  "zsize": 16,
  "slices": [
    [
      "vvvvvvvvvvvvvvvv",
      "aaaaaaaaaaaaaaav",
      "bbbbbbbbbbbbbaav",
      "bcccccbHHHHHbaav",
      "HcccccbHHHHHbaav",
      "HcccccbbbbHHbaav",
      "HcccccbccbHHbaav",
      "bcccccbccbHHbaav",
      "bcccccbccbHHbaav",
      "bcccccbccbHHbaav",
      "bcccccbccbHHbaav",
      "bcccccbccbHHbaav",
      "bcccccbccbHHbaav",
      "bcccccbccbHHbaav",
      "bbbbbbbbbbHHbaav",
      "HHHHHHHHHHHHbaav"
    ],
    [
      "vvvvvvvvvvvvvvvv",
      "aaaaaaaaaaaaaaav",
      "bbbbbbbbbbbbbaav",
      "bdddedbHHHHHbaav",
      "      bHHHHHbaav",
      "     ebbbbHHbaav",
      "    dfg hbHHbaav",
      "b    ibjhbHHbaav",
      "bk    b lbHHbaav",
      "bk  mibnobHHbaav",
      "b   mib hbHHbaav",
      "bk   ibhpbHHbaav",
      "bk    bphbHHbaav",
      "b!eqribppbssbaav",
      "bbbbbbbbbbssbaav",
      "            baav"
    ],
    [
      "vvvvvvvvvvvvvvvv",
      "aaaaaaaaaaaaaaav",
      "bbbbbbbbbbbbbaav",
      "b  d tbHHHHHbaav",
      "u     bHHHHHbaav",
      "u     bbbbHHbaav",
      "u   mwx hbHHbaav",
      "b     b  bHHbaav",
      "bky  wb  bHHbaav",
      "bky d b  bssbaav",
      "bA  d b obssbaav",
      "bky  ebB b  baav",
      "bky  wbChb  baav",
      "bAAA  bhpb  baav",
      "bbbbbbbbbb  baav",
      "            baav"
    ],
    [
      "vvvvvvvvvvvvvvvv",
      "aaaaaaaaaaaaaaav",
      "bbbbbbbbbbbbbaav",
      "be    bHHHHHbaav",
      "u     bHHHHHbaav",
      "u     bbbbssbaav",
      "u     b obssbaav",
      "b    eb  b  baav",
      "bD    b  b  baav",
      "bD    b  b  baav",
      "b     b  b  baav",
      "bD    b  b  baav",
      "bD    b  b  baav",
      "b  A eb Eb  baav",
      "bbbbbbbbbb  baav",
      "      F     baav"
    ],
    [
      "vvvvvvvvvvvvvvvv",
      "aaaaaaaaaaaaaaav",
      "bbbbbbbbbbbbbaav",
      "bAAAAAb     baav",
      "I    Ab     baav",
      "I    Abssb  baav",
      "I    Abssb  baav",
      "b    AbHHb  baav",
      "b    AbHHb  baav",
      "b    AbHHb  baav",
      "b    AbHHb  baav",
      "b    AbHHb  baav",
      "b    AbHHb  baav",
      "bAAAAAbHHb  baav",
      "bbbbbAbbbb  baav",
      "     Ab     baav"
    ],
    [
      "vvvvvvvvvvvvvvvv",
      "aaaaaaaaaaaaaaav",
      "bbbbbbbbbbbbbaav",
      "JJJJJJb     baav",
      "JJJJJJb     baav",
      "JJJJJJb  b  baav",
      "JJJJJJb  b  baav",
      "JJJJJJb  b  baav",
      "JJJJJJb  b  baav",
      "JJJJJJbssb  baav",
      "JJJJJJbssb  baav",
      "JJJJJJbHHb  baav",
      "JJJJJJbHHb  baav",
      "JJJJJJbHHb  baav",
      "JJJJJJbbbbbbbaav",
      "JJJJJJb     baav"
    ]
  ]
}