{
  "name": "multi_residential2_1_ground",
  "refpalette": "c70cities:multi_residential2_1_ground_palette",
  "xsize": 16,
  "zsize": 16,
  "slices": [
    [
      "GGGGabaccGcbGGGG",
      "GGGGcGGccabGGGGG",
      "GGGGGGcbcbcbGGGG",
      "GGGGcbGcabbcGGGG",
      "GGddddddddddddGG",
      "ddddddddddddddGG",
      "dddddHHHeeedddGG",
      "dddddHfghijdddGG",
      "dddddHHHklmdddGG",
      "dddddHHHnopdddGG",
      "ddddddddddddddGG",
      "GGddddddddddddGG",
      "GGGGGGGGGGGGGGGG",
      "GGGGGGGGGGGGGGGG",
      "GGGGGGGGGGGGGGGG",
      "GGGGGGGGGGGGGGGG"
    ],
    [
      "  qr     st rq u",
      "  qrt s    srq u",
      "  qr  t     rq w",
      "  qr s   s trq u",
      " xvvvvv  vvvvv u",
      "x v        yAv u",
      "            Bv w",
      "            Cv u",
      "            Cv u",
      " x          Dv u",
      "E v       FIJv u",
      "  vvvvvvvvvvvv w",
      "               u",
      "K              u",
      "u              u",
      "KuuuuwuuuuwuuuuK"
    ],
    [
      "   r        r  u",
      "   r        r  u",
      "   r        r  w",
      "   r        r  u",
      "  vvvvv  vvvvv u",
      "  v         Av u",
      "  L         Mv w",
      "  L         Nv u",
      "  L         Ov u",
      "  L          v u",
      "  v         Pv u",
      "  vvvvvvvvvvvv w",
      "               u",
      "K              u",
      "u              u",
      "KuuuuwuuuuwuuuuK"
    ],
    [
      "  Qr        rR  ",
      "  Qr        rR  ",
      "  Qr        rR  ",
      "  Qr        rR  ",
      "  vvvvvvvvvvvv  ",
      "  v          v  ",
      "  L          v  ",
      "  L          v  ",
      "  L          v  ",
      "  L        S v  ",
      "  v        TPv  ",
      "  vvUUUvvUUUvv  ",
      "                ",
      "                ",
      "                ",
      "                "
    ],
    [
      "   QVVVVVVVVR   ",
      "   QVVVVVVVVR   ",
      "   QVVVVVVVVR   ",
      "   QVVVVVVVVR   ",
      "  vvvvvvvvvvvv  ",
      "  v          v  ",
      "  vW         v  ",
      "  vW         v  ",
      "  vW         v  ",
      "  vW         v  ",
      "  v         Pv  ",
      "  vvvvvvvvvvvv  ",
      "                ",
      "                ",
      "                ",
      "                "
    ],
    [
      "    QXY  ZXR    ",
      "    QX0123XR    ",
      "    QX0  4XR    ",
      "    Q555555R    ",
      "  vvvvvvvvvvvv  ",
      "  v6666666666v  ",
      "  v6666666666v  ",
      "  v6666666666v  ",
      "  v6666666666v  ",
      "  v6666666666v  ",
      "  v6666666666v  ",
      "  vvvvvvvvvvvv  ",
      "                ",
      "                ",
      "                ",
      "                "
    ]
  ]
}