{
  "name": "multi_megatower1_4_floor1",
  "refpalette": "c70cities:multi_megatower1_4_floor1_palette",
  "xsize": 16,
  "zsize": 16,
  "slices": [
    [
      "a   bccccdcefghh",
      "a   bccccdcefghh",
      "a   bccccdcefghh",
      "ijkkbccccdcefghh",
      "bbbblcccccclfhhh",
      "bbbbbbbbbbbefhhh",
      "bbbbbbbbbbbefhhh",
      "bbbbbbbbbbbefhhh",
      "bbbbbbbbbbbefhhh",
      "bbbbbbbbbbbefhhh",
      "bbbbbbbbbbbefhhh",
      "bbbblbbbbbblfhhh",
      "bbbbbbbbbbbefhhh",
      "bbbbbbbbbbbefhhh",
      "bbbbbbbbbbbefhhh",
      "bbbmbbbbbbbefhhh"
    ],
    [
      "a   a n n       ",
      "a   aopop       ",
      "a   a   n       ",
      "akqqarr n       ",
      "stuwlxxyx  l    ",
      "    A           ",
      "    B  CD       ",
      "E   F  I        ",
      "E   J  CD       ",
      "    B           ",
      "   KA  CD       ",
      "  LLl  I   l    ",
      "   KA  CD       ",
      "   MA           ",
      "    A  CD       ",
      " NNOA  I    PQ  "
    ],
    [
      "a   a n nR      ",
      "a   aSpSpR      ",
      "a   a   nR      ",
      "ak  a   n       ",
      "s TUlxxVx  l    ",
      "    A           ",
      "    B           ",
      "    W  I        ",
      "    X           ",
      "    B           ",
      "   YA           ",
      "   Zl  I   l    ",
      "   YA           ",
      "    A           ",
      "    A           ",
      "    A  I        "
    ],
    [
      "a   a n n0      ",
      "a   apppp0      ",
      "a   a   n0      ",
      "akkka   n       ",
      "s1  lxx2x  l    ",
      "    A           ",
      "    B           ",
      "    B  3        ",
      "    B           ",
      "    B           ",
      "    A           ",
      "    l  4   l    ",
      "    A           ",
      "    A           ",
      "    A           ",
      "    A  3        "
    ],
    [
      "a   a5p5p       ",
      "a   apppp       ",
      "a   a555p       ",
      "akkka555p       ",
      "sssslxxxx  l    ",
      "    6           ",
      "    7 898       ",
      "    6 9@9       ",
      "    7 898       ",
      "    6           ",
      "   #7 898       ",
      "6767l 9@9  l    ",
      "   #6 898       ",
      "    7           ",
      "    6 898       ",
      "    7 9@9       "
    ],
    [
      "$  $%   ^       ",
      "$  $%&! ^       ",
      "$  $%&& ^       ",
      "$$$$%   ^       ",
      "****l^^^^  l    ",
      "((((%           ",
      "((((%           ",
      "((((%           ",
      "((((%           ",
      "((((%           ",
      "((((%           ",
      "****l      l    ",
      "((((%           ",
      "((((%           ",
      "((((%           ",
      "((((%           "
    ]
  ]
}