{
  "name": "multi_laboratory1_13_base3",
  "refpalette": "c70cities:multi_laboratory1_13_base3_palette",
  "xsize": 16,
  "zsize": 16,
  "slices": [
    [
      "aaaaaaaaaaaaabcv",
      "aaaaaaaaaaaaabcv",
      "aaaadaaaaaaaabcv",
      "aaaaaaaaaaaaabcv",
      "aaaaaaaaaaaaabcv",
      "aaaaaaaaaaaaabcv",
      "aaaaaaaaaaaaabcv",
      "aaaaaaaaaaaaabcv",
      "aaaaaaaaaaaaabcv",
      "aaaadaaaaaaaabcv",
      "aaaaaaaaaaaaabcv",
      "aaaaaaaaaaaaabcv",
      "aaaaaaaaaaaaabcv",
      "aaaaaaaaaaaaabcv",
      "aaaaaaaaaaaaabcv",
      "aaaaaaaaaaaaabcv"
    ],
    [
      "ef  g  h  i jbcv",
      " f  kl   hm jbcv",
      " f  dno    pqbcv",
      "rs  kth     qbcv",
      " f  kt i hi jbcv",
      "    k h  p pjbcv",
      "    k     mujbcv",
      "    k  m    jbcv",
      "    kl  www  bcv",
      "kkkkdno www  bcv",
      "   xky  www  bcv",
      "    kyypwAA  bcv",
      "    kyym B   bcv",
      "CC  kyp      bcv",
      "D   k!yE  E  bcv",
      "F   kyy     Ibcv"
    ],
    [
      "    g        bcv",
      " J  kl      Jbcv",
      " J  dnK      bcv",
      "    k        bcv",
      "    L       Mbcv",
      "    L       Jbcv",
      "    L       Jbcv",
      "    L       Mbcv",
      "    kl  NNN  bcv",
      "LLLkdnK NNN  bcv",
      "    ky  NNN  bcv",
      "    Oy  PAQ  bcv",
      "    Oy   R   bcv",
      "    Oy       bcv",
      "    O        bcv",
      "    ky       bcv"
    ],
    [
      "    g        bcv",
      "    k        bcv",
      "    dS       bcv",
      "    k        bcv",
      "    L        bcv",
      "    L        bcv",
      "    L        bcv",
      "    L        bcv",
      "    k    NN  bcv",
      "LLLkdS   NN  bcv",
      "    k    NN  bcv",
      "    Ty   AQ  bcv",
      "    Ty       bcv",
      "    T        bcv",
      "    T        bcv",
      "    ky       bcv"
    ],
    [
      "    k        bcv",
      "    k        bcv",
      "    dS       bcv",
      "    k       Ubcv",
      "    k        bcv",
      "    k        bcv",
      "    k        bcv",
      "    k        bcv",
      "    k        bcv",
      "kkkkdS       bcv",
      "    k        bcv",
      "    k        bcv",
      "    k        bcv",
      "    k        bcv",
      "    k        bcv",
      "    k        bcv"
    ],
    [
      "VVWVXSYWYYZYSbcv",
      "VVVVXSYWYYZYSbcv",
      "VVVVdSYYYYYYSbcv",
      "VVVVXSYYYYYYSbcv",
      "VVWVXSYZYYZYSbcv",
      "VVWVXSYWYYWYSbcv",
      "VVWVXSYZYYZYSbcv",
      "VVWVXSYZYYWYSbcv",
      "VVVVXSYYYYYYSbcv",
      "0000dSYYYYYYSbcv",
      "YYYYXSYWYYWYSbcv",
      "YYYYXSYWYYWYSbcv",
      "YYYYXSYZYYWYSbcv",
      "WWYYXSYWYYWYSbcv",
      "YWYYXSYYYYYYSbcv",
      "YWYYXSYYYYYYSbcv"
    ]
  ]
}