{
  "name": "multi_megatower1_7_floor5",
  "refpalette": "c70cities:multi_megatower1_7_floor5_palette",
  "xsize": 16,
  "zsize": 16,
  "slices": [
    [
      "aaab            ",
      "aaac            ",
      "aaa c           ",
      "aaac            ",
      "aadef           ",
      "aaab            ",
      "aaa b           ",
      "aaab            ",
      "aaac            ",
      "aaa c           ",
      "aaac            ",
      "aadef           ",
      "aaab            ",
      "aaa b           ",
      "aaab            ",
      "aaac            "
    ],
    [
      "g hb            ",
      "  hc            ",
      "i h             ",
      "jkhc            ",
      "lld f           ",
      "  hb            ",
      " mh             ",
      "nnhb            ",
      " mhc            ",
      "nnh             ",
      " mhc            ",
      "lldef           ",
      "  hb            ",
      "  h             ",
      "o hb            ",
      "  hc            "
    ],
    [
      "  pb            ",
      "  pc            ",
      "  p             ",
      " qhc            ",
      "lld f           ",
      "  hb            ",
      " rh             ",
      "nnhb            ",
      " rhc            ",
      "nnh             ",
      " rhc            ",
      "lldef           ",
      "  hb            ",
      "  p             ",
      "  pb            ",
      "  pc            "
    ],
    [
      "  sb            ",
      "  sc            ",
      "  s             ",
      " qhc            ",
      "lld f           ",
      "  hb            ",
      "  h             ",
      "nnhb            ",
      "  hc            ",
      "nnh             ",
      "  hc            ",
      "lldef           ",
      "  hb            ",
      "  s             ",
      "  sb            ",
      "  sc            "
    ],
    [
      "tthb            ",
      "tthc            ",
      "uth             ",
      "tthc            ",
      "lld f           ",
      "wwhb            ",
      "w!h             ",
      "wwhb            ",
      "wxhc            ",
      "wwh             ",
      "wxhc            ",
      "lldef           ",
      "tthb            ",
      "uth             ",
      "tthb            ",
      "tthc            "
    ],
    [
      "yABb            ",
      "CABc            ",
      "DABc            ",
      " ABc            ",
      "EEdef           ",
      "CABb            ",
      "AABb            ",
      "CABb            ",
      "AABc            ",
      " ABc            ",
      "AABc            ",
      "EEdef           ",
      "CABb            ",
      "DABb            ",
      " ABb            ",
      "CABc            "
    ]
  ]
}