{
  "name": "multi_laboratory1_1_base2",
  "refpalette": "c70cities:multi_laboratory1_1_base2_palette",
  "xsize": 16,
  "zsize": 16,
  "slices": [
    [
      "zabccccccccccccc",
      "zabccccccccccccc",
      "zabccccccccccccc",
      "zabccccccccccccc",
      "zabccccccccccccc",
      "zabccccccccccccc",
      "zabccccccccdcccc",
      "zabccccccccccccc",
      "zabccccccccccccc",
      "zabccccccccccccc",
      "zabccccccccccccc",
      "zabccccccccccccc",
      "zabcccccccccccce",
      "zabccccccccdccce",
      "zabcccccccccccef",
      "zabccccccccccce "
    ],
    [
      "zabghhhhhhgi    ",
      "zabh j    ki    ",
      "zabh      li    ",
      "zabh      mi    ",
      "zabh    no p    ",
      "zabgqrsrqqqi    ",
      "zabiiiiiiiidf t ",
      "zabl uuuulli    ",
      "zab  w     i    ",
      "zabx    j  i    ",
      "zabx  yno  i    ",
      "zabA BBBBn i    ",
      "zabCmuuuu  i  DE",
      "zab  FI    d  fE",
      "zab        i  Ef",
      "zabA my    J  E "
    ],
    [
      "zabghhhhhhgi    ",
      "zabh       K    ",
      "zabh       K    ",
      "zabh       i    ",
      "zabh       L    ",
      "zabgq   Ms i    ",
      "zabiiiiiiiidN   ",
      "zab   OPQ  i    ",
      "zab        K    ",
      "zab        K    ",
      "zab        K    ",
      "zab   RST  K    ",
      "zab  U O   i   E",
      "zab        d  NE",
      "zab        i  Ef",
      "zab        J  E "
    ],
    [
      "zabgVVVVVVgi    ",
      "zab        W    ",
      "zabX       W    ",
      "zabY       i    ",
      "zabZ       W    ",
      "zabg       i    ",
      "zabiiiiiiiidN   ",
      "zab        i    ",
      "zab        K    ",
      "zab        K    ",
      "zab        K    ",
      "zab        K    ",
      "zab        i   E",
      "zab        d  NE",
      "zab        i  Ef",
      "zab        J  E "
    ],
    [
      "zabg      gi    ",
      "zab !      i    ",
      "zab        i    ",
      "zab0       i    ",
      "zab        i    ",
      "zabg       i    ",
      "zabiiiiiiiid    ",
      "zab        i    ",
      "zab        i    ",
      "zab        i    ",
      "zab        i    ",
      "zab        i    ",
      "zab        i   E",
      "zab        d   E",
      "zab        i  Ef",
      "zab        i  E "
    ],
    [
      "zabg111111gW2222",
      "zab13111141W2522",
      "zab11111111W2522",
      "zab11111111W2522",
      "zab14111131W2522",
      "zabg1111111W2222",
      "zabiiiiiiiid2222",
      "zab66666666W2222",
      "zab66666666W2222",
      "zab66766566W2222",
      "zab66766366W2222",
      "zab66566566W2222",
      "zab66366766W222E",
      "zab66666666d222E",
      "zab66666666W22Ef",
      "zab66566766W22E "
    ]
  ]
}