{
  "name": "multi_hospital_0_base1",
  "refpalette": "c70cities:multi_hospital_0_base1_palette",
  "xsize": 16,
  "zsize": 16,
  "slices": [
    [
      "vvvvvvvvvvvvvvvv",
      "vaaaaaaaaaaaaaaa",
      "vaaaaaaaaaaaaaaa",
      "vaaaaaaaabbbbbbb",
      "vaaaaaaaabbbbbbb",
      "vaaaaaaaabbbbbbb",
      "vaaaaaaaabbbbbbb",
      "vaaaaaaaabbbbbbb",
      "vacddddddceeebbb",
      "vadffffff   gbbb",
      "vadffffff   gbbb",
      "vadffffffe eebbb",
      "vadffffffbbbbbbb",
      "vadffffffbbbbbbb",
      "vadffffffbbbbbbb",
      "vadffffffbbbbbbb"
    ],
    [
      "vvvvvvvvvvvvvvvv",
      "vaaaaaaaaaaaaaaa",
      "vaaaaaaaaaaaaaaa",
      "vaaaaaaaahhhhhhh",
      "vaaaaaaaah  i   ",
      "vaaaaaaaahj i   ",
      "vaaaaaaaahk ii  ",
      "vaaaaaaaah      ",
      "vacddddddceee   ",
      "vad         l   ",
      "vadmm       n   ",
      "vado     e ee   ",
      "vadp   qdbrrrrst",
      "vadp j udw      ",
      "vad  x  dw      ",
      "vad yAB dbmm   m"
    ],
    [
      "vvvvvvvvvvvvvvvv",
      "vaaaaaaaaaaaaaaa",
      "vaaaaaaaaaaaaaaa",
      "vaaaaaaaahhhhhhh",
      "vaaaaaaaahj i   ",
      "vaaaaaaaahk i   ",
      "vaaaaaaaah  ii  ",
      "vaaaaaaaah      ",
      "vacddddddceee   ",
      "vad         C   ",
      "vadD        E   ",
      "vad     Fe eeI  ",
      "vadJ   idbrrrrKL",
      "vad  M  dw      ",
      "vad  M  dw      ",
      "vad NMO dbD     "
    ],
    [
      "vvvvvvvvvvvvvvvv",
      "vaaaaaaaaaaaaaaa",
      "vaaaaaaaaaaaaaaa",
      "vaaaaaaaahhhhhhh",
      "vaaaaaaaahPji   ",
      "vaaaaaaaah ji   ",
      "vaaaaaaaah  i   ",
      "vaaaaaaaah  i   ",
      "vacddddddceee   ",
      "vad      Q  R   ",
      "vad      Q  R   ",
      "vad      e ee   ",
      "vad    idbrrrrSS",
      "vad     dw      ",
      "vad     dw      ",
      "vad B y db      "
    ],
    [
      "vvvvvvvvvvvvvvvv",
      "vaaaaaaaaaaaaaaa",
      "vaaaaaaaaaaaaaaa",
      "vaaaaaaaahhhhhhh",
      "vaaaaaaaah  i   ",
      "vaaaaaaaah Ti   ",
      "vaaaaaaaah ji   ",
      "vaaaaaaaah  i   ",
      "vacddddddceee   ",
      "vad      e  e   ",
      "vad      e  e   ",
      "vad      e ee   ",
      "vad     dbrrrrrr",
      "vad     dw      ",
      "vad     dw      ",
      "vad  P  db      "
    ],
    [
      "vvvvvvvvvvvvvvvv",
      "vaaaaaaaaaaaaaaa",
      "vaaaaaaaaaaaaaaa",
      "vaaaaaaaahhhhhhh",
      "vaaaaaaaah  iUUU",
      "vaaaaaaaah  iUUU",
      "vaaaaaaaah TiUUU",
      "vaaaaaaaah jiUUU",
      "vacddddddceeebbb",
      "vadjjjjjje  eUUU",
      "vadjjjjjje  eUUU",
      "vadjjjjjje Vebbb",
      "vadjjjjjdbWWWWWW",
      "vadjjjjjdbpppppp",
      "vadjjjjjdbpppppp",
      "vadjjjjjdbpppppp"
    ]
  ]
}