{
  "name": "multi_condo1_3_ground",
  "refpalette": "c70cities:multi_condo1_3_ground_palette",
  "xsize": 16,
  "zsize": 16,
  "slices": [
    [
      "GGGGGGGGGGGGGGGG",
      "GGGGGGaGGGGGGGGG",
      "bGGGGGaccccccGGG",
      "dGGGGGa     cGGG",
      "ecccccc     cGGG",
      "cGGGGGc  c  cGGG",
      "cGGGGGc  c  cGGG",
      "cGGGGGc  c  cGGG",
      "cGGGGGc  c  cGGG",
      "cGGGGGc  c  cGGG",
      "cGGGGGc  c  cGGG",
      "cGGGGGc  c  cGGG",
      "cGGGGGc  c  cGGG",
      "cGGGGGc  c  caaa",
      "cccccccHHccccGGG",
      "      cHHHHHHHHH"
    ],
    [
      "                ",
      "      a         ",
      "b     a         ",
      "      a         ",
      "     cc         ",
      "      c         ",
      "      c         ",
      "      c         ",
      "      c         ",
      "      c         ",
      "      c         ",
      "      c         ",
      "      c         ",
      "      c      aaa",
      "      c         ",
      "      c         "
    ],
    [
      "                ",
      "      a         ",
      "      a         ",
      "      a         ",
      "     cc         ",
      "      c         ",
      "      c         ",
      "      c         ",
      "      c         ",
      "      c         ",
      "      c         ",
      "      c         ",
      "      c         ",
      "      c      aaa",
      "      c         ",
      "      c         "
    ],
    [
      "                ",
      "      a         ",
      "      a         ",
      "      a         ",
      "     cc         ",
      "      c         ",
      "      c         ",
      "      c         ",
      "      c         ",
      "      c         ",
      "      c         ",
      "      c         ",
      "      c         ",
      "      c      aaa",
      "      c         ",
      "      c         "
    ],
    [
      "                ",
      "      a         ",
      "      a         ",
      "      a         ",
      "ccccccc         ",
      "      c         ",
      "      c         ",
      "      c         ",
      "      c         ",
      "      c         ",
      "      c         ",
      "      c         ",
      "      c         ",
      "      c      aaa",
      "      c         ",
      "      c         "
    ],
    [
      "                ",
      "      a         ",
      "ffffffa         ",
      "      a         ",
      "ccccccc         ",
      "      c         ",
      "      c         ",
      "      c         ",
      "      c         ",
      "      c         ",
      "      c         ",
      "      c         ",
      "      c         ",
      "      c      aaa",
      "      c         ",
      "      c         "
    ]
  ]
}