{
  "name": "multi_megatower1_7_floor11",
  "refpalette": "c70cities:multi_megatower1_7_floor11_palette",
  "xsize": 16,
  "zsize": 16,
  "slices": [
    [
      "aaabc           ",
      "aaabd           ",
      "aaabd           ",
      "aaabd           ",
      "eefghi          ",
      "eeabc           ",
      "eeabc           ",
      "eeabc           ",
      "eeabd           ",
      "eeabd           ",
      "eeabd           ",
      "eefghi          ",
      "aaabc           ",
      "aaabc           ",
      "aaabc           ",
      "aaabd           "
    ],
    [
      "j k c           ",
      "  k d           ",
      "l k d           ",
      "m!k d           ",
      "nnf hi          ",
      "ook c           ",
      " pk c           ",
      "ook c           ",
      " pk d           ",
      "ook d           ",
      " pk d           ",
      "nnf hi          ",
      "qrk c           ",
      "  k c           ",
      "s k c           ",
      "  k d           "
    ],
    [
      "  t c           ",
      "  t d           ",
      "  t d           ",
      " uk d           ",
      "nnf hi          ",
      "ook c           ",
      "  k c           ",
      "ook c           ",
      "  k d           ",
      "ook d           ",
      "  k d           ",
      "nnf hi          ",
      "  k c           ",
      "  t c           ",
      "  t c           ",
      "  t d           "
    ],
    [
      "  w c           ",
      "  w d           ",
      "  w d           ",
      " uk d           ",
      "nnf hi          ",
      "ook c           ",
      "  k c           ",
      "ook c           ",
      "  k d           ",
      "ook d           ",
      "  k d           ",
      "nnf hi          ",
      "  k c           ",
      "  w c           ",
      "  w c           ",
      "  w d           "
    ],
    [
      "xxk c           ",
      "xxk d           ",
      "xxk d           ",
      "xxk d           ",
      "nnf hi          ",
      "yyk c           ",
      "yAk c           ",
      "yyk c           ",
      "yAk d           ",
      "yyk d           ",
      "yAk d           ",
      "nnf hi          ",
      "xxk c           ",
      "xxk c           ",
      "xxk c           ",
      "xxk d           "
    ],
    [
      " BC c           ",
      "DBC d           ",
      " BC d           ",
      " BC d           ",
      "EEfFhi          ",
      "DBC c           ",
      "BBC c           ",
      "DBC c           ",
      "BBC d           ",
      " BC d           ",
      "BBC d           ",
      "EEfFhi          ",
      "DBC c           ",
      " BC c           ",
      " BC c           ",
      "DBC d           "
    ]
  ]
}