{
  "name": "multi_megatower1_7_floor9",
  "refpalette": "c70cities:multi_megatower1_7_floor9_palette",
  "xsize": 16,
  "zsize": 16,
  "slices": [
    [
      "aaabc           ",
      "aaabd           ",
      "aaabd           ",
      "aaabd           ",
      "aaefgh          ",
      "aaabc           ",
      "aaabc           ",
      "aaabc           ",
      "aaabd           ",
      "aaabd           ",
      "aaabd           ",
      "aaefgh          ",
      "aaabc           ",
      "aaabc           ",
      "aaabc           ",
      "aaabd           "
    ],
    [
      "ijk c           ",
      " jk d           ",
      " lk d           ",
      "mmk d           ",
      "nne h           ",
      "  k c           ",
      " ok c           ",
      "ppk c           ",
      " ok d           ",
      "ppk d           ",
      " ok d           ",
      "nne h           ",
      "qrk c           ",
      "  k c           ",
      "  k c           ",
      "s k d           "
    ],
    [
      " jk c           ",
      " lk d           ",
      "  k d           ",
      "mmk d           ",
      "nne h           ",
      "  k c           ",
      " tk c           ",
      "ppk c           ",
      " tk d           ",
      "ppk d           ",
      " tk d           ",
      "nne h           ",
      " uk c           ",
      "  w c           ",
      "  w c           ",
      "  w d           "
    ],
    [
      " ik c           ",
      " lk d           ",
      "  k d           ",
      " mk d           ",
      "nne h           ",
      "  k c           ",
      "  k c           ",
      "ppk c           ",
      "  k d           ",
      "ppk d           ",
      "  k d           ",
      "nne h           ",
      " uk c           ",
      "  x c           ",
      "  x c           ",
      "  x d           "
    ],
    [
      "yyk c           ",
      "yyk d           ",
      "Ayk d           ",
      "yyk d           ",
      "nne h           ",
      "BBk c           ",
      "BCk c           ",
      "BBk c           ",
      "BCk d           ",
      "BBk d           ",
      "BCk d           ",
      "nne h           ",
      "  k c           ",
      "  k c           ",
      "  k c           ",
      "  k d           "
    ],
    [
      " DE c           ",
      "iDE d           ",
      "FDE d           ",
      "iDE d           ",
      "IIegh           ",
      "iDE c           ",
      "DDE c           ",
      "iDE c           ",
      "DDE d           ",
      " DE d           ",
      "DDE d           ",
      "IIegh           ",
      "yyE c           ",
      "AyE c           ",
      "yyE c           ",
      "yyE d           "
    ]
  ]
}