{
  "name": "multi_megatower1_4_floor1",
  "refpalette": "c70cities:multi_megatower1_4_floor1_palette",
  "xsize": 16,
  "zsize": 16,
  "slices": [
    [
      "a   bccccdcefghh",
      "a   bccccdcefghh",
      "a   bccccdcefghh",
      "ijkkbccccdcefghh",
      "bbbblcccccclfhhh",
      "bbbbbbbbbbbefhhh",
      "bbbbbbbbbbbefhhh",
      "bbbbbbbbbbbefhhh",
      "bbbbbbbbbbbefhhh",
      "bbbbbbbbbbbefhhh",
      "bbbbbbbbbbbefhhh",
      "bbbblbbbbbblfhhh",
      "bbbbbbbbbbbefhhh",
      "bbbbbbbbbbbefhhh",
      "bbbbbbbbbbbefhhh",
      "bbbmbbbbbbbefhhh"
    ],
    [
      "a   a n n       ",
      "a   aopop       ",
      "a   a   n       ",
      "akqqarr n       ",
      "stuwlxxyx  l    ",
      "    A           ",
      "    B  CD       ",
      "E   F  I        ",
      "E   J  CD       ",
      "    B           ",
      "   KA  CD       ",
      "  LLl  I   l    ",
      "   KA  CD       ",
      "   MA           ",
      "    A  CD       ",
      " NNOA  I    PQ  "
    ],
    [
      "a   a n n       ",
      "a   aRpRp       ",
      "a   a   n       ",
      "ak  a   n       ",
      "s STlxxUx  l    ",
      "    A           ",
      "    B           ",
      "    V  I        ",
      "    W           ",
      "    B           ",
      "   XA           ",
      "   Yl  I   l    ",
      "   XA           ",
      "    A           ",
      "    A           ",
      "    A  I        "
    ],
    [
      "a   a n nZ      ",
      "a   appppZ      ",
      "a   a   nZ      ",
      "akkka   n       ",
      "s0  lxx1x  l    ",
      "    A           ",
      "    B           ",
      "    B  2        ",
      "    B           ",
      "    B           ",
      "    A           ",
      "    l  2   l    ",
      "    A           ",
      "    A           ",
      "    A           ",
      "    A  2        "
    ],
    [
      "a   a3p3p       ",
      "a   apppp       ",
      "a   a333p       ",
      "akkka333p       ",
      "sssslxxxx  l    ",
      "    4           ",
      "    5 676       ",
      "    4 787       ",
      "    5 676       ",
      "    4           ",
      "   95 676       ",
      "4545l 787  l    ",
      "   94 676       ",
      "    5           ",
      "    4 676       ",
      "    5 787       "
    ],
    [
      "@  @#   $       ",
      "@  @#%! $       ",
      "@  @#%% $       ",
      "@@@@#   $       ",
      "^^^^l$$$$  l    ",
      "&&&&#           ",
      "&&&&#           ",
      "&&&&#           ",
      "&&&&#           ",
      "&&&&#           ",
      "&&&&#           ",
      "^^^^l      l    ",
      "&&&&#           ",
      "&&&&#           ",
      "&&&&#           ",
      "&&&&#           "
    ]
  ]
}