{
  "name": "multi_laboratory1_0_base6",
  "refpalette": "c70cities:multi_laboratory1_0_base6_palette",
  "xsize": 16,
  "zsize": 16,
  "slices": [
    [
      "zzzzzzzzzzzzzzzz",
      "zaaaaaaaaaaaaaaa",
      "zabbbbbbbbbbcccc",
      "zabdddddddde    ",
      "zabdddddddde    ",
      "zabddddddddeeeee",
      "zabddddddddffff!",
      "zabddddddddfffff",
      "zabffffffffeffff",
      "zabddddddddfffff",
      "zabddddddddfffff",
      "zabddddddddfffff",
      "zabddddddddfffff",
      "zabddddddddfffff",
      "zabddddddddfffff",
      "zabffffffffeffff"
    ],
    [
      "zzzzzzzzzzzzzzzz",
      "zaaaaaaaaaaaaaaa",
      "zabbbbbbbbbbcccc",
      "zabghghghghi    ",
      "zabg g g g i    ",
      "zabjkjkjkjkeiiii",
      "zab        l   m",
      "zabnnoooonni    ",
      "zabiiiiiiiiep   ",
      "zabqqrrrrqqi   s",
      "zab        t    ",
      "zab        i    ",
      "zabuwuwuwuwix   ",
      "zab y y y yix   ",
      "zabAyAyAyAyiBC  ",
      "zaeiiiiiiiieiiiD"
    ],
    [
      "zzzzzzzzzzzzzzzz",
      "zaaaaaaaaaaaaaaa",
      "zabbbbbbbbbbcccc",
      "zabg g g g i    ",
      "zabg g g g i    ",
      "zabjEjEjEjEeiiii",
      "zab        F IJm",
      "zabKLLLLLLKi    ",
      "zabiiiiiiiie   s",
      "zabKMMMMMMNi    ",
      "zab        O    ",
      "zab        i    ",
      "zabPwPwPwPwi    ",
      "zab y y y yi    ",
      "zab y y y yi    ",
      "zaeiiiiiiiieiiiQ"
    ],
    [
      "zzzzzzzzzzzzzzzz",
      "zaaaaaaaaaaaaaaa",
      "zabbbbbbbbbbcccc",
      "zabg g g g i    ",
      "zabg g g g i    ",
      "zabjjjjjjjjiiiii",
      "zab        i RSm",
      "zab LLLLLL i   s",
      "zabiiiiiiiie    ",
      "zab MMMMMM i    ",
      "zab        i    ",
      "zab        i    ",
      "zabwwwwwwwwi    ",
      "zab y y y yi    ",
      "zab y y y yi    ",
      "zaeiiiiiiiieiiiT"
    ],
    [
      "zzzzzzzzzzzzzzzz",
      "zaaaaaaaaaaaaaaa",
      "zabbbbbbbbbbcccc",
      "zabUVUVUVUVi    ",
      "zabUUUUUUUUi    ",
      "zabUUUUUUUUiiiii",
      "zabUUUUUUUUi  WX",
      "zabUUUUUUUUi    ",
      "zabiiiiiiiie    ",
      "zabUUUUUUUUi    ",
      "zabUUUUUUUUi    ",
      "zabUUUUUUUUi    ",
      "zabUUUUUUUUi    ",
      "zabUUUUUUUUi    ",
      "zabVUVUVUVUi    ",
      "zaeiiiiiiiieiiii"
    ],
    [
      "zzzzzzzzzzzzzzzz",
      "zaaaaaaaaaaaaaaa",
      "zabbbbbbbbbbcccc",
      "zab Y Y Y Yi    ",
      "zab Y Y Y Yi    ",
      "zab Y Y Y Yiiiii",
      "zab Y Y Y Yi W  ",
      "zabYYYYYYYYi    ",
      "zabiiiiiiiie    ",
      "zabYYYYYYYYi    ",
      "zabY Y Y Y i    ",
      "zabY Y Y Y i    ",
      "zabY Y Y Y i    ",
      "zabY Y Y Y i    ",
      "zabY Y Y Y i    ",
      "zaeiiiiiiiieiiii"
    ]
  ]
}