{
  "name": "multi_flatapartment_1_ground",
  "refpalette": "c70cities:multi_flatapartment_1_ground_palette",
  "xsize": 16,
  "zsize": 16,
  "slices": [
    [
      "aaaGGGGGGGGGGGGG",
      "aaaaaaaaaaaaaaaa",
      "aaaaaaaaaaaaaaaa",
      "aaaaaaaaaaaaaaaa",
      "aaaaaaaaaaaaaaaa",
      "aaaaaaaaaaaaaaaa",
      "aaaaaaaaaaaaaaaa",
      "aaaaaaaaaaaaaaaa",
      "aaaaaaaaaaaaaaaa",
      "aaaaaaaaaaaaaaaa",
      "aaaaaaaaaaaaaaaa",
      "aaaaaaaaaaaaaaaa",
      "aaaaaaaaaaaaaaaa",
      "aaaaaaaaaaaaaaaa",
      "aaaaaaaaaaaaaaaa",
      "aaaGGGGGaaaaGGGG"
    ],
    [
      "   bbbbbbbbbbbbb",
      "   cdddcddddcddd",
      "                ",
      "                ",
      "    e f      e f",
      "   cg hciiiicg h",
      "  e fj klllmn oe",
      "  g hj k   pn og",
      "  e fj k   pn oe",
      "  g hj kq  pn og",
      "   ce fcr   ce f",
      "    g h      g h",
      "                ",
      "                ",
      "   csssc    csss",
      "   bbbbb    bbbb"
    ],
    [
      "                ",
      "   t   t    t   ",
      "                ",
      "                ",
      "                ",
      "   t   tiiiit   ",
      "       klll!n   ",
      "       k   pn   ",
      "       kq  pn   ",
      "       kr  pn   ",
      "   t   t    t   ",
      "                ",
      "                ",
      "                ",
      "   t   t    t   ",
      "                "
    ],
    [
      "                ",
      "  utu utu  utu u",
      "                ",
      "                ",
      "                ",
      "   t   tuuuut   ",
      "       u    u   ",
      "       uq   u   ",
      "       ur   u   ",
      "       u    u   ",
      "   t   t    t   ",
      "                ",
      "                ",
      "                ",
      "  utu utu  utu u",
      "                "
    ],
    [
      "                ",
      "ww t w t ww t w ",
      "   x   x    x   ",
      "                ",
      "                ",
      "   t   tiiiit   ",
      "       kqy  n   ",
      "       kr   n   ",
      "       k    n   ",
      "       k    n   ",
      "   t   t    t   ",
      "                ",
      "                ",
      "   x   x    x   ",
      "ww t w t ww t w ",
      "                "
    ],
    [
      "                ",
      "wwwwwwwwwwwwwwww",
      "aaaaaaaaaaaaaaaa",
      "   a   a    a   ",
      "   a   a    a   ",
      "aaaaaaattttttaaa",
      "   a   t Aqyt   ",
      "   a   t    t   ",
      "   a   t    t   ",
      "   a   t    t   ",
      "aaaaaaattttttaaa",
      "   a   a    a   ",
      "   a   a    a   ",
      "aaaaaaaaaaaaaaaa",
      "wwwwwwwwwwwwwwww",
      "                "
    ]
  ]
}