{
  "name": "multi_megatower1_7_floor10",
  "refpalette": "c70cities:multi_megatower1_7_floor10_palette",
  "xsize": 16,
  "zsize": 16,
  "slices": [
    [
      "aaabc           ",
      "aaabd           ",
      "aaabd           ",
      "aaabd           ",
      "eefghi          ",
      "eeabc           ",
      "eeabc           ",
      "eeabc           ",
      "eeabd           ",
      "eeabd           ",
      "eeabd           ",
      "eefghi          ",
      "aaabc           ",
      "aaabc           ",
      "aaabc           ",
      "aaabd           "
    ],
    [
      "j k c           ",
      "  k d           ",
      "l k d           ",
      "mnk d           ",
      "oof hi          ",
      "ppk c           ",
      " qk c           ",
      "ppk c           ",
      " qk d           ",
      "ppk d           ",
      " qk d           ",
      "oof hi          ",
      " rk c           ",
      "  k c           ",
      "s k c           ",
      "  k d           "
    ],
    [
      "  t c           ",
      "  t d           ",
      "  t d           ",
      " uk d           ",
      "oof hi          ",
      "ppk c           ",
      "  k c           ",
      "ppk c           ",
      "  k d           ",
      "ppk d           ",
      "  k d           ",
      "oof hi          ",
      "  k c           ",
      "  t c           ",
      "  t c           ",
      "  t d           "
    ],
    [
      "  w c           ",
      "  w d           ",
      "  w d           ",
      " uk d           ",
      "oof hi          ",
      "ppk c           ",
      "  k c           ",
      "ppk c           ",
      "  k d           ",
      "ppk d           ",
      "  k d           ",
      "oof hi          ",
      "  k c           ",
      "  w c           ",
      "  w c           ",
      "  w d           "
    ],
    [
      "xxk c           ",
      "xxk d           ",
      "xxk d           ",
      "xxk d           ",
      "oof hi          ",
      "yyk c           ",
      "y!k c           ",
      "yyk c           ",
      "yAk d           ",
      "yyk d           ",
      "yAk d           ",
      "oof hi          ",
      "xxk c           ",
      "xxk c           ",
      "xxk c           ",
      "xxk d           "
    ],
    [
      " BC c           ",
      "DBC d           ",
      " BC d           ",
      " BC d           ",
      "EEfFhi          ",
      "DBC c           ",
      "BBC c           ",
      "DBC c           ",
      "BBC d           ",
      " BC d           ",
      "BBC d           ",
      "EEfFhi          ",
      "DBC c           ",
      " BC c           ",
      " BC c           ",
      "DBC d           "
    ]
  ]
}