{
  "name": "multi_laboratory1_4_base2",
  "refpalette": "c70cities:multi_laboratory1_4_base2_palette",
  "xsize": 16,
  "zsize": 16,
  "slices": [
    [
      "zabccccccccdcccc",
      "zabccccccccccccc",
      "zabccccccccccccc",
      "zabccccccccccccc",
      "zabccccccccccccc",
      "zabccccccccccccc",
      "zabccccccccccccc",
      "zabccccccccdcccc",
      "zabeeeeeeeeccccc",
      "zabeeeeeeeeccccc",
      "zabeeeeeeeeccccc",
      "zabeeeeeeeeccccc",
      "zabeeee!eeeccccc",
      "zabbbbbbbbbbbbbb",
      "zaaaaaaaaaaaaaaa",
      "zzzzzzzzzzzzzzzz"
    ],
    [
      "zabffffffffd   g",
      "zabGGGhij kf  lg",
      "zabGmGGij nf opq",
      "zabGGGGij kf  rr",
      "zabGGGGij  f    ",
      "zabGGGhij  s    ",
      "zabmGhhij  f    ",
      "zabffffffffd    ",
      "zabttuuuuttf    ",
      "zab        w    ",
      "zabxyAyAyAyf    ",
      "zab B B B Bf    ",
      "zabCBCBCBCBfDEE ",
      "zabbbbbbbbbbbbbb",
      "zaaaaaaaaaaaaaaa",
      "zzzzzzzzzzzzzzzz"
    ],
    [
      "zabffffffffd    ",
      "zab FIJK   f    ",
      "zabLLM K  Nf   O",
      "zabIP PK   f  o ",
      "zabFQ  K   f    ",
      "zabIRI K   S    ",
      "zabLFTUK   f    ",
      "zabffffffffd    ",
      "zabVWWWWWWVf    ",
      "zab        X    ",
      "zabYyZyZyZyf    ",
      "zab B B B Bf    ",
      "zab B B B Bf    ",
      "zabbbbbbbbbbbbbb",
      "zaaaaaaaaaaaaaaa",
      "zzzzzzzzzzzzzzzz"
    ],
    [
      "zabffffffffd    ",
      "zab    K   f    ",
      "zab L  K   f0   ",
      "zab    K   f0   ",
      "zabF   K   f    ",
      "zab    K   1    ",
      "zabL   K   f    ",
      "zabffffffffd    ",
      "zab WWWWWW f    ",
      "zab        f    ",
      "zabyyyyyyyyf    ",
      "zab B B B Bf    ",
      "zab B B B Bf    ",
      "zabbbbbbbbbbbbbb",
      "zaaaaaaaaaaaaaaa",
      "zzzzzzzzzzzzzzzz"
    ],
    [
      "zabffffffffd    ",
      "zab    K   f    ",
      "zab    K   f    ",
      "zab    K   f    ",
      "zab    K   f    ",
      "zab    K   f    ",
      "zab    K   f    ",
      "zabffffffffd    ",
      "zab22222222f    ",
      "zab22 22222f    ",
      "zab2 222222f    ",
      "zab22222222f    ",
      "zab32323232f    ",
      "zabbbbbbbbbbbbbb",
      "zaaaaaaaaaaaaaaa",
      "zzzzzzzzzzzzzzzz"
    ],
    [
      "zabffffffffd4454",
      "zab6666777714484",
      "zab666677!714484",
      "zab6666777714455",
      "zab6666777714444",
      "zab6666779714444",
      "zab6666777714444",
      "zabffffffffdffff",
      "zab@@@@@@@@f####",
      "zab@ @ @$@ f#5##",
      "zab@$@ @ @ f#5##",
      "zab@$@ @ @ f#5##",
      "zab@ @ @ @ f####",
      "zabbbbbbbbbbbbbb",
      "zaaaaaaaaaaaaaaa",
      "zzzzzzzzzzzzzzzz"
    ]
  ]
}