{
  "name": "park_deadzone_4",
  "refpalette": "c70cities:park_deadzone_4_palette",
  "xsize": 16,
  "zsize": 16,
  "slices": [
    [
      "                ",
      "                ",
      "     aaaaaa     ",
      "   aabbbbbbaa   ",
      "   abbcdddbba   ",
      "  abbdddeddbba  ",
      "  abdefzzfdeba  ",
      "  abddzzzzddba  ",
      "  abdczzczedba  ",
      "  abddfzzfddba  ",
      "  abbddedddbba  ",
      "   abbdddcbba   ",
      "   aabbbbbbaa   ",
      "     aaaaaa     ",
      "                ",
      "                "
    ],
    [
      "                ",
      "                ",
      "                ",
      "                ",
      "       cgg      ",
      "     gg  gg     ",
      "      hcihg     ",
      "    c  ici g    ",
      "    g icc  g    ",
      "    gghcihcg    ",
      "     gg cgg     ",
      "      ggg       ",
      "                ",
      "                ",
      "                ",
      "                "
    ],
    [
      "                ",
      "                ",
      "                ",
      "                ",
      "        gg      ",
      "     g   gg     ",
      "    ggh  hgg    ",
      "    g      g    ",
      "    g      g    ",
      "    ggh  h      ",
      "     gg         ",
      "      gg        ",
      "                ",
      "                ",
      "                ",
      "                "
    ],
    [
      "                ",
      "                ",
      "                ",
      "                ",
      "                ",
      "                ",
      "      hhhh      ",
      "      h  h      ",
      "      h  h      ",
      "      hhhh      ",
      "                ",
      "                ",
      "                ",
      "                ",
      "                ",
      "                "
    ],
    [
      "                ",
      "                ",
      "                ",
      "                ",
      "                ",
      "                ",
      "      j  j      ",
      "                ",
      "                ",
      "      j  j      ",
      "                ",
      "                ",
      "                ",
      "                ",
      "                ",
      "                "
    ]
  ]
}