{
  "name": "park_deadzone_11",
  "refpalette": "c70cities:park_deadzone_11_palette",
  "xsize": 16,
  "zsize": 16,
  "slices": [
    [
      "  a aa aa a aa  ",
      "ababzbabbzzbabb ",
      "abbzbbzbbzbbzba ",
      " zbzzzbzzbzbzbza",
      " bzbzzzbzzzzbbba",
      "aabzbbzbbzzzzzb ",
      "azbzbbbzbbzbzbza",
      " zzbbbbbbbbzzbb ",
      "  bzbbbbbbbzbza ",
      " abbbbbbbbbzzbza",
      " aabbbbbbbzzbzza",
      "  b bbbbbbbzzbba",
      "  babbbzbbzbbzaa",
      "  abaabbbzbbzbb ",
      "    bazbzabzzbba",
      "     aaaa a a  a"
    ],
    [
      "                ",
      "    c    c      ",
      "   c  c         ",
      "   c          c ",
      "  c   d         ",
      "         c   c  ",
      " c    e  f  c   ",
      "     ghi    j   ",
      "    klmin    c  ",
      "    op qir      ",
      "    stuwor  x c ",
      "    yAAoB  C    ",
      "     Bxef       ",
      "      e  c  c   ",
      "           c    ",
      "                "
    ],
    [
      "                ",
      "                ",
      "                ",
      "                ",
      "                ",
      "                ",
      "                ",
      "       D        ",
      "      EF        ",
      "        j       ",
      "                ",
      "     AE         ",
      "     I          ",
      "                ",
      "                ",
      "                "
    ]
  ]
}