{
  "name": "park_deadzone_12",
  "refpalette": "c70cities:park_deadzone_12_palette",
  "xsize": 16,
  "zsize": 16,
  "slices": [
    [
      "aaaaaaaaaaaaaaaa",
      "ababzbabbzzbabba",
      "abcccbzbbzbcccaa",
      "azczzdbdzbzzzcza",
      "abcbzdzdzddzbcba",
      "aabzzzzzzzzzzzba",
      "azbzddzzzdzzzbza",
      "azzbzzzzzzzzzbba",
      "abbdzdzzzzzzbzaa",
      "azbzzdzzzzddzbza",
      "aazbzzdzdzzzzzza",
      "abcddzzddzzdzcba",
      "azczbbzzzbzbbcaa",
      "abcccbbzbzbcccba",
      "aabzbazbzabzzbba",
      "aaaaaaaaaaaaaaaa"
    ],
    [
      "                ",
      "          e     ",
      "  fff e    ff   ",
      "  fee     e ef  ",
      "  f e      g f  ",
      "   e h i    ee  ",
      "      j   kg  e ",
      " e   e     e    ",
      "    e        e  ",
      "   h   e    j   ",
      "    ei   e  e   ",
      "  f  jl   j ef  ",
      " e e  iii e  f  ",
      "  fff    e  ff  ",
      "      e    e    ",
      "                "
    ],
    [
      "                ",
      "                ",
      "  ff        f   ",
      "  f             ",
      "  f             ",
      "                ",
      "                ",
      "                ",
      "                ",
      "                ",
      "                ",
      "                ",
      "             f  ",
      "   ff        f  ",
      "                ",
      "                "
    ]
  ]
}