{
  "name": "park_deadzone_1",
  "refpalette": "c70cities:park_deadzone_1_palette",
  "xsize": 16,
  "zsize": 16,
  "slices": [
    [
      "         zz zz  ",
      "     zabzzzzzzzz",
      "   azzzczbzacaaz",
      "  bc cccacb czzz",
      "  czczazzbac  zz",
      " z zczczzaac az ",
      " zzc zzazazzzzz ",
      " bbb zczzzzazz  ",
      "  aa zaczzczcz  ",
      "zzaa zccczczzz  ",
      " zzzzaazzaczazz ",
      " zz zzzzzzzzzzzz",
      " zzzzzz  z zzzzz",
      "  zzzz zzzzzzzz ",
      "  zzzzzzzzz zz  ",
      "   z   z        "
    ],
    [
      "                ",
      "           d    ",
      "    eee         ",
      "        c       ",
      "   c  cca     d ",
      "   e ezaa       ",
      "     dzzz  ed   ",
      "      zzz cc    ",
      "       zzccc    ",
      "         ccc    ",
      "    d    cc     ",
      "    e  d c  de  ",
      " e  e        e  ",
      "        e  e    ",
      "    e  e        ",
      "                "
    ],
    [
      "                ",
      "                ",
      "                ",
      "                ",
      "                ",
      "        c       ",
      "      ecz       ",
      "       ee       ",
      "                ",
      "                ",
      "                ",
      "                ",
      "                ",
      "                ",
      "                ",
      "                "
    ]
  ]
}