{
  "name": "park_10",
  "refpalette": "c70cities:park_10_palette",
  "xsize": 16,
  "zsize": 16,
  "slices": [
    [
      "aaaaaaabbaaaaaaa",
      "acdddcabbacdddca",
      "aeGGGeabbaeGGGea",
      "aefffeabbaefffea",
      "aefffeabbaefffea",
      "acgggcabbacgggca",
      "aaaaaaabbaaaaaaa",
      "bbbbbbbbbbbbbbbb",
      "bbbbbbbbbbbbbbbb",
      "aaaaaaabbaaaaaaa",
      "achhhcabbachhhca",
      "aefffeabbaefffea",
      "aefffeabbaefffea",
      "aeGGGeabbaeGGGea",
      "acdddcabbacdddca",
      "aaaaaaabbaaaaaaa"
    ],
    [
      "                ",
      " iiiii    iiiii ",
      " i  ji    ikj i ",
      " ilmni    imnli ",
      " i   i    i   i ",
      " i   i    i   i ",
      "                ",
      "                ",
      "                ",
      "                ",
      " i   i    i   i ",
      " i   i    i   i ",
      " ilopi    iopli ",
      " ij qi    ij ki ",
      " iiiii    iiiii ",
      "                "
    ],
    [
      "                ",
      "                ",
      "    ~       ~   ",
      "                ",
      "                ",
      "                ",
      "                ",
      "                ",
      "                ",
      "                ",
      "                ",
      "                ",
      "             r  ",
      "  ~        ~    ",
      "                ",
      "                "
    ]
  ]
}