{
  "name": "park_deadzone_6",
  "refpalette": "c70cities:park_deadzone_6_palette",
  "xsize": 16,
  "zsize": 16,
  "slices": [
    [
      "aaaaaaaaaaaaaaaa",
      "ababzbabbzzbabba",
      "abcccbzbbzbcccaa",
      "azczzdbdzbzzzcza",
      "abcbzdzdzddzbcba",
      "aabzzzzzzzzzzzba",
      "azbzddzzzdzzzbza",
      "azzbzzzzzzzzzbba",
      "abbdzdzzzzzzbzaa",
      "azbzzdzzzzddzbza",
      "aazbzzdzdzzzzzza",
      "abcddzzddzzdzcba",
      "azczbbzzzbzbbcaa",
      "abcccbbzbzbcccba",
      "aabzbazbzabzzbba",
      "aaaaaaaaaaaaaaaa"
    ],
    [
      "                ",
      "                ",
      "  eee      ee   ",
      "  e          e  ",
      "  e        f e  ",
      "     g h        ",
      "      i   jf    ",
      "                ",
      "                ",
      "   g        i   ",
      "     h          ",
      "  e  ik   i  e  ",
      "      hhh    e  ",
      "  eee       ee  ",
      "                ",
      "                "
    ],
    [
      "                ",
      "                ",
      "  ee        e   ",
      "  e             ",
      "  e             ",
      "                ",
      "                ",
      "                ",
      "                ",
      "                ",
      "                ",
      "                ",
      "             e  ",
      "   ee        e  ",
      "                ",
      "                "
    ]
  ]
}