{
  "name": "park_8",
  "refpalette": "c70cities:park_8_palette",
  "xsize": 16,
  "zsize": 16,
  "slices": [
    [
      "aaaaaaaaaaaaaaaa",
      "aGGGbbbbbbbbbGGa",
      "aGccbdddddddbcca",
      "aeeeeeddddddbcca",
      "aedddeddddddbcca",
      "aedddfddddfdbcca",
      "aedddeddddddbcca",
      "aedgggggddddbcca",
      "aedgdddgeeeeeeca",
      "aeegdddgdddddeca",
      "aGhgdfdgddfddeca",
      "aGfgdddgdddddeca",
      "aGfgggggdddddeGa",
      "aGfddddedddddeGa",
      "aGhfffheeeeeeeGa",
      "aaaaaaaaaaaaaaaa"
    ],
    [
      "                ",
      "    bbbbbbbbb   ",
      "    biiiiiiib   ",
      " jeeeeiiiiiib   ",
      " jdddkiiiiiib   ",
      " jdddfiiiifib   ",
      " jdddeiiiiiib   ",
      " jdgggggiiiib   ",
      " jdgdddgekeeee  ",
      " jjgdddgddddde  ",
      "  lgdfdgddfdde  ",
      "  lgdddgddddde  ",
      "  lgggggdddddj  ",
      "  l    jdddddj  ",
      "  llllljjjjjjj  ",
      "                "
    ],
    [
      "                ",
      "                ",
      "                ",
      " eeeee          ",
      " eiiimn         ",
      " eiiif    f     ",
      " eiiie          ",
      " eigkggg n      ",
      " eigdddgemeeee  ",
      " eegdddgiiiiie  ",
      "   gdfdgiifiie  ",
      "   gdddkiiiiie  ",
      "   gggggiiiiie  ",
      "       eiiiiie  ",
      "       eeeeeee  ",
      "                "
    ],
    [
      "                ",
      "                ",
      "                ",
      "                ",
      "                ",
      "     f    f     ",
      "    n           ",
      "   gmggg        ",
      "   giiigjjjjjj  ",
      "   giiig     j  ",
      "   gifig  f  j  ",
      "   giiimn    j  ",
      "   ggggg     j  ",
      "       j     j  ",
      "       jjjjjjj  ",
      "                "
    ],
    [
      "                ",
      "                ",
      "                ",
      "                ",
      "                ",
      "     f    f     ",
      "                ",
      "                ",
      "                ",
      "                ",
      "     f    f     ",
      "                ",
      "                ",
      "                ",
      "                ",
      "                "
    ],
    [
      "                ",
      "                ",
      "                ",
      "                ",
      "                ",
      "     oooooo     ",
      "     o    o     ",
      "     o    o     ",
      "     o    o     ",
      "     o    o     ",
      "     oooooo     ",
      "                ",
      "                ",
      "                ",
      "                ",
      "                "
    ]
  ]
}