{
  "name": "park_1",
  "refpalette": "c70cities:park_1_palette",
  "xsize": 16,
  "zsize": 16,
  "slices": [
    [
      "                ",
      " abbbba  abbbba ",
      " b            b ",
      " b            b ",
      " b  c      d  b ",
      " b  e      f  b ",
      " a     gg     a ",
      " b    ghig    b ",
      " b    gjkg    b ",
      " a     gg     a ",
      " b  c      d  b ",
      " b  e      f  b ",
      " b            b ",
      " b            b ",
      " abbbba  abbbba ",
      "                "
    ],
    [
      "                ",
      " lbbbbb  bbbbbl ",
      " b            b ",
      " b            b ",
      " b            b ",
      " b            b ",
      " b            b ",
      " b            b ",
      " b            b ",
      " b            b ",
      " b            b ",
      "              b ",
      " b            b ",
      " b            b ",
      " lb bbb  bbbbb  ",
      "                "
    ],
    [
      "                ",
      "   b b   bb bb  ",
      " b            b ",
      "              b ",
      " b              ",
      " b              ",
      " b            b ",
      "              b ",
      " b            b ",
      " b              ",
      "              b ",
      "                ",
      " b            b ",
      " b            b ",
      "  b  bb  bb  b  ",
      "                "
    ]
  ]
}