{
  "name": "park_deadzone_3",
  "refpalette": "c70cities:park_deadzone_3_palette",
  "xsize": 16,
  "zsize": 16,
  "slices": [
    [
      "                ",
      "     aaaaaa     ",
      "   aaazzzzaaa   ",
      "  aazzzzzzzzaa  ",
      "  azzzbbbbzzza  ",
      " aazzbbbbbbzzaa ",
      " azzbbbbbbbbzzac",
      " azzbbbbbbbbbbdc",
      " azzbbbbbbbbbbdc",
      " azzbbbbbbbbzzac",
      " aazzbbbbbbzzaa ",
      "  azzzbbbbzzza  ",
      "  aazzzbbzzzaa  ",
      "   aaazbbzaaa   ",
      "     aaeeaa     ",
      "      cccc      "
    ],
    [
      "                ",
      "                ",
      "      f ff      ",
      "     gfggfgf    ",
      "   ffghhhhfgf   ",
      "   gfhijklh g   ",
      "  fghi     h f  ",
      "  ffhj          ",
      "  fghk          ",
      "   ghl     hff  ",
      "   fgh    hgg   ",
      "    g h  hggf   ",
      "    fgf  g f    ",
      "      g  f      ",
      "                ",
      "                "
    ],
    [
      "                ",
      "                ",
      "                ",
      "                ",
      "      mmmm      ",
      "     m    m     ",
      "    m      m    ",
      "    m           ",
      "    m           ",
      "    m      m    ",
      "     m    m     ",
      "      m  m      ",
      "                ",
      "                ",
      "                ",
      "                "
    ]
  ]
}