{
  "name": "park_deadzone_9",
  "refpalette": "c70cities:park_deadzone_9_palette",
  "xsize": 16,
  "zsize": 16,
  "slices": [
    [
      "aaaaaaaaaaaaaaaa",
      "ababzbabbzzbabba",
      "abbzbbzbbzbbzbaa",
      "azbzzzbzzbzzzbza",
      "abzbzzzzzzzzabba",
      "aabzzzzzzzzzzzba",
      "azbzzzzccczzzbza",
      "azzbzzcdddczzaba",
      "abbzzzcdddczbzaa",
      "azbzzzcdddczzbza",
      "aazbzzzccczzzzza",
      "abbzzzzzzzzzzbba",
      "azzzbazzzbzbbzaa",
      "abzbzbbzbzabzbba",
      "aabzbazbzabzzbba",
      "aaaaaaaaaaaaaaaa"
    ],
    [
      "                ",
      "    e     e     ",
      "      e     e   ",
      " e fff ffffff   ",
      "  gf gg e e     ",
      "   h   iii efe  ",
      "   h ejcccj f e ",
      "  ef kclclcmf   ",
      "   f kclllcm e  ",
      " e f kclclcmf   ",
      "    e jcccj f e ",
      "   f n ooo ef   ",
      "  eff fff fffe  ",
      "  e      e  e   ",
      "   e  e    ee   ",
      "                "
    ],
    [
      "                ",
      "                ",
      "                ",
      "   ffffffff f   ",
      "   f        f   ",
      "            f   ",
      "            f   ",
      "   f        f   ",
      "   f        f   ",
      "   f        f   ",
      "   f        f   ",
      "   f        f   ",
      "   ff  fffff    ",
      "                ",
      "                ",
      "                "
    ]
  ]
}