{
  "name": "park_10",
  "refpalette": "c70cities:park_10_palette",
  "xsize": 16,
  "zsize": 16,
  "slices": [
    [
      "aaaaaaabbaaaaaaa",
      "acdddcabbacdddca",
      "aeGGfeabbaeGGGea",
      "aegggeabbaegggea",
      "aegggeabbaegggea",
      "achhhcabbachhhca",
      "aaaaaaabbaaaaaaa",
      "bbbbbbbbbbbbbbbb",
      "bbbbbbbbbbbbbbbb",
      "aaaaaaabbaaaaaaa",
      "aciiicabbaciiica",
      "aegggeabbaegggea",
      "aegggeabbaegggea",
      "aeGGGeabbaeGGGea",
      "acdddcabbacdddca",
      "aaaaaaabbaaaaaaa"
    ],
    [
      "                ",
      " jjjjj    jjjjj ",
      " j  cj    jkl j ",
      " jmnoj    jnomj ",
      " j   j    j   j ",
      " j   j    j   j ",
      "                ",
      "                ",
      "                ",
      "                ",
      " j   j    j   j ",
      " j   j    j   j ",
      " jmpqj    jpqmj ",
      " jl rj    jl kj ",
      " jjjjj    jjjjj ",
      "                "
    ],
    [
      "                ",
      "                ",
      "    c       ~   ",
      "                ",
      "                ",
      "                ",
      "                ",
      "                ",
      "                ",
      "                ",
      "                ",
      "                ",
      "             s  ",
      "  ~             ",
      "                ",
      "                "
    ],
    [
      "   ttt          ",
      "  ttttt         ",
      "  ttctt         ",
      "  ttttt         ",
      "  tttt          ",
      "                ",
      "                ",
      "                ",
      "                ",
      "                ",
      "                ",
      "                ",
      "                ",
      "                ",
      "                ",
      "                "
    ],
    [
      "  tttt          ",
      "  ttttt         ",
      "  ttctt         ",
      "  ttttt         ",
      "   ttt          ",
      "                ",
      "                ",
      "                ",
      "                ",
      "                ",
      "                ",
      "                ",
      "                ",
      "                ",
      "                ",
      "                "
    ],
    [
      "                ",
      "   tt           ",
      "   tct          ",
      "    tt          ",
      "                ",
      "                ",
      "                ",
      "                ",
      "                ",
      "                ",
      "                ",
      "                ",
      "                ",
      "                ",
      "                ",
      "                "
    ],
    [
      "                ",
      "    t           ",
      "   ttt          ",
      "    t           ",
      "                ",
      "                ",
      "                ",
      "                ",
      "                ",
      "                ",
      "                ",
      "                ",
      "                ",
      "                ",
      "                ",
      "                "
    ]
  ]
}