{
  "name": "park_5",
  "refpalette": "c70cities:park_5_palette",
  "xsize": 16,
  "zsize": 16,
  "slices": [
    [
      "aaaaaaaaaaaaaaaa",
      "aGGGGGGbGGGGGGGa",
      "aGGGbbbbbGbbGGGa",
      "aGGbGbcGGcGGbGGa",
      "aGGbbGddddGbGGGa",
      "aGbbGdeeeedGbbGa",
      "aGbcdeeeeeedcbGa",
      "abGGdeeeeeedGGba",
      "abbGdeeeeeedGbba",
      "aGbcdeeeeeedcbGa",
      "aGGbGdeeeedGbbGa",
      "aGGGbGddddGbbbGa",
      "aGGbbbcGGcbbbGGa",
      "aGGGbGbbbbbbGGGa",
      "aGGGGGGbbGGGGGGa",
      "aaaaaaaaaaaaaaaa"
    ],
    [
      "                ",
      "   f        g   ",
      "              h ",
      " hh   iiii   h  ",
      "     ieeeei     ",
      "    iejeejei    ",
      " g iejejjeje    ",
      "   ieejjjjeei   ",
      "   ieejjjjeei   ",
      "   iejejjejei g ",
      "    iejeejei    ",
      "      eeeei     ",
      " h    ii i    f ",
      "             kh ",
      " ghk        gf  ",
      "                "
    ],
    [
      "                ",
      "                ",
      "                ",
      "                ",
      "      aaaa      ",
      "                ",
      "    a l  l a    ",
      "    a      a    ",
      "    a      a    ",
      "    a l  l a    ",
      "                ",
      "      aaaa      ",
      "                ",
      "             m  ",
      "   m            ",
      "                "
    ]
  ]
}