{
  "name": "park_7",
  "refpalette": "c70cities:park_7_palette",
  "xsize": 16,
  "zsize": 16,
  "slices": [
    [
      "aaaaaaaaaaaaaaaa",
      "aGGGGGGGGGGGGGGa",
      "aGGGGGGGGGGGGGGa",
      "aGbbbGGbbbGGGGGa",
      "aGbbbbbbbbbbbGGa",
      "aGbccccddccccbGa",
      "aGbccccddcccccba",
      "aGbccccddcccccba",
      "aGbccccddcccccba",
      "aGbccccddcccccba",
      "aGbccccddccccbGa",
      "aGbbbbbbbbbbbGGa",
      "aGbbbGGbbbGGGGGa",
      "aGGGGGGGGGGGGGGa",
      "aGGGGGGGGGGGGGGa",
      "aaaaaaaaaaaaaaaa"
    ],
    [
      "                ",
      "                ",
      "                ",
      "  ddd  ddd      ",
      "  dccccddcccc   ",
      "  ce         c  ",
      "  c          ec ",
      "  c           c ",
      "  c           c ",
      "  c          ec ",
      "  ce         c  ",
      "  dccccddcccc   ",
      "  ddd  ddd      ",
      "                ",
      "                ",
      "                "
    ],
    [
      "                ",
      "                ",
      "                ",
      "  dd   dd       ",
      "  dccccddcccc   ",
      "  ce         d  ",
      "  c          ec ",
      "  c           d ",
      "  c           d ",
      "  c          ec ",
      "  ce         d  ",
      "  dccccddcccc   ",
      "  dd   dd       ",
      "                ",
      "                ",
      "                "
    ],
    [
      "                ",
      "                ",
      "                ",
      "                ",
      "   ccccd cccc   ",
      "  ce    d    d  ",
      "  c     d    d  ",
      " cc     d    c  ",
      " cc     d    c  ",
      "  c     d    d  ",
      "  ce    d    d  ",
      "   ccccd cccc   ",
      "                ",
      "                ",
      "                ",
      "                "
    ],
    [
      "                ",
      "                ",
      "                ",
      "                ",
      "          d     ",
      "   ccccd ccccc  ",
      "   ccccd ccccc  ",
      " ccccccd cffcc  ",
      " ccccccd cffcc  ",
      "   ccccd ccccc  ",
      "   ccccd ccccc  ",
      "          d     ",
      "                ",
      "                ",
      "                ",
      "                "
    ],
    [
      "                ",
      "                ",
      "                ",
      "                ",
      "          d     ",
      "          d     ",
      "                ",
      "                ",
      "                ",
      "                ",
      "          d     ",
      "          d     ",
      "                ",
      "                ",
      "                ",
      "                "
    ]
  ]
}