{
  "name": "park_12",
  "refpalette": "c70cities:park_12_palette",
  "xsize": 16,
  "zsize": 16,
  "slices": [
    [
      "aaaaabccccdaaaaa",
      "aeeeeeeeeeeeeeea",
      "aeeeeeeeeeeeeeea",
      "aeeeeeeeeeeeeeea",
      "aeeeaffffffaeeea",
      "geeehiGGGGijeeeg",
      "ceeehGGGGGGjeeec",
      "ceeehGGGGGGjeeec",
      "ceeehGGGGGGjeeec",
      "ceeehGGGGGGjeeec",
      "keeehiGGGGijeeek",
      "aeeeallllllaeeea",
      "aeeeeeeeeeeeeeea",
      "aeeeeeeeeeeeeeea",
      "aeeeeeeeeeeeeeea",
      "aaaaabccccdaaaaa"
    ],
    [
      "    m      m    ",
      "                ",
      "                ",
      "                ",
      "m              m",
      "     nnopnn     ",
      "     noq pn     ",
      "     pr orq     ",
      "     oqp q      ",
      "     npqron     ",
      "     nnopnn     ",
      "m              m",
      "                ",
      "                ",
      "                ",
      "    m      m    "
    ],
    [
      "    s      s    ",
      "                ",
      "                ",
      "                ",
      "s              s",
      "                ",
      "                ",
      "                ",
      "                ",
      "                ",
      "                ",
      "s              s",
      "                ",
      "                ",
      "                ",
      "    s      s    "
    ],
    [
      "    s      s    ",
      "                ",
      "                ",
      "                ",
      "s              s",
      "                ",
      "                ",
      "                ",
      "                ",
      "                ",
      "                ",
      "s              s",
      "                ",
      "                ",
      "                ",
      "    s      s    "
    ],
    [
      "    s      s    ",
      "    t      u    ",
      "    w      w    ",
      "                ",
      "sux          yts",
      "                ",
      "                ",
      "                ",
      "                ",
      "                ",
      "                ",
      "stx          yus",
      "                ",
      "    A      A    ",
      "    t      u    ",
      "    s      s    "
    ],
    [
      "    B      B    ",
      "    C      C    ",
      "                ",
      "                ",
      "DC            CE",
      "                ",
      "                ",
      "                ",
      "                ",
      "                ",
      "                ",
      "DC            CE",
      "                ",
      "                ",
      "    C      C    ",
      "    F      F    "
    ]
  ]
}