{
  "name": "park_11",
  "refpalette": "c70cities:park_11_palette",
  "xsize": 16,
  "zsize": 16,
  "slices": [
    [
      "vaaaavvvvvvaaaav",
      "bccccccccccccccd",
      "bccccvvvvvvccccd",
      "bccccveeeevccccd",
      "bccccveffevccccd",
      "vcvvvveffevvvvvv",
      "vcveeeeffeeeeghh",
      "vcvefffffffffijj",
      "vcvefffffffffijj",
      "vcveeeeffeeeeghh",
      "vcvvvveffevvvvvv",
      "bccccveffevccccd",
      "bccccveeeevccccd",
      "bccccvvvvvvccccd",
      "bccccccccccccccd",
      "vkkkkvvvvvvkkkkv"
    ],
    [
      "vllllvmvvmvllllv",
      "ncccccccccccccco",
      "nccccvvvvvvcccco",
      "nccccvGGGGvcccco",
      "nccccvGffGvcccco",
      "vcvvvveffevvvvvv",
      "mcvGGeeffeeeg   ",
      "vcvGffffffffi   ",
      "vcvGffffffffi   ",
      "mcvGGeeffeeeg   ",
      "vcvvvveffevvvvvv",
      "nccccvGffGvcccco",
      "nccccvGGGGvcccco",
      "nccccvvvvvvcccco",
      "ncccccccccccccco",
      "vppppvmvvmvppppv"
    ],
    [
      "vvvvvvvvvvvvvvvv",
      "vqGGGGGGGGGGGGqv",
      "vGGGGvvvvvvGGGGv",
      "vGGGGvrrrrvGGGGv",
      "vGGGGvrstrvGGGGv",
      "vGvvvv    vvvvvv",
      "vGvrr      v    ",
      "vGvru           ",
      "vGvrw           ",
      "vGvrr      v    ",
      "vGvvvv    vvvvvv",
      "vGGGGvrxyrvGGGGv",
      "vGGGGvrrrrvGGGGv",
      "vGGGGvvvvvvGGGGv",
      "vqGGGGGGGGGGGGqv",
      "vvvvvvvvvvvvvvvv"
    ],
    [
      "                ",
      " AAABCD C B AAA ",
      " A  B      BB A ",
      " ABE       BEBA ",
      "  BB        B   ",
      " B              ",
      " D         F    ",
      " C              ",
      "                ",
      " I         F    ",
      " J              ",
      "  J          B  ",
      " A K       BEBA ",
      " AJJ          A ",
      " AAAJI DCIBBAAA ",
      "                "
    ],
    [
      "                ",
      "                ",
      "                ",
      "   ~        ~   ",
      "                ",
      "                ",
      "                ",
      "                ",
      "                ",
      "                ",
      "                ",
      "                ",
      "   ~        ~   ",
      "                ",
      "                ",
      "                "
    ]
  ]
}