{
  "name": "park_10",
  "refpalette": "c70cities:park_10_palette",
  "xsize": 16,
  "zsize": 16,
  "slices": [
    [
      "aaaaaaabbaaaaaaa",
      "acdddcabbacdddca",
      "aeGGfeabbaeGGGea",
      "aegggeabbaegggea",
      "aegggeabbaegggea",
      "achhhcabbachhhca",
      "aaaaaaabbaaaaaaa",
      "bbbbbbbbbbbbbbbb",
      "bbbbbbbbbbbbbbbb",
      "aaaaaaabbaaaaaaa",
      "aciiicabbaciiica",
      "aegggeabbaegggea",
      "aegggeabbaegggea",
      "aeGGGeabbaefGGea",
      "acdddcabbacdddca",
      "aaaaaaabbaaaaaaa"
    ],
    [
      "                ",
      " jjjjj    jjjjj ",
      " j  cj    jkl j ",
      " jmnoj    jnomj ",
      " j   j    j   j ",
      " j   j    j   j ",
      "                ",
      "                ",
      "                ",
      "                ",
      " j   j    j   j ",
      " j   j    j   j ",
      " jmpqj    jpqmj ",
      " jl rj    jc kj ",
      " jjjjj    jjjjj ",
      "                "
    ],
    [
      "                ",
      "                ",
      "    c       ~   ",
      "                ",
      "                ",
      "                ",
      "                ",
      "                ",
      "                ",
      "                ",
      "                ",
      "                ",
      "             s  ",
      "  ~        c    ",
      "                ",
      "                "
    ],
    [
      "   ttt          ",
      "  ttttt         ",
      "  ttctt         ",
      "  ttttt         ",
      "  tttt          ",
      "                ",
      "                ",
      "                ",
      "                ",
      "                ",
      "                ",
      "                ",
      "                ",
      "           c    ",
      "                ",
      "                "
    ],
    [
      "  tttt          ",
      "  ttttt         ",
      "  ttctt         ",
      "  ttttt         ",
      "   ttt          ",
      "                ",
      "                ",
      "                ",
      "                ",
      "                ",
      "                ",
      "          ttt   ",
      "         ttttt  ",
      "         ttctt  ",
      "         ttttt  ",
      "         tttt   "
    ],
    [
      "                ",
      "   tt           ",
      "   tct          ",
      "    tt          ",
      "                ",
      "                ",
      "                ",
      "                ",
      "                ",
      "                ",
      "                ",
      "         ttttt  ",
      "         ttttt  ",
      "         ttctt  ",
      "         ttttt  ",
      "         ttttt  "
    ],
    [
      "                ",
      "    t           ",
      "   ttt          ",
      "    t           ",
      "                ",
      "                ",
      "                ",
      "                ",
      "                ",
      "                ",
      "                ",
      "                ",
      "           t    ",
      "          tct   ",
      "          ttt   ",
      "                "
    ],
    [
      "                ",
      "                ",
      "                ",
      "                ",
      "                ",
      "                ",
      "                ",
      "                ",
      "                ",
      "                ",
      "                ",
      "                ",
      "           t    ",
      "          ttt   ",
      "           t    ",
      "                "
    ]
  ]
}