{
  "name": "park_6",
  "refpalette": "c70cities:park_6_palette",
  "xsize": 16,
  "zsize": 16,
  "slices": [
    [
      "aaaaaaaaaaaaaaaa",
      "aGGGGGGGGGGGGGGa",
      "aGGGGGGGGGGbbGGa",
      "aGGbbbbbGGGGGcGa",
      "aGGbbbbbbGcGcGGa",
      "aGGbbbbbbcccGGGa",
      "aGGbbbbbbcGccGGa",
      "aGGbbbbbGGccGGGa",
      "aGGGGGGGGGccGGGa",
      "aGGGGGGGGGcccGGa",
      "aGGGGGGGGGGccGGa",
      "aGGGGGGGGGGccGGa",
      "aGGGGGGGGGGccGGa",
      "aGGGGGGGGGccGGGa",
      "aGGGGGGGGGGccGGa",
      "aaaaaaaaaaaaaaaa"
    ],
    [
      "                ",
      "   de  fe  gg   ",
      "  hhhhhhh ijjk  ",
      " lhmmmmmhn oo   ",
      " fhmpppma       ",
      "  hmpppma    q  ",
      " nhmpppma       ",
      "  hmmmmmhd  dd  ",
      " dhhhhhhhe    q ",
      " n den lnq   d  ",
      " r fr r         ",
      "   rrr  sd      ",
      "  r tr  d       ",
      "    r  r     q  ",
      " dr   q   q     ",
      "                "
    ],
    [
      "                ",
      "                ",
      "            u   ",
      "   wwwww        ",
      "   wxyAw        ",
      "   wB           ",
      "   wC  w        ",
      "   wwwww        ",
      "                ",
      "                ",
      "                ",
      "                ",
      "    ~           ",
      "                ",
      "                ",
      "                "
    ],
    [
      "                ",
      "                ",
      "   DDDDD        ",
      "     w          ",
      "    E           ",
      "                ",
      "                ",
      "     w          ",
      "   FFFFF        ",
      "                ",
      "                ",
      "                ",
      "                ",
      "                ",
      "                ",
      "                "
    ],
    [
      "                ",
      "                ",
      "                ",
      "   DDDDD        ",
      "   II  I        ",
      "   IIIII        ",
      "   II  I        ",
      "   FFFFF        ",
      "                ",
      "                ",
      "                ",
      "                ",
      "                ",
      "                ",
      "                ",
      "                "
    ],
    [
      "                ",
      "                ",
      "                ",
      "                ",
      "   JJJJJ        ",
      "   J   J        ",
      "   JJJJJ        ",
      "                ",
      "                ",
      "                ",
      "                ",
      "                ",
      "                ",
      "                ",
      "                ",
      "                "
    ]
  ]
}