{
  "name": "park_deadzone_10",
  "refpalette": "c70cities:park_deadzone_10_palette",
  "xsize": 16,
  "zsize": 16,
  "slices": [
    [
      "  aa aaaa aa  aa",
      "ababzbabbzzbaa a",
      " bbzbbzbbzbbaza ",
      "azbzzzbzzbzzzbaa",
      "abzzzzzzzzzzbbb ",
      "aabzzzzzzzzzzzb ",
      "azzzzzzzzzzzzbza",
      "azzbzzzzzzzzzbba",
      "azbzzzczzzzzbzaa",
      "azbzzdedzzzzzbza",
      " bzbzzczzzzzzzz ",
      "abbzzbzzzzzzzbba",
      "aazbbbzzzbzbbza ",
      "aaabzbbzbzbbzbb ",
      " aaabazbzabzaaa ",
      "a  a  aaaaa  a  "
    ],
    [
      "                ",
      "    fg   f      ",
      "  g   f         ",
      " h ijk ff  f    ",
      "  jjjj azz      ",
      "  j z bzaa  ff  ",
      " ffg zzbbzaz  f ",
      "    zbzzbbzzf   ",
      "   fzdddbbz     ",
      " f fzdldbzzz    ",
      "     dddzzaf f  ",
      "   ff azbzf f   ",
      "  f    fz       ",
      "    f           ",
      "                ",
      "                "
    ],
    [
      "                ",
      "                ",
      "   i            ",
      "   i            ",
      "    j    f      ",
      "    j mf        ",
      "     f          ",
      "     no         ",
      "    fpqp  f     ",
      "    fq q  f     ",
      "     pqpf       ",
      "         f      ",
      "                ",
      "                ",
      "                ",
      "                "
    ],
    [
      "                ",
      "   i            ",
      "                ",
      "   i            ",
      "                ",
      "                ",
      "      r         ",
      "      o         ",
      "     psp        ",
      "      t         ",
      "     p p        ",
      "                ",
      "                ",
      "                ",
      "                ",
      "                "
    ],
    [
      "                ",
      "   u            ",
      "                ",
      "   m            ",
      "   i            ",
      "                ",
      "                ",
      "                ",
      "     qwq        ",
      "     wtw        ",
      "     qwq        ",
      "                ",
      "                ",
      "                ",
      "                ",
      "                "
    ],
    [
      "                ",
      "                ",
      "                ",
      "                ",
      "   i            ",
      "                ",
      "                ",
      "                ",
      "                ",
      "      q         ",
      "                ",
      "                ",
      "                ",
      "                ",
      "                ",
      "                "
    ]
  ]
}