{
  "name": "park_deadzone_2",
  "refpalette": "c70cities:park_deadzone_2_palette",
  "xsize": 16,
  "zsize": 16,
  "slices": [
    [
      "      abba      ",
      "    zza bazz    ",
      "  zzzzabbazzzz  ",
      "  zzzzcddczzzz  ",
      " zzzezcddczezzz ",
      " zzzzccddcczzzz ",
      "aaaccccddccccaaa",
      "a bddddzzddddbb ",
      " bbddddzzdddd ab",
      "aaaccccddccccaaa",
      " zzzzccddcczzzz ",
      " zzzezcddczezzz ",
      "  zzzzcddczzzz  ",
      "  zzzzabaazzzz  ",
      "    zza bazz    ",
      "      aaba      "
    ],
    [
      "                ",
      "    f     f     ",
      "  gfhi    iffj  ",
      "  f ii    ii f  ",
      "  iiii    iiii  ",
      " iifi      iifj ",
      "       bb       ",
      "      bkkb      ",
      "      bkkb      ",
      "       bb       ",
      " f fi      iiil ",
      "  iiii    iii f ",
      "  fhii    ii f  ",
      "   f i    ihf   ",
      "    lf    ff    ",
      "                "
    ],
    [
      "                ",
      "                ",
      "                ",
      "          i     ",
      "          i     ",
      "    i           ",
      "                ",
      "                ",
      "                ",
      "                ",
      "           ii   ",
      "    ii    i     ",
      "     i          ",
      "                ",
      "                ",
      "                "
    ]
  ]
}