{
  "name": "park_3",
  "refpalette": "c70cities:park_3_palette",
  "xsize": 16,
  "zsize": 16,
  "slices": [
    [
      "  a       aa    ",
      " bccccba bccccb ",
      " c   a        c ",
      " ca        a  ca",
      "aca d      e  c ",
      " c  f      ga c ",
      " b     hh     b ",
      " c    hijh    c ",
      " c    hklh   aca",
      " b     hh     ba",
      "aca d      e  c ",
      "ac  f      g ac ",
      " c   a       aca",
      " c         a  c ",
      " bccccb  bccccb ",
      "   a a      aa  "
    ],
    [
      "                ",
      " mccccc  cccccm ",
      " c            c ",
      " c            c ",
      " c            c ",
      " c            c ",
      " c            c ",
      " c            c ",
      " c            c ",
      " c            c ",
      " c            c ",
      "              c ",
      " c            c ",
      " c            c ",
      " mc ccc  ccccc  ",
      "                "
    ],
    [
      "                ",
      "   c c   cc cc  ",
      " c            c ",
      "              c ",
      " c              ",
      " c              ",
      " c            c ",
      "              c ",
      " c            c ",
      " c              ",
      "              c ",
      "                ",
      " c            c ",
      " c            c ",
      "  c  cc  cc  c  ",
      "                "
    ]
  ]
}