{
  "name": "seahouse_1",
  "refpalette": "c70cities:seahouse_1_palette",
  "xsize": 16,
  "zsize": 16,
  "slices": [
    [
      "~~~~~~~~~~~~~~~~",
      "~~~~~~~~~~~~~~~~",
      "~~~~~~~~~~~~~~~~",
      "~~~~~~~~~~~~~~~~",
      "~~~~~~~~~~~~~~~~",
      "~~~~~~~~~~~~~~~~",
      "~~~~~~~~~~~~~~~~",
      "~~~~~~~~~~~~~~~~",
      "~~~~~~~~~~~~~~~~",
      "~~~~~~~~~~~~~~~~",
      "~~~~~~~~~~~~~~~~",
      "~~~~~~~~~~~~~~~~",
      "~~~~~~~~~~~~~~~~",
      "~~~~~~~~~~~~~~~~",
      "~~~~~~~~~~~~~~~~",
      "~~~~~~~~~~~~~~~~"
    ],
    [
      "aaaaaaaaaaaaaaaa",
      "aaaaaaaaaaaaaaaa",
      "aaaaaaabcccccbaa",
      "aaaaaaaaaaaaaaaa",
      "aaaaaaaaaaaaaaaa",
      "aaaaaaaaaaaaaaaa",
      "aaaaaaabcccccbaa",
      "aaaaaaaaaaaaaaaa",
      "aaaaaaaadddddaaa",
      "aaaaaaaaaaaaaaaa",
      "aaaaaaabcccccbaa",
      "aaaaaaaaaaaaaaaa",
      "aaaaaaaaaaaaaaaa",
      "aaaaaaaaaaaaaaaa",
      "aaaaaaaaaaaaaaaa",
      "aaaaaaaaaaaaaaaa"
    ],
    [
      "                ",
      "      eeeeeeeee ",
      "     feggggggge ",
      "      eggggggge ",
      "      eggggggge ",
      "    f eggggggge ",
      "      eggggggge ",
      "      eggggggge ",
      "     feggggggge ",
      "      eggggggge ",
      "      eggggggge ",
      "      eeeeeeeee ",
      "      eeeeeeeee ",
      " f    eeeeeeeee ",
      "     f        f ",
      "          h     "
    ],
    [
      "      iiiiiiiii ",
      "     j klllllm n",
      "     j ooooooopn",
      "     jqrstuwsr n",
      "     j xytAByCDn",
      "     jqxyE FyC n",
      "     j xyIqJyC n",
      "     jAxyA KyCDn",
      "     j xyB LyM n",
      "     j rsyNysr n",
      "     j  O      n",
      "     j PQR     n",
      "      S       S ",
      "                ",
      "                ",
      "                "
    ],
    [
      "                ",
      "        m  p    ",
      "       ooTTToo  ",
      "       rsUUVsr  ",
      "        yB ByW  ",
      "        T   T   ",
      "        T  XT   ",
      "        T   TW  ",
      "        yB Yy   ",
      "       rsyZysr  ",
      "                ",
      "                ",
      "                ",
      "                ",
      "                ",
      "                "
    ],
    [
      "                ",
      "                ",
      "       ooooooo  ",
      "       0syyys1  ",
      "       0yB By1  ",
      "       0y   y1  ",
      "       0y   y1  ",
      "       0yU  y1  ",
      "       0y!UBy1  ",
      "       0syyys1  ",
      "       2222222  ",
      "       2222222  ",
      "       2222222  ",
      "                ",
      "                ",
      "                "
    ],
    [
      "                ",
      "                ",
      "                ",
      "        33333   ",
      "        33333   ",
      "        333 3   ",
      "        3U 33   ",
      "        33 33   ",
      "        33333   ",
      "        33333   ",
      "                ",
      "                ",
      "                ",
      "                ",
      "                ",
      "                "
    ]
  ]
}