{
  "name": "seahouse_1",
  "refpalette": "c70cities:seahouse_1_palette",
  "xsize": 16,
  "zsize": 16,
  "slices": [
    [
      "~~~~~~~~~~~~~~~~",
      "~~~~~~~~~~~~~~~~",
      "~~~~~~~~~~~~~~~~",
      "~~~~~~~~~~~~~~~~",
      "~~~~~~~~~~~~~~~~",
      "~~~~~~~~~~~~~~~~",
      "~~~~~~~~~~~~~~~~",
      "~~~~~~~~~~~~~~~~",
      "~~~~~~~~~~~~~~~~",
      "~~~~~~~~~~~~~~~~",
      "~~~~~~~~~~~~~~~~",
      "~~~~~~~~~~~~~~~~",
      "~~~~~~~~~~~~~~~~",
      "~~~~~~~~~~~~~~~~",
      "~~~~~~~~~~~~~~~~",
      "~~~~~~~~~~~~~~~~"
    ],
    [
      "aaaaaaaaaaaaaaaa",
      "aaaaaaaaaaaaaaaa",
      "aaaaaaabcccccbaa",
      "aaaaaaaaaaaaaaaa",
      "aaaaaaaaaaaaaaaa",
      "aaaaaaaaaaaaaaaa",
      "aaaaaaabcccccbaa",
      "aaaaaaaaaaaaaaaa",
      "aaaaaaaaaaaaaaaa",
      "aaaaaaaaaaaaaaaa",
      "aaaaaaabcccccbaa",
      "aaaaaaaaaaaaaaaa",
      "aaaaaaaaaaaaaaaa",
      "aaaaaaaaaaaaaaaa",
      "aaaaaaaaaaaaaaaa",
      "aaaaaaaaaaaaaaaa"
    ],
    [
      "                ",
      "      ddddddddd ",
      "     edfffffffd ",
      "      dfffffffd ",
      "      dfffffffd ",
      "    e dfffffffd ",
      "      dfffffffd ",
      "      dfffffffd ",
      "     edfffffffd ",
      "      dfffffffd ",
      "      dfffffffd ",
      "      ddddddddd ",
      "      ddddddddd ",
      " e    ddddddddd ",
      "     e        e ",
      "          g     "
    ],
    [
      "      hhhhhhhhh ",
      "     i jkkkkkl m",
      "     i nnnnnnnom",
      "     ipqrsturq m",
      "     i wxsyAxBCm",
      "     ipwxD ExB m",
      "     i wxFpIxB m",
      "     iywxy JxBCm",
      "     i wxA KxL m",
      "     i qrxMxrq m",
      "     i  N      m",
      "     i OPQ     m",
      "      R       R ",
      "                ",
      "                ",
      "                "
    ],
    [
      "                ",
      "        l  o    ",
      "       nnSSSnn  ",
      "       qrTTUrq  ",
      "        xA AxV  ",
      "        S   S   ",
      "        S  WS   ",
      "        S   SV  ",
      "        xA Xx   ",
      "       qrxYxrq  ",
      "                ",
      "                ",
      "                ",
      "                ",
      "                ",
      "                "
    ],
    [
      "                ",
      "                ",
      "       nnnnnnn  ",
      "       Zrxxxr0  ",
      "       ZxA Ax0  ",
      "       Zx   x0  ",
      "       Zx   x0  ",
      "       ZxT  x0  ",
      "       Zx!TAx0  ",
      "       Zrxxxr0  ",
      "       1111111  ",
      "       1111111  ",
      "       1111111  ",
      "                ",
      "                ",
      "                "
    ],
    [
      "                ",
      "                ",
      "                ",
      "        22222   ",
      "        22222   ",
      "        222 2   ",
      "        2T 22   ",
      "        22 22   ",
      "        22222   ",
      "        22222   ",
      "                ",
      "                ",
      "                ",
      "                ",
      "                ",
      "                "
    ]
  ]
}