{
  "name": "seahouse_1",
  "refpalette": "c70cities:seahouse_1_palette",
  "xsize": 16,
  "zsize": 16,
  "slices": [
    [
      "~~~~~~~~~~~~~~~~",
      "~~~~~~~~~~~~~~~~",
      "~~~~~~~~~~~~~~~~",
      "~~~~~~~~~~~~~~~~",
      "~~~~~~~~~~~~~~~~",
      "~~~~~~~~~~~~~~~~",
      "~~~~~~~~~~~~~~~~",
      "~~~~~~~~~~~~~~~~",
      "~~~~~~~~~~~~~~~~",
      "~~~~~~~~~~~~~~~~",
      "~~~~~~~~~~~~~~~~",
      "~~~~~~~~~~~~~~~~",
      "~~~~~~~~~~~~~~~~",
      "~~~~~~~~~~~~~~~~",
      "~~~~~~~~~~~~~~~~",
      "~~~~~~~~~~~~~~~~"
    ],
    [
      "aaaaaaaaaaaaaaaa",
      "aaaaaaaaaaaaaaaa",
      "aaaaaaabcccccbaa",
      "aaaaaaaaaaaaaaaa",
      "aaaaaaaaaaaaaaaa",
      "aaaaaaaaaaaaaaaa",
      "aaaaaaabcccccbaa",
      "aaaaaaaaaaaaaaaa",
      "aaaaaaaaaaaaaaaa",
      "aaaaaaaaaaaaaaaa",
      "aaaaaaabcccccbaa",
      "aaaaaaaaaaaaaaaa",
      "aaaaaaaaaaaaaaaa",
      "aaaaaaaaaaaaaaaa",
      "aaaaaaaaaaaaaaaa",
      "aaaaaaaaaaaaaaaa"
    ],
    [
      "                ",
      "      ddddddddd ",
      "     edfffffffd ",
      "      dfffffffd ",
      "      dfffffffd ",
      "    e dfffffffd ",
      "      dfffffffd ",
      "      dfffffffd ",
      "     edfffffffd ",
      "      dfffffffd ",
      "      dfffffffd ",
      "      ddddddddd ",
      "      ddddddddd ",
      " e    ddddddddd ",
      "     e        e ",
      "          g     "
    ],
    [
      "      hhhhhhhhh ",
      "     i jkkkkkl m",
      "     i nnnnnnnom",
      "     ipqrsturq m",
      "     i wxsyAxBCm",
      "     ipwxD ExB m",
      "     i wxFpIxB m",
      "     iywxy JxBCm",
      "     i wxA KxL m",
      "     i qrxMxrq m",
      "     i  N      m",
      "     i OPQ     m",
      "      R       R ",
      "                ",
      "                ",
      "                "
    ],
    [
      "                ",
      "        l  o    ",
      "       nnSSSnn  ",
      "       qrt Trq  ",
      "        xA AxU  ",
      "        S   S   ",
      "        S  VS   ",
      "        S   SU  ",
      "        xA Wx   ",
      "       qrxXxrq  ",
      "                ",
      "                ",
      "                ",
      "                ",
      "                ",
      "                "
    ],
    [
      "                ",
      "                ",
      "       nnnnnnn  ",
      "       YrxxxrZ  ",
      "       YxA AxZ  ",
      "       Yx   xZ  ",
      "       Yx   xZ  ",
      "       Yxt  xZ  ",
      "       Yx!tAxZ  ",
      "       YrxxxrZ  ",
      "       0000000  ",
      "       0000000  ",
      "       0000000  ",
      "                ",
      "                ",
      "                "
    ],
    [
      "                ",
      "                ",
      "                ",
      "        11111   ",
      "        11111   ",
      "        111 1   ",
      "        1t 11   ",
      "        11 11   ",
      "        11111   ",
      "        11111   ",
      "                ",
      "                ",
      "                ",
      "                ",
      "                ",
      "                "
    ]
  ]
}