{
  "name": "stair_deadzone_2",
  "refpalette": "c70cities:stair_deadzone_2_palette",
  "xsize": 16,
  "zsize": 16,
  "slices": [
    [
      "ababaabaabba    ",
      "zzzzzzzzzzza    ",
      "zzzzzzzzzzzb    ",
      "zzzazzzazzza    ",
      "aaabbaaaabab    ",
      "a        HHccccc",
      "b        HHccccc",
      "b        HHccccc",
      "a        HHccccc",
      "a        HHccccc",
      "a        HHccccc",
      "ababaaaaaaab    ",
      "zzzazzzbzzza    ",
      "zzzzzzzzzzza    ",
      "zzzzzzzzzzzb    ",
      "aaababaaabab    "
    ],
    [
      "                ",
      " d dd d d d     ",
      "dd  dd   d      ",
      " eefeeef ee     ",
      "bavaabaabvgg    ",
      "b      HHc      ",
      "b      HHc      ",
      "a      HHc      ",
      "a      HHc      ",
      "a      HHc      ",
      "v      HHc      ",
      "aabaaababagg    ",
      "eeef eefe e     ",
      "d dd d  d       ",
      "d d   dd  d     ",
      "                "
    ],
    [
      "                ",
      "                ",
      "                ",
      "   h   h        ",
      "bavabbvbggg     ",
      "a    HHc        ",
      "b    HHc        ",
      "a    HHc        ",
      "a    HHc        ",
      "v    HHc        ",
      "b    HHc        ",
      "baaaaaavggg     ",
      "   h   h        ",
      "                ",
      "                ",
      "                "
    ],
    [
      "                ",
      "                ",
      "                ",
      "                ",
      "abbbvvggg       ",
      "a  HHc          ",
      "v  HHc          ",
      "a  HHc          ",
      "b  HHc          ",
      "b  HHc          ",
      "b  HHc          ",
      "aabavaggg       ",
      "                ",
      "                ",
      "                ",
      "                "
    ],
    [
      "                ",
      "                ",
      "                ",
      "                ",
      "aavbggg         ",
      "bHHc            ",
      "bHHc            ",
      "vHHc            ",
      "vHHc            ",
      "bHHc            ",
      "vHHc            ",
      "abbaggg         ",
      "                ",
      "                ",
      "                ",
      "                "
    ],
    [
      "                ",
      "                ",
      "                ",
      "                ",
      "bvggg           ",
      "Hc              ",
      "Hc              ",
      "Hc              ",
      "Hc              ",
      "Hc              ",
      "Hc              ",
      "vbggg           ",
      "                ",
      "                ",
      "                ",
      "                "
    ]
  ],
  "meta": [
    {
      "integer": 5,
      "key": "z1"
    },
    {
      "integer": 10,
      "key": "z2"
    }
  ]
}