{
  "name": "stair_deadzone_1",
  "refpalette": "c70cities:stair_deadzone_1_palette",
  "xsize": 16,
  "zsize": 16,
  "slices": [
    [
      "aabbbbbcbaabdddd",
      "e         vffffd",
      "e         vffffg",
      "e         vffffh",
      "eeeeeeeeeeeefffh",
      "evvzzzzzzeHffffg",
      "evvzzzzzzezffffd",
      "evvzzzzzzezffffg",
      "evvzzzzzzeHffffd",
      "evvzzzzzzezffffd",
      "evvzzzzzzeHffffd",
      "eeeeeeeeeeeefffg",
      "e         bffffd",
      "e         vffffg",
      "e         iffffj",
      "ccabbbbbcaaeggjj"
    ],
    [
      "acbbccababkk    ",
      "        vl      ",
      "        vl      ",
      "        vl      ",
      "eeeeeeeeebkk    ",
      "vvvHHHHHHf      ",
      "vvvHHHHHzf      ",
      "vvvHHHHHHf      ",
      "vvvHHHHHzf      ",
      "vvvHHHHHzf      ",
      "vvvHHHHHzf      ",
      "eeeeeeeeebkm    ",
      "        vl      ",
      "        cd      ",
      "        cb      ",
      "cbbabbccaakk    "
    ],
    [
      "bbccbbabkkk     ",
      "      vl        ",
      "      vl        ",
      "      vl        ",
      "eeeeeeeckkk     ",
      "vvvHHHzf        ",
      "vvvHHHHf        ",
      "vvvHHHHz        ",
      "vvvHHHzf        ",
      "vvvHHHzf        ",
      "vvvHHHHf        ",
      "eeeeeebbkkkn    ",
      "      cl        ",
      "      cj        ",
      "      vd        ",
      "cbbacbaakkk     "
    ],
    [
      "acccbbkkk       ",
      "    vl          ",
      "    vl          ",
      "    vl          ",
      "eeeeeckkk       ",
      "vvvzHf          ",
      "vvvHHf          ",
      "vvvHHz          ",
      "vvvHzf          ",
      "vvvHzf          ",
      "vvvHzf          ",
      "eeeecekkk  n    ",
      "    vl          ",
      "    aj          ",
      "    cl          ",
      "ccabbakkk       "
    ],
    [
      "acabkkk         ",
      "  vl            ",
      "  vl            ",
      "  vl            ",
      "eecckkk         ",
      "HHzz            ",
      "HHzz            ",
      "HHzf            ",
      "HHHf            ",
      "HHHf       o    ",
      "HHHf       k    ",
      "eeeekkk    k    ",
      "  al            ",
      "  cj            ",
      "  vl            ",
      "cccakkk         "
    ],
    [
      "aakkk           ",
      "vl              ",
      "vl              ",
      "vl              ",
      "cekkk           ",
      "Hf              ",
      "Hf              ",
      "Hf              ",
      "Hz              ",
      "Hz         f    ",
      "Hf         f    ",
      "ebkkk           ",
      "vj              ",
      "vl              ",
      "vj              ",
      "chkkk           "
    ]
  ],
  "meta": [
    {
      "integer": 4,
      "key": "z1"
    },
    {
      "integer": 11,
      "key": "z2"
    }
  ]
}