{
  "name": "stair_1",
  "refpalette": "c70cities:stair_1_palette",
  "xsize": 16,
  "zsize": 16,
  "slices": [
    [
      "aaaaaaaaaaaabbbb",
      "acccccccccvddddb",
      "acccccccccvddddb",
      "acccccccccvddddb",
      "aaaaaaaaaaaaaaab",
      "acvcccccGGGGGGab",
      "acvcccccGGGGGGab",
      "acvcccccGGGGGGab",
      "acvcccccGGGGGGab",
      "acvcccccGGGGGGab",
      "acvcccccGGGGGGab",
      "aaaaaaaaaaaaaaab",
      "acccccccccvddddb",
      "acccccccccvddddb",
      "acccccccccvddddb",
      "aaaaaaaaaaaabbbb"
    ],
    [
      "aaaaaaaaaeeeffff",
      "vcccccccvdffffff",
      "vcccccccvdffffff",
      "vcccccccvdffffff",
      "aaaaaaaaaeeeffff",
      "vcvggggahfffffff",
      "vcvggggahfffffff",
      "vcvggggahfffffff",
      "vcvggggahfffffff",
      "vcvggggahfffffff",
      "vcvggggahfffffff",
      "aaaaaaaaaeeeffff",
      "vcccccccvdffffff",
      "vcccccccvdffffff",
      "vcccccccvdffffff",
      "aaaaaaaaaeeeffff"
    ],
    [
      "aaaaaaaeeeffffff",
      "vcccccvdffffffff",
      "vcccccvdffffffff",
      "vcccccvdffffffff",
      "aaaaaaaeeeffffff",
      "vvvfffffffffffff",
      "vvviffffffffffff",
      "vvvfffffffffffff",
      "vvvfffffffffffff",
      "vvviffffffffffff",
      "vvvfffffffffffff",
      "aaaaaaaeeeffffff",
      "vcccccvdffffffff",
      "vcccccvdffffffff",
      "vcccccvdffffffff",
      "aaaaaaaeeeffffff"
    ],
    [
      "aaaaaeeeffffffff",
      "vcccvdffffffffff",
      "vcccvdffffffffff",
      "vcccvdffffffffff",
      "aaaaaeeeffffffff",
      "vvvfffffffffffff",
      "vgjkffffffffffff",
      "vvvfffffffffffff",
      "vvvfffffffffffff",
      "vgjkffffffffffff",
      "vvvfffffffffffff",
      "aaaaaeeeffffffff",
      "vcccvdffffffffff",
      "vcccvdffffffffff",
      "vcccvdffffffffff",
      "aaaaaeeeffffffff"
    ],
    [
      "aaaeeeffffffffff",
      "vcvdffffffffffff",
      "vcvdffffffffffff",
      "vcvdffffffffffff",
      "aaaeeeffffffffff",
      "vvvlffffffffffff",
      "vvvlffffffffffff",
      "vvvlffffffffffff",
      "vvvlffffffffffff",
      "vvvlffffffffffff",
      "vvvlffffffffffff",
      "aaaeeeffffffffff",
      "vcvdffffffffffff",
      "vcvdffffffffffff",
      "vcvdffffffffffff",
      "aaaeeeffffffffff"
    ],
    [
      "aeeeffffffffffff",
      "vdffffffffffffff",
      "vdffffffffffffff",
      "vdffffffffffffff",
      "aeeeffffffffffff",
      "fffeffffffffffff",
      "fffeffffffffffff",
      "fffeffffffffffff",
      "fffeffffffffffff",
      "fffeffffffffffff",
      "fffeffffffffffff",
      "aeeeffffffffffff",
      "vdffffffffffffff",
      "vdffffffffffffff",
      "vdffffffffffffff",
      "aeeeffffffffffff"
    ]
  ],
  "meta": [
    {
      "integer": 0,
      "key": "z1"
    },
    {
      "integer": 15,
      "key": "z2"
    }
  ]
}