{
  "name": "stair_1",
  "refpalette": "c70cities:stair_1_palette",
  "xsize": 16,
  "zsize": 16,
  "slices": [
    [
      "aaaaaaaaaaaabbbb",
      "a         vccccb",
      "a         vccccb",
      "a         vccccb",
      "aaaaaaaaaaaaaaab",
      "a vdddddGGGGGGab",
      "a vdddddGGGGGGab",
      "a vdddddGGGGGGab",
      "a vdddddGGGGGGab",
      "a vdddddGGGGGGab",
      "a vdddddGGGGGGab",
      "aaaaaaaaaaaaaaab",
      "a         vccccb",
      "a         vccccb",
      "a         vccccb",
      "aaaaaaaaaaaabbbb"
    ],
    [
      "aaaaaaaaaeee    ",
      "        vc      ",
      "        vc      ",
      "        vc      ",
      "aaaaaaaaaeee    ",
      "  vffffag       ",
      "  vffffag       ",
      "  vffffag       ",
      "  vffffag       ",
      "  vffffag       ",
      "  vffffag       ",
      "aaaaaaaaaeee    ",
      "        vc      ",
      "        vc      ",
      "        vc      ",
      "aaaaaaaaaeee    "
    ],
    [
      "aaaaaaaeee      ",
      "      vc        ",
      "      vc        ",
      "      vc        ",
      "aaaaaaaeee      ",
      "  v             ",
      "vvvh            ",
      "  v             ",
      "  v             ",
      "vvvh            ",
      "  v             ",
      "aaaaaaaeee      ",
      "      vc        ",
      "      vc        ",
      "      vc        ",
      "aaaaaaaeee      "
    ],
    [
      "aaaaaeee        ",
      "    vc          ",
      "    vc          ",
      "    vc          ",
      "aaaaaeee        ",
      " vv             ",
      "vfij            ",
      " vv             ",
      " vv             ",
      "vfij            ",
      " vv             ",
      "aaaaaeee        ",
      "    vc          ",
      "    vc          ",
      "    vc          ",
      "aaaaaeee        "
    ],
    [
      "aaaeee          ",
      "  vc            ",
      "  vc            ",
      "  vc            ",
      "aaaeee          ",
      "vvvk            ",
      "vvvk            ",
      "vvvk            ",
      "vvvk            ",
      "vvvk            ",
      "vvvk            ",
      "aaaeee          ",
      "  vc            ",
      "  vc            ",
      "  vc            ",
      "aaaeee          "
    ],
    [
      "aeee            ",
      "vc              ",
      "vc              ",
      "vc              ",
      "aeee            ",
      "   e            ",
      "   e            ",
      "   e            ",
      "   e            ",
      "   e            ",
      "   e            ",
      "aeee            ",
      "vc              ",
      "vc              ",
      "vc              ",
      "aeee            "
    ],
    [
      "                ",
      "        ~       ",
      "                ",
      "          ~     ",
      "          ~     ",
      "       ~ ~      ",
      "          ~~    ",
      "          ~     ",
      "       ~        ",
      "                ",
      "                ",
      "                ",
      "                ",
      "                ",
      "                ",
      "                "
    ]
  ],
  "meta": [
    {
      "integer": 4,
      "key": "z1"
    },
    {
      "integer": 11,
      "key": "z2"
    }
  ]
}