{
  "name": "stair_3",
  "refpalette": "c70cities:stair_3_palette",
  "xsize": 16,
  "zsize": 16,
  "slices": [
    [
      "abbbbbbbbbbbbbbb",
      "accccccccccccccb",
      "accccccccccccccb",
      "adddddddddddcccb",
      "adGGGGGGGGGdcccb",
      "adGGGGGGGGGdcccb",
      "adGGGGGGGGGdcccb",
      "adddddddddddcccb",
      "accccccccccccccb",
      "accccccccccccccb",
      "eeeeeeeeeeeebbbb",
      "afffffffffghhhhh",
      "afffffffffghhhhh",
      "afffffffffghhhhh",
      "afffffffffghhhhh",
      "eeeeeeeeeeeebbbb"
    ],
    [
      "aiiiiiiiiiiiiiii",
      "aiiiiiiiiiiiiiii",
      "aiiiiiiiiiiiiiii",
      "ajjjjjjjjjjjiiii",
      "ajkiiikiiikjiiii",
      "ajkilikilikjiiii",
      "ajkiiikiiikjiiii",
      "ajjjjjjjjjjjiiii",
      "aiiiiiiiiiiiiiii",
      "aiiiiiiiiiiiiiii",
      "eeeeeeeeeemmiiii",
      "afffffffghiiiiii",
      "afffffffghiiiiii",
      "afffffffghiiiiii",
      "afffffffghiiiiii",
      "eeeeeeeeeemmiiii"
    ],
    [
      "aiiiiiiiiiiiiiii",
      "aiiiiiiiiiiiiiii",
      "aiiiiiiiiiiiiiii",
      "aiiiiiiiiiiiiiii",
      "aiiiiiiiiiiiiiii",
      "aiii~iii~iiiiiii",
      "aiiiiiiiiiiiiiii",
      "aiiiiiiiiiiiiiii",
      "aiiiiiiiiiiiiiii",
      "aiiiiiiiiiiiiiii",
      "eeeeeeeemmiiiiii",
      "afffffghiiiiiiii",
      "afffffghiiiiiiii",
      "afffffghiiiiiiii",
      "afffffghiiiiiiii",
      "eeeeeeeemmiiiiii"
    ],
    [
      "aiiiiiiiiiiiiiii",
      "aiiiiiiiiiiiiiii",
      "aiiiiiiiiiiiiiii",
      "aiiiiiiiiiiiiiii",
      "aiiiiiiiiiiiiiii",
      "aiiiiiiiiiiiiiii",
      "aiiiiiiiiiiiiiii",
      "aiiiiiiiiiiiiiii",
      "aiiiiiiiiiiiiiii",
      "aiiiiiiiiiiiiiii",
      "eeeeeemmiiiiiiii",
      "afffghiiiiiiiiii",
      "afffghiiiiiiiiii",
      "afffghiiiiiiiiii",
      "afffghiiiiiiiiii",
      "eeeeeemmiiiiiiii"
    ],
    [
      "aiiiiiiiiiiiiiii",
      "aiiiiiiiiiiiiiii",
      "aiiiiiiiiiiiiiii",
      "aiiiiiiiiiiiiiii",
      "aiiiiiiiiiiiiiii",
      "aiiiiiiiiiiiiiii",
      "aiiiiiiiiiiiiiii",
      "aiiiiiiiiiiiiiii",
      "aiiiiiiiiiiiiiii",
      "aiiiiiiiiiiiiiii",
      "eeeemmiiiiiiiiii",
      "afghiiiiiiiiiiii",
      "afghiiiiiiiiiiii",
      "afghiiiiiiiiiiii",
      "afghiiiiiiiiiiii",
      "eeeemmiiiiiiiiii"
    ],
    [
      "biiiiiiiiiiiiiii",
      "biiiiiiiiiiiiiii",
      "biiiiiiiiiiiiiii",
      "biiiiiiiiiiiiiii",
      "biiiiiiiiiiiiiii",
      "biiiiiiiiiiiiiii",
      "biiiiiiiiiiiiiii",
      "biiiiiiiiiiiiiii",
      "biiiiiiiiiiiiiii",
      "biiiiiiiiiiiiiii",
      "eemmiiiiiiiiiiii",
      "ghiiiiiiiiiiiiii",
      "ghiiiiiiiiiiiiii",
      "ghiiiiiiiiiiiiii",
      "ghiiiiiiiiiiiiii",
      "eemmiiiiiiiiiiii"
    ]
  ],
  "meta": [
    {
      "integer": 11,
      "key": "z1"
    },
    {
      "integer": 14,
      "key": "z2"
    }
  ]
}