{
  "name": "stair_1",
  "refpalette": "c70cities:stair_1_palette",
  "xsize": 16,
  "zsize": 16,
  "slices": [
    [
      "aaaaaaaaaaaabbbb",
      "acccccccccvddddb",
      "acccccccccvddddb",
      "acccccccccvddddb",
      "aaaaaaaaaaaaaaab",
      "acvcccccGGGGGGab",
      "acvcccccGGGGGGab",
      "acvcccccGGGGGGab",
      "acvcccccGGGGGGab",
      "acvcccccGGGGGGab",
      "acvcccccGGGGGGab",
      "aaaaaaaaaaaaaaab",
      "acccccccccvddddb",
      "acccccccccvddddb",
      "acccccccccvddddb",
      "aaaaaaaaaaaabbbb"
    ],
    [
      "aaaaaaaaaeeeffff",
      "ccccccccvdffffff",
      "ccccccccvdffffff",
      "ccccccccvdffffff",
      "aaaaaaaaaeeeffff",
      "vcvggggahfffffff",
      "vcvggggahfffffff",
      "vcvggggahfffffff",
      "vcvggggahfffffff",
      "vcvggggahfffffff",
      "vcvggggahfffffff",
      "aaaaaaaaaeeeffff",
      "ccccccccvdffffff",
      "ccccccccvdffffff",
      "ccccccccvdffffff",
      "aaaaaaaaaeeeffff"
    ],
    [
      "aaaaaaaeeeffffff",
      "ccccccvdffffffff",
      "ccccccvdffffffff",
      "ccccccvdffffffff",
      "aaaaaaaeeeffffff",
      "vvvfffffffffffff",
      "vvviffffffffffff",
      "vvvfffffffffffff",
      "vvvfffffffffffff",
      "vvviffffffffffff",
      "vvvfffffffffffff",
      "aaaaaaaeeeffffff",
      "ccccccvdffffffff",
      "ccccccvdffffffff",
      "ccccccvdffffffff",
      "aaaaaaaeeeffffff"
    ],
    [
      "aaaaaeeeffffffff",
      "ccccvdffffffffff",
      "ccccvdffffffffff",
      "ccccvdffffffffff",
      "aaaaaeeeffffffff",
      "vvvfffffffffffff",
      "vgjkffffffffffff",
      "vvvfffffffffffff",
      "vvvfffffffffffff",
      "vgjkffffffffffff",
      "vvvfffffffffffff",
      "aaaaaeeeffffffff",
      "ccccvdffffffffff",
      "ccccvdffffffffff",
      "ccccvdffffffffff",
      "aaaaaeeeffffffff"
    ],
    [
      "aaaeeeffffffffff",
      "ccvdffffffffffff",
      "ccvdffffffffffff",
      "ccvdffffffffffff",
      "aaaeeeffffffffff",
      "vvvlffffffffffff",
      "vvvlffffffffffff",
      "vvvlffffffffffff",
      "vvvlffffffffffff",
      "vvvlffffffffffff",
      "vvvlffffffffffff",
      "aaaeeeffffffffff",
      "ccvdffffffffffff",
      "ccvdffffffffffff",
      "ccvdffffffffffff",
      "aaaeeeffffffffff"
    ],
    [
      "aeeeffffffffffff",
      "vdffffffffffffff",
      "vdffffffffffffff",
      "vdffffffffffffff",
      "aeeeffffffffffff",
      "fffeffffffffffff",
      "fffeffffffffffff",
      "fffeffffffffffff",
      "fffeffffffffffff",
      "fffeffffffffffff",
      "fffeffffffffffff",
      "aeeeffffffffffff",
      "vdffffffffffffff",
      "vdffffffffffffff",
      "vdffffffffffffff",
      "aeeeffffffffffff"
    ]
  ],
  "meta": [
    {
      "integer": 0,
      "key": "z1"
    },
    {
      "integer": 15,
      "key": "z2"
    }
  ]
}