{
  "name": "stair_deadzone_1",
  "refpalette": "c70cities:stair_deadzone_1_palette",
  "xsize": 16,
  "zsize": 16,
  "slices": [
    [
      "ababaaaaaaababcd",
      "a           efff",
      "a           efff",
      "b           efff",
      "avvvvvvvvvvbaacc",
      "a        HHggggg",
      "b        HHggggg",
      "b        HHggggg",
      "a        HHggggg",
      "a        HHggggg",
      "a        HHggggg",
      "bvvvvvvvvvvabvdc",
      "a           efff",
      "a           efff",
      "a           efff",
      "aaabbaaaababvacd"
    ],
    [
      "aabaaabababahh  ",
      "b         ef    ",
      "a         ef    ",
      "a         ef    ",
      "avvvvvvvvaabhi  ",
      "b      HHg      ",
      "b      HHg      ",
      "a      HHg      ",
      "a      HHg      ",
      "a      HHg      ",
      "v      HHg      ",
      "vvvvvvvvvvabhi  ",
      "b         ef    ",
      "a         ef    ",
      "v         ef    ",
      "bavaabaabvbahh  "
    ],
    [
      "baaaaaavbahhh   ",
      "b       ef      ",
      "a       ef      ",
      "b       ef      ",
      "vvvvvvvbbahhhj  ",
      "a    HHg        ",
      "b    HHg        ",
      "a    HHg        ",
      "a    HHg        ",
      "v    HHg        ",
      "b    HHg        ",
      "avvvvvvabahhhj  ",
      "b       ef      ",
      "b       ef      ",
      "a       ef      ",
      "bavabbvbvahhh   "
    ],
    [
      "aabavavahhh     ",
      "b     ef        ",
      "v     ef        ",
      "a     ef        ",
      "avvvvvaahhh  k  ",
      "a  HHg          ",
      "v  HHg          ",
      "a  HHg          ",
      "b  HHg          ",
      "b  HHg          ",
      "b  HHg          ",
      "avvvvavahhh  k  ",
      "b     ef        ",
      "b     ef        ",
      "a     ef        ",
      "abbbvvvvhhh     "
    ],
    [
      "abbabbhhh       ",
      "a   ef          ",
      "a   ef          ",
      "b   ef          ",
      "avvavbhhh       ",
      "bHHg            ",
      "bHHg            ",
      "vHHg            ",
      "vHHg            ",
      "bHHg            ",
      "vHHg            ",
      "bvvbbbhhh       ",
      "a   ef          ",
      "a   ef          ",
      "b   ef          ",
      "aavbvbhhh       "
    ],
    [
      "vbbvhhh         ",
      "beef            ",
      "veef            ",
      "beef            ",
      "bvbbhhh         ",
      "Hg              ",
      "Hg              ",
      "Hg              ",
      "Hg              ",
      "Hg              ",
      "Hg              ",
      "vbvbhhh         ",
      "beef            ",
      "beef            ",
      "veef            ",
      "bvbahhh         "
    ]
  ],
  "meta": [
    {
      "integer": 0,
      "key": "z1"
    },
    {
      "integer": 15,
      "key": "z2"
    }
  ]
}