{
  "name": "stair_4",
  "refpalette": "c70cities:stair_4_palette",
  "xsize": 16,
  "zsize": 16,
  "slices": [
    [
      "aaaa            ",
      "GGbc            ",
      "GGbc            ",
      "GGbc            ",
      "GGbc            ",
      "aGbc            ",
      "GGbc            ",
      "GGbc            ",
      "GGbc            ",
      "GGbc            ",
      "aGbc            ",
      "GGbc            ",
      "GGbc            ",
      "GGbc            ",
      "GGbc            ",
      "aaaa            "
    ],
    [
      "ddddd           ",
      "efddd           ",
      "egddd           ",
      "edddd           ",
      "egddd           ",
      "hfddd           ",
      "egddd           ",
      "egddd           ",
      "efddd           ",
      "egddd           ",
      "hdddd           ",
      "egddd           ",
      "efddd           ",
      "egddd           ",
      "edddd           ",
      "ddddd           "
    ],
    [
      "ddddd           ",
      "ddddd           ",
      "edddd           ",
      "edddd           ",
      "edddd           ",
      "hdddd           ",
      "edddd           ",
      "edddd           ",
      "edddd           ",
      "edddd           ",
      "hdddd           ",
      "edddd           ",
      "edddd           ",
      "ddddd           ",
      "edddd           ",
      "ddddd           "
    ],
    [
      "ddddd           ",
      "ddddd           ",
      "ddddd           ",
      "edddd           ",
      "ddddd           ",
      "hhddd           ",
      "ddddd           ",
      "ddddd           ",
      "edddd           ",
      "ddddd           ",
      "hhddd           ",
      "ddddd           ",
      "ddddd           ",
      "ddddd           ",
      "ddddd           ",
      "ddddd           "
    ],
    [
      "ddddd           ",
      "ddddd           ",
      "ddddd           ",
      "ddddd           ",
      "idddd           ",
      "hhhdd           ",
      "ddddi           ",
      "ddddd           ",
      "ddddd           ",
      "ddddi           ",
      "hhhdd           ",
      "idddd           ",
      "ddddd           ",
      "ddddd           ",
      "ddddd           ",
      "ddddd           "
    ],
    [
      "vdddd           ",
      "vdddd           ",
      "vdddd           ",
      "jvddd           ",
      "jjvdd           ",
      "jjjvv           ",
      "jjjjjv          ",
      "jjjjjv          ",
      "jjjjjv          ",
      "jjjjjv          ",
      "jjjvv           ",
      "jjvd            ",
      "jvddd           ",
      "vdddd           ",
      "vdddd           ",
      "vdddd           "
    ]
  ],
  "meta": [
    {
      "integer": 3,
      "key": "z1"
    },
    {
      "integer": 12,
      "key": "z2"
    }
  ]
}