{
  "name": "stair_5",
  "refpalette": "c70cities:stair_5_palette",
  "xsize": 16,
  "zsize": 16,
  "slices": [
    [
      "aaaaaaaaaaaabccb",
      "aaaaaaaaaaaabccb",
      "aaaaaaaaaaadvvvv",
      "aaaaaaaaaaadvvvv",
      "aaaaaaaaaaaddddd",
      "aaaaaaaaaaaaaaaa",
      "aaaaaaaaaaaaaaaa",
      "aaaaaaaaaaaaaaaa",
      "aaaaaaaaaaaaaaaa",
      "aaaaaaaaaaaaaaaa",
      "aaaaaaaaaaaaaaaa",
      "dddddaaaaaaddddd",
      "vaaedaaaaaadeaav",
      "aaaadaaaaaadaaaa",
      "aaaadaaaaaadaaaa",
      "vaaedaaaaaadeaav"
    ],
    [
      "aaaaaaaaaaaaaaaa",
      "aaaaaaaaaaaaaaaa",
      "aaaaaaaaaaaafbbf",
      "aaaaaaaaaaaavccv",
      "aaaaaaaaaaaagaag",
      "aaaaaaaaaaaaaaaa",
      "aaaaaaaaaaaaaaaa",
      "aaaaaaaaaaaaaaaa",
      "aaaaaaaaaaaaaaaa",
      "aaaaaaaaaaaaaaaa",
      "aaaaaaaaaaaaaaaa",
      "aaaaaaaaaaaaaaaa",
      "vaaeaaaaaaaaeaav",
      "aaaaaaaaaaaaaaaa",
      "aaaaaaaaaaaaaaaa",
      "vaaeaaaaaaaaeaav"
    ],
    [
      "aaaaaaaaaaaaaaaa",
      "aaaaaaaaaaaaaaaa",
      "aaaaaaaaaaaahaah",
      "aaaaaaaaaaaavaav",
      "aaaaaaaaaaaaibbi",
      "aaaaaaaaaaaavjjv",
      "aaaaaaaaaaaagaag",
      "aaaaaaaaaaaagaag",
      "aaaaaaaaaaaagaag",
      "aaaaaaaaaaaagaag",
      "aaaaaaaaaaaaaaaa",
      "aaaaaaaaaaaaaaaa",
      "vaaeaaaaaaaaeaav",
      "aaaaaaaaaaaaaaaa",
      "aaaaaaaaaaaaaaaa",
      "vaaeaaaaaaaaeaav"
    ],
    [
      "aaaaaaaaaaaaaaaa",
      "aaaaaaaaaaaaaaaa",
      "aaaaaaaaaaaaaaaa",
      "aaaaaaaaaaaaaaaa",
      "aaaaaaaaaaaaiaai",
      "aaaaaaaaaaaaiaai",
      "aaaaaaaaaaaaibbi",
      "aaaaaaaaaaaaibbi",
      "aaaaaaaaaaaaibbi",
      "aaaaaaaaaaaaibbi",
      "aaaaaaaaaaaavjjv",
      "aaaaaaaaaaaagaag",
      "vaaeaaaaaaaaeaav",
      "aaaaaaaaaaaaaaaa",
      "aaaaaaaaaaaaaaaa",
      "vaaeaaaaaaaaeaav"
    ],
    [
      "aaaaaaaaaaaaaaaa",
      "aaaaaaaaaaaaaaaa",
      "aaaaaaaaaaaaaaaa",
      "aaaaaaaaaaaaaaaa",
      "aaaaaaaaaaaaaaaa",
      "aaaaaaaaaaaaaaaa",
      "aaaaaaaaaaaaaaaa",
      "aaaaaaaaaaaaaaaa",
      "aaaaaaaaaaaaaaaa",
      "aaaaaaaaaaaaiaai",
      "aaaaaaaaaaaaiaai",
      "aaaaaaaaaaaaibbi",
      "vggvggggggggvjjv",
      "gaagaaaaaaaagaag",
      "gaagaaaaaaaagaag",
      "vggvggggggggvggv"
    ],
    [
      "aaaaaaaaaaaaaaaa",
      "aaaaaaaaaaaaaaaa",
      "aaaaaaaaaaaaaaaa",
      "aaaaaaaaaaaaaaaa",
      "aaaaaaaaaaaaaaaa",
      "aaaaaaaaaaaaaaaa",
      "aaaaaaaaaaaaaaaa",
      "aaaaaaaaaaaaaaaa",
      "aaaaaaaaaaaaaaaa",
      "aaaaaaaaaaaaaaaa",
      "aaaaaaaaaaaaaaaa",
      "aaaaaaaaaaaaaaaa",
      "vddviiiiiiiivaav",
      "bbbbbbbbbbbbbbbd",
      "bbbbbbbbbbbbbbbd",
      "vddviiiiiiiivddv"
    ]
  ],
  "meta": [
    {
      "integer": 12,
      "key": "z1"
    },
    {
      "integer": 15,
      "key": "z2"
    }
  ]
}