{
  "name": "stair_2",
  "refpalette": "c70cities:stair_2_palette",
  "xsize": 16,
  "zsize": 16,
  "slices": [
    [
      "aaaaaaaaaaaaaaaa",
      "abbbbbbbbbbbbbba",
      "abGGGGGGGGGGGGba",
      "abGGGGGGGGGGGGba",
      "ccccccccccccccaa",
      "cddddddddddHHeee",
      "cddddddddddHHeee",
      "cddddddddddHHeee",
      "cddddddddddHHeee",
      "cddddddddddHHeee",
      "cddddddddddHHeee",
      "cccHccHccHccccaa",
      "abGGGGGGGGGGGGba",
      "abGGGGGGGGGGGGba",
      "abbbbbbbbbbbbbba",
      "aaaaaaaaaaaaaaaa"
    ],
    [
      "ffffffffffffffff",
      "fggggggggggggggf",
      "fgfhffhffhffhfgf",
      "fgffffffffffffgf",
      "ccciccicciccafff",
      "cddjddjddjHeffff",
      "cddddddddHHeffff",
      "cddddddddHHeffff",
      "cddddddddHHeffff",
      "cddddddddHHeffff",
      "cddjddjddjHeffff",
      "ccciccicciccafff",
      "fgffffffffffffgf",
      "fgfhffhffhffhfgf",
      "fggfggggggggfggf",
      "ffffffffffffffff"
    ],
    [
      "ffffffffffffffff",
      "ffffffffffffffff",
      "fffhffhffhffhfff",
      "ffffffffffffffff",
      "ccccccccccafffff",
      "cddddddHHeffffff",
      "cddddddHHeffffff",
      "cddddddHHeffffff",
      "cddddddHHeffffff",
      "cddddddHHeffffff",
      "cddddddHHeffffff",
      "ccccccccccafffff",
      "ffffffffffffffff",
      "fffhffhffhffhfff",
      "ffffffffffffffff",
      "ffffffffffffffff"
    ],
    [
      "ffffffffffffffff",
      "ffffffffffffffff",
      "ffffffffffffffff",
      "ffffffffffffffff",
      "ccccccccafffffff",
      "cddddHHeffffffff",
      "cddddHHeffffffff",
      "cddddHHeffffffff",
      "cddddHHeffffffff",
      "cddddHHeffffffff",
      "cddddHHeffffffff",
      "ccccccccafffffff",
      "ffffffffffffffff",
      "ffffffffffffffff",
      "ffffffffffffffff",
      "ffffffffffffffff"
    ],
    [
      "ffffffffffffffff",
      "ffffffffffffffff",
      "ffffffffffffffff",
      "ffffffffffffffff",
      "ccccccafffffffff",
      "cddHHeffffffffff",
      "cddHHeffffffffff",
      "cddHHeffffffffff",
      "cddHHeffffffffff",
      "cddHHeffffffffff",
      "cddHHeffffffffff",
      "ccccccafffffffff",
      "ffffffffffffffff",
      "ffffffffffffffff",
      "ffffffffffffffff",
      "ffffffffffffffff"
    ],
    [
      "ffffffffffffffff",
      "ffffffffffffffff",
      "ffffffffffffffff",
      "ffffffffffffffff",
      "ccccafffffffffff",
      "HHHeffffffffffff",
      "HHHeffffffffffff",
      "HHHeffffffffffff",
      "HHHeffffffffffff",
      "HHHeffffffffffff",
      "HHHeffffffffffff",
      "ccccafffffffffff",
      "ffffffffffffffff",
      "ffffffffffffffff",
      "ffffffffffffffff",
      "ffffffffffffffff"
    ],
    [
      "ffffffffffffffff",
      "ffffffffffffffff",
      "ffffffffffffffff",
      "ffffffffffffffff",
      "ffffffffffffffff",
      "ffffffffffffffff",
      "ffffffffffffffff",
      "ffffffffffffffff",
      "ffffffffffffffff",
      "ffffffffffffffff",
      "ffffffffffffffff",
      "ffffffffffffffff",
      "ffffffffffffffff",
      "ffffffffffffffff",
      "ffffffffffffffff",
      "ffffffffffffffff"
    ]
  ],
  "meta": [
    {
      "integer": 5,
      "key": "z1"
    },
    {
      "integer": 10,
      "key": "z2"
    }
  ]
}