{
  "name": "treehouse_1",
  "refpalette": "c70cities:treehouse_1_palette",
  "xsize": 16,
  "zsize": 16,
  "slices": [
    [
      "aaaaaaaaaaaaaaaa",
      "aaaaaaaaaaaaaaaa",
      "aaaaaaaaaaaaaaaa",
      "aaaaaaaaaaaaaaaa",
      "aaaaaaaaaaaaaaaa",
      "aaaaaaaaaaaaaaaa",
      "aaaaaaaaaaaaaaaa",
      "aaaaaaaaaaaaaaaa",
      "aaaaaaaaaaaaaaaa",
      "aaaaaaaaaaaaaaaa",
      "aaaaaaaaaaaaaaaa",
      "aaaaaaaaaaaaaaaa",
      "aaaaaaaaaaaaaaaa",
      "aaaaaaaaaaaaaaaa",
      "aaaaaaaaaaaaaaaa",
      "aaaaaaaaaaaaaaaa"
    ],
    [
      "aaaaaaaaaaaaaaaa",
      "aaaaaaaaaaaaaaaa",
      "aaaaaaaaaaaaaaaa",
      "aaaaaaaaaaaaaaaa",
      "aaaaaaaaaaaaaaaa",
      "aaaaaaaaaaaaaaaa",
      "aaaaaaaaaaaaaaaa",
      "aaaaaaaaaaaaaaaa",
      "aaaaaaaaaaaaaaaa",
      "aaaaaaaaaaaaaaaa",
      "aaaaaaaaaaaaaaaa",
      "aaaaaaaaaaaaaaaa",
      "aaaaaaaaaaaaaaaa",
      "aaaaaaaaaaaaaaaa",
      "aaaaaaaaaaaaaaaa",
      "aaaaaaaaaaaaaaaa"
    ],
    [
      "GGGGGGGGGGGGGGGG",
      "GGGGGGGGGGGGGGGG",
      "GGGGGGGGGGGGGGGG",
      "GGGGGGGGGGGGGGGG",
      "GGGGGGGGGGGGGGGG",
      "GGaaGGGGbGbcbGGG",
      "GaaaGGGGcbbccGGG",
      "GaaaGGGdGbbbbGGG",
      "GaaaGGGebbbbGGGG",
      "GaGGGeGefbbbbGGG",
      "GGGGGGeGcbbbcGGG",
      "GGGGGeeGbcbcbGGG",
      "GGGGGeGebbbbGGGG",
      "GGGeeGGGGbcbcGGG",
      "GGGGGeGGGGGGGGGG",
      "GGeGGGGGGGGGGGGG"
    ],
    [
      "  gggg h gghgggg",
      "ggh gghgg h ghgh",
      "hgg h ghh gggggg",
      "gghgg   gg gg hg",
      "ghggg  iiiiiiigg",
      "ggjkgggi g   ih ",
      "gjjklggig  g i g",
      " jjkgg d     igh",
      "gjjkmhno    higg",
      " j p  g i    igg",
      "g l g        igg",
      " gg g      g ihg",
      "gg    g     gigg",
      "hg   g  g g  igh",
      "g     giiiiiiigg",
      "gg   g hgggh ggg"
    ],
    [
      "       q   q    ",
      "  q   q   q  q q",
      "q   q  qq       ",
      "  q           q ",
      " q              ",
      "              q ",
      "  j    i        ",
      "  j    dr      q",
      "  j  q o    q   ",
      "        i       ",
      "                ",
      "              q ",
      "                ",
      "q              q",
      "                ",
      "       q   q    "
    ],
    [
      "                ",
      "                ",
      "                ",
      "                ",
      "                ",
      "                ",
      "       isss     ",
      "      tdtus     ",
      "       osss     ",
      "        i       ",
      "                ",
      "                ",
      "                ",
      "                ",
      "                ",
      "                "
    ],
    [
      "                ",
      "                ",
      "                ",
      "                ",
      "                ",
      "       wwww     ",
      "     ssx iyA    ",
      "     urd  BA    ",
      "     ssoCiyA    ",
      "        iDD     ",
      "                ",
      "                ",
      "                ",
      "                ",
      "                ",
      "                "
    ],
    [
      "                ",
      "                ",
      "                ",
      "                ",
      "                ",
      "     www        ",
      "    Ei   i      ",
      "    EF d        ",
      "    Ei oIi      ",
      "     DD i       ",
      "                ",
      "                ",
      "                ",
      "                ",
      "                ",
      "                "
    ],
    [
      "                ",
      "                ",
      "                ",
      "                ",
      "                ",
      "                ",
      "     i  sJKK    ",
      "       dJLss    ",
      "     i oMMMM    ",
      "        i       ",
      "                ",
      "                ",
      "                ",
      "                ",
      "                ",
      "                "
    ],
    [
      "                ",
      "                ",
      "                ",
      "                ",
      "                ",
      "          N     ",
      "    KKKK NJN    ",
      "    ssLdxxxx    ",
      "    MMJo        ",
      "     J  i       ",
      "                ",
      "                ",
      "                ",
      "                ",
      "                ",
      "                "
    ],
    [
      "                ",
      "                ",
      "                ",
      "                ",
      "         NNN    ",
      "        jNNNN   ",
      "       jNNNNN   ",
      "    xxxdNNNNN   ",
      "       o NNN    ",
      "    N   i       ",
      "   NJN          ",
      "    N           ",
      "                ",
      "                ",
      "                ",
      "                "
    ],
    [
      "                ",
      "                ",
      "                ",
      "        N       ",
      "       NjNNN    ",
      "        NNNNN   ",
      "        ONNNN   ",
      "       dJNNNN   ",
      "   NNN oJNNN    ",
      "  NNNNN j       ",
      "  NNNNN         ",
      "  NNNNN         ",
      "   NNN          ",
      "                ",
      "                ",
      "                "
    ],
    [
      "                ",
      "                ",
      "       NNN      ",
      "      NNNNN     ",
      "      NNNNNN    ",
      "      NNNNNNN   ",
      "       NPNJNN   ",
      "       dQJNNN   ",
      "   NNN E NNN    ",
      "  NNNNN D       ",
      "  NNNNN  j      ",
      "  NNNNN NjN     ",
      "   NNN   N      ",
      "                ",
      "                ",
      "                "
    ],
    [
      "                ",
      "                ",
      "       NNN      ",
      "      NNNNN     ",
      "      NNNNN     ",
      "      NNNNN N   ",
      "       NRNNJJN  ",
      "       d SN N   ",
      "   NNN   R      ",
      "  NNNNN NNN     ",
      "  NNNNNNNNNN    ",
      "  NNNNNNNNNN    ",
      "   NNN NNNNN    ",
      "        NNN     ",
      "                ",
      "                "
    ],
    [
      "                ",
      "                ",
      "       NNN      ",
      "      NNNNN     ",
      "      NNNNNNNN  ",
      "      NNNNNNNNN ",
      "       NNNNNNNN ",
      "      NdNRNNNNN ",
      "       NR  NNN  ",
      "    N   NNN     ",
      "   NNN NNNNN    ",
      "    N  NNNNN    ",
      "       NNNNN    ",
      "        NNN     ",
      "                ",
      "                "
    ],
    [
      "                ",
      "                ",
      "                ",
      "        N       ",
      "       NNN NNN  ",
      "      NNN NNNNN ",
      "     NNNNNNNNNN ",
      "     NNNNNNNNNN ",
      "     NNNNN NNN  ",
      "      NNNNN     ",
      "       NNNNN    ",
      "       NNNNN    ",
      "       NNNNN    ",
      "        NNN     ",
      "                ",
      "                "
    ],
    [
      "                ",
      "                ",
      "                ",
      "                ",
      "           NNN  ",
      "      NNN NNNNN ",
      "     NNNNNNNNNN ",
      "     NNNNNNNNNN ",
      "     NNNNN NNN  ",
      "      NNN       ",
      "         N      ",
      "        NNN     ",
      "         N      ",
      "                ",
      "                ",
      "                "
    ],
    [
      "                ",
      "                ",
      "                ",
      "                ",
      "                ",
      "      NNN   N   ",
      "     NNNNN NNN  ",
      "     NNNNN  N   ",
      "     NNNNN      ",
      "      NNN       ",
      "                ",
      "                ",
      "                ",
      "                ",
      "                ",
      "                "
    ],
    [
      "                ",
      "                ",
      "                ",
      "                ",
      "                ",
      "                ",
      "       N        ",
      "      NNN       ",
      "       N        ",
      "                ",
      "                ",
      "                ",
      "                ",
      "                ",
      "                ",
      "                "
    ]
  ]
}