{
  "name": "treehouse_1",
  "refpalette": "c70cities:treehouse_1_palette",
  "xsize": 16,
  "zsize": 16,
  "slices": [
    [
      "aaaaaaaaaaaaaaaa",
      "aaaaaaaaaaaaaaaa",
      "aaaaaaaaaaaaaaaa",
      "aaaaaaaaaaaaaaaa",
      "aaaaaaaaaaaaaaaa",
      "aaaaaaaaaaaaaaaa",
      "aaaaaaaaaaaaaaaa",
      "aaaaaaaaaaaaaaaa",
      "aaaaaaaaaaaaaaaa",
      "aaaaaaaaaaaaaaaa",
      "aaaaaaaaaaaaaaaa",
      "aaaaaaaaaaaaaaaa",
      "aaaaaaaaaaaaaaaa",
      "aaaaaaaaaaaaaaaa",
      "aaaaaaaaaaaaaaaa",
      "aaaaaaaaaaaaaaaa"
    ],
    [
      "aaaaaaaaaaaaaaaa",
      "aaaaaaaaaaaaaaaa",
      "aaaaaaaaaaaaaaaa",
      "aaaaaaaaaaaaaaaa",
      "aaaaaaaaaaaaaaaa",
      "aaaaaaaaaaaaaaaa",
      "aaaaaaaaaaaaaaaa",
      "aaaaaaaaaaaaaaaa",
      "aaaaaaaaaaaaaaaa",
      "aaaaaaaaaaaaaaaa",
      "aaaaaaaaaaaaaaaa",
      "aaaaaaaaaaaaaaaa",
      "aaaaaaaaaaaaaaaa",
      "aaaaaaaaaaaaaaaa",
      "aaaaaaaaaaaaaaaa",
      "aaaaaaaaaaaaaaaa"
    ],
    [
      "GGGGGGGGGGGGGGGG",
      "GGGGGGGGGGGGGGGG",
      "GGGGGGGGGGGGGGGG",
      "GGGGGGGGGGGGGGGG",
      "GGGGGGGGGGGGGGGG",
      "GGaaGGGGbGbcbGGG",
      "GaaaGGGGcbbccGGG",
      "GaaaGGGdGbbbbGGG",
      "GaaaGGGebbbbGGGG",
      "GaGGGeGefbbbbGGG",
      "GGGGGGeGcbbbcGGG",
      "GGGGGeeGbcbcbGGG",
      "GGGGGeGebbbbGGGG",
      "GGGeeGGGcbcbcGGG",
      "GGGGGeGGGGGGGGGG",
      "GGeGGGGGGGGGGGGG"
    ],
    [
      "                ",
      "                ",
      "                ",
      "                ",
      "       ggggggg  ",
      "  hi   g     g  ",
      " hhij  g     g  ",
      " hhi   d     g  ",
      " hhik lm     g  ",
      " h n    g    g  ",
      "  j          g  ",
      "             g  ",
      "             g  ",
      "             g  ",
      "       ggggggg  ",
      "                "
    ],
    [
      "                ",
      "                ",
      "                ",
      "                ",
      "                ",
      "                ",
      "  h    g        ",
      "  h    do       ",
      "  h    m        ",
      "        g       ",
      "                ",
      "                ",
      "                ",
      "                ",
      "                ",
      "                "
    ],
    [
      "                ",
      "                ",
      "                ",
      "                ",
      "                ",
      "                ",
      "       gppp     ",
      "      qdqrp     ",
      "       mppp     ",
      "        g       ",
      "                ",
      "                ",
      "                ",
      "                ",
      "                ",
      "                "
    ],
    [
      "                ",
      "                ",
      "                ",
      "                ",
      "                ",
      "       ssss     ",
      "     ppt guw    ",
      "     rod  xw    ",
      "     ppmyguw    ",
      "        gAA     ",
      "                ",
      "                ",
      "                ",
      "                ",
      "                ",
      "                "
    ],
    [
      "                ",
      "                ",
      "                ",
      "                ",
      "                ",
      "     sss        ",
      "    Bg   g      ",
      "    BC d        ",
      "    Bg mDg      ",
      "     AA g       ",
      "                ",
      "                ",
      "                ",
      "                ",
      "                ",
      "                "
    ],
    [
      "                ",
      "                ",
      "                ",
      "                ",
      "                ",
      "                ",
      "     g  pEFF    ",
      "       dEIpp    ",
      "     g mJJJJ    ",
      "        g       ",
      "                ",
      "                ",
      "                ",
      "                ",
      "                ",
      "                "
    ],
    [
      "                ",
      "                ",
      "                ",
      "                ",
      "                ",
      "          K     ",
      "    FFFF KEK    ",
      "    ppIdtttt    ",
      "    JJEm        ",
      "     E  g       ",
      "                ",
      "                ",
      "                ",
      "                ",
      "                ",
      "                "
    ],
    [
      "                ",
      "                ",
      "                ",
      "                ",
      "         KKK    ",
      "        hKKKK   ",
      "       hKKKKK   ",
      "    tttdKKKKK   ",
      "       m KKK    ",
      "    K   g       ",
      "   KEK          ",
      "    K           ",
      "                ",
      "                ",
      "                ",
      "                "
    ],
    [
      "                ",
      "                ",
      "                ",
      "        K       ",
      "       KhKKK    ",
      "        KKKKK   ",
      "        LKKKK   ",
      "       dEKKKK   ",
      "   KKK mEKKK    ",
      "  KKKKK h       ",
      "  KKKKK         ",
      "  KKKKK         ",
      "   KKK          ",
      "                ",
      "                ",
      "                "
    ],
    [
      "                ",
      "                ",
      "       KKK      ",
      "      KKKKK     ",
      "      KKKKKK    ",
      "      KKKKKKK   ",
      "       MNKEKK   ",
      "       dOEKKK   ",
      "   KKK B KKK    ",
      "  KKKKK A       ",
      "  KKKKK  h      ",
      "  KKKKK KhK     ",
      "   KKK   K      ",
      "                ",
      "                ",
      "                "
    ],
    [
      "                ",
      "                ",
      "       KKK      ",
      "      KKKKK     ",
      "      KKKKK     ",
      "      KKKKK K   ",
      "       MPKKEEK  ",
      "       d  K K   ",
      "   KKK   P      ",
      "  KKKKK KKK     ",
      "  KKKKKKKKKK    ",
      "  KKKKKKKKKK    ",
      "   KKK KKKKK    ",
      "        KKK     ",
      "                ",
      "                "
    ],
    [
      "                ",
      "                ",
      "       KKK      ",
      "      KKKKK     ",
      "      KKKKKKKK  ",
      "      KKKKKKKKK ",
      "       KKKKKKKK ",
      "      KdKPKKKKK ",
      "       KP  KKK  ",
      "    K   KKK     ",
      "   KKK KKKKK    ",
      "    K  KKKKK    ",
      "       KKKKK    ",
      "        KKK     ",
      "                ",
      "                "
    ],
    [
      "                ",
      "                ",
      "                ",
      "        K       ",
      "       KKK KKK  ",
      "      KKK KKKKK ",
      "     KKKKKKKKKK ",
      "     KKKKKKKKKK ",
      "     KKKKK KKK  ",
      "      KKKKK     ",
      "       KKKKK    ",
      "       KKKKK    ",
      "       KKKKK    ",
      "        KKK     ",
      "                ",
      "                "
    ],
    [
      "                ",
      "                ",
      "                ",
      "                ",
      "           KKK  ",
      "      KKK KKKKK ",
      "     KKKKKKKKKK ",
      "     KKKKKKKKKK ",
      "     KKKKK KKK  ",
      "      KKK       ",
      "         K      ",
      "        KKK     ",
      "         K      ",
      "                ",
      "                ",
      "                "
    ],
    [
      "                ",
      "                ",
      "                ",
      "                ",
      "                ",
      "      KKK   K   ",
      "     KKKKK KKK  ",
      "     KKKKK  K   ",
      "     KKKKK      ",
      "      KKK       ",
      "                ",
      "                ",
      "                ",
      "                ",
      "                ",
      "                "
    ],
    [
      "                ",
      "                ",
      "                ",
      "                ",
      "                ",
      "                ",
      "       K        ",
      "      KKK       ",
      "       K        ",
      "                ",
      "                ",
      "                ",
      "                ",
      "                ",
      "                ",
      "                "
    ]
  ]
}