{
  "name": "villager_1",
  "refpalette": "c70cities:villager_1_palette",
  "xsize": 16,
  "zsize": 16,
  "slices": [
    [
      "aaaaaaaaaaaaaaaa",
      "aaaaaaaaaaaaaaaa",
      "aaaaaaaaaaaaaaaa",
      "aaaaaaaaaaaaaaaa",
      "aaaaaaaaaaaaaaaa",
      "aaaaaaaaaaaaaaaa",
      "aaaaaaaaaaaaaaaa",
      "aaaaaaaaaaaaaaaa",
      "aaaaaaaaaaaaaaaa",
      "aaaaaaaaaaaaaaaa",
      "aaaaaaaaaaaaaaaa",
      "aaaaaaaaaaaaaaaa",
      "aaaaaaaaaaaaaaaa",
      "aaaaaaaaaaaaaaaa",
      "aaaaaaaaaaaaaaaa",
      "aaaaaaaaaaaaaaaa"
    ],
    [
      "aaaaaaaaaaaaaaaa",
      "aaaaaaaaaaaaaaaa",
      "aaaaaaaaaaaaaaaa",
      "aaaaaaaaaaaaaaaa",
      "aaaaaaaaaaaaaaaa",
      "aaaaaaaaaaaaaaaa",
      "aaaaaaaaaaaaaaaa",
      "aaaaaaaaaaaaaaaa",
      "aaaaaaaaaaaaaaaa",
      "aaaaaaaaaaaaaaaa",
      "aaaaaaaaaaaaaaaa",
      "aaaaaaaaaaaaaaaa",
      "aaaaaaaaaaaaaaaa",
      "aaaaaaaaaaaaaaaa",
      "aaaaaaaaaaaaaaaa",
      "aaaaaaaaaaaaaaaa"
    ],
    [
      "GGGGGGGGGGGGGGGG",
      "GGGGbGbGbGGbGGGG",
      "GGGbGbGbbbGbGbGG",
      "GGbbbGGGGGGGbGGG",
      "GbGbGGvvvvGGbGbG",
      "GGbGGvvvvvvGGbbG",
      "GbbGvvvvvvvvGbbG",
      "GGbGvvvccvvvGbGG",
      "GbbGvvvccvvvGbbG",
      "GbbGvvvvvvvvGbbG",
      "GGbGGvvvvvvGGGbG",
      "GbGbGGvvvvGGGbbG",
      "GGbbbGGGGGGGbbGG",
      "GGGGbbGbbbbbGGGG",
      "GGGGbGbbbbbGbGGG",
      "GGGGGGGGGGGGGGGG"
    ],
    [
      "                ",
      "                ",
      "                ",
      "      de f      ",
      "     evvvve     ",
      "   dfvggggve    ",
      "   evghgghgvf   ",
      "   fvggicggve   ",
      "   evggjjggvd   ",
      "   evghgghgve   ",
      "    evggggve    ",
      "     fvvvvf     ",
      "      e  e      ",
      "                ",
      "                ",
      "                "
    ],
    [
      "                ",
      "                ",
      "                ",
      "                ",
      "                ",
      "                ",
      "                ",
      "       ji       ",
      "       cc       ",
      "                ",
      "                ",
      "                ",
      "                ",
      "                ",
      "                ",
      "                "
    ],
    [
      "                ",
      "                ",
      "                ",
      "                ",
      "                ",
      "                ",
      "      kl        ",
      "      icj       ",
      "      iji       ",
      "      kl        ",
      "                ",
      "                ",
      "                ",
      "                ",
      "                ",
      "                "
    ],
    [
      "                ",
      "                ",
      "                ",
      "                ",
      "                ",
      "                ",
      "       mi       ",
      "      nkc       ",
      "      nki       ",
      "       mi       ",
      "                ",
      "                ",
      "                ",
      "                ",
      "                ",
      "                "
    ],
    [
      "                ",
      "                ",
      "                ",
      "                ",
      "                ",
      "                ",
      "        o       ",
      "       pc       ",
      "       mc       ",
      "        q       ",
      "                ",
      "                ",
      "                ",
      "                ",
      "                ",
      "                "
    ],
    [
      "                ",
      "                ",
      "                ",
      "                ",
      "                ",
      "                ",
      "       rs       ",
      "      tpju      ",
      "      wxju      ",
      "       yA       ",
      "                ",
      "                ",
      "                ",
      "                ",
      "                ",
      "                "
    ],
    [
      "                ",
      "                ",
      "                ",
      "                ",
      "                ",
      "                ",
      "       ts       ",
      "      siiB      ",
      "      AccC      ",
      "       wA       ",
      "                ",
      "                ",
      "                ",
      "                ",
      "                ",
      "                "
    ],
    [
      "                ",
      "                ",
      "                ",
      "                ",
      "                ",
      "                ",
      "       st       ",
      "       DcC      ",
      "       DiB      ",
      "       yw       ",
      "                ",
      "                ",
      "                ",
      "                ",
      "                ",
      "                "
    ],
    [
      "                ",
      "                ",
      "                ",
      "                ",
      "                ",
      "                ",
      "       tt       ",
      "       ccB      ",
      "       ccB      ",
      "       Ay       ",
      "                ",
      "                ",
      "                ",
      "                ",
      "                ",
      "                "
    ],
    [
      "                ",
      "                ",
      "                ",
      "                ",
      "                ",
      "                ",
      "                ",
      "       EE       ",
      "       EE       ",
      "                ",
      "                ",
      "                ",
      "                ",
      "                ",
      "                ",
      "                "
    ]
  ]
}