{
  "name": "villager_1",
  "refpalette": "c70cities:villager_1_palette",
  "xsize": 16,
  "zsize": 16,
  "slices": [
    [
      "GGGGGGGGGGGGGGGG",
      "GGGGaGaGaGGaGGGG",
      "GGGaGaGaaaGaGaGG",
      "GGaaaGGGGGGGaGGG",
      "GaGaGGvvvvGGaGaG",
      "GGaGGvvvvvvGGaaG",
      "GaaGvvvvvvvvGaaG",
      "GGaGvvvbbvvvGaGG",
      "GaaGvvvbbvvvGaaG",
      "GaaGvvvvvvvvGaaG",
      "GGaGGvvvvvvGGGaG",
      "GaGaGGvvvvGGGaaG",
      "GGaaaGGGGGGGaaGG",
      "GGGGaaGaaaGaGGGG",
      "GGGGaGaaaaaGaGGG",
      "GGGGGGGGGGGGGGGG"
    ],
    [
      " c   c  ccc     ",
      "cc   c c c   cc ",
      "cc            c ",
      "c     cd ec   c ",
      "     dvvvvdc    ",
      "c  cevffffvdc   ",
      "   dvfgffgfve  c",
      "c  evffhbffvd   ",
      "c  dvffiiffvc  c",
      "c  dvfgffgfvd  c",
      "cc cdvffffvdcc c",
      "  c cevvvve c   ",
      "     cdcddcc   c",
      " ccc  c     cc c",
      "cc c          c ",
      " c      c c     "
    ],
    [
      "                ",
      "                ",
      "                ",
      "                ",
      "                ",
      "                ",
      "                ",
      "       ih       ",
      "       bb       ",
      "                ",
      "                ",
      "                ",
      "                ",
      "                ",
      "                ",
      "                "
    ],
    [
      "                ",
      "                ",
      "                ",
      "                ",
      "                ",
      "                ",
      "      jk        ",
      "      hbi       ",
      "      hih       ",
      "      jk        ",
      "                ",
      "                ",
      "                ",
      "                ",
      "                ",
      "                "
    ],
    [
      "                ",
      "                ",
      "                ",
      "                ",
      "                ",
      "                ",
      "       lh       ",
      "      mjb       ",
      "      mjh       ",
      "       lh       ",
      "                ",
      "                ",
      "                ",
      "                ",
      "                ",
      "                "
    ],
    [
      "                ",
      "                ",
      "                ",
      "                ",
      "                ",
      "                ",
      "        n       ",
      "       ob       ",
      "       lb       ",
      "        p       ",
      "                ",
      "                ",
      "                ",
      "                ",
      "                ",
      "                "
    ],
    [
      "                ",
      "                ",
      "                ",
      "                ",
      "                ",
      "                ",
      "       qr       ",
      "      soit      ",
      "      uwit      ",
      "       xy       ",
      "                ",
      "                ",
      "                ",
      "                ",
      "                ",
      "                "
    ],
    [
      "                ",
      "                ",
      "                ",
      "                ",
      "                ",
      "                ",
      "       sr       ",
      "      rhhA      ",
      "      ybbB      ",
      "       uy       ",
      "                ",
      "                ",
      "                ",
      "                ",
      "                ",
      "                "
    ],
    [
      "                ",
      "                ",
      "                ",
      "                ",
      "                ",
      "                ",
      "       rs       ",
      "       CbB      ",
      "       ChA      ",
      "       xu       ",
      "                ",
      "                ",
      "                ",
      "                ",
      "                ",
      "                "
    ],
    [
      "                ",
      "                ",
      "                ",
      "                ",
      "                ",
      "                ",
      "       ss       ",
      "       bbA      ",
      "       bbA      ",
      "       yx       ",
      "                ",
      "                ",
      "                ",
      "                ",
      "                ",
      "                "
    ],
    [
      "                ",
      "                ",
      "                ",
      "                ",
      "                ",
      "                ",
      "                ",
      "       DD       ",
      "       DD       ",
      "                ",
      "                ",
      "                ",
      "                ",
      "                ",
      "                ",
      "                "
    ]
  ]
}