{
  "name": "highway_bridge_bi",
  "refpalette": "c70cities:highway_bridge_bi_palette",
  "xsize": 16,
  "zsize": 16,
  "slices": [
    [
      "vvvvvvvvvvvvvvvv",
      "vvvvvvvvvvvvvvvv",
      "vvvvvvvvvvvvvvvv",
      "vvvvvvvvvvvvvvvv",
      "vvvvvvvvvvvvvvvv",
      "vvvvvvvvvvvvvvvv",
      "vvvvvvvvvvvvvvvv",
      "vvvvvvvvvvvvvvvv",
      "vvvvvvvvvvvvvvvv",
      "vvvvvvvvvvvvvvvv",
      "vvvvvvvvvvvvvvvv",
      "vvvvvvvvvvvvvvvv",
      "vvvvvvvvvvvvvvvv",
      "vvvvvvvvvvvvvvvv",
      "vvvvvvvvvvvvvvvv",
      "vvvvvvvvvvvvvvv "
    ],
    [
      "v=aaaaa==HH HH=v",
      "==HHHHH==HHHHH==",
      "HHHHHHHHHHbHHHHa",
      "HHHHHHHHHbHHHHHa",
      "HHHHHHcHHHHHHHHa",
      "HHHHHHHHdHHHHHHa",
      "HHHHebHHHHHHHHHa",
      "==HHbHHHHHdHHH==",
      "==HHbHHdHfHHHH==",
      "aHHcHHHdHHHHHHHH",
      "aHHHHcHdfHHHHHHH",
      "aHHHdHHHHHHdHHHH",
      "aHHHHHddHHHHHHHH",
      "aHHHHHHdHHHHHHHH",
      "==HHHHH==HHHHH==",
      "v=HHHHH==aaaaa=v"
    ],
    [
      "gh            hg",
      "hh            hh",
      "     iii        ",
      "                ",
      "    j      k    ",
      "           k    ",
      "           k    ",
      "                ",
      "                ",
      "           j    ",
      "            k   ",
      " l    j     k   ",
      "          mm    ",
      "                ",
      "hh  i     m   hh",
      "ghn           hg"
    ],
    [
      "g              g",
      "                ",
      "                ",
      "                ",
      "                ",
      "                ",
      "                ",
      "                ",
      "                ",
      "                ",
      "                ",
      "                ",
      "                ",
      "                ",
      "                ",
      "g              g"
    ],
    [
      "n              n",
      "                ",
      "                ",
      "                ",
      "                ",
      "                ",
      "                ",
      "                ",
      "                ",
      "                ",
      "                ",
      "                ",
      "                ",
      "                ",
      "                ",
      "n              n"
    ],
    [
      "n               ",
      "                ",
      "                ",
      "                ",
      "                ",
      "                ",
      "                ",
      "                ",
      "                ",
      "                ",
      "                ",
      "                ",
      "                ",
      "                ",
      "                ",
      "               n"
    ]
  ],
  "meta": [
    {
      "key": "support",
      "char": "v"
    }
  ]
}