{
  "name": "highway_tunnel",
  "refpalette": "c70cities:highway_tunnel_palette",
  "xsize": 16,
  "zsize": 16,
  "slices": [
    [
      "aaaaaaaaaaaaaaaa",
      "vvvvvvvvvvvvvvvv",
      "v               ",
      "v               ",
      "v               ",
      "v               ",
      "v               ",
      "v               ",
      "v               ",
      "v               ",
      "v               ",
      "v               ",
      "v               ",
      "v               ",
      "vvvvvvvvvvvvvvvv",
      "bbbbbbbbbbbbbbbb"
    ],
    [
      "vvvvvvvvvvvvvvvv",
      "================",
      "HHHHHHHHHHHHHHHH",
      "HHHHHHHHHHHHHHHH",
      "HccHHccHHccHHccH",
      "HHHHHHHHHHHHHHHH",
      "HHHHHHHHHHHHHHHH",
      "HHHHHHHHHHHHHHHH",
      "HHHHHHHHHHHHHHHH",
      "HHHHHHHHHHHHHHHH",
      "HHHHHHHHHHHHHHHH",
      "HccHHccHHccHHccH",
      "HHHHHHHHHHHHHHHH",
      "HHHHHHHHHHHHHHHH",
      "================",
      "vvvvvvvvvvvvvvvv"
    ],
    [
      "vvvdvvvvvvvdvvvv",
      "eee~eeeeeee~eeee",
      "~~~~~~~~~~~~~~~~",
      "~~~~~~~~~~~~~~~~",
      "~~~~~~~~~~~~~~~~",
      "~~~~~~~~~~~~~~~~",
      "~~~~~~~~~~~~~~~~",
      "ffffffffffffffff",
      "ffffffffffffffff",
      "~~~~~~~~~~~~~~~~",
      "~~~~~~~~~~~~~~~~",
      "~~~~~~~~~~~~~~~~",
      "~~~~~~~~~~~~~~~~",
      "~~~~~~~~~~~~~~~~",
      "eee~eeeeeee~eeee",
      "vvvgvvvvvvvgvvvv"
    ],
    [
      "vvvdvvvvvvvdvvvv",
      "~~~~~~~~~~~~~~~~",
      "~~~~~~~~~~~~~~~~",
      "~~~~~~~~~~~~~~~~",
      "~~~~~~~~~~~~~~~~",
      "~~~~~~~~~~~~~~~~",
      "~~~~~~~~~~~~~~~~",
      "~~~~~~~~~~~~~~~~",
      "~~~~~~~~~~~~~~~~",
      "~~~~~~~~~~~~~~~~",
      "~~~~~~~~~~~~~~~~",
      "~~~~~~~~~~~~~~~~",
      "~~~~~~~~~~~~~~~~",
      "~~~~~~~~~~~~~~~~",
      "~~~~~~~~~~~~~~~~",
      "vvvgvvvvvvvgvvvv"
    ],
    [
      "vvvvvvvvvvvvvvvv",
      "~~~~~~~~~~~~~~~~",
      "~~~~~~~~~~~~~~~~",
      "~~~~~~~~~~~~~~~~",
      "~~~~~~~~~~~~~~~~",
      "~~~~~~~~~~~~~~~~",
      "~~~~~~~~~~~~~~~~",
      "~~~~~~~~~~~~~~~~",
      "~~~~~~~~~~~~~~~~",
      "~~~~~~~~~~~~~~~~",
      "~~~~~~~~~~~~~~~~",
      "~~~~~~~~~~~~~~~~",
      "~~~~~~~~~~~~~~~~",
      "~~~~~~~~~~~~~~~~",
      "~~~~~~~~~~~~~~~~",
      "vvvvvvvvvvvvvvvv"
    ],
    [
      "                ",
      "vvvvvvvvvvvvvvvv",
      "vvvvvvvvvvvvvvvv",
      "~~~~~~~~~~~~~~~~",
      "~~~~~~~~~~~~~~~~",
      "~~~~~~~~~~~~~~~~",
      "~~~~~~~~~~~~~~~~",
      "~~~~~~~~~~~~~~~~",
      "~~~~~~~~~~~~~~~~",
      "~~~~~~~~~~~~~~~~",
      "~~~~~~~~~~~~~~~~",
      "~~~~~~~~~~~~~~~~",
      "~~~~~~~~~~~~~~~~",
      "vvvvvvvvvvvvvvvv",
      "vvvvvvvvvvvvvvvv",
      "                "
    ],
    [
      "                ",
      "                ",
      "                ",
      "vvvvvvvvvvvvvvvv",
      "vvvhvvvvvvvvvvvv",
      "vvvvvvvvvvvvvvvv",
      "vvvvvvvvvvvvvvvv",
      "vvvvvvvvvvvvvvvv",
      "vvvvvvvvvvvvvvvv",
      "vvvvvvvvvvvvvvvv",
      "vvvvvvvvvvvvvvvv",
      "vvvhvvvvvvvvvvvv",
      "vvvvvvvvvvvvvvvv",
      "                ",
      "                ",
      "                "
    ]
  ]
}