{
  "name": "highway_bridge_bi",
  "refpalette": "c70cities:highway_bridge_bi_palette",
  "xsize": 16,
  "zsize": 16,
  "slices": [
    [
      "vvvvvvvvvvvvvvvv",
      "vvvvvvvvvvvvvvvv",
      "vvvvvvvvvvvvvvvv",
      "vvvvvvvvvvvvvvvv",
      "vvvvvvvvvvvvvvvv",
      "vvvvvvvvvvvvvvvv",
      "vvvvvvvvvvvvvvvv",
      "vvvvvvvvvvvvvvvv",
      "vvvvvvvvvvvvvvvv",
      "vvvvvvvvvvvvvvvv",
      "vvvvvvvvvvvvvvvv",
      "vvvvvvvvvvvvvvvv",
      "vvvvvvvvvvvvvvvv",
      "vvvvvvvvvvvvvvvv",
      "vvvvvvvvvvvvvvvv",
      "vvvvvvvvvvvvvvv "
    ],
    [
      "v=aaaaa==HH HH=v",
      "==HHHHH==HHHHH==",
      "HHHHHHHHHHbHHHHa",
      "HHHHHHHHHbHHHHHa",
      "HHHHHHcHHHHHHHHa",
      "HHHHHHHHdHHHHHHa",
      "HHHHebHHHHHHHHHa",
      "==HHbHHHHHdHHH==",
      "==HHbHHdHfHHHH==",
      "aHHcHHHdHHHHHHHH",
      "aHHHHcHdfHHHHHHH",
      "aHHHdHHHHHHdHHHH",
      "aHHHHHddHHHHHHHH",
      "aHHHHHHdHHHHHHHH",
      "==HHHHH==HHHHH==",
      "v=HHHHH==aaaaa=v"
    ],
    [
      "gh            hg",
      "hh            hh",
      "     iii        ",
      "             j  ",
      " k  l      m j  ",
      " k         m j  ",
      " k         m    ",
      "             j  ",
      "                ",
      "           l    ",
      "            m   ",
      " n    l     m   ",
      "          oo    ",
      "                ",
      "hh  i     o   hh",
      "ghp           hg"
    ],
    [
      "g              g",
      "                ",
      "                ",
      "                ",
      "                ",
      "                ",
      "                ",
      "                ",
      "                ",
      "                ",
      "                ",
      "                ",
      "                ",
      "                ",
      "                ",
      "g              g"
    ],
    [
      "p              p",
      "                ",
      "                ",
      "                ",
      "                ",
      "                ",
      "                ",
      "                ",
      "                ",
      "                ",
      "                ",
      "                ",
      "                ",
      "                ",
      "                ",
      "p              p"
    ],
    [
      "p               ",
      "                ",
      "                ",
      "                ",
      "                ",
      "                ",
      "                ",
      "                ",
      "                ",
      "                ",
      "                ",
      "                ",
      "                ",
      "                ",
      "                ",
      "               p"
    ]
  ],
  "meta": [
    {
      "key": "support",
      "char": "v"
    }
  ]
}