{
  "name": "highway_open_bi",
  "refpalette": "c70cities:highway_open_bi_palette",
  "xsize": 16,
  "zsize": 16,
  "slices": [
    [
      "vvvvvvvvvvvvvvvv",
      "vvvvvvvvvvvvvvvv",
      "vvvvvvvvvvvvvvvv",
      "vvvvvvvvvvvvvvvv",
      "vvvvvvvvvvvvvvvv",
      "vvvvvvvvvvvvvvvv",
      "vvvvvvvvvvvvvvvv",
      "vvvvvvvvvvvvvvvv",
      "vvvvvvvvvvvvvvvv",
      "vvvvvvvvvvvvvvvv",
      "vvvvvvvvvvvvvvvv",
      "vvvvvvvvvvvvvvvv",
      "vvvvvvvvvvvvvvvv",
      "vvvvvvvvvvvvvvvv",
      "vvvvvvvvvvvvvvvv",
      "vvvvvvvvvvvvvvv "
    ],
    [
      "v=aaaaa==HH HH=v",
      "==HHHHH==HHHHH==",
      "HHHHHHHHHHbHHHHa",
      "HHHHHHHHHbHHHHHa",
      "HHHHHHcHHHHHHHHa",
      "HHHHHHHHdHHHHHHa",
      "HHHHebHHHHHHHHHa",
      "==HHbHHHHHdHHH==",
      "==HHbHHdHfHHHH==",
      "aHHcHHHdHHHHHHHH",
      "aHHHHcHdfHHHHHHH",
      "aHHHdHHHHHHdHHHH",
      "aHHHHHddHHHHHHHH",
      "aHHHHHHdHHHHHHHH",
      "==HHHHH==HHHHH==",
      "v=HHHHH==aaaaa=v"
    ],
    [
      "gh            hg",
      "hh            hh",
      "     iii        ",
      "             j  ",
      " j  k      l j  ",
      " j         l j  ",
      " j         l    ",
      "             j  ",
      "                ",
      "           k    ",
      "            l   ",
      " m    k     l   ",
      "          nn    ",
      "                ",
      "hh  i     n   hh",
      "gho           hg"
    ],
    [
      "g              g",
      "                ",
      "                ",
      "                ",
      "                ",
      "                ",
      "                ",
      "                ",
      "                ",
      "                ",
      "                ",
      "                ",
      "                ",
      "                ",
      "                ",
      "g              g"
    ],
    [
      "o              o",
      "                ",
      "                ",
      "                ",
      "                ",
      "                ",
      "                ",
      "                ",
      "                ",
      "                ",
      "                ",
      "                ",
      "                ",
      "                ",
      "                ",
      "o              o"
    ],
    [
      "o               ",
      "                ",
      "                ",
      "                ",
      "                ",
      "                ",
      "                ",
      "                ",
      "                ",
      "                ",
      "                ",
      "                ",
      "                ",
      "                ",
      "                ",
      "               o"
    ]
  ]
}