{
  "name": "highway_tunnel_bi",
  "refpalette": "c70cities:highway_tunnel_bi_palette",
  "xsize": 16,
  "zsize": 16,
  "slices": [
    [
      "vvvvvvvvvvvvvvvv",
      "vvvvvvvvvvvvvvvv",
      "vvvvvvvvvvvvvvvv",
      "vvvvvvvvvvvvvvvv",
      "vvvvvvvvvvvvvvvv",
      "vvvvvvvvvvvvvvvv",
      "vvvvvvvvvvvvvvvv",
      "vvvvvvvvvvvvvvvv",
      "vvvvvvvvvvvvvvvv",
      "vvvvvvvvvvvvvvvv",
      "vvvvvvvvvvvvvvvv",
      "vvvvvvvvvvvvvvvv",
      "vvvvvvvvvvvvvvvv",
      "vvvvvvvvvvvvvvvv",
      "vvvvvvvvvvvvvvvv",
      "vvvvvvvvvvvvvvvv"
    ],
    [
      "v=aaaaaHHHHHHH=v",
      "==HHHHHHHHHHHH==",
      "HHHHHHHHHHHHHHHa",
      "HHHHHHHHHHHHHHHa",
      "HHHHHHHHHHHHHHHa",
      "HHHHHHHHHHHHHHHa",
      "HHHHHHHHHHHHHHHa",
      "HHHHHHHHHHHHHHHH",
      "HHHHHHHHHHHHHHHH",
      "aHHHHHHHHHHHHHHH",
      "aHHHHHHHHHHHHHHH",
      "aHHHHHHHHHHHHHHH",
      "aHHHHHHHHHHHHHHH",
      "aHHHHHHHHHHHHHHH",
      "==HHHHHHHHHHHH==",
      "v=HHHHHHHaaaaa=v"
    ],
    [
      "vb~~~~~cc~~~~~bv",
      "bb~~~~~cc~~~~~bb",
      "~~~~~~~~~~~~~~~~",
      "~~~~~~~~~~~~~~~~",
      "~~~~~~~~~~~d~~~~",
      "~~~~~~~~~~~~~~~~",
      "~~~~~~~~~~~~~~~~",
      "cc~~~~~~~~~~~~cc",
      "cc~~~~~~~~~~~~cc",
      "~~~~~~~~~~~~~~~~",
      "~~~~~~~~~~~~~~~~",
      "~~~~~~~~~~~~~~~~",
      "~~~~~~~~~~~~~~~~",
      "~~~~~~~~~~~~~~~~",
      "bb~~~~~cc~~~~~bb",
      "vb~ ~~~cc~~~~~bv"
    ],
    [
      "v~~~~~~~~~~~~~~v",
      "~~~~~~~~~~~~~~~~",
      "~~~~~~~~~~~~~~~~",
      "~~~~~~~~~~~~~~~~",
      "~~~~~~~~~~~e~~~~",
      "~~~~~~~~~~~~~~~~",
      "~~~~~~~~~~~~~~~~",
      "~~~~~~~~~~~~~~~~",
      "~~~~~~~~~~~~~~~~",
      "~~~~~~~~~~~~~~~~",
      "~~~~~~~~~~~~~~~~",
      "~~~~~~~~~~~~~~~~",
      "~~~~~~~~~~~~~~~~",
      "~~~~~~~~~~~~~~~~",
      "~~~~~~~~~~~~~~~~",
      "v~~~~~~~~~~~~~~v"
    ],
    [
      "v~~~~~~~~~~~~~~v",
      "~~~~~~~~~~~~~~~~",
      "~~~~~~~~~~~~~~~~",
      "~~~~~~~~~~~~~~~~",
      "~~~~~~~~~~~~~~~~",
      "~~~~~~~~~~~~~~~~",
      "~~~~~~~~~~~~~~~~",
      "~~~~~~~~~~~~~~~~",
      "~~~~~~~~~~~~~~~~",
      "~~~~~~~~~~~~~~~~",
      "~~~~~~~~~~~~~~~~",
      "~~~~~~~~~~~~~~~~",
      "~~~~~~~~~~~~~~~~",
      "~~~~~~~~~~~~~~~~",
      "~~~~~~~~~~~~~~~~",
      "v~~~~~~~~~~~~~~v"
    ],
    [
      "~vv~~~~~~~~~~vv~",
      "vvv~~~~~~~~~~vvv",
      "vvv~~~~~~~~~~vvv",
      "~~~~~~~~~~~~~~~~",
      "~~~~~~~~~~~~~~~~",
      "~~~~~~~~~~~~~~~~",
      "~~~~~~~~~~~~~~~~",
      "~~~~~~~~~~~~~~~~",
      "~~~~~~~~~~~~~~~~",
      "~~~~~~~~~~~~~~~~",
      "~~~~~~~~~~~~~~~~",
      "~~~~~~~~~~~~~~~~",
      "~~~~~~~~~~~~~~~~",
      "vvv~~~~~~~~~~vvv",
      "vvv~~~~~~~~~~vvv",
      "~vv~~~~~~~~~~vv~"
    ],
    [
      "   vvvvvvvvvv   ",
      "   vvvvvvvvvv   ",
      "   vvvvvvvvvv   ",
      "vvvvvvvvvvvvvvvv",
      "vvvvfvvvvvv vvvv",
      "vvvvvvvvvvvvvvvv",
      "vvvvvvvvvvvvvvvv",
      "vvvvvvvvvvvvvvvv",
      "vvvvvvvvvvvvvvvv",
      "vvvvvvvvvvvvvvvv",
      "vvvvvvvvvvvvvvvv",
      "vvvvfvvvvvvfvvvv",
      "vvvvvvvvvvvvvvvv",
      "   vvvvvvvvvv   ",
      "   vvvvvvvvvv   ",
      "   vvvvvvvvvv   "
    ]
  ]
}