{
  "name": "rails_down1",
  "refpalette": "c70cities:rails_down1_palette",
  "xsize": 16,
  "zsize": 16,
  "slices": [
    [
      "                ",
      "                ",
      "a               ",
      "a               ",
      "HH              ",
      "HH              ",
      "HH              ",
      "HH              ",
      "HH              ",
      "HH              ",
      "HH              ",
      "HH              ",
      "HH              ",
      "a               ",
      "a               ",
      "                "
    ],
    [
      "                ",
      "                ",
      "aa              ",
      "ba              ",
      "ccHH            ",
      "~~HH            ",
      "~~HH            ",
      "~~HH            ",
      "~~HH            ",
      "~~HH            ",
      "~~HH            ",
      "~~HH            ",
      "cc~H            ",
      "Ha              ",
      "aa              ",
      "                "
    ],
    [
      "                ",
      "                ",
      "aaa             ",
      "daa             ",
      "~~ccHH          ",
      "~~~~HH          ",
      "~~~~HH          ",
      "~~~~HH          ",
      "~~~~HH          ",
      "~~~~HH          ",
      "~~~~HH          ",
      "~~~~HH          ",
      "~~ccHH          ",
      "daa             ",
      "aaa             ",
      "                "
    ],
    [
      "                ",
      "                ",
      "aaaa            ",
      "daaa            ",
      "~~~~ccHH        ",
      "~~~~~~HH        ",
      "~~~~~~HH        ",
      "~~~~~~HH        ",
      "~~~~~~HH        ",
      "~~~~~~HH        ",
      "~~~~~~HH        ",
      "~~~~~~HH        ",
      "~~~~ccHH        ",
      "daaa            ",
      "aaaa            ",
      "                "
    ],
    [
      "                ",
      "                ",
      "aaaaaaa         ",
      "daaaaaa         ",
      "~~~~~~ccHH      ",
      "~~~~~~~~HH      ",
      "~~~~~~~~HH      ",
      "~~~~~~~~HH      ",
      "~~~~~~~~HH      ",
      "~~~~~~~~HH      ",
      "~~~~~~~~HH      ",
      "~~~~~~~~HH      ",
      "~~~~~~ccHH      ",
      "daaaaa          ",
      "aaaaaa          ",
      "                "
    ],
    [
      "                ",
      "                ",
      "aaaaaaaa        ",
      "Haaaaaaa        ",
      "~~~~~~~~ccHH    ",
      "~~~~~~~~~~HH    ",
      "~~~~~~~~~~HH    ",
      "~~~~~~~~~~HH    ",
      "~~~~~~~~~~HH    ",
      "~~~~~~~~~~HH    ",
      "~~~~~~~~~~HH    ",
      "~~~~~~~~~~HH    ",
      "~~~~~~~~ccHH    ",
      "Haaaaaaa        ",
      "aaaaaaaa        ",
      "                "
    ],
    [
      "               a",
      "               a",
      "       aaaaaaaaa",
      "eeeeeeeaaaaaaaaa",
      "~~~~~~~~~~ccHHHH",
      "~~~~~~~~~~~~HHHH",
      "~~~~~~~~~~~~HHHH",
      "~~~~~~~~~~~~HHHH",
      "~~~~~~~~~~~~HHHH",
      "~~~~~~~~~~~~HHHH",
      "~~~~~~~~~~~~HHHH",
      "~~~~~~~~~~~~HHHH",
      "~~~~~~~~~~ccHHHH",
      "eeeeeeeaaaaaaaaa",
      "~~~~~~~aaaaaaaaa",
      "               a"
    ],
    [
      "               a",
      "               a",
      "               a",
      "effffffeaaaaaaaa",
      "e~~~~~~~~~~~gggg",
      "e~~~~~~~~~~~~~~~",
      "e~~~~~~~~~~~~~~~",
      "e~~~~~~~~~~~~~~~",
      "e~~~~~~~~~~~~~~h",
      "e~~~~~~~~~~~~~~~",
      "e~~~~~~~~~~~~~~~",
      "e~~~~~~~~~~~~~~~",
      "e~~~~~~~~~~~gggg",
      "effffffeaaaaaaaa",
      "~~~~~~~~~~~~~~~a",
      "               a"
    ],
    [
      "               i",
      "               i",
      "               i",
      "efffffffeiiiiiii",
      "f~~~~~~~~~~~~~~~",
      "f~~~~~~~~~~~~~~~",
      "f~~~~~~~~~~~~~~~",
      "f~~~~~~~~~~~~~~~",
      "f~~~~~~~~~~~~~~~",
      "f~~~~~~~~~~~~~~~",
      "f~~~~~~~~~~~~~~~",
      "f~~~~~~~~~~~~~~~",
      "f~~~~~~~~~~~~~~~",
      "efffffffeiiiiiii",
      "~~~~~~~~~~~~~~~i",
      "               i"
    ],
    [
      "                ",
      "                ",
      "                ",
      "e~~~~~~~e~~~~~~~",
      "f~~~~~~~~~~~~~~~",
      "f~~~~~~~~~~~~~~~",
      "f~~~~~~~~~~~~~~~",
      "f~~~~~~~~~~~~~~~",
      "f~~~~~~~~~~~~~~~",
      "f~~~~~~~~~~~~~~~",
      "f~~~~~~~~~~~~~~~",
      "f~~~~~~~~~~~~~~~",
      "f~~~~~~~~~~~~~~~",
      "e~~~~~~~e~~~~~~~",
      "~~~~~~~~~~~~~~~~",
      "                "
    ],
    [
      "                ",
      "                ",
      "                ",
      "jjjkkk~~~e~~~~~~",
      "jlllkl~~~~~~~~~~",
      "jlllkl~~~~~~~~~~",
      "~jjk~~~~~~~~~~~~",
      "jmmmmm~~~~~~~~~~",
      "jmmmmm~~~~~~~~~~",
      "jmmmmm~~~~~~~~~~",
      "~jjk~~~~~~~~~~~~",
      "jlllkl~~~~~~~~~~",
      "jlllkl~~~~~~~~~~",
      "jjjkkk~~~e~~~~~~",
      "~~~~~~~~~~~~~~~~",
      "                "
    ],
    [
      "                ",
      "                ",
      "                ",
      "~~~~~~jjne~~~~~~",
      "~~~~~~lljk~~~~~~",
      "~~~~~~lljk~~~~~~",
      "~~~~jjkk~~~~~~~~",
      "~~~~~~lmm~~~~~~~",
      "~~~~~~lmm~~~~~~~",
      "~~~~~~lmm~~~~~~~",
      "~~~~jjkk~~~~~~~~",
      "~~~~~~lljk~~~~~~",
      "~~~~~~lljk~~~~~~",
      "~~~~~~jjee~~~~~~",
      "~~~~~~~~~~~~~~~~",
      "                "
    ],
    [
      "                ",
      "                ",
      "                ",
      "~~~~~~~~~jekk~~~",
      "~~~~~~~~~lllk~~~",
      "~~~~~~~~~lllk~~~",
      "~~~~~~~~jjkkk~~~",
      "~~~~~~~j~lmmk~~~",
      "~~~~~~~j~lmmk~~~",
      "~~~~~~~j~lmmk~~~",
      "~~~~~~~~jjkkk~~~",
      "~~~~~~~~~lllk~~~",
      "~~~~~~~~~lllk~~~",
      "~~~~~~~~~jekk~~~",
      "~~~~~~~~~~~~~~~~",
      "                "
    ],
    [
      "                ",
      "                ",
      "                ",
      "~~~~~~~~~~~~~~~~",
      "~~~~~~~~~~~~~~~~",
      "~~~~~~~~~~~~~~~~",
      "~~~~~~~~~~~~~~~~",
      "~~~~~~~~~~~~~~~~",
      "~~~~~~~~~~~~~~~~",
      "~~~~~~~~~~~~~~~~",
      "~~~~~~~~~~~~~~~~",
      "~~~~~~~~~~~~~~~~",
      "~~~~~~~~~~~~~~~~",
      "~~~~~~~~~~~~~~~~",
      "                ",
      "                "
    ],
    [
      "                ",
      "                ",
      "                ",
      "~~~~~~~~~~~~~~~~",
      "~~~~~~~~~~~~~~~~",
      "~~~~~~~~~~~~~~~~",
      "~~~~~~~~~~~~~~~~",
      "~~~~~~~~~~~~~~~~",
      "~~~~~~~~~~~~~~~~",
      "~~~~~~~~~~~~~~~~",
      "~~~~~~~~~~~~~~~~",
      "~~~~~~~~~~~~~~~~",
      "~~~~~~~~~~~~~~~~",
      "~~~~~~~~~~~~~~~~",
      "                ",
      "                "
    ],
    [
      "                ",
      "                ",
      "                ",
      "~~~~~~~~~~~~~~~~",
      "~~~~~~~~~~~~~~~~",
      "~~~~~~~~~~~~~~~~",
      "~~~~~~~~~~~~~~~~",
      "~~~~~~~~~~~~~~~~",
      "~~~~~~~~~~~~~~~~",
      "~~~~~~~~~~~~~~~~",
      "~~~~~~~~~~~~~~~~",
      "~~~~~~~~~~~~~~~~",
      "~~~~~~~~~~~~~~~~",
      "~~~~~~~~~~~~~~~~",
      "                ",
      "                "
    ]
  ]
}