{
  "name": "rails_vertical",
  "refpalette": "c70cities:rails_vertical_palette",
  "xsize": 16,
  "zsize": 16,
  "slices": [
    [
      "    aHHHHHHHa   ",
      "     aHHHHHa    ",
      "     aHHHHHa    ",
      "     aHHHHHa    ",
      "     aHHHHHa    ",
      "     aHHHHHa    ",
      "     aHHHHHa    ",
      "     aHHHHHa    ",
      "    aHHHHHHHa   ",
      "     aHHHHHa    ",
      "     aHHHHHa    ",
      "     aHHHHHa    ",
      "     aHHHHHa    ",
      "     aHHHHHa    ",
      "     aHHHHHa    ",
      "     aHHHHHa    "
    ],
    [
      "    abc~d~cba   ",
      "     ac~d~ca    ",
      "     ac~d~ca    ",
      "     ac~d~ca    ",
      "     ac~d~ca    ",
      "     ac~d~ca    ",
      "     ac~d~ca    ",
      "     ac~d~ca    ",
      "    abc~d~cba   ",
      "     ac~d~ca    ",
      "     ac~d~ca    ",
      "     ac~d~ca    ",
      "     ac~d~ca    ",
      "     ac~d~ca    ",
      "     ac~d~ca    ",
      "     ac~d~ca    "
    ],
    [
      "    ab~~~~~ba   ",
      "     a~~~~~a    ",
      "     a~~~~~a    ",
      "     a~~~~~a    ",
      "     a~~~~~a    ",
      "     a~~~~~a    ",
      "     a~~~~~a    ",
      "     a~~~~~a    ",
      "    ab~~~~~ba   ",
      "     a~~~~~a    ",
      "     a~~~~~a    ",
      "     a~~~~~a    ",
      "     a~~~~~a    ",
      "     a~~~~~a    ",
      "     a~~~~~a    ",
      "     a~~~~~a    "
    ],
    [
      "    ab~~~~~ba   ",
      "     a~~~~~a    ",
      "     a~~~~~a    ",
      "     a~~~~~a    ",
      "     a~~~~~a    ",
      "     a~~~~~a    ",
      "     a~~~~~a    ",
      "     a~~~~~a    ",
      "    ab~~~~~ba   ",
      "     a~~~~~a    ",
      "     a~~~~~a    ",
      "     a~~~~~a    ",
      "     a~~~~~a    ",
      "     a~~~~~a    ",
      "     a~~~~~a    ",
      "     a~~~~~a    "
    ],
    [
      "    aH~~~~~Ha   ",
      "     a~~~~~a    ",
      "     a~~~~~a    ",
      "     a~~~~~a    ",
      "     a~~~~~a    ",
      "     a~~~~~a    ",
      "     a~~~~~a    ",
      "     a~~~~~a    ",
      "    aH~~~~~Ha   ",
      "     a~~~~~a    ",
      "     a~~~~~a    ",
      "     a~~~~~a    ",
      "     a~~~~~a    ",
      "     a~~~~~a    ",
      "     a~~~~~a    ",
      "     a~~~~~a    "
    ],
    [
      "     aaaaaaa    ",
      "     efgggfe    ",
      "     efgggfe    ",
      "     efgggfe    ",
      "     efgggfe    ",
      "     efgggfe    ",
      "     efgggfe    ",
      "     efgggfe    ",
      "     aaaaaaa    ",
      "     efgggfe    ",
      "     efgggfe    ",
      "     efgggfe    ",
      "     efgggfe    ",
      "     efgggfe    ",
      "     efgggfe    ",
      "     efgggfe    "
    ]
  ]
}