{
  "name": "rails_3split",
  "refpalette": "c70cities:rails_3split_palette",
  "xsize": 16,
  "zsize": 16,
  "slices": [
    [
      "   aHHHHHHHHHa~ ",
      "   aHHHHHHHHHa~ ",
      "aaaaHHHHHHHHHaHa",
      "bHHbHHHHHHHHHbHb",
      "HHHHHHHHHHHHHHHH",
      "HHHHHHHHHHHHHHHH",
      "HHHHHHHHHHHHHHHH",
      "HHHHHHHHHHHHHHHH",
      "HHHHHHHHHHHHHHHH",
      "HHHHHHHHHHHHHHHH",
      "HHHHHHHHHHHHHHHH",
      "HHHHHHHHHHHHHHHH",
      "HHHHHHHHHHHHHHHH",
      "baabHHHHHHHHHbHb",
      "aaaaHHHHHHHHHaaa",
      "   aHHHHHHHHH~  "
    ],
    [
      "   ac~~~d~~~ca~ ",
      "   ac~~~d~~~ca~ ",
      "aaaac~~~d~~~caaa",
      "eaaec~~~d~~~ceae",
      "ccccc~~~d~~~cccc",
      "~~~~~~~~d~~~~~~~",
      "~~~~~~~~d~~~~~~~",
      "~~~~~~~~d~~~~~~~",
      "ffffffffgfffffff",
      "~~~~~~~~d~~~~~~~",
      "~~~~~~~~d~~~~~~~",
      "~~~~~~~~d~~~~~~~",
      "ccccc~~~d~~~cccc",
      "eaaec~~~d~~~ceae",
      "aaaac~~~d~~~caaa",
      "   ac~~~d~~~ca  "
    ],
    [
      "   a~~~~~~~~~a~ ",
      "   a~~~~~~~~~a~ ",
      "aaaa~~~~~~~~~aaa",
      "eaae~~~~~~~~~eae",
      "~~~~~~~~~~~~~~~~",
      "~~~~~~~~~~~~~~~~",
      "~~~~~~~~~~~~~~~~",
      "~~~~~~~~~~~~~~~~",
      "~~~~~~~~~~~~~~~~",
      "~~~~~~~~~~~~~~~~",
      "~~~~~~~~~~~~~~~~",
      "~~~~~~~~~~~~~~~~",
      "~~~~~~~~~~~~~~~~",
      "eaae~~~~~~~~~eae",
      "aaaa~~~~~~~~~aaa",
      "   a~~~~~~~~~a  "
    ],
    [
      "   a~~~~~~~~~a~ ",
      "   a~~~~~~~~~a~ ",
      "aaaa~~~~~~~~~aaa",
      "eaae~~~~~~~~~eae",
      "~~~~~~~~~~~~~~~~",
      "~~~~~~~~~~~~~~~~",
      "~~~~~~~~~~~~~~~~",
      "~~~~~~~~~~~~~~~~",
      "~~~~~~~~~~~~~~~~",
      "~~~~~~~~~~~~~~~~",
      "~~~~~~~~~~~~~~~~",
      "~~~~~~~~~~~~~~~~",
      "~~~~~~~~~~~~~~~~",
      "eaae~~~~~~~~~eae",
      "aaaa~~~~~~~~~aaa",
      "   a~~~~~~~~~a  "
    ],
    [
      "   a~~~~~~~~~a~ ",
      "   a~~~~~~~~~a~ ",
      "aaaa~~~~~~~~~aaa",
      "eaae~~~~~~~~~eae",
      "~~~~~~~~~~~~~~~~",
      "~~~~~~~~~~~~~~~~",
      "~~~~~~~~~~~~~~~~",
      "~~~~~~~~~~~~~~~~",
      "~~~~~~~~~~~~~~~~",
      "~~~~~~~~~~~~~~~~",
      "~~~~~~~~~~~~~~~~",
      "~~~~~~~~~~~~~~~~",
      "~~~~~~~~~~~~~~~~",
      "eaae~~~~~~~~~eae",
      "aaaa~~~~~~~~~aaa",
      "   a~~~~~~~~~a  "
    ],
    [
      "   h~~~~~~~~~h~ ",
      "   h~~~~~~~~~h~ ",
      "aaah~~~~~~~~~haa",
      "HhhH~~~~~~~~~HhH",
      "~~~~~~~~~~~~~~~~",
      "~~~~~~~~~~~~~~~~",
      "~~~~~~~~~~~~~~~~",
      "~~~~~~~~~~~~~~~~",
      "~~~~~~~~~~~~~~~~",
      "~~~~~~~~~~~~~~~~",
      "~~~~~~~~~~~~~~~~",
      "~~~~~~~~~~~~~~~~",
      "~~~~~~~~~~~~~~~~",
      "HhhH~~~~~~~~~HhH",
      "aaah~~~~~~~~~haa",
      "   h~~~~~~~~~h  "
    ],
    [
      "   a~~~~~~~~~a~ ",
      "   a~~~~~~~~~a~ ",
      "aaaa~~~~~~~~~aaa",
      "eaae~~~~~~~~~eae",
      "~~~~~~~~~~~~~~~~",
      "~~~~~~~~~~~~~~~~",
      "~~~~~~~~~~~~~~~~",
      "~~~~~~~~~~~~~~~~",
      "~~~~~~~~~~~~~~~~",
      "~~~~~~~~~~~~~~~~",
      "~~~~~~~~~~~~~~~~",
      "~~~~~~~~~~~~~~~~",
      "~~~~~~~~~~~~~~~~",
      "eaae~~~~~~~~~eae",
      "aaaa~~~~~~~~~aaa",
      "   a~~~~~~~~~a  "
    ],
    [
      "   aHiiiiiiiHa~ ",
      "   ai~~~~~~~ia~ ",
      "aaaai~~~~~~~iaaa",
      "Haabi~~~~~~~ibaH",
      "iiiiiiiiiiiiiiii",
      "i~~~i~~~~~~~i~~i",
      "i~~~i~~~~~~~i~~i",
      "i~~~i~~~~~~~i~~i",
      "i~~~i~~~~~~~i~~i",
      "i~~~i~~~~~~~i~~i",
      "i~~~i~~~~~~~i~~i",
      "i~~~i~~~~~~~i~~i",
      "iiiiiiiiiiiiiiii",
      "Haabi~~~~~~~ibaH",
      "aaaai~~~~~~~iaaa",
      "   aHiiiiiiiHa  "
    ],
    [
      "    hhaaaaahh   ",
      "    hhjkkkjhh   ",
      "    hhjkkkjhh   ",
      "hhhhhhjkkkjhhhhh",
      "hhhhhhjkkkjhhhhh",
      "hhhhhhjkkkjhhhhh",
      "jjjjjjjkkkjjjjjj",
      "kkkkkkkkkkkkkkkk",
      "kkkkkkkkkkkkkkkk",
      "kkkkkkkkkkkkkkkk",
      "jjjjjjjkkkjjjjjj",
      "hhhhhhjkkkjhhhhh",
      "hhhhhhjkkkjhhhhh",
      "hhhhhhjkkkjhhhhh",
      "    hhjkkkjhh   ",
      "    hhaaaaahh   "
    ]
  ]
}