{
  "name": "rails_bend",
  "refpalette": "c70cities:rails_bend_palette",
  "xsize": 16,
  "zsize": 16,
  "slices": [
    [
      "    abHHHHHHa   ",
      "    aaHHHHHaa   ",
      "aaaaaaHHHHHaa   ",
      "HHaaHaHHHHHaa   ",
      "HHHHHHHHHHHaa   ",
      "HHHHHHHHHHHba   ",
      "HHHHHHHHHHHaa   ",
      "HHHHHHHHHHHaa   ",
      "HHHHHHHHHHHaa   ",
      "HHHHHHHHHHHaa   ",
      "HHHHHHHHHHHba   ",
      "HHHHHHHHHHHaa   ",
      "aaaabaHHHHHaa   ",
      "aaaaaaHHHHHaa   ",
      "    aaHHHHHaa   ",
      "    aHHHHHHHa   "
    ],
    [
      "    acd~e~dca   ",
      "    aad~e~daa   ",
      "aaaaaad~e~daa   ",
      "aaaacad~e~daa   ",
      "ddddddd~e~daa   ",
      "~~~~~~~~e~dca   ",
      "fffffff~e~daa   ",
      "~~~~~~~~e~daa   ",
      "~~~~~~~~e~daa   ",
      "fffffff~e~daa   ",
      "~~~~~~~~e~dca   ",
      "ddddddd~e~daa   ",
      "aaaacad~e~daa   ",
      "aaaaaad~e~daa   ",
      "    aad~e~daa   ",
      "    acd~e~dca   "
    ],
    [
      "    ac~~~~~ca   ",
      "    aa~~~~~aa   ",
      "aaaaaa~~~~~aa   ",
      "aaaaca~~~~~aa   ",
      "~~~~~~~~~~~aa   ",
      "~~~~~~~~~~~ca   ",
      "~~~~~~~~~~~aa   ",
      "~~~~~~~~~~~aa   ",
      "~~~~~~~~~~~aa   ",
      "~~~~~~~~~~~aa   ",
      "~~~~~~~~~~~ca   ",
      "~~~~~~~~~~~aa   ",
      "aaaaca~~~~~aa   ",
      "aaaaaa~~~~~aa   ",
      "    aa~~~~~aa   ",
      "    ac~~~~~ca   "
    ],
    [
      "    ac~~~~~ca   ",
      "    aa~~~~~aa   ",
      "aaaaaa~~~~~aa   ",
      "aaaaca~~~~~aa   ",
      "~~~~~~~~~~~aa   ",
      "~~~~~~~~~~~ca   ",
      "~~~~~~~~~~~aa   ",
      "~~~~~~~~~~~aa   ",
      "~~~~~~~~~~~aa   ",
      "~~~~~~~~~~~aa   ",
      "~~~~~~~~~~~ca   ",
      "~~~~~~~~~~~aa   ",
      "aaaaca~~~~~aa   ",
      "aaaaaa~~~~~aa   ",
      "    aa~~~~~aa   ",
      "    ac~~~~~ca   "
    ],
    [
      "    aH~~~~~Ha   ",
      "    aa~~~~~aa   ",
      "aaaaaa~~~~~aa   ",
      "aaaaHa~~~~~aa   ",
      "~~~~g~~~~~~aa   ",
      "~~~~~~~~~~~Ha   ",
      "~~~~~~~~~~~aa   ",
      "~~~~~~~~~~~aa   ",
      "~~~~~~~~~~~aa   ",
      "~~~~~~~~~~~aa   ",
      "~~~~~~~~~~~Ha   ",
      "~~~~g~~~~~~aa   ",
      "aaaaHa~~~~~aa   ",
      "aaaaaa~~~~~aa   ",
      "    aa~~~~~aa   ",
      "    aH~~~~~Ha   "
    ],
    [
      "     haaaaah    ",
      "     hijjjih    ",
      "     hijjjih    ",
      "hhhhhhijjjih    ",
      "hhhhhhijjjih    ",
      "iiiiiiijjjih    ",
      "jjjjjjjjjjih    ",
      "jjjjjjjjjjih    ",
      "jjjjjjjjjjih    ",
      "jjjjjjjjjjih    ",
      "iiiiiiijjjih    ",
      "hhhhhhijjjih    ",
      "hhhhhhijjjih    ",
      "     hijjjih    ",
      "     hijjjih    ",
      "     haaaaah    "
    ]
  ]
}