{
  "name": "rails_vertical_water",
  "refpalette": "c70cities:rails_vertical_water_palette",
  "xsize": 16,
  "zsize": 16,
  "slices": [
    [
      "    aHHHHHHHa   ",
      "     bHHHHHb    ",
      "     bHHHHHb    ",
      "     bHHHHHb    ",
      "     bHHHHHb    ",
      "     bHHHHHb    ",
      "     bHHHHHb    ",
      "     bHHHHHb    ",
      "    aHHHHHHHa   ",
      "     bHHHHHb    ",
      "     bHHHHHb    ",
      "     bHHHHHb    ",
      "     bHHHHHb    ",
      "     bHHHHHb    ",
      "     bHHHHHb    ",
      "     bHHHHHb    "
    ],
    [
      "    bcd~e~dcb   ",
      "     fd~e~df    ",
      "     fd~e~df    ",
      "     fd~e~df    ",
      "     cd~e~dc    ",
      "     fd~e~df    ",
      "     fd~e~df    ",
      "     fd~e~df    ",
      "    bcd~e~dcb   ",
      "     fd~e~df    ",
      "     fd~e~df    ",
      "     fd~e~df    ",
      "     cd~e~dc    ",
      "     fd~e~df    ",
      "     fd~e~df    ",
      "     fd~e~df    "
    ],
    [
      "    bc~~~~~cb   ",
      "     f~~~~~f    ",
      "     f~~~~~f    ",
      "     f~~~~~f    ",
      "     c~~~~~c    ",
      "     f~~~~~f    ",
      "     f~~~~~f    ",
      "     f~~~~~f    ",
      "    bc~~~~~cb   ",
      "     f~~~~~f    ",
      "     f~~~~~f    ",
      "     f~~~~~f    ",
      "     c~~~~~c    ",
      "     f~~~~~f    ",
      "     f~~~~~f    ",
      "     f~~~~~f    "
    ],
    [
      "    bc~~~~~cb   ",
      "     f~~~~~f    ",
      "     f~~~~~f    ",
      "     f~~~~~f    ",
      "     c~~~~~c    ",
      "     f~~~~~f    ",
      "     f~~~~~f    ",
      "     f~~~~~f    ",
      "    bc~~~~~cb   ",
      "     f~~~~~f    ",
      "     f~~~~~f    ",
      "     f~~~~~f    ",
      "     c~~~~~c    ",
      "     f~~~~~f    ",
      "     f~~~~~f    ",
      "     f~~~~~f    "
    ],
    [
      "    bc~~~~~cb   ",
      "     f~~~~~f    ",
      "     f~~~~~f    ",
      "     f~~~~~f    ",
      "     c~~~~~c    ",
      "     f~~~~~f    ",
      "     f~~~~~f    ",
      "     f~~~~~f    ",
      "    bc~~~~~cb   ",
      "     f~~~~~f    ",
      "     f~~~~~f    ",
      "     f~~~~~f    ",
      "     c~~~~~c    ",
      "     f~~~~~f    ",
      "     f~~~~~f    ",
      "     f~~~~~f    "
    ],
    [
      "     bbbbbbb    ",
      "      fffff     ",
      "      fffff     ",
      "      fffff     ",
      "      ggggg     ",
      "      fffff     ",
      "      fffff     ",
      "      fffff     ",
      "     bbbbbbb    ",
      "      fffff     ",
      "      fffff     ",
      "      fffff     ",
      "      ggggg     ",
      "      fffff     ",
      "      fffff     ",
      "      fffff     "
    ]
  ]
}