{
  "name": "rails_horizontal_end",
  "refpalette": "c70cities:rails_horizontal_end_palette",
  "xsize": 16,
  "zsize": 16,
  "slices": [
    [
      "                ",
      "                ",
      "aaaaaaaaaaaaaaaa",
      "HaaaHaaHHaaaHaaa",
      "HHHHHHHHHHHHHHHH",
      "HHHHHHHHHHHHHHHH",
      "HHHHHHHHHHHHHHHH",
      "HHHHHHHHHHHHHHHH",
      "HHHHHHHHH!HHHHHH",
      "HHHHHHHHHHHHHHHH",
      "HHHHHHHHHHHHHHHH",
      "HHHHHHHHHHHHHHHH",
      "HaaaHaaaHaaaHaaa",
      "aaaaaaaaaaaaaaaa",
      "                ",
      "                "
    ],
    [
      "                ",
      "                ",
      "aaaaaaaaaaaaaaaa",
      "baaabaaHHaaabaaa",
      "cc ccdcHHceccccc",
      "       fghh hi h",
      "jjjjj  H k l kkk",
      "      mg mhh h  ",
      "       mHh ehh  ",
      "jjjjjjjHgknl   k",
      "      mHHhhohi h",
      "cccciccHHciccccc",
      "baaabaaHHaaabaaa",
      "aaaaaaaaaaaaaaaa",
      "                ",
      "                "
    ],
    [
      "                ",
      "                ",
      "aaaaaaaaaaaaaaaa",
      "baaabaaHHaaabaaa",
      "      iHH  i    ",
      "        H       ",
      "       p        ",
      "        H       ",
      "        p       ",
      "       mp       ",
      "       H        ",
      "   i   Hp       ",
      "baaabaaHHaaabaaa",
      "aaaaaaaaaaaaaaaa",
      "                ",
      "                "
    ],
    [
      "                ",
      "                ",
      "aaaaaaaaaaaaaaaa",
      "baaabaaHHaaabaaa",
      "       HHi      ",
      "       H        ",
      "       oH       ",
      "        H       ",
      "        g       ",
      "        H       ",
      "       Hq       ",
      "       HHi      ",
      "baaabaaHHaaabaaa",
      "aaaaaaaaaaaaaaaa",
      "                ",
      "                "
    ],
    [
      "                ",
      "                ",
      "aaaaaaaaaaaaaaaa",
      "HaaaHaaHHaaaHaaa",
      "ri  ri HHi iri  ",
      "       gp       ",
      "     i HHi      ",
      "       HH       ",
      "        H       ",
      "       qg       ",
      "   i   gHi      ",
      "r i r iHHi ir   ",
      "HaaaHaaHHaaaHaaa",
      "aaaaaaaaaaaaaaaa",
      "                ",
      "                "
    ],
    [
      "                ",
      "                ",
      "                ",
      "ssssssssssssssss",
      "ssssssssssssssss",
      "ffftfftpgtffffff",
      "uuuuuuuppuuuuuuu",
      "uuuuuuuHHuuuuuuu",
      "uuuuuuuHHuuuuuuu",
      "uuuuuuugguuuuuuu",
      "fffffffppfffffff",
      "ssssssssssssssss",
      "ssssssssssssssss",
      "                ",
      "                ",
      "                "
    ]
  ]
}