{
  "name": "rails_bend",
  "refpalette": "c70cities:rails_bend_palette",
  "xsize": 16,
  "zsize": 16,
  "slices": [
    [
      "    abHHHHHHa   ",
      "aaaaaaHHHHHaa   ",
      "aaabaHHHHHHaa   ",
      "HHaaHHHHHHHaa   ",
      "HHHHHHHHHHHaa   ",
      "HHHHHHHHHHHba   ",
      "HHHHHHHHHHHaa   ",
      "HHHHHHHHHHHaa   ",
      "HHHHHHHHHHHaa   ",
      "HHHHHHHHHHHaa   ",
      "HHHHHHHHHHHba   ",
      "HHHHHHHHHHHaa   ",
      "aaaaHHHHHHHaa   ",
      "aaabaHHHHHHaa   ",
      "aaaaaaHHHHHaa   ",
      "    aHHHHHHHa   "
    ],
    [
      "    acd~~~dca   ",
      "aaaaad~~~~daa   ",
      "aaacd~~~~~daa   ",
      "dddd~~~~e~daa   ",
      "~~~~~~~~~~daa   ",
      "~~~~~~~~~~dca   ",
      "~~~f~~~~~~daa   ",
      "~~~~~g~~e~daa   ",
      "~~~~~~~~~~daa   ",
      "~~~~~e~~~~daa   ",
      "~h~~~~~~~~dca   ",
      "~~~~~~~g~~daa   ",
      "dddd~~~~~~daa   ",
      "aaacd~~~~~daa   ",
      "aaaaad~~~~daa   ",
      "    acd~~~dca   "
    ],
    [
      "    ac~~~~~ca   ",
      "aaaaa~~~~~~aa   ",
      "aaac~~~~~~~aa   ",
      "~~~~~~~~~~~aa   ",
      "~~~~~~~~~~~aa   ",
      "~~~~~~~~~~~ca   ",
      "~~~~~~~~~~~aa   ",
      "~~~~~~~~~~~aa   ",
      "~~~~~~~~~~~aa   ",
      "~~~~~~~~~~~aa   ",
      "~~~~~~~~~~~ca   ",
      "~~~~~~~~~~~aa   ",
      "~~~~~~~~~~~aa   ",
      "aaac~~~~~~~aa   ",
      "aaaaa~~~~~~aa   ",
      "    ac~~~~~ca   "
    ],
    [
      "    ac~~~~~ca   ",
      "aaaaa~~~~~~aa   ",
      "aaac~~~~~~~aa   ",
      "~~~~~~~~~~~aa   ",
      "~~~~~~~~~~~aa   ",
      "~~~~~~~~~~~ca   ",
      "~~~~~~~~~~~aa   ",
      "~~~~~~~~~~~aa   ",
      "~~~~~~~~~~~aa   ",
      "~~~~~~~~~~~aa   ",
      "~~~~~~~~~~~ca   ",
      "~~~~~~~~~~~aa   ",
      "~~~~~~~~~~~aa   ",
      "aaac~~~~~~~aa   ",
      "aaaaa~~~~~~aa   ",
      "    ac~~~~~ca   "
    ],
    [
      "    aH~~~~~Ha   ",
      "aaaaa~~~~~~aa   ",
      "aaaHi~~~~~~aa   ",
      "i~~~i~~~~~~aa   ",
      "i~~~i~~~~~~aa   ",
      "i~~~i~~~~~~Ha   ",
      "i~~~i~~~~~~aa   ",
      "i~~~i~~~~~~aa   ",
      "i~~~i~~~~~~aa   ",
      "i~~~i~~~~~~aa   ",
      "i~~~i~~~~~~Ha   ",
      "i~~~i~~~~~~aa   ",
      "i~~~i~~~~~~aa   ",
      "aaaci~~~~~~aa   ",
      "aaaaa~~~~~~aa   ",
      "    aH~~~~~Ha   "
    ],
    [
      "     jaaaaaj    ",
      "     jklllkj    ",
      "jjjjjjklllkj    ",
      "jjjjjjklllkj    ",
      "jjjjjjklllkj    ",
      "kkkkkkklllkj    ",
      "llllllllllkj    ",
      "llllllllllkj    ",
      "llllllllllkj    ",
      "llllllllllkj    ",
      "kkkkkkklllkj    ",
      "jjjjjjklllkj    ",
      "jjjjjjklllkj    ",
      "jjjjjjklllkj    ",
      "     jklllkj    ",
      "     jaaaaaj    "
    ]
  ]
}