{
  "name": "rails_vertical_water",
  "refpalette": "c70cities:rails_vertical_water_palette",
  "xsize": 16,
  "zsize": 16,
  "slices": [
    [
      " aHbHbHHHHHbHbba",
      "  bbHbHHHHHbHbb ",
      "  bbHbHHHHHbHbb ",
      "  bbHbHHHHHbHbb ",
      "  bbHbHHHHHbHbb ",
      "  bbHbHHHHHbHbb ",
      "  bbHbHHHHHbHbb ",
      "  bbHbHHHHHbHbb ",
      " aHbHbHHHHHbHbHa",
      "  bbHbHHHHHbHbb ",
      "  bbHbHHHHHbHbb ",
      "  bbHbHHHHHbHbb ",
      "  bbHbHHHHHbHbb ",
      "  bbHbHHHHHbHbb ",
      "  bbHbHHHHHbHbb ",
      "  bbHbHHHHHbHbb "
    ],
    [
      "  bc~c~~d~~c~cb ",
      "  ec~c~~d~~c~ce ",
      "  ec~c~~d~~c~ce ",
      "  ec~c~~d~~c~ce ",
      "  fc~c~~d~~c~cf ",
      "  ec~c~~d~~c~ce ",
      "  ec~c~~d~~c~ce ",
      "  ec~c~~d~~c~ce ",
      "  bc~c~~d~~c~cb ",
      "  ec~c~~d~~c~ce ",
      "  ec~c~~d~~c~ce ",
      "  ec~c~~d~~c~ce ",
      "  fc~c~~d~~c~cf ",
      "  ec~c~~d~~c~ce ",
      "  ec~c~~d~~c~ce ",
      "  ec~c~~d~~c~ce "
    ],
    [
      "  b~~~~~~~~~~~b ",
      "  e~~~~~~~~~~~e ",
      "  e~~~~~~~~~~~e ",
      "  e~~~~~~~~~~~e ",
      "  f~~~~~~~~~~~f ",
      "  e~~~~~~~~~~~e ",
      "  e~~~~~~~~~~~e ",
      "  e~~~~~~~~~~~e ",
      "  b~~~~~~~~~~~b ",
      "  e~~~~~~~~~~~e ",
      "  e~~~~~~~~~~~e ",
      "  e~~~~~~~~~~~e ",
      "  f~~~~~~~~~~~f ",
      "  e~~~~~~~~~~~e ",
      "  e~~~~~~~~~~~e ",
      "  e~~~~~~~~~~~e "
    ],
    [
      "  b~~~~~~~~~~~b ",
      "  e~~~~~~~~~~~e ",
      "  e~~~~~~~~~~~e ",
      "  e~~~~~~~~~~~e ",
      "  f~~~~~~~~~~~f ",
      "  e~~~~~~~~~~~e ",
      "  e~~~~~~~~~~~e ",
      "  e~~~~~~~~~~~e ",
      "  b~~~~~~~~~~~b ",
      "  e~~~~~~~~~~~e ",
      "  e~~~~~~~~~~~e ",
      "  e~~~~~~~~~~~e ",
      "  f~~~~~~~~~~~f ",
      "  e~~~~~~~~~~~e ",
      "  e~~~~~~~~~~~e ",
      "  e~~~~~~~~~~~e "
    ],
    [
      "  b~~~~~~~~~~~b ",
      "  e~~~~~~~~~~~e ",
      "  e~~~~~~~~~~~e ",
      "  e~~~~~~~~~~~e ",
      "  f~~~~~~~~~~~f ",
      "  e~~~~~~~~~~~e ",
      "  e~~~~~~~~~~~e ",
      "  e~~~~~~~~~~~e ",
      "  b~~~~~~~~~~~b ",
      "  e~~~~~~~~~~~e ",
      "  e~~~~~~~~~~~e ",
      "  e~~~~~~~~~~~e ",
      "  f~~~~~~~~~~~f ",
      "  e~~~~~~~~~~~e ",
      "  e~~~~~~~~~~~e ",
      "  e~~~~~~~~~~~e "
    ],
    [
      "  b~~~~~~~~~~~b ",
      "  e~~~~~~~~~~~e ",
      "  e~~~~~~~~~~~e ",
      "  e~~~~~~~~~~~e ",
      "  f~~~~~~~~~~~f ",
      "  e~~~~~~~~~~~e ",
      "  e~~~~~~~~~~~e ",
      "  e~~~~~~~~~~~e ",
      "  b~~~~~~~~~~~b ",
      "  e~~~~~~~~~~~e ",
      "  e~~~~~~~~~~~e ",
      "  e~~~~~~~~~~~e ",
      "  f~~~~~~~~~~~f ",
      "  e~~~~~~~~~~~e ",
      "  e~~~~~~~~~~~e ",
      "  e~~~~~~~~~~~e "
    ],
    [
      "  b~~~~~~~~~~~b ",
      "  ee~~~~~~~~~ee ",
      "  ee~~~~~~~~~ee ",
      "  ee~~~~~~~~~ee ",
      "  ff~~~~~~~~~ff ",
      "  ee~~~~~~~~~ee ",
      "  ee~~~~~~~~~ee ",
      "  ee~~~~~~~~~ee ",
      "  bf~~~~~~~~~fb ",
      "  ee~~~~~~~~~ee ",
      "  ee~~~~~~~~~ee ",
      "  ee~~~~~~~~~ee ",
      "  ff~~~~~~~~~ff ",
      "  ee~~~~~~~~~ee ",
      "  ee~~~~~~~~~ee ",
      "  ee~~~~~~~~~ee "
    ],
    [
      "   bba~~~~~abb~ ",
      "   eee~~~~~eee~ ",
      "   eee~~~~~eee~ ",
      "   eee~~~~~eee~ ",
      "   ggg~~~~~ggg~ ",
      "   eee~~~~~eee~ ",
      "   eee~~~~~eee~ ",
      "   eee~~~~~eee~ ",
      "   bba~~~~~abb~ ",
      "   eee~~~~~eee~ ",
      "   eee~~~~~eee~ ",
      "   eee~~~~~eee~ ",
      "   ggg~~~~~ggg~ ",
      "   eee~~~~~eee~ ",
      "   eee~~~~~eee~ ",
      "   eee~~~~~eee~ "
    ],
    [
      "     bbbbbbb    ",
      "      eeeee     ",
      "      eeeee     ",
      "      eeeee     ",
      "      ggggg     ",
      "      eeeee     ",
      "      eeeee     ",
      "      eeeee     ",
      "     bbbbbbb    ",
      "      eeeee     ",
      "      eeeee     ",
      "      eeeee     ",
      "      ggggg     ",
      "      eeeee     ",
      "      eeeee     ",
      "      eeeee     "
    ]
  ]
}