{
  "name": "rails_horizontal",
  "refpalette": "c70cities:rails_horizontal_palette",
  "xsize": 16,
  "zsize": 16,
  "slices": [
    [
      "                ",
      "                ",
      "aaaaaaaaaaaaaaaa",
      "HaaaHaaaHaaaHaaa",
      "HHHHHHHHHHHHHHHH",
      "HHHHHHHHHHHHHHHH",
      "HHHHHHHHHHHHHHHH",
      "HHHHHHHHHHHHHHHH",
      "HHHHHHHHHHHHHHHH",
      "HHHHHHHHHHHHHHHH",
      "HHHHHHHHHHHHHHHH",
      "HHHHHHHHHHHHHHHH",
      "HHHHHHHHHHHHHHHH",
      "HaaaHaaaaaaaaaaa",
      "aaaaaaaaaaaaaaaa",
      "                "
    ],
    [
      "                ",
      "                ",
      "aaaaaaaaaaaaaaaa",
      "baaabaaabaaabaaa",
      "cccccccccccccccc",
      "~~~~~~~~~~~~~~~~",
      "~~~~~~~~~~~~~~~~",
      "~~~~~~~~~~~~~~~~",
      "dddddddddddddddd",
      "~~~~~~~~~~~~~~~~",
      "~~~~~~~~~~~~~~~~",
      "~~~~~~~~~~~~~~~~",
      "cccccccccccccccc",
      "baaabaaabaaabaaa",
      "aaaaaaaaaaaaaaaa",
      "                "
    ],
    [
      "                ",
      "                ",
      "aaaaaaaaaaaaaaaa",
      "baaabaaabaaabaaa",
      "~~~~~~~~~~~~~~~~",
      "~~~~~~~~~~~~~~~~",
      "~~~~~~~~~~~~~~~~",
      "~~~~~~~~~~~~~~~~",
      "~~~~~~~~~~~~~~~~",
      "~~~~~~~~~~~~~~~~",
      "~~~~~~~~~~~~~~~~",
      "~~~~~~~~~~~~~~~~",
      "~~~~~~~~~~~~~~~~",
      "baaabaaabaaabaaa",
      "aaaaaaaaaaaaaaaa",
      "                "
    ],
    [
      "                ",
      "                ",
      "aaaaaaaaaaaaaaaa",
      "baaabaaabaaabaaa",
      "~~~~~~~~~~~~~~~~",
      "~~~~~~~~~~~~~~~~",
      "~~~~~~~~~~~~~~~~",
      "~~~~~~~~~~~~~~~~",
      "~~~~~~~~~~~~~~~~",
      "~~~~~~~~~~~~~~~~",
      "~~~~~~~~~~~~~~~~",
      "~~~~~~~~~~~~~~~~",
      "~~~~~~~~~~~~~~~~",
      "baaabaaabaaabaaa",
      "aaaaaaaaaaaaaaaa",
      "                "
    ],
    [
      "                ",
      "                ",
      "aaaaaaaaaaaaaaaa",
      "b~~~b~~~b~~~b~~~",
      "~~~~~~~~~~~~~~~~",
      "~~~~~~~~~~~~~~~~",
      "~~~~~~~~~~~~~~~~",
      "~~~~~~~~~~~~~~~~",
      "~~~~~~~~~~~~~~~~",
      "~~~~~~~~~~~~~~~~",
      "~~~~~~~~~~~~~~~~",
      "~~~~~~~~~~~~~~~~",
      "~~~~~~~~~~~~~~~~",
      "b~~~b~~~b~~~b~~~",
      "aaaaaaaaaaaaaaaa",
      "                "
    ],
    [
      "                ",
      "                ",
      "aaaaaaaaaaaaaaaa",
      "HeeeHeeeHeeeHeee",
      "~~~~~~~~~~~~~~~~",
      "~~~~~~~~~~~~~~~~",
      "~~~~~~~~~~~~~~~~",
      "~~~~~~~~~~~~~~~~",
      "~~~~~~~~~~~~~~~~",
      "~~~~~~~~~~~~~~~~",
      "~~~~~~~~~~~~~~~~",
      "~~~~~~~~~~~~~~~~",
      "~~~~~~~~~~~~~~~~",
      "HeeeHeeeHeeeHeee",
      "aaaaaaaaaaaaaaaa",
      "                "
    ],
    [
      "                ",
      "                ",
      "aaaaaaaaaaaaaaaa",
      "b~~~b~~~b~~~b~~~",
      "~~~~~~~~~~~~~~~~",
      "~~~~~~~~~~~~~~~~",
      "~~~~~~~~~~~~~~~~",
      "~~~~~~~~~~~~~~~~",
      "~~~~~~~~~~~~~~~~",
      "~~~~~~~~~~~~~~~~",
      "~~~~~~~~~~~~~~~~",
      "~~~~~~~~~~~~~~~~",
      "~~~~~~~~~~~~~~~~",
      "b~~~b~~~b~~~b~~~",
      "aaaaaaaaaaaaaaaa",
      "                "
    ],
    [
      "                ",
      "                ",
      "aaaaaaaaaaaaaaaa",
      "faaafaaafaaafaaa",
      "g~~~g~~~g~~~g~~~",
      "~~~~g~~~~~~~g~~~",
      "~~~~g~~~~~~~g~~~",
      "~~~~g~~~~~~~g~~~",
      "~~~~g~~~~~~~g~~~",
      "~~~~g~~~~~~~g~~~",
      "~~~~g~~~~~~~g~~~",
      "~~~~g~~~~~~~g~~~",
      "g~~~g~~~g~~~g~~~",
      "faaafaaafaaafaaa",
      "aaaaaaaaaaaaaaaa",
      "                "
    ],
    [
      "                ",
      "                ",
      "                ",
      "eeeeeeeeeeeeeeee",
      "eeeeeeeeeeeeeeee",
      "hhhhhhhhhhhhhhhh",
      "iiiiiiiiiiiiiiii",
      "iiiiiiiiiiiiiiii",
      "iiiiiiiiiiiiiiii",
      "iiiiiiiiiiiiiiii",
      "iiiiiiiiiiiiiiii",
      "hhhhhhhhhhhhhhhh",
      "eeeeeeeeeeeeeeee",
      "eeeeeeeeeeeeeeee",
      "                ",
      "                "
    ]
  ]
}