{
  "name": "rails_vertical_water",
  "refpalette": "c70cities:rails_vertical_water_palette",
  "xsize": 16,
  "zsize": 16,
  "slices": [
    [
      " aHbHHHHHHHHHbba",
      "  bbHHHHHHHHHbb ",
      "  bbHHHHHHHHHbb ",
      "  bbHHHHHHHHHbb ",
      "  bbHHHHHHHHHbb ",
      "  bbHHHHHHHHHbb ",
      "  bbHHHHHHHHHbb ",
      "  bbHHHHHHHHHbb ",
      " aHbHHHHHHHHHbHa",
      "  bbHHHHHHHHHbb ",
      "  bbHHHHHHHHHbb ",
      "  bbHHHHHHHHHbb ",
      "  bbHHHHHHHHHbb ",
      "  bbHHHHHHHHHbb ",
      "  bbHHHHHHHHHbb ",
      "  bbHHHHHHHHHbb "
    ],
    [
      "  bc~~~~d~~~~cb ",
      "  ec~~~~d~~~~ce ",
      "  ec~~~~d~~~~ce ",
      "  ec~~~~d~~~~ce ",
      "  fc~~~~d~~~~cf ",
      "  ec~~~~d~~~~ce ",
      "  ec~~~~d~~~~ce ",
      "  ec~~~~d~~~~ce ",
      "  bc~~~~d~~~~cb ",
      "  ec~~~~d~~~~ce ",
      "  ec~~~~d~~~~ce ",
      "  ec~~~~d~~~~ce ",
      "  fc~~~~d~~~~cf ",
      "  ec~~~~d~~~~ce ",
      "  ec~~~~d~~~~ce ",
      "  ec~~~~d~~~~ce "
    ],
    [
      "  b~~~~~~~~~~~b ",
      "  e~~~~~~~~~~~e ",
      "  e~~~~~~~~~~~e ",
      "  e~~~~~~~~~~~e ",
      "  f~~~~~~~~~~~f ",
      "  e~~~~~~~~~~~e ",
      "  e~~~~~~~~~~~e ",
      "  e~~~~~~~~~~~e ",
      "  b~~~~~~~~~~~b ",
      "  e~~~~~~~~~~~e ",
      "  e~~~~~~~~~~~e ",
      "  e~~~~~~~~~~~e ",
      "  f~~~~~~~~~~~f ",
      "  e~~~~~~~~~~~e ",
      "  e~~~~~~~~~~~e ",
      "  e~~~~~~~~~~~e "
    ],
    [
      "  b~~~~~~~~~~~b ",
      "  e~~~~~~~~~~~e ",
      "  e~~~~~~~~~~~e ",
      "  e~~~~~~~~~~~e ",
      "  f~~~~~~~~~~~f ",
      "  e~~~~~~~~~~~e ",
      "  e~~~~~~~~~~~e ",
      "  e~~~~~~~~~~~e ",
      "  b~~~~~~~~~~~b ",
      "  e~~~~~~~~~~~e ",
      "  e~~~~~~~~~~~e ",
      "  e~~~~~~~~~~~e ",
      "  f~~~~~~~~~~~f ",
      "  e~~~~~~~~~~~e ",
      "  e~~~~~~~~~~~e ",
      "  e~~~~~~~~~~~e "
    ],
    [
      "  b~~~~~~~~~~~b ",
      "  e~~~~~~~~~~~e ",
      "  e~~~~~~~~~~~e ",
      "  e~~~~~~~~~~~e ",
      "  f~~~~~~~~~~~f ",
      "  e~~~~~~~~~~~e ",
      "  e~~~~~~~~~~~e ",
      "  e~~~~~~~~~~~e ",
      "  b~~~~~~~~~~~b ",
      "  e~~~~~~~~~~~e ",
      "  e~~~~~~~~~~~e ",
      "  e~~~~~~~~~~~e ",
      "  f~~~~~~~~~~~f ",
      "  e~~~~~~~~~~~e ",
      "  e~~~~~~~~~~~e ",
      "  e~~~~~~~~~~~e "
    ],
    [
      "  b~~~~~~~~~~~b ",
      "  e~~~~~~~~~~~e ",
      "  e~~~~~~~~~~~e ",
      "  e~~~~~~~~~~~e ",
      "  f~~~~~~~~~~~f ",
      "  e~~~~~~~~~~~e ",
      "  e~~~~~~~~~~~e ",
      "  e~~~~~~~~~~~e ",
      "  b~~~~~~~~~~~b ",
      "  e~~~~~~~~~~~e ",
      "  e~~~~~~~~~~~e ",
      "  e~~~~~~~~~~~e ",
      "  f~~~~~~~~~~~f ",
      "  e~~~~~~~~~~~e ",
      "  e~~~~~~~~~~~e ",
      "  e~~~~~~~~~~~e "
    ],
    [
      "  b~~~~~~~~~~~b ",
      "  ee~~~~~~~~~ee ",
      "  ee~~~~~~~~~ee ",
      "  ee~~~~~~~~~ee ",
      "  ff~~~~~~~~~ff ",
      "  ee~~~~~~~~~ee ",
      "  ee~~~~~~~~~ee ",
      "  ee~~~~~~~~~ee ",
      "  bf~~~~~~~~~fb ",
      "  ee~~~~~~~~~ee ",
      "  ee~~~~~~~~~ee ",
      "  ee~~~~~~~~~ee ",
      "  ff~~~~~~~~~ff ",
      "  ee~~~~~~~~~ee ",
      "  ee~~~~~~~~~ee ",
      "  ee~~~~~~~~~ee "
    ],
    [
      "   bba~~~~~abb~ ",
      "   eee~~~~~eee~ ",
      "   eee~~~~~eee~ ",
      "   eee~~~~~eee~ ",
      "   ggg~~~~~ggg~ ",
      "   eee~~~~~eee~ ",
      "   eee~~~~~eee~ ",
      "   eee~~~~~eee~ ",
      "   bba~~~~~abb~ ",
      "   eee~~~~~eee~ ",
      "   eee~~~~~eee~ ",
      "   eee~~~~~eee~ ",
      "   ggg~~~~~ggg~ ",
      "   eee~~~~~eee~ ",
      "   eee~~~~~eee~ ",
      "   eee~~~~~eee~ "
    ],
    [
      "     bbbbbbb    ",
      "      eeeee     ",
      "      eeeee     ",
      "      eeeee     ",
      "      ggggg     ",
      "      eeeee     ",
      "      eeeee     ",
      "      eeeee     ",
      "     bbbbbbb    ",
      "      eeeee     ",
      "      eeeee     ",
      "      eeeee     ",
      "      ggggg     ",
      "      eeeee     ",
      "      eeeee     ",
      "      eeeee     "
    ]
  ]
}