{
  "name": "rails_down2",
  "refpalette": "c70cities:rails_down2_palette",
  "xsize": 16,
  "zsize": 16,
  "slices": [
    [
      "                ",
      "                ",
      "aa            ~ ",
      "baccc         ~~",
      "HH c          ~~",
      "HH            ~~",
      "HH            ~~",
      "HH            ~~",
      "HH            ~~",
      "HH            ~~",
      "HH            ~~",
      "HH            ~~",
      "Ha            ~~",
      "aa              ",
      "                ",
      "                "
    ],
    [
      "                ",
      "                ",
      "aaa           ~~",
      "daaccc        ~~",
      "efHccc        ~~",
      "  H  c        ~~",
      "  H           ~~",
      "  H           ~~",
      "  H           ~~",
      "  H           ~~",
      "  H           ~~",
      "efH           ~~",
      "daa           ~~",
      "aaa             ",
      "                ",
      "                "
    ],
    [
      "                ",
      "                ",
      "aaaa          ~~",
      "daaac         ~c",
      "~~fHc         ~c",
      "~~ H          ~c",
      "   H          ~c",
      "   H          ~c",
      "~~ H          ~c",
      "~~ H          cc",
      "~~ H        cccc",
      "~~fH         ccc",
      "daaa          ~~",
      "aaaa            ",
      "                ",
      "                "
    ],
    [
      "                ",
      "                ",
      "aaaaa         ~~",
      "daaaa         cc",
      "~~~fH        ccc",
      "~~~ H        cc~",
      " ~~ H        ccc",
      "~~  H     c cccc",
      "~~~ H       cccc",
      "~~~ H     c cccc",
      "~~~ H     cccccc",
      "~~~fH     cccccc",
      "daaaa         ~~",
      "aaaaa           ",
      "                ",
      "                "
    ],
    [
      "                ",
      "                ",
      "aaaaaa          ",
      "HaaaHa     c c  ",
      "~~~~fH      cc  ",
      "~~~~ H      cc  ",
      "~~~~ H      cc  ",
      "~ ~~ H   c  cc c",
      "~~~~ H      cccc",
      "~ ~~ H   ccccccc",
      "~~~~ H    cccccc",
      "~~~~fH    cccccc",
      "Haaaba          ",
      "aaaaaa          ",
      "                ",
      "                "
    ],
    [
      "                ",
      "                ",
      " aaaaaa         ",
      "gaaadaa    cc   ",
      "g~~~~fH     c   ",
      "f~~~~ H         ",
      "v~~~~ H     c   ",
      "v~~~~~H     cc  ",
      "v~~ ~ H     cc  ",
      "v~ ~~ H   cccc  ",
      "f~~~~~H   ccccc ",
      "g~~~~fH   ccccc ",
      "gaaadaa         ",
      " aaaaaa         ",
      "                ",
      "                "
    ],
    [
      "                ",
      "                ",
      "  aaaaaa        ",
      " gaadaaa    c   ",
      " g~~~~fH        ",
      " f~~~~~H        ",
      " v~~~  H        ",
      " v~~~~~H    c   ",
      " v~~~~~H    cc  ",
      " v~~~  H  cccc  ",
      " f~ ~  H  cccc  ",
      " g~~~~fH  ccc   ",
      " gaadaaa        ",
      "  aaaaaa        ",
      "                ",
      "                "
    ],
    [
      "                ",
      "                ",
      "   aaaaaa       ",
      "  gadaaaa       ",
      "  g~~~~fH       ",
      "  f~~~~ H       ",
      "  v~~~~ H       ",
      "  v~~~~ H       ",
      "  v~~~~ H       ",
      "  v~~~~ H ccc   ",
      "  f~~~~ H  cc   ",
      "  g~~~~fH  cc   ",
      "  gadaaaa       ",
      "   aaaaaa       ",
      "                ",
      "                "
    ],
    [
      "                ",
      "                ",
      "   ~aaaaaa~     ",
      "   gHaaaHa~     ",
      "   g~~~~fH~     ",
      "   f~~~~~H~     ",
      "   v~~~~ H~~    ",
      "   v~~~ ~H~     ",
      "   v~~~~~H~     ",
      "   v~~~~ H~     ",
      "   f~~~~ H~cc   ",
      "   g~~~~fH~ c   ",
      "   gHaaaHa~     ",
      "    aaaaaa      ",
      "                ",
      "                "
    ],
    [
      "                ",
      "                ",
      " ~   aaaaaa     ",
      " ~  gaaadaa     ",
      " ~  g~~~~fH     ",
      " ~  f~~~~ H     ",
      " ~  v~~~~ H     ",
      " ~  v~~~~ H     ",
      " ~  v~~~~ H     ",
      " ~  v~~~~ H     ",
      " ~  f~~~~ H     ",
      " ~  g~~~~fH     ",
      " ~  gaaadaa     ",
      "     aaaaaa     ",
      "                ",
      "                "
    ],
    [
      "                ",
      "                ",
      " ~    aaaaaa    ",
      " ~   gaadaaa    ",
      " ~   g~~~~fH    ",
      " ~   f~~~~~H    ",
      " ~   v~~~~ H    ",
      " ~   v~~~~~H    ",
      "     v~~~~~H    ",
      "     v~~~~ H    ",
      "    ~f~~~~ H    ",
      "     g~~~~fH    ",
      "     gaadaaa    ",
      "      aaaaaa    ",
      "                ",
      "                "
    ],
    [
      "                ",
      "                ",
      "       aaaaaa   ",
      "      gadaaaa   ",
      "      g~~~~fH   ",
      "      f~~~~~HH  ",
      "      v~  ~ HH  ",
      "     ~v~~~~~HH  ",
      "     ~v~~~~~HH  ",
      "      v ~~~ HH  ",
      "     ~f~~~~~HH  ",
      "      g~~~~fH  c",
      "     ~gadaaaa   ",
      "       aaaaaa   ",
      "                ",
      "                "
    ],
    [
      "                ",
      "                ",
      "        aaaaaaaa",
      "       gHaaaHaaa",
      "       g~~~~fHHH",
      "       f~~~~  HH",
      "  ~    v~~~   HH",
      "  ~    v~~~~~ HH",
      "  ~    v~~ ~~ HH",
      "  ~    v~~    HH",
      "  ~    f~~~~~ HH",
      "  ~    g~~~~fHHH",
      "  ~    gHaaaHaaa",
      "        aaaaaaaa",
      "                ",
      "                "
    ],
    [
      "                ",
      "                ",
      "         aaaaaaa",
      "        gaaadaaa",
      "        g~~~~eee",
      "        f~~~~   ",
      "        v~~~~  h",
      "        v~~~~   ",
      "        v~~~~   ",
      "        v~~~    ",
      "        f~~~~   ",
      "        g~~~~eee",
      "        gaaadaaa",
      "         aaaaaaa",
      "                ",
      "                "
    ],
    [
      "                ",
      "                ",
      "~         aaaaaa",
      "~        gaadaaa",
      "~        g~~~~~~",
      "~        f~~~~~~",
      "~        v~~~ ~~",
      "~        v~~~ ~~",
      "~        v~~~~~~",
      "~        v~~  ~~",
      "~        f~~~~~~",
      "~        g~~~~~~",
      "~        gaadaaa",
      "          aaaaaa",
      "                ",
      "                "
    ],
    [
      "                ",
      "                ",
      "           aaaaa",
      "          gadaaa",
      "          g~~~~~",
      "          f~~~~~",
      "          v~~~~~",
      "          v~~~~~",
      "          v~~~~~",
      "          v~~~~~",
      "          f~~~~~",
      "          g~~~~~",
      "          gadaaa",
      "           aaaaa",
      "                ",
      "                "
    ],
    [
      "                ",
      "                ",
      "  ~         aaaa",
      "           gHaaa",
      "           g~~~~",
      "           f~~~~",
      "           v~~~~",
      "           v~~~~",
      "           v~~~~",
      "           v~~~~",
      "           f~~~~",
      "           g~~~~",
      "           gHaaa",
      "            aaaa",
      "                ",
      "                "
    ],
    [
      "                ",
      "                ",
      "                ",
      "            gggg",
      "            gggg",
      "            ffff",
      "            vvvv",
      "            vvvv",
      "            vvvv",
      "            vvvv",
      "            ffff",
      "            gggg",
      "            gggg",
      "                ",
      "                ",
      "                "
    ]
  ]
}