{
  "name": "rails_3split",
  "refpalette": "c70cities:rails_3split_palette",
  "xsize": 16,
  "zsize": 16,
  "slices": [
    [
      "    aHaHHHaba   ",
      "    aaaHHHaaa   ",
      "aaaaaaaHHHaaaaaa",
      "baaabaaHHHaaHaaa",
      "HHHHHHHHHHHHHHHH",
      "HHHHHHHHHHHHHHHH",
      "HHHHHHHHHHHHHHHH",
      "HHHHHHHHHHHHHHHH",
      "HHHHHHHHHHHHHHHH",
      "HHHHHHHHHHHHHHHH",
      "HHHHHHHHHHHHHHHH",
      "HHHHHHHHHHHHHHHH",
      "HaaaHaHHHHHabaaH",
      "aaaaaaHHHHHaaaaa",
      "    aaHHHHHaa   ",
      "    abHHHHHHa   "
    ],
    [
      "    acd~e~dca   ",
      "    aad~e~daa   ",
      "aaaaaad~e~daaaaa",
      "caaacad~e~dacaaa",
      "dddddd~~e~dd~ddd",
      "~~~~~~~~~~~~~~~~",
      "ffffffffffffffff",
      "~~~~~~~~~~~~~~~~",
      "~~~~~~~~~~~~~~~~",
      "ffffffffffffffff",
      "~~~~~~~~~~~~~~~~",
      "ddddddd~e~dddddd",
      "caaacad~e~dacaaa",
      "aaaaaad~e~daaaaa",
      "    aad~e~daa   ",
      "    acd~e~dca   "
    ],
    [
      "    ac~~~~~ca   ",
      "    aa~~~~~aa   ",
      "aaaaaa~~~~~aaaaa",
      "caaaca~~~~~acaaa",
      "~~~~~~~~~~~~~~~~",
      "~~~~~~~~~~~~~~~~",
      "~~~~~~~~~~~~~~~~",
      "~~~~~~~~~~~~~~~~",
      "~~~~~~~~~~~~~~~~",
      "~~~~~~~~~~~~~~~~",
      "~~~~~~~~~~~~~~~~",
      "~~~~~~~~~~~~~~~~",
      "caaaca~~~~~acaaa",
      "aaaaaa~~~~~aaaaa",
      "    aa~~~~~aa   ",
      "    ac~~~~~ca   "
    ],
    [
      "    ac~~~~~ca   ",
      "    aa~~~~~aa   ",
      "aaaaaa~~~~~aaaaa",
      "caaaca~~~~~acaaa",
      "~~~~~~~~~~~~~~~~",
      "~~~~~~~~~~~~~~~~",
      "~~~~~~~~~~~~~~~~",
      "~~~~~~~~~~~~~~~~",
      "~~~~~~~~~~~~~~~~",
      "~~~~~~~~~~~~~~~~",
      "~~~~~~~~~~~~~~~~",
      "~~~~~~~~~~~~~~~~",
      "caaaca~~~~~acaaa",
      "aaaaaa~~~~~aaaaa",
      "    aa~~~~~aa   ",
      "    ac~~~~~ca   "
    ],
    [
      "    aH~~~~~Ha   ",
      "    aa~~~~~aa   ",
      "aaaaaa~~~~~aaaaa",
      "HaaaHa~~~~~aHaaa",
      "g~~~g~~~~~~~g~~~",
      "~~~~~~~~~~~~~~~~",
      "~~~~~~~~~~~~~~~~",
      "~~~~~~~~~~~~~~~~",
      "~~~~~~~~~~~~~~~~",
      "~~~~~~~~~~~~~~~~",
      "~~~~~~~~~~~~~~~~",
      "g~~~g~~~~~~~g~~~",
      "HaaaHa~~~~~aHaaa",
      "aaaaaa~~~~~aaaaa",
      "    aa~~~~~aa   ",
      "    aH~~~~~Ha   "
    ],
    [
      "     haaaaah    ",
      "     hijjjih    ",
      "     hijjjih    ",
      "hhhhhhijjjihhhhh",
      "hhhhhhijjjihhhhh",
      "iiiiiiijjjiiiiii",
      "jjjjjjjjjjjjjjjj",
      "jjjjjjjjjjjjjjjj",
      "jjjjjjjjjjjjjjjj",
      "jjjjjjjjjjjjjjjj",
      "iiiiiiijjjiiiiii",
      "hhhhhhijjjihhhhh",
      "hhhhhhijjjihhhhh",
      "~~~~~hijjjih~~~~",
      "     hijjjih    ",
      "     haaaaah    "
    ]
  ]
}