{
  "name": "rails_down1",
  "refpalette": "c70cities:rails_down1_palette",
  "xsize": 16,
  "zsize": 16,
  "slices": [
    [
      "                ",
      "                ",
      "a~~~~~~~        ",
      "a~~~~~~~        ",
      "H~~~~~~~        ",
      "H~~~~~~~        ",
      "H~~~~~~~        ",
      "H~~~~~~~        ",
      "H~~~~~~~        ",
      "H~~~~~~~        ",
      "H~~~~~~~        ",
      "H~~~~~~~        ",
      "a~~~~~~~        ",
      "a               ",
      "                ",
      "                "
    ],
    [
      "                ",
      "                ",
      "aa~~~~~~        ",
      "ba~~~~~~        ",
      "cH~~~~~~        ",
      " H~~~~~~        ",
      " H~~~~~~        ",
      " H~~~~~~        ",
      " H~~~~~~        ",
      " H~~~~~~        ",
      " H~~~~~~        ",
      "cH~~~~~~        ",
      "Ha~~~~~~        ",
      "aa              ",
      "                ",
      "                "
    ],
    [
      "                ",
      "                ",
      "aaa~~~~~        ",
      "daa~~~~~        ",
      "~cH~~~~~        ",
      "~ H~~~~~        ",
      "~ H~~~~~        ",
      "~ H~~~~~        ",
      "~~H~~~~~        ",
      "~ H~~~~~        ",
      "~ H~~~~~        ",
      "~cH~~~~~        ",
      "daa~~~~~        ",
      "aaa             ",
      "                ",
      "                "
    ],
    [
      "                ",
      "                ",
      "aaaa~~~~        ",
      "daaa~~~~        ",
      "~~cH~~~~        ",
      "~~ H~~~~        ",
      "~~ H~~~~        ",
      "~~~H~~~~        ",
      "~~ H~~~~        ",
      "~~ H~~~~        ",
      "~~ H~~~~        ",
      "~~cH~~~~        ",
      "daaa~~~~        ",
      "aaaa            ",
      "                ",
      "                "
    ],
    [
      "                ",
      "                ",
      "aaaaa~~~        ",
      "daaaa~~~        ",
      "~~~cH~~~        ",
      "~~~ H~~~        ",
      "~~~ H~ ~        ",
      "~~~ H~~~        ",
      "~~~ H~~~        ",
      "~~~ H~~~        ",
      "~~~ H~~~        ",
      "~~~cH~~~        ",
      "daaaa~~~        ",
      "aaaaa           ",
      "                ",
      "                "
    ],
    [
      "                ",
      "                ",
      "aaaaaaa~        ",
      "Haaaaaa~        ",
      "~~~~cHH~        ",
      " ~~~~HH~~       ",
      "~~ ~ HH~        ",
      "~~~~~HH~        ",
      "~~   HH~        ",
      "~~~~ HH~        ",
      "~~~ ~HH~        ",
      "~~~~cHH~        ",
      "Haaaaaa~        ",
      "aaaaaaa~        ",
      "                ",
      "                "
    ],
    [
      "               a",
      "               a",
      "~~~~~~~~~~~~~~~a",
      "eeeeeeeaaaaaaaaa",
      "e~~~~cHHHHHHHHHH",
      "e~~~~~~HHHHHHHHH",
      "e~~~  ~HHHHHHHHH",
      "e~~~~~~HHHHHHHHH",
      "e~ ~~~~HHHHHHHHH",
      "e~~~  ~HHHHHHHHH",
      "e~~~~~~HHHHHHHHH",
      "e~~~~cHHHHHHHHHH",
      "eeeeeeeaaaaaaaaa",
      "               a",
      "               a",
      "               a"
    ],
    [
      "               a",
      "               a",
      "~~~~~~~~~~~~~~~a",
      "effffffeaaaaaaaa",
      "f~~~~~gggggggggg",
      "f~~~~~~~~~~~~~~~",
      "f~~~~~  hhhh hhh",
      "f~~~~~~~~~~~~~~~",
      "f~~~~~~~~~~~~~~~",
      "f~~~~~  hh hhhhh",
      "f~~~~~~~~~~~~~~~",
      "f~~~~~gggggggggg",
      "effffffeaaaaaaaa",
      "               a",
      "               a",
      "               a"
    ],
    [
      "                ",
      "                ",
      "~~~~~~~~~~~~~~~~",
      "efffffffe~~~~~~~",
      "f~~~~~~~~~~~~~~~",
      "f~~~~~~~~~~~~~~~",
      "f~~~~~~~~~~~~~~~",
      "f~~~~~~~~~~~~~~~",
      "f~~~~~~~~~~~~~~~",
      "f~~~~~~~~~~~~~~~",
      "f~~~~~~~~~~~~~~~",
      "f~~~~~~~~~~~~~~~",
      "efffffffe~~~~~~~",
      "                ",
      "                ",
      "                "
    ],
    [
      "                ",
      "                ",
      "~~~~~~~~~~~~~~~~",
      "e~~~~~~~~e~~~~~~",
      "~~~~~~~~~~~~~~~~",
      "~~~~~~~~~~~~~~~~",
      "~~~~~~~~~~~~~~~~",
      "~~~~~~~~~~~~~~~~",
      "~~~~~~~~~~~~~~~~",
      "~~~~~~~~~~~~~~~~",
      "~~~~~~~~~~~~~~~~",
      "~~~~~~~~~~~~~~~~",
      "e~~~~~~~~e~~~~~~",
      "                ",
      "                ",
      "                "
    ],
    [
      "                ",
      "                ",
      "~~~~~~~~~~~~~~~~",
      "iiijjj~~~~e~~~~~",
      "ikkkjk~~~~~~~~~~",
      "ikkkjk~~~~~~~~~~",
      " iij~j~~~~~~~~~~",
      "illlll~~~~~~~~~~",
      "illlll~~~~~~~~~~",
      " iij~j~~~~~~~~~~",
      "ikkkjk~~~~~~~~~~",
      "ikkkjk~~~~~~~~~~",
      "iiijjj~~~~e~~~~~",
      "                ",
      "                ",
      "                "
    ],
    [
      "                ",
      "                ",
      "~~~~~~~~~~~~~~~~",
      "~~~~~~iiijjej~~~",
      "~~~~~~kkikkkj~~~",
      "~~~~~~kkikkkj~~~",
      "~~~~~~ii~jjj~~~~",
      "~~~~~~llllllj~~~",
      "~~~~~~llllllj~~~",
      "~~~~~~ii~jjj~~~~",
      "~~~~~~kkikkkj~~~",
      "~~~~~~kkikkkj~~~",
      "~~~~~~iiijjej~~~",
      "                ",
      "                ",
      "                "
    ]
  ]
}