{
  "name": "rails_vertical",
  "refpalette": "c70cities:rails_vertical_palette",
  "xsize": 16,
  "zsize": 16,
  "slices": [
    [
      " aaaHHHHHHHHHaba",
      "  aaHHHHHHHHHaa ",
      "  aaHHHHHHHHHaa ",
      "  aaHHHHHHHHHaa ",
      "  aaHHHHHHHHHaa ",
      "  aaHHHHHHHHHaa ",
      "  aaHHHHHHHHHaa ",
      "  aaHHHHHHHHHaa ",
      " abaHHHHHHHHHaaa",
      "  aaHHHHHHHHHaa ",
      "  aaHHHHHHHHHaa ",
      "  aaHHHHHHHHHaa ",
      "  aaHHHHHHHHHaa ",
      "  aaHHHHHHHHHaa ",
      "  aaHHHHHHHHHaa ",
      "  aaHHHHHHHHHaa "
    ],
    [
      " acd~~~~e~~~~dca",
      "  ad~~~~e~~~~da ",
      "  ad~~~~e~~~~da ",
      "  ad~~~~e~~~~da ",
      "  ad~~~~e~~~~da ",
      "  ad~~~~e~~~~da ",
      "  ad~~~~e~~~~da ",
      "  ad~~~~e~~~~da ",
      " acd~~~~e~~~~dca",
      "  ad~~~~e~~~~da ",
      "  ad~~~~e~~~~da ",
      "  ad~~~~e~~~~da ",
      "  ad~~~~e~~~~da ",
      "  ad~~~~e~~~~da ",
      "  ad~~~~e~~~~da ",
      "  ad~~~~e~~~~da "
    ],
    [
      " ac~~~~~~~~~~~ca",
      "  a~~~~~~~~~~~a ",
      "  a~~~~~~~~~~~a ",
      "  a~~~~~~~~~~~a ",
      "  a~~~~~~~~~~~a ",
      "  a~~~~~~~~~~~a ",
      "  a~~~~~~~~~~~a ",
      "  a~~~~~~~~~~~a ",
      " ac~~~~~~~~~~~ca",
      "  a~~~~~~~~~~~a ",
      "  a~~~~~~~~~~~a ",
      "  a~~~~~~~~~~~a ",
      "  a~~~~~~~~~~~a ",
      "  a~~~~~~~~~~~a ",
      "  a~~~~~~~~~~~a ",
      "  a~~~~~~~~~~~a "
    ],
    [
      " ac~~~~~~~~~~~ca",
      "  a~~~~~~~~~~~a ",
      "  a~~~~~~~~~~~a ",
      "  a~~~~~~~~~~~a ",
      "  a~~~~~~~~~~~a ",
      "  a~~~~~~~~~~~a ",
      "  a~~~~~~~~~~~a ",
      "  a~~~~~~~~~~~a ",
      " ac~~~~~~~~~~~ca",
      "  a~~~~~~~~~~~a ",
      "  a~~~~~~~~~~~a ",
      "  a~~~~~~~~~~~a ",
      "  a~~~~~~~~~~~a ",
      "  a~~~~~~~~~~~a ",
      "  a~~~~~~~~~~~a ",
      "  a~~~~~~~~~~~a "
    ],
    [
      " ac~~~~~~~~~~~ca",
      "  a~~~~~~~~~~~a ",
      "  a~~~~~~~~~~~a ",
      "  a~~~~~~~~~~~a ",
      "  a~~~~~~~~~~~a ",
      "  a~~~~~~~~~~~a ",
      "  a~~~~~~~~~~~a ",
      "  a~~~~~~~~~~~a ",
      " ac~~~~~~~~~~~ca",
      "  a~~~~~~~~~~~a ",
      "  a~~~~~~~~~~~a ",
      "  a~~~~~~~~~~~a ",
      "  a~~~~~~~~~~~a ",
      "  a~~~~~~~~~~~a ",
      "  a~~~~~~~~~~~a ",
      "  a~~~~~~~~~~~a "
    ],
    [
      " ac~~~~~~~~~~~ca",
      "  a~~~~~~~~~~~a ",
      "  a~~~~~~~~~~~a ",
      "  a~~~~~~~~~~~a ",
      "  a~~~~~~~~~~~a ",
      "  a~~~~~~~~~~~a ",
      "  a~~~~~~~~~~~a ",
      "  a~~~~~~~~~~~a ",
      " ac~~~~~~~~~~~ca",
      "  a~~~~~~~~~~~a ",
      "  a~~~~~~~~~~~a ",
      "  a~~~~~~~~~~~a ",
      "  a~~~~~~~~~~~a ",
      "  a~~~~~~~~~~~a ",
      "  a~~~~~~~~~~~a ",
      "  a~~~~~~~~~~~a "
    ],
    [
      " aaH~~~~~~~~~Haa",
      "  aa~~~~~~~~~aa ",
      "  aa~~~~~~~~~aa ",
      "  aa~~~~~~~~~aa ",
      "  aa~~~~~~~~~aa ",
      "  aa~~~~~~~~~aa ",
      "  aa~~~~~~~~~aa ",
      "  aa~~~~~~~~~aa ",
      " aaH~~~~~~~~~Haa",
      "  aa~~~~~~~~~aa ",
      "  aa~~~~~~~~~aa ",
      "  aa~~~~~~~~~aa ",
      "  aa~~~~~~~~~aa ",
      "  aa~~~~~~~~~aa ",
      "  aa~~~~~~~~~aa ",
      "  aa~~~~~~~~~aa "
    ],
    [
      " aaaHHfffffHHaaa",
      "   aaa~~~~~aaa~ ",
      "   aaa~~~~~aaa~ ",
      "   aaa~~~~~aaa~ ",
      "   aaa~~~~~aaa~ ",
      "   aaa~~~~~aaa~ ",
      "   aaa~~~~~aaa~ ",
      "   aaa~~~~~aaa~ ",
      " aaaHHfffffHHaaa",
      "   aaa~~~~~aaa~ ",
      "   aaa~~~~~aaa~ ",
      "   aaa~~~~~aaa~ ",
      "   aaa~~~~~aaa~ ",
      "   aaa~~~~~aaa~ ",
      "   aaa~~~~~aaa~ ",
      "   aaa~~~~~aaa~ "
    ],
    [
      "  aaaaHHHHHaaaa ",
      "     ghiiihg    ",
      "     ghiiihg    ",
      "     ghiiihg    ",
      "     ghiiihg    ",
      "     ghiiihg    ",
      "     ghiiihg    ",
      "     ghiiihg    ",
      "  aaaaHHHHHaaaa ",
      "     ghiiihg    ",
      "     ghiiihg    ",
      "     ghiiihg    ",
      "     ghiiihg    ",
      "     ghiiihg    ",
      "     ghiiihg    ",
      "     ghiiihg    "
    ]
  ]
}