{
  "name": "rails_3split",
  "refpalette": "c70cities:rails_3split_palette",
  "xsize": 16,
  "zsize": 16,
  "slices": [
    [
      "    abHHHHHba   ",
      "aaaaaHHHHHHHaaaa",
      "baaHHHHHHHHHHHHb",
      "HHHHHHHHHHHHHHHH",
      "HHHHHHHHHHHHHHHH",
      "HHHHHHHHHHHHHHHH",
      "HHHHHHHHHHHHHHHH",
      "HHHHHHHHHHHHHHHH",
      "HHHHHHHHHHHHHHHH",
      "HHHHHHHHHHHHHHHH",
      "HHHHHHHHHHHHHHHH",
      "HHHHHHHHHHHHHHHH",
      "HHHHHHHHHHHHHHHH",
      "baaHHHHHHHHHHHHb",
      "aaaaaHHHHHHHHaaa",
      "    abHHHHHbH   "
    ],
    [
      "    acd~e~dca   ",
      "aaaaad~~~~~daaaa",
      "caaad~~~~~~~daac",
      "dddd~~~~~~~~~ddd",
      "~~~~~~~~~~~~~~~~",
      "~~~~~~f~~~f~~~~~",
      "g~~~~~~~~~~~~~~g",
      "~~~g~~~~~~~~~~~~",
      "~~~~~~~~~~~g~~~~",
      "g~~~~~~~e~~~~~~g",
      "~~~~~~f~~~~~~~~~",
      "~~~~~~~~~~~~~~~~",
      "dddd~f~~~g~~~ddd",
      "caaad~~~~~~~daac",
      "aaaaad~~~~~daaaa",
      "    acd~e~dca   "
    ],
    [
      "    ac~~~~~ca   ",
      "aaaaa~~~~~~~aaaa",
      "caaa~~~~~~~~~aac",
      "~~~~~~~~~~~~~~~~",
      "~~~~~~~~~~~~~~~~",
      "~~~~~~~~~~~~~~~~",
      "~~~~~~~~~~~~~~~~",
      "~~~~~~~~~~~~~~~~",
      "~~~~~~~~~~~~~~~~",
      "~~~~~~~~~~~~~~~~",
      "~~~~~~~~~~~~~~~~",
      "~~~~~~~~~~~~~~~~",
      "~~~~~~~~~~~~~~~~",
      "caaa~~~~~~~~~aac",
      "aaaaa~~~~~~~aaaa",
      "    ac~~~~~ca   "
    ],
    [
      "    ac~~~~~ca   ",
      "aaaaa~~~~~~~aaaa",
      "caaa~~~~~~~~~aac",
      "~~~~~~~~~~~~~~~~",
      "~~~~~~~~~~~~~~~~",
      "~~~~~~~~~~~~~~~~",
      "~~~~~~~~~~~~~~~~",
      "~~~~~~~~~~~~~~~~",
      "~~~~~~~~~~~~~~~~",
      "~~~~~~~~~~~~~~~~",
      "~~~~~~~~~~~~~~~~",
      "~~~~~~~~~~~~~~~~",
      "~~~~~~~~~~~~~~~~",
      "caaa~~~~~~~~~aac",
      "aaaaa~~~~~~~aaaa",
      "    ac~~~~~ca   "
    ],
    [
      "    aH~~~~~Ha   ",
      "aaaaH~~~~~~~Haaa",
      "Haaah~~~~~~~haaH",
      "h~~~h~~~~~~~h~~h",
      "h~~~h~~~~~~~h~~h",
      "h~~~h~~~~~~~h~~h",
      "h~~~h~~~~~~~h~~h",
      "h~~~h~~~~~~~h~~h",
      "h~~~h~~~~~~~h~~h",
      "h~~~h~~~~~~~h~~h",
      "h~~~h~~~~~~~h~~h",
      "h~~~h~~~~~~~h~~h",
      "h~~~h~~~~~~~h~~h",
      "Haaah~~~~~~~haaH",
      "aaaaH~~~~~~~Haaa",
      "    aH~~~~~Ha   "
    ],
    [
      "     iaaaaai    ",
      "     ijkkkji    ",
      "iiiiiijkkkjiiiii",
      "iiiiiijkkkjiiiii",
      "iiiiiijkkkjiiiii",
      "jjjjjjjkkkjjjjjj",
      "kkkkkkkkkkkkkkkk",
      "kkkkkkkkkkkkkkkk",
      "kkkkkkkkkkkkkkkk",
      "kkkkkkkkkkkkkkkk",
      "jjjjjjjkkkjjjjjj",
      "iiiiiijkkkjiiiii",
      "iiiiiijkkkjiiiii",
      "iiiiiijkkkjiiiii",
      "     ijkkkji    ",
      "     iaaaaai    "
    ]
  ]
}