{
  "name": "rails_down2",
  "refpalette": "c70cities:rails_down2_palette",
  "xsize": 16,
  "zsize": 16,
  "slices": [
    [
      "                ",
      "                ",
      "Haaaaaaaaaaaaaaa",
      "baaaaaaaaaaaaaaa",
      "HHaaaaaaaaaaaaaa",
      "HHaaaaaaaaaaaaaa",
      "HHaaaaaaaaaaaaaa",
      "HHaaaaaaaaaaaaaa",
      "HHaaaaaaaaaaaaaa",
      "HHaaaaaaaaaaaaaa",
      "HHaaaaaaaaaaaaaa",
      "HHaaaaaaaaaaaaaa",
      "HHaaaaaaaaaaaaaa",
      "baaaaaaaaaaaaaaa",
      "Haaaaaaaaaaaaaaa",
      "                "
    ],
    [
      "                ",
      "                ",
      "Haa  c c c c  aa",
      "daaeee         a",
      "fgHeee          ",
      "~~H  e   c   c  ",
      "~~H             ",
      "~~H             ",
      "~~H      c   c  ",
      "~~H             ",
      "~~H             ",
      "~~H      c   c  ",
      "fgH             ",
      "daa            a",
      "Haa  c c c c  aa",
      "                "
    ],
    [
      "                ",
      "                ",
      "Haaa c c c c  aa",
      "daaae          a",
      "~~gHe          e",
      "~~~H     c   c e",
      "~~~H           e",
      "~~~H           e",
      "~~~H     c   c e",
      "~~~H          ee",
      "~~~H        eee ",
      "~~~H     c  ecee",
      "~~gH         ee ",
      "daaa           a",
      "Haaa c c c c  aa",
      "                "
    ],
    [
      "                ",
      "                ",
      "Haaaac c c c  aa",
      "daaaa         ea",
      "~~~gH        eee",
      "~~~~H    c   ce ",
      "~~~~H        eee",
      "~~~~H     e eeee",
      "~~~~H    c  ecee",
      "~~~~H     e eeee",
      "~~~~H     eeeee ",
      "~~~~H    ceeecee",
      "~~~gH     eeeee ",
      "daaaa          a",
      "Haaaac c c c  aa",
      "                "
    ],
    [
      "                ",
      "                ",
      "Haaaaa c c c  aa",
      "daaaHa     e e a",
      "~~~~gH      ee  ",
      "~~~~~H   c  ec  ",
      "~~~~~H      ee  ",
      "~~~~~H   e  ee e",
      "~~~~~H   c  ecee",
      "~~~~~H   eeeeeee",
      "~~~~~H    eeeee ",
      "~~~~~H   ceeecee",
      "~~~~gH    eeeee ",
      "daaaba         a",
      "Haaaaa c c c  aa",
      "                "
    ],
    [
      "                ",
      "                ",
      "Haaaaaac c c  aa",
      "Haaadaa    ee  a",
      "~~~~~gH     e   ",
      "~~~~~~H  c   c  ",
      "~~~~~~H     e   ",
      "~~~~~~H     ee  ",
      "~~~~~~H  c  ec  ",
      "~~~~~~H   eeee  ",
      "~~~~~~H   eeeee ",
      "~~~~~~H  ceeece ",
      "~~~~~gH   eeeee ",
      "Haaadaa        a",
      "Haaaaaac c c  aa",
      "                "
    ],
    [
      "                ",
      "                ",
      "Haaaaaaa c c  aa",
      "~haadaaa    e  a",
      "~~~~~~gH        ",
      "~~~~~~~H c   c  ",
      "~~~~~~~H        ",
      "~~~~~~~H    e   ",
      "~~~~~~~H c  ec  ",
      "~~~~~~~H  eeee  ",
      "~~~~~~~H  eeee  ",
      "~~~~~~~H c eec  ",
      "~~~~~~gH  eee   ",
      "~haadaaa       a",
      "Haaaaaaa c c  aa",
      "                "
    ],
    [
      "                ",
      "                ",
      "Haaaaaaaac c  aa",
      "~~hadaaaa      a",
      "~~~~~~~gH       ",
      "~~~~~~~~Hc   c  ",
      "~~~~~~~~H       ",
      "~~~~~~~~H       ",
      "~~~~~~~~Hc   c  ",
      "~~~~~~~~H eee   ",
      "~~~~~~~~H  ee   ",
      "~~~~~~~~Hc eec  ",
      "~~~~~~~gH  ee   ",
      "~~hadaaaa      a",
      "Haaaaaaaac c  aa",
      "                "
    ],
    [
      "                ",
      "                ",
      "Haaaaaaaaa c  aa",
      "h~~hdaaaHa     a",
      "h~~~~~~~gH      ",
      "h~~~~~~~~H   c  ",
      "h~~~~~~~~H      ",
      "h~~~~~~~~H      ",
      "h~~~~~~~~H   c  ",
      "h~~~~~~~~H      ",
      "h~~~~~~~~H ee   ",
      "h~~~~~~~~H eec  ",
      "h~~~~~~~gH  e   ",
      "h~~hdaaaHa     a",
      "Haaaaaaaaa c  aa",
      "                "
    ],
    [
      "                ",
      "                ",
      "aaaaaaaaaaac  aa",
      "a~~~Haaadaa    a",
      "a~~~~~~~~gH     ",
      "d~~~~~~~~~H  c  ",
      "a~~~~~~~~~H     ",
      "a~~~~~~~~~H     ",
      "a~~~~~~~~~H  c  ",
      "a~~~~~~~~~H     ",
      "a~~~~~~~~~H     ",
      "d~~~~~~~~~H  c  ",
      "a~~~~~~~~gH     ",
      "a~~~Haaadaa    a",
      "aaaaaaaaaaac  aa",
      "                "
    ],
    [
      "                ",
      "                ",
      "aaaaaaaaaaaa  aa",
      "a~~~dhaadaaa   a",
      "a~~~~~~~~~gH    ",
      "d~~~~~~~~~~H c  ",
      "a~~~~~~~~~~H    ",
      "a~~~~~~~~~~H    ",
      "a~~~~~~~~~~H c  ",
      "a~~~~~~~~~~H    ",
      "a~~~~~~~~~~H    ",
      "d~~~~~~~~~~H c  ",
      "a~~~~~~~~~gH    ",
      "a~~~dhaadaaa   a",
      "aaaaaaaaaaaa  aa",
      "                "
    ],
    [
      "                ",
      "                ",
      "aaaaaaaaaaaaa aa",
      "a~~~d~hadaaaa  a",
      "a~~~~~~~~~~gH   ",
      "d~~~~~~~~~~~HH  ",
      "a~~~~~~~~~~~HH  ",
      "a~~~~~~~~~~~HH  ",
      "a~~~~~~~~~~~HH  ",
      "a~~~~~~~~~~~HH  ",
      "a~~~~~~~~~~~HH  ",
      "d~~~~~~~~~~~HH  ",
      "a~~~~~~~~~~gH   ",
      "a~~~d~hadaaaa  a",
      "aaaaaaaaaaaaa aa",
      "                "
    ],
    [
      "                ",
      "                ",
      "aaaaaaaaaaaaaaaa",
      "a~~~d~~hdaaaHaaa",
      "a~~~~~~~~~~~gHHH",
      "d~~~~~~~~~~~~~HH",
      "a~~~~~~~~~~~~~HH",
      "a~~~~~~~~~~~~~HH",
      "a~~~~~~~~~~~~~HH",
      "a~~~~~~~~~~~~~HH",
      "a~~~~~~~~~~~~~HH",
      "d~~~~~~~~~~~~~HH",
      "a~~~~~~~~~~~gHHH",
      "a~~~d~~hdaaaHaaa",
      "aaaaaaaaaaaaaaaa",
      "                "
    ],
    [
      "                ",
      "                ",
      "aaaaaaaaaaaaaaaa",
      "a~~~d~~~Haaadaaa",
      "a~~~~~~~~~~~~fff",
      "d~~~~~~~~~~~~~~~",
      "a~~~~~~~~~~~~~~~",
      "a~~~~~~~~~~~~~~~",
      "a~~~~~~~~~~~~~~i",
      "a~~~~~~~~~~~~~~~",
      "a~~~~~~~~~~~~~~~",
      "d~~~~~~~~~~~~~~~",
      "a~~~~~~~~~~~~fff",
      "a~~~d~~~Haaadaaa",
      "aaaaaaaaaaaaaaaa",
      "                "
    ],
    [
      "                ",
      "                ",
      "aaaaaaaaaaaaaaaa",
      "a~~~d~~~dhaadaaa",
      "a~~~~~~~~~~~~~~~",
      "d~~~~~~~~~~~~~~~",
      "a~~~~~~~~~~~~~~~",
      "a~~~~~~~~~~~~~~~",
      "a~~~~~~~~~~~~~~~",
      "a~~~~~~~~~~~~~~~",
      "a~~~~~~~~~~~~~~~",
      "d~~~~~~~~~~~~~~~",
      "a~~~~~~~~~~~~~~~",
      "a~~~d~~~dhaadaaa",
      "aaaaaaaaaaaaaaaa",
      "                "
    ],
    [
      "                ",
      "                ",
      "aaaaaaaaaaaaaaaa",
      "a~~~d~~~d~hadaaa",
      "a~~~~~~~~~~~~~~~",
      "d~~~~~~~~~~~~~~~",
      "a~~~~~~~~~~~~~~~",
      "a~~~~~~~~~~~~~~~",
      "a~~~~~~~~~~~~~~~",
      "a~~~~~~~~~~~~~~~",
      "a~~~~~~~~~~~~~~~",
      "d~~~~~~~~~~~~~~~",
      "a~~~~~~~~~~~~~~~",
      "a~~~d~~~d~hadaaa",
      "aaaaaaaaaaaaaaaa",
      "                "
    ],
    [
      "                ",
      "                ",
      "aaaaaaaaaaaaaaaa",
      "a~~~d~~~d~~hdaaa",
      "a~~~~~~~~~~~~~~~",
      "d~~~~~~~~~~~~~~~",
      "a~~~~~~~~~~~~~~~",
      "a~~~~~~~~~~~~~~~",
      "a~~~~~~~~~~~~~~~",
      "a~~~~~~~~~~~~~~~",
      "a~~~~~~~~~~~~~~~",
      "d~~~~~~~~~~~~~~~",
      "a~~~~~~~~~~~~~~~",
      "a~~~d~~~d~~hdaaa",
      "aaaaaaaaaaaaaaaa",
      "                "
    ],
    [
      "                ",
      "                ",
      "aaaaaaaaaaaaaaaa",
      "a~~~b~~~b~~~bhhh",
      "a~~~~~~~~~~~~~~~",
      "d~~~~~~~~~~~~~~~",
      "a~~~~~~~~~~~~~~~",
      "a~~~~~~~~~~~~~~~",
      "a~~~~~~~~~~~~~~~",
      "a~~~~~~~~~~~~~~~",
      "a~~~~~~~~~~~~~~~",
      "d~~~~~~~~~~~~~~~",
      "a~~~~~~~~~~~~~~~",
      "a~~~b~~~b~~~bhhh",
      "aaaaaaaaaaaaaaaa",
      "                "
    ],
    [
      "                ",
      "                ",
      "                ",
      " hhhhhhhhhhhhhhh",
      " hhhhhhhhhhhhhhj",
      " ggggggggggggggk",
      " vvvvvvvvvvvvvvl",
      " vvvvvvvvvvvvvvl",
      " vvvvvvvvvvvvvvl",
      " vvvvvvvvvvvvvvl",
      " vvvvvvvvvvvvvvl",
      " ggggggggggggggk",
      " hhhhhhhhhhhhhhj",
      " hhhhhhhhhhhhhhh",
      "                ",
      "                "
    ]
  ]
}