{
  "name": "rails_vertical",
  "refpalette": "c70cities:rails_vertical_palette",
  "xsize": 16,
  "zsize": 16,
  "slices": [
    [
      " aaaHaHHHHHaHaba",
      "  aaHaHHHHHaHaa ",
      "  aaHaHHHHHaHaa ",
      "  aaHaHHHHHaHaa ",
      "  aaHaHHHHHaHaa ",
      "  aaHaHHHHHaHaa ",
      "  aaHaHHHHHaHaa ",
      "  aaHaHHHHHaHaa ",
      " abaHaHHHHHaHaaa",
      "  aaHaHHHHHaHaa ",
      "  aaHaHHHHHaHaa ",
      "  aaHaHHHHHaHaa ",
      "  aaHaHHHHHaHaa ",
      "  aaHaHHHHHaHaa ",
      "  aaHaHHHHHaHaa ",
      "  aaHaHHHHHaHaa "
    ],
    [
      " acd~d~~e~~d~dca",
      "  ad~d~~e~~d~da ",
      "  ad~d~~e~~d~da ",
      "  ad~d~~e~~d~da ",
      "  ad~d~~e~~d~da ",
      "  ad~d~~e~~d~da ",
      "  ad~d~~e~~d~da ",
      "  ad~d~~e~~d~da ",
      " acd~d~~e~~d~dca",
      "  ad~d~~e~~d~da ",
      "  ad~d~~e~~d~da ",
      "  ad~d~~e~~d~da ",
      "  ad~d~~e~~d~da ",
      "  ad~d~~e~~d~da ",
      "  ad~d~~e~~d~da ",
      "  ad~d~~e~~d~da "
    ],
    [
      " ac~~~~~~~~~~~ca",
      "  a~~~~~~~~~~~a ",
      "  a~~~~~~~~~~~a ",
      "  a~~~~~~~~~~~a ",
      "  a~~~~~~~~~~~a ",
      "  a~~~~~~~~~~~a ",
      "  a~~~~~~~~~~~a ",
      "  a~~~~~~~~~~~a ",
      " ac~~~~~~~~~~~ca",
      "  a~~~~~~~~~~~a ",
      "  a~~~~~~~~~~~a ",
      "  a~~~~~~~~~~~a ",
      "  a~~~~~~~~~~~a ",
      "  a~~~~~~~~~~~a ",
      "  a~~~~~~~~~~~a ",
      "  a~~~~~~~~~~~a "
    ],
    [
      " ac~~~~~~~~~~~ca",
      "  a~~~~~~~~~~~a ",
      "  a~~~~~~~~~~~a ",
      "  a~~~~~~~~~~~a ",
      "  a~~~~~~~~~~~a ",
      "  a~~~~~~~~~~~a ",
      "  a~~~~~~~~~~~a ",
      "  a~~~~~~~~~~~a ",
      " ac~~~~~~~~~~~ca",
      "  a~~~~~~~~~~~a ",
      "  a~~~~~~~~~~~a ",
      "  a~~~~~~~~~~~a ",
      "  a~~~~~~~~~~~a ",
      "  a~~~~~~~~~~~a ",
      "  a~~~~~~~~~~~a ",
      "  a~~~~~~~~~~~a "
    ],
    [
      " ac~~~~~~~~~~~ca",
      "  a~~~~~~~~~~~a ",
      "  a~~~~~~~~~~~a ",
      "  a~~~~~~~~~~~a ",
      "  a~~~~~~~~~~~a ",
      "  a~~~~~~~~~~~a ",
      "  a~~~~~~~~~~~a ",
      "  a~~~~~~~~~~~a ",
      " ac~~~~~~~~~~~ca",
      "  a~~~~~~~~~~~a ",
      "  a~~~~~~~~~~~a ",
      "  a~~~~~~~~~~~a ",
      "  a~~~~~~~~~~~a ",
      "  a~~~~~~~~~~~a ",
      "  a~~~~~~~~~~~a ",
      "  a~~~~~~~~~~~a "
    ],
    [
      " ac~~~~~~~~~~~ca",
      "  a~~~~~~~~~~~a ",
      "  a~~~~~~~~~~~a ",
      "  a~~~~~~~~~~~a ",
      "  a~~~~~~~~~~~a ",
      "  a~~~~~~~~~~~a ",
      "  a~~~~~~~~~~~a ",
      "  a~~~~~~~~~~~a ",
      " ac~~~~~~~~~~~ca",
      "  a~~~~~~~~~~~a ",
      "  a~~~~~~~~~~~a ",
      "  a~~~~~~~~~~~a ",
      "  a~~~~~~~~~~~a ",
      "  a~~~~~~~~~~~a ",
      "  a~~~~~~~~~~~a ",
      "  a~~~~~~~~~~~a "
    ],
    [
      " aaH~~~~~~~~~Haa",
      "  aa~~~~~~~~~aa ",
      "  aa~~~~~~~~~aa ",
      "  aa~~~~~~~~~aa ",
      "  aa~~~~~~~~~aa ",
      "  aa~~~~~~~~~aa ",
      "  aa~~~~~~~~~aa ",
      "  aa~~~~~~~~~aa ",
      " aaH~~~~~~~~~Haa",
      "  aa~~~~~~~~~aa ",
      "  aa~~~~~~~~~aa ",
      "  aa~~~~~~~~~aa ",
      "  aa~~~~~~~~~aa ",
      "  aa~~~~~~~~~aa ",
      "  aa~~~~~~~~~aa ",
      "  aa~~~~~~~~~aa "
    ],
    [
      " aaaHHfffffHHaaa",
      "   aaa~~~~~aaa~ ",
      "   aaa~~~~~aaa~ ",
      "   aaa~~~~~aaa~ ",
      "   aaa~~~~~aaa~ ",
      "   aaa~~~~~aaa~ ",
      "   aaa~~~~~aaa~ ",
      "   aaa~~~~~aaa~ ",
      " aaaHHfffffHHaaa",
      "   aaa~~~~~aaa~ ",
      "   aaa~~~~~aaa~ ",
      "   aaa~~~~~aaa~ ",
      "   aaa~~~~~aaa~ ",
      "   aaa~~~~~aaa~ ",
      "   aaa~~~~~aaa~ ",
      "   aaa~~~~~aaa~ "
    ],
    [
      "  aaaaHHHHHaaaa ",
      "     ghiiihg    ",
      "     ghiiihg    ",
      "     ghiiihg    ",
      "     ghiiihg    ",
      "     ghiiihg    ",
      "     ghiiihg    ",
      "     ghiiihg    ",
      "  aaaaHHHHHaaaa ",
      "     ghiiihg    ",
      "     ghiiihg    ",
      "     ghiiihg    ",
      "     ghiiihg    ",
      "     ghiiihg    ",
      "     ghiiihg    ",
      "     ghiiihg    "
    ]
  ]
}