{
  "name": "rails_bend",
  "refpalette": "c70cities:rails_bend_palette",
  "xsize": 16,
  "zsize": 16,
  "slices": [
    [
      " abaHHHHHHHHHaba",
      " aaaHHHHHHHHHaaa",
      "aaaaHHHHHHHHHaaa",
      "HHbaHHHHHHHHHaaa",
      "HHHHHHHHHHHHHaaa",
      "HHHHHHHHHHHHHaba",
      "HHHHHHHHHHHHHaaa",
      "HHHHHHHHHHHHHaaa",
      "HHHHHHHHHHHHHaaa",
      "HHHHHHHHHHHHHaaa",
      "HHHHHHHHHHHHHaba",
      "HHHHHHHHHHHHHaaa",
      "HHHHHHHHHHHHHaaa",
      "aabaHHHHHHHHHaaa",
      "aaaaHHHHHHHHHaaa",
      " abaHHHHHHHHHaba"
    ],
    [
      " acdd~~~e~~~ddca",
      " aad~~~~~~~~~daa",
      "aaad~~~~~~~~~daa",
      "aacd~~~~e~~~~daa",
      "dddd~~~~~~~~~daa",
      "~~~~~~~~~~~~~dca",
      "~~~f~~~~~~~~~daa",
      "~~~~~g~~e~~~~daa",
      "h~~~~~~~~~~~~daa",
      "~~~~~e~~~~~~~daa",
      "~~g~~~~~~~~~~dca",
      "~~~~~~~g~~~~~daa",
      "dddd~~~~~~~~~daa",
      "aacd~~~~~~~~~daa",
      "aaad~~~~~~~~~daa",
      " acdd~~~e~~~ddca"
    ],
    [
      " ac~~~~~~~~~~~ca",
      " aa~~~~~~~~~~~aa",
      "aaa~~~~~~~~~~~aa",
      "aac~~~~~~~~~~~aa",
      "~~~~~~~~~~~~~~aa",
      "~~~~~~~~~~~~~~ca",
      "~~~~~~~~~~~~~~aa",
      "~~~~~~~~~~~~~~aa",
      "~~~~~~~~~~~~~~aa",
      "~~~~~~~~~~~~~~aa",
      "~~~~~~~~~~~~~~ca",
      "~~~~~~~~~~~~~~aa",
      "~~~~~~~~~~~~~~aa",
      "aac~~~~~~~~~~~aa",
      "aaa~~~~~~~~~~~aa",
      " ac~~~~~~~~~~~ca"
    ],
    [
      " ac~~~~~~~~~~~ca",
      " aa~~~~~~~~~~~aa",
      "aaa~~~~~~~~~~~aa",
      "aac~~~~~~~~~~~aa",
      "~~~~~~~~~~~~~~aa",
      "~~~~~~~~~~~~~~ca",
      "~~~~~~~~~~~~~~aa",
      "~~~~~~~~~~~~~~aa",
      "~~~~~~~~~~~~~~aa",
      "~~~~~~~~~~~~~~aa",
      "~~~~~~~~~~~~~~ca",
      "~~~~~~~~~~~~~~aa",
      "~~~~~~~~~~~~~~aa",
      "aac~~~~~~~~~~~aa",
      "aaa~~~~~~~~~~~aa",
      " ac~~~~~~~~~~~ca"
    ],
    [
      " ac~~~~~~~~~~~ca",
      " a~~~~~~~~~~~~~a",
      "aa~~~~~~~~~~~~~a",
      "~~c~~~~~~~~~~~~a",
      "~~~~~~~~~~~~~~~a",
      "~~~~~~~~~~~~~~ca",
      "~~~~~~~~~~~~~~~a",
      "~~~~~~~~~~~~~~~a",
      "~~~~~~~~~~~~~~~a",
      "~~~~~~~~~~~~~~~a",
      "~~~~~~~~~~~~~~ca",
      "~~~~~~~~~~~~~~~a",
      "~~~~~~~~~~~~~~~a",
      "~~c~~~~~~~~~~~~a",
      "aa~~~~~~~~~~~~~a",
      " ac~~~~~~~~~~~ca"
    ],
    [
      " aH~~~~~~~~~~~Ha",
      " ai~~~~~~~~~~~ia",
      "aai~~~~~~~~~~~ia",
      "iiH~~~~~~~~~~~ia",
      "~~~~~~~~~~~~~~ia",
      "~~~~~~~~~~~~~~Ha",
      "~~~~~~~~~~~~~~ia",
      "~~~~~~~~~~~~~~ia",
      "~~~~~~~~~~~~~~ia",
      "~~~~~~~~~~~~~~ia",
      "~~~~~~~~~~~~~~Ha",
      "~~~~~~~~~~~~~~ia",
      "~~~~~~~~~~~~~~ia",
      "iiH~~~~~~~~~~~ia",
      "aai~~~~~~~~~~~ia",
      " aH~~~~~~~~~~~Ha"
    ],
    [
      " ac~~~~~~~~~~~ca",
      " a~~~~~~~~~~~~~a",
      "aa~~~~~~~~~~~~~a",
      "~~c~~~~~~~~~~~~a",
      "~~~~~~~~~~~~~~~a",
      "~~~~~~~~~~~~~~ca",
      "~~~~~~~~~~~~~~~a",
      "~~~~~~~~~~~~~~~a",
      "~~~~~~~~~~~~~~~a",
      "~~~~~~~~~~~~~~~a",
      "~~~~~~~~~~~~~~ca",
      "~~~~~~~~~~~~~~~a",
      "~~~~~~~~~~~~~~~a",
      "~~c~~~~~~~~~~~~a",
      "aa~~~~~~~~~~~~~a",
      " ac~~~~~~~~~~~ca"
    ],
    [
      " abjjjjjjjjjjjba",
      " aa~~~~~~~~~~~aa",
      "aaa~~~~~~~~~~~aa",
      "aab~~~~~~~~~~~aa",
      "j~j~~~~~~~~~~~aa",
      "jjjjjjjjjjjjjjba",
      "j~j~~~~~~~~~~~aa",
      "j~j~~~~~~~~~~~aa",
      "j~j~~~~~~~~~~~aa",
      "j~j~~~~~~~~~~~aa",
      "jjjjjjjjjjjjjjba",
      "j~j~~~~~~~~~~~aa",
      "j~j~~~~~~~~~~~aa",
      "aab~~~~~~~~~~~aa",
      "aaa~~~~~~~~~~~aa",
      " abjjjjjjjjjjjba"
    ],
    [
      "  iaaaaaaaaaaai ",
      "  iklllllllllki ",
      "  iklllllllllki ",
      "iiiklllllllllki ",
      "iiiklllllllllki ",
      "iiiklllllllllki ",
      "kkkklllllllllki ",
      "lllllllllllllki ",
      "lllllllllllllki ",
      "lllllllllllllki ",
      "kkkklllllllllki ",
      "iiiklllllllllki ",
      "iiiklllllllllki ",
      "iiiklllllllllki ",
      "  iklllllllllki ",
      "  iaaaaaaaaaaai "
    ]
  ]
}