{
  "name": "rails_horizontal_water",
  "refpalette": "c70cities:rails_horizontal_water_palette",
  "xsize": 16,
  "zsize": 16,
  "slices": [
    [
      "                ",
      "                ",
      "   a       a    ",
      "bbbbbbbbbbbbbbbb",
      "HHHHHHHHHHHHHHHH",
      "HHHHHHHHHHHHHHHH",
      "HHHHHHHHHHHHHHHH",
      "HHHHHHHHHHHHHHHH",
      "HHHHHHHHHHHHHHHH",
      "HHHHHHHHHHHHHHHH",
      "HHHHHHHHHHHHHHHH",
      "HHHHHHHHHHHHHHHH",
      "bbbbbbbbbbbbbbbb",
      "bbbbbbbbbbbbbbbb",
      "   a       a    ",
      "                "
    ],
    [
      "                ",
      "                ",
      "   b       b    ",
      "bbbbbbbbbbbbbbbb",
      "cccccccccccccccc",
      "~~~~~~~~~~~~~~~~",
      "~~~~~~~~~~~~~~~~",
      "~~~~~~~~~~~~~~~~",
      "dddddddddddddddd",
      "~~~~~~~~~~~~~~~~",
      "~~~~~~~~~~~~~~~~",
      "~~~~~~~~~~~~~~~~",
      "cccccccccccccccc",
      "bbbbbbbbbbbbbbbb",
      "   b       b    ",
      "                "
    ],
    [
      "                ",
      "                ",
      "   b       b    ",
      "eeefeeefeeefeeef",
      "~~~~~~~~~~~~~~~~",
      "~~~~~~~~~~~~~~~~",
      "~~~~~~~~~~~~~~~~",
      "~~~~~~~~~~~~~~~~",
      "~~~~~~~~~~~~~~~~",
      "~~~~~~~~~~~~~~~~",
      "~~~~~~~~~~~~~~~~",
      "~~~~~~~~~~~~~~~~",
      "~~~~~~~~~~~~~~~~",
      "eeefeeefeeefeeef",
      "   b       b    ",
      "                "
    ],
    [
      "                ",
      "                ",
      "   b       b    ",
      "eeefeeefeeefeeef",
      "~~~~~~~~~~~~~~~~",
      "~~~~~~~~~~~~~~~~",
      "~~~~~~~~~~~~~~~~",
      "~~~~~~~~~~~~~~~~",
      "~~~~~~~~~~~~~~~~",
      "~~~~~~~~~~~~~~~~",
      "~~~~~~~~~~~~~~~~",
      "~~~~~~~~~~~~~~~~",
      "~~~~~~~~~~~~~~~~",
      "eeefeeefeeefeeef",
      "   b       b    ",
      "                "
    ],
    [
      "                ",
      "                ",
      "   b       b    ",
      "eeefeeefeeefeeef",
      "~~~~~~~~~~~~~~~~",
      "~~~~~~~~~~~~~~~~",
      "~~~~~~~~~~~~~~~~",
      "~~~~~~~~~~~~~~~~",
      "~~~~~~~~~~~~~~~~",
      "~~~~~~~~~~~~~~~~",
      "~~~~~~~~~~~~~~~~",
      "~~~~~~~~~~~~~~~~",
      "~~~~~~~~~~~~~~~~",
      "eeefeeefeeefeeef",
      "   b       b    ",
      "                "
    ],
    [
      "                ",
      "                ",
      "   b       b    ",
      "eeefeeefeeefeeef",
      "~~~~~~~~~~~~~~~~",
      "~~~~~~~~~~~~~~~~",
      "~~~~~~~~~~~~~~~~",
      "~~~~~~~~~~~~~~~~",
      "~~~~~~~~~~~~~~~~",
      "~~~~~~~~~~~~~~~~",
      "~~~~~~~~~~~~~~~~",
      "~~~~~~~~~~~~~~~~",
      "~~~~~~~~~~~~~~~~",
      "eeefeeefeeefeeef",
      "   b       b    ",
      "                "
    ],
    [
      "                ",
      "                ",
      "   b       b    ",
      "eeefeeefeeefeeef",
      "~~~~~~~~~~~~~~~~",
      "~~~~~~~~~~~~~~~~",
      "~~~~~~~~~~~~~~~~",
      "~~~~~~~~~~~~~~~~",
      "~~~~~~~~~~~~~~~~",
      "~~~~~~~~~~~~~~~~",
      "~~~~~~~~~~~~~~~~",
      "~~~~~~~~~~~~~~~~",
      "~~~~~~~~~~~~~~~~",
      "eeefeeefeeefeeef",
      "   b       b    ",
      "                "
    ],
    [
      "                ",
      "                ",
      "   b       b    ",
      "   b       b    ",
      "eeeaeeegeeeaeeeg",
      "~~~~~~~~~~~~~~~~",
      "~~~~~~~~~~~~~~~~",
      "~~~~~~~~~~~~~~~~",
      "~~~~~~~~~~~~~~~~",
      "~~~~~~~~~~~~~~~~",
      "~~~~~~~~~~~~~~~~",
      "~~~~~~~~~~~~~~~~",
      "eeeaeeegeeeaeeeg",
      "   b       b    ",
      "   b       b    ",
      "                "
    ],
    [
      "                ",
      "                ",
      "                ",
      "   b       b    ",
      "   b       b    ",
      "hhhbhhhhhhhbhhhh",
      "eeebeeegeeebeeeg",
      "eeebeeegeeebeeeg",
      "eeebeeegeeebeeeg",
      "eeebeeegeeebeeeg",
      "eeebeeegeeebeeeg",
      "hhhbhhhhhhhbhhhh",
      "   b       b    ",
      "   b       b    ",
      "                ",
      "                "
    ]
  ]
}