{
  "name": "station_openroof",
  "refpalette": "c70cities:station_openroof_palette",
  "xsize": 16,
  "zsize": 16,
  "slices": [
    [
      "aaaaaaaaaaaaaaaa",
      "HHHHHHHHHHHHHHHH",
      "HHHHHHHHHHHHHHHH",
      "HHHHHHHHHHHHHHHH",
      "HHHHHHHHHHHHHHHH",
      "HHHHHHHHHHHHHHHH",
      "HHHHHHHHHHHHHHHH",
      "HHHHHHHHHHHHHHHH",
      "HHHHHHHHHHHHHHHH",
      "HHHHHHHHHHHHHHHH",
      "HHHHHHHHHHHHHHHH",
      "HHHHHHHHHHHHHHHH",
      "HHHHHHHHHHHHHHHH",
      "HHHHHHHHHHHHHHHH",
      "HHHHHHHHHHHHHHHH",
      "aaaaaaaaaaaaaaaa"
    ],
    [
      "aaaaaaaaaaaaaaaa",
      "bbbbbbbbbbbbbbbb",
      "bbbbbbbbbbbbbbbb",
      "bcbcbcbbbcbcbcbc",
      "dddddddedddddddd",
      "                ",
      "                ",
      "   ff f ff      ",
      "gggggggggggggggg",
      "   ff f ff      ",
      "                ",
      "                ",
      "dddddddddddddddd",
      "bcbcbcbcbcbcbcbc",
      "bbbbbbbbbbbbbbbb",
      "aaaaaaaaaaaaaaaa"
    ],
    [
      "hhhihjhhhjhihhhh",
      " ka a lmnka a ln",
      "                ",
      "                ",
      "                ",
      "                ",
      "   ooopooo      ",
      "   ooooooo      ",
      "   ooooooo      ",
      "   ooooooo      ",
      "   oooqooo      ",
      "                ",
      "                ",
      "                ",
      " ka akrstka akrt",
      "hhuiujhhhjuiuhhh"
    ],
    [
      "  hihj   jhih   ",
      " ka a    ka a   ",
      "                ",
      "                ",
      "                ",
      "                ",
      "   owoxowo      ",
      "   yA   Ay      ",
      "   BC   DE      ",
      "   yA   Ay      ",
      "   owoFowo      ",
      "                ",
      "                ",
      "                ",
      " ka ak   ka a   ",
      "  uiuj   juiu   "
    ],
    [
      "  hihj   jhih   ",
      "  a a     a a   ",
      "                ",
      "                ",
      "                ",
      "                ",
      "   o oIo o      ",
      "   w     w      ",
      "                ",
      "   w     w      ",
      "   o oJo o      ",
      "                ",
      "                ",
      "                ",
      "  a a     a a   ",
      "  uiuj   juiu   "
    ],
    [
      "  hihj   jhih   ",
      "  a a     a a   ",
      "  K K     K K   ",
      "                ",
      "                ",
      "                ",
      "   ooooooo      ",
      "   y  L  y      ",
      "   w  M  w      ",
      "   y  M  y      ",
      "   ooooooo      ",
      "                ",
      "                ",
      "  N N     N N   ",
      "  a a     a a   ",
      "   i j   j i    "
    ],
    [
      "  hihj   jhih   ",
      "  a a     a a   ",
      "                ",
      "                ",
      "                ",
      "                ",
      "   OOOOOOO      ",
      "   ooooooo      ",
      "   ooooooo      ",
      "   ooooooo      ",
      "   PPPPPPP      ",
      "                ",
      "                ",
      "                ",
      "  a a     a a   ",
      "   i j   j i    "
    ],
    [
      "  hihj   jhih   ",
      "  a a     a a   ",
      "                ",
      "                ",
      "                ",
      "                ",
      "                ",
      "                ",
      "                ",
      "                ",
      "                ",
      "                ",
      "                ",
      "                ",
      "  a a     a a   ",
      "   i j   j i    "
    ],
    [
      "QQRRRQQQQQRRRQQQ",
      "QQaQaQQQQQaQaQQQ",
      "  fjfjjjjjfjf   ",
      "  fff     fff   ",
      "  f f     f f   ",
      "  f f     f f   ",
      "  f f     f f   ",
      "  f f     f f   ",
      "  f f     f f   ",
      "  f f     f f   ",
      "  f f     f f   ",
      "  f f     f f   ",
      "  fff     f f   ",
      "  fjfjjjjjfjf   ",
      "QQaQaQQQQQaQaQQQ",
      "QQSSSQQQQQSSSQQQ"
    ],
    [
      "                ",
      "QQTQTQQQQQTQTQQQ",
      "QQTQTQQQQQTQTQQQ",
      "QQTQTQQQQQTQTQQQ",
      "TT T TTTTT T TTT",
      "UUUUUUUUUUUUUUUU",
      "VVVVVVVVVVVVVVVV",
      "VVVVVVVVVVVVVVVV",
      "VVVVVVVVVVVVVVVV",
      "VVVVVVVVVVVVVVVV",
      "VVVVVVVVVVVVVVVV",
      "UUUUUUUUUUUUUUUU",
      "QQ Q QQQQQ Q QQQ",
      "QQTQTQQQQQTQTQQQ",
      "QQTQTQQQQQTQTQQQ",
      "                "
    ]
  ]
}