{
  "name": "station_open",
  "refpalette": "c70cities:station_open_palette",
  "xsize": 16,
  "zsize": 16,
  "slices": [
    [
      "aaaaaaaaaaaaaaaa",
      "HHHHHHHHHHHHHHHH",
      "HHHHHHHHHHHHHHHH",
      "HHHHHHHHHHHHHHHH",
      "HHHHHHHHHHHHHHHH",
      "HHHHHHHHHHHHHHHH",
      "HHHHHHHHHHHHHHHH",
      "HHHHHHHHHHHHHHHH",
      "HHHHHHHHHHHHHHHH",
      "HHHHHHHHHHHHHHHH",
      "HHHHHHHHHHHHHHHH",
      "HHHHHHHHHHHHHHHH",
      "HHHHHHHHHHHHHHHH",
      "HHHHHHHHHHHHHHHH",
      "HHHHHHHHHHHHHHHH",
      "aaaaaaaaaaaaaaaa"
    ],
    [
      "aaaaaaaaaaaaaaaa",
      "bbbbbbbbbbbbbbbb",
      "bbbbbbbbbbbbbbbb",
      "bcbcbcbcbcbcbcbc",
      "ddddddd dddddddd",
      "                ",
      "eeeeeeeeeeeeeeee",
      "                ",
      "                ",
      "eeeeeeeeeeeeeeee",
      "                ",
      "dddddddddddddddd",
      "bcbcbcbcbcbcbcbc",
      "bbbbbbbbbbbbbbbb",
      "bbbbbbbbbbbbbbbb",
      "aaaaaaaaaaaaaaaa"
    ],
    [
      "~~~~~~~~~~~~~~~~",
      "~f~ f~gh~f~ f~gh",
      "~~~~~~~~~~~~~~~~",
      "~~~~~~~~~~~~~~~~",
      "~~~~~~~~~~~~~~~~",
      "~~~~iiiii~~~~~~~",
      "~~~~ii ii~~~~~~~",
      "~~~~iiiii~~~~~~~",
      "~~~~~      ~~~~~",
      "~~~~~     ~~~~~~",
      "~~~~~     ~~~~~~",
      "~~~~~      ~~~~~",
      "~~~~~~~~~~~~~~~~",
      "~~~~~~~~~~~~~~~~",
      "~f~ f~jk~f~ f~jk",
      "~~~~~~~~~~~~~~~~"
    ],
    [
      "~~~~~~~~~~~~~~~~",
      "~f~~f~~~~f~~f~~~",
      "~~~~~~~~~~~~~~~~",
      "~~~~~~~~~~~~~~~~",
      "~~~~~~ ~~~~~~~~~",
      "~~~~li~il~~~~~~~",
      "~~~~mnopm~~~~~~~",
      "~~~~lmmml~~~~~~~",
      "~~~~~     ~~~~~~",
      "~~~~~ ~ ~ ~~~~~~",
      "~~~~~ ~~  ~~~~~~",
      "~~~~~     ~~~~~~",
      "~~~~~~~~~~~~~~~~",
      "~~~~~~~~~~~~~~~~",
      "~f~~f~~~~f~~f~~~",
      "~~~~~~~~~~~~~~~~"
    ],
    [
      "~~~~~~~~~~~~~~~~",
      "~~~~~~~~~~~~~~~~",
      "~~~~~~~~~~~~~~~~",
      "~~~~~~~~~~~~~~~~",
      "~~~~~~~~~~~~~~~~",
      "~~~~qi~ir~~~~~~~",
      "~~  q  ~m~~~~~~~",
      "~~~~qmmmr~~~~~~~",
      "~~~~~~    ~~~~~~",
      "~~~~~     ~~~~~~",
      "~~~~      ~~~~~~",
      "~~~~~     ~~~~~~",
      "~~~~~~~~~~~~~~~~",
      "~~~~~~~~~~~~~~~~",
      "~~~~~~~~~~~~~~~~",
      "~~~~~~~~~~~~~~~~"
    ],
    [
      "~~~~~~~~~~~~~~~~",
      "~~~~~~~~~~~~~~~~",
      "~~~~~~~~~~~~~~~~",
      "~~~~~~~~~~~~~~~~",
      "~~~~~ ~~~~~~~~~~",
      "~~~~sssss~~~~~~~",
      "~~ ~tuuut ~~~~~~",
      "~~~~wwwww~~~~~~~",
      "~~~~~~~~~~~~~~~~",
      "~~~~~  ~~~~~~~~~",
      "~~~~  ~~~~~~~~~~",
      "~~~~  ~~~~~~~~~~",
      "~~~~~~~~~~~~~~~~",
      "~~~~~~~~~~~~~~~~",
      "~~~~~~~~~~~~~~~~",
      "~~~~~~~~~~~~~~~~"
    ],
    [
      "                ",
      "                ",
      "                ",
      "                ",
      "                ",
      "                ",
      "                ",
      "                ",
      "                ",
      "                ",
      "                ",
      "                ",
      "                ",
      "                ",
      "                ",
      "~~~~~~~~~ ~~~~~~"
    ]
  ]
}