{
  "name": "station_underground_stairs",
  "refpalette": "c70cities:station_underground_stairs_palette",
  "xsize": 16,
  "zsize": 16,
  "slices": [
    [
      "aaaaaaaaaaaaaaaa",
      "HHHHHHHHHHHHHHHH",
      "HHHHHHHHHHHHHHHH",
      "HHHHHHHHHHHHHHHH",
      "HHHHHHHHHHHHHHHH",
      "HHHHHHHHHHHHHHHH",
      "HHHHHHHHHHHHHHHH",
      "HHHHHHHHHHHHHHHH",
      "HHHHHHHHHHHHHHHH",
      "HHHHHHHHHHHHHHHH",
      "HHHHHHHHHHHHHHHH",
      "HHHHHHHHHHHHHHHH",
      "HHHHHHHHHHHHHHHH",
      "HHHHHHHHHHHHHHHH",
      "HHHHHHHHHHHHHHHH",
      "aaaaaaaaaaaaaaaa"
    ],
    [
      "aaaaaaaaaaaaaaaa",
      "bcccHcccbcccHccc",
      "cccccccccccccccc",
      "cdcdcdcdcdcdcdcd",
      "eeeeeeeeeeeeeeee",
      "~~~~~~~~~~~~~~~~",
      "ffffffffffffffff",
      "~~~~~~~~~~~~~~~~",
      "~~~~~~~~~~~~~~~~",
      "ffffffffffffffff",
      "~~~~~~~~~~~~~~~~",
      "eeeeeeeeeeeeeeee",
      "cdcdcdcdcdcdcdcd",
      "cccccccccccccccc",
      "HcccbcccHcccbccc",
      "aaaaaaaaaaaaaaaa"
    ],
    [
      "aaaaaaaaaaaaaaaa",
      "ghijgk~kghijg~~~",
      "~~~~~~~~~~~~~~~~",
      "~~~~~~~~~~~~~~~~",
      "~~~~~~~~~~~~~~~~",
      "~~~~~~~~~~~~~~~~",
      "~~~~~~~~~~~~~~~~",
      "~~~~~~~~~~~~~~~~",
      "~~~~~~~~~~~~~~~~",
      "~~~~~~~~~~~~~~~~",
      "~~~~~~~~~~~~~~~~",
      "~~~~~~~~~~~~~~~~",
      "~~~~~~~~~~~~~~~~",
      "~~l~~~mm~~~~~~~~",
      "gnopge~~gnopg~~l",
      "aaaaaaaaaaaaaaaa"
    ],
    [
      "aaaaaaaaaaaaaaaa",
      "g~~~g~~~g~~~g~~~",
      "~~~~~~~~~~~~~~~~",
      "~~~~~~~~~~~~~~~~",
      "~~~~~~~~~~~~~~~~",
      "~~~~~~~~~~~~~~~~",
      "~~~~~~~~~~~~~~~~",
      "~~~~~~~~~~~~~~~~",
      "~~~~~~~~~~~~~~~~",
      "~~~~~~~~~~~~~~~~",
      "~~~~~~~~~~~~~~~~",
      "~~~~~~~~~~~~~~~~",
      "~~~~~~~~~~~~~~~~",
      "~~~~~~mm~~~~~~~~",
      "g~~~g~e~g~~~g~~~",
      "aaaaaaaaaaaaaaaa"
    ],
    [
      "aaaaaaaaaaaaaaaa",
      "g~~~gl~~g~~~g~~l",
      "q~~~q~~~q~~~q~~~",
      "q~~~q~~~q~~~q~~~",
      "q~~~q~~~q~~~q~~~",
      "~~~~~~~~~~~~~~~~",
      "~~~~~~~~~~~~~~~~",
      "~~~~~~~~~~~~~~~~",
      "~~~~~~~~~~~~~~~~",
      "~~~~~~~~~~~~~~~~",
      "~~~~~~~~~~~~~~~~",
      "q~~~q~~~q~~~q~~~",
      "q~~~q~~~q~~~q~~~",
      "q~~~q~mmq~~~q~~~",
      "g~~~g~~egl~~g~~~",
      "aaaaaaaaaaaaaaaa"
    ],
    [
      "rrrrrrrrrrrrrrrr",
      "rrrrrrrrrrrrrrrr",
      "rrrrrrrrrrrrrrrr",
      "rrrrrrrrrrrrrrrr",
      "rrrrrrrrrrrrrrrr",
      "ssssssssssssssss",
      "HvvvHvvvHvvvHvvv",
      "HvvvHvvvHvvvHvvv",
      "HvvvHvvvHvvvHvvv",
      "HvvvHvvvHvvvHvvv",
      "ssssssssssssssss",
      "rrrrrrrrrrrrrrrr",
      "rrrrrrrrrrrrrrrr",
      "rrrrrrrrrrrrrrrr",
      "rrrrr~~~errrrrrr",
      "rrrrrrrrrrrrrrrr"
    ]
  ]
}