{
  "name": "station_openroof",
  "refpalette": "c70cities:station_openroof_palette",
  "xsize": 16,
  "zsize": 16,
  "slices": [
    [
      "aaaaaaaaaaaaaaaa",
      "HHHHHHHHHHHHHHHH",
      "HHHHHHHHHHHHHHHH",
      "HHHHHHHHHHHHHHHH",
      "HHHHHHHHHHHHHHHH",
      "HHHHHHHHHHHHHHHH",
      "HHHHHHHHHHHHHHHH",
      "HHHHHHHHHHHHHHHH",
      "HHHHHHHHHHHHHHHH",
      "HHHHHHHHHHHHHHHH",
      "HHHHHHHHHHHHHHHH",
      "HHHHHHHHHHHHHHHH",
      "HHHHHHHHHHHHHHHH",
      "HHHHHHHHHHHHHHHH",
      "HHHHHHHHHHHHHHHH",
      "aaaaaaaaaaaaaaaa"
    ],
    [
      "aaaaaaaaaaaaaaaa",
      "bbbbbbbbbbbbbbbb",
      "bbbbbbbbbbbbbbbb",
      "bcbcbcbbbcbcbcbc",
      "dddddddddddddddd",
      "~~~~~~~~~~~~~~~~",
      "eeeeee eeeeeeeee",
      "~~~~~~~~~~~~~~~~",
      "~~~~~~~~~~~~~~~~",
      "eeee eeeeeee eee",
      "~~~~~~~~~~~~~~~~",
      "dddddddddddddddd",
      "bcbcbcbbbcbcbcbc",
      "bbbbbbbbbbbbbbbb",
      "bbbbbbbbbbbbbbbb",
      "aaaaaaaaaaaaaaaa"
    ],
    [
      "~~fgf~~~~~fgf~~~",
      "~ha~a~ij~ha~a~ij",
      "~~~~~~~~~~~~~~~~",
      "~~~~~~~~~~~~~~~~",
      "~~~~~~~~~~~~~~~~",
      "~~~~~~~~~~~~~~~~",
      "~~~~~~~~~~~~~~~~",
      "~~~~~~~~~~~~~~~~",
      "~~~~~~~~~~~~~~~~",
      "~~~~~~~~~~~~~~~~",
      "~~~~~~~~~~~~~~~~",
      "~~~~~~~~~~~~~~~~",
      "~~~~~~~~~~~~~~~~",
      "~~~~~~~~~~~~~~~~",
      "~ha~a~kl~ha~a~kl",
      "~~fgf~~~~~fgf~~~"
    ],
    [
      "~~fgf~~~~~fgf~~~",
      "~ha~a~~~~ha~a~~~",
      "~~~~~~~~~~~~~~~~",
      "~~~~~~~~~~~~~~~~",
      "~~~~~~~~~~~~~~~~",
      "~~~~~~~~~~~~~~~~",
      "~~~~~~~~~~~~~~~~",
      "~~~~~~~~~~~~~~~~",
      "~~~~~~~~~~~~~~~~",
      "~~~~~~~~~~~~~~ ~",
      "~~~~~~~~~~~~~~~~",
      "~~~~~~~~~~~~~~~~",
      "~~~~~~~~~~~~~~~~",
      "~~~~~~~~~~~~~~~~",
      "~ha~a~~~~~a~a~~~",
      "~~fgf~~~~~fgf~~~"
    ],
    [
      "~~fgf~~~~~fgf~~~",
      "~~a~a~~~~~ama~~~",
      "~~~~~~~~~~~~~~~~",
      "~~~~~~~~~~~~~~~~",
      "~~~~~~~~~~~~~~~~",
      "~~~~~~~~~~~~~~~~",
      "~~~~~~~~~~~~~~~~",
      "~~~~~~~~~~~~~~~~",
      "~~~~~~~~~~~~~~~~",
      "~~~~~~~~~~~~~~~~",
      "~~~~~~~~~~~~~~~~",
      "~~~~~~~~~~~~~~~~",
      "~~~~~~~~~~~~~~~~",
      "~~~~~~~~~~~~~~~~",
      "~~ana~~~~~ana~~~",
      "~~fgf~~~~~fgf~~~"
    ],
    [
      "oopppooooopppooo",
      "ooaoaoooooaoaooo",
      "~~q~q~~~~~q~q~~~",
      "~~qqq~~~~~qqq~~~",
      "~~q~q~~~~~q~q~~~",
      "~~q~q~~~~~q~q~~~",
      "~~q~q~~~~~q~q~~~",
      "~~q~q~~~~~q~q~~~",
      "~~q~q~~~~~q~q~~~",
      "~~q~q~~~~~q~q~~~",
      "~~q~q~~~~~q~q~~~",
      "~~q~q~~~~~q~q~~~",
      "~~qqq~~~~~qqq~~~",
      "~~q~q~~~~~q~q~~~",
      "ooaoaoooooaoaooo",
      "oorrrooooorrrooo"
    ],
    [
      "~~~~~~~~~~~~~~~~",
      "oososooooososooo",
      "oososooooososooo",
      "oososooooososooo",
      "ss s sssss s sss",
      "tttttttttttttttt",
      "uuuuuuuuuuuuuuuu",
      "uuuuuuuuuuuuuuuu",
      "uuuuuuuuuuuuuuuu",
      "uuuuuuuuuuuuuuuu",
      "tttttttttttttttt",
      "ss s sssss s sss",
      "oososooooososooo",
      "oososooooososooo",
      "oososooooososooo",
      "~~~~~~~~~~~~~~~~"
    ]
  ]
}