{
  "name": "station_openroof",
  "refpalette": "c70cities:station_openroof_palette",
  "xsize": 16,
  "zsize": 16,
  "slices": [
    [
      "aaaaaaaaaaaaaaaa",
      "HHHHHHHHHHHHHHHH",
      "HHHHHHHHHHHHHHHH",
      "HHHHHHHHHHHHHHHH",
      "HHHHHHHHHHHHHHHH",
      "HHHHHHHHHHHHHHHH",
      "HHHHHHHHHHHHHHHH",
      "HHHHHHHHHHHHHHHH",
      "HHHHHHHHHHHHHHHH",
      "HHHHHHHHHHHHHHHH",
      "HHHHHHHHHHHHHHHH",
      "HHHHHHHHHHHHHHHH",
      "HHHHHHHHHHHHHHHH",
      "HHHHHHHHHHHHHHHH",
      "HHHHHHHHHHHHHHHH",
      "aaaaaaaaaaaaaaaa"
    ],
    [
      "aaaaaaaaaaaaaaaa",
      "bbbbbbbbbbbbbbbb",
      "bbbbbbbbbbbbbbbb",
      "bcbcbcbbbcbcbcbc",
      "dddddddedddddddd",
      "                ",
      "                ",
      "   ff f ff      ",
      "gggggggggggggggg",
      "   ff f ff      ",
      "                ",
      "                ",
      "dddddddddddddddd",
      "bcbcbcbcbcbcbcbc",
      "bbbbbbbbbbbbbbbb",
      "aaaaaaaaaaaaaaaa"
    ],
    [
      "hhhihjhhhjhihhhh",
      " ka a lmnka a ln",
      "                ",
      "                ",
      "                ",
      "                ",
      "   ooopooo      ",
      "   ooooooo      ",
      "   ooooooo      ",
      "   ooooooo      ",
      "   oooqooo      ",
      "                ",
      "                ",
      "                ",
      " ka akrstka akrt",
      "hhuiujhhhjuiuhhh"
    ],
    [
      "  hihj   jhih   ",
      " ka a    ka a   ",
      "                ",
      "                ",
      "                ",
      "                ",
      "   owoxowo      ",
      "   yA   Ay      ",
      "   BC   CD      ",
      "   yA   Ay      ",
      "   owoEowo      ",
      "                ",
      "                ",
      "                ",
      " ka ak   ka a   ",
      "  uiuj   juiu   "
    ],
    [
      "  hihj   jhih   ",
      "  a a     a a   ",
      "                ",
      "                ",
      "                ",
      "                ",
      "   o oFo o      ",
      "   w     w      ",
      "                ",
      "   w     w      ",
      "   o oIo o      ",
      "                ",
      "                ",
      "                ",
      "  a a     a a   ",
      "  uiuj   juiu   "
    ],
    [
      "  hihj   jhih   ",
      "  a a     a a   ",
      "  J J     J J   ",
      "                ",
      "                ",
      "                ",
      "   ooooooo      ",
      "   y  K  y      ",
      "   w  L  w      ",
      "   y  L  y      ",
      "   ooooooo      ",
      "                ",
      "                ",
      "  M M     M M   ",
      "  a a     a a   ",
      "   i j   j i    "
    ],
    [
      "  hihj   jhih   ",
      "  a a     a a   ",
      "                ",
      "                ",
      "                ",
      "                ",
      "   NNNNNNN      ",
      "   ooooooo      ",
      "   ooooooo      ",
      "   ooooooo      ",
      "   OOOOOOO      ",
      "                ",
      "                ",
      "                ",
      "  a a     a a   ",
      "   i j   j i    "
    ],
    [
      "  hihj   jhih   ",
      "  a a     a a   ",
      "                ",
      "                ",
      "                ",
      "                ",
      "                ",
      "                ",
      "                ",
      "                ",
      "                ",
      "                ",
      "                ",
      "                ",
      "  a a     a a   ",
      "   i j   j i    "
    ],
    [
      "PPQQQPPPPPQQQPPP",
      "PPaPaPPPPPaPaPPP",
      "  fjfjjjjjfjf   ",
      "  fff     fff   ",
      "  f f     f f   ",
      "  f f     f f   ",
      "  f f     f f   ",
      "  f f     f f   ",
      "  f f     f f   ",
      "  f f     f f   ",
      "  f f     f f   ",
      "  f f     f f   ",
      "  fff     f f   ",
      "  fjfjjjjjfjf   ",
      "PPaPaPPPPPaPaPPP",
      "PPRRRPPPPPRRRPPP"
    ],
    [
      "                ",
      "PPSPSPPPPPSPSPPP",
      "PPSPSPPPPPSPSPPP",
      "PPSPSPPPPPSPSPPP",
      "SS S SSSSS S SSS",
      "TTTTTTTTTTTTTTTT",
      "UUUUUUUUUUUUUUUU",
      "UUUUUUUUUUUUUUUU",
      "UUUUUUUUUUUUUUUU",
      "UUUUUUUUUUUUUUUU",
      "UUUUUUUUUUUUUUUU",
      "TTTTTTTTTTTTTTTT",
      "PP P PPPPP P PPP",
      "PPSPSPPPPPSPSPPP",
      "PPSPSPPPPPSPSPPP",
      "                "
    ]
  ]
}