{
  "name": "station_staircase_surface",
  "refpalette": "c70cities:station_staircase_surface_palette",
  "xsize": 16,
  "zsize": 16,
  "slices": [
    [
      "aaaaaaaaaaaaaaaa",
      "aGGabbbbbbbbbbba",
      "aGGabccbbbbbbbba",
      "aGGabbbbbbdddbba",
      "aGGabccbbbdcdbba",
      "aGGabbbbbbdddbba",
      "aGGabccbbbbbbbba",
      "aGGabbbbbbbbbbba",
      "aGGaaaaaaaaaaaaa",
      "aaaaaaaaaaaaaaaa",
      "eeeeeeeefffaaaaa",
      "fghhhhhhhhfaaaaa",
      "fghihihihifaaaaa",
      "fghh~~~~jjfaaaaa",
      "fghi~~~~jjfaaaaa",
      "eeeeeeeefffaaaaa"
    ],
    [
      "~~~~~~~~~~~~~~~~",
      "~kk~~~~~~~~~~~~~",
      "~kk~~~~~~~~~~~~~",
      "~lk~~~~~~~~~~~~~",
      "~kl~~~~~~~~m~~~~",
      "~kl~~~~~~~~~~~~~",
      "~kk~~~~~~~~~~~~~",
      "~lk~~~~~~~~~~~~~",
      "~kl~~~~~~~~~~~~~",
      "~~~~~~~~no~~no~~",
      "eppp~~~~e~~~~~q~",
      "pr~~~~~~st~~st~~",
      "pr~~~~~~~~~~~~~~",
      "pr~~~~~~~~~~~~~~",
      "pr~~~~~~~~~~~~~~",
      "epppppppe~~~~~~~"
    ],
    [
      "~~~~~~~~~~~~~~~~",
      "~uu~~~~~~~~~~~~~",
      "~uu~~~~~~~~~~~~~",
      "~~u~~~~~~~~~~~~~",
      "~u~~~~~~~wxyA~~~",
      "~u~~~~~~~~~~~~~~",
      "~uu~~~~~~~~~~~~~",
      "~~u~~~~~~~~~~~~~",
      "~u~~~~~~~~~~~~~~",
      "~~~~~~~~~~~~~~~~",
      "epp~~~~~~e~~~~~~",
      "p~~~~~~~~~~~~~~~",
      "pB~~~~~~~~~~~~~~",
      "pB~~~~~~~~~~~~~~",
      "p~~~~~~~~~~~~~~~",
      "epppp~~~~e~~~~~~"
    ],
    [
      "~~~~~~~~~~~~~~~~",
      "~~~~~~~~~~~~~~~~",
      "~~~~~~~~~~~~~~~~",
      "~~~~~~~~~~~~~~~~",
      "~~~~~~~~~C~~x~~~",
      "~~~~~~~~~~~~~~~~",
      "~~~~~~~~~~~~~~~~",
      "~~~~~~~~~~~~~~~~",
      "~~~~~~~~~~~~~~~~",
      "~~~~~~~~~~~~~~~~",
      "DDDEEE~~~~e~~~~~",
      "jjjFFF~~~~~~~~~~",
      "jjjFFF~~~~~~~~~~",
      "jjjFFF~~~~~~~~~~",
      "jjjFFF~~~~~~~~~~",
      "DDDEEE~~~~e~~~~~"
    ],
    [
      "~~~~~~~~~~~~~~~~",
      "~~~~~~~~~~~~~~~~",
      "~~~~~~~~~~~~~~~~",
      "~~~~~~~~~~~~~~~~",
      "~~~~~~~~~yyyy~~~",
      "~~~~~~~~~~~~~~~~",
      "~~~~~~~~~~~~~~~~",
      "~~~~~~~~~~~~~~~~",
      "~~~~~~~~~~~~~~~~",
      "~~~~~~~~~~~~~~~~",
      "~~~~~~DDDEEeE~~~",
      "~~~~~~jjjFFFF~~~",
      "~~~~~~jjjFFFF~~~",
      "~~~~~~jjjFFFF~~~",
      "~~~~~~jjjFFFF~~~",
      "~~~~~~DDDEEeE~~~"
    ]
  ]
}