{
  "name": "station_underground",
  "refpalette": "c70cities:station_underground_palette",
  "xsize": 16,
  "zsize": 16,
  "slices": [
    [
      "aaaaaaaaaaaaaaaa",
      "HHHHHHHHHHHHHHHH",
      "HHHHHHHHHHHHHHHH",
      "HHHHHHHHHHHHHHHH",
      "HHHHHHHHHHHHHHHH",
      "HHHHHHHHHHHHHHHH",
      "HHHHHHHHHHHHHHHH",
      "HHHHHHHHHHHHHHHH",
      "HHHHHHHHHHHHHHHH",
      "HHHHHHHHHHHHHHHH",
      "HHHHHHHHHHHHHHHH",
      "HHHHHHHHHHHHHHHH",
      "HHHHHHHHHHHHHHHH",
      "HHHHHHHHHHHHHHHH",
      "HHHHHHHHHHHHHHHH",
      "aaaaaaaaaaaaaaaa"
    ],
    [
      "aaaaaaaaaaaaaaaa",
      "HbbbcbbbHbbbHbbb",
      "bbbbbbbbbbbbbbbb",
      "bdbdbdbdbdbdbdbd",
      "eeeeeeeeeeeeeeee",
      "~~~~~~~~~~~~~~~~",
      "ffffffffffffffff",
      "~~~~~~~~~~~~~~~~",
      "~~~~~~~~~~~~~~~~",
      "ffffffffffffffff",
      "~~~~~~~~~~~~~~~~",
      "eeeeeeeeeeeeeeee",
      "bdbdbdbdbdbdbdbd",
      "bbbbbbbbbbbbbbbb",
      "HbbbHbbbHbbbcbbb",
      "aaaaaaaaaaaaaaaa"
    ],
    [
      "aaaaaaaaaaaaaaaa",
      "g   gh~hg   g  ~",
      "~~~~~~~~i~~~~~~~",
      "~~~~~~~~~~~~~~~~",
      "~~~~~~~~~~~~~~~~",
      "~~~~~~~~~~~~~~~~",
      "~~~~~~~~~~~~~~~~",
      "~~~~~~~~~~~~~~~~",
      "~~~~~~~~~~~~~~~~",
      "~~~~~~~~~~~~~~~~",
      "~~~~~~~~~~~~~~~~",
      "~~~~~~~~~~~~~~~~",
      "~~~~~~~~~~~~~~~~",
      "~~~~~~~~~~~~~~~~",
      "g   gh~hg   g  i",
      "aaaaaaaaaaaaaaaa"
    ],
    [
      "aaaaaaaaaaaaaaaa",
      "g~~~g~~~g~~~gi~~",
      "~~~~~~~~~~~~~~~~",
      "~~~~~~~~~~~~~~~~",
      "~~~~~~~~~~~~~~~~",
      "~~~~~~~~~~~~~~~~",
      "~~~~~~~~~~~~~~~~",
      "~~~~~~~~~~~~~~~~",
      "~~~~~~~~~~~~~~~~",
      "~~~~~~~~~~~~~~~~",
      "~~~~~~~~~~~~~~~~",
      "~~~~~~~~~~~~~~~~",
      "~~~~~~~~~~~~~~~~",
      "~~~~~~~~~~~~~~~~",
      "g~~~gi~~g~~~g~~~",
      "aaaaaaaaaaaaaaaa"
    ],
    [
      "aaaaaaaaaaaaaaaa",
      "gi~~g~~~g~~ig~~~",
      "j~~~j~~~j~~~j~~~",
      "j~~~j~~~j~~~j~~~",
      "j~~~j~~~j~~~j~~~",
      "~~~~~~~~~~~~~~~~",
      "~~~~~~~~~~~~~~~~",
      "~~~~~~~~~~~~~~~~",
      "~~~~~~~~~~~~~~~~",
      "~~~~~~~~~~~~~~~~",
      "~~~~~~~~~~~~~~~~",
      "j~~~j~~~j~~~j~~~",
      "j~~~j~~~j~~~j~~~",
      "j~~~j~~~j~~~j~~~",
      "g~~~g~~~g~~~gi~~",
      "aaaaaaaaaaaaaaaa"
    ],
    [
      "kkkkkkkkkkkkkkkk",
      "kkkkkkkkkkkkkkkk",
      "kkkkkkkkkkkkkkkk",
      "kkkkkkkkkkkkkkkk",
      "kkkkkkkkkkkkkkkk",
      "llllllllllllllll",
      "HvvvHvvvHvvvHvvv",
      "HvvvHvvvHvvvHvvv",
      "HvvvHvvvHvvvHvvv",
      "HvvvHvvvHvvvHvvv",
      "llllllllllllllll",
      "kkkkkkkkkkkkkkkk",
      "kkkkkkkkkkkkkkkk",
      "kkkkkkkkkkkkkkkk",
      "kkkkkkkkkkkkkkkk",
      "kkkkkkkkkkkkkkkk"
    ]
  ]
}