{
  "name": "station_staircase_surface",
  "refpalette": "c70cities:station_staircase_surface_palette",
  "xsize": 16,
  "zsize": 16,
  "slices": [
    [
      "aaaaaaaaaaaaabbb",
      "cdee~~~~~~ffcbbb",
      "cdeg~~~~~~ffcbbb",
      "aaaaaaaaaaaaabbb",
      "bGGbbbbbbbbbbbbb",
      "bGGbbbbbbbbbbbbb",
      "bGGbhhhhhhhhhhbb",
      "bGGbhihihhihihbb",
      "bGGbhihihhihihbb",
      "bGGbhhhhhhhhhhbb",
      "bGGbbbbbbbbbbbbb",
      "bbbbbbbbbbbbbbbb",
      "aaaaaaaaaaaaabbb",
      "cdee~~~~~~ffcbbb",
      "cdeg~~~~~~ffcbbb",
      "aaaaaaaaaaaaabbb"
    ],
    [
      "ajjjjjjja~~~~~~~",
      "kl~~~~~~~~~~~~~~",
      "kl~~~~~~~~~~~~~~",
      "ajjjjjjjam~~~~~~",
      "~~~~no~~no~~~~~~",
      "~p~~~~~~~~~~~~~~",
      "~~p~~~~~~~~~~~~~",
      "~p~~~~~q~~q~~~~~",
      "~~~~~~~~~~~~~~~~",
      "~~p~~~~~~~~~~~~~",
      "~p~~~~~~~~~~~~~~",
      "~~~~rs~~rs~~~~~~",
      "ajjjjjjjam~~~~~~",
      "kl~~~~~~~~~~~~~~",
      "kl~~~~~~~~~~~~~~",
      "ajjjjjjja~~~~~~~"
    ],
    [
      "ajjjjj~~~a~~~~~~",
      "kt~~~~~~~~~~~~~~",
      "kt~~~~~~~~~~~~~~",
      "ajjjjj~~~a~~~~~~",
      "~~~~~~~~~~~~~~~~",
      "~u~~~~~~~~~~~~~~",
      "~~u~~~~~~~~~~~~~",
      "~u~~~~wxyAxB~~~~",
      "~~~~~~~~~~~~~~~~",
      "~~u~~~~~~~~~~~~~",
      "~u~~~~~~~~~~~~~~",
      "~~~~~~~~~~~~~~~~",
      "ajjjjj~~~a~~~~~~",
      "kt~~~~~~~~~~~~~~",
      "kt~~~~~~~~~~~~~~",
      "ajjjjj~~~a~~~~~~"
    ],
    [
      "CCCDDD~~~~a~~~~~",
      "fffEEE~~~~~~~~~~",
      "fffEEE~~~~~~~~~~",
      "CCCDDD~~~~a~~~~~",
      "~~~~~~~~~~~~~~~~",
      "~~~~~~~~~~~~~~~~",
      "~~~~~~~~~~~~~~~~",
      "~~~~~~y~~~~A~~~~",
      "~~~~~~~~~~~~~~~~",
      "~~~~~~~~~~~~~~~~",
      "~~~~~~~~~~~~~~~~",
      "~~~~~~~~~~~~~~~~",
      "CCCDDD~~~~a~~~~~",
      "fffEEE~~~~~~~~~~",
      "fffEEE~~~~~~~~~~",
      "CCCDDD~~~~a~~~~~"
    ],
    [
      "~~~~~~CCCDDaD~~~",
      "~~~~~~fffEEEE~~~",
      "~~~~~~fffEEEE~~~",
      "~~~~~~CCCDDaD~~~",
      "~~~~~~~~~~~~~~~~",
      "~~~~~~~~~~~~~~~~",
      "~~~~~~~~~~~~~~~~",
      "~~~~~~xx~~xx~~~~",
      "~~~~~~~~~~~~~~~~",
      "~~~~~~~~~~~~~~~~",
      "~~~~~~~~~~~~~~~~",
      "~~~~~~~~~~~~~~~~",
      "~~~~~~CCCDDaD~~~",
      "~~~~~~fffEEEE~~~",
      "~~~~~~fffEEEE~~~",
      "~~~~~~CCCDDaD~~~"
    ],
    [
      "~~~~~~~~~~~~~~~~",
      "~~~~~~~~~~~~~~~~",
      "~~~~~~~~~~~~~~~~",
      "~~~~~~~~~~~~~~~~",
      "~~~~~~~~~~~~~~~~",
      "~~~~~~~~~~~~~~~~",
      "~~~~~~~~~~~~~~~~",
      "~~~~~~~~~~~~~~~~",
      "~~~~~~~~~~~~~~~~",
      "~~~~~~~~~~~~~~~~",
      "~~~~~~~~~~~~~~~~",
      "~~~~~~~~~~~~~~~~",
      "~~~~~~~~~~~~~~~~",
      "~~~~~~~~~~~~~~~~",
      "~~~~~~~~~~~~~~~~",
      "~~~~~~~~~~~~~~~~"
    ],
    [
      "~~~~~~~~~~~~~~~~",
      "~~~~~~~~~~~~~~~~",
      "~~~~~~~~~~~~~~~~",
      "~~~~~~~~~~~~~~~~",
      "~~~~~~~~~~~~~~~~",
      "~~~~~~~~~~~~~~~~",
      "~~~~~~~~~~~~~~~~",
      "~~~~~~~~~~~~~~~~",
      "~~~~~~~~~~~~~~~~",
      "~~~~~~~~~~~~~~~~",
      "~~~~~~~~~~~~~~~~",
      "~~~~~~~~~~~~~~~~",
      "~~~~~~~~~~~~~~~~",
      "~~~~~~~~~~~~~~~~",
      "~~~~~~~~~~~~~~~~",
      "~~~~~~~~~~~~~~~~"
    ],
    [
      "~~~~~~~~~~~~~~~~",
      "~~~~~~~~~~~~~~~~",
      "~~~~~~~~~~~~~~~~",
      "~~~~~~~~~~~~~~~~",
      "~~~~~~~~~~~~~~~~",
      "~~~~~~~~~~~~~~~~",
      "~~~~~~~~~~~~~~~~",
      "~~~~~~~~~~~~~~~~",
      "~~~~~~~~~~~~~~~~",
      "~~~~~~~~~~~~~~~~",
      "~~~~~~~~~~~~~~~~",
      "~~~~~~~~~~~~~~~~",
      "~~~~~~~~~~~~~~~~",
      "~~~~~~~~~~~~~~~~",
      "~~~~~~~~~~~~~~~~",
      "~~~~~~~~~~~~~~~~"
    ],
    [
      "~~~~~~~~~~~~~~~~",
      "~~~~~~~~~~~~~~~~",
      "~~~~~~~~~~~~~~~~",
      "~~~~~~~~~~~~~~~~",
      "~~~~~~~~~~~~~~~~",
      "~~~~~~~~~~~~~~~~",
      "~~~~~~~~~~~~~~~~",
      "~~~~~~~~~~~~~~~~",
      "~~~~~~~~~~~~~~~~",
      "~~~~~~~~~~~~~~~~",
      "~~~~~~~~~~~~~~~~",
      "~~~~~~~~~~~~~~~~",
      "~~~~~~~~~~~~~~~~",
      "~~~~~~~~~~~~~~~~",
      "~~~~~~~~~~~~~~~~",
      "~~~~~~~~~~~~~~~~"
    ]
  ]
}