{
  "name": "station_staircase",
  "refpalette": "c70cities:station_staircase_palette",
  "xsize": 16,
  "zsize": 16,
  "slices": [
    [
      "                ",
      "                ",
      "                ",
      "                ",
      "                ",
      "                ",
      "                ",
      "                ",
      "                ",
      "                ",
      "aaaaaaaaaaa     ",
      "bcccccccccb     ",
      "b~~~~~~~~~b     ",
      "bdd~~~~~~~b     ",
      "bdd~~~~~~~b     ",
      "bbbbbbbbbbb     "
    ],
    [
      "                ",
      "                ",
      "                ",
      "                ",
      "                ",
      "                ",
      "                ",
      "                ",
      "                ",
      "                ",
      "aaaaaaaaaaa     ",
      "bc~~c~cc~cb     ",
      "b~~~~~~~~~b     ",
      "b~~d~~~~~~b     ",
      "b~~d~~~~~~b     ",
      "bbbbbbbbbbb     "
    ],
    [
      "                ",
      "                ",
      "                ",
      "                ",
      "                ",
      "                ",
      "                ",
      "                ",
      "                ",
      "                ",
      "aaaaaaaaaaa     ",
      "bceec~c~ccb     ",
      "b~~~~~~~~~b     ",
      "b~~~d~~~~~b     ",
      "b~~~d~~~~~b     ",
      "bbbbbbbbbbb     "
    ],
    [
      "                ",
      "                ",
      "                ",
      "                ",
      "                ",
      "                ",
      "                ",
      "                ",
      "                ",
      "                ",
      "aaaaaaaaaaa     ",
      "bcffccc~ccb     ",
      "b~~~~~~~~~b     ",
      "b~~~~d~~~~b     ",
      "b~~~~d~~~~b     ",
      "bbbbbbbbbbb     "
    ],
    [
      "                ",
      "                ",
      "                ",
      "                ",
      "                ",
      "                ",
      "                ",
      "                ",
      "                ",
      "                ",
      "aaaaaaaaaaa     ",
      "bcccccccccb     ",
      "bg~~~~~~~~b     ",
      "b~~~~~d~~~b     ",
      "b~~~~~d~~~b     ",
      "bbbbbbbbbbb     "
    ],
    [
      "                ",
      "                ",
      "                ",
      "                ",
      "                ",
      "                ",
      "                ",
      "                ",
      "                ",
      "                ",
      "aaaaaaaaaaa     ",
      "bhhhhhhhhhb     ",
      "bhhhhhhhhhb     ",
      "bhh~~~~dhhb     ",
      "bhh~~~~dhhb     ",
      "bbbbbbbbbbb     "
    ]
  ]
}