{
  "name": "station_underground",
  "refpalette": "c70cities:station_underground_palette",
  "xsize": 16,
  "zsize": 16,
  "slices": [
    [
      "aaaaaaaaaaaaaaaa",
      "HHHHHHHHHHHHHHHH",
      "HHHHHHHHHHHHHHHH",
      "HHHHHHHHHHHHHHHH",
      "HHHHHHHHHHHHHHHH",
      "HHHHHHHHHHHHHHHH",
      "HHHHHHHHHHHHHHHH",
      "HHHHHHHHHHHHHHHH",
      "HHHHHHHHHHHHHHHH",
      "HHHHHHHHHHHHHHHH",
      "HHHHHHHHHHHHHHHH",
      "HHHHHHHHHHHHHHHH",
      "HHHHHHHHHHHHHHHH",
      "HHHHHHHHHHHHHHHH",
      "HHHHHHHHHHHHHHHH",
      "aaaaaaaaaaaaaaaa"
    ],
    [
      "aaaaaaaaaaaaaaaa",
      "HbbbcbbbHbbbHbbb",
      "bbbbbbbbbbbbbbbb",
      "bdbdbdbdbdbdbdbd",
      "eeeeeeeeeeeeeeee",
      "~~~~~~~~~~~~~~~~",
      "~~~~~~~~~~~~~~~~",
      "~~~~~~~~~~~~~~~~",
      "ffffffffffffffff",
      "~~~~~~~~~~~~~~~~",
      "~~~~~~~~~~~~~~~~",
      "~~~~~~~~~~~~~~~~",
      "eeeeeeeeeeeeeeee",
      "bdbdbdbdbdbdbdbd",
      "HbbbHbbbHbbbcbbb",
      "aaaaaaaaaaaaaaaa"
    ],
    [
      "aaaaaaaaaaaaaaaa",
      "g~~hgi~ig~~~gh~~",
      "~~~~~~~~j~~~~~~~",
      "~~~~~~~~~~~~~~~~",
      "~~~~~~~~~~~~~~~~",
      "~~~~~~~~~~~~~~~~",
      "~~~~~~~~~~~~~~~~",
      "~~~~~~~~~~~~~~~~",
      "~~~~~~~~~~~~~~~~",
      "~~~~~~~~~~~~~~~~",
      "~~~~~~~~~~~~~~~~",
      "~~~~~~~~~~~~~~~~",
      "~~~~~~~~~~~~~~~~",
      "~~~~~~~~~~~~~~~~",
      "g~~hgi~ig~~~gh~j",
      "aaaaaaaaaaaaaaaa"
    ],
    [
      "aaaaaaaaaaaaaaaa",
      "g~~hg~~~g~~~gj~~",
      "~~~~~~~~~~~~~~~~",
      "~~~~~~~~~~~~~~~~",
      "~~~~~~~~~~~~~~~~",
      "~~~~~~~~~~~~~~~~",
      "~~~~~~~~~~~~~~~~",
      "~~~~~~~~~~~~~~~~",
      "~~~~~~~~~~~~~~~~",
      "~~~~~~~~~~~~~~~~",
      "~~~~~~~~~~~~~~~~",
      "~~~~~~~~~~~~~~~~",
      "~~~~~~~~~~~~~~~~",
      "~~~~~~~~~~~~~~~~",
      "g~~hgj~~g~~~gh~~",
      "aaaaaaaaaaaaaaaa"
    ],
    [
      "aaaaaaaaaaaaaaaa",
      "gj~hg~~~g~~jgh~~",
      "~~~~~~~~~~~~~~~~",
      "~~~~~~~~~~~~~~~~",
      "~~~~~~~~~~~~~~~~",
      "~~~~~~~~~~~~~~~~",
      "~~~~~~~~~~~~~~~~",
      "~~~~~~~~~~~~~~~~",
      "~~~~~~~~~~~~~~~~",
      "~~~~~~~~~~~~~~~~",
      "~~~~~~~~~~~~~~~~",
      "~~~~~~~~~~~~~~~~",
      "~~~~~~~~~~~~~~~~",
      "~~~~~~~~~~~~~~~~",
      "g~~hg~~~g~~~gj~~",
      "aaaaaaaaaaaaaaaa"
    ],
    [
      "aaaaaaaaaaaaaaaa",
      "gkkkgkkkgkkkgkkk",
      "~~~~~~~~~~~~~~~~",
      "~~~~~~~~~~~~~~~~",
      "~~~~~~~~~~~~~~~~",
      "~~~~~~~~~~~~~~~~",
      "~~~~~~~~~~~~~~~~",
      "~~~~~~~~~~~~~~~~",
      "~~~~~~~~~~~~~~~~",
      "~~~~~~~~~~~~~~~~",
      "~~~~~~~~~~~~~~~~",
      "~~~~~~~~~~~~~~~~",
      "~~~~~~~~~~~~~~~~",
      "~~~~~~~~~~~~~~~~",
      "gkkkgkkkgkkkgkkk",
      "aaaaaaaaaaaaaaaa"
    ],
    [
      "aaaaaaaaaaaaaaaa",
      "g~~~g~~~g~~~g~~~",
      "~~~~~~~~~~~~~~~~",
      "~~~~~~~~~~~~~~~~",
      "~~~~~~~~~~~~~~~~",
      "~~~~~~~~~~~~~~~~",
      "~~~~~~~~~~~~~~~~",
      "~~~~~~~~~~~~~~~~",
      "~~~~~~~~~~~~~~~~",
      "~~~~~~~~~~~~~~~~",
      "~~~~~~~~~~~~~~~~",
      "~~~~~~~~~~~~~~~~",
      "~~~~~~~~~~~~~~~~",
      "~~~~~~~~~~~~~~~~",
      "g~~~g~~~g~~~g~~~",
      "aaaaaaaaaaaaaaaa"
    ],
    [
      "aaaaaaaaaaaaaaaa",
      "gjllglllglljglll",
      "m~~~m~~~m~~~m~~~",
      "m~~~m~~~m~~~m~~~",
      "m~~~m~~~m~~~m~~~",
      "m~~~m~~~m~~~m~~~",
      "~~~~~~~~~~~~~~~~",
      "~~~~~~~~~~~~~~~~",
      "~~~~~~~~~~~~~~~~",
      "~~~~~~~~~~~~~~~~",
      "~~~~~~~~~~~~~~~~",
      "m~~~m~~~m~~~m~~~",
      "m~~~m~~~m~~~m~~~",
      "m~~~m~~~m~~~m~~~",
      "glllglllglllglll",
      "aaaaaaaaaaaaaaaa"
    ],
    [
      "kkkkkkkkkkkkkkkk",
      "kkkkkkkkkkkkkkkk",
      "kkkkkkkkkkkkkkkk",
      "kkkkkkkkkkkkkkkk",
      "kkkkkkkkkkkkkkkk",
      "nnnnnnnnnnnnnnnn",
      "HvvvHvvvHvvvHvvv",
      "HvvvHvvvHvvvHvvv",
      "HvvvHvvvHvvvHvvv",
      "HvvvHvvvHvvvHvvv",
      "HvvvHvvvHvvvHvvv",
      "nnnnnnnnnnnnnnnn",
      "kkkkkkkkkkkkkkkk",
      "kkkkkkkkkkkkkkkk",
      "kkkkkkkkkkkkkkkk",
      "kkkkkkkkkkkkkkkk"
    ]
  ]
}