{
  "name": "station_staircase",
  "refpalette": "c70cities:station_staircase_palette",
  "xsize": 16,
  "zsize": 16,
  "slices": [
    [
      "aaaaaaaaaaaaaaaa",
      "abbb~~~~~~ccbbba",
      "abbb~~~~~~ccbbba",
      "abbbbbbbbbbbbbba",
      "abbbbbbbbbbbbbba",
      "~~~~~~~~~~~~~~~~",
      "~~~~~~~~~~~~~~~~",
      "~~~~~~~~~~~~~~~~",
      "~~~~~~~~~~~~~~~~",
      "~~~~~~~~~~~~~~~~",
      "~~~~~~~~~~~~~~~~",
      "abbbbbbbbbbbbbba",
      "abbbbbbbbbbbbbba",
      "abbb~~~~~~ccbbba",
      "abbb~~~~~~ccbbba",
      "aaaaaaaaaaaaaaaa"
    ],
    [
      "aaaaaaaaaaaaaaaa",
      "a~~c~~~~~~~~~dea",
      "a~~c~~~~~~~~~dfa",
      "a~~~~~~~~~~~~dfa",
      "aggahhhhhhaggdfa",
      "abbb~~~~~~bbbbea",
      "abbb~~~~~~bbbbea",
      "abbb~~~~~~bbbbea",
      "abbb~~~~~~bbbbea",
      "abbb~~~~~~bbbbea",
      "abbb~~~~~~bbbbea",
      "aggahhhhhhaggdfa",
      "a~~~~~~~~~~~~dfa",
      "a~~c~~~~~~~~~dfa",
      "a~~c~~~~~~~~~dea",
      "aaaaaaaaaaaaaaaa"
    ],
    [
      "aaaaaaaaaaaaaaaa",
      "a~~~c~~~~~~~~~ea",
      "a~~~c~~~~~~~~~~a",
      "a~~~~~~~~~~~~~~a",
      "a~~a~~~~~~a~~~~a",
      "a~~h~~~~~~h~~dea",
      "a~~h~~~~~~h~~dfa",
      "a~~h~~~~~~h~~dfa",
      "a~~h~~~~~~h~~dfa",
      "a~~h~~~~~~h~~dfa",
      "a~~h~~~~~~h~~dea",
      "a~~a~~~~~~a~~~~a",
      "a~~~~~~~~~~~~~~a",
      "a~~~c~~~~~~~~~~a",
      "a~~~c~~~~~~~~~ea",
      "aaaaaaaaaaaaaaaa"
    ],
    [
      "aaaaaaaaaaaaaaaa",
      "a~~~~cc~~~~~~~ea",
      "a~~~~cc~~~~~~~~a",
      "a~~~~~~~~~~~~~ia",
      "a~~a~~~~~~a~~~~a",
      "a~~~~~~~~~~~~~ea",
      "a~~~~~~~~~~~~~ia",
      "a~~~~~~~~~~~~~~a",
      "a~~~~~~~~~~~~~~a",
      "a~~~~~~~~~~~~~ia",
      "a~~~~~~~~~~~~~ea",
      "a~~a~~~~~~a~~~~a",
      "a~~~~~~~~~~~~~~a",
      "a~~~~cc~~~~~~~ia",
      "a~~~~cc~~~~~~~ea",
      "aaaaaaaaaaaaaaaa"
    ],
    [
      "aaaaaaaaaaaaaaaa",
      "a~~~~~~c~~~~~~ea",
      "a~~~~~~c~~~~~~ia",
      "a~~~~~~~~~~~~~ja",
      "a~~k~~~~~~k~~~ia",
      "a~~~~~~~~~~~~~ea",
      "a~~~~~~~~~~~~~ja",
      "a~~~~~~~~~~~~~ia",
      "a~~~~~~~~~~~~~ia",
      "a~~~~~~~~~~~~~ja",
      "a~~~~~~~~~~~~~ea",
      "a~~k~~~~~~k~~~ia",
      "a~~~~~~~~~~~~~ia",
      "a~~~~~~c~~~~~~ja",
      "a~~~~~~c~~~~~~ea",
      "aaaaaaaaaaaaaaaa"
    ],
    [
      "aaaaaaaaaaaaaaaa",
      "alll~~~~ccalllla",
      "alll~~~~ccalllla",
      "alllllllllllllla",
      "alllllllllllllla",
      "alll~~~~~~llllla",
      "alll~~~~~~llllla",
      "alll~~~~~~llllla",
      "alll~~~~~~llllla",
      "alll~~~~~~llllla",
      "alll~~~~~~llllla",
      "alllllllllllllla",
      "alllllllllllllla",
      "alll~~~~ccalllla",
      "alll~~~~ccalllla",
      "aaaaaaaaaaaaaaaa"
    ]
  ]
}